Workbook
Name JanActual: #REF!
Name JanActual2: #REF!
Name JanExpected: #REF!
Name JanExpectedDelta: #REF!
Name JanExpectedPercent: #REF!
Name JanExpPercent: #REF!
Name JanForecasted: #REF!
Name JanForecastedDelta: #REF!
Name JanForecastedPercent: #REF!
Name portfolio: Sites!$B$1:$B$1
Name Year: Sites!#REF!

Sheet Year to Date
A1: {=portfolio} -> City of Peoria | D1: Year to Date Actual v. Expected | G1: Year to Date Actual v. Forecasted
A2: Total | C2: =SUM(C4:C97) -> 3493009.1 | D2: =SUM(D4:D97) -> 3441136.5 | E2: =C2-D2 -> 51872.584 | F2: =IFERROR(E2/D2, 0) -> 0.015074259 | G2: =SUM(G4:G97) -> 3752275 | H2: =C2-G2 -> -259265.98 | I2: =IFERROR(H2/G2, 0) -> -0.069095675
A3: Site | B3: State | C3: Actual | D3: Expected | E3: Delta | F3: % | G3: Forecasted | H3: Delta | I3: %
A4: {=Sites[Site]} -> AZ: Peoria - Beardsley WWTP - Ad. Bldg | B4: {=Sites[State]} -> AZ | C4: =SUM('1st Qtr'!C4, '2nd Qtr'!C4, '3rd Qtr'!C4, '4th Qtr'!C4) -> 83316.666 | D4: =SUM('1st Qtr'!D4, '2nd Qtr'!D4, '3rd Qtr'!D4, '4th Qtr'!D4) -> 74989.692 | E4: =IF(AND(ISNUMBER(C4),ISNUMBER(D4)), C4-D4, "") -> 8326.9744 | F4: =IFERROR(E4/D4, "") -> 0.11104159 | G4: =SUM('1st Qtr'!G4,'2nd Qtr'!G4,'3rd Qtr'!G4,'4th Qtr'!G4) -> 159640.03 | H4: =SUM('1st Qtr'!H4, '2nd Qtr'!H4, '3rd Qtr'!H4, '4th Qtr'!H4) -> -76323.363 | I4: =IFERROR(H4/G4, "") -> -0.47809665
A5: AZ: Peoria - Fire Station 191 | B5: AZ | C5: =SUM('1st Qtr'!C5, '2nd Qtr'!C5, '3rd Qtr'!C5, '4th Qtr'!C5) -> 161199.69 | D5: =SUM('1st Qtr'!D5, '2nd Qtr'!D5, '3rd Qtr'!D5, '4th Qtr'!D5) -> 138421.97 | E5: =IF(AND(ISNUMBER(C5),ISNUMBER(D5)), C5-D5, "") -> 22777.728 | F5: =IFERROR(E5/D5, "") -> 0.16455284 | G5: =SUM('1st Qtr'!G5,'2nd Qtr'!G5,'3rd Qtr'!G5,'4th Qtr'!G5) -> 160628 | H5: =SUM('1st Qtr'!H5, '2nd Qtr'!H5, '3rd Qtr'!H5, '4th Qtr'!H5) -> 571.6942 | I5: =IFERROR(H5/G5, "") -> 0.0035591192
A6: AZ: Peoria - Fire Station 195 | B6: AZ | C6: =SUM('1st Qtr'!C6, '2nd Qtr'!C6, '3rd Qtr'!C6, '4th Qtr'!C6) -> 80378.841 | D6: =SUM('1st Qtr'!D6, '2nd Qtr'!D6, '3rd Qtr'!D6, '4th Qtr'!D6) -> 80737.501 | E6: =IF(AND(ISNUMBER(C6),ISNUMBER(D6)), C6-D6, "") -> -358.66015 | F6: =IFERROR(E6/D6, "") -> -0.0044422994 | G6: =SUM('1st Qtr'!G6,'2nd Qtr'!G6,'3rd Qtr'!G6,'4th Qtr'!G6) -> 93968.815 | H6: =SUM('1st Qtr'!H6, '2nd Qtr'!H6, '3rd Qtr'!H6, '4th Qtr'!H6) -> -13589.974 | I6: =IFERROR(H6/G6, "") -> -0.14462217
A7: AZ: Peoria - Fire Station 196 | B7: AZ | C7: =SUM('1st Qtr'!C7, '2nd Qtr'!C7, '3rd Qtr'!C7, '4th Qtr'!C7) -> 59289.72 | D7: =SUM('1st Qtr'!D7, '2nd Qtr'!D7, '3rd Qtr'!D7, '4th Qtr'!D7) -> 0 | E7: =IF(AND(ISNUMBER(C7),ISNUMBER(D7)), C7-D7, "") -> 59289.72 | F7: =IFERROR(E7/D7, 0) -> 0 | G7: =SUM('1st Qtr'!G7,'2nd Qtr'!G7,'3rd Qtr'!G7,'4th Qtr'!G7) -> 0 | H7: =SUM('1st Qtr'!H7, '2nd Qtr'!H7, '3rd Qtr'!H7, '4th Qtr'!H7) -> 59289.72 | I7: =IFERROR(H7/G7, 0) -> 0
A8: AZ: Peoria - Fire Station 197 | B8: AZ | C8: =SUM('1st Qtr'!C8, '2nd Qtr'!C8, '3rd Qtr'!C8, '4th Qtr'!C8) -> 23292.79 | D8: =SUM('1st Qtr'!D8, '2nd Qtr'!D8, '3rd Qtr'!D8, '4th Qtr'!D8) -> 97548.573 | E8: =IF(AND(ISNUMBER(C8),ISNUMBER(D8)), C8-D8, "") -> -74255.783 | F8: =IFERROR(E8/D8, "") -> -0.76121854 | G8: =SUM('1st Qtr'!G8,'2nd Qtr'!G8,'3rd Qtr'!G8,'4th Qtr'!G8) -> 118786.22 | H8: =SUM('1st Qtr'!H8, '2nd Qtr'!H8, '3rd Qtr'!H8, '4th Qtr'!H8) -> -95493.426 | I8: =IFERROR(H8/G8, "") -> -0.80390999
A9: AZ: Peoria - Sunrise Library | B9: AZ | C9: =SUM('1st Qtr'!C9, '2nd Qtr'!C9, '3rd Qtr'!C9, '4th Qtr'!C9) -> 316504.99 | D9: =SUM('1st Qtr'!D9, '2nd Qtr'!D9, '3rd Qtr'!D9, '4th Qtr'!D9) -> 278446.52 | E9: =IF(AND(ISNUMBER(C9),ISNUMBER(D9)), C9-D9, "") -> 38058.472 | F9: =IFERROR(E9/D9, "") -> 0.13668144 | G9: =SUM('1st Qtr'!G9,'2nd Qtr'!G9,'3rd Qtr'!G9,'4th Qtr'!G9) -> 367402 | H9: =SUM('1st Qtr'!H9, '2nd Qtr'!H9, '3rd Qtr'!H9, '4th Qtr'!H9) -> -50897.008 | I9: =IFERROR(H9/G9, "") -> -0.1385322
A10: AZ: Peoria - Beardsley WWTP | B10: AZ | C10: =SUM('1st Qtr'!C10, '2nd Qtr'!C10, '3rd Qtr'!C10, '4th Qtr'!C10) -> 2295929 | D10: =SUM('1st Qtr'!D10, '2nd Qtr'!D10, '3rd Qtr'!D10, '4th Qtr'!D10) -> 2449622.4 | E10: =IF(AND(ISNUMBER(C10),ISNUMBER(D10)), C10-D10, "") -> -153693.4 | F10: =IFERROR(E10/D10, "") -> -0.06274167 | G10: =SUM('1st Qtr'!G10,'2nd Qtr'!G10,'3rd Qtr'!G10,'4th Qtr'!G10) -> 2226921 | H10: =SUM('1st Qtr'!H10, '2nd Qtr'!H10, '3rd Qtr'!H10, '4th Qtr'!H10) -> 69008 | I10: =IFERROR(H10/G10, "") -> 0.030988077
A11: AZ: Peoria - City Hall | B11: AZ | C11: =SUM('1st Qtr'!C11, '2nd Qtr'!C11, '3rd Qtr'!C11, '4th Qtr'!C11) -> 209989.37 | D11: =SUM('1st Qtr'!D11, '2nd Qtr'!D11, '3rd Qtr'!D11, '4th Qtr'!D11) -> 194665.27 | E11: =IF(AND(ISNUMBER(C11),ISNUMBER(D11)), C11-D11, "") -> 15324.1 | F11: =IFERROR(E11/D11, "") -> 0.078720257 | G11: =SUM('1st Qtr'!G11,'2nd Qtr'!G11,'3rd Qtr'!G11,'4th Qtr'!G11) -> 350839.99 | H11: =SUM('1st Qtr'!H11, '2nd Qtr'!H11, '3rd Qtr'!H11, '4th Qtr'!H11) -> -141711.08 | I11: =IFERROR(H11/G11, "") -> -0.4039194
A12: AZ: Peoria - Pinnacle Peak | B12: AZ | C12: =SUM('1st Qtr'!C12, '2nd Qtr'!C12, '3rd Qtr'!C12, '4th Qtr'!C12) -> 263108 | D12: =SUM('1st Qtr'!D12, '2nd Qtr'!D12, '3rd Qtr'!D12, '4th Qtr'!D12) -> 126704.57 | E12: =IF(AND(ISNUMBER(C12),ISNUMBER(D12)), C12-D12, "") -> 136403.43 | F12: =IFERROR(E12/D12, "") -> 1.0765471 | G12: =SUM('1st Qtr'!G12,'2nd Qtr'!G12,'3rd Qtr'!G12,'4th Qtr'!G12) -> 274089 | H12: =SUM('1st Qtr'!H12, '2nd Qtr'!H12, '3rd Qtr'!H12, '4th Qtr'!H12) -> -10981 | I12: =IFERROR(H12/G12, "") -> -0.040063629

Sheet 1st Qtr
A1: {=portfolio} -> City of Peoria | D1: 1st Quarter Actual v. Expected | G1: 1st Quarter Actual v. Forecasted
A2: Total | C2: =SUM(C4:C96) -> 736720 | D2: =SUM(D4:D96) -> 721451.33 | E2: =C2-D2 -> 15268.672 | F2: =IFERROR(E2/D2, 0) -> 0.021163828 | G2: =SUM(G4:G96) -> 847363.96 | H2: =C2-G2 -> -110643.96 | I2: =IFERROR(H2/G2, 0) -> -0.1305743
A3: Site | B3: State | C3: Actual | D3: Expected | E3: Delta | F3: % | G3: Forecasted | H3: Delta | I3: %
A4: {=Sites[Site]} -> AZ: Peoria - Beardsley WWTP - Ad. Bldg | B4: {=Sites[State]} -> AZ | C4: =SUM(Jan!C4, Feb!C4, Mar!C4) -> 16455.855 | D4: =SUM(Jan!D4, Feb!D4, Mar!D4) -> 12969.027 | E4: =IF(AND(ISNUMBER(C4),ISNUMBER(D4)), C4-D4, "") -> 3486.8285 | F4: =IFERROR(E4/D4, "") -> 0.26885814 | G4: =SUM(Jan!G4, Feb!G4, Mar!G4) -> 31737.821 | H4: =SUM(Jan!H4, Feb!H4, Mar!H4) -> -15281.966 | I4: =IFERROR(H4/G4, "") -> -0.48150645
A5: AZ: Peoria - Fire Station 191 | B5: AZ | C5: =SUM(Jan!C5, Feb!C5, Mar!C5) -> 32853.712 | D5: =SUM(Jan!D5, Feb!D5, Mar!D5) -> 28830.925 | E5: =IF(AND(ISNUMBER(C5),ISNUMBER(D5)), C5-D5, "") -> 4022.7873 | F5: =IFERROR(E5/D5, "") -> 0.13953029 | G5: =SUM(Jan!G5, Feb!G5, Mar!G5) -> 35205 | H5: =SUM(Jan!H5, Feb!H5, Mar!H5) -> -2351.2877 | I5: =IFERROR(H5/G5, "") -> -0.066788459
A6: AZ: Peoria - Fire Station 195 | B6: AZ | C6: =SUM(Jan!C6, Feb!C6, Mar!C6) -> 16098.688 | D6: =SUM(Jan!D6, Feb!D6, Mar!D6) -> 15356.848 | E6: =IF(AND(ISNUMBER(C6),ISNUMBER(D6)), C6-D6, "") -> 741.84031 | F6: =IFERROR(E6/D6, "") -> 0.048306808 | G6: =SUM(Jan!G6, Feb!G6, Mar!G6) -> 20490.702 | H6: =SUM(Jan!H6, Feb!H6, Mar!H6) -> -4392.0137 | I6: =IFERROR(H6/G6, "") -> -0.21434179
A7: AZ: Peoria - Fire Station 196 | B7: AZ | C7: =SUM(Jan!C7, Feb!C7, Mar!C7) -> 11913.281 | D7: =SUM(Jan!D7, Feb!D7, Mar!D7) -> 0 | E7: =IF(AND(ISNUMBER(C7),ISNUMBER(D7)), C7-D7, "") -> 11913.281 | F7: =IFERROR(E7/D7, 0) -> 0 | G7: =SUM(Jan!G7, Feb!G7, Mar!G7) -> 0 | H7: =SUM(Jan!H7, Feb!H7, Mar!H7) -> 11913.281 | I7: =IFERROR(H7/G7, 0) -> 0
A8: AZ: Peoria - Fire Station 197 | B8: AZ | C8: =SUM(Jan!C8, Feb!C8, Mar!C8) -> 24755.487 | D8: =SUM(Jan!D8, Feb!D8, Mar!D8) -> 19852.923 | E8: =IF(AND(ISNUMBER(C8),ISNUMBER(D8)), C8-D8, "") -> 4902.5639 | F8: =IFERROR(E8/D8, "") -> 0.24694419 | G8: =SUM(Jan!G8, Feb!G8, Mar!G8) -> 25838.861 | H8: =SUM(Jan!H8, Feb!H8, Mar!H8) -> -1083.3741 | I8: =IFERROR(H8/G8, "") -> -0.04192809
A9: AZ: Peoria - Sunrise Library | B9: AZ | C9: =SUM(Jan!C9, Feb!C9, Mar!C9) -> 63863.231 | D9: =SUM(Jan!D9, Feb!D9, Mar!D9) -> 48887.25 | E9: =IF(AND(ISNUMBER(C9),ISNUMBER(D9)), C9-D9, "") -> 14975.981 | F9: =IFERROR(E9/D9, "") -> 0.30633715 | G9: =SUM(Jan!G9, Feb!G9, Mar!G9) -> 80048 | H9: =SUM(Jan!H9, Feb!H9, Mar!H9) -> -16184.769 | I9: =IFERROR(H9/G9, "") -> -0.2021883
A10: AZ: Peoria - Beardsley WWTP | B10: AZ | C10: =SUM(Jan!C10, Feb!C10, Mar!C10) -> 450652 | D10: =SUM(Jan!D10, Feb!D10, Mar!D10) -> 496026.1 | E10: =IF(AND(ISNUMBER(C10),ISNUMBER(D10)), C10-D10, "") -> -45374.1 | F10: =IFERROR(E10/D10, "") -> -0.091475227 | G10: =SUM(Jan!G10, Feb!G10, Mar!G10) -> 483706 | H10: =SUM(Jan!H10, Feb!H10, Mar!H10) -> -33054 | I10: =IFERROR(H10/G10, "") -> -0.068334898
A11: AZ: Peoria - City Hall | B11: AZ | C11: =SUM(Jan!C11, Feb!C11, Mar!C11) -> 66030.5 | D11: =SUM(Jan!D11, Feb!D11, Mar!D11) -> 63679.03 | E11: =IF(AND(ISNUMBER(C11),ISNUMBER(D11)), C11-D11, "") -> 2351.47 | F11: =IFERROR(E11/D11, "") -> 0.036926913 | G11: =SUM(Jan!G11, Feb!G11, Mar!G11) -> 110627.58 | H11: =SUM(Jan!H11, Feb!H11, Mar!H11) -> -44597.08 | I11: =IFERROR(H11/G11, "") -> -0.40312804
A12: AZ: Peoria - Pinnacle Peak | B12: AZ | C12: =SUM(Jan!C12, Feb!C12, Mar!C12) -> 54097.25 | D12: =SUM(Jan!D12, Feb!D12, Mar!D12) -> 35849.23 | E12: =IF(AND(ISNUMBER(C12),ISNUMBER(D12)), C12-D12, "") -> 18248.02 | F12: =IFERROR(E12/D12, "") -> 0.50902125 | G12: =SUM(Jan!G12, Feb!G12, Mar!G12) -> 59710 | H12: =SUM(Jan!H12, Feb!H12, Mar!H12) -> -5612.75 | I12: =IFERROR(H12/G12, "") -> -0.094000167

Sheet 2nd Qtr
A1: {=portfolio} -> City of Peoria | D1: 2nd Quarter Actual v. Expected | G1: 2nd Quarter Actual v. Forecasted
A2: Total | C2: =SUM(C4:C97) -> 1067912.5 | D2: =SUM(D4:D97) -> 1079461.2 | E2: =C2-D2 -> -11548.662 | F2: =IFERROR(E2/D2, 0) -> -0.010698543 | G2: =SUM(G4:G97) -> 1041663 | H2: =C2-G2 -> 26249.565 | I2: =IFERROR(H2/G2, 0) -> 0.025199671
A3: Site | B3: State | C3: Actual | D3: Expected | E3: Delta | F3: % | G3: Forecasted | H3: Delta | I3: %
A4: {=Sites[Site]} -> AZ: Peoria - Beardsley WWTP - Ad. Bldg | B4: {=Sites[State]} -> AZ | C4: =SUM(Apr!C4, May!C4, Jun!C4) -> 27340.573 | D4: =SUM(Apr!D4, May!D4, Jun!D4) -> 27234.171 | E4: =IF(AND(ISNUMBER(C4),ISNUMBER(D4)), C4-D4, "") -> 106.40166 | F4: =IFERROR(E4/D4, "") -> 0.0039069174 | G4: =SUM(Apr!G4,May!G4,Jun!G4) -> 53488.8 | H4: =SUM(Apr!H4, May!H4, Jun!H4) -> -26148.227 | I4: =IFERROR(H4/G4, "") -> -0.48885425
A5: AZ: Peoria - Fire Station 191 | B5: AZ | C5: =SUM(Apr!C5, May!C5, Jun!C5) -> 47966.597 | D5: =SUM(Apr!D5, May!D5, Jun!D5) -> 43109.28 | E5: =IF(AND(ISNUMBER(C5),ISNUMBER(D5)), C5-D5, "") -> 4857.3174 | F5: =IFERROR(E5/D5, "") -> 0.11267452 | G5: =SUM(Apr!G5,May!G5,Jun!G5) -> 49116 | H5: =SUM(Apr!H5, May!H5, Jun!H5) -> -1149.4026 | I5: =IFERROR(H5/G5, "") -> -0.023401796
A6: AZ: Peoria - Fire Station 195 | B6: AZ | C6: =SUM(Apr!C6, May!C6, Jun!C6) -> 25985.312 | D6: =SUM(Apr!D6, May!D6, Jun!D6) -> 27100.639 | E6: =IF(AND(ISNUMBER(C6),ISNUMBER(D6)), C6-D6, "") -> -1115.3267 | F6: =IFERROR(E6/D6, "") -> -0.041154996 | G6: =SUM(Apr!G6,May!G6,Jun!G6) -> 28764.6 | H6: =SUM(Apr!H6, May!H6, Jun!H6) -> -2779.2877 | I6: =IFERROR(H6/G6, "") -> -0.096621809
A7: AZ: Peoria - Fire Station 196 | B7: AZ | C7: =SUM(Apr!C7, May!C7, Jun!C7) -> 18927.862 | D7: =SUM(Apr!D7, May!D7, Jun!D7) -> 0 | E7: =IF(AND(ISNUMBER(C7),ISNUMBER(D7)), C7-D7, "") -> 18927.862 | F7: =IFERROR(E7/D7, "") | G7: =SUM(Apr!G7,May!G7,Jun!G7) -> 0 | H7: =SUM(Apr!H7, May!H7, Jun!H7) -> 18927.862 | I7: =IFERROR(H7/G7, "")
A8: AZ: Peoria - Fire Station 197 | B8: AZ | C8: =SUM(Apr!C8, May!C8, Jun!C8) -> 38437.314 | D8: =SUM(Apr!D8, May!D8, Jun!D8) -> 30624.127 | E8: =IF(AND(ISNUMBER(C8),ISNUMBER(D8)), C8-D8, "") -> 7813.1874 | F8: =IFERROR(E8/D8, "") -> 0.25513176 | G8: =SUM(Apr!G8,May!G8,Jun!G8) -> 37474.57 | H8: =SUM(Apr!H8, May!H8, Jun!H8) -> 962.74444 | I8: =IFERROR(H8/G8, "") -> 0.025690607
A9: AZ: Peoria - Sunrise Library | B9: AZ | C9: =SUM(Apr!C9, May!C9, Jun!C9) -> 107516.13 | D9: =SUM(Apr!D9, May!D9, Jun!D9) -> 100593.15 | E9: =IF(AND(ISNUMBER(C9),ISNUMBER(D9)), C9-D9, "") -> 6922.9756 | F9: =IFERROR(E9/D9, "") -> 0.068821541 | G9: =SUM(Apr!G9,May!G9,Jun!G9) -> 112423 | H9: =SUM(Apr!H9, May!H9, Jun!H9) -> -4906.8744 | I9: =IFERROR(H9/G9, "") -> -0.043646535
A10: AZ: Peoria - Beardsley WWTP | B10: AZ | C10: =SUM(Apr!C10, May!C10, Jun!C10) -> 719877 | D10: =SUM(Apr!D10, May!D10, Jun!D10) -> 793136.5 | E10: =IF(AND(ISNUMBER(C10),ISNUMBER(D10)), C10-D10, "") -> -73259.5 | F10: =IFERROR(E10/D10, "") -> -0.092366825 | G10: =SUM(Apr!G10,May!G10,Jun!G10) -> 676447 | H10: =SUM(Apr!H10, May!H10, Jun!H10) -> 43430 | I10: =IFERROR(H10/G10, "") -> 0.064203108
A11: AZ: Peoria - City Hall | B11: AZ | C11: =SUM(Apr!C11, May!C11, Jun!C11) -> 0 | D11: =SUM(Apr!D11, May!D11, Jun!D11) -> 0 | E11: =IF(AND(ISNUMBER(C11),ISNUMBER(D11)), C11-D11, "") -> 0 | F11: =IFERROR(E11/D11, "") | G11: =SUM(Apr!G11,May!G11,Jun!G11) -> 0 | H11: =SUM(Apr!H11, May!H11, Jun!H11) -> 0 | I11: =IFERROR(H11/G11, "")
A12: AZ: Peoria - Pinnacle Peak | B12: AZ | C12: =SUM(Apr!C12, May!C12, Jun!C12) -> 81861.75 | D12: =SUM(Apr!D12, May!D12, Jun!D12) -> 57663.33 | E12: =IF(AND(ISNUMBER(C12),ISNUMBER(D12)), C12-D12, "") -> 24198.42 | F12: =IFERROR(E12/D12, "") -> 0.41965006 | G12: =SUM(Apr!G12,May!G12,Jun!G12) -> 83949 | H12: =SUM(Apr!H12, May!H12, Jun!H12) -> -2087.25 | I12: =IFERROR(H12/G12, "") -> -0.02486331

Sheet 3rd Qtr
A1: {=portfolio} -> City of Peoria | D1: 3rd Quarter Actual v. Expected | G1: 3rd Quarter Actual v. Forecasted
A2: Total | C2: =SUM(C4:C97) -> 975413.96 | D2: =SUM(D4:D97) -> 963807.43 | E2: =C2-D2 -> 11606.522 | F2: =IFERROR(E2/D2, 0) -> 0.012042366 | G2: =SUM(G4:G97) -> 1071590.9 | H2: =C2-G2 -> -96176.986 | I2: =IFERROR(H2/G2, 0) -> -0.089751586
A3: Site | B3: State | C3: Actual | D3: Expected | E3: Delta | F3: % | G3: Forecasted | H3: Delta | I3: %
A4: {=Sites[Site]} -> AZ: Peoria - Beardsley WWTP - Ad. Bldg | B4: {=Sites[State]} -> AZ | C4: =SUM(Jul!C4, Aug!C4, Sep!C4) -> 24617.046 | D4: =SUM(Jul!D4, Aug!D4, Sep!D4) -> 23722.953 | E4: =IF(AND(ISNUMBER(C4),ISNUMBER(D4)), C4-D4, "") -> 894.09304 | F4: =IFERROR(E4/D4, "") -> 0.037688944 | G4: =SUM(Jul!G4,Aug!G4,Sep!G4) -> 46722.89 | H4: =SUM(Jul!H4, Aug!H4, Sep!H4) -> -22105.844 | I4: =IFERROR(H4/G4, "") -> -0.47312664
A5: AZ: Peoria - Fire Station 191 | B5: AZ | C5: =SUM(Jul!C5, Aug!C5, Sep!C5) -> 46487.25 | D5: =SUM(Jul!D5, Aug!D5, Sep!D5) -> 39099.05 | E5: =IF(AND(ISNUMBER(C5),ISNUMBER(D5)), C5-D5, "") -> 7388.1996 | F5: =IFERROR(E5/D5, "") -> 0.1889611 | G5: =SUM(Jul!G5,Aug!G5,Sep!G5) -> 43749 | H5: =SUM(Jul!H5, Aug!H5, Sep!H5) -> 2738.2496 | I5: =IFERROR(H5/G5, "") -> 0.062589994
A6: AZ: Peoria - Fire Station 195 | B6: AZ | C6: =SUM(Jul!C6, Aug!C6, Sep!C6) -> 23841.173 | D6: =SUM(Jul!D6, Aug!D6, Sep!D6) -> 24378.758 | E6: =IF(AND(ISNUMBER(C6),ISNUMBER(D6)), C6-D6, "") -> -537.58476 | F6: =IFERROR(E6/D6, "") -> -0.02205136 | G6: =SUM(Jul!G6,Aug!G6,Sep!G6) -> 25513.161 | H6: =SUM(Jul!H6, Aug!H6, Sep!H6) -> -1671.9878 | I6: =IFERROR(H6/G6, "") -> -0.065534324
A7: AZ: Peoria - Fire Station 196 | B7: AZ | C7: =SUM(Jul!C7, Aug!C7, Sep!C7) -> 17021.009 | D7: =SUM(Jul!D7, Aug!D7, Sep!D7) -> 0 | E7: =IF(AND(ISNUMBER(C7),ISNUMBER(D7)), C7-D7, "") -> 17021.009 | F7: =IFERROR(E7/D7, "") | G7: =SUM(Jul!G7,Aug!G7,Sep!G7) -> 0 | H7: =SUM(Jul!H7, Aug!H7, Sep!H7) -> 17021.009 | I7: =IFERROR(H7/G7, "")
A8: AZ: Peoria - Fire Station 197 | B8: AZ | C8: =SUM(Jul!C8, Aug!C8, Sep!C8) -> -65176.475 | D8: =SUM(Jul!D8, Aug!D8, Sep!D8) -> 27569.982 | E8: =IF(AND(ISNUMBER(C8),ISNUMBER(D8)), C8-D8, "") -> -92746.457 | F8: =IFERROR(E8/D8, "") -> -3.3640376 | G8: =SUM(Jul!G8,Aug!G8,Sep!G8) -> 31246.16 | H8: =SUM(Jul!H8, Aug!H8, Sep!H8) -> -96422.635 | I8: =IFERROR(H8/G8, "") -> -3.0859035
A9: AZ: Peoria - Sunrise Library | B9: AZ | C9: =SUM(Jul!C9, Aug!C9, Sep!C9) -> 96687.886 | D9: =SUM(Jul!D9, Aug!D9, Sep!D9) -> 86906.26 | E9: =IF(AND(ISNUMBER(C9),ISNUMBER(D9)), C9-D9, "") -> 9781.6265 | F9: =IFERROR(E9/D9, "") -> 0.11255376 | G9: =SUM(Jul!G9,Aug!G9,Sep!G9) -> 99763 | H9: =SUM(Jul!H9, Aug!H9, Sep!H9) -> -3075.1135 | I9: =IFERROR(H9/G9, "") -> -0.030824189
A10: AZ: Peoria - Beardsley WWTP | B10: AZ | C10: =SUM(Jul!C10, Aug!C10, Sep!C10) -> 694350.83 | D10: =SUM(Jul!D10, Aug!D10, Sep!D10) -> 695127.7 | E10: =IF(AND(ISNUMBER(C10),ISNUMBER(D10)), C10-D10, "") -> -776.87376 | F10: =IFERROR(E10/D10, "") -> -0.0011175986 | G10: =SUM(Jul!G10,Aug!G10,Sep!G10) -> 612493 | H10: =SUM(Jul!H10, Aug!H10, Sep!H10) -> 81857.826 | I10: =IFERROR(H10/G10, "") -> 0.13364696
A11: AZ: Peoria - City Hall | B11: AZ | C11: =SUM(Jul!C11, Aug!C11, Sep!C11) -> 62694.12 | D11: =SUM(Jul!D11, Aug!D11, Sep!D11) -> 55898.36 | E11: =IF(AND(ISNUMBER(C11),ISNUMBER(D11)), C11-D11, "") -> 6795.76 | F11: =IFERROR(E11/D11, "") -> 0.12157351 | G11: =SUM(Jul!G11,Aug!G11,Sep!G11) -> 137716.73 | H11: =SUM(Jul!H11, Aug!H11, Sep!H11) -> -75022.61 | I11: =IFERROR(H11/G11, "") -> -0.54476032
A12: AZ: Peoria - Pinnacle Peak | B12: AZ | C12: =SUM(Jul!C12, Aug!C12, Sep!C12) -> 74891.12 | D12: =SUM(Jul!D12, Aug!D12, Sep!D12) -> 11104.37 | E12: =IF(AND(ISNUMBER(C12),ISNUMBER(D12)), C12-D12, "") -> 63786.75 | F12: =IFERROR(E12/D12, "") -> 5.7442923 | G12: =SUM(Jul!G12,Aug!G12,Sep!G12) -> 74387 | H12: =SUM(Jul!H12, Aug!H12, Sep!H12) -> 504.12 | I12: =IFERROR(H12/G12, "") -> 0.0067769906

Sheet 4th Qtr
A1: {=portfolio} -> City of Peoria | D1: 4th Quarter Actual v. Expected | G1: 4th Quarter Actual v. Forecasted
A2: Total | C2: =SUM(C4:C97) -> 712962.58 | D2: =SUM(D4:D97) -> 676416.53 | E2: =C2-D2 -> 36546.053 | F2: =IFERROR(E2/D2, 0) -> 0.054028918 | G2: =SUM(G4:G97) -> 791657.18 | H2: =C2-G2 -> -78694.596 | I2: =IFERROR(H2/G2, 0) -> -0.099404892
A3: Site | B3: State | C3: Actual | D3: Expected | E3: Delta | F3: % | G3: Forecasted | H3: Delta | I3: %
A4: {=Sites[Site]} -> AZ: Peoria - Beardsley WWTP - Ad. Bldg | B4: {=Sites[State]} -> AZ | C4: =SUM(Oct!C4, Nov!C4, Dec!C4) -> 14903.192 | D4: =SUM(Oct!D4, Nov!D4, Dec!D4) -> 11063.541 | E4: =IF(AND(ISNUMBER(C4),ISNUMBER(D4)), C4-D4, "") -> 3839.6512 | F4: =IFERROR(E4/D4, "") -> 0.34705445 | G4: =SUM(Oct!G4,Nov!G4,Dec!G4) -> 27690.518 | H4: =SUM(Oct!H4, Nov!H4, Dec!H4) -> -12787.326 | I4: =IFERROR(H4/G4, "") -> -0.46179439
A5: AZ: Peoria - Fire Station 191 | B5: AZ | C5: =SUM(Oct!C5, Nov!C5, Dec!C5) -> 33892.135 | D5: =SUM(Oct!D5, Nov!D5, Dec!D5) -> 27382.711 | E5: =IF(AND(ISNUMBER(C5),ISNUMBER(D5)), C5-D5, "") -> 6509.4239 | F5: =IFERROR(E5/D5, "") -> 0.23772021 | G5: =SUM(Oct!G5,Nov!G5,Dec!G5) -> 32558 | H5: =SUM(Oct!H5, Nov!H5, Dec!H5) -> 1334.1349 | I5: =IFERROR(H5/G5, "") -> 0.040977176
A6: AZ: Peoria - Fire Station 195 | B6: AZ | C6: =SUM(Oct!C6, Nov!C6, Dec!C6) -> 14453.667 | D6: =SUM(Oct!D6, Nov!D6, Dec!D6) -> 13901.256 | E6: =IF(AND(ISNUMBER(C6),ISNUMBER(D6)), C6-D6, "") -> 552.41097 | F6: =IFERROR(E6/D6, "") -> 0.039738206 | G6: =SUM(Oct!G6,Nov!G6,Dec!G6) -> 19200.352 | H6: =SUM(Oct!H6, Nov!H6, Dec!H6) -> -4746.685 | I6: =IFERROR(H6/G6, "") -> -0.24721865
A7: AZ: Peoria - Fire Station 196 | B7: AZ | C7: =SUM(Oct!C7, Nov!C7, Dec!C7) -> 11427.568 | D7: =SUM(Oct!D7, Nov!D7, Dec!D7) -> 0 | E7: =IF(AND(ISNUMBER(C7),ISNUMBER(D7)), C7-D7, "") -> 11427.568 | F7: =IFERROR(E7/D7, "") | G7: =SUM(Oct!G7,Nov!G7,Dec!G7) -> 0 | H7: =SUM(Oct!H7, Nov!H7, Dec!H7) -> 11427.568 | I7: =IFERROR(H7/G7, "")
A8: AZ: Peoria - Fire Station 197 | B8: AZ | C8: =SUM(Oct!C8, Nov!C8, Dec!C8) -> 25276.464 | D8: =SUM(Oct!D8, Nov!D8, Dec!D8) -> 19501.541 | E8: =IF(AND(ISNUMBER(C8),ISNUMBER(D8)), C8-D8, "") -> 5774.9233 | F8: =IFERROR(E8/D8, "") -> 0.29612651 | G8: =SUM(Oct!G8,Nov!G8,Dec!G8) -> 24226.625 | H8: =SUM(Oct!H8, Nov!H8, Dec!H8) -> 1049.8393 | I8: =IFERROR(H8/G8, "") -> 0.043334113
A9: AZ: Peoria - Sunrise Library | B9: AZ | C9: =SUM(Oct!C9, Nov!C9, Dec!C9) -> 48437.749 | D9: =SUM(Oct!D9, Nov!D9, Dec!D9) -> 42059.86 | E9: =IF(AND(ISNUMBER(C9),ISNUMBER(D9)), C9-D9, "") -> 6377.8893 | F9: =IFERROR(E9/D9, "") -> 0.15163839 | G9: =SUM(Oct!G9,Nov!G9,Dec!G9) -> 75168 | H9: =SUM(Oct!H9, Nov!H9, Dec!H9) -> -26730.251 | I9: =IFERROR(H9/G9, "") -> -0.35560678
A10: AZ: Peoria - Beardsley WWTP | B10: AZ | C10: =SUM(Oct!C10, Nov!C10, Dec!C10) -> 431049.17 | D10: =SUM(Oct!D10, Nov!D10, Dec!D10) -> 465332.1 | E10: =IF(AND(ISNUMBER(C10),ISNUMBER(D10)), C10-D10, "") -> -34282.926 | F10: =IFERROR(E10/D10, "") -> -0.073674106 | G10: =SUM(Oct!G10,Nov!G10,Dec!G10) -> 454275 | H10: =SUM(Oct!H10, Nov!H10, Dec!H10) -> -23225.826 | I10: =IFERROR(H10/G10, "") -> -0.051127238
A11: AZ: Peoria - City Hall | B11: AZ | C11: =SUM(Oct!C11, Nov!C11, Dec!C11) -> 81264.75 | D11: =SUM(Oct!D11, Nov!D11, Dec!D11) -> 75087.88 | E11: =IF(AND(ISNUMBER(C11),ISNUMBER(D11)), C11-D11, "") -> 6176.87 | F11: =IFERROR(E11/D11, "") -> 0.082261878 | G11: =SUM(Oct!G11,Nov!G11,Dec!G11) -> 102495.68 | H11: =SUM(Oct!H11, Nov!H11, Dec!H11) -> -22091.39 | I11: =IFERROR(H11/G11, "") -> -0.21553484
A12: AZ: Peoria - Pinnacle Peak | B12: AZ | C12: =SUM(Oct!C12, Nov!C12, Dec!C12) -> 52257.88 | D12: =SUM(Oct!D12, Nov!D12, Dec!D12) -> 22087.637 | E12: =IF(AND(ISNUMBER(C12),ISNUMBER(D12)), C12-D12, "") -> 30170.243 | F12: =IFERROR(E12/D12, "") -> 1.3659335 | G12: =SUM(Oct!G12,Nov!G12,Dec!G12) -> 56043 | H12: =SUM(Oct!H12, Nov!H12, Dec!H12) -> -3785.12 | I12: =IFERROR(H12/G12, "") -> -0.067539568

Sheet Jan
A1: {=portfolio} -> City of Peoria | D1: January Actual v. Expected | G1: January Actual v. Forecasted
A2: Total | C2: =SUM(C4:C96) -> 181579.38 | D2: =SUM(D4:D96) -> 192109.33 | E2: =C2-D2 -> -10529.948 | F2: =IFERROR(E2/D2, 0) -> -0.054812267 | G2: =SUM(G4:G96) -> 240650.96 | H2: =C2-G2 -> -59071.579 | I2: =IFERROR(H2/G2, 0) -> -0.24546579 | J2: =IF(AND(TODAY()>DATE(2024, 1, 1), COUNTA(Sites[Site])<>(COUNT(C:C)-1)), "Some sites are missing actual data; if new sites were added, make sure they are aligned correctly (including prior months!)", "")
A3: Site | B3: State | C3: Actual | D3: Expected | E3: Delta | F3: % | G3: Forecasted | H3: Delta | I3: % | J3: Notes | K3: Service Requests
A4: {=Sites[Site]} -> AZ: Peoria - Beardsley WWTP - Ad. Bldg | B4: {=Sites[State]} -> AZ | C4: 4095.2355 | D4: 2888.027 | E4: =IF(AND(ISNUMBER(C4),ISNUMBER(D4)), C4-D4, "") -> 1207.2085 | F4: =IFERROR(E4/D4, "") -> 0.41800457 | G4: 8175.821 | H4: =IF(AND(ISNUMBER(C4),ISNUMBER(G4)), C4-G4, "") -> -4080.5855 | I4: =IFERROR(H4/G4, "") -> -0.49910407
A5: AZ: Peoria - Fire Station 191 | B5: AZ | C5: 8711.7123 | D5: 7611.925 | E5: =IF(AND(ISNUMBER(C5),ISNUMBER(D5)), C5-D5, "") -> 1099.7873 | F5: =IFERROR(E5/D5, "") -> 0.14448215 | G5: 10085 | H5: =IF(AND(ISNUMBER(C5),ISNUMBER(G5)), C5-G5, "") -> -1373.2877 | I5: =IFERROR(H5/G5, "") -> -0.13617131
A6: AZ: Peoria - Fire Station 195 | B6: AZ | C6: 4067.6883 | D6: 3810.848 | E6: =IF(AND(ISNUMBER(C6),ISNUMBER(D6)), C6-D6, "") -> 256.84031 | F6: =IFERROR(E6/D6, "") -> 0.067397155 | G6: 5705.702 | H6: =IF(AND(ISNUMBER(C6),ISNUMBER(G6)), C6-G6, "") -> -1638.0137 | I6: =IFERROR(H6/G6, "") -> -0.28708364
A7: AZ: Peoria - Fire Station 196 | B7: AZ | C7: 3092.2812 | D7: 0 | E7: =IF(AND(ISNUMBER(C7),ISNUMBER(D7)), C7-D7, "") -> 3092.2812 | F7: =IFERROR(E7/D7, 0) -> 0 | G7: 0 | H7: =IF(AND(ISNUMBER(C7),ISNUMBER(G7)), C7-G7, "") -> 3092.2812 | I7: =IFERROR(H7/G7, 0) -> 0
A8: AZ: Peoria - Fire Station 197 | B8: AZ | C8: 6174.4869 | D8: 5275.923 | E8: =IF(AND(ISNUMBER(C8),ISNUMBER(D8)), C8-D8, "") -> 898.56392 | F8: =IFERROR(E8/D8, "") -> 0.17031407 | G8: 7203.861 | H8: =IF(AND(ISNUMBER(C8),ISNUMBER(G8)), C8-G8, "") -> -1029.3741 | I8: =IFERROR(H8/G8, "") -> -0.142892 | J8: 1. Inverter is offline from 01/01 to 01/04 | K8: 1. SR079271
A9: AZ: Peoria - Sunrise Library | B9: AZ | C9: 15881.231 | D9: 10942.25 | E9: =IF(AND(ISNUMBER(C9),ISNUMBER(D9)), C9-D9, "") -> 4938.9807 | F9: =IFERROR(E9/D9, "") -> 0.45136793 | G9: 22243 | H9: =IF(AND(ISNUMBER(C9),ISNUMBER(G9)), C9-G9, "") -> -6361.7693 | I9: =IFERROR(H9/G9, "") -> -0.2860122
A10: AZ: Peoria - Beardsley WWTP | B10: AZ | C10: 102879 | D10: 128491.1 | E10: =IF(AND(ISNUMBER(C10),ISNUMBER(D10)), C10-D10, "") -> -25612.1 | F10: =IFERROR(E10/D10, "") -> -0.19932976 | G10: 138763 | H10: =IF(AND(ISNUMBER(C10),ISNUMBER(G10)), C10-G10, "") -> -35884 | I10: =IFERROR(H10/G10, "") -> -0.25859919 | J10: 1. Inverter B2 was back online from 01/24. | K10: 1. SR075641
A11: AZ: Peoria - City Hall | B11: AZ | C11: 22132.5 | D11: 21050.03 | E11: =IF(AND(ISNUMBER(C11),ISNUMBER(D11)), C11-D11, "") -> 1082.47 | F11: =IFERROR(E11/D11, "") -> 0.05142368 | G11: 31892.58 | H11: =IF(AND(ISNUMBER(C11),ISNUMBER(G11)), C11-G11, "") -> -9760.08 | I11: =IFERROR(H11/G11, "") -> -0.3060298
A12: AZ: Peoria - Pinnacle Peak | B12: AZ | C12: 14545.25 | D12: 12039.23 | E12: =IF(AND(ISNUMBER(C12),ISNUMBER(D12)), C12-D12, "") -> 2506.02 | F12: =IFERROR(E12/D12, "") -> 0.20815451 | G12: 16582 | H12: =IF(AND(ISNUMBER(C12),ISNUMBER(G12)), C12-G12, "") -> -2036.75 | I12: =IFERROR(H12/G12, "") -> -0.12282897
E13: =IF(AND(ISNUMBER(C13),ISNUMBER(D13)), C13-D13, "") | F13: =IFERROR(E13/D13, "") | H13: =IF(AND(ISNUMBER(C13),ISNUMBER(G13)), C13-G13, "") | I13: =IFERROR(H13/G13, "")

Sheet Feb
A1: {=portfolio} -> City of Peoria | D1: February Actual v. Expected | G1: February Actual v. Forecasted
A2: Total | C2: =SUM(C4:C97) -> 246771 | D2: =SUM(D4:D97) -> 232313 | E2: =C2-D2 -> 14458 | F2: =IFERROR(E2/D2, 0) -> 0.062235002 | G2: =SUM(G4:G97) -> 263500 | H2: =C2-G2 -> -16729 | I2: =IFERROR(H2/G2, 0) -> -0.063487666 | J2: =IF(AND(TODAY()>DATE(2024, 2, 1), COUNTA(Sites[Site])<>(COUNT(C:C)-1)), "Some sites are missing actual data; if new sites were added, make sure they are aligned correctly (including prior months!)", "")
A3: Site | B3: State | C3: Actual | D3: Expected | E3: Delta | F3: % | G3: Forecasted | H3: Delta | I3: % | J3: Notes | K3: Service Requests
A4: {=Sites[Site]} -> AZ: Peoria - Beardsley WWTP - Ad. Bldg | B4: {=Sites[State]} -> AZ | C4: 5177 | D4: 3849 | E4: =IF(AND(ISNUMBER(C4),ISNUMBER(D4)), C4-D4, "") -> 1328 | F4: =IFERROR(E4/D4, "") -> 0.34502468 | G4: 9684 | H4: =IF(AND(ISNUMBER(C4),ISNUMBER(G4)), C4-G4, "") -> -4507 | I4: =IFERROR(H4/G4, "") -> -0.46540686
A5: AZ: Peoria - Fire Station 191 | B5: AZ | C5: 10399 | D5: 9070 | E5: =IF(AND(ISNUMBER(C5),ISNUMBER(D5)), C5-D5, "") -> 1329 | F5: =IFERROR(E5/D5, "") -> 0.14652701 | G5: 10905 | H5: =IF(AND(ISNUMBER(C5),ISNUMBER(G5)), C5-G5, "") -> -506 | I5: =IFERROR(H5/G5, "") -> -0.046400734
A6: AZ: Peoria - Fire Station 195 | B6: AZ | C6: 5100 | D6: 4747 | E6: =IF(AND(ISNUMBER(C6),ISNUMBER(D6)), C6-D6, "") -> 353 | F6: =IFERROR(E6/D6, "") -> 0.074362755 | G6: 6454 | H6: =IF(AND(ISNUMBER(C6),ISNUMBER(G6)), C6-G6, "") -> -1354 | I6: =IFERROR(H6/G6, "") -> -0.20979238
A7: AZ: Peoria - Fire Station 196 | B7: AZ | C7: 3670 | D7: 0 | E7: =IF(AND(ISNUMBER(C7),ISNUMBER(D7)), C7-D7, "") -> 3670 | F7: =IFERROR(E7/D7, "") | G7: 0 | H7: =IF(AND(ISNUMBER(C7),ISNUMBER(G7)), C7-G7, "") -> 3670 | I7: =IFERROR(H7/G7, "")
A8: AZ: Peoria - Fire Station 197 | B8: AZ | C8: 7942 | D8: 6180 | E8: =IF(AND(ISNUMBER(C8),ISNUMBER(D8)), C8-D8, "") -> 1762 | F8: =IFERROR(E8/D8, "") -> 0.28511327 | G8: 8038 | H8: =IF(AND(ISNUMBER(C8),ISNUMBER(G8)), C8-G8, "") -> -96 | I8: =IFERROR(H8/G8, "") -> -0.011943269
A9: AZ: Peoria - Sunrise Library | B9: AZ | C9: 20134 | D9: 14918 | E9: =IF(AND(ISNUMBER(C9),ISNUMBER(D9)), C9-D9, "") -> 5216 | F9: =IFERROR(E9/D9, "") -> 0.34964472 | G9: 25213 | H9: =IF(AND(ISNUMBER(C9),ISNUMBER(G9)), C9-G9, "") -> -5079 | I9: =IFERROR(H9/G9, "") -> -0.2014437
A10: AZ: Peoria - Beardsley WWTP | B10: AZ | C10: 149372 | D10: 154491 | E10: =IF(AND(ISNUMBER(C10),ISNUMBER(D10)), C10-D10, "") -> -5119 | F10: =IFERROR(E10/D10, "") -> -0.033134616 | G10: 149996 | H10: =IF(AND(ISNUMBER(C10),ISNUMBER(G10)), C10-G10, "") -> -624 | I10: =IFERROR(H10/G10, "") -> -0.0041601109
A11: AZ: Peoria - City Hall | B11: AZ | C11: 27969 | D11: 26428 | E11: =IF(AND(ISNUMBER(C11),ISNUMBER(D11)), C11-D11, "") -> 1541 | F11: =IFERROR(E11/D11, "") -> 0.058309369 | G11: 34422 | H11: =IF(AND(ISNUMBER(C11),ISNUMBER(G11)), C11-G11, "") -> -6453 | I11: =IFERROR(H11/G11, "") -> -0.18746732
A12: AZ: Peoria - Pinnacle Peak | B12: AZ | C12: 17008 | D12: 12630 | E12: =IF(AND(ISNUMBER(C12),ISNUMBER(D12)), C12-D12, "") -> 4378 | F12: =IFERROR(E12/D12, "") -> 0.346635 | G12: 18788 | H12: =IF(AND(ISNUMBER(C12),ISNUMBER(G12)), C12-G12, "") -> -1780 | I12: =IFERROR(H12/G12, "") -> -0.094741324

Sheet Mar
A1: {=portfolio} -> City of Peoria | D1: March Actual v. Expected | G1: March Actual v. Forecasted
A2: Total | C2: =SUM(C4:C97) -> 308369.62 | D2: =SUM(D4:D97) -> 297029 | E2: =C2-D2 -> 11340.62 | F2: =IFERROR(E2/D2, 0) -> 0.038180178 | G2: =SUM(G4:G97) -> 343213 | H2: =C2-G2 -> -34843.38 | I2: =IFERROR(H2/G2, 0) -> -0.10152115 | J2: =IF(AND(TODAY()>DATE(2024, 3, 1), COUNTA(Sites[Site])<>(COUNT(C:C)-1)), "Some sites are missing actual data; if new sites were added, make sure they are aligned correctly (including prior months!)", "")
A3: Site | B3: State | C3: Actual | D3: Expected | E3: Delta | F3: % | G3: Forecasted | H3: Delta | I3: % | J3: Notes | K3: Service Requests
A4: {=Sites[Site]} -> AZ: Peoria - Beardsley WWTP - Ad. Bldg | B4: {=Sites[State]} -> AZ | C4: 7183.62 | D4: 6232 | E4: =IF(AND(ISNUMBER(C4),ISNUMBER(D4)), C4-D4, "") -> 951.62 | F4: =IFERROR(E4/D4, "") -> 0.15269897 | G4: 13878 | H4: =IF(AND(ISNUMBER(C4),ISNUMBER(G4)), C4-G4, "") -> -6694.38 | I4: =IFERROR(H4/G4, "") -> -0.48237354
A5: AZ: Peoria - Fire Station 191 | B5: AZ | C5: 13743 | D5: 12149 | E5: =IF(AND(ISNUMBER(C5),ISNUMBER(D5)), C5-D5, "") -> 1594 | F5: =IFERROR(E5/D5, "") -> 0.13120421 | G5: 14215 | H5: =IF(AND(ISNUMBER(C5),ISNUMBER(G5)), C5-G5, "") -> -472 | I5: =IFERROR(H5/G5, "") -> -0.033204362
A6: AZ: Peoria - Fire Station 195 | B6: AZ | C6: 6931 | D6: 6799 | E6: =IF(AND(ISNUMBER(C6),ISNUMBER(D6)), C6-D6, "") -> 132 | F6: =IFERROR(E6/D6, "") -> 0.01941462 | G6: 8331 | H6: =IF(AND(ISNUMBER(C6),ISNUMBER(G6)), C6-G6, "") -> -1400 | I6: =IFERROR(H6/G6, "") -> -0.16804705
A7: AZ: Peoria - Fire Station 196 | B7: AZ | C7: 5151 | D7: 0 | E7: =IF(AND(ISNUMBER(C7),ISNUMBER(D7)), C7-D7, "") -> 5151 | F7: =IFERROR(E7/D7, "") | G7: 0 | H7: =IF(AND(ISNUMBER(C7),ISNUMBER(G7)), C7-G7, "") -> 5151 | I7: =IFERROR(H7/G7, "")
A8: AZ: Peoria - Fire Station 197 | B8: AZ | C8: 10639 | D8: 8397 | E8: =IF(AND(ISNUMBER(C8),ISNUMBER(D8)), C8-D8, "") -> 2242 | F8: =IFERROR(E8/D8, "") -> 0.26700012 | G8: 10597 | H8: =IF(AND(ISNUMBER(C8),ISNUMBER(G8)), C8-G8, "") -> 42 | I8: =IFERROR(H8/G8, "") -> 0.0039633859
A9: AZ: Peoria - Sunrise Library | B9: AZ | C9: 27848 | D9: 23027 | E9: =IF(AND(ISNUMBER(C9),ISNUMBER(D9)), C9-D9, "") -> 4821 | F9: =IFERROR(E9/D9, "") -> 0.20936292 | G9: 32592 | H9: =IF(AND(ISNUMBER(C9),ISNUMBER(G9)), C9-G9, "") -> -4744 | I9: =IFERROR(H9/G9, "") -> -0.14555719
A10: AZ: Peoria - Beardsley WWTP | B10: AZ | C10: 198401 | D10: 213044 | E10: =IF(AND(ISNUMBER(C10),ISNUMBER(D10)), C10-D10, "") -> -14643 | F10: =IFERROR(E10/D10, "") -> -0.068732281 | G10: 194947 | H10: =IF(AND(ISNUMBER(C10),ISNUMBER(G10)), C10-G10, "") -> 3454 | I10: =IFERROR(H10/G10, "") -> 0.017717636 | J10: 1. Inverter A1 derated due to fan fault on 03/06 2. Inverter A1 is offline from 03/19 at 15:15 and inverter being RMA'd | K10: 1. SR081608 2. SR082243
A11: AZ: Peoria - City Hall | B11: AZ | C11: 15929 | D11: 16201 | E11: =IF(AND(ISNUMBER(C11),ISNUMBER(D11)), C11-D11, "") -> -272 | F11: =IFERROR(E11/D11, "") -> -0.016789087 | G11: 44313 | H11: =IF(AND(ISNUMBER(C11),ISNUMBER(G11)), C11-G11, "") -> -28384 | I11: =IFERROR(H11/G11, "") -> -0.64053438 | J11: 1. Inverters A1 and B1 tripped offline on 03/07 at 11:45 and back online on 03/08 2. Site is offline from 03/14 at 12:45pm, PV disconnect on the conductors being replaced | K11: 1. SR081644 2. SR081906
A12: AZ: Peoria - Pinnacle Peak | B12: AZ | C12: 22544 | D12: 11180 | E12: =IF(AND(ISNUMBER(C12),ISNUMBER(D12)), C12-D12, "") -> 11364 | F12: =IFERROR(E12/D12, "") -> 1.016458 | G12: 24340 | H12: =IF(AND(ISNUMBER(C12),ISNUMBER(G12)), C12-G12, "") -> -1796 | I12: =IFERROR(H12/G12, "") -> -0.073788003 | J12: 1. Weather station has inetermittent communication

Sheet Apr
A1: {=portfolio} -> City of Peoria | D1: April Actual v. Expected | G1: April Actual v. Forecasted
A2: Total | C2: =SUM(C4:C97) -> 348492.52 | D2: =SUM(D4:D97) -> 354061.45 | E2: =C2-D2 -> -5568.9315 | F2: =IFERROR(E2/D2, 0) -> -0.015728714 | G2: =SUM(G4:G97) -> 330828.79 | H2: =C2-G2 -> 17663.736 | I2: =IFERROR(H2/G2, 0) -> 0.053392377 | J2: =IF(AND(TODAY()>DATE(2024, 4, 1), COUNTA(Sites[Site])<>(COUNT(C:C)-1)), "Some sites are missing actual data; if new sites were added, make sure they are aligned correctly (including prior months!)", "")
A3: Site | B3: State | C3: Actual | D3: Expected | E3: Delta | F3: % | G3: Forecasted | H3: Delta | I3: % | J3: Notes | K3: Service Requests
A4: {=Sites[Site]} -> AZ: Peoria - Beardsley WWTP - Ad. Bldg | B4: {=Sites[State]} -> AZ | C4: 8720.7717 | D4: 8349.031 | E4: =IF(AND(ISNUMBER(C4),ISNUMBER(D4)), C4-D4, "") -> 371.74066 | F4: =IFERROR(E4/D4, "") -> 0.044525006 | G4: 16395.85 | H4: =IF(AND(ISNUMBER(C4),ISNUMBER(G4)), C4-G4, "") -> -7675.0783 | I4: =IFERROR(H4/G4, "") -> -0.46811104
A5: AZ: Peoria - Fire Station 191 | B5: AZ | C5: 15860.889 | D5: 14030.94 | E5: =IF(AND(ISNUMBER(C5),ISNUMBER(D5)), C5-D5, "") -> 1829.9492 | F5: =IFERROR(E5/D5, "") -> 0.13042242 | G5: 15870 | H5: =IF(AND(ISNUMBER(C5),ISNUMBER(G5)), C5-G5, "") -> -9.1107867 | I5: =IFERROR(H5/G5, "") -> -0.00057408864
A6: AZ: Peoria - Fire Station 195 | B6: AZ | C6: 8407.8763 | D6: 8550.174 | E6: =IF(AND(ISNUMBER(C6),ISNUMBER(D6)), C6-D6, "") -> -142.29765 | F6: =IFERROR(E6/D6, "") -> -0.016642662 | G6: 9202.688 | H6: =IF(AND(ISNUMBER(C6),ISNUMBER(G6)), C6-G6, "") -> -794.81165 | I6: =IFERROR(H6/G6, "") -> -0.086367337
A7: AZ: Peoria - Fire Station 196 | B7: AZ | C7: 6233.5575 | D7: 0 | E7: =IF(AND(ISNUMBER(C7),ISNUMBER(D7)), C7-D7, "") -> 6233.5575 | F7: =IFERROR(E7/D7, "") | G7: 0 | H7: =IF(AND(ISNUMBER(C7),ISNUMBER(G7)), C7-G7, "") -> 6233.5575 | I7: =IFERROR(H7/G7, "")
A8: AZ: Peoria - Fire Station 197 | B8: AZ | C8: 12695.55 | D8: 10000.94 | E8: =IF(AND(ISNUMBER(C8),ISNUMBER(D8)), C8-D8, "") -> 2694.6101 | F8: =IFERROR(E8/D8, "") -> 0.26943569 | G8: 11803.25 | H8: =IF(AND(ISNUMBER(C8),ISNUMBER(G8)), C8-G8, "") -> 892.30012 | I8: =IFERROR(H8/G8, "") -> 0.075597833
A9: AZ: Peoria - Sunrise Library | B9: AZ | C9: 34382.129 | D9: 30715.89 | E9: =IF(AND(ISNUMBER(C9),ISNUMBER(D9)), C9-D9, "") -> 3666.2386 | F9: =IFERROR(E9/D9, "") -> 0.11935967 | G9: 35984 | H9: =IF(AND(ISNUMBER(C9),ISNUMBER(G9)), C9-G9, "") -> -1601.8714 | I9: =IFERROR(H9/G9, "") -> -0.044516212
A10: AZ: Peoria - Beardsley WWTP | B10: AZ | C10: 235341 | D10: 258608 | E10: =IF(AND(ISNUMBER(C10),ISNUMBER(D10)), C10-D10, "") -> -23267 | F10: =IFERROR(E10/D10, "") -> -0.089970148 | G10: 214683 | H10: =IF(AND(ISNUMBER(C10),ISNUMBER(G10)), C10-G10, "") -> 20658 | I10: =IFERROR(H10/G10, "") -> 0.096225598 | J10: 1. Inverter A1 is offline from 03/19. Inverter being RMA'd 2. Site performance dropping down due to issue with trackers | K10: 1. SR082243 2. SR085326
A11: AZ: Peoria - City Hall | B11: AZ | C11: 0 | D11: 0 | E11: =IF(AND(ISNUMBER(C11),ISNUMBER(D11)), C11-D11, "") -> 0 | F11: =IFERROR(E11/D11, "") | G11: 0 | H11: =IF(AND(ISNUMBER(C11),ISNUMBER(G11)), C11-G11, "") -> 0 | I11: =IFERROR(H11/G11, "") | J11: 1. Site is offline from 03/14 at 12:45pm, PV disconnect on the conductors being replaced | K11: 1. SR081906
A12: AZ: Peoria - Pinnacle Peak | B12: AZ | C12: 26850.75 | D12: 23806.48 | E12: =IF(AND(ISNUMBER(C12),ISNUMBER(D12)), C12-D12, "") -> 3044.27 | F12: =IFERROR(E12/D12, "") -> 0.12787569 | G12: 26890 | H12: =IF(AND(ISNUMBER(C12),ISNUMBER(G12)), C12-G12, "") -> -39.25 | I12: =IFERROR(H12/G12, "") -> -0.0014596504 | J12: 1. Weather station has intermittent communication | K12: 1. SR085026

Sheet May
A1: {=portfolio} -> City of Peoria | D1: May Actual v. Expected | G1: May Actual v. Forecasted
A2: Total | C2: =SUM(C4:C97) -> 378228.46 | D2: =SUM(D4:D97) -> 388147.32 | E2: =C2-D2 -> -9918.8598 | F2: =IFERROR(E2/D2, 0) -> -0.025554369 | G2: =SUM(G4:G97) -> 360995.32 | H2: =C2-G2 -> 17233.133 | I2: =IFERROR(H2/G2, 0) -> 0.04773783 | J2: =IF(AND(TODAY()>DATE(2024, 5, 1), COUNTA(Sites[Site])<>(COUNT(C:C)-1)), "Some sites are missing actual data; if new sites were added, make sure they are aligned correctly (including prior months!)", "")
A3: Site | B3: State | C3: Actual | D3: Expected | E3: Delta | F3: % | G3: Forecasted | H3: Delta | I3: % | J3: Notes | K3: Service Requests
A4: {=Sites[Site]} -> AZ: Peoria - Beardsley WWTP - Ad. Bldg | B4: {=Sites[State]} -> AZ | C4: 9755.371 | D4: 9756.597 | E4: =IF(AND(ISNUMBER(C4),ISNUMBER(D4)), C4-D4, "") -> -1.226 | F4: =IFERROR(E4/D4, "") -> -0.00012565857 | G4: 18639.09 | H4: =IF(AND(ISNUMBER(C4),ISNUMBER(G4)), C4-G4, "") -> -8883.719 | I4: =IFERROR(H4/G4, "") -> -0.47661764
A5: AZ: Peoria - Fire Station 191 | B5: AZ | C5: 16947.38 | D5: 15356.98 | E5: =IF(AND(ISNUMBER(C5),ISNUMBER(D5)), C5-D5, "") -> 1590.3995 | F5: =IFERROR(E5/D5, "") -> 0.103562 | G5: 16950 | H5: =IF(AND(ISNUMBER(C5),ISNUMBER(G5)), C5-G5, "") -> -2.62048 | I5: =IFERROR(H5/G5, "") -> -0.00015460059 | J5: 1. Inverter A1 tripped offline at 13:15 on 05/20 and back online at 07:00 on 05/21. | K5: 1. SR084926
A6: AZ: Peoria - Fire Station 195 | B6: AZ | C6: 9245.7329 | D6: 9660.439 | E6: =IF(AND(ISNUMBER(C6),ISNUMBER(D6)), C6-D6, "") -> -414.70614 | F6: =IFERROR(E6/D6, "") -> -0.042928291 | G6: 9977.693 | H6: =IF(AND(ISNUMBER(C6),ISNUMBER(G6)), C6-G6, "") -> -731.96014 | I6: =IFERROR(H6/G6, "") -> -0.073359657
A7: AZ: Peoria - Fire Station 196 | B7: AZ | C7: 6718.6373 | D7: 0 | E7: =IF(AND(ISNUMBER(C7),ISNUMBER(D7)), C7-D7, "") -> 6718.6373 | F7: =IFERROR(E7/D7, "") | G7: 0 | H7: =IF(AND(ISNUMBER(C7),ISNUMBER(G7)), C7-G7, "") -> 6718.6373 | I7: =IFERROR(H7/G7, "")
A8: AZ: Peoria - Fire Station 197 | B8: AZ | C8: 13710.069 | D8: 10958.49 | E8: =IF(AND(ISNUMBER(C8),ISNUMBER(D8)), C8-D8, "") -> 2751.5789 | F8: =IFERROR(E8/D8, "") -> 0.25109106 | G8: 13024.54 | H8: =IF(AND(ISNUMBER(C8),ISNUMBER(G8)), C8-G8, "") -> 685.52892 | I8: =IFERROR(H8/G8, "") -> 0.052633638
A9: AZ: Peoria - Sunrise Library | B9: AZ | C9: 38342.147 | D9: 36469.66 | E9: =IF(AND(ISNUMBER(C9),ISNUMBER(D9)), C9-D9, "") -> 1872.4866 | F9: =IFERROR(E9/D9, "") -> 0.051343681 | G9: 39002 | H9: =IF(AND(ISNUMBER(C9),ISNUMBER(G9)), C9-G9, "") -> -659.85343 | I9: =IFERROR(H9/G9, "") -> -0.016918451
A10: AZ: Peoria - Beardsley WWTP | B10: AZ | C10: 254408 | D10: 283723 | E10: =IF(AND(ISNUMBER(C10),ISNUMBER(D10)), C10-D10, "") -> -29315 | F10: =IFERROR(E10/D10, "") -> -0.10332261 | G10: 234267 | H10: =IF(AND(ISNUMBER(C10),ISNUMBER(G10)), C10-G10, "") -> 20141 | I10: =IFERROR(H10/G10, "") -> 0.08597455 | J10: 1. Inverters B2 tripped offline at 15:00 on 05/14. Inverter being RMA'D. 2. Inverter A1 is offline from 03/19. Inverter being RMA'd 3. Site performance dropping down due to issue with trackers | K10: 1. SR084705 2. SR082243 3. SR085326
A11: AZ: Peoria - City Hall | B11: AZ | C11: 0 | D11: 0 | E11: =IF(AND(ISNUMBER(C11),ISNUMBER(D11)), C11-D11, "") -> 0 | F11: =IFERROR(E11/D11, "") | G11: 0 | H11: =IF(AND(ISNUMBER(C11),ISNUMBER(G11)), C11-G11, "") -> 0 | I11: =IFERROR(H11/G11, "") | J11: 1. Site is offline from 03/14 at 12:45pm, PV disconnect on the conductors being replaced | K11: 1. SR081906
A12: AZ: Peoria - Pinnacle Peak | B12: AZ | C12: 29101.12 | D12: 22222.15 | E12: =IF(AND(ISNUMBER(C12),ISNUMBER(D12)), C12-D12, "") -> 6878.97 | F12: =IFERROR(E12/D12, "") -> 0.30955466 | G12: 29135 | H12: =IF(AND(ISNUMBER(C12),ISNUMBER(G12)), C12-G12, "") -> -33.88 | I12: =IFERROR(H12/G12, "") -> -0.0011628625 | J12: 1. Weather station has intermittent communication | K12: 1. SR085026

Sheet Jun
A1: {=portfolio} -> City of Peoria | D1: June Actual v. Expected | G1: June Actual v. Forecasted
A2: Total | C2: =SUM(C4:C97) -> 341191.55 | D2: =SUM(D4:D97) -> 337252.43 | E2: =C2-D2 -> 3939.1288 | F2: =IFERROR(E2/D2, 0) -> 0.011680061 | G2: =SUM(G4:G97) -> 349838.86 | H2: =C2-G2 -> -8647.3042 | I2: =IFERROR(H2/G2, 0) -> -0.024717964 | J2: =IF(AND(TODAY()>DATE(2024, 6, 1), COUNTA(Sites[Site])<>(COUNT(C:C)-1)), "Some sites are missing actual data; if new sites were added, make sure they are aligned correctly (including prior months!)", "")
A3: Site | B3: State | C3: Actual | D3: Expected | E3: Delta | F3: % | G3: Forecasted | H3: Delta | I3: % | J3: Notes | K3: Service Requests
A4: {=Sites[Site]} -> AZ: Peoria - Beardsley WWTP - Ad. Bldg | B4: {=Sites[State]} -> AZ | C4: 8864.43 | D4: 9128.543 | E4: =IF(AND(ISNUMBER(C4),ISNUMBER(D4)), C4-D4, "") -> -264.113 | F4: =IFERROR(E4/D4, "") -> -0.028932657 | G4: 18453.86 | H4: =IF(AND(ISNUMBER(C4),ISNUMBER(G4)), C4-G4, "") -> -9589.43 | I4: =IFERROR(H4/G4, "") -> -0.51964359
A5: AZ: Peoria - Fire Station 191 | B5: AZ | C5: 15158.329 | D5: 13721.36 | E5: =IF(AND(ISNUMBER(C5),ISNUMBER(D5)), C5-D5, "") -> 1436.9686 | F5: =IFERROR(E5/D5, "") -> 0.10472494 | G5: 16296 | H5: =IF(AND(ISNUMBER(C5),ISNUMBER(G5)), C5-G5, "") -> -1137.6714 | I5: =IFERROR(H5/G5, "") -> -0.069812921
A6: AZ: Peoria - Fire Station 195 | B6: AZ | C6: 8331.7031 | D6: 8890.026 | E6: =IF(AND(ISNUMBER(C6),ISNUMBER(D6)), C6-D6, "") -> -558.32289 | F6: =IFERROR(E6/D6, "") -> -0.062803291 | G6: 9584.219 | H6: =IF(AND(ISNUMBER(C6),ISNUMBER(G6)), C6-G6, "") -> -1252.5159 | I6: =IFERROR(H6/G6, "") -> -0.13068523
A7: AZ: Peoria - Fire Station 196 | B7: AZ | C7: 5975.6673 | D7: 0 | E7: =IF(AND(ISNUMBER(C7),ISNUMBER(D7)), C7-D7, "") -> 5975.6673 | F7: =IFERROR(E7/D7, "") | G7: 0 | H7: =IF(AND(ISNUMBER(C7),ISNUMBER(G7)), C7-G7, "") -> 5975.6673 | I7: =IFERROR(H7/G7, "")
A8: AZ: Peoria - Fire Station 197 | B8: AZ | C8: 12031.695 | D8: 9664.697 | E8: =IF(AND(ISNUMBER(C8),ISNUMBER(D8)), C8-D8, "") -> 2366.9984 | F8: =IFERROR(E8/D8, "") -> 0.24491181 | G8: 12646.78 | H8: =IF(AND(ISNUMBER(C8),ISNUMBER(G8)), C8-G8, "") -> -615.0846 | I8: =IFERROR(H8/G8, "") -> -0.048635669
A9: AZ: Peoria - Sunrise Library | B9: AZ | C9: 34791.85 | D9: 33407.6 | E9: =IF(AND(ISNUMBER(C9),ISNUMBER(D9)), C9-D9, "") -> 1384.2504 | F9: =IFERROR(E9/D9, "") -> 0.041435194 | G9: 37437 | H9: =IF(AND(ISNUMBER(C9),ISNUMBER(G9)), C9-G9, "") -> -2645.1496 | I9: =IFERROR(H9/G9, "") -> -0.070656025
A10: AZ: Peoria - Beardsley WWTP | B10: AZ | C10: 230128 | D10: 250805.5 | E10: =IF(AND(ISNUMBER(C10),ISNUMBER(D10)), C10-D10, "") -> -20677.5 | F10: =IFERROR(E10/D10, "") -> -0.082444364 | G10: 227497 | H10: =IF(AND(ISNUMBER(C10),ISNUMBER(G10)), C10-G10, "") -> 2631 | I10: =IFERROR(H10/G10, "") -> 0.011564988 | J10: 1. Inverter A1 is offline from 03/19. Inverter being RMA'd. 2. Inverters B2 is offline from 05/14 and back online at 14:00 on 06/13. 3. Site performance dropping down due to issue with trackers | K10: 1. SR082243 2. SR084705 3. SR085326
A11: AZ: Peoria - City Hall | B11: AZ | C11: 0 | D11: 0 | E11: =IF(AND(ISNUMBER(C11),ISNUMBER(D11)), C11-D11, "") -> 0 | F11: =IFERROR(E11/D11, "") | G11: 0 | H11: =IF(AND(ISNUMBER(C11),ISNUMBER(G11)), C11-G11, "") -> 0 | I11: =IFERROR(H11/G11, "") | J11: 1. Site is offline from 03/14 at 12:45pm, PV disconnect on the conductors being replaced | K11: 1. SR081906
A12: AZ: Peoria - Pinnacle Peak | B12: AZ | C12: 25909.88 | D12: 11634.7 | E12: =IF(AND(ISNUMBER(C12),ISNUMBER(D12)), C12-D12, "") -> 14275.18 | F12: =IFERROR(E12/D12, "") -> 1.2269487 | G12: 27924 | H12: =IF(AND(ISNUMBER(C12),ISNUMBER(G12)), C12-G12, "") -> -2014.12 | I12: =IFERROR(H12/G12, "") -> -0.072128635 | J12: 1. Weather station has intermittent communication | K12: 1. SR085026

Sheet Jul
A1: {=portfolio} -> City of Peoria | D1: July Actual v. Expected | G1: July Actual v. Forecasted
A2: Total | C2: =SUM(C4:C97) -> 262642.66 | D2: =SUM(D4:D97) -> 322422.04 | E2: =C2-D2 -> -59779.383 | F2: =IFERROR(E2/D2, 0) -> -0.18540724 | G2: =SUM(G4:G97) -> 375813.14 | H2: =C2-G2 -> -113170.48 | I2: =IFERROR(H2/G2, 0) -> -0.30113497 | J2: =IF(AND(TODAY()>DATE(2024, 7, 1), COUNTA(Sites[Site])<>(COUNT(C:C)-1)), "Some sites are missing actual data; if new sites were added, make sure they are aligned correctly (including prior months!)", "")
A3: Site | B3: State | C3: Actual | D3: Expected | E3: Delta | F3: % | G3: Forecasted | H3: Delta | I3: % | J3: Notes | K3: Service Requests
A4: {=Sites[Site]} -> AZ: Peoria - Beardsley WWTP - Ad. Bldg | B4: {=Sites[State]} -> AZ | C4: 8860.7456 | D4: 9151.83 | E4: =IF(AND(ISNUMBER(C4),ISNUMBER(D4)), C4-D4, "") -> -291.08439 | F4: =IFERROR(E4/D4, "") -> -0.03180614 | G4: 17180.62 | H4: =IF(AND(ISNUMBER(C4),ISNUMBER(G4)), C4-G4, "") -> -8319.8744 | I4: =IFERROR(H4/G4, "") -> -0.48425926
A5: AZ: Peoria - Fire Station 191 | B5: AZ | C5: 16134.865 | D5: 14071.41 | E5: =IF(AND(ISNUMBER(C5),ISNUMBER(D5)), C5-D5, "") -> 2063.4548 | F5: =IFERROR(E5/D5, "") -> 0.14664165 | G5: 15200 | H5: =IF(AND(ISNUMBER(C5),ISNUMBER(G5)), C5-G5, "") -> 934.8648 | I5: =IFERROR(H5/G5, "") -> 0.061504263
A6: AZ: Peoria - Fire Station 195 | B6: AZ | C6: 8617.1092 | D6: 9070.423 | E6: =IF(AND(ISNUMBER(C6),ISNUMBER(D6)), C6-D6, "") -> -453.31379 | F6: =IFERROR(E6/D6, "") -> -0.049977139 | G6: 8967.653 | H6: =IF(AND(ISNUMBER(C6),ISNUMBER(G6)), C6-G6, "") -> -350.54379 | I6: =IFERROR(H6/G6, "") -> -0.039089803
A7: AZ: Peoria - Fire Station 196 | B7: AZ | C7: 6151.8966 | D7: 0 | E7: =IF(AND(ISNUMBER(C7),ISNUMBER(D7)), C7-D7, "") -> 6151.8966 | F7: =IFERROR(E7/D7, "") | G7: 0 | H7: =IF(AND(ISNUMBER(C7),ISNUMBER(G7)), C7-G7, "") -> 6151.8966 | I7: =IFERROR(H7/G7, "")
A8: AZ: Peoria - Fire Station 197 | B8: AZ | C8: -87607.245 | D8: 9961.106 | E8: =IF(AND(ISNUMBER(C8),ISNUMBER(D8)), C8-D8, "") -> -97568.351 | F8: =IFERROR(E8/D8, "") -> -9.7949315 | G8: 10595.21 | H8: =IF(AND(ISNUMBER(C8),ISNUMBER(G8)), C8-G8, "") -> -98202.455 | I8: =IFERROR(H8/G8, "") -> -9.2685709
A9: AZ: Peoria - Sunrise Library | B9: AZ | C9: 35689.421 | D9: 33483.07 | E9: =IF(AND(ISNUMBER(C9),ISNUMBER(D9)), C9-D9, "") -> 2206.3508 | F9: =IFERROR(E9/D9, "") -> 0.065894518 | G9: 35051 | H9: =IF(AND(ISNUMBER(C9),ISNUMBER(G9)), C9-G9, "") -> 638.42076 | I9: =IFERROR(H9/G9, "") -> 0.018214053
A10: AZ: Peoria - Beardsley WWTP | B10: AZ | C10: 248136 | D10: 244140.2 | E10: =IF(AND(ISNUMBER(C10),ISNUMBER(D10)), C10-D10, "") -> 3995.8 | F10: =IFERROR(E10/D10, "") -> 0.016366825 | G10: 214802 | H10: =IF(AND(ISNUMBER(C10),ISNUMBER(G10)), C10-G10, "") -> 33334 | I10: =IFERROR(H10/G10, "") -> 0.15518477
A11: AZ: Peoria - City Hall | B11: AZ | C11: 0 | D11: 0 | E11: =IF(AND(ISNUMBER(C11),ISNUMBER(D11)), C11-D11, "") -> 0 | F11: =IFERROR(E11/D11, "") | G11: 47881.66 | H11: =IF(AND(ISNUMBER(C11),ISNUMBER(G11)), C11-G11, "") -> -47881.66 | I11: =IFERROR(H11/G11, "") -> -1
A12: AZ: Peoria - Pinnacle Peak | B12: AZ | C12: 26659.87 | D12: 2544.006 | E12: =IF(AND(ISNUMBER(C12),ISNUMBER(D12)), C12-D12, "") -> 24115.864 | F12: =IFERROR(E12/D12, "") -> 9.4794839 | G12: 26135 | H12: =IF(AND(ISNUMBER(C12),ISNUMBER(G12)), C12-G12, "") -> 524.87 | I12: =IFERROR(H12/G12, "") -> 0.02008303 | J12: 1. Weather station has intermittent in communication. | K12: 1.SR085026

Sheet Aug
A1: {=portfolio} -> City of Peoria | D1: August Actual v. Expected | G1: August Actual v. Forecasted
A2: Total | C2: =SUM(C4:C97) -> 360867.28 | D2: =SUM(D4:D97) -> 321919.84 | E2: =C2-D2 -> 38947.436 | F2: =IFERROR(E2/D2, 0) -> 0.12098489 | G2: =SUM(G4:G97) -> 361153.93 | H2: =C2-G2 -> -286.65342 | I2: =IFERROR(H2/G2, 0) -> -0.00079371534 | J2: =IF(AND(TODAY()>DATE(2024, 8, 1), COUNTA(Sites[Site])<>(COUNT(C:C)-1)), "Some sites are missing actual data; if new sites were added, make sure they are aligned correctly (including prior months!)", "")
A3: Site | B3: State | C3: Actual | D3: Expected | E3: Delta | F3: % | G3: Forecasted | H3: Delta | I3: % | J3: Notes | K3: Service Requests
A4: {=Sites[Site]} -> AZ: Peoria - Beardsley WWTP - Ad. Bldg | B4: {=Sites[State]} -> AZ | C4: 8285.5619 | D4: 8009.606 | E4: =IF(AND(ISNUMBER(C4),ISNUMBER(D4)), C4-D4, "") -> 275.95589 | F4: =IFERROR(E4/D4, "") -> 0.034453116 | G4: 15895.69 | H4: =IF(AND(ISNUMBER(C4),ISNUMBER(G4)), C4-G4, "") -> -7610.1281 | I4: =IFERROR(H4/G4, "") -> -0.47875419
A5: AZ: Peoria - Fire Station 191 | B5: AZ | C5: 15382.899 | D5: 12819.21 | E5: =IF(AND(ISNUMBER(C5),ISNUMBER(D5)), C5-D5, "") -> 2563.6891 | F5: =IFERROR(E5/D5, "") -> 0.19998807 | G5: 14707 | H5: =IF(AND(ISNUMBER(C5),ISNUMBER(G5)), C5-G5, "") -> 675.8991 | I5: =IFERROR(H5/G5, "") -> 0.045957646
A6: AZ: Peoria - Fire Station 195 | B6: AZ | C6: 7900.155 | D6: 8134.832 | E6: =IF(AND(ISNUMBER(C6),ISNUMBER(D6)), C6-D6, "") -> -234.67703 | F6: =IFERROR(E6/D6, "") -> -0.028848418 | G6: 8530.243 | H6: =IF(AND(ISNUMBER(C6),ISNUMBER(G6)), C6-G6, "") -> -630.08803 | I6: =IFERROR(H6/G6, "") -> -0.073865191
A7: AZ: Peoria - Fire Station 196 | B7: AZ | C7: 5599.9328 | D7: 0 | E7: =IF(AND(ISNUMBER(C7),ISNUMBER(D7)), C7-D7, "") -> 5599.9328 | F7: =IFERROR(E7/D7, "") | G7: 0 | H7: =IF(AND(ISNUMBER(C7),ISNUMBER(G7)), C7-G7, "") -> 5599.9328 | I7: =IFERROR(H7/G7, "")
A8: AZ: Peoria - Fire Station 197 | B8: AZ | C8: 11415.668 | D8: 9068.914 | E8: =IF(AND(ISNUMBER(C8),ISNUMBER(D8)), C8-D8, "") -> 2346.7543 | F8: =IFERROR(E8/D8, "") -> 0.25876906 | G8: 10320.93 | H8: =IF(AND(ISNUMBER(C8),ISNUMBER(G8)), C8-G8, "") -> 1094.7383 | I8: =IFERROR(H8/G8, "") -> 0.10606974
A9: AZ: Peoria - Sunrise Library | B9: AZ | C9: 31947.063 | D9: 29001.08 | E9: =IF(AND(ISNUMBER(C9),ISNUMBER(D9)), C9-D9, "") -> 2945.9825 | F9: =IFERROR(E9/D9, "") -> 0.10158182 | G9: 33358 | H9: =IF(AND(ISNUMBER(C9),ISNUMBER(G9)), C9-G9, "") -> -1410.9375 | I9: =IFERROR(H9/G9, "") -> -0.042296825
A10: AZ: Peoria - Beardsley WWTP | B10: AZ | C10: 233803 | D10: 235029.9 | E10: =IF(AND(ISNUMBER(C10),ISNUMBER(D10)), C10-D10, "") -> -1226.9 | F10: =IFERROR(E10/D10, "") -> -0.0052201869 | G10: 207181 | H10: =IF(AND(ISNUMBER(C10),ISNUMBER(G10)), C10-G10, "") -> 26622 | I10: =IFERROR(H10/G10, "") -> 0.12849634
A11: AZ: Peoria - City Hall | B11: AZ | C11: 21778.5 | D11: 19263.73 | E11: =IF(AND(ISNUMBER(C11),ISNUMBER(D11)), C11-D11, "") -> 2514.77 | F11: =IFERROR(E11/D11, "") -> 0.13054429 | G11: 46289.07 | H11: =IF(AND(ISNUMBER(C11),ISNUMBER(G11)), C11-G11, "") -> -24510.57 | I11: =IFERROR(H11/G11, "") -> -0.52951096
A12: AZ: Peoria - Pinnacle Peak | B12: AZ | C12: 24754.5 | D12: 592.5714 | E12: =IF(AND(ISNUMBER(C12),ISNUMBER(D12)), C12-D12, "") -> 24161.929 | F12: =IFERROR(E12/D12, "") -> 40.774713 | G12: 24872 | H12: =IF(AND(ISNUMBER(C12),ISNUMBER(G12)), C12-G12, "") -> -117.5 | I12: =IFERROR(H12/G12, "") -> -0.0047241878 | J12: 1. Weather station has intermittent in communication. | K12: 1.SR085026

Sheet Sep
A1: {=portfolio} -> City of Peoria | D1: September Actual v. Expected | G1: September Actual v. Forecasted
A2: Total | C2: =SUM(C4:C97) -> 351904.01 | D2: =SUM(D4:D97) -> 319465.54 | E2: =C2-D2 -> 32438.468 | F2: =IFERROR(E2/D2, 0) -> 0.1015398 | G2: =SUM(G4:G97) -> 334623.86 | H2: =C2-G2 -> 17280.148 | I2: =IFERROR(H2/G2, 0) -> 0.051640514 | J2: =IF(AND(TODAY()>DATE(2024, 9, 1), COUNTA(Sites[Site])<>(COUNT(C:C)-1)), "Some sites are missing actual data; if new sites were added, make sure they are aligned correctly (including prior months!)", "")
A3: Site | B3: State | C3: Actual | D3: Expected | E3: Delta | F3: % | G3: Forecasted | H3: Delta | I3: % | J3: Notes | K3: Service Requests
A4: {=Sites[Site]} -> AZ: Peoria - Beardsley WWTP - Ad. Bldg | B4: {=Sites[State]} -> AZ | C4: 7470.7385 | D4: 6561.517 | E4: =IF(AND(ISNUMBER(C4),ISNUMBER(D4)), C4-D4, "") -> 909.22154 | F4: =IFERROR(E4/D4, "") -> 0.1385688 | G4: 13646.58 | H4: =IF(AND(ISNUMBER(C4),ISNUMBER(G4)), C4-G4, "") -> -6175.8415 | I4: =IFERROR(H4/G4, "") -> -0.45255599 | J4: 1. Site is offline from 11:06AM to 11:26AM on 09/12/2024. | K4: 1. SR090335
A5: AZ: Peoria - Fire Station 191 | B5: AZ | C5: 14969.486 | D5: 12208.43 | E5: =IF(AND(ISNUMBER(C5),ISNUMBER(D5)), C5-D5, "") -> 2761.0557 | F5: =IFERROR(E5/D5, "") -> 0.22615977 | G5: 13842 | H5: =IF(AND(ISNUMBER(C5),ISNUMBER(G5)), C5-G5, "") -> 1127.4857 | I5: =IFERROR(H5/G5, "") -> 0.081453962
A6: AZ: Peoria - Fire Station 195 | B6: AZ | C6: 7323.9091 | D6: 7173.503 | E6: =IF(AND(ISNUMBER(C6),ISNUMBER(D6)), C6-D6, "") -> 150.40606 | F6: =IFERROR(E6/D6, "") -> 0.020966892 | G6: 8015.265 | H6: =IF(AND(ISNUMBER(C6),ISNUMBER(G6)), C6-G6, "") -> -691.35594 | I6: =IFERROR(H6/G6, "") -> -0.086254907
A7: AZ: Peoria - Fire Station 196 | B7: AZ | C7: 5269.1792 | D7: 0 | E7: =IF(AND(ISNUMBER(C7),ISNUMBER(D7)), C7-D7, "") -> 5269.1792 | F7: =IFERROR(E7/D7, "") | G7: 0 | H7: =IF(AND(ISNUMBER(C7),ISNUMBER(G7)), C7-G7, "") -> 5269.1792 | I7: =IFERROR(H7/G7, "")
A8: AZ: Peoria - Fire Station 197 | B8: AZ | C8: 11015.101 | D8: 8539.962 | E8: =IF(AND(ISNUMBER(C8),ISNUMBER(D8)), C8-D8, "") -> 2475.1393 | F8: =IFERROR(E8/D8, "") -> 0.28983024 | G8: 10330.02 | H8: =IF(AND(ISNUMBER(C8),ISNUMBER(G8)), C8-G8, "") -> 685.08127 | I8: =IFERROR(H8/G8, "") -> 0.066319453
A9: AZ: Peoria - Sunrise Library | B9: AZ | C9: 29051.403 | D9: 24422.11 | E9: =IF(AND(ISNUMBER(C9),ISNUMBER(D9)), C9-D9, "") -> 4629.2932 | F9: =IFERROR(E9/D9, "") -> 0.18955337 | G9: 31354 | H9: =IF(AND(ISNUMBER(C9),ISNUMBER(G9)), C9-G9, "") -> -2302.5968 | I9: =IFERROR(H9/G9, "") -> -0.073438693
A10: AZ: Peoria - Beardsley WWTP | B10: AZ | C10: 212411.83 | D10: 215957.6 | E10: =IF(AND(ISNUMBER(C10),ISNUMBER(D10)), C10-D10, "") -> -3545.7738 | F10: =IFERROR(E10/D10, "") -> -0.016418842 | G10: 190510 | H10: =IF(AND(ISNUMBER(C10),ISNUMBER(G10)), C10-G10, "") -> 21901.826 | I10: =IFERROR(H10/G10, "") -> 0.11496418 | J10: 1. Inverter D3 is offline on 09/15, 09/26, 09/28 and 09/29, it was back online on 09/30 | K10: 1. SR090556
A11: AZ: Peoria - City Hall | B11: AZ | C11: 40915.62 | D11: 36634.63 | E11: =IF(AND(ISNUMBER(C11),ISNUMBER(D11)), C11-D11, "") -> 4280.99 | F11: =IFERROR(E11/D11, "") -> 0.11685637 | G11: 43546 | H11: =IF(AND(ISNUMBER(C11),ISNUMBER(G11)), C11-G11, "") -> -2630.38 | I11: =IFERROR(H11/G11, "") -> -0.06040463
A12: AZ: Peoria - Pinnacle Peak | B12: AZ | C12: 23476.75 | D12: 7967.793 | E12: =IF(AND(ISNUMBER(C12),ISNUMBER(D12)), C12-D12, "") -> 15508.957 | F12: =IFERROR(E12/D12, "") -> 1.9464558 | G12: 23380 | H12: =IF(AND(ISNUMBER(C12),ISNUMBER(G12)), C12-G12, "") -> 96.75 | I12: =IFERROR(H12/G12, "") -> 0.0041381523

Sheet Oct
A1: {=portfolio} -> City of Peoria | D1: October Actual v. Expected | G1: October Actual v. Forecasted
A2: Total | C2: =SUM(C4:C97) -> 295517.52 | D2: =SUM(D4:D97) -> 275920.6 | E2: =C2-D2 -> 19596.927 | F2: =IFERROR(E2/D2, 0) -> 0.07102379 | G2: =SUM(G4:G97) -> 311766.88 | H2: =C2-G2 -> -16249.359 | I2: =IFERROR(H2/G2, 0) -> -0.052120223 | J2: =IF(AND(TODAY()>DATE(2024, 10, 1), COUNTA(Sites[Site])<>(COUNT(C:C)-1)), "Some sites are missing actual data; if new sites were added, make sure they are aligned correctly (including prior months!)", "")
A3: Site | B3: State | C3: Actual | D3: Expected | E3: Delta | F3: % | G3: Forecasted | H3: Delta | I3: % | J3: Notes | K3: Service Requests
A4: {=Sites[Site]} -> AZ: Peoria - Beardsley WWTP - Ad. Bldg | B4: {=Sites[State]} -> AZ | C4: 6015.4268 | D4: 4940.316 | E4: =IF(AND(ISNUMBER(C4),ISNUMBER(D4)), C4-D4, "") -> 1075.1108 | F4: =IFERROR(E4/D4, "") -> 0.21761984 | G4: 11655.42 | H4: =IF(AND(ISNUMBER(C4),ISNUMBER(G4)), C4-G4, "") -> -5639.9932 | I4: =IFERROR(H4/G4, "") -> -0.48389447
A5: AZ: Peoria - Fire Station 191 | B5: AZ | C5: 13373.952 | D5: 10717.53 | E5: =IF(AND(ISNUMBER(C5),ISNUMBER(D5)), C5-D5, "") -> 2656.4219 | F5: =IFERROR(E5/D5, "") -> 0.24785766 | G5: 12781 | H5: =IF(AND(ISNUMBER(C5),ISNUMBER(G5)), C5-G5, "") -> 592.95194 | I5: =IFERROR(H5/G5, "") -> 0.046393235
A6: AZ: Peoria - Fire Station 195 | B6: AZ | C6: 6142.0705 | D6: 5725.615 | E6: =IF(AND(ISNUMBER(C6),ISNUMBER(D6)), C6-D6, "") -> 416.45551 | F6: =IFERROR(E6/D6, "") -> 0.072735506 | G6: 7504.627 | H6: =IF(AND(ISNUMBER(C6),ISNUMBER(G6)), C6-G6, "") -> -1362.5565 | I6: =IFERROR(H6/G6, "") -> -0.18156219
A7: AZ: Peoria - Fire Station 196 | B7: AZ | C7: 4547 | D7: 0 | E7: =IF(AND(ISNUMBER(C7),ISNUMBER(D7)), C7-D7, "") -> 4547 | F7: =IFERROR(E7/D7, "") | G7: 0 | H7: =IF(AND(ISNUMBER(C7),ISNUMBER(G7)), C7-G7, "") -> 4547 | I7: =IFERROR(H7/G7, "")
A8: AZ: Peoria - Fire Station 197 | B8: AZ | C8: 9869.3579 | D8: 7620.654 | E8: =IF(AND(ISNUMBER(C8),ISNUMBER(D8)), C8-D8, "") -> 2248.7039 | F8: =IFERROR(E8/D8, "") -> 0.29508017 | G8: 9793.404 | H8: =IF(AND(ISNUMBER(C8),ISNUMBER(G8)), C8-G8, "") -> 75.95388 | I8: =IFERROR(H8/G8, "") -> 0.0077556159
A9: AZ: Peoria - Sunrise Library | B9: AZ | C9: 23485.291 | D9: 18665.71 | E9: =IF(AND(ISNUMBER(C9),ISNUMBER(D9)), C9-D9, "") -> 4819.5807 | F9: =IFERROR(E9/D9, "") -> 0.25820506 | G9: 29371 | H9: =IF(AND(ISNUMBER(C9),ISNUMBER(G9)), C9-G9, "") -> -5885.7093 | I9: =IFERROR(H9/G9, "") -> -0.20039186
A10: AZ: Peoria - Beardsley WWTP | B10: AZ | C10: 177436.17 | D10: 186273.1 | E10: =IF(AND(ISNUMBER(C10),ISNUMBER(D10)), C10-D10, "") -> -8836.9262 | F10: =IFERROR(E10/D10, "") -> -0.0474407 | G10: 178526 | H10: =IF(AND(ISNUMBER(C10),ISNUMBER(G10)), C10-G10, "") -> -1089.8262 | I10: =IFERROR(H10/G10, "") -> -0.00610458 | J10: 1.Inverter D3 was offline at 06:30 on 10/01 and back online at 06:15 on 10/03 and Inverter D3 was offline at 06:30 on 10/5 and back online at 06:15 on 10/06 and the Inverter D3 was being RMA'd from 10/10. 2.Inverter B4 tripped offline at 10:00 on 10/14 and back online at 11:15 on 10/22. 3.Since there are several trackers stuck in the afternoon hours. The inverters that are being affected by this are: A1, A2, B1, B2, B3, B4, C1, C2, C3, D2, D3, D4. | K10: 1.SR090556 2.SR092124 3.SR092803
A11: AZ: Peoria - City Hall | B11: AZ | C11: 34054.5 | D11: 31373.5 | E11: =IF(AND(ISNUMBER(Nov!C11),ISNUMBER(Nov!D11)), Nov!C11-Nov!D11, "") -> 2035.16 | F11: =IFERROR(E11/Nov!D11, "") -> 0.084570732 | G11: 40236.43 | H11: =IF(AND(ISNUMBER(Nov!C11),ISNUMBER(Nov!G11)), Nov!C11-Nov!G11, "") -> -7042.39 | I11: =IFERROR(H11/G11, "") -> -0.17502522
A12: AZ: Peoria - Pinnacle Peak | B12: AZ | C12: 20593.75 | D12: 10604.17 | E12: =IF(AND(ISNUMBER(C12),ISNUMBER(D12)), C12-D12, "") -> 9989.58 | F12: =IFERROR(E12/D12, "") -> 0.94204261 | G12: 21899 | H12: =IF(AND(ISNUMBER(C12),ISNUMBER(G12)), C12-G12, "") -> -1305.25 | I12: =IFERROR(H12/G12, "") -> -0.059603178 | J12: 1. Weather station has inetermittent communication due to that expected values are low. | K12: 1.SR085026

Sheet Nov
A1: {=portfolio} -> City of Peoria | D1: November Actual v. Expected | G1: November Actual v. Forecasted
A2: Total | C2: =SUM(C4:C97) -> 232806.76 | D2: =SUM(D4:D97) -> 216911.91 | E2: =C2-D2 -> 15894.852 | F2: =IFERROR(E2/D2, 0) -> 0.073277914 | G2: =SUM(G4:G97) -> 253457.82 | H2: =C2-G2 -> -20651.059 | I2: =IFERROR(H2/G2, 0) -> -0.081477299 | J2: =IF(AND(TODAY()>DATE(2024, 11, 1), COUNTA(Sites[Site])<>(COUNT(C:C)-1)), "Some sites are missing actual data; if new sites were added, make sure they are aligned correctly (including prior months!)", "")
A3: Site | B3: State | C3: Actual | D3: Expected | E3: Delta | F3: % | G3: Forecasted | H3: Delta | I3: % | J3: Notes | K3: Service Requests
A4: {=Sites[Site]} -> AZ: Peoria - Beardsley WWTP - Ad. Bldg | B4: {=Sites[State]} -> AZ | C4: 4830.9142 | D4: 3454.2 | E4: =IF(AND(ISNUMBER(C4),ISNUMBER(D4)), C4-D4, "") -> 1376.7142 | F4: =IFERROR(E4/D4, "") -> 0.39856239 | G4: 8649.383 | H4: =IF(AND(ISNUMBER(C4),ISNUMBER(G4)), C4-G4, "") -> -3818.4688 | I4: =IFERROR(H4/G4, "") -> -0.44147297
A5: AZ: Peoria - Fire Station 191 | B5: AZ | C5: 11151.564 | D5: 8995.459 | E5: =IF(AND(ISNUMBER(C5),ISNUMBER(D5)), C5-D5, "") -> 2156.1054 | F5: =IFERROR(E5/D5, "") -> 0.2396882 | G5: 10527 | H5: =IF(AND(ISNUMBER(C5),ISNUMBER(G5)), C5-G5, "") -> 624.56442 | I5: =IFERROR(H5/G5, "") -> 0.059329763
A6: AZ: Peoria - Fire Station 195 | B6: AZ | C6: 4595.2836 | D6: 4484.665 | E6: =IF(AND(ISNUMBER(C6),ISNUMBER(D6)), C6-D6, "") -> 110.61857 | F6: =IFERROR(E6/D6, "") -> 0.02466596 | G6: 6117.767 | H6: =IF(AND(ISNUMBER(C6),ISNUMBER(G6)), C6-G6, "") -> -1522.4834 | I6: =IFERROR(H6/G6, "") -> -0.24886261
