Workbook
Name JanActual: #REF!
Name JanActual2: #REF!
Name JanExpected: #REF!
Name JanExpectedDelta: #REF!
Name JanExpectedPercent: #REF!
Name JanExpPercent: #REF!
Name JanForecasted: #REF!
Name JanForecastedDelta: #REF!
Name JanForecastedPercent: #REF!
Name portfolio: Sites!$B$1:$B$1
Name Year: Sites!#REF!

Sheet Year to Date
A1: {=portfolio} -> Generate Capital | E1: Year to Date Actual v. Expected | H1: Year to Date Actual v. Forecasted | K1: YtD Availability
A2: Total | D2: =SUM(D4:D200) -> 2.6538566e+08 | E2: =SUM(E4:E138) -> 86991351 | F2: =D2-E2 -> 1.7839431e+08 | G2: =IFERROR(F2/E2, 0) -> 2.0507132 | H2: =SUM(H4:H138) -> 2.1453042e+08 | I2: =D2-H2 -> 50855239 | J2: =IFERROR(I2/H2, 0) -> 0.23705374
A3: Site | B3: State | C3: SOL# | D3: Actual | E3: Expected | F3: Delta | G3: % | H3: Forecasted | I3: Delta | J3: % | K3: Site Availability
A4: {=Sites[Site]} -> Farmer | B4: {=Sites[State]} -> AZ | C4: =Sites[[#This Row],[SOL'#]] -> SOL-10748 | D4: =SUM('1st Qtr'!D4, '2nd Qtr'!D4, '3rd Qtr'!D4, '4th Qtr'!D4) -> 129168.86 | E4: =SUM('1st Qtr'!E4, '2nd Qtr'!E4, '3rd Qtr'!E4, '4th Qtr'!E4) -> 37285.274 | F4: =IF(AND(ISNUMBER(D4),ISNUMBER(E4)), D4-E4, "") -> 91883.589 | G4: =IFERROR(F4/E4, "") -> 2.4643399 | H4: =SUM('1st Qtr'!H4+'2nd Qtr'!H4+'3rd Qtr'!H4+'4th Qtr'!H4) -> 122327.51 | I4: =SUM('1st Qtr'!I4, '2nd Qtr'!I4, '3rd Qtr'!I4, '4th Qtr'!I4) -> 6841.3574 | J4: =IFERROR(I4/H4, "") -> 0.055926567 | K4: =IFERROR(AVERAGE(Jan!K4, Feb!K4, Mar!K4, Apr!K4, May!K4, Jun!K4, Jul!K4, Aug!K4, Sep!K4, Oct!K4, Nov!K4, Dec!K4),"") -> 0.9996124
A5: Fulton | B5: AZ | C5: =Sites[[#This Row],[SOL'#]] -> SOL-10749 | D5: =SUM('1st Qtr'!D5, '2nd Qtr'!D5, '3rd Qtr'!D5, '4th Qtr'!D5) -> 500073 | E5: =SUM('1st Qtr'!E5, '2nd Qtr'!E5, '3rd Qtr'!E5, '4th Qtr'!E5) -> 241816.75 | F5: =IF(AND(ISNUMBER(D5),ISNUMBER(E5)), D5-E5, "") -> 258256.25 | G5: =IFERROR(F5/E5, "") -> 1.0679833 | H5: =SUM('1st Qtr'!H5+'2nd Qtr'!H5+'3rd Qtr'!H5+'4th Qtr'!H5) -> 595510.1 | I5: =SUM('1st Qtr'!I5, '2nd Qtr'!I5, '3rd Qtr'!I5, '4th Qtr'!I5) -> -95437.1 | J5: =IFERROR(I5/H5, "") -> -0.16026109 | K5: =IFERROR(AVERAGE(Jan!K5, Feb!K5, Mar!K5, Apr!K5, May!K5, Jun!K5, Jul!K5, Aug!K5, Sep!K5, Oct!K5, Nov!K5, Dec!K5),"") -> 0.9966893
A6: JFK Elementary | B6: AZ | C6: =Sites[[#This Row],[SOL'#]] -> SOL-10758 | D6: =SUM('1st Qtr'!D6, '2nd Qtr'!D6, '3rd Qtr'!D6, '4th Qtr'!D6) -> -1029121.7 | E6: =SUM('1st Qtr'!E6, '2nd Qtr'!E6, '3rd Qtr'!E6, '4th Qtr'!E6) -> 0 | F6: =IF(AND(ISNUMBER(D6),ISNUMBER(E6)), D6-E6, "") -> -1029121.7 | G6: =IFERROR(F6/E6, "") | H6: =SUM('1st Qtr'!H6+'2nd Qtr'!H6+'3rd Qtr'!H6+'4th Qtr'!H6) -> 180722 | I6: =SUM('1st Qtr'!I6, '2nd Qtr'!I6, '3rd Qtr'!I6, '4th Qtr'!I6) -> -1209843.7 | J6: =IFERROR(I6/H6, "") -> -6.6945013 | K6: =IFERROR(AVERAGE(Jan!K6, Feb!K6, Mar!K6, Apr!K6, May!K6, Jun!K6, Jul!K6, Aug!K6, Sep!K6, Oct!K6, Nov!K6, Dec!K6),"") -> 0.74997377
A7: Noble | B7: AZ | C7: =Sites[[#This Row],[SOL'#]] -> SOL-10750 | D7: =SUM('1st Qtr'!D7, '2nd Qtr'!D7, '3rd Qtr'!D7, '4th Qtr'!D7) -> 98780.804 | E7: =SUM('1st Qtr'!E7, '2nd Qtr'!E7, '3rd Qtr'!E7, '4th Qtr'!E7) -> 62997.764 | F7: =IF(AND(ISNUMBER(D7),ISNUMBER(E7)), D7-E7, "") -> 35783.04 | G7: =IFERROR(F7/E7, "") -> 0.56800492 | H7: =SUM('1st Qtr'!H7+'2nd Qtr'!H7+'3rd Qtr'!H7+'4th Qtr'!H7) -> 137640.33 | I7: =SUM('1st Qtr'!I7, '2nd Qtr'!I7, '3rd Qtr'!I7, '4th Qtr'!I7) -> -38859.526 | J7: =IFERROR(I7/H7, "") -> -0.2823266 | K7: =IFERROR(AVERAGE(Jan!K7, Feb!K7, Mar!K7, Apr!K7, May!K7, Jun!K7, Jul!K7, Aug!K7, Sep!K7, Oct!K7, Nov!K7, Dec!K7),"") -> 0.9610567
A8: Parking 3 | B8: AZ | C8: =Sites[[#This Row],[SOL'#]] -> SOL-10751 | D8: =SUM('1st Qtr'!D8, '2nd Qtr'!D8, '3rd Qtr'!D8, '4th Qtr'!D8) -> 270270.01 | E8: =SUM('1st Qtr'!E8, '2nd Qtr'!E8, '3rd Qtr'!E8, '4th Qtr'!E8) -> 138991.53 | F8: =IF(AND(ISNUMBER(D8),ISNUMBER(E8)), D8-E8, "") -> 131278.48 | G8: =IFERROR(F8/E8, "") -> 0.94450708 | H8: =SUM('1st Qtr'!H8+'2nd Qtr'!H8+'3rd Qtr'!H8+'4th Qtr'!H8) -> 296249.62 | I8: =SUM('1st Qtr'!I8, '2nd Qtr'!I8, '3rd Qtr'!I8, '4th Qtr'!I8) -> -25979.606 | J8: =IFERROR(I8/H8, "") -> -0.087694986 | K8: =IFERROR(AVERAGE(Jan!K8, Feb!K8, Mar!K8, Apr!K8, May!K8, Jun!K8, Jul!K8, Aug!K8, Sep!K8, Oct!K8, Nov!K8, Dec!K8),"") -> 0.90212869
A9: PE East | B9: AZ | C9: =Sites[[#This Row],[SOL'#]] -> SOL-10752 | D9: =SUM('1st Qtr'!D9, '2nd Qtr'!D9, '3rd Qtr'!D9, '4th Qtr'!D9) -> 287786.01 | E9: =SUM('1st Qtr'!E9, '2nd Qtr'!E9, '3rd Qtr'!E9, '4th Qtr'!E9) -> 100252.46 | F9: =IF(AND(ISNUMBER(D9),ISNUMBER(E9)), D9-E9, "") -> 187533.55 | G9: =IFERROR(F9/E9, "") -> 1.8706129 | H9: =SUM('1st Qtr'!H9+'2nd Qtr'!H9+'3rd Qtr'!H9+'4th Qtr'!H9) -> 291561.8 | I9: =SUM('1st Qtr'!I9, '2nd Qtr'!I9, '3rd Qtr'!I9, '4th Qtr'!I9) -> -3775.7904 | J9: =IFERROR(I9/H9, "") -> -0.012950223 | K9: =IFERROR(AVERAGE(Jan!K9, Feb!K9, Mar!K9, Apr!K9, May!K9, Jun!K9, Jul!K9, Aug!K9, Sep!K9, Oct!K9, Nov!K9, Dec!K9),"") -> 0.99930198
A10: Schwada | B10: AZ | C10: =Sites[[#This Row],[SOL'#]] -> SOL-10753 | D10: =SUM('1st Qtr'!D10, '2nd Qtr'!D10, '3rd Qtr'!D10, '4th Qtr'!D10) -> 126800.16 | E10: =SUM('1st Qtr'!E10, '2nd Qtr'!E10, '3rd Qtr'!E10, '4th Qtr'!E10) -> 41274.715 | F10: =IF(AND(ISNUMBER(D10),ISNUMBER(E10)), D10-E10, "") -> 85525.447 | G10: =IFERROR(F10/E10, "") -> 2.0721027 | H10: =SUM('1st Qtr'!H10+'2nd Qtr'!H10+'3rd Qtr'!H10+'4th Qtr'!H10) -> 125830 | I10: =SUM('1st Qtr'!I10, '2nd Qtr'!I10, '3rd Qtr'!I10, '4th Qtr'!I10) -> 970.16214 | J10: =IFERROR(I10/H10, "") -> 0.0077101021 | K10: =IFERROR(AVERAGE(Jan!K10, Feb!K10, Mar!K10, Apr!K10, May!K10, Jun!K10, Jul!K10, Aug!K10, Sep!K10, Oct!K10, Nov!K10, Dec!K10),"") -> 0.99354839
A11: Starshine | B11: AZ | C11: =Sites[[#This Row],[SOL'#]] -> SOL-10757 | D11: =SUM('1st Qtr'!D11, '2nd Qtr'!D11, '3rd Qtr'!D11, '4th Qtr'!D11) -> -940287.28 | E11: =SUM('1st Qtr'!E11, '2nd Qtr'!E11, '3rd Qtr'!E11, '4th Qtr'!E11) -> 0 | F11: =IF(AND(ISNUMBER(D11),ISNUMBER(E11)), D11-E11, "") -> -940287.28 | G11: =IFERROR(F11/E11, "") | H11: =SUM('1st Qtr'!H11+'2nd Qtr'!H11+'3rd Qtr'!H11+'4th Qtr'!H11) -> 93543 | I11: =SUM('1st Qtr'!I11, '2nd Qtr'!I11, '3rd Qtr'!I11, '4th Qtr'!I11) -> -1033830.3 | J11: =IFERROR(I11/H11, "") -> -11.051926 | K11: =IFERROR(AVERAGE(Jan!K11, Feb!K11, Mar!K11, Apr!K11, May!K11, Jun!K11, Jul!K11, Aug!K11, Sep!K11, Oct!K11, Nov!K11, Dec!K11),"") -> 0.66234191
A12: Yuma Airport | B12: AZ | C12: =Sites[[#This Row],[SOL'#]] -> SOL-10754 | D12: =SUM('1st Qtr'!D12, '2nd Qtr'!D12, '3rd Qtr'!D12, '4th Qtr'!D12) -> 748529 | E12: =SUM('1st Qtr'!E12, '2nd Qtr'!E12, '3rd Qtr'!E12, '4th Qtr'!E12) -> 910308.38 | F12: =IF(AND(ISNUMBER(D12),ISNUMBER(E12)), D12-E12, "") -> -161779.38 | G12: =IFERROR(F12/E12, "") -> -0.17771931 | H12: =SUM('1st Qtr'!H12+'2nd Qtr'!H12+'3rd Qtr'!H12+'4th Qtr'!H12) -> 759063 | I12: =SUM('1st Qtr'!I12, '2nd Qtr'!I12, '3rd Qtr'!I12, '4th Qtr'!I12) -> -10534 | J12: =IFERROR(I12/H12, "") -> -0.013877636 | K12: =IFERROR(AVERAGE(Jan!K12, Feb!K12, Mar!K12, Apr!K12, May!K12, Jun!K12, Jul!K12, Aug!K12, Sep!K12, Oct!K12, Nov!K12, Dec!K12),"") -> 1
A13: Kinsman | B13: OH | C13: =Sites[[#This Row],[SOL'#]] -> SOL-10762 | D13: =SUM('1st Qtr'!D13, '2nd Qtr'!D13, '3rd Qtr'!D13, '4th Qtr'!D13) -> 844175.11 | E13: =SUM('1st Qtr'!E13, '2nd Qtr'!E13, '3rd Qtr'!E13, '4th Qtr'!E13) -> 1089511.4 | F13: =IF(AND(ISNUMBER(D13),ISNUMBER(E13)), D13-E13, "") -> -245336.25 | G13: =IFERROR(F13/E13, "") -> -0.22518008 | H13: =SUM('1st Qtr'!H13+'2nd Qtr'!H13+'3rd Qtr'!H13+'4th Qtr'!H13) -> 1039848 | I13: =SUM('1st Qtr'!I13, '2nd Qtr'!I13, '3rd Qtr'!I13, '4th Qtr'!I13) -> -195672.89 | J13: =IFERROR(I13/H13, "") -> -0.18817451 | K13: =IFERROR(AVERAGE(Jan!K13, Feb!K13, Mar!K13, Apr!K13, May!K13, Jun!K13, Jul!K13, Aug!K13, Sep!K13, Oct!K13, Nov!K13, Dec!K13),"") -> 0.98598175
A14: Wooster | B14: OH | C14: =Sites[[#This Row],[SOL'#]] -> SOL-10763 | D14: =SUM('1st Qtr'!D14, '2nd Qtr'!D14, '3rd Qtr'!D14, '4th Qtr'!D14) -> 178790.75 | E14: =SUM('1st Qtr'!E14, '2nd Qtr'!E14, '3rd Qtr'!E14, '4th Qtr'!E14) -> 0 | F14: =IF(AND(ISNUMBER(D14),ISNUMBER(E14)), D14-E14, "") -> 178790.75 | G14: =IFERROR(F14/E14, "") | H14: =SUM('1st Qtr'!H14+'2nd Qtr'!H14+'3rd Qtr'!H14+'4th Qtr'!H14) -> 242411 | I14: =SUM('1st Qtr'!I14, '2nd Qtr'!I14, '3rd Qtr'!I14, '4th Qtr'!I14) -> -63620.25 | J14: =IFERROR(I14/H14, "") -> -0.26244787 | K14: =IFERROR(AVERAGE(Jan!K14, Feb!K14, Mar!K14, Apr!K14, May!K14, Jun!K14, Jul!K14, Aug!K14, Sep!K14, Oct!K14, Nov!K14, Dec!K14),"") -> 1
A15: Globe Gila CC | B15: AZ | C15: =Sites[[#This Row],[SOL'#]] -> SOL-10755 | D15: =SUM('1st Qtr'!D15, '2nd Qtr'!D15, '3rd Qtr'!D15, '4th Qtr'!D15) -> -1358643.4 | E15: =SUM('1st Qtr'!E15, '2nd Qtr'!E15, '3rd Qtr'!E15, '4th Qtr'!E15) -> 48461.452 | F15: =IF(AND(ISNUMBER(D15),ISNUMBER(E15)), D15-E15, "") -> -1407104.9 | G15: =IFERROR(F15/E15, "") -> -29.035549 | H15: =SUM('1st Qtr'!H15+'2nd Qtr'!H15+'3rd Qtr'!H15+'4th Qtr'!H15) -> 166022 | I15: =SUM('1st Qtr'!I15, '2nd Qtr'!I15, '3rd Qtr'!I15, '4th Qtr'!I15) -> -1524665.4 | J15: =IFERROR(I15/H15, "") -> -9.1835143 | K15: =IFERROR(AVERAGE(Jan!K15, Feb!K15, Mar!K15, Apr!K15, May!K15, Jun!K15, Jul!K15, Aug!K15, Sep!K15, Oct!K15, Nov!K15, Dec!K15),"") -> 0.99992132
A16: Payson Gila CC | B16: AZ | C16: =Sites[[#This Row],[SOL'#]] -> SOL-10756 | D16: =SUM('1st Qtr'!D16, '2nd Qtr'!D16, '3rd Qtr'!D16, '4th Qtr'!D16) -> 98918.258 | E16: =SUM('1st Qtr'!E16, '2nd Qtr'!E16, '3rd Qtr'!E16, '4th Qtr'!E16) -> 25114.707 | F16: =IF(AND(ISNUMBER(D16),ISNUMBER(E16)), D16-E16, "") -> 73803.551 | G16: =IFERROR(F16/E16, "") -> 2.9386586 | H16: =SUM('1st Qtr'!H16+'2nd Qtr'!H16+'3rd Qtr'!H16+'4th Qtr'!H16) -> 128723 | I16: =SUM('1st Qtr'!I16, '2nd Qtr'!I16, '3rd Qtr'!I16, '4th Qtr'!I16) -> -29804.742 | J16: =IFERROR(I16/H16, "") -> -0.2315417 | K16: =IFERROR(AVERAGE(Jan!K16, Feb!K16, Mar!K16, Apr!K16, May!K16, Jun!K16, Jul!K16, Aug!K16, Sep!K16, Oct!K16, Nov!K16, Dec!K16),"") -> 0.99790884
... A138: Ridgeway #2 | B138: NY | C138: =Sites[[#This Row],[SOL'#]] -> SOL-11027 | D138: =SUM('1st Qtr'!D138, '2nd Qtr'!D138, '3rd Qtr'!D138, '4th Qtr'!D138) -> 3747929.4 | E138: =SUM('1st Qtr'!E138, '2nd Qtr'!E138, '3rd Qtr'!E138, '4th Qtr'!E138) -> 0 | F138: =IF(AND(ISNUMBER(D138),ISNUMBER(E138)), D138-E138, "") -> 3747929.4 | G138: =IFERROR(F138/E138, "") | H138: =SUM('1st Qtr'!H138+'2nd Qtr'!H138+'3rd Qtr'!H138+'4th Qtr'!H138) -> 1798380 | I138: =SUM('1st Qtr'!I138, '2nd Qtr'!I138, '3rd Qtr'!I138, '4th Qtr'!I138) -> 1949549.4 | J138: =IFERROR(I138/H138, "") -> 1.0840587 | K138: =IFERROR(AVERAGE(Jan!K138, Feb!K138, Mar!K138, Apr!K138, May!K138, Jun!K138, Jul!K138, Aug!K138, Sep!K138, Oct!K138, Nov!K138, Dec!K138),"")
A139: Spencer | B139: NY | C139: =Sites[[#This Row],[SOL'#]] -> SOL-11017 | D139: =SUM('1st Qtr'!D139, '2nd Qtr'!D139, '3rd Qtr'!D139, '4th Qtr'!D139) -> 6238595.8 | E139: =SUM('1st Qtr'!E139, '2nd Qtr'!E139, '3rd Qtr'!E139, '4th Qtr'!E139) -> 0 | F139: =IF(AND(ISNUMBER(D139),ISNUMBER(E139)), D139-E139, "") -> 6238595.8 | G139: =IFERROR(F139/E139, "") | H139: =SUM('1st Qtr'!H139+'2nd Qtr'!H139+'3rd Qtr'!H139+'4th Qtr'!H139) -> 3451000 | I139: =SUM('1st Qtr'!I139, '2nd Qtr'!I139, '3rd Qtr'!I139, '4th Qtr'!I139) -> 2787595.8 | K139: =IFERROR(AVERAGE(Jan!K139, Feb!K139, Mar!K139, Apr!K139, May!K139, Jun!K139, Jul!K139, Aug!K139, Sep!K139, Oct!K139, Nov!K139, Dec!K139),"")
A140: Reisender | B140: NY | C140: ='1st Qtr'!C140 -> SOL-10886 | D140: =SUM('1st Qtr'!D140, '2nd Qtr'!D140, '3rd Qtr'!D140, '4th Qtr'!D140) -> 1447640 | E140: =SUM('1st Qtr'!E140, '2nd Qtr'!E140, '3rd Qtr'!E140, '4th Qtr'!E140) -> 1469154.3 | F140: =IF(AND(ISNUMBER(D140),ISNUMBER(E140)), D140-E140, "") -> -21514.28 | G140: =IFERROR(F140/E140, "") -> -0.01464399 | H140: =SUM('1st Qtr'!H140+'2nd Qtr'!H140+'3rd Qtr'!H140+'4th Qtr'!H140) -> 1500075 | I140: =SUM('1st Qtr'!I140, '2nd Qtr'!I140, '3rd Qtr'!I140, '4th Qtr'!I140) -> -52435 | K140: =IFERROR(AVERAGE(Jan!K140, Feb!K140, Mar!K140, Apr!K140, May!K140, Jun!K140, Jul!K140, Aug!K140, Sep!K140, Oct!K140, Nov!K140, Dec!K140),"")
A141: Finney | B141: NY | C141: =Sites[[#This Row],[SOL'#]] -> SOL-10999 | D141: =SUM('1st Qtr'!D141, '2nd Qtr'!D141, '3rd Qtr'!D141, '4th Qtr'!D141) -> 3289070 | E141: =SUM('1st Qtr'!E141, '2nd Qtr'!E141, '3rd Qtr'!E141, '4th Qtr'!E141) -> 0 | F141: =IF(AND(ISNUMBER(D141),ISNUMBER(E141)), D141-E141, "") -> 3289070 | G141: =IFERROR(F141/E141, "") | H141: =SUM('1st Qtr'!H141+'2nd Qtr'!H141+'3rd Qtr'!H141+'4th Qtr'!H141) -> 3307438 | I141: =SUM('1st Qtr'!I141, '2nd Qtr'!I141, '3rd Qtr'!I141, '4th Qtr'!I141) -> -334948 | K141: =IFERROR(AVERAGE(Jan!K141, Feb!K141, Mar!K141, Apr!K141, May!K141, Jun!K141, Jul!K141, Aug!K141, Sep!K141, Oct!K141, Nov!K141, Dec!K141),"")
A142: Davis Solar | B142: NY | C142: =Sites[[#This Row],[SOL'#]] -> SOL-10958 | D142: =SUM('1st Qtr'!D142, '2nd Qtr'!D142, '3rd Qtr'!D142, '4th Qtr'!D142) -> 1996108 | E142: =SUM('1st Qtr'!E142, '2nd Qtr'!E142, '3rd Qtr'!E142, '4th Qtr'!E142) -> 3366819.1 | F142: =IF(AND(ISNUMBER(D142),ISNUMBER(E142)), D142-E142, "") -> -1370711.1 | G142: =IFERROR(F142/E142, "") -> -0.40712348 | H142: =SUM('1st Qtr'!H142+'2nd Qtr'!H142+'3rd Qtr'!H142+'4th Qtr'!H142) -> 3688372 | I142: =SUM('1st Qtr'!I142, '2nd Qtr'!I142, '3rd Qtr'!I142, '4th Qtr'!I142) -> -915105 | K142: =IFERROR(AVERAGE(Jan!K142, Feb!K142, Mar!K142, Apr!K142, May!K142, Jun!K142, Jul!K142, Aug!K142, Sep!K142, Oct!K142, Nov!K142, Dec!K142),"") -> 0.62107122
A143: Genesee | B143: NY | C143: =Sites[[#This Row],[SOL'#]] -> SOL-10951 | D143: =SUM('1st Qtr'!D143, '2nd Qtr'!D143, '3rd Qtr'!D143, '4th Qtr'!D143) -> 3457864.9 | E143: =SUM('1st Qtr'!E143, '2nd Qtr'!E143, '3rd Qtr'!E143, '4th Qtr'!E143) -> 0 | F143: =IF(AND(ISNUMBER(D143),ISNUMBER(E143)), D143-E143, "") -> 3457864.9 | G143: =IFERROR(F143/E143, "") | H143: =SUM('1st Qtr'!H143+'2nd Qtr'!H143+'3rd Qtr'!H143+'4th Qtr'!H143) -> 2677368 | I143: =SUM('1st Qtr'!I143, '2nd Qtr'!I143, '3rd Qtr'!I143, '4th Qtr'!I143) -> 780496.9 | K143: =IFERROR(AVERAGE(Jan!K143, Feb!K143, Mar!K143, Apr!K143, May!K143, Jun!K143, Jul!K143, Aug!K143, Sep!K143, Oct!K143, Nov!K143, Dec!K143),"")
A144: Landau I | B144: NY | C144: =Sites[[#This Row],[SOL'#]] -> SOL-10891 | D144: =SUM('1st Qtr'!D144, '2nd Qtr'!D144, '3rd Qtr'!D144, '4th Qtr'!D144) -> 1343756 | E144: =SUM('1st Qtr'!E144, '2nd Qtr'!E144, '3rd Qtr'!E144, '4th Qtr'!E144) -> 0 | F144: =IF(AND(ISNUMBER(D144),ISNUMBER(E144)), D144-E144, "") -> 1343756 | G144: =IFERROR(F144/E144, "") | H144: =SUM('1st Qtr'!H144+'2nd Qtr'!H144+'3rd Qtr'!H144+'4th Qtr'!H144) -> 1214601 | I144: =SUM('1st Qtr'!I144, '2nd Qtr'!I144, '3rd Qtr'!I144, '4th Qtr'!I144) -> 129155 | K144: =IFERROR(AVERAGE(Jan!K144, Feb!K144, Mar!K144, Apr!K144, May!K144, Jun!K144, Jul!K144, Aug!K144, Sep!K144, Oct!K144, Nov!K144, Dec!K144),"")
A145: Landau II | B145: NY | C145: =Sites[[#This Row],[SOL'#]] -> SOL-10895 | D145: =SUM('1st Qtr'!D145, '2nd Qtr'!D145, '3rd Qtr'!D145, '4th Qtr'!D145) -> 1148070 | E145: =SUM('1st Qtr'!E145, '2nd Qtr'!E145, '3rd Qtr'!E145, '4th Qtr'!E145) -> 0 | F145: =IF(AND(ISNUMBER(D145),ISNUMBER(E145)), D145-E145, "") -> 1148070 | G145: =IFERROR(F145/E145, "") | H145: =SUM('1st Qtr'!H145+'2nd Qtr'!H145+'3rd Qtr'!H145+'4th Qtr'!H145) -> 2553284 | I145: =SUM('1st Qtr'!I145, '2nd Qtr'!I145, '3rd Qtr'!I145, '4th Qtr'!I145) -> -1405214 | K145: =IFERROR(AVERAGE(Jan!K145, Feb!K145, Mar!K145, Apr!K145, May!K145, Jun!K145, Jul!K145, Aug!K145, Sep!K145, Oct!K145, Nov!K145, Dec!K145),"")
A146: New Beginnings | B146: NY | C146: =Sites[[#This Row],[SOL'#]] -> SOL-10890 | D146: =SUM('1st Qtr'!D146, '2nd Qtr'!D146, '3rd Qtr'!D146, '4th Qtr'!D146) -> 1366080 | E146: =SUM('1st Qtr'!E146, '2nd Qtr'!E146, '3rd Qtr'!E146, '4th Qtr'!E146) -> 1419126.4 | F146: =IF(AND(ISNUMBER(D146),ISNUMBER(E146)), D146-E146, "") -> -53046.37 | G146: =IFERROR(F146/E146, "") -> -0.037379596 | H146: =SUM('1st Qtr'!H146+'2nd Qtr'!H146+'3rd Qtr'!H146+'4th Qtr'!H146) -> 1567327 | I146: =SUM('1st Qtr'!I146, '2nd Qtr'!I146, '3rd Qtr'!I146, '4th Qtr'!I146) -> -194180.21 | K146: =IFERROR(AVERAGE(Jan!K146, Feb!K146, Mar!K146, Apr!K146, May!K146, Jun!K146, Jul!K146, Aug!K146, Sep!K146, Oct!K146, Nov!K146, Dec!K146),"")
A147: Guilin Farm Solar | B147: NY | C147: =Sites[[#This Row],[SOL'#]] -> SOL-10998 | D147: =SUM('1st Qtr'!D147, '2nd Qtr'!D147, '3rd Qtr'!D147, '4th Qtr'!D147) -> 3832471 | E147: =SUM('1st Qtr'!E147, '2nd Qtr'!E147, '3rd Qtr'!E147, '4th Qtr'!E147) -> 3956414 | F147: =IF(AND(ISNUMBER(D147),ISNUMBER(E147)), D147-E147, "") -> -123943 | G147: =IFERROR(F147/E147, "") -> -0.031327106 | H147: =SUM('1st Qtr'!H147+'2nd Qtr'!H147+'3rd Qtr'!H147+'4th Qtr'!H147) -> 4351974.9 | I147: =SUM('1st Qtr'!I147, '2nd Qtr'!I147, '3rd Qtr'!I147, '4th Qtr'!I147) -> -519503.9 | K147: =IFERROR(AVERAGE(Jan!K147, Feb!K147, Mar!K147, Apr!K147, May!K147, Jun!K147, Jul!K147, Aug!K147, Sep!K147, Oct!K147, Nov!K147, Dec!K147),"")
A148: Brodhead Solar | B148: NY | C148: =Sites[[#This Row],[SOL'#]] -> SOL-10899 | D148: =SUM('1st Qtr'!D148, '2nd Qtr'!D148, '3rd Qtr'!D148, '4th Qtr'!D148) -> 1831518 | E148: =SUM('1st Qtr'!E148, '2nd Qtr'!E148, '3rd Qtr'!E148, '4th Qtr'!E148) -> 1928514.5 | F148: =IF(AND(ISNUMBER(D148),ISNUMBER(E148)), D148-E148, "") -> -96996.5 | G148: =IFERROR(F148/E148, "") -> -0.050295966 | H148: =SUM('1st Qtr'!H148+'2nd Qtr'!H148+'3rd Qtr'!H148+'4th Qtr'!H148) -> 1971095.9 | I148: =SUM('1st Qtr'!I148, '2nd Qtr'!I148, '3rd Qtr'!I148, '4th Qtr'!I148) -> -139577.9 | K148: =IFERROR(AVERAGE(Jan!K148, Feb!K148, Mar!K148, Apr!K148, May!K148, Jun!K148, Jul!K148, Aug!K148, Sep!K148, Oct!K148, Nov!K148, Dec!K148),"")
A149: Svenski | B149: NY | C149: =Sites[[#This Row],[SOL'#]] -> SOL-10894 | D149: =SUM('1st Qtr'!D149, '2nd Qtr'!D149, '3rd Qtr'!D149, '4th Qtr'!D149) -> 1330592 | E149: =SUM('1st Qtr'!E149, '2nd Qtr'!E149, '3rd Qtr'!E149, '4th Qtr'!E149) -> 0 | F149: =IF(AND(ISNUMBER(D149),ISNUMBER(E149)), D149-E149, "") -> 1330592 | G149: =IFERROR(F149/E149, "") | H149: =SUM('1st Qtr'!H149+'2nd Qtr'!H149+'3rd Qtr'!H149+'4th Qtr'!H149) -> 1225802 | I149: =SUM('1st Qtr'!I149, '2nd Qtr'!I149, '3rd Qtr'!I149, '4th Qtr'!I149) -> 104790 | K149: =IFERROR(AVERAGE(Jan!K149, Feb!K149, Mar!K149, Apr!K149, May!K149, Jun!K149, Jul!K149, Aug!K149, Sep!K149, Oct!K149, Nov!K149, Dec!K149),"")
A150: Bantam | B150: NY | C150: =Sites[[#This Row],[SOL'#]] -> SOL-10986 | D150: =SUM('1st Qtr'!D150, '2nd Qtr'!D150, '3rd Qtr'!D150, '4th Qtr'!D150) -> 3406880 | E150: =SUM('1st Qtr'!E150, '2nd Qtr'!E150, '3rd Qtr'!E150, '4th Qtr'!E150) -> 0 | F150: =IF(AND(ISNUMBER(D150),ISNUMBER(E150)), D150-E150, "") -> 3406880 | G150: =IFERROR(F150/E150, "") | H150: =SUM('1st Qtr'!H150+'2nd Qtr'!H150+'3rd Qtr'!H150+'4th Qtr'!H150) -> 3409269 | I150: =SUM('1st Qtr'!I150, '2nd Qtr'!I150, '3rd Qtr'!I150, '4th Qtr'!I150) -> -2389 | K150: =IFERROR(AVERAGE(Jan!K150, Feb!K150, Mar!K150, Apr!K150, May!K150, Jun!K150, Jul!K150, Aug!K150, Sep!K150, Oct!K150, Nov!K150, Dec!K150),"")
A151: Bogart | B151: NY | C151: =Sites[[#This Row],[SOL'#]] -> SOL-10887 | D151: =SUM('1st Qtr'!D151, '2nd Qtr'!D151, '3rd Qtr'!D151, '4th Qtr'!D151) -> 1131450 | E151: =SUM('1st Qtr'!E151, '2nd Qtr'!E151, '3rd Qtr'!E151, '4th Qtr'!E151) -> 1478092.9 | F151: =IF(AND(ISNUMBER(D151),ISNUMBER(E151)), D151-E151, "") -> -346642.85 | G151: =IFERROR(F151/E151, "") -> -0.23452035 | H151: =SUM('1st Qtr'!H151+'2nd Qtr'!H151+'3rd Qtr'!H151+'4th Qtr'!H151) -> 1540873 | I151: =SUM('1st Qtr'!I151, '2nd Qtr'!I151, '3rd Qtr'!I151, '4th Qtr'!I151) -> -409423 | K151: =IFERROR(AVERAGE(Jan!K151, Feb!K151, Mar!K151, Apr!K151, May!K151, Jun!K151, Jul!K151, Aug!K151, Sep!K151, Oct!K151, Nov!K151, Dec!K151),"")
A152: Dubois | B152: NY | C152: =Sites[[#This Row],[SOL'#]] -> SOL-10892 | D152: =SUM('1st Qtr'!D152, '2nd Qtr'!D152, '3rd Qtr'!D152, '4th Qtr'!D152) -> 1424205 | E152: =SUM('1st Qtr'!E152, '2nd Qtr'!E152, '3rd Qtr'!E152, '4th Qtr'!E152) -> 0 | F152: =IF(AND(ISNUMBER(D152),ISNUMBER(E152)), D152-E152, "") -> 1424205 | G152: =IFERROR(F152/E152, "") | H152: =SUM('1st Qtr'!H152+'2nd Qtr'!H152+'3rd Qtr'!H152+'4th Qtr'!H152) -> 848352 | I152: =SUM('1st Qtr'!I152, '2nd Qtr'!I152, '3rd Qtr'!I152, '4th Qtr'!I152) -> 235198 | K152: =IFERROR(AVERAGE(Jan!K152, Feb!K152, Mar!K152, Apr!K152, May!K152, Jun!K152, Jul!K152, Aug!K152, Sep!K152, Oct!K152, Nov!K152, Dec!K152),"")
... A160: Drinkwater | B160: NY | C160: =Sites[[#This Row],[SOL'#]] -> SOL-10896 | D160: =SUM('1st Qtr'!D160, '2nd Qtr'!D160, '3rd Qtr'!D160, '4th Qtr'!D160) -> 1641661 | E160: =SUM('1st Qtr'!E160, '2nd Qtr'!E160, '3rd Qtr'!E160, '4th Qtr'!E160) -> 0 | F160: =IF(AND(ISNUMBER(D160),ISNUMBER(E160)), D160-E160, "") -> 1641661 | G160: =IFERROR(F160/E160, "") | H160: =SUM('1st Qtr'!H160+'2nd Qtr'!H160+'3rd Qtr'!H160+'4th Qtr'!H160) -> 1245202 | I160: =SUM('1st Qtr'!I160, '2nd Qtr'!I160, '3rd Qtr'!I160, '4th Qtr'!I160) -> 396459 | K160: =IFERROR(AVERAGE(Jan!K160, Feb!K160, Mar!K160, Apr!K160, May!K160, Jun!K160, Jul!K160, Aug!K160, Sep!K160, Oct!K160, Nov!K160, Dec!K160),"")
A161: Altamont | B161: NY | C161: SOL-11085 | D161: =SUM('1st Qtr'!D161, '2nd Qtr'!D161, '3rd Qtr'!D161, '4th Qtr'!D161) -> 3647157 | E161: =SUM('1st Qtr'!E161, '2nd Qtr'!E161, '3rd Qtr'!E161, '4th Qtr'!E161) -> 3978255 | F161: =IF(AND(ISNUMBER(D161),ISNUMBER(E161)), D161-E161, "") -> -331098.02 | G161: =IFERROR(F161/E161, "") -> -0.083226947 | H161: =SUM('1st Qtr'!H161+'2nd Qtr'!H161+'3rd Qtr'!H161+'4th Qtr'!H161) -> 4036770.1 | I161: =SUM('1st Qtr'!I161, '2nd Qtr'!I161, '3rd Qtr'!I161, '4th Qtr'!I161) -> -52988.7 | K161: =IFERROR(AVERAGE(Jan!K161, Feb!K161, Mar!K161, Apr!K161, May!K161, Jun!K161, Jul!K161, Aug!K161, Sep!K161, Oct!K161, Nov!K161, Dec!K161),"") -> 0.59117325

Sheet 1st Qtr
A1: {=portfolio} -> Generate Capital | E1: 1st Quarter Actual v. Expected | H1: 1st Quarter Actual v. Forecasted | K1: Q1 Availability
A2: Total | D2: =SUM(D4:D138) -> 43033145 | E2: =SUM(E4:E138) -> 17967144 | F2: =D2-E2 -> 25066001 | G2: =IFERROR(F2/E2, 0) -> 1.3951022 | H2: =SUM(H4:H138) -> 43989265 | I2: =D2-H2 -> -956119.74 | J2: =IFERROR(I2/H2, 0) -> -0.021735297
A3: Site | B3: State | C3: SOL# | D3: Actual | E3: Expected | F3: Delta | G3: % | H3: Forecasted | I3: Delta | J3: % | K3: Site Availability
A4: {=Sites[Site]} -> Farmer | B4: {=Sites[State]} -> AZ | C4: =Sites[[#This Row],[SOL'#]] -> SOL-10748 | D4: =SUM(Jan!D4, Feb!D4, Mar!D4) -> 32706.188 | E4: =SUM(Jan!E4, Feb!E4, Mar!E4) -> 0 | F4: =IF(AND(ISNUMBER(D4),ISNUMBER(E4)), D4-E4, "") -> 32706.188 | G4: =IFERROR(F4/E4, "") | H4: =SUM(Jan!H4, Feb!H4, Mar!H4) -> 31200.866 | I4: =SUM(Jan!I4, Feb!I4, Mar!I4) -> 1505.3216 | J4: =IFERROR(I4/H4, "") -> 0.048246149 | K4: =IFERROR(AVERAGE(Jan!K4, Feb!K4, Mar!K4),"") -> 1
A5: Fulton | B5: AZ | C5: =Sites[[#This Row],[SOL'#]] -> SOL-10749 | D5: =SUM(Jan!D5, Feb!D5, Mar!D5) -> 107842 | E5: =SUM(Jan!E5, Feb!E5, Mar!E5) -> 0 | F5: =IF(AND(ISNUMBER(D5),ISNUMBER(E5)), D5-E5, "") -> 107842 | G5: =IFERROR(F5/E5, "") | H5: =SUM(Jan!H5, Feb!H5, Mar!H5) -> 130168.14 | I5: =SUM(Jan!I5, Feb!I5, Mar!I5) -> -22326.14 | J5: =IFERROR(I5/H5, "") -> -0.1715177 | K5: =IFERROR(AVERAGE(Jan!K5, Feb!K5, Mar!K5),"") -> 1
A6: JFK Elementary | B6: AZ | C6: =Sites[[#This Row],[SOL'#]] -> SOL-10758 | D6: =SUM(Jan!D6, Feb!D6, Mar!D6) -> -1179066.6 | E6: =SUM(Jan!E6, Feb!E6, Mar!E6) -> 0 | F6: =IF(AND(ISNUMBER(D6),ISNUMBER(E6)), D6-E6, "") -> -1179066.6 | G6: =IFERROR(F6/E6, "") | H6: =SUM(Jan!H6, Feb!H6, Mar!H6) -> 48788 | I6: =SUM(Jan!I6, Feb!I6, Mar!I6) -> -1227854.6 | J6: =IFERROR(I6/H6, "") -> -25.167143 | K6: =IFERROR(AVERAGE(Jan!K6, Feb!K6, Mar!K6),"") -> 1
A7: Noble | B7: AZ | C7: =Sites[[#This Row],[SOL'#]] -> SOL-10750 | D7: =SUM(Jan!D7, Feb!D7, Mar!D7) -> 31148.188 | E7: =SUM(Jan!E7, Feb!E7, Mar!E7) -> 0 | F7: =IF(AND(ISNUMBER(D7),ISNUMBER(E7)), D7-E7, "") -> 31148.188 | G7: =IFERROR(F7/E7, "") | H7: =SUM(Jan!H7, Feb!H7, Mar!H7) -> 34362.62 | I7: =SUM(Jan!I7, Feb!I7, Mar!I7) -> -3214.4318 | J7: =IFERROR(I7/H7, "") -> -0.093544434 | K7: =IFERROR(AVERAGE(Jan!K7, Feb!K7, Mar!K7),"") -> 1
A8: Parking 3 | B8: AZ | C8: =Sites[[#This Row],[SOL'#]] -> SOL-10751 | D8: =SUM(Jan!D8, Feb!D8, Mar!D8) -> 72830.711 | E8: =SUM(Jan!E8, Feb!E8, Mar!E8) -> 0 | F8: =IF(AND(ISNUMBER(D8),ISNUMBER(E8)), D8-E8, "") -> 72830.711 | G8: =IFERROR(F8/E8, "") | H8: =SUM(Jan!H8, Feb!H8, Mar!H8) -> 75774.7 | I8: =SUM(Jan!I8, Feb!I8, Mar!I8) -> -2943.989 | J8: =IFERROR(I8/H8, "") -> -0.038851873 | K8: =IFERROR(AVERAGE(Jan!K8, Feb!K8, Mar!K8),"") -> 1
A9: PE East | B9: AZ | C9: =Sites[[#This Row],[SOL'#]] -> SOL-10752 | D9: =SUM(Jan!D9, Feb!D9, Mar!D9) -> 74341.755 | E9: =SUM(Jan!E9, Feb!E9, Mar!E9) -> 0 | F9: =IF(AND(ISNUMBER(D9),ISNUMBER(E9)), D9-E9, "") -> 74341.755 | G9: =IFERROR(F9/E9, "") | H9: =SUM(Jan!H9, Feb!H9, Mar!H9) -> 75686.65 | I9: =SUM(Jan!I9, Feb!I9, Mar!I9) -> -1344.8953 | J9: =IFERROR(I9/H9, "") -> -0.017769254 | K9: =IFERROR(AVERAGE(Jan!K9, Feb!K9, Mar!K9),"") -> 1
A10: Schwada | B10: AZ | C10: =Sites[[#This Row],[SOL'#]] -> SOL-10753 | D10: =SUM(Jan!D10, Feb!D10, Mar!D10) -> 32098.435 | E10: =SUM(Jan!E10, Feb!E10, Mar!E10) -> 0 | F10: =IF(AND(ISNUMBER(D10),ISNUMBER(E10)), D10-E10, "") -> 32098.435 | G10: =IFERROR(F10/E10, "") | H10: =SUM(Jan!H10, Feb!H10, Mar!H10) -> 32349 | I10: =SUM(Jan!I10, Feb!I10, Mar!I10) -> -250.56529 | J10: =IFERROR(I10/H10, "") -> -0.0077456889 | K10: =IFERROR(AVERAGE(Jan!K10, Feb!K10, Mar!K10),"") -> 1
A11: Starshine | B11: AZ | C11: =Sites[[#This Row],[SOL'#]] -> SOL-10757 | D11: =SUM(Jan!D11, Feb!D11, Mar!D11) -> 14150.6 | E11: =SUM(Jan!E11, Feb!E11, Mar!E11) -> 0 | F11: =IF(AND(ISNUMBER(D11),ISNUMBER(E11)), D11-E11, "") -> 14150.6 | G11: =IFERROR(F11/E11, "") | H11: =SUM(Jan!H11, Feb!H11, Mar!H11) -> 19968 | I11: =SUM(Jan!I11, Feb!I11, Mar!I11) -> -5817.4004 | J11: =IFERROR(I11/H11, "") -> -0.29133616 | K11: =IFERROR(AVERAGE(Jan!K11, Feb!K11, Mar!K11),"") -> 1
A12: Yuma Airport | B12: AZ | C12: =Sites[[#This Row],[SOL'#]] -> SOL-10754 | D12: =SUM(Jan!D12, Feb!D12, Mar!D12) -> 197991 | E12: =SUM(Jan!E12, Feb!E12, Mar!E12) -> 251330.95 | F12: =IF(AND(ISNUMBER(D12),ISNUMBER(E12)), D12-E12, "") -> -53339.95 | G12: =IFERROR(F12/E12, "") -> -0.21222993 | H12: =SUM(Jan!H12, Feb!H12, Mar!H12) -> 206622 | I12: =SUM(Jan!I12, Feb!I12, Mar!I12) -> -8631 | J12: =IFERROR(I12/H12, "") -> -0.041771931 | K12: =IFERROR(AVERAGE(Jan!K12, Feb!K12, Mar!K12),"") -> 1
A13: Kinsman | B13: OH | C13: =Sites[[#This Row],[SOL'#]] -> SOL-10762 | D13: =SUM(Jan!D13, Feb!D13, Mar!D13) -> 192798.97 | E13: =SUM(Jan!E13, Feb!E13, Mar!E13) -> 215347.16 | F13: =IF(AND(ISNUMBER(D13),ISNUMBER(E13)), D13-E13, "") -> -22548.191 | G13: =IFERROR(F13/E13, "") -> -0.10470624 | H13: =SUM(Jan!H13, Feb!H13, Mar!H13) -> 205726 | I13: =SUM(Jan!I13, Feb!I13, Mar!I13) -> -12927.031 | J13: =IFERROR(I13/H13, "") -> -0.062836157 | K13: =IFERROR(AVERAGE(Jan!K13, Feb!K13, Mar!K13),"") -> 0.95440437
A14: Wooster | B14: OH | C14: =Sites[[#This Row],[SOL'#]] -> SOL-10763 | D14: =SUM(Jan!D14, Feb!D14, Mar!D14) -> 41860.5 | E14: =SUM(Jan!E14, Feb!E14, Mar!E14) -> 0 | F14: =IF(AND(ISNUMBER(D14),ISNUMBER(E14)), D14-E14, "") -> 41860.5 | G14: =IFERROR(F14/E14, "") | H14: =SUM(Jan!H14, Feb!H14, Mar!H14) -> 46251 | I14: =SUM(Jan!I14, Feb!I14, Mar!I14) -> -4390.5 | J14: =IFERROR(I14/H14, "") -> -0.094927677 | K14: =IFERROR(AVERAGE(Jan!K14, Feb!K14, Mar!K14),"") -> 1
A15: Globe Gila CC | B15: AZ | C15: =Sites[[#This Row],[SOL'#]] -> SOL-10755 | D15: =SUM(Jan!D15, Feb!D15, Mar!D15) -> 37604.585 | E15: =SUM(Jan!E15, Feb!E15, Mar!E15) -> 24701.2 | F15: =IF(AND(ISNUMBER(D15),ISNUMBER(E15)), D15-E15, "") -> 12903.385 | G15: =IFERROR(F15/E15, "") -> 0.52237887 | H15: =SUM(Jan!H15, Feb!H15, Mar!H15) -> 37905 | I15: =SUM(Jan!I15, Feb!I15, Mar!I15) -> -300.41497 | J15: =IFERROR(I15/H15, "") -> -0.0079254709 | K15: =IFERROR(AVERAGE(Jan!K15, Feb!K15, Mar!K15),"") -> 0.99973773
A16: Payson Gila CC | B16: AZ | C16: =Sites[[#This Row],[SOL'#]] -> SOL-10756 | D16: =SUM(Jan!D16, Feb!D16, Mar!D16) -> 25234.584 | E16: =SUM(Jan!E16, Feb!E16, Mar!E16) -> 0 | F16: =IF(AND(ISNUMBER(D16),ISNUMBER(E16)), D16-E16, "") -> 25234.584 | G16: =IFERROR(F16/E16, "") | H16: =SUM(Jan!H16, Feb!H16, Mar!H16) -> 29085 | I16: =SUM(Jan!I16, Feb!I16, Mar!I16) -> -3850.4157 | J16: =IFERROR(I16/H16, "") -> -0.13238493 | K16: =IFERROR(AVERAGE(Jan!K16, Feb!K16, Mar!K16),"") -> 1
... A62: QMOA | B62: NY | C62: =Sites[[#This Row],[SOL'#]] -> SOL-10415 | D62: =SUM(Jan!D62, Feb!D62, Mar!D62) -> 9674.6 | E62: =SUM(Jan!E62, Feb!E62, Mar!E62) -> 0 | F62: =IF(AND(ISNUMBER(D62),ISNUMBER(E62)), D62-E62, "") -> 9674.6 | G62: =IFERROR(F62/E62, "") | H62: =SUM(Jan!H62, Feb!H62, Mar!H62) -> 11837.222 | I62: =SUM(Jan!I62, Feb!I62, Mar!I62) -> -2162.622 | J62: =IFERROR(I62/H62, "") -> -0.18269675 | K62: =IFERROR(AVERAGE(Jan!K62, Feb!K62, Mar!K62),"") -> 0.972999
A63: X024 | B63: NY | C63: =Sites[[#This Row],[SOL'#]] -> SOL-10419 | D63: =SUM(Jan!D63, Feb!D63, Mar!D63) -> 38634.912 | E63: =SUM(Jan!E63, Feb!E63, Mar!E63) -> 51601.59 | F63: =IF(AND(ISNUMBER(D63),ISNUMBER(E63)), D63-E63, "") -> -12966.677 | G63: =IFERROR(F63/E63, "") -> -0.25128446 | H63: =SUM(Jan!H63, Feb!H63, Mar!H63) -> 38352 | I63: =SUM(Jan!I63, Feb!I63, Mar!I63) -> 282.9125 | J63: =IFERROR(I63/H63, "") -> 0.0073767339 | K63: =IFERROR(AVERAGE(Jan!K63, Feb!K63, Mar!K63),"") -> 0.9278809 | O63: IF(COUNTA(Jan!K64, Feb!K64, Mar!K64)," ",SUM(Jan!K64, Feb!K64, Mar!K64))/3
A64: X026 | B64: NY | C64: =Sites[[#This Row],[SOL'#]] -> SOL-10420 | D64: =SUM(Jan!D64, Feb!D64, Mar!D64) -> 30231.2 | E64: =SUM(Jan!E64, Feb!E64, Mar!E64) -> 41023.51 | F64: =IF(AND(ISNUMBER(D64),ISNUMBER(E64)), D64-E64, "") -> -10792.31 | G64: =IFERROR(F64/E64, "") -> -0.26307622 | H64: =SUM(Jan!H64, Feb!H64, Mar!H64) -> 53576.53 | I64: =SUM(Jan!I64, Feb!I64, Mar!I64) -> -23345.33 | J64: =IFERROR(I64/H64, "") -> -0.435738 | K64: =IFERROR(AVERAGE(Jan!K64, Feb!K64, Mar!K64),"") | O64: =IF(COUNTA(Jan!K64, Feb!K64, Mar!K64)," ",SUM(Jan!K64, Feb!K64, Mar!K64))/3 -> 0
A65: X090 | B65: NY | C65: =Sites[[#This Row],[SOL'#]] -> SOL-10925 | D65: =SUM(Jan!D65, Feb!D65, Mar!D65) -> 30633.648 | E65: =SUM(Jan!E65, Feb!E65, Mar!E65) -> 27558.474 | F65: =IF(AND(ISNUMBER(D65),ISNUMBER(E65)), D65-E65, "") -> 3075.1744 | G65: =IFERROR(F65/E65, "") -> 0.11158725 | H65: =SUM(Jan!H65, Feb!H65, Mar!H65) -> 35328 | I65: =SUM(Jan!I65, Feb!I65, Mar!I65) -> -4694.3516 | J65: =IFERROR(I65/H65, "") -> -0.13287906 | K65: =IFERROR(AVERAGE(Jan!K65, Feb!K65, Mar!K65),"")
A66: X117 | B66: NY | C66: =Sites[[#This Row],[SOL'#]] -> SOL-10422 | D66: =SUM(Jan!D66, Feb!D66, Mar!D66) -> 23648.8 | E66: =SUM(Jan!E66, Feb!E66, Mar!E66) -> 35151.579 | F66: =IF(AND(ISNUMBER(D66),ISNUMBER(E66)), D66-E66, "") -> -11502.779 | G66: =IFERROR(F66/E66, "") -> -0.32723364 | H66: =SUM(Jan!H66, Feb!H66, Mar!H66) -> 59162.86 | I66: =SUM(Jan!I66, Feb!I66, Mar!I66) -> -35514.06 | J66: =IFERROR(I66/H66, "") -> -0.60027625 | K66: =IFERROR(AVERAGE(Jan!K66, Feb!K66, Mar!K66),"")
A67: X125 | B67: NY | C67: =Sites[[#This Row],[SOL'#]] -> SOL-10423 | D67: =SUM(Jan!D67, Feb!D67, Mar!D67) -> 47490.219 | E67: =SUM(Jan!E67, Feb!E67, Mar!E67) -> 60381.86 | F67: =IF(AND(ISNUMBER(D67),ISNUMBER(E67)), D67-E67, "") -> -12891.641 | G67: =IFERROR(F67/E67, "") -> -0.21350189 | H67: =SUM(Jan!H67, Feb!H67, Mar!H67) -> 43137.52 | I67: =SUM(Jan!I67, Feb!I67, Mar!I67) -> 4352.6987 | J67: =IFERROR(I67/H67, "") -> 0.10090285 | K67: =IFERROR(AVERAGE(Jan!K67, Feb!K67, Mar!K67),"")
A68: X134 | B68: NY | C68: =Sites[[#This Row],[SOL'#]] -> SOL-10424 | D68: =SUM(Jan!D68, Feb!D68, Mar!D68) -> 44627.344 | E68: =SUM(Jan!E68, Feb!E68, Mar!E68) -> 0 | F68: =IF(AND(ISNUMBER(D68),ISNUMBER(E68)), D68-E68, "") -> 44627.344 | G68: =IFERROR(F68/E68, "") | H68: =SUM(Jan!H68, Feb!H68, Mar!H68) -> 0 | I68: =SUM(Jan!I68, Feb!I68, Mar!I68) -> 44627.344 | J68: =IFERROR(I68/H68, "") | K68: =IFERROR(AVERAGE(Jan!K68, Feb!K68, Mar!K68),"")
A69: X135 | B69: NY | C69: =Sites[[#This Row],[SOL'#]] -> SOL-10425 | D69: =SUM(Jan!D69, Feb!D69, Mar!D69) -> 35026.578 | E69: =SUM(Jan!E69, Feb!E69, Mar!E69) -> 0 | F69: =IF(AND(ISNUMBER(D69),ISNUMBER(E69)), D69-E69, "") -> 35026.578 | G69: =IFERROR(F69/E69, "") | H69: =SUM(Jan!H69, Feb!H69, Mar!H69) -> 0 | I69: =SUM(Jan!I69, Feb!I69, Mar!I69) -> 35026.578 | J69: =IFERROR(I69/H69, "") | K69: =IFERROR(AVERAGE(Jan!K69, Feb!K69, Mar!K69),"")
A70: X139 JHS 222 | B70: NY | C70: =Sites[[#This Row],[SOL'#]] -> SOL-10426 | D70: =SUM(Jan!D70, Feb!D70, Mar!D70) -> 57659.3 | E70: =SUM(Jan!E70, Feb!E70, Mar!E70) -> 67980.32 | F70: =IF(AND(ISNUMBER(D70),ISNUMBER(E70)), D70-E70, "") -> -10321.02 | G70: =IFERROR(F70/E70, "") -> -0.15182365 | H70: =SUM(Jan!H70, Feb!H70, Mar!H70) -> 60317 | I70: =SUM(Jan!I70, Feb!I70, Mar!I70) -> -2657.7002 | J70: =IFERROR(I70/H70, "") -> -0.044062208 | K70: =IFERROR(AVERAGE(Jan!K70, Feb!K70, Mar!K70),"") -> 0.99797803
A71: X140 | B71: NY | C71: =Sites[[#This Row],[SOL'#]] -> SOL-10926 | D71: =SUM(Jan!D71, Feb!D71, Mar!D71) -> 31019.895 | E71: =SUM(Jan!E71, Feb!E71, Mar!E71) -> 30916.939 | F71: =IF(AND(ISNUMBER(D71),ISNUMBER(E71)), D71-E71, "") -> 102.95578 | G71: =IFERROR(F71/E71, "") -> 0.0033300766 | H71: =SUM(Jan!H71, Feb!H71, Mar!H71) -> 36808.678 | I71: =SUM(Jan!I71, Feb!I71, Mar!I71) -> -5788.7832 | J71: =IFERROR(I71/H71, "") -> -0.15726681 | K71: =IFERROR(AVERAGE(Jan!K71, Feb!K71, Mar!K71),"") -> 0
A72: X166 | B72: NY | C72: =Sites[[#This Row],[SOL'#]] -> SOL-10427 | D72: =SUM(Jan!D72, Feb!D72, Mar!D72) -> 34206 | E72: =SUM(Jan!E72, Feb!E72, Mar!E72) -> 40811.386 | F72: =IF(AND(ISNUMBER(D72),ISNUMBER(E72)), D72-E72, "") -> -6605.386 | G72: =IFERROR(F72/E72, "") -> -0.16185155 | H72: =SUM(Jan!H72, Feb!H72, Mar!H72) -> 0 | I72: =SUM(Jan!I72, Feb!I72, Mar!I72) -> 34206 | J72: =IFERROR(I72/H72, "") | K72: =IFERROR(AVERAGE(Jan!K72, Feb!K72, Mar!K72),"")
A73: Murphy | B73: MN | C73: =Sites[[#This Row],[SOL'#]] -> SOL-10094 | D73: =SUM(Jan!D73, Feb!D73, Mar!D73) -> 1633280 | E73: =SUM(Jan!E73, Feb!E73, Mar!E73) -> 1972653.5 | F73: =IF(AND(ISNUMBER(D73),ISNUMBER(E73)), D73-E73, "") -> -339373.5 | G73: =IFERROR(F73/E73, "") -> -0.17203908 | H73: =SUM(Jan!H73, Feb!H73, Mar!H73) -> 2001538.9 | I73: =SUM(Jan!I73, Feb!I73, Mar!I73) -> -368258.9 | J73: =IFERROR(I73/H73, "") -> -0.18398788 | K73: =IFERROR(AVERAGE(Jan!K73, Feb!K73, Mar!K73),"") -> 0.95532627
A74: Terning | B74: MN | C74: =Sites[[#This Row],[SOL'#]] -> SOL-10093 | D74: =SUM(Jan!D74, Feb!D74, Mar!D74) -> 1735581.9 | E74: =SUM(Jan!E74, Feb!E74, Mar!E74) -> 2080164.3 | F74: =IF(AND(ISNUMBER(D74),ISNUMBER(E74)), D74-E74, "") -> -344582.42 | G74: =IFERROR(F74/E74, "") -> -0.16565154 | H74: =SUM(Jan!H74, Feb!H74, Mar!H74) -> 1899129.7 | I74: =SUM(Jan!I74, Feb!I74, Mar!I74) -> -163547.82 | J74: =IFERROR(I74/H74, "") -> -0.086117244 | K74: =IFERROR(AVERAGE(Jan!K74, Feb!K74, Mar!K74),"") -> 0.98567737
A75: Boas Road 04 | B75: NY | C75: =Sites[[#This Row],[SOL'#]] -> SOL-10908 | D75: =SUM(Jan!D75, Feb!D75, Mar!D75) -> 526966 | E75: =SUM(Jan!E75, Feb!E75, Mar!E75) -> 584293.79 | F75: =IF(AND(ISNUMBER(D75),ISNUMBER(E75)), D75-E75, "") -> -57327.79 | G75: =IFERROR(F75/E75, "") -> -0.098114666 | H75: =SUM(Jan!H75, Feb!H75, Mar!H75) -> 681203.91 | I75: =SUM(Jan!I75, Feb!I75, Mar!I75) -> -154237.91 | J75: =IFERROR(I75/H75, "") -> -0.22641959 | K75: =IFERROR(AVERAGE(Jan!K75, Feb!K75, Mar!K75),"") -> 0.94646667
A76: Kelly Bridge Farm | B76: NY | C76: =Sites[[#This Row],[SOL'#]] -> SOL-10911 | D76: =SUM(Jan!D76, Feb!D76, Mar!D76) -> 610490 | E76: =SUM(Jan!E76, Feb!E76, Mar!E76) -> 575148.26 | F76: =IF(AND(ISNUMBER(D76),ISNUMBER(E76)), D76-E76, "") -> 35341.74 | G76: =IFERROR(F76/E76, "") -> 0.061448052 | H76: =SUM(Jan!H76, Feb!H76, Mar!H76) -> 663561.21 | I76: =SUM(Jan!I76, Feb!I76, Mar!I76) -> -53071.21 | J76: =IFERROR(I76/H76, "") -> -0.079979374 | K76: =IFERROR(AVERAGE(Jan!K76, Feb!K76, Mar!K76),"") -> 0.9675
... A160: Drinkwater | B160: NY | C160: =Sites[[#This Row],[SOL'#]] -> SOL-10896 | D160: =SUM(Jan!D160, Feb!D160, Mar!D160) -> 0 | E160: =SUM(Jan!E160, Feb!E160, Mar!E160) -> 0 | F160: =IF(AND(ISNUMBER(D160),ISNUMBER(E160)), D160-E160, "") -> 0 | G160: =IFERROR(F160/E160, "") | H160: =SUM(Jan!H160, Feb!H160, Mar!H160) -> 0 | I160: =SUM(Jan!I160, Feb!I160, Mar!I160) -> 0 | J160: =IFERROR(I160/H160, "") | K160: =IFERROR(AVERAGE(Jan!K160, Feb!K160, Mar!K160),"")
A161: Altamont | B161: NY | C161: SOL-11085 | D161: =SUM(Jan!D161, Feb!D161, Mar!D161) -> 0 | E161: =SUM(Jan!E161, Feb!E161, Mar!E161) -> 0 | F161: =IF(AND(ISNUMBER(D161),ISNUMBER(E161)), D161-E161, "") -> 0 | G161: =IFERROR(F161/E161, "") | H161: =SUM(Jan!H161, Feb!H161, Mar!H161) -> 0 | I161: =SUM(Jan!I161, Feb!I161, Mar!I161) -> 0 | J161: =IFERROR(I161/H161, "") | K161: =IFERROR(AVERAGE(Jan!K161, Feb!K161, Mar!K161),"") -> 0

Sheet 2nd Qtr
A1: {=portfolio} -> Generate Capital | E1: 2nd Quarter Actual v. Expected | H1: 2nd Quarter Actual v. Forecasted | K1: Q2 Availability
A2: Total | D2: =SUM(D4:D100) -> 50973996 | E2: =SUM(E4:E100) -> 23156312 | F2: =D2-E2 -> 27817684 | G2: =IFERROR(F2/E2, 0) -> 1.2013003 | H2: =SUM(H4:H100) -> 46730431 | I2: =D2-H2 -> 4243564.8 | J2: =IFERROR(I2/H2, 0) -> 0.09080945
A3: Site | B3: State | C3: SOL# | D3: Actual | E3: Expected | F3: Delta | G3: % | H3: Forecasted | I3: Delta | J3: % | K3: Site Availability
A4: {=Sites[Site]} -> Farmer | B4: {=Sites[State]} -> AZ | C4: =Sites[[#This Row],[SOL'#]] -> SOL-10748 | D4: =SUM(Apr!D4, May!D4, Jun!D4) -> 43015.561 | E4: =SUM(Apr!E4, May!E4, Jun!E4) -> 4619.663 | F4: =IF(AND(ISNUMBER(D4),ISNUMBER(E4)), D4-E4, "") -> 38395.898 | G4: =IFERROR(F4/E4, "") -> 8.3114067 | H4: =SUM(Apr!H4, May!H4, Jun!H4) -> 40656.85 | I4: =SUM(Apr!I4, May!I4, Jun!I4) -> 2358.7112 | J4: =IFERROR(I4/H4, "") -> 0.058015098 | K4: =IFERROR(AVERAGE(Apr!K4,May!K4,Jun!K4),"") -> 1
A5: Fulton | B5: AZ | C5: =Sites[[#This Row],[SOL'#]] -> SOL-10749 | D5: =SUM(Apr!D5, May!D5, Jun!D5) -> 195784.25 | E5: =SUM(Apr!E5, May!E5, Jun!E5) -> 32871.56 | F5: =IF(AND(ISNUMBER(D5),ISNUMBER(E5)), D5-E5, "") -> 162912.69 | G5: =IFERROR(F5/E5, "") -> 4.9560377 | H5: =SUM(Apr!H5, May!H5, Jun!H5) -> 221317.44 | I5: =SUM(Apr!I5, May!I5, Jun!I5) -> -25533.19 | J5: =IFERROR(I5/H5, "") -> -0.11536908 | K5: =IFERROR(AVERAGE(Apr!K5,May!K5,Jun!K5),"") -> 1
A6: JFK Elementary | B6: AZ | C6: =Sites[[#This Row],[SOL'#]] -> SOL-10758 | D6: =SUM(Apr!D6, May!D6, Jun!D6) -> 66638.204 | E6: =SUM(Apr!E6, May!E6, Jun!E6) -> 0 | F6: =IF(AND(ISNUMBER(D6),ISNUMBER(E6)), D6-E6, "") -> 66638.204 | G6: =IFERROR(F6/E6, "") | H6: =SUM(Apr!H6, May!H6, Jun!H6) -> 58079 | I6: =SUM(Apr!I6, May!I6, Jun!I6) -> 8559.2036 | J6: =IFERROR(I6/H6, "") -> 0.14737175 | K6: =IFERROR(AVERAGE(Apr!K6,May!K6,Jun!K6),"") -> 0.83333333
A7: Noble | B7: AZ | C7: =Sites[[#This Row],[SOL'#]] -> SOL-10750 | D7: =SUM(Apr!D7, May!D7, Jun!D7) -> 28784.061 | E7: =SUM(Apr!E7, May!E7, Jun!E7) -> 7863.594 | F7: =IF(AND(ISNUMBER(D7),ISNUMBER(E7)), D7-E7, "") -> 20920.467 | G7: =IFERROR(F7/E7, "") -> 2.6604206 | H7: =SUM(Apr!H7, May!H7, Jun!H7) -> 45648.84 | I7: =SUM(Apr!I7, May!I7, Jun!I7) -> -16864.779 | J7: =IFERROR(I7/H7, "") -> -0.36944594 | K7: =IFERROR(AVERAGE(Apr!K7,May!K7,Jun!K7),"") -> 0.99183673
A8: Parking 3 | B8: AZ | C8: =Sites[[#This Row],[SOL'#]] -> SOL-10751 | D8: =SUM(Apr!D8, May!D8, Jun!D8) -> 91309.238 | E8: =SUM(Apr!E8, May!E8, Jun!E8) -> 19878.29 | F8: =IF(AND(ISNUMBER(D8),ISNUMBER(E8)), D8-E8, "") -> 71430.948 | G8: =IFERROR(F8/E8, "") -> 3.5934151 | H8: =SUM(Apr!H8, May!H8, Jun!H8) -> 98753.6 | I8: =SUM(Apr!I8, May!I8, Jun!I8) -> -7444.3622 | J8: =IFERROR(I8/H8, "") -> -0.075383198 | K8: =IFERROR(AVERAGE(Apr!K8,May!K8,Jun!K8),"") -> 0.9
A9: PE East | B9: AZ | C9: =Sites[[#This Row],[SOL'#]] -> SOL-10752 | D9: =SUM(Apr!D9, May!D9, Jun!D9) -> 97023.621 | E9: =SUM(Apr!E9, May!E9, Jun!E9) -> 13998.62 | F9: =IF(AND(ISNUMBER(D9),ISNUMBER(E9)), D9-E9, "") -> 83025.001 | G9: =IFERROR(F9/E9, "") -> 5.9309418 | H9: =SUM(Apr!H9, May!H9, Jun!H9) -> 98159.94 | I9: =SUM(Apr!I9, May!I9, Jun!I9) -> -1136.3192 | J9: =IFERROR(I9/H9, "") -> -0.011576201 | K9: =IFERROR(AVERAGE(Apr!K9,May!K9,Jun!K9),"") -> 0.99767327
A10: Schwada | B10: AZ | C10: =Sites[[#This Row],[SOL'#]] -> SOL-10753 | D10: =SUM(Apr!D10, May!D10, Jun!D10) -> 43708.489 | E10: =SUM(Apr!E10, May!E10, Jun!E10) -> 5763.341 | F10: =IF(AND(ISNUMBER(D10),ISNUMBER(E10)), D10-E10, "") -> 37945.148 | G10: =IFERROR(F10/E10, "") -> 6.5838804 | H10: =SUM(Apr!H10, May!H10, Jun!H10) -> 42109 | I10: =SUM(Apr!I10, May!I10, Jun!I10) -> 1599.4891 | J10: =IFERROR(I10/H10, "") -> 0.037984496 | K10: =IFERROR(AVERAGE(Apr!K10,May!K10,Jun!K10),"") -> 1
A11: Starshine | B11: AZ | C11: =Sites[[#This Row],[SOL'#]] -> SOL-10757 | D11: =SUM(Apr!D11, May!D11, Jun!D11) -> -988879.3 | E11: =SUM(Apr!E11, May!E11, Jun!E11) -> 0 | F11: =IF(AND(ISNUMBER(D11),ISNUMBER(E11)), D11-E11, "") -> -988879.3 | G11: =IFERROR(F11/E11, "") | H11: =SUM(Apr!H11, May!H11, Jun!H11) -> 35234 | I11: =SUM(Apr!I11, May!I11, Jun!I11) -> -1024113.3 | J11: =IFERROR(I11/H11, "") -> -29.066053 | K11: =IFERROR(AVERAGE(Apr!K11,May!K11,Jun!K11),"") -> 0.77739987
A12: Yuma Airport | B12: AZ | C12: =Sites[[#This Row],[SOL'#]] -> SOL-10754 | D12: =SUM(Apr!D12, May!D12, Jun!D12) -> 252815 | E12: =SUM(Apr!E12, May!E12, Jun!E12) -> 295661.99 | F12: =IF(AND(ISNUMBER(D12),ISNUMBER(E12)), D12-E12, "") -> -42846.99 | G12: =IFERROR(F12/E12, "") -> -0.14491883 | H12: =SUM(Apr!H12, May!H12, Jun!H12) -> 252289 | I12: =SUM(Apr!I12, May!I12, Jun!I12) -> 526 | J12: =IFERROR(I12/H12, "") -> 0.0020849106 | K12: =IFERROR(AVERAGE(Apr!K12,May!K12,Jun!K12),"") -> 1
A13: Kinsman | B13: OH | C13: =Sites[[#This Row],[SOL'#]] -> SOL-10762 | D13: =SUM(Apr!D13, May!D13, Jun!D13) -> 309245.97 | E13: =SUM(Apr!E13, May!E13, Jun!E13) -> 379438.3 | F13: =IF(AND(ISNUMBER(D13),ISNUMBER(E13)), D13-E13, "") -> -70192.331 | G13: =IFERROR(F13/E13, "") -> -0.18499011 | H13: =SUM(Apr!H13, May!H13, Jun!H13) -> 372182 | I13: =SUM(Apr!I13, May!I13, Jun!I13) -> -62936.031 | J13: =IFERROR(I13/H13, "") -> -0.16910015 | K13: =IFERROR(AVERAGE(Apr!K13,May!K13,Jun!K13),"") -> 1
A14: Wooster | B14: OH | C14: =Sites[[#This Row],[SOL'#]] -> SOL-10763 | D14: =SUM(Apr!D14, May!D14, Jun!D14) -> 67831.5 | E14: =SUM(Apr!E14, May!E14, Jun!E14) -> 0 | F14: =IF(AND(ISNUMBER(D14),ISNUMBER(E14)), D14-E14, "") -> 67831.5 | G14: =IFERROR(F14/E14, "") | H14: =SUM(Apr!H14, May!H14, Jun!H14) -> 89122 | I14: =SUM(Apr!I14, May!I14, Jun!I14) -> -21290.5 | J14: =IFERROR(I14/H14, "") -> -0.23889163 | K14: =IFERROR(AVERAGE(Apr!K14,May!K14,Jun!K14),"") -> 1
A15: Globe Gila CC | B15: AZ | C15: =Sites[[#This Row],[SOL'#]] -> SOL-10755 | D15: =SUM(Apr!D15, May!D15, Jun!D15) -> -1455820.2 | E15: =SUM(Apr!E15, May!E15, Jun!E15) -> 23760.252 | F15: =IF(AND(ISNUMBER(D15),ISNUMBER(E15)), D15-E15, "") -> -1479580.4 | G15: =IFERROR(F15/E15, "") -> -62.271243 | H15: =SUM(Apr!H15, May!H15, Jun!H15) -> 60212 | I15: =SUM(Apr!I15, May!I15, Jun!I15) -> -1516032.2 | J15: =IFERROR(I15/H15, "") -> -25.17824 | K15: =IFERROR(AVERAGE(Apr!K15,May!K15,Jun!K15),"") -> 1
A16: Payson Gila CC | B16: AZ | C16: =Sites[[#This Row],[SOL'#]] -> SOL-10756 | D16: =SUM(Apr!D16, May!D16, Jun!D16) -> 41672.571 | E16: =SUM(Apr!E16, May!E16, Jun!E16) -> 3463.349 | F16: =IF(AND(ISNUMBER(D16),ISNUMBER(E16)), D16-E16, "") -> 38209.222 | G16: =IFERROR(F16/E16, "") -> 11.032449 | H16: =SUM(Apr!H16, May!H16, Jun!H16) -> 46661 | I16: =SUM(Apr!I16, May!I16, Jun!I16) -> -4988.4286 | J16: =IFERROR(I16/H16, "") -> -0.10690788 | K16: =IFERROR(AVERAGE(Apr!K16,May!K16,Jun!K16),"") -> 1
... A160: Drinkwater | B160: NY | C160: =Sites[[#This Row],[SOL'#]] -> SOL-10896 | D160: =SUM(Apr!D160, May!D160, Jun!D160) -> 410647 | E160: =SUM(Apr!E160, May!E160, Jun!E160) -> 0 | F160: =IF(AND(ISNUMBER(D160),ISNUMBER(E160)), D160-E160, "") -> 410647 | G160: =IFERROR(F160/E160, "") | H160: =SUM(Apr!H160, May!H160, Jun!H160) -> 0 | I160: =SUM(Apr!I160, May!I160, Jun!I160) -> 410647 | J160: =IFERROR(I160/H160, "") | K160: =IFERROR(AVERAGE(Apr!K160,May!K160,Jun!K160),"")
A161: Altamont | B161: NY | C161: SOL-11085 | D161: =SUM(Apr!D161, May!D161, Jun!D161) -> 892354 | E161: =SUM(Apr!E161, May!E161, Jun!E161) -> 1062738.2 | F161: =IF(AND(ISNUMBER(D161),ISNUMBER(E161)), D161-E161, "") -> -170384.22 | G161: =IFERROR(F161/E161, "") -> -0.16032567 | H161: =SUM(Apr!H161, May!H161, Jun!H161) -> 1593579.8 | I161: =SUM(Apr!I161, May!I161, Jun!I161) -> 0 | J161: =IFERROR(I161/H161, "") -> 0 | K161: =IFERROR(AVERAGE(Apr!K161,May!K161,Jun!K161),"") -> 0.6417296

Sheet 3rd Qtr
A1: {=portfolio} -> Generate Capital | E1: 3rd Quarter Actual v. Expected | H1: 3rd Quarter Actual v. Forecasted | K1: Q3 Availability
A2: Total | D2: =SUM(D4:D100) -> 53836025 | E2: =SUM(E4:E100) -> 21762903 | F2: =D2-E2 -> 32073122 | G2: =IFERROR(F2/E2, 0) -> 1.473752 | H2: =SUM(H4:H100) -> 59267580 | I2: =D2-H2 -> -5431555.3 | J2: =IFERROR(I2/H2, 0) -> -0.091644628
A3: Site | B3: State | C3: SOL# | D3: Actual | E3: Expected | F3: Delta | G3: % | H3: Forecasted | I3: Delta | J3: % | K3: Site Availability
A4: {=Sites[Site]} -> Farmer | B4: {=Sites[State]} -> AZ | C4: =Sites[[#This Row],[SOL'#]] -> SOL-10748 | D4: =SUM(Jul!D4, Aug!D4, Sep!D4) -> 41095.12 | E4: =SUM(Jul!E4, Aug!E4, Sep!E4) -> 24870.055 | F4: =IF(AND(ISNUMBER(D4),ISNUMBER(E4)), D4-E4, "") -> 16225.065 | G4: =IFERROR(F4/E4, "") -> 0.65239361 | H4: =SUM(Jul!H4,Aug!H4,Sep!H4) -> 39065.49 | I4: =SUM(Jul!I4, Aug!I4, Sep!I4) -> 2029.6301 | J4: =IFERROR(I4/H4, "") -> 0.051954553 | K4: =IFERROR(AVERAGE(Jul!K4, Aug!K4, Sep!K4),"") -> 0.998708
A5: Fulton | B5: AZ | C5: =Sites[[#This Row],[SOL'#]] -> SOL-10749 | D5: =SUM(Jul!D5, Aug!D5, Sep!D5) -> 159935.75 | E5: =SUM(Jul!E5, Aug!E5, Sep!E5) -> 164812.4 | F5: =IF(AND(ISNUMBER(D5),ISNUMBER(E5)), D5-E5, "") -> -4876.65 | G5: =IFERROR(F5/E5, "") -> -0.029589096 | H5: =SUM(Jul!H5,Aug!H5,Sep!H5) -> 194976.14 | I5: =SUM(Jul!I5, Aug!I5, Sep!I5) -> -35040.39 | J5: =IFERROR(I5/H5, "") -> -0.1797163 | K5: =IFERROR(AVERAGE(Jul!K5, Aug!K5, Sep!K5),"") -> 1
A6: JFK Elementary | B6: AZ | C6: =Sites[[#This Row],[SOL'#]] -> SOL-10758 | D6: =SUM(Jul!D6, Aug!D6, Sep!D6) -> 62748.989 | E6: =SUM(Jul!E6, Aug!E6, Sep!E6) -> 0 | F6: =IF(AND(ISNUMBER(D6),ISNUMBER(E6)), D6-E6, "") -> 62748.989 | G6: =IFERROR(F6/E6, "") | H6: =SUM(Jul!H6,Aug!H6,Sep!H6) -> 56143 | I6: =SUM(Jul!I6, Aug!I6, Sep!I6) -> 6605.9891 | J6: =IFERROR(I6/H6, "") -> 0.11766363 | K6: =IFERROR(AVERAGE(Jul!K6, Aug!K6, Sep!K6),"") -> 0.49991257
A7: Noble | B7: AZ | C7: =Sites[[#This Row],[SOL'#]] -> SOL-10750 | D7: =SUM(Jul!D7, Aug!D7, Sep!D7) -> 28010.874 | E7: =SUM(Jul!E7, Aug!E7, Sep!E7) -> 42057.23 | F7: =IF(AND(ISNUMBER(D7),ISNUMBER(E7)), D7-E7, "") -> -14046.356 | G7: =IFERROR(F7/E7, "") -> -0.33398197 | H7: =SUM(Jul!H7,Aug!H7,Sep!H7) -> 44891.67 | I7: =SUM(Jul!I7, Aug!I7, Sep!I7) -> -16880.796 | J7: =IFERROR(I7/H7, "") -> -0.37603405 | K7: =IFERROR(AVERAGE(Jul!K7, Aug!K7, Sep!K7),"") -> 0.89985763
A8: Parking 3 | B8: AZ | C8: =Sites[[#This Row],[SOL'#]] -> SOL-10751 | D8: =SUM(Jul!D8, Aug!D8, Sep!D8) -> 75718.458 | E8: =SUM(Jul!E8, Aug!E8, Sep!E8) -> 95719.27 | F8: =IF(AND(ISNUMBER(D8),ISNUMBER(E8)), D8-E8, "") -> -20000.812 | G8: =IFERROR(F8/E8, "") -> -0.20895283 | H8: =SUM(Jul!H8,Aug!H8,Sep!H8) -> 95629.77 | I8: =SUM(Jul!I8, Aug!I8, Sep!I8) -> -19911.312 | J8: =IFERROR(I8/H8, "") -> -0.20821249 | K8: =IFERROR(AVERAGE(Jul!K8, Aug!K8, Sep!K8),"") -> 0.77521877
A9: PE East | B9: AZ | C9: =Sites[[#This Row],[SOL'#]] -> SOL-10752 | D9: =SUM(Jul!D9, Aug!D9, Sep!D9) -> 89283.253 | E9: =SUM(Jul!E9, Aug!E9, Sep!E9) -> 69083.06 | F9: =IF(AND(ISNUMBER(D9),ISNUMBER(E9)), D9-E9, "") -> 20200.193 | G9: =IFERROR(F9/E9, "") -> 0.29240443 | H9: =SUM(Jul!H9,Aug!H9,Sep!H9) -> 90548.3 | I9: =SUM(Jul!I9, Aug!I9, Sep!I9) -> -1265.047 | J9: =IFERROR(I9/H9, "") -> -0.013970964 | K9: =IFERROR(AVERAGE(Jul!K9, Aug!K9, Sep!K9),"") -> 1
A10: Schwada | B10: AZ | C10: =Sites[[#This Row],[SOL'#]] -> SOL-10753 | D10: =SUM(Jul!D10, Aug!D10, Sep!D10) -> 40493.995 | E10: =SUM(Jul!E10, Aug!E10, Sep!E10) -> 28442.035 | F10: =IF(AND(ISNUMBER(D10),ISNUMBER(E10)), D10-E10, "") -> 12051.96 | G10: =IFERROR(F10/E10, "") -> 0.42373762 | H10: =SUM(Jul!H10,Aug!H10,Sep!H10) -> 40256 | I10: =SUM(Jul!I10, Aug!I10, Sep!I10) -> 237.99536 | J10: =IFERROR(I10/H10, "") -> 0.0059120468 | K10: =IFERROR(AVERAGE(Jul!K10, Aug!K10, Sep!K10),"") -> 1
A11: Starshine | B11: AZ | C11: =Sites[[#This Row],[SOL'#]] -> SOL-10757 | D11: =SUM(Jul!D11, Aug!D11, Sep!D11) -> 27372.207 | E11: =SUM(Jul!E11, Aug!E11, Sep!E11) -> 0 | F11: =IF(AND(ISNUMBER(D11),ISNUMBER(E11)), D11-E11, "") -> 27372.207 | G11: =IFERROR(F11/E11, "") | H11: =SUM(Jul!H11,Aug!H11,Sep!H11) -> 30120 | I11: =SUM(Jul!I11, Aug!I11, Sep!I11) -> -2747.7934 | J11: =IFERROR(I11/H11, "") -> -0.091228201 | K11: =IFERROR(AVERAGE(Jul!K11, Aug!K11, Sep!K11),"") -> 0.32490117
A12: Yuma Airport | B12: AZ | C12: =Sites[[#This Row],[SOL'#]] -> SOL-10754 | D12: =SUM(Jul!D12, Aug!D12, Sep!D12) -> 235675 | E12: =SUM(Jul!E12, Aug!E12, Sep!E12) -> 273384.67 | F12: =IF(AND(ISNUMBER(D12),ISNUMBER(E12)), D12-E12, "") -> -37709.67 | G12: =IFERROR(F12/E12, "") -> -0.1379363 | H12: =SUM(Jul!H12,Aug!H12,Sep!H12) -> 230676 | I12: =SUM(Jul!I12, Aug!I12, Sep!I12) -> 4999 | J12: =IFERROR(I12/H12, "") -> 0.021671088 | K12: =IFERROR(AVERAGE(Jul!K12, Aug!K12, Sep!K12),"") -> 1
A13: Kinsman | B13: OH | C13: =Sites[[#This Row],[SOL'#]] -> SOL-10762 | D13: =SUM(Jul!D13, Aug!D13, Sep!D13) -> 265232.62 | E13: =SUM(Jul!E13, Aug!E13, Sep!E13) -> 383034.7 | F13: =IF(AND(ISNUMBER(D13),ISNUMBER(E13)), D13-E13, "") -> -117802.08 | G13: =IFERROR(F13/E13, "") -> -0.30754936 | H13: =SUM(Jul!H13,Aug!H13,Sep!H13) -> 374505 | I13: =SUM(Jul!I13, Aug!I13, Sep!I13) -> -109272.38 | J13: =IFERROR(I13/H13, "") -> -0.29177815 | K13: =IFERROR(AVERAGE(Jul!K13, Aug!K13, Sep!K13),"") -> 1
A14: Wooster | B14: OH | C14: =Sites[[#This Row],[SOL'#]] -> SOL-10763 | D14: =SUM(Jul!D14, Aug!D14, Sep!D14) -> 60024 | E14: =SUM(Jul!E14, Aug!E14, Sep!E14) -> 0 | F14: =IF(AND(ISNUMBER(D14),ISNUMBER(E14)), D14-E14, "") -> 60024 | G14: =IFERROR(F14/E14, "") | H14: =SUM(Jul!H14,Aug!H14,Sep!H14) -> 87418 | I14: =SUM(Jul!I14, Aug!I14, Sep!I14) -> -27394 | J14: =IFERROR(I14/H14, "") -> -0.31336796 | K14: =IFERROR(AVERAGE(Jul!K14, Aug!K14, Sep!K14),"") -> 1
A15: Globe Gila CC | B15: AZ | C15: =Sites[[#This Row],[SOL'#]] -> SOL-10755 | D15: =SUM(Jul!D15, Aug!D15, Sep!D15) -> 48062.895 | E15: =SUM(Jul!E15, Aug!E15, Sep!E15) -> 0 | F15: =IF(AND(ISNUMBER(D15),ISNUMBER(E15)), D15-E15, "") -> 48062.895 | G15: =IFERROR(F15/E15, "") | H15: =SUM(Jul!H15,Aug!H15,Sep!H15) -> 53157 | I15: =SUM(Jul!I15, Aug!I15, Sep!I15) -> -5094.1046 | J15: =IFERROR(I15/H15, "") -> -0.095831303 | K15: =IFERROR(AVERAGE(Jul!K15, Aug!K15, Sep!K15),"") -> 1
A16: Payson Gila CC | B16: AZ | C16: =Sites[[#This Row],[SOL'#]] -> SOL-10756 | D16: =SUM(Jul!D16, Aug!D16, Sep!D16) -> 22466.126 | E16: =SUM(Jul!E16, Aug!E16, Sep!E16) -> 17170.503 | F16: =IF(AND(ISNUMBER(D16),ISNUMBER(E16)), D16-E16, "") -> 5295.6229 | G16: =IFERROR(F16/E16, "") -> 0.30841397 | H16: =SUM(Jul!H16,Aug!H16,Sep!H16) -> 41733 | I16: =SUM(Jul!I16, Aug!I16, Sep!I16) -> -19266.874 | J16: =IFERROR(I16/H16, "") -> -0.46167 | K16: =IFERROR(AVERAGE(Jul!K16, Aug!K16, Sep!K16),"") -> 0.99419193
... A160: Drinkwater | B160: NY | C160: =Sites[[#This Row],[SOL'#]] -> SOL-10896 | D160: =SUM(Jul!D160, Aug!D160, Sep!D160) -> 1231014 | E160: =SUM(Jul!E160, Aug!E160, Sep!E160) -> 0 | F160: =IF(AND(ISNUMBER(D160),ISNUMBER(E160)), D160-E160, "") -> 1231014 | G160: =IFERROR(F160/E160, "") | H160: =SUM(Jul!H160,Aug!H160,Sep!H160) -> 1245202 | I160: =SUM(Jul!I160, Aug!I160, Sep!I160) -> -14188 | J160: =IFERROR(I160/H160, "") -> -0.011394135 | K160: =IFERROR(AVERAGE(Jul!K160, Aug!K160, Sep!K160),"")
A161: Altamont | B161: NY | C161: SOL-11085 | D161: =SUM(Jul!D161, Aug!D161, Sep!D161) -> 2058946 | E161: =SUM(Jul!E161, Aug!E161, Sep!E161) -> 2159800.4 | F161: =IF(AND(ISNUMBER(D161),ISNUMBER(E161)), D161-E161, "") -> -100854.4 | G161: =IFERROR(F161/E161, "") -> -0.046696167 | H161: =SUM(Jul!H161,Aug!H161,Sep!H161) -> 2020093.6 | I161: =SUM(Jul!I161, Aug!I161, Sep!I161) -> -52988.7 | J161: =IFERROR(I161/H161, "") -> -0.026230814 | K161: =IFERROR(AVERAGE(Jul!K161, Aug!K161, Sep!K161),"") -> 0.99551457

Sheet 4th Qtr
A1: {=portfolio} -> Generate Capital | E1: 4th Quarter Actual v. Expected | H1: 4th Quarter Actual v. Forecasted | K1: Q4 Availability
A2: Total | D2: =SUM(D4:D100) -> 3619914.1 | E2: =SUM(E4:E100) -> 3732929.8 | F2: =D2-E2 -> -113015.75 | G2: =IFERROR(F2/E2, 0) -> -0.030275349 | H2: =SUM(H4:H100) -> 3268905.7 | I2: =D2-H2 -> 351008.4 | J2: =IFERROR(I2/H2, 0) -> 0.10737795
A3: Site | B3: State | C3: SOL# | D3: Actual | E3: Expected | F3: Delta | G3: % | H3: Forecasted | I3: Delta | J3: % | K3: Site Availability
A4: {=Sites[Site]} -> Farmer | B4: {=Sites[State]} -> AZ | C4: =Sites[[#This Row],[SOL'#]] -> SOL-10748 | D4: =SUM(Oct!D4, Nov!D4, Dec!D4) -> 12351.995 | E4: =SUM(Oct!E4, Nov!E4, Dec!E4) -> 7795.556 | F4: =IF(AND(ISNUMBER(D4),ISNUMBER(E4)), D4-E4, "") -> 4556.4386 | G4: =IFERROR(F4/E4, "") -> 0.5844918 | H4: =SUM(Oct!H4,Nov!H4,Dec!H4) -> 11404.3 | I4: =SUM(Oct!I4, Nov!I4, Dec!I4) -> 947.69455 | J4: =IFERROR(I4/H4, "") -> 0.083099756 | K4: =IFERROR(AVERAGE(Oct!K4, Nov!K4, Dec!K4),"") -> 1
A5: Fulton | B5: AZ | C5: =Sites[[#This Row],[SOL'#]] -> SOL-10749 | D5: =SUM(Oct!D5, Nov!D5, Dec!D5) -> 36511 | E5: =SUM(Oct!E5, Nov!E5, Dec!E5) -> 44132.79 | F5: =IF(AND(ISNUMBER(D5),ISNUMBER(E5)), D5-E5, "") -> -7621.79 | G5: =IFERROR(F5/E5, "") -> -0.1727013 | H5: =SUM(Oct!H5,Nov!H5,Dec!H5) -> 49048.38 | I5: =SUM(Oct!I5, Nov!I5, Dec!I5) -> -12537.38 | J5: =IFERROR(I5/H5, "") -> -0.25561252 | K5: =IFERROR(AVERAGE(Oct!K5, Nov!K5, Dec!K5),"") -> 0.966893
A6: JFK Elementary | B6: AZ | C6: =Sites[[#This Row],[SOL'#]] -> SOL-10758 | D6: =SUM(Oct!D6, Nov!D6, Dec!D6) -> 20557.688 | E6: =SUM(Oct!E6, Nov!E6, Dec!E6) -> 0 | F6: =IF(AND(ISNUMBER(D6),ISNUMBER(E6)), D6-E6, "") -> 20557.688 | G6: =IFERROR(F6/E6, "") | H6: =SUM(Oct!H6,Nov!H6,Dec!H6) -> 17712 | I6: =SUM(Oct!I6, Nov!I6, Dec!I6) -> 2845.6879 | J6: =IFERROR(I6/H6, "") -> 0.1606644 | K6: =IFERROR(AVERAGE(Oct!K6, Nov!K6, Dec!K6),"") -> 0.5
A7: Noble | B7: AZ | C7: =Sites[[#This Row],[SOL'#]] -> SOL-10750 | D7: =SUM(Oct!D7, Nov!D7, Dec!D7) -> 10837.68 | E7: =SUM(Oct!E7, Nov!E7, Dec!E7) -> 13076.94 | F7: =IF(AND(ISNUMBER(D7),ISNUMBER(E7)), D7-E7, "") -> -2239.2595 | G7: =IFERROR(F7/E7, "") -> -0.17123727 | H7: =SUM(Oct!H7,Nov!H7,Dec!H7) -> 12737.2 | I7: =SUM(Oct!I7, Nov!I7, Dec!I7) -> -1899.5195 | J7: =IFERROR(I7/H7, "") -> -0.14913164 | K7: =IFERROR(AVERAGE(Oct!K7, Nov!K7, Dec!K7),"") -> 0.9354839
A8: Parking 3 | B8: AZ | C8: =Sites[[#This Row],[SOL'#]] -> SOL-10751 | D8: =SUM(Oct!D8, Nov!D8, Dec!D8) -> 30411.607 | E8: =SUM(Oct!E8, Nov!E8, Dec!E8) -> 23393.97 | F8: =IF(AND(ISNUMBER(D8),ISNUMBER(E8)), D8-E8, "") -> 7017.637 | G8: =IFERROR(F8/E8, "") -> 0.29997632 | H8: =SUM(Oct!H8,Nov!H8,Dec!H8) -> 26091.55 | I8: =SUM(Oct!I8, Nov!I8, Dec!I8) -> 4320.057 | J8: =IFERROR(I8/H8, "") -> 0.16557303 | K8: =IFERROR(AVERAGE(Oct!K8, Nov!K8, Dec!K8),"") -> 0.9956306
A9: PE East | B9: AZ | C9: =Sites[[#This Row],[SOL'#]] -> SOL-10752 | D9: =SUM(Oct!D9, Nov!D9, Dec!D9) -> 27137.381 | E9: =SUM(Oct!E9, Nov!E9, Dec!E9) -> 17170.78 | F9: =IF(AND(ISNUMBER(D9),ISNUMBER(E9)), D9-E9, "") -> 9966.6012 | G9: =IFERROR(F9/E9, "") -> 0.58043963 | H9: =SUM(Oct!H9,Nov!H9,Dec!H9) -> 27166.91 | I9: =SUM(Oct!I9, Nov!I9, Dec!I9) -> -29.528849 | J9: =IFERROR(I9/H9, "") -> -0.0010869418 | K9: =IFERROR(AVERAGE(Oct!K9, Nov!K9, Dec!K9),"") -> 1
A10: Schwada | B10: AZ | C10: =Sites[[#This Row],[SOL'#]] -> SOL-10753 | D10: =SUM(Oct!D10, Nov!D10, Dec!D10) -> 10499.243 | E10: =SUM(Oct!E10, Nov!E10, Dec!E10) -> 7069.339 | F10: =IF(AND(ISNUMBER(D10),ISNUMBER(E10)), D10-E10, "") -> 3429.904 | G10: =IFERROR(F10/E10, "") -> 0.48518029 | H10: =SUM(Oct!H10,Nov!H10,Dec!H10) -> 11116 | I10: =SUM(Oct!I10, Nov!I10, Dec!I10) -> -616.75704 | J10: =IFERROR(I10/H10, "") -> -0.055483721 | K10: =IFERROR(AVERAGE(Oct!K10, Nov!K10, Dec!K10),"") -> 0.9354839
A11: Starshine | B11: AZ | C11: =Sites[[#This Row],[SOL'#]] -> SOL-10757 | D11: =SUM(Oct!D11, Nov!D11, Dec!D11) -> 7069.2122 | E11: =SUM(Oct!E11, Nov!E11, Dec!E11) -> 0 | F11: =IF(AND(ISNUMBER(D11),ISNUMBER(E11)), D11-E11, "") -> 7069.2122 | G11: =IFERROR(F11/E11, "") | H11: =SUM(Oct!H11,Nov!H11,Dec!H11) -> 8221 | I11: =SUM(Oct!I11, Nov!I11, Dec!I11) -> -1151.7878 | J11: =IFERROR(I11/H11, "") -> -0.14010313 | K11: =IFERROR(AVERAGE(Oct!K11, Nov!K11, Dec!K11),"") -> 0.316516
A12: Yuma Airport | B12: AZ | C12: =Sites[[#This Row],[SOL'#]] -> SOL-10754 | D12: =SUM(Oct!D12, Nov!D12, Dec!D12) -> 62048 | E12: =SUM(Oct!E12, Nov!E12, Dec!E12) -> 89930.77 | F12: =IF(AND(ISNUMBER(D12),ISNUMBER(E12)), D12-E12, "") -> -27882.77 | G12: =IFERROR(F12/E12, "") -> -0.31004705 | H12: =SUM(Oct!H12,Nov!H12,Dec!H12) -> 69476 | I12: =SUM(Oct!I12, Nov!I12, Dec!I12) -> -7428 | J12: =IFERROR(I12/H12, "") -> -0.10691462 | K12: =IFERROR(AVERAGE(Oct!K12, Nov!K12, Dec!K12),"") -> 1
A13: Kinsman | B13: OH | C13: =Sites[[#This Row],[SOL'#]] -> SOL-10762 | D13: =SUM(Oct!D13, Nov!D13, Dec!D13) -> 76897.547 | E13: =SUM(Oct!E13, Nov!E13, Dec!E13) -> 111691.2 | F13: =IF(AND(ISNUMBER(D13),ISNUMBER(E13)), D13-E13, "") -> -34793.653 | G13: =IFERROR(F13/E13, "") -> -0.31151651 | H13: =SUM(Oct!H13,Nov!H13,Dec!H13) -> 87435 | I13: =SUM(Oct!I13, Nov!I13, Dec!I13) -> -10537.453 | J13: =IFERROR(I13/H13, "") -> -0.12051756 | K13: =IFERROR(AVERAGE(Oct!K13, Nov!K13, Dec!K13),"") -> 0.9966044
A14: Wooster | B14: OH | C14: =Sites[[#This Row],[SOL'#]] -> SOL-10763 | D14: =SUM(Oct!D14, Nov!D14, Dec!D14) -> 9074.75 | E14: =SUM(Oct!E14, Nov!E14, Dec!E14) -> 0 | F14: =IF(AND(ISNUMBER(D14),ISNUMBER(E14)), D14-E14, "") -> 9074.75 | G14: =IFERROR(F14/E14, "") | H14: =SUM(Oct!H14,Nov!H14,Dec!H14) -> 19620 | I14: =SUM(Oct!I14, Nov!I14, Dec!I14) -> -10545.25 | J14: =IFERROR(I14/H14, "") -> -0.53747452 | K14: =IFERROR(AVERAGE(Oct!K14, Nov!K14, Dec!K14),"") -> 1
A15: Globe Gila CC | B15: AZ | C15: =Sites[[#This Row],[SOL'#]] -> SOL-10755 | D15: =SUM(Oct!D15, Nov!D15, Dec!D15) -> 11509.275 | E15: =SUM(Oct!E15, Nov!E15, Dec!E15) -> 0 | F15: =IF(AND(ISNUMBER(D15),ISNUMBER(E15)), D15-E15, "") -> 11509.275 | G15: =IFERROR(F15/E15, "") | H15: =SUM(Oct!H15,Nov!H15,Dec!H15) -> 14748 | I15: =SUM(Oct!I15, Nov!I15, Dec!I15) -> -3238.7254 | J15: =IFERROR(I15/H15, "") -> -0.21960438 | K15: =IFERROR(AVERAGE(Oct!K15, Nov!K15, Dec!K15),"") -> 1
A16: Payson Gila CC | B16: AZ | C16: =Sites[[#This Row],[SOL'#]] -> SOL-10756 | D16: =SUM(Oct!D16, Nov!D16, Dec!D16) -> 9544.9763 | E16: =SUM(Oct!E16, Nov!E16, Dec!E16) -> 4480.855 | F16: =IF(AND(ISNUMBER(D16),ISNUMBER(E16)), D16-E16, "") -> 5064.1213 | G16: =IFERROR(F16/E16, "") -> 1.1301685 | H16: =SUM(Oct!H16,Nov!H16,Dec!H16) -> 11244 | I16: =SUM(Oct!I16, Nov!I16, Dec!I16) -> -1699.0237 | J16: =IFERROR(I16/H16, "") -> -0.15110492 | K16: =IFERROR(AVERAGE(Oct!K16, Nov!K16, Dec!K16),"") -> 0.9965126
... A160: Drinkwater | B160: NY | C160: =Sites[[#This Row],[SOL'#]] -> SOL-10896 | D160: =SUM(Oct!D160, Nov!D160, Dec!D160) -> 0 | E160: =SUM(Oct!E160, Nov!E160, Dec!E160) -> 0 | F160: =IF(AND(ISNUMBER(D160),ISNUMBER(E160)), D160-E160, "") -> 0 | G160: =IFERROR(F160/E160, "") | H160: =SUM(Oct!H160,Nov!H160,Dec!H160) -> 0 | I160: =SUM(Oct!I160, Nov!I160, Dec!I160) -> 0 | J160: =IFERROR(I160/H160, "") | K160: =IFERROR(AVERAGE(Oct!K160, Nov!K160, Dec!K160),"")
A161: Altamont | B161: NY | C161: SOL-11085 | D161: =SUM(Oct!D161, Nov!D161, Dec!D161) -> 695857 | E161: =SUM(Oct!E161, Nov!E161, Dec!E161) -> 755716.4 | F161: =IF(AND(ISNUMBER(D161),ISNUMBER(E161)), D161-E161, "") -> -59859.4 | G161: =IFERROR(F161/E161, "") -> -0.079208814 | H161: =SUM(Oct!H161,Nov!H161,Dec!H161) -> 423096.7 | I161: =SUM(Oct!I161, Nov!I161, Dec!I161) -> 0 | J161: =IFERROR(I161/H161, "") -> 0 | K161: =IFERROR(AVERAGE(Oct!K161, Nov!K161, Dec!K161),"") -> 1

Sheet Jan
A1: {=portfolio} -> Generate Capital | E1: January Actual v. Expected | H1: January Actual v. Forecasted | K1: January Availability
