Workbook
Name JanActual: '01-2024'!$C$3:$C$23
Name JanActual2: '01-2024'!#REF!
Name JanExpected: '01-2024'!$D$3:$D$23
Name JanExpectedDelta: '01-2024'!$E$3:$E$23
Name JanExpectedPercent: '01-2024'!$F$3:$F$23
Name JanExpPercent: '01-2024'!$F$3:$F$23
Name JanForecasted: '01-2024'!$G$3:$G$23
Name JanForecastedDelta: '01-2024'!$H$3:$H$23
Name JanForecastedPercent: '01-2024'!$I$3:$I$23
Name portfolio: Sites!$B$1:$B$1

Sheet YTD Total 2023
A1: {=portfolio} -> 38 DN | C1: Year to Date 2024 Actual v. Expected | G1: Year to Date 2024 Forecasted | J1: NOTES | K1: SR
A2: Site | B2: State | C2: Actual | D2: Expected | E2: Delta | F2: % | G2: Forecasted | H2: Delta | I2: %
A3: {=Sites[Site]} -> 6th St. | B3: {=Sites[State]} -> CA | C3: =SUM('1st Quarter 2023'!C3, '2nd Quarter 2023'!C3, '3rd Quarter 2023'!C3, '4th Quarter 2024'!C3) -> 124703.5 | D3: =SUM('1st Quarter 2023'!D3, '2nd Quarter 2023'!D3, '3rd Quarter 2023'!D3, '4th Quarter 2024'!D3) -> 103355.9 | E3: =C3-D3 -> 21347.6 | F3: =IFERROR(E3/D3, 0) -> 0.20654457 | G3: =SUM('1st Quarter 2023'!G3, '2nd Quarter 2023'!G3, '3rd Quarter 2023'!G3, '4th Quarter 2024'!G3) -> 146126.1 | H3: =C3-G3 -> -21422.6 | I3: =IFERROR(H3/G3, 0) -> -0.14660352
A4: Barton Acres | B4: MA | C4: =SUM('1st Quarter 2023'!C4, '2nd Quarter 2023'!C4, '3rd Quarter 2023'!C4, '4th Quarter 2024'!C4) -> 31509 | D4: =SUM('1st Quarter 2023'!D4, '2nd Quarter 2023'!D4, '3rd Quarter 2023'!D4, '4th Quarter 2024'!D4) -> 84215.44 | E4: =C4-D4 -> -52706.44 | F4: =IFERROR(E4/D4, 0) -> -0.62585246 | G4: =SUM('1st Quarter 2023'!G4, '2nd Quarter 2023'!G4, '3rd Quarter 2023'!G4, '4th Quarter 2024'!G4) -> 69453.12 | H4: =C4-G4 -> -37944.12 | I4: =IFERROR(H4/G4, 0) -> -0.54632708
A5: Bowden | B5: MA | C5: =SUM('1st Quarter 2023'!C5, '2nd Quarter 2023'!C5, '3rd Quarter 2023'!C5, '4th Quarter 2024'!C5) -> 69313 | D5: =SUM('1st Quarter 2023'!D5, '2nd Quarter 2023'!D5, '3rd Quarter 2023'!D5, '4th Quarter 2024'!D5) -> 124922.7 | E5: =C5-D5 -> -55609.7 | F5: =IFERROR(E5/D5, 0) -> -0.44515288 | G5: =SUM('1st Quarter 2023'!G5, '2nd Quarter 2023'!G5, '3rd Quarter 2023'!G5, '4th Quarter 2024'!G5) -> 167677.4 | H5: =C5-G5 -> -98364.4 | I5: =IFERROR(H5/G5, 0) -> -0.58662885
A6: Blair Wire Village | B6: MA | C6: =SUM('1st Quarter 2023'!C6, '2nd Quarter 2023'!C6, '3rd Quarter 2023'!C6, '4th Quarter 2024'!C6) -> 38474 | D6: =SUM('1st Quarter 2023'!D6, '2nd Quarter 2023'!D6, '3rd Quarter 2023'!D6, '4th Quarter 2024'!D6) -> 97645.68 | E6: =C6-D6 -> -59171.68 | F6: =IFERROR(E6/D6, 0) -> -0.60598359 | G6: =SUM('1st Quarter 2023'!G6, '2nd Quarter 2023'!G6, '3rd Quarter 2023'!G6, '4th Quarter 2024'!G6) -> 83112.14 | H6: =C6-G6 -> -44638.14 | I6: =IFERROR(H6/G6, 0) -> -0.53708327
A7: Boutilier | B7: MA | C7: =SUM('1st Quarter 2023'!C7, '2nd Quarter 2023'!C7, '3rd Quarter 2023'!C7, '4th Quarter 2024'!C7) -> 104475 | D7: =SUM('1st Quarter 2023'!D7, '2nd Quarter 2023'!D7, '3rd Quarter 2023'!D7, '4th Quarter 2024'!D7) -> 117645.2 | E7: =C7-D7 -> -13170.2 | F7: =IFERROR(E7/D7, 0) -> -0.11194847 | G7: =SUM('1st Quarter 2023'!G7, '2nd Quarter 2023'!G7, '3rd Quarter 2023'!G7, '4th Quarter 2024'!G7) -> 190658.8 | H7: =C7-G7 -> -86183.8 | I7: =IFERROR(H7/G7, 0) -> -0.45203159
A8: Cherry Valley | B8: MA | C8: =SUM('1st Quarter 2023'!C8, '2nd Quarter 2023'!C16, '3rd Quarter 2023'!C8, '4th Quarter 2024'!C8) -> 33861 | D8: =SUM('1st Quarter 2023'!D8, '2nd Quarter 2023'!D16, '3rd Quarter 2023'!D8, '4th Quarter 2024'!D8) -> 93717.02 | E8: =C8-D8 -> -59856.02 | F8: =IFERROR(E8/D8, 0) -> -0.6386889 | G8: =SUM('1st Quarter 2023'!G8, '2nd Quarter 2023'!G16, '3rd Quarter 2023'!G8, '4th Quarter 2024'!G8) -> 77483 | H8: =C8-G8 -> -43622 | I8: =IFERROR(H8/G8, 0) -> -0.56298801
A9: Cohasse | B9: MA | C9: =SUM('1st Quarter 2023'!C9, '2nd Quarter 2023'!C17, '3rd Quarter 2023'!C17, '4th Quarter 2024'!C9) -> 37057 | D9: =SUM('1st Quarter 2023'!D9, '2nd Quarter 2023'!D17, '3rd Quarter 2023'!D17, '4th Quarter 2024'!D9) -> 86836.54 | E9: =C9-D9 -> -49779.54 | F9: =IFERROR(E9/D9, 0) -> -0.57325568 | G9: =SUM('1st Quarter 2023'!G9, '2nd Quarter 2023'!G17, '3rd Quarter 2023'!G17, '4th Quarter 2024'!G9) -> 114180.6 | H9: =C9-G9 -> -77123.6 | I9: =IFERROR(H9/G9, 0) -> -0.67545275
A10: ISM Dighton Solar 2 | B10: MA | C10: =SUM('1st Quarter 2023'!C10, '2nd Quarter 2023'!C18, '3rd Quarter 2023'!C18, '4th Quarter 2024'!C10) -> 123864 | D10: =SUM('1st Quarter 2023'!D10, '2nd Quarter 2023'!D18, '3rd Quarter 2023'!D18, '4th Quarter 2024'!D10) -> 178054.9 | E10: =C10-D10 -> -54190.9 | F10: =IFERROR(E10/D10, 0) -> -0.30434939 | G10: =SUM('1st Quarter 2023'!G10, '2nd Quarter 2023'!G18, '3rd Quarter 2023'!G18, '4th Quarter 2024'!G10) -> 195853.9 | H10: =C10-G10 -> -71989.9 | I10: =IFERROR(H10/G10, 0) -> -0.3675694
A11: Dudley River 1 | B11: MA | C11: =SUM('1st Quarter 2023'!C11, '2nd Quarter 2023'!C19, '3rd Quarter 2023'!C19, '4th Quarter 2024'!C19) -> 43519 | D11: =SUM('1st Quarter 2023'!D11, '2nd Quarter 2023'!D19, '3rd Quarter 2023'!D19, '4th Quarter 2024'!D19) -> 68762.9 | E11: =C11-D11 -> -25243.9 | F11: =IFERROR(E11/D11, 0) -> -0.36711512 | G11: =SUM('1st Quarter 2023'!G11, '2nd Quarter 2023'!G19, '3rd Quarter 2023'!G19, '4th Quarter 2024'!G19) -> 83762.23 | H11: =C11-G11 -> -40243.23 | I11: =IFERROR(H11/G11, 0) -> -0.48044602
A12: Dudley River 2 | B12: MA | C12: =SUM('1st Quarter 2023'!C12, '2nd Quarter 2023'!C20, '3rd Quarter 2023'!C20, '4th Quarter 2024'!C20) -> 44123 | D12: =SUM('1st Quarter 2023'!D12, '2nd Quarter 2023'!D20, '3rd Quarter 2023'!D20, '4th Quarter 2024'!D20) -> 70139.57 | E12: =C12-D12 -> -26016.57 | F12: =IFERROR(E12/D12, 0) -> -0.37092571 | G12: =SUM('1st Quarter 2023'!G12, '2nd Quarter 2023'!G20, '3rd Quarter 2023'!G20, '4th Quarter 2024'!G20) -> 81919.43 | H12: =C12-G12 -> -37796.43 | I12: =IFERROR(H12/G12, 0) -> -0.46138541
A13: Dudley River 3 | B13: MA | C13: =SUM('1st Quarter 2023'!C13, '2nd Quarter 2023'!C21, '3rd Quarter 2023'!C21, '4th Quarter 2024'!C21) -> 47297 | D13: =SUM('1st Quarter 2023'!D13, '2nd Quarter 2023'!D21, '3rd Quarter 2023'!D21, '4th Quarter 2024'!D21) -> 71573.83 | E13: =C13-D13 -> -24276.83 | F13: =IFERROR(E13/D13, 0) -> -0.33918584 | G13: =SUM('1st Quarter 2023'!G13, '2nd Quarter 2023'!G21, '3rd Quarter 2023'!G21, '4th Quarter 2024'!G21) -> 84149.19 | H13: =C13-G13 -> -36852.19 | I13: =IFERROR(H13/G13, 0) -> -0.43793874
A14: Flint Pond | B14: MA | C14: =SUM('1st Quarter 2023'!C14, '2nd Quarter 2023'!C22, '3rd Quarter 2023'!C22, '4th Quarter 2024'!C22) -> 16497.5 | D14: =SUM('1st Quarter 2023'!D14, '2nd Quarter 2023'!D22, '3rd Quarter 2023'!D22, '4th Quarter 2024'!D22) -> 40276 | E14: =C14-D14 -> -23778.5 | F14: =IFERROR(E14/D14, 0) -> -0.59038882 | G14: =SUM('1st Quarter 2023'!G14, '2nd Quarter 2023'!G22, '3rd Quarter 2023'!G22, '4th Quarter 2024'!G22) -> 33543.68 | H14: =C14-G14 -> -17046.18 | I14: =IFERROR(H14/G14, 0) -> -0.50817859
A15: Incom | B15: MA | C15: =SUM('1st Quarter 2023'!C15, '2nd Quarter 2023'!C23, '3rd Quarter 2023'!C23, '4th Quarter 2024'!C23) -> 83086 | D15: =SUM('1st Quarter 2023'!D15, '2nd Quarter 2023'!D23, '3rd Quarter 2023'!D23, '4th Quarter 2024'!D23) -> 159872.4 | E15: =C15-D15 -> -76786.4 | F15: =IFERROR(E15/D15, 0) -> -0.48029804 | G15: =SUM('1st Quarter 2023'!G15, '2nd Quarter 2023'!G23, '3rd Quarter 2023'!G23, '4th Quarter 2024'!G23) -> 220156.9 | H15: =C15-G15 -> -137070.9 | I15: =IFERROR(H15/G15, 0) -> -0.62260551
A16: JH | B16: MA | C16: =SUM('1st Quarter 2023'!C16, '2nd Quarter 2023'!C24, '3rd Quarter 2023'!C24, '4th Quarter 2024'!C24) -> 32274 | D16: =SUM('1st Quarter 2023'!D16, '2nd Quarter 2023'!D24, '3rd Quarter 2023'!D24, '4th Quarter 2024'!D24) -> 86355.93 | E16: =C16-D16 -> -54081.93 | F16: =IFERROR(E16/D16, 0) -> -0.6262677 | G16: =SUM('1st Quarter 2023'!G16, '2nd Quarter 2023'!G24, '3rd Quarter 2023'!G24, '4th Quarter 2024'!G24) -> 106218.7 | H16: =C16-G16 -> -73944.7 | I16: =IFERROR(H16/G16, 0) -> -0.6961552
A17: Ledeaux | B17: MA | C17: =SUM('1st Quarter 2023'!C17, '2nd Quarter 2023'!C25, '3rd Quarter 2023'!C25, '4th Quarter 2024'!C25) -> 28537 | D17: =SUM('1st Quarter 2023'!D17, '2nd Quarter 2023'!D25, '3rd Quarter 2023'!D25, '4th Quarter 2024'!D25) -> 58671.27 | E17: =C17-D17 -> -30134.27 | F17: =IFERROR(E17/D17, 0) -> -0.51361203 | G17: =SUM('1st Quarter 2023'!G17, '2nd Quarter 2023'!G25, '3rd Quarter 2023'!G25, '4th Quarter 2024'!G25) -> 98769.99 | H17: =C17-G17 -> -70232.99 | I17: =IFERROR(H17/G17, 0) -> -0.71107621
A18: Palombo A | B18: MA | C18: =SUM('1st Quarter 2023'!C18, '2nd Quarter 2023'!C26, '3rd Quarter 2023'!C26, '4th Quarter 2024'!C26) -> 79689.003 | D18: =SUM('1st Quarter 2023'!D18, '2nd Quarter 2023'!D26, '3rd Quarter 2023'!D26, '4th Quarter 2024'!D26) -> 187942.8 | E18: =C18-D18 -> -108253.8 | F18: =IFERROR(E18/D18, 0) -> -0.57599332 | G18: =SUM('1st Quarter 2023'!G18, '2nd Quarter 2023'!G26, '3rd Quarter 2023'!G26, '4th Quarter 2024'!G26) -> 250093 | H18: =C18-G18 -> -170404 | I18: =IFERROR(H18/G18, 0) -> -0.68136252
A19: Palombo B | B19: MA | C19: =SUM('1st Quarter 2023'!C19, '2nd Quarter 2023'!C27, '3rd Quarter 2023'!C27, '4th Quarter 2024'!C27) -> 32703 | D19: =SUM('1st Quarter 2023'!D19, '2nd Quarter 2023'!D27, '3rd Quarter 2023'!D27, '4th Quarter 2024'!D27) -> 91961.55 | E19: =C19-D19 -> -59258.55 | F19: =IFERROR(E19/D19, 0) -> -0.64438398 | G19: =SUM('1st Quarter 2023'!G19, '2nd Quarter 2023'!G27, '3rd Quarter 2023'!G27, '4th Quarter 2024'!G27) -> 71768.39 | H19: =C19-G19 -> -39065.39 | I19: =IFERROR(H19/G19, 0) -> -0.54432585
A20: St Josephs Church | B20: MA | C20: =SUM('1st Quarter 2023'!C20, '2nd Quarter 2023'!C28, '3rd Quarter 2023'!C28, '4th Quarter 2024'!C28) -> 37183 | D20: =SUM('1st Quarter 2023'!D20, '2nd Quarter 2023'!D28, '3rd Quarter 2023'!D28, '4th Quarter 2024'!D28) -> 87772.32 | E20: =C20-D20 -> -50589.32 | F20: =IFERROR(E20/D20, 0) -> -0.57636986 | G20: =SUM('1st Quarter 2023'!G20, '2nd Quarter 2023'!G28, '3rd Quarter 2023'!G28, '4th Quarter 2024'!G28) -> 91531.02 | H20: =C20-G20 -> -54348.02 | I20: =IFERROR(H20/G20, 0) -> -0.59376614
A21: Sunset A | B21: MA | C21: =SUM('1st Quarter 2023'!C21, '2nd Quarter 2023'!C29, '3rd Quarter 2023'!C29, '4th Quarter 2024'!C29) -> 16708.5 | D21: =SUM('1st Quarter 2023'!D21, '2nd Quarter 2023'!D29, '3rd Quarter 2023'!D29, '4th Quarter 2024'!D29) -> 42789.35 | E21: =C21-D21 -> -26080.85 | F21: =IFERROR(E21/D21, 0) -> -0.60951732 | G21: =SUM('1st Quarter 2023'!G21, '2nd Quarter 2023'!G29, '3rd Quarter 2023'!G29, '4th Quarter 2024'!G29) -> 32696.87 | H21: =C21-G21 -> -15988.37 | I21: =IFERROR(H21/G21, 0) -> -0.48898778
A22: Sunset B | B22: MA | C22: =SUM('1st Quarter 2023'!C22, '2nd Quarter 2023'!C30, '3rd Quarter 2023'!C30, '4th Quarter 2024'!C30) -> 16074.25 | D22: =SUM('1st Quarter 2023'!D22, '2nd Quarter 2023'!D30, '3rd Quarter 2023'!D30, '4th Quarter 2024'!D30) -> 29669.2 | E22: =C22-D22 -> -13594.95 | F22: =IFERROR(E22/D22, 0) -> -0.45821761 | G22: =SUM('1st Quarter 2023'!G22, '2nd Quarter 2023'!G30, '3rd Quarter 2023'!G30, '4th Quarter 2024'!G30) -> 32307.32 | H22: =C22-G22 -> -16233.07 | I22: =IFERROR(H22/G22, 0) -> -0.50245796
A23: Woodchuck | B23: MA | C23: =SUM('1st Quarter 2023'!C23, '2nd Quarter 2023'!C31, '3rd Quarter 2023'!C31, '4th Quarter 2024'!C31) -> 33788 | D23: =SUM('1st Quarter 2023'!D23, '2nd Quarter 2023'!D31, '3rd Quarter 2023'!D31, '4th Quarter 2024'!D31) -> 71556.68 | E23: =C23-D23 -> -37768.68 | F23: =IFERROR(E23/D23, 0) -> -0.52781487 | G23: =SUM('1st Quarter 2023'!G23, '2nd Quarter 2023'!G31, '3rd Quarter 2023'!G31, '4th Quarter 2024'!G31) -> 96097.7 | H23: =C23-G23 -> -62309.7 | I23: =IFERROR(H23/G23, 0) -> -0.64839949
A24: Total | C24: =SUM(C3:C23) -> 1074735.8 | D24: =SUM(D3:D23) -> 1953737.2 | E24: =C24-D24 -> -879001.43 | F24: =IFERROR(E24/D24, 0) -> -0.44990771 | G24: =SUM(G3:G23) -> 2327559.5 | H24: =C24-G24 -> -1252823.7 | I24: =IFERROR(H24/G24, 0) -> -0.53825637
A26: Values in gold exceed expected or forecasted by 10% or more.
A28: Values in red are below expected or forecasted by 10% or more.

Sheet 1st Quarter 2023
A1: {=portfolio} -> 38 DN | C1: 1st Quarter 2024 Actual v. Expected | G1: 1st Quarter 2024 Forecasted | J1: NOTES | K1: SR
A2: Site | B2: State | C2: Actual | D2: Expected | E2: Delta | F2: % | G2: Forecasted | H2: Delta | I2: %
A3: {=Sites[Site]} -> 6th St. | B3: {=Sites[State]} -> CA | C3: =SUM('01-2024'!C3, '02-2024'!C3, '03-2024'!C3) -> 124703.5 | D3: =SUM('01-2024'!D3, '02-2024'!D3, '03-2024'!D3) -> 103355.9 | E3: =C3-D3 -> 21347.6 | F3: =IFERROR(E3/D3, 0) -> 0.20654457 | G3: =SUM('01-2024'!G3, '02-2024'!G3, '03-2024'!G3) -> 146126.1 | H3: =C3-G3 -> -21422.6 | I3: =IFERROR(H3/G3, 0) -> -0.14660352
A4: Barton Acres | B4: MA | C4: =SUM('01-2024'!C4, '02-2024'!C4, '03-2024'!C4) -> 31509 | D4: =SUM('01-2024'!D4, '02-2024'!D4, '03-2024'!D4) -> 84215.44 | E4: =C4-D4 -> -52706.44 | F4: =IFERROR(E4/D4, 0) -> -0.62585246 | G4: =SUM('01-2024'!G4, '02-2024'!G4, '03-2024'!G4) -> 69453.12 | H4: =C4-G4 -> -37944.12 | I4: =IFERROR(H4/G4, 0) -> -0.54632708
A5: Bowden | B5: MA | C5: =SUM('01-2024'!C5, '02-2024'!C5, '03-2024'!C5) -> 69313 | D5: =SUM('01-2024'!D5, '02-2024'!D5, '03-2024'!D5) -> 124922.7 | E5: =C5-D5 -> -55609.7 | F5: =IFERROR(E5/D5, 0) -> -0.44515288 | G5: =SUM('01-2024'!G5, '02-2024'!G5, '03-2024'!G5) -> 167677.4 | H5: =C5-G5 -> -98364.4 | I5: =IFERROR(H5/G5, 0) -> -0.58662885
A6: Blair Wire Village | B6: MA | C6: =SUM('01-2024'!C6, '02-2024'!C6, '03-2024'!C6) -> 38474 | D6: =SUM('01-2024'!D6, '02-2024'!D6, '03-2024'!D6) -> 97645.68 | E6: =C6-D6 -> -59171.68 | F6: =IFERROR(E6/D6, 0) -> -0.60598359 | G6: =SUM('01-2024'!G6, '02-2024'!G6, '03-2024'!G6) -> 83112.14 | H6: =C6-G6 -> -44638.14 | I6: =IFERROR(H6/G6, 0) -> -0.53708327
A7: Boutilier | B7: MA | C7: =SUM('01-2024'!C7, '02-2024'!C7, '03-2024'!C7) -> 104475 | D7: =SUM('01-2024'!D7, '02-2024'!D7, '03-2024'!D7) -> 117645.2 | E7: =C7-D7 -> -13170.2 | F7: =IFERROR(E7/D7, 0) -> -0.11194847 | G7: =SUM('01-2024'!G7, '02-2024'!G7, '03-2024'!G7) -> 190658.8 | H7: =C7-G7 -> -86183.8 | I7: =IFERROR(H7/G7, 0) -> -0.45203159
A8: Cherry Valley | B8: MA | C8: =SUM('01-2024'!C8, '02-2024'!C8, '03-2024'!C8) -> 33861 | D8: =SUM('01-2024'!D8, '02-2024'!D8, '03-2024'!D8) -> 93717.02 | E8: =C8-D8 -> -59856.02 | F8: =IFERROR(E8/D8, 0) -> -0.6386889 | G8: =SUM('01-2024'!G8, '02-2024'!G8, '03-2024'!G8) -> 77483 | H8: =C8-G8 -> -43622 | I8: =IFERROR(H8/G8, 0) -> -0.56298801
A9: Cohasse | B9: MA | C9: =SUM('01-2024'!C9, '02-2024'!C9, '03-2024'!C9) -> 37057 | D9: =SUM('01-2024'!D9, '02-2024'!D9, '03-2024'!D9) -> 86836.54 | E9: =C9-D9 -> -49779.54 | F9: =IFERROR(E9/D9, 0) -> -0.57325568 | G9: =SUM('01-2024'!G9, '02-2024'!G9, '03-2024'!G9) -> 114180.6 | H9: =C9-G9 -> -77123.6 | I9: =IFERROR(H9/G9, 0) -> -0.67545275
A10: ISM Dighton Solar 2 | B10: MA | C10: =SUM('01-2024'!C10, '02-2024'!C10, '03-2024'!C10) -> 123864 | D10: =SUM('01-2024'!D10, '02-2024'!D10, '03-2024'!D10) -> 178054.9 | E10: =C10-D10 -> -54190.9 | F10: =IFERROR(E10/D10, 0) -> -0.30434939 | G10: =SUM('01-2024'!G10, '02-2024'!G10, '03-2024'!G10) -> 195853.9 | H10: =C10-G10 -> -71989.9 | I10: =IFERROR(H10/G10, 0) -> -0.3675694
A11: Dudley River 1 | B11: MA | C11: =SUM('01-2024'!C11, '02-2024'!C11, '03-2024'!C11) -> 43519 | D11: =SUM('01-2024'!D11, '02-2024'!D11, '03-2024'!D11) -> 68762.9 | E11: =C11-D11 -> -25243.9 | F11: =IFERROR(E11/D11, 0) -> -0.36711512 | G11: =SUM('01-2024'!G11, '02-2024'!G11, '03-2024'!G11) -> 83762.23 | H11: =C11-G11 -> -40243.23 | I11: =IFERROR(H11/G11, 0) -> -0.48044602
A12: Dudley River 2 | B12: MA | C12: =SUM('01-2024'!C12, '02-2024'!C12, '03-2024'!C12) -> 44123 | D12: =SUM('01-2024'!D12, '02-2024'!D12, '03-2024'!D12) -> 70139.57 | E12: =C12-D12 -> -26016.57 | F12: =IFERROR(E12/D12, 0) -> -0.37092571 | G12: =SUM('01-2024'!G12, '02-2024'!G12, '03-2024'!G12) -> 81919.43 | H12: =C12-G12 -> -37796.43 | I12: =IFERROR(H12/G12, 0) -> -0.46138541
A13: Dudley River 3 | B13: MA | C13: =SUM('01-2024'!C13, '02-2024'!C13, '03-2024'!C13) -> 47297 | D13: =SUM('01-2024'!D13, '02-2024'!D13, '03-2024'!D13) -> 71573.83 | E13: =C13-D13 -> -24276.83 | F13: =IFERROR(E13/D13, 0) -> -0.33918584 | G13: =SUM('01-2024'!G13, '02-2024'!G13, '03-2024'!G13) -> 84149.19 | H13: =C13-G13 -> -36852.19 | I13: =IFERROR(H13/G13, 0) -> -0.43793874
A14: Flint Pond | B14: MA | C14: =SUM('01-2024'!C14, '02-2024'!C14, '03-2024'!C14) -> 16497.5 | D14: =SUM('01-2024'!D14, '02-2024'!D14, '03-2024'!D14) -> 40276 | E14: =C14-D14 -> -23778.5 | F14: =IFERROR(E14/D14, 0) -> -0.59038882 | G14: =SUM('01-2024'!G14, '02-2024'!G14, '03-2024'!G14) -> 33543.68 | H14: =C14-G14 -> -17046.18 | I14: =IFERROR(H14/G14, 0) -> -0.50817859
A15: Incom | B15: MA | C15: =SUM('01-2024'!C15, '02-2024'!C15, '03-2024'!C15) -> 83086 | D15: =SUM('01-2024'!D15, '02-2024'!D15, '03-2024'!D15) -> 159872.4 | E15: =C15-D15 -> -76786.4 | F15: =IFERROR(E15/D15, 0) -> -0.48029804 | G15: =SUM('01-2024'!G15, '02-2024'!G15, '03-2024'!G15) -> 220156.9 | H15: =C15-G15 -> -137070.9 | I15: =IFERROR(H15/G15, 0) -> -0.62260551
... A23: Woodchuck | B23: MA | C23: =SUM('01-2024'!C23, '02-2024'!C23, '03-2024'!C23) -> 33788 | D23: =SUM('01-2024'!D23, '02-2024'!D23, '03-2024'!D23) -> 71556.68 | E23: =C23-D23 -> -37768.68 | F23: =IFERROR(E23/D23, 0) -> -0.52781487 | G23: =SUM('01-2024'!G23, '02-2024'!G23, '03-2024'!G23) -> 96097.7 | H23: =C23-G23 -> -62309.7 | I23: =IFERROR(H23/G23, 0) -> -0.64839949
A24: Total | C24: =SUM(C3:C23) -> 1074735.8 | D24: =SUM(D3:D23) -> 1953737.2 | E24: =C24-D24 -> -879001.43 | F24: =IFERROR(E24/D24, 0) -> -0.44990771 | G24: =SUM(G3:G23) -> 2327559.5 | H24: =C24-G24 -> -1252823.7 | I24: =IFERROR(H24/G24, 0) -> -0.53825637
A26: Values in gold exceed expected or forecasted by 10% or more.
A28: Values in red are below expected or forecasted by 10% or more.

Sheet 2nd Quarter 2023
A1: {=portfolio} -> 38 DN | C1: 2nd Quarter 2024 Actual v. Expected | G1: 2nd Quarter 2024 Forecasted | J1: NOTES | K1: SR
A2: Site | B2: State | C2: Actual | D2: Expected | E2: Delta | F2: % | G2: Forecasted | H2: Delta | I2: %
A3: {=Sites[Site]} -> 6th St. | B3: {=Sites[State]} -> CA | C3: =SUM('04-2024'!C3, '05-2024'!C3, '06-2024'!C3) -> 0 | D3: =SUM('04-2024'!D3, '05-2024'!D3, '06-2024'!D3) -> 0 | E3: =C3-D3 -> 0 | F3: =IFERROR(E3/D3, 0) -> 0 | G3: =SUM('04-2024'!G3, '05-2024'!G3, '06-2024'!G3) -> 0 | H3: =C3-G3 -> 0 | I3: =IFERROR(H3/G3, 0) -> 0
A4: Barton Acres | B4: MA | C4: =SUM('04-2024'!C4, '05-2024'!C4, '06-2024'!C4) -> 0 | D4: =SUM('04-2024'!D4, '05-2024'!D4, '06-2024'!D4) -> 0 | E4: =C4-D4 -> 0 | F4: =IFERROR(E4/D4, 0) -> 0 | G4: =SUM('04-2024'!G4, '05-2024'!G4, '06-2024'!G4) -> 0 | H4: =C4-G4 -> 0 | I4: =IFERROR(H4/G4, 0) -> 0
A5: Bowden | B5: MA | C5: =SUM('04-2024'!C5, '05-2024'!C5, '06-2024'!C5) -> 0 | D5: =SUM('04-2024'!D5, '05-2024'!D5, '06-2024'!D5) -> 0 | E5: =C5-D5 -> 0 | F5: =IFERROR(E5/D5, 0) -> 0 | G5: =SUM('04-2024'!G5, '05-2024'!G5, '06-2024'!G5) -> 0 | H5: =C5-G5 -> 0 | I5: =IFERROR(H5/G5, 0) -> 0
A6: Blair Wire Village | B6: MA | C6: =SUM('04-2024'!C6, '05-2024'!C6, '06-2024'!C6) -> 0 | D6: =SUM('04-2024'!D6, '05-2024'!D6, '06-2024'!D6) -> 0 | E6: =C6-D6 -> 0 | F6: =IFERROR(E6/D6, 0) -> 0 | G6: =SUM('04-2024'!G6, '05-2024'!G6, '06-2024'!G6) -> 0 | H6: =C6-G6 -> 0 | I6: =IFERROR(H6/G6, 0) -> 0
A7: Boutilier | B7: MA | C7: =SUM('04-2024'!C7, '05-2024'!C7, '06-2024'!C7) -> 0 | D7: =SUM('04-2024'!D7, '05-2024'!D7, '06-2024'!D7) -> 0 | E7: =C7-D7 -> 0 | F7: =IFERROR(E7/D7, 0) -> 0 | G7: =SUM('04-2024'!G7, '05-2024'!G7, '06-2024'!G7) -> 0 | H7: =C7-G7 -> 0 | I7: =IFERROR(H7/G7, 0) -> 0
A8: Cherry Valley | B8: MA | C8: =SUM('04-2024'!C8, '05-2024'!C8, '06-2024'!C8) -> 0 | D8: =SUM('04-2024'!D8, '05-2024'!D8, '06-2024'!D8) -> 0 | E8: =C8-D8 -> 0 | F8: =IFERROR(E8/D8, 0) -> 0 | G8: =SUM('04-2024'!G8, '05-2024'!G8, '06-2024'!G8) -> 0 | H8: =C8-G8 -> 0 | I8: =IFERROR(H8/G8, 0) -> 0
A9: Cohasse | B9: MA | C9: =SUM('04-2024'!C9, '05-2024'!C9, '06-2024'!C9) -> 0 | D9: =SUM('04-2024'!D9, '05-2024'!D9, '06-2024'!D9) -> 0 | E9: =C9-D9 -> 0 | F9: =IFERROR(E9/D9, 0) -> 0 | G9: =SUM('04-2024'!G9, '05-2024'!G9, '06-2024'!G9) -> 0 | H9: =C9-G9 -> 0 | I9: =IFERROR(H9/G9, 0) -> 0
A10: ISM Dighton Solar 2 | B10: MA | C10: =SUM('04-2024'!C10, '05-2024'!C10, '06-2024'!C10) -> 0 | D10: =SUM('04-2024'!D10, '05-2024'!D10, '06-2024'!D10) -> 0 | E10: =C10-D10 -> 0 | F10: =IFERROR(E10/D10, 0) -> 0 | G10: =SUM('04-2024'!G10, '05-2024'!G10, '06-2024'!G10) -> 0 | H10: =C10-G10 -> 0 | I10: =IFERROR(H10/G10, 0) -> 0
A11: Dudley River 1 | B11: MA | C11: =SUM('04-2024'!C11, '05-2024'!C11, '06-2024'!C11) -> 0 | D11: =SUM('04-2024'!D11, '05-2024'!D11, '06-2024'!D11) -> 0 | E11: =C11-D11 -> 0 | F11: =IFERROR(E11/D11, 0) -> 0 | G11: =SUM('04-2024'!G11, '05-2024'!G11, '06-2024'!G11) -> 0 | H11: =C11-G11 -> 0 | I11: =IFERROR(H11/G11, 0) -> 0
A12: Dudley River 2 | B12: MA | C12: =SUM('04-2024'!C12, '05-2024'!C12, '06-2024'!C12) -> 0 | D12: =SUM('04-2024'!D12, '05-2024'!D12, '06-2024'!D12) -> 0 | E12: =C12-D12 -> 0 | F12: =IFERROR(E12/D12, 0) -> 0 | G12: =SUM('04-2024'!G12, '05-2024'!G12, '06-2024'!G12) -> 0 | H12: =C12-G12 -> 0 | I12: =IFERROR(H12/G12, 0) -> 0
A13: Dudley River 3 | B13: MA | C13: =SUM('04-2024'!C13, '05-2024'!C13, '06-2024'!C13) -> 0 | D13: =SUM('04-2024'!D13, '05-2024'!D13, '06-2024'!D13) -> 0 | E13: =C13-D13 -> 0 | F13: =IFERROR(E13/D13, 0) -> 0 | G13: =SUM('04-2024'!G13, '05-2024'!G13, '06-2024'!G13) -> 0 | H13: =C13-G13 -> 0 | I13: =IFERROR(H13/G13, 0) -> 0
A14: Flint Pond | B14: MA | C14: =SUM('04-2024'!C14, '05-2024'!C14, '06-2024'!C14) -> 0 | D14: =SUM('04-2024'!D14, '05-2024'!D14, '06-2024'!D14) -> 0 | E14: =C14-D14 -> 0 | F14: =IFERROR(E14/D14, 0) -> 0 | G14: =SUM('04-2024'!G14, '05-2024'!G14, '06-2024'!G14) -> 0 | H14: =C14-G14 -> 0 | I14: =IFERROR(H14/G14, 0) -> 0
A15: Incom | B15: MA | C15: =SUM('04-2024'!C15, '05-2024'!C15, '06-2024'!C15) -> 0 | D15: =SUM('04-2024'!D15, '05-2024'!D15, '06-2024'!D15) -> 0 | E15: =C15-D15 -> 0 | F15: =IFERROR(E15/D15, 0) -> 0 | G15: =SUM('04-2024'!G15, '05-2024'!G15, '06-2024'!G15) -> 0 | H15: =C15-G15 -> 0 | I15: =IFERROR(H15/G15, 0) -> 0
... A23: Woodchuck | B23: MA | C23: =SUM('04-2024'!C23, '05-2024'!C23, '06-2024'!C23) -> 0 | D23: =SUM('04-2024'!D23, '05-2024'!D23, '06-2024'!D23) -> 0 | E23: =C23-D23 -> 0 | F23: =IFERROR(E23/D23, 0) -> 0 | G23: =SUM('04-2024'!G23, '05-2024'!G23, '06-2024'!G23) -> 0 | H23: =C23-G23 -> 0 | I23: =IFERROR(H23/G23, 0) -> 0
A24: Total | C24: =SUM(C3:C23) -> 0 | D24: =SUM(D3:D23) -> 0 | E24: =C24-D24 -> 0 | F24: =IFERROR(E24/D24, 0) -> 0 | G24: =SUM(G3:G23) -> 0 | H24: =C24-G24 -> 0 | I24: =IFERROR(H24/G24, 0) -> 0
A26: Values in gold exceed expected or forecasted by 10% or more.
A28: Values in red are below expected or forecasted by 10% or more.

Sheet 3rd Quarter 2023
A1: {=portfolio} -> 38 DN | C1: 3rd Quarter 2024 Actual v. Expected | G1: 3rd Quarter 2024 Forecasted | J1: NOTES | K1: SR
A2: Site | B2: State | C2: Actual | D2: Expected | E2: Delta | F2: % | G2: Forecasted | H2: Delta | I2: %
A3: {=Sites[Site]} -> 6th St. | B3: {=Sites[State]} -> CA | C3: =SUM('07-2024'!C3, '08-2024'!C3, '09-2024'!C3) -> 0 | D3: =SUM('07-2024'!D3, '08-2024'!D3, '09-2024'!D3) -> 0 | E3: =C3-D3 -> 0 | F3: =IFERROR(E3/D3, 0) -> 0 | G3: =SUM('07-2024'!G3, '08-2024'!G3, '09-2024'!G3) -> 0 | H3: =C3-G3 -> 0 | I3: =IFERROR(H3/G3, 0) -> 0
A4: Barton Acres | B4: MA | C4: =SUM('07-2024'!C4, '08-2024'!C4, '09-2024'!C4) -> 0 | D4: =SUM('07-2024'!D4, '08-2024'!D4, '09-2024'!D4) -> 0 | E4: =C4-D4 -> 0 | F4: =IFERROR(E4/D4, 0) -> 0 | G4: =SUM('07-2024'!G4, '08-2024'!G4, '09-2024'!G4) -> 0 | H4: =C4-G4 -> 0 | I4: =IFERROR(H4/G4, 0) -> 0
A5: Bowden | B5: MA | C5: =SUM('07-2024'!C5, '08-2024'!C5, '09-2024'!C5) -> 0 | D5: =SUM('07-2024'!D5, '08-2024'!D5, '09-2024'!D5) -> 0 | E5: =C5-D5 -> 0 | F5: =IFERROR(E5/D5, 0) -> 0 | G5: =SUM('07-2024'!G5, '08-2024'!G5, '09-2024'!G5) -> 0 | H5: =C5-G5 -> 0 | I5: =IFERROR(H5/G5, 0) -> 0
A6: Blair Wire Village | B6: MA | C6: =SUM('07-2024'!C6, '08-2024'!C6, '09-2024'!C6) -> 0 | D6: =SUM('07-2024'!D6, '08-2024'!D6, '09-2024'!D6) -> 0 | E6: =C6-D6 -> 0 | F6: =IFERROR(E6/D6, 0) -> 0 | G6: =SUM('07-2024'!G6, '08-2024'!G6, '09-2024'!G6) -> 0 | H6: =C6-G6 -> 0 | I6: =IFERROR(H6/G6, 0) -> 0
A7: Boutilier | B7: MA | C7: =SUM('07-2024'!C7, '08-2024'!C7, '09-2024'!C7) -> 0 | D7: =SUM('07-2024'!D7, '08-2024'!D7, '09-2024'!D7) -> 0 | E7: =C7-D7 -> 0 | F7: =IFERROR(E7/D7, 0) -> 0 | G7: =SUM('07-2024'!G7, '08-2024'!G7, '09-2024'!G7) -> 0 | H7: =C7-G7 -> 0 | I7: =IFERROR(H7/G7, 0) -> 0
A8: Cherry Valley | B8: MA | C8: =SUM('07-2024'!C8, '08-2024'!C8, '09-2024'!C8) -> 0 | D8: =SUM('07-2024'!D8, '08-2024'!D8, '09-2024'!D8) -> 0 | E8: =C8-D8 -> 0 | F8: =IFERROR(E8/D8, 0) -> 0 | G8: =SUM('07-2024'!G8, '08-2024'!G8, '09-2024'!G8) -> 0 | H8: =C8-G8 -> 0 | I8: =IFERROR(H8/G8, 0) -> 0
A9: Cohasse | B9: MA | C9: =SUM('07-2024'!C9, '08-2024'!C9, '09-2024'!C9) -> 0 | D9: =SUM('07-2024'!D9, '08-2024'!D9, '09-2024'!D9) -> 0 | E9: =C9-D9 -> 0 | F9: =IFERROR(E9/D9, 0) -> 0 | G9: =SUM('07-2024'!G9, '08-2024'!G9, '09-2024'!G9) -> 0 | H9: =C9-G9 -> 0 | I9: =IFERROR(H9/G9, 0) -> 0
A10: ISM Dighton Solar 2 | B10: MA | C10: =SUM('07-2024'!C10, '08-2024'!C10, '09-2024'!C10) -> 0 | D10: =SUM('07-2024'!D10, '08-2024'!D10, '09-2024'!D10) -> 0 | E10: =C10-D10 -> 0 | F10: =IFERROR(E10/D10, 0) -> 0 | G10: =SUM('07-2024'!G10, '08-2024'!G10, '09-2024'!G10) -> 0 | H10: =C10-G10 -> 0 | I10: =IFERROR(H10/G10, 0) -> 0
A11: Dudley River 1 | B11: MA | C11: =SUM('07-2024'!C11, '08-2024'!C11, '09-2024'!C11) -> 0 | D11: =SUM('07-2024'!D11, '08-2024'!D11, '09-2024'!D11) -> 0 | E11: =C11-D11 -> 0 | F11: =IFERROR(E11/D11, 0) -> 0 | G11: =SUM('07-2024'!G11, '08-2024'!G11, '09-2024'!G11) -> 0 | H11: =C11-G11 -> 0 | I11: =IFERROR(H11/G11, 0) -> 0
A12: Dudley River 2 | B12: MA | C12: =SUM('07-2024'!C12, '08-2024'!C12, '09-2024'!C12) -> 0 | D12: =SUM('07-2024'!D12, '08-2024'!D12, '09-2024'!D12) -> 0 | E12: =C12-D12 -> 0 | F12: =IFERROR(E12/D12, 0) -> 0 | G12: =SUM('07-2024'!G12, '08-2024'!G12, '09-2024'!G12) -> 0 | H12: =C12-G12 -> 0 | I12: =IFERROR(H12/G12, 0) -> 0
A13: Dudley River 3 | B13: MA | C13: =SUM('07-2024'!C13, '08-2024'!C13, '09-2024'!C13) -> 0 | D13: =SUM('07-2024'!D13, '08-2024'!D13, '09-2024'!D13) -> 0 | E13: =C13-D13 -> 0 | F13: =IFERROR(E13/D13, 0) -> 0 | G13: =SUM('07-2024'!G13, '08-2024'!G13, '09-2024'!G13) -> 0 | H13: =C13-G13 -> 0 | I13: =IFERROR(H13/G13, 0) -> 0
A14: Flint Pond | B14: MA | C14: =SUM('07-2024'!C14, '08-2024'!C14, '09-2024'!C14) -> 0 | D14: =SUM('07-2024'!D14, '08-2024'!D14, '09-2024'!D14) -> 0 | E14: =C14-D14 -> 0 | F14: =IFERROR(E14/D14, 0) -> 0 | G14: =SUM('07-2024'!G14, '08-2024'!G14, '09-2024'!G14) -> 0 | H14: =C14-G14 -> 0 | I14: =IFERROR(H14/G14, 0) -> 0
A15: Incom | B15: MA | C15: =SUM('07-2024'!C15, '08-2024'!C15, '09-2024'!C15) -> 0 | D15: =SUM('07-2024'!D15, '08-2024'!D15, '09-2024'!D15) -> 0 | E15: =C15-D15 -> 0 | F15: =IFERROR(E15/D15, 0) -> 0 | G15: =SUM('07-2024'!G15, '08-2024'!G15, '09-2024'!G15) -> 0 | H15: =C15-G15 -> 0 | I15: =IFERROR(H15/G15, 0) -> 0
... A23: Woodchuck | B23: MA | C23: =SUM('07-2024'!C23, '08-2024'!C23, '09-2024'!C23) -> 0 | D23: =SUM('07-2024'!D23, '08-2024'!D23, '09-2024'!D23) -> 0 | E23: =C23-D23 -> 0 | F23: =IFERROR(E23/D23, 0) -> 0 | G23: =SUM('07-2024'!G23, '08-2024'!G23, '09-2024'!G23) -> 0 | H23: =C23-G23 -> 0 | I23: =IFERROR(H23/G23, 0) -> 0
A24: Total | C24: =SUM(C3:C23) -> 0 | D24: =SUM(D3:D23) -> 0 | E24: =C24-D24 -> 0 | F24: =IFERROR(E24/D24, 0) -> 0 | G24: =SUM(G3:G23) -> 0 | H24: =C24-G24 -> 0 | I24: =IFERROR(H24/G24, 0) -> 0
A26: Values in gold exceed expected or forecasted by 10% or more.
A28: Values in red are below expected or forecasted by 10% or more.

Sheet 4th Quarter 2024
A1: {=portfolio} -> 38 DN | C1: 4th Quarter 2024 Actual v. Expected | G1: 4th Quarter 2024 Forecasted | J1: NOTES | K1: SR
A2: Site | B2: State | C2: Actual | D2: Expected | E2: Delta | F2: % | G2: Forecasted | H2: Delta | I2: %
A3: {=Sites[Site]} -> 6th St. | B3: {=Sites[State]} -> CA | C3: =SUM('10-2024'!C3, '11-2024'!C3, '12-2024'!C3) -> 0 | D3: =SUM('10-2024'!D3, '11-2024'!D3, '12-2024'!D3) -> 0 | E3: =C3-D3 -> 0 | F3: =IFERROR(E3/D3, 0) -> 0 | G3: =SUM('10-2024'!G3, '11-2024'!G3, '12-2024'!G3) -> 0 | H3: =C3-G3 -> 0 | I3: =IFERROR(H3/G3, 0) -> 0
A4: Barton Acres | B4: MA | C4: =SUM('10-2024'!C4, '11-2024'!C4, '12-2024'!C4) -> 0 | D4: =SUM('10-2024'!D4, '11-2024'!D4, '12-2024'!D4) -> 0 | E4: =C4-D4 -> 0 | F4: =IFERROR(E4/D4, 0) -> 0 | G4: =SUM('10-2024'!G4, '11-2024'!G4, '12-2024'!G4) -> 0 | H4: =C4-G4 -> 0 | I4: =IFERROR(H4/G4, 0) -> 0
A5: Bowden | B5: MA | C5: =SUM('10-2024'!C5, '11-2024'!C5, '12-2024'!C5) -> 0 | D5: =SUM('10-2024'!D5, '11-2024'!D5, '12-2024'!D5) -> 0 | E5: =C5-D5 -> 0 | F5: =IFERROR(E5/D5, 0) -> 0 | G5: =SUM('10-2024'!G5, '11-2024'!G5, '12-2024'!G5) -> 0 | H5: =C5-G5 -> 0 | I5: =IFERROR(H5/G5, 0) -> 0
A6: Blair Wire Village | B6: MA | C6: =SUM('10-2024'!C6, '11-2024'!C6, '12-2024'!C6) -> 0 | D6: =SUM('10-2024'!D6, '11-2024'!D6, '12-2024'!D6) -> 0 | E6: =C6-D6 -> 0 | F6: =IFERROR(E6/D6, 0) -> 0 | G6: =SUM('10-2024'!G6, '11-2024'!G6, '12-2024'!G6) -> 0 | H6: =C6-G6 -> 0 | I6: =IFERROR(H6/G6, 0) -> 0
A7: Boutilier | B7: MA | C7: =SUM('10-2024'!C7, '11-2024'!C7, '12-2024'!C7) -> 0 | D7: =SUM('10-2024'!D7, '11-2024'!D7, '12-2024'!D7) -> 0 | E7: =C7-D7 -> 0 | F7: =IFERROR(E7/D7, 0) -> 0 | G7: =SUM('10-2024'!G7, '11-2024'!G7, '12-2024'!G7) -> 0 | H7: =C7-G7 -> 0 | I7: =IFERROR(H7/G7, 0) -> 0
A8: Cherry Valley | B8: MA | C8: =SUM('10-2024'!C8, '11-2024'!C8, '12-2024'!C8) -> 0 | D8: =SUM('10-2024'!D8, '11-2024'!D8, '12-2024'!D8) -> 0 | E8: =C8-D8 -> 0 | F8: =IFERROR(E8/D8, 0) -> 0 | G8: =SUM('10-2024'!G8, '11-2024'!G8, '12-2024'!G8) -> 0 | H8: =C8-G8 -> 0 | I8: =IFERROR(H8/G8, 0) -> 0
A9: Cohasse | B9: MA | C9: =SUM('10-2024'!C9, '11-2024'!C9, '12-2024'!C9) -> 0 | D9: =SUM('10-2024'!D9, '11-2024'!D9, '12-2024'!D9) -> 0 | E9: =C9-D9 -> 0 | F9: =IFERROR(E9/D9, 0) -> 0 | G9: =SUM('10-2024'!G9, '11-2024'!G9, '12-2024'!G9) -> 0 | H9: =C9-G9 -> 0 | I9: =IFERROR(H9/G9, 0) -> 0
A10: ISM Dighton Solar 2 | B10: MA | C10: =SUM('10-2024'!C10, '11-2024'!C10, '12-2024'!C10) -> 0 | D10: =SUM('10-2024'!D10, '11-2024'!D10, '12-2024'!D10) -> 0 | E10: =C10-D10 -> 0 | F10: =IFERROR(E10/D10, 0) -> 0 | G10: =SUM('10-2024'!G10, '11-2024'!G10, '12-2024'!G10) -> 0 | H10: =C10-G10 -> 0 | I10: =IFERROR(H10/G10, 0) -> 0
A11: Dudley River 1 | B11: MA | C11: =SUM('10-2024'!C11, '11-2024'!C11, '12-2024'!C11) -> 0 | D11: =SUM('10-2024'!D11, '11-2024'!D11, '12-2024'!D11) -> 0 | E11: =C11-D11 -> 0 | F11: =IFERROR(E11/D11, 0) -> 0 | G11: =SUM('10-2024'!G11, '11-2024'!G11, '12-2024'!G11) -> 0 | H11: =C11-G11 -> 0 | I11: =IFERROR(H11/G11, 0) -> 0
A12: Dudley River 2 | B12: MA | C12: =SUM('10-2024'!C12, '11-2024'!C12, '12-2024'!C12) -> 0 | D12: =SUM('10-2024'!D12, '11-2024'!D12, '12-2024'!D12) -> 0 | E12: =C12-D12 -> 0 | F12: =IFERROR(E12/D12, 0) -> 0 | G12: =SUM('10-2024'!G12, '11-2024'!G12, '12-2024'!G12) -> 0 | H12: =C12-G12 -> 0 | I12: =IFERROR(H12/G12, 0) -> 0
A13: Dudley River 3 | B13: MA | C13: =SUM('10-2024'!C13, '11-2024'!C13, '12-2024'!C13) -> 0 | D13: =SUM('10-2024'!D13, '11-2024'!D13, '12-2024'!D13) -> 0 | E13: =C13-D13 -> 0 | F13: =IFERROR(E13/D13, 0) -> 0 | G13: =SUM('10-2024'!G13, '11-2024'!G13, '12-2024'!G13) -> 0 | H13: =C13-G13 -> 0 | I13: =IFERROR(H13/G13, 0) -> 0
A14: Flint Pond | B14: MA | C14: =SUM('10-2024'!C14, '11-2024'!C14, '12-2024'!C14) -> 0 | D14: =SUM('10-2024'!D14, '11-2024'!D14, '12-2024'!D14) -> 0 | E14: =C14-D14 -> 0 | F14: =IFERROR(E14/D14, 0) -> 0 | G14: =SUM('10-2024'!G14, '11-2024'!G14, '12-2024'!G14) -> 0 | H14: =C14-G14 -> 0 | I14: =IFERROR(H14/G14, 0) -> 0
A15: Incom | B15: MA | C15: =SUM('10-2024'!C15, '11-2024'!C15, '12-2024'!C15) -> 0 | D15: =SUM('10-2024'!D15, '11-2024'!D15, '12-2024'!D15) -> 0 | E15: =C15-D15 -> 0 | F15: =IFERROR(E15/D15, 0) -> 0 | G15: =SUM('10-2024'!G15, '11-2024'!G15, '12-2024'!G15) -> 0 | H15: =C15-G15 -> 0 | I15: =IFERROR(H15/G15, 0) -> 0
... A23: Woodchuck | B23: MA | C23: =SUM('10-2024'!C23, '11-2024'!C23, '12-2024'!C23) -> 0 | D23: =SUM('10-2024'!D23, '11-2024'!D23, '12-2024'!D23) -> 0 | E23: =C23-D23 -> 0 | F23: =IFERROR(E23/D23, 0) -> 0 | G23: =SUM('10-2024'!G23, '11-2024'!G23, '12-2024'!G23) -> 0 | H23: =C23-G23 -> 0 | I23: =IFERROR(H23/G23, 0) -> 0
A24: Total | C24: =SUM(C3:C23) -> 0 | D24: =SUM(D3:D23) -> 0 | E24: =C24-D24 -> 0 | F24: =IFERROR(E24/D24, 0) -> 0 | G24: =SUM(G3:G23) -> 0 | H24: =C24-G24 -> 0 | I24: =IFERROR(H24/G24, 0) -> 0
A26: Values in gold exceed expected or forecasted by 10% or more.
A28: Values in red are below expected or forecasted by 10% or more.

Sheet 01-2024
A1: {=portfolio} -> 38 DN | C1: 01-2024 Actual v. Expected | G1: 01-2024 Actual v. Forecasted | J1: NOTES | K1: SR
A2: Site | B2: State | C2: Actual | D2: Expected | E2: Delta | F2: % | G2: Forecasted | H2: Delta | I2: %
A3: {=Sites[Site]} -> 6th St. | B3: {=Sites[State]} -> CA | C3: {=IF(INDIRECT("'" & $A3 & "'!B5:J5")="", "", INDIRECT("'" & $A3 & "'!B5:J5"))} -> 124703.5 | D3: 103355.9 | E3: 21347.6 | F3: 0.20654457 | G3: 146126.1 | H3: -21422.6 | I3: -0.14660352 | J3: 1. Inverter 28 was offline from 12/14 and back online on 01/25 | K3: 1. SR079280
A4: Barton Acres | B4: MA | C4: {=IF(INDIRECT("'" & $A4 & "'!B5:J5")="", "", INDIRECT("'" & $A4 & "'!B5:J5"))} -> 31509 | D4: 84215.44 | E4: -52706.44 | F4: -0.62585246 | G4: 69453.12 | H4: -37944.12 | I4: -0.54632708
A5: Bowden | B5: MA | C5: {=IF(INDIRECT("'" & $A5 & "'!B5:J5")="", "", INDIRECT("'" & $A5 & "'!B5:J5"))} -> 69313 | D5: 124922.7 | E5: -55609.7 | F5: -0.44515288 | G5: 167677.4 | H5: -98364.4 | I5: -0.58662885
A6: Blair Wire Village | B6: MA | C6: {=IF(INDIRECT("'" & $A6 & "'!B5:J5")="", "", INDIRECT("'" & $A6 & "'!B5:J5"))} -> 38474 | D6: 97645.68 | E6: -59171.68 | F6: -0.60598359 | G6: 83112.14 | H6: -44638.14 | I6: -0.53708327 | J6: 1. Relay tripped and site is experiencing an outage on 01/07 at 09:47 and reclosed at 18:30 | K6: 1. SR079999
A7: Boutilier | B7: MA | C7: {=IF(INDIRECT("'" & $A7 & "'!B5:J5")="", "", INDIRECT("'" & $A7 & "'!B5:J5"))} -> 104475 | D7: 117645.2 | E7: -13170.2 | F7: -0.11194847 | G7: 190658.8 | H7: -86183.8 | I7: -0.45203159
A8: Cherry Valley | B8: MA | C8: {=IF(INDIRECT("'" & $A8 & "'!B5:J5")="", "", INDIRECT("'" & $A8 & "'!B5:J5"))} -> 33861 | D8: 93717.02 | E8: -59856.02 | F8: -0.6386889 | G8: 77483 | H8: -43622 | I8: -0.56298801 | J8: 1. Inverter B stopped communicating at 08:15 on 01/23 and technican reset the inverter at 12:00 2. Inverter B stopped communicating on 01/28 at 111:15 and and technician reset the inverter at 12:00. on 01/29 3. Site tripped offline at 10:45 on 01/07 and back online 23:15 same day. | K8: 1. SR080405 2. SR080529 3. SR080002
A9: Cohasse | B9: MA | C9: {=IF(INDIRECT("'" & $A9 & "'!B5:J5")="", "", INDIRECT("'" & $A9 & "'!B5:J5"))} -> 37057 | D9: 86836.54 | E9: -49779.54 | F9: -0.57325568 | G9: 114180.6 | H9: -77123.6 | I9: -0.67545275 | J9: 1. site tripped offline at 21:00 on 01/09 and back online at 8:30 on 01/10. | K9: 1. SR080109
A10: ISM Dighton Solar 2 | B10: MA | C10: {=IF(INDIRECT("'" & $A10 & "'!B5:J5")="", "", INDIRECT("'" & $A10 & "'!B5:J5"))} -> 123864 | D10: 178054.9 | E10: -54190.9 | F10: -0.30434939 | G10: 195853.9 | H10: -71989.9 | I10: -0.3675694 | J10: 1. SEL Relay 2 tripped offline at 23:00 on 01/30 and reclosed at 10:45 on 01/31 2. Planned outage on 01/25 at 9:00 and site reclosed at 17:00 on same day. | K10: 1. SR080611 2. SR080054
A11: Dudley River 1 | B11: MA | C11: {=IF(INDIRECT("'" & $A11 & "'!B5:J5")="", "", INDIRECT("'" & $A11 & "'!B5:J5"))} -> 43519 | D11: 68762.9 | E11: -25243.9 | F11: -0.36711512 | G11: 83762.23 | H11: -40243.23 | I11: -0.48044602
A12: Dudley River 2 | B12: MA | C12: {=IF(INDIRECT("'" & $A12 & "'!B5:J5")="", "", INDIRECT("'" & $A12 & "'!B5:J5"))} -> 44123 | D12: 70139.57 | E12: -26016.57 | F12: -0.37092571 | G12: 81919.43 | H12: -37796.43 | I12: -0.46138541
A13: Dudley River 3 | B13: MA | C13: {=IF(INDIRECT("'" & $A13 & "'!B5:J5")="", "", INDIRECT("'" & $A13 & "'!B5:J5"))} -> 47297 | D13: 71573.83 | E13: -24276.83 | F13: -0.33918584 | G13: 84149.19 | H13: -36852.19 | I13: -0.43793874
A14: Flint Pond | B14: MA | C14: {=IF(INDIRECT("'" & $A14 & "'!B5:J5")="", "", INDIRECT("'" & $A14 & "'!B5:J5"))} -> 16497.5 | D14: 40276 | E14: -23778.5 | F14: -0.59038882 | G14: 33543.68 | H14: -17046.18 | I14: -0.50817859 | J14: 1. site offline on 01/07 at 05:00 and resolved at 07:15 | K14: 1. SR079998
A15: Incom | B15: MA | C15: {=IF(INDIRECT("'" & $A15 & "'!B5:J5")="", "", INDIRECT("'" & $A15 & "'!B5:J5"))} -> 83086 | D15: 159872.4 | E15: -76786.4 | F15: -0.48029804 | G15: 220156.9 | H15: -137070.9 | I15: -0.62260551 | J15: 1. Site was offline on 01/25 at 04:45 and reclosed at 16:00 | K15: 1. SR080455
A16: JH | B16: MA | C16: {=IF(INDIRECT("'" & $A16 & "'!B5:J5")="", "", INDIRECT("'" & $A16 & "'!B5:J5"))} -> 32274 | D16: 86355.93 | E16: -54081.93 | F16: -0.6262677 | G16: 106218.7 | H16: -73944.7 | I16: -0.6961552
A17: Ledeaux | B17: MA | C17: {=IF(INDIRECT("'" & $A17 & "'!B5:J5")="", "", INDIRECT("'" & $A17 & "'!B5:J5"))} -> 28537 | D17: 58671.27 | E17: -30134.27 | F17: -0.51361203 | G17: 98769.99 | H17: -70232.99 | I17: -0.71107621
A18: Palombo A | B18: MA | C18: {=IF(INDIRECT("'" & $A18 & "'!B5:J5")="", "", INDIRECT("'" & $A18 & "'!B5:J5"))} -> 79689.003 | D18: 187942.8 | E18: -108253.8 | F18: -0.57599332 | G18: 250093 | H18: -170404 | I18: -0.68136252
A19: Palombo B | B19: MA | C19: {=IF(INDIRECT("'" & $A19 & "'!B5:J5")="", "", INDIRECT("'" & $A19 & "'!B5:J5"))} -> 32703 | D19: 91961.55 | E19: -59258.55 | F19: -0.64438398 | G19: 71768.39 | H19: -39065.39 | I19: -0.54432585
A20: St Josephs Church | B20: MA | C20: {=IF(INDIRECT("'" & $A20 & "'!B5:J5")="", "", INDIRECT("'" & $A20 & "'!B5:J5"))} -> 37183 | D20: 87772.32 | E20: -50589.32 | F20: -0.57636986 | G20: 91531.02 | H20: -54348.02 | I20: -0.59376614
A21: Sunset A | B21: MA | C21: {=IF(INDIRECT("'" & $A21 & "'!B5:J5")="", "", INDIRECT("'" & $A21 & "'!B5:J5"))} -> 16708.5 | D21: 42789.35 | E21: -26080.85 | F21: -0.60951732 | G21: 32696.87 | H21: -15988.37 | I21: -0.48898778 | J21: 1. Relay tripped at 3:50 Am on 01/30 and auto reclosed in minutes | K21: 1. SR080186
A22: Sunset B | B22: MA | C22: {=IF(INDIRECT("'" & $A22 & "'!B5:J5")="", "", INDIRECT("'" & $A22 & "'!B5:J5"))} -> 16074.25 | D22: 29669.2 | E22: -13594.95 | F22: -0.45821761 | G22: 32307.32 | H22: -16233.07 | I22: -0.50245796 | J22: 1. Relay tripped at 3:50 Am on 01/30 and auto reclosed in minutes | K22: 1. SR080187
A23: Woodchuck | B23: MA | C23: {=IF(INDIRECT("'" & $A23 & "'!B5:J5")="", "", INDIRECT("'" & $A23 & "'!B5:J5"))} -> 33788 | D23: 71556.68 | E23: -37768.68 | F23: -0.52781487 | G23: 96097.7 | H23: -62309.7 | I23: -0.64839949
A24: Total | C24: =SUM(C3:C23) -> 1074735.8 | D24: =SUM(D3:D23) -> 1953737.2 | E24: =C24-D24 -> -879001.43 | F24: =IFERROR(E24/D24, 0) -> -0.44990771 | G24: =SUM(G3:G23) -> 2327559.5 | H24: =C24-G24 -> -1252823.7 | I24: =IFERROR(H24/G24, 0) -> -0.53825637
A26: Values in gold exceed expected or forecasted by 10% or more.
A28: Values in red are below expected or forecasted by 10% or more.

Sheet 02-2024
A1: {=portfolio} -> 38 DN | C1: 02-2024 Actual v. Expected | G1: 02-2024 Actual v. Forecasted | J1: NOTES | K1: SR
A2: Site | B2: State | C2: Actual | D2: Expected | E2: Delta | F2: % | G2: Forecasted | H2: Delta | I2: %
A3: {=Sites[Site]} -> 6th St. | B3: {=Sites[State]} -> CA | C3: {=IF(INDIRECT("'" & $A3 & "'!B6:J6")="", "", INDIRECT("'" & $A3 & "'!B6:J6"))} | E3: 0 | F3: 0 | H3: 0 | I3: 0
A4: Barton Acres | B4: MA | C4: {=IF(INDIRECT("'" & $A4 & "'!B6:J6")="", "", INDIRECT("'" & $A4 & "'!B6:J6"))} | E4: 0 | F4: 0 | H4: 0 | I4: 0
A5: Bowden | B5: MA | C5: {=IF(INDIRECT("'" & $A5 & "'!B6:J6")="", "", INDIRECT("'" & $A5 & "'!B6:J6"))} | E5: 0 | F5: 0 | H5: 0 | I5: 0
A6: Blair Wire Village | B6: MA | C6: {=IF(INDIRECT("'" & $A6 & "'!B6:J6")="", "", INDIRECT("'" & $A6 & "'!B6:J6"))} | E6: 0 | F6: 0 | H6: 0 | I6: 0
A7: Boutilier | B7: MA | C7: {=IF(INDIRECT("'" & $A7 & "'!B6:J6")="", "", INDIRECT("'" & $A7 & "'!B6:J6"))} | E7: 0 | F7: 0 | H7: 0 | I7: 0
A8: Cherry Valley | B8: MA | C8: {=IF(INDIRECT("'" & $A8 & "'!B6:J6")="", "", INDIRECT("'" & $A8 & "'!B6:J6"))} | E8: 0 | F8: 0 | H8: 0 | I8: 0
A9: Cohasse | B9: MA | C9: {=IF(INDIRECT("'" & $A9 & "'!B6:J6")="", "", INDIRECT("'" & $A9 & "'!B6:J6"))} | E9: 0 | F9: 0 | H9: 0 | I9: 0
A10: ISM Dighton Solar 2 | B10: MA | C10: {=IF(INDIRECT("'" & $A10 & "'!B6:J6")="", "", INDIRECT("'" & $A10 & "'!B6:J6"))} | E10: 0 | F10: 0 | H10: 0 | I10: 0
A11: Dudley River 1 | B11: MA | C11: {=IF(INDIRECT("'" & $A11 & "'!B6:J6")="", "", INDIRECT("'" & $A11 & "'!B6:J6"))} | E11: 0 | F11: 0 | H11: 0 | I11: 0
A12: Dudley River 2 | B12: MA | C12: {=IF(INDIRECT("'" & $A12 & "'!B6:J6")="", "", INDIRECT("'" & $A12 & "'!B6:J6"))} | E12: 0 | F12: 0 | H12: 0 | I12: 0
A13: Dudley River 3 | B13: MA | C13: {=IF(INDIRECT("'" & $A13 & "'!B6:J6")="", "", INDIRECT("'" & $A13 & "'!B6:J6"))} | E13: 0 | F13: 0 | H13: 0 | I13: 0
A14: Flint Pond | B14: MA | C14: {=IF(INDIRECT("'" & $A14 & "'!B6:J6")="", "", INDIRECT("'" & $A14 & "'!B6:J6"))} | E14: 0 | F14: 0 | H14: 0 | I14: 0
A15: Incom | B15: MA | C15: {=IF(INDIRECT("'" & $A15 & "'!B6:J6")="", "", INDIRECT("'" & $A15 & "'!B6:J6"))} | E15: 0 | F15: 0 | H15: 0 | I15: 0
... A23: Woodchuck | B23: MA | C23: {=IF(INDIRECT("'" & $A23 & "'!B6:J6")="", "", INDIRECT("'" & $A23 & "'!B6:J6"))} | E23: 0 | F23: 0 | H23: 0 | I23: 0
A24: Total | C24: =SUM(C3:C23) -> 0 | D24: =SUM(D3:D23) -> 0 | E24: =C24-D24 -> 0 | F24: =IFERROR(E24/D24, 0) -> 0 | G24: =SUM(G3:G23) -> 0 | H24: =C24-G24 -> 0 | I24: =IFERROR(H24/G24, 0) -> 0
A26: Values in gold exceed expected or forecasted by 10% or more.
A28: Values in red are below expected or forecasted by 10% or more.

Sheet 03-2024
A1: {=portfolio} -> 38 DN | C1: 03-2024 Actual v. Expected | G1: 03-2024 Actual v. Forecasted | J1: NOTES | K1: SR
A2: Site | B2: State | C2: Actual | D2: Expected | E2: Delta | F2: % | G2: Forecasted | H2: Delta | I2: %
A3: {=Sites[Site]} -> 6th St. | B3: {=Sites[State]} -> CA | C3: {=IF(INDIRECT("'" & $A3 & "'!B7:J7")="", "", INDIRECT("'" & $A3 & "'!B7:J7"))} | E3: 0 | F3: 0 | H3: 0 | I3: 0
A4: Barton Acres | B4: MA | C4: {=IF(INDIRECT("'" & $A4 & "'!B7:J7")="", "", INDIRECT("'" & $A4 & "'!B7:J7"))} | E4: 0 | F4: 0 | H4: 0 | I4: 0
A5: Bowden | B5: MA | C5: {=IF(INDIRECT("'" & $A5 & "'!B7:J7")="", "", INDIRECT("'" & $A5 & "'!B7:J7"))} | E5: 0 | F5: 0 | H5: 0 | I5: 0
A6: Blair Wire Village | B6: MA | C6: {=IF(INDIRECT("'" & $A6 & "'!B7:J7")="", "", INDIRECT("'" & $A6 & "'!B7:J7"))} | E6: 0 | F6: 0 | H6: 0 | I6: 0
A7: Boutilier | B7: MA | C7: {=IF(INDIRECT("'" & $A7 & "'!B7:J7")="", "", INDIRECT("'" & $A7 & "'!B7:J7"))} | E7: 0 | F7: 0 | H7: 0 | I7: 0
A8: Cherry Valley | B8: MA | C8: {=IF(INDIRECT("'" & $A8 & "'!B7:J7")="", "", INDIRECT("'" & $A8 & "'!B7:J7"))} | E8: 0 | F8: 0 | H8: 0 | I8: 0
A9: Cohasse | B9: MA | C9: {=IF(INDIRECT("'" & $A9 & "'!B7:J7")="", "", INDIRECT("'" & $A9 & "'!B7:J7"))} | E9: 0 | F9: 0 | H9: 0 | I9: 0
A10: ISM Dighton Solar 2 | B10: MA | C10: {=IF(INDIRECT("'" & $A10 & "'!B7:J7")="", "", INDIRECT("'" & $A10 & "'!B7:J7"))} | E10: 0 | F10: 0 | H10: 0 | I10: 0
A11: Dudley River 1 | B11: MA | C11: {=IF(INDIRECT("'" & $A11 & "'!B7:J7")="", "", INDIRECT("'" & $A11 & "'!B7:J7"))} | E11: 0 | F11: 0 | H11: 0 | I11: 0
A12: Dudley River 2 | B12: MA | C12: {=IF(INDIRECT("'" & $A12 & "'!B7:J7")="", "", INDIRECT("'" & $A12 & "'!B7:J7"))} | E12: 0 | F12: 0 | H12: 0 | I12: 0
A13: Dudley River 3 | B13: MA | C13: {=IF(INDIRECT("'" & $A13 & "'!B7:J7")="", "", INDIRECT("'" & $A13 & "'!B7:J7"))} | E13: 0 | F13: 0 | H13: 0 | I13: 0
A14: Flint Pond | B14: MA | C14: {=IF(INDIRECT("'" & $A14 & "'!B7:J7")="", "", INDIRECT("'" & $A14 & "'!B7:J7"))} | E14: 0 | F14: 0 | H14: 0 | I14: 0
A15: Incom | B15: MA | C15: {=IF(INDIRECT("'" & $A15 & "'!B7:J7")="", "", INDIRECT("'" & $A15 & "'!B7:J7"))} | E15: 0 | F15: 0 | H15: 0 | I15: 0
... A23: Woodchuck | B23: MA | C23: {=IF(INDIRECT("'" & $A23 & "'!B7:J7")="", "", INDIRECT("'" & $A23 & "'!B7:J7"))} | E23: 0 | F23: 0 | H23: 0 | I23: 0
A24: Total | C24: =SUM(C3:C23) -> 0 | D24: =SUM(D3:D23) -> 0 | E24: =C24-D24 -> 0 | F24: =IFERROR(E24/D24, 0) -> 0 | G24: =SUM(G3:G23) -> 0 | H24: =C24-G24 -> 0 | I24: =IFERROR(H24/G24, 0) -> 0
A26: Values in gold exceed expected or forecasted by 10% or more.
A28: Values in red are below expected or forecasted by 10% or more.

Sheet 04-2024
A1: {=portfolio} -> 38 DN | C1: 04-2023 Actual v. Expected | G1: 04-2023 Actual v. Forecasted | J1: NOTES | K1: SR
A2: Site | B2: State | C2: Actual | D2: Expected | E2: Delta | F2: % | G2: Forecasted | H2: Delta | I2: %
A3: {=Sites[Site]} -> 6th St. | B3: {=Sites[State]} -> CA | C3: {=IF(INDIRECT("'" & $A3 & "'!B8:J8")="", "", INDIRECT("'" & $A3 & "'!B8:J8"))} | E3: 0 | F3: 0 | H3: 0 | I3: 0
A4: Barton Acres | B4: MA | C4: {=IF(INDIRECT("'" & $A4 & "'!B8:J8")="", "", INDIRECT("'" & $A4 & "'!B8:J8"))} | E4: 0 | F4: 0 | H4: 0 | I4: 0
A5: Bowden | B5: MA | C5: {=IF(INDIRECT("'" & $A5 & "'!B8:J8")="", "", INDIRECT("'" & $A5 & "'!B8:J8"))} | E5: 0 | F5: 0 | H5: 0 | I5: 0
A6: Blair Wire Village | B6: MA | C6: {=IF(INDIRECT("'" & $A6 & "'!B8:J8")="", "", INDIRECT("'" & $A6 & "'!B8:J8"))} | E6: 0 | F6: 0 | H6: 0 | I6: 0
A7: Boutilier | B7: MA | C7: {=IF(INDIRECT("'" & $A7 & "'!B8:J8")="", "", INDIRECT("'" & $A7 & "'!B8:J8"))} | E7: 0 | F7: 0 | H7: 0 | I7: 0
A8: Cherry Valley | B8: MA | C8: {=IF(INDIRECT("'" & $A8 & "'!B8:J8")="", "", INDIRECT("'" & $A8 & "'!B8:J8"))} | E8: 0 | F8: 0 | H8: 0 | I8: 0
A9: Cohasse | B9: MA | C9: {=IF(INDIRECT("'" & $A9 & "'!B8:J8")="", "", INDIRECT("'" & $A9 & "'!B8:J8"))} | E9: 0 | F9: 0 | H9: 0 | I9: 0
A10: ISM Dighton Solar 2 | B10: MA | C10: {=IF(INDIRECT("'" & $A10 & "'!B8:J8")="", "", INDIRECT("'" & $A10 & "'!B8:J8"))} | E10: 0 | F10: 0 | H10: 0 | I10: 0
A11: Dudley River 1 | B11: MA | C11: {=IF(INDIRECT("'" & $A11 & "'!B8:J8")="", "", INDIRECT("'" & $A11 & "'!B8:J8"))} | E11: 0 | F11: 0 | H11: 0 | I11: 0
A12: Dudley River 2 | B12: MA | C12: {=IF(INDIRECT("'" & $A12 & "'!B8:J8")="", "", INDIRECT("'" & $A12 & "'!B8:J8"))} | E12: 0 | F12: 0 | H12: 0 | I12: 0
A13: Dudley River 3 | B13: MA | C13: {=IF(INDIRECT("'" & $A13 & "'!B8:J8")="", "", INDIRECT("'" & $A13 & "'!B8:J8"))} | E13: 0 | F13: 0 | H13: 0 | I13: 0
A14: Flint Pond | B14: MA | C14: {=IF(INDIRECT("'" & $A14 & "'!B8:J8")="", "", INDIRECT("'" & $A14 & "'!B8:J8"))} | E14: 0 | F14: 0 | H14: 0 | I14: 0
A15: Incom | B15: MA | C15: {=IF(INDIRECT("'" & $A15 & "'!B8:J8")="", "", INDIRECT("'" & $A15 & "'!B8:J8"))} | E15: 0 | F15: 0 | H15: 0 | I15: 0
... A23: Woodchuck | B23: MA | C23: {=IF(INDIRECT("'" & $A23 & "'!B8:J8")="", "", INDIRECT("'" & $A23 & "'!B8:J8"))} | E23: 0 | F23: 0 | H23: 0 | I23: 0
A24: Total | C24: =SUM(C3:C23) -> 0 | D24: =SUM(D3:D23) -> 0 | E24: =C24-D24 -> 0 | F24: =IFERROR(E24/D24, 0) -> 0 | G24: =SUM(G3:G23) -> 0 | H24: =C24-G24 -> 0 | I24: =IFERROR(H24/G24, 0) -> 0
A26: Values in gold exceed expected or forecasted by 10% or more.
A28: Values in red are below expected or forecasted by 10% or more.

Sheet 05-2024
A1: {=portfolio} -> 38 DN | C1: 05-2024 Actual v. Expected | G1: 05-2024 Actual v. Forecasted | J1: NOTES | K1: SR
A2: Site | B2: State | C2: Actual | D2: Expected | E2: Delta | F2: % | G2: Forecasted | H2: Delta | I2: %
A3: {=Sites[Site]} -> 6th St. | B3: {=Sites[State]} -> CA | C3: {=IF(INDIRECT("'" & $A3 & "'!B9:J9")="", "", INDIRECT("'" & $A3 & "'!B9:J9"))} | E3: 0 | F3: 0 | H3: 0 | I3: 0
A4: Barton Acres | B4: MA | C4: {=IF(INDIRECT("'" & $A4 & "'!B9:J9")="", "", INDIRECT("'" & $A4 & "'!B9:J9"))} | E4: 0 | F4: 0 | H4: 0 | I4: 0
A5: Bowden | B5: MA | C5: {=IF(INDIRECT("'" & $A5 & "'!B9:J9")="", "", INDIRECT("'" & $A5 & "'!B9:J9"))} | E5: 0 | F5: 0 | H5: 0 | I5: 0
A6: Blair Wire Village | B6: MA | C6: {=IF(INDIRECT("'" & $A6 & "'!B9:J9")="", "", INDIRECT("'" & $A6 & "'!B9:J9"))} | E6: 0 | F6: 0 | H6: 0 | I6: 0
A7: Boutilier | B7: MA | C7: {=IF(INDIRECT("'" & $A7 & "'!B9:J9")="", "", INDIRECT("'" & $A7 & "'!B9:J9"))} | E7: 0 | F7: 0 | H7: 0 | I7: 0
A8: Cherry Valley | B8: MA | C8: {=IF(INDIRECT("'" & $A8 & "'!B9:J9")="", "", INDIRECT("'" & $A8 & "'!B9:J9"))} | E8: 0 | F8: 0 | H8: 0 | I8: 0
A9: Cohasse | B9: MA | C9: {=IF(INDIRECT("'" & $A9 & "'!B9:J9")="", "", INDIRECT("'" & $A9 & "'!B9:J9"))} | E9: 0 | F9: 0 | H9: 0 | I9: 0
A10: ISM Dighton Solar 2 | B10: MA | C10: {=IF(INDIRECT("'" & $A10 & "'!B9:J9")="", "", INDIRECT("'" & $A10 & "'!B9:J9"))} | E10: 0 | F10: 0 | H10: 0 | I10: 0
A11: Dudley River 1 | B11: MA | C11: {=IF(INDIRECT("'" & $A11 & "'!B9:J9")="", "", INDIRECT("'" & $A11 & "'!B9:J9"))} | E11: 0 | F11: 0 | H11: 0 | I11: 0
A12: Dudley River 2 | B12: MA | C12: {=IF(INDIRECT("'" & $A12 & "'!B9:J9")="", "", INDIRECT("'" & $A12 & "'!B9:J9"))} | E12: 0 | F12: 0 | H12: 0 | I12: 0
A13: Dudley River 3 | B13: MA | C13: {=IF(INDIRECT("'" & $A13 & "'!B9:J9")="", "", INDIRECT("'" & $A13 & "'!B9:J9"))} | E13: 0 | F13: 0 | H13: 0 | I13: 0
A14: Flint Pond | B14: MA | C14: {=IF(INDIRECT("'" & $A14 & "'!B9:J9")="", "", INDIRECT("'" & $A14 & "'!B9:J9"))} | E14: 0 | F14: 0 | H14: 0 | I14: 0
A15: Incom | B15: MA | C15: {=IF(INDIRECT("'" & $A15 & "'!B9:J9")="", "", INDIRECT("'" & $A15 & "'!B9:J9"))} | E15: 0 | F15: 0 | H15: 0 | I15: 0
... A23: Woodchuck | B23: MA | C23: {=IF(INDIRECT("'" & $A23 & "'!B9:J9")="", "", INDIRECT("'" & $A23 & "'!B9:J9"))} | E23: 0 | F23: 0 | H23: 0 | I23: 0
A24: Total | C24: =SUM(C3:C23) -> 0 | D24: =SUM(D3:D23) -> 0 | E24: =C24-D24 -> 0 | F24: =IFERROR(E24/D24, 0) -> 0 | G24: =SUM(G3:G23) -> 0 | H24: =C24-G24 -> 0 | I24: =IFERROR(H24/G24, 0) -> 0
A26: Values in gold exceed expected or forecasted by 10% or more.
A28: Values in red are below expected or forecasted by 10% or more.

Sheet 06-2024
A1: {=portfolio} -> 38 DN | C1: 06-2024 Actual v. Expected | G1: 06-2024 Actual v. Forecasted | J1: NOTES | K1: SR
A2: Site | B2: State | C2: Actual | D2: Expected | E2: Delta | F2: % | G2: Forecasted | H2: Delta | I2: %
A3: {=Sites[Site]} -> 6th St. | B3: {=Sites[State]} -> CA | C3: {=IF(INDIRECT("'" & $A3 & "'!B10:J10")="", "", INDIRECT("'" & $A3 & "'!B10:J10"))} | E3: 0 | F3: 0 | H3: 0 | I3: 0
A4: Barton Acres | B4: MA | C4: {=IF(INDIRECT("'" & $A4 & "'!B10:J10")="", "", INDIRECT("'" & $A4 & "'!B10:J10"))} | E4: 0 | F4: 0 | H4: 0 | I4: 0
A5: Bowden | B5: MA | C5: {=IF(INDIRECT("'" & $A5 & "'!B10:J10")="", "", INDIRECT("'" & $A5 & "'!B10:J10"))} | E5: 0 | F5: 0 | H5: 0 | I5: 0
A6: Blair Wire Village | B6: MA | C6: {=IF(INDIRECT("'" & $A6 & "'!B10:J10")="", "", INDIRECT("'" & $A6 & "'!B10:J10"))} | E6: 0 | F6: 0 | H6: 0 | I6: 0
A7: Boutilier | B7: MA | C7: {=IF(INDIRECT("'" & $A7 & "'!B10:J10")="", "", INDIRECT("'" & $A7 & "'!B10:J10"))} | E7: 0 | F7: 0 | H7: 0 | I7: 0
A8: Cherry Valley | B8: MA | C8: {=IF(INDIRECT("'" & $A8 & "'!B10:J10")="", "", INDIRECT("'" & $A8 & "'!B10:J10"))} | E8: 0 | F8: 0 | H8: 0 | I8: 0
A9: Cohasse | B9: MA | C9: {=IF(INDIRECT("'" & $A9 & "'!B10:J10")="", "", INDIRECT("'" & $A9 & "'!B10:J10"))} | E9: 0 | F9: 0 | H9: 0 | I9: 0
A10: ISM Dighton Solar 2 | B10: MA | C10: {=IF(INDIRECT("'" & $A10 & "'!B10:J10")="", "", INDIRECT("'" & $A10 & "'!B10:J10"))} | E10: 0 | F10: 0 | H10: 0 | I10: 0
A11: Dudley River 1 | B11: MA | C11: {=IF(INDIRECT("'" & $A11 & "'!B10:J10")="", "", INDIRECT("'" & $A11 & "'!B10:J10"))} | E11: 0 | F11: 0 | H11: 0 | I11: 0
A12: Dudley River 2 | B12: MA | C12: {=IF(INDIRECT("'" & $A12 & "'!B10:J10")="", "", INDIRECT("'" & $A12 & "'!B10:J10"))} | E12: 0 | F12: 0 | H12: 0 | I12: 0
A13: Dudley River 3 | B13: MA | C13: {=IF(INDIRECT("'" & $A13 & "'!B10:J10")="", "", INDIRECT("'" & $A13 & "'!B10:J10"))} | E13: 0 | F13: 0 | H13: 0 | I13: 0
A14: Flint Pond | B14: MA | C14: {=IF(INDIRECT("'" & $A14 & "'!B10:J10")="", "", INDIRECT("'" & $A14 & "'!B10:J10"))} | E14: 0 | F14: 0 | H14: 0 | I14: 0
A15: Incom | B15: MA | C15: {=IF(INDIRECT("'" & $A15 & "'!B10:J10")="", "", INDIRECT("'" & $A15 & "'!B10:J10"))} | E15: 0 | F15: 0 | H15: 0 | I15: 0
... A23: Woodchuck | B23: MA | C23: {=IF(INDIRECT("'" & $A23 & "'!B10:J10")="", "", INDIRECT("'" & $A23 & "'!B10:J10"))} | E23: 0 | F23: 0 | H23: 0 | I23: 0
A24: Total | C24: =SUM(C3:C23) -> 0 | D24: =SUM(D3:D23) -> 0 | E24: =C24-D24 -> 0 | F24: =IFERROR(E24/D24, 0) -> 0 | G24: =SUM(G3:G23) -> 0 | H24: =C24-G24 -> 0 | I24: =IFERROR(H24/G24, 0) -> 0
A26: Values in gold exceed expected or forecasted by 10% or more.
A28: Values in red are below expected or forecasted by 10% or more.

Sheet 07-2024
A1: {=portfolio} -> 38 DN | C1: 07-2024 Actual v. Expected | G1: 07-2024 Actual v. Forecasted | J1: NOTES | K1: SR
A2: Site | B2: State | C2: Actual | D2: Expected | E2: Delta | F2: % | G2: Forecasted | H2: Delta | I2: %
A3: {=Sites[Site]} -> 6th St. | B3: {=Sites[State]} -> CA | C3: {=IF(INDIRECT("'" & $A3 & "'!B11:J11")="", "", INDIRECT("'" & $A3 & "'!B11:J11"))} | E3: 0 | F3: 0 | H3: 0 | I3: 0
A4: Barton Acres | B4: MA | C4: {=IF(INDIRECT("'" & $A4 & "'!B11:J11")="", "", INDIRECT("'" & $A4 & "'!B11:J11"))} | E4: 0 | F4: 0 | H4: 0 | I4: 0
A5: Bowden | B5: MA | C5: {=IF(INDIRECT("'" & $A5 & "'!B11:J11")="", "", INDIRECT("'" & $A5 & "'!B11:J11"))} | E5: 0 | F5: 0 | H5: 0 | I5: 0
A6: Blair Wire Village | B6: MA | C6: {=IF(INDIRECT("'" & $A6 & "'!B11:J11")="", "", INDIRECT("'" & $A6 & "'!B11:J11"))} | E6: 0 | F6: 0 | H6: 0 | I6: 0
A7: Boutilier | B7: MA | C7: {=IF(INDIRECT("'" & $A7 & "'!B11:J11")="", "", INDIRECT("'" & $A7 & "'!B11:J11"))} | E7: 0 | F7: 0 | H7: 0 | I7: 0
A8: Cherry Valley | B8: MA | C8: {=IF(INDIRECT("'" & $A8 & "'!B11:J11")="", "", INDIRECT("'" & $A8 & "'!B11:J11"))} | E8: 0 | F8: 0 | H8: 0 | I8: 0
A9: Cohasse | B9: MA | C9: {=IF(INDIRECT("'" & $A9 & "'!B11:J11")="", "", INDIRECT("'" & $A9 & "'!B11:J11"))} | E9: 0 | F9: 0 | H9: 0 | I9: 0
A10: ISM Dighton Solar 2 | B10: MA | C10: {=IF(INDIRECT("'" & $A10 & "'!B11:J11")="", "", INDIRECT("'" & $A10 & "'!B11:J11"))} | E10: 0 | F10: 0 | H10: 0 | I10: 0
A11: Dudley River 1 | B11: MA | C11: {=IF(INDIRECT("'" & $A11 & "'!B11:J11")="", "", INDIRECT("'" & $A11 & "'!B11:J11"))} | E11: 0 | F11: 0 | H11: 0 | I11: 0
A12: Dudley River 2 | B12: MA | C12: {=IF(INDIRECT("'" & $A12 & "'!B11:J11")="", "", INDIRECT("'" & $A12 & "'!B11:J11"))} | E12: 0 | F12: 0 | H12: 0 | I12: 0
A13: Dudley River 3 | B13: MA | C13: {=IF(INDIRECT("'" & $A13 & "'!B11:J11")="", "", INDIRECT("'" & $A13 & "'!B11:J11"))} | E13: 0 | F13: 0 | H13: 0 | I13: 0
A14: Flint Pond | B14: MA | C14: {=IF(INDIRECT("'" & $A14 & "'!B11:J11")="", "", INDIRECT("'" & $A14 & "'!B11:J11"))} | E14: 0 | F14: 0 | H14: 0 | I14: 0
A15: Incom | B15: MA | C15: {=IF(INDIRECT("'" & $A15 & "'!B11:J11")="", "", INDIRECT("'" & $A15 & "'!B11:J11"))} | E15: 0 | F15: 0 | H15: 0 | I15: 0
... A23: Woodchuck | B23: MA | C23: {=IF(INDIRECT("'" & $A23 & "'!B11:J11")="", "", INDIRECT("'" & $A23 & "'!B11:J11"))} | E23: 0 | F23: 0 | H23: 0 | I23: 0
A24: Total | C24: =SUM(C3:C23) -> 0 | D24: =SUM(D3:D23) -> 0 | E24: =C24-D24 -> 0 | F24: =IFERROR(E24/D24, 0) -> 0 | G24: =SUM(G3:G23) -> 0 | H24: =C24-G24 -> 0 | I24: =IFERROR(H24/G24, 0) -> 0
A26: Values in gold exceed expected or forecasted by 10% or more.
A28: Values in red are below expected or forecasted by 10% or more.

Sheet 08-2024
A1: {=portfolio} -> 38 DN | C1: 08-2024 Actual v. Expected | G1: 08-2024 Actual v. Forecasted | J1: NOTES | K1: SR
A2: Site | B2: State | C2: Actual | D2: Expected | E2: Delta | F2: % | G2: Forecasted | H2: Delta | I2: %
A3: {=Sites[Site]} -> 6th St. | B3: {=Sites[State]} -> CA | C3: {=IF(INDIRECT("'" & $A3 & "'!B12:J12")="", "", INDIRECT("'" & $A3 & "'!B12:J12"))} | E3: 0 | F3: 0 | H3: 0 | I3: 0
A4: Barton Acres | B4: MA | C4: {=IF(INDIRECT("'" & $A4 & "'!B12:J12")="", "", INDIRECT("'" & $A4 & "'!B12:J12"))} | E4: 0 | F4: 0 | H4: 0 | I4: 0
A5: Bowden | B5: MA | C5: {=IF(INDIRECT("'" & $A5 & "'!B12:J12")="", "", INDIRECT("'" & $A5 & "'!B12:J12"))} | E5: 0 | F5: 0 | H5: 0 | I5: 0
A6: Blair Wire Village | B6: MA | C6: {=IF(INDIRECT("'" & $A6 & "'!B12:J12")="", "", INDIRECT("'" & $A6 & "'!B12:J12"))} | E6: 0 | F6: 0 | H6: 0 | I6: 0
A7: Boutilier | B7: MA | C7: {=IF(INDIRECT("'" & $A7 & "'!B12:J12")="", "", INDIRECT("'" & $A7 & "'!B12:J12"))} | E7: 0 | F7: 0 | H7: 0 | I7: 0
A8: Cherry Valley | B8: MA | C8: {=IF(INDIRECT("'" & $A8 & "'!B12:J12")="", "", INDIRECT("'" & $A8 & "'!B12:J12"))} | E8: 0 | F8: 0 | H8: 0 | I8: 0
A9: Cohasse | B9: MA | C9: {=IF(INDIRECT("'" & $A9 & "'!B12:J12")="", "", INDIRECT("'" & $A9 & "'!B12:J12"))} | E9: 0 | F9: 0 | H9: 0 | I9: 0
A10: ISM Dighton Solar 2 | B10: MA | C10: {=IF(INDIRECT("'" & $A10 & "'!B12:J12")="", "", INDIRECT("'" & $A10 & "'!B12:J12"))} | E10: 0 | F10: 0 | H10: 0 | I10: 0
A11: Dudley River 1 | B11: MA | C11: {=IF(INDIRECT("'" & $A11 & "'!B12:J12")="", "", INDIRECT("'" & $A11 & "'!B12:J12"))} | E11: 0 | F11: 0 | H11: 0 | I11: 0
A12: Dudley River 2 | B12: MA | C12: {=IF(INDIRECT("'" & $A12 & "'!B12:J12")="", "", INDIRECT("'" & $A12 & "'!B12:J12"))} | E12: 0 | F12: 0 | H12: 0 | I12: 0
A13: Dudley River 3 | B13: MA | C13: {=IF(INDIRECT("'" & $A13 & "'!B12:J12")="", "", INDIRECT("'" & $A13 & "'!B12:J12"))} | E13: 0 | F13: 0 | H13: 0 | I13: 0
A14: Flint Pond | B14: MA | C14: {=IF(INDIRECT("'" & $A14 & "'!B12:J12")="", "", INDIRECT("'" & $A14 & "'!B12:J12"))} | E14: 0 | F14: 0 | H14: 0 | I14: 0
A15: Incom | B15: MA | C15: {=IF(INDIRECT("'" & $A15 & "'!B12:J12")="", "", INDIRECT("'" & $A15 & "'!B12:J12"))} | E15: 0 | F15: 0 | H15: 0 | I15: 0
... A23: Woodchuck | B23: MA | C23: {=IF(INDIRECT("'" & $A23 & "'!B12:J12")="", "", INDIRECT("'" & $A23 & "'!B12:J12"))} | E23: 0 | F23: 0 | H23: 0 | I23: 0
A24: Total | C24: =SUM(C3:C23) -> 0 | D24: =SUM(D3:D23) -> 0 | E24: =C24-D24 -> 0 | F24: =IFERROR(E24/D24, 0) -> 0 | G24: =SUM(G3:G23) -> 0 | H24: =C24-G24 -> 0 | I24: =IFERROR(H24/G24, 0) -> 0
A26: Values in gold exceed expected or forecasted by 10% or more.
A28: Values in red are below expected or forecasted by 10% or more.

Sheet 09-2024
A1: {=portfolio} -> 38 DN | C1: 09-2024 Actual v. Expected | G1: 09-2024 Actual v. Forecasted | J1: NOTES | K1: SR
A2: Site | B2: State | C2: Actual | D2: Expected | E2: Delta | F2: % | G2: Forecasted | H2: Delta | I2: %
A3: {=Sites[Site]} -> 6th St. | B3: {=Sites[State]} -> CA | C3: {=IF(INDIRECT("'" & $A3 & "'!B13:J13")="", "", INDIRECT("'" & $A3 & "'!B13:J13"))} | E3: 0 | F3: 0 | H3: 0 | I3: 0
A4: Barton Acres | B4: MA | C4: {=IF(INDIRECT("'" & $A4 & "'!B13:J13")="", "", INDIRECT("'" & $A4 & "'!B13:J13"))} | E4: 0 | F4: 0 | H4: 0 | I4: 0
A5: Bowden | B5: MA | C5: {=IF(INDIRECT("'" & $A5 & "'!B13:J13")="", "", INDIRECT("'" & $A5 & "'!B13:J13"))} | E5: 0 | F5: 0 | H5: 0 | I5: 0
A6: Blair Wire Village | B6: MA | C6: {=IF(INDIRECT("'" & $A6 & "'!B13:J13")="", "", INDIRECT("'" & $A6 & "'!B13:J13"))} | E6: 0 | F6: 0 | H6: 0 | I6: 0
A7: Boutilier | B7: MA | C7: {=IF(INDIRECT("'" & $A7 & "'!B13:J13")="", "", INDIRECT("'" & $A7 & "'!B13:J13"))} | E7: 0 | F7: 0 | H7: 0 | I7: 0
A8: Cherry Valley | B8: MA | C8: {=IF(INDIRECT("'" & $A8 & "'!B13:J13")="", "", INDIRECT("'" & $A8 & "'!B13:J13"))} | E8: 0 | F8: 0 | H8: 0 | I8: 0
A9: Cohasse | B9: MA | C9: {=IF(INDIRECT("'" & $A9 & "'!B13:J13")="", "", INDIRECT("'" & $A9 & "'!B13:J13"))} | E9: 0 | F9: 0 | H9: 0 | I9: 0
A10: ISM Dighton Solar 2 | B10: MA | C10: {=IF(INDIRECT("'" & $A10 & "'!B13:J13")="", "", INDIRECT("'" & $A10 & "'!B13:J13"))} | E10: 0 | F10: 0 | H10: 0 | I10: 0
A11: Dudley River 1 | B11: MA | C11: {=IF(INDIRECT("'" & $A11 & "'!B13:J13")="", "", INDIRECT("'" & $A11 & "'!B13:J13"))} | E11: 0 | F11: 0 | H11: 0 | I11: 0
A12: Dudley River 2 | B12: MA | C12: {=IF(INDIRECT("'" & $A12 & "'!B13:J13")="", "", INDIRECT("'" & $A12 & "'!B13:J13"))} | E12: 0 | F12: 0 | H12: 0 | I12: 0
A13: Dudley River 3 | B13: MA | C13: {=IF(INDIRECT("'" & $A13 & "'!B13:J13")="", "", INDIRECT("'" & $A13 & "'!B13:J13"))} | E13: 0 | F13: 0 | H13: 0 | I13: 0
A14: Flint Pond | B14: MA | C14: {=IF(INDIRECT("'" & $A14 & "'!B13:J13")="", "", INDIRECT("'" & $A14 & "'!B13:J13"))} | E14: 0 | F14: 0 | H14: 0 | I14: 0
