Workbook
Name JanActual: Jan!$C$3:$C$16
Name JanActual2: Jan!#REF!
Name JanExpected: Jan!$D$3:$D$16
Name JanExpectedDelta: Jan!$E$3:$E$16
Name JanExpectedPercent: Jan!$F$3:$F$16
Name JanExpPercent: Jan!$F$3:$F$16
Name JanForecasted: Jan!$G$3:$G$16
Name JanForecastedDelta: Jan!$H$3:$H$16
Name JanForecastedPercent: Jan!$I$3:$I$16
Name portfolio: Sites!$B$1:$B$1

Sheet YTD Total
A1: {=portfolio} -> Catalyze | C1: Year to Date 2024 Actual v. Expected | G1: Year to Date 2024 Forecasted
A2: Site | B2: State | C2: Actual | D2: Expected | E2: Delta | F2: % | G2: Forecasted | H2: Delta | I2: %
A3: {=Sites[Site]} -> Fresno - 3150 Shaw Ave | B3: {=Sites[State]} -> CA | C3: =SUM('1st Qtr'!C3, '2nd Qtr'!C3, '3rd Qtr'!C3, '4th Qtr'!C3) -> 40368.438 | D3: =SUM('1st Qtr'!D3, '2nd Qtr'!D3, '3rd Qtr'!D3, '4th Qtr'!D3) -> 39837.75 | E3: =C3-D3 -> 530.6875 | F3: =IFERROR(E3/D3, 0) -> 0.013321222 | G3: =SUM('1st Qtr'!G3, '2nd Qtr'!G3, '3rd Qtr'!G3, '4th Qtr'!G3) -> 48161.71 | H3: =C3-G3 -> -7793.2725 | I3: =IFERROR(H3/G3, 0) -> -0.1618147
A4: Adelanto - 1 Sheep Creek Road | B4: CA | C4: =SUM('1st Qtr'!C4, '2nd Qtr'!C4, '3rd Qtr'!C4, '4th Qtr'!C4) -> 80417 | D4: =SUM('1st Qtr'!D4, '2nd Qtr'!D4, '3rd Qtr'!D4, '4th Qtr'!D4) -> 352340 | E4: =C4-D4 -> -271923 | F4: =IFERROR(E4/D4, 0) -> -0.77176307 | G4: =SUM('1st Qtr'!G4, '2nd Qtr'!G4, '3rd Qtr'!G4, '4th Qtr'!G4) -> 479912 | H4: =C4-G4 -> -399495 | I4: =IFERROR(H4/G4, 0) -> -0.83243386
A5: Blackstone - 83 Federal Street | B5: MA | C5: =SUM('1st Qtr'!C5, '2nd Qtr'!C5, '3rd Qtr'!C5, '4th Qtr'!C5) -> 106968 | D5: =SUM('1st Qtr'!D5, '2nd Qtr'!D5, '3rd Qtr'!D5, '4th Qtr'!D5) -> 0 | E5: =C5-D5 -> 106968 | F5: =IFERROR(E5/D5, 0) -> 0 | G5: =SUM('1st Qtr'!G5, '2nd Qtr'!G5, '3rd Qtr'!G5, '4th Qtr'!G5) -> 352931.5 | H5: =C5-G5 -> -245963.5 | I5: =IFERROR(H5/G5, 0) -> -0.69691569
A6: Charlton - 299 Worcester Road | B6: MA | C6: =SUM('1st Qtr'!C6, '2nd Qtr'!C6, '3rd Qtr'!C6, '4th Qtr'!C6) -> 11889 | D6: =SUM('1st Qtr'!D6, '2nd Qtr'!D6, '3rd Qtr'!D6, '4th Qtr'!D6) -> 21739.23 | E6: =C6-D6 -> -9850.23 | F6: =IFERROR(E6/D6, 0) -> -0.4531085 | G6: =SUM('1st Qtr'!G6, '2nd Qtr'!G6, '3rd Qtr'!G6, '4th Qtr'!G6) -> 32151.25 | H6: =C6-G6 -> -20262.25 | I6: =IFERROR(H6/G6, 0) -> -0.63021655
A7: Wareham - 8 Thatcher Drive | B7: MA | C7: =SUM('1st Qtr'!C7, '2nd Qtr'!C7, '3rd Qtr'!C7, '4th Qtr'!C7) -> 5780.1687 | D7: =SUM('1st Qtr'!D7, '2nd Qtr'!D7, '3rd Qtr'!D7, '4th Qtr'!D7) -> 7080.061 | E7: =C7-D7 -> -1299.8923 | F7: =IFERROR(E7/D7, 0) -> -0.18359903 | G7: =SUM('1st Qtr'!G7, '2nd Qtr'!G7, '3rd Qtr'!G7, '4th Qtr'!G7) -> 8785.329 | H7: =C7-G7 -> -3005.1603 | I7: =IFERROR(H7/G7, 0) -> -0.34206577
A8: West Yarmouth - 42 Mid Tech | B8: MA | C8: =SUM('1st Qtr'!C8, '2nd Qtr'!C8, '3rd Qtr'!C8, '4th Qtr'!C8) -> 4426.7571 | D8: =SUM('1st Qtr'!D8, '2nd Qtr'!D8, '3rd Qtr'!D8, '4th Qtr'!D8) -> 5459.478 | E8: =C8-D8 -> -1032.7209 | F8: =IFERROR(E8/D8, 0) -> -0.1891611 | G8: =SUM('1st Qtr'!G8, '2nd Qtr'!G8, '3rd Qtr'!G8, '4th Qtr'!G8) -> 6769.56 | H8: =C8-G8 -> -2342.8029 | I8: =IFERROR(H8/G8, 0) -> -0.34607905
A9: Harrison - 130 Union Street | B9: NY | C9: =SUM('1st Qtr'!C9, '2nd Qtr'!C9, '3rd Qtr'!C9, '4th Qtr'!C9) -> 5693.0625 | D9: =SUM('1st Qtr'!D9, '2nd Qtr'!D9, '3rd Qtr'!D9, '4th Qtr'!D9) -> 9025.686 | E9: =C9-D9 -> -3332.6235 | F9: =IFERROR(E9/D9, 0) -> -0.3692377 | G9: =SUM('1st Qtr'!G9, '2nd Qtr'!G9, '3rd Qtr'!G9, '4th Qtr'!G9) -> 10708.14 | H9: =C9-G9 -> -5015.0775 | I9: =IFERROR(H9/G9, 0) -> -0.46834254
A10: Staten Island - Ellis Storage | B10: NY | C10: =SUM('1st Qtr'!C10, '2nd Qtr'!C10, '3rd Qtr'!C10, '4th Qtr'!C10) -> 12897.375 | D10: =SUM('1st Qtr'!D10, '2nd Qtr'!D10, '3rd Qtr'!D10, '4th Qtr'!D10) -> 21330.59 | E10: =C10-D10 -> -8433.215 | F10: =IFERROR(E10/D10, 0) -> -0.39535779 | G10: =SUM('1st Qtr'!G10, '2nd Qtr'!G10, '3rd Qtr'!G10, '4th Qtr'!G10) -> 23412.4 | H10: =C10-G10 -> -10515.025 | I10: =IFERROR(H10/G10, 0) -> -0.44912205
A11: Amherst - 595 Scholles Road | B11: NY | C11: =SUM('1st Qtr'!C11, '2nd Qtr'!C11, '3rd Qtr'!C11, '4th Qtr'!C11) -> 99935 | D11: =SUM('1st Qtr'!D11, '2nd Qtr'!D11, '3rd Qtr'!D11, '4th Qtr'!D11) -> 131383.6 | E11: =C11-D11 -> -31448.6 | F11: =IFERROR(E11/D11, 0) -> -0.23936473 | G11: =SUM('1st Qtr'!G11, '2nd Qtr'!G11, '3rd Qtr'!G11, '4th Qtr'!G11) -> 286492 | H11: =C11-G11 -> -186557 | I11: =IFERROR(H11/G11, 0) -> -0.651177
A12: Lancaster 1 - Gunnville Road | B12: NY | C12: =SUM('1st Qtr'!C12, '2nd Qtr'!C12, '3rd Qtr'!C12, '4th Qtr'!C12) -> 0 | D12: =SUM('1st Qtr'!D12, '2nd Qtr'!D12, '3rd Qtr'!D12, '4th Qtr'!D12) -> 0 | E12: =C12-D12 -> 0 | F12: =IFERROR(E12/D12, 0) -> 0 | G12: =SUM('1st Qtr'!G12, '2nd Qtr'!G12, '3rd Qtr'!G12, '4th Qtr'!G12) -> 0 | H12: =C12-G12 -> 0 | I12: =IFERROR(H12/G12, 0) -> 0
A13: Lancaster 2 - Shisler Road | B13: NY | C13: =SUM('1st Qtr'!C13, '2nd Qtr'!C13, '3rd Qtr'!C13, '4th Qtr'!C13) -> 0 | D13: =SUM('1st Qtr'!D13, '2nd Qtr'!D13, '3rd Qtr'!D13, '4th Qtr'!D13) -> 0 | E13: =C13-D13 -> 0 | F13: =IFERROR(E13/D13, 0) -> 0 | G13: =SUM('1st Qtr'!G13, '2nd Qtr'!G13, '3rd Qtr'!G13, '4th Qtr'!G13) -> 0 | H13: =C13-G13 -> 0 | I13: =IFERROR(H13/G13, 0) -> 0
A14: Fullerton - 200 W Orangethorpe | B14: CA | C14: =SUM('1st Qtr'!C14, '2nd Qtr'!C14, '3rd Qtr'!C14, '4th Qtr'!C14) -> 66219.879 | D14: =SUM('1st Qtr'!D14, '2nd Qtr'!D14, '3rd Qtr'!D14, '4th Qtr'!D14) -> 65950.86 | E14: =C14-D14 -> 269.01891 | F14: =IFERROR(E14/D14, 0) -> 0.0040790811 | G14: =SUM('1st Qtr'!G14, '2nd Qtr'!G14, '3rd Qtr'!G14, '4th Qtr'!G14) -> 75151.27 | H14: =C14-G14 -> -8931.3911 | I14: =IFERROR(H14/G14, 0) -> -0.11884551
A15: El Paso - 10500 Railroad Drive | B15: TX | C15: =SUM('1st Qtr'!C15, '2nd Qtr'!C15, '3rd Qtr'!C15, '4th Qtr'!C15) -> 94436.375 | D15: =SUM('1st Qtr'!D15, '2nd Qtr'!D15, '3rd Qtr'!D15, '4th Qtr'!D15) -> 110748.9 | E15: =C15-D15 -> -16312.525 | F15: =IFERROR(E15/D15, 0) -> -0.14729289 | G15: =SUM('1st Qtr'!G15, '2nd Qtr'!G15, '3rd Qtr'!G15, '4th Qtr'!G15) -> 95880.07 | H15: =C15-G15 -> -1443.695 | I15: =IFERROR(H15/G15, 0) -> -0.0150573
A16: Friona - 900 Millard Ave | B16: TX | C16: =SUM('1st Qtr'!C16, '2nd Qtr'!C16, '3rd Qtr'!C16, '4th Qtr'!C16) -> 63501.438 | D16: =SUM('1st Qtr'!D16, '2nd Qtr'!D16, '3rd Qtr'!D16, '4th Qtr'!D16) -> 68753.48 | E16: =C16-D16 -> -5252.0425 | F16: =IFERROR(E16/D16, 0) -> -0.076389479 | G16: =SUM('1st Qtr'!G16, '2nd Qtr'!G16, '3rd Qtr'!G16, '4th Qtr'!G16) -> 72881.62 | H16: =C16-G16 -> -9380.1825 | I16: =IFERROR(H16/G16, 0) -> -0.12870436
A17: Total | C17: =SUM(C3:C16) -> 592532.49 | D17: =SUM(D3:D16) -> 833649.64 | E17: =C17-D17 -> -241117.14 | F17: =IFERROR(E17/D17, 0) -> -0.28923079 | G17: =SUM(G3:G16) -> 1493236.8 | H17: =C17-G17 -> -900704.36 | I17: =IFERROR(H17/G17, 0) -> -0.60318921
A19: Values in gold exceed expected or forecasted by 10% or more.
A21: Values in red are below expected or forecasted by 10% or more.

Sheet 1st Qtr
A1: {=portfolio} -> Catalyze | C1: 1st Quarter 2024 Actual v. Expected | G1: 1st Quarter 2024 Forecasted
A2: Site | B2: State | C2: Actual | D2: Expected | E2: Delta | F2: % | G2: Forecasted | H2: Delta | I2: %
A3: {=Sites[Site]} -> Fresno - 3150 Shaw Ave | B3: {=Sites[State]} -> CA | C3: =SUM(Jan!C3, Feb!C3, Mar!C3) -> 40368.438 | D3: =SUM(Jan!D3, Feb!D3, Mar!D3) -> 39837.75 | E3: =C3-D3 -> 530.6875 | F3: =IFERROR(E3/D3, 0) -> 0.013321222 | G3: =SUM(Jan!G3, Feb!G3, Mar!G3) -> 48161.71 | H3: =C3-G3 -> -7793.2725 | I3: =IFERROR(H3/G3, 0) -> -0.1618147
A4: Adelanto - 1 Sheep Creek Road | B4: CA | C4: =SUM(Jan!C4, Feb!C4, Mar!C4) -> 80417 | D4: =SUM(Jan!D4, Feb!D4, Mar!D4) -> 352340 | E4: =C4-D4 -> -271923 | F4: =IFERROR(E4/D4, 0) -> -0.77176307 | G4: =SUM(Jan!G4, Feb!G4, Mar!G4) -> 479912 | H4: =C4-G4 -> -399495 | I4: =IFERROR(H4/G4, 0) -> -0.83243386
A5: Blackstone - 83 Federal Street | B5: MA | C5: =SUM(Jan!C5, Feb!C5, Mar!C5) -> 106968 | D5: =SUM(Jan!D5, Feb!D5, Mar!D5) -> 0 | E5: =C5-D5 -> 106968 | F5: =IFERROR(E5/D5, 0) -> 0 | G5: =SUM(Jan!G5, Feb!G5, Mar!G5) -> 352931.5 | H5: =C5-G5 -> -245963.5 | I5: =IFERROR(H5/G5, 0) -> -0.69691569
A6: Charlton - 299 Worcester Road | B6: MA | C6: =SUM(Jan!C6, Feb!C6, Mar!C6) -> 11889 | D6: =SUM(Jan!D6, Feb!D6, Mar!D6) -> 21739.23 | E6: =C6-D6 -> -9850.23 | F6: =IFERROR(E6/D6, 0) -> -0.4531085 | G6: =SUM(Jan!G6, Feb!G6, Mar!G6) -> 32151.25 | H6: =C6-G6 -> -20262.25 | I6: =IFERROR(H6/G6, 0) -> -0.63021655
A7: Wareham - 8 Thatcher Drive | B7: MA | C7: =SUM(Jan!C7, Feb!C7, Mar!C7) -> 5780.1687 | D7: =SUM(Jan!D7, Feb!D7, Mar!D7) -> 7080.061 | E7: =C7-D7 -> -1299.8923 | F7: =IFERROR(E7/D7, 0) -> -0.18359903 | G7: =SUM(Jan!G7, Feb!G7, Mar!G7) -> 8785.329 | H7: =C7-G7 -> -3005.1603 | I7: =IFERROR(H7/G7, 0) -> -0.34206577
A8: West Yarmouth - 42 Mid Tech | B8: MA | C8: =SUM(Jan!C8, Feb!C8, Mar!C8) -> 4426.7571 | D8: =SUM(Jan!D8, Feb!D8, Mar!D8) -> 5459.478 | E8: =C8-D8 -> -1032.7209 | F8: =IFERROR(E8/D8, 0) -> -0.1891611 | G8: =SUM(Jan!G8, Feb!G8, Mar!G8) -> 6769.56 | H8: =C8-G8 -> -2342.8029 | I8: =IFERROR(H8/G8, 0) -> -0.34607905
A9: Harrison - 130 Union Street | B9: NY | C9: =SUM(Jan!C9, Feb!C9, Mar!C9) -> 5693.0625 | D9: =SUM(Jan!D9, Feb!D9, Mar!D9) -> 9025.686 | E9: =C9-D9 -> -3332.6235 | F9: =IFERROR(E9/D9, 0) -> -0.3692377 | G9: =SUM(Jan!G9, Feb!G9, Mar!G9) -> 10708.14 | H9: =C9-G9 -> -5015.0775 | I9: =IFERROR(H9/G9, 0) -> -0.46834254
A10: Staten Island - Ellis Storage | B10: NY | C10: =SUM(Jan!C10, Feb!C10, Mar!C10) -> 12897.375 | D10: =SUM(Jan!D10, Feb!D10, Mar!D10) -> 21330.59 | E10: =C10-D10 -> -8433.215 | F10: =IFERROR(E10/D10, 0) -> -0.39535779 | G10: =SUM(Jan!G10, Feb!G10, Mar!G10) -> 23412.4 | H10: =C10-G10 -> -10515.025 | I10: =IFERROR(H10/G10, 0) -> -0.44912205
A11: Amherst - 595 Scholles Road | B11: NY | C11: =SUM(Jan!C11, Feb!C11, Mar!C11) -> 99935 | D11: =SUM(Jan!D11, Feb!D11, Mar!D11) -> 131383.6 | E11: =C11-D11 -> -31448.6 | F11: =IFERROR(E11/D11, 0) -> -0.23936473 | G11: =SUM(Jan!G11, Feb!G11, Mar!G11) -> 286492 | H11: =C11-G11 -> -186557 | I11: =IFERROR(H11/G11, 0) -> -0.651177
A12: Lancaster 1 - Gunnville Road | B12: NY | C12: =SUM(Jan!C12, Feb!C12, Mar!C12) -> 0 | D12: =SUM(Jan!D12, Feb!D12, Mar!D12) -> 0 | E12: =C12-D12 -> 0 | F12: =IFERROR(E12/D12, 0) -> 0 | G12: =SUM(Jan!G12, Feb!G12, Mar!G12) -> 0 | H12: =C12-G12 -> 0 | I12: =IFERROR(H12/G12, 0) -> 0
A13: Lancaster 2 - Shisler Road | B13: NY | C13: =SUM(Jan!C13, Feb!C13, Mar!C13) -> 0 | D13: =SUM(Jan!D13, Feb!D13, Mar!D13) -> 0 | E13: =C13-D13 -> 0 | F13: =IFERROR(E13/D13, 0) -> 0 | G13: =SUM(Jan!G13, Feb!G13, Mar!G13) -> 0 | H13: =C13-G13 -> 0 | I13: =IFERROR(H13/G13, 0) -> 0
A14: Fullerton - 200 W Orangethorpe | B14: CA | C14: =SUM(Jan!C14, Feb!C14, Mar!C14) -> 66219.879 | D14: =SUM(Jan!D14, Feb!D14, Mar!D14) -> 65950.86 | E14: =C14-D14 -> 269.01891 | F14: =IFERROR(E14/D14, 0) -> 0.0040790811 | G14: =SUM(Jan!G14, Feb!G14, Mar!G14) -> 75151.27 | H14: =C14-G14 -> -8931.3911 | I14: =IFERROR(H14/G14, 0) -> -0.11884551
A15: El Paso - 10500 Railroad Drive | B15: TX | C15: =SUM(Jan!C15, Feb!C15, Mar!C15) -> 94436.375 | D15: =SUM(Jan!D15, Feb!D15, Mar!D15) -> 110748.9 | E15: =C15-D15 -> -16312.525 | F15: =IFERROR(E15/D15, 0) -> -0.14729289 | G15: =SUM(Jan!G15, Feb!G15, Mar!G15) -> 95880.07 | H15: =C15-G15 -> -1443.695 | I15: =IFERROR(H15/G15, 0) -> -0.0150573
A16: Friona - 900 Millard Ave | B16: TX | C16: =SUM(Jan!C16, Feb!C16, Mar!C16) -> 63501.438 | D16: =SUM(Jan!D16, Feb!D16, Mar!D16) -> 68753.48 | E16: =C16-D16 -> -5252.0425 | F16: =IFERROR(E16/D16, 0) -> -0.076389479 | G16: =SUM(Jan!G16, Feb!G16, Mar!G16) -> 72881.62 | H16: =C16-G16 -> -9380.1825 | I16: =IFERROR(H16/G16, 0) -> -0.12870436
A17: Total | C17: =SUM(C3:C16) -> 592532.49 | D17: =SUM(D3:D16) -> 833649.64 | E17: =C17-D17 -> -241117.14 | F17: =IFERROR(E17/D17, 0) -> -0.28923079 | G17: =SUM(G3:G16) -> 1493236.8 | H17: =C17-G17 -> -900704.36 | I17: =IFERROR(H17/G17, 0) -> -0.60318921
A19: Values in gold exceed expected or forecasted by 10% or more.
A21: Values in red are below expected or forecasted by 10% or more.

Sheet 2nd Qtr
A1: {=portfolio} -> Catalyze | C1: 2nd Quarter 2024 Actual v. Expected | G1: 2nd Quarter 2024 Forecasted
A2: Site | B2: State | C2: Actual | D2: Expected | E2: Delta | F2: % | G2: Forecasted | H2: Delta | I2: %
A3: {=Sites[Site]} -> Fresno - 3150 Shaw Ave | B3: {=Sites[State]} -> CA | C3: =SUM(Apr!C3, May!C3, Jun!C3) -> 0 | D3: =SUM(Apr!D3, May!D3, Jun!D3) -> 0 | E3: =C3-D3 -> 0 | F3: =IFERROR(E3/D3, 0) -> 0 | G3: =SUM(Apr!G3, May!G3, Jun!G3) -> 0 | H3: =C3-G3 -> 0 | I3: =IFERROR(H3/G3, 0) -> 0
A4: Adelanto - 1 Sheep Creek Road | B4: CA | C4: =SUM(Apr!C4, May!C4, Jun!C4) -> 0 | D4: =SUM(Apr!D4, May!D4, Jun!D4) -> 0 | E4: =C4-D4 -> 0 | F4: =IFERROR(E4/D4, 0) -> 0 | G4: =SUM(Apr!G4, May!G4, Jun!G4) -> 0 | H4: =C4-G4 -> 0 | I4: =IFERROR(H4/G4, 0) -> 0
A5: Blackstone - 83 Federal Street | B5: MA | C5: =SUM(Apr!C5, May!C5, Jun!C5) -> 0 | D5: =SUM(Apr!D5, May!D5, Jun!D5) -> 0 | E5: =C5-D5 -> 0 | F5: =IFERROR(E5/D5, 0) -> 0 | G5: =SUM(Apr!G5, May!G5, Jun!G5) -> 0 | H5: =C5-G5 -> 0 | I5: =IFERROR(H5/G5, 0) -> 0
A6: Charlton - 299 Worcester Road | B6: MA | C6: =SUM(Apr!C6, May!C6, Jun!C6) -> 0 | D6: =SUM(Apr!D6, May!D6, Jun!D6) -> 0 | E6: =C6-D6 -> 0 | F6: =IFERROR(E6/D6, 0) -> 0 | G6: =SUM(Apr!G6, May!G6, Jun!G6) -> 0 | H6: =C6-G6 -> 0 | I6: =IFERROR(H6/G6, 0) -> 0
A7: Wareham - 8 Thatcher Drive | B7: MA | C7: =SUM(Apr!C7, May!C7, Jun!C7) -> 0 | D7: =SUM(Apr!D7, May!D7, Jun!D7) -> 0 | E7: =C7-D7 -> 0 | F7: =IFERROR(E7/D7, 0) -> 0 | G7: =SUM(Apr!G7, May!G7, Jun!G7) -> 0 | H7: =C7-G7 -> 0 | I7: =IFERROR(H7/G7, 0) -> 0
A8: West Yarmouth - 42 Mid Tech | B8: MA | C8: =SUM(Apr!C8, May!C8, Jun!C8) -> 0 | D8: =SUM(Apr!D8, May!D8, Jun!D8) -> 0 | E8: =C8-D8 -> 0 | F8: =IFERROR(E8/D8, 0) -> 0 | G8: =SUM(Apr!G8, May!G8, Jun!G8) -> 0 | H8: =C8-G8 -> 0 | I8: =IFERROR(H8/G8, 0) -> 0
A9: Harrison - 130 Union Street | B9: NY | C9: =SUM(Apr!C9, May!C9, Jun!C9) -> 0 | D9: =SUM(Apr!D9, May!D9, Jun!D9) -> 0 | E9: =C9-D9 -> 0 | F9: =IFERROR(E9/D9, 0) -> 0 | G9: =SUM(Apr!G9, May!G9, Jun!G9) -> 0 | H9: =C9-G9 -> 0 | I9: =IFERROR(H9/G9, 0) -> 0
A10: Staten Island - Ellis Storage | B10: NY | C10: =SUM(Apr!C10, May!C10, Jun!C10) -> 0 | D10: =SUM(Apr!D10, May!D10, Jun!D10) -> 0 | E10: =C10-D10 -> 0 | F10: =IFERROR(E10/D10, 0) -> 0 | G10: =SUM(Apr!G10, May!G10, Jun!G10) -> 0 | H10: =C10-G10 -> 0 | I10: =IFERROR(H10/G10, 0) -> 0
A11: Amherst - 595 Scholles Road | B11: NY | C11: =SUM(Apr!C11, May!C11, Jun!C11) -> 0 | D11: =SUM(Apr!D11, May!D11, Jun!D11) -> 0 | E11: =C11-D11 -> 0 | F11: =IFERROR(E11/D11, 0) -> 0 | G11: =SUM(Apr!G11, May!G11, Jun!G11) -> 0 | H11: =C11-G11 -> 0 | I11: =IFERROR(H11/G11, 0) -> 0
A12: Lancaster 1 - Gunnville Road | B12: NY | C12: =SUM(Apr!C12, May!C12, Jun!C12) -> 0 | D12: =SUM(Apr!D12, May!D12, Jun!D12) -> 0 | E12: =C12-D12 -> 0 | F12: =IFERROR(E12/D12, 0) -> 0 | G12: =SUM(Apr!G12, May!G12, Jun!G12) -> 0 | H12: =C12-G12 -> 0 | I12: =IFERROR(H12/G12, 0) -> 0
A13: Lancaster 2 - Shisler Road | B13: NY | C13: =SUM(Apr!C13, May!C13, Jun!C13) -> 0 | D13: =SUM(Apr!D13, May!D13, Jun!D13) -> 0 | E13: =C13-D13 -> 0 | F13: =IFERROR(E13/D13, 0) -> 0 | G13: =SUM(Apr!G13, May!G13, Jun!G13) -> 0 | H13: =C13-G13 -> 0 | I13: =IFERROR(H13/G13, 0) -> 0
A14: Fullerton - 200 W Orangethorpe | B14: CA | C14: =SUM(Apr!C14, May!C14, Jun!C14) -> 0 | D14: =SUM(Apr!D14, May!D14, Jun!D14) -> 0 | E14: =C14-D14 -> 0 | F14: =IFERROR(E14/D14, 0) -> 0 | G14: =SUM(Apr!G14, May!G14, Jun!G14) -> 0 | H14: =C14-G14 -> 0 | I14: =IFERROR(H14/G14, 0) -> 0
A15: El Paso - 10500 Railroad Drive | B15: TX | C15: =SUM(Apr!C15, May!C15, Jun!C15) -> 0 | D15: =SUM(Apr!D15, May!D15, Jun!D15) -> 0 | E15: =C15-D15 -> 0 | F15: =IFERROR(E15/D15, 0) -> 0 | G15: =SUM(Apr!G15, May!G15, Jun!G15) -> 0 | H15: =C15-G15 -> 0 | I15: =IFERROR(H15/G15, 0) -> 0
A16: Friona - 900 Millard Ave | B16: TX | C16: =SUM(Apr!C16, May!C16, Jun!C16) -> 0 | D16: =SUM(Apr!D16, May!D16, Jun!D16) -> 0 | E16: =C16-D16 -> 0 | F16: =IFERROR(E16/D16, 0) -> 0 | G16: =SUM(Apr!G16, May!G16, Jun!G16) -> 0 | H16: =C16-G16 -> 0 | I16: =IFERROR(H16/G16, 0) -> 0
A17: Total | C17: =SUM(C3:C16) -> 0 | D17: =SUM(D3:D16) -> 0 | E17: =C17-D17 -> 0 | F17: =IFERROR(E17/D17, 0) -> 0 | G17: =SUM(G3:G16) -> 0 | H17: =C17-G17 -> 0 | I17: =IFERROR(H17/G17, 0) -> 0
A19: Values in gold exceed expected or forecasted by 10% or more.
A21: Values in red are below expected or forecasted by 10% or more.

Sheet 3rd Qtr
A1: {=portfolio} -> Catalyze | C1: 3rd Quarter 2024 Actual v. Expected | G1: 3rd Quarter 2024 Forecasted
A2: Site | B2: State | C2: Actual | D2: Expected | E2: Delta | F2: % | G2: Forecasted | H2: Delta | I2: %
A3: {=Sites[Site]} -> Fresno - 3150 Shaw Ave | B3: {=Sites[State]} -> CA | C3: =SUM(Jul!C3, Aug!C3, Sep!C3) -> 0 | D3: =SUM(Jul!D3, Aug!D3, Sep!D3) -> 0 | E3: =C3-D3 -> 0 | F3: =IFERROR(E3/D3, 0) -> 0 | G3: =SUM(Jul!G3, Aug!G3, Sep!G3) -> 0 | H3: =C3-G3 -> 0 | I3: =IFERROR(H3/G3, 0) -> 0
A4: Adelanto - 1 Sheep Creek Road | B4: CA | C4: =SUM(Jul!C4, Aug!C4, Sep!C4) -> 0 | D4: =SUM(Jul!D4, Aug!D4, Sep!D4) -> 0 | E4: =C4-D4 -> 0 | F4: =IFERROR(E4/D4, 0) -> 0 | G4: =SUM(Jul!G4, Aug!G4, Sep!G4) -> 0 | H4: =C4-G4 -> 0 | I4: =IFERROR(H4/G4, 0) -> 0
A5: Blackstone - 83 Federal Street | B5: MA | C5: =SUM(Jul!C5, Aug!C5, Sep!C5) -> 0 | D5: =SUM(Jul!D5, Aug!D5, Sep!D5) -> 0 | E5: =C5-D5 -> 0 | F5: =IFERROR(E5/D5, 0) -> 0 | G5: =SUM(Jul!G5, Aug!G5, Sep!G5) -> 0 | H5: =C5-G5 -> 0 | I5: =IFERROR(H5/G5, 0) -> 0
A6: Charlton - 299 Worcester Road | B6: MA | C6: =SUM(Jul!C6, Aug!C6, Sep!C6) -> 0 | D6: =SUM(Jul!D6, Aug!D6, Sep!D6) -> 0 | E6: =C6-D6 -> 0 | F6: =IFERROR(E6/D6, 0) -> 0 | G6: =SUM(Jul!G6, Aug!G6, Sep!G6) -> 0 | H6: =C6-G6 -> 0 | I6: =IFERROR(H6/G6, 0) -> 0
A7: Wareham - 8 Thatcher Drive | B7: MA | C7: =SUM(Jul!C7, Aug!C7, Sep!C7) -> 0 | D7: =SUM(Jul!D7, Aug!D7, Sep!D7) -> 0 | E7: =C7-D7 -> 0 | F7: =IFERROR(E7/D7, 0) -> 0 | G7: =SUM(Jul!G7, Aug!G7, Sep!G7) -> 0 | H7: =C7-G7 -> 0 | I7: =IFERROR(H7/G7, 0) -> 0
A8: West Yarmouth - 42 Mid Tech | B8: MA | C8: =SUM(Jul!C8, Aug!C8, Sep!C8) -> 0 | D8: =SUM(Jul!D8, Aug!D8, Sep!D8) -> 0 | E8: =C8-D8 -> 0 | F8: =IFERROR(E8/D8, 0) -> 0 | G8: =SUM(Jul!G8, Aug!G8, Sep!G8) -> 0 | H8: =C8-G8 -> 0 | I8: =IFERROR(H8/G8, 0) -> 0
A9: Harrison - 130 Union Street | B9: NY | C9: =SUM(Jul!C9, Aug!C9, Sep!C9) -> 0 | D9: =SUM(Jul!D9, Aug!D9, Sep!D9) -> 0 | E9: =C9-D9 -> 0 | F9: =IFERROR(E9/D9, 0) -> 0 | G9: =SUM(Jul!G9, Aug!G9, Sep!G9) -> 0 | H9: =C9-G9 -> 0 | I9: =IFERROR(H9/G9, 0) -> 0
A10: Staten Island - Ellis Storage | B10: NY | C10: =SUM(Jul!C10, Aug!C10, Sep!C10) -> 0 | D10: =SUM(Jul!D10, Aug!D10, Sep!D10) -> 0 | E10: =C10-D10 -> 0 | F10: =IFERROR(E10/D10, 0) -> 0 | G10: =SUM(Jul!G10, Aug!G10, Sep!G10) -> 0 | H10: =C10-G10 -> 0 | I10: =IFERROR(H10/G10, 0) -> 0
A11: Amherst - 595 Scholles Road | B11: NY | C11: =SUM(Jul!C11, Aug!C11, Sep!C11) -> 0 | D11: =SUM(Jul!D11, Aug!D11, Sep!D11) -> 0 | E11: =C11-D11 -> 0 | F11: =IFERROR(E11/D11, 0) -> 0 | G11: =SUM(Jul!G11, Aug!G11, Sep!G11) -> 0 | H11: =C11-G11 -> 0 | I11: =IFERROR(H11/G11, 0) -> 0
A12: Lancaster 1 - Gunnville Road | B12: NY | C12: =SUM(Jul!C12, Aug!C12, Sep!C12) -> 0 | D12: =SUM(Jul!D12, Aug!D12, Sep!D12) -> 0 | E12: =C12-D12 -> 0 | F12: =IFERROR(E12/D12, 0) -> 0 | G12: =SUM(Jul!G12, Aug!G12, Sep!G12) -> 0 | H12: =C12-G12 -> 0 | I12: =IFERROR(H12/G12, 0) -> 0
A13: Lancaster 2 - Shisler Road | B13: NY | C13: =SUM(Jul!C13, Aug!C13, Sep!C13) -> 0 | D13: =SUM(Jul!D13, Aug!D13, Sep!D13) -> 0 | E13: =C13-D13 -> 0 | F13: =IFERROR(E13/D13, 0) -> 0 | G13: =SUM(Jul!G13, Aug!G13, Sep!G13) -> 0 | H13: =C13-G13 -> 0 | I13: =IFERROR(H13/G13, 0) -> 0
A14: Fullerton - 200 W Orangethorpe | B14: CA | C14: =SUM(Jul!C14, Aug!C14, Sep!C14) -> 0 | D14: =SUM(Jul!D14, Aug!D14, Sep!D14) -> 0 | E14: =C14-D14 -> 0 | F14: =IFERROR(E14/D14, 0) -> 0 | G14: =SUM(Jul!G14, Aug!G14, Sep!G14) -> 0 | H14: =C14-G14 -> 0 | I14: =IFERROR(H14/G14, 0) -> 0
A15: El Paso - 10500 Railroad Drive | B15: TX | C15: =SUM(Jul!C15, Aug!C15, Sep!C15) -> 0 | D15: =SUM(Jul!D15, Aug!D15, Sep!D15) -> 0 | E15: =C15-D15 -> 0 | F15: =IFERROR(E15/D15, 0) -> 0 | G15: =SUM(Jul!G15, Aug!G15, Sep!G15) -> 0 | H15: =C15-G15 -> 0 | I15: =IFERROR(H15/G15, 0) -> 0
A16: Friona - 900 Millard Ave | B16: TX | C16: =SUM(Jul!C16, Aug!C16, Sep!C16) -> 0 | D16: =SUM(Jul!D16, Aug!D16, Sep!D16) -> 0 | E16: =C16-D16 -> 0 | F16: =IFERROR(E16/D16, 0) -> 0 | G16: =SUM(Jul!G16, Aug!G16, Sep!G16) -> 0 | H16: =C16-G16 -> 0 | I16: =IFERROR(H16/G16, 0) -> 0
A17: Total | C17: =SUM(C3:C16) -> 0 | D17: =SUM(D3:D16) -> 0 | E17: =C17-D17 -> 0 | F17: =IFERROR(E17/D17, 0) -> 0 | G17: =SUM(G3:G16) -> 0 | H17: =C17-G17 -> 0 | I17: =IFERROR(H17/G17, 0) -> 0
A19: Values in gold exceed expected or forecasted by 10% or more.
A21: Values in red are below expected or forecasted by 10% or more.

Sheet 4th Qtr
A1: {=portfolio} -> Catalyze | C1: 4th Quarter 2024 Actual v. Expected | G1: 4th Quarter 2024 Forecasted
A2: Site | B2: State | C2: Actual | D2: Expected | E2: Delta | F2: % | G2: Forecasted | H2: Delta | I2: %
A3: {=Sites[Site]} -> Fresno - 3150 Shaw Ave | B3: {=Sites[State]} -> CA | C3: =SUM(Oct!C3, Nov!C3, Dec!C3) -> 0 | D3: =SUM(Oct!D3, Nov!D3, Dec!D3) -> 0 | E3: =C3-D3 -> 0 | F3: =IFERROR(E3/D3, 0) -> 0 | G3: =SUM(Oct!G3, Nov!G3, Dec!G3) -> 0 | H3: =C3-G3 -> 0 | I3: =IFERROR(H3/G3, 0) -> 0
A4: Adelanto - 1 Sheep Creek Road | B4: CA | C4: =SUM(Oct!C4, Nov!C4, Dec!C4) -> 0 | D4: =SUM(Oct!D4, Nov!D4, Dec!D4) -> 0 | E4: =C4-D4 -> 0 | F4: =IFERROR(E4/D4, 0) -> 0 | G4: =SUM(Oct!G4, Nov!G4, Dec!G4) -> 0 | H4: =C4-G4 -> 0 | I4: =IFERROR(H4/G4, 0) -> 0
A5: Blackstone - 83 Federal Street | B5: MA | C5: =SUM(Oct!C5, Nov!C5, Dec!C5) -> 0 | D5: =SUM(Oct!D5, Nov!D5, Dec!D5) -> 0 | E5: =C5-D5 -> 0 | F5: =IFERROR(E5/D5, 0) -> 0 | G5: =SUM(Oct!G5, Nov!G5, Dec!G5) -> 0 | H5: =C5-G5 -> 0 | I5: =IFERROR(H5/G5, 0) -> 0
A6: Charlton - 299 Worcester Road | B6: MA | C6: =SUM(Oct!C6, Nov!C6, Dec!C6) -> 0 | D6: =SUM(Oct!D6, Nov!D6, Dec!D6) -> 0 | E6: =C6-D6 -> 0 | F6: =IFERROR(E6/D6, 0) -> 0 | G6: =SUM(Oct!G6, Nov!G6, Dec!G6) -> 0 | H6: =C6-G6 -> 0 | I6: =IFERROR(H6/G6, 0) -> 0
A7: Wareham - 8 Thatcher Drive | B7: MA | C7: =SUM(Oct!C7, Nov!C7, Dec!C7) -> 0 | D7: =SUM(Oct!D7, Nov!D7, Dec!D7) -> 0 | E7: =C7-D7 -> 0 | F7: =IFERROR(E7/D7, 0) -> 0 | G7: =SUM(Oct!G7, Nov!G7, Dec!G7) -> 0 | H7: =C7-G7 -> 0 | I7: =IFERROR(H7/G7, 0) -> 0
A8: West Yarmouth - 42 Mid Tech | B8: MA | C8: =SUM(Oct!C8, Nov!C8, Dec!C8) -> 0 | D8: =SUM(Oct!D8, Nov!D8, Dec!D8) -> 0 | E8: =C8-D8 -> 0 | F8: =IFERROR(E8/D8, 0) -> 0 | G8: =SUM(Oct!G8, Nov!G8, Dec!G8) -> 0 | H8: =C8-G8 -> 0 | I8: =IFERROR(H8/G8, 0) -> 0
A9: Harrison - 130 Union Street | B9: NY | C9: =SUM(Oct!C9, Nov!C9, Dec!C9) -> 0 | D9: =SUM(Oct!D9, Nov!D9, Dec!D9) -> 0 | E9: =C9-D9 -> 0 | F9: =IFERROR(E9/D9, 0) -> 0 | G9: =SUM(Oct!G9, Nov!G9, Dec!G9) -> 0 | H9: =C9-G9 -> 0 | I9: =IFERROR(H9/G9, 0) -> 0
A10: Staten Island - Ellis Storage | B10: NY | C10: =SUM(Oct!C10, Nov!C10, Dec!C10) -> 0 | D10: =SUM(Oct!D10, Nov!D10, Dec!D10) -> 0 | E10: =C10-D10 -> 0 | F10: =IFERROR(E10/D10, 0) -> 0 | G10: =SUM(Oct!G10, Nov!G10, Dec!G10) -> 0 | H10: =C10-G10 -> 0 | I10: =IFERROR(H10/G10, 0) -> 0
A11: Amherst - 595 Scholles Road | B11: NY | C11: =SUM(Oct!C11, Nov!C11, Dec!C11) -> 0 | D11: =SUM(Oct!D11, Nov!D11, Dec!D11) -> 0 | E11: =C11-D11 -> 0 | F11: =IFERROR(E11/D11, 0) -> 0 | G11: =SUM(Oct!G11, Nov!G11, Dec!G11) -> 0 | H11: =C11-G11 -> 0 | I11: =IFERROR(H11/G11, 0) -> 0
A12: Lancaster 1 - Gunnville Road | B12: NY | C12: =SUM(Oct!C12, Nov!C12, Dec!C12) -> 0 | D12: =SUM(Oct!D12, Nov!D12, Dec!D12) -> 0 | E12: =C12-D12 -> 0 | F12: =IFERROR(E12/D12, 0) -> 0 | G12: =SUM(Oct!G12, Nov!G12, Dec!G12) -> 0 | H12: =C12-G12 -> 0 | I12: =IFERROR(H12/G12, 0) -> 0
A13: Lancaster 2 - Shisler Road | B13: NY | C13: =SUM(Oct!C13, Nov!C13, Dec!C13) -> 0 | D13: =SUM(Oct!D13, Nov!D13, Dec!D13) -> 0 | E13: =C13-D13 -> 0 | F13: =IFERROR(E13/D13, 0) -> 0 | G13: =SUM(Oct!G13, Nov!G13, Dec!G13) -> 0 | H13: =C13-G13 -> 0 | I13: =IFERROR(H13/G13, 0) -> 0
A14: Fullerton - 200 W Orangethorpe | B14: CA | C14: =SUM(Oct!C14, Nov!C14, Dec!C14) -> 0 | D14: =SUM(Oct!D14, Nov!D14, Dec!D14) -> 0 | E14: =C14-D14 -> 0 | F14: =IFERROR(E14/D14, 0) -> 0 | G14: =SUM(Oct!G14, Nov!G14, Dec!G14) -> 0 | H14: =C14-G14 -> 0 | I14: =IFERROR(H14/G14, 0) -> 0
A15: El Paso - 10500 Railroad Drive | B15: TX | C15: =SUM(Oct!C15, Nov!C15, Dec!C15) -> 0 | D15: =SUM(Oct!D15, Nov!D15, Dec!D15) -> 0 | E15: =C15-D15 -> 0 | F15: =IFERROR(E15/D15, 0) -> 0 | G15: =SUM(Oct!G15, Nov!G15, Dec!G15) -> 0 | H15: =C15-G15 -> 0 | I15: =IFERROR(H15/G15, 0) -> 0
A16: Friona - 900 Millard Ave | B16: TX | C16: =SUM(Oct!C16, Nov!C16, Dec!C16) -> 0 | D16: =SUM(Oct!D16, Nov!D16, Dec!D16) -> 0 | E16: =C16-D16 -> 0 | F16: =IFERROR(E16/D16, 0) -> 0 | G16: =SUM(Oct!G16, Nov!G16, Dec!G16) -> 0 | H16: =C16-G16 -> 0 | I16: =IFERROR(H16/G16, 0) -> 0
A17: Total | C17: =SUM(C3:C16) -> 0 | D17: =SUM(D3:D16) -> 0 | E17: =C17-D17 -> 0 | F17: =IFERROR(E17/D17, 0) -> 0 | G17: =SUM(G3:G16) -> 0 | H17: =C17-G17 -> 0 | I17: =IFERROR(H17/G17, 0) -> 0
A19: Values in gold exceed expected or forecasted by 10% or more.
A21: Values in red are below expected or forecasted by 10% or more.

Sheet Jan
A1: {=portfolio} -> Catalyze | C1: January Actual v. Expected | G1: January Actual v. Forecasted | J1: NOTES | K1: SR
A2: Site | B2: State | C2: Actual | D2: Expected | E2: Delta | F2: % | G2: Forecasted | H2: Delta | I2: %
A3: {=Sites[Site]} -> Fresno - 3150 Shaw Ave | B3: {=Sites[State]} -> CA | C3: {=IF(INDIRECT("'" & $A3 & "'!B5:J5")="", "", INDIRECT("'" & $A3 & "'!B5:J5"))} -> 40368.438 | D3: 39837.75 | E3: 530.6875 | F3: 0.013321222 | G3: 48161.71 | H3: -7793.2725 | I3: -0.1618147 | J3: 1.Inverter 5 tripped offline on 01/19/2024 at 12:30 & back online at 14:00. | K3: 1.SR080353
A4: Adelanto - 1 Sheep Creek Road | B4: CA | C4: {=IF(INDIRECT("'" & $A4 & "'!B5:J5")="", "", INDIRECT("'" & $A4 & "'!B5:J5"))} -> 80417 | D4: 352340 | E4: -271923 | F4: -0.77176307 | G4: 479912 | H4: -399495 | I4: -0.83243386 | J4: 1. Site frequently experiencing outages due to its ongoing curtailment by CAISO | K4: 1. SR077480, SR079342
A5: Blackstone - 83 Federal Street | B5: MA | C5: {=IF(INDIRECT("'" & $A5 & "'!B5:J5")="", "", INDIRECT("'" & $A5 & "'!B5:J5"))} -> 106968 | D5: 0 | E5: 106968 | F5: 0 | G5: 352931.5 | H5: -245963.5 | I5: -0.69691569 | J5: 1. SIte was offline from 01/15/2024 - 01/17/2024. | K5: 1. SR080251
A6: Charlton - 299 Worcester Road | B6: MA | C6: {=IF(INDIRECT("'" & $A6 & "'!B5:J5")="", "", INDIRECT("'" & $A6 & "'!B5:J5"))} -> 11889 | D6: 21739.23 | E6: -9850.23 | F6: -0.4531085 | G6: 32151.25 | H6: -20262.25 | I6: -0.63021655 | J6: 1. Site was offline on 01/27/2024 & back online on 01/29/2024. | K6: 1. SR080523
A7: Wareham - 8 Thatcher Drive | B7: MA | C7: {=IF(INDIRECT("'" & $A7 & "'!B5:J5")="", "", INDIRECT("'" & $A7 & "'!B5:J5"))} -> 5780.1687 | D7: 7080.061 | E7: -1299.8923 | F7: -0.18359903 | G7: 8785.329 | H7: -3005.1603 | I7: -0.34206577
A8: West Yarmouth - 42 Mid Tech | B8: MA | C8: {=IF(INDIRECT("'" & $A8 & "'!B5:J5")="", "", INDIRECT("'" & $A8 & "'!B5:J5"))} -> 4426.7571 | D8: 5459.478 | E8: -1032.7209 | F8: -0.1891611 | G8: 6769.56 | H8: -2342.8029 | I8: -0.34607905
A9: Harrison - 130 Union Street | B9: NY | C9: {=IF(INDIRECT("'" & $A9 & "'!B5:J5")="", "", INDIRECT("'" & $A9 & "'!B5:J5"))} -> 5693.0625 | D9: 9025.686 | E9: -3332.6235 | F9: -0.3692377 | G9: 10708.14 | H9: -5015.0775 | I9: -0.46834254
A10: Staten Island - Ellis Storage | B10: NY | C10: {=IF(INDIRECT("'" & $A10 & "'!B5:J5")="", "", INDIRECT("'" & $A10 & "'!B5:J5"))} -> 12897.375 | D10: 21330.59 | E10: -8433.215 | F10: -0.39535779 | G10: 23412.4 | H10: -10515.025 | I10: -0.44912205
A11: Amherst - 595 Scholles Road | B11: NY | C11: {=IF(INDIRECT("'" & $A11 & "'!B5:J5")="", "", INDIRECT("'" & $A11 & "'!B5:J5"))} -> 99935 | D11: 131383.6 | E11: -31448.6 | F11: -0.23936473 | G11: 286492 | H11: -186557 | I11: -0.651177 | J11: 1. Site tripped offlline at 01/31/2024 at 09:30 & back online at 11:41. 2. Inverter 1 was offline on 01/10/2024 & back online at 01/11/2024 at 16:30. | K11: 1.SR080616 2. SR080129
A12: Lancaster 1 - Gunnville Road | B12: NY | C12: {=IF(INDIRECT("'" & $A12 & "'!B5:J5")="", "", INDIRECT("'" & $A12 & "'!B5:J5"))} | E12: 0 | F12: 0 | H12: 0 | I12: 0
A13: Lancaster 2 - Shisler Road | B13: NY | C13: {=IF(INDIRECT("'" & $A13 & "'!B5:J5")="", "", INDIRECT("'" & $A13 & "'!B5:J5"))} | E13: 0 | F13: 0 | H13: 0 | I13: 0
A14: Fullerton - 200 W Orangethorpe | B14: CA | C14: {=IF(INDIRECT("'" & $A14 & "'!B5:J5")="", "", INDIRECT("'" & $A14 & "'!B5:J5"))} -> 66219.879 | D14: 65950.86 | E14: 269.01891 | F14: 0.0040790811 | G14: 75151.27 | H14: -8931.3911 | I14: -0.11884551
A15: El Paso - 10500 Railroad Drive | B15: TX | C15: {=IF(INDIRECT("'" & $A15 & "'!B5:J5")="", "", INDIRECT("'" & $A15 & "'!B5:J5"))} -> 94436.375 | D15: 110748.9 | E15: -16312.525 | F15: -0.14729289 | G15: 95880.07 | H15: -1443.695 | I15: -0.0150573
A16: Friona - 900 Millard Ave | B16: TX | C16: {=IF(INDIRECT("'" & $A16 & "'!B5:J5")="", "", INDIRECT("'" & $A16 & "'!B5:J5"))} -> 63501.438 | D16: 68753.48 | E16: -5252.0425 | F16: -0.076389479 | G16: 72881.62 | H16: -9380.1825 | I16: -0.12870436 | J16: 1. Inverter 6 tripping on & off throught out the month. 2. Inverter 7 has tripping event on 01/12,1/14,1/16,1/19. | K16: 1. SR074295 2. SR079995
A17: Total | C17: =SUM(C3:C16) -> 592532.49 | D17: =SUM(D3:D16) -> 833649.64 | E17: =C17-D17 -> -241117.14 | F17: =IFERROR(E17/D17, 0) -> -0.28923079 | G17: =SUM(G3:G16) -> 1493236.8 | H17: =C17-G17 -> -900704.36 | I17: =IFERROR(H17/G17, 0) -> -0.60318921
A19: Values in gold exceed expected or forecasted by 10% or more.
A21: Values in red are below expected or forecasted by 10% or more.
G23: 48161.71 | J23: 1.Inverter 5 tripped offline on 01/19/2024 at 12:30 & back online at 14:00. | K23: 1.SR080353
G24: 479912 | J24: 1. Site frequently experiencing outages due to its ongoing curtailment by CAISO | K24: 1. SR077480, SR079342
G25: 352931.5 | J25: 1. SIte was offline from 01/15/2024 - 01/17/2024. | K25: 1. SR080251
G26: 32151.25 | J26: 1. Site was offline on 01/27/2024 & back online on 01/29/2024. | K26: 1. SR080523
G27: 8785.329
G28: 6769.56
G29: 10708.14
G30: 23412.4
G31: 286492 | J31: 1. Site tripped offlline at 01/31/2024 at 09:30 & back online at 11:41. 2. Inverter 1 was offline on 01/10/2024 & back online at 01/11/2024 at 16:30. | K31: 1.SR080616 2. SR080129
G34: 75151.27
G35: 95880.07
G36: 72881.62 | J36: 1. Inverter 6 tripping on & off throught out the month. 2. Inverter 7 has tripping event on 01/12,1/14,1/16,1/19. | K36: 1. SR074295 2. SR079995

Sheet Feb
A1: {=portfolio} -> Catalyze | C1: February Actual v. Expected | G1: February Actual v. Forecasted | J1: NOTES | K1: SR
A2: Site | B2: State | C2: Actual | D2: Expected | E2: Delta | F2: % | G2: Forecasted | H2: Delta | I2: %
A3: {=Sites[Site]} -> Fresno - 3150 Shaw Ave | B3: {=Sites[State]} -> CA | C3: {=IF(INDIRECT("'" & $A3 & "'!B6:J6")="", "", INDIRECT("'" & $A3 & "'!B6:J6"))} | E3: 0 | F3: 0 | H3: 0 | I3: 0
A4: Adelanto - 1 Sheep Creek Road | B4: CA | C4: {=IF(INDIRECT("'" & $A4 & "'!B6:J6")="", "", INDIRECT("'" & $A4 & "'!B6:J6"))} | E4: 0 | F4: 0 | H4: 0 | I4: 0
A5: Blackstone - 83 Federal Street | B5: MA | C5: {=IF(INDIRECT("'" & $A5 & "'!B6:J6")="", "", INDIRECT("'" & $A5 & "'!B6:J6"))} | E5: 0 | F5: 0 | H5: 0 | I5: 0
A6: Charlton - 299 Worcester Road | B6: MA | C6: {=IF(INDIRECT("'" & $A6 & "'!B6:J6")="", "", INDIRECT("'" & $A6 & "'!B6:J6"))} | E6: 0 | F6: 0 | H6: 0 | I6: 0
A7: Wareham - 8 Thatcher Drive | B7: MA | C7: {=IF(INDIRECT("'" & $A7 & "'!B6:J6")="", "", INDIRECT("'" & $A7 & "'!B6:J6"))} | E7: 0 | F7: 0 | H7: 0 | I7: 0
A8: West Yarmouth - 42 Mid Tech | B8: MA | C8: {=IF(INDIRECT("'" & $A8 & "'!B6:J6")="", "", INDIRECT("'" & $A8 & "'!B6:J6"))} | E8: 0 | F8: 0 | H8: 0 | I8: 0
A9: Harrison - 130 Union Street | B9: NY | C9: {=IF(INDIRECT("'" & $A9 & "'!B6:J6")="", "", INDIRECT("'" & $A9 & "'!B6:J6"))} | E9: 0 | F9: 0 | H9: 0 | I9: 0
A10: Staten Island - Ellis Storage | B10: NY | C10: {=IF(INDIRECT("'" & $A10 & "'!B6:J6")="", "", INDIRECT("'" & $A10 & "'!B6:J6"))} | E10: 0 | F10: 0 | H10: 0 | I10: 0
A11: Amherst - 595 Scholles Road | B11: NY | C11: {=IF(INDIRECT("'" & $A11 & "'!B6:J6")="", "", INDIRECT("'" & $A11 & "'!B6:J6"))} | E11: 0 | F11: 0 | H11: 0 | I11: 0
A12: Lancaster 1 - Gunnville Road | B12: NY | C12: {=IF(INDIRECT("'" & $A12 & "'!B6:J6")="", "", INDIRECT("'" & $A12 & "'!B6:J6"))} | E12: 0 | F12: 0 | H12: 0 | I12: 0
A13: Lancaster 2 - Shisler Road | B13: NY | C13: {=IF(INDIRECT("'" & $A13 & "'!B6:J6")="", "", INDIRECT("'" & $A13 & "'!B6:J6"))} | E13: 0 | F13: 0 | H13: 0 | I13: 0
A14: Fullerton - 200 W Orangethorpe | B14: CA | C14: {=IF(INDIRECT("'" & $A14 & "'!B6:J6")="", "", INDIRECT("'" & $A14 & "'!B6:J6"))} | E14: 0 | F14: 0 | H14: 0 | I14: 0
A15: El Paso - 10500 Railroad Drive | B15: TX | C15: {=IF(INDIRECT("'" & $A15 & "'!B6:J6")="", "", INDIRECT("'" & $A15 & "'!B6:J6"))} | E15: 0 | F15: 0 | H15: 0 | I15: 0
A16: Friona - 900 Millard Ave | B16: TX | C16: {=IF(INDIRECT("'" & $A16 & "'!B6:J6")="", "", INDIRECT("'" & $A16 & "'!B6:J6"))} | E16: 0 | F16: 0 | H16: 0 | I16: 0
A17: Total | C17: =SUM(C3:C16) -> 0 | D17: =SUM(D3:D16) -> 0 | E17: =C17-D17 -> 0 | F17: =IFERROR(E17/D17, 0) -> 0 | G17: =SUM(G3:G16) -> 0 | H17: =C17-G17 -> 0 | I17: =IFERROR(H17/G17, 0) -> 0
A19: Values in gold exceed expected or forecasted by 10% or more.
A21: Values in red are below expected or forecasted by 10% or more.

Sheet Mar
A1: {=portfolio} -> Catalyze | C1: March Actual v. Expected | G1: March Actual v. Forecasted | J1: NOTES | K1: SR
A2: Site | B2: State | C2: Actual | D2: Expected | E2: Delta | F2: % | G2: Forecasted | H2: Delta | I2: %
A3: {=Sites[Site]} -> Fresno - 3150 Shaw Ave | B3: {=Sites[State]} -> CA | C3: {=IF(INDIRECT("'" & $A3 & "'!B7:J7")="", "", INDIRECT("'" & $A3 & "'!B7:J7"))} | E3: 0 | F3: 0 | H3: 0 | I3: 0
A4: Adelanto - 1 Sheep Creek Road | B4: CA | C4: {=IF(INDIRECT("'" & $A4 & "'!B7:J7")="", "", INDIRECT("'" & $A4 & "'!B7:J7"))} | E4: 0 | F4: 0 | H4: 0 | I4: 0
A5: Blackstone - 83 Federal Street | B5: MA | C5: {=IF(INDIRECT("'" & $A5 & "'!B7:J7")="", "", INDIRECT("'" & $A5 & "'!B7:J7"))} | E5: 0 | F5: 0 | H5: 0 | I5: 0
A6: Charlton - 299 Worcester Road | B6: MA | C6: {=IF(INDIRECT("'" & $A6 & "'!B7:J7")="", "", INDIRECT("'" & $A6 & "'!B7:J7"))} | E6: 0 | F6: 0 | H6: 0 | I6: 0
A7: Wareham - 8 Thatcher Drive | B7: MA | C7: {=IF(INDIRECT("'" & $A7 & "'!B7:J7")="", "", INDIRECT("'" & $A7 & "'!B7:J7"))} | E7: 0 | F7: 0 | H7: 0 | I7: 0
A8: West Yarmouth - 42 Mid Tech | B8: MA | C8: {=IF(INDIRECT("'" & $A8 & "'!B7:J7")="", "", INDIRECT("'" & $A8 & "'!B7:J7"))} | E8: 0 | F8: 0 | H8: 0 | I8: 0
A9: Harrison - 130 Union Street | B9: NY | C9: {=IF(INDIRECT("'" & $A9 & "'!B7:J7")="", "", INDIRECT("'" & $A9 & "'!B7:J7"))} | E9: 0 | F9: 0 | H9: 0 | I9: 0
A10: Staten Island - Ellis Storage | B10: NY | C10: {=IF(INDIRECT("'" & $A10 & "'!B7:J7")="", "", INDIRECT("'" & $A10 & "'!B7:J7"))} | E10: 0 | F10: 0 | H10: 0 | I10: 0
A11: Amherst - 595 Scholles Road | B11: NY | C11: {=IF(INDIRECT("'" & $A11 & "'!B7:J7")="", "", INDIRECT("'" & $A11 & "'!B7:J7"))} | E11: 0 | F11: 0 | H11: 0 | I11: 0
A12: Lancaster 1 - Gunnville Road | B12: NY | C12: {=IF(INDIRECT("'" & $A12 & "'!B7:J7")="", "", INDIRECT("'" & $A12 & "'!B7:J7"))} | E12: 0 | F12: 0 | H12: 0 | I12: 0
A13: Lancaster 2 - Shisler Road | B13: NY | C13: {=IF(INDIRECT("'" & $A13 & "'!B7:J7")="", "", INDIRECT("'" & $A13 & "'!B7:J7"))} | E13: 0 | F13: 0 | H13: 0 | I13: 0
A14: Fullerton - 200 W Orangethorpe | B14: CA | C14: {=IF(INDIRECT("'" & $A14 & "'!B7:J7")="", "", INDIRECT("'" & $A14 & "'!B7:J7"))} | E14: 0 | F14: 0 | H14: 0 | I14: 0
A15: El Paso - 10500 Railroad Drive | B15: TX | C15: {=IF(INDIRECT("'" & $A15 & "'!B7:J7")="", "", INDIRECT("'" & $A15 & "'!B7:J7"))} | E15: 0 | F15: 0 | H15: 0 | I15: 0
A16: Friona - 900 Millard Ave | B16: TX | C16: {=IF(INDIRECT("'" & $A16 & "'!B7:J7")="", "", INDIRECT("'" & $A16 & "'!B7:J7"))} | E16: 0 | F16: 0 | H16: 0 | I16: 0
A17: Total | C17: =SUM(C3:C16) -> 0 | D17: =SUM(D3:D16) -> 0 | E17: =C17-D17 -> 0 | F17: =IFERROR(E17/D17, 0) -> 0 | G17: =SUM(G3:G16) -> 0 | H17: =C17-G17 -> 0 | I17: =IFERROR(H17/G17, 0) -> 0
A19: Values in gold exceed expected or forecasted by 10% or more.
A21: Values in red are below expected or forecasted by 10% or more.

Sheet Apr
A1: {=portfolio} -> Catalyze | C1: April Actual v. Expected | G1: April Actual v. Forecasted | J1: NOTES | K1: SR
A2: Site | B2: State | C2: Actual | D2: Expected | E2: Delta | F2: % | G2: Forecasted | H2: Delta | I2: %
A3: {=Sites[Site]} -> Fresno - 3150 Shaw Ave | B3: {=Sites[State]} -> CA | C3: {=IF(INDIRECT("'" & $A3 & "'!B8:J8")="", "", INDIRECT("'" & $A3 & "'!B8:J8"))} | E3: 0 | F3: 0 | H3: 0 | I3: 0
A4: Adelanto - 1 Sheep Creek Road | B4: CA | C4: {=IF(INDIRECT("'" & $A4 & "'!B8:J8")="", "", INDIRECT("'" & $A4 & "'!B8:J8"))} | E4: 0 | F4: 0 | H4: 0 | I4: 0
A5: Blackstone - 83 Federal Street | B5: MA | C5: {=IF(INDIRECT("'" & $A5 & "'!B8:J8")="", "", INDIRECT("'" & $A5 & "'!B8:J8"))} | E5: 0 | F5: 0 | H5: 0 | I5: 0
A6: Charlton - 299 Worcester Road | B6: MA | C6: {=IF(INDIRECT("'" & $A6 & "'!B8:J8")="", "", INDIRECT("'" & $A6 & "'!B8:J8"))} | E6: 0 | F6: 0 | H6: 0 | I6: 0
A7: Wareham - 8 Thatcher Drive | B7: MA | C7: {=IF(INDIRECT("'" & $A7 & "'!B8:J8")="", "", INDIRECT("'" & $A7 & "'!B8:J8"))} | E7: 0 | F7: 0 | H7: 0 | I7: 0
A8: West Yarmouth - 42 Mid Tech | B8: MA | C8: {=IF(INDIRECT("'" & $A8 & "'!B8:J8")="", "", INDIRECT("'" & $A8 & "'!B8:J8"))} | E8: 0 | F8: 0 | H8: 0 | I8: 0
A9: Harrison - 130 Union Street | B9: NY | C9: {=IF(INDIRECT("'" & $A9 & "'!B8:J8")="", "", INDIRECT("'" & $A9 & "'!B8:J8"))} | E9: 0 | F9: 0 | H9: 0 | I9: 0
A10: Staten Island - Ellis Storage | B10: NY | C10: {=IF(INDIRECT("'" & $A10 & "'!B8:J8")="", "", INDIRECT("'" & $A10 & "'!B8:J8"))} | E10: 0 | F10: 0 | H10: 0 | I10: 0
A11: Amherst - 595 Scholles Road | B11: NY | C11: {=IF(INDIRECT("'" & $A11 & "'!B8:J8")="", "", INDIRECT("'" & $A11 & "'!B8:J8"))} | E11: 0 | F11: 0 | H11: 0 | I11: 0
A12: Lancaster 1 - Gunnville Road | B12: NY | C12: {=IF(INDIRECT("'" & $A12 & "'!B8:J8")="", "", INDIRECT("'" & $A12 & "'!B8:J8"))} | E12: 0 | F12: 0 | H12: 0 | I12: 0
A13: Lancaster 2 - Shisler Road | B13: NY | C13: {=IF(INDIRECT("'" & $A13 & "'!B8:J8")="", "", INDIRECT("'" & $A13 & "'!B8:J8"))} | E13: 0 | F13: 0 | H13: 0 | I13: 0
A14: Fullerton - 200 W Orangethorpe | B14: CA | C14: {=IF(INDIRECT("'" & $A14 & "'!B8:J8")="", "", INDIRECT("'" & $A14 & "'!B8:J8"))} | E14: 0 | F14: 0 | H14: 0 | I14: 0
A15: El Paso - 10500 Railroad Drive | B15: TX | C15: {=IF(INDIRECT("'" & $A15 & "'!B8:J8")="", "", INDIRECT("'" & $A15 & "'!B8:J8"))} | E15: 0 | F15: 0 | H15: 0 | I15: 0
A16: Friona - 900 Millard Ave | B16: TX | C16: {=IF(INDIRECT("'" & $A16 & "'!B8:J8")="", "", INDIRECT("'" & $A16 & "'!B8:J8"))} | E16: 0 | F16: 0 | H16: 0 | I16: 0
A17: Total | C17: =SUM(C3:C16) -> 0 | D17: =SUM(D3:D16) -> 0 | E17: =C17-D17 -> 0 | F17: =IFERROR(E17/D17, 0) -> 0 | G17: =SUM(G3:G16) -> 0 | H17: =C17-G17 -> 0 | I17: =IFERROR(H17/G17, 0) -> 0
A19: Values in gold exceed expected or forecasted by 10% or more.
A21: Values in red are below expected or forecasted by 10% or more.

Sheet May
A1: {=portfolio} -> Catalyze | C1: May Actual v. Expected | G1: May Actual v. Forecasted | J1: NOTES | K1: SR
A2: Site | B2: State | C2: Actual | D2: Expected | E2: Delta | F2: % | G2: Forecasted | H2: Delta | I2: %
A3: {=Sites[Site]} -> Fresno - 3150 Shaw Ave | B3: {=Sites[State]} -> CA | C3: {=IF(INDIRECT("'" & $A3 & "'!B9:J9")="", "", INDIRECT("'" & $A3 & "'!B9:J9"))} | E3: 0 | F3: 0 | H3: 0 | I3: 0
A4: Adelanto - 1 Sheep Creek Road | B4: CA | C4: {=IF(INDIRECT("'" & $A4 & "'!B9:J9")="", "", INDIRECT("'" & $A4 & "'!B9:J9"))} | E4: 0 | F4: 0 | H4: 0 | I4: 0
A5: Blackstone - 83 Federal Street | B5: MA | C5: {=IF(INDIRECT("'" & $A5 & "'!B9:J9")="", "", INDIRECT("'" & $A5 & "'!B9:J9"))} | E5: 0 | F5: 0 | H5: 0 | I5: 0
A6: Charlton - 299 Worcester Road | B6: MA | C6: {=IF(INDIRECT("'" & $A6 & "'!B9:J9")="", "", INDIRECT("'" & $A6 & "'!B9:J9"))} | E6: 0 | F6: 0 | H6: 0 | I6: 0
A7: Wareham - 8 Thatcher Drive | B7: MA | C7: {=IF(INDIRECT("'" & $A7 & "'!B9:J9")="", "", INDIRECT("'" & $A7 & "'!B9:J9"))} | E7: 0 | F7: 0 | H7: 0 | I7: 0
A8: West Yarmouth - 42 Mid Tech | B8: MA | C8: {=IF(INDIRECT("'" & $A8 & "'!B9:J9")="", "", INDIRECT("'" & $A8 & "'!B9:J9"))} | E8: 0 | F8: 0 | H8: 0 | I8: 0
A9: Harrison - 130 Union Street | B9: NY | C9: {=IF(INDIRECT("'" & $A9 & "'!B9:J9")="", "", INDIRECT("'" & $A9 & "'!B9:J9"))} | E9: 0 | F9: 0 | H9: 0 | I9: 0
A10: Staten Island - Ellis Storage | B10: NY | C10: {=IF(INDIRECT("'" & $A10 & "'!B9:J9")="", "", INDIRECT("'" & $A10 & "'!B9:J9"))} | E10: 0 | F10: 0 | H10: 0 | I10: 0
A11: Amherst - 595 Scholles Road | B11: NY | C11: {=IF(INDIRECT("'" & $A11 & "'!B9:J9")="", "", INDIRECT("'" & $A11 & "'!B9:J9"))} | E11: 0 | F11: 0 | H11: 0 | I11: 0
A12: Lancaster 1 - Gunnville Road | B12: NY | C12: {=IF(INDIRECT("'" & $A12 & "'!B9:J9")="", "", INDIRECT("'" & $A12 & "'!B9:J9"))} | E12: 0 | F12: 0 | H12: 0 | I12: 0
A13: Lancaster 2 - Shisler Road | B13: NY | C13: {=IF(INDIRECT("'" & $A13 & "'!B9:J9")="", "", INDIRECT("'" & $A13 & "'!B9:J9"))} | E13: 0 | F13: 0 | H13: 0 | I13: 0
A14: Fullerton - 200 W Orangethorpe | B14: CA | C14: {=IF(INDIRECT("'" & $A14 & "'!B9:J9")="", "", INDIRECT("'" & $A14 & "'!B9:J9"))} | E14: 0 | F14: 0 | H14: 0 | I14: 0
A15: El Paso - 10500 Railroad Drive | B15: TX | C15: {=IF(INDIRECT("'" & $A15 & "'!B9:J9")="", "", INDIRECT("'" & $A15 & "'!B9:J9"))} | E15: 0 | F15: 0 | H15: 0 | I15: 0
A16: Friona - 900 Millard Ave | B16: TX | C16: {=IF(INDIRECT("'" & $A16 & "'!B9:J9")="", "", INDIRECT("'" & $A16 & "'!B9:J9"))} | E16: 0 | F16: 0 | H16: 0 | I16: 0
A17: Total | C17: =SUM(C3:C16) -> 0 | D17: =SUM(D3:D16) -> 0 | E17: =C17-D17 -> 0 | F17: =IFERROR(E17/D17, 0) -> 0 | G17: =SUM(G3:G16) -> 0 | H17: =C17-G17 -> 0 | I17: =IFERROR(H17/G17, 0) -> 0
A19: Values in gold exceed expected or forecasted by 10% or more.
A21: Values in red are below expected or forecasted by 10% or more.

Sheet Jun
A1: {=portfolio} -> Catalyze | C1: June Actual v. Expected | G1: June Actual v. Forecasted | J1: NOTES | K1: SR
A2: Site | B2: State | C2: Actual | D2: Expected | E2: Delta | F2: % | G2: Forecasted | H2: Delta | I2: %
A3: {=Sites[Site]} -> Fresno - 3150 Shaw Ave | B3: {=Sites[State]} -> CA | C3: {=IF(INDIRECT("'" & $A3 & "'!B10:J10")="", "", INDIRECT("'" & $A3 & "'!B10:J10"))} | E3: 0 | F3: 0 | H3: 0 | I3: 0
A4: Adelanto - 1 Sheep Creek Road | B4: CA | C4: {=IF(INDIRECT("'" & $A4 & "'!B10:J10")="", "", INDIRECT("'" & $A4 & "'!B10:J10"))} | E4: 0 | F4: 0 | H4: 0 | I4: 0
A5: Blackstone - 83 Federal Street | B5: MA | C5: {=IF(INDIRECT("'" & $A5 & "'!B10:J10")="", "", INDIRECT("'" & $A5 & "'!B10:J10"))} | E5: 0 | F5: 0 | H5: 0 | I5: 0
A6: Charlton - 299 Worcester Road | B6: MA | C6: {=IF(INDIRECT("'" & $A6 & "'!B10:J10")="", "", INDIRECT("'" & $A6 & "'!B10:J10"))} | E6: 0 | F6: 0 | H6: 0 | I6: 0
A7: Wareham - 8 Thatcher Drive | B7: MA | C7: {=IF(INDIRECT("'" & $A7 & "'!B10:J10")="", "", INDIRECT("'" & $A7 & "'!B10:J10"))} | E7: 0 | F7: 0 | H7: 0 | I7: 0
A8: West Yarmouth - 42 Mid Tech | B8: MA | C8: {=IF(INDIRECT("'" & $A8 & "'!B10:J10")="", "", INDIRECT("'" & $A8 & "'!B10:J10"))} | E8: 0 | F8: 0 | H8: 0 | I8: 0
A9: Harrison - 130 Union Street | B9: NY | C9: {=IF(INDIRECT("'" & $A9 & "'!B10:J10")="", "", INDIRECT("'" & $A9 & "'!B10:J10"))} | E9: 0 | F9: 0 | H9: 0 | I9: 0
A10: Staten Island - Ellis Storage | B10: NY | C10: {=IF(INDIRECT("'" & $A10 & "'!B10:J10")="", "", INDIRECT("'" & $A10 & "'!B10:J10"))} | E10: 0 | F10: 0 | H10: 0 | I10: 0
A11: Amherst - 595 Scholles Road | B11: NY | C11: {=IF(INDIRECT("'" & $A11 & "'!B10:J10")="", "", INDIRECT("'" & $A11 & "'!B10:J10"))} | E11: 0 | F11: 0 | H11: 0 | I11: 0
A12: Lancaster 1 - Gunnville Road | B12: NY | C12: {=IF(INDIRECT("'" & $A12 & "'!B10:J10")="", "", INDIRECT("'" & $A12 & "'!B10:J10"))} | E12: 0 | F12: 0 | H12: 0 | I12: 0
A13: Lancaster 2 - Shisler Road | B13: NY | C13: {=IF(INDIRECT("'" & $A13 & "'!B10:J10")="", "", INDIRECT("'" & $A13 & "'!B10:J10"))} | E13: 0 | F13: 0 | H13: 0 | I13: 0
A14: Fullerton - 200 W Orangethorpe | B14: CA | C14: {=IF(INDIRECT("'" & $A14 & "'!B10:J10")="", "", INDIRECT("'" & $A14 & "'!B10:J10"))} | E14: 0 | F14: 0 | H14: 0 | I14: 0
A15: El Paso - 10500 Railroad Drive | B15: TX | C15: {=IF(INDIRECT("'" & $A15 & "'!B10:J10")="", "", INDIRECT("'" & $A15 & "'!B10:J10"))} | E15: 0 | F15: 0 | H15: 0 | I15: 0
A16: Friona - 900 Millard Ave | B16: TX | C16: {=IF(INDIRECT("'" & $A16 & "'!B10:J10")="", "", INDIRECT("'" & $A16 & "'!B10:J10"))} | E16: 0 | F16: 0 | H16: 0 | I16: 0
A17: Total | C17: =SUM(C3:C16) -> 0 | D17: =SUM(D3:D16) -> 0 | E17: =C17-D17 -> 0 | F17: =IFERROR(E17/D17, 0) -> 0 | G17: =SUM(G3:G16) -> 0 | H17: =C17-G17 -> 0 | I17: =IFERROR(H17/G17, 0) -> 0
A19: Values in gold exceed expected or forecasted by 10% or more.
A21: Values in red are below expected or forecasted by 10% or more.

Sheet Jul
A1: {=portfolio} -> Catalyze | C1: July Actual v. Expected | G1: July Actual v. Forecasted | J1: NOTES | K1: SR
A2: Site | B2: State | C2: Actual | D2: Expected | E2: Delta | F2: % | G2: Forecasted | H2: Delta | I2: %
A3: {=Sites[Site]} -> Fresno - 3150 Shaw Ave | B3: {=Sites[State]} -> CA | C3: {=IF(INDIRECT("'" & $A3 & "'!B11:J11")="", "", INDIRECT("'" & $A3 & "'!B11:J11"))} | E3: 0 | F3: 0 | H3: 0 | I3: 0
A4: Adelanto - 1 Sheep Creek Road | B4: CA | C4: {=IF(INDIRECT("'" & $A4 & "'!B11:J11")="", "", INDIRECT("'" & $A4 & "'!B11:J11"))} | E4: 0 | F4: 0 | H4: 0 | I4: 0
A5: Blackstone - 83 Federal Street | B5: MA | C5: {=IF(INDIRECT("'" & $A5 & "'!B11:J11")="", "", INDIRECT("'" & $A5 & "'!B11:J11"))} | E5: 0 | F5: 0 | H5: 0 | I5: 0
A6: Charlton - 299 Worcester Road | B6: MA | C6: {=IF(INDIRECT("'" & $A6 & "'!B11:J11")="", "", INDIRECT("'" & $A6 & "'!B11:J11"))} | E6: 0 | F6: 0 | H6: 0 | I6: 0
A7: Wareham - 8 Thatcher Drive | B7: MA | C7: {=IF(INDIRECT("'" & $A7 & "'!B11:J11")="", "", INDIRECT("'" & $A7 & "'!B11:J11"))} | E7: 0 | F7: 0 | H7: 0 | I7: 0
A8: West Yarmouth - 42 Mid Tech | B8: MA | C8: {=IF(INDIRECT("'" & $A8 & "'!B11:J11")="", "", INDIRECT("'" & $A8 & "'!B11:J11"))} | E8: 0 | F8: 0 | H8: 0 | I8: 0
A9: Harrison - 130 Union Street | B9: NY | C9: {=IF(INDIRECT("'" & $A9 & "'!B11:J11")="", "", INDIRECT("'" & $A9 & "'!B11:J11"))} | E9: 0 | F9: 0 | H9: 0 | I9: 0
A10: Staten Island - Ellis Storage | B10: NY | C10: {=IF(INDIRECT("'" & $A10 & "'!B11:J11")="", "", INDIRECT("'" & $A10 & "'!B11:J11"))} | E10: 0 | F10: 0 | H10: 0 | I10: 0
A11: Amherst - 595 Scholles Road | B11: NY | C11: {=IF(INDIRECT("'" & $A11 & "'!B11:J11")="", "", INDIRECT("'" & $A11 & "'!B11:J11"))} | E11: 0 | F11: 0 | H11: 0 | I11: 0
A12: Lancaster 1 - Gunnville Road | B12: NY | C12: {=IF(INDIRECT("'" & $A12 & "'!B11:J11")="", "", INDIRECT("'" & $A12 & "'!B11:J11"))} | E12: 0 | F12: 0 | H12: 0 | I12: 0
A13: Lancaster 2 - Shisler Road | B13: NY | C13: {=IF(INDIRECT("'" & $A13 & "'!B11:J11")="", "", INDIRECT("'" & $A13 & "'!B11:J11"))} | E13: 0 | F13: 0 | H13: 0 | I13: 0
A14: Fullerton - 200 W Orangethorpe | B14: CA | C14: {=IF(INDIRECT("'" & $A14 & "'!B11:J11")="", "", INDIRECT("'" & $A14 & "'!B11:J11"))} | E14: 0 | F14: 0 | H14: 0 | I14: 0
A15: El Paso - 10500 Railroad Drive | B15: TX | C15: {=IF(INDIRECT("'" & $A15 & "'!B11:J11")="", "", INDIRECT("'" & $A15 & "'!B11:J11"))} | E15: 0 | F15: 0 | H15: 0 | I15: 0
A16: Friona - 900 Millard Ave | B16: TX | C16: {=IF(INDIRECT("'" & $A16 & "'!B11:J11")="", "", INDIRECT("'" & $A16 & "'!B11:J11"))} | E16: 0 | F16: 0 | H16: 0 | I16: 0
A17: Total | C17: =SUM(C3:C16) -> 0 | D17: =SUM(D3:D16) -> 0 | E17: =C17-D17 -> 0 | F17: =IFERROR(E17/D17, 0) -> 0 | G17: =SUM(G3:G16) -> 0 | H17: =C17-G17 -> 0 | I17: =IFERROR(H17/G17, 0) -> 0
A19: Values in gold exceed expected or forecasted by 10% or more.
A21: Values in red are below expected or forecasted by 10% or more.

Sheet Aug
A1: {=portfolio} -> Catalyze | C1: August Actual v. Expected | G1: August Actual v. Forecasted | J1: NOTES | K1: SR
A2: Site | B2: State | C2: Actual | D2: Expected | E2: Delta | F2: % | G2: Forecasted | H2: Delta | I2: %
A3: {=Sites[Site]} -> Fresno - 3150 Shaw Ave | B3: {=Sites[State]} -> CA | C3: {=IF(INDIRECT("'" & $A3 & "'!B12:J12")="", "", INDIRECT("'" & $A3 & "'!B12:J12"))} | E3: 0 | F3: 0 | H3: 0 | I3: 0
A4: Adelanto - 1 Sheep Creek Road | B4: CA | C4: {=IF(INDIRECT("'" & $A4 & "'!B12:J12")="", "", INDIRECT("'" & $A4 & "'!B12:J12"))} | E4: 0 | F4: 0 | H4: 0 | I4: 0
A5: Blackstone - 83 Federal Street | B5: MA | C5: {=IF(INDIRECT("'" & $A5 & "'!B12:J12")="", "", INDIRECT("'" & $A5 & "'!B12:J12"))} | E5: 0 | F5: 0 | H5: 0 | I5: 0
A6: Charlton - 299 Worcester Road | B6: MA | C6: {=IF(INDIRECT("'" & $A6 & "'!B12:J12")="", "", INDIRECT("'" & $A6 & "'!B12:J12"))} | E6: 0 | F6: 0 | H6: 0 | I6: 0
A7: Wareham - 8 Thatcher Drive | B7: MA | C7: {=IF(INDIRECT("'" & $A7 & "'!B12:J12")="", "", INDIRECT("'" & $A7 & "'!B12:J12"))} | E7: 0 | F7: 0 | H7: 0 | I7: 0
A8: West Yarmouth - 42 Mid Tech | B8: MA | C8: {=IF(INDIRECT("'" & $A8 & "'!B12:J12")="", "", INDIRECT("'" & $A8 & "'!B12:J12"))} | E8: 0 | F8: 0 | H8: 0 | I8: 0
A9: Harrison - 130 Union Street | B9: NY | C9: {=IF(INDIRECT("'" & $A9 & "'!B12:J12")="", "", INDIRECT("'" & $A9 & "'!B12:J12"))} | E9: 0 | F9: 0 | H9: 0 | I9: 0
A10: Staten Island - Ellis Storage | B10: NY | C10: {=IF(INDIRECT("'" & $A10 & "'!B12:J12")="", "", INDIRECT("'" & $A10 & "'!B12:J12"))} | E10: 0 | F10: 0 | H10: 0 | I10: 0
A11: Amherst - 595 Scholles Road | B11: NY | C11: {=IF(INDIRECT("'" & $A11 & "'!B12:J12")="", "", INDIRECT("'" & $A11 & "'!B12:J12"))} | E11: 0 | F11: 0 | H11: 0 | I11: 0
A12: Lancaster 1 - Gunnville Road | B12: NY | C12: {=IF(INDIRECT("'" & $A12 & "'!B12:J12")="", "", INDIRECT("'" & $A12 & "'!B12:J12"))} | E12: 0 | F12: 0 | H12: 0 | I12: 0
A13: Lancaster 2 - Shisler Road | B13: NY | C13: {=IF(INDIRECT("'" & $A13 & "'!B12:J12")="", "", INDIRECT("'" & $A13 & "'!B12:J12"))} | E13: 0 | F13: 0 | H13: 0 | I13: 0
A14: Fullerton - 200 W Orangethorpe | B14: CA | C14: {=IF(INDIRECT("'" & $A14 & "'!B12:J12")="", "", INDIRECT("'" & $A14 & "'!B12:J12"))} | E14: 0 | F14: 0 | H14: 0 | I14: 0
A15: El Paso - 10500 Railroad Drive | B15: TX | C15: {=IF(INDIRECT("'" & $A15 & "'!B12:J12")="", "", INDIRECT("'" & $A15 & "'!B12:J12"))} | E15: 0 | F15: 0 | H15: 0 | I15: 0
A16: Friona - 900 Millard Ave | B16: TX | C16: {=IF(INDIRECT("'" & $A16 & "'!B12:J12")="", "", INDIRECT("'" & $A16 & "'!B12:J12"))} | E16: 0 | F16: 0 | H16: 0 | I16: 0
A17: Total | C17: =SUM(C3:C16) -> 0 | D17: =SUM(D3:D16) -> 0 | E17: =C17-D17 -> 0 | F17: =IFERROR(E17/D17, 0) -> 0 | G17: =SUM(G3:G16) -> 0 | H17: =C17-G17 -> 0 | I17: =IFERROR(H17/G17, 0) -> 0
A19: Values in gold exceed expected or forecasted by 10% or more.
A21: Values in red are below expected or forecasted by 10% or more.

Sheet Sep
A1: {=portfolio} -> Catalyze | C1: September Actual v. Expected | G1: September Actual v. Forecasted | J1: NOTES | K1: SR
A2: Site | B2: State | C2: Actual | D2: Expected | E2: Delta | F2: % | G2: Forecasted | H2: Delta | I2: %
A3: {=Sites[Site]} -> Fresno - 3150 Shaw Ave | B3: {=Sites[State]} -> CA | C3: {=IF(INDIRECT("'" & $A3 & "'!B13:J13")="", "", INDIRECT("'" & $A3 & "'!B13:J13"))} | E3: 0 | F3: 0 | H3: 0 | I3: 0
A4: Adelanto - 1 Sheep Creek Road | B4: CA | C4: {=IF(INDIRECT("'" & $A4 & "'!B13:J13")="", "", INDIRECT("'" & $A4 & "'!B13:J13"))} | E4: 0 | F4: 0 | H4: 0 | I4: 0
A5: Blackstone - 83 Federal Street | B5: MA | C5: {=IF(INDIRECT("'" & $A5 & "'!B13:J13")="", "", INDIRECT("'" & $A5 & "'!B13:J13"))} | E5: 0 | F5: 0 | H5: 0 | I5: 0
A6: Charlton - 299 Worcester Road | B6: MA
A7: Wareham - 8 Thatcher Drive | B7: MA | C7: {=IF(INDIRECT("'" & $A7 & "'!B13:J13")="", "", INDIRECT("'" & $A7 & "'!B13:J13"))} | E7: 0 | F7: 0 | H7: 0 | I7: 0
A8: West Yarmouth - 42 Mid Tech | B8: MA | C8: {=IF(INDIRECT("'" & $A8 & "'!B13:J13")="", "", INDIRECT("'" & $A8 & "'!B13:J13"))} | E8: 0 | F8: 0 | H8: 0 | I8: 0
A9: Harrison - 130 Union Street | B9: NY | C9: {=IF(INDIRECT("'" & $A9 & "'!B13:J13")="", "", INDIRECT("'" & $A9 & "'!B13:J13"))} | E9: 0 | F9: 0 | H9: 0 | I9: 0
A10: Staten Island - Ellis Storage | B10: NY | C10: {=IF(INDIRECT("'" & $A10 & "'!B13:J13")="", "", INDIRECT("'" & $A10 & "'!B13:J13"))} | E10: 0 | F10: 0 | H10: 0 | I10: 0
A11: Amherst - 595 Scholles Road | B11: NY | C11: {=IF(INDIRECT("'" & $A11 & "'!B13:J13")="", "", INDIRECT("'" & $A11 & "'!B13:J13"))} | E11: 0 | F11: 0 | H11: 0 | I11: 0
A12: Lancaster 1 - Gunnville Road | B12: NY | C12: {=IF(INDIRECT("'" & $A12 & "'!B13:J13")="", "", INDIRECT("'" & $A12 & "'!B13:J13"))} | E12: 0 | F12: 0 | H12: 0 | I12: 0
A13: Lancaster 2 - Shisler Road | B13: NY | C13: {=IF(INDIRECT("'" & $A13 & "'!B13:J13")="", "", INDIRECT("'" & $A13 & "'!B13:J13"))} | E13: 0 | F13: 0 | H13: 0 | I13: 0
A14: Fullerton - 200 W Orangethorpe | B14: CA | C14: {=IF(INDIRECT("'" & $A14 & "'!B13:J13")="", "", INDIRECT("'" & $A14 & "'!B13:J13"))} | E14: 0 | F14: 0 | H14: 0 | I14: 0
A15: El Paso - 10500 Railroad Drive | B15: TX | C15: {=IF(INDIRECT("'" & $A15 & "'!B13:J13")="", "", INDIRECT("'" & $A15 & "'!B13:J13"))} | E15: 0 | F15: 0 | H15: 0 | I15: 0
A16: Friona - 900 Millard Ave | B16: TX | C16: {=IF(INDIRECT("'" & $A16 & "'!B13:J13")="", "", INDIRECT("'" & $A16 & "'!B13:J13"))} | E16: 0 | F16: 0 | H16: 0 | I16: 0
A17: Total | C17: =SUM(C3:C16) -> 0 | D17: =SUM(D3:D16) -> 0 | E17: =C17-D17 -> 0 | F17: =IFERROR(E17/D17, 0) -> 0 | G17: =SUM(G3:G16) -> 0 | H17: =C17-G17 -> 0 | I17: =IFERROR(H17/G17, 0) -> 0
A21: Values in gold exceed expected or forecasted by 10% or more.
A23: Values in red are below expected or forecasted by 10% or more.

Sheet Oct
A1: {=portfolio} -> Catalyze | C1: October Actual v. Expected | G1: October Actual v. Forecasted | J1: NOTES | K1: SR
A2: Site | B2: State | C2: Actual | D2: Expected | E2: Delta | F2: % | G2: Forecasted | H2: Delta | I2: %
A3: {=Sites[Site]} -> Fresno - 3150 Shaw Ave | B3: {=Sites[State]} -> CA | C3: {=IF(INDIRECT("'" & $A3 & "'!B14:J14")="", "", INDIRECT("'" & $A3 & "'!B14:J14"))} | E3: 0 | F3: 0 | H3: 0 | I3: 0
A4: Adelanto - 1 Sheep Creek Road | B4: CA | C4: {=IF(INDIRECT("'" & $A4 & "'!B14:J14")="", "", INDIRECT("'" & $A4 & "'!B14:J14"))} | E4: 0 | F4: 0 | H4: 0 | I4: 0
A5: Blackstone - 83 Federal Street | B5: MA | C5: {=IF(INDIRECT("'" & $A5 & "'!B14:J14")="", "", INDIRECT("'" & $A5 & "'!B14:J14"))} | E5: 0 | F5: 0 | H5: 0 | I5: 0
A6: Charlton - 299 Worcester Road | B6: MA | C6: {=IF(INDIRECT("'" & $A6 & "'!B14:J14")="", "", INDIRECT("'" & $A6 & "'!B14:J14"))} | E6: 0 | F6: 0 | H6: 0 | I6: 0
A7: Wareham - 8 Thatcher Drive | B7: MA | C7: {=IF(INDIRECT("'" & $A7 & "'!B14:J14")="", "", INDIRECT("'" & $A7 & "'!B14:J14"))} | E7: 0 | F7: 0 | H7: 0 | I7: 0
A8: West Yarmouth - 42 Mid Tech | B8: MA | C8: {=IF(INDIRECT("'" & $A8 & "'!B14:J14")="", "", INDIRECT("'" & $A8 & "'!B14:J14"))} | E8: 0 | F8: 0 | H8: 0 | I8: 0
A9: Harrison - 130 Union Street | B9: NY | C9: {=IF(INDIRECT("'" & $A9 & "'!B14:J14")="", "", INDIRECT("'" & $A9 & "'!B14:J14"))} | E9: 0 | F9: 0 | H9: 0 | I9: 0
A10: Staten Island - Ellis Storage | B10: NY | C10: {=IF(INDIRECT("'" & $A10 & "'!B14:J14")="", "", INDIRECT("'" & $A10 & "'!B14:J14"))} | E10: 0 | F10: 0 | H10: 0 | I10: 0
A11: Amherst - 595 Scholles Road | B11: NY | C11: {=IF(INDIRECT("'" & $A11 & "'!B14:J14")="", "", INDIRECT("'" & $A11 & "'!B14:J14"))} | E11: 0 | F11: 0 | H11: 0 | I11: 0
A12: Lancaster 1 - Gunnville Road | B12: NY | C12: {=IF(INDIRECT("'" & $A12 & "'!B14:J14")="", "", INDIRECT("'" & $A12 & "'!B14:J14"))} | E12: 0 | F12: 0 | H12: 0 | I12: 0
A13: Lancaster 2 - Shisler Road | B13: NY | C13: {=IF(INDIRECT("'" & $A13 & "'!B14:J14")="", "", INDIRECT("'" & $A13 & "'!B14:J14"))} | E13: 0 | F13: 0 | H13: 0 | I13: 0
A14: Fullerton - 200 W Orangethorpe | B14: CA | C14: {=IF(INDIRECT("'" & $A14 & "'!B14:J14")="", "", INDIRECT("'" & $A14 & "'!B14:J14"))} | E14: 0 | F14: 0 | H14: 0 | I14: 0
A15: El Paso - 10500 Railroad Drive | B15: TX | C15: {=IF(INDIRECT("'" & $A15 & "'!B14:J14")="", "", INDIRECT("'" & $A15 & "'!B14:J14"))} | E15: 0 | F15: 0 | H15: 0 | I15: 0
A16: Friona - 900 Millard Ave | B16: TX | C16: {=IF(INDIRECT("'" & $A16 & "'!B14:J14")="", "", INDIRECT("'" & $A16 & "'!B14:J14"))} | E16: 0 | F16: 0 | H16: 0 | I16: 0
A17: Total | C17: =SUM(C3:C16) -> 0 | D17: =SUM(D3:D16) -> 0 | E17: =C17-D17 -> 0 | F17: =IFERROR(E17/D17, 0) -> 0 | G17: =SUM(G3:G16) -> 0 | H17: =C17-G17 -> 0 | I17: =IFERROR(H17/G17, 0) -> 0
A19: Values in gold exceed expected or forecasted by 10% or more.
A21: Values in red are below expected or forecasted by 10% or more.

Sheet Nov
A1: {=portfolio} -> Catalyze | C1: November Actual v. Expected | G1: November Actual v. Forecasted | J1: NOTES | K1: SR
A2: Site | B2: State | C2: Actual | D2: Expected | E2: Delta | F2: % | G2: Forecasted | H2: Delta | I2: %
A3: {=Sites[Site]} -> Fresno - 3150 Shaw Ave | B3: {=Sites[State]} -> CA | C3: {=IF(INDIRECT("'" & $A3 & "'!B15:J15")="", "", INDIRECT("'" & $A3 & "'!B15:J15"))} | E3: 0 | F3: 0 | H3: 0 | I3: 0
A4: Adelanto - 1 Sheep Creek Road | B4: CA | C4: {=IF(INDIRECT("'" & $A4 & "'!B15:J15")="", "", INDIRECT("'" & $A4 & "'!B15:J15"))} | E4: 0 | F4: 0 | H4: 0 | I4: 0
A5: Blackstone - 83 Federal Street | B5: MA | C5: {=IF(INDIRECT("'" & $A5 & "'!B15:J15")="", "", INDIRECT("'" & $A5 & "'!B15:J15"))} | E5: 0 | F5: 0 | H5: 0 | I5: 0
A6: Charlton - 299 Worcester Road | B6: MA | C6: {=IF(INDIRECT("'" & $A6 & "'!B15:J15")="", "", INDIRECT("'" & $A6 & "'!B15:J15"))} | E6: 0 | F6: 0 | H6: 0 | I6: 0
A7: Wareham - 8 Thatcher Drive | B7: MA | C7: {=IF(INDIRECT("'" & $A7 & "'!B15:J15")="", "", INDIRECT("'" & $A7 & "'!B15:J15"))} | E7: 0 | F7: 0 | H7: 0 | I7: 0
A8: West Yarmouth - 42 Mid Tech | B8: MA | C8: {=IF(INDIRECT("'" & $A8 & "'!B15:J15")="", "", INDIRECT("'" & $A8 & "'!B15:J15"))} | E8: 0 | F8: 0 | H8: 0 | I8: 0
A9: Harrison - 130 Union Street | B9: NY | C9: {=IF(INDIRECT("'" & $A9 & "'!B15:J15")="", "", INDIRECT("'" & $A9 & "'!B15:J15"))} | E9: 0 | F9: 0 | H9: 0 | I9: 0
A10: Staten Island - Ellis Storage | B10: NY | C10: {=IF(INDIRECT("'" & $A10 & "'!B15:J15")="", "", INDIRECT("'" & $A10 & "'!B15:J15"))} | E10: 0 | F10: 0 | H10: 0 | I10: 0
A11: Amherst - 595 Scholles Road | B11: NY | C11: {=IF(INDIRECT("'" & $A11 & "'!B15:J15")="", "", INDIRECT("'" & $A11 & "'!B15:J15"))} | E11: 0 | F11: 0 | H11: 0 | I11: 0
A12: Lancaster 1 - Gunnville Road | B12: NY | C12: {=IF(INDIRECT("'" & $A12 & "'!B15:J15")="", "", INDIRECT("'" & $A12 & "'!B15:J15"))} | E12: 0 | F12: 0 | H12: 0 | I12: 0
A13: Lancaster 2 - Shisler Road | B13: NY | C13: {=IF(INDIRECT("'" & $A13 & "'!B15:J15")="", "", INDIRECT("'" & $A13 & "'!B15:J15"))} | E13: 0 | F13: 0 | H13: 0 | I13: 0
A14: Fullerton - 200 W Orangethorpe | B14: CA | C14: {=IF(INDIRECT("'" & $A14 & "'!B15:J15")="", "", INDIRECT("'" & $A14 & "'!B15:J15"))} | E14: 0 | F14: 0 | H14: 0 | I14: 0
A15: El Paso - 10500 Railroad Drive | B15: TX | C15: {=IF(INDIRECT("'" & $A15 & "'!B15:J15")="", "", INDIRECT("'" & $A15 & "'!B15:J15"))} | E15: 0 | F15: 0 | H15: 0 | I15: 0
A16: Friona - 900 Millard Ave | B16: TX | C16: {=IF(INDIRECT("'" & $A16 & "'!B15:J15")="", "", INDIRECT("'" & $A16 & "'!B15:J15"))} | E16: 0 | F16: 0 | H16: 0 | I16: 0
A17: Total | C17: =SUM(C3:C16) -> 0 | D17: =SUM(D3:D16) -> 0 | E17: =C17-D17 -> 0 | F17: =IFERROR(E17/D17, 0) -> 0 | G17: =SUM(G3:G16) -> 0 | H17: =C17-G17 -> 0 | I17: =IFERROR(H17/G17, 0) -> 0
A19: Values in gold exceed expected or forecasted by 10% or more.
A21: Values in red are below expected or forecasted by 10% or more.

Sheet Dec
A1: {=portfolio} -> Catalyze | C1: December Actual v. Expected | G1: December Actual v. Forecasted | J1: NOTES | K1: SR
A2: Site | B2: State | C2: Actual | D2: Expected | E2: Delta | F2: % | G2: Forecasted | H2: Delta | I2: %
A3: {=Sites[Site]} -> Fresno - 3150 Shaw Ave | B3: {=Sites[State]} -> CA | C3: {=IF(INDIRECT("'" & $A3 & "'!B16:J16")="", "", INDIRECT("'" & $A3 & "'!B16:J16"))} | E3: 0 | F3: 0 | H3: 0 | I3: 0
