Workbook
Name JanActual: Jan!$C$3:$C$58
Name JanActual2: Jan!#REF!
Name JanExpected: Jan!$D$3:$D$58
Name JanExpectedDelta: Jan!$E$3:$E$58
Name JanExpectedPercent: Jan!$F$3:$F$58
Name JanExpPercent: Jan!$F$3:$F$58
Name JanForecasted: Jan!$G$3:$G$58
Name JanForecastedDelta: Jan!$H$3:$H$58
Name JanForecastedPercent: Jan!$I$3:$I$58
Name portfolio: Sites!$B$1:$B$1

Sheet YTD Total 2023
A1: {=portfolio} -> Generate Capital | C1: Year to Date 2024 Actual v. Expected | G1: Year to Date 2024 Forecasted
A2: Site | B2: Portfolio | C2: Actual | D2: Expected | E2: Delta | F2: % | G2: Forecasted | H2: Delta | I2: %
A3: {=Sites[Site]} -> Farmer | B3: {=Sites[Portfolio]} -> Blue Renewables | C3: =SUM('1st Qtr'!C3, '2nd Qtr'!C3, '3rd Qtr'!C3, '4th Qtr'!C3) -> 9019.8056 | D3: =SUM('1st Qtr'!D3, '2nd Qtr'!D3, '3rd Qtr'!D3, '4th Qtr'!D3) -> 7182.884 | E3: =C3-D3 -> 1836.9216 | F3: =IFERROR(E3/D3, 0) -> 0.25573594 | G3: =SUM('1st Qtr'!G3, '2nd Qtr'!G3, '3rd Qtr'!G3, '4th Qtr'!G3) -> 9612.777 | H3: =C3-G3 -> -592.97143 | I3: =IFERROR(H3/G3, 0) -> -0.061685758
A4: Fulton | B4: Blue Renewables | C4: =SUM('1st Qtr'!C4, '2nd Qtr'!C4, '3rd Qtr'!C4, '4th Qtr'!C4) -> 29434.75 | D4: =SUM('1st Qtr'!D4, '2nd Qtr'!D4, '3rd Qtr'!D4, '4th Qtr'!D4) -> 28981.22 | E4: =C4-D4 -> 453.53 | F4: =IFERROR(E4/D4, 0) -> 0.0156491 | G4: =SUM('1st Qtr'!G4, '2nd Qtr'!G4, '3rd Qtr'!G4, '4th Qtr'!G4) -> 39673.79 | H4: =C4-G4 -> -10239.04 | I4: =IFERROR(H4/G4, 0) -> -0.25808071
A5: JFK Elementary | B5: Blue Renewables | C5: =SUM('1st Qtr'!C5, '2nd Qtr'!C5, '3rd Qtr'!C5, '4th Qtr'!C5) -> 15656.69 | D5: =SUM('1st Qtr'!D5, '2nd Qtr'!D5, '3rd Qtr'!D5, '4th Qtr'!D5) -> 0 | E5: =C5-D5 -> 15656.69 | F5: =IFERROR(E5/D5, 0) -> 0 | G5: =SUM('1st Qtr'!G5, '2nd Qtr'!G5, '3rd Qtr'!G5, '4th Qtr'!G5) -> 1973 | H5: =C5-G5 -> 13683.69 | I5: =IFERROR(H5/G5, 0) -> 6.9354739
A6: Noble | B6: Blue Renewables | C6: =SUM('1st Qtr'!C6, '2nd Qtr'!C6, '3rd Qtr'!C6, '4th Qtr'!C6) -> 8806.2478 | D6: =SUM('1st Qtr'!D6, '2nd Qtr'!D6, '3rd Qtr'!D6, '4th Qtr'!D6) -> 12098.42 | E6: =C6-D6 -> -3292.1722 | F6: =IFERROR(E6/D6, 0) -> -0.27211588 | G6: =SUM('1st Qtr'!G6, '2nd Qtr'!G6, '3rd Qtr'!G6, '4th Qtr'!G6) -> 11218.66 | H6: =C6-G6 -> -2412.4122 | I6: =IFERROR(H6/G6, 0) -> -0.21503568
A7: Parking 3 | B7: Blue Renewables | C7: =SUM('1st Qtr'!C7, '2nd Qtr'!C7, '3rd Qtr'!C7, '4th Qtr'!C7) -> 16586.8 | D7: =SUM('1st Qtr'!D7, '2nd Qtr'!D7, '3rd Qtr'!D7, '4th Qtr'!D7) -> 24366.89 | E7: =C7-D7 -> -7780.09 | F7: =IFERROR(E7/D7, 0) -> -0.31928941 | G7: =SUM('1st Qtr'!G7, '2nd Qtr'!G7, '3rd Qtr'!G7, '4th Qtr'!G7) -> 24201.63 | H7: =C7-G7 -> -7614.83 | I7: =IFERROR(H7/G7, 0) -> -0.3146412
A8: PE East | B8: Blue Renewables | C8: =SUM('1st Qtr'!C8, '2nd Qtr'!C8, '3rd Qtr'!C8, '4th Qtr'!C8) -> 20730.183 | D8: =SUM('1st Qtr'!D8, '2nd Qtr'!D8, '3rd Qtr'!D8, '4th Qtr'!D8) -> 16836.22 | E8: =C8-D8 -> 3893.9634 | F8: =IFERROR(E8/D8, 0) -> 0.23128489 | G8: =SUM('1st Qtr'!G8, '2nd Qtr'!G8, '3rd Qtr'!G8, '4th Qtr'!G8) -> 24326.73 | H8: =C8-G8 -> -3596.5466 | I8: =IFERROR(H8/G8, 0) -> -0.14784341
A9: Schwada | B9: Blue Renewables | C9: =SUM('1st Qtr'!C9, '2nd Qtr'!C9, '3rd Qtr'!C9, '4th Qtr'!C9) -> 8912.9888 | D9: =SUM('1st Qtr'!D9, '2nd Qtr'!D9, '3rd Qtr'!D9, '4th Qtr'!D9) -> 7118.619 | E9: =C9-D9 -> 1794.3698 | F9: =IFERROR(E9/D9, 0) -> 0.25206712 | G9: =SUM('1st Qtr'!G9, '2nd Qtr'!G9, '3rd Qtr'!G9, '4th Qtr'!G9) -> 10705 | H9: =C9-G9 -> -1792.0112 | I9: =IFERROR(H9/G9, 0) -> -0.16739946
A10: Starshine | B10: Blue Renewables | C10: =SUM('1st Qtr'!C10, '2nd Qtr'!C10, '3rd Qtr'!C10, '4th Qtr'!C10) -> 3747.203 | D10: =SUM('1st Qtr'!D10, '2nd Qtr'!D10, '3rd Qtr'!D10, '4th Qtr'!D10) -> 0 | E10: =C10-D10 -> 3747.203 | F10: =IFERROR(E10/D10, 0) -> 0 | G10: =SUM('1st Qtr'!G10, '2nd Qtr'!G10, '3rd Qtr'!G10, '4th Qtr'!G10) -> 0 | H10: =C10-G10 -> 3747.203 | I10: =IFERROR(H10/G10, 0) -> 0
A11: Yuma Airport | B11: Blue Renewables | C11: =SUM('1st Qtr'!C11, '2nd Qtr'!C11, '3rd Qtr'!C11, '4th Qtr'!C11) -> 52995 | D11: =SUM('1st Qtr'!D11, '2nd Qtr'!D11, '3rd Qtr'!D11, '4th Qtr'!D11) -> 74566.16 | E11: =C11-D11 -> -21571.16 | F11: =IFERROR(E11/D11, 0) -> -0.28928887 | G11: =SUM('1st Qtr'!G11, '2nd Qtr'!G11, '3rd Qtr'!G11, '4th Qtr'!G11) -> 67067 | H11: =C11-G11 -> -14072 | I11: =IFERROR(H11/G11, 0) -> -0.20982003
A12: Kinsman | B12: Blue Renewables | C12: =SUM('1st Qtr'!C12, '2nd Qtr'!C12, '3rd Qtr'!C12, '4th Qtr'!C12) -> 20047.789 | D12: =SUM('1st Qtr'!D12, '2nd Qtr'!D12, '3rd Qtr'!D12, '4th Qtr'!D12) -> 40688.25 | E12: =C12-D12 -> -20640.461 | F12: =IFERROR(E12/D12, 0) -> -0.50728308 | G12: =SUM('1st Qtr'!G12, '2nd Qtr'!G12, '3rd Qtr'!G12, '4th Qtr'!G12) -> 55531 | H12: =C12-G12 -> -35483.211 | I12: =IFERROR(H12/G12, 0) -> -0.63898023
A13: Wooster | B13: Blue Renewables | C13: =SUM('1st Qtr'!C13, '2nd Qtr'!C13, '3rd Qtr'!C13, '4th Qtr'!C13) -> 6323.25 | D13: =SUM('1st Qtr'!D13, '2nd Qtr'!D13, '3rd Qtr'!D13, '4th Qtr'!D13) -> 0 | E13: =C13-D13 -> 6323.25 | F13: =IFERROR(E13/D13, 0) -> 0 | G13: =SUM('1st Qtr'!G13, '2nd Qtr'!G13, '3rd Qtr'!G13, '4th Qtr'!G13) -> 12400 | H13: =C13-G13 -> -6076.75 | I13: =IFERROR(H13/G13, 0) -> -0.49006048
A14: Globe Gila CC | B14: CC Gen Equity | C14: =SUM('1st Qtr'!C14, '2nd Qtr'!C14, '3rd Qtr'!C14, '4th Qtr'!C14) -> 10382.778 | D14: =SUM('1st Qtr'!D14, '2nd Qtr'!D14, '3rd Qtr'!D14, '4th Qtr'!D14) -> 0 | E14: =C14-D14 -> 10382.778 | F14: =IFERROR(E14/D14, 0) -> 0 | G14: =SUM('1st Qtr'!G14, '2nd Qtr'!G14, '3rd Qtr'!G14, '4th Qtr'!G14) -> 11007 | H14: =C14-G14 -> -624.22218 | I14: =IFERROR(H14/G14, 0) -> -0.056711382
A15: Payson Gila CC | B15: CC Gen Equity | C15: =SUM('1st Qtr'!C15, '2nd Qtr'!C15, '3rd Qtr'!C15, '4th Qtr'!C15) -> 6804.5808 | D15: =SUM('1st Qtr'!D15, '2nd Qtr'!D15, '3rd Qtr'!D15, '4th Qtr'!D15) -> 0 | E15: =C15-D15 -> 6804.5808 | F15: =IFERROR(E15/D15, 0) -> 0 | G15: =SUM('1st Qtr'!G15, '2nd Qtr'!G15, '3rd Qtr'!G15, '4th Qtr'!G15) -> 8517 | H15: =C15-G15 -> -1712.4192 | I15: =IFERROR(H15/G15, 0) -> -0.20105896
... A136: Spaulding HS | B136: Sunraise | C136: =SUM('1st Qtr'!C136, '2nd Qtr'!C136, '3rd Qtr'!C136, '4th Qtr'!C136) -> 2486.1235 | D136: =SUM('1st Qtr'!D136, '2nd Qtr'!D136, '3rd Qtr'!D136, '4th Qtr'!D136) -> 6531.708 | E136: =C136-D136 -> -4045.5845 | F136: =IFERROR(E136/D136, 0) -> -0.6193762 | G136: =SUM('1st Qtr'!G136, '2nd Qtr'!G136, '3rd Qtr'!G136, '4th Qtr'!G136) -> 5447.299 | H136: =C136-G136 -> -2961.1755 | I136: =IFERROR(H136/G136, 0) -> -0.54360436
A137: Total | C137: =SUM(C3:C136) -> 5231538.1 | D137: =SUM(D3:D136) -> 2882632.9 | E137: =C137-D137 -> 2348905.2 | F137: =IFERROR(E137/D137, 0) -> 0.81484712 | G137: =SUM(G3:G136) -> 9202509.7 | H137: =C137-G137 -> -3970971.6 | I137: =IFERROR(H137/G137, 0) -> -0.43150964
A139: Values in gold exceed expected or forecasted by 10% or more.
A141: Values in red are below expected or forecasted by 10% or more.

Sheet 1st Qtr
A1: {=portfolio} -> Generate Capital | C1: 1st Quarter 2024 Actual v. Expected | G1: 1st Quarter 2024 Forecasted
A2: Site | B2: Portfolio | C2: Actual | D2: Expected | E2: Delta | F2: % | G2: Forecasted | H2: Delta | I2: %
A3: {=Sites[Site]} -> Farmer | B3: {=Sites[Portfolio]} -> Blue Renewables | C3: =SUM(Jan!C3, Feb!C3, Mar!C3) -> 9019.8056 | D3: =SUM(Jan!D3, Feb!D3, Mar!D3) -> 7182.884 | E3: =C3-D3 -> 1836.9216 | F3: =IFERROR(E3/D3, 0) -> 0.25573594 | G3: =SUM(Jan!G3, Feb!G3, Mar!G3) -> 9612.777 | H3: =C3-G3 -> -592.97143 | I3: =IFERROR(H3/G3, 0) -> -0.061685758
A4: Fulton | B4: Blue Renewables | C4: =SUM(Jan!C4, Feb!C4, Mar!C4) -> 29434.75 | D4: =SUM(Jan!D4, Feb!D4, Mar!D4) -> 28981.22 | E4: =C4-D4 -> 453.53 | F4: =IFERROR(E4/D4, 0) -> 0.0156491 | G4: =SUM(Jan!G4, Feb!G4, Mar!G4) -> 39673.79 | H4: =C4-G4 -> -10239.04 | I4: =IFERROR(H4/G4, 0) -> -0.25808071
A5: JFK Elementary | B5: Blue Renewables | C5: =SUM(Jan!C5, Feb!C5, Mar!C5) -> 15656.69 | D5: =SUM(Jan!D5, Feb!D5, Mar!D5) -> 0 | E5: =C5-D5 -> 15656.69 | F5: =IFERROR(E5/D5, 0) -> 0 | G5: =SUM(Jan!G5, Feb!G5, Mar!G5) -> 1973 | H5: =C5-G5 -> 13683.69 | I5: =IFERROR(H5/G5, 0) -> 6.9354739
A6: Noble | B6: Blue Renewables | C6: =SUM(Jan!C6, Feb!C6, Mar!C6) -> 8806.2478 | D6: =SUM(Jan!D6, Feb!D6, Mar!D6) -> 12098.42 | E6: =C6-D6 -> -3292.1722 | F6: =IFERROR(E6/D6, 0) -> -0.27211588 | G6: =SUM(Jan!G6, Feb!G6, Mar!G6) -> 11218.66 | H6: =C6-G6 -> -2412.4122 | I6: =IFERROR(H6/G6, 0) -> -0.21503568
A7: Parking 3 | B7: Blue Renewables | C7: =SUM(Jan!C7, Feb!C7, Mar!C7) -> 16586.8 | D7: =SUM(Jan!D7, Feb!D7, Mar!D7) -> 24366.89 | E7: =C7-D7 -> -7780.09 | F7: =IFERROR(E7/D7, 0) -> -0.31928941 | G7: =SUM(Jan!G7, Feb!G7, Mar!G7) -> 24201.63 | H7: =C7-G7 -> -7614.83 | I7: =IFERROR(H7/G7, 0) -> -0.3146412
A8: PE East | B8: Blue Renewables | C8: =SUM(Jan!C8, Feb!C8, Mar!C8) -> 20730.183 | D8: =SUM(Jan!D8, Feb!D8, Mar!D8) -> 16836.22 | E8: =C8-D8 -> 3893.9634 | F8: =IFERROR(E8/D8, 0) -> 0.23128489 | G8: =SUM(Jan!G8, Feb!G8, Mar!G8) -> 24326.73 | H8: =C8-G8 -> -3596.5466 | I8: =IFERROR(H8/G8, 0) -> -0.14784341
A9: Schwada | B9: Blue Renewables | C9: =SUM(Jan!C9, Feb!C9, Mar!C9) -> 8912.9888 | D9: =SUM(Jan!D9, Feb!D9, Mar!D9) -> 7118.619 | E9: =C9-D9 -> 1794.3698 | F9: =IFERROR(E9/D9, 0) -> 0.25206712 | G9: =SUM(Jan!G9, Feb!G9, Mar!G9) -> 10705 | H9: =C9-G9 -> -1792.0112 | I9: =IFERROR(H9/G9, 0) -> -0.16739946
A10: Starshine | B10: Blue Renewables | C10: =SUM(Jan!C10, Feb!C10, Mar!C10) -> 3747.203 | D10: =SUM(Jan!D10, Feb!D10, Mar!D10) -> 0 | E10: =C10-D10 -> 3747.203 | F10: =IFERROR(E10/D10, 0) -> 0 | G10: =SUM(Jan!G10, Feb!G10, Mar!G10) -> 0 | H10: =C10-G10 -> 3747.203 | I10: =IFERROR(H10/G10, 0) -> 0
A11: Yuma Airport | B11: Blue Renewables | C11: =SUM(Jan!C11, Feb!C11, Mar!C11) -> 52995 | D11: =SUM(Jan!D11, Feb!D11, Mar!D11) -> 74566.16 | E11: =C11-D11 -> -21571.16 | F11: =IFERROR(E11/D11, 0) -> -0.28928887 | G11: =SUM(Jan!G11, Feb!G11, Mar!G11) -> 67067 | H11: =C11-G11 -> -14072 | I11: =IFERROR(H11/G11, 0) -> -0.20982003
A12: Kinsman | B12: Blue Renewables | C12: =SUM(Jan!C12, Feb!C12, Mar!C12) -> 20047.789 | D12: =SUM(Jan!D12, Feb!D12, Mar!D12) -> 40688.25 | E12: =C12-D12 -> -20640.461 | F12: =IFERROR(E12/D12, 0) -> -0.50728308 | G12: =SUM(Jan!G12, Feb!G12, Mar!G12) -> 55531 | H12: =C12-G12 -> -35483.211 | I12: =IFERROR(H12/G12, 0) -> -0.63898023
A13: Wooster | B13: Blue Renewables | C13: =SUM(Jan!C13, Feb!C13, Mar!C13) -> 6323.25 | D13: =SUM(Jan!D13, Feb!D13, Mar!D13) -> 0 | E13: =C13-D13 -> 6323.25 | F13: =IFERROR(E13/D13, 0) -> 0 | G13: =SUM(Jan!G13, Feb!G13, Mar!G13) -> 12400 | H13: =C13-G13 -> -6076.75 | I13: =IFERROR(H13/G13, 0) -> -0.49006048
A14: Globe Gila CC | B14: CC Gen Equity | C14: =SUM(Jan!C14, Feb!C14, Mar!C14) -> 10382.778 | D14: =SUM(Jan!D14, Feb!D14, Mar!D14) -> 0 | E14: =C14-D14 -> 10382.778 | F14: =IFERROR(E14/D14, 0) -> 0 | G14: =SUM(Jan!G14, Feb!G14, Mar!G14) -> 11007 | H14: =C14-G14 -> -624.22218 | I14: =IFERROR(H14/G14, 0) -> -0.056711382
A15: Payson Gila CC | B15: CC Gen Equity | C15: =SUM(Jan!C15, Feb!C15, Mar!C15) -> 6804.5808 | D15: =SUM(Jan!D15, Feb!D15, Mar!D15) -> 0 | E15: =C15-D15 -> 6804.5808 | F15: =IFERROR(E15/D15, 0) -> 0 | G15: =SUM(Jan!G15, Feb!G15, Mar!G15) -> 8517 | H15: =C15-G15 -> -1712.4192 | I15: =IFERROR(H15/G15, 0) -> -0.20105896
... A136: Spaulding HS | B136: Sunraise | C136: =SUM(Jan!C136, Feb!C136, Mar!C136) -> 2486.1235 | D136: =SUM(Jan!D136, Feb!D136, Mar!D136) -> 6531.708 | E136: =C136-D136 -> -4045.5845 | F136: =IFERROR(E136/D136, 0) -> -0.6193762 | G136: =SUM(Jan!G136, Feb!G136, Mar!G136) -> 5447.299 | H136: =C136-G136 -> -2961.1755 | I136: =IFERROR(H136/G136, 0) -> -0.54360436
A137: Total | C137: =SUM(C3:C136) -> 5231538.1 | D137: =SUM(D3:D136) -> 2882632.9 | E137: =C137-D137 -> 2348905.2 | F137: =IFERROR(E137/D137, 0) -> 0.81484712 | G137: =SUM(G3:G136) -> 9202509.7 | H137: =C137-G137 -> -3970971.6 | I137: =IFERROR(H137/C137, 0) -> -0.75904477
A139: Values in gold exceed expected or forecasted by 10% or more.
A141: Values in red are below expected or forecasted by 10% or more.

Sheet 2nd Qtr
A1: {=portfolio} -> Generate Capital | C1: 2nd Quarter 2024 Actual v. Expected | G1: 2nd Quarter 2024 Forecasted
A2: Site | B2: Portfolio | C2: Actual | D2: Expected | E2: Delta | F2: % | G2: Forecasted | H2: Delta | I2: %
A3: {=Sites[Site]} -> Farmer | B3: {=Sites[Portfolio]} -> Blue Renewables | C3: =SUM(Apr!C3, May!C3, Jun!C3) -> 0 | D3: =SUM(Apr!D3, May!D3, Jun!D3) -> 0 | E3: =C3-D3 -> 0 | F3: =IFERROR(E3/D3, 0) -> 0 | G3: =SUM(Apr!G3, May!G3, Jun!G3) -> 0 | H3: =C3-G3 -> 0 | I3: =IFERROR(H3/G3, 0) -> 0
A4: Fulton | B4: Blue Renewables | C4: =SUM(Apr!C4, May!C4, Jun!C4) -> 0 | D4: =SUM(Apr!D4, May!D4, Jun!D4) -> 0 | E4: =C4-D4 -> 0 | F4: =IFERROR(E4/D4, 0) -> 0 | G4: =SUM(Apr!G4, May!G4, Jun!G4) -> 0 | H4: =C4-G4 -> 0 | I4: =IFERROR(H4/G4, 0) -> 0
A5: JFK Elementary | B5: Blue Renewables | C5: =SUM(Apr!C5, May!C5, Jun!C5) -> 0 | D5: =SUM(Apr!D5, May!D5, Jun!D5) -> 0 | E5: =C5-D5 -> 0 | F5: =IFERROR(E5/D5, 0) -> 0 | G5: =SUM(Apr!G5, May!G5, Jun!G5) -> 0 | H5: =C5-G5 -> 0 | I5: =IFERROR(H5/G5, 0) -> 0
A6: Noble | B6: Blue Renewables | C6: =SUM(Apr!C6, May!C6, Jun!C6) -> 0 | D6: =SUM(Apr!D6, May!D6, Jun!D6) -> 0 | E6: =C6-D6 -> 0 | F6: =IFERROR(E6/D6, 0) -> 0 | G6: =SUM(Apr!G6, May!G6, Jun!G6) -> 0 | H6: =C6-G6 -> 0 | I6: =IFERROR(H6/G6, 0) -> 0
A7: Parking 3 | B7: Blue Renewables | C7: =SUM(Apr!C7, May!C7, Jun!C7) -> 0 | D7: =SUM(Apr!D7, May!D7, Jun!D7) -> 0 | E7: =C7-D7 -> 0 | F7: =IFERROR(E7/D7, 0) -> 0 | G7: =SUM(Apr!G7, May!G7, Jun!G7) -> 0 | H7: =C7-G7 -> 0 | I7: =IFERROR(H7/G7, 0) -> 0
A8: PE East | B8: Blue Renewables | C8: =SUM(Apr!C8, May!C8, Jun!C8) -> 0 | D8: =SUM(Apr!D8, May!D8, Jun!D8) -> 0 | E8: =C8-D8 -> 0 | F8: =IFERROR(E8/D8, 0) -> 0 | G8: =SUM(Apr!G8, May!G8, Jun!G8) -> 0 | H8: =C8-G8 -> 0 | I8: =IFERROR(H8/G8, 0) -> 0
A9: Schwada | B9: Blue Renewables | C9: =SUM(Apr!C9, May!C9, Jun!C9) -> 0 | D9: =SUM(Apr!D9, May!D9, Jun!D9) -> 0 | E9: =C9-D9 -> 0 | F9: =IFERROR(E9/D9, 0) -> 0 | G9: =SUM(Apr!G9, May!G9, Jun!G9) -> 0 | H9: =C9-G9 -> 0 | I9: =IFERROR(H9/G9, 0) -> 0
A10: Starshine | B10: Blue Renewables | C10: =SUM(Apr!C10, May!C10, Jun!C10) -> 0 | D10: =SUM(Apr!D10, May!D10, Jun!D10) -> 0 | E10: =C10-D10 -> 0 | F10: =IFERROR(E10/D10, 0) -> 0 | G10: =SUM(Apr!G10, May!G10, Jun!G10) -> 0 | H10: =C10-G10 -> 0 | I10: =IFERROR(H10/G10, 0) -> 0
A11: Yuma Airport | B11: Blue Renewables | C11: =SUM(Apr!C11, May!C11, Jun!C11) -> 0 | D11: =SUM(Apr!D11, May!D11, Jun!D11) -> 0 | E11: =C11-D11 -> 0 | F11: =IFERROR(E11/D11, 0) -> 0 | G11: =SUM(Apr!G11, May!G11, Jun!G11) -> 0 | H11: =C11-G11 -> 0 | I11: =IFERROR(H11/G11, 0) -> 0
A12: Kinsman | B12: Blue Renewables | C12: =SUM(Apr!C12, May!C12, Jun!C12) -> 0 | D12: =SUM(Apr!D12, May!D12, Jun!D12) -> 0 | E12: =C12-D12 -> 0 | F12: =IFERROR(E12/D12, 0) -> 0 | G12: =SUM(Apr!G12, May!G12, Jun!G12) -> 0 | H12: =C12-G12 -> 0 | I12: =IFERROR(H12/G12, 0) -> 0
A13: Wooster | B13: Blue Renewables | C13: =SUM(Apr!C13, May!C13, Jun!C13) -> 0 | D13: =SUM(Apr!D13, May!D13, Jun!D13) -> 0 | E13: =C13-D13 -> 0 | F13: =IFERROR(E13/D13, 0) -> 0 | G13: =SUM(Apr!G13, May!G13, Jun!G13) -> 0 | H13: =C13-G13 -> 0 | I13: =IFERROR(H13/G13, 0) -> 0
A14: Globe Gila CC | B14: CC Gen Equity | C14: =SUM(Apr!C14, May!C14, Jun!C14) -> 0 | D14: =SUM(Apr!D14, May!D14, Jun!D14) -> 0 | E14: =C14-D14 -> 0 | F14: =IFERROR(E14/D14, 0) -> 0 | G14: =SUM(Apr!G14, May!G14, Jun!G14) -> 0 | H14: =C14-G14 -> 0 | I14: =IFERROR(H14/G14, 0) -> 0
A15: Payson Gila CC | B15: CC Gen Equity | C15: =SUM(Apr!C15, May!C15, Jun!C15) -> 0 | D15: =SUM(Apr!D15, May!D15, Jun!D15) -> 0 | E15: =C15-D15 -> 0 | F15: =IFERROR(E15/D15, 0) -> 0 | G15: =SUM(Apr!G15, May!G15, Jun!G15) -> 0 | H15: =C15-G15 -> 0 | I15: =IFERROR(H15/G15, 0) -> 0
... A136: Spaulding HS | B136: Sunraise | C136: =SUM(Apr!C136, May!C136, Jun!C136) -> 0 | D136: =SUM(Apr!D136, May!D136, Jun!D136) -> 0 | E136: =C136-D136 -> 0 | F136: =IFERROR(E136/D136, 0) -> 0 | G136: =SUM(Apr!G136, May!G136, Jun!G136) -> 0 | H136: =C136-G136 -> 0 | I136: =IFERROR(H136/G136, 0) -> 0
A137: Total | C137: =SUM(C3:C8) -> 0 | D137: =SUM(D3:D8) -> 0 | E137: =C137-D137 -> 0 | F137: =IFERROR(E137/D137, 0) -> 0 | G137: =SUM(G3:G8) -> 0 | H137: =C137-G137 -> 0 | I137: =IFERROR(H137/C137, 0) -> 0
A139: Values in gold exceed expected or forecasted by 10% or more.
A141: Values in red are below expected or forecasted by 10% or more.

Sheet 3rd Qtr
A1: {=portfolio} -> Generate Capital | C1: 3rd Quarter 2024 Actual v. Expected | G1: 3rd Quarter 2024 Forecasted
A2: Site | B2: Portfolio | C2: Actual | D2: Expected | E2: Delta | F2: % | G2: Forecasted | H2: Delta | I2: %
A3: {=Sites[Site]} -> Farmer | B3: {=Sites[Portfolio]} -> Blue Renewables | C3: =SUM(Jul!C3, Aug!C3, Sep!C3) -> 0 | D3: =SUM(Jul!D3, Aug!D3, Sep!D3) -> 0 | E3: =C3-D3 -> 0 | F3: =IFERROR(E3/D3, 0) -> 0 | G3: =SUM(Jul!G3, Aug!G3, Sep!G3) -> 0 | H3: =C3-G3 -> 0 | I3: =IFERROR(H3/G3, 0) -> 0
A4: Fulton | B4: Blue Renewables | C4: =SUM(Jul!C4, Aug!C4, Sep!C4) -> 0 | D4: =SUM(Jul!D4, Aug!D4, Sep!D4) -> 0 | E4: =C4-D4 -> 0 | F4: =IFERROR(E4/D4, 0) -> 0 | G4: =SUM(Jul!G4, Aug!G4, Sep!G4) -> 0 | H4: =C4-G4 -> 0 | I4: =IFERROR(H4/G4, 0) -> 0
A5: JFK Elementary | B5: Blue Renewables | C5: =SUM(Jul!C5, Aug!C5, Sep!C5) -> 0 | D5: =SUM(Jul!D5, Aug!D5, Sep!D5) -> 0 | E5: =C5-D5 -> 0 | F5: =IFERROR(E5/D5, 0) -> 0 | G5: =SUM(Jul!G5, Aug!G5, Sep!G5) -> 0 | H5: =C5-G5 -> 0 | I5: =IFERROR(H5/G5, 0) -> 0
A6: Noble | B6: Blue Renewables | C6: =SUM(Jul!C6, Aug!C6, Sep!C6) -> 0 | D6: =SUM(Jul!D6, Aug!D6, Sep!D6) -> 0 | E6: =C6-D6 -> 0 | F6: =IFERROR(E6/D6, 0) -> 0 | G6: =SUM(Jul!G6, Aug!G6, Sep!G6) -> 0 | H6: =C6-G6 -> 0 | I6: =IFERROR(H6/G6, 0) -> 0
A7: Parking 3 | B7: Blue Renewables | C7: =SUM(Jul!C7, Aug!C7, Sep!C7) -> 0 | D7: =SUM(Jul!D7, Aug!D7, Sep!D7) -> 0 | E7: =C7-D7 -> 0 | F7: =IFERROR(E7/D7, 0) -> 0 | G7: =SUM(Jul!G7, Aug!G7, Sep!G7) -> 0 | H7: =C7-G7 -> 0 | I7: =IFERROR(H7/G7, 0) -> 0
A8: PE East | B8: Blue Renewables | C8: =SUM(Jul!C8, Aug!C8, Sep!C8) -> 0 | D8: =SUM(Jul!D8, Aug!D8, Sep!D8) -> 0 | E8: =C8-D8 -> 0 | F8: =IFERROR(E8/D8, 0) -> 0 | G8: =SUM(Jul!G8, Aug!G8, Sep!G8) -> 0 | H8: =C8-G8 -> 0 | I8: =IFERROR(H8/G8, 0) -> 0
A9: Schwada | B9: Blue Renewables | C9: =SUM(Jul!C9, Aug!C9, Sep!C9) -> 0 | D9: =SUM(Jul!D9, Aug!D9, Sep!D9) -> 0 | E9: =C9-D9 -> 0 | F9: =IFERROR(E9/D9, 0) -> 0 | G9: =SUM(Jul!G9, Aug!G9, Sep!G9) -> 0 | H9: =C9-G9 -> 0 | I9: =IFERROR(H9/G9, 0) -> 0
A10: Starshine | B10: Blue Renewables | C10: =SUM(Jul!C10, Aug!C10, Sep!C10) -> 0 | D10: =SUM(Jul!D10, Aug!D10, Sep!D10) -> 0 | E10: =C10-D10 -> 0 | F10: =IFERROR(E10/D10, 0) -> 0 | G10: =SUM(Jul!G10, Aug!G10, Sep!G10) -> 0 | H10: =C10-G10 -> 0 | I10: =IFERROR(H10/G10, 0) -> 0
A11: Yuma Airport | B11: Blue Renewables | C11: =SUM(Jul!C11, Aug!C11, Sep!C11) -> 0 | D11: =SUM(Jul!D11, Aug!D11, Sep!D11) -> 0 | E11: =C11-D11 -> 0 | F11: =IFERROR(E11/D11, 0) -> 0 | G11: =SUM(Jul!G11, Aug!G11, Sep!G11) -> 0 | H11: =C11-G11 -> 0 | I11: =IFERROR(H11/G11, 0) -> 0
A12: Kinsman | B12: Blue Renewables | C12: =SUM(Jul!C12, Aug!C12, Sep!C12) -> 0 | D12: =SUM(Jul!D12, Aug!D12, Sep!D12) -> 0 | E12: =C12-D12 -> 0 | F12: =IFERROR(E12/D12, 0) -> 0 | G12: =SUM(Jul!G12, Aug!G12, Sep!G12) -> 0 | H12: =C12-G12 -> 0 | I12: =IFERROR(H12/G12, 0) -> 0
A13: Wooster | B13: Blue Renewables | C13: =SUM(Jul!C13, Aug!C13, Sep!C13) -> 0 | D13: =SUM(Jul!D13, Aug!D13, Sep!D13) -> 0 | E13: =C13-D13 -> 0 | F13: =IFERROR(E13/D13, 0) -> 0 | G13: =SUM(Jul!G13, Aug!G13, Sep!G13) -> 0 | H13: =C13-G13 -> 0 | I13: =IFERROR(H13/G13, 0) -> 0
A14: Globe Gila CC | B14: CC Gen Equity | C14: =SUM(Jul!C14, Aug!C14, Sep!C14) -> 0 | D14: =SUM(Jul!D14, Aug!D14, Sep!D14) -> 0 | E14: =C14-D14 -> 0 | F14: =IFERROR(E14/D14, 0) -> 0 | G14: =SUM(Jul!G14, Aug!G14, Sep!G14) -> 0 | H14: =C14-G14 -> 0 | I14: =IFERROR(H14/G14, 0) -> 0
A15: Payson Gila CC | B15: CC Gen Equity | C15: =SUM(Jul!C15, Aug!C15, Sep!C15) -> 0 | D15: =SUM(Jul!D15, Aug!D15, Sep!D15) -> 0 | E15: =C15-D15 -> 0 | F15: =IFERROR(E15/D15, 0) -> 0 | G15: =SUM(Jul!G15, Aug!G15, Sep!G15) -> 0 | H15: =C15-G15 -> 0 | I15: =IFERROR(H15/G15, 0) -> 0
... A136: Spaulding HS | B136: Sunraise | C136: =SUM(Jul!C136, Aug!C136, Sep!C136) -> 0 | D136: =SUM(Jul!D136, Aug!D136, Sep!D136) -> 0 | E136: =C136-D136 -> 0 | F136: =IFERROR(E136/D136, 0) -> 0 | G136: =SUM(Jul!G136, Aug!G136, Sep!G136) -> 0 | H136: =C136-G136 -> 0 | I136: =IFERROR(H136/G136, 0) -> 0
A137: Total | C137: =SUM(C3:C8) -> 0 | D137: =SUM(D3:D8) -> 0 | E137: =C137-D137 -> 0 | F137: =IFERROR(E137/D137, 0) -> 0 | G137: =SUM(G3:G8) -> 0 | H137: =C137-G137 -> 0 | I137: =IFERROR(H137/C137, 0) -> 0
A139: Values in gold exceed expected or forecasted by 10% or more.
A141: Values in red are below expected or forecasted by 10% or more.

Sheet 4th Qtr
A1: {=portfolio} -> Generate Capital | C1: 4th Quarter 2024 Actual v. Expected | G1: 4th Quarter 2024 Forecasted
A2: Site | B2: Portfolio | C2: Actual | D2: Expected | E2: Delta | F2: % | G2: Forecasted | H2: Delta | I2: %
A3: {=Sites[Site]} -> Farmer | B3: {=Sites[Portfolio]} -> Blue Renewables | C3: =SUM(Oct!C3, Nov!C3, Dec!C3) -> 0 | D3: =SUM(Oct!D3, Nov!D3, Dec!D3) -> 0 | E3: =C3-D3 -> 0 | F3: =IFERROR(E3/D3, 0) -> 0 | G3: =SUM(Oct!G3, Nov!G3, Dec!G3) -> 0 | H3: =C3-G3 -> 0 | I3: =IFERROR(H3/G3, 0) -> 0
A4: Fulton | B4: Blue Renewables | C4: =SUM(Oct!C4, Nov!C4, Dec!C4) -> 0 | D4: =SUM(Oct!D4, Nov!D4, Dec!D4) -> 0 | E4: =C4-D4 -> 0 | F4: =IFERROR(E4/D4, 0) -> 0 | G4: =SUM(Oct!G4, Nov!G4, Dec!G4) -> 0 | H4: =C4-G4 -> 0 | I4: =IFERROR(H4/G4, 0) -> 0
A5: JFK Elementary | B5: Blue Renewables | C5: =SUM(Oct!C5, Nov!C5, Dec!C5) -> 0 | D5: =SUM(Oct!D5, Nov!D5, Dec!D5) -> 0 | E5: =C5-D5 -> 0 | F5: =IFERROR(E5/D5, 0) -> 0 | G5: =SUM(Oct!G5, Nov!G5, Dec!G5) -> 0 | H5: =C5-G5 -> 0 | I5: =IFERROR(H5/G5, 0) -> 0
A6: Noble | B6: Blue Renewables | C6: =SUM(Oct!C6, Nov!C6, Dec!C6) -> 0 | D6: =SUM(Oct!D6, Nov!D6, Dec!D6) -> 0 | E6: =C6-D6 -> 0 | F6: =IFERROR(E6/D6, 0) -> 0 | G6: =SUM(Oct!G6, Nov!G6, Dec!G6) -> 0 | H6: =C6-G6 -> 0 | I6: =IFERROR(H6/G6, 0) -> 0
A7: Parking 3 | B7: Blue Renewables | C7: =SUM(Oct!C7, Nov!C7, Dec!C7) -> 0 | D7: =SUM(Oct!D7, Nov!D7, Dec!D7) -> 0 | E7: =C7-D7 -> 0 | F7: =IFERROR(E7/D7, 0) -> 0 | G7: =SUM(Oct!G7, Nov!G7, Dec!G7) -> 0 | H7: =C7-G7 -> 0 | I7: =IFERROR(H7/G7, 0) -> 0
A8: PE East | B8: Blue Renewables | C8: =SUM(Oct!C8, Nov!C8, Dec!C8) -> 0 | D8: =SUM(Oct!D8, Nov!D8, Dec!D8) -> 0 | E8: =C8-D8 -> 0 | F8: =IFERROR(E8/D8, 0) -> 0 | G8: =SUM(Oct!G8, Nov!G8, Dec!G8) -> 0 | H8: =C8-G8 -> 0 | I8: =IFERROR(H8/G8, 0) -> 0
A9: Schwada | B9: Blue Renewables | C9: =SUM(Oct!C9, Nov!C9, Dec!C9) -> 0 | D9: =SUM(Oct!D9, Nov!D9, Dec!D9) -> 0 | E9: =C9-D9 -> 0 | F9: =IFERROR(E9/D9, 0) -> 0 | G9: =SUM(Oct!G9, Nov!G9, Dec!G9) -> 0 | H9: =C9-G9 -> 0 | I9: =IFERROR(H9/G9, 0) -> 0
A10: Starshine | B10: Blue Renewables | C10: =SUM(Oct!C10, Nov!C10, Dec!C10) -> 0 | D10: =SUM(Oct!D10, Nov!D10, Dec!D10) -> 0 | E10: =C10-D10 -> 0 | F10: =IFERROR(E10/D10, 0) -> 0 | G10: =SUM(Oct!G10, Nov!G10, Dec!G10) -> 0 | H10: =C10-G10 -> 0 | I10: =IFERROR(H10/G10, 0) -> 0
A11: Yuma Airport | B11: Blue Renewables | C11: =SUM(Oct!C11, Nov!C11, Dec!C11) -> 0 | D11: =SUM(Oct!D11, Nov!D11, Dec!D11) -> 0 | E11: =C11-D11 -> 0 | F11: =IFERROR(E11/D11, 0) -> 0 | G11: =SUM(Oct!G11, Nov!G11, Dec!G11) -> 0 | H11: =C11-G11 -> 0 | I11: =IFERROR(H11/G11, 0) -> 0
A12: Kinsman | B12: Blue Renewables | C12: =SUM(Oct!C12, Nov!C12, Dec!C12) -> 0 | D12: =SUM(Oct!D12, Nov!D12, Dec!D12) -> 0 | E12: =C12-D12 -> 0 | F12: =IFERROR(E12/D12, 0) -> 0 | G12: =SUM(Oct!G12, Nov!G12, Dec!G12) -> 0 | H12: =C12-G12 -> 0 | I12: =IFERROR(H12/G12, 0) -> 0
A13: Wooster | B13: Blue Renewables | C13: =SUM(Oct!C13, Nov!C13, Dec!C13) -> 0 | D13: =SUM(Oct!D13, Nov!D13, Dec!D13) -> 0 | E13: =C13-D13 -> 0 | F13: =IFERROR(E13/D13, 0) -> 0 | G13: =SUM(Oct!G13, Nov!G13, Dec!G13) -> 0 | H13: =C13-G13 -> 0 | I13: =IFERROR(H13/G13, 0) -> 0
A14: Globe Gila CC | B14: CC Gen Equity | C14: =SUM(Oct!C14, Nov!C14, Dec!C14) -> 0 | D14: =SUM(Oct!D14, Nov!D14, Dec!D14) -> 0 | E14: =C14-D14 -> 0 | F14: =IFERROR(E14/D14, 0) -> 0 | G14: =SUM(Oct!G14, Nov!G14, Dec!G14) -> 0 | H14: =C14-G14 -> 0 | I14: =IFERROR(H14/G14, 0) -> 0
A15: Payson Gila CC | B15: CC Gen Equity | C15: =SUM(Oct!C15, Nov!C15, Dec!C15) -> 0 | D15: =SUM(Oct!D15, Nov!D15, Dec!D15) -> 0 | E15: =C15-D15 -> 0 | F15: =IFERROR(E15/D15, 0) -> 0 | G15: =SUM(Oct!G15, Nov!G15, Dec!G15) -> 0 | H15: =C15-G15 -> 0 | I15: =IFERROR(H15/G15, 0) -> 0
... A136: Spaulding HS | B136: Sunraise | C136: =SUM(Oct!C136, Nov!C136, Dec!C136) -> 0 | D136: =SUM(Oct!D136, Nov!D136, Dec!D136) -> 0 | E136: =C136-D136 -> 0 | F136: =IFERROR(E136/D136, 0) -> 0 | G136: =SUM(Oct!G136, Nov!G136, Dec!G136) -> 0 | H136: =C136-G136 -> 0 | I136: =IFERROR(H136/G136, 0) -> 0
A137: Total | C137: =SUM(C3:C8) -> 0 | D137: =SUM(D3:D8) -> 0 | E137: =C137-D137 -> 0 | F137: =IFERROR(E137/D137, 0) -> 0 | G137: =SUM(G3:G8) -> 0 | H137: =C137-G137 -> 0 | I137: =IFERROR(H137/C137, 0) -> 0
A139: Values in gold exceed expected or forecasted by 10% or more.
A141: Values in red are below expected or forecasted by 10% or more.

Sheet Jan
A1: {=portfolio} -> Generate Capital | C1: January Actual v. Expected | G1: January Actual v. Forecasted | J1: NOTES | K1: SR
A2: Site | B2: Portfolio | C2: Actual | D2: Expected | E2: Delta | F2: % | G2: Forecasted | H2: Delta | I2: %
A3: {=Sites[Site]} -> Farmer | B3: {=Sites[Portfolio]} -> Blue Renewables | C3: {=IF(INDIRECT("'" & $A3 & "'!B5:J5")="", "", INDIRECT("'" & $A3 & "'!B5:J5"))} -> 9019.8056 | D3: 7182.884 | E3: 1836.9216 | F3: 0.25573594 | G3: 9612.777 | H3: -592.97143 | I3: -0.061685758
A4: Fulton | B4: Blue Renewables | C4: {=IF(INDIRECT("'" & $A4 & "'!B5:J5")="", "", INDIRECT("'" & $A4 & "'!B5:J5"))} -> 29434.75 | D4: 28981.22 | E4: 453.53 | F4: 0.0156491 | G4: 39673.79 | H4: -10239.04 | I4: -0.25808071
A5: JFK Elementary | B5: Blue Renewables | C5: {=IF(INDIRECT("'" & $A5 & "'!B5:J5")="", "", INDIRECT("'" & $A5 & "'!B5:J5"))} -> 15656.69 | D5: 0 | E5: 15656.69 | F5: 0 | G5: 1973 | H5: 13683.69 | I5: 6.9354739
A6: Noble | B6: Blue Renewables | C6: {=IF(INDIRECT("'" & $A6 & "'!B5:J5")="", "", INDIRECT("'" & $A6 & "'!B5:J5"))} -> 8806.2478 | D6: 12098.42 | E6: -3292.1722 | F6: -0.27211588 | G6: 11218.66 | H6: -2412.4122 | I6: -0.21503568
A7: Parking 3 | B7: Blue Renewables | C7: {=IF(INDIRECT("'" & $A7 & "'!B5:J5")="", "", INDIRECT("'" & $A7 & "'!B5:J5"))} -> 16586.8 | D7: 24366.89 | E7: -7780.09 | F7: -0.31928941 | G7: 24201.63 | H7: -7614.83 | I7: -0.3146412 | J7: 1.Inverter 1.1 is offline from 01/05 and back online on 01/17 at 10:45AM 2. Inverter 1.1 is offline from 07:00AM on 01/20 and back online at 11:00 on 01/22 | K7: 1.SR079991 2.SR080358
A8: PE East | B8: Blue Renewables | C8: {=IF(INDIRECT("'" & $A8 & "'!B5:J5")="", "", INDIRECT("'" & $A8 & "'!B5:J5"))} -> 20730.183 | D8: 16836.22 | E8: 3893.9634 | F8: 0.23128489 | G8: 24326.73 | H8: -3596.5466 | I8: -0.14784341
A9: Schwada | B9: Blue Renewables | C9: {=IF(INDIRECT("'" & $A9 & "'!B5:J5")="", "", INDIRECT("'" & $A9 & "'!B5:J5"))} -> 8912.9888 | D9: 7118.619 | E9: 1794.3698 | F9: 0.25206712 | G9: 10705 | H9: -1792.0112 | I9: -0.16739946
A10: Starshine | B10: Blue Renewables | C10: {=IF(INDIRECT("'" & $A10 & "'!B5:J5")="", "", INDIRECT("'" & $A10 & "'!B5:J5"))} -> 3747.203 | D10: 0 | E10: 3747.203 | F10: 0 | G10: 0 | H10: 3747.203 | I10: 0 | J10: 1.Site did not started on 01/25 and started late on 01/27. | K10: 1.SR080480
A11: Yuma Airport | B11: Blue Renewables | C11: {=IF(INDIRECT("'" & $A11 & "'!B5:J5")="", "", INDIRECT("'" & $A11 & "'!B5:J5"))} -> 52995 | D11: 74566.16 | E11: -21571.16 | F11: -0.28928887 | G11: 67067 | H11: -14072 | I11: -0.20982003
A12: Kinsman | B12: Blue Renewables | C12: {=IF(INDIRECT("'" & $A12 & "'!B5:J5")="", "", INDIRECT("'" & $A12 & "'!B5:J5"))} -> 20047.789 | D12: 40688.25 | E12: -20640.461 | F12: -0.50728308 | G12: 55531 | H12: -35483.211 | I12: -0.63898023 | J12: 1. Inveter B did not started for production 1/15 and 1/24. | K12: 1. SR080237
A13: Wooster | B13: Blue Renewables | C13: {=IF(INDIRECT("'" & $A13 & "'!B5:J5")="", "", INDIRECT("'" & $A13 & "'!B5:J5"))} -> 6323.25 | D13: 0 | E13: 6323.25 | F13: 0 | G13: 12400 | H13: -6076.75 | I13: -0.49006048
A14: Globe Gila CC | B14: CC Gen Equity | C14: {=IF(INDIRECT("'" & $A14 & "'!B5:J5")="", "", INDIRECT("'" & $A14 & "'!B5:J5"))} -> 10382.778 | D14: 0 | E14: 10382.778 | F14: 0 | G14: 11007 | H14: -624.22218 | I14: -0.056711382
A15: Payson Gila CC | B15: CC Gen Equity | C15: {=IF(INDIRECT("'" & $A15 & "'!B5:J5")="", "", INDIRECT("'" & $A15 & "'!B5:J5"))} -> 6804.5808 | D15: 0 | E15: 6804.5808 | F15: 0 | G15: 8517 | H15: -1712.4192 | I15: -0.20105896
A16: SCNM | B16: CC Gen Equity | C16: {=IF(INDIRECT("'" & $A16 & "'!B5:J5")="", "", INDIRECT("'" & $A16 & "'!B5:J5"))} -> 51680.32 | D16: 0 | E16: 51680.32 | F16: 0 | G16: 28849 | H16: 22831.32 | I16: 0.79140767
A17: Sequoia Charter School | B17: CC Gen Equity | C17: {=IF(INDIRECT("'" & $A17 & "'!B5:J5")="", "", INDIRECT("'" & $A17 & "'!B5:J5"))} -> 20768 | D17: 0 | E17: 20768 | F17: 0 | G17: 8180 | H17: 12588 | I17: 1.5388753
A18: RCAB | B18: GESF2 | C18: {=IF(INDIRECT("'" & $A18 & "'!B5:J5")="", "", INDIRECT("'" & $A18 & "'!B5:J5"))} -> 23135 | D18: 43481.12 | E18: -20346.12 | F18: -0.46792999 | G18: 47410.87 | H18: -24275.87 | I18: -0.51203173
A19: Spectro Coatings | B19: GESF2 | C19: {=IF(INDIRECT("'" & $A19 & "'!B5:J5")="", "", INDIRECT("'" & $A19 & "'!B5:J5"))} -> 5510.625 | D19: 12146.73 | E19: -6636.105 | F19: -0.54632852 | G19: 11789.76 | H19: -6279.135 | I19: -0.53259227 | J19: 1. Site was offline on 1/22 at 15:30 and back online on 1/23 11:45. | K19: 1. SR080401
A20: K026 | B20: Hudson | C20: {=IF(INDIRECT("'" & $A20 & "'!B5:J5")="", "", INDIRECT("'" & $A20 & "'!B5:J5"))} -> 7049.125 | D20: 12398.04 | E20: -5348.915 | F20: -0.43143231 | G20: 18592.65 | H20: -11543.525 | I20: -0.62086497
A21: K041 | B21: Hudson | C21: {=IF(INDIRECT("'" & $A21 & "'!B5:J5")="", "", INDIRECT("'" & $A21 & "'!B5:J5"))} -> 2400.5966 | D21: 0 | E21: 2400.5966 | F21: 0 | G21: 0 | H21: 2400.5966 | I21: 0 | J21: 1. Site started production from 1/18 | K21: 1. SR079892
A22: K043 | B22: Hudson | C22: {=IF(INDIRECT("'" & $A22 & "'!B5:J5")="", "", INDIRECT("'" & $A22 & "'!B5:J5"))} -> 7037.3281 | D22: 10909.38 | E22: -3872.0519 | F22: -0.35492868 | G22: 20258 | H22: -13220.672 | I22: -0.65261486
A23: K058 | B23: Hudson | C23: {=IF(INDIRECT("'" & $A23 & "'!B5:J5")="", "", INDIRECT("'" & $A23 & "'!B5:J5"))} -> 5262.6875 | D23: 8705.562 | E23: -3442.8745 | F23: -0.39547987 | G23: 13134.4 | H23: -7871.7125 | I23: -0.5993203
A24: K115 | B24: Hudson | C24: {=IF(INDIRECT("'" & $A24 & "'!B5:J5")="", "", INDIRECT("'" & $A24 & "'!B5:J5"))} -> 1496.6526 | D24: 5139.646 | E24: -3642.9934 | F24: -0.7088024 | G24: 4549.33 | H24: -3052.6774 | I24: -0.67101692 | J24: 1. Ongoing construction to the array on the roof. 70 percent of the array is offline for construction | K24: 1. SR077214
A25: K152 | B25: Hudson | C25: {=IF(INDIRECT("'" & $A25 & "'!B5:J5")="", "", INDIRECT("'" & $A25 & "'!B5:J5"))} -> 1927.1875 | D25: 3008.157 | E25: -1080.9695 | F25: -0.3593461 | G25: 798 | H25: 1129.1875 | I25: 1.4150219
A26: K166 | B26: Hudson | C26: {=IF(INDIRECT("'" & $A26 & "'!B5:J5")="", "", INDIRECT("'" & $A26 & "'!B5:J5"))} -> 7390.625 | D26: 11891.79 | E26: -4501.165 | F26: -0.3785103 | G26: 18302.04 | H26: -10911.415 | I26: -0.59618573
A27: K206 | B27: Hudson | C27: {=IF(INDIRECT("'" & $A27 & "'!B5:J5")="", "", INDIRECT("'" & $A27 & "'!B5:J5"))} -> 4600.7732 | D27: 0 | E27: 4600.7732 | F27: 0 | G27: 0 | H27: 4600.7732 | I27: 0
A28: K251 | B28: Hudson | C28: {=IF(INDIRECT("'" & $A28 & "'!B5:J5")="", "", INDIRECT("'" & $A28 & "'!B5:J5"))} -> 4966.375 | D28: 7470.177 | E28: -2503.802 | F28: -0.33517305 | G28: 9815.687 | H28: -4849.312 | I28: -0.49403694
A29: K269 | B29: Hudson | C29: {=IF(INDIRECT("'" & $A29 & "'!B5:J5")="", "", INDIRECT("'" & $A29 & "'!B5:J5"))} -> 4328.3125 | D29: 0 | E29: 4328.3125 | F29: 0 | G29: 10978.73 | H29: -6650.4175 | I29: -0.60575472
A30: K273 | B30: Hudson | C30: {=IF(INDIRECT("'" & $A30 & "'!B5:J5")="", "", INDIRECT("'" & $A30 & "'!B5:J5"))} -> 5062.0312 | D30: 0 | E30: 5062.0312 | F30: 0 | G30: 11224 | H30: -6161.9688 | I30: -0.54899935
A31: K287 | B31: Hudson | C31: {=IF(INDIRECT("'" & $A31 & "'!B5:J5")="", "", INDIRECT("'" & $A31 & "'!B5:J5"))} -> 3720.0499 | D31: 5487.586 | E31: -1767.5361 | F31: -0.3220972 | G31: 0 | H31: 3720.0499 | I31: 0
A32: K298 | B32: Hudson | C32: {=IF(INDIRECT("'" & $A32 & "'!B5:J5")="", "", INDIRECT("'" & $A32 & "'!B5:J5"))} -> 3421.0781 | D32: 7008.588 | E32: -3587.5099 | F32: -0.51187342 | G32: 0 | H32: 3421.0781 | I32: 0 | J32: 1. Inverter 1 primary unit offline on 01/19/2024 & back online 01/25/2024 at 10:00. | K32: 1. SR080472
A33: K335 | B33: Hudson | C33: {=IF(INDIRECT("'" & $A33 & "'!B5:J5")="", "", INDIRECT("'" & $A33 & "'!B5:J5"))} -> 4100.5625 | D33: 7358.259 | E33: -3257.6965 | F33: -0.44272653 | G33: 11610 | H33: -7509.4375 | I33: -0.64680771
A34: K345 | B34: Hudson | C34: {=IF(INDIRECT("'" & $A34 & "'!B5:J5")="", "", INDIRECT("'" & $A34 & "'!B5:J5"))} -> 4561.2969 | D34: 0 | E34: 4561.2969 | F34: 0 | G34: 0 | H34: 4561.2969 | I34: 0 | J34: 1. Site tripped offline on 01/11 at 8:15 and back online at 11:15, but inverter 2 again tripped offline 2. Inverter 2 tripped offline on 01/11 at 11:45 and back online on 01/12 | K34: 1. SR080156 2. SR080165
A35: K445 | B35: Hudson | C35: {=IF(INDIRECT("'" & $A35 & "'!B5:J5")="", "", INDIRECT("'" & $A35 & "'!B5:J5"))} -> 4488.8051 | D35: 0 | E35: 4488.8051 | F35: 0 | G35: 0 | H35: 4488.8051 | I35: 0
A36: K495 | B36: Hudson | C36: {=IF(INDIRECT("'" & $A36 & "'!B5:J5")="", "", INDIRECT("'" & $A36 & "'!B5:J5"))} -> 20449.188 | D36: 0 | E36: 20449.188 | F36: 0 | G36: 0 | H36: 20449.188 | I36: 0 | J36: 1. Inverter 4 tripped offline at 10:50 at 01/17 & back online on 01/20/2024. 2. Inverter 8 left unit offline on 01/07/2024 & back online at 01/08/2024 and also left unit offline from 01/16 to 01/22 | K36: 1.SR080297 2.SR080299
A37: M020 | B37: Hudson | C37: {=IF(INDIRECT("'" & $A37 & "'!B5:J5")="", "", INDIRECT("'" & $A37 & "'!B5:J5"))} -> 4382.6562 | D37: 7052.359 | E37: -2669.7028 | F37: -0.37855457 | G37: 0 | H37: 4382.6562 | I37: 0
A38: M092 | B38: Hudson | C38: {=IF(INDIRECT("'" & $A38 & "'!B5:J5")="", "", INDIRECT("'" & $A38 & "'!B5:J5"))} -> 4470.75 | D38: 7217.819 | E38: -2747.069 | F38: -0.38059544 | G38: 11299.41 | H38: -6828.66 | I38: -0.60433775
A39: M143 | B39: Hudson | C39: {=IF(INDIRECT("'" & $A39 & "'!B5:J5")="", "", INDIRECT("'" & $A39 & "'!B5:J5"))} -> 4964.5 | D39: 7892.974 | E39: -2928.474 | F39: -0.37102289 | G39: 15533.26 | H39: -10568.76 | I39: -0.68039549
A40: M144 | B40: Hudson | C40: {=IF(INDIRECT("'" & $A40 & "'!B5:J5")="", "", INDIRECT("'" & $A40 & "'!B5:J5"))} -> 7482.3594 | D40: 0 | E40: 7482.3594 | F40: 0 | G40: 0 | H40: 7482.3594 | I40: 0
...

Sheet Feb
A1: {=portfolio} -> Generate Capital | C1: February Actual v. Expected | G1: February Actual v. Forecasted | J1: NOTES | K1: SR
A2: Site | B2: Portfolio | C2: Actual | D2: Expected | E2: Delta | F2: % | G2: Forecasted | H2: Delta | I2: %
A3: {=Sites[Site]} -> Farmer | B3: {=Sites[Portfolio]} -> Blue Renewables | C3: {=IF(INDIRECT("'" & $A3 & "'!B6:J6")="", "", INDIRECT("'" & $A3 & "'!B6:J6"))} | E3: 0 | F3: 0 | H3: 0 | I3: 0
A4: Fulton | B4: Blue Renewables | C4: {=IF(INDIRECT("'" & $A4 & "'!B6:J6")="", "", INDIRECT("'" & $A4 & "'!B6:J6"))} | E4: 0 | F4: 0 | H4: 0 | I4: 0
A5: JFK Elementary | B5: Blue Renewables | C5: {=IF(INDIRECT("'" & $A5 & "'!B6:J6")="", "", INDIRECT("'" & $A5 & "'!B6:J6"))} | E5: 0 | F5: 0 | H5: 0 | I5: 0
A6: Noble | B6: Blue Renewables | C6: {=IF(INDIRECT("'" & $A6 & "'!B6:J6")="", "", INDIRECT("'" & $A6 & "'!B6:J6"))} | E6: 0 | F6: 0 | H6: 0 | I6: 0
A7: Parking 3 | B7: Blue Renewables | C7: {=IF(INDIRECT("'" & $A7 & "'!B6:J6")="", "", INDIRECT("'" & $A7 & "'!B6:J6"))} | E7: 0 | F7: 0 | H7: 0 | I7: 0
A8: PE East | B8: Blue Renewables | C8: {=IF(INDIRECT("'" & $A8 & "'!B6:J6")="", "", INDIRECT("'" & $A8 & "'!B6:J6"))} | E8: 0 | F8: 0 | H8: 0 | I8: 0
A9: Schwada | B9: Blue Renewables | C9: {=IF(INDIRECT("'" & $A9 & "'!B6:J6")="", "", INDIRECT("'" & $A9 & "'!B6:J6"))} | E9: 0 | F9: 0 | H9: 0 | I9: 0
A10: Starshine | B10: Blue Renewables | C10: {=IF(INDIRECT("'" & $A10 & "'!B6:J6")="", "", INDIRECT("'" & $A10 & "'!B6:J6"))} | E10: 0 | F10: 0 | H10: 0 | I10: 0
A11: Yuma Airport | B11: Blue Renewables | C11: {=IF(INDIRECT("'" & $A11 & "'!B6:J6")="", "", INDIRECT("'" & $A11 & "'!B6:J6"))} | E11: 0 | F11: 0 | H11: 0 | I11: 0
A12: Kinsman | B12: Blue Renewables | C12: {=IF(INDIRECT("'" & $A12 & "'!B6:J6")="", "", INDIRECT("'" & $A12 & "'!B6:J6"))} | E12: 0 | F12: 0 | H12: 0 | I12: 0
A13: Wooster | B13: Blue Renewables | C13: {=IF(INDIRECT("'" & $A13 & "'!B6:J6")="", "", INDIRECT("'" & $A13 & "'!B6:J6"))} | E13: 0 | F13: 0 | H13: 0 | I13: 0
A14: Globe Gila CC | B14: CC Gen Equity | C14: {=IF(INDIRECT("'" & $A14 & "'!B6:J6")="", "", INDIRECT("'" & $A14 & "'!B6:J6"))} | E14: 0 | F14: 0 | H14: 0 | I14: 0
A15: Payson Gila CC | B15: CC Gen Equity | C15: {=IF(INDIRECT("'" & $A15 & "'!B6:J6")="", "", INDIRECT("'" & $A15 & "'!B6:J6"))} | E15: 0 | F15: 0 | H15: 0 | I15: 0
... A136: Spaulding HS | B136: Sunraise | C136: {=IF(INDIRECT("'" & $A136 & "'!B6:J6")="", "", INDIRECT("'" & $A136 & "'!B6:J6"))} | E136: 0 | F136: 0 | H136: 0 | I136: 0
A137: Total | C137: =SUM(C3:C61) -> 0 | D137: =SUM(D3:D61) -> 0 | E137: =C137-D137 -> 0 | F137: =IFERROR(E137/D137, 0) -> 0 | G137: =SUM(G3:G61) -> 0 | H137: =C137-G137 -> 0 | I137: =IFERROR(H137/G137, 0) -> 0
A139: Values in gold exceed expected or forecasted by 10% or more.
A141: Values in red are below expected or forecasted by 10% or more.

Sheet Mar
A1: {=portfolio} -> Generate Capital | C1: March Actual v. Expected | G1: March Actual v. Forecasted | J1: NOTES | K1: SR
A2: Site | B2: Portfolio | C2: Actual | D2: Expected | E2: Delta | F2: % | G2: Forecasted | H2: Delta | I2: %
A3: {=Sites[Site]} -> Farmer | B3: {=Sites[Portfolio]} -> Blue Renewables | C3: {=IF(INDIRECT("'" & $A3 & "'!B7:J7")="", "", INDIRECT("'" & $A3 & "'!B7:J7"))} | E3: 0 | F3: 0 | H3: 0 | I3: 0
A4: Fulton | B4: Blue Renewables | C4: {=IF(INDIRECT("'" & $A4 & "'!B7:J7")="", "", INDIRECT("'" & $A4 & "'!B7:J7"))} | E4: 0 | F4: 0 | H4: 0 | I4: 0
A5: JFK Elementary | B5: Blue Renewables | C5: {=IF(INDIRECT("'" & $A5 & "'!B7:J7")="", "", INDIRECT("'" & $A5 & "'!B7:J7"))} | E5: 0 | F5: 0 | H5: 0 | I5: 0
A6: Noble | B6: Blue Renewables | C6: {=IF(INDIRECT("'" & $A6 & "'!B7:J7")="", "", INDIRECT("'" & $A6 & "'!B7:J7"))} | E6: 0 | F6: 0 | H6: 0 | I6: 0
A7: Parking 3 | B7: Blue Renewables | C7: {=IF(INDIRECT("'" & $A7 & "'!B7:J7")="", "", INDIRECT("'" & $A7 & "'!B7:J7"))} | E7: 0 | F7: 0 | H7: 0 | I7: 0
A8: PE East | B8: Blue Renewables | C8: {=IF(INDIRECT("'" & $A8 & "'!B7:J7")="", "", INDIRECT("'" & $A8 & "'!B7:J7"))} | E8: 0 | F8: 0 | H8: 0 | I8: 0
A9: Schwada | B9: Blue Renewables | C9: {=IF(INDIRECT("'" & $A9 & "'!B7:J7")="", "", INDIRECT("'" & $A9 & "'!B7:J7"))} | E9: 0 | F9: 0 | H9: 0 | I9: 0
A10: Starshine | B10: Blue Renewables | C10: {=IF(INDIRECT("'" & $A10 & "'!B7:J7")="", "", INDIRECT("'" & $A10 & "'!B7:J7"))} | E10: 0 | F10: 0 | H10: 0 | I10: 0
A11: Yuma Airport | B11: Blue Renewables | C11: {=IF(INDIRECT("'" & $A11 & "'!B7:J7")="", "", INDIRECT("'" & $A11 & "'!B7:J7"))} | E11: 0 | F11: 0 | H11: 0 | I11: 0
A12: Kinsman | B12: Blue Renewables | C12: {=IF(INDIRECT("'" & $A12 & "'!B7:J7")="", "", INDIRECT("'" & $A12 & "'!B7:J7"))} | E12: 0 | F12: 0 | H12: 0 | I12: 0
A13: Wooster | B13: Blue Renewables | C13: {=IF(INDIRECT("'" & $A13 & "'!B7:J7")="", "", INDIRECT("'" & $A13 & "'!B7:J7"))} | E13: 0 | F13: 0 | H13: 0 | I13: 0
A14: Globe Gila CC | B14: CC Gen Equity | C14: {=IF(INDIRECT("'" & $A14 & "'!B7:J7")="", "", INDIRECT("'" & $A14 & "'!B7:J7"))} | E14: 0 | F14: 0 | H14: 0 | I14: 0
A15: Payson Gila CC | B15: CC Gen Equity | C15: {=IF(INDIRECT("'" & $A15 & "'!B7:J7")="", "", INDIRECT("'" & $A15 & "'!B7:J7"))} | E15: 0 | F15: 0 | H15: 0 | I15: 0
... A136: Spaulding HS | B136: Sunraise | C136: {=IF(INDIRECT("'" & $A136 & "'!B7:J7")="", "", INDIRECT("'" & $A136 & "'!B7:J7"))} | E136: 0 | F136: 0 | H136: 0 | I136: 0
A137: Total | C137: =SUM(C3:C61) -> 0 | D137: =SUM(D3:D61) -> 0 | E137: =C137-D137 -> 0 | F137: =IFERROR(E137/D137, 0) -> 0 | G137: =SUM(G3:G61) -> 0 | H137: =C137-G137 -> 0 | I137: =IFERROR(H137/G137, 0) -> 0
A139: Values in gold exceed expected or forecasted by 10% or more.
A141: Values in red are below expected or forecasted by 10% or more.

Sheet Apr
A1: {=portfolio} -> Generate Capital | C1: April Actual v. Expected | G1: April Actual v. Forecasted | J1: NOTES | K1: SR
A2: Site | B2: Portfolio | C2: Actual | D2: Expected | E2: Delta | F2: % | G2: Forecasted | H2: Delta | I2: %
A3: {=Sites[Site]} -> Farmer | B3: {=Sites[Portfolio]} -> Blue Renewables | C3: {=IF(INDIRECT("'" & $A3 & "'!B8:J8")="", "", INDIRECT("'" & $A3 & "'!B8:J8"))} | E3: 0 | F3: 0 | H3: 0 | I3: 0
A4: Fulton | B4: Blue Renewables | C4: {=IF(INDIRECT("'" & $A4 & "'!B8:J8")="", "", INDIRECT("'" & $A4 & "'!B8:J8"))} | E4: 0 | F4: 0 | H4: 0 | I4: 0
A5: JFK Elementary | B5: Blue Renewables | C5: {=IF(INDIRECT("'" & $A5 & "'!B8:J8")="", "", INDIRECT("'" & $A5 & "'!B8:J8"))} | E5: 0 | F5: 0 | H5: 0 | I5: 0
A6: Noble | B6: Blue Renewables | C6: {=IF(INDIRECT("'" & $A6 & "'!B8:J8")="", "", INDIRECT("'" & $A6 & "'!B8:J8"))} | E6: 0 | F6: 0 | H6: 0 | I6: 0
A7: Parking 3 | B7: Blue Renewables | C7: {=IF(INDIRECT("'" & $A7 & "'!B8:J8")="", "", INDIRECT("'" & $A7 & "'!B8:J8"))} | E7: 0 | F7: 0 | H7: 0 | I7: 0
A8: PE East | B8: Blue Renewables | C8: {=IF(INDIRECT("'" & $A8 & "'!B8:J8")="", "", INDIRECT("'" & $A8 & "'!B8:J8"))} | E8: 0 | F8: 0 | H8: 0 | I8: 0
A9: Schwada | B9: Blue Renewables | C9: {=IF(INDIRECT("'" & $A9 & "'!B8:J8")="", "", INDIRECT("'" & $A9 & "'!B8:J8"))} | E9: 0 | F9: 0 | H9: 0 | I9: 0
A10: Starshine | B10: Blue Renewables | C10: {=IF(INDIRECT("'" & $A10 & "'!B8:J8")="", "", INDIRECT("'" & $A10 & "'!B8:J8"))} | E10: 0 | F10: 0 | H10: 0 | I10: 0
A11: Yuma Airport | B11: Blue Renewables | C11: {=IF(INDIRECT("'" & $A11 & "'!B8:J8")="", "", INDIRECT("'" & $A11 & "'!B8:J8"))} | E11: 0 | F11: 0 | H11: 0 | I11: 0
A12: Kinsman | B12: Blue Renewables | C12: {=IF(INDIRECT("'" & $A12 & "'!B8:J8")="", "", INDIRECT("'" & $A12 & "'!B8:J8"))} | E12: 0 | F12: 0 | H12: 0 | I12: 0
A13: Wooster | B13: Blue Renewables | C13: {=IF(INDIRECT("'" & $A13 & "'!B8:J8")="", "", INDIRECT("'" & $A13 & "'!B8:J8"))} | E13: 0 | F13: 0 | H13: 0 | I13: 0
A14: Globe Gila CC | B14: CC Gen Equity | C14: {=IF(INDIRECT("'" & $A14 & "'!B8:J8")="", "", INDIRECT("'" & $A14 & "'!B8:J8"))} | E14: 0 | F14: 0 | H14: 0 | I14: 0
A15: Payson Gila CC | B15: CC Gen Equity | C15: {=IF(INDIRECT("'" & $A15 & "'!B8:J8")="", "", INDIRECT("'" & $A15 & "'!B8:J8"))} | E15: 0 | F15: 0 | H15: 0 | I15: 0
... A136: Spaulding HS | B136: Sunraise | C136: {=IF(INDIRECT("'" & $A136 & "'!B8:J8")="", "", INDIRECT("'" & $A136 & "'!B8:J8"))} | E136: 0 | F136: 0 | H136: 0 | I136: 0
A137: Total | C137: =SUM(C3:C61) -> 0 | D137: =SUM(D3:D61) -> 0 | E137: =C137-D137 -> 0 | F137: =IFERROR(E137/D137, 0) -> 0 | G137: =SUM(G3:G61) -> 0 | H137: =C137-G137 -> 0 | I137: =IFERROR(H137/G137, 0) -> 0
A139: Values in gold exceed expected or forecasted by 10% or more.
A141: Values in red are below expected or forecasted by 10% or more.

Sheet May
A1: {=portfolio} -> Generate Capital | C1: May Actual v. Expected | G1: May Actual v. Forecasted | J1: NOTES | K1: SR
A2: Site | B2: Portfolio | C2: Actual | D2: Expected | E2: Delta | F2: % | G2: Forecasted | H2: Delta | I2: %
A3: {=Sites[Site]} -> Farmer | B3: {=Sites[Portfolio]} -> Blue Renewables | C3: {=IF(INDIRECT("'" & $A3 & "'!B9:J9")="", "", INDIRECT("'" & $A3 & "'!B9:J9"))} | E3: 0 | F3: 0 | H3: 0 | I3: 0
A4: Fulton | B4: Blue Renewables | C4: {=IF(INDIRECT("'" & $A4 & "'!B9:J9")="", "", INDIRECT("'" & $A4 & "'!B9:J9"))} | E4: 0 | F4: 0 | H4: 0 | I4: 0
A5: JFK Elementary | B5: Blue Renewables | C5: {=IF(INDIRECT("'" & $A5 & "'!B9:J9")="", "", INDIRECT("'" & $A5 & "'!B9:J9"))} | E5: 0 | F5: 0 | H5: 0 | I5: 0
A6: Noble | B6: Blue Renewables | C6: {=IF(INDIRECT("'" & $A6 & "'!B9:J9")="", "", INDIRECT("'" & $A6 & "'!B9:J9"))} | E6: 0 | F6: 0 | H6: 0 | I6: 0
A7: Parking 3 | B7: Blue Renewables | C7: {=IF(INDIRECT("'" & $A7 & "'!B9:J9")="", "", INDIRECT("'" & $A7 & "'!B9:J9"))} | E7: 0 | F7: 0 | H7: 0 | I7: 0
A8: PE East | B8: Blue Renewables | C8: {=IF(INDIRECT("'" & $A8 & "'!B9:J9")="", "", INDIRECT("'" & $A8 & "'!B9:J9"))} | E8: 0 | F8: 0 | H8: 0 | I8: 0
A9: Schwada | B9: Blue Renewables | C9: {=IF(INDIRECT("'" & $A9 & "'!B9:J9")="", "", INDIRECT("'" & $A9 & "'!B9:J9"))} | E9: 0 | F9: 0 | H9: 0 | I9: 0
A10: Starshine | B10: Blue Renewables | C10: {=IF(INDIRECT("'" & $A10 & "'!B9:J9")="", "", INDIRECT("'" & $A10 & "'!B9:J9"))} | E10: 0 | F10: 0 | H10: 0 | I10: 0
A11: Yuma Airport | B11: Blue Renewables | C11: {=IF(INDIRECT("'" & $A11 & "'!B9:J9")="", "", INDIRECT("'" & $A11 & "'!B9:J9"))} | E11: 0 | F11: 0 | H11: 0 | I11: 0
A12: Kinsman | B12: Blue Renewables | C12: {=IF(INDIRECT("'" & $A12 & "'!B9:J9")="", "", INDIRECT("'" & $A12 & "'!B9:J9"))} | E12: 0 | F12: 0 | H12: 0 | I12: 0
A13: Wooster | B13: Blue Renewables | C13: {=IF(INDIRECT("'" & $A13 & "'!B9:J9")="", "", INDIRECT("'" & $A13 & "'!B9:J9"))} | E13: 0 | F13: 0 | H13: 0 | I13: 0
A14: Globe Gila CC | B14: CC Gen Equity | C14: {=IF(INDIRECT("'" & $A14 & "'!B9:J9")="", "", INDIRECT("'" & $A14 & "'!B9:J9"))} | E14: 0 | F14: 0 | H14: 0 | I14: 0
A15: Payson Gila CC | B15: CC Gen Equity | C15: {=IF(INDIRECT("'" & $A15 & "'!B9:J9")="", "", INDIRECT("'" & $A15 & "'!B9:J9"))} | E15: 0 | F15: 0 | H15: 0 | I15: 0
... A136: Spaulding HS | B136: Sunraise | C136: {=IF(INDIRECT("'" & $A136 & "'!B9:J9")="", "", INDIRECT("'" & $A136 & "'!B9:J9"))} | E136: 0 | F136: 0 | H136: 0 | I136: 0
A137: Total | C137: =SUM(C3:C61) -> 0 | D137: =SUM(D3:D61) -> 0 | E137: =C137-D137 -> 0 | F137: =IFERROR(E137/D137, 0) -> 0 | G137: =SUM(G3:G61) -> 0 | H137: =C137-G137 -> 0 | I137: =IFERROR(H137/G137, 0) -> 0
A139: Values in gold exceed expected or forecasted by 10% or more.
A141: Values in red are below expected or forecasted by 10% or more.

Sheet Jun
A1: {=portfolio} -> Generate Capital | C1: June Actual v. Expected | G1: June Actual v. Forecasted | J1: NOTES | K1: SR
A2: Site | B2: Portfolio | C2: Actual | D2: Expected | E2: Delta | F2: % | G2: Forecasted | H2: Delta | I2: %
A3: {=Sites[Site]} -> Farmer | B3: {=Sites[Portfolio]} -> Blue Renewables | C3: {=IF(INDIRECT("'" & $A3 & "'!B10:J10")="", "", INDIRECT("'" & $A3 & "'!B10:J10"))} | E3: 0 | F3: 0 | H3: 0 | I3: 0
A4: Fulton | B4: Blue Renewables | C4: {=IF(INDIRECT("'" & $A4 & "'!B10:J10")="", "", INDIRECT("'" & $A4 & "'!B10:J10"))} | E4: 0 | F4: 0 | H4: 0 | I4: 0
A5: JFK Elementary | B5: Blue Renewables | C5: {=IF(INDIRECT("'" & $A5 & "'!B10:J10")="", "", INDIRECT("'" & $A5 & "'!B10:J10"))} | E5: 0 | F5: 0 | H5: 0 | I5: 0
A6: Noble | B6: Blue Renewables | C6: {=IF(INDIRECT("'" & $A6 & "'!B10:J10")="", "", INDIRECT("'" & $A6 & "'!B10:J10"))} | E6: 0 | F6: 0 | H6: 0 | I6: 0
A7: Parking 3 | B7: Blue Renewables | C7: {=IF(INDIRECT("'" & $A7 & "'!B10:J10")="", "", INDIRECT("'" & $A7 & "'!B10:J10"))} | E7: 0 | F7: 0 | H7: 0 | I7: 0
A8: PE East | B8: Blue Renewables | C8: {=IF(INDIRECT("'" & $A8 & "'!B10:J10")="", "", INDIRECT("'" & $A8 & "'!B10:J10"))} | E8: 0 | F8: 0 | H8: 0 | I8: 0
A9: Schwada | B9: Blue Renewables | C9: {=IF(INDIRECT("'" & $A9 & "'!B10:J10")="", "", INDIRECT("'" & $A9 & "'!B10:J10"))} | E9: 0 | F9: 0 | H9: 0 | I9: 0
A10: Starshine | B10: Blue Renewables | C10: {=IF(INDIRECT("'" & $A10 & "'!B10:J10")="", "", INDIRECT("'" & $A10 & "'!B10:J10"))} | E10: 0 | F10: 0 | H10: 0 | I10: 0
A11: Yuma Airport | B11: Blue Renewables | C11: {=IF(INDIRECT("'" & $A11 & "'!B10:J10")="", "", INDIRECT("'" & $A11 & "'!B10:J10"))} | E11: 0 | F11: 0 | H11: 0 | I11: 0
A12: Kinsman | B12: Blue Renewables | C12: {=IF(INDIRECT("'" & $A12 & "'!B10:J10")="", "", INDIRECT("'" & $A12 & "'!B10:J10"))} | E12: 0 | F12: 0 | H12: 0 | I12: 0
A13: Wooster | B13: Blue Renewables | C13: {=IF(INDIRECT("'" & $A13 & "'!B10:J10")="", "", INDIRECT("'" & $A13 & "'!B10:J10"))} | E13: 0 | F13: 0 | H13: 0 | I13: 0
A14: Globe Gila CC | B14: CC Gen Equity | C14: {=IF(INDIRECT("'" & $A14 & "'!B10:J10")="", "", INDIRECT("'" & $A14 & "'!B10:J10"))} | E14: 0 | F14: 0 | H14: 0 | I14: 0
A15: Payson Gila CC | B15: CC Gen Equity | C15: {=IF(INDIRECT("'" & $A15 & "'!B10:J10")="", "", INDIRECT("'" & $A15 & "'!B10:J10"))} | E15: 0 | F15: 0 | H15: 0 | I15: 0
... A64: X090 | B64: Hudson | C64: {=IF(INDIRECT("'" & $A64 & "'!B10:J10")="", "", INDIRECT("'" & $A64 & "'!B10:J10"))} | E64: 0 | F64: 0 | H64: 0 | I64: 0
A65: X117 | B65: Hudson | C65: {=IF(INDIRECT("'" & $A65 & "'!B10:J10")="", "", INDIRECT("'" & $A65 & "'!B10:J10"))} | F65: 0 | H65: 0 | I65: 0
A66: X125 | B66: Hudson | C66: {=IF(INDIRECT("'" & $A66 & "'!B10:J10")="", "", INDIRECT("'" & $A66 & "'!B10:J10"))} | E66: 0 | F66: 0 | H66: 0 | I66: 0
A67: X134 | B67: Hudson | C67: {=IF(INDIRECT("'" & $A67 & "'!B10:J10")="", "", INDIRECT("'" & $A67 & "'!B10:J10"))} | E67: 0 | F67: 0 | H67: 0 | I67: 0
A68: X135 | B68: Hudson | C68: {=IF(INDIRECT("'" & $A68 & "'!B10:J10")="", "", INDIRECT("'" & $A68 & "'!B10:J10"))} | E68: 0 | F68: 0 | H68: 0 | I68: 0
A69: X139 JHS 222 | B69: Hudson | C69: {=IF(INDIRECT("'" & $A69 & "'!B10:J10")="", "", INDIRECT("'" & $A69 & "'!B10:J10"))} | E69: 0 | F69: 0 | H69: 0 | I69: 0
A70: X140 | B70: Hudson | C70: {=IF(INDIRECT("'" & $A70 & "'!B10:J10")="", "", INDIRECT("'" & $A70 & "'!B10:J10"))} | E70: 0 | F70: 0 | H70: 0 | I70: 0
A71: X166 | B71: Hudson | C71: {=IF(INDIRECT("'" & $A71 & "'!B10:J10")="", "", INDIRECT("'" & $A71 & "'!B10:J10"))} | E71: 0 | F71: 0 | H71: 0 | I71: 0
A72: Murphy | B72: MN Community Solar | C72: {=IF(INDIRECT("'" & $A72 & "'!B10:J10")="", "", INDIRECT("'" & $A72 & "'!B10:J10"))} | E72: 0 | F72: 0 | H72: 0 | I72: 0
A73: Terning | B73: MN Community Solar | C73: {=IF(INDIRECT("'" & $A73 & "'!B10:J10")="", "", INDIRECT("'" & $A73 & "'!B10:J10"))} | E73: 0 | F73: 0 | H73: 0 | I73: 0
A74: Boas Road 04 | B74: NYCS I | C74: {=IF(INDIRECT("'" & $A74 & "'!B10:J10")="", "", INDIRECT("'" & $A74 & "'!B10:J10"))} | E74: 0 | F74: 0 | H74: 0 | I74: 0
A75: Kelly Bridge Farm | B75: NYCS I | C75: {=IF(INDIRECT("'" & $A75 & "'!B10:J10")="", "", INDIRECT("'" & $A75 & "'!B10:J10"))} | E75: 0 | F75: 0 | H75: 0 | I75: 0
A76: Pool Brook Road | B76: NYCS I | C76: {=IF(INDIRECT("'" & $A76 & "'!B10:J10")="", "", INDIRECT("'" & $A76 & "'!B10:J10"))} | E76: 0 | F76: 0 | H76: 0 | I76: 0
A77: Sackett Lake | B77: NYCS I | C77: {=IF(INDIRECT("'" & $A77 & "'!B10:J10")="", "", INDIRECT("'" & $A77 & "'!B10:J10"))} | E77: 0 | F77: 0 | H77: 0 | I77: 0
... A136: Spaulding HS | B136: Sunraise | C136: {=IF(INDIRECT("'" & $A136 & "'!B10:J10")="", "", INDIRECT("'" & $A136 & "'!B10:J10"))} | E136: 0 | F136: 0 | H136: 0 | I136: 0
A137: Total | C137: =SUM(C3:C61) -> 0 | D137: =SUM(D3:D61) -> 0 | E137: =C137-D137 -> 0 | F137: =IFERROR(E137/D137, 0) -> 0 | G137: =SUM(G3:G61) -> 0 | H137: =C137-G137 -> 0 | I137: =IFERROR(H137/G137, 0) -> 0
A139: Values in gold exceed expected or forecasted by 10% or more.
A141: Values in red are below expected or forecasted by 10% or more.

Sheet Jul
A1: {=portfolio} -> Generate Capital | C1: July Actual v. Expected | G1: July Actual v. Forecasted | J1: NOTES | K1: SR
A2: Site | B2: Portfolio | C2: Actual | D2: Expected | E2: Delta | F2: % | G2: Forecasted | H2: Delta | I2: %
A3: {=Sites[Site]} -> Farmer | B3: {=Sites[Portfolio]} -> Blue Renewables | C3: {=IF(INDIRECT("'" & $A3 & "'!B11:J11")="", "", INDIRECT("'" & $A3 & "'!B11:J11"))} | E3: 0 | F3: 0 | H3: 0 | I3: 0
A4: Fulton | B4: Blue Renewables | C4: {=IF(INDIRECT("'" & $A4 & "'!B11:J11")="", "", INDIRECT("'" & $A4 & "'!B11:J11"))} | E4: 0 | F4: 0 | H4: 0 | I4: 0
A5: JFK Elementary | B5: Blue Renewables | C5: {=IF(INDIRECT("'" & $A5 & "'!B11:J11")="", "", INDIRECT("'" & $A5 & "'!B11:J11"))} | E5: 0 | F5: 0 | H5: 0 | I5: 0
A6: Noble | B6: Blue Renewables | C6: {=IF(INDIRECT("'" & $A6 & "'!B11:J11")="", "", INDIRECT("'" & $A6 & "'!B11:J11"))} | E6: 0 | F6: 0 | H6: 0 | I6: 0
A7: Parking 3 | B7: Blue Renewables | C7: {=IF(INDIRECT("'" & $A7 & "'!B11:J11")="", "", INDIRECT("'" & $A7 & "'!B11:J11"))} | E7: 0 | F7: 0 | H7: 0 | I7: 0
A8: PE East | B8: Blue Renewables | C8: {=IF(INDIRECT("'" & $A8 & "'!B11:J11")="", "", INDIRECT("'" & $A8 & "'!B11:J11"))} | E8: 0 | F8: 0 | H8: 0 | I8: 0
A9: Schwada | B9: Blue Renewables | C9: {=IF(INDIRECT("'" & $A9 & "'!B11:J11")="", "", INDIRECT("'" & $A9 & "'!B11:J11"))} | E9: 0 | F9: 0 | H9: 0 | I9: 0
A10: Starshine | B10: Blue Renewables | C10: {=IF(INDIRECT("'" & $A10 & "'!B11:J11")="", "", INDIRECT("'" & $A10 & "'!B11:J11"))} | E10: 0 | F10: 0 | H10: 0 | I10: 0
A11: Yuma Airport | B11: Blue Renewables | C11: {=IF(INDIRECT("'" & $A11 & "'!B11:J11")="", "", INDIRECT("'" & $A11 & "'!B11:J11"))} | E11: 0 | F11: 0 | H11: 0 | I11: 0
A12: Kinsman | B12: Blue Renewables | C12: {=IF(INDIRECT("'" & $A12 & "'!B11:J11")="", "", INDIRECT("'" & $A12 & "'!B11:J11"))} | E12: 0 | F12: 0 | H12: 0 | I12: 0
A13: Wooster | B13: Blue Renewables | C13: {=IF(INDIRECT("'" & $A13 & "'!B11:J11")="", "", INDIRECT("'" & $A13 & "'!B11:J11"))} | E13: 0 | F13: 0 | H13: 0 | I13: 0
A14: Globe Gila CC | B14: CC Gen Equity | C14: {=IF(INDIRECT("'" & $A14 & "'!B11:J11")="", "", INDIRECT("'" & $A14 & "'!B11:J11"))} | E14: 0 | F14: 0 | H14: 0 | I14: 0
A15: Payson Gila CC | B15: CC Gen Equity | C15: {=IF(INDIRECT("'" & $A15 & "'!B11:J11")="", "", INDIRECT("'" & $A15 & "'!B11:J11"))} | E15: 0 | F15: 0 | H15: 0 | I15: 0
... A64: X090 | B64: Hudson | C64: {=IF(INDIRECT("'" & $A64 & "'!B11:J11")="", "", INDIRECT("'" & $A64 & "'!B11:J11"))} | E64: 0 | F64: 0 | H64: 0 | I64: 0
A65: X117 | B65: Hudson | C65: {=IF(INDIRECT("'" & $A65 & "'!B11:J11")="", "", INDIRECT("'" & $A65 & "'!B11:J11"))} | F65: 0 | H65: 0 | I65: 0
A66: X125 | B66: Hudson | C66: {=IF(INDIRECT("'" & $A66 & "'!B11:J11")="", "", INDIRECT("'" & $A66 & "'!B11:J11"))} | E66: 0 | F66: 0 | H66: 0 | I66: 0
A67: X134 | B67: Hudson | C67: {=IF(INDIRECT("'" & $A67 & "'!B11:J11")="", "", INDIRECT("'" & $A67 & "'!B11:J11"))} | E67: 0 | F67: 0 | H67: 0 | I67: 0
A68: X135 | B68: Hudson | C68: {=IF(INDIRECT("'" & $A68 & "'!B11:J11")="", "", INDIRECT("'" & $A68 & "'!B11:J11"))} | E68: 0 | F68: 0 | H68: 0 | I68: 0
A69: X139 JHS 222 | B69: Hudson | C69: {=IF(INDIRECT("'" & $A69 & "'!B11:J11")="", "", INDIRECT("'" & $A69 & "'!B11:J11"))} | E69: 0 | F69: 0 | H69: 0 | I69: 0
A70: X140 | B70: Hudson | C70: {=IF(INDIRECT("'" & $A70 & "'!B11:J11")="", "", INDIRECT("'" & $A70 & "'!B11:J11"))} | E70: 0 | F70: 0 | H70: 0 | I70: 0
A71: X166 | B71: Hudson | C71: {=IF(INDIRECT("'" & $A71 & "'!B11:J11")="", "", INDIRECT("'" & $A71 & "'!B11:J11"))} | E71: 0 | F71: 0 | H71: 0 | I71: 0
A72: Murphy | B72: MN Community Solar | C72: {=IF(INDIRECT("'" & $A72 & "'!B11:J11")="", "", INDIRECT("'" & $A72 & "'!B11:J11"))} | E72: 0 | F72: 0 | H72: 0 | I72: 0
A73: Terning | B73: MN Community Solar | C73: {=IF(INDIRECT("'" & $A73 & "'!B11:J11")="", "", INDIRECT("'" & $A73 & "'!B11:J11"))} | E73: 0 | F73: 0 | H73: 0 | I73: 0
A74: Boas Road 04 | B74: NYCS I | C74: {=IF(INDIRECT("'" & $A74 & "'!B11:J11")="", "", INDIRECT("'" & $A74 & "'!B11:J11"))} | E74: 0 | F74: 0 | H74: 0 | I74: 0
A75: Kelly Bridge Farm | B75: NYCS I | C75: {=IF(INDIRECT("'" & $A75 & "'!B11:J11")="", "", INDIRECT("'" & $A75 & "'!B11:J11"))} | E75: 0 | F75: 0 | H75: 0 | I75: 0
A76: Pool Brook Road | B76: NYCS I | C76: {=IF(INDIRECT("'" & $A76 & "'!B11:J11")="", "", INDIRECT("'" & $A76 & "'!B11:J11"))} | E76: 0 | F76: 0 | H76: 0 | I76: 0
A77: Sackett Lake | B77: NYCS I | C77: {=IF(INDIRECT("'" & $A77 & "'!B11:J11")="", "", INDIRECT("'" & $A77 & "'!B11:J11"))} | E77: 0 | F77: 0 | H77: 0 | I77: 0
... A136: Spaulding HS | B136: Sunraise | C136: {=IF(INDIRECT("'" & $A136 & "'!B11:J11")="", "", INDIRECT("'" & $A136 & "'!B11:J11"))} | E136: 0 | F136: 0 | H136: 0 | I136: 0
A137: Total | C137: =SUM(C3:C61) -> 0 | D137: =SUM(D3:D61) -> 0 | E137: =C137-D137 -> 0 | F137: =IFERROR(E137/D137, 0) -> 0 | G137: =SUM(G3:G61) -> 0 | H137: =C137-G137 -> 0 | I137: =IFERROR(H137/G137, 0) -> 0
A139: Values in gold exceed expected or forecasted by 10% or more.
A141: Values in red are below expected or forecasted by 10% or more.

Sheet Aug
A1: {=portfolio} -> Generate Capital | C1: August Actual v. Expected | G1: August Actual v. Forecasted | J1: NOTES | K1: SR
A2: Site | B2: Portfolio | C2: Actual | D2: Expected | E2: Delta | F2: % | G2: Forecasted | H2: Delta | I2: %
A3: {=Sites[Site]} -> Farmer | B3: {=Sites[Portfolio]} -> Blue Renewables | C3: {=IF(INDIRECT("'" & $A3 & "'!B12:J12")="", "", INDIRECT("'" & $A3 & "'!B12:J12"))} | E3: 0 | F3: 0 | H3: 0 | I3: 0
A4: Fulton | B4: Blue Renewables | C4: {=IF(INDIRECT("'" & $A4 & "'!B12:J12")="", "", INDIRECT("'" & $A4 & "'!B12:J12"))} | E4: 0 | F4: 0 | H4: 0 | I4: 0
A5: JFK Elementary | B5: Blue Renewables | C5: {=IF(INDIRECT("'" & $A5 & "'!B12:J12")="", "", INDIRECT("'" & $A5 & "'!B12:J12"))} | E5: 0 | F5: 0 | H5: 0 | I5: 0
A6: Noble | B6: Blue Renewables | C6: {=IF(INDIRECT("'" & $A6 & "'!B12:J12")="", "", INDIRECT("'" & $A6 & "'!B12:J12"))} | E6: 0 | F6: 0 | H6: 0 | I6: 0
A7: Parking 3 | B7: Blue Renewables | C7: {=IF(INDIRECT("'" & $A7 & "'!B12:J12")="", "", INDIRECT("'" & $A7 & "'!B12:J12"))} | E7: 0 | F7: 0 | H7: 0 | I7: 0
A8: PE East | B8: Blue Renewables | C8: {=IF(INDIRECT("'" & $A8 & "'!B12:J12")="", "", INDIRECT("'" & $A8 & "'!B12:J12"))} | E8: 0 | F8: 0 | H8: 0 | I8: 0
A9: Schwada | B9: Blue Renewables | C9: {=IF(INDIRECT("'" & $A9 & "'!B12:J12")="", "", INDIRECT("'" & $A9 & "'!B12:J12"))} | E9: 0 | F9: 0 | H9: 0 | I9: 0
A10: Starshine | B10: Blue Renewables | C10: {=IF(INDIRECT("'" & $A10 & "'!B12:J12")="", "", INDIRECT("'" & $A10 & "'!B12:J12"))} | E10: 0 | F10: 0 | H10: 0 | I10: 0
A11: Yuma Airport | B11: Blue Renewables | C11: {=IF(INDIRECT("'" & $A11 & "'!B12:J12")="", "", INDIRECT("'" & $A11 & "'!B12:J12"))} | E11: 0 | F11: 0 | H11: 0 | I11: 0
A12: Kinsman | B12: Blue Renewables | C12: {=IF(INDIRECT("'" & $A12 & "'!B12:J12")="", "", INDIRECT("'" & $A12 & "'!B12:J12"))} | E12: 0 | F12: 0 | H12: 0 | I12: 0
A13: Wooster | B13: Blue Renewables | C13: {=IF(INDIRECT("'" & $A13 & "'!B12:J12")="", "", INDIRECT("'" & $A13 & "'!B12:J12"))} | E13: 0 | F13: 0 | H13: 0 | I13: 0
A14: Globe Gila CC | B14: CC Gen Equity | C14: {=IF(INDIRECT("'" & $A14 & "'!B12:J12")="", "", INDIRECT("'" & $A14 & "'!B12:J12"))} | E14: 0 | F14: 0 | H14: 0 | I14: 0
A15: Payson Gila CC | B15: CC Gen Equity | C15: {=IF(INDIRECT("'" & $A15 & "'!B12:J12")="", "", INDIRECT("'" & $A15 & "'!B12:J12"))} | E15: 0 | F15: 0 | H15: 0 | I15: 0
... A64: X090 | B64: Hudson | C64: {=IF(INDIRECT("'" & $A64 & "'!B12:J12")="", "", INDIRECT("'" & $A64 & "'!B12:J12"))} | E64: 0 | F64: 0 | H64: 0 | I64: 0
A65: X117 | B65: Hudson | C65: {=IF(INDIRECT("'" & $A65 & "'!B12:J12")="", "", INDIRECT("'" & $A65 & "'!B12:J12"))} | F65: 0 | H65: 0 | I65: 0
A66: X125 | B66: Hudson | C66: {=IF(INDIRECT("'" & $A66 & "'!B12:J12")="", "", INDIRECT("'" & $A66 & "'!B12:J12"))} | E66: 0 | F66: 0 | H66: 0 | I66: 0
A67: X134 | B67: Hudson | C67: {=IF(INDIRECT("'" & $A67 & "'!B12:J12")="", "", INDIRECT("'" & $A67 & "'!B12:J12"))} | E67: 0 | F67: 0 | H67: 0 | I67: 0
A68: X135 | B68: Hudson | C68: {=IF(INDIRECT("'" & $A68 & "'!B12:J12")="", "", INDIRECT("'" & $A68 & "'!B12:J12"))} | E68: 0 | F68: 0 | H68: 0 | I68: 0
A69: X139 JHS 222 | B69: Hudson | C69: {=IF(INDIRECT("'" & $A69 & "'!B12:J12")="", "", INDIRECT("'" & $A69 & "'!B12:J12"))} | E69: 0 | F69: 0 | H69: 0 | I69: 0
A70: X140 | B70: Hudson | C70: {=IF(INDIRECT("'" & $A70 & "'!B12:J12")="", "", INDIRECT("'" & $A70 & "'!B12:J12"))} | E70: 0 | F70: 0 | H70: 0 | I70: 0
A71: X166 | B71: Hudson | C71: {=IF(INDIRECT("'" & $A71 & "'!B12:J12")="", "", INDIRECT("'" & $A71 & "'!B12:J12"))} | E71: 0 | F71: 0 | H71: 0 | I71: 0
