Workbook
Name JanActual: Jan!$C$3:$C$31
Name JanActual2: Jan!#REF!
Name JanExpected: Jan!$D$3:$D$31
Name JanExpectedDelta: Jan!$E$3:$E$31
Name JanExpectedPercent: Jan!$F$3:$F$31
Name JanExpPercent: Jan!$F$3:$F$31
Name JanForecasted: Jan!$G$3:$G$31
Name JanForecastedDelta: Jan!$H$3:$H$31
Name JanForecastedPercent: Jan!$I$3:$I$31
Name portfolio: Sites!$B$1:$B$1

Sheet YTD Total
A1: {=portfolio} -> Greenbacker | C1: Year to Date 2024 Actual v. Expected | G1: Year to Date 2024 Forecasted | J1: NOTES | K1: SR
A2: Site | B2: State | C2: Actual | D2: Expected | E2: Delta | F2: % | G2: Forecasted | H2: Delta | I2: %
A3: {=Sites[Site]} -> 10 Walpole Park South | B3: {=Sites[State]} -> MA | C3: =SUM('1st Qtr'!C3, '2nd Qtr'!C3, '3rd Qtr'!C3, '4th Qtr'!C3) -> 3478.8125 | D3: =SUM('1st Qtr'!D3, '2nd Qtr'!D3, '3rd Qtr'!D3, '4th Qtr'!D3) -> 6181.574 | E3: =C3-D3 -> -2702.7615 | F3: =IFERROR(E3/D3, 0) -> -0.43722869 | G3: =SUM('1st Qtr'!G3, '2nd Qtr'!G3, '3rd Qtr'!G3, '4th Qtr'!G3) -> 6823.253 | H3: =C3-G3 -> -3344.4405 | I3: =IFERROR(H3/G3, 0) -> -0.49015338
A4: 15 Walpole Park South | B4: MA | C4: =SUM('1st Qtr'!C4, '2nd Qtr'!C4, '3rd Qtr'!C4, '4th Qtr'!C4) -> 12517 | D4: =SUM('1st Qtr'!D4, '2nd Qtr'!D4, '3rd Qtr'!D4, '4th Qtr'!D4) -> 22722.47 | E4: =C4-D4 -> -10205.47 | F4: =IFERROR(E4/D4, 0) -> -0.44913559 | G4: =SUM('1st Qtr'!G4, '2nd Qtr'!G4, '3rd Qtr'!G4, '4th Qtr'!G4) -> 21603.71 | H4: =C4-G4 -> -9086.71 | I4: =IFERROR(H4/G4, 0) -> -0.42060878
A5: 19 Walpole Park South | B5: MA | C5: =SUM('1st Qtr'!C5, '2nd Qtr'!C5, '3rd Qtr'!C5, '4th Qtr'!C5) -> 7105.375 | D5: =SUM('1st Qtr'!D5, '2nd Qtr'!D5, '3rd Qtr'!D5, '4th Qtr'!D5) -> 13704.15 | E5: =C5-D5 -> -6598.775 | F5: =IFERROR(E5/D5, 0) -> -0.48151655 | G5: =SUM('1st Qtr'!G5, '2nd Qtr'!G5, '3rd Qtr'!G5, '4th Qtr'!G5) -> 14450.27 | H5: =C5-G5 -> -7344.895 | I5: =IFERROR(H5/G5, 0) -> -0.50828773
A6: 23 Walpole Park South | B6: MA | C6: =SUM('1st Qtr'!C6, '2nd Qtr'!C6, '3rd Qtr'!C6, '4th Qtr'!C6) -> 10190.25 | D6: =SUM('1st Qtr'!D6, '2nd Qtr'!D6, '3rd Qtr'!D6, '4th Qtr'!D6) -> 16832.77 | E6: =C6-D6 -> -6642.52 | F6: =IFERROR(E6/D6, 0) -> -0.39461835 | G6: =SUM('1st Qtr'!G6, '2nd Qtr'!G6, '3rd Qtr'!G6, '4th Qtr'!G6) -> 18563.55 | H6: =C6-G6 -> -8373.3 | I6: =IFERROR(H6/G6, 0) -> -0.45106135
A7: 24 Walpole Park South | B7: MA | C7: =SUM('1st Qtr'!C7, '2nd Qtr'!C7, '3rd Qtr'!C7, '4th Qtr'!C7) -> 15037 | D7: =SUM('1st Qtr'!D7, '2nd Qtr'!D7, '3rd Qtr'!D7, '4th Qtr'!D7) -> 14267.73 | E7: =C7-D7 -> 769.27 | F7: =IFERROR(E7/D7, 0) -> 0.053916776 | G7: =SUM('1st Qtr'!G7, '2nd Qtr'!G7, '3rd Qtr'!G7, '4th Qtr'!G7) -> 28642.02 | H7: =C7-G7 -> -13605.02 | I7: =IFERROR(H7/G7, 0) -> -0.47500211
A8: 25 Walpole Park South | B8: MA | C8: =SUM('1st Qtr'!C8, '2nd Qtr'!C8, '3rd Qtr'!C8, '4th Qtr'!C8) -> 15224.5 | D8: =SUM('1st Qtr'!D8, '2nd Qtr'!D8, '3rd Qtr'!D8, '4th Qtr'!D8) -> 26799 | E8: =C8-D8 -> -11574.5 | F8: =IFERROR(E8/D8, 0) -> -0.43190044 | G8: =SUM('1st Qtr'!G8, '2nd Qtr'!G8, '3rd Qtr'!G8, '4th Qtr'!G8) -> 29130.79 | H8: =C8-G8 -> -13906.29 | I8: =IFERROR(H8/G8, 0) -> -0.47737428
A9: 3 Walpole Park South | B9: MA | C9: =SUM('1st Qtr'!C9, '2nd Qtr'!C9, '3rd Qtr'!C9, '4th Qtr'!C9) -> 19881.5 | D9: =SUM('1st Qtr'!D9, '2nd Qtr'!D9, '3rd Qtr'!D9, '4th Qtr'!D9) -> 35122.52 | E9: =C9-D9 -> -15241.02 | F9: =IFERROR(E9/D9, 0) -> -0.43393868 | G9: =SUM('1st Qtr'!G9, '2nd Qtr'!G9, '3rd Qtr'!G9, '4th Qtr'!G9) -> 34800.55 | H9: =C9-G9 -> -14919.05 | I9: =IFERROR(H9/G9, 0) -> -0.42870156
A10: 4 Walpole Park South | B10: MA | C10: =SUM('1st Qtr'!C10, '2nd Qtr'!C10, '3rd Qtr'!C10, '4th Qtr'!C10) -> 10678.25 | D10: =SUM('1st Qtr'!D10, '2nd Qtr'!D10, '3rd Qtr'!D10, '4th Qtr'!D10) -> 19843.16 | E10: =C10-D10 -> -9164.91 | F10: =IFERROR(E10/D10, 0) -> -0.46186746 | G10: =SUM('1st Qtr'!G10, '2nd Qtr'!G10, '3rd Qtr'!G10, '4th Qtr'!G10) -> 19687.72 | H10: =C10-G10 -> -9009.47 | I10: =IFERROR(H10/G10, 0) -> -0.45761876
A11: Brockton | B11: MA | C11: =SUM('1st Qtr'!C11, '2nd Qtr'!C11, '3rd Qtr'!C11, '4th Qtr'!C11) -> 21358 | D11: =SUM('1st Qtr'!D11, '2nd Qtr'!D11, '3rd Qtr'!D11, '4th Qtr'!D11) -> 29225.2 | E11: =C11-D11 -> -7867.2 | F11: =IFERROR(E11/D11, 0) -> -0.26919234 | G11: =SUM('1st Qtr'!G11, '2nd Qtr'!G11, '3rd Qtr'!G11, '4th Qtr'!G11) -> 35891.12 | H11: =C11-G11 -> -14533.12 | I11: =IFERROR(H11/G11, 0) -> -0.40492244
A12: Canton | B12: MA | C12: =SUM('1st Qtr'!C12, '2nd Qtr'!C12, '3rd Qtr'!C12, '4th Qtr'!C12) -> 17412.25 | D12: =SUM('1st Qtr'!D12, '2nd Qtr'!D12, '3rd Qtr'!D12, '4th Qtr'!D12) -> 31213.29 | E12: =C12-D12 -> -13801.04 | F12: =IFERROR(E12/D12, 0) -> -0.44215269 | G12: =SUM('1st Qtr'!G12, '2nd Qtr'!G12, '3rd Qtr'!G12, '4th Qtr'!G12) -> 30904.81 | H12: =C12-G12 -> -13492.56 | I12: =IFERROR(H12/G12, 0) -> -0.43658447
A13: Chelsea | B13: MA | C13: =SUM('1st Qtr'!C13, '2nd Qtr'!C13, '3rd Qtr'!C13, '4th Qtr'!C13) -> 38716 | D13: =SUM('1st Qtr'!D13, '2nd Qtr'!D13, '3rd Qtr'!D13, '4th Qtr'!D13) -> 54336.05 | E13: =C13-D13 -> -15620.05 | F13: =IFERROR(E13/D13, 0) -> -0.28747121 | G13: =SUM('1st Qtr'!G13, '2nd Qtr'!G13, '3rd Qtr'!G13, '4th Qtr'!G13) -> 55003.46 | H13: =C13-G13 -> -16287.46 | I13: =IFERROR(H13/G13, 0) -> -0.29611701
A14: Hamilton Landfill | B14: MA | C14: =SUM('1st Qtr'!C14, '2nd Qtr'!C14, '3rd Qtr'!C14, '4th Qtr'!C14) -> 30221 | D14: =SUM('1st Qtr'!D14, '2nd Qtr'!D14, '3rd Qtr'!D14, '4th Qtr'!D14) -> 58716 | E14: =C14-D14 -> -28495 | F14: =IFERROR(E14/D14, 0) -> -0.48530213 | G14: =SUM('1st Qtr'!G14, '2nd Qtr'!G14, '3rd Qtr'!G14, '4th Qtr'!G14) -> 0 | H14: =C14-G14 -> 30221 | I14: =IFERROR(H14/G14, 0) -> 0
A15: Holliston | B15: MA | C15: =SUM('1st Qtr'!C15, '2nd Qtr'!C15, '3rd Qtr'!C15, '4th Qtr'!C15) -> 37423.5 | D15: =SUM('1st Qtr'!D15, '2nd Qtr'!D15, '3rd Qtr'!D15, '4th Qtr'!D15) -> 60597.82 | E15: =C15-D15 -> -23174.32 | F15: =IFERROR(E15/D15, 0) -> -0.38242828 | G15: =SUM('1st Qtr'!G15, '2nd Qtr'!G15, '3rd Qtr'!G15, '4th Qtr'!G15) -> 84734.92 | H15: =C15-G15 -> -47311.42 | I15: =IFERROR(H15/G15, 0) -> -0.55834619
... A32: Danville | B32: IL | C32: =SUM('1st Qtr'!C32, '2nd Qtr'!C32, '3rd Qtr'!C32, '4th Qtr'!C32) -> 119051 | D32: =SUM('1st Qtr'!D32, '2nd Qtr'!D32, '3rd Qtr'!D32, '4th Qtr'!D32) -> 0 | E32: =C32-D32 -> 119051 | F32: =IFERROR(E32/D32, 0) -> 0 | G32: =SUM('1st Qtr'!G32, '2nd Qtr'!G32, '3rd Qtr'!G32, '4th Qtr'!G32) -> 0 | H32: =C32-G32 -> 119051 | I32: =IFERROR(H32/G32, 0) -> 0
A33: Total | C33: =SUM(C3:C32) -> 1255667.5 | D33: =SUM(D3:D32) -> 1584905.3 | E33: =C33-D33 -> -329237.8 | F33: =IFERROR(E33/D33, 0) -> -0.20773342 | G33: =SUM(G3:G32) -> 1501477.3 | H33: =C33-G33 -> -245809.86 | I33: =IFERROR(H33/G33, 0) -> -0.163712
A35: Values in gold exceed expected or forecasted by 10% or more.
A37: Values in red are below expected or forecasted by 10% or more.

Sheet 1st Qtr
A1: {=portfolio} -> Greenbacker | C1: 1st Quarter 2024 Actual v. Expected | G1: 1st Quarter 2024 Forecasted | J1: NOTES | K1: SR
A2: Site | B2: State | C2: Actual | D2: Expected | E2: Delta | F2: % | G2: Forecasted | H2: Delta | I2: %
A3: {=Sites[Site]} -> 10 Walpole Park South | B3: {=Sites[State]} -> MA | C3: =SUM(Jan!C3, Feb!C3, Mar!C3) -> 3478.8125 | D3: =SUM(Jan!D3, Feb!D3, Mar!D3) -> 6181.574 | E3: =C3-D3 -> -2702.7615 | F3: =IFERROR(E3/D3, 0) -> -0.43722869 | G3: =SUM(Jan!G3, Feb!G3, Mar!G3) -> 6823.253 | H3: =C3-G3 -> -3344.4405 | I3: =IFERROR(H3/G3, 0) -> -0.49015338
A4: 15 Walpole Park South | B4: MA | C4: =SUM(Jan!C4, Feb!C4, Mar!C4) -> 12517 | D4: =SUM(Jan!D4, Feb!D4, Mar!D4) -> 22722.47 | E4: =C4-D4 -> -10205.47 | F4: =IFERROR(E4/D4, 0) -> -0.44913559 | G4: =SUM(Jan!G4, Feb!G4, Mar!G4) -> 21603.71 | H4: =C4-G4 -> -9086.71 | I4: =IFERROR(H4/G4, 0) -> -0.42060878
A5: 19 Walpole Park South | B5: MA | C5: =SUM(Jan!C5, Feb!C5, Mar!C5) -> 7105.375 | D5: =SUM(Jan!D5, Feb!D5, Mar!D5) -> 13704.15 | E5: =C5-D5 -> -6598.775 | F5: =IFERROR(E5/D5, 0) -> -0.48151655 | G5: =SUM(Jan!G5, Feb!G5, Mar!G5) -> 14450.27 | H5: =C5-G5 -> -7344.895 | I5: =IFERROR(H5/G5, 0) -> -0.50828773
A6: 23 Walpole Park South | B6: MA | C6: =SUM(Jan!C6, Feb!C6, Mar!C6) -> 10190.25 | D6: =SUM(Jan!D6, Feb!D6, Mar!D6) -> 16832.77 | E6: =C6-D6 -> -6642.52 | F6: =IFERROR(E6/D6, 0) -> -0.39461835 | G6: =SUM(Jan!G6, Feb!G6, Mar!G6) -> 18563.55 | H6: =C6-G6 -> -8373.3 | I6: =IFERROR(H6/G6, 0) -> -0.45106135
A7: 24 Walpole Park South | B7: MA | C7: =SUM(Jan!C7, Feb!C7, Mar!C7) -> 15037 | D7: =SUM(Jan!D7, Feb!D7, Mar!D7) -> 14267.73 | E7: =C7-D7 -> 769.27 | F7: =IFERROR(E7/D7, 0) -> 0.053916776 | G7: =SUM(Jan!G7, Feb!G7, Mar!G7) -> 28642.02 | H7: =C7-G7 -> -13605.02 | I7: =IFERROR(H7/G7, 0) -> -0.47500211
A8: 25 Walpole Park South | B8: MA | C8: =SUM(Jan!C8, Feb!C8, Mar!C8) -> 15224.5 | D8: =SUM(Jan!D8, Feb!D8, Mar!D8) -> 26799 | E8: =C8-D8 -> -11574.5 | F8: =IFERROR(E8/D8, 0) -> -0.43190044 | G8: =SUM(Jan!G8, Feb!G8, Mar!G8) -> 29130.79 | H8: =C8-G8 -> -13906.29 | I8: =IFERROR(H8/G8, 0) -> -0.47737428
A9: 3 Walpole Park South | B9: MA | C9: =SUM(Jan!C9, Feb!C9, Mar!C9) -> 19881.5 | D9: =SUM(Jan!D9, Feb!D9, Mar!D9) -> 35122.52 | E9: =C9-D9 -> -15241.02 | F9: =IFERROR(E9/D9, 0) -> -0.43393868 | G9: =SUM(Jan!G9, Feb!G9, Mar!G9) -> 34800.55 | H9: =C9-G9 -> -14919.05 | I9: =IFERROR(H9/G9, 0) -> -0.42870156
A10: 4 Walpole Park South | B10: MA | C10: =SUM(Jan!C10, Feb!C10, Mar!C10) -> 10678.25 | D10: =SUM(Jan!D10, Feb!D10, Mar!D10) -> 19843.16 | E10: =C10-D10 -> -9164.91 | F10: =IFERROR(E10/D10, 0) -> -0.46186746 | G10: =SUM(Jan!G10, Feb!G10, Mar!G10) -> 19687.72 | H10: =C10-G10 -> -9009.47 | I10: =IFERROR(H10/G10, 0) -> -0.45761876
A11: Brockton | B11: MA | C11: =SUM(Jan!C11, Feb!C11, Mar!C11) -> 21358 | D11: =SUM(Jan!D11, Feb!D11, Mar!D11) -> 29225.2 | E11: =C11-D11 -> -7867.2 | F11: =IFERROR(E11/D11, 0) -> -0.26919234 | G11: =SUM(Jan!G11, Feb!G11, Mar!G11) -> 35891.12 | H11: =C11-G11 -> -14533.12 | I11: =IFERROR(H11/G11, 0) -> -0.40492244
A12: Canton | B12: MA | C12: =SUM(Jan!C12, Feb!C12, Mar!C12) -> 17412.25 | D12: =SUM(Jan!D12, Feb!D12, Mar!D12) -> 31213.29 | E12: =C12-D12 -> -13801.04 | F12: =IFERROR(E12/D12, 0) -> -0.44215269 | G12: =SUM(Jan!G12, Feb!G12, Mar!G12) -> 30904.81 | H12: =C12-G12 -> -13492.56 | I12: =IFERROR(H12/G12, 0) -> -0.43658447
A13: Chelsea | B13: MA | C13: =SUM(Jan!C13, Feb!C13, Mar!C13) -> 38716 | D13: =SUM(Jan!D13, Feb!D13, Mar!D13) -> 54336.05 | E13: =C13-D13 -> -15620.05 | F13: =IFERROR(E13/D13, 0) -> -0.28747121 | G13: =SUM(Jan!G13, Feb!G13, Mar!G13) -> 55003.46 | H13: =C13-G13 -> -16287.46 | I13: =IFERROR(H13/G13, 0) -> -0.29611701
A14: Hamilton Landfill | B14: MA | C14: =SUM(Jan!C14, Feb!C14, Mar!C14) -> 30221 | D14: =SUM(Jan!D14, Feb!D14, Mar!D14) -> 58716 | E14: =C14-D14 -> -28495 | F14: =IFERROR(E14/D14, 0) -> -0.48530213 | G14: =SUM(Jan!G14, Feb!G14, Mar!G14) -> 0 | H14: =C14-G14 -> 30221 | I14: =IFERROR(H14/G14, 0) -> 0
A15: Holliston | B15: MA | C15: =SUM(Jan!C15, Feb!C15, Mar!C15) -> 37423.5 | D15: =SUM(Jan!D15, Feb!D15, Mar!D15) -> 60597.82 | E15: =C15-D15 -> -23174.32 | F15: =IFERROR(E15/D15, 0) -> -0.38242828 | G15: =SUM(Jan!G15, Feb!G15, Mar!G15) -> 84734.92 | H15: =C15-G15 -> -47311.42 | I15: =IFERROR(H15/G15, 0) -> -0.55834619
... A32: Danville | B32: IL | C32: =SUM(Jan!C32, Feb!C32, Mar!C32) -> 119051 | D32: =SUM(Jan!D32, Feb!D32, Mar!D32) -> 0 | E32: =C32-D32 -> 119051 | F32: =IFERROR(E32/D32, 0) -> 0 | G32: =SUM(Jan!G32, Feb!G32, Mar!G32) -> 0 | H32: =C32-G32 -> 119051 | I32: =IFERROR(H32/G32, 0) -> 0
A33: Total | C33: =SUM(C3:C31) -> 1136616.5 | D33: =SUM(D3:D31) -> 1584905.3 | E33: =C33-D33 -> -448288.8 | F33: =IFERROR(E33/D33, 0) -> -0.28284896 | G33: =SUM(G3:G31) -> 1501477.3 | H33: =C33-G33 -> -364860.86 | I33: =IFERROR(H33/G33, 0) -> -0.24300124
A35: Values in gold exceed expected or forecasted by 10% or more.
A37: Values in red are below expected or forecasted by 10% or more.

Sheet 2nd Qtr
A1: {=portfolio} -> Greenbacker | C1: 2nd Quarter 2024 Actual v. Expected | G1: 2nd Quarter 2024 Forecasted | J1: NOTES | K1: SR
A2: Site | B2: State | C2: Actual | D2: Expected | E2: Delta | F2: % | G2: Forecasted | H2: Delta | I2: %
A3: {=Sites[Site]} -> 10 Walpole Park South | B3: {=Sites[State]} -> MA | C3: =SUM(Apr!C3, May!C3, Jun!C3) -> 0 | D3: =SUM(Apr!D3, May!D3, Jun!D3) -> 0 | E3: =C3-D3 -> 0 | F3: =IFERROR(E3/D3, 0) -> 0 | G3: =SUM(Apr!G3, May!G3, Jun!G3) -> 0 | H3: =C3-G3 -> 0 | I3: =IFERROR(H3/G3, 0) -> 0
A4: 15 Walpole Park South | B4: MA | C4: =SUM(Apr!C4, May!C4, Jun!C4) -> 0 | D4: =SUM(Apr!D4, May!D4, Jun!D4) -> 0 | E4: =C4-D4 -> 0 | F4: =IFERROR(E4/D4, 0) -> 0 | G4: =SUM(Apr!G4, May!G4, Jun!G4) -> 0 | H4: =C4-G4 -> 0 | I4: =IFERROR(H4/G4, 0) -> 0
A5: 19 Walpole Park South | B5: MA | C5: =SUM(Apr!C5, May!C5, Jun!C5) -> 0 | D5: =SUM(Apr!D5, May!D5, Jun!D5) -> 0 | E5: =C5-D5 -> 0 | F5: =IFERROR(E5/D5, 0) -> 0 | G5: =SUM(Apr!G5, May!G5, Jun!G5) -> 0 | H5: =C5-G5 -> 0 | I5: =IFERROR(H5/G5, 0) -> 0
A6: 23 Walpole Park South | B6: MA | C6: =SUM(Apr!C6, May!C6, Jun!C6) -> 0 | D6: =SUM(Apr!D6, May!D6, Jun!D6) -> 0 | E6: =C6-D6 -> 0 | F6: =IFERROR(E6/D6, 0) -> 0 | G6: =SUM(Apr!G6, May!G6, Jun!G6) -> 0 | H6: =C6-G6 -> 0 | I6: =IFERROR(H6/G6, 0) -> 0
A7: 24 Walpole Park South | B7: MA | C7: =SUM(Apr!C7, May!C7, Jun!C7) -> 0 | D7: =SUM(Apr!D7, May!D7, Jun!D7) -> 0 | E7: =C7-D7 -> 0 | F7: =IFERROR(E7/D7, 0) -> 0 | G7: =SUM(Apr!G7, May!G7, Jun!G7) -> 0 | H7: =C7-G7 -> 0 | I7: =IFERROR(H7/G7, 0) -> 0
A8: 25 Walpole Park South | B8: MA | C8: =SUM(Apr!C8, May!C8, Jun!C8) -> 0 | D8: =SUM(Apr!D8, May!D8, Jun!D8) -> 0 | E8: =C8-D8 -> 0 | F8: =IFERROR(E8/D8, 0) -> 0 | G8: =SUM(Apr!G8, May!G8, Jun!G8) -> 0 | H8: =C8-G8 -> 0 | I8: =IFERROR(H8/G8, 0) -> 0
A9: 3 Walpole Park South | B9: MA | C9: =SUM(Apr!C9, May!C9, Jun!C9) -> 0 | D9: =SUM(Apr!D9, May!D9, Jun!D9) -> 0 | E9: =C9-D9 -> 0 | F9: =IFERROR(E9/D9, 0) -> 0 | G9: =SUM(Apr!G9, May!G9, Jun!G9) -> 0 | H9: =C9-G9 -> 0 | I9: =IFERROR(H9/G9, 0) -> 0
A10: 4 Walpole Park South | B10: MA | C10: =SUM(Apr!C10, May!C10, Jun!C10) -> 0 | D10: =SUM(Apr!D10, May!D10, Jun!D10) -> 0 | E10: =C10-D10 -> 0 | F10: =IFERROR(E10/D10, 0) -> 0 | G10: =SUM(Apr!G10, May!G10, Jun!G10) -> 0 | H10: =C10-G10 -> 0 | I10: =IFERROR(H10/G10, 0) -> 0
A11: Brockton | B11: MA | C11: =SUM(Apr!C11, May!C11, Jun!C11) -> 0 | D11: =SUM(Apr!D11, May!D11, Jun!D11) -> 0 | E11: =C11-D11 -> 0 | F11: =IFERROR(E11/D11, 0) -> 0 | G11: =SUM(Apr!G11, May!G11, Jun!G11) -> 0 | H11: =C11-G11 -> 0 | I11: =IFERROR(H11/G11, 0) -> 0
A12: Canton | B12: MA | C12: =SUM(Apr!C12, May!C12, Jun!C12) -> 0 | D12: =SUM(Apr!D12, May!D12, Jun!D12) -> 0 | E12: =C12-D12 -> 0 | F12: =IFERROR(E12/D12, 0) -> 0 | G12: =SUM(Apr!G12, May!G12, Jun!G12) -> 0 | H12: =C12-G12 -> 0 | I12: =IFERROR(H12/G12, 0) -> 0
A13: Chelsea | B13: MA | C13: =SUM(Apr!C13, May!C13, Jun!C13) -> 0 | D13: =SUM(Apr!D13, May!D13, Jun!D13) -> 0 | E13: =C13-D13 -> 0 | F13: =IFERROR(E13/D13, 0) -> 0 | G13: =SUM(Apr!G13, May!G13, Jun!G13) -> 0 | H13: =C13-G13 -> 0 | I13: =IFERROR(H13/G13, 0) -> 0
A14: Hamilton Landfill | B14: MA | C14: =SUM(Apr!C14, May!C14, Jun!C14) -> 0 | D14: =SUM(Apr!D14, May!D14, Jun!D14) -> 0 | E14: =C14-D14 -> 0 | F14: =IFERROR(E14/D14, 0) -> 0 | G14: =SUM(Apr!G14, May!G14, Jun!G14) -> 0 | H14: =C14-G14 -> 0 | I14: =IFERROR(H14/G14, 0) -> 0
A15: Holliston | B15: MA | C15: =SUM(Apr!C15, May!C15, Jun!C15) -> 0 | D15: =SUM(Apr!D15, May!D15, Jun!D15) -> 0 | E15: =C15-D15 -> 0 | F15: =IFERROR(E15/D15, 0) -> 0 | G15: =SUM(Apr!G15, May!G15, Jun!G15) -> 0 | H15: =C15-G15 -> 0 | I15: =IFERROR(H15/G15, 0) -> 0
... A32: Danville | B32: IL | C32: =SUM(Apr!C32, May!C32, Jun!C32) -> 0 | D32: =SUM(Apr!D32, May!D32, Jun!D32) -> 0 | E32: =C32-D32 -> 0 | F32: =IFERROR(E32/D32, 0) -> 0 | G32: =SUM(Apr!G32, May!G32, Jun!G32) -> 0 | H32: =C32-G32 -> 0 | I32: =IFERROR(H32/G32, 0) -> 0
A33: Total | C33: =SUM(C3:C31) -> 0 | D33: =SUM(D3:D31) -> 0 | E33: =C33-D33 -> 0 | F33: =IFERROR(E33/D33, 0) -> 0 | G33: =SUM(G3:G31) -> 0 | H33: =C33-G33 -> 0 | I33: =IFERROR(H33/G33, 0) -> 0
A35: Values in gold exceed expected or forecasted by 10% or more.
A37: Values in red are below expected or forecasted by 10% or more.

Sheet 3rd Qtr
A1: {=portfolio} -> Greenbacker | C1: 3rd Quarter 2024 Actual v. Expected | G1: 3rd Quarter 2024 Forecasted | J1: NOTES | K1: SR
A2: Site | B2: State | C2: Actual | D2: Expected | E2: Delta | F2: % | G2: Forecasted | H2: Delta | I2: %
A3: {=Sites[Site]} -> 10 Walpole Park South | B3: {=Sites[State]} -> MA | C3: =SUM(Jul!C3, Aug!C3, Sep!C3) -> 0 | D3: =SUM(Jul!D3, Aug!D3, Sep!D3) -> 0 | E3: =C3-D3 -> 0 | F3: =IFERROR(E3/D3, 0) -> 0 | G3: =SUM(Jul!G3, Aug!G3, Sep!G3) -> 0 | H3: =C3-G3 -> 0 | I3: =IFERROR(H3/G3, 0) -> 0
A4: 15 Walpole Park South | B4: MA | C4: =SUM(Jul!C4, Aug!C4, Sep!C4) -> 0 | D4: =SUM(Jul!D4, Aug!D4, Sep!D4) -> 0 | E4: =C4-D4 -> 0 | F4: =IFERROR(E4/D4, 0) -> 0 | G4: =SUM(Jul!G4, Aug!G4, Sep!G4) -> 0 | H4: =C4-G4 -> 0 | I4: =IFERROR(H4/G4, 0) -> 0
A5: 19 Walpole Park South | B5: MA | C5: =SUM(Jul!C5, Aug!C5, Sep!C5) -> 0 | D5: =SUM(Jul!D5, Aug!D5, Sep!D5) -> 0 | E5: =C5-D5 -> 0 | F5: =IFERROR(E5/D5, 0) -> 0 | G5: =SUM(Jul!G5, Aug!G5, Sep!G5) -> 0 | H5: =C5-G5 -> 0 | I5: =IFERROR(H5/G5, 0) -> 0
A6: 23 Walpole Park South | B6: MA | C6: =SUM(Jul!C6, Aug!C6, Sep!C6) -> 0 | D6: =SUM(Jul!D6, Aug!D6, Sep!D6) -> 0 | E6: =C6-D6 -> 0 | F6: =IFERROR(E6/D6, 0) -> 0 | G6: =SUM(Jul!G6, Aug!G6, Sep!G6) -> 0 | H6: =C6-G6 -> 0 | I6: =IFERROR(H6/G6, 0) -> 0
A7: 24 Walpole Park South | B7: MA | C7: =SUM(Jul!C7, Aug!C7, Sep!C7) -> 0 | D7: =SUM(Jul!D7, Aug!D7, Sep!D7) -> 0 | E7: =C7-D7 -> 0 | F7: =IFERROR(E7/D7, 0) -> 0 | G7: =SUM(Jul!G7, Aug!G7, Sep!G7) -> 0 | H7: =C7-G7 -> 0 | I7: =IFERROR(H7/G7, 0) -> 0
A8: 25 Walpole Park South | B8: MA | C8: =SUM(Jul!C8, Aug!C8, Sep!C8) -> 0 | D8: =SUM(Jul!D8, Aug!D8, Sep!D8) -> 0 | E8: =C8-D8 -> 0 | F8: =IFERROR(E8/D8, 0) -> 0 | G8: =SUM(Jul!G8, Aug!G8, Sep!G8) -> 0 | H8: =C8-G8 -> 0 | I8: =IFERROR(H8/G8, 0) -> 0
A9: 3 Walpole Park South | B9: MA | C9: =SUM(Jul!C9, Aug!C9, Sep!C9) -> 0 | D9: =SUM(Jul!D9, Aug!D9, Sep!D9) -> 0 | E9: =C9-D9 -> 0 | F9: =IFERROR(E9/D9, 0) -> 0 | G9: =SUM(Jul!G9, Aug!G9, Sep!G9) -> 0 | H9: =C9-G9 -> 0 | I9: =IFERROR(H9/G9, 0) -> 0
A10: 4 Walpole Park South | B10: MA | C10: =SUM(Jul!C10, Aug!C10, Sep!C10) -> 0 | D10: =SUM(Jul!D10, Aug!D10, Sep!D10) -> 0 | E10: =C10-D10 -> 0 | F10: =IFERROR(E10/D10, 0) -> 0 | G10: =SUM(Jul!G10, Aug!G10, Sep!G10) -> 0 | H10: =C10-G10 -> 0 | I10: =IFERROR(H10/G10, 0) -> 0
A11: Brockton | B11: MA | C11: =SUM(Jul!C11, Aug!C11, Sep!C11) -> 0 | D11: =SUM(Jul!D11, Aug!D11, Sep!D11) -> 0 | E11: =C11-D11 -> 0 | F11: =IFERROR(E11/D11, 0) -> 0 | G11: =SUM(Jul!G11, Aug!G11, Sep!G11) -> 0 | H11: =C11-G11 -> 0 | I11: =IFERROR(H11/G11, 0) -> 0
A12: Canton | B12: MA | C12: =SUM(Jul!C12, Aug!C12, Sep!C12) -> 0 | D12: =SUM(Jul!D12, Aug!D12, Sep!D12) -> 0 | E12: =C12-D12 -> 0 | F12: =IFERROR(E12/D12, 0) -> 0 | G12: =SUM(Jul!G12, Aug!G12, Sep!G12) -> 0 | H12: =C12-G12 -> 0 | I12: =IFERROR(H12/G12, 0) -> 0
A13: Chelsea | B13: MA | C13: =SUM(Jul!C13, Aug!C13, Sep!C13) -> 0 | D13: =SUM(Jul!D13, Aug!D13, Sep!D13) -> 0 | E13: =C13-D13 -> 0 | F13: =IFERROR(E13/D13, 0) -> 0 | G13: =SUM(Jul!G13, Aug!G13, Sep!G13) -> 0 | H13: =C13-G13 -> 0 | I13: =IFERROR(H13/G13, 0) -> 0
A14: Hamilton Landfill | B14: MA | C14: =SUM(Jul!C14, Aug!C14, Sep!C14) -> 0 | D14: =SUM(Jul!D14, Aug!D14, Sep!D14) -> 0 | E14: =C14-D14 -> 0 | F14: =IFERROR(E14/D14, 0) -> 0 | G14: =SUM(Jul!G14, Aug!G14, Sep!G14) -> 0 | H14: =C14-G14 -> 0 | I14: =IFERROR(H14/G14, 0) -> 0
A15: Holliston | B15: MA | C15: =SUM(Jul!C15, Aug!C15, Sep!C15) -> 0 | D15: =SUM(Jul!D15, Aug!D15, Sep!D15) -> 0 | E15: =C15-D15 -> 0 | F15: =IFERROR(E15/D15, 0) -> 0 | G15: =SUM(Jul!G15, Aug!G15, Sep!G15) -> 0 | H15: =C15-G15 -> 0 | I15: =IFERROR(H15/G15, 0) -> 0
... A32: Danville | B32: IL | C32: =SUM(Jul!C32, Aug!C32, Sep!C32) -> 0 | D32: =SUM(Jul!D32, Aug!D32, Sep!D32) -> 0 | E32: =C32-D32 -> 0 | F32: =IFERROR(E32/D32, 0) -> 0 | G32: =SUM(Jul!G32, Aug!G32, Sep!G32) -> 0 | H32: =C32-G32 -> 0 | I32: =IFERROR(H32/G32, 0) -> 0
A33: Total | C33: =SUM(C3:C31) -> 0 | D33: =SUM(D3:D31) -> 0 | E33: =C33-D33 -> 0 | F33: =IFERROR(E33/D33, 0) -> 0 | G33: =SUM(G3:G31) -> 0 | H33: =C33-G33 -> 0 | I33: =IFERROR(H33/G33, 0) -> 0
A35: Values in gold exceed expected or forecasted by 10% or more.
A37: Values in red are below expected or forecasted by 10% or more.

Sheet 4th Qtr
A1: {=portfolio} -> Greenbacker | C1: 4th Quarter 2024 Actual v. Expected | G1: 4th Quarter 2024 Forecasted | J1: NOTES | K1: SR
A2: Site | B2: State | C2: Actual | D2: Expected | E2: Delta | F2: % | G2: Forecasted | H2: Delta | I2: %
A3: {=Sites[Site]} -> 10 Walpole Park South | B3: {=Sites[State]} -> MA | C3: =SUM(Oct!C3, Nov!C3, Dec!C3) -> 0 | D3: =SUM(Oct!D3, Nov!D3, Dec!D3) -> 0 | E3: =C3-D3 -> 0 | F3: =IFERROR(E3/D3, 0) -> 0 | G3: =SUM(Oct!G3, Nov!G3, Dec!G3) -> 0 | H3: =C3-G3 -> 0 | I3: =IFERROR(H3/G3, 0) -> 0
A4: 15 Walpole Park South | B4: MA | C4: =SUM(Oct!C4, Nov!C4, Dec!C4) -> 0 | D4: =SUM(Oct!D4, Nov!D4, Dec!D4) -> 0 | E4: =C4-D4 -> 0 | F4: =IFERROR(E4/D4, 0) -> 0 | G4: =SUM(Oct!G4, Nov!G4, Dec!G4) -> 0 | H4: =C4-G4 -> 0 | I4: =IFERROR(H4/G4, 0) -> 0
A5: 19 Walpole Park South | B5: MA | C5: =SUM(Oct!C5, Nov!C5, Dec!C5) -> 0 | D5: =SUM(Oct!D5, Nov!D5, Dec!D5) -> 0 | E5: =C5-D5 -> 0 | F5: =IFERROR(E5/D5, 0) -> 0 | G5: =SUM(Oct!G5, Nov!G5, Dec!G5) -> 0 | H5: =C5-G5 -> 0 | I5: =IFERROR(H5/G5, 0) -> 0
A6: 23 Walpole Park South | B6: MA | C6: =SUM(Oct!C6, Nov!C6, Dec!C6) -> 0 | D6: =SUM(Oct!D6, Nov!D6, Dec!D6) -> 0 | E6: =C6-D6 -> 0 | F6: =IFERROR(E6/D6, 0) -> 0 | G6: =SUM(Oct!G6, Nov!G6, Dec!G6) -> 0 | H6: =C6-G6 -> 0 | I6: =IFERROR(H6/G6, 0) -> 0
A7: 24 Walpole Park South | B7: MA | C7: =SUM(Oct!C7, Nov!C7, Dec!C7) -> 0 | D7: =SUM(Oct!D7, Nov!D7, Dec!D7) -> 0 | E7: =C7-D7 -> 0 | F7: =IFERROR(E7/D7, 0) -> 0 | G7: =SUM(Oct!G7, Nov!G7, Dec!G7) -> 0 | H7: =C7-G7 -> 0 | I7: =IFERROR(H7/G7, 0) -> 0
A8: 25 Walpole Park South | B8: MA | C8: =SUM(Oct!C8, Nov!C8, Dec!C8) -> 0 | D8: =SUM(Oct!D8, Nov!D8, Dec!D8) -> 0 | E8: =C8-D8 -> 0 | F8: =IFERROR(E8/D8, 0) -> 0 | G8: =SUM(Oct!G8, Nov!G8, Dec!G8) -> 0 | H8: =C8-G8 -> 0 | I8: =IFERROR(H8/G8, 0) -> 0
A9: 3 Walpole Park South | B9: MA | C9: =SUM(Oct!C9, Nov!C9, Dec!C9) -> 0 | D9: =SUM(Oct!D9, Nov!D9, Dec!D9) -> 0 | E9: =C9-D9 -> 0 | F9: =IFERROR(E9/D9, 0) -> 0 | G9: =SUM(Oct!G9, Nov!G9, Dec!G9) -> 0 | H9: =C9-G9 -> 0 | I9: =IFERROR(H9/G9, 0) -> 0
A10: 4 Walpole Park South | B10: MA | C10: =SUM(Oct!C10, Nov!C10, Dec!C10) -> 0 | D10: =SUM(Oct!D10, Nov!D10, Dec!D10) -> 0 | E10: =C10-D10 -> 0 | F10: =IFERROR(E10/D10, 0) -> 0 | G10: =SUM(Oct!G10, Nov!G10, Dec!G10) -> 0 | H10: =C10-G10 -> 0 | I10: =IFERROR(H10/G10, 0) -> 0
A11: Brockton | B11: MA | C11: =SUM(Oct!C11, Nov!C11, Dec!C11) -> 0 | D11: =SUM(Oct!D11, Nov!D11, Dec!D11) -> 0 | E11: =C11-D11 -> 0 | F11: =IFERROR(E11/D11, 0) -> 0 | G11: =SUM(Oct!G11, Nov!G11, Dec!G11) -> 0 | H11: =C11-G11 -> 0 | I11: =IFERROR(H11/G11, 0) -> 0
A12: Canton | B12: MA | C12: =SUM(Oct!C12, Nov!C12, Dec!C12) -> 0 | D12: =SUM(Oct!D12, Nov!D12, Dec!D12) -> 0 | E12: =C12-D12 -> 0 | F12: =IFERROR(E12/D12, 0) -> 0 | G12: =SUM(Oct!G12, Nov!G12, Dec!G12) -> 0 | H12: =C12-G12 -> 0 | I12: =IFERROR(H12/G12, 0) -> 0
A13: Chelsea | B13: MA | C13: =SUM(Oct!C13, Nov!C13, Dec!C13) -> 0 | D13: =SUM(Oct!D13, Nov!D13, Dec!D13) -> 0 | E13: =C13-D13 -> 0 | F13: =IFERROR(E13/D13, 0) -> 0 | G13: =SUM(Oct!G13, Nov!G13, Dec!G13) -> 0 | H13: =C13-G13 -> 0 | I13: =IFERROR(H13/G13, 0) -> 0
A14: Hamilton Landfill | B14: MA | C14: =SUM(Oct!C14, Nov!C14, Dec!C14) -> 0 | D14: =SUM(Oct!D14, Nov!D14, Dec!D14) -> 0 | E14: =C14-D14 -> 0 | F14: =IFERROR(E14/D14, 0) -> 0 | G14: =SUM(Oct!G14, Nov!G14, Dec!G14) -> 0 | H14: =C14-G14 -> 0 | I14: =IFERROR(H14/G14, 0) -> 0
A15: Holliston | B15: MA | C15: =SUM(Oct!C15, Nov!C15, Dec!C15) -> 0 | D15: =SUM(Oct!D15, Nov!D15, Dec!D15) -> 0 | E15: =C15-D15 -> 0 | F15: =IFERROR(E15/D15, 0) -> 0 | G15: =SUM(Oct!G15, Nov!G15, Dec!G15) -> 0 | H15: =C15-G15 -> 0 | I15: =IFERROR(H15/G15, 0) -> 0
... A32: Danville | B32: IL | C32: =SUM(Oct!C32, Nov!C32, Dec!C32) -> 0 | D32: =SUM(Oct!D32, Nov!D32, Dec!D32) -> 0 | E32: =C32-D32 -> 0 | F32: =IFERROR(E32/D32, 0) -> 0 | G32: =SUM(Oct!G32, Nov!G32, Dec!G32) -> 0 | H32: =C32-G32 -> 0 | I32: =IFERROR(H32/G32, 0) -> 0
A33: Total | C33: =SUM(C3:C31) -> 0 | D33: =SUM(D3:D31) -> 0 | E33: =C33-D33 -> 0 | F33: =IFERROR(E33/D33, 0) -> 0 | G33: =SUM(G3:G31) -> 0 | H33: =C33-G33 -> 0 | I33: =IFERROR(H33/G33, 0) -> 0
A35: Values in gold exceed expected or forecasted by 10% or more.
A37: Values in red are below expected or forecasted by 10% or more.

Sheet Jan
A1: {=portfolio} -> Greenbacker | C1: 01-2024 Actual v. Expected | G1: 01-2024 Actual v. Forecasted | J1: NOTES | K1: SR
A2: Site | B2: State | C2: Actual | D2: Expected | E2: Delta | F2: % | G2: Forecasted | H2: Delta | I2: %
A3: {=Sites[Site]} -> 10 Walpole Park South | B3: {=Sites[State]} -> MA | C3: {=IF(INDIRECT("'" & $A3 & "'!B5:J5")="", "", INDIRECT("'" & $A3 & "'!B5:J5"))} -> 3478.8125 | D3: 6181.574 | E3: -2702.7615 | F3: -0.43722869 | G3: 6823.253 | H3: -3344.4405 | I3: -0.49015338
A4: 15 Walpole Park South | B4: MA | C4: {=IF(INDIRECT("'" & $A4 & "'!B5:J5")="", "", INDIRECT("'" & $A4 & "'!B5:J5"))} -> 12517 | D4: 22722.47 | E4: -10205.47 | F4: -0.44913559 | G4: 21603.71 | H4: -9086.71 | I4: -0.42060878
A5: 19 Walpole Park South | B5: MA | C5: {=IF(INDIRECT("'" & $A5 & "'!B5:J5")="", "", INDIRECT("'" & $A5 & "'!B5:J5"))} -> 7105.375 | D5: 13704.15 | E5: -6598.775 | F5: -0.48151655 | G5: 14450.27 | H5: -7344.895 | I5: -0.50828773
A6: 23 Walpole Park South | B6: MA | C6: {=IF(INDIRECT("'" & $A6 & "'!B5:J5")="", "", INDIRECT("'" & $A6 & "'!B5:J5"))} -> 10190.25 | D6: 16832.77 | E6: -6642.52 | F6: -0.39461835 | G6: 18563.55 | H6: -8373.3 | I6: -0.45106135
A7: 24 Walpole Park South | B7: MA | C7: {=IF(INDIRECT("'" & $A7 & "'!B5:J5")="", "", INDIRECT("'" & $A7 & "'!B5:J5"))} -> 15037 | D7: 14267.73 | E7: 769.27 | F7: 0.053916776 | G7: 28642.02 | H7: -13605.02 | I7: -0.47500211 | J7: 1. Inverter 8 was offline on 01/15/24 7 and back online on 01/17/2024. | K7: 1.SR080248
A8: 25 Walpole Park South | B8: MA | C8: {=IF(INDIRECT("'" & $A8 & "'!B5:J5")="", "", INDIRECT("'" & $A8 & "'!B5:J5"))} -> 15224.5 | D8: 26799 | E8: -11574.5 | F8: -0.43190044 | G8: 29130.79 | H8: -13906.29 | I8: -0.47737428
A9: 3 Walpole Park South | B9: MA | C9: {=IF(INDIRECT("'" & $A9 & "'!B5:J5")="", "", INDIRECT("'" & $A9 & "'!B5:J5"))} -> 19881.5 | D9: 35122.52 | E9: -15241.02 | F9: -0.43393868 | G9: 34800.55 | H9: -14919.05 | I9: -0.42870156
A10: 4 Walpole Park South | B10: MA | C10: {=IF(INDIRECT("'" & $A10 & "'!B5:J5")="", "", INDIRECT("'" & $A10 & "'!B5:J5"))} -> 10678.25 | D10: 19843.16 | E10: -9164.91 | F10: -0.46186746 | G10: 19687.72 | H10: -9009.47 | I10: -0.45761876
A11: Brockton | B11: MA | C11: {=IF(INDIRECT("'" & $A11 & "'!B5:J5")="", "", INDIRECT("'" & $A11 & "'!B5:J5"))} -> 21358 | D11: 29225.2 | E11: -7867.2 | F11: -0.26919234 | G11: 35891.12 | H11: -14533.12 | I11: -0.40492244
A12: Canton | B12: MA | C12: {=IF(INDIRECT("'" & $A12 & "'!B5:J5")="", "", INDIRECT("'" & $A12 & "'!B5:J5"))} -> 17412.25 | D12: 31213.29 | E12: -13801.04 | F12: -0.44215269 | G12: 30904.81 | H12: -13492.56 | I12: -0.43658447 | J12: 1. Inverter 4 tripped offline on 01/12/2024 at 08:30 & back online on 01/17/2024 at 14:30. | K12: 1.SR080166
A13: Chelsea | B13: MA | C13: {=IF(INDIRECT("'" & $A13 & "'!B5:J5")="", "", INDIRECT("'" & $A13 & "'!B5:J5"))} -> 38716 | D13: 54336.05 | E13: -15620.05 | F13: -0.28747121 | G13: 55003.46 | H13: -16287.46 | I13: -0.29611701
A14: Hamilton Landfill | B14: MA | C14: {=IF(INDIRECT("'" & $A14 & "'!B5:J5")="", "", INDIRECT("'" & $A14 & "'!B5:J5"))} -> 30221 | D14: 58716 | E14: -28495 | F14: -0.48530213 | G14: 0 | H14: 30221 | I14: 0
A15: Holliston | B15: MA | C15: {=IF(INDIRECT("'" & $A15 & "'!B5:J5")="", "", INDIRECT("'" & $A15 & "'!B5:J5"))} -> 37423.5 | D15: 60597.82 | E15: -23174.32 | F15: -0.38242828 | G15: 84734.92 | H15: -47311.42 | I15: -0.55834619 | J15: 1.Site tripped offline on 01/13/2024 at 03:30 & back on 01/16/2024 mid day. | K15: 1. SR080182
A16: Natick HS - Carports | B16: MA | C16: {=IF(INDIRECT("'" & $A16 & "'!B5:J5")="", "", INDIRECT("'" & $A16 & "'!B5:J5"))} -> 13924 | D16: 29010 | E16: -15086 | F16: -0.52002758 | G16: 0 | H16: 13924 | I16: 0
A17: Norton | B17: MA | C17: {=IF(INDIRECT("'" & $A17 & "'!B5:J5")="", "", INDIRECT("'" & $A17 & "'!B5:J5"))} -> 93336 | D17: 144118.9 | E17: -50782.9 | F17: -0.35236808 | G17: 162736.5 | H17: -69400.5 | I17: -0.42645934 | J17: 1. Inverter 1 was tripped offline on 01/02/2024 at 8:45 & back online on 01/03/2024 at 11:30. 2. Site was offline tripped offline on 01/21/2024 at 11:45 & back online on 01/22/2024 at 10:30. | K17: 1. SR079865 2. SR080375
A18: Palmer - Boston Rd. | B18: MA | C18: {=IF(INDIRECT("'" & $A18 & "'!B5:J5")="", "", INDIRECT("'" & $A18 & "'!B5:J5"))} -> 18016.048 | D18: 31872.06 | E18: -13856.012 | F18: -0.43473853 | G18: 45090 | H18: -27073.952 | I18: -0.6004425
A19: Shirley Bartkus | B19: MA | C19: {=IF(INDIRECT("'" & $A19 & "'!B5:J5")="", "", INDIRECT("'" & $A19 & "'!B5:J5"))} -> 24169.871 | D19: 47290.29 | E19: -23120.419 | F19: -0.48890415 | G19: 65151 | H19: -40981.129 | I19: -0.62901765
A20: Stoughton | B20: MA | C20: {=IF(INDIRECT("'" & $A20 & "'!B5:J5")="", "", INDIRECT("'" & $A20 & "'!B5:J5"))} -> 22398.5 | D20: 29378.29 | E20: -6979.79 | F20: -0.23758326 | G20: 35608.12 | H20: -13209.62 | I20: -0.37097213
A21: Wellfleet Landfill | B21: MA | C21: {=IF(INDIRECT("'" & $A21 & "'!B5:J5")="", "", INDIRECT("'" & $A21 & "'!B5:J5"))} -> 40023 | D21: 57476 | E21: -17453 | F21: -0.30365718 | G21: 0 | H21: 40023 | I21: 0 | J21: 1. Site was tripped offline on 01/07 at 18:15 and back online on 01/08 at 12:00 | K21: 1. SR080033
A22: Wilmington Garage & Building 7 | B22: MA | C22: {=IF(INDIRECT("'" & $A22 & "'!B5:J5")="", "", INDIRECT("'" & $A22 & "'!B5:J5"))} -> 28124.62 | D22: 53740.59 | E22: -25615.97 | F22: -0.47665963 | G22: 51473.44 | H22: -23348.82 | I22: -0.45360908
A23: Woburn | B23: MA | C23: {=IF(INDIRECT("'" & $A23 & "'!B5:J5")="", "", INDIRECT("'" & $A23 & "'!B5:J5"))} -> 47752.5 | D23: 99772.07 | E23: -52019.57 | F23: -0.52138409 | G23: 69636.91 | H23: -21884.41 | I23: -0.31426452 | J23: 1. Inverter 17 tripped offline on 01/23/2024 at 12:00 & back online at 16:30. | K23: 1. SR079023
A24: Friendship Solar 1 | B24: MD | C24: {=IF(INDIRECT("'" & $A24 & "'!B5:J5")="", "", INDIRECT("'" & $A24 & "'!B5:J5"))} -> 185310 | D24: 198138.4 | E24: -12828.4 | F24: -0.064744643 | G24: 253076.2 | H24: -67766.2 | I24: -0.26776994
A25: Friendship Solar 2 | B25: MD | C25: {=IF(INDIRECT("'" & $A25 & "'!B5:J5")="", "", INDIRECT("'" & $A25 & "'!B5:J5"))} -> 183527 | D25: 204402.5 | E25: -20875.5 | F25: -0.10212938 | G25: 250422.2 | H25: -66895.2 | I25: -0.26712967
A26: 101 Carnegie Center | B26: NJ | C26: {=IF(INDIRECT("'" & $A26 & "'!B5:J5")="", "", INDIRECT("'" & $A26 & "'!B5:J5"))} -> 42576 | D26: 72136 | E26: -29560 | F26: -0.40978152 | G26: 0 | H26: 42576 | I26: 0 | J26: 1.Inverters 14 and 18 tripped offline on 01/23/2024 at 13:45 & back online on 01/24/2024. | K26: 1. SR080417
A27: 302 Carnegie Center | B27: NJ | C27: {=IF(INDIRECT("'" & $A27 & "'!B5:J5")="", "", INDIRECT("'" & $A27 & "'!B5:J5"))} -> 18853 | D27: 28852 | E27: -9999 | F27: -0.34656176 | G27: 0 | H27: 18853 | I27: 0
A28: 510 Carnegie Center | B28: NJ | C28: {=IF(INDIRECT("'" & $A28 & "'!B5:J5")="", "", INDIRECT("'" & $A28 & "'!B5:J5"))} -> 40883 | D28: 79791 | E28: -38908 | F28: -0.48762392 | G28: 0 | H28: 40883 | I28: 0 | J28: 1. Inverter 7 tripped offline at 12/05/2023 at 13:00 & back online at 01/24 at 12:15. 2. Inverters 2, 5, and 24 tripped offline on 01/23/2024 & back online on 01/24/2024. | K28: 1.SR078798 2. SR080419
A29: 701 Carnegie Center | B29: NJ | C29: {=IF(INDIRECT("'" & $A29 & "'!B5:J5")="", "", INDIRECT("'" & $A29 & "'!B5:J5"))} -> 36140 | D29: 59926 | E29: -23786 | F29: -0.39692287 | G29: 0 | H29: 36140 | I29: 0
A30: Hudson County Correction | B30: NJ | C30: {=IF(INDIRECT("'" & $A30 & "'!B5:J5")="", "", INDIRECT("'" & $A30 & "'!B5:J5"))} -> 52029.49 | D30: 59439.43 | E30: -7409.9403 | F30: -0.12466372 | G30: 87395.78 | H30: -35366.29 | I30: -0.40466817
A31: ER Bison Solar | B31: PA | C31: {=IF(INDIRECT("'" & $A31 & "'!B5:J5")="", "", INDIRECT("'" & $A31 & "'!B5:J5"))} -> 50310 | D31: 0 | E31: 50310 | F31: 0 | G31: 100651 | H31: -50341 | I31: -0.500154
A32: Danville | B32: IL | C32: {=IF(INDIRECT("'" & $A32 & "'!B5:J5")="", "", INDIRECT("'" & $A32 & "'!B5:J5"))} -> 119051 | D32: 0 | E32: 119051 | F32: 0 | G32: 0 | H32: 119051 | I32: 0
A33: Total | C33: =SUM(C3:C31) -> 1136616.5 | D33: =SUM(D3:D31) -> 1584905.3 | E33: =C33-D33 -> -448288.8 | F33: =IFERROR(E33/D33, 0) -> -0.28284896 | G33: =SUM(G3:G31) -> 1501477.3 | H33: =C33-G33 -> -364860.86 | I33: =IFERROR(H33/G33, 0) -> -0.24300124
A35: Values in gold exceed expected or forecasted by 10% or more.
A37: Values in red are below expected or forecasted by 10% or more.

Sheet Feb
A1: {=portfolio} -> Greenbacker | C1: 02-2024 Actual v. Expected | G1: 02-2024 Actual v. Forecasted | J1: NOTES | K1: SR
A2: Site | B2: State | C2: Actual | D2: Expected | E2: Delta | F2: % | G2: Forecasted | H2: Delta | I2: %
A3: {=Sites[Site]} -> 10 Walpole Park South | B3: {=Sites[State]} -> MA | C3: {=IF(INDIRECT("'" & $A3 & "'!B6:J6")="", "", INDIRECT("'" & $A3 & "'!B6:J6"))} | E3: 0 | F3: 0 | H3: 0 | I3: 0
A4: 15 Walpole Park South | B4: MA | C4: {=IF(INDIRECT("'" & $A4 & "'!B6:J6")="", "", INDIRECT("'" & $A4 & "'!B6:J6"))} | E4: 0 | F4: 0 | H4: 0 | I4: 0
A5: 19 Walpole Park South | B5: MA | C5: {=IF(INDIRECT("'" & $A5 & "'!B6:J6")="", "", INDIRECT("'" & $A5 & "'!B6:J6"))} | E5: 0 | F5: 0 | H5: 0 | I5: 0
A6: 23 Walpole Park South | B6: MA | C6: {=IF(INDIRECT("'" & $A6 & "'!B6:J6")="", "", INDIRECT("'" & $A6 & "'!B6:J6"))} | E6: 0 | F6: 0 | H6: 0 | I6: 0
A7: 24 Walpole Park South | B7: MA | C7: {=IF(INDIRECT("'" & $A7 & "'!B6:J6")="", "", INDIRECT("'" & $A7 & "'!B6:J6"))} | E7: 0 | F7: 0 | H7: 0 | I7: 0
A8: 25 Walpole Park South | B8: MA | C8: {=IF(INDIRECT("'" & $A8 & "'!B6:J6")="", "", INDIRECT("'" & $A8 & "'!B6:J6"))} | E8: 0 | F8: 0 | H8: 0 | I8: 0
A9: 3 Walpole Park South | B9: MA | C9: {=IF(INDIRECT("'" & $A9 & "'!B6:J6")="", "", INDIRECT("'" & $A9 & "'!B6:J6"))} | E9: 0 | F9: 0 | H9: 0 | I9: 0
A10: 4 Walpole Park South | B10: MA | C10: {=IF(INDIRECT("'" & $A10 & "'!B6:J6")="", "", INDIRECT("'" & $A10 & "'!B6:J6"))} | E10: 0 | F10: 0 | H10: 0 | I10: 0
A11: Brockton | B11: MA | C11: {=IF(INDIRECT("'" & $A11 & "'!B6:J6")="", "", INDIRECT("'" & $A11 & "'!B6:J6"))} | E11: 0 | F11: 0 | H11: 0 | I11: 0
A12: Canton | B12: MA | C12: {=IF(INDIRECT("'" & $A12 & "'!B6:J6")="", "", INDIRECT("'" & $A12 & "'!B6:J6"))} | E12: 0 | F12: 0 | H12: 0 | I12: 0
A13: Chelsea | B13: MA | C13: {=IF(INDIRECT("'" & $A13 & "'!B6:J6")="", "", INDIRECT("'" & $A13 & "'!B6:J6"))} | E13: 0 | F13: 0 | H13: 0 | I13: 0
A14: Hamilton Landfill | B14: MA | C14: {=IF(INDIRECT("'" & $A14 & "'!B6:J6")="", "", INDIRECT("'" & $A14 & "'!B6:J6"))} | E14: 0 | F14: 0 | H14: 0 | I14: 0
A15: Holliston | B15: MA | C15: {=IF(INDIRECT("'" & $A15 & "'!B6:J6")="", "", INDIRECT("'" & $A15 & "'!B6:J6"))} | E15: 0 | F15: 0 | H15: 0 | I15: 0
... A31: ER Bison Solar | B31: PA | C31: {=IF(INDIRECT("'" & $A31 & "'!B6:J6")="", "", INDIRECT("'" & $A31 & "'!B6:J6"))} | E31: 0 | F31: 0 | H31: 0 | I31: 0
A32: Danville | B32: IL | C32: {=IF(INDIRECT("'" & $A32 & "'!B6:J6")="", "", INDIRECT("'" & $A32 & "'!B6:J6"))} | E32: 0 | F32: 0 | G32: 0 | H32: 0 | I32: 0
A33: Total | C33: =SUM(C3:C31) -> 0 | D33: =SUM(D3:D31) -> 0 | E33: =C33-D33 -> 0 | F33: =IFERROR(E33/D33, 0) -> 0 | G33: =SUM(G3:G31) -> 0 | H33: =C33-G33 -> 0 | I33: =IFERROR(H33/G33, 0) -> 0
A35: Values in gold exceed expected or forecasted by 10% or more.
A37: Values in red are below expected or forecasted by 10% or more.

Sheet Mar
A1: {=portfolio} -> Greenbacker | C1: 03-2024 Actual v. Expected | G1: 03-2024 Actual v. Forecasted | J1: NOTES | K1: SR
A2: Site | B2: State | C2: Actual | D2: Expected | E2: Delta | F2: % | G2: Forecasted | H2: Delta | I2: %
A3: {=Sites[Site]} -> 10 Walpole Park South | B3: {=Sites[State]} -> MA | C3: {=IF(INDIRECT("'" & $A3 & "'!B7:J7")="", "", INDIRECT("'" & $A3 & "'!B7:J7"))} | E3: 0 | F3: 0 | H3: 0 | I3: 0
A4: 15 Walpole Park South | B4: MA | C4: {=IF(INDIRECT("'" & $A4 & "'!B7:J7")="", "", INDIRECT("'" & $A4 & "'!B7:J7"))} | E4: 0 | F4: 0 | H4: 0 | I4: 0
A5: 19 Walpole Park South | B5: MA | C5: {=IF(INDIRECT("'" & $A5 & "'!B7:J7")="", "", INDIRECT("'" & $A5 & "'!B7:J7"))} | E5: 0 | F5: 0 | H5: 0 | I5: 0
A6: 23 Walpole Park South | B6: MA | C6: {=IF(INDIRECT("'" & $A6 & "'!B7:J7")="", "", INDIRECT("'" & $A6 & "'!B7:J7"))} | E6: 0 | F6: 0 | H6: 0 | I6: 0
A7: 24 Walpole Park South | B7: MA | C7: {=IF(INDIRECT("'" & $A7 & "'!B7:J7")="", "", INDIRECT("'" & $A7 & "'!B7:J7"))} | E7: 0 | F7: 0 | H7: 0 | I7: 0
A8: 25 Walpole Park South | B8: MA | C8: {=IF(INDIRECT("'" & $A8 & "'!B7:J7")="", "", INDIRECT("'" & $A8 & "'!B7:J7"))} | E8: 0 | F8: 0 | H8: 0 | I8: 0
A9: 3 Walpole Park South | B9: MA | C9: {=IF(INDIRECT("'" & $A9 & "'!B7:J7")="", "", INDIRECT("'" & $A9 & "'!B7:J7"))} | E9: 0 | F9: 0 | H9: 0 | I9: 0
A10: 4 Walpole Park South | B10: MA | C10: {=IF(INDIRECT("'" & $A10 & "'!B7:J7")="", "", INDIRECT("'" & $A10 & "'!B7:J7"))} | E10: 0 | F10: 0 | H10: 0 | I10: 0
A11: Brockton | B11: MA | C11: {=IF(INDIRECT("'" & $A11 & "'!B7:J7")="", "", INDIRECT("'" & $A11 & "'!B7:J7"))} | E11: 0 | F11: 0 | H11: 0 | I11: 0
A12: Canton | B12: MA | C12: {=IF(INDIRECT("'" & $A12 & "'!B7:J7")="", "", INDIRECT("'" & $A12 & "'!B7:J7"))} | E12: 0 | F12: 0 | H12: 0 | I12: 0
A13: Chelsea | B13: MA | C13: {=IF(INDIRECT("'" & $A13 & "'!B7:J7")="", "", INDIRECT("'" & $A13 & "'!B7:J7"))} | E13: 0 | F13: 0 | H13: 0 | I13: 0
A14: Hamilton Landfill | B14: MA | C14: {=IF(INDIRECT("'" & $A14 & "'!B7:J7")="", "", INDIRECT("'" & $A14 & "'!B7:J7"))} | E14: 0 | F14: 0 | H14: 0 | I14: 0
A15: Holliston | B15: MA | C15: {=IF(INDIRECT("'" & $A15 & "'!B7:J7")="", "", INDIRECT("'" & $A15 & "'!B7:J7"))} | E15: 0 | F15: 0 | H15: 0 | I15: 0
... A31: ER Bison Solar | B31: PA | C31: {=IF(INDIRECT("'" & $A31 & "'!B7:J7")="", "", INDIRECT("'" & $A31 & "'!B7:J7"))} | E31: 0 | F31: 0 | H31: 0 | I31: 0
A32: Danville | B32: IL | C32: {=IF(INDIRECT("'" & $A32 & "'!B7:J7")="", "", INDIRECT("'" & $A32 & "'!B7:J7"))} | E32: 0 | F32: 0 | G32: 0 | H32: 0 | I32: 0
A33: Total | C33: =SUM(C3:C31) -> 0 | D33: =SUM(D3:D31) -> 0 | E33: =C33-D33 -> 0 | F33: =IFERROR(E33/D33, 0) -> 0 | G33: =SUM(G3:G31) -> 0 | H33: =C33-G33 -> 0 | I33: =IFERROR(H33/G33, 0) -> 0
A35: Values in gold exceed expected or forecasted by 10% or more.
A37: Values in red are below expected or forecasted by 10% or more.

Sheet Apr
A1: {=portfolio} -> Greenbacker | C1: 04-2024 Actual v. Expected | G1: 04-2024 Actual v. Forecasted | J1: NOTES | K1: SR
A2: Site | B2: State | C2: Actual | D2: Expected | E2: Delta | F2: % | G2: Forecasted | H2: Delta | I2: %
A3: {=Sites[Site]} -> 10 Walpole Park South | B3: {=Sites[State]} -> MA | C3: {=IF(INDIRECT("'" & $A3 & "'!B8:J8")="", "", INDIRECT("'" & $A3 & "'!B8:J8"))} | E3: 0 | F3: 0 | H3: 0 | I3: 0
A4: 15 Walpole Park South | B4: MA | C4: {=IF(INDIRECT("'" & $A4 & "'!B8:J8")="", "", INDIRECT("'" & $A4 & "'!B8:J8"))} | E4: 0 | F4: 0 | H4: 0 | I4: 0
A5: 19 Walpole Park South | B5: MA | C5: {=IF(INDIRECT("'" & $A5 & "'!B8:J8")="", "", INDIRECT("'" & $A5 & "'!B8:J8"))} | E5: 0 | F5: 0 | H5: 0 | I5: 0
A6: 23 Walpole Park South | B6: MA | C6: {=IF(INDIRECT("'" & $A6 & "'!B8:J8")="", "", INDIRECT("'" & $A6 & "'!B8:J8"))} | E6: 0 | F6: 0 | H6: 0 | I6: 0
A7: 24 Walpole Park South | B7: MA | C7: {=IF(INDIRECT("'" & $A7 & "'!B8:J8")="", "", INDIRECT("'" & $A7 & "'!B8:J8"))} | E7: 0 | F7: 0 | H7: 0 | I7: 0
A8: 25 Walpole Park South | B8: MA | C8: {=IF(INDIRECT("'" & $A8 & "'!B8:J8")="", "", INDIRECT("'" & $A8 & "'!B8:J8"))} | E8: 0 | F8: 0 | H8: 0 | I8: 0
A9: 3 Walpole Park South | B9: MA | C9: {=IF(INDIRECT("'" & $A9 & "'!B8:J8")="", "", INDIRECT("'" & $A9 & "'!B8:J8"))} | E9: 0 | F9: 0 | H9: 0 | I9: 0
A10: 4 Walpole Park South | B10: MA | C10: {=IF(INDIRECT("'" & $A10 & "'!B8:J8")="", "", INDIRECT("'" & $A10 & "'!B8:J8"))} | E10: 0 | F10: 0 | H10: 0 | I10: 0
A11: Brockton | B11: MA | C11: {=IF(INDIRECT("'" & $A11 & "'!B8:J8")="", "", INDIRECT("'" & $A11 & "'!B8:J8"))} | E11: 0 | F11: 0 | H11: 0 | I11: 0
A12: Canton | B12: MA | C12: {=IF(INDIRECT("'" & $A12 & "'!B8:J8")="", "", INDIRECT("'" & $A12 & "'!B8:J8"))} | E12: 0 | F12: 0 | H12: 0 | I12: 0
A13: Chelsea | B13: MA | C13: {=IF(INDIRECT("'" & $A13 & "'!B8:J8")="", "", INDIRECT("'" & $A13 & "'!B8:J8"))} | E13: 0 | F13: 0 | H13: 0 | I13: 0
A14: Hamilton Landfill | B14: MA | C14: {=IF(INDIRECT("'" & $A14 & "'!B8:J8")="", "", INDIRECT("'" & $A14 & "'!B8:J8"))} | E14: 0 | F14: 0 | H14: 0 | I14: 0
A15: Holliston | B15: MA | C15: {=IF(INDIRECT("'" & $A15 & "'!B8:J8")="", "", INDIRECT("'" & $A15 & "'!B8:J8"))} | E15: 0 | F15: 0 | H15: 0 | I15: 0
... A31: ER Bison Solar | B31: PA | C31: {=IF(INDIRECT("'" & $A31 & "'!B8:J8")="", "", INDIRECT("'" & $A31 & "'!B8:J8"))} | E31: 0 | F31: 0 | H31: 0 | I31: 0
A32: Danville | B32: IL | C32: {=IF(INDIRECT("'" & $A32 & "'!B8:J8")="", "", INDIRECT("'" & $A32 & "'!B8:J8"))} | E32: 0 | F32: 0 | G32: 0 | H32: 0 | I32: 0
A33: Total | C33: =SUM(C3:C31) -> 0 | D33: =SUM(D3:D31) -> 0 | E33: =C33-D33 -> 0 | F33: =IFERROR(E33/D33, 0) -> 0 | G33: =SUM(G3:G31) -> 0 | H33: =C33-G33 -> 0 | I33: =IFERROR(H33/G33, 0) -> 0
A35: Values in gold exceed expected or forecasted by 10% or more.
A37: Values in red are below expected or forecasted by 10% or more.

Sheet May
A1: {=portfolio} -> Greenbacker | C1: 05-2024 Actual v. Expected | G1: 05-2024 Actual v. Forecasted | J1: NOTES | K1: SR
A2: Site | B2: State | C2: Actual | D2: Expected | E2: Delta | F2: % | G2: Forecasted | H2: Delta | I2: %
A3: {=Sites[Site]} -> 10 Walpole Park South | B3: {=Sites[State]} -> MA | C3: {=IF(INDIRECT("'" & $A3 & "'!B9:J9")="", "", INDIRECT("'" & $A3 & "'!B9:J9"))} | E3: 0 | F3: 0 | H3: 0 | I3: 0
A4: 15 Walpole Park South | B4: MA | C4: {=IF(INDIRECT("'" & $A4 & "'!B9:J9")="", "", INDIRECT("'" & $A4 & "'!B9:J9"))} | E4: 0 | F4: 0 | H4: 0 | I4: 0
A5: 19 Walpole Park South | B5: MA | C5: {=IF(INDIRECT("'" & $A5 & "'!B9:J9")="", "", INDIRECT("'" & $A5 & "'!B9:J9"))} | E5: 0 | F5: 0 | H5: 0 | I5: 0
A6: 23 Walpole Park South | B6: MA | C6: {=IF(INDIRECT("'" & $A6 & "'!B9:J9")="", "", INDIRECT("'" & $A6 & "'!B9:J9"))} | E6: 0 | F6: 0 | H6: 0 | I6: 0
A7: 24 Walpole Park South | B7: MA | C7: {=IF(INDIRECT("'" & $A7 & "'!B9:J9")="", "", INDIRECT("'" & $A7 & "'!B9:J9"))} | E7: 0 | F7: 0 | H7: 0 | I7: 0
A8: 25 Walpole Park South | B8: MA | C8: {=IF(INDIRECT("'" & $A8 & "'!B9:J9")="", "", INDIRECT("'" & $A8 & "'!B9:J9"))} | E8: 0 | F8: 0 | H8: 0 | I8: 0
A9: 3 Walpole Park South | B9: MA | C9: {=IF(INDIRECT("'" & $A9 & "'!B9:J9")="", "", INDIRECT("'" & $A9 & "'!B9:J9"))} | E9: 0 | F9: 0 | H9: 0 | I9: 0
A10: 4 Walpole Park South | B10: MA | C10: {=IF(INDIRECT("'" & $A10 & "'!B9:J9")="", "", INDIRECT("'" & $A10 & "'!B9:J9"))} | E10: 0 | F10: 0 | H10: 0 | I10: 0
A11: Brockton | B11: MA | C11: {=IF(INDIRECT("'" & $A11 & "'!B9:J9")="", "", INDIRECT("'" & $A11 & "'!B9:J9"))} | E11: 0 | F11: 0 | H11: 0 | I11: 0
A12: Canton | B12: MA | C12: {=IF(INDIRECT("'" & $A12 & "'!B9:J9")="", "", INDIRECT("'" & $A12 & "'!B9:J9"))} | E12: 0 | F12: 0 | H12: 0 | I12: 0
A13: Chelsea | B13: MA | C13: {=IF(INDIRECT("'" & $A13 & "'!B9:J9")="", "", INDIRECT("'" & $A13 & "'!B9:J9"))} | E13: 0 | F13: 0 | H13: 0 | I13: 0
A14: Hamilton Landfill | B14: MA | C14: {=IF(INDIRECT("'" & $A14 & "'!B9:J9")="", "", INDIRECT("'" & $A14 & "'!B9:J9"))} | E14: 0 | F14: 0 | H14: 0 | I14: 0
A15: Holliston | B15: MA | C15: {=IF(INDIRECT("'" & $A15 & "'!B9:J9")="", "", INDIRECT("'" & $A15 & "'!B9:J9"))} | E15: 0 | F15: 0 | H15: 0 | I15: 0
... A31: ER Bison Solar | B31: PA | C31: {=IF(INDIRECT("'" & $A31 & "'!B9:J9")="", "", INDIRECT("'" & $A31 & "'!B9:J9"))} | E31: 0 | F31: 0 | H31: 0 | I31: 0
A32: Danville | B32: IL | C32: {=IF(INDIRECT("'" & $A32 & "'!B9:J9")="", "", INDIRECT("'" & $A32 & "'!B9:J9"))} | E32: 0 | F32: 0 | G32: 0 | H32: 0 | I32: 0
A33: Total | C33: =SUM(C3:C31) -> 0 | D33: =SUM(D3:D31) -> 0 | E33: =C33-D33 -> 0 | F33: =IFERROR(E33/D33, 0) -> 0 | G33: =SUM(G3:G31) -> 0 | H33: =C33-G33 -> 0 | I33: =IFERROR(H33/G33, 0) -> 0
A35: Values in gold exceed expected or forecasted by 10% or more.
A37: Values in red are below expected or forecasted by 10% or more.

Sheet Jun
A1: {=portfolio} -> Greenbacker | C1: 06-2024 Actual v. Expected | G1: 06-2024 Actual v. Forecasted | J1: NOTES | K1: SR
A2: Site | B2: State | C2: Actual | D2: Expected | E2: Delta | F2: % | G2: Forecasted | H2: Delta | I2: %
A3: {=Sites[Site]} -> 10 Walpole Park South | B3: {=Sites[State]} -> MA | C3: {=IF(INDIRECT("'" & $A3 & "'!B10:J10")="", "", INDIRECT("'" & $A3 & "'!B10:J10"))} | E3: 0 | F3: 0 | H3: 0 | I3: 0
A4: 15 Walpole Park South | B4: MA | C4: {=IF(INDIRECT("'" & $A4 & "'!B10:J10")="", "", INDIRECT("'" & $A4 & "'!B10:J10"))} | E4: 0 | F4: 0 | H4: 0 | I4: 0
A5: 19 Walpole Park South | B5: MA | C5: {=IF(INDIRECT("'" & $A5 & "'!B10:J10")="", "", INDIRECT("'" & $A5 & "'!B10:J10"))} | E5: 0 | F5: 0 | H5: 0 | I5: 0
A6: 23 Walpole Park South | B6: MA | C6: {=IF(INDIRECT("'" & $A6 & "'!B10:J10")="", "", INDIRECT("'" & $A6 & "'!B10:J10"))} | E6: 0 | F6: 0 | H6: 0 | I6: 0
A7: 24 Walpole Park South | B7: MA | C7: {=IF(INDIRECT("'" & $A7 & "'!B10:J10")="", "", INDIRECT("'" & $A7 & "'!B10:J10"))} | E7: 0 | F7: 0 | H7: 0 | I7: 0
A8: 25 Walpole Park South | B8: MA | C8: {=IF(INDIRECT("'" & $A8 & "'!B10:J10")="", "", INDIRECT("'" & $A8 & "'!B10:J10"))} | E8: 0 | F8: 0 | H8: 0 | I8: 0
A9: 3 Walpole Park South | B9: MA | C9: {=IF(INDIRECT("'" & $A9 & "'!B10:J10")="", "", INDIRECT("'" & $A9 & "'!B10:J10"))} | E9: 0 | F9: 0 | H9: 0 | I9: 0
A10: 4 Walpole Park South | B10: MA | C10: {=IF(INDIRECT("'" & $A10 & "'!B10:J10")="", "", INDIRECT("'" & $A10 & "'!B10:J10"))} | E10: 0 | F10: 0 | H10: 0 | I10: 0
A11: Brockton | B11: MA | C11: {=IF(INDIRECT("'" & $A11 & "'!B10:J10")="", "", INDIRECT("'" & $A11 & "'!B10:J10"))} | E11: 0 | F11: 0 | H11: 0 | I11: 0
A12: Canton | B12: MA | C12: {=IF(INDIRECT("'" & $A12 & "'!B10:J10")="", "", INDIRECT("'" & $A12 & "'!B10:J10"))} | E12: 0 | F12: 0 | H12: 0 | I12: 0
A13: Chelsea | B13: MA | C13: {=IF(INDIRECT("'" & $A13 & "'!B10:J10")="", "", INDIRECT("'" & $A13 & "'!B10:J10"))} | E13: 0 | F13: 0 | H13: 0 | I13: 0
A14: Hamilton Landfill | B14: MA | C14: {=IF(INDIRECT("'" & $A14 & "'!B10:J10")="", "", INDIRECT("'" & $A14 & "'!B10:J10"))} | E14: 0 | F14: 0 | H14: 0 | I14: 0
A15: Holliston | B15: MA | C15: {=IF(INDIRECT("'" & $A15 & "'!B10:J10")="", "", INDIRECT("'" & $A15 & "'!B10:J10"))} | E15: 0 | F15: 0 | H15: 0 | I15: 0
... A31: ER Bison Solar | B31: PA | C31: {=IF(INDIRECT("'" & $A31 & "'!B10:J10")="", "", INDIRECT("'" & $A31 & "'!B10:J10"))} | E31: 0 | F31: 0 | H31: 0 | I31: 0
A32: Danville | B32: IL | C32: {=IF(INDIRECT("'" & $A32 & "'!B10:J10")="", "", INDIRECT("'" & $A32 & "'!B10:J10"))} | E32: 0 | F32: 0 | G32: 0 | H32: 0 | I32: 0
A33: Total | C33: =SUM(C3:C31) -> 0 | D33: =SUM(D3:D31) -> 0 | E33: =C33-D33 -> 0 | F33: =IFERROR(E33/D33, 0) -> 0 | G33: =SUM(G3:G31) -> 0 | H33: =C33-G33 -> 0 | I33: =IFERROR(H33/G33, 0) -> 0
A35: Values in gold exceed expected or forecasted by 10% or more.
A37: Values in red are below expected or forecasted by 10% or more.

Sheet Jul
A1: {=portfolio} -> Greenbacker | C1: 07-2024 Actual v. Expected | G1: 07-2024 Actual v. Forecasted | J1: NOTES | K1: SR
A2: Site | B2: State | C2: Actual | D2: Expected | E2: Delta | F2: % | G2: Forecasted | H2: Delta | I2: %
A3: {=Sites[Site]} -> 10 Walpole Park South | B3: {=Sites[State]} -> MA | C3: {=IF(INDIRECT("'" & $A3 & "'!B11:J11")="", "", INDIRECT("'" & $A3 & "'!B11:J11"))} | E3: 0 | F3: 0 | H3: 0 | I3: 0
A4: 15 Walpole Park South | B4: MA | C4: {=IF(INDIRECT("'" & $A4 & "'!B11:J11")="", "", INDIRECT("'" & $A4 & "'!B11:J11"))} | E4: 0 | F4: 0 | H4: 0 | I4: 0
A5: 19 Walpole Park South | B5: MA | C5: {=IF(INDIRECT("'" & $A5 & "'!B11:J11")="", "", INDIRECT("'" & $A5 & "'!B11:J11"))} | E5: 0 | F5: 0 | H5: 0 | I5: 0
A6: 23 Walpole Park South | B6: MA | C6: {=IF(INDIRECT("'" & $A6 & "'!B11:J11")="", "", INDIRECT("'" & $A6 & "'!B11:J11"))} | E6: 0 | F6: 0 | H6: 0 | I6: 0
A7: 24 Walpole Park South | B7: MA | C7: {=IF(INDIRECT("'" & $A7 & "'!B11:J11")="", "", INDIRECT("'" & $A7 & "'!B11:J11"))} | E7: 0 | F7: 0 | H7: 0 | I7: 0
A8: 25 Walpole Park South | B8: MA | C8: {=IF(INDIRECT("'" & $A8 & "'!B11:J11")="", "", INDIRECT("'" & $A8 & "'!B11:J11"))} | E8: 0 | F8: 0 | H8: 0 | I8: 0
A9: 3 Walpole Park South | B9: MA | C9: {=IF(INDIRECT("'" & $A9 & "'!B11:J11")="", "", INDIRECT("'" & $A9 & "'!B11:J11"))} | E9: 0 | F9: 0 | H9: 0 | I9: 0
A10: 4 Walpole Park South | B10: MA | C10: {=IF(INDIRECT("'" & $A10 & "'!B11:J11")="", "", INDIRECT("'" & $A10 & "'!B11:J11"))} | E10: 0 | F10: 0 | H10: 0 | I10: 0
A11: Brockton | B11: MA | C11: {=IF(INDIRECT("'" & $A11 & "'!B11:J11")="", "", INDIRECT("'" & $A11 & "'!B11:J11"))} | E11: 0 | F11: 0 | H11: 0 | I11: 0
A12: Canton | B12: MA | C12: {=IF(INDIRECT("'" & $A12 & "'!B11:J11")="", "", INDIRECT("'" & $A12 & "'!B11:J11"))} | E12: 0 | F12: 0 | H12: 0 | I12: 0
A13: Chelsea | B13: MA | C13: {=IF(INDIRECT("'" & $A13 & "'!B11:J11")="", "", INDIRECT("'" & $A13 & "'!B11:J11"))} | E13: 0 | F13: 0 | H13: 0 | I13: 0
A14: Hamilton Landfill | B14: MA | C14: {=IF(INDIRECT("'" & $A14 & "'!B11:J11")="", "", INDIRECT("'" & $A14 & "'!B11:J11"))} | E14: 0 | F14: 0 | H14: 0 | I14: 0
A15: Holliston | B15: MA | C15: {=IF(INDIRECT("'" & $A15 & "'!B11:J11")="", "", INDIRECT("'" & $A15 & "'!B11:J11"))} | E15: 0 | F15: 0 | H15: 0 | I15: 0
... A31: ER Bison Solar | B31: PA | C31: {=IF(INDIRECT("'" & $A31 & "'!B11:J11")="", "", INDIRECT("'" & $A31 & "'!B11:J11"))} | E31: 0 | F31: 0 | H31: 0 | I31: 0
A32: Danville | B32: IL | C32: {=IF(INDIRECT("'" & $A32 & "'!B11:J11")="", "", INDIRECT("'" & $A32 & "'!B11:J11"))} | E32: 0 | F32: 0 | G32: 0 | H32: 0 | I32: 0
A33: Total | C33: =SUM(C3:C31) -> 0 | D33: =SUM(D3:D31) -> 0 | E33: =C33-D33 -> 0 | F33: =IFERROR(E33/D33, 0) -> 0 | G33: =SUM(G3:G31) -> 0 | H33: =C33-G33 -> 0 | I33: =IFERROR(H33/G33, 0) -> 0
A35: Values in gold exceed expected or forecasted by 10% or more.
A37: Values in red are below expected or forecasted by 10% or more.

Sheet Aug
A1: {=portfolio} -> Greenbacker | C1: 08-2024 Actual v. Expected | G1: 08-2024 Actual v. Forecasted | J1: NOTES | K1: SR
A2: Site | B2: State | C2: Actual | D2: Expected | E2: Delta | F2: % | G2: Forecasted | H2: Delta | I2: %
A3: {=Sites[Site]} -> 10 Walpole Park South | B3: {=Sites[State]} -> MA | C3: {=IF(INDIRECT("'" & $A3 & "'!B12:J12")="", "", INDIRECT("'" & $A3 & "'!B12:J12"))} | E3: 0 | F3: 0 | H3: 0 | I3: 0
A4: 15 Walpole Park South | B4: MA | C4: {=IF(INDIRECT("'" & $A4 & "'!B12:J12")="", "", INDIRECT("'" & $A4 & "'!B12:J12"))} | E4: 0 | F4: 0 | H4: 0 | I4: 0
A5: 19 Walpole Park South | B5: MA | C5: {=IF(INDIRECT("'" & $A5 & "'!B12:J12")="", "", INDIRECT("'" & $A5 & "'!B12:J12"))} | E5: 0 | F5: 0 | H5: 0 | I5: 0
A6: 23 Walpole Park South | B6: MA | C6: {=IF(INDIRECT("'" & $A6 & "'!B12:J12")="", "", INDIRECT("'" & $A6 & "'!B12:J12"))} | E6: 0 | F6: 0 | H6: 0 | I6: 0
A7: 24 Walpole Park South | B7: MA | C7: {=IF(INDIRECT("'" & $A7 & "'!B12:J12")="", "", INDIRECT("'" & $A7 & "'!B12:J12"))} | E7: 0 | F7: 0 | H7: 0 | I7: 0
A8: 25 Walpole Park South | B8: MA | C8: {=IF(INDIRECT("'" & $A8 & "'!B12:J12")="", "", INDIRECT("'" & $A8 & "'!B12:J12"))} | E8: 0 | F8: 0 | H8: 0 | I8: 0
A9: 3 Walpole Park South | B9: MA | C9: {=IF(INDIRECT("'" & $A9 & "'!B12:J12")="", "", INDIRECT("'" & $A9 & "'!B12:J12"))} | E9: 0 | F9: 0 | H9: 0 | I9: 0
A10: 4 Walpole Park South | B10: MA | C10: {=IF(INDIRECT("'" & $A10 & "'!B12:J12")="", "", INDIRECT("'" & $A10 & "'!B12:J12"))} | E10: 0 | F10: 0 | H10: 0 | I10: 0
A11: Brockton | B11: MA | C11: {=IF(INDIRECT("'" & $A11 & "'!B12:J12")="", "", INDIRECT("'" & $A11 & "'!B12:J12"))} | E11: 0 | F11: 0 | H11: 0 | I11: 0
A12: Canton | B12: MA | C12: {=IF(INDIRECT("'" & $A12 & "'!B12:J12")="", "", INDIRECT("'" & $A12 & "'!B12:J12"))} | E12: 0 | F12: 0 | H12: 0 | I12: 0
A13: Chelsea | B13: MA | C13: {=IF(INDIRECT("'" & $A13 & "'!B12:J12")="", "", INDIRECT("'" & $A13 & "'!B12:J12"))} | E13: 0 | F13: 0 | H13: 0 | I13: 0
A14: Hamilton Landfill | B14: MA | C14: {=IF(INDIRECT("'" & $A14 & "'!B12:J12")="", "", INDIRECT("'" & $A14 & "'!B12:J12"))} | E14: 0 | F14: 0 | H14: 0 | I14: 0
A15: Holliston | B15: MA | C15: {=IF(INDIRECT("'" & $A15 & "'!B12:J12")="", "", INDIRECT("'" & $A15 & "'!B12:J12"))} | E15: 0 | F15: 0 | H15: 0 | I15: 0
... A31: ER Bison Solar | B31: PA | C31: {=IF(INDIRECT("'" & $A31 & "'!B12:J12")="", "", INDIRECT("'" & $A31 & "'!B12:J12"))} | E31: 0 | F31: 0 | H31: 0 | I31: 0
A32: Danville | B32: IL | C32: {=IF(INDIRECT("'" & $A32 & "'!B12:J12")="", "", INDIRECT("'" & $A32 & "'!B12:J12"))} | E32: 0 | F32: 0 | G32: 0 | H32: 0 | I32: 0
A33: Total | C33: =SUM(C3:C31) -> 0 | D33: =SUM(D3:D31) -> 0 | E33: =C33-D33 -> 0 | F33: =IFERROR(E33/D33, 0) -> 0 | G33: =SUM(G3:G31) -> 0 | H33: =C33-G33 -> 0 | I33: =IFERROR(H33/G33, 0) -> 0
A35: Values in gold exceed expected or forecasted by 10% or more.
A37: Values in red are below expected or forecasted by 10% or more.

Sheet Sep
A1: {=portfolio} -> Greenbacker | C1: 09-2024 Actual v. Expected | G1: 09-2024 Actual v. Forecasted | J1: NOTES | K1: SR
A2: Site | B2: State | C2: Actual | D2: Expected | E2: Delta | F2: % | G2: Forecasted | H2: Delta | I2: %
A3: {=Sites[Site]} -> 10 Walpole Park South | B3: {=Sites[State]} -> MA | C3: {=IF(INDIRECT("'" & $A3 & "'!B13:J13")="", "", INDIRECT("'" & $A3 & "'!B13:J13"))} | E3: 0 | F3: 0 | H3: 0 | I3: 0
A4: 15 Walpole Park South | B4: MA | C4: {=IF(INDIRECT("'" & $A4 & "'!B13:J13")="", "", INDIRECT("'" & $A4 & "'!B13:J13"))} | E4: 0 | F4: 0 | H4: 0 | I4: 0
A5: 19 Walpole Park South | B5: MA | C5: {=IF(INDIRECT("'" & $A5 & "'!B13:J13")="", "", INDIRECT("'" & $A5 & "'!B13:J13"))} | E5: 0 | F5: 0 | H5: 0 | I5: 0
A6: 23 Walpole Park South | B6: MA | C6: {=IF(INDIRECT("'" & $A6 & "'!B13:J13")="", "", INDIRECT("'" & $A6 & "'!B13:J13"))} | E6: 0 | F6: 0 | H6: 0 | I6: 0
A7: 24 Walpole Park South | B7: MA | C7: {=IF(INDIRECT("'" & $A7 & "'!B13:J13")="", "", INDIRECT("'" & $A7 & "'!B13:J13"))} | E7: 0 | F7: 0 | H7: 0 | I7: 0
A8: 25 Walpole Park South | B8: MA | C8: {=IF(INDIRECT("'" & $A8 & "'!B13:J13")="", "", INDIRECT("'" & $A8 & "'!B13:J13"))} | E8: 0 | F8: 0 | H8: 0 | I8: 0
A9: 3 Walpole Park South | B9: MA | C9: {=IF(INDIRECT("'" & $A9 & "'!B13:J13")="", "", INDIRECT("'" & $A9 & "'!B13:J13"))} | E9: 0 | F9: 0 | H9: 0 | I9: 0
A10: 4 Walpole Park South | B10: MA | C10: {=IF(INDIRECT("'" & $A10 & "'!B13:J13")="", "", INDIRECT("'" & $A10 & "'!B13:J13"))} | E10: 0 | F10: 0 | H10: 0 | I10: 0
A11: Brockton | B11: MA | C11: {=IF(INDIRECT("'" & $A11 & "'!B13:J13")="", "", INDIRECT("'" & $A11 & "'!B13:J13"))} | E11: 0 | F11: 0 | H11: 0 | I11: 0
A12: Canton | B12: MA | C12: {=IF(INDIRECT("'" & $A12 & "'!B13:J13")="", "", INDIRECT("'" & $A12 & "'!B13:J13"))} | E12: 0 | F12: 0 | H12: 0 | I12: 0
A13: Chelsea | B13: MA | C13: {=IF(INDIRECT("'" & $A13 & "'!B13:J13")="", "", INDIRECT("'" & $A13 & "'!B13:J13"))} | E13: 0 | F13: 0 | H13: 0 | I13: 0
A14: Hamilton Landfill | B14: MA | C14: {=IF(INDIRECT("'" & $A14 & "'!B13:J13")="", "", INDIRECT("'" & $A14 & "'!B13:J13"))} | E14: 0 | F14: 0 | H14: 0 | I14: 0
A15: Holliston | B15: MA | C15: {=IF(INDIRECT("'" & $A15 & "'!B13:J13")="", "", INDIRECT("'" & $A15 & "'!B13:J13"))} | E15: 0 | F15: 0 | H15: 0 | I15: 0
... A31: ER Bison Solar | B31: PA | C31: {=IF(INDIRECT("'" & $A31 & "'!B13:J13")="", "", INDIRECT("'" & $A31 & "'!B13:J13"))} | E31: 0 | F31: 0 | H31: 0 | I31: 0
A32: Danville | B32: IL | C32: {=IF(INDIRECT("'" & $A32 & "'!B13:J13")="", "", INDIRECT("'" & $A32 & "'!B13:J13"))} | E32: 0 | F32: 0 | G32: 0 | H32: 0 | I32: 0
A33: Total | C33: =SUM(C3:C31) -> 0 | D33: =SUM(D3:D31) -> 0 | E33: =C33-D33 -> 0 | F33: =IFERROR(E33/D33, 0) -> 0 | G33: =SUM(G3:G31) -> 0 | H33: =C33-G33 -> 0 | I33: =IFERROR(H33/G33, 0) -> 0
A35: Values in gold exceed expected or forecasted by 10% or more.
A37: Values in red are below expected or forecasted by 10% or more.

Sheet Oct
A1: {=portfolio} -> Greenbacker | C1: 10-2024 Actual v. Expected | G1: 10-2024 Actual v. Forecasted | J1: NOTES | K1: SR
A2: Site | B2: State | C2: Actual | D2: Expected | E2: Delta | F2: % | G2: Forecasted | H2: Delta | I2: %
A3: {=Sites[Site]} -> 10 Walpole Park South | B3: {=Sites[State]} -> MA | C3: {=IF(INDIRECT("'" & $A3 & "'!B14:J14")="", "", INDIRECT("'" & $A3 & "'!B14:J14"))} | E3: 0 | F3: 0 | H3: 0 | I3: 0
A4: 15 Walpole Park South | B4: MA | C4: {=IF(INDIRECT("'" & $A4 & "'!B14:J14")="", "", INDIRECT("'" & $A4 & "'!B14:J14"))} | E4: 0 | F4: 0 | H4: 0 | I4: 0
A5: 19 Walpole Park South | B5: MA | C5: {=IF(INDIRECT("'" & $A5 & "'!B14:J14")="", "", INDIRECT("'" & $A5 & "'!B14:J14"))} | E5: 0 | F5: 0 | H5: 0 | I5: 0
A6: 23 Walpole Park South | B6: MA | C6: {=IF(INDIRECT("'" & $A6 & "'!B14:J14")="", "", INDIRECT("'" & $A6 & "'!B14:J14"))} | E6: 0 | F6: 0 | H6: 0 | I6: 0
A7: 24 Walpole Park South | B7: MA | C7: {=IF(INDIRECT("'" & $A7 & "'!B14:J14")="", "", INDIRECT("'" & $A7 & "'!B14:J14"))} | E7: 0 | F7: 0 | H7: 0 | I7: 0
A8: 25 Walpole Park South | B8: MA | C8: {=IF(INDIRECT("'" & $A8 & "'!B14:J14")="", "", INDIRECT("'" & $A8 & "'!B14:J14"))} | E8: 0 | F8: 0 | H8: 0 | I8: 0
A9: 3 Walpole Park South | B9: MA | C9: {=IF(INDIRECT("'" & $A9 & "'!B14:J14")="", "", INDIRECT("'" & $A9 & "'!B14:J14"))} | E9: 0 | F9: 0 | H9: 0 | I9: 0
A10: 4 Walpole Park South | B10: MA | C10: {=IF(INDIRECT("'" & $A10 & "'!B14:J14")="", "", INDIRECT("'" & $A10 & "'!B14:J14"))} | E10: 0 | F10: 0 | H10: 0 | I10: 0
A11: Brockton | B11: MA | C11: {=IF(INDIRECT("'" & $A11 & "'!B14:J14")="", "", INDIRECT("'" & $A11 & "'!B14:J14"))} | E11: 0 | F11: 0 | H11: 0 | I11: 0
A12: Canton | B12: MA | C12: {=IF(INDIRECT("'" & $A12 & "'!B14:J14")="", "", INDIRECT("'" & $A12 & "'!B14:J14"))} | E12: 0 | F12: 0 | H12: 0 | I12: 0
A13: Chelsea | B13: MA | C13: {=IF(INDIRECT("'" & $A13 & "'!B14:J14")="", "", INDIRECT("'" & $A13 & "'!B14:J14"))} | E13: 0 | F13: 0 | H13: 0 | I13: 0
A14: Hamilton Landfill | B14: MA | C14: {=IF(INDIRECT("'" & $A14 & "'!B14:J14")="", "", INDIRECT("'" & $A14 & "'!B14:J14"))} | E14: 0 | F14: 0 | H14: 0 | I14: 0
A15: Holliston | B15: MA | C15: {=IF(INDIRECT("'" & $A15 & "'!B14:J14")="", "", INDIRECT("'" & $A15 & "'!B14:J14"))} | E15: 0 | F15: 0 | H15: 0 | I15: 0
... A31: ER Bison Solar | B31: PA | C31: {=IF(INDIRECT("'" & $A31 & "'!B14:J14")="", "", INDIRECT("'" & $A31 & "'!B14:J14"))} | E31: 0 | F31: 0 | H31: 0 | I31: 0
A32: Danville | B32: IL | C32: {=IF(INDIRECT("'" & $A32 & "'!B14:J14")="", "", INDIRECT("'" & $A32 & "'!B14:J14"))} | E32: 0 | F32: 0 | G32: 0 | H32: 0 | I32: 0
A33: Total | C33: =SUM(C3:C31) -> 0 | D33: =SUM(D3:D31) -> 0 | E33: =C33-D33 -> 0 | F33: =IFERROR(E33/D33, 0) -> 0 | G33: =SUM(G3:G31) -> 0 | H33: =C33-G33 -> 0 | I33: =IFERROR(H33/G33, 0) -> 0
A35: Values in gold exceed expected or forecasted by 10% or more.
A37: Values in red are below expected or forecasted by 10% or more.

Sheet Nov
A1: {=portfolio} -> Greenbacker | C1: 11-2024 Actual v. Expected | G1: 11-2024 Actual v. Forecasted | J1: NOTES | K1: SR
A2: Site | B2: State | C2: Actual | D2: Expected | E2: Delta | F2: % | G2: Forecasted | H2: Delta | I2: %
A3: {=Sites[Site]} -> 10 Walpole Park South | B3: {=Sites[State]} -> MA | C3: {=IF(INDIRECT("'" & $A3 & "'!B15:J15")="", "", INDIRECT("'" & $A3 & "'!B15:J15"))} | E3: 0 | F3: 0 | H3: 0 | I3: 0
A4: 15 Walpole Park South | B4: MA | C4: {=IF(INDIRECT("'" & $A4 & "'!B15:J15")="", "", INDIRECT("'" & $A4 & "'!B15:J15"))} | E4: 0 | F4: 0 | H4: 0 | I4: 0
A5: 19 Walpole Park South | B5: MA | C5: {=IF(INDIRECT("'" & $A5 & "'!B15:J15")="", "", INDIRECT("'" & $A5 & "'!B15:J15"))} | E5: 0 | F5: 0 | H5: 0 | I5: 0
