Workbook
Name JanActual: Jan!$C$3:$C$27
Name JanActual2: Jan!#REF!
Name JanExpected: Jan!$D$3:$D$27
Name JanExpectedDelta: Jan!$E$3:$E$27
Name JanExpectedPercent: Jan!$F$3:$F$27
Name JanExpPercent: Jan!$F$3:$F$27
Name JanForecasted: Jan!$G$3:$G$27
Name JanForecastedDelta: Jan!$H$3:$H$27
Name JanForecastedPercent: Jan!$I$3:$I$27
Name portfolio: Sites!$B$1:$B$1

Sheet YTD Total
A1: {=portfolio} -> Lodestar | C1: Year to Date 2024 Actual v. Expected | G1: Year to Date 2024 Forecasted
A2: Site | B2: State | C2: Actual | D2: Expected | E2: Delta | F2: % | G2: Forecasted | H2: Delta | I2: %
A3: {=Sites[Site]} -> Barkhamsted | B3: {=Sites[State]} -> CT | C3: =SUM('1st Qtr'!C3, '2nd Qtr'!C3, '3rd Qtr'!C3, '4th Qtr'!C3) -> 40962 | D3: =SUM('1st Qtr'!D3, '2nd Qtr'!D3, '3rd Qtr'!D3, '4th Qtr'!D3) -> 81116.11 | E3: =C3-D3 -> -40154.11 | F3: =IFERROR(E3/D3, 0) -> -0.49502016 | G3: =SUM('1st Qtr'!G3, '2nd Qtr'!G3, '3rd Qtr'!G3, '4th Qtr'!G3) -> 95666.17 | H3: =C3-G3 -> -54704.17 | I3: =IFERROR(H3/G3, 0) -> -0.57182356
A4: Bunce | B4: CT | C4: =SUM('1st Qtr'!C4, '2nd Qtr'!C4, '3rd Qtr'!C4, '4th Qtr'!C4) -> 85317.75 | D4: =SUM('1st Qtr'!D4, '2nd Qtr'!D4, '3rd Qtr'!D4, '4th Qtr'!D4) -> 134339.2 | E4: =C4-D4 -> -49021.45 | F4: =IFERROR(E4/D4, 0) -> -0.36490801 | G4: =SUM('1st Qtr'!G4, '2nd Qtr'!G4, '3rd Qtr'!G4, '4th Qtr'!G4) -> 0 | H4: =C4-G4 -> 85317.75 | I4: =IFERROR(H4/G4, 0) -> 0
A5: Norcap North | B5: CT | C5: =SUM('1st Qtr'!C5, '2nd Qtr'!C5, '3rd Qtr'!C5, '4th Qtr'!C5) -> 86946 | D5: =SUM('1st Qtr'!D5, '2nd Qtr'!D5, '3rd Qtr'!D5, '4th Qtr'!D5) -> 190151.4 | E5: =C5-D5 -> -103205.4 | F5: =IFERROR(E5/D5, 0) -> -0.54275383 | G5: =SUM('1st Qtr'!G5, '2nd Qtr'!G5, '3rd Qtr'!G5, '4th Qtr'!G5) -> 179846.6 | H5: =C5-G5 -> -92900.6 | I5: =IFERROR(H5/G5, 0) -> -0.51655466
A6: Norcap South | B6: CT | C6: =SUM('1st Qtr'!C6, '2nd Qtr'!C6, '3rd Qtr'!C6, '4th Qtr'!C6) -> 92879.5 | D6: =SUM('1st Qtr'!D6, '2nd Qtr'!D6, '3rd Qtr'!D6, '4th Qtr'!D6) -> 212284 | E6: =C6-D6 -> -119404.5 | F6: =IFERROR(E6/D6, 0) -> -0.56247527 | G6: =SUM('1st Qtr'!G6, '2nd Qtr'!G6, '3rd Qtr'!G6, '4th Qtr'!G6) -> 156565.5 | H6: =C6-G6 -> -63686 | I6: =IFERROR(H6/G6, 0) -> -0.40676905
A7: Platt Hill | B7: CT | C7: =SUM('1st Qtr'!C7, '2nd Qtr'!C7, '3rd Qtr'!C7, '4th Qtr'!C7) -> 104226.49 | D7: =SUM('1st Qtr'!D7, '2nd Qtr'!D7, '3rd Qtr'!D7, '4th Qtr'!D7) -> 164040.9 | E7: =C7-D7 -> -59814.406 | F7: =IFERROR(E7/D7, 0) -> -0.36463105 | G7: =SUM('1st Qtr'!G7, '2nd Qtr'!G7, '3rd Qtr'!G7, '4th Qtr'!G7) -> 232504.1 | H7: =C7-G7 -> -128277.61 | I7: =IFERROR(H7/G7, 0) -> -0.55172191
A8: Powder Hill | B8: CT | C8: =SUM('1st Qtr'!C8, '2nd Qtr'!C8, '3rd Qtr'!C8, '4th Qtr'!C8) -> 73609 | D8: =SUM('1st Qtr'!D8, '2nd Qtr'!D8, '3rd Qtr'!D8, '4th Qtr'!D8) -> 144364.9 | E8: =C8-D8 -> -70755.9 | F8: =IFERROR(E8/D8, 0) -> -0.49011844 | G8: =SUM('1st Qtr'!G8, '2nd Qtr'!G8, '3rd Qtr'!G8, '4th Qtr'!G8) -> 155676 | H8: =C8-G8 -> -82067 | I8: =IFERROR(H8/G8, 0) -> -0.52716539
A9: Sand Road | B9: CT | C9: =SUM('1st Qtr'!C9, '2nd Qtr'!C9, '3rd Qtr'!C9, '4th Qtr'!C9) -> 78068.5 | D9: =SUM('1st Qtr'!D9, '2nd Qtr'!D9, '3rd Qtr'!D9, '4th Qtr'!D9) -> 124790 | E9: =C9-D9 -> -46721.5 | F9: =IFERROR(E9/D9, 0) -> -0.37440099 | G9: =SUM('1st Qtr'!G9, '2nd Qtr'!G9, '3rd Qtr'!G9, '4th Qtr'!G9) -> 145302 | H9: =C9-G9 -> -67233.5 | I9: =IFERROR(H9/G9, 0) -> -0.46271559
A10: Suffield | B10: CT | C10: =SUM('1st Qtr'!C10, '2nd Qtr'!C10, '3rd Qtr'!C10, '4th Qtr'!C10) -> 86425 | D10: =SUM('1st Qtr'!D10, '2nd Qtr'!D10, '3rd Qtr'!D10, '4th Qtr'!D10) -> 139100 | E10: =C10-D10 -> -52675 | F10: =IFERROR(E10/D10, 0) -> -0.3786844 | G10: =SUM('1st Qtr'!G10, '2nd Qtr'!G10, '3rd Qtr'!G10, '4th Qtr'!G10) -> 191955.4 | H10: =C10-G10 -> -105530.4 | I10: =IFERROR(H10/G10, 0) -> -0.54976521
A11: Ashby-Duffy | B11: MA | C11: =SUM('1st Qtr'!C11, '2nd Qtr'!C11, '3rd Qtr'!C11, '4th Qtr'!C11) -> 83884 | D11: =SUM('1st Qtr'!D11, '2nd Qtr'!D11, '3rd Qtr'!D11, '4th Qtr'!D11) -> 228874 | E11: =C11-D11 -> -144990 | F11: =IFERROR(E11/D11, 0) -> -0.63349266 | G11: =SUM('1st Qtr'!G11, '2nd Qtr'!G11, '3rd Qtr'!G11, '4th Qtr'!G11) -> 158269.5 | H11: =C11-G11 -> -74385.5 | I11: =IFERROR(H11/G11, 0) -> -0.46999264
A12: Ashland | B12: MA | C12: =SUM('1st Qtr'!C12, '2nd Qtr'!C12, '3rd Qtr'!C12, '4th Qtr'!C12) -> 3053 | D12: =SUM('1st Qtr'!D12, '2nd Qtr'!D12, '3rd Qtr'!D12, '4th Qtr'!D12) -> 18082.05 | E12: =C12-D12 -> -15029.05 | F12: =IFERROR(E12/D12, 0) -> -0.83115852 | G12: =SUM('1st Qtr'!G12, '2nd Qtr'!G12, '3rd Qtr'!G12, '4th Qtr'!G12) -> 134293.1 | H12: =C12-G12 -> -131240.1 | I12: =IFERROR(H12/G12, 0) -> -0.97726614
A13: Barrington | B13: MA | C13: =SUM('1st Qtr'!C13, '2nd Qtr'!C13, '3rd Qtr'!C13, '4th Qtr'!C13) -> 15412 | D13: =SUM('1st Qtr'!D13, '2nd Qtr'!D13, '3rd Qtr'!D13, '4th Qtr'!D13) -> 23642.96 | E13: =C13-D13 -> -8230.96 | F13: =IFERROR(E13/D13, 0) -> -0.34813577 | G13: =SUM('1st Qtr'!G13, '2nd Qtr'!G13, '3rd Qtr'!G13, '4th Qtr'!G13) -> 35820 | H13: =C13-G13 -> -20408 | I13: =IFERROR(H13/G13, 0) -> -0.56973758
A14: Bedford - 205 Burlington Rd | B14: MA | C14: =SUM('1st Qtr'!C14, '2nd Qtr'!C14, '3rd Qtr'!C14, '4th Qtr'!C14) -> 7938 | D14: =SUM('1st Qtr'!D14, '2nd Qtr'!D14, '3rd Qtr'!D14, '4th Qtr'!D14) -> 0 | E14: =C14-D14 -> 7938 | F14: =IFERROR(E14/D14, 0) -> 0 | G14: =SUM('1st Qtr'!G14, '2nd Qtr'!G14, '3rd Qtr'!G14, '4th Qtr'!G14) -> 0 | H14: =C14-G14 -> 7938 | I14: =IFERROR(H14/G14, 0) -> 0
A15: Billerica - 6 Cook Street | B15: MA | C15: =SUM('1st Qtr'!C15, '2nd Qtr'!C15, '3rd Qtr'!C15, '4th Qtr'!C15) -> 7069 | D15: =SUM('1st Qtr'!D15, '2nd Qtr'!D15, '3rd Qtr'!D15, '4th Qtr'!D15) -> 0 | E15: =C15-D15 -> 7069 | F15: =IFERROR(E15/D15, 0) -> 0 | G15: =SUM('1st Qtr'!G15, '2nd Qtr'!G15, '3rd Qtr'!G15, '4th Qtr'!G15) -> 0 | H15: =C15-G15 -> 7069 | I15: =IFERROR(H15/G15, 0) -> 0
... A27: Smith Creek | B27: NY | C27: =SUM('1st Qtr'!C27, '2nd Qtr'!C27, '3rd Qtr'!C27, '4th Qtr'!C27) -> 140087 | D27: =SUM('1st Qtr'!D27, '2nd Qtr'!D27, '3rd Qtr'!D27, '4th Qtr'!D27) -> 237488.5 | E27: =C27-D27 -> -97401.5 | F27: =IFERROR(E27/D27, 0) -> -0.41013144 | G27: =SUM('1st Qtr'!G27, '2nd Qtr'!G27, '3rd Qtr'!G27, '4th Qtr'!G27) -> 400605.5 | H27: =C27-G27 -> -260518.5 | I27: =IFERROR(H27/G27, 0) -> -0.65031184
A28: Total | C28: =SUM(C3:C27) -> 1646953.4 | D28: =SUM(D3:D27) -> 2934622.4 | E28: =C28-D28 -> -1287669 | F28: =IFERROR(E28/D28, 0) -> -0.43878523 | G28: =SUM(G3:G27) -> 3459095.5 | H28: =C28-G28 -> -1812142.1 | I28: =IFERROR(H28/G28, 0) -> -0.52387743
A30: Values in gold exceed expected or forecasted by 10% or more.
A32: Values in red are below expected or forecasted by 10% or more.

Sheet 1st Qtr
A1: {=portfolio} -> Lodestar | C1: 1st Quarter 2024 Actual v. Expected | G1: 1st Quarter 2024 Forecasted
A2: Site | B2: State | C2: Actual | D2: Expected | E2: Delta | F2: % | G2: Forecasted | H2: Delta | I2: %
A3: {=Sites[Site]} -> Barkhamsted | B3: {=Sites[State]} -> CT | C3: =SUM(Jan!C3, Feb!C3, Mar!C3) -> 40962 | D3: =SUM(Jan!D3, Feb!D3, Mar!D3) -> 81116.11 | E3: =C3-D3 -> -40154.11 | F3: =IFERROR(E3/D3, 0) -> -0.49502016 | G3: =SUM(Jan!G3, Feb!G3, Mar!G3) -> 95666.17 | H3: =C3-G3 -> -54704.17 | I3: =IFERROR(H3/G3, 0) -> -0.57182356
A4: Bunce | B4: CT | C4: =SUM(Jan!C4, Feb!C4, Mar!C4) -> 85317.75 | D4: =SUM(Jan!D4, Feb!D4, Mar!D4) -> 134339.2 | E4: =C4-D4 -> -49021.45 | F4: =IFERROR(E4/D4, 0) -> -0.36490801 | G4: =SUM(Jan!G4, Feb!G4, Mar!G4) -> 0 | H4: =C4-G4 -> 85317.75 | I4: =IFERROR(H4/G4, 0) -> 0
A5: Norcap North | B5: CT | C5: =SUM(Jan!C5, Feb!C5, Mar!C5) -> 86946 | D5: =SUM(Jan!D5, Feb!D5, Mar!D5) -> 190151.4 | E5: =C5-D5 -> -103205.4 | F5: =IFERROR(E5/D5, 0) -> -0.54275383 | G5: =SUM(Jan!G5, Feb!G5, Mar!G5) -> 179846.6 | H5: =C5-G5 -> -92900.6 | I5: =IFERROR(H5/G5, 0) -> -0.51655466
A6: Norcap South | B6: CT | C6: =SUM(Jan!C6, Feb!C6, Mar!C6) -> 92879.5 | D6: =SUM(Jan!D6, Feb!D6, Mar!D6) -> 212284 | E6: =C6-D6 -> -119404.5 | F6: =IFERROR(E6/D6, 0) -> -0.56247527 | G6: =SUM(Jan!G6, Feb!G6, Mar!G6) -> 156565.5 | H6: =C6-G6 -> -63686 | I6: =IFERROR(H6/G6, 0) -> -0.40676905
A7: Platt Hill | B7: CT | C7: =SUM(Jan!C7, Feb!C7, Mar!C7) -> 104226.49 | D7: =SUM(Jan!D7, Feb!D7, Mar!D7) -> 164040.9 | E7: =C7-D7 -> -59814.406 | F7: =IFERROR(E7/D7, 0) -> -0.36463105 | G7: =SUM(Jan!G7, Feb!G7, Mar!G7) -> 232504.1 | H7: =C7-G7 -> -128277.61 | I7: =IFERROR(H7/G7, 0) -> -0.55172191
A8: Powder Hill | B8: CT | C8: =SUM(Jan!C8, Feb!C8, Mar!C8) -> 73609 | D8: =SUM(Jan!D8, Feb!D8, Mar!D8) -> 144364.9 | E8: =C8-D8 -> -70755.9 | F8: =IFERROR(E8/D8, 0) -> -0.49011844 | G8: =SUM(Jan!G8, Feb!G8, Mar!G8) -> 155676 | H8: =C8-G8 -> -82067 | I8: =IFERROR(H8/G8, 0) -> -0.52716539
A9: Sand Road | B9: CT | C9: =SUM(Jan!C9, Feb!C9, Mar!C9) -> 78068.5 | D9: =SUM(Jan!D9, Feb!D9, Mar!D9) -> 124790 | E9: =C9-D9 -> -46721.5 | F9: =IFERROR(E9/D9, 0) -> -0.37440099 | G9: =SUM(Jan!G9, Feb!G9, Mar!G9) -> 145302 | H9: =C9-G9 -> -67233.5 | I9: =IFERROR(H9/G9, 0) -> -0.46271559
A10: Suffield | B10: CT | C10: =SUM(Jan!C10, Feb!C10, Mar!C10) -> 86425 | D10: =SUM(Jan!D10, Feb!D10, Mar!D10) -> 139100 | E10: =C10-D10 -> -52675 | F10: =IFERROR(E10/D10, 0) -> -0.3786844 | G10: =SUM(Jan!G10, Feb!G10, Mar!G10) -> 191955.4 | H10: =C10-G10 -> -105530.4 | I10: =IFERROR(H10/G10, 0) -> -0.54976521
A11: Ashby-Duffy | B11: MA | C11: =SUM(Jan!C11, Feb!C11, Mar!C11) -> 83884 | D11: =SUM(Jan!D11, Feb!D11, Mar!D11) -> 228874 | E11: =C11-D11 -> -144990 | F11: =IFERROR(E11/D11, 0) -> -0.63349266 | G11: =SUM(Jan!G11, Feb!G11, Mar!G11) -> 158269.5 | H11: =C11-G11 -> -74385.5 | I11: =IFERROR(H11/G11, 0) -> -0.46999264
A12: Ashland | B12: MA | C12: =SUM(Jan!C12, Feb!C12, Mar!C12) -> 3053 | D12: =SUM(Jan!D12, Feb!D12, Mar!D12) -> 18082.05 | E12: =C12-D12 -> -15029.05 | F12: =IFERROR(E12/D12, 0) -> -0.83115852 | G12: =SUM(Jan!G12, Feb!G12, Mar!G12) -> 134293.1 | H12: =C12-G12 -> -131240.1 | I12: =IFERROR(H12/G12, 0) -> -0.97726614
A13: Barrington | B13: MA | C13: =SUM(Jan!C13, Feb!C13, Mar!C13) -> 15412 | D13: =SUM(Jan!D13, Feb!D13, Mar!D13) -> 23642.96 | E13: =C13-D13 -> -8230.96 | F13: =IFERROR(E13/D13, 0) -> -0.34813577 | G13: =SUM(Jan!G13, Feb!G13, Mar!G13) -> 35820 | H13: =C13-G13 -> -20408 | I13: =IFERROR(H13/G13, 0) -> -0.56973758
A14: Bedford - 205 Burlington Rd | B14: MA | C14: =SUM(Jan!C14, Feb!C14, Mar!C14) -> 7938 | D14: =SUM(Jan!D14, Feb!D14, Mar!D14) -> 0 | E14: =C14-D14 -> 7938 | F14: =IFERROR(E14/D14, 0) -> 0 | G14: =SUM(Jan!G14, Feb!G14, Mar!G14) -> 0 | H14: =C14-G14 -> 7938 | I14: =IFERROR(H14/G14, 0) -> 0
A15: Billerica - 6 Cook Street | B15: MA | C15: =SUM(Jan!C15, Feb!C15, Mar!C15) -> 7069 | D15: =SUM(Jan!D15, Feb!D15, Mar!D15) -> 0 | E15: =C15-D15 -> 7069 | F15: =IFERROR(E15/D15, 0) -> 0 | G15: =SUM(Jan!G15, Feb!G15, Mar!G15) -> 0 | H15: =C15-G15 -> 7069 | I15: =IFERROR(H15/G15, 0) -> 0
... A27: Smith Creek | B27: NY | C27: =SUM(Jan!C27, Feb!C27, Mar!C27) -> 140087 | D27: =SUM(Jan!D27, Feb!D27, Mar!D27) -> 237488.5 | E27: =C27-D27 -> -97401.5 | F27: =IFERROR(E27/D27, 0) -> -0.41013144 | G27: =SUM(Jan!G27, Feb!G27, Mar!G27) -> 400605.5 | H27: =C27-G27 -> -260518.5 | I27: =IFERROR(H27/G27, 0) -> -0.65031184
A28: Total | C28: =SUM(C3:C27) -> 1646953.4 | D28: =SUM(D3:D27) -> 2934622.4 | E28: =C28-D28 -> -1287669 | F28: =IFERROR(E28/D28, 0) -> -0.43878523 | G28: =SUM(G3:G27) -> 3459095.5 | H28: =C28-G28 -> -1812142.1 | I28: =IFERROR(H28/G28, 0) -> -0.52387743
A30: Values in gold exceed expected or forecasted by 10% or more.
A32: Values in red are below expected or forecasted by 10% or more.

Sheet 2nd Qtr
A1: {=portfolio} -> Lodestar | C1: 2nd Quarter 2024 Actual v. Expected | G1: 2nd Quarter 2024 Forecasted
A2: Site | B2: State | C2: Actual | D2: Expected | E2: Delta | F2: % | G2: Forecasted | H2: Delta | I2: %
A3: {=Sites[Site]} -> Barkhamsted | B3: {=Sites[State]} -> CT | C3: =SUM(Apr!C3, May!C3, Jun!C3) -> 0 | D3: =SUM(Apr!D3, May!D3, Jun!D3) -> 0 | E3: =C3-D3 -> 0 | F3: =IFERROR(E3/D3, 0) -> 0 | G3: =SUM(Apr!G3, May!G3, Jun!G3) -> 0 | H3: =C3-G3 -> 0 | I3: =IFERROR(H3/G3, 0) -> 0
A4: Bunce | B4: CT | C4: =SUM(Apr!C4, May!C4, Jun!C4) -> 0 | D4: =SUM(Apr!D4, May!D4, Jun!D4) -> 0 | E4: =C4-D4 -> 0 | F4: =IFERROR(E4/D4, 0) -> 0 | G4: =SUM(Apr!G4, May!G4, Jun!G4) -> 0 | H4: =C4-G4 -> 0 | I4: =IFERROR(H4/G4, 0) -> 0
A5: Norcap North | B5: CT | C5: =SUM(Apr!C5, May!C5, Jun!C5) -> 0 | D5: =SUM(Apr!D5, May!D5, Jun!D5) -> 0 | E5: =C5-D5 -> 0 | F5: =IFERROR(E5/D5, 0) -> 0 | G5: =SUM(Apr!G5, May!G5, Jun!G5) -> 0 | H5: =C5-G5 -> 0 | I5: =IFERROR(H5/G5, 0) -> 0
A6: Norcap South | B6: CT | C6: =SUM(Apr!C6, May!C6, Jun!C6) -> 0 | D6: =SUM(Apr!D6, May!D6, Jun!D6) -> 0 | E6: =C6-D6 -> 0 | F6: =IFERROR(E6/D6, 0) -> 0 | G6: =SUM(Apr!G6, May!G6, Jun!G6) -> 0 | H6: =C6-G6 -> 0 | I6: =IFERROR(H6/G6, 0) -> 0
A7: Platt Hill | B7: CT | C7: =SUM(Apr!C7, May!C7, Jun!C7) -> 0 | D7: =SUM(Apr!D7, May!D7, Jun!D7) -> 0 | E7: =C7-D7 -> 0 | F7: =IFERROR(E7/D7, 0) -> 0 | G7: =SUM(Apr!G7, May!G7, Jun!G7) -> 0 | H7: =C7-G7 -> 0 | I7: =IFERROR(H7/G7, 0) -> 0
A8: Powder Hill | B8: CT | C8: =SUM(Apr!C8, May!C8, Jun!C8) -> 0 | D8: =SUM(Apr!D8, May!D8, Jun!D8) -> 0 | E8: =C8-D8 -> 0 | F8: =IFERROR(E8/D8, 0) -> 0 | G8: =SUM(Apr!G8, May!G8, Jun!G8) -> 0 | H8: =C8-G8 -> 0 | I8: =IFERROR(H8/G8, 0) -> 0
A9: Sand Road | B9: CT | C9: =SUM(Apr!C9, May!C9, Jun!C9) -> 0 | D9: =SUM(Apr!D9, May!D9, Jun!D9) -> 0 | E9: =C9-D9 -> 0 | F9: =IFERROR(E9/D9, 0) -> 0 | G9: =SUM(Apr!G9, May!G9, Jun!G9) -> 0 | H9: =C9-G9 -> 0 | I9: =IFERROR(H9/G9, 0) -> 0
A10: Suffield | B10: CT | C10: =SUM(Apr!C10, May!C10, Jun!C10) -> 0 | D10: =SUM(Apr!D10, May!D10, Jun!D10) -> 0 | E10: =C10-D10 -> 0 | F10: =IFERROR(E10/D10, 0) -> 0 | G10: =SUM(Apr!G10, May!G10, Jun!G10) -> 0 | H10: =C10-G10 -> 0 | I10: =IFERROR(H10/G10, 0) -> 0
A11: Ashby-Duffy | B11: MA | C11: =SUM(Apr!C11, May!C11, Jun!C11) -> 0 | D11: =SUM(Apr!D11, May!D11, Jun!D11) -> 0 | E11: =C11-D11 -> 0 | F11: =IFERROR(E11/D11, 0) -> 0 | G11: =SUM(Apr!G11, May!G11, Jun!G11) -> 0 | H11: =C11-G11 -> 0 | I11: =IFERROR(H11/G11, 0) -> 0
A12: Ashland | B12: MA | C12: =SUM(Apr!C12, May!C12, Jun!C12) -> 0 | D12: =SUM(Apr!D12, May!D12, Jun!D12) -> 0 | E12: =C12-D12 -> 0 | F12: =IFERROR(E12/D12, 0) -> 0 | G12: =SUM(Apr!G12, May!G12, Jun!G12) -> 0 | H12: =C12-G12 -> 0 | I12: =IFERROR(H12/G12, 0) -> 0
A13: Barrington | B13: MA | C13: =SUM(Apr!C13, May!C13, Jun!C13) -> 0 | D13: =SUM(Apr!D13, May!D13, Jun!D13) -> 0 | E13: =C13-D13 -> 0 | F13: =IFERROR(E13/D13, 0) -> 0 | G13: =SUM(Apr!G13, May!G13, Jun!G13) -> 0 | H13: =C13-G13 -> 0 | I13: =IFERROR(H13/G13, 0) -> 0
A14: Bedford - 205 Burlington Rd | B14: MA | C14: =SUM(Apr!C14, May!C14, Jun!C14) -> 0 | D14: =SUM(Apr!D14, May!D14, Jun!D14) -> 0 | E14: =C14-D14 -> 0 | F14: =IFERROR(E14/D14, 0) -> 0 | G14: =SUM(Apr!G14, May!G14, Jun!G14) -> 0 | H14: =C14-G14 -> 0 | I14: =IFERROR(H14/G14, 0) -> 0
A15: Billerica - 6 Cook Street | B15: MA | C15: =SUM(Apr!C15, May!C15, Jun!C15) -> 0 | D15: =SUM(Apr!D15, May!D15, Jun!D15) -> 0 | E15: =C15-D15 -> 0 | F15: =IFERROR(E15/D15, 0) -> 0 | G15: =SUM(Apr!G15, May!G15, Jun!G15) -> 0 | H15: =C15-G15 -> 0 | I15: =IFERROR(H15/G15, 0) -> 0
... A27: Smith Creek | B27: NY | C27: =SUM(Apr!C27, May!C27, Jun!C27) -> 0 | D27: =SUM(Apr!D27, May!D27, Jun!D27) -> 0 | E27: =C27-D27 -> 0 | F27: =IFERROR(E27/D27, 0) -> 0 | G27: =SUM(Apr!G27, May!G27, Jun!G27) -> 0 | H27: =C27-G27 -> 0 | I27: =IFERROR(H27/G27, 0) -> 0
A28: Total | C28: =SUM(C3:C27) -> 0 | D28: =SUM(D3:D27) -> 0 | E28: =C28-D28 -> 0 | F28: =IFERROR(E28/D28, 0) -> 0 | G28: =SUM(G3:G27) -> 0 | H28: =C28-G28 -> 0 | I28: =IFERROR(H28/G28, 0) -> 0
A30: Values in gold exceed expected or forecasted by 10% or more.
A32: Values in red are below expected or forecasted by 10% or more.

Sheet 3rd Qtr
A1: {=portfolio} -> Lodestar | C1: 3rd Quarter 2024 Actual v. Expected | G1: 3rd Quarter 2024 Forecasted
A2: Site | B2: State | C2: Actual | D2: Expected | E2: Delta | F2: % | G2: Forecasted | H2: Delta | I2: %
A3: {=Sites[Site]} -> Barkhamsted | B3: {=Sites[State]} -> CT | C3: =SUM(Jul!C3, Aug!C3, Sep!C3) -> 0 | D3: =SUM(Jul!D3, Aug!D3, Sep!D3) -> 0 | E3: =C3-D3 -> 0 | F3: =IFERROR(E3/D3, 0) -> 0 | G3: =SUM(Jul!G3, Aug!G3, Sep!G3) -> 0 | H3: =C3-G3 -> 0 | I3: =IFERROR(H3/G3, 0) -> 0
A4: Bunce | B4: CT | C4: =SUM(Jul!C4, Aug!C4, Sep!C4) -> 0 | D4: =SUM(Jul!D4, Aug!D4, Sep!D4) -> 0 | E4: =C4-D4 -> 0 | F4: =IFERROR(E4/D4, 0) -> 0 | G4: =SUM(Jul!G4, Aug!G4, Sep!G4) -> 0 | H4: =C4-G4 -> 0 | I4: =IFERROR(H4/G4, 0) -> 0
A5: Norcap North | B5: CT | C5: =SUM(Jul!C5, Aug!C5, Sep!C5) -> 0 | D5: =SUM(Jul!D5, Aug!D5, Sep!D5) -> 0 | E5: =C5-D5 -> 0 | F5: =IFERROR(E5/D5, 0) -> 0 | G5: =SUM(Jul!G5, Aug!G5, Sep!G5) -> 0 | H5: =C5-G5 -> 0 | I5: =IFERROR(H5/G5, 0) -> 0
A6: Norcap South | B6: CT | C6: =SUM(Jul!C6, Aug!C6, Sep!C6) -> 0 | D6: =SUM(Jul!D6, Aug!D6, Sep!D6) -> 0 | E6: =C6-D6 -> 0 | F6: =IFERROR(E6/D6, 0) -> 0 | G6: =SUM(Jul!G6, Aug!G6, Sep!G6) -> 0 | H6: =C6-G6 -> 0 | I6: =IFERROR(H6/G6, 0) -> 0
A7: Platt Hill | B7: CT | C7: =SUM(Jul!C7, Aug!C7, Sep!C7) -> 0 | D7: =SUM(Jul!D7, Aug!D7, Sep!D7) -> 0 | E7: =C7-D7 -> 0 | F7: =IFERROR(E7/D7, 0) -> 0 | G7: =SUM(Jul!G7, Aug!G7, Sep!G7) -> 0 | H7: =C7-G7 -> 0 | I7: =IFERROR(H7/G7, 0) -> 0
A8: Powder Hill | B8: CT | C8: =SUM(Jul!C8, Aug!C8, Sep!C8) -> 0 | D8: =SUM(Jul!D8, Aug!D8, Sep!D8) -> 0 | E8: =C8-D8 -> 0 | F8: =IFERROR(E8/D8, 0) -> 0 | G8: =SUM(Jul!G8, Aug!G8, Sep!G8) -> 0 | H8: =C8-G8 -> 0 | I8: =IFERROR(H8/G8, 0) -> 0
A9: Sand Road | B9: CT | C9: =SUM(Jul!C9, Aug!C9, Sep!C9) -> 0 | D9: =SUM(Jul!D9, Aug!D9, Sep!D9) -> 0 | E9: =C9-D9 -> 0 | F9: =IFERROR(E9/D9, 0) -> 0 | G9: =SUM(Jul!G9, Aug!G9, Sep!G9) -> 0 | H9: =C9-G9 -> 0 | I9: =IFERROR(H9/G9, 0) -> 0
A10: Suffield | B10: CT | C10: =SUM(Jul!C10, Aug!C10, Sep!C10) -> 0 | D10: =SUM(Jul!D10, Aug!D10, Sep!D10) -> 0 | E10: =C10-D10 -> 0 | F10: =IFERROR(E10/D10, 0) -> 0 | G10: =SUM(Jul!G10, Aug!G10, Sep!G10) -> 0 | H10: =C10-G10 -> 0 | I10: =IFERROR(H10/G10, 0) -> 0
A11: Ashby-Duffy | B11: MA | C11: =SUM(Jul!C11, Aug!C11, Sep!C11) -> 0 | D11: =SUM(Jul!D11, Aug!D11, Sep!D11) -> 0 | E11: =C11-D11 -> 0 | F11: =IFERROR(E11/D11, 0) -> 0 | G11: =SUM(Jul!G11, Aug!G11, Sep!G11) -> 0 | H11: =C11-G11 -> 0 | I11: =IFERROR(H11/G11, 0) -> 0
A12: Ashland | B12: MA | C12: =SUM(Jul!C12, Aug!C12, Sep!C12) -> 0 | D12: =SUM(Jul!D12, Aug!D12, Sep!D12) -> 0 | E12: =C12-D12 -> 0 | F12: =IFERROR(E12/D12, 0) -> 0 | G12: =SUM(Jul!G12, Aug!G12, Sep!G12) -> 0 | H12: =C12-G12 -> 0 | I12: =IFERROR(H12/G12, 0) -> 0
A13: Barrington | B13: MA | C13: =SUM(Jul!C13, Aug!C13, Sep!C13) -> 0 | D13: =SUM(Jul!D13, Aug!D13, Sep!D13) -> 0 | E13: =C13-D13 -> 0 | F13: =IFERROR(E13/D13, 0) -> 0 | G13: =SUM(Jul!G13, Aug!G13, Sep!G13) -> 0 | H13: =C13-G13 -> 0 | I13: =IFERROR(H13/G13, 0) -> 0
A14: Bedford - 205 Burlington Rd | B14: MA | C14: =SUM(Jul!C14, Aug!C14, Sep!C14) -> 0 | D14: =SUM(Jul!D14, Aug!D14, Sep!D14) -> 0 | E14: =C14-D14 -> 0 | F14: =IFERROR(E14/D14, 0) -> 0 | G14: =SUM(Jul!G14, Aug!G14, Sep!G14) -> 0 | H14: =C14-G14 -> 0 | I14: =IFERROR(H14/G14, 0) -> 0
A15: Billerica - 6 Cook Street | B15: MA | C15: =SUM(Jul!C15, Aug!C15, Sep!C15) -> 0 | D15: =SUM(Jul!D15, Aug!D15, Sep!D15) -> 0 | E15: =C15-D15 -> 0 | F15: =IFERROR(E15/D15, 0) -> 0 | G15: =SUM(Jul!G15, Aug!G15, Sep!G15) -> 0 | H15: =C15-G15 -> 0 | I15: =IFERROR(H15/G15, 0) -> 0
... A27: Smith Creek | B27: NY | C27: =SUM(Jul!C27, Aug!C27, Sep!C27) -> 0 | D27: =SUM(Jul!D27, Aug!D27, Sep!D27) -> 0 | E27: =C27-D27 -> 0 | F27: =IFERROR(E27/D27, 0) -> 0 | G27: =SUM(Jul!G27, Aug!G27, Sep!G27) -> 0 | H27: =C27-G27 -> 0 | I27: =IFERROR(H27/G27, 0) -> 0
A28: Total | C28: =SUM(C3:C27) -> 0 | D28: =SUM(D3:D27) -> 0 | E28: =C28-D28 -> 0 | F28: =IFERROR(E28/D28, 0) -> 0 | G28: =SUM(G3:G27) -> 0 | H28: =C28-G28 -> 0 | I28: =IFERROR(H28/G28, 0) -> 0
A30: Values in gold exceed expected or forecasted by 10% or more.
A32: Values in red are below expected or forecasted by 10% or more.

Sheet 4th Qtr
A1: {=portfolio} -> Lodestar | C1: 4th Quarter 2024 Actual v. Expected | G1: 4th Quarter 2024 Forecasted
A2: Site | B2: State | C2: Actual | D2: Expected | E2: Delta | F2: % | G2: Forecasted | H2: Delta | I2: %
A3: {=Sites[Site]} -> Barkhamsted | B3: {=Sites[State]} -> CT | C3: =SUM(Oct!C3, Nov!C3, Dec!C3) -> 0 | D3: =SUM(Oct!D3, Nov!D3, Dec!D3) -> 0 | E3: =C3-D3 -> 0 | F3: =IFERROR(E3/D3, 0) -> 0 | G3: =SUM(Oct!G3, Nov!G3, Dec!G3) -> 0 | H3: =C3-G3 -> 0 | I3: =IFERROR(H3/G3, 0) -> 0
A4: Bunce | B4: CT | C4: =SUM(Oct!C4, Nov!C4, Dec!C4) -> 0 | D4: =SUM(Oct!D4, Nov!D4, Dec!D4) -> 0 | E4: =C4-D4 -> 0 | F4: =IFERROR(E4/D4, 0) -> 0 | G4: =SUM(Oct!G4, Nov!G4, Dec!G4) -> 0 | H4: =C4-G4 -> 0 | I4: =IFERROR(H4/G4, 0) -> 0
A5: Norcap North | B5: CT | C5: =SUM(Oct!C5, Nov!C5, Dec!C5) -> 0 | D5: =SUM(Oct!D5, Nov!D5, Dec!D5) -> 0 | E5: =C5-D5 -> 0 | F5: =IFERROR(E5/D5, 0) -> 0 | G5: =SUM(Oct!G5, Nov!G5, Dec!G5) -> 0 | H5: =C5-G5 -> 0 | I5: =IFERROR(H5/G5, 0) -> 0
A6: Norcap South | B6: CT | C6: =SUM(Oct!C6, Nov!C6, Dec!C6) -> 0 | D6: =SUM(Oct!D6, Nov!D6, Dec!D6) -> 0 | E6: =C6-D6 -> 0 | F6: =IFERROR(E6/D6, 0) -> 0 | G6: =SUM(Oct!G6, Nov!G6, Dec!G6) -> 0 | H6: =C6-G6 -> 0 | I6: =IFERROR(H6/G6, 0) -> 0
A7: Platt Hill | B7: CT | C7: =SUM(Oct!C7, Nov!C7, Dec!C7) -> 0 | D7: =SUM(Oct!D7, Nov!D7, Dec!D7) -> 0 | E7: =C7-D7 -> 0 | F7: =IFERROR(E7/D7, 0) -> 0 | G7: =SUM(Oct!G7, Nov!G7, Dec!G7) -> 0 | H7: =C7-G7 -> 0 | I7: =IFERROR(H7/G7, 0) -> 0
A8: Powder Hill | B8: CT | C8: =SUM(Oct!C8, Nov!C8, Dec!C8) -> 0 | D8: =SUM(Oct!D8, Nov!D8, Dec!D8) -> 0 | E8: =C8-D8 -> 0 | F8: =IFERROR(E8/D8, 0) -> 0 | G8: =SUM(Oct!G8, Nov!G8, Dec!G8) -> 0 | H8: =C8-G8 -> 0 | I8: =IFERROR(H8/G8, 0) -> 0
A9: Sand Road | B9: CT | C9: =SUM(Oct!C9, Nov!C9, Dec!C9) -> 0 | D9: =SUM(Oct!D9, Nov!D9, Dec!D9) -> 0 | E9: =C9-D9 -> 0 | F9: =IFERROR(E9/D9, 0) -> 0 | G9: =SUM(Oct!G9, Nov!G9, Dec!G9) -> 0 | H9: =C9-G9 -> 0 | I9: =IFERROR(H9/G9, 0) -> 0
A10: Suffield | B10: CT | C10: =SUM(Oct!C10, Nov!C10, Dec!C10) -> 0 | D10: =SUM(Oct!D10, Nov!D10, Dec!D10) -> 0 | E10: =C10-D10 -> 0 | F10: =IFERROR(E10/D10, 0) -> 0 | G10: =SUM(Oct!G10, Nov!G10, Dec!G10) -> 0 | H10: =C10-G10 -> 0 | I10: =IFERROR(H10/G10, 0) -> 0
A11: Ashby-Duffy | B11: MA | C11: =SUM(Oct!C11, Nov!C11, Dec!C11) -> 0 | D11: =SUM(Oct!D11, Nov!D11, Dec!D11) -> 0 | E11: =C11-D11 -> 0 | F11: =IFERROR(E11/D11, 0) -> 0 | G11: =SUM(Oct!G11, Nov!G11, Dec!G11) -> 0 | H11: =C11-G11 -> 0 | I11: =IFERROR(H11/G11, 0) -> 0
A12: Ashland | B12: MA | C12: =SUM(Oct!C12, Nov!C12, Dec!C12) -> 0 | D12: =SUM(Oct!D12, Nov!D12, Dec!D12) -> 0 | E12: =C12-D12 -> 0 | F12: =IFERROR(E12/D12, 0) -> 0 | G12: =SUM(Oct!G12, Nov!G12, Dec!G12) -> 0 | H12: =C12-G12 -> 0 | I12: =IFERROR(H12/G12, 0) -> 0
A13: Barrington | B13: MA | C13: =SUM(Oct!C13, Nov!C13, Dec!C13) -> 0 | D13: =SUM(Oct!D13, Nov!D13, Dec!D13) -> 0 | E13: =C13-D13 -> 0 | F13: =IFERROR(E13/D13, 0) -> 0 | G13: =SUM(Oct!G13, Nov!G13, Dec!G13) -> 0 | H13: =C13-G13 -> 0 | I13: =IFERROR(H13/G13, 0) -> 0
A14: Bedford - 205 Burlington Rd | B14: MA | C14: =SUM(Oct!C14, Nov!C14, Dec!C14) -> 0 | D14: =SUM(Oct!D14, Nov!D14, Dec!D14) -> 0 | E14: =C14-D14 -> 0 | F14: =IFERROR(E14/D14, 0) -> 0 | G14: =SUM(Oct!G14, Nov!G14, Dec!G14) -> 0 | H14: =C14-G14 -> 0 | I14: =IFERROR(H14/G14, 0) -> 0
A15: Billerica - 6 Cook Street | B15: MA | C15: =SUM(Oct!C15, Nov!C15, Dec!C15) -> 0 | D15: =SUM(Oct!D15, Nov!D15, Dec!D15) -> 0 | E15: =C15-D15 -> 0 | F15: =IFERROR(E15/D15, 0) -> 0 | G15: =SUM(Oct!G15, Nov!G15, Dec!G15) -> 0 | H15: =C15-G15 -> 0 | I15: =IFERROR(H15/G15, 0) -> 0
... A27: Smith Creek | B27: NY | C27: =SUM(Oct!C27, Nov!C27, Dec!C27) -> 0 | D27: =SUM(Oct!D27, Nov!D27, Dec!D27) -> 0 | E27: =C27-D27 -> 0 | F27: =IFERROR(E27/D27, 0) -> 0 | G27: =SUM(Oct!G27, Nov!G27, Dec!G27) -> 0 | H27: =C27-G27 -> 0 | I27: =IFERROR(H27/G27, 0) -> 0
A28: Total | C28: =SUM(C3:C27) -> 0 | D28: =SUM(D3:D27) -> 0 | E28: =C28-D28 -> 0 | F28: =IFERROR(E28/D28, 0) -> 0 | G28: =SUM(G3:G27) -> 0 | H28: =C28-G28 -> 0 | I28: =IFERROR(H28/G28, 0) -> 0
A30: Values in gold exceed expected or forecasted by 10% or more.
A32: Values in red are below expected or forecasted by 10% or more.

Sheet Jan
A1: {=portfolio} -> Lodestar | C1: January Actual v. Expected | G1: January Actual v. Forecasted | J1: NOTES | K1: SR
A2: Site | B2: State | C2: Actual | D2: Expected | E2: Delta | F2: % | G2: Forecasted | H2: Delta | I2: %
A3: {=Sites[Site]} -> Barkhamsted | B3: {=Sites[State]} -> CT | C3: {=IF(INDIRECT("'" & $A3 & "'!B5:J5")="", "", INDIRECT("'" & $A3 & "'!B5:J5"))} -> 40962 | D3: 81116.11 | E3: -40154.11 | F3: -0.49502016 | G3: 95666.17 | H3: -54704.17 | I3: -0.57182356
A4: Bunce | B4: CT | C4: {=IF(INDIRECT("'" & $A4 & "'!B5:J5")="", "", INDIRECT("'" & $A4 & "'!B5:J5"))} -> 85317.75 | D4: 134339.2 | E4: -49021.45 | F4: -0.36490801 | G4: 0 | H4: 85317.75 | I4: 0
A5: Norcap North | B5: CT | C5: {=IF(INDIRECT("'" & $A5 & "'!B5:J5")="", "", INDIRECT("'" & $A5 & "'!B5:J5"))} -> 86946 | D5: 190151.4 | E5: -103205.4 | F5: -0.54275383 | G5: 179846.6 | H5: -92900.6 | I5: -0.51655466 | J5: 1. Inverter 1 started at 14:00 on 01/05. 2. Inverter 1 offline on 01/07 and resolved on 01/10 and reporting Bus Differential High Fault - Fault 0110. 2. inverter 4 is currently offline on 01/07 and resolved on 01/09 and reporting Bus Differential High Fault - Fault 0110. 3. Inverters 1, 4 and 11 are offline on 01/13 and resolved on 01/14 due to "Bus differential high fault". 4. Inverter 11 is offline on 01/13 resolved on 01/19 due to Bus differential fault. 5. Inverter 11 is offline from 01/19 due to Bus differential fault. | K5: 1. SR079979 2. SR080049 3. SR080194 4. SR080314 5. SR080441
A6: Norcap South | B6: CT | C6: {=IF(INDIRECT("'" & $A6 & "'!B5:J5")="", "", INDIRECT("'" & $A6 & "'!B5:J5"))} -> 92879.5 | D6: 212284 | E6: -119404.5 | F6: -0.56247527 | G6: 156565.5 | H6: -63686 | I6: -0.40676905 | J6: 1.Inverters 61 to 64 have tripped offline at 11:15am on 01/01 and resolved next day 2.Inverters 61 to 64 have tripped offline at 11:15am on 01/15 and resolved next day 3.Inverter 48 was offline due to "Bus sum high" fault on 01/27 and RMA'd | K6: 1.SR079853 2.SR080230 3.SR080522
A7: Platt Hill | B7: CT | C7: {=IF(INDIRECT("'" & $A7 & "'!B5:J5")="", "", INDIRECT("'" & $A7 & "'!B5:J5"))} -> 104226.49 | D7: 164040.9 | E7: -59814.406 | F7: -0.36463105 | G7: 232504.1 | H7: -128277.61 | I7: -0.55172191
A8: Powder Hill | B8: CT | C8: {=IF(INDIRECT("'" & $A8 & "'!B5:J5")="", "", INDIRECT("'" & $A8 & "'!B5:J5"))} -> 73609 | D8: 144364.9 | E8: -70755.9 | F8: -0.49011844 | G8: 155676 | H8: -82067 | I8: -0.52716539 | J8: 1.Inverter 1 is offline and reporting "Excessive Leakage Current" from 01/01 to 01/15 2.Inverter 5 is offline and reporting "Internal hardware failure" on 01/22 and back online next day 3.Inverter 1 is offline and reporting "Excessive Leakage Current from 01/25 and still offline | K8: 1.SR078505 2.SR080384 3.SR080614
A9: Sand Road | B9: CT | C9: {=IF(INDIRECT("'" & $A9 & "'!B5:J5")="", "", INDIRECT("'" & $A9 & "'!B5:J5"))} -> 78068.5 | D9: 124790 | E9: -46721.5 | F9: -0.37440099 | G9: 145302 | H9: -67233.5 | I9: -0.46271559
A10: Suffield | B10: CT | C10: {=IF(INDIRECT("'" & $A10 & "'!B5:J5")="", "", INDIRECT("'" & $A10 & "'!B5:J5"))} -> 86425 | D10: 139100 | E10: -52675 | F10: -0.3786844 | G10: 191955.4 | H10: -105530.4 | I10: -0.54976521 | J10: 1.Site tripped offline on 01/16 at 19:15 and autoreclosed at 19:30 2. CB 1.8 on DAS, (CB 10 onsite) was offline from 01/23 to 02/01. | K10: 1.SR080271 2.SR080413
A11: Ashby-Duffy | B11: MA | C11: {=IF(INDIRECT("'" & $A11 & "'!B5:J5")="", "", INDIRECT("'" & $A11 & "'!B5:J5"))} -> 83884 | D11: 228874 | E11: -144990 | F11: -0.63349266 | G11: 158269.5 | H11: -74385.5 | I11: -0.46999264
A12: Ashland | B12: MA | C12: {=IF(INDIRECT("'" & $A12 & "'!B5:J5")="", "", INDIRECT("'" & $A12 & "'!B5:J5"))} -> 3053 | D12: 18082.05 | E12: -15029.05 | F12: -0.83115852 | G12: 134293.1 | H12: -131240.1 | I12: -0.97726614 | J12: 1.Site was tripped offline from 12/22/2023 to 01/10/2024 and again tripped offline on the same day and still offline | K12: 1.SR080143
A13: Barrington | B13: MA | C13: {=IF(INDIRECT("'" & $A13 & "'!B5:J5")="", "", INDIRECT("'" & $A13 & "'!B5:J5"))} -> 15412 | D13: 23642.96 | E13: -8230.96 | F13: -0.34813577 | G13: 35820 | H13: -20408 | I13: -0.56973758
A14: Bedford - 205 Burlington Rd | B14: MA | C14: {=IF(INDIRECT("'" & $A14 & "'!B5:J5")="", "", INDIRECT("'" & $A14 & "'!B5:J5"))} -> 7938 | D14: 0 | E14: 7938 | F14: 0 | G14: 0 | H14: 7938 | I14: 0
A15: Billerica - 6 Cook Street | B15: MA | C15: {=IF(INDIRECT("'" & $A15 & "'!B5:J5")="", "", INDIRECT("'" & $A15 & "'!B5:J5"))} -> 7069 | D15: 0 | E15: 7069 | F15: 0 | G15: 0 | H15: 7069 | I15: 0
A16: Billerica - 780 Boston Road | B16: MA | C16: {=IF(INDIRECT("'" & $A16 & "'!B5:J5")="", "", INDIRECT("'" & $A16 & "'!B5:J5"))} -> 7922 | D16: 0 | E16: 7922 | F16: 0 | G16: 0 | H16: 7922 | I16: 0
A17: Cheshire | B17: MA | C17: {=IF(INDIRECT("'" & $A17 & "'!B5:J5")="", "", INDIRECT("'" & $A17 & "'!B5:J5"))} -> 15272 | D17: 27330.66 | E17: -12058.66 | F17: -0.44121364 | G17: 24314.38 | H17: -9042.38 | I17: -0.37189433
A18: Lilly Lane | B18: MA | C18: {=IF(INDIRECT("'" & $A18 & "'!B5:J5")="", "", INDIRECT("'" & $A18 & "'!B5:J5"))} -> 37262 | D18: 61721.41 | E18: -24459.41 | F18: -0.39628729 | G18: 113135.5 | H18: -75873.5 | I18: -0.67064272
A19: Monument Valley | B19: MA | C19: {=IF(INDIRECT("'" & $A19 & "'!B5:J5")="", "", INDIRECT("'" & $A19 & "'!B5:J5"))} -> 68801 | D19: 28968.03 | E19: 39832.97 | F19: 1.3750666 | G19: 0 | H19: 68801 | I19: 0
A20: Nationwide | B20: MA | C20: {=IF(INDIRECT("'" & $A20 & "'!B5:J5")="", "", INDIRECT("'" & $A20 & "'!B5:J5"))} -> 98960 | D20: 221313.9 | E20: -122353.9 | F20: -0.55285231 | G20: 298977.6 | H20: -200017.6 | I20: -0.6690053 | J20: 1.Inverters 20,24,25 and 26 came back online on 01/25 | K20: 1.SR077715
A21: Pulpit Hill | B21: MA | C21: {=IF(INDIRECT("'" & $A21 & "'!B5:J5")="", "", INDIRECT("'" & $A21 & "'!B5:J5"))} -> 147440 | D21: 286661.3 | E21: -139221.3 | F21: -0.48566479 | G21: 356965.5 | H21: -209525.5 | I21: -0.58696289
A22: Sandwich | B22: MA | C22: {=IF(INDIRECT("'" & $A22 & "'!B5:J5")="", "", INDIRECT("'" & $A22 & "'!B5:J5"))} -> 69116 | D22: 0 | E22: 69116 | F22: 0 | G22: 0 | H22: 69116 | I22: 0 | J22: 1.Site was offline at around 6:30am and later back online at 19:15 due to planned outage 2.Site was offline from 01/12 till 01/26 due to planned outage. | K22: 1.SR080613 2.SR080117
A23: Sturbridge Barn | B23: MA | C23: {=IF(INDIRECT("'" & $A23 & "'!B5:J5")="", "", INDIRECT("'" & $A23 & "'!B5:J5"))} -> 40594 | D23: 79345.86 | E23: -38751.86 | F23: -0.48839171 | G23: 110612.6 | H23: -70018.6 | I23: -0.63300745 | J23: 1.Site has a brief outage and later auto reclosed. | K23: 1.SR080569
A24: Sturbridge Garage | B24: MA | C24: {=IF(INDIRECT("'" & $A24 & "'!B5:J5")="", "", INDIRECT("'" & $A24 & "'!B5:J5"))} -> 20528.25 | D24: 36997.33 | E24: -16469.08 | F24: -0.44514239 | G24: 55886.08 | H24: -35357.83 | I24: -0.63267687 | J24: 1.Inverter 11 tripped offline on an arc fault on 01/31 at EOD and back online next day. | K24: 1.SR080631
A25: Halsey Valley | B25: NY | C25: {=IF(INDIRECT("'" & $A25 & "'!B5:J5")="", "", INDIRECT("'" & $A25 & "'!B5:J5"))} -> 147564 | D25: 292774.6 | E25: -145210.6 | F25: -0.49598087 | G25: 384000 | H25: -236436 | I25: -0.61571875 | J25: 1. Site tripped offline at 10:05 am on 01/05 and back online at 7:00 Am on 01/06. 2. Inverter 29 started late for the production on 01/15, 01/17 and 01/20 3. Inverter was 25 tripped offline on 01/22 and back online 02/06. 4. Site has a brief outage and later self resolved on 01/29 | K25: 1.SR079976 2.SR080227 3.SR080394 4.SR080570
A26: Hunt Creek | B26: NY | C26: {=IF(INDIRECT("'" & $A26 & "'!B5:J5")="", "", INDIRECT("'" & $A26 & "'!B5:J5"))} -> 87616.95 | D26: 201235.3 | E26: -113618.35 | F26: -0.56460447 | G26: 228700 | H26: -141083.05 | I26: -0.61689134
A27: Smith Creek | B27: NY | C27: {=IF(INDIRECT("'" & $A27 & "'!B5:J5")="", "", INDIRECT("'" & $A27 & "'!B5:J5"))} -> 140087 | D27: 237488.5 | E27: -97401.5 | F27: -0.41013144 | G27: 400605.5 | H27: -260518.5 | I27: -0.65031184
A28: Total | C28: =SUM(C3:C27) -> 1646953.4 | D28: =SUM(D3:D27) -> 2934622.4 | E28: =C28-D28 -> -1287669 | F28: =IFERROR(E28/D28, 0) -> -0.43878523 | G28: =SUM(G3:G27) -> 3459095.5 | H28: =C28-G28 -> -1812142.1 | I28: =IFERROR(H28/G28, 0) -> -0.52387743
A30: Values in gold exceed expected or forecasted by 10% or more.
A32: Values in red are below expected or forecasted by 10% or more.

Sheet Feb
A1: {=portfolio} -> Lodestar | C1: February Actual v. Expected | G1: February Actual v. Forecasted | J1: NOTES | K1: SR
A2: Site | B2: State | C2: Actual | D2: Expected | E2: Delta | F2: % | G2: Forecasted | H2: Delta | I2: %
A3: {=Sites[Site]} -> Barkhamsted | B3: {=Sites[State]} -> CT | C3: {=IF(INDIRECT("'" & $A3 & "'!B6:J6")="", "", INDIRECT("'" & $A3 & "'!B6:J6"))} | E3: 0 | F3: 0 | H3: 0 | I3: 0
A4: Bunce | B4: CT | C4: {=IF(INDIRECT("'" & $A4 & "'!B6:J6")="", "", INDIRECT("'" & $A4 & "'!B6:J6"))} | E4: 0 | F4: 0 | H4: 0 | I4: 0
A5: Norcap North | B5: CT | C5: {=IF(INDIRECT("'" & $A5 & "'!B6:J6")="", "", INDIRECT("'" & $A5 & "'!B6:J6"))} | E5: 0 | F5: 0 | H5: 0 | I5: 0
A6: Norcap South | B6: CT | C6: {=IF(INDIRECT("'" & $A6 & "'!B6:J6")="", "", INDIRECT("'" & $A6 & "'!B6:J6"))} | E6: 0 | F6: 0 | H6: 0 | I6: 0
A7: Platt Hill | B7: CT | C7: {=IF(INDIRECT("'" & $A7 & "'!B6:J6")="", "", INDIRECT("'" & $A7 & "'!B6:J6"))} | E7: 0 | F7: 0 | H7: 0 | I7: 0
A8: Powder Hill | B8: CT | C8: {=IF(INDIRECT("'" & $A8 & "'!B6:J6")="", "", INDIRECT("'" & $A8 & "'!B6:J6"))} | E8: 0 | F8: 0 | H8: 0 | I8: 0
A9: Sand Road | B9: CT | C9: {=IF(INDIRECT("'" & $A9 & "'!B6:J6")="", "", INDIRECT("'" & $A9 & "'!B6:J6"))} | E9: 0 | F9: 0 | H9: 0 | I9: 0
A10: Suffield | B10: CT | C10: {=IF(INDIRECT("'" & $A10 & "'!B6:J6")="", "", INDIRECT("'" & $A10 & "'!B6:J6"))} | E10: 0 | F10: 0 | H10: 0 | I10: 0
A11: Ashby-Duffy | B11: MA | C11: {=IF(INDIRECT("'" & $A11 & "'!B6:J6")="", "", INDIRECT("'" & $A11 & "'!B6:J6"))} | E11: 0 | F11: 0 | H11: 0 | I11: 0
A12: Ashland | B12: MA | C12: {=IF(INDIRECT("'" & $A12 & "'!B6:J6")="", "", INDIRECT("'" & $A12 & "'!B6:J6"))} | E12: 0 | F12: 0 | H12: 0 | I12: 0
A13: Barrington | B13: MA | C13: {=IF(INDIRECT("'" & $A13 & "'!B6:J6")="", "", INDIRECT("'" & $A13 & "'!B6:J6"))} | E13: 0 | F13: 0 | H13: 0 | I13: 0
A14: Bedford - 205 Burlington Rd | B14: MA | C14: {=IF(INDIRECT("'" & $A14 & "'!B6:J6")="", "", INDIRECT("'" & $A14 & "'!B6:J6"))} | E14: 0 | F14: 0 | H14: 0 | I14: 0
A15: Billerica - 6 Cook Street | B15: MA | C15: {=IF(INDIRECT("'" & $A15 & "'!B6:J6")="", "", INDIRECT("'" & $A15 & "'!B6:J6"))} | E15: 0 | F15: 0 | H15: 0 | I15: 0
... A27: Smith Creek | B27: NY | C27: {=IF(INDIRECT("'" & $A27 & "'!B6:J6")="", "", INDIRECT("'" & $A27 & "'!B6:J6"))} | E27: 0 | F27: 0 | H27: 0 | I27: 0
A28: Total | C28: =SUM(C3:C27) -> 0 | D28: =SUM(D3:D27) -> 0 | E28: =C28-D28 -> 0 | F28: =IFERROR(E28/D28, 0) -> 0 | G28: =SUM(G3:G27) -> 0 | H28: =C28-G28 -> 0 | I28: =IFERROR(H28/G28, 0) -> 0
A30: Values in gold exceed expected or forecasted by 10% or more.
A32: Values in red are below expected or forecasted by 10% or more.

Sheet Mar
A1: {=portfolio} -> Lodestar | C1: March Actual v. Expected | G1: March Actual v. Forecasted | J1: NOTES | K1: SR
A2: Site | B2: State | C2: Actual | D2: Expected | E2: Delta | F2: % | G2: Forecasted | H2: Delta | I2: %
A3: {=Sites[Site]} -> Barkhamsted | B3: {=Sites[State]} -> CT | C3: {=IF(INDIRECT("'" & $A3 & "'!B7:J7")="", "", INDIRECT("'" & $A3 & "'!B7:J7"))} | E3: 0 | F3: 0 | H3: 0 | I3: 0
A4: Bunce | B4: CT | C4: {=IF(INDIRECT("'" & $A4 & "'!B7:J7")="", "", INDIRECT("'" & $A4 & "'!B7:J7"))} | E4: 0 | F4: 0 | H4: 0 | I4: 0
A5: Norcap North | B5: CT | C5: {=IF(INDIRECT("'" & $A5 & "'!B7:J7")="", "", INDIRECT("'" & $A5 & "'!B7:J7"))} | E5: 0 | F5: 0 | H5: 0 | I5: 0
A6: Norcap South | B6: CT | C6: {=IF(INDIRECT("'" & $A6 & "'!B7:J7")="", "", INDIRECT("'" & $A6 & "'!B7:J7"))} | E6: 0 | F6: 0 | H6: 0 | I6: 0
A7: Platt Hill | B7: CT | C7: {=IF(INDIRECT("'" & $A7 & "'!B7:J7")="", "", INDIRECT("'" & $A7 & "'!B7:J7"))} | E7: 0 | F7: 0 | H7: 0 | I7: 0
A8: Powder Hill | B8: CT | C8: {=IF(INDIRECT("'" & $A8 & "'!B7:J7")="", "", INDIRECT("'" & $A8 & "'!B7:J7"))} | E8: 0 | F8: 0 | H8: 0 | I8: 0
A9: Sand Road | B9: CT | C9: {=IF(INDIRECT("'" & $A9 & "'!B7:J7")="", "", INDIRECT("'" & $A9 & "'!B7:J7"))} | E9: 0 | F9: 0 | H9: 0 | I9: 0
A10: Suffield | B10: CT | C10: {=IF(INDIRECT("'" & $A10 & "'!B7:J7")="", "", INDIRECT("'" & $A10 & "'!B7:J7"))} | E10: 0 | F10: 0 | H10: 0 | I10: 0
A11: Ashby-Duffy | B11: MA | C11: {=IF(INDIRECT("'" & $A11 & "'!B7:J7")="", "", INDIRECT("'" & $A11 & "'!B7:J7"))} | E11: 0 | F11: 0 | H11: 0 | I11: 0
A12: Ashland | B12: MA | C12: {=IF(INDIRECT("'" & $A12 & "'!B7:J7")="", "", INDIRECT("'" & $A12 & "'!B7:J7"))} | E12: 0 | F12: 0 | H12: 0 | I12: 0
A13: Barrington | B13: MA | C13: {=IF(INDIRECT("'" & $A13 & "'!B7:J7")="", "", INDIRECT("'" & $A13 & "'!B7:J7"))} | E13: 0 | F13: 0 | H13: 0 | I13: 0
A14: Bedford - 205 Burlington Rd | B14: MA | C14: {=IF(INDIRECT("'" & $A14 & "'!B7:J7")="", "", INDIRECT("'" & $A14 & "'!B7:J7"))} | E14: 0 | F14: 0 | H14: 0 | I14: 0
A15: Billerica - 6 Cook Street | B15: MA | C15: {=IF(INDIRECT("'" & $A15 & "'!B7:J7")="", "", INDIRECT("'" & $A15 & "'!B7:J7"))} | E15: 0 | F15: 0 | H15: 0 | I15: 0
... A27: Smith Creek | B27: NY | C27: {=IF(INDIRECT("'" & $A27 & "'!B7:J7")="", "", INDIRECT("'" & $A27 & "'!B7:J7"))} | E27: 0 | F27: 0 | H27: 0 | I27: 0
A28: Total | C28: =SUM(C3:C27) -> 0 | D28: =SUM(D3:D27) -> 0 | E28: =C28-D28 -> 0 | F28: =IFERROR(E28/D28, 0) -> 0 | G28: =SUM(G3:G27) -> 0 | H28: =C28-G28 -> 0 | I28: =IFERROR(H28/G28, 0) -> 0
A30: Values in gold exceed expected or forecasted by 10% or more.
A32: Values in red are below expected or forecasted by 10% or more.

Sheet Apr
A1: {=portfolio} -> Lodestar | C1: April Actual v. Expected | G1: April Actual v. Forecasted | J1: NOTES | K1: SR
A2: Site | B2: State | C2: Actual | D2: Expected | E2: Delta | F2: % | G2: Forecasted | H2: Delta | I2: %
A3: {=Sites[Site]} -> Barkhamsted | B3: {=Sites[State]} -> CT | C3: {=IF(INDIRECT("'" & $A3 & "'!B8:J8")="", "", INDIRECT("'" & $A3 & "'!B8:J8"))} | E3: 0 | F3: 0 | H3: 0 | I3: 0
A4: Bunce | B4: CT | C4: {=IF(INDIRECT("'" & $A4 & "'!B8:J8")="", "", INDIRECT("'" & $A4 & "'!B8:J8"))} | E4: 0 | F4: 0 | H4: 0 | I4: 0
A5: Norcap North | B5: CT | C5: {=IF(INDIRECT("'" & $A5 & "'!B8:J8")="", "", INDIRECT("'" & $A5 & "'!B8:J8"))} | E5: 0 | F5: 0 | H5: 0 | I5: 0
A6: Norcap South | B6: CT | C6: {=IF(INDIRECT("'" & $A6 & "'!B8:J8")="", "", INDIRECT("'" & $A6 & "'!B8:J8"))} | E6: 0 | F6: 0 | H6: 0 | I6: 0
A7: Platt Hill | B7: CT | C7: {=IF(INDIRECT("'" & $A7 & "'!B8:J8")="", "", INDIRECT("'" & $A7 & "'!B8:J8"))} | E7: 0 | F7: 0 | H7: 0 | I7: 0
A8: Powder Hill | B8: CT | C8: {=IF(INDIRECT("'" & $A8 & "'!B8:J8")="", "", INDIRECT("'" & $A8 & "'!B8:J8"))} | E8: 0 | F8: 0 | H8: 0 | I8: 0
A9: Sand Road | B9: CT | C9: {=IF(INDIRECT("'" & $A9 & "'!B8:J8")="", "", INDIRECT("'" & $A9 & "'!B8:J8"))} | E9: 0 | F9: 0 | H9: 0 | I9: 0
A10: Suffield | B10: CT | C10: {=IF(INDIRECT("'" & $A10 & "'!B8:J8")="", "", INDIRECT("'" & $A10 & "'!B8:J8"))} | E10: 0 | F10: 0 | H10: 0 | I10: 0
A11: Ashby-Duffy | B11: MA | C11: {=IF(INDIRECT("'" & $A11 & "'!B8:J8")="", "", INDIRECT("'" & $A11 & "'!B8:J8"))} | E11: 0 | F11: 0 | H11: 0 | I11: 0
A12: Ashland | B12: MA | C12: {=IF(INDIRECT("'" & $A12 & "'!B8:J8")="", "", INDIRECT("'" & $A12 & "'!B8:J8"))} | E12: 0 | F12: 0 | H12: 0 | I12: 0
A13: Barrington | B13: MA | C13: {=IF(INDIRECT("'" & $A13 & "'!B8:J8")="", "", INDIRECT("'" & $A13 & "'!B8:J8"))} | E13: 0 | F13: 0 | H13: 0 | I13: 0
A14: Bedford - 205 Burlington Rd | B14: MA | C14: {=IF(INDIRECT("'" & $A14 & "'!B8:J8")="", "", INDIRECT("'" & $A14 & "'!B8:J8"))} | E14: 0 | F14: 0 | H14: 0 | I14: 0
A15: Billerica - 6 Cook Street | B15: MA | C15: {=IF(INDIRECT("'" & $A15 & "'!B8:J8")="", "", INDIRECT("'" & $A15 & "'!B8:J8"))} | E15: 0 | F15: 0 | H15: 0 | I15: 0
... A27: Smith Creek | B27: NY | C27: {=IF(INDIRECT("'" & $A27 & "'!B8:J8")="", "", INDIRECT("'" & $A27 & "'!B8:J8"))} | E27: 0 | F27: 0 | H27: 0 | I27: 0
A28: Total | C28: =SUM(C3:C27) -> 0 | D28: =SUM(D3:D27) -> 0 | E28: =C28-D28 -> 0 | F28: =IFERROR(E28/D28, 0) -> 0 | G28: =SUM(G3:G27) -> 0 | H28: =C28-G28 -> 0 | I28: =IFERROR(H28/G28, 0) -> 0
A30: Values in gold exceed expected or forecasted by 10% or more.
A32: Values in red are below expected or forecasted by 10% or more.

Sheet May
A1: {=portfolio} -> Lodestar | C1: May Actual v. Expected | G1: May Actual v. Forecasted | J1: NOTES | K1: SR
A2: Site | B2: State | C2: Actual | D2: Expected | E2: Delta | F2: % | G2: Forecasted | H2: Delta | I2: %
A3: {=Sites[Site]} -> Barkhamsted | B3: {=Sites[State]} -> CT | C3: {=IF(INDIRECT("'" & $A3 & "'!B9:J9")="", "", INDIRECT("'" & $A3 & "'!B9:J9"))} | E3: 0 | F3: 0 | H3: 0 | I3: 0
A4: Bunce | B4: CT | C4: {=IF(INDIRECT("'" & $A4 & "'!B9:J9")="", "", INDIRECT("'" & $A4 & "'!B9:J9"))} | E4: 0 | F4: 0 | H4: 0 | I4: 0
A5: Norcap North | B5: CT | C5: {=IF(INDIRECT("'" & $A5 & "'!B9:J9")="", "", INDIRECT("'" & $A5 & "'!B9:J9"))} | E5: 0 | F5: 0 | H5: 0 | I5: 0
A6: Norcap South | B6: CT | C6: {=IF(INDIRECT("'" & $A6 & "'!B9:J9")="", "", INDIRECT("'" & $A6 & "'!B9:J9"))} | E6: 0 | F6: 0 | H6: 0 | I6: 0
A7: Platt Hill | B7: CT | C7: {=IF(INDIRECT("'" & $A7 & "'!B9:J9")="", "", INDIRECT("'" & $A7 & "'!B9:J9"))} | E7: 0 | F7: 0 | H7: 0 | I7: 0
A8: Powder Hill | B8: CT | C8: {=IF(INDIRECT("'" & $A8 & "'!B9:J9")="", "", INDIRECT("'" & $A8 & "'!B9:J9"))} | E8: 0 | F8: 0 | H8: 0 | I8: 0
A9: Sand Road | B9: CT | C9: {=IF(INDIRECT("'" & $A9 & "'!B9:J9")="", "", INDIRECT("'" & $A9 & "'!B9:J9"))} | E9: 0 | F9: 0 | H9: 0 | I9: 0
A10: Suffield | B10: CT | C10: {=IF(INDIRECT("'" & $A10 & "'!B9:J9")="", "", INDIRECT("'" & $A10 & "'!B9:J9"))} | E10: 0 | F10: 0 | H10: 0 | I10: 0
A11: Ashby-Duffy | B11: MA | C11: {=IF(INDIRECT("'" & $A11 & "'!B9:J9")="", "", INDIRECT("'" & $A11 & "'!B9:J9"))} | E11: 0 | F11: 0 | H11: 0 | I11: 0
A12: Ashland | B12: MA | C12: {=IF(INDIRECT("'" & $A12 & "'!B9:J9")="", "", INDIRECT("'" & $A12 & "'!B9:J9"))} | E12: 0 | F12: 0 | H12: 0 | I12: 0
A13: Barrington | B13: MA | C13: {=IF(INDIRECT("'" & $A13 & "'!B9:J9")="", "", INDIRECT("'" & $A13 & "'!B9:J9"))} | E13: 0 | F13: 0 | H13: 0 | I13: 0
A14: Bedford - 205 Burlington Rd | B14: MA | C14: {=IF(INDIRECT("'" & $A14 & "'!B9:J9")="", "", INDIRECT("'" & $A14 & "'!B9:J9"))} | E14: 0 | F14: 0 | H14: 0 | I14: 0
A15: Billerica - 6 Cook Street | B15: MA | C15: {=IF(INDIRECT("'" & $A15 & "'!B9:J9")="", "", INDIRECT("'" & $A15 & "'!B9:J9"))} | E15: 0 | F15: 0 | H15: 0 | I15: 0
... A27: Smith Creek | B27: NY | C27: {=IF(INDIRECT("'" & $A27 & "'!B9:J9")="", "", INDIRECT("'" & $A27 & "'!B9:J9"))} | E27: 0 | F27: 0 | H27: 0 | I27: 0
A28: Total | C28: =SUM(C3:C27) -> 0 | D28: =SUM(D3:D27) -> 0 | E28: =C28-D28 -> 0 | F28: =IFERROR(E28/D28, 0) -> 0 | G28: =SUM(G3:G27) -> 0 | H28: =C28-G28 -> 0 | I28: =IFERROR(H28/G28, 0) -> 0
A30: Values in gold exceed expected or forecasted by 10% or more.
A32: Values in red are below expected or forecasted by 10% or more.

Sheet Jun
A1: {=portfolio} -> Lodestar | C1: June Actual v. Expected | G1: June Actual v. Forecasted | J1: NOTES | K1: SR
A2: Site | B2: State | C2: Actual | D2: Expected | E2: Delta | F2: % | G2: Forecasted | H2: Delta | I2: %
A3: {=Sites[Site]} -> Barkhamsted | B3: {=Sites[State]} -> CT | C3: {=IF(INDIRECT("'" & $A3 & "'!B10:J10")="", "", INDIRECT("'" & $A3 & "'!B10:J10"))} | E3: 0 | F3: 0 | H3: 0 | I3: 0
A4: Bunce | B4: CT | C4: {=IF(INDIRECT("'" & $A4 & "'!B10:J10")="", "", INDIRECT("'" & $A4 & "'!B10:J10"))} | E4: 0 | F4: 0 | H4: 0 | I4: 0
A5: Norcap North | B5: CT | C5: {=IF(INDIRECT("'" & $A5 & "'!B10:J10")="", "", INDIRECT("'" & $A5 & "'!B10:J10"))} | E5: 0 | F5: 0 | H5: 0 | I5: 0
A6: Norcap South | B6: CT | C6: {=IF(INDIRECT("'" & $A6 & "'!B10:J10")="", "", INDIRECT("'" & $A6 & "'!B10:J10"))} | E6: 0 | F6: 0 | H6: 0 | I6: 0
A7: Platt Hill | B7: CT | C7: {=IF(INDIRECT("'" & $A7 & "'!B10:J10")="", "", INDIRECT("'" & $A7 & "'!B10:J10"))} | E7: 0 | F7: 0 | H7: 0 | I7: 0
A8: Powder Hill | B8: CT | C8: {=IF(INDIRECT("'" & $A8 & "'!B10:J10")="", "", INDIRECT("'" & $A8 & "'!B10:J10"))} | E8: 0 | F8: 0 | H8: 0 | I8: 0
A9: Sand Road | B9: CT | C9: {=IF(INDIRECT("'" & $A9 & "'!B10:J10")="", "", INDIRECT("'" & $A9 & "'!B10:J10"))} | E9: 0 | F9: 0 | H9: 0 | I9: 0
A10: Suffield | B10: CT | C10: {=IF(INDIRECT("'" & $A10 & "'!B10:J10")="", "", INDIRECT("'" & $A10 & "'!B10:J10"))} | E10: 0 | F10: 0 | H10: 0 | I10: 0
A11: Ashby-Duffy | B11: MA | C11: {=IF(INDIRECT("'" & $A11 & "'!B10:J10")="", "", INDIRECT("'" & $A11 & "'!B10:J10"))} | E11: 0 | F11: 0 | H11: 0 | I11: 0
A12: Ashland | B12: MA | C12: {=IF(INDIRECT("'" & $A12 & "'!B10:J10")="", "", INDIRECT("'" & $A12 & "'!B10:J10"))} | E12: 0 | F12: 0 | H12: 0 | I12: 0
A13: Barrington | B13: MA | C13: {=IF(INDIRECT("'" & $A13 & "'!B10:J10")="", "", INDIRECT("'" & $A13 & "'!B10:J10"))} | E13: 0 | F13: 0 | H13: 0 | I13: 0
A14: Bedford - 205 Burlington Rd | B14: MA | C14: {=IF(INDIRECT("'" & $A14 & "'!B10:J10")="", "", INDIRECT("'" & $A14 & "'!B10:J10"))} | E14: 0 | F14: 0 | H14: 0 | I14: 0
A15: Billerica - 6 Cook Street | B15: MA | C15: {=IF(INDIRECT("'" & $A15 & "'!B10:J10")="", "", INDIRECT("'" & $A15 & "'!B10:J10"))} | E15: 0 | F15: 0 | H15: 0 | I15: 0
... A27: Smith Creek | B27: NY | C27: {=IF(INDIRECT("'" & $A27 & "'!B10:J10")="", "", INDIRECT("'" & $A27 & "'!B10:J10"))} | E27: 0 | F27: 0 | H27: 0 | I27: 0
A28: Total | C28: =SUM(C3:C27) -> 0 | D28: =SUM(D3:D27) -> 0 | E28: =C28-D28 -> 0 | F28: =IFERROR(E28/D28, 0) -> 0 | G28: =SUM(G3:G27) -> 0 | H28: =C28-G28 -> 0 | I28: =IFERROR(H28/G28, 0) -> 0
A30: Values in gold exceed expected or forecasted by 10% or more.
A32: Values in red are below expected or forecasted by 10% or more.

Sheet Jul
A1: {=portfolio} -> Lodestar | C1: July Actual v. Expected | G1: July Actual v. Forecasted | J1: NOTES | K1: SR
A2: Site | B2: State | C2: Actual | D2: Expected | E2: Delta | F2: % | G2: Forecasted | H2: Delta | I2: %
A3: {=Sites[Site]} -> Barkhamsted | B3: {=Sites[State]} -> CT | C3: {=IF(INDIRECT("'" & $A3 & "'!B11:J11")="", "", INDIRECT("'" & $A3 & "'!B11:J11"))} | E3: 0 | F3: 0 | H3: 0 | I3: 0
A4: Bunce | B4: CT | C4: {=IF(INDIRECT("'" & $A4 & "'!B11:J11")="", "", INDIRECT("'" & $A4 & "'!B11:J11"))} | E4: 0 | F4: 0 | H4: 0 | I4: 0
A5: Norcap North | B5: CT | C5: {=IF(INDIRECT("'" & $A5 & "'!B11:J11")="", "", INDIRECT("'" & $A5 & "'!B11:J11"))} | E5: 0 | F5: 0 | H5: 0 | I5: 0
A6: Norcap South | B6: CT | C6: {=IF(INDIRECT("'" & $A6 & "'!B11:J11")="", "", INDIRECT("'" & $A6 & "'!B11:J11"))} | E6: 0 | F6: 0 | H6: 0 | I6: 0
A7: Platt Hill | B7: CT | C7: {=IF(INDIRECT("'" & $A7 & "'!B11:J11")="", "", INDIRECT("'" & $A7 & "'!B11:J11"))} | E7: 0 | F7: 0 | H7: 0 | I7: 0
A8: Powder Hill | B8: CT | C8: {=IF(INDIRECT("'" & $A8 & "'!B11:J11")="", "", INDIRECT("'" & $A8 & "'!B11:J11"))} | E8: 0 | F8: 0 | H8: 0 | I8: 0
A9: Sand Road | B9: CT | C9: {=IF(INDIRECT("'" & $A9 & "'!B11:J11")="", "", INDIRECT("'" & $A9 & "'!B11:J11"))} | E9: 0 | F9: 0 | H9: 0 | I9: 0
A10: Suffield | B10: CT | C10: {=IF(INDIRECT("'" & $A10 & "'!B11:J11")="", "", INDIRECT("'" & $A10 & "'!B11:J11"))} | E10: 0 | F10: 0 | H10: 0 | I10: 0
A11: Ashby-Duffy | B11: MA | C11: {=IF(INDIRECT("'" & $A11 & "'!B11:J11")="", "", INDIRECT("'" & $A11 & "'!B11:J11"))} | E11: 0 | F11: 0 | H11: 0 | I11: 0
A12: Ashland | B12: MA | C12: {=IF(INDIRECT("'" & $A12 & "'!B11:J11")="", "", INDIRECT("'" & $A12 & "'!B11:J11"))} | E12: 0 | F12: 0 | H12: 0 | I12: 0
A13: Barrington | B13: MA | C13: {=IF(INDIRECT("'" & $A13 & "'!B11:J11")="", "", INDIRECT("'" & $A13 & "'!B11:J11"))} | E13: 0 | F13: 0 | H13: 0 | I13: 0
A14: Bedford - 205 Burlington Rd | B14: MA | C14: {=IF(INDIRECT("'" & $A14 & "'!B11:J11")="", "", INDIRECT("'" & $A14 & "'!B11:J11"))} | E14: 0 | F14: 0 | H14: 0 | I14: 0
A15: Billerica - 6 Cook Street | B15: MA | C15: {=IF(INDIRECT("'" & $A15 & "'!B11:J11")="", "", INDIRECT("'" & $A15 & "'!B11:J11"))} | E15: 0 | F15: 0 | H15: 0 | I15: 0
... A27: Smith Creek | B27: NY | C27: {=IF(INDIRECT("'" & $A27 & "'!B11:J11")="", "", INDIRECT("'" & $A27 & "'!B11:J11"))} | E27: 0 | F27: 0 | H27: 0 | I27: 0
A28: Total | C28: =SUM(C3:C27) -> 0 | D28: =SUM(D3:D27) -> 0 | E28: =C28-D28 -> 0 | F28: =IFERROR(E28/D28, 0) -> 0 | G28: =SUM(G3:G27) -> 0 | H28: =C28-G28 -> 0 | I28: =IFERROR(H28/G28, 0) -> 0
A30: Values in gold exceed expected or forecasted by 10% or more.
A32: Values in red are below expected or forecasted by 10% or more.

Sheet Aug
A1: {=portfolio} -> Lodestar | C1: August Actual v. Expected | G1: August Actual v. Forecasted | J1: NOTES | K1: SR
A2: Site | B2: State | C2: Actual | D2: Expected | E2: Delta | F2: % | G2: Forecasted | H2: Delta | I2: %
A3: {=Sites[Site]} -> Barkhamsted | B3: {=Sites[State]} -> CT | C3: {=IF(INDIRECT("'" & $A3 & "'!B12:J12")="", "", INDIRECT("'" & $A3 & "'!B12:J12"))} | E3: 0 | F3: 0 | H3: 0 | I3: 0
A4: Bunce | B4: CT | C4: {=IF(INDIRECT("'" & $A4 & "'!B12:J12")="", "", INDIRECT("'" & $A4 & "'!B12:J12"))} | E4: 0 | F4: 0 | H4: 0 | I4: 0
A5: Norcap North | B5: CT | C5: {=IF(INDIRECT("'" & $A5 & "'!B12:J12")="", "", INDIRECT("'" & $A5 & "'!B12:J12"))} | E5: 0 | F5: 0 | H5: 0 | I5: 0
A6: Norcap South | B6: CT | C6: {=IF(INDIRECT("'" & $A6 & "'!B12:J12")="", "", INDIRECT("'" & $A6 & "'!B12:J12"))} | E6: 0 | F6: 0 | H6: 0 | I6: 0
A7: Platt Hill | B7: CT | C7: {=IF(INDIRECT("'" & $A7 & "'!B12:J12")="", "", INDIRECT("'" & $A7 & "'!B12:J12"))} | E7: 0 | F7: 0 | H7: 0 | I7: 0
A8: Powder Hill | B8: CT | C8: {=IF(INDIRECT("'" & $A8 & "'!B12:J12")="", "", INDIRECT("'" & $A8 & "'!B12:J12"))} | E8: 0 | F8: 0 | H8: 0 | I8: 0
A9: Sand Road | B9: CT | C9: {=IF(INDIRECT("'" & $A9 & "'!B12:J12")="", "", INDIRECT("'" & $A9 & "'!B12:J12"))} | E9: 0 | F9: 0 | H9: 0 | I9: 0
A10: Suffield | B10: CT | C10: {=IF(INDIRECT("'" & $A10 & "'!B12:J12")="", "", INDIRECT("'" & $A10 & "'!B12:J12"))} | E10: 0 | F10: 0 | H10: 0 | I10: 0
A11: Ashby-Duffy | B11: MA | C11: {=IF(INDIRECT("'" & $A11 & "'!B12:J12")="", "", INDIRECT("'" & $A11 & "'!B12:J12"))} | E11: 0 | F11: 0 | H11: 0 | I11: 0
A12: Ashland | B12: MA | C12: {=IF(INDIRECT("'" & $A12 & "'!B12:J12")="", "", INDIRECT("'" & $A12 & "'!B12:J12"))} | E12: 0 | F12: 0 | H12: 0 | I12: 0
A13: Barrington | B13: MA | C13: {=IF(INDIRECT("'" & $A13 & "'!B12:J12")="", "", INDIRECT("'" & $A13 & "'!B12:J12"))} | E13: 0 | F13: 0 | H13: 0 | I13: 0
A14: Bedford - 205 Burlington Rd | B14: MA | C14: {=IF(INDIRECT("'" & $A14 & "'!B12:J12")="", "", INDIRECT("'" & $A14 & "'!B12:J12"))} | E14: 0 | F14: 0 | H14: 0 | I14: 0
A15: Billerica - 6 Cook Street | B15: MA | C15: {=IF(INDIRECT("'" & $A15 & "'!B12:J12")="", "", INDIRECT("'" & $A15 & "'!B12:J12"))} | E15: 0 | F15: 0 | H15: 0 | I15: 0
... A27: Smith Creek | B27: NY | C27: {=IF(INDIRECT("'" & $A27 & "'!B12:J12")="", "", INDIRECT("'" & $A27 & "'!B12:J12"))} | E27: 0 | F27: 0 | H27: 0 | I27: 0
A28: Total | C28: =SUM(C3:C27) -> 0 | D28: =SUM(D3:D27) -> 0 | E28: =C28-D28 -> 0 | F28: =IFERROR(E28/D28, 0) -> 0 | G28: =SUM(G3:G27) -> 0 | H28: =C28-G28 -> 0 | I28: =IFERROR(H28/G28, 0) -> 0
A30: Values in gold exceed expected or forecasted by 10% or more.
A32: Values in red are below expected or forecasted by 10% or more.

Sheet Sep
A1: {=portfolio} -> Lodestar | C1: September Actual v. Expected | G1: September Actual v. Forecasted | J1: NOTES | K1: SR
A2: Site | B2: State | C2: Actual | D2: Expected | E2: Delta | F2: % | G2: Forecasted | H2: Delta | I2: %
A3: {=Sites[Site]} -> Barkhamsted | B3: {=Sites[State]} -> CT | C3: {=IF(INDIRECT("'" & $A3 & "'!B13:J13")="", "", INDIRECT("'" & $A3 & "'!B13:J13"))} | E3: 0 | F3: 0 | H3: 0 | I3: 0
A4: Bunce | B4: CT | C4: {=IF(INDIRECT("'" & $A4 & "'!B13:J13")="", "", INDIRECT("'" & $A4 & "'!B13:J13"))} | E4: 0 | F4: 0 | H4: 0 | I4: 0
A5: Norcap North | B5: CT | C5: {=IF(INDIRECT("'" & $A5 & "'!B13:J13")="", "", INDIRECT("'" & $A5 & "'!B13:J13"))} | E5: 0 | F5: 0 | H5: 0 | I5: 0
A6: Norcap South | B6: CT | C6: {=IF(INDIRECT("'" & $A6 & "'!B13:J13")="", "", INDIRECT("'" & $A6 & "'!B13:J13"))} | E6: 0 | F6: 0 | H6: 0 | I6: 0
A7: Platt Hill | B7: CT | C7: {=IF(INDIRECT("'" & $A7 & "'!B13:J13")="", "", INDIRECT("'" & $A7 & "'!B13:J13"))} | E7: 0 | F7: 0 | H7: 0 | I7: 0
A8: Powder Hill | B8: CT | C8: {=IF(INDIRECT("'" & $A8 & "'!B13:J13")="", "", INDIRECT("'" & $A8 & "'!B13:J13"))} | E8: 0 | F8: 0 | H8: 0 | I8: 0
A9: Sand Road | B9: CT | C9: {=IF(INDIRECT("'" & $A9 & "'!B13:J13")="", "", INDIRECT("'" & $A9 & "'!B13:J13"))} | E9: 0 | F9: 0 | H9: 0 | I9: 0
A10: Suffield | B10: CT | C10: {=IF(INDIRECT("'" & $A10 & "'!B13:J13")="", "", INDIRECT("'" & $A10 & "'!B13:J13"))} | E10: 0 | F10: 0 | H10: 0 | I10: 0
A11: Ashby-Duffy | B11: MA | C11: {=IF(INDIRECT("'" & $A11 & "'!B13:J13")="", "", INDIRECT("'" & $A11 & "'!B13:J13"))} | E11: 0 | F11: 0 | H11: 0 | I11: 0
A12: Ashland | B12: MA | C12: {=IF(INDIRECT("'" & $A12 & "'!B13:J13")="", "", INDIRECT("'" & $A12 & "'!B13:J13"))} | E12: 0 | F12: 0 | H12: 0 | I12: 0
A13: Barrington | B13: MA | C13: {=IF(INDIRECT("'" & $A13 & "'!B13:J13")="", "", INDIRECT("'" & $A13 & "'!B13:J13"))} | E13: 0 | F13: 0 | H13: 0 | I13: 0
A14: Bedford - 205 Burlington Rd | B14: MA | C14: {=IF(INDIRECT("'" & $A14 & "'!B13:J13")="", "", INDIRECT("'" & $A14 & "'!B13:J13"))} | E14: 0 | F14: 0 | H14: 0 | I14: 0
A15: Billerica - 6 Cook Street | B15: MA | C15: {=IF(INDIRECT("'" & $A15 & "'!B13:J13")="", "", INDIRECT("'" & $A15 & "'!B13:J13"))} | E15: 0 | F15: 0 | H15: 0 | I15: 0
... A27: Smith Creek | B27: NY | C27: {=IF(INDIRECT("'" & $A27 & "'!B13:J13")="", "", INDIRECT("'" & $A27 & "'!B13:J13"))} | E27: 0 | F27: 0 | H27: 0 | I27: 0
A28: Total | C28: =SUM(C3:C27) -> 0 | D28: =SUM(D3:D27) -> 0 | E28: =C28-D28 -> 0 | F28: =IFERROR(E28/D28, 0) -> 0 | G28: =SUM(G3:G27) -> 0 | H28: =C28-G28 -> 0 | I28: =IFERROR(H28/G28, 0) -> 0
A30: Values in gold exceed expected or forecasted by 10% or more.
A32: Values in red are below expected or forecasted by 10% or more.

Sheet Oct
A1: {=portfolio} -> Lodestar | C1: October Actual v. Expected | G1: October Actual v. Forecasted | J1: NOTES | K1: SR
A2: Site | B2: State | C2: Actual | D2: Expected | E2: Delta | F2: % | G2: Forecasted | H2: Delta | I2: %
A3: {=Sites[Site]} -> Barkhamsted | B3: {=Sites[State]} -> CT | C3: {=IF(INDIRECT("'" & $A3 & "'!B14:J14")="", "", INDIRECT("'" & $A3 & "'!B14:J14"))} | E3: 0 | F3: 0 | H3: 0 | I3: 0
A4: Bunce | B4: CT | C4: {=IF(INDIRECT("'" & $A4 & "'!B14:J14")="", "", INDIRECT("'" & $A4 & "'!B14:J14"))} | E4: 0 | F4: 0 | H4: 0 | I4: 0
A5: Norcap North | B5: CT | C5: {=IF(INDIRECT("'" & $A5 & "'!B14:J14")="", "", INDIRECT("'" & $A5 & "'!B14:J14"))} | E5: 0 | F5: 0 | H5: 0 | I5: 0
A6: Norcap South | B6: CT | C6: {=IF(INDIRECT("'" & $A6 & "'!B14:J14")="", "", INDIRECT("'" & $A6 & "'!B14:J14"))} | E6: 0 | F6: 0 | H6: 0 | I6: 0
A7: Platt Hill | B7: CT | C7: {=IF(INDIRECT("'" & $A7 & "'!B14:J14")="", "", INDIRECT("'" & $A7 & "'!B14:J14"))} | E7: 0 | F7: 0 | H7: 0 | I7: 0
A8: Powder Hill | B8: CT | C8: {=IF(INDIRECT("'" & $A8 & "'!B14:J14")="", "", INDIRECT("'" & $A8 & "'!B14:J14"))} | E8: 0 | F8: 0 | H8: 0 | I8: 0
A9: Sand Road | B9: CT | C9: {=IF(INDIRECT("'" & $A9 & "'!B14:J14")="", "", INDIRECT("'" & $A9 & "'!B14:J14"))} | E9: 0 | F9: 0 | H9: 0 | I9: 0
A10: Suffield | B10: CT | C10: {=IF(INDIRECT("'" & $A10 & "'!B14:J14")="", "", INDIRECT("'" & $A10 & "'!B14:J14"))} | E10: 0 | F10: 0 | H10: 0 | I10: 0
A11: Ashby-Duffy | B11: MA | C11: {=IF(INDIRECT("'" & $A11 & "'!B14:J14")="", "", INDIRECT("'" & $A11 & "'!B14:J14"))} | E11: 0 | F11: 0 | H11: 0 | I11: 0
A12: Ashland | B12: MA | C12: {=IF(INDIRECT("'" & $A12 & "'!B14:J14")="", "", INDIRECT("'" & $A12 & "'!B14:J14"))} | E12: 0 | F12: 0 | H12: 0 | I12: 0
A13: Barrington | B13: MA | C13: {=IF(INDIRECT("'" & $A13 & "'!B14:J14")="", "", INDIRECT("'" & $A13 & "'!B14:J14"))} | E13: 0 | F13: 0 | H13: 0 | I13: 0
A14: Bedford - 205 Burlington Rd | B14: MA | C14: {=IF(INDIRECT("'" & $A14 & "'!B14:J14")="", "", INDIRECT("'" & $A14 & "'!B14:J14"))} | E14: 0 | F14: 0 | H14: 0 | I14: 0
A15: Billerica - 6 Cook Street | B15: MA | C15: {=IF(INDIRECT("'" & $A15 & "'!B14:J14")="", "", INDIRECT("'" & $A15 & "'!B14:J14"))} | E15: 0 | F15: 0 | H15: 0 | I15: 0
... A27: Smith Creek | B27: NY | C27: {=IF(INDIRECT("'" & $A27 & "'!B14:J14")="", "", INDIRECT("'" & $A27 & "'!B14:J14"))} | E27: 0 | F27: 0 | H27: 0 | I27: 0
A28: Total | C28: =SUM(C3:C27) -> 0 | D28: =SUM(D3:D27) -> 0 | E28: =C28-D28 -> 0 | F28: =IFERROR(E28/D28, 0) -> 0 | G28: =SUM(G3:G27) -> 0 | H28: =C28-G28 -> 0 | I28: =IFERROR(H28/G28, 0) -> 0
A30: Values in gold exceed expected or forecasted by 10% or more.
A32: Values in red are below expected or forecasted by 10% or more.

Sheet Nov
A1: {=portfolio} -> Lodestar | C1: November Actual v. Expected | G1: November Actual v. Forecasted | J1: NOTES | K1: SR
A2: Site | B2: State | C2: Actual | D2: Expected | E2: Delta | F2: % | G2: Forecasted | H2: Delta | I2: %
A3: {=Sites[Site]} -> Barkhamsted | B3: {=Sites[State]} -> CT | C3: {=IF(INDIRECT("'" & $A3 & "'!B15:J15")="", "", INDIRECT("'" & $A3 & "'!B15:J15"))} | E3: 0 | F3: 0 | H3: 0 | I3: 0
A4: Bunce | B4: CT | C4: {=IF(INDIRECT("'" & $A4 & "'!B15:J15")="", "", INDIRECT("'" & $A4 & "'!B15:J15"))} | E4: 0 | F4: 0 | H4: 0 | I4: 0
A5: Norcap North | B5: CT | C5: {=IF(INDIRECT("'" & $A5 & "'!B15:J15")="", "", INDIRECT("'" & $A5 & "'!B15:J15"))} | E5: 0 | F5: 0 | H5: 0 | I5: 0
A6: Norcap South | B6: CT | C6: {=IF(INDIRECT("'" & $A6 & "'!B15:J15")="", "", INDIRECT("'" & $A6 & "'!B15:J15"))} | E6: 0 | F6: 0 | H6: 0 | I6: 0
A7: Platt Hill | B7: CT | C7: {=IF(INDIRECT("'" & $A7 & "'!B15:J15")="", "", INDIRECT("'" & $A7 & "'!B15:J15"))} | E7: 0 | F7: 0 | H7: 0 | I7: 0
A8: Powder Hill | B8: CT | C8: {=IF(INDIRECT("'" & $A8 & "'!B15:J15")="", "", INDIRECT("'" & $A8 & "'!B15:J15"))} | E8: 0 | F8: 0 | H8: 0 | I8: 0
A9: Sand Road | B9: CT | C9: {=IF(INDIRECT("'" & $A9 & "'!B15:J15")="", "", INDIRECT("'" & $A9 & "'!B15:J15"))} | E9: 0 | F9: 0 | H9: 0 | I9: 0
A10: Suffield | B10: CT | C10: {=IF(INDIRECT("'" & $A10 & "'!B15:J15")="", "", INDIRECT("'" & $A10 & "'!B15:J15"))} | E10: 0 | F10: 0 | H10: 0 | I10: 0
A11: Ashby-Duffy | B11: MA | C11: {=IF(INDIRECT("'" & $A11 & "'!B15:J15")="", "", INDIRECT("'" & $A11 & "'!B15:J15"))} | E11: 0 | F11: 0 | H11: 0 | I11: 0
A12: Ashland | B12: MA | C12: {=IF(INDIRECT("'" & $A12 & "'!B15:J15")="", "", INDIRECT("'" & $A12 & "'!B15:J15"))} | E12: 0 | F12: 0 | H12: 0 | I12: 0
A13: Barrington | B13: MA | C13: {=IF(INDIRECT("'" & $A13 & "'!B15:J15")="", "", INDIRECT("'" & $A13 & "'!B15:J15"))} | E13: 0 | F13: 0 | H13: 0 | I13: 0
A14: Bedford - 205 Burlington Rd | B14: MA | C14: {=IF(INDIRECT("'" & $A14 & "'!B15:J15")="", "", INDIRECT("'" & $A14 & "'!B15:J15"))} | E14: 0 | F14: 0 | H14: 0 | I14: 0
A15: Billerica - 6 Cook Street | B15: MA | C15: {=IF(INDIRECT("'" & $A15 & "'!B15:J15")="", "", INDIRECT("'" & $A15 & "'!B15:J15"))} | E15: 0 | F15: 0 | H15: 0 | I15: 0
... A27: Smith Creek | B27: NY | C27: {=IF(INDIRECT("'" & $A27 & "'!B15:J15")="", "", INDIRECT("'" & $A27 & "'!B15:J15"))} | E27: 0 | F27: 0 | H27: 0 | I27: 0
A28: Total | C28: =SUM(C3:C27) -> 0 | D28: =SUM(D3:D27) -> 0 | E28: =C28-D28 -> 0 | F28: =IFERROR(E28/D28, 0) -> 0 | G28: =SUM(G3:G27) -> 0 | H28: =C28-G28 -> 0 | I28: =IFERROR(H28/G28, 0) -> 0
A30: Values in gold exceed expected or forecasted by 10% or more.
A32: Values in red are below expected or forecasted by 10% or more.

Sheet Dec
A1: {=portfolio} -> Lodestar | C1: December Actual v. Expected | G1: December Actual v. Forecasted | J1: NOTES | K1: SR
A2: Site | B2: State | C2: Actual | D2: Expected | E2: Delta | F2: % | G2: Forecasted | H2: Delta | I2: %
A3: {=Sites[Site]} -> Barkhamsted | B3: {=Sites[State]} -> CT | C3: {=IF(INDIRECT("'" & $A3 & "'!B16:J16")="", "", INDIRECT("'" & $A3 & "'!B16:J16"))} | E3: 0 | F3: 0 | H3: 0 | I3: 0
A4: Bunce | B4: CT | C4: {=IF(INDIRECT("'" & $A4 & "'!B16:J16")="", "", INDIRECT("'" & $A4 & "'!B16:J16"))} | E4: 0 | F4: 0 | H4: 0 | I4: 0
