Workbook
Name JanActual: '01-2024'!$C$3:$C$15
Name JanActual2: '01-2024'!#REF!
Name JanExpected: '01-2024'!$D$3:$D$15
Name JanExpectedDelta: '01-2024'!$E$3:$E$15
Name JanExpectedPercent: '01-2024'!$F$3:$F$15
Name JanExpPercent: '01-2024'!$F$3:$F$15
Name JanForecasted: '01-2024'!$G$3:$G$15
Name JanForecastedDelta: '01-2024'!$H$3:$H$15
Name JanForecastedPercent: '01-2024'!$I$3:$I$15
Name portfolio: Sites!$B$1:$B$1

Sheet YTD Total 2024
A1: {=portfolio} -> MN8 Bond | C1: Year to Date 2024 Actual v. Expected | G1: Year to Date 2024 Forecasted | J1: NOTES | K1: SR
A2: Site | B2: State | C2: Actual | D2: Expected | E2: Delta | F2: % | G2: Forecasted | H2: Delta | I2: %
A3: {=Sites[Site]} -> Grafton II | B3: {=Sites[State]} -> MA | C3: =SUM('1st Quarter 2024'!C3, '2nd Quarter 2024'!C3, '3rd Quarter 2024'!C3, '4th Quarter 2024'!C3) -> 108788.84 | D3: =SUM('1st Quarter 2024'!D3, '2nd Quarter 2024'!D3, '3rd Quarter 2024'!D3, '4th Quarter 2024'!D3) -> 176557 | E3: =C3-D3 -> -67768.159 | F3: =IFERROR(E3/D3, 0) -> -0.38383162 | G3: =SUM('1st Quarter 2024'!G3, '2nd Quarter 2024'!G3, '3rd Quarter 2024'!G3, '4th Quarter 2024'!G3) -> 245116 | H3: =C3-G3 -> -136327.16 | I3: =IFERROR(H3/G3, 0) -> -0.55617405
A4: Clara Barton | B4: MA | C4: =SUM('1st Quarter 2024'!C4, '2nd Quarter 2024'!C4, '3rd Quarter 2024'!C4, '4th Quarter 2024'!C4) -> 41686.145 | D4: =SUM('1st Quarter 2024'!D4, '2nd Quarter 2024'!D4, '3rd Quarter 2024'!D4, '4th Quarter 2024'!D4) -> 61398.72 | E4: =C4-D4 -> -19712.575 | F4: =IFERROR(E4/D4, 0) -> -0.32105841 | G4: =SUM('1st Quarter 2024'!G4, '2nd Quarter 2024'!G4, '3rd Quarter 2024'!G4, '4th Quarter 2024'!G4) -> 84576.48 | H4: =C4-G4 -> -42890.335 | I4: =IFERROR(H4/G4, 0) -> -0.50711895
A5: Fairhaven Solar | B5: MA | C5: =SUM('1st Quarter 2024'!C5, '2nd Quarter 2024'!C5, '3rd Quarter 2024'!C5, '4th Quarter 2024'!C5) -> 55436 | D5: =SUM('1st Quarter 2024'!D5, '2nd Quarter 2024'!D5, '3rd Quarter 2024'!D5, '4th Quarter 2024'!D5) -> 67352.87 | E5: =C5-D5 -> -11916.87 | F5: =IFERROR(E5/D5, 0) -> -0.17693188 | G5: =SUM('1st Quarter 2024'!G5, '2nd Quarter 2024'!G5, '3rd Quarter 2024'!G5, '4th Quarter 2024'!G5) -> 63727.01 | H5: =C5-G5 -> -8291.01 | I5: =IFERROR(H5/G5, 0) -> -0.13010198
A6: Plympton-1 | B6: MA | C6: =SUM('1st Quarter 2024'!C6, '2nd Quarter 2024'!C6, '3rd Quarter 2024'!C6, '4th Quarter 2024'!C6) -> 67619 | D6: =SUM('1st Quarter 2024'!D6, '2nd Quarter 2024'!D6, '3rd Quarter 2024'!D6, '4th Quarter 2024'!D6) -> 73871.03 | E6: =C6-D6 -> -6252.03 | F6: =IFERROR(E6/D6, 0) -> -0.084634396 | G6: =SUM('1st Quarter 2024'!G6, '2nd Quarter 2024'!G6, '3rd Quarter 2024'!G6, '4th Quarter 2024'!G6) -> 79420.95 | H6: =C6-G6 -> -11801.95 | I6: =IFERROR(H6/G6, 0) -> -0.14859996
A7: French River 2 | B7: MA | C7: =SUM('1st Quarter 2024'!C7, '2nd Quarter 2024'!C7, '3rd Quarter 2024'!C7, '4th Quarter 2024'!C7) -> 41541.11 | D7: =SUM('1st Quarter 2024'!D7, '2nd Quarter 2024'!D7, '3rd Quarter 2024'!D7, '4th Quarter 2024'!D7) -> 80016.27 | E7: =C7-D7 -> -38475.16 | F7: =IFERROR(E7/D7, 0) -> -0.48084171 | G7: =SUM('1st Quarter 2024'!G7, '2nd Quarter 2024'!G7, '3rd Quarter 2024'!G7, '4th Quarter 2024'!G7) -> 78833 | H7: =C7-G7 -> -37291.89 | I7: =IFERROR(H7/G7, 0) -> -0.47304923
A8: French River 3 | B8: MA | C8: =SUM('1st Quarter 2024'!C8, '2nd Quarter 2024'!C8, '3rd Quarter 2024'!C8, '4th Quarter 2024'!C8) -> 86149.12 | D8: =SUM('1st Quarter 2024'!D8, '2nd Quarter 2024'!D8, '3rd Quarter 2024'!D8, '4th Quarter 2024'!D8) -> 150506.8 | E8: =C8-D8 -> -64357.68 | F8: =IFERROR(E8/D8, 0) -> -0.42760646 | G8: =SUM('1st Quarter 2024'!G8, '2nd Quarter 2024'!G8, '3rd Quarter 2024'!G8, '4th Quarter 2024'!G8) -> 151308.7 | H8: =C8-G8 -> -65159.58 | I8: =IFERROR(H8/G8, 0) -> -0.43064001
A9: French River 4 | B9: MA | C9: =SUM('1st Quarter 2024'!C9, '2nd Quarter 2024'!C9, '3rd Quarter 2024'!C9, '4th Quarter 2024'!C9) -> 85549.466 | D9: =SUM('1st Quarter 2024'!D9, '2nd Quarter 2024'!D9, '3rd Quarter 2024'!D9, '4th Quarter 2024'!D9) -> 154184.8 | E9: =C9-D9 -> -68635.334 | F9: =IFERROR(E9/D9, 0) -> -0.4451498 | G9: =SUM('1st Quarter 2024'!G9, '2nd Quarter 2024'!G9, '3rd Quarter 2024'!G9, '4th Quarter 2024'!G9) -> 157760 | H9: =C9-G9 -> -72210.534 | I9: =IFERROR(H9/G9, 0) -> -0.45772397
A10: French River 5 | B10: MA | C10: =SUM('1st Quarter 2024'!C10, '2nd Quarter 2024'!C10, '3rd Quarter 2024'!C10, '4th Quarter 2024'!C10) -> 83292.5 | D10: =SUM('1st Quarter 2024'!D10, '2nd Quarter 2024'!D10, '3rd Quarter 2024'!D10, '4th Quarter 2024'!D10) -> 147678.6 | E10: =C10-D10 -> -64386.1 | F10: =IFERROR(E10/D10, 0) -> -0.43598802 | G10: =SUM('1st Quarter 2024'!G10, '2nd Quarter 2024'!G10, '3rd Quarter 2024'!G10, '4th Quarter 2024'!G10) -> 154754.9 | H10: =C10-G10 -> -71462.4 | I10: =IFERROR(H10/G10, 0) -> -0.46177795
A11: French River 6 | B11: MA | C11: =SUM('1st Quarter 2024'!C11, '2nd Quarter 2024'!C11, '3rd Quarter 2024'!C11, '4th Quarter 2024'!C11) -> 78703 | D11: =SUM('1st Quarter 2024'!D11, '2nd Quarter 2024'!D11, '3rd Quarter 2024'!D11, '4th Quarter 2024'!D11) -> 125159 | E11: =C11-D11 -> -46456 | F11: =IFERROR(E11/D11, 0) -> -0.37117586 | G11: =SUM('1st Quarter 2024'!G11, '2nd Quarter 2024'!G11, '3rd Quarter 2024'!G11, '4th Quarter 2024'!G11) -> 148483.1 | H11: =C11-G11 -> -69780.1 | I11: =IFERROR(H11/G11, 0) -> -0.46995315
A12: Stillwater River 1A | B12: MA | C12: =SUM('1st Quarter 2024'!C12, '2nd Quarter 2024'!C12, '3rd Quarter 2024'!C12, '4th Quarter 2024'!C12) -> 21302 | D12: =SUM('1st Quarter 2024'!D12, '2nd Quarter 2024'!D12, '3rd Quarter 2024'!D12, '4th Quarter 2024'!D12) -> 36938.76 | E12: =C12-D12 -> -15636.76 | F12: =IFERROR(E12/D12, 0) -> -0.42331578 | G12: =SUM('1st Quarter 2024'!G12, '2nd Quarter 2024'!G12, '3rd Quarter 2024'!G12, '4th Quarter 2024'!G12) -> 38086.07 | H12: =C12-G12 -> -16784.07 | I12: =IFERROR(H12/G12, 0) -> -0.44068789
A13: Stillwater River 2 | B13: MA | C13: =SUM('1st Quarter 2024'!C13, '2nd Quarter 2024'!C13, '3rd Quarter 2024'!C13, '4th Quarter 2024'!C13) -> 44604.12 | D13: =SUM('1st Quarter 2024'!D13, '2nd Quarter 2024'!D13, '3rd Quarter 2024'!D13, '4th Quarter 2024'!D13) -> 82849.68 | E13: =C13-D13 -> -38245.56 | F13: =IFERROR(E13/D13, 0) -> -0.46162592 | G13: =SUM('1st Quarter 2024'!G13, '2nd Quarter 2024'!G13, '3rd Quarter 2024'!G13, '4th Quarter 2024'!G13) -> 79775.59 | H13: =C13-G13 -> -35171.47 | I13: =IFERROR(H13/G13, 0) -> -0.4408801
A14: Stillwater River 3 | B14: MA | C14: =SUM('1st Quarter 2024'!C14, '2nd Quarter 2024'!C14, '3rd Quarter 2024'!C14, '4th Quarter 2024'!C14) -> 44552 | D14: =SUM('1st Quarter 2024'!D14, '2nd Quarter 2024'!D14, '3rd Quarter 2024'!D14, '4th Quarter 2024'!D14) -> 81817.76 | E14: =C14-D14 -> -37265.76 | F14: =IFERROR(E14/D14, 0) -> -0.45547275 | G14: =SUM('1st Quarter 2024'!G14, '2nd Quarter 2024'!G14, '3rd Quarter 2024'!G14, '4th Quarter 2024'!G14) -> 78530.19 | H14: =C14-G14 -> -33978.19 | I14: =IFERROR(H14/G14, 0) -> -0.43267678
A15: Stillwater River 4 | B15: MA | C15: =SUM('1st Quarter 2024'!C15, '2nd Quarter 2024'!C15, '3rd Quarter 2024'!C15, '4th Quarter 2024'!C15) -> 18009.312 | D15: =SUM('1st Quarter 2024'!D15, '2nd Quarter 2024'!D15, '3rd Quarter 2024'!D15, '4th Quarter 2024'!D15) -> 32813.84 | E15: =C15-D15 -> -14804.527 | F15: =IFERROR(E15/D15, 0) -> -0.45116718 | G15: =SUM('1st Quarter 2024'!G15, '2nd Quarter 2024'!G15, '3rd Quarter 2024'!G15, '4th Quarter 2024'!G15) -> 35648.47 | H15: =C15-G15 -> -17639.158 | I15: =IFERROR(H15/G15, 0) -> -0.49480826
A16: Total | C16: =SUM(C3:C15) -> 777232.61 | D16: =SUM(D3:D15) -> 1271145.1 | E16: =C16-D16 -> -493912.52 | F16: =IFERROR(E16/D16, 0) -> -0.38855714 | G16: =SUM(G3:G15) -> 1396020.5 | H16: =C16-G16 -> -618787.85 | I16: =IFERROR(H16/G16, 0) -> -0.44325127
A18: Values in gold exceed expected or forecasted by 10% or more.
A20: Values in red are below expected or forecasted by 10% or more.

Sheet 1st Quarter 2024
A1: {=portfolio} -> MN8 Bond | C1: 1st Quarter 2024 Actual v. Expected | G1: 1st Quarter 2024 Forecasted | J1: NOTES | K1: SR
A2: Site | B2: State | C2: Actual | D2: Expected | E2: Delta | F2: % | G2: Forecasted | H2: Delta | I2: %
A3: {=Sites[Site]} -> Grafton II | B3: {=Sites[State]} -> MA | C3: =SUM('01-2024'!C3, '02-2024'!C3, '03-2024'!C3) -> 108788.84 | D3: =SUM('01-2024'!D3, '02-2024'!D3, '03-2024'!D3) -> 176557 | E3: =C3-D3 -> -67768.159 | F3: =IFERROR(E3/D3, 0) -> -0.38383162 | G3: =SUM('01-2024'!G3, '02-2024'!G3, '03-2024'!G3) -> 245116 | H3: =C3-G3 -> -136327.16 | I3: =IFERROR(H3/G3, 0) -> -0.55617405
A4: Clara Barton | B4: MA | C4: =SUM('01-2024'!C4, '02-2024'!C4, '03-2024'!C4) -> 41686.145 | D4: =SUM('01-2024'!D4, '02-2024'!D4, '03-2024'!D4) -> 61398.72 | E4: =C4-D4 -> -19712.575 | F4: =IFERROR(E4/D4, 0) -> -0.32105841 | G4: =SUM('01-2024'!G4, '02-2024'!G4, '03-2024'!G4) -> 84576.48 | H4: =C4-G4 -> -42890.335 | I4: =IFERROR(H4/G4, 0) -> -0.50711895
A5: Fairhaven Solar | B5: MA | C5: =SUM('01-2024'!C5, '02-2024'!C5, '03-2024'!C5) -> 55436 | D5: =SUM('01-2024'!D5, '02-2024'!D5, '03-2024'!D5) -> 67352.87 | E5: =C5-D5 -> -11916.87 | F5: =IFERROR(E5/D5, 0) -> -0.17693188 | G5: =SUM('01-2024'!G5, '02-2024'!G5, '03-2024'!G5) -> 63727.01 | H5: =C5-G5 -> -8291.01 | I5: =IFERROR(H5/G5, 0) -> -0.13010198
A6: Plympton-1 | B6: MA | C6: =SUM('01-2024'!C6, '02-2024'!C6, '03-2024'!C6) -> 67619 | D6: =SUM('01-2024'!D6, '02-2024'!D6, '03-2024'!D6) -> 73871.03 | E6: =C6-D6 -> -6252.03 | F6: =IFERROR(E6/D6, 0) -> -0.084634396 | G6: =SUM('01-2024'!G6, '02-2024'!G6, '03-2024'!G6) -> 79420.95 | H6: =C6-G6 -> -11801.95 | I6: =IFERROR(H6/G6, 0) -> -0.14859996
A7: French River 2 | B7: MA | C7: =SUM('01-2024'!C7, '02-2024'!C7, '03-2024'!C7) -> 41541.11 | D7: =SUM('01-2024'!D7, '02-2024'!D7, '03-2024'!D7) -> 80016.27 | E7: =C7-D7 -> -38475.16 | F7: =IFERROR(E7/D7, 0) -> -0.48084171 | G7: =SUM('01-2024'!G7, '02-2024'!G7, '03-2024'!G7) -> 78833 | H7: =C7-G7 -> -37291.89 | I7: =IFERROR(H7/G7, 0) -> -0.47304923
A8: French River 3 | B8: MA | C8: =SUM('01-2024'!C8, '02-2024'!C8, '03-2024'!C8) -> 86149.12 | D8: =SUM('01-2024'!D8, '02-2024'!D8, '03-2024'!D8) -> 150506.8 | E8: =C8-D8 -> -64357.68 | F8: =IFERROR(E8/D8, 0) -> -0.42760646 | G8: =SUM('01-2024'!G8, '02-2024'!G8, '03-2024'!G8) -> 151308.7 | H8: =C8-G8 -> -65159.58 | I8: =IFERROR(H8/G8, 0) -> -0.43064001
A9: French River 4 | B9: MA | C9: =SUM('01-2024'!C9, '02-2024'!C9, '03-2024'!C9) -> 85549.466 | D9: =SUM('01-2024'!D9, '02-2024'!D9, '03-2024'!D9) -> 154184.8 | E9: =C9-D9 -> -68635.334 | F9: =IFERROR(E9/D9, 0) -> -0.4451498 | G9: =SUM('01-2024'!G9, '02-2024'!G9, '03-2024'!G9) -> 157760 | H9: =C9-G9 -> -72210.534 | I9: =IFERROR(H9/G9, 0) -> -0.45772397
A10: French River 5 | B10: MA | C10: =SUM('01-2024'!C10, '02-2024'!C10, '03-2024'!C10) -> 83292.5 | D10: =SUM('01-2024'!D10, '02-2024'!D10, '03-2024'!D10) -> 147678.6 | E10: =C10-D10 -> -64386.1 | F10: =IFERROR(E10/D10, 0) -> -0.43598802 | G10: =SUM('01-2024'!G10, '02-2024'!G10, '03-2024'!G10) -> 154754.9 | H10: =C10-G10 -> -71462.4 | I10: =IFERROR(H10/G10, 0) -> -0.46177795
A11: French River 6 | B11: MA | C11: =SUM('01-2024'!C11, '02-2024'!C11, '03-2024'!C11) -> 78703 | D11: =SUM('01-2024'!D11, '02-2024'!D11, '03-2024'!D11) -> 125159 | E11: =C11-D11 -> -46456 | F11: =IFERROR(E11/D11, 0) -> -0.37117586 | G11: =SUM('01-2024'!G11, '02-2024'!G11, '03-2024'!G11) -> 148483.1 | H11: =C11-G11 -> -69780.1 | I11: =IFERROR(H11/G11, 0) -> -0.46995315
A12: Stillwater River 1A | B12: MA | C12: =SUM('01-2024'!C12, '02-2024'!C12, '03-2024'!C12) -> 21302 | D12: =SUM('01-2024'!D12, '02-2024'!D12, '03-2024'!D12) -> 36938.76 | E12: =C12-D12 -> -15636.76 | F12: =IFERROR(E12/D12, 0) -> -0.42331578 | G12: =SUM('01-2024'!G12, '02-2024'!G12, '03-2024'!G12) -> 38086.07 | H12: =C12-G12 -> -16784.07 | I12: =IFERROR(H12/G12, 0) -> -0.44068789
A13: Stillwater River 2 | B13: MA | C13: =SUM('01-2024'!C13, '02-2024'!C13, '03-2024'!C13) -> 44604.12 | D13: =SUM('01-2024'!D13, '02-2024'!D13, '03-2024'!D13) -> 82849.68 | E13: =C13-D13 -> -38245.56 | F13: =IFERROR(E13/D13, 0) -> -0.46162592 | G13: =SUM('01-2024'!G13, '02-2024'!G13, '03-2024'!G13) -> 79775.59 | H13: =C13-G13 -> -35171.47 | I13: =IFERROR(H13/G13, 0) -> -0.4408801
A14: Stillwater River 3 | B14: MA | C14: =SUM('01-2024'!C14, '02-2024'!C14, '03-2024'!C14) -> 44552 | D14: =SUM('01-2024'!D14, '02-2024'!D14, '03-2024'!D14) -> 81817.76 | E14: =C14-D14 -> -37265.76 | F14: =IFERROR(E14/D14, 0) -> -0.45547275 | G14: =SUM('01-2024'!G14, '02-2024'!G14, '03-2024'!G14) -> 78530.19 | H14: =C14-G14 -> -33978.19 | I14: =IFERROR(H14/G14, 0) -> -0.43267678
A15: Stillwater River 4 | B15: MA | C15: =SUM('01-2024'!C15, '02-2024'!C15, '03-2024'!C15) -> 18009.312 | D15: =SUM('01-2024'!D15, '02-2024'!D15, '03-2024'!D15) -> 32813.84 | E15: =C15-D15 -> -14804.527 | F15: =IFERROR(E15/D15, 0) -> -0.45116718 | G15: =SUM('01-2024'!G15, '02-2024'!G15, '03-2024'!G15) -> 35648.47 | H15: =C15-G15 -> -17639.158 | I15: =IFERROR(H15/G15, 0) -> -0.49480826
A16: Total | C16: =SUM(C3:C15) -> 777232.61 | D16: =SUM(D3:D15) -> 1271145.1 | E16: =C16-D16 -> -493912.52 | F16: =IFERROR(E16/D16, 0) -> -0.38855714 | G16: =SUM(G3:G15) -> 1396020.5 | H16: =C16-G16 -> -618787.85 | I16: =IFERROR(H16/G16, 0) -> -0.44325127
A18: Values in gold exceed expected or forecasted by 10% or more.
A20: Values in red are below expected or forecasted by 10% or more.

Sheet 2nd Quarter 2024
A1: {=portfolio} -> MN8 Bond | C1: 2nd Quarter 2024 Actual v. Expected | G1: 2nd Quarter 2024 Forecasted | J1: NOTES | K1: SR
A2: Site | B2: State | C2: Actual | D2: Expected | E2: Delta | F2: % | G2: Forecasted | H2: Delta | I2: %
A3: {=Sites[Site]} -> Grafton II | B3: {=Sites[State]} -> MA | C3: =SUM('04-2024'!C3, '05-2024'!C3, '06-2024'!C3) -> 0 | D3: =SUM('04-2024'!D3, '05-2024'!D3, '06-2024'!D3) -> 0 | E3: =C3-D3 -> 0 | F3: =IFERROR(E3/D3, 0) -> 0 | G3: =SUM('04-2024'!G3, '05-2024'!G3, '06-2024'!G3) -> 0 | H3: =C3-G3 -> 0 | I3: =IFERROR(H3/G3, 0) -> 0
A4: Clara Barton | B4: MA | C4: =SUM('04-2024'!C4, '05-2024'!C4, '06-2024'!C4) -> 0 | D4: =SUM('04-2024'!D4, '05-2024'!D4, '06-2024'!D4) -> 0 | E4: =C4-D4 -> 0 | F4: =IFERROR(E4/D4, 0) -> 0 | G4: =SUM('04-2024'!G4, '05-2024'!G4, '06-2024'!G4) -> 0 | H4: =C4-G4 -> 0 | I4: =IFERROR(H4/G4, 0) -> 0
A5: Fairhaven Solar | B5: MA | C5: =SUM('04-2024'!C5, '05-2024'!C5, '06-2024'!C5) -> 0 | D5: =SUM('04-2024'!D5, '05-2024'!D5, '06-2024'!D5) -> 0 | E5: =C5-D5 -> 0 | F5: =IFERROR(E5/D5, 0) -> 0 | G5: =SUM('04-2024'!G5, '05-2024'!G5, '06-2024'!G5) -> 0 | H5: =C5-G5 -> 0 | I5: =IFERROR(H5/G5, 0) -> 0
A6: Plympton-1 | B6: MA | C6: =SUM('04-2024'!C6, '05-2024'!C6, '06-2024'!C6) -> 0 | D6: =SUM('04-2024'!D6, '05-2024'!D6, '06-2024'!D6) -> 0 | E6: =C6-D6 -> 0 | F6: =IFERROR(E6/D6, 0) -> 0 | G6: =SUM('04-2024'!G6, '05-2024'!G6, '06-2024'!G6) -> 0 | H6: =C6-G6 -> 0 | I6: =IFERROR(H6/G6, 0) -> 0
A7: French River 2 | B7: MA | C7: =SUM('04-2024'!C7, '05-2024'!C7, '06-2024'!C7) -> 0 | D7: =SUM('04-2024'!D7, '05-2024'!D7, '06-2024'!D7) -> 0 | E7: =C7-D7 -> 0 | F7: =IFERROR(E7/D7, 0) -> 0 | G7: =SUM('04-2024'!G7, '05-2024'!G7, '06-2024'!G7) -> 0 | H7: =C7-G7 -> 0 | I7: =IFERROR(H7/G7, 0) -> 0
A8: French River 3 | B8: MA | C8: =SUM('04-2024'!C8, '05-2024'!C8, '06-2024'!C8) -> 0 | D8: =SUM('04-2024'!D8, '05-2024'!D8, '06-2024'!D8) -> 0 | E8: =C8-D8 -> 0 | F8: =IFERROR(E8/D8, 0) -> 0 | G8: =SUM('04-2024'!G8, '05-2024'!G8, '06-2024'!G8) -> 0 | H8: =C8-G8 -> 0 | I8: =IFERROR(H8/G8, 0) -> 0
A9: French River 4 | B9: MA | C9: =SUM('04-2024'!C9, '05-2024'!C9, '06-2024'!C9) -> 0 | D9: =SUM('04-2024'!D9, '05-2024'!D9, '06-2024'!D9) -> 0 | E9: =C9-D9 -> 0 | F9: =IFERROR(E9/D9, 0) -> 0 | G9: =SUM('04-2024'!G9, '05-2024'!G9, '06-2024'!G9) -> 0 | H9: =C9-G9 -> 0 | I9: =IFERROR(H9/G9, 0) -> 0
A10: French River 5 | B10: MA | C10: =SUM('04-2024'!C10, '05-2024'!C10, '06-2024'!C10) -> 0 | D10: =SUM('04-2024'!D10, '05-2024'!D10, '06-2024'!D10) -> 0 | E10: =C10-D10 -> 0 | F10: =IFERROR(E10/D10, 0) -> 0 | G10: =SUM('04-2024'!G10, '05-2024'!G10, '06-2024'!G10) -> 0 | H10: =C10-G10 -> 0 | I10: =IFERROR(H10/G10, 0) -> 0
A11: French River 6 | B11: MA | C11: =SUM('04-2024'!C11, '05-2024'!C11, '06-2024'!C11) -> 0 | D11: =SUM('04-2024'!D11, '05-2024'!D11, '06-2024'!D11) -> 0 | E11: =C11-D11 -> 0 | F11: =IFERROR(E11/D11, 0) -> 0 | G11: =SUM('04-2024'!G11, '05-2024'!G11, '06-2024'!G11) -> 0 | H11: =C11-G11 -> 0 | I11: =IFERROR(H11/G11, 0) -> 0
A12: Stillwater River 1A | B12: MA | C12: =SUM('04-2024'!C12, '05-2024'!C12, '06-2024'!C12) -> 0 | D12: =SUM('04-2024'!D12, '05-2024'!D12, '06-2024'!D12) -> 0 | E12: =C12-D12 -> 0 | F12: =IFERROR(E12/D12, 0) -> 0 | G12: =SUM('04-2024'!G12, '05-2024'!G12, '06-2024'!G12) -> 0 | H12: =C12-G12 -> 0 | I12: =IFERROR(H12/G12, 0) -> 0
A13: Stillwater River 2 | B13: MA | C13: =SUM('04-2024'!C13, '05-2024'!C13, '06-2024'!C13) -> 0 | D13: =SUM('04-2024'!D13, '05-2024'!D13, '06-2024'!D13) -> 0 | E13: =C13-D13 -> 0 | F13: =IFERROR(E13/D13, 0) -> 0 | G13: =SUM('04-2024'!G13, '05-2024'!G13, '06-2024'!G13) -> 0 | H13: =C13-G13 -> 0 | I13: =IFERROR(H13/G13, 0) -> 0
A14: Stillwater River 3 | B14: MA | C14: =SUM('04-2024'!C14, '05-2024'!C14, '06-2024'!C14) -> 0 | D14: =SUM('04-2024'!D14, '05-2024'!D14, '06-2024'!D14) -> 0 | E14: =C14-D14 -> 0 | F14: =IFERROR(E14/D14, 0) -> 0 | G14: =SUM('04-2024'!G14, '05-2024'!G14, '06-2024'!G14) -> 0 | H14: =C14-G14 -> 0 | I14: =IFERROR(H14/G14, 0) -> 0
A15: Stillwater River 4 | B15: MA | C15: =SUM('04-2024'!C15, '05-2024'!C15, '06-2024'!C15) -> 0 | D15: =SUM('04-2024'!D15, '05-2024'!D15, '06-2024'!D15) -> 0 | E15: =C15-D15 -> 0 | F15: =IFERROR(E15/D15, 0) -> 0 | G15: =SUM('04-2024'!G15, '05-2024'!G15, '06-2024'!G15) -> 0 | H15: =C15-G15 -> 0 | I15: =IFERROR(H15/G15, 0) -> 0
A16: Total | C16: =SUM(C3:C15) -> 0 | D16: =SUM(D3:D15) -> 0 | E16: =C16-D16 -> 0 | F16: =IFERROR(E16/D16, 0) -> 0 | G16: =SUM(G3:G15) -> 0 | H16: =C16-G16 -> 0 | I16: =IFERROR(H16/G16, 0) -> 0
A18: Values in gold exceed expected or forecasted by 10% or more.
A20: Values in red are below expected or forecasted by 10% or more.

Sheet 3rd Quarter 2024
A1: {=portfolio} -> MN8 Bond | C1: 3rd Quarter 2024 Actual v. Expected | G1: 3rd Quarter 2024 Forecasted | J1: NOTES | K1: SR
A2: Site | B2: State | C2: Actual | D2: Expected | E2: Delta | F2: % | G2: Forecasted | H2: Delta | I2: %
A3: {=Sites[Site]} -> Grafton II | B3: {=Sites[State]} -> MA | C3: =SUM('07-2024'!C3, '08-2024'!C3, '09-2024'!C3) -> 0 | D3: =SUM('07-2024'!D3, '08-2024'!D3, '09-2024'!D3) -> 0 | E3: =C3-D3 -> 0 | F3: =IFERROR(E3/D3, 0) -> 0 | G3: =SUM('07-2024'!G3, '08-2024'!G3, '09-2024'!G3) -> 0 | H3: =C3-G3 -> 0 | I3: =IFERROR(H3/G3, 0) -> 0
A4: Clara Barton | B4: MA | C4: =SUM('07-2024'!C4, '08-2024'!C4, '09-2024'!C4) -> 0 | D4: =SUM('07-2024'!D4, '08-2024'!D4, '09-2024'!D4) -> 0 | E4: =C4-D4 -> 0 | F4: =IFERROR(E4/D4, 0) -> 0 | G4: =SUM('07-2024'!G4, '08-2024'!G4, '09-2024'!G4) -> 0 | H4: =C4-G4 -> 0 | I4: =IFERROR(H4/G4, 0) -> 0
A5: Fairhaven Solar | B5: MA | C5: =SUM('07-2024'!C5, '08-2024'!C5, '09-2024'!C5) -> 0 | D5: =SUM('07-2024'!D5, '08-2024'!D5, '09-2024'!D5) -> 0 | E5: =C5-D5 -> 0 | F5: =IFERROR(E5/D5, 0) -> 0 | G5: =SUM('07-2024'!G5, '08-2024'!G5, '09-2024'!G5) -> 0 | H5: =C5-G5 -> 0 | I5: =IFERROR(H5/G5, 0) -> 0
A6: Plympton-1 | B6: MA | C6: =SUM('07-2024'!C6, '08-2024'!C6, '09-2024'!C6) -> 0 | D6: =SUM('07-2024'!D6, '08-2024'!D6, '09-2024'!D6) -> 0 | E6: =C6-D6 -> 0 | F6: =IFERROR(E6/D6, 0) -> 0 | G6: =SUM('07-2024'!G6, '08-2024'!G6, '09-2024'!G6) -> 0 | H6: =C6-G6 -> 0 | I6: =IFERROR(H6/G6, 0) -> 0
A7: French River 2 | B7: MA | C7: =SUM('07-2024'!C7, '08-2024'!C7, '09-2024'!C7) -> 0 | D7: =SUM('07-2024'!D7, '08-2024'!D7, '09-2024'!D7) -> 0 | E7: =C7-D7 -> 0 | F7: =IFERROR(E7/D7, 0) -> 0 | G7: =SUM('07-2024'!G7, '08-2024'!G7, '09-2024'!G7) -> 0 | H7: =C7-G7 -> 0 | I7: =IFERROR(H7/G7, 0) -> 0
A8: French River 3 | B8: MA | C8: =SUM('07-2024'!C8, '08-2024'!C8, '09-2024'!C8) -> 0 | D8: =SUM('07-2024'!D8, '08-2024'!D8, '09-2024'!D8) -> 0 | E8: =C8-D8 -> 0 | F8: =IFERROR(E8/D8, 0) -> 0 | G8: =SUM('07-2024'!G8, '08-2024'!G8, '09-2024'!G8) -> 0 | H8: =C8-G8 -> 0 | I8: =IFERROR(H8/G8, 0) -> 0
A9: French River 4 | B9: MA | C9: =SUM('07-2024'!C9, '08-2024'!C9, '09-2024'!C9) -> 0 | D9: =SUM('07-2024'!D9, '08-2024'!D9, '09-2024'!D9) -> 0 | E9: =C9-D9 -> 0 | F9: =IFERROR(E9/D9, 0) -> 0 | G9: =SUM('07-2024'!G9, '08-2024'!G9, '09-2024'!G9) -> 0 | H9: =C9-G9 -> 0 | I9: =IFERROR(H9/G9, 0) -> 0
A10: French River 5 | B10: MA | C10: =SUM('07-2024'!C10, '08-2024'!C10, '09-2024'!C10) -> 0 | D10: =SUM('07-2024'!D10, '08-2024'!D10, '09-2024'!D10) -> 0 | E10: =C10-D10 -> 0 | F10: =IFERROR(E10/D10, 0) -> 0 | G10: =SUM('07-2024'!G10, '08-2024'!G10, '09-2024'!G10) -> 0 | H10: =C10-G10 -> 0 | I10: =IFERROR(H10/G10, 0) -> 0
A11: French River 6 | B11: MA | C11: =SUM('07-2024'!C11, '08-2024'!C11, '09-2024'!C11) -> 0 | D11: =SUM('07-2024'!D11, '08-2024'!D11, '09-2024'!D11) -> 0 | E11: =C11-D11 -> 0 | F11: =IFERROR(E11/D11, 0) -> 0 | G11: =SUM('07-2024'!G11, '08-2024'!G11, '09-2024'!G11) -> 0 | H11: =C11-G11 -> 0 | I11: =IFERROR(H11/G11, 0) -> 0
A12: Stillwater River 1A | B12: MA | C12: =SUM('07-2024'!C12, '08-2024'!C12, '09-2024'!C12) -> 0 | D12: =SUM('07-2024'!D12, '08-2024'!D12, '09-2024'!D12) -> 0 | E12: =C12-D12 -> 0 | F12: =IFERROR(E12/D12, 0) -> 0 | G12: =SUM('07-2024'!G12, '08-2024'!G12, '09-2024'!G12) -> 0 | H12: =C12-G12 -> 0 | I12: =IFERROR(H12/G12, 0) -> 0
A13: Stillwater River 2 | B13: MA | C13: =SUM('07-2024'!C13, '08-2024'!C13, '09-2024'!C13) -> 0 | D13: =SUM('07-2024'!D13, '08-2024'!D13, '09-2024'!D13) -> 0 | E13: =C13-D13 -> 0 | F13: =IFERROR(E13/D13, 0) -> 0 | G13: =SUM('07-2024'!G13, '08-2024'!G13, '09-2024'!G13) -> 0 | H13: =C13-G13 -> 0 | I13: =IFERROR(H13/G13, 0) -> 0
A14: Stillwater River 3 | B14: MA | C14: =SUM('07-2024'!C14, '08-2024'!C14, '09-2024'!C14) -> 0 | D14: =SUM('07-2024'!D14, '08-2024'!D14, '09-2024'!D14) -> 0 | E14: =C14-D14 -> 0 | F14: =IFERROR(E14/D14, 0) -> 0 | G14: =SUM('07-2024'!G14, '08-2024'!G14, '09-2024'!G14) -> 0 | H14: =C14-G14 -> 0 | I14: =IFERROR(H14/G14, 0) -> 0
A15: Stillwater River 4 | B15: MA | C15: =SUM('07-2024'!C15, '08-2024'!C15, '09-2024'!C15) -> 0 | D15: =SUM('07-2024'!D15, '08-2024'!D15, '09-2024'!D15) -> 0 | E15: =C15-D15 -> 0 | F15: =IFERROR(E15/D15, 0) -> 0 | G15: =SUM('07-2024'!G15, '08-2024'!G15, '09-2024'!G15) -> 0 | H15: =C15-G15 -> 0 | I15: =IFERROR(H15/G15, 0) -> 0
A16: Total | C16: =SUM(C3:C15) -> 0 | D16: =SUM(D3:D15) -> 0 | E16: =C16-D16 -> 0 | F16: =IFERROR(E16/D16, 0) -> 0 | G16: =SUM(G3:G15) -> 0 | H16: =C16-G16 -> 0 | I16: =IFERROR(H16/G16, 0) -> 0
A18: Values in gold exceed expected or forecasted by 10% or more.
A20: Values in red are below expected or forecasted by 10% or more.

Sheet 4th Quarter 2024
A1: {=portfolio} -> MN8 Bond | C1: 4th Quarter 2024 Actual v. Expected | G1: 4th Quarter 2024 Forecasted | J1: NOTES | K1: SR
A2: Site | B2: State | C2: Actual | D2: Expected | E2: Delta | F2: % | G2: Forecasted | H2: Delta | I2: %
A3: {=Sites[Site]} -> Grafton II | B3: {=Sites[State]} -> MA | C3: =SUM('10-2024'!C3, '11-2024'!C3, '12-2024'!C3) -> 0 | D3: =SUM('10-2024'!D3, '11-2024'!D3, '12-2024'!D3) -> 0 | E3: =C3-D3 -> 0 | F3: =IFERROR(E3/C3, 0) -> 0 | G3: =SUM('10-2024'!G3, '11-2024'!G3, '12-2024'!G3) -> 0 | H3: =F3-G3 -> 0 | I3: =IFERROR(H3/F3, 0) -> 0
A4: Clara Barton | B4: MA | C4: =SUM('10-2024'!C4, '11-2024'!C4, '12-2024'!C4) -> 0 | D4: =SUM('10-2024'!D4, '11-2024'!D4, '12-2024'!D4) -> 0 | E4: =C4-D4 -> 0 | F4: =IFERROR(E4/C4, 0) -> 0 | G4: =SUM('10-2024'!G4, '11-2024'!G4, '12-2024'!G4) -> 0 | H4: =F4-G4 -> 0 | I4: =IFERROR(H4/F4, 0) -> 0
A5: Fairhaven Solar | B5: MA | C5: =SUM('10-2024'!C5, '11-2024'!C5, '12-2024'!C5) -> 0 | D5: =SUM('10-2024'!D5, '11-2024'!D5, '12-2024'!D5) -> 0 | E5: =C5-D5 -> 0 | F5: =IFERROR(E5/C5, 0) -> 0 | G5: =SUM('10-2024'!G5, '11-2024'!G5, '12-2024'!G5) -> 0 | H5: =F5-G5 -> 0 | I5: =IFERROR(H5/F5, 0) -> 0
A6: Plympton-1 | B6: MA | C6: =SUM('10-2024'!C6, '11-2024'!C6, '12-2024'!C6) -> 0 | D6: =SUM('10-2024'!D6, '11-2024'!D6, '12-2024'!D6) -> 0 | E6: =C6-D6 -> 0 | F6: =IFERROR(E6/C6, 0) -> 0 | G6: =SUM('10-2024'!G6, '11-2024'!G6, '12-2024'!G6) -> 0 | H6: =F6-G6 -> 0 | I6: =IFERROR(H6/F6, 0) -> 0
A7: French River 2 | B7: MA | C7: =SUM('10-2024'!C7, '11-2024'!C7, '12-2024'!C7) -> 0 | D7: =SUM('10-2024'!D7, '11-2024'!D7, '12-2024'!D7) -> 0 | E7: =C7-D7 -> 0 | F7: =IFERROR(E7/C7, 0) -> 0 | G7: =SUM('10-2024'!G7, '11-2024'!G7, '12-2024'!G7) -> 0 | H7: =F7-G7 -> 0 | I7: =IFERROR(H7/F7, 0) -> 0
A8: French River 3 | B8: MA | C8: =SUM('10-2024'!C8, '11-2024'!C8, '12-2024'!C8) -> 0 | D8: =SUM('10-2024'!D8, '11-2024'!D8, '12-2024'!D8) -> 0 | E8: =C8-D8 -> 0 | F8: =IFERROR(E8/C8, 0) -> 0 | G8: =SUM('10-2024'!G8, '11-2024'!G8, '12-2024'!G8) -> 0 | H8: =F8-G8 -> 0 | I8: =IFERROR(H8/F8, 0) -> 0
A9: French River 4 | B9: MA | C9: =SUM('10-2024'!C9, '11-2024'!C9, '12-2024'!C9) -> 0 | D9: =SUM('10-2024'!D9, '11-2024'!D9, '12-2024'!D9) -> 0 | E9: =C9-D9 -> 0 | F9: =IFERROR(E9/C9, 0) -> 0 | G9: =SUM('10-2024'!G9, '11-2024'!G9, '12-2024'!G9) -> 0 | H9: =F9-G9 -> 0 | I9: =IFERROR(H9/F9, 0) -> 0
A10: French River 5 | B10: MA | C10: =SUM('10-2024'!C10, '11-2024'!C10, '12-2024'!C10) -> 0 | D10: =SUM('10-2024'!D10, '11-2024'!D10, '12-2024'!D10) -> 0 | E10: =C10-D10 -> 0 | F10: =IFERROR(E10/C10, 0) -> 0 | G10: =SUM('10-2024'!G10, '11-2024'!G10, '12-2024'!G10) -> 0 | H10: =F10-G10 -> 0 | I10: =IFERROR(H10/F10, 0) -> 0
A11: French River 6 | B11: MA | C11: =SUM('10-2024'!C11, '11-2024'!C11, '12-2024'!C11) -> 0 | D11: =SUM('10-2024'!D11, '11-2024'!D11, '12-2024'!D11) -> 0 | E11: =C11-D11 -> 0 | F11: =IFERROR(E11/C11, 0) -> 0 | G11: =SUM('10-2024'!G11, '11-2024'!G11, '12-2024'!G11) -> 0 | H11: =F11-G11 -> 0 | I11: =IFERROR(H11/F11, 0) -> 0
A12: Stillwater River 1A | B12: MA | C12: =SUM('10-2024'!C12, '11-2024'!C12, '12-2024'!C12) -> 0 | D12: =SUM('10-2024'!D12, '11-2024'!D12, '12-2024'!D12) -> 0 | E12: =C12-D12 -> 0 | F12: =IFERROR(E12/C12, 0) -> 0 | G12: =SUM('10-2024'!G12, '11-2024'!G12, '12-2024'!G12) -> 0 | H12: =F12-G12 -> 0 | I12: =IFERROR(H12/F12, 0) -> 0
A13: Stillwater River 2 | B13: MA | C13: =SUM('10-2024'!C13, '11-2024'!C13, '12-2024'!C13) -> 0 | D13: =SUM('10-2024'!D13, '11-2024'!D13, '12-2024'!D13) -> 0 | E13: =C13-D13 -> 0 | F13: =IFERROR(E13/C13, 0) -> 0 | G13: =SUM('10-2024'!G13, '11-2024'!G13, '12-2024'!G13) -> 0 | H13: =F13-G13 -> 0 | I13: =IFERROR(H13/F13, 0) -> 0
A14: Stillwater River 3 | B14: MA | C14: =SUM('10-2024'!C14, '11-2024'!C14, '12-2024'!C14) -> 0 | D14: =SUM('10-2024'!D14, '11-2024'!D14, '12-2024'!D14) -> 0 | E14: =C14-D14 -> 0 | F14: =IFERROR(E14/C14, 0) -> 0 | G14: =SUM('10-2024'!G14, '11-2024'!G14, '12-2024'!G14) -> 0 | H14: =F14-G14 -> 0 | I14: =IFERROR(H14/F14, 0) -> 0
A15: Stillwater River 4 | B15: MA | C15: =SUM('10-2024'!C15, '11-2024'!C15, '12-2024'!C15) -> 0 | D15: =SUM('10-2024'!D15, '11-2024'!D15, '12-2024'!D15) -> 0 | E15: =C15-D15 -> 0 | F15: =IFERROR(E15/C15, 0) -> 0 | G15: =SUM('10-2024'!G15, '11-2024'!G15, '12-2024'!G15) -> 0 | H15: =F15-G15 -> 0 | I15: =IFERROR(H15/F15, 0) -> 0
A16: Total | C16: =SUM(C3:C15) -> 0 | D16: =SUM(D3:D15) -> 0 | E16: =C16-D16 -> 0 | F16: =IFERROR(E16/D16, 0) -> 0 | G16: =SUM(G3:G15) -> 0 | H16: =C16-G16 -> 0 | I16: =IFERROR(H16/G16, 0) -> 0
A18: Values in gold exceed expected or forecasted by 10% or more.
A20: Values in red are below expected or forecasted by 10% or more.

Sheet 01-2024
A1: {=portfolio} -> MN8 Bond | C1: 01-2024 Actual v. Expected | G1: 01-2024 Actual v. Forecasted | J1: NOTES | K1: SR
A2: Site | B2: State | C2: Actual | D2: Expected | E2: Delta | F2: % | G2: Forecasted | H2: Delta | I2: %
A3: {=Sites[Site]} -> Grafton II | B3: {=Sites[State]} -> MA | C3: {=IF(INDIRECT("'" & $A3 & "'!B5:J5")="", "", INDIRECT("'" & $A3 & "'!B5:J5"))} -> 108788.84 | D3: 176557 | E3: -67768.159 | F3: -0.38383162 | G3: 245116 | H3: -136327.16 | I3: -0.55617405 | J3: 1. Site tripped offline on 01/10 at 13:15 and later back online on 01/11 at 11:45AM. 2. Inverter 5.6B was did not came back online after site re-enerziation 01/11 at and later back online on 01/12 at 09:15AM. 3. Inverters 5.7B, 6.2B, and 6.5B are offline from 01/25 and later 5.7B is back online on 01/30 at 09:00AM | K3: 1. SR080136 2. SR080158 3. SR080474
A4: Clara Barton | B4: MA | C4: {=IF(INDIRECT("'" & $A4 & "'!B5:J5")="", "", INDIRECT("'" & $A4 & "'!B5:J5"))} -> 41686.145 | D4: 61398.72 | E4: -19712.575 | F4: -0.32105841 | G4: 84576.48 | H4: -42890.335 | I4: -0.50711895 | J4: 1. Inverter 5.8 has tripped offline on 01/17 at 12:00 and back oline on 01/17 at 15:00. 2. Site tripped offline on 01/26 at 18:45 and back online on 01/27 at 10:45AM | K4: 1. SR080289 2. SR080520
A5: Fairhaven Solar | B5: MA | C5: {=IF(INDIRECT("'" & $A5 & "'!B5:J5")="", "", INDIRECT("'" & $A5 & "'!B5:J5"))} -> 55436 | D5: 67352.87 | E5: -11916.87 | F5: -0.17693188 | G5: 63727.01 | H5: -8291.01 | I5: -0.13010198 | J5: 1. Inverter 3 is offline on 01/11 after site is re-energized later back online on 01/11 at 13:30. 2. Inverters 1,4 12, 25, 28, 29 & 49 offline on 01/15 from 07:00AM and later back online on 01/17 at 11:15AM. 3. Site was tripped offline on 01/11 at 07:00 and back online 11:45 | K5: 1. SR080159 2. SR080243 1. SR080152
A6: Plympton-1 | B6: MA | C6: {=IF(INDIRECT("'" & $A6 & "'!B5:J5")="", "", INDIRECT("'" & $A6 & "'!B5:J5"))} -> 67619 | D6: 73871.03 | E6: -6252.03 | F6: -0.084634396 | G6: 79420.95 | H6: -11801.95 | I6: -0.14859996
A7: French River 2 | B7: MA | C7: {=IF(INDIRECT("'" & $A7 & "'!B5:J5")="", "", INDIRECT("'" & $A7 & "'!B5:J5"))} -> 41541.11 | D7: 80016.27 | E7: -38475.16 | F7: -0.48084171 | G7: 78833 | H7: -37291.89 | I7: -0.47304923 | J7: 01. Site was tripped offline on 01/26 at 18:00 and back online at 01/27 at 8:00 AM. | K7: 1. SR080519
A8: French River 3 | B8: MA | C8: {=IF(INDIRECT("'" & $A8 & "'!B5:J5")="", "", INDIRECT("'" & $A8 & "'!B5:J5"))} -> 86149.12 | D8: 150506.8 | E8: -64357.68 | F8: -0.42760646 | G8: 151308.7 | H8: -65159.58 | I8: -0.43064001 | J8: 01. Site was tripped offline on 01/26 at 18:00 and back online at 01/27 at 8:00 AM. | K8: 1. SR080519
A9: French River 4 | B9: MA | C9: {=IF(INDIRECT("'" & $A9 & "'!B5:J5")="", "", INDIRECT("'" & $A9 & "'!B5:J5"))} -> 85549.466 | D9: 154184.8 | E9: -68635.334 | F9: -0.4451498 | G9: 157760 | H9: -72210.534 | I9: -0.45772397 | J9: 01. Site was tripped offline on 01/26 at 18:00 and back online at 01/27 at 8:00 AM. | K9: 1. SR080519
A10: French River 5 | B10: MA | C10: {=IF(INDIRECT("'" & $A10 & "'!B5:J5")="", "", INDIRECT("'" & $A10 & "'!B5:J5"))} -> 83292.5 | D10: 147678.6 | E10: -64386.1 | F10: -0.43598802 | G10: 154754.9 | H10: -71462.4 | I10: -0.46177795 | J10: 1. Inverter 62 is offline on 01/14 and later back online on 01/15 2. Site was tripped offline on 01/26 at 18:00 and back online at 01/27 at 8:00 AM. | K10: 1. SR080199 2. SR080519
A11: French River 6 | B11: MA | C11: {=IF(INDIRECT("'" & $A11 & "'!B5:J5")="", "", INDIRECT("'" & $A11 & "'!B5:J5"))} -> 78703 | D11: 125159 | E11: -46456 | F11: -0.37117586 | G11: 148483.1 | H11: -69780.1 | I11: -0.46995315 | J11: 1. Inverter 41B is offline on 01/13 and later back online 01/14. 2. Inverter 62B is offline on 01/14 and later back online on 01/15. 3. Inverters 60 and 62 are tripped offline on 01/22 at 14:00, later 62B is back online on 01/23 at 07:00AM and 60B have multiple tripping events. 4. Site was tripped offline on 01/26 at 18:00 and back online at 01/27 at 8:00 AM. | K11: 1. SR080195 2. SR080198 3. SR080402 4. SR080519
A12: Stillwater River 1A | B12: MA | C12: {=IF(INDIRECT("'" & $A12 & "'!B5:J5")="", "", INDIRECT("'" & $A12 & "'!B5:J5"))} -> 21302 | D12: 36938.76 | E12: -15636.76 | F12: -0.42331578 | G12: 38086.07 | H12: -16784.07 | I12: -0.44068789 | J12: 01. Site was tripped offline on 01/26 at 18:00 and back online at 01/27 at 8:00 AM. | K12: 1. SR080519
A13: Stillwater River 2 | B13: MA | C13: {=IF(INDIRECT("'" & $A13 & "'!B5:J5")="", "", INDIRECT("'" & $A13 & "'!B5:J5"))} -> 44604.12 | D13: 82849.68 | E13: -38245.56 | F13: -0.46162592 | G13: 79775.59 | H13: -35171.47 | I13: -0.4408801 | J13: 01. Site was tripped offline on 01/26 at 18:00 and back online at 01/27 at 8:00 AM. | K13: 1. SR080519
A14: Stillwater River 3 | B14: MA | C14: {=IF(INDIRECT("'" & $A14 & "'!B5:J5")="", "", INDIRECT("'" & $A14 & "'!B5:J5"))} -> 44552 | D14: 81817.76 | E14: -37265.76 | F14: -0.45547275 | G14: 78530.19 | H14: -33978.19 | I14: -0.43267678 | J14: 01. Site was tripped offline on 01/26 at 18:00 and back online at 01/27 at 8:00 AM. | K14: 1. SR080519
A15: Stillwater River 4 | B15: MA | C15: {=IF(INDIRECT("'" & $A15 & "'!B5:J5")="", "", INDIRECT("'" & $A15 & "'!B5:J5"))} -> 18009.312 | D15: 32813.84 | E15: -14804.527 | F15: -0.45116718 | G15: 35648.47 | H15: -17639.158 | I15: -0.49480826 | J15: 01. Site was tripped offline on 01/26 at 18:00 and back online at 01/27 at 8:00 AM. | K15: 1. SR080519
A16: Total | C16: =SUM(C3:C15) -> 777232.61 | D16: =SUM(D3:D15) -> 1271145.1 | E16: =C16-D16 -> -493912.52 | F16: =IFERROR(E16/D16, 0) -> -0.38855714 | G16: =SUM(G3:G15) -> 1396020.5 | H16: =C16-G16 -> -618787.85 | I16: =IFERROR(H16/G16, 0) -> -0.44325127
A18: Values in gold exceed expected or forecasted by 10% or more.
A20: Values in red are below expected or forecasted by 10% or more.

Sheet 02-2024
A1: {=portfolio} -> MN8 Bond | C1: 02-2024 Actual v. Expected | G1: 02-2024 Actual v. Forecasted | J1: NOTES | K1: SR
A2: Site | B2: State | C2: Actual | D2: Expected | E2: Delta | F2: % | G2: Forecasted | H2: Delta | I2: %
A3: {=Sites[Site]} -> Grafton II | B3: {=Sites[State]} -> MA | C3: {=IF(INDIRECT("'" & $A3 & "'!B6:J6")="", "", INDIRECT("'" & $A3 & "'!B6:J6"))} | E3: 0 | F3: 0 | H3: 0 | I3: 0
A4: Clara Barton | B4: MA | C4: {=IF(INDIRECT("'" & $A4 & "'!B6:J6")="", "", INDIRECT("'" & $A4 & "'!B6:J6"))} | E4: 0 | F4: 0 | H4: 0 | I4: 0
A5: Fairhaven Solar | B5: MA | C5: {=IF(INDIRECT("'" & $A5 & "'!B6:J6")="", "", INDIRECT("'" & $A5 & "'!B6:J6"))} | E5: 0 | F5: 0 | H5: 0 | I5: 0
A6: Plympton-1 | B6: MA | C6: {=IF(INDIRECT("'" & $A6 & "'!B6:J6")="", "", INDIRECT("'" & $A6 & "'!B6:J6"))} | E6: 0 | F6: 0 | H6: 0 | I6: 0
A7: French River 2 | B7: MA | C7: {=IF(INDIRECT("'" & $A7 & "'!B6:J6")="", "", INDIRECT("'" & $A7 & "'!B6:J6"))} | E7: 0 | F7: 0 | H7: 0 | I7: 0
A8: French River 3 | B8: MA | C8: {=IF(INDIRECT("'" & $A8 & "'!B6:J6")="", "", INDIRECT("'" & $A8 & "'!B6:J6"))} | E8: 0 | F8: 0 | H8: 0 | I8: 0
A9: French River 4 | B9: MA | C9: {=IF(INDIRECT("'" & $A9 & "'!B6:J6")="", "", INDIRECT("'" & $A9 & "'!B6:J6"))} | E9: 0 | F9: 0 | H9: 0 | I9: 0
A10: French River 5 | B10: MA | C10: {=IF(INDIRECT("'" & $A10 & "'!B6:J6")="", "", INDIRECT("'" & $A10 & "'!B6:J6"))} | E10: 0 | F10: 0 | H10: 0 | I10: 0
A11: French River 6 | B11: MA | C11: {=IF(INDIRECT("'" & $A11 & "'!B6:J6")="", "", INDIRECT("'" & $A11 & "'!B6:J6"))} | E11: 0 | F11: 0 | H11: 0 | I11: 0
A12: Stillwater River 1A | B12: MA | C12: {=IF(INDIRECT("'" & $A12 & "'!B6:J6")="", "", INDIRECT("'" & $A12 & "'!B6:J6"))} | E12: 0 | F12: 0 | H12: 0 | I12: 0
A13: Stillwater River 2 | B13: MA | C13: {=IF(INDIRECT("'" & $A13 & "'!B6:J6")="", "", INDIRECT("'" & $A13 & "'!B6:J6"))} | E13: 0 | F13: 0 | H13: 0 | I13: 0
A14: Stillwater River 3 | B14: MA | C14: {=IF(INDIRECT("'" & $A14 & "'!B6:J6")="", "", INDIRECT("'" & $A14 & "'!B6:J6"))} | E14: 0 | F14: 0 | H14: 0 | I14: 0
A15: Stillwater River 4 | B15: MA | C15: {=IF(INDIRECT("'" & $A15 & "'!B6:J6")="", "", INDIRECT("'" & $A15 & "'!B6:J6"))} | E15: 0 | F15: 0 | H15: 0 | I15: 0
A16: Total | C16: =SUM(C3:C15) -> 0 | D16: =SUM(D3:D15) -> 0 | E16: =C16-D16 -> 0 | F16: =IFERROR(E16/D16, 0) -> 0 | G16: =SUM(G3:G15) -> 0 | H16: =C16-G16 -> 0 | I16: =IFERROR(H16/G16, 0) -> 0
A18: Values in gold exceed expected or forecasted by 10% or more.
A20: Values in red are below expected or forecasted by 10% or more.

Sheet 03-2024
A1: {=portfolio} -> MN8 Bond | C1: 03-2024 Actual v. Expected | G1: 03-2024 Actual v. Forecasted | J1: NOTES | K1: SR
A2: Site | B2: State | C2: Actual | D2: Expected | E2: Delta | F2: % | G2: Forecasted | H2: Delta | I2: %
A3: {=Sites[Site]} -> Grafton II | B3: {=Sites[State]} -> MA | C3: {=IF(INDIRECT("'" & $A3 & "'!B7:J7")="", "", INDIRECT("'" & $A3 & "'!B7:J7"))} | E3: 0 | F3: 0 | H3: 0 | I3: 0
A4: Clara Barton | B4: MA | C4: {=IF(INDIRECT("'" & $A4 & "'!B7:J7")="", "", INDIRECT("'" & $A4 & "'!B7:J7"))} | E4: 0 | F4: 0 | H4: 0 | I4: 0
A5: Fairhaven Solar | B5: MA | C5: {=IF(INDIRECT("'" & $A5 & "'!B7:J7")="", "", INDIRECT("'" & $A5 & "'!B7:J7"))} | E5: 0 | F5: 0 | H5: 0 | I5: 0
A6: Plympton-1 | B6: MA | C6: {=IF(INDIRECT("'" & $A6 & "'!B7:J7")="", "", INDIRECT("'" & $A6 & "'!B7:J7"))} | E6: 0 | F6: 0 | H6: 0 | I6: 0
A7: French River 2 | B7: MA | C7: {=IF(INDIRECT("'" & $A7 & "'!B7:J7")="", "", INDIRECT("'" & $A7 & "'!B7:J7"))} | E7: 0 | F7: 0 | H7: 0 | I7: 0
A8: French River 3 | B8: MA | C8: {=IF(INDIRECT("'" & $A8 & "'!B7:J7")="", "", INDIRECT("'" & $A8 & "'!B7:J7"))} | E8: 0 | F8: 0 | H8: 0 | I8: 0
A9: French River 4 | B9: MA | C9: {=IF(INDIRECT("'" & $A9 & "'!B7:J7")="", "", INDIRECT("'" & $A9 & "'!B7:J7"))} | E9: 0 | F9: 0 | H9: 0 | I9: 0
A10: French River 5 | B10: MA | C10: {=IF(INDIRECT("'" & $A10 & "'!B7:J7")="", "", INDIRECT("'" & $A10 & "'!B7:J7"))} | E10: 0 | F10: 0 | H10: 0 | I10: 0
A11: French River 6 | B11: MA | C11: {=IF(INDIRECT("'" & $A11 & "'!B7:J7")="", "", INDIRECT("'" & $A11 & "'!B7:J7"))} | E11: 0 | F11: 0 | H11: 0 | I11: 0
A12: Stillwater River 1A | B12: MA | C12: {=IF(INDIRECT("'" & $A12 & "'!B7:J7")="", "", INDIRECT("'" & $A12 & "'!B7:J7"))} | E12: 0 | F12: 0 | H12: 0 | I12: 0
A13: Stillwater River 2 | B13: MA | C13: {=IF(INDIRECT("'" & $A13 & "'!B7:J7")="", "", INDIRECT("'" & $A13 & "'!B7:J7"))} | E13: 0 | F13: 0 | H13: 0 | I13: 0
A14: Stillwater River 3 | B14: MA | C14: {=IF(INDIRECT("'" & $A14 & "'!B7:J7")="", "", INDIRECT("'" & $A14 & "'!B7:J7"))} | E14: 0 | F14: 0 | H14: 0 | I14: 0
A15: Stillwater River 4 | B15: MA | C15: {=IF(INDIRECT("'" & $A15 & "'!B7:J7")="", "", INDIRECT("'" & $A15 & "'!B7:J7"))} | E15: 0 | F15: 0 | H15: 0 | I15: 0
A16: Total | C16: =SUM(C3:C15) -> 0 | D16: =SUM(D3:D15) -> 0 | E16: =C16-D16 -> 0 | F16: =IFERROR(E16/D16, 0) -> 0 | G16: =SUM(G3:G15) -> 0 | H16: =C16-G16 -> 0 | I16: =IFERROR(H16/G16, 0) -> 0
A18: Values in gold exceed expected or forecasted by 10% or more.
A20: Values in red are below expected or forecasted by 10% or more.

Sheet 04-2024
A1: {=portfolio} -> MN8 Bond | C1: 04-2024 Actual v. Expected | G1: 04-2024 Actual v. Forecasted | J1: NOTES | K1: SR
A2: Site | B2: State | C2: Actual | D2: Expected | E2: Delta | F2: % | G2: Forecasted | H2: Delta | I2: %
A3: {=Sites[Site]} -> Grafton II | B3: {=Sites[State]} -> MA | C3: {=IF(INDIRECT("'" & $A3 & "'!B8:J8")="", "", INDIRECT("'" & $A3 & "'!B8:J8"))} | E3: 0 | F3: 0 | H3: 0 | I3: 0
A4: Clara Barton | B4: MA | C4: {=IF(INDIRECT("'" & $A4 & "'!B8:J8")="", "", INDIRECT("'" & $A4 & "'!B8:J8"))} | E4: 0 | F4: 0 | H4: 0 | I4: 0
A5: Fairhaven Solar | B5: MA | C5: {=IF(INDIRECT("'" & $A5 & "'!B8:J8")="", "", INDIRECT("'" & $A5 & "'!B8:J8"))} | E5: 0 | F5: 0 | H5: 0 | I5: 0
A6: Plympton-1 | B6: MA | C6: {=IF(INDIRECT("'" & $A6 & "'!B8:J8")="", "", INDIRECT("'" & $A6 & "'!B8:J8"))} | E6: 0 | F6: 0 | H6: 0 | I6: 0
A7: French River 2 | B7: MA | C7: {=IF(INDIRECT("'" & $A7 & "'!B8:J8")="", "", INDIRECT("'" & $A7 & "'!B8:J8"))} | E7: 0 | F7: 0 | H7: 0 | I7: 0
A8: French River 3 | B8: MA | C8: {=IF(INDIRECT("'" & $A8 & "'!B8:J8")="", "", INDIRECT("'" & $A8 & "'!B8:J8"))} | E8: 0 | F8: 0 | H8: 0 | I8: 0
A9: French River 4 | B9: MA | C9: {=IF(INDIRECT("'" & $A9 & "'!B8:J8")="", "", INDIRECT("'" & $A9 & "'!B8:J8"))} | E9: 0 | F9: 0 | H9: 0 | I9: 0
A10: French River 5 | B10: MA | C10: {=IF(INDIRECT("'" & $A10 & "'!B8:J8")="", "", INDIRECT("'" & $A10 & "'!B8:J8"))} | E10: 0 | F10: 0 | H10: 0 | I10: 0
A11: French River 6 | B11: MA | C11: {=IF(INDIRECT("'" & $A11 & "'!B8:J8")="", "", INDIRECT("'" & $A11 & "'!B8:J8"))} | E11: 0 | F11: 0 | H11: 0 | I11: 0
A12: Stillwater River 1A | B12: MA | C12: {=IF(INDIRECT("'" & $A12 & "'!B8:J8")="", "", INDIRECT("'" & $A12 & "'!B8:J8"))} | E12: 0 | F12: 0 | H12: 0 | I12: 0
A13: Stillwater River 2 | B13: MA | C13: {=IF(INDIRECT("'" & $A13 & "'!B8:J8")="", "", INDIRECT("'" & $A13 & "'!B8:J8"))} | E13: 0 | F13: 0 | H13: 0 | I13: 0
A14: Stillwater River 3 | B14: MA | C14: {=IF(INDIRECT("'" & $A14 & "'!B8:J8")="", "", INDIRECT("'" & $A14 & "'!B8:J8"))} | E14: 0 | F14: 0 | H14: 0 | I14: 0
A15: Stillwater River 4 | B15: MA | C15: {=IF(INDIRECT("'" & $A15 & "'!B8:J8")="", "", INDIRECT("'" & $A15 & "'!B8:J8"))} | E15: 0 | F15: 0 | H15: 0 | I15: 0
A16: Total | C16: =SUM(C3:C15) -> 0 | D16: =SUM(D3:D15) -> 0 | E16: =C16-D16 -> 0 | F16: =IFERROR(E16/D16, 0) -> 0 | G16: =SUM(G3:G15) -> 0 | H16: =C16-G16 -> 0 | I16: =IFERROR(H16/G16, 0) -> 0
A18: Values in gold exceed expected or forecasted by 10% or more.
A20: Values in red are below expected or forecasted by 10% or more.

Sheet 05-2024
A1: {=portfolio} -> MN8 Bond | C1: 05-2024 Actual v. Expected | G1: 05-2024 Actual v. Forecasted | J1: NOTES | K1: SR
A2: Site | B2: State | C2: Actual | D2: Expected | E2: Delta | F2: % | G2: Forecasted | H2: Delta | I2: %
A3: {=Sites[Site]} -> Grafton II | B3: {=Sites[State]} -> MA | C3: {=IF(INDIRECT("'" & $A3 & "'!B9:J9")="", "", INDIRECT("'" & $A3 & "'!B9:J9"))} | E3: 0 | F3: 0 | H3: 0 | I3: 0
A4: Clara Barton | B4: MA | C4: {=IF(INDIRECT("'" & $A4 & "'!B9:J9")="", "", INDIRECT("'" & $A4 & "'!B9:J9"))} | E4: 0 | F4: 0 | H4: 0 | I4: 0
A5: Fairhaven Solar | B5: MA | C5: {=IF(INDIRECT("'" & $A5 & "'!B9:J9")="", "", INDIRECT("'" & $A5 & "'!B9:J9"))} | E5: 0 | F5: 0 | H5: 0 | I5: 0
A6: Plympton-1 | B6: MA | C6: {=IF(INDIRECT("'" & $A6 & "'!B9:J9")="", "", INDIRECT("'" & $A6 & "'!B9:J9"))} | E6: 0 | F6: 0 | H6: 0 | I6: 0
A7: French River 2 | B7: MA | C7: {=IF(INDIRECT("'" & $A7 & "'!B9:J9")="", "", INDIRECT("'" & $A7 & "'!B9:J9"))} | E7: 0 | F7: 0 | H7: 0 | I7: 0
A8: French River 3 | B8: MA | C8: {=IF(INDIRECT("'" & $A8 & "'!B9:J9")="", "", INDIRECT("'" & $A8 & "'!B9:J9"))} | E8: 0 | F8: 0 | H8: 0 | I8: 0
A9: French River 4 | B9: MA | C9: {=IF(INDIRECT("'" & $A9 & "'!B9:J9")="", "", INDIRECT("'" & $A9 & "'!B9:J9"))} | E9: 0 | F9: 0 | H9: 0 | I9: 0
A10: French River 5 | B10: MA | C10: {=IF(INDIRECT("'" & $A10 & "'!B9:J9")="", "", INDIRECT("'" & $A10 & "'!B9:J9"))} | E10: 0 | F10: 0 | H10: 0 | I10: 0
A11: French River 6 | B11: MA | C11: {=IF(INDIRECT("'" & $A11 & "'!B9:J9")="", "", INDIRECT("'" & $A11 & "'!B9:J9"))} | E11: 0 | F11: 0 | H11: 0 | I11: 0
A12: Stillwater River 1A | B12: MA | C12: {=IF(INDIRECT("'" & $A12 & "'!B9:J9")="", "", INDIRECT("'" & $A12 & "'!B9:J9"))} | E12: 0 | F12: 0 | H12: 0 | I12: 0
A13: Stillwater River 2 | B13: MA | C13: {=IF(INDIRECT("'" & $A13 & "'!B9:J9")="", "", INDIRECT("'" & $A13 & "'!B9:J9"))} | E13: 0 | F13: 0 | H13: 0 | I13: 0
A14: Stillwater River 3 | B14: MA | C14: {=IF(INDIRECT("'" & $A14 & "'!B9:J9")="", "", INDIRECT("'" & $A14 & "'!B9:J9"))} | E14: 0 | F14: 0 | H14: 0 | I14: 0
A15: Stillwater River 4 | B15: MA | C15: {=IF(INDIRECT("'" & $A15 & "'!B9:J9")="", "", INDIRECT("'" & $A15 & "'!B9:J9"))} | E15: 0 | F15: 0 | H15: 0 | I15: 0
A16: Total | C16: =SUM(C3:C15) -> 0 | D16: =SUM(D3:D15) -> 0 | E16: =C16-D16 -> 0 | F16: =IFERROR(E16/D16, 0) -> 0 | G16: =SUM(G3:G15) -> 0 | H16: =C16-G16 -> 0 | I16: =IFERROR(H16/G16, 0) -> 0
A18: Values in gold exceed expected or forecasted by 10% or more.
A20: Values in red are below expected or forecasted by 10% or more.

Sheet 06-2024
A1: {=portfolio} -> MN8 Bond | C1: 06-2024 Actual v. Expected | G1: 06-2024 Actual v. Forecasted | J1: NOTES | K1: SR
A2: Site | B2: State | C2: Actual | D2: Expected | E2: Delta | F2: % | G2: Forecasted | H2: Delta | I2: %
A3: {=Sites[Site]} -> Grafton II | B3: {=Sites[State]} -> MA | C3: {=IF(INDIRECT("'" & $A3 & "'!B10:J10")="", "", INDIRECT("'" & $A3 & "'!B10:J10"))} | E3: 0 | F3: 0 | H3: 0 | I3: 0
A4: Clara Barton | B4: MA | C4: {=IF(INDIRECT("'" & $A4 & "'!B10:J10")="", "", INDIRECT("'" & $A4 & "'!B10:J10"))} | E4: 0 | F4: 0 | H4: 0 | I4: 0
A5: Fairhaven Solar | B5: MA | C5: {=IF(INDIRECT("'" & $A5 & "'!B10:J10")="", "", INDIRECT("'" & $A5 & "'!B10:J10"))} | E5: 0 | F5: 0 | H5: 0 | I5: 0
A6: Plympton-1 | B6: MA | C6: {=IF(INDIRECT("'" & $A6 & "'!B10:J10")="", "", INDIRECT("'" & $A6 & "'!B10:J10"))} | E6: 0 | F6: 0 | H6: 0 | I6: 0
A7: French River 2 | B7: MA | C7: {=IF(INDIRECT("'" & $A7 & "'!B10:J10")="", "", INDIRECT("'" & $A7 & "'!B10:J10"))} | E7: 0 | F7: 0 | H7: 0 | I7: 0
A8: French River 3 | B8: MA | C8: {=IF(INDIRECT("'" & $A8 & "'!B10:J10")="", "", INDIRECT("'" & $A8 & "'!B10:J10"))} | E8: 0 | F8: 0 | H8: 0 | I8: 0
A9: French River 4 | B9: MA | C9: {=IF(INDIRECT("'" & $A9 & "'!B10:J10")="", "", INDIRECT("'" & $A9 & "'!B10:J10"))} | E9: 0 | F9: 0 | H9: 0 | I9: 0
A10: French River 5 | B10: MA | C10: {=IF(INDIRECT("'" & $A10 & "'!B10:J10")="", "", INDIRECT("'" & $A10 & "'!B10:J10"))} | E10: 0 | F10: 0 | H10: 0 | I10: 0
A11: French River 6 | B11: MA | C11: {=IF(INDIRECT("'" & $A11 & "'!B10:J10")="", "", INDIRECT("'" & $A11 & "'!B10:J10"))} | E11: 0 | F11: 0 | H11: 0 | I11: 0
A12: Stillwater River 1A | B12: MA | C12: {=IF(INDIRECT("'" & $A12 & "'!B10:J10")="", "", INDIRECT("'" & $A12 & "'!B10:J10"))} | E12: 0 | F12: 0 | H12: 0 | I12: 0
A13: Stillwater River 2 | B13: MA | C13: {=IF(INDIRECT("'" & $A13 & "'!B10:J10")="", "", INDIRECT("'" & $A13 & "'!B10:J10"))} | E13: 0 | F13: 0 | H13: 0 | I13: 0
A14: Stillwater River 3 | B14: MA | C14: {=IF(INDIRECT("'" & $A14 & "'!B10:J10")="", "", INDIRECT("'" & $A14 & "'!B10:J10"))} | E14: 0 | F14: 0 | H14: 0 | I14: 0
A15: Stillwater River 4 | B15: MA | C15: {=IF(INDIRECT("'" & $A15 & "'!B10:J10")="", "", INDIRECT("'" & $A15 & "'!B10:J10"))} | E15: 0 | F15: 0 | H15: 0 | I15: 0
A16: Total | C16: =SUM(C3:C15) -> 0 | D16: =SUM(D3:D15) -> 0 | E16: =C16-D16 -> 0 | F16: =IFERROR(E16/D16, 0) -> 0 | G16: =SUM(G3:G15) -> 0 | H16: =C16-G16 -> 0 | I16: =IFERROR(H16/G16, 0) -> 0
A18: Values in gold exceed expected or forecasted by 10% or more.
A20: Values in red are below expected or forecasted by 10% or more.

Sheet 07-2024
A1: {=portfolio} -> MN8 Bond | C1: 07-2024 Actual v. Expected | G1: 07-2024 Actual v. Forecasted | J1: NOTES | K1: SR
A2: Site | B2: State | C2: Actual | D2: Expected | E2: Delta | F2: % | G2: Forecasted | H2: Delta | I2: %
A3: {=Sites[Site]} -> Grafton II | B3: {=Sites[State]} -> MA | C3: {=IF(INDIRECT("'" & $A3 & "'!B11:J11")="", "", INDIRECT("'" & $A3 & "'!B11:J11"))} | E3: 0 | F3: 0 | H3: 0 | I3: 0
A4: Clara Barton | B4: MA | C4: {=IF(INDIRECT("'" & $A4 & "'!B11:J11")="", "", INDIRECT("'" & $A4 & "'!B11:J11"))} | E4: 0 | F4: 0 | H4: 0 | I4: 0
A5: Fairhaven Solar | B5: MA | C5: {=IF(INDIRECT("'" & $A5 & "'!B11:J11")="", "", INDIRECT("'" & $A5 & "'!B11:J11"))} | E5: 0 | F5: 0 | H5: 0 | I5: 0
A6: Plympton-1 | B6: MA | C6: {=IF(INDIRECT("'" & $A6 & "'!B11:J11")="", "", INDIRECT("'" & $A6 & "'!B11:J11"))} | E6: 0 | F6: 0 | H6: 0 | I6: 0
A7: French River 2 | B7: MA | C7: {=IF(INDIRECT("'" & $A7 & "'!B11:J11")="", "", INDIRECT("'" & $A7 & "'!B11:J11"))} | E7: 0 | F7: 0 | H7: 0 | I7: 0
A8: French River 3 | B8: MA | C8: {=IF(INDIRECT("'" & $A8 & "'!B11:J11")="", "", INDIRECT("'" & $A8 & "'!B11:J11"))} | E8: 0 | F8: 0 | H8: 0 | I8: 0
A9: French River 4 | B9: MA | C9: {=IF(INDIRECT("'" & $A9 & "'!B11:J11")="", "", INDIRECT("'" & $A9 & "'!B11:J11"))} | E9: 0 | F9: 0 | H9: 0 | I9: 0
A10: French River 5 | B10: MA | C10: {=IF(INDIRECT("'" & $A10 & "'!B11:J11")="", "", INDIRECT("'" & $A10 & "'!B11:J11"))} | E10: 0 | F10: 0 | H10: 0 | I10: 0
A11: French River 6 | B11: MA | C11: {=IF(INDIRECT("'" & $A11 & "'!B11:J11")="", "", INDIRECT("'" & $A11 & "'!B11:J11"))} | E11: 0 | F11: 0 | H11: 0 | I11: 0
A12: Stillwater River 1A | B12: MA | C12: {=IF(INDIRECT("'" & $A12 & "'!B11:J11")="", "", INDIRECT("'" & $A12 & "'!B11:J11"))} | E12: 0 | F12: 0 | H12: 0 | I12: 0
A13: Stillwater River 2 | B13: MA | C13: {=IF(INDIRECT("'" & $A13 & "'!B11:J11")="", "", INDIRECT("'" & $A13 & "'!B11:J11"))} | E13: 0 | F13: 0 | H13: 0 | I13: 0
A14: Stillwater River 3 | B14: MA | C14: {=IF(INDIRECT("'" & $A14 & "'!B11:J11")="", "", INDIRECT("'" & $A14 & "'!B11:J11"))} | E14: 0 | F14: 0 | H14: 0 | I14: 0
A15: Stillwater River 4 | B15: MA | C15: {=IF(INDIRECT("'" & $A15 & "'!B11:J11")="", "", INDIRECT("'" & $A15 & "'!B11:J11"))} | E15: 0 | F15: 0 | H15: 0 | I15: 0
A16: Total | C16: =SUM(C3:C15) -> 0 | D16: =SUM(D3:D15) -> 0 | E16: =C16-D16 -> 0 | F16: =IFERROR(E16/D16, 0) -> 0 | G16: =SUM(G3:G15) -> 0 | H16: =C16-G16 -> 0 | I16: =IFERROR(H16/G16, 0) -> 0
A18: Values in gold exceed expected or forecasted by 10% or more.
A20: Values in red are below expected or forecasted by 10% or more.

Sheet 08-2024
A1: {=portfolio} -> MN8 Bond | C1: 08-2024 Actual v. Expected | G1: 08-2024 Actual v. Forecasted | J1: NOTES | K1: SR
A2: Site | B2: State | C2: Actual | D2: Expected | E2: Delta | F2: % | G2: Forecasted | H2: Delta | I2: %
A3: {=Sites[Site]} -> Grafton II | B3: {=Sites[State]} -> MA | C3: {=IF(INDIRECT("'" & $A3 & "'!B12:J12")="", "", INDIRECT("'" & $A3 & "'!B12:J12"))} | E3: 0 | F3: 0 | H3: 0 | I3: 0
A4: Clara Barton | B4: MA | C4: {=IF(INDIRECT("'" & $A4 & "'!B12:J12")="", "", INDIRECT("'" & $A4 & "'!B12:J12"))} | E4: 0 | F4: 0 | H4: 0 | I4: 0
A5: Fairhaven Solar | B5: MA | C5: {=IF(INDIRECT("'" & $A5 & "'!B12:J12")="", "", INDIRECT("'" & $A5 & "'!B12:J12"))} | E5: 0 | F5: 0 | H5: 0 | I5: 0
A6: Plympton-1 | B6: MA | C6: {=IF(INDIRECT("'" & $A6 & "'!B12:J12")="", "", INDIRECT("'" & $A6 & "'!B12:J12"))} | E6: 0 | F6: 0 | H6: 0 | I6: 0
A7: French River 2 | B7: MA | C7: {=IF(INDIRECT("'" & $A7 & "'!B12:J12")="", "", INDIRECT("'" & $A7 & "'!B12:J12"))} | E7: 0 | F7: 0 | H7: 0 | I7: 0
A8: French River 3 | B8: MA | C8: {=IF(INDIRECT("'" & $A8 & "'!B12:J12")="", "", INDIRECT("'" & $A8 & "'!B12:J12"))} | E8: 0 | F8: 0 | H8: 0 | I8: 0
A9: French River 4 | B9: MA | C9: {=IF(INDIRECT("'" & $A9 & "'!B12:J12")="", "", INDIRECT("'" & $A9 & "'!B12:J12"))} | E9: 0 | F9: 0 | H9: 0 | I9: 0
A10: French River 5 | B10: MA | C10: {=IF(INDIRECT("'" & $A10 & "'!B12:J12")="", "", INDIRECT("'" & $A10 & "'!B12:J12"))} | E10: 0 | F10: 0 | H10: 0 | I10: 0
A11: French River 6 | B11: MA | C11: {=IF(INDIRECT("'" & $A11 & "'!B12:J12")="", "", INDIRECT("'" & $A11 & "'!B12:J12"))} | E11: 0 | F11: 0 | H11: 0 | I11: 0
A12: Stillwater River 1A | B12: MA | C12: {=IF(INDIRECT("'" & $A12 & "'!B12:J12")="", "", INDIRECT("'" & $A12 & "'!B12:J12"))} | E12: 0 | F12: 0 | H12: 0 | I12: 0
A13: Stillwater River 2 | B13: MA | C13: {=IF(INDIRECT("'" & $A13 & "'!B12:J12")="", "", INDIRECT("'" & $A13 & "'!B12:J12"))} | E13: 0 | F13: 0 | H13: 0 | I13: 0
A14: Stillwater River 3 | B14: MA | C14: {=IF(INDIRECT("'" & $A14 & "'!B12:J12")="", "", INDIRECT("'" & $A14 & "'!B12:J12"))} | E14: 0 | F14: 0 | H14: 0 | I14: 0
A15: Stillwater River 4 | B15: MA | C15: {=IF(INDIRECT("'" & $A15 & "'!B12:J12")="", "", INDIRECT("'" & $A15 & "'!B12:J12"))} | E15: 0 | F15: 0 | H15: 0 | I15: 0
A16: Total | C16: =SUM(C3:C15) -> 0 | D16: =SUM(D3:D15) -> 0 | E16: =C16-D16 -> 0 | F16: =IFERROR(E16/D16, 0) -> 0 | G16: =SUM(G3:G15) -> 0 | H16: =C16-G16 -> 0 | I16: =IFERROR(H16/G16, 0) -> 0
A18: Values in gold exceed expected or forecasted by 10% or more.
A20: Values in red are below expected or forecasted by 10% or more.

Sheet 09-2024
A1: {=portfolio} -> MN8 Bond | C1: 09-2024 Actual v. Expected | G1: 09-2024 Actual v. Forecasted | J1: NOTES | K1: SR
A2: Site | B2: State | C2: Actual | D2: Expected | E2: Delta | F2: % | G2: Forecasted | H2: Delta | I2: %
A3: {=Sites[Site]} -> Grafton II | B3: {=Sites[State]} -> MA | C3: {=IF(INDIRECT("'" & $A3 & "'!B13:J13")="", "", INDIRECT("'" & $A3 & "'!B13:J13"))} | E3: 0 | F3: 0 | H3: 0 | I3: 0
A4: Clara Barton | B4: MA | C4: {=IF(INDIRECT("'" & $A4 & "'!B13:J13")="", "", INDIRECT("'" & $A4 & "'!B13:J13"))} | E4: 0 | F4: 0 | H4: 0 | I4: 0
A5: Fairhaven Solar | B5: MA | C5: {=IF(INDIRECT("'" & $A5 & "'!B13:J13")="", "", INDIRECT("'" & $A5 & "'!B13:J13"))} | E5: 0 | F5: 0 | H5: 0 | I5: 0
A6: Plympton-1 | B6: MA | C6: {=IF(INDIRECT("'" & $A6 & "'!B13:J13")="", "", INDIRECT("'" & $A6 & "'!B13:J13"))} | E6: 0 | F6: 0 | H6: 0 | I6: 0
A7: French River 2 | B7: MA | C7: {=IF(INDIRECT("'" & $A7 & "'!B13:J13")="", "", INDIRECT("'" & $A7 & "'!B13:J13"))} | E7: 0 | F7: 0 | H7: 0 | I7: 0
A8: French River 3 | B8: MA | C8: {=IF(INDIRECT("'" & $A8 & "'!B13:J13")="", "", INDIRECT("'" & $A8 & "'!B13:J13"))} | E8: 0 | F8: 0 | H8: 0 | I8: 0
A9: French River 4 | B9: MA | C9: {=IF(INDIRECT("'" & $A9 & "'!B13:J13")="", "", INDIRECT("'" & $A9 & "'!B13:J13"))} | E9: 0 | F9: 0 | H9: 0 | I9: 0
A10: French River 5 | B10: MA | C10: {=IF(INDIRECT("'" & $A10 & "'!B13:J13")="", "", INDIRECT("'" & $A10 & "'!B13:J13"))} | E10: 0 | F10: 0 | H10: 0 | I10: 0
A11: French River 6 | B11: MA | C11: {=IF(INDIRECT("'" & $A11 & "'!B13:J13")="", "", INDIRECT("'" & $A11 & "'!B13:J13"))} | E11: 0 | F11: 0 | H11: 0 | I11: 0
A12: Stillwater River 1A | B12: MA | C12: {=IF(INDIRECT("'" & $A12 & "'!B13:J13")="", "", INDIRECT("'" & $A12 & "'!B13:J13"))} | E12: 0 | F12: 0 | H12: 0 | I12: 0
A13: Stillwater River 2 | B13: MA | C13: {=IF(INDIRECT("'" & $A13 & "'!B13:J13")="", "", INDIRECT("'" & $A13 & "'!B13:J13"))} | E13: 0 | F13: 0 | H13: 0 | I13: 0
A14: Stillwater River 3 | B14: MA | C14: {=IF(INDIRECT("'" & $A14 & "'!B13:J13")="", "", INDIRECT("'" & $A14 & "'!B13:J13"))} | E14: 0 | F14: 0 | H14: 0 | I14: 0
A15: Stillwater River 4 | B15: MA | C15: {=IF(INDIRECT("'" & $A15 & "'!B13:J13")="", "", INDIRECT("'" & $A15 & "'!B13:J13"))} | E15: 0 | F15: 0 | H15: 0 | I15: 0
A16: Total | C16: =SUM(C3:C15) -> 0 | D16: =SUM(D3:D15) -> 0 | E16: =C16-D16 -> 0 | F16: =IFERROR(E16/D16, 0) -> 0 | G16: =SUM(G3:G15) -> 0 | H16: =C16-G16 -> 0 | I16: =IFERROR(H16/G16, 0) -> 0
A18: Values in gold exceed expected or forecasted by 10% or more.
A20: Values in red are below expected or forecasted by 10% or more.

Sheet 10-2024
A1: {=portfolio} -> MN8 Bond | C1: 10-2024 Actual v. Expected | G1: 10-2024 Actual v. Forecasted | J1: NOTES | K1: SR
A2: Site | B2: State | C2: Actual | D2: Expected | E2: Delta | F2: % | G2: Forecasted | H2: Delta | I2: %
A3: {=Sites[Site]} -> Grafton II | B3: {=Sites[State]} -> MA | C3: {=IF(INDIRECT("'" & $A3 & "'!B14:J14")="", "", INDIRECT("'" & $A3 & "'!B14:J14"))} | E3: 0 | F3: 0 | H3: 0 | I3: 0
A4: Clara Barton | B4: MA | C4: {=IF(INDIRECT("'" & $A4 & "'!B14:J14")="", "", INDIRECT("'" & $A4 & "'!B14:J14"))} | E4: 0 | F4: 0 | H4: 0 | I4: 0
A5: Fairhaven Solar | B5: MA | C5: {=IF(INDIRECT("'" & $A5 & "'!B14:J14")="", "", INDIRECT("'" & $A5 & "'!B14:J14"))} | E5: 0 | F5: 0 | H5: 0 | I5: 0
A6: Plympton-1 | B6: MA | C6: {=IF(INDIRECT("'" & $A6 & "'!B14:J14")="", "", INDIRECT("'" & $A6 & "'!B14:J14"))} | E6: 0 | F6: 0 | H6: 0 | I6: 0
A7: French River 2 | B7: MA | C7: {=IF(INDIRECT("'" & $A7 & "'!B14:J14")="", "", INDIRECT("'" & $A7 & "'!B14:J14"))} | E7: 0 | F7: 0 | H7: 0 | I7: 0
A8: French River 3 | B8: MA | C8: {=IF(INDIRECT("'" & $A8 & "'!B14:J14")="", "", INDIRECT("'" & $A8 & "'!B14:J14"))} | E8: 0 | F8: 0 | H8: 0 | I8: 0
A9: French River 4 | B9: MA | C9: {=IF(INDIRECT("'" & $A9 & "'!B14:J14")="", "", INDIRECT("'" & $A9 & "'!B14:J14"))} | E9: 0 | F9: 0 | H9: 0 | I9: 0
A10: French River 5 | B10: MA | C10: {=IF(INDIRECT("'" & $A10 & "'!B14:J14")="", "", INDIRECT("'" & $A10 & "'!B14:J14"))} | E10: 0 | F10: 0 | H10: 0 | I10: 0
A11: French River 6 | B11: MA | C11: {=IF(INDIRECT("'" & $A11 & "'!B14:J14")="", "", INDIRECT("'" & $A11 & "'!B14:J14"))} | E11: 0 | F11: 0 | H11: 0 | I11: 0
A12: Stillwater River 1A | B12: MA | C12: {=IF(INDIRECT("'" & $A12 & "'!B14:J14")="", "", INDIRECT("'" & $A12 & "'!B14:J14"))} | E12: 0 | F12: 0 | H12: 0 | I12: 0
A13: Stillwater River 2 | B13: MA | C13: {=IF(INDIRECT("'" & $A13 & "'!B14:J14")="", "", INDIRECT("'" & $A13 & "'!B14:J14"))} | E13: 0 | F13: 0 | H13: 0 | I13: 0
A14: Stillwater River 3 | B14: MA | C14: {=IF(INDIRECT("'" & $A14 & "'!B14:J14")="", "", INDIRECT("'" & $A14 & "'!B14:J14"))} | E14: 0 | F14: 0 | H14: 0 | I14: 0
A15: Stillwater River 4 | B15: MA | C15: {=IF(INDIRECT("'" & $A15 & "'!B14:J14")="", "", INDIRECT("'" & $A15 & "'!B14:J14"))} | E15: 0 | F15: 0 | H15: 0 | I15: 0
A16: Total | C16: =SUM(C3:C15) -> 0 | D16: =SUM(D3:D15) -> 0 | E16: =C16-D16 -> 0 | F16: =IFERROR(E16/D16, 0) -> 0 | G16: =SUM(G3:G15) -> 0 | H16: =C16-G16 -> 0 | I16: =IFERROR(H16/G16, 0) -> 0
A18: Values in gold exceed expected or forecasted by 10% or more.
A20: Values in red are below expected or forecasted by 10% or more.

Sheet 11-2024
A1: {=portfolio} -> MN8 Bond | C1: 11-2024 Actual v. Expected | G1: 11-2024 Actual v. Forecasted | J1: NOTES | K1: SR
A2: Site | B2: State | C2: Actual | D2: Expected | E2: Delta | F2: % | G2: Forecasted | H2: Delta | I2: %
A3: {=Sites[Site]} -> Grafton II | B3: {=Sites[State]} -> MA | C3: {=IF(INDIRECT("'" & $A3 & "'!B15:J15")="", "", INDIRECT("'" & $A3 & "'!B15:J15"))} | E3: 0 | F3: 0 | H3: 0 | I3: 0
A4: Clara Barton | B4: MA | C4: {=IF(INDIRECT("'" & $A4 & "'!B15:J15")="", "", INDIRECT("'" & $A4 & "'!B15:J15"))} | E4: 0 | F4: 0 | H4: 0 | I4: 0
A5: Fairhaven Solar | B5: MA | C5: {=IF(INDIRECT("'" & $A5 & "'!B15:J15")="", "", INDIRECT("'" & $A5 & "'!B15:J15"))} | E5: 0 | F5: 0 | H5: 0 | I5: 0
A6: Plympton-1 | B6: MA | C6: {=IF(INDIRECT("'" & $A6 & "'!B15:J15")="", "", INDIRECT("'" & $A6 & "'!B15:J15"))} | E6: 0 | F6: 0 | H6: 0 | I6: 0
A7: French River 2 | B7: MA | C7: {=IF(INDIRECT("'" & $A7 & "'!B15:J15")="", "", INDIRECT("'" & $A7 & "'!B15:J15"))} | E7: 0 | F7: 0 | H7: 0 | I7: 0
A8: French River 3 | B8: MA | C8: {=IF(INDIRECT("'" & $A8 & "'!B15:J15")="", "", INDIRECT("'" & $A8 & "'!B15:J15"))} | E8: 0 | F8: 0 | H8: 0 | I8: 0
A9: French River 4 | B9: MA | C9: {=IF(INDIRECT("'" & $A9 & "'!B15:J15")="", "", INDIRECT("'" & $A9 & "'!B15:J15"))} | E9: 0 | F9: 0 | H9: 0 | I9: 0
A10: French River 5 | B10: MA | C10: {=IF(INDIRECT("'" & $A10 & "'!B15:J15")="", "", INDIRECT("'" & $A10 & "'!B15:J15"))} | E10: 0 | F10: 0 | H10: 0 | I10: 0
A11: French River 6 | B11: MA | C11: {=IF(INDIRECT("'" & $A11 & "'!B15:J15")="", "", INDIRECT("'" & $A11 & "'!B15:J15"))} | E11: 0 | F11: 0 | H11: 0 | I11: 0
A12: Stillwater River 1A | B12: MA | C12: {=IF(INDIRECT("'" & $A12 & "'!B15:J15")="", "", INDIRECT("'" & $A12 & "'!B15:J15"))} | E12: 0 | F12: 0 | H12: 0 | I12: 0
A13: Stillwater River 2 | B13: MA | C13: {=IF(INDIRECT("'" & $A13 & "'!B15:J15")="", "", INDIRECT("'" & $A13 & "'!B15:J15"))} | E13: 0 | F13: 0 | H13: 0 | I13: 0
A14: Stillwater River 3 | B14: MA | C14: {=IF(INDIRECT("'" & $A14 & "'!B15:J15")="", "", INDIRECT("'" & $A14 & "'!B15:J15"))} | E14: 0 | F14: 0 | H14: 0 | I14: 0
A15: Stillwater River 4 | B15: MA | C15: {=IF(INDIRECT("'" & $A15 & "'!B15:J15")="", "", INDIRECT("'" & $A15 & "'!B15:J15"))} | E15: 0 | F15: 0 | H15: 0 | I15: 0
A16: Total | C16: =SUM(C3:C15) -> 0 | D16: =SUM(D3:D15) -> 0 | E16: =C16-D16 -> 0 | F16: =IFERROR(E16/D16, 0) -> 0 | G16: =SUM(G3:G15) -> 0 | H16: =C16-G16 -> 0 | I16: =IFERROR(H16/G16, 0) -> 0
A18: Values in gold exceed expected or forecasted by 10% or more.
A20: Values in red are below expected or forecasted by 10% or more.

Sheet 12-2024
A1: {=portfolio} -> MN8 Bond | C1: 12-2024 Actual v. Expected | G1: 12-2024 Actual v. Forecasted | J1: NOTES | K1: SR
A2: Site | B2: State | C2: Actual | D2: Expected | E2: Delta | F2: % | G2: Forecasted | H2: Delta | I2: %
A3: {=Sites[Site]} -> Grafton II | B3: {=Sites[State]} -> MA | C3: {=IF(INDIRECT("'" & $A3 & "'!B16:J16")="", "", INDIRECT("'" & $A3 & "'!B16:J16"))} | E3: 0 | F3: 0 | H3: 0 | I3: 0
A4: Clara Barton | B4: MA | C4: {=IF(INDIRECT("'" & $A4 & "'!B16:J16")="", "", INDIRECT("'" & $A4 & "'!B16:J16"))} | E4: 0 | F4: 0 | H4: 0 | I4: 0
A5: Fairhaven Solar | B5: MA | C5: {=IF(INDIRECT("'" & $A5 & "'!B16:J16")="", "", INDIRECT("'" & $A5 & "'!B16:J16"))} | E5: 0 | F5: 0 | H5: 0 | I5: 0
A6: Plympton-1 | B6: MA | C6: {=IF(INDIRECT("'" & $A6 & "'!B16:J16")="", "", INDIRECT("'" & $A6 & "'!B16:J16"))} | E6: 0 | F6: 0 | H6: 0 | I6: 0
A7: French River 2 | B7: MA | C7: {=IF(INDIRECT("'" & $A7 & "'!B16:J16")="", "", INDIRECT("'" & $A7 & "'!B16:J16"))} | E7: 0 | F7: 0 | H7: 0 | I7: 0
