Workbook
Name JanActual: '01-2024'!$C$3:$C$15
Name JanActual2: '01-2024'!#REF!
Name JanExpected: '01-2024'!$D$3:$D$15
Name JanExpectedDelta: '01-2024'!$E$3:$E$15
Name JanExpectedPercent: '01-2024'!$F$3:$F$15
Name JanExpPercent: '01-2024'!$F$3:$F$15
Name JanForecasted: '01-2024'!$G$3:$G$15
Name JanForecastedDelta: '01-2024'!$H$3:$H$15
Name JanForecastedPercent: '01-2024'!$I$3:$I$15
Name portfolio: Sites!$B$1:$B$1

Sheet YTD Total 2024
A1: {=portfolio} -> MN8 KEF | C1: Year to Date 2024 Actual v. Expected | G1: Year to Date 2024 Forecasted | J1: NOTES | K1: SR
A2: Site | B2: State | C2: Actual | D2: Expected | E2: Delta | F2: % | G2: Forecasted | H2: Delta | I2: %
A3: {=Sites[Site]} -> Williamsburg A | B3: {=Sites[State]} -> MA | C3: =SUM('1st Quarter 2024'!C3, '2nd Quarter 2024'!C3, '3rd Quarter 2024'!C3, '4th Quarter 2024'!C3) -> 34976.74 | D3: =SUM('1st Quarter 2024'!D3, '2nd Quarter 2024'!D3, '3rd Quarter 2024'!D3, '4th Quarter 2024'!D3) -> 63711.84 | E3: =C3-D3 -> -28735.1 | F3: =IFERROR(E3/D3, 0) -> -0.45101663 | G3: =SUM('1st Quarter 2024'!G3, '2nd Quarter 2024'!G3, '3rd Quarter 2024'!G3, '4th Quarter 2024'!G3) -> 96254.79 | H3: =C3-G3 -> -61278.05 | I3: =IFERROR(H3/G3, 0) -> -0.63662338
A4: Orange A KB | B4: MA | C4: =SUM('1st Quarter 2024'!C4, '2nd Quarter 2024'!C4, '3rd Quarter 2024'!C4, '4th Quarter 2024'!C4) -> 36812.441 | D4: =SUM('1st Quarter 2024'!D4, '2nd Quarter 2024'!D4, '3rd Quarter 2024'!D4, '4th Quarter 2024'!D4) -> 50249.95 | E4: =C4-D4 -> -13437.509 | F4: =IFERROR(E4/D4, 0) -> -0.26741337 | G4: =SUM('1st Quarter 2024'!G4, '2nd Quarter 2024'!G4, '3rd Quarter 2024'!G4, '4th Quarter 2024'!G4) -> 78902.03 | H4: =C4-G4 -> -42089.589 | I4: =IFERROR(H4/G4, 0) -> -0.53344114
A5: Goshen A | B5: MA | C5: =SUM('1st Quarter 2024'!C5, '2nd Quarter 2024'!C5, '3rd Quarter 2024'!C5, '4th Quarter 2024'!C5) -> 25506 | D5: =SUM('1st Quarter 2024'!D5, '2nd Quarter 2024'!D5, '3rd Quarter 2024'!D5, '4th Quarter 2024'!D5) -> 57487.3 | E5: =C5-D5 -> -31981.3 | F5: =IFERROR(E5/D5, 0) -> -0.5563194 | G5: =SUM('1st Quarter 2024'!G5, '2nd Quarter 2024'!G5, '3rd Quarter 2024'!G5, '4th Quarter 2024'!G5) -> 45574.37 | H5: =C5-G5 -> -20068.37 | I5: =IFERROR(H5/G5, 0) -> -0.44034333
A6: Phillipston A KB | B6: MA | C6: =SUM('1st Quarter 2024'!C6, '2nd Quarter 2024'!C6, '3rd Quarter 2024'!C6, '4th Quarter 2024'!C6) -> 28771 | D6: =SUM('1st Quarter 2024'!D6, '2nd Quarter 2024'!D6, '3rd Quarter 2024'!D6, '4th Quarter 2024'!D6) -> 81174.38 | E6: =C6-D6 -> -52403.38 | F6: =IFERROR(E6/D6, 0) -> -0.64556551 | G6: =SUM('1st Quarter 2024'!G6, '2nd Quarter 2024'!G6, '3rd Quarter 2024'!G6, '4th Quarter 2024'!G6) -> 48828.99 | H6: =C6-G6 -> -20057.99 | I6: =IFERROR(H6/G6, 0) -> -0.41078036
A7: Uxbridge D | B7: MA | C7: =SUM('1st Quarter 2024'!C7, '2nd Quarter 2024'!C7, '3rd Quarter 2024'!C7, '4th Quarter 2024'!C7) -> 42944 | D7: =SUM('1st Quarter 2024'!D7, '2nd Quarter 2024'!D7, '3rd Quarter 2024'!D7, '4th Quarter 2024'!D7) -> 75174.5 | E7: =C7-D7 -> -32230.5 | F7: =IFERROR(E7/D7, 0) -> -0.42874246 | G7: =SUM('1st Quarter 2024'!G7, '2nd Quarter 2024'!G7, '3rd Quarter 2024'!G7, '4th Quarter 2024'!G7) -> 103260 | H7: =C7-G7 -> -60316 | I7: =IFERROR(H7/G7, 0) -> -0.58411776
A8: West Bridgewater A&B | B8: MA | C8: =SUM('1st Quarter 2024'!C8, '2nd Quarter 2024'!C8, '3rd Quarter 2024'!C8, '4th Quarter 2024'!C8) -> 84322 | D8: =SUM('1st Quarter 2024'!D8, '2nd Quarter 2024'!D8, '3rd Quarter 2024'!D8, '4th Quarter 2024'!D8) -> 126671.7 | E8: =C8-D8 -> -42349.7 | F8: =IFERROR(E8/D8, 0) -> -0.33432645 | G8: =SUM('1st Quarter 2024'!G8, '2nd Quarter 2024'!G8, '3rd Quarter 2024'!G8, '4th Quarter 2024'!G8) -> 169067.9 | H8: =C8-G8 -> -84745.9 | I8: =IFERROR(H8/G8, 0) -> -0.50125364
A9: Sutton A | B9: MA | C9: =SUM('1st Quarter 2024'!C9, '2nd Quarter 2024'!C9, '3rd Quarter 2024'!C9, '4th Quarter 2024'!C9) -> 30226 | D9: =SUM('1st Quarter 2024'!D9, '2nd Quarter 2024'!D9, '3rd Quarter 2024'!D9, '4th Quarter 2024'!D9) -> 57946.25 | E9: =C9-D9 -> -27720.25 | F9: =IFERROR(E9/D9, 0) -> -0.47837867 | G9: =SUM('1st Quarter 2024'!G9, '2nd Quarter 2024'!G9, '3rd Quarter 2024'!G9, '4th Quarter 2024'!G9) -> 93432.82 | H9: =C9-G9 -> -63206.82 | I9: =IFERROR(H9/G9, 0) -> -0.67649483
A10: North Adams A | B10: MA | C10: =SUM('1st Quarter 2024'!C10, '2nd Quarter 2024'!C10, '3rd Quarter 2024'!C10, '4th Quarter 2024'!C10) -> 33659 | D10: =SUM('1st Quarter 2024'!D10, '2nd Quarter 2024'!D10, '3rd Quarter 2024'!D10, '4th Quarter 2024'!D10) -> 55008.74 | E10: =C10-D10 -> -21349.74 | F10: =IFERROR(E10/D10, 0) -> -0.38811542 | G10: =SUM('1st Quarter 2024'!G10, '2nd Quarter 2024'!G10, '3rd Quarter 2024'!G10, '4th Quarter 2024'!G10) -> 98462.86 | H10: =C10-G10 -> -64803.86 | I10: =IFERROR(H10/G10, 0) -> -0.65815537
A11: North Adams B | B11: MA | C11: =SUM('1st Quarter 2024'!C11, '2nd Quarter 2024'!C11, '3rd Quarter 2024'!C11, '4th Quarter 2024'!C11) -> 25714 | D11: =SUM('1st Quarter 2024'!D11, '2nd Quarter 2024'!D11, '3rd Quarter 2024'!D11, '4th Quarter 2024'!D11) -> 47004.33 | E11: =C11-D11 -> -21290.33 | F11: =IFERROR(E11/D11, 0) -> -0.45294402 | G11: =SUM('1st Quarter 2024'!G11, '2nd Quarter 2024'!G11, '3rd Quarter 2024'!G11, '4th Quarter 2024'!G11) -> 98462.86 | H11: =C11-G11 -> -72748.86 | I11: =IFERROR(H11/G11, 0) -> -0.73884569
A12: Clarksburg A | B12: MA | C12: =SUM('1st Quarter 2024'!C12, '2nd Quarter 2024'!C12, '3rd Quarter 2024'!C12, '4th Quarter 2024'!C12) -> 25169 | D12: =SUM('1st Quarter 2024'!D12, '2nd Quarter 2024'!D12, '3rd Quarter 2024'!D12, '4th Quarter 2024'!D12) -> 48116.73 | E12: =C12-D12 -> -22947.73 | F12: =IFERROR(E12/D12, 0) -> -0.4769179 | G12: =SUM('1st Quarter 2024'!G12, '2nd Quarter 2024'!G12, '3rd Quarter 2024'!G12, '4th Quarter 2024'!G12) -> 98015.59 | H12: =C12-G12 -> -72846.59 | I12: =IFERROR(H12/G12, 0) -> -0.74321432
A13: Swansea B | B13: MA | C13: =SUM('1st Quarter 2024'!C13, '2nd Quarter 2024'!C13, '3rd Quarter 2024'!C13, '4th Quarter 2024'!C13) -> 54645 | D13: =SUM('1st Quarter 2024'!D13, '2nd Quarter 2024'!D13, '3rd Quarter 2024'!D13, '4th Quarter 2024'!D13) -> 81330.64 | E13: =C13-D13 -> -26685.64 | F13: =IFERROR(E13/D13, 0) -> -0.328113 | G13: =SUM('1st Quarter 2024'!G13, '2nd Quarter 2024'!G13, '3rd Quarter 2024'!G13, '4th Quarter 2024'!G13) -> 50080.16 | H13: =C13-G13 -> 4564.84 | I13: =IFERROR(H13/G13, 0) -> 0.091150667
A14: Wareham 2 | B14: MA | C14: =SUM('1st Quarter 2024'!C14, '2nd Quarter 2024'!C14, '3rd Quarter 2024'!C14, '4th Quarter 2024'!C14) -> 59387.25 | D14: =SUM('1st Quarter 2024'!D14, '2nd Quarter 2024'!D14, '3rd Quarter 2024'!D14, '4th Quarter 2024'!D14) -> 65302.43 | E14: =C14-D14 -> -5915.18 | F14: =IFERROR(E14/D14, 0) -> -0.090581315 | G14: =SUM('1st Quarter 2024'!G14, '2nd Quarter 2024'!G14, '3rd Quarter 2024'!G14, '4th Quarter 2024'!G14) -> 103231.1 | H14: =C14-G14 -> -43843.85 | I14: =IFERROR(H14/G14, 0) -> -0.42471552
A15: Kingston 1 KB | B15: MA | C15: =SUM('1st Quarter 2024'!C15, '2nd Quarter 2024'!C15, '3rd Quarter 2024'!C15, '4th Quarter 2024'!C15) -> 46172 | D15: =SUM('1st Quarter 2024'!D15, '2nd Quarter 2024'!D15, '3rd Quarter 2024'!D15, '4th Quarter 2024'!D15) -> 64095.79 | E15: =C15-D15 -> -17923.79 | F15: =IFERROR(E15/D15, 0) -> -0.27964068 | G15: =SUM('1st Quarter 2024'!G15, '2nd Quarter 2024'!G15, '3rd Quarter 2024'!G15, '4th Quarter 2024'!G15) -> 78554.16 | H15: =C15-G15 -> -32382.16 | I15: =IFERROR(H15/G15, 0) -> -0.41222718
... A19: Plympton A-2 | B19: MA | C19: =SUM('1st Quarter 2024'!C19, '2nd Quarter 2024'!C19, '3rd Quarter 2024'!C19, '4th Quarter 2024'!C19) -> 60641 | D19: =SUM('1st Quarter 2024'!D19, '2nd Quarter 2024'!D19, '3rd Quarter 2024'!D19, '4th Quarter 2024'!D19) -> 77649.14 | E19: =C19-D19 -> -17008.14 | F19: =IFERROR(E19/D19, 0) -> -0.21903836 | G19: =SUM('1st Quarter 2024'!G19, '2nd Quarter 2024'!G19, '3rd Quarter 2024'!G19, '4th Quarter 2024'!G19) -> 98644.24 | H19: =C19-G19 -> -38003.24 | I19: =IFERROR(H19/G19, 0) -> -0.38525554
A20: Total | C20: =SUM(C3:C19) -> 779580.43 | D20: =SUM(D3:D19) -> 1198900 | E20: =C20-D20 -> -419319.56 | F20: =IFERROR(E20/D20, 0) -> -0.34975358 | G20: =SUM(G3:G19) -> 1598697.1 | H20: =C20-G20 -> -819116.63 | I20: =IFERROR(H20/G20, 0) -> -0.51236513
A22: Values in gold exceed expected or forecasted by 10% or more.
A24: Values in red are below expected or forecasted by 10% or more.

Sheet 1st Quarter 2024
A1: {=portfolio} -> MN8 KEF | C1: 1st Quarter 2024 Actual v. Expected | G1: 1st Quarter 2024 Forecasted | J1: NOTES | K1: SR
A2: Site | B2: State | C2: Actual | D2: Expected | E2: Delta | F2: % | G2: Forecasted | H2: Delta | I2: %
A3: {=Sites[Site]} -> Williamsburg A | B3: {=Sites[State]} -> MA | C3: =SUM('01-2024'!C3, '02-2024'!C3, '03-2024'!C3) -> 34976.74 | D3: =SUM('01-2024'!D3, '02-2024'!D3, '03-2024'!D3) -> 63711.84 | E3: =C3-D3 -> -28735.1 | F3: =IFERROR(E3/D3, 0) -> -0.45101663 | G3: =SUM('01-2024'!G3, '02-2024'!G3, '03-2024'!G3) -> 96254.79 | H3: =C3-G3 -> -61278.05 | I3: =IFERROR(H3/G3, 0) -> -0.63662338
A4: Orange A KB | B4: MA | C4: =SUM('01-2024'!C4, '02-2024'!C4, '03-2024'!C4) -> 36812.441 | D4: =SUM('01-2024'!D4, '02-2024'!D4, '03-2024'!D4) -> 50249.95 | E4: =C4-D4 -> -13437.509 | F4: =IFERROR(E4/D4, 0) -> -0.26741337 | G4: =SUM('01-2024'!G4, '02-2024'!G4, '03-2024'!G4) -> 78902.03 | H4: =C4-G4 -> -42089.589 | I4: =IFERROR(H4/G4, 0) -> -0.53344114
A5: Goshen A | B5: MA | C5: =SUM('01-2024'!C5, '02-2024'!C5, '03-2024'!C5) -> 25506 | D5: =SUM('01-2024'!D5, '02-2024'!D5, '03-2024'!D5) -> 57487.3 | E5: =C5-D5 -> -31981.3 | F5: =IFERROR(E5/D5, 0) -> -0.5563194 | G5: =SUM('01-2024'!G5, '02-2024'!G5, '03-2024'!G5) -> 45574.37 | H5: =C5-G5 -> -20068.37 | I5: =IFERROR(H5/G5, 0) -> -0.44034333
A6: Phillipston A KB | B6: MA | C6: =SUM('01-2024'!C6, '02-2024'!C6, '03-2024'!C6) -> 28771 | D6: =SUM('01-2024'!D6, '02-2024'!D6, '03-2024'!D6) -> 81174.38 | E6: =C6-D6 -> -52403.38 | F6: =IFERROR(E6/D6, 0) -> -0.64556551 | G6: =SUM('01-2024'!G6, '02-2024'!G6, '03-2024'!G6) -> 48828.99 | H6: =C6-G6 -> -20057.99 | I6: =IFERROR(H6/G6, 0) -> -0.41078036
A7: Uxbridge D | B7: MA | C7: =SUM('01-2024'!C7, '02-2024'!C7, '03-2024'!C7) -> 42944 | D7: =SUM('01-2024'!D7, '02-2024'!D7, '03-2024'!D7) -> 75174.5 | E7: =C7-D7 -> -32230.5 | F7: =IFERROR(E7/D7, 0) -> -0.42874246 | G7: =SUM('01-2024'!G7, '02-2024'!G7, '03-2024'!G7) -> 103260 | H7: =C7-G7 -> -60316 | I7: =IFERROR(H7/G7, 0) -> -0.58411776
A8: West Bridgewater A&B | B8: MA | C8: =SUM('01-2024'!C8, '02-2024'!C8, '03-2024'!C8) -> 84322 | D8: =SUM('01-2024'!D8, '02-2024'!D8, '03-2024'!D8) -> 126671.7 | E8: =C8-D8 -> -42349.7 | F8: =IFERROR(E8/D8, 0) -> -0.33432645 | G8: =SUM('01-2024'!G8, '02-2024'!G8, '03-2024'!G8) -> 169067.9 | H8: =C8-G8 -> -84745.9 | I8: =IFERROR(H8/G8, 0) -> -0.50125364
A9: Sutton A | B9: MA | C9: =SUM('01-2024'!C9, '02-2024'!C9, '03-2024'!C9) -> 30226 | D9: =SUM('01-2024'!D9, '02-2024'!D9, '03-2024'!D9) -> 57946.25 | E9: =C9-D9 -> -27720.25 | F9: =IFERROR(E9/D9, 0) -> -0.47837867 | G9: =SUM('01-2024'!G9, '02-2024'!G9, '03-2024'!G9) -> 93432.82 | H9: =C9-G9 -> -63206.82 | I9: =IFERROR(H9/G9, 0) -> -0.67649483
A10: North Adams A | B10: MA | C10: =SUM('01-2024'!C10, '02-2024'!C10, '03-2024'!C10) -> 33659 | D10: =SUM('01-2024'!D10, '02-2024'!D10, '03-2024'!D10) -> 55008.74 | E10: =C10-D10 -> -21349.74 | F10: =IFERROR(E10/D10, 0) -> -0.38811542 | G10: =SUM('01-2024'!G10, '02-2024'!G10, '03-2024'!G10) -> 98462.86 | H10: =C10-G10 -> -64803.86 | I10: =IFERROR(H10/G10, 0) -> -0.65815537
A11: North Adams B | B11: MA | C11: =SUM('01-2024'!C11, '02-2024'!C11, '03-2024'!C11) -> 25714 | D11: =SUM('01-2024'!D11, '02-2024'!D11, '03-2024'!D11) -> 47004.33 | E11: =C11-D11 -> -21290.33 | F11: =IFERROR(E11/D11, 0) -> -0.45294402 | G11: =SUM('01-2024'!G11, '02-2024'!G11, '03-2024'!G11) -> 98462.86 | H11: =C11-G11 -> -72748.86 | I11: =IFERROR(H11/G11, 0) -> -0.73884569
A12: Clarksburg A | B12: MA | C12: =SUM('01-2024'!C12, '02-2024'!C12, '03-2024'!C12) -> 25169 | D12: =SUM('01-2024'!D12, '02-2024'!D12, '03-2024'!D12) -> 48116.73 | E12: =C12-D12 -> -22947.73 | F12: =IFERROR(E12/D12, 0) -> -0.4769179 | G12: =SUM('01-2024'!G12, '02-2024'!G12, '03-2024'!G12) -> 98015.59 | H12: =C12-G12 -> -72846.59 | I12: =IFERROR(H12/G12, 0) -> -0.74321432
A13: Swansea B | B13: MA | C13: =SUM('01-2024'!C13, '02-2024'!C13, '03-2024'!C13) -> 54645 | D13: =SUM('01-2024'!D13, '02-2024'!D13, '03-2024'!D13) -> 81330.64 | E13: =C13-D13 -> -26685.64 | F13: =IFERROR(E13/D13, 0) -> -0.328113 | G13: =SUM('01-2024'!G13, '02-2024'!G13, '03-2024'!G13) -> 50080.16 | H13: =C13-G13 -> 4564.84 | I13: =IFERROR(H13/G13, 0) -> 0.091150667
A14: Wareham 2 | B14: MA | C14: =SUM('01-2024'!C14, '02-2024'!C14, '03-2024'!C14) -> 59387.25 | D14: =SUM('01-2024'!D14, '02-2024'!D14, '03-2024'!D14) -> 65302.43 | E14: =C14-D14 -> -5915.18 | F14: =IFERROR(E14/D14, 0) -> -0.090581315 | G14: =SUM('01-2024'!G14, '02-2024'!G14, '03-2024'!G14) -> 103231.1 | H14: =C14-G14 -> -43843.85 | I14: =IFERROR(H14/G14, 0) -> -0.42471552
A15: Kingston 1 KB | B15: MA | C15: =SUM('01-2024'!C15, '02-2024'!C15, '03-2024'!C15) -> 46172 | D15: =SUM('01-2024'!D15, '02-2024'!D15, '03-2024'!D15) -> 64095.79 | E15: =C15-D15 -> -17923.79 | F15: =IFERROR(E15/D15, 0) -> -0.27964068 | G15: =SUM('01-2024'!G15, '02-2024'!G15, '03-2024'!G15) -> 78554.16 | H15: =C15-G15 -> -32382.16 | I15: =IFERROR(H15/G15, 0) -> -0.41222718
... A19: Plympton A-2 | B19: MA | C19: =SUM('01-2024'!C19, '02-2024'!C19, '03-2024'!C19) -> 60641 | D19: =SUM('01-2024'!D19, '02-2024'!D19, '03-2024'!D19) -> 77649.14 | E19: =C19-D19 -> -17008.14 | F19: =IFERROR(E19/D19, 0) -> -0.21903836 | G19: =SUM('01-2024'!G19, '02-2024'!G19, '03-2024'!G19) -> 98644.24 | H19: =C19-G19 -> -38003.24 | I19: =IFERROR(H19/G19, 0) -> -0.38525554
A20: Total | C20: =SUM(C3:C19) -> 779580.43 | D20: =SUM(D3:D19) -> 1198900 | E20: =C20-D20 -> -419319.56 | F20: =IFERROR(E20/D20, 0) -> -0.34975358 | G20: =SUM(G3:G19) -> 1598697.1 | H20: =C20-G20 -> -819116.63 | I20: =IFERROR(H20/G20, 0) -> -0.51236513
A22: Values in gold exceed expected or forecasted by 10% or more.
A24: Values in red are below expected or forecasted by 10% or more.

Sheet 2nd Quarter 2024
A1: {=portfolio} -> MN8 KEF | C1: 2nd Quarter 2024 Actual v. Expected | G1: 2nd Quarter 2024 Forecasted | J1: NOTES | K1: SR
A2: Site | B2: State | C2: Actual | D2: Expected | E2: Delta | F2: % | G2: Forecasted | H2: Delta | I2: %
A3: {=Sites[Site]} -> Williamsburg A | B3: {=Sites[State]} -> MA | C3: =SUM('04-2024'!C3, '05-2024'!C3, '06-2024'!C3) -> 0 | D3: =SUM('04-2024'!D3, '05-2024'!D3, '06-2024'!D3) -> 0 | E3: =C3-D3 -> 0 | F3: =IFERROR(E3/D3, 0) -> 0 | G3: =SUM('04-2024'!G3, '05-2024'!G3, '06-2024'!G3) -> 0 | H3: =C3-G3 -> 0 | I3: =IFERROR(H3/G3, 0) -> 0
A4: Orange A KB | B4: MA | C4: =SUM('04-2024'!C4, '05-2024'!C4, '06-2024'!C4) -> 0 | D4: =SUM('04-2024'!D4, '05-2024'!D4, '06-2024'!D4) -> 0 | E4: =C4-D4 -> 0 | F4: =IFERROR(E4/D4, 0) -> 0 | G4: =SUM('04-2024'!G4, '05-2024'!G4, '06-2024'!G4) -> 0 | H4: =C4-G4 -> 0 | I4: =IFERROR(H4/G4, 0) -> 0
A5: Goshen A | B5: MA | C5: =SUM('04-2024'!C5, '05-2024'!C5, '06-2024'!C5) -> 0 | D5: =SUM('04-2024'!D5, '05-2024'!D5, '06-2024'!D5) -> 0 | E5: =C5-D5 -> 0 | F5: =IFERROR(E5/D5, 0) -> 0 | G5: =SUM('04-2024'!G5, '05-2024'!G5, '06-2024'!G5) -> 0 | H5: =C5-G5 -> 0 | I5: =IFERROR(H5/G5, 0) -> 0
A6: Phillipston A KB | B6: MA | C6: =SUM('04-2024'!C6, '05-2024'!C6, '06-2024'!C6) -> 0 | D6: =SUM('04-2024'!D6, '05-2024'!D6, '06-2024'!D6) -> 0 | E6: =C6-D6 -> 0 | F6: =IFERROR(E6/D6, 0) -> 0 | G6: =SUM('04-2024'!G6, '05-2024'!G6, '06-2024'!G6) -> 0 | H6: =C6-G6 -> 0 | I6: =IFERROR(H6/G6, 0) -> 0
A7: Uxbridge D | B7: MA | C7: =SUM('04-2024'!C7, '05-2024'!C7, '06-2024'!C7) -> 0 | D7: =SUM('04-2024'!D7, '05-2024'!D7, '06-2024'!D7) -> 0 | E7: =C7-D7 -> 0 | F7: =IFERROR(E7/D7, 0) -> 0 | G7: =SUM('04-2024'!G7, '05-2024'!G7, '06-2024'!G7) -> 0 | H7: =C7-G7 -> 0 | I7: =IFERROR(H7/G7, 0) -> 0
A8: West Bridgewater A&B | B8: MA | C8: =SUM('04-2024'!C8, '05-2024'!C8, '06-2024'!C8) -> 0 | D8: =SUM('04-2024'!D8, '05-2024'!D8, '06-2024'!D8) -> 0 | E8: =C8-D8 -> 0 | F8: =IFERROR(E8/D8, 0) -> 0 | G8: =SUM('04-2024'!G8, '05-2024'!G8, '06-2024'!G8) -> 0 | H8: =C8-G8 -> 0 | I8: =IFERROR(H8/G8, 0) -> 0
A9: Sutton A | B9: MA | C9: =SUM('04-2024'!C9, '05-2024'!C9, '06-2024'!C9) -> 0 | D9: =SUM('04-2024'!D9, '05-2024'!D9, '06-2024'!D9) -> 0 | E9: =C9-D9 -> 0 | F9: =IFERROR(E9/D9, 0) -> 0 | G9: =SUM('04-2024'!G9, '05-2024'!G9, '06-2024'!G9) -> 0 | H9: =C9-G9 -> 0 | I9: =IFERROR(H9/G9, 0) -> 0
A10: North Adams A | B10: MA | C10: =SUM('04-2024'!C10, '05-2024'!C10, '06-2024'!C10) -> 0 | D10: =SUM('04-2024'!D10, '05-2024'!D10, '06-2024'!D10) -> 0 | E10: =C10-D10 -> 0 | F10: =IFERROR(E10/D10, 0) -> 0 | G10: =SUM('04-2024'!G10, '05-2024'!G10, '06-2024'!G10) -> 0 | H10: =C10-G10 -> 0 | I10: =IFERROR(H10/G10, 0) -> 0
A11: North Adams B | B11: MA | C11: =SUM('04-2024'!C11, '05-2024'!C11, '06-2024'!C11) -> 0 | D11: =SUM('04-2024'!D11, '05-2024'!D11, '06-2024'!D11) -> 0 | E11: =C11-D11 -> 0 | F11: =IFERROR(E11/D11, 0) -> 0 | G11: =SUM('04-2024'!G11, '05-2024'!G11, '06-2024'!G11) -> 0 | H11: =C11-G11 -> 0 | I11: =IFERROR(H11/G11, 0) -> 0
A12: Clarksburg A | B12: MA | C12: =SUM('04-2024'!C12, '05-2024'!C12, '06-2024'!C12) -> 0 | D12: =SUM('04-2024'!D12, '05-2024'!D12, '06-2024'!D12) -> 0 | E12: =C12-D12 -> 0 | F12: =IFERROR(E12/D12, 0) -> 0 | G12: =SUM('04-2024'!G12, '05-2024'!G12, '06-2024'!G12) -> 0 | H12: =C12-G12 -> 0 | I12: =IFERROR(H12/G12, 0) -> 0
A13: Swansea B | B13: MA | C13: =SUM('04-2024'!C13, '05-2024'!C13, '06-2024'!C13) -> 0 | D13: =SUM('04-2024'!D13, '05-2024'!D13, '06-2024'!D13) -> 0 | E13: =C13-D13 -> 0 | F13: =IFERROR(E13/D13, 0) -> 0 | G13: =SUM('04-2024'!G13, '05-2024'!G13, '06-2024'!G13) -> 0 | H13: =C13-G13 -> 0 | I13: =IFERROR(H13/G13, 0) -> 0
A14: Wareham 2 | B14: MA | C14: =SUM('04-2024'!C14, '05-2024'!C14, '06-2024'!C14) -> 0 | D14: =SUM('04-2024'!D14, '05-2024'!D14, '06-2024'!D14) -> 0 | E14: =C14-D14 -> 0 | F14: =IFERROR(E14/D14, 0) -> 0 | G14: =SUM('04-2024'!G14, '05-2024'!G14, '06-2024'!G14) -> 0 | H14: =C14-G14 -> 0 | I14: =IFERROR(H14/G14, 0) -> 0
A15: Kingston 1 KB | B15: MA | C15: =SUM('04-2024'!C15, '05-2024'!C15, '06-2024'!C15) -> 0 | D15: =SUM('04-2024'!D15, '05-2024'!D15, '06-2024'!D15) -> 0 | E15: =C15-D15 -> 0 | F15: =IFERROR(E15/D15, 0) -> 0 | G15: =SUM('04-2024'!G15, '05-2024'!G15, '06-2024'!G15) -> 0 | H15: =C15-G15 -> 0 | I15: =IFERROR(H15/G15, 0) -> 0
... A19: Plympton A-2 | B19: MA | C19: =SUM('04-2024'!C19, '05-2024'!C19, '06-2024'!C19) -> 0 | D19: =SUM('04-2024'!D19, '05-2024'!D19, '06-2024'!D19) -> 0 | E19: =C19-D19 -> 0 | F19: =IFERROR(E19/D19, 0) -> 0 | G19: =SUM('04-2024'!G19, '05-2024'!G19, '06-2024'!G19) -> 0 | H19: =C19-G19 -> 0 | I19: =IFERROR(H19/G19, 0) -> 0
A20: Total | C20: =SUM(C3:C19) -> 0 | D20: =SUM(D3:D19) -> 0 | E20: =C20-D20 -> 0 | F20: =IFERROR(E20/D20, 0) -> 0 | G20: =SUM(G3:G19) -> 0 | H20: =C20-G20 -> 0 | I20: =IFERROR(H20/G20, 0) -> 0
A22: Values in gold exceed expected or forecasted by 10% or more.
A24: Values in red are below expected or forecasted by 10% or more.

Sheet 3rd Quarter 2024
A1: {=portfolio} -> MN8 KEF | C1: 3rd Quarter 2024 Actual v. Expected | G1: 3rd Quarter 2024 Forecasted | J1: NOTES | K1: SR
A2: Site | B2: State | C2: Actual | D2: Expected | E2: Delta | F2: % | G2: Forecasted | H2: Delta | I2: %
A3: {=Sites[Site]} -> Williamsburg A | B3: {=Sites[State]} -> MA | C3: =SUM('07-2024'!C3, '08-2024'!C3, '09-2024'!C3) -> 0 | D3: =SUM('07-2024'!D3, '08-2024'!D3, '09-2024'!D3) -> 0 | E3: =C3-D3 -> 0 | F3: =IFERROR(E3/D3, 0) -> 0 | G3: =SUM('07-2024'!G3, '08-2024'!G3, '09-2024'!G3) -> 0 | H3: =C3-G3 -> 0 | I3: =IFERROR(H3/G3, 0) -> 0
A4: Orange A KB | B4: MA | C4: =SUM('07-2024'!C4, '08-2024'!C4, '09-2024'!C4) -> 0 | D4: =SUM('07-2024'!D4, '08-2024'!D4, '09-2024'!D4) -> 0 | E4: =C4-D4 -> 0 | F4: =IFERROR(E4/D4, 0) -> 0 | G4: =SUM('07-2024'!G4, '08-2024'!G4, '09-2024'!G4) -> 0 | H4: =C4-G4 -> 0 | I4: =IFERROR(H4/G4, 0) -> 0
A5: Goshen A | B5: MA | C5: =SUM('07-2024'!C5, '08-2024'!C5, '09-2024'!C5) -> 0 | D5: =SUM('07-2024'!D5, '08-2024'!D5, '09-2024'!D5) -> 0 | E5: =C5-D5 -> 0 | F5: =IFERROR(E5/D5, 0) -> 0 | G5: =SUM('07-2024'!G5, '08-2024'!G5, '09-2024'!G5) -> 0 | H5: =C5-G5 -> 0 | I5: =IFERROR(H5/G5, 0) -> 0
A6: Phillipston A KB | B6: MA | C6: =SUM('07-2024'!C6, '08-2024'!C6, '09-2024'!C6) -> 0 | D6: =SUM('07-2024'!D6, '08-2024'!D6, '09-2024'!D6) -> 0 | E6: =C6-D6 -> 0 | F6: =IFERROR(E6/D6, 0) -> 0 | G6: =SUM('07-2024'!G6, '08-2024'!G6, '09-2024'!G6) -> 0 | H6: =C6-G6 -> 0 | I6: =IFERROR(H6/G6, 0) -> 0
A7: Uxbridge D | B7: MA | C7: =SUM('07-2024'!C7, '08-2024'!C7, '09-2024'!C7) -> 0 | D7: =SUM('07-2024'!D7, '08-2024'!D7, '09-2024'!D7) -> 0 | E7: =C7-D7 -> 0 | F7: =IFERROR(E7/D7, 0) -> 0 | G7: =SUM('07-2024'!G7, '08-2024'!G7, '09-2024'!G7) -> 0 | H7: =C7-G7 -> 0 | I7: =IFERROR(H7/G7, 0) -> 0
A8: West Bridgewater A&B | B8: MA | C8: =SUM('07-2024'!C8, '08-2024'!C8, '09-2024'!C8) -> 0 | D8: =SUM('07-2024'!D8, '08-2024'!D8, '09-2024'!D8) -> 0 | E8: =C8-D8 -> 0 | F8: =IFERROR(E8/D8, 0) -> 0 | G8: =SUM('07-2024'!G8, '08-2024'!G8, '09-2024'!G8) -> 0 | H8: =C8-G8 -> 0 | I8: =IFERROR(H8/G8, 0) -> 0
A9: Sutton A | B9: MA | C9: =SUM('07-2024'!C9, '08-2024'!C9, '09-2024'!C9) -> 0 | D9: =SUM('07-2024'!D9, '08-2024'!D9, '09-2024'!D9) -> 0 | E9: =C9-D9 -> 0 | F9: =IFERROR(E9/D9, 0) -> 0 | G9: =SUM('07-2024'!G9, '08-2024'!G9, '09-2024'!G9) -> 0 | H9: =C9-G9 -> 0 | I9: =IFERROR(H9/G9, 0) -> 0
A10: North Adams A | B10: MA | C10: =SUM('07-2024'!C10, '08-2024'!C10, '09-2024'!C10) -> 0 | D10: =SUM('07-2024'!D10, '08-2024'!D10, '09-2024'!D10) -> 0 | E10: =C10-D10 -> 0 | F10: =IFERROR(E10/D10, 0) -> 0 | G10: =SUM('07-2024'!G10, '08-2024'!G10, '09-2024'!G10) -> 0 | H10: =C10-G10 -> 0 | I10: =IFERROR(H10/G10, 0) -> 0
A11: North Adams B | B11: MA | C11: =SUM('07-2024'!C11, '08-2024'!C11, '09-2024'!C11) -> 0 | D11: =SUM('07-2024'!D11, '08-2024'!D11, '09-2024'!D11) -> 0 | E11: =C11-D11 -> 0 | F11: =IFERROR(E11/D11, 0) -> 0 | G11: =SUM('07-2024'!G11, '08-2024'!G11, '09-2024'!G11) -> 0 | H11: =C11-G11 -> 0 | I11: =IFERROR(H11/G11, 0) -> 0
A12: Clarksburg A | B12: MA | C12: =SUM('07-2024'!C12, '08-2024'!C12, '09-2024'!C12) -> 0 | D12: =SUM('07-2024'!D12, '08-2024'!D12, '09-2024'!D12) -> 0 | E12: =C12-D12 -> 0 | F12: =IFERROR(E12/D12, 0) -> 0 | G12: =SUM('07-2024'!G12, '08-2024'!G12, '09-2024'!G12) -> 0 | H12: =C12-G12 -> 0 | I12: =IFERROR(H12/G12, 0) -> 0
A13: Swansea B | B13: MA | C13: =SUM('07-2024'!C13, '08-2024'!C13, '09-2024'!C13) -> 0 | D13: =SUM('07-2024'!D13, '08-2024'!D13, '09-2024'!D13) -> 0 | E13: =C13-D13 -> 0 | F13: =IFERROR(E13/D13, 0) -> 0 | G13: =SUM('07-2024'!G13, '08-2024'!G13, '09-2024'!G13) -> 0 | H13: =C13-G13 -> 0 | I13: =IFERROR(H13/G13, 0) -> 0
A14: Wareham 2 | B14: MA | C14: =SUM('07-2024'!C14, '08-2024'!C14, '09-2024'!C14) -> 0 | D14: =SUM('07-2024'!D14, '08-2024'!D14, '09-2024'!D14) -> 0 | E14: =C14-D14 -> 0 | F14: =IFERROR(E14/D14, 0) -> 0 | G14: =SUM('07-2024'!G14, '08-2024'!G14, '09-2024'!G14) -> 0 | H14: =C14-G14 -> 0 | I14: =IFERROR(H14/G14, 0) -> 0
A15: Kingston 1 KB | B15: MA | C15: =SUM('07-2024'!C15, '08-2024'!C15, '09-2024'!C15) -> 0 | D15: =SUM('07-2024'!D15, '08-2024'!D15, '09-2024'!D15) -> 0 | E15: =C15-D15 -> 0 | F15: =IFERROR(E15/D15, 0) -> 0 | G15: =SUM('07-2024'!G15, '08-2024'!G15, '09-2024'!G15) -> 0 | H15: =C15-G15 -> 0 | I15: =IFERROR(H15/G15, 0) -> 0
... A19: Plympton A-2 | B19: MA | C19: =SUM('07-2024'!C19, '08-2024'!C19, '09-2024'!C19) -> 0 | D19: =SUM('07-2024'!D19, '08-2024'!D19, '09-2024'!D19) -> 0 | E19: =C19-D19 -> 0 | F19: =IFERROR(E19/D19, 0) -> 0 | G19: =SUM('07-2024'!G19, '08-2024'!G19, '09-2024'!G19) -> 0 | H19: =C19-G19 -> 0 | I19: =IFERROR(H19/G19, 0) -> 0
A20: Total | C20: =SUM(C3:C19) -> 0 | D20: =SUM(D3:D19) -> 0 | E20: =C20-D20 -> 0 | F20: =IFERROR(E20/D20, 0) -> 0 | G20: =SUM(G3:G19) -> 0 | H20: =C20-G20 -> 0 | I20: =IFERROR(H20/G20, 0) -> 0
A22: Values in gold exceed expected or forecasted by 10% or more.
A24: Values in red are below expected or forecasted by 10% or more.

Sheet 4th Quarter 2024
A1: {=portfolio} -> MN8 KEF | C1: 4th Quarter 2024 Actual v. Expected | G1: 4th Quarter 2024 Forecasted | J1: NOTES | K1: SR
A2: Site | B2: State | C2: Actual | D2: Expected | E2: Delta | F2: % | G2: Forecasted | H2: Delta | I2: %
A3: {=Sites[Site]} -> Williamsburg A | B3: {=Sites[State]} -> MA | C3: =SUM('10-2024'!C3, '11-2024'!C3, '12-2024'!C3) -> 0 | D3: =SUM('10-2024'!D3, '11-2024'!D3, '12-2024'!D3) -> 0 | E3: =C3-D3 -> 0 | F3: =IFERROR(E3/D3, 0) -> 0 | G3: =SUM('10-2024'!G3, '11-2024'!G3, '12-2024'!G3) -> 0 | H3: =C3-G3 -> 0 | I3: =IFERROR(H3/G3, 0) -> 0
A4: Orange A KB | B4: MA | C4: =SUM('10-2024'!C4, '11-2024'!C4, '12-2024'!C4) -> 0 | D4: =SUM('10-2024'!D4, '11-2024'!D4, '12-2024'!D4) -> 0 | E4: =C4-D4 -> 0 | F4: =IFERROR(E4/D4, 0) -> 0 | G4: =SUM('10-2024'!G4, '11-2024'!G4, '12-2024'!G4) -> 0 | H4: =C4-G4 -> 0 | I4: =IFERROR(H4/G4, 0) -> 0
A5: Goshen A | B5: MA | C5: =SUM('10-2024'!C5, '11-2024'!C5, '12-2024'!C5) -> 0 | D5: =SUM('10-2024'!D5, '11-2024'!D5, '12-2024'!D5) -> 0 | E5: =C5-D5 -> 0 | F5: =IFERROR(E5/D5, 0) -> 0 | G5: =SUM('10-2024'!G5, '11-2024'!G5, '12-2024'!G5) -> 0 | H5: =C5-G5 -> 0 | I5: =IFERROR(H5/G5, 0) -> 0
A6: Phillipston A KB | B6: MA | C6: =SUM('10-2024'!C6, '11-2024'!C6, '12-2024'!C6) -> 0 | D6: =SUM('10-2024'!D6, '11-2024'!D6, '12-2024'!D6) -> 0 | E6: =C6-D6 -> 0 | F6: =IFERROR(E6/D6, 0) -> 0 | G6: =SUM('10-2024'!G6, '11-2024'!G6, '12-2024'!G6) -> 0 | H6: =C6-G6 -> 0 | I6: =IFERROR(H6/G6, 0) -> 0
A7: Uxbridge D | B7: MA | C7: =SUM('10-2024'!C7, '11-2024'!C7, '12-2024'!C7) -> 0 | D7: =SUM('10-2024'!D7, '11-2024'!D7, '12-2024'!D7) -> 0 | E7: =C7-D7 -> 0 | F7: =IFERROR(E7/D7, 0) -> 0 | G7: =SUM('10-2024'!G7, '11-2024'!G7, '12-2024'!G7) -> 0 | H7: =C7-G7 -> 0 | I7: =IFERROR(H7/G7, 0) -> 0
A8: West Bridgewater A&B | B8: MA | C8: =SUM('10-2024'!C8, '11-2024'!C8, '12-2024'!C8) -> 0 | D8: =SUM('10-2024'!D8, '11-2024'!D8, '12-2024'!D8) -> 0 | E8: =C8-D8 -> 0 | F8: =IFERROR(E8/D8, 0) -> 0 | G8: =SUM('10-2024'!G8, '11-2024'!G8, '12-2024'!G8) -> 0 | H8: =C8-G8 -> 0 | I8: =IFERROR(H8/G8, 0) -> 0
A9: Sutton A | B9: MA | C9: =SUM('10-2024'!C9, '11-2024'!C9, '12-2024'!C9) -> 0 | D9: =SUM('10-2024'!D9, '11-2024'!D9, '12-2024'!D9) -> 0 | E9: =C9-D9 -> 0 | F9: =IFERROR(E9/D9, 0) -> 0 | G9: =SUM('10-2024'!G9, '11-2024'!G9, '12-2024'!G9) -> 0 | H9: =C9-G9 -> 0 | I9: =IFERROR(H9/G9, 0) -> 0
A10: North Adams A | B10: MA | C10: =SUM('10-2024'!C10, '11-2024'!C10, '12-2024'!C10) -> 0 | D10: =SUM('10-2024'!D10, '11-2024'!D10, '12-2024'!D10) -> 0 | E10: =C10-D10 -> 0 | F10: =IFERROR(E10/D10, 0) -> 0 | G10: =SUM('10-2024'!G10, '11-2024'!G10, '12-2024'!G10) -> 0 | H10: =C10-G10 -> 0 | I10: =IFERROR(H10/G10, 0) -> 0
A11: North Adams B | B11: MA | C11: =SUM('10-2024'!C11, '11-2024'!C11, '12-2024'!C11) -> 0 | D11: =SUM('10-2024'!D11, '11-2024'!D11, '12-2024'!D11) -> 0 | E11: =C11-D11 -> 0 | F11: =IFERROR(E11/D11, 0) -> 0 | G11: =SUM('10-2024'!G11, '11-2024'!G11, '12-2024'!G11) -> 0 | H11: =C11-G11 -> 0 | I11: =IFERROR(H11/G11, 0) -> 0
A12: Clarksburg A | B12: MA | C12: =SUM('10-2024'!C12, '11-2024'!C12, '12-2024'!C12) -> 0 | D12: =SUM('10-2024'!D12, '11-2024'!D12, '12-2024'!D12) -> 0 | E12: =C12-D12 -> 0 | F12: =IFERROR(E12/D12, 0) -> 0 | G12: =SUM('10-2024'!G12, '11-2024'!G12, '12-2024'!G12) -> 0 | H12: =C12-G12 -> 0 | I12: =IFERROR(H12/G12, 0) -> 0
A13: Swansea B | B13: MA | C13: =SUM('10-2024'!C13, '11-2024'!C13, '12-2024'!C13) -> 0 | D13: =SUM('10-2024'!D13, '11-2024'!D13, '12-2024'!D13) -> 0 | E13: =C13-D13 -> 0 | F13: =IFERROR(E13/D13, 0) -> 0 | G13: =SUM('10-2024'!G13, '11-2024'!G13, '12-2024'!G13) -> 0 | H13: =C13-G13 -> 0 | I13: =IFERROR(H13/G13, 0) -> 0
A14: Wareham 2 | B14: MA | C14: =SUM('10-2024'!C14, '11-2024'!C14, '12-2024'!C14) -> 0 | D14: =SUM('10-2024'!D14, '11-2024'!D14, '12-2024'!D14) -> 0 | E14: =C14-D14 -> 0 | F14: =IFERROR(E14/D14, 0) -> 0 | G14: =SUM('10-2024'!G14, '11-2024'!G14, '12-2024'!G14) -> 0 | H14: =C14-G14 -> 0 | I14: =IFERROR(H14/G14, 0) -> 0
A15: Kingston 1 KB | B15: MA | C15: =SUM('10-2024'!C15, '11-2024'!C15, '12-2024'!C15) -> 0 | D15: =SUM('10-2024'!D15, '11-2024'!D15, '12-2024'!D15) -> 0 | E15: =C15-D15 -> 0 | F15: =IFERROR(E15/D15, 0) -> 0 | G15: =SUM('10-2024'!G15, '11-2024'!G15, '12-2024'!G15) -> 0 | H15: =C15-G15 -> 0 | I15: =IFERROR(H15/G15, 0) -> 0
... A19: Plympton A-2 | B19: MA | C19: =SUM('10-2024'!C19, '11-2024'!C19, '12-2024'!C19) -> 0 | D19: =SUM('10-2024'!D19, '11-2024'!D19, '12-2024'!D19) -> 0 | E19: =C19-D19 -> 0 | F19: =IFERROR(E19/D19, 0) -> 0 | G19: =SUM('10-2024'!G19, '11-2024'!G19, '12-2024'!G19) -> 0 | H19: =C19-G19 -> 0 | I19: =IFERROR(H19/G19, 0) -> 0
A20: Total | C20: =SUM(C3:C19) -> 0 | D20: =SUM(D3:D19) -> 0 | E20: =C20-D20 -> 0 | F20: =IFERROR(E20/D20, 0) -> 0 | G20: =SUM(G3:G19) -> 0 | H20: =C20-G20 -> 0 | I20: =IFERROR(H20/G20, 0) -> 0
A22: Values in gold exceed expected or forecasted by 10% or more.
A24: Values in red are below expected or forecasted by 10% or more.

Sheet 01-2024
A1: {=portfolio} -> MN8 KEF | C1: 1-2024 Actual v. Expected | G1: 1-2024 Actual v. Forecasted | J1: NOTES | K1: SR
A2: Site | B2: State | C2: Actual | D2: Expected | E2: Delta | F2: % | G2: Forecasted | H2: Delta | I2: %
A3: {=Sites[Site]} -> Williamsburg A | B3: {=Sites[State]} -> MA | C3: {=IF(INDIRECT("'" & $A3 & "'!B5:J5")="", "", INDIRECT("'" & $A3 & "'!B5:J5"))} -> 34976.74 | D3: 63711.84 | E3: -28735.1 | F3: -0.45101663 | G3: 96254.79 | H3: -61278.05 | I3: -0.63662338
A4: Orange A KB | B4: MA | C4: {=IF(INDIRECT("'" & $A4 & "'!B5:J5")="", "", INDIRECT("'" & $A4 & "'!B5:J5"))} -> 36812.441 | D4: 50249.95 | E4: -13437.509 | F4: -0.26741337 | G4: 78902.03 | H4: -42089.589 | I4: -0.53344114 | J4: 1. Site tripped offline on 01/13 multiple times early in the morningand auto-closed shortly after | K4: 1. SR080185
A5: Goshen A | B5: MA | C5: {=IF(INDIRECT("'" & $A5 & "'!B5:J5")="", "", INDIRECT("'" & $A5 & "'!B5:J5"))} -> 25506 | D5: 57487.3 | E5: -31981.3 | F5: -0.5563194 | G5: 45574.37 | H5: -20068.37 | I5: -0.44034333 | J5: 1. Site tripped on 01/14 at 14:30 and later back online on 01/15 at 10:00AM 2. Site tripped offline on 01/25 at 11:06AM and later back online 01/25 at 11:27AM. | K5: 1. SR080209 2. SR080465
A6: Phillipston A KB | B6: MA | C6: {=IF(INDIRECT("'" & $A6 & "'!B5:J5")="", "", INDIRECT("'" & $A6 & "'!B5:J5"))} -> 28771 | D6: 81174.38 | E6: -52403.38 | F6: -0.64556551 | G6: 48828.99 | H6: -20057.99 | I6: -0.41078036
A7: Uxbridge D | B7: MA | C7: {=IF(INDIRECT("'" & $A7 & "'!B5:J5")="", "", INDIRECT("'" & $A7 & "'!B5:J5"))} -> 42944 | D7: 75174.5 | E7: -32230.5 | F7: -0.42874246 | G7: 103260 | H7: -60316 | I7: -0.58411776
A8: West Bridgewater A&B | B8: MA | C8: {=IF(INDIRECT("'" & $A8 & "'!B5:J5")="", "", INDIRECT("'" & $A8 & "'!B5:J5"))} -> 84322 | D8: 126671.7 | E8: -42349.7 | F8: -0.33432645 | G8: 169067.9 | H8: -84745.9 | I8: -0.50125364
A9: Sutton A | B9: MA | C9: {=IF(INDIRECT("'" & $A9 & "'!B5:J5")="", "", INDIRECT("'" & $A9 & "'!B5:J5"))} -> 30226 | D9: 57946.25 | E9: -27720.25 | F9: -0.47837867 | G9: 93432.82 | H9: -63206.82 | I9: -0.67649483
A10: North Adams A | B10: MA | C10: {=IF(INDIRECT("'" & $A10 & "'!B5:J5")="", "", INDIRECT("'" & $A10 & "'!B5:J5"))} -> 33659 | D10: 55008.74 | E10: -21349.74 | F10: -0.38811542 | G10: 98462.86 | H10: -64803.86 | I10: -0.65815537 | J10: 1. Inverter 3.3 is offline on 01/13 at 07:00AM, later back online on 01/13 at 12:45PM and tripping on and off multiple days on and off. | K10: 1. SR080193
A11: North Adams B | B11: MA | C11: {=IF(INDIRECT("'" & $A11 & "'!B5:J5")="", "", INDIRECT("'" & $A11 & "'!B5:J5"))} -> 25714 | D11: 47004.33 | E11: -21290.33 | F11: -0.45294402 | G11: 98462.86 | H11: -72748.86 | I11: -0.73884569
A12: Clarksburg A | B12: MA | C12: {=IF(INDIRECT("'" & $A12 & "'!B5:J5")="", "", INDIRECT("'" & $A12 & "'!B5:J5"))} -> 25169 | D12: 48116.73 | E12: -22947.73 | F12: -0.4769179 | G12: 98015.59 | H12: -72846.59 | I12: -0.74321432
A13: Swansea B | B13: MA | C13: {=IF(INDIRECT("'" & $A13 & "'!B5:J5")="", "", INDIRECT("'" & $A13 & "'!B5:J5"))} -> 54645 | D13: 81330.64 | E13: -26685.64 | F13: -0.328113 | G13: 50080.16 | H13: 4564.84 | I13: 0.091150667 | J13: 1. Site tripped offline on 01/29 at 16:00 and later back online on 01/30 at 11:15AM. | K13: 1. SR080590
A14: Wareham 2 | B14: MA | C14: {=IF(INDIRECT("'" & $A14 & "'!B5:J5")="", "", INDIRECT("'" & $A14 & "'!B5:J5"))} -> 59387.25 | D14: 65302.43 | E14: -5915.18 | F14: -0.090581315 | G14: 103231.1 | H14: -43843.85 | I14: -0.42471552
A15: Kingston 1 KB | B15: MA | C15: {=IF(INDIRECT("'" & $A15 & "'!B5:J5")="", "", INDIRECT("'" & $A15 & "'!B5:J5"))} -> 46172 | D15: 64095.79 | E15: -17923.79 | F15: -0.27964068 | G15: 78554.16 | H15: -32382.16 | I15: -0.41222718 | J15: 1. Site tripped on 01/14 at 16:45 and later back online on 01/15 at 14:30. 2. Site tripped offline due to utility outage on 01/16 at 11:30AM and utility cleared outage on 01/18 at 07:45AM. | K15: 1. SR080216 2. SR080258
A16: Kingston 2 KB | B16: MA | C16: {=IF(INDIRECT("'" & $A16 & "'!B5:J5")="", "", INDIRECT("'" & $A16 & "'!B5:J5"))} -> 38326 | D16: 38638.25 | E16: -312.25 | F16: -0.0080813701 | G16: 63052.82 | H16: -24726.82 | I16: -0.39216041 | J16: 1. Site tripped on 01/14 at 16:45 and later back online on 01/15 at 14:30. 2. Site tripped offline due to utility outage on 01/16 at 11:30AM and utility cleared outage on 01/18 at 07:45AM. | K16: 1. SR080217 2. SR080259
A17: Holliston B | B17: MA | C17: {=IF(INDIRECT("'" & $A17 & "'!B5:J5")="", "", INDIRECT("'" & $A17 & "'!B5:J5"))} -> 32229 | D17: 61034.62 | E17: -28805.62 | F17: -0.47195542 | G17: 98146.17 | H17: -65917.17 | I17: -0.67162244
A18: Fairhaven C | B18: MA | C18: {=IF(INDIRECT("'" & $A18 & "'!B5:J5")="", "", INDIRECT("'" & $A18 & "'!B5:J5"))} -> 120080 | D18: 148303.4 | E18: -28223.4 | F18: -0.19030852 | G18: 176726.2 | H18: -56646.2 | I18: -0.32053086 | J18: 1. Site tripped offline on 01/11 at 07:00AM and later back online on 01/12 at 07:45AM. 2. Inverter 47 was offline after site re-energize the site on 01/12 and back online on 14:15. | K18: 1. SR080149 2. SR080171
A19: Plympton A-2 | B19: MA | C19: {=IF(INDIRECT("'" & $A19 & "'!B5:J5")="", "", INDIRECT("'" & $A19 & "'!B5:J5"))} -> 60641 | D19: 77649.14 | E19: -17008.14 | F19: -0.21903836 | G19: 98644.24 | H19: -38003.24 | I19: -0.38525554 | J19: 1. Site tripped offline on 01/10 at 03:26AM and later back online on 01/10 at 06:24AM. | K19: 1. SR080115
A20: Total | C20: =SUM(C3:C19) -> 779580.43 | D20: =SUM(D3:D19) -> 1198900 | E20: =C20-D20 -> -419319.56 | F20: =IFERROR(E20/D20, 0) -> -0.34975358 | G20: =SUM(G3:G19) -> 1598697.1 | H20: =C20-G20 -> -819116.63 | I20: =IFERROR(H20/G20, 0) -> -0.51236513
A22: Values in gold exceed expected or forecasted by 10% or more.
A24: Values in red are below expected or forecasted by 10% or more.

Sheet 02-2024
A1: {=portfolio} -> MN8 KEF | C1: 2-2024 Actual v. Expected | G1: 2-2024 Actual v. Forecasted | J1: NOTES | K1: SR
A2: Site | B2: State | C2: Actual | D2: Expected | E2: Delta | F2: % | G2: Forecasted | H2: Delta | I2: %
A3: {=Sites[Site]} -> Williamsburg A | B3: {=Sites[State]} -> MA | C3: {=IF(INDIRECT("'" & $A3 & "'!B6:J6")="", "", INDIRECT("'" & $A3 & "'!B6:J6"))} | E3: 0 | F3: 0 | H3: 0 | I3: 0
A4: Orange A KB | B4: MA | C4: {=IF(INDIRECT("'" & $A4 & "'!B6:J6")="", "", INDIRECT("'" & $A4 & "'!B6:J6"))} | E4: 0 | F4: 0 | H4: 0 | I4: 0
A5: Goshen A | B5: MA | C5: {=IF(INDIRECT("'" & $A5 & "'!B6:J6")="", "", INDIRECT("'" & $A5 & "'!B6:J6"))} | E5: 0 | F5: 0 | H5: 0 | I5: 0
A6: Phillipston A KB | B6: MA | C6: {=IF(INDIRECT("'" & $A6 & "'!B6:J6")="", "", INDIRECT("'" & $A6 & "'!B6:J6"))} | E6: 0 | F6: 0 | H6: 0 | I6: 0
A7: Uxbridge D | B7: MA | C7: {=IF(INDIRECT("'" & $A7 & "'!B6:J6")="", "", INDIRECT("'" & $A7 & "'!B6:J6"))} | E7: 0 | F7: 0 | H7: 0 | I7: 0
A8: West Bridgewater A&B | B8: MA | C8: {=IF(INDIRECT("'" & $A8 & "'!B6:J6")="", "", INDIRECT("'" & $A8 & "'!B6:J6"))} | E8: 0 | F8: 0 | H8: 0 | I8: 0
A9: Sutton A | B9: MA | C9: {=IF(INDIRECT("'" & $A9 & "'!B6:J6")="", "", INDIRECT("'" & $A9 & "'!B6:J6"))} | E9: 0 | F9: 0 | H9: 0 | I9: 0
A10: North Adams A | B10: MA | C10: {=IF(INDIRECT("'" & $A10 & "'!B6:J6")="", "", INDIRECT("'" & $A10 & "'!B6:J6"))} | E10: 0 | F10: 0 | H10: 0 | I10: 0
A11: North Adams B | B11: MA | C11: {=IF(INDIRECT("'" & $A11 & "'!B6:J6")="", "", INDIRECT("'" & $A11 & "'!B6:J6"))} | E11: 0 | F11: 0 | H11: 0 | I11: 0
A12: Clarksburg A | B12: MA | C12: {=IF(INDIRECT("'" & $A12 & "'!B6:J6")="", "", INDIRECT("'" & $A12 & "'!B6:J6"))} | E12: 0 | F12: 0 | H12: 0 | I12: 0
A13: Swansea B | B13: MA | C13: {=IF(INDIRECT("'" & $A13 & "'!B6:J6")="", "", INDIRECT("'" & $A13 & "'!B6:J6"))} | E13: 0 | F13: 0 | H13: 0 | I13: 0
A14: Wareham 2 | B14: MA | C14: {=IF(INDIRECT("'" & $A14 & "'!B6:J6")="", "", INDIRECT("'" & $A14 & "'!B6:J6"))} | E14: 0 | F14: 0 | H14: 0 | I14: 0
A15: Kingston 1 KB | B15: MA | C15: {=IF(INDIRECT("'" & $A15 & "'!B6:J6")="", "", INDIRECT("'" & $A15 & "'!B6:J6"))} | E15: 0 | F15: 0 | H15: 0 | I15: 0
... A19: Plympton A-2 | B19: MA | C19: {=IF(INDIRECT("'" & $A19 & "'!B6:J6")="", "", INDIRECT("'" & $A19 & "'!B6:J6"))} | E19: 0 | F19: 0 | H19: 0 | I19: 0
A20: Total | C20: =SUM(C3:C19) -> 0 | D20: =SUM(D3:D19) -> 0 | E20: =C20-D20 -> 0 | F20: =IFERROR(E20/D20, 0) -> 0 | G20: =SUM(G3:G19) -> 0 | H20: =C20-G20 -> 0 | I20: =IFERROR(H20/G20, 0) -> 0
A22: Values in gold exceed expected or forecasted by 10% or more.
A24: Values in red are below expected or forecasted by 10% or more.

Sheet 03-2024
A1: {=portfolio} -> MN8 KEF | C1: 3-2024 Actual v. Expected | G1: 3-2024 Actual v. Forecasted | J1: NOTES | K1: SR
A2: Site | B2: State | C2: Actual | D2: Expected | E2: Delta | F2: % | G2: Forecasted | H2: Delta | I2: %
A3: {=Sites[Site]} -> Williamsburg A | B3: {=Sites[State]} -> MA | C3: {=IF(INDIRECT("'" & $A3 & "'!B7:J7")="", "", INDIRECT("'" & $A3 & "'!B7:J7"))} | E3: 0 | F3: 0 | H3: 0 | I3: 0
A4: Orange A KB | B4: MA | C4: {=IF(INDIRECT("'" & $A4 & "'!B7:J7")="", "", INDIRECT("'" & $A4 & "'!B7:J7"))} | E4: 0 | F4: 0 | H4: 0 | I4: 0
A5: Goshen A | B5: MA | C5: {=IF(INDIRECT("'" & $A5 & "'!B7:J7")="", "", INDIRECT("'" & $A5 & "'!B7:J7"))} | E5: 0 | F5: 0 | H5: 0 | I5: 0
A6: Phillipston A KB | B6: MA | C6: {=IF(INDIRECT("'" & $A6 & "'!B7:J7")="", "", INDIRECT("'" & $A6 & "'!B7:J7"))} | E6: 0 | F6: 0 | H6: 0 | I6: 0
A7: Uxbridge D | B7: MA | C7: {=IF(INDIRECT("'" & $A7 & "'!B7:J7")="", "", INDIRECT("'" & $A7 & "'!B7:J7"))} | E7: 0 | F7: 0 | H7: 0 | I7: 0
A8: West Bridgewater A&B | B8: MA | C8: {=IF(INDIRECT("'" & $A8 & "'!B7:J7")="", "", INDIRECT("'" & $A8 & "'!B7:J7"))} | E8: 0 | F8: 0 | H8: 0 | I8: 0
A9: Sutton A | B9: MA | C9: {=IF(INDIRECT("'" & $A9 & "'!B7:J7")="", "", INDIRECT("'" & $A9 & "'!B7:J7"))} | E9: 0 | F9: 0 | H9: 0 | I9: 0
A10: North Adams A | B10: MA | C10: {=IF(INDIRECT("'" & $A10 & "'!B7:J7")="", "", INDIRECT("'" & $A10 & "'!B7:J7"))} | E10: 0 | F10: 0 | H10: 0 | I10: 0
A11: North Adams B | B11: MA | C11: {=IF(INDIRECT("'" & $A11 & "'!B7:J7")="", "", INDIRECT("'" & $A11 & "'!B7:J7"))} | E11: 0 | F11: 0 | H11: 0 | I11: 0
A12: Clarksburg A | B12: MA | C12: {=IF(INDIRECT("'" & $A12 & "'!B7:J7")="", "", INDIRECT("'" & $A12 & "'!B7:J7"))} | E12: 0 | F12: 0 | H12: 0 | I12: 0
A13: Swansea B | B13: MA | C13: {=IF(INDIRECT("'" & $A13 & "'!B7:J7")="", "", INDIRECT("'" & $A13 & "'!B7:J7"))} | E13: 0 | F13: 0 | H13: 0 | I13: 0
A14: Wareham 2 | B14: MA | C14: {=IF(INDIRECT("'" & $A14 & "'!B7:J7")="", "", INDIRECT("'" & $A14 & "'!B7:J7"))} | E14: 0 | F14: 0 | H14: 0 | I14: 0
A15: Kingston 1 KB | B15: MA | C15: {=IF(INDIRECT("'" & $A15 & "'!B7:J7")="", "", INDIRECT("'" & $A15 & "'!B7:J7"))} | E15: 0 | F15: 0 | H15: 0 | I15: 0
... A19: Plympton A-2 | B19: MA | C19: {=IF(INDIRECT("'" & $A19 & "'!B7:J7")="", "", INDIRECT("'" & $A19 & "'!B7:J7"))} | E19: 0 | F19: 0 | H19: 0 | I19: 0
A20: Total | C20: =SUM(C3:C19) -> 0 | D20: =SUM(D3:D19) -> 0 | E20: =C20-D20 -> 0 | F20: =IFERROR(E20/D20, 0) -> 0 | G20: =SUM(G3:G19) -> 0 | H20: =C20-G20 -> 0 | I20: =IFERROR(H20/G20, 0) -> 0
A22: Values in gold exceed expected or forecasted by 10% or more.
A24: Values in red are below expected or forecasted by 10% or more.

Sheet 04-2024
A1: {=portfolio} -> MN8 KEF | C1: 4-2024 Actual v. Expected | G1: 4-2024 Actual v. Forecasted | J1: NOTES | K1: SR
A2: Site | B2: State | C2: Actual | D2: Expected | E2: Delta | F2: % | G2: Forecasted | H2: Delta | I2: %
A3: {=Sites[Site]} -> Williamsburg A | B3: {=Sites[State]} -> MA | C3: {=IF(INDIRECT("'" & $A3 & "'!B8:J8")="", "", INDIRECT("'" & $A3 & "'!B8:J8"))} | E3: 0 | F3: 0 | H3: 0 | I3: 0
A4: Orange A KB | B4: MA | C4: {=IF(INDIRECT("'" & $A4 & "'!B8:J8")="", "", INDIRECT("'" & $A4 & "'!B8:J8"))} | E4: 0 | F4: 0 | H4: 0 | I4: 0
A5: Goshen A | B5: MA | C5: {=IF(INDIRECT("'" & $A5 & "'!B8:J8")="", "", INDIRECT("'" & $A5 & "'!B8:J8"))} | E5: 0 | F5: 0 | H5: 0 | I5: 0
A6: Phillipston A KB | B6: MA | C6: {=IF(INDIRECT("'" & $A6 & "'!B8:J8")="", "", INDIRECT("'" & $A6 & "'!B8:J8"))} | E6: 0 | F6: 0 | H6: 0 | I6: 0
A7: Uxbridge D | B7: MA | C7: {=IF(INDIRECT("'" & $A7 & "'!B8:J8")="", "", INDIRECT("'" & $A7 & "'!B8:J8"))} | E7: 0 | F7: 0 | H7: 0 | I7: 0
A8: West Bridgewater A&B | B8: MA | C8: {=IF(INDIRECT("'" & $A8 & "'!B8:J8")="", "", INDIRECT("'" & $A8 & "'!B8:J8"))} | E8: 0 | F8: 0 | H8: 0 | I8: 0
A9: Sutton A | B9: MA | C9: {=IF(INDIRECT("'" & $A9 & "'!B8:J8")="", "", INDIRECT("'" & $A9 & "'!B8:J8"))} | E9: 0 | F9: 0 | H9: 0 | I9: 0
A10: North Adams A | B10: MA | C10: {=IF(INDIRECT("'" & $A10 & "'!B8:J8")="", "", INDIRECT("'" & $A10 & "'!B8:J8"))} | E10: 0 | F10: 0 | H10: 0 | I10: 0
A11: North Adams B | B11: MA | C11: {=IF(INDIRECT("'" & $A11 & "'!B8:J8")="", "", INDIRECT("'" & $A11 & "'!B8:J8"))} | E11: 0 | F11: 0 | H11: 0 | I11: 0
A12: Clarksburg A | B12: MA | C12: {=IF(INDIRECT("'" & $A12 & "'!B8:J8")="", "", INDIRECT("'" & $A12 & "'!B8:J8"))} | E12: 0 | F12: 0 | H12: 0 | I12: 0
A13: Swansea B | B13: MA | C13: {=IF(INDIRECT("'" & $A13 & "'!B8:J8")="", "", INDIRECT("'" & $A13 & "'!B8:J8"))} | E13: 0 | F13: 0 | H13: 0 | I13: 0
A14: Wareham 2 | B14: MA | C14: {=IF(INDIRECT("'" & $A14 & "'!B8:J8")="", "", INDIRECT("'" & $A14 & "'!B8:J8"))} | E14: 0 | F14: 0 | H14: 0 | I14: 0
A15: Kingston 1 KB | B15: MA | C15: {=IF(INDIRECT("'" & $A15 & "'!B8:J8")="", "", INDIRECT("'" & $A15 & "'!B8:J8"))} | E15: 0 | F15: 0 | H15: 0 | I15: 0
... A19: Plympton A-2 | B19: MA | C19: {=IF(INDIRECT("'" & $A19 & "'!B8:J8")="", "", INDIRECT("'" & $A19 & "'!B8:J8"))} | E19: 0 | F19: 0 | H19: 0 | I19: 0
A20: Total | C20: =SUM(C3:C19) -> 0 | D20: =SUM(D3:D19) -> 0 | E20: =C20-D20 -> 0 | F20: =IFERROR(E20/D20, 0) -> 0 | G20: =SUM(G3:G19) -> 0 | H20: =C20-G20 -> 0 | I20: =IFERROR(H20/G20, 0) -> 0
A22: Values in gold exceed expected or forecasted by 10% or more.
A24: Values in red are below expected or forecasted by 10% or more.

Sheet 05-2024
A1: {=portfolio} -> MN8 KEF | C1: 5-2024 Actual v. Expected | G1: 5-2024 Actual v. Forecasted | J1: NOTES | K1: SR
A2: Site | B2: State | C2: Actual | D2: Expected | E2: Delta | F2: % | G2: Forecasted | H2: Delta | I2: %
A3: {=Sites[Site]} -> Williamsburg A | B3: {=Sites[State]} -> MA | C3: {=IF(INDIRECT("'" & $A3 & "'!B9:J9")="", "", INDIRECT("'" & $A3 & "'!B9:J9"))} | E3: 0 | F3: 0 | H3: 0 | I3: 0
A4: Orange A KB | B4: MA | C4: {=IF(INDIRECT("'" & $A4 & "'!B9:J9")="", "", INDIRECT("'" & $A4 & "'!B9:J9"))} | E4: 0 | F4: 0 | H4: 0 | I4: 0
A5: Goshen A | B5: MA | C5: {=IF(INDIRECT("'" & $A5 & "'!B9:J9")="", "", INDIRECT("'" & $A5 & "'!B9:J9"))} | E5: 0 | F5: 0 | H5: 0 | I5: 0
A6: Phillipston A KB | B6: MA | C6: {=IF(INDIRECT("'" & $A6 & "'!B9:J9")="", "", INDIRECT("'" & $A6 & "'!B9:J9"))} | E6: 0 | F6: 0 | H6: 0 | I6: 0
A7: Uxbridge D | B7: MA | C7: {=IF(INDIRECT("'" & $A7 & "'!B9:J9")="", "", INDIRECT("'" & $A7 & "'!B9:J9"))} | E7: 0 | F7: 0 | H7: 0 | I7: 0
A8: West Bridgewater A&B | B8: MA | C8: {=IF(INDIRECT("'" & $A8 & "'!B9:J9")="", "", INDIRECT("'" & $A8 & "'!B9:J9"))} | E8: 0 | F8: 0 | H8: 0 | I8: 0
A9: Sutton A | B9: MA | C9: {=IF(INDIRECT("'" & $A9 & "'!B9:J9")="", "", INDIRECT("'" & $A9 & "'!B9:J9"))} | E9: 0 | F9: 0 | H9: 0 | I9: 0
A10: North Adams A | B10: MA | C10: {=IF(INDIRECT("'" & $A10 & "'!B9:J9")="", "", INDIRECT("'" & $A10 & "'!B9:J9"))} | E10: 0 | F10: 0 | H10: 0 | I10: 0
A11: North Adams B | B11: MA | C11: {=IF(INDIRECT("'" & $A11 & "'!B9:J9")="", "", INDIRECT("'" & $A11 & "'!B9:J9"))} | E11: 0 | F11: 0 | H11: 0 | I11: 0
A12: Clarksburg A | B12: MA | C12: {=IF(INDIRECT("'" & $A12 & "'!B9:J9")="", "", INDIRECT("'" & $A12 & "'!B9:J9"))} | E12: 0 | F12: 0 | H12: 0 | I12: 0
A13: Swansea B | B13: MA | C13: {=IF(INDIRECT("'" & $A13 & "'!B9:J9")="", "", INDIRECT("'" & $A13 & "'!B9:J9"))} | E13: 0 | F13: 0 | H13: 0 | I13: 0
A14: Wareham 2 | B14: MA | C14: {=IF(INDIRECT("'" & $A14 & "'!B9:J9")="", "", INDIRECT("'" & $A14 & "'!B9:J9"))} | E14: 0 | F14: 0 | H14: 0 | I14: 0
A15: Kingston 1 KB | B15: MA | C15: {=IF(INDIRECT("'" & $A15 & "'!B9:J9")="", "", INDIRECT("'" & $A15 & "'!B9:J9"))} | E15: 0 | F15: 0 | H15: 0 | I15: 0
... A19: Plympton A-2 | B19: MA | C19: {=IF(INDIRECT("'" & $A19 & "'!B9:J9")="", "", INDIRECT("'" & $A19 & "'!B9:J9"))} | E19: 0 | F19: 0 | H19: 0 | I19: 0
A20: Total | C20: =SUM(C3:C19) -> 0 | D20: =SUM(D3:D19) -> 0 | E20: =C20-D20 -> 0 | F20: =IFERROR(E20/D20, 0) -> 0 | G20: =SUM(G3:G19) -> 0 | H20: =C20-G20 -> 0 | I20: =IFERROR(H20/G20, 0) -> 0
A22: Values in gold exceed expected or forecasted by 10% or more.
A24: Values in red are below expected or forecasted by 10% or more.

Sheet 06-2024
A1: {=portfolio} -> MN8 KEF | C1: 6-2024 Actual v. Expected | G1: 6-2024 Actual v. Forecasted | J1: NOTES | K1: SR
A2: Site | B2: State | C2: Actual | D2: Expected | E2: Delta | F2: % | G2: Forecasted | H2: Delta | I2: %
A3: {=Sites[Site]} -> Williamsburg A | B3: {=Sites[State]} -> MA | C3: {=IF(INDIRECT("'" & $A3 & "'!B10:J10")="", "", INDIRECT("'" & $A3 & "'!B10:J10"))} | E3: 0 | F3: 0 | H3: 0 | I3: 0
A4: Orange A KB | B4: MA | C4: {=IF(INDIRECT("'" & $A4 & "'!B10:J10")="", "", INDIRECT("'" & $A4 & "'!B10:J10"))} | E4: 0 | F4: 0 | H4: 0 | I4: 0
A5: Goshen A | B5: MA | C5: {=IF(INDIRECT("'" & $A5 & "'!B10:J10")="", "", INDIRECT("'" & $A5 & "'!B10:J10"))} | E5: 0 | F5: 0 | H5: 0 | I5: 0
A6: Phillipston A KB | B6: MA | C6: {=IF(INDIRECT("'" & $A6 & "'!B10:J10")="", "", INDIRECT("'" & $A6 & "'!B10:J10"))} | E6: 0 | F6: 0 | H6: 0 | I6: 0
A7: Uxbridge D | B7: MA | C7: {=IF(INDIRECT("'" & $A7 & "'!B10:J10")="", "", INDIRECT("'" & $A7 & "'!B10:J10"))} | E7: 0 | F7: 0 | H7: 0 | I7: 0
A8: West Bridgewater A&B | B8: MA | C8: {=IF(INDIRECT("'" & $A8 & "'!B10:J10")="", "", INDIRECT("'" & $A8 & "'!B10:J10"))} | E8: 0 | F8: 0 | H8: 0 | I8: 0
A9: Sutton A | B9: MA | C9: {=IF(INDIRECT("'" & $A9 & "'!B10:J10")="", "", INDIRECT("'" & $A9 & "'!B10:J10"))} | E9: 0 | F9: 0 | H9: 0 | I9: 0
A10: North Adams A | B10: MA | C10: {=IF(INDIRECT("'" & $A10 & "'!B10:J10")="", "", INDIRECT("'" & $A10 & "'!B10:J10"))} | E10: 0 | F10: 0 | H10: 0 | I10: 0
A11: North Adams B | B11: MA | C11: {=IF(INDIRECT("'" & $A11 & "'!B10:J10")="", "", INDIRECT("'" & $A11 & "'!B10:J10"))} | E11: 0 | F11: 0 | H11: 0 | I11: 0
A12: Clarksburg A | B12: MA | C12: {=IF(INDIRECT("'" & $A12 & "'!B10:J10")="", "", INDIRECT("'" & $A12 & "'!B10:J10"))} | E12: 0 | F12: 0 | H12: 0 | I12: 0
A13: Swansea B | B13: MA | C13: {=IF(INDIRECT("'" & $A13 & "'!B10:J10")="", "", INDIRECT("'" & $A13 & "'!B10:J10"))} | E13: 0 | F13: 0 | H13: 0 | I13: 0
A14: Wareham 2 | B14: MA | C14: {=IF(INDIRECT("'" & $A14 & "'!B10:J10")="", "", INDIRECT("'" & $A14 & "'!B10:J10"))} | E14: 0 | F14: 0 | H14: 0 | I14: 0
A15: Kingston 1 KB | B15: MA | C15: {=IF(INDIRECT("'" & $A19 & "'!B10:J10")="", "", INDIRECT("'" & $A19 & "'!B10:J10"))} | E15: 0 | F15: 0 | H15: 0 | I15: 0
A16: Kingston 2 KB | B16: MA | C16: {=IF(INDIRECT("'" & $A16 & "'!B10:J10")="", "", INDIRECT("'" & $A16 & "'!B10:J10"))} | E16: 0 | F16: 0 | H16: 0 | I16: 0
A17: Holliston B | B17: MA | C17: {=IF(INDIRECT("'" & $A17 & "'!B10:J10")="", "", INDIRECT("'" & $A17 & "'!B10:J10"))} | E17: 0 | F17: 0 | H17: 0 | I17: 0
A18: Fairhaven C | B18: MA | C18: {=IF(INDIRECT("'" & $A18 & "'!B10:J10")="", "", INDIRECT("'" & $A18 & "'!B10:J10"))} | E18: 0 | F18: 0 | H18: 0 | I18: 0
A19: Plympton A-2 | B19: MA | C19: {=IF(INDIRECT("'" & $A19 & "'!B10:J10")="", "", INDIRECT("'" & $A19 & "'!B10:J10"))} | E19: 0 | F19: 0 | H19: 0 | I19: 0
A20: Total | C20: =SUM(C3:C19) -> 0 | D20: =SUM(D3:D19) -> 0 | E20: =C20-D20 -> 0 | F20: =IFERROR(E20/D20, 0) -> 0 | G20: =SUM(G3:G19) -> 0 | H20: =C20-G20 -> 0 | I20: =IFERROR(H20/G20, 0) -> 0
A22: Values in gold exceed expected or forecasted by 10% or more.
A24: Values in red are below expected or forecasted by 10% or more.

Sheet 07-2024
A1: {=portfolio} -> MN8 KEF | C1: 7-2024 Actual v. Expected | G1: 7-2024 Actual v. Forecasted | J1: NOTES | K1: SR
A2: Site | B2: State | C2: Actual | D2: Expected | E2: Delta | F2: % | G2: Forecasted | H2: Delta | I2: %
A3: {=Sites[Site]} -> Williamsburg A | B3: {=Sites[State]} -> MA | C3: {=IF(INDIRECT("'" & $A3 & "'!B11:J11")="", "", INDIRECT("'" & $A3 & "'!B11:J11"))} | E3: 0 | F3: 0 | H3: 0 | I3: 0
A4: Orange A KB | B4: MA | C4: {=IF(INDIRECT("'" & $A4 & "'!B11:J11")="", "", INDIRECT("'" & $A4 & "'!B11:J11"))} | E4: 0 | F4: 0 | H4: 0 | I4: 0
A5: Goshen A | B5: MA | C5: {=IF(INDIRECT("'" & $A5 & "'!B11:J11")="", "", INDIRECT("'" & $A5 & "'!B11:J11"))} | E5: 0 | F5: 0 | H5: 0 | I5: 0
A6: Phillipston A KB | B6: MA | C6: {=IF(INDIRECT("'" & $A6 & "'!B11:J11")="", "", INDIRECT("'" & $A6 & "'!B11:J11"))} | E6: 0 | F6: 0 | H6: 0 | I6: 0
A7: Uxbridge D | B7: MA | C7: {=IF(INDIRECT("'" & $A7 & "'!B11:J11")="", "", INDIRECT("'" & $A7 & "'!B11:J11"))} | E7: 0 | F7: 0 | H7: 0 | I7: 0
A8: West Bridgewater A&B | B8: MA | C8: {=IF(INDIRECT("'" & $A8 & "'!B11:J11")="", "", INDIRECT("'" & $A8 & "'!B11:J11"))} | E8: 0 | F8: 0 | H8: 0 | I8: 0
A9: Sutton A | B9: MA | C9: {=IF(INDIRECT("'" & $A9 & "'!B11:J11")="", "", INDIRECT("'" & $A9 & "'!B11:J11"))} | E9: 0 | F9: 0 | H9: 0 | I9: 0
A10: North Adams A | B10: MA | C10: {=IF(INDIRECT("'" & $A10 & "'!B11:J11")="", "", INDIRECT("'" & $A10 & "'!B11:J11"))} | E10: 0 | F10: 0 | H10: 0 | I10: 0
A11: North Adams B | B11: MA | C11: {=IF(INDIRECT("'" & $A11 & "'!B11:J11")="", "", INDIRECT("'" & $A11 & "'!B11:J11"))} | E11: 0 | F11: 0 | H11: 0 | I11: 0
A12: Clarksburg A | B12: MA | C12: {=IF(INDIRECT("'" & $A12 & "'!B11:J11")="", "", INDIRECT("'" & $A12 & "'!B11:J11"))} | E12: 0 | F12: 0 | H12: 0 | I12: 0
A13: Swansea B | B13: MA | C13: {=IF(INDIRECT("'" & $A13 & "'!B11:J11")="", "", INDIRECT("'" & $A13 & "'!B11:J11"))} | E13: 0 | F13: 0 | H13: 0 | I13: 0
A14: Wareham 2 | B14: MA | C14: {=IF(INDIRECT("'" & $A14 & "'!B11:J11")="", "", INDIRECT("'" & $A14 & "'!B11:J11"))} | E14: 0 | F14: 0 | H14: 0 | I14: 0
A15: Kingston 1 KB | B15: MA | C15: {=IF(INDIRECT("'" & $A15 & "'!B11:J11")="", "", INDIRECT("'" & $A15 & "'!B11:J11"))} | E15: 0 | F15: 0 | H15: 0 | I15: 0
... A19: Plympton A-2 | B19: MA | C19: {=IF(INDIRECT("'" & $A19 & "'!B11:J11")="", "", INDIRECT("'" & $A19 & "'!B11:J11"))} | E19: 0 | F19: 0 | H19: 0 | I19: 0
A20: Total | C20: =SUM(C3:C19) -> 0 | D20: =SUM(D3:D19) -> 0 | E20: =C20-D20 -> 0 | F20: =IFERROR(E20/D20, 0) -> 0 | G20: =SUM(G3:G19) -> 0 | H20: =C20-G20 -> 0 | I20: =IFERROR(H20/G20, 0) -> 0
A22: Values in gold exceed expected or forecasted by 10% or more.
A24: Values in red are below expected or forecasted by 10% or more.

Sheet 08-2024
A1: {=portfolio} -> MN8 KEF | C1: 8-2024 Actual v. Expected | G1: 8-2024 Actual v. Forecasted | J1: NOTES | K1: SR
A2: Site | B2: State | C2: Actual | D2: Expected | E2: Delta | F2: % | G2: Forecasted | H2: Delta | I2: %
A3: {=Sites[Site]} -> Williamsburg A | B3: {=Sites[State]} -> MA | C3: {=IF(INDIRECT("'" & $A3 & "'!B12:J12")="", "", INDIRECT("'" & $A3 & "'!B12:J12"))} | E3: 0 | F3: 0 | H3: 0 | I3: 0
A4: Orange A KB | B4: MA | C4: {=IF(INDIRECT("'" & $A4 & "'!B12:J12")="", "", INDIRECT("'" & $A4 & "'!B12:J12"))} | E4: 0 | F4: 0 | H4: 0 | I4: 0
A5: Goshen A | B5: MA | C5: {=IF(INDIRECT("'" & $A5 & "'!B12:J12")="", "", INDIRECT("'" & $A5 & "'!B12:J12"))} | E5: 0 | F5: 0 | H5: 0 | I5: 0
A6: Phillipston A KB | B6: MA | C6: {=IF(INDIRECT("'" & $A6 & "'!B12:J12")="", "", INDIRECT("'" & $A6 & "'!B12:J12"))} | E6: 0 | F6: 0 | H6: 0 | I6: 0
A7: Uxbridge D | B7: MA | C7: {=IF(INDIRECT("'" & $A7 & "'!B12:J12")="", "", INDIRECT("'" & $A7 & "'!B12:J12"))} | E7: 0 | F7: 0 | H7: 0 | I7: 0
A8: West Bridgewater A&B | B8: MA | C8: {=IF(INDIRECT("'" & $A8 & "'!B12:J12")="", "", INDIRECT("'" & $A8 & "'!B12:J12"))} | E8: 0 | F8: 0 | H8: 0 | I8: 0
A9: Sutton A | B9: MA | C9: {=IF(INDIRECT("'" & $A9 & "'!B12:J12")="", "", INDIRECT("'" & $A9 & "'!B12:J12"))} | E9: 0 | F9: 0 | H9: 0 | I9: 0
A10: North Adams A | B10: MA | C10: {=IF(INDIRECT("'" & $A10 & "'!B12:J12")="", "", INDIRECT("'" & $A10 & "'!B12:J12"))} | E10: 0 | F10: 0 | H10: 0 | I10: 0
A11: North Adams B | B11: MA | C11: {=IF(INDIRECT("'" & $A11 & "'!B12:J12")="", "", INDIRECT("'" & $A11 & "'!B12:J12"))} | E11: 0 | F11: 0 | H11: 0 | I11: 0
A12: Clarksburg A | B12: MA | C12: {=IF(INDIRECT("'" & $A12 & "'!B12:J12")="", "", INDIRECT("'" & $A12 & "'!B12:J12"))} | E12: 0 | F12: 0 | H12: 0 | I12: 0
A13: Swansea B | B13: MA | C13: {=IF(INDIRECT("'" & $A13 & "'!B12:J12")="", "", INDIRECT("'" & $A13 & "'!B12:J12"))} | E13: 0 | F13: 0 | H13: 0 | I13: 0
A14: Wareham 2 | B14: MA | C14: {=IF(INDIRECT("'" & $A14 & "'!B12:J12")="", "", INDIRECT("'" & $A14 & "'!B12:J12"))} | E14: 0 | F14: 0 | H14: 0 | I14: 0
A15: Kingston 1 KB | B15: MA | C15: {=IF(INDIRECT("'" & $A15 & "'!B12:J12")="", "", INDIRECT("'" & $A15 & "'!B12:J12"))} | E15: 0 | F15: 0 | H15: 0 | I15: 0
... A19: Plympton A-2 | B19: MA | C19: {=IF(INDIRECT("'" & $A19 & "'!B12:J12")="", "", INDIRECT("'" & $A19 & "'!B12:J12"))} | E19: 0 | F19: 0 | H19: 0 | I19: 0
A20: Total | C20: =SUM(C3:C19) -> 0 | D20: =SUM(D3:D19) -> 0 | E20: =C20-D20 -> 0 | F20: =IFERROR(E20/D20, 0) -> 0 | G20: =SUM(G3:G19) -> 0 | H20: =C20-G20 -> 0 | I20: =IFERROR(H20/G20, 0) -> 0
A22: Values in gold exceed expected or forecasted by 10% or more.
A24: Values in red are below expected or forecasted by 10% or more.

Sheet 09-2024
A1: {=portfolio} -> MN8 KEF | C1: 9-2024 Actual v. Expected | G1: 9-2024 Actual v. Forecasted | J1: NOTES | K1: SR
A2: Site | B2: State | C2: Actual | D2: Expected | E2: Delta | F2: % | G2: Forecasted | H2: Delta | I2: %
A3: {=Sites[Site]} -> Williamsburg A | B3: {=Sites[State]} -> MA | C3: {=IF(INDIRECT("'" & $A3 & "'!B13:J13")="", "", INDIRECT("'" & $A3 & "'!B13:J13"))} | E3: 0 | F3: 0 | H3: 0 | I3: 0
A4: Orange A KB | B4: MA | C4: {=IF(INDIRECT("'" & $A4 & "'!B13:J13")="", "", INDIRECT("'" & $A4 & "'!B13:J13"))} | E4: 0 | F4: 0 | H4: 0 | I4: 0
A5: Goshen A | B5: MA | C5: {=IF(INDIRECT("'" & $A5 & "'!B13:J13")="", "", INDIRECT("'" & $A5 & "'!B13:J13"))} | E5: 0 | F5: 0 | H5: 0 | I5: 0
A6: Phillipston A KB | B6: MA | C6: {=IF(INDIRECT("'" & $A6 & "'!B13:J13")="", "", INDIRECT("'" & $A6 & "'!B13:J13"))} | E6: 0 | F6: 0 | H6: 0 | I6: 0
A7: Uxbridge D | B7: MA | C7: {=IF(INDIRECT("'" & $A7 & "'!B13:J13")="", "", INDIRECT("'" & $A7 & "'!B13:J13"))} | E7: 0 | F7: 0 | H7: 0 | I7: 0
A8: West Bridgewater A&B | B8: MA | C8: {=IF(INDIRECT("'" & $A8 & "'!B13:J13")="", "", INDIRECT("'" & $A8 & "'!B13:J13"))} | E8: 0 | F8: 0 | H8: 0 | I8: 0
A9: Sutton A | B9: MA | C9: {=IF(INDIRECT("'" & $A9 & "'!B13:J13")="", "", INDIRECT("'" & $A9 & "'!B13:J13"))} | E9: 0 | F9: 0 | H9: 0 | I9: 0
A10: North Adams A | B10: MA | C10: {=IF(INDIRECT("'" & $A10 & "'!B13:J13")="", "", INDIRECT("'" & $A10 & "'!B13:J13"))} | E10: 0 | F10: 0 | H10: 0 | I10: 0
A11: North Adams B | B11: MA | C11: {=IF(INDIRECT("'" & $A11 & "'!B13:J13")="", "", INDIRECT("'" & $A11 & "'!B13:J13"))} | E11: 0 | F11: 0 | H11: 0 | I11: 0
A12: Clarksburg A | B12: MA | C12: {=IF(INDIRECT("'" & $A12 & "'!B13:J13")="", "", INDIRECT("'" & $A12 & "'!B13:J13"))} | E12: 0 | F12: 0 | H12: 0 | I12: 0
A13: Swansea B | B13: MA | C13: {=IF(INDIRECT("'" & $A13 & "'!B13:J13")="", "", INDIRECT("'" & $A13 & "'!B13:J13"))} | E13: 0 | F13: 0 | H13: 0 | I13: 0
A14: Wareham 2 | B14: MA | C14: {=IF(INDIRECT("'" & $A14 & "'!B13:J13")="", "", INDIRECT("'" & $A14 & "'!B13:J13"))} | E14: 0 | F14: 0 | H14: 0 | I14: 0
A15: Kingston 1 KB | B15: MA | C15: {=IF(INDIRECT("'" & $A15 & "'!B13:J13")="", "", INDIRECT("'" & $A15 & "'!B13:J13"))} | E15: 0 | F15: 0 | H15: 0 | I15: 0
... A19: Plympton A-2 | B19: MA | C19: {=IF(INDIRECT("'" & $A19 & "'!B13:J13")="", "", INDIRECT("'" & $A19 & "'!B13:J13"))} | E19: 0 | F19: 0 | H19: 0 | I19: 0
A20: Total | C20: =SUM(C3:C19) -> 0 | D20: =SUM(D3:D19) -> 0 | E20: =C20-D20 -> 0 | F20: =IFERROR(E20/D20, 0) -> 0 | G20: =SUM(G3:G19) -> 0 | H20: =C20-G20 -> 0 | I20: =IFERROR(H20/G20, 0) -> 0
A22: Values in gold exceed expected or forecasted by 10% or more.
A24: Values in red are below expected or forecasted by 10% or more.

Sheet 10-2024
A1: {=portfolio} -> MN8 KEF | C1: 10-2024 Actual v. Expected | G1: 10-2024 Actual v. Forecasted | J1: NOTES | K1: SR
A2: Site | B2: State | C2: Actual | D2: Expected | E2: Delta | F2: % | G2: Forecasted | H2: Delta | I2: %
A3: {=Sites[Site]} -> Williamsburg A | B3: {=Sites[State]} -> MA | C3: {=IF(INDIRECT("'" & $A3 & "'!B14:J14")="", "", INDIRECT("'" & $A3 & "'!B14:J14"))} | E3: 0 | F3: 0 | H3: 0 | I3: 0
A4: Orange A KB | B4: MA | C4: {=IF(INDIRECT("'" & $A4 & "'!B14:J14")="", "", INDIRECT("'" & $A4 & "'!B14:J14"))} | E4: 0 | F4: 0 | H4: 0 | I4: 0
A5: Goshen A | B5: MA | C5: {=IF(INDIRECT("'" & $A5 & "'!B14:J14")="", "", INDIRECT("'" & $A5 & "'!B14:J14"))} | E5: 0 | F5: 0 | H5: 0 | I5: 0
A6: Phillipston A KB | B6: MA | C6: {=IF(INDIRECT("'" & $A6 & "'!B14:J14")="", "", INDIRECT("'" & $A6 & "'!B14:J14"))} | E6: 0 | F6: 0 | H6: 0 | I6: 0
A7: Uxbridge D | B7: MA | C7: {=IF(INDIRECT("'" & $A7 & "'!B14:J14")="", "", INDIRECT("'" & $A7 & "'!B14:J14"))} | E7: 0 | F7: 0 | H7: 0 | I7: 0
A8: West Bridgewater A&B | B8: MA | C8: {=IF(INDIRECT("'" & $A8 & "'!B14:J14")="", "", INDIRECT("'" & $A8 & "'!B14:J14"))} | E8: 0 | F8: 0 | H8: 0 | I8: 0
A9: Sutton A | B9: MA | C9: {=IF(INDIRECT("'" & $A9 & "'!B14:J14")="", "", INDIRECT("'" & $A9 & "'!B14:J14"))} | E9: 0 | F9: 0 | H9: 0 | I9: 0
A10: North Adams A | B10: MA | C10: {=IF(INDIRECT("'" & $A10 & "'!B14:J14")="", "", INDIRECT("'" & $A10 & "'!B14:J14"))} | E10: 0 | F10: 0 | H10: 0 | I10: 0
A11: North Adams B | B11: MA | C11: {=IF(INDIRECT("'" & $A11 & "'!B14:J14")="", "", INDIRECT("'" & $A11 & "'!B14:J14"))} | E11: 0 | F11: 0 | H11: 0 | I11: 0
A12: Clarksburg A | B12: MA | C12: {=IF(INDIRECT("'" & $A12 & "'!B14:J14")="", "", INDIRECT("'" & $A12 & "'!B14:J14"))} | E12: 0 | F12: 0 | H12: 0 | I12: 0
A13: Swansea B | B13: MA | C13: {=IF(INDIRECT("'" & $A13 & "'!B14:J14")="", "", INDIRECT("'" & $A13 & "'!B14:J14"))} | E13: 0 | F13: 0 | H13: 0 | I13: 0
A14: Wareham 2 | B14: MA | C14: {=IF(INDIRECT("'" & $A14 & "'!B14:J14")="", "", INDIRECT("'" & $A14 & "'!B14:J14"))} | E14: 0 | F14: 0 | H14: 0 | I14: 0
A15: Kingston 1 KB | B15: MA | C15: {=IF(INDIRECT("'" & $A15 & "'!B14:J14")="", "", INDIRECT("'" & $A15 & "'!B14:J14"))} | E15: 0 | F15: 0 | H15: 0 | I15: 0
... A19: Plympton A-2 | B19: MA | C19: {=IF(INDIRECT("'" & $A19 & "'!B14:J14")="", "", INDIRECT("'" & $A19 & "'!B14:J14"))} | E19: 0 | F19: 0 | H19: 0 | I19: 0
A20: Total | C20: =SUM(C3:C19) -> 0 | D20: =SUM(D3:D19) -> 0 | E20: =C20-D20 -> 0 | F20: =IFERROR(E20/D20, 0) -> 0 | G20: =SUM(G3:G19) -> 0 | H20: =C20-G20 -> 0 | I20: =IFERROR(H20/G20, 0) -> 0
A22: Values in gold exceed expected or forecasted by 10% or more.
A24: Values in red are below expected or forecasted by 10% or more.

Sheet 11-2024
A1: {=portfolio} -> MN8 KEF | C1: 11-2024 Actual v. Expected | G1: 11-2024 Actual v. Forecasted | J1: NOTES | K1: SR
A2: Site | B2: State | C2: Actual | D2: Expected | E2: Delta | F2: % | G2: Forecasted | H2: Delta | I2: %
A3: {=Sites[Site]} -> Williamsburg A | B3: {=Sites[State]} -> MA | C3: {=IF(INDIRECT("'" & $A3 & "'!B15:J15")="", "", INDIRECT("'" & $A3 & "'!B15:J15"))} | E3: 0 | F3: 0 | H3: 0 | I3: 0
