Workbook
Name JanActual: '01-2024'!$C$3:$C$64
Name JanActual2: '01-2024'!$H$3:$H$64
Name JanExpected: '01-2024'!$D$3:$D$64
Name JanExpectedDelta: '01-2024'!$E$3:$E$64
Name JanExpectedPercent: '01-2024'!$F$3:$F$64
Name JanExpPercent: '01-2024'!$F$3:$F$64
Name JanForecasted: '01-2024'!$I$3:$I$64
Name JanForecastedDelta: '01-2024'!$J$3:$J$64
Name JanForecastedPercent: '01-2024'!$K$3:$K$64

Sheet YTD Total 2024
A1: WELLS FARGO | B1: YTD Total 2024 Actual v. Expected | G1: YTD Total 2024 Actual v. Forecasted
A2: State | B2: Actual | C2: Expected | D2: Delta | E2: % | G2: Actual | H2: Forecasted | I2: Delta | J2: %
A3: {=_xlfn.UNIQUE(Sites[State])} -> CA | B3: ='1st Quarter 2024'!B3+'2nd Quarter 2024'!B3+'3rd Quarter 2024'!B3+'4th Quarter 2024'!B3 -> 20561.362 | C3: ='1st Quarter 2024'!C3+'2nd Quarter 2024'!C3+'3rd Quarter 2024'!C3+'4th Quarter 2024'!C3 -> 25565.67 | D3: =B3-C3 -> -5004.3081 | E3: =IFERROR(D3/C3, "-") -> -0.19574328 | G3: ='1st Quarter 2024'!G3+'2nd Quarter 2024'!G3+'3rd Quarter 2024'!G3+'4th Quarter 2024'!G3 -> 20561.362 | H3: ='1st Quarter 2024'!H3+'2nd Quarter 2024'!H3+'3rd Quarter 2024'!H3+'4th Quarter 2024'!H3 -> 24910.173 | I3: =G3-H3 -> -4348.8111 | J3: =IFERROR(I3/H3, "-") -> -0.17457972 | L3: Gold highlighted cells for Actual Production vs Expected and Forecasted values varying positive 10% or more.
A4: CO | B4: ='1st Quarter 2024'!B4+'2nd Quarter 2024'!B4+'3rd Quarter 2024'!B4+'4th Quarter 2024'!B4 -> 14268.598 | C4: ='1st Quarter 2024'!C4+'2nd Quarter 2024'!C4+'3rd Quarter 2024'!C4+'4th Quarter 2024'!C4 -> 0 | D4: =B4-C4 -> 14268.598 | E4: =IFERROR(D4/C4, "-") -> - | G4: ='1st Quarter 2024'!G4+'2nd Quarter 2024'!G4+'3rd Quarter 2024'!G4+'4th Quarter 2024'!G4 -> 14268.598 | H4: ='1st Quarter 2024'!H4+'2nd Quarter 2024'!H4+'3rd Quarter 2024'!H4+'4th Quarter 2024'!H4 -> 15280.869 | I4: =G4-H4 -> -1012.2706 | J4: =IFERROR(I4/H4, "-") -> -0.066244311 | L4: Red highlighted cells for Actual Production vs Expected and Forecasted values varying negative 10% or more.
A5: CT | B5: ='1st Quarter 2024'!B5+'2nd Quarter 2024'!B5+'3rd Quarter 2024'!B5+'4th Quarter 2024'!B5 -> 237.44058 | C5: ='1st Quarter 2024'!C5+'2nd Quarter 2024'!C5+'3rd Quarter 2024'!C5+'4th Quarter 2024'!C5 -> 664.2131 | D5: =B5-C5 -> -426.77252 | E5: =IFERROR(D5/C5, "-") -> -0.64252349 | G5: ='1st Quarter 2024'!G5+'2nd Quarter 2024'!G5+'3rd Quarter 2024'!G5+'4th Quarter 2024'!G5 -> 237.44058 | H5: ='1st Quarter 2024'!H5+'2nd Quarter 2024'!H5+'3rd Quarter 2024'!H5+'4th Quarter 2024'!H5 -> 650.032 | I5: =G5-H5 -> -412.59142 | J5: =IFERROR(I5/H5, "-") -> -0.63472479
A6: FL | B6: ='1st Quarter 2024'!B6+'2nd Quarter 2024'!B6+'3rd Quarter 2024'!B6+'4th Quarter 2024'!B6 -> 1428.4985 | C6: ='1st Quarter 2024'!C6+'2nd Quarter 2024'!C6+'3rd Quarter 2024'!C6+'4th Quarter 2024'!C6 -> 2582.073 | D6: =B6-C6 -> -1153.5745 | E6: =IFERROR(D6/C6, "-") -> -0.44676292 | G6: ='1st Quarter 2024'!G6+'2nd Quarter 2024'!G6+'3rd Quarter 2024'!G6+'4th Quarter 2024'!G6 -> 1428.4985 | H6: ='1st Quarter 2024'!H6+'2nd Quarter 2024'!H6+'3rd Quarter 2024'!H6+'4th Quarter 2024'!H6 -> 3451.661 | I6: =G6-H6 -> -2023.1625 | J6: =IFERROR(I6/H6, "-") -> -0.58614171
A7: IA | B7: ='1st Quarter 2024'!B7+'2nd Quarter 2024'!B7+'3rd Quarter 2024'!B7+'4th Quarter 2024'!B7 -> 99895.938 | C7: ='1st Quarter 2024'!C7+'2nd Quarter 2024'!C7+'3rd Quarter 2024'!C7+'4th Quarter 2024'!C7 -> 29613.754 | D7: =B7-C7 -> 70282.183 | E7: =IFERROR(D7/C7, "-") -> 2.3732953 | G7: ='1st Quarter 2024'!G7+'2nd Quarter 2024'!G7+'3rd Quarter 2024'!G7+'4th Quarter 2024'!G7 -> 99895.938 | H7: ='1st Quarter 2024'!H7+'2nd Quarter 2024'!H7+'3rd Quarter 2024'!H7+'4th Quarter 2024'!H7 -> 185906.71 | I7: =G7-H7 -> -86010.769 | J7: =IFERROR(I7/H7, "-") -> -0.46265555
A8: NC | B8: ='1st Quarter 2024'!B8+'2nd Quarter 2024'!B8+'3rd Quarter 2024'!B8+'4th Quarter 2024'!B8 -> 0 | C8: ='1st Quarter 2024'!C8+'2nd Quarter 2024'!C8+'3rd Quarter 2024'!C8+'4th Quarter 2024'!C8 -> 0 | D8: =B8-C8 -> 0 | E8: =IFERROR(D8/C8, "-") -> - | G8: ='1st Quarter 2024'!G8+'2nd Quarter 2024'!G8+'3rd Quarter 2024'!G8+'4th Quarter 2024'!G8 -> 0 | H8: ='1st Quarter 2024'!H8+'2nd Quarter 2024'!H8+'3rd Quarter 2024'!H8+'4th Quarter 2024'!H8 -> 0 | I8: =G8-H8 -> 0 | J8: =IFERROR(I8/H8, "-") -> -
A9: NJ | B9: ='1st Quarter 2024'!B9+'2nd Quarter 2024'!B9+'3rd Quarter 2024'!B9+'4th Quarter 2024'!B9 -> 22784.798 | C9: ='1st Quarter 2024'!C9+'2nd Quarter 2024'!C9+'3rd Quarter 2024'!C9+'4th Quarter 2024'!C9 -> 29041.817 | D9: =B9-C9 -> -6257.0181 | E9: =IFERROR(D9/C9, "-") -> -0.21544858 | G9: ='1st Quarter 2024'!G9+'2nd Quarter 2024'!G9+'3rd Quarter 2024'!G9+'4th Quarter 2024'!G9 -> 22784.798 | H9: ='1st Quarter 2024'!H9+'2nd Quarter 2024'!H9+'3rd Quarter 2024'!H9+'4th Quarter 2024'!H9 -> 40758.549 | I9: =G9-H9 -> -17973.751 | J9: =IFERROR(I9/H9, "-") -> -0.44098112
A10: TX | B10: ='1st Quarter 2024'!B10+'2nd Quarter 2024'!B10+'3rd Quarter 2024'!B10+'4th Quarter 2024'!B10 -> 275701.25 | C10: ='1st Quarter 2024'!C10+'2nd Quarter 2024'!C10+'3rd Quarter 2024'!C10+'4th Quarter 2024'!C10 -> 318383.4 | D10: =B10-C10 -> -42682.15 | E10: =IFERROR(D10/C10, "-") -> -0.13405897 | G10: ='1st Quarter 2024'!G10+'2nd Quarter 2024'!G10+'3rd Quarter 2024'!G10+'4th Quarter 2024'!G10 -> 275701.25 | H10: ='1st Quarter 2024'!H10+'2nd Quarter 2024'!H10+'3rd Quarter 2024'!H10+'4th Quarter 2024'!H10 -> 427842.06 | I10: =G10-H10 -> -152140.81 | J10: =IFERROR(I10/H10, "-") -> -0.3556004
A11: Total | B11: ='1st Quarter 2024'!B11+'2nd Quarter 2024'!B11+'3rd Quarter 2024'!B10+'4th Quarter 2024'!B10 -> 434877.89 | C11: ='1st Quarter 2024'!C11+'2nd Quarter 2024'!C11+'3rd Quarter 2024'!C10+'4th Quarter 2024'!C10 -> 405850.93 | D11: =B11-C11 -> 29026.959 | E11: =IFERROR(D11/C11, "-") -> 0.071521233 | G11: ='1st Quarter 2024'!G11+'2nd Quarter 2024'!G11+'3rd Quarter 2024'!G10+'4th Quarter 2024'!G10 -> 434877.89 | H11: ='1st Quarter 2024'!H11+'2nd Quarter 2024'!H11+'3rd Quarter 2024'!H10+'4th Quarter 2024'!H10 -> 698800.05 | I11: =G11-H11 -> -263922.16 | J11: =IFERROR(I11/H11, "-") -> -0.37767909

Sheet 1st Quarter 2024
A1: WELLS FARGO | B1: 1st Quarter 2024 Actual v. Expected | G1: 1st Quarter 2024 Actual v. Forecasted
A2: State | B2: Actual | C2: Expected | D2: Delta | E2: % | G2: Actual | H2: Forecasted | I2: Delta | J2: %
A3: {=_xlfn.UNIQUE(Sites[State])} -> CA | B3: {=SUM(_xlfn._xlws.FILTER('01-2024'!C$3:$C$64,'01-2024'!$B$3:$B$64=$A3), _xlfn._xlws.FILTER('02-2024'!C$3:$C$64,'02-2024'!$B$3:$B$64=$A3), _xlfn._xlws.FILTER('03-2024'!C$3:$C$64,'03-2024'!$B$3:$B$64=$A3))} -> 20561.362 | C3: {=SUM(_xlfn._xlws.FILTER('01-2024'!D$3:$D$64,'01-2024'!$B$3:$B$64=$A3), _xlfn._xlws.FILTER('02-2024'!D$3:$D$64,'02-2024'!$B$3:$B$64=$A3), _xlfn._xlws.FILTER('03-2024'!D$3:$D$64,'03-2024'!$B$3:$B$64=$A3))} -> 25565.67 | D3: =B3-C3 -> -5004.3081 | E3: =IFERROR(D3/C3, "-") -> -0.19574328 | G3: =B3 -> 20561.362 | H3: {=SUM(_xlfn._xlws.FILTER('01-2024'!$I$3:$I$64,'01-2024'!$B$3:$B$64=$A3), _xlfn._xlws.FILTER('02-2024'!$I$3:$I$64,'02-2024'!$B$3:$B$64=$A3), _xlfn._xlws.FILTER('03-2024'!I$3:$I$64,'03-2024'!$B$3:$B$64=$A3))} -> 24910.173 | I3: =G3-H3 -> -4348.8111 | J3: =IFERROR(I3/H3, "-") -> -0.17457972 | L3: Gold highlighted cells for Actual Production vs Expected and Forecasted values varying positive 10% or more.
A4: CO | B4: {=SUM(_xlfn._xlws.FILTER('01-2024'!C$3:$C$64,'01-2024'!$B$3:$B$64=$A4), _xlfn._xlws.FILTER('02-2024'!C$3:$C$64,'02-2024'!$B$3:$B$64=$A4), _xlfn._xlws.FILTER('03-2024'!C$3:$C$64,'03-2024'!$B$3:$B$64=$A4))} -> 14268.598 | C4: {=SUM(_xlfn._xlws.FILTER('01-2024'!D$3:$D$64,'01-2024'!$B$3:$B$64=$A4), _xlfn._xlws.FILTER('02-2024'!D$3:$D$64,'02-2024'!$B$3:$B$64=$A4), _xlfn._xlws.FILTER('03-2024'!D$3:$D$64,'03-2024'!$B$3:$B$64=$A4))} -> 0 | D4: =B4-C4 -> 14268.598 | E4: =IFERROR(D4/C4, "-") -> - | G4: =B4 -> 14268.598 | H4: {=SUM(_xlfn._xlws.FILTER('01-2024'!$I$3:$I$64,'01-2024'!$B$3:$B$64=$A4), _xlfn._xlws.FILTER('02-2024'!$I$3:$I$64,'02-2024'!$B$3:$B$64=$A4), _xlfn._xlws.FILTER('03-2024'!I$3:$I$64,'03-2024'!$B$3:$B$64=$A4))} -> 15280.869 | I4: =G4-H4 -> -1012.2706 | J4: =IFERROR(I4/H4, "-") -> -0.066244311 | L4: Red highlighted cells for Actual Production vs Expected and Forecasted values varying negative 10% or more.
A5: CT | B5: {=SUM(_xlfn._xlws.FILTER('01-2024'!C$3:$C$64,'01-2024'!$B$3:$B$64=$A5), _xlfn._xlws.FILTER('02-2024'!C$3:$C$64,'02-2024'!$B$3:$B$64=$A5), _xlfn._xlws.FILTER('03-2024'!C$3:$C$64,'03-2024'!$B$3:$B$64=$A5))} -> 237.44058 | C5: {=SUM(_xlfn._xlws.FILTER('01-2024'!D$3:$D$64,'01-2024'!$B$3:$B$64=$A5), _xlfn._xlws.FILTER('02-2024'!D$3:$D$64,'02-2024'!$B$3:$B$64=$A5), _xlfn._xlws.FILTER('03-2024'!D$3:$D$64,'03-2024'!$B$3:$B$64=$A5))} -> 664.2131 | D5: =B5-C5 -> -426.77252 | E5: =IFERROR(D5/C5, "-") -> -0.64252349 | G5: =B5 -> 237.44058 | H5: {=SUM(_xlfn._xlws.FILTER('01-2024'!$I$3:$I$64,'01-2024'!$B$3:$B$64=$A5), _xlfn._xlws.FILTER('02-2024'!$I$3:$I$64,'02-2024'!$B$3:$B$64=$A5), _xlfn._xlws.FILTER('03-2024'!I$3:$I$64,'03-2024'!$B$3:$B$64=$A5))} -> 650.032 | I5: =G5-H5 -> -412.59142 | J5: =IFERROR(I5/H5, "-") -> -0.63472479
A6: FL | B6: {=SUM(_xlfn._xlws.FILTER('01-2024'!C$3:$C$64,'01-2024'!$B$3:$B$64=$A6), _xlfn._xlws.FILTER('02-2024'!C$3:$C$64,'02-2024'!$B$3:$B$64=$A6), _xlfn._xlws.FILTER('03-2024'!C$3:$C$64,'03-2024'!$B$3:$B$64=$A6))} -> 1428.4985 | C6: {=SUM(_xlfn._xlws.FILTER('01-2024'!D$3:$D$64,'01-2024'!$B$3:$B$64=$A6), _xlfn._xlws.FILTER('02-2024'!D$3:$D$64,'02-2024'!$B$3:$B$64=$A6), _xlfn._xlws.FILTER('03-2024'!D$3:$D$64,'03-2024'!$B$3:$B$64=$A6))} -> 2582.073 | D6: =B6-C6 -> -1153.5745 | E6: =IFERROR(D6/C6, "-") -> -0.44676292 | G6: =B6 -> 1428.4985 | H6: {=SUM(_xlfn._xlws.FILTER('01-2024'!$I$3:$I$64,'01-2024'!$B$3:$B$64=$A6), _xlfn._xlws.FILTER('02-2024'!$I$3:$I$64,'02-2024'!$B$3:$B$64=$A6), _xlfn._xlws.FILTER('03-2024'!I$3:$I$64,'03-2024'!$B$3:$B$64=$A6))} -> 3451.661 | I6: =G6-H6 -> -2023.1625 | J6: =IFERROR(I6/H6, "-") -> -0.58614171
A7: IA | B7: {=SUM(_xlfn._xlws.FILTER('01-2024'!C$3:$C$64,'01-2024'!$B$3:$B$64=$A7), _xlfn._xlws.FILTER('02-2024'!C$3:$C$64,'02-2024'!$B$3:$B$64=$A7), _xlfn._xlws.FILTER('03-2024'!C$3:$C$64,'03-2024'!$B$3:$B$64=$A7))} -> 99895.938 | C7: {=SUM(_xlfn._xlws.FILTER('01-2024'!D$3:$D$64,'01-2024'!$B$3:$B$64=$A7), _xlfn._xlws.FILTER('02-2024'!D$3:$D$64,'02-2024'!$B$3:$B$64=$A7), _xlfn._xlws.FILTER('03-2024'!D$3:$D$64,'03-2024'!$B$3:$B$64=$A7))} -> 29613.754 | D7: =B7-C7 -> 70282.183 | E7: =IFERROR(D7/C7, "-") -> 2.3732953 | G7: =B7 -> 99895.938 | H7: {=SUM(_xlfn._xlws.FILTER('01-2024'!$I$3:$I$64,'01-2024'!$B$3:$B$64=$A7), _xlfn._xlws.FILTER('02-2024'!$I$3:$I$64,'02-2024'!$B$3:$B$64=$A7), _xlfn._xlws.FILTER('03-2024'!I$3:$I$64,'03-2024'!$B$3:$B$64=$A7))} -> 185906.71 | I7: =G7-H7 -> -86010.769 | J7: =IFERROR(I7/H7, "-") -> -0.46265555
A8: NC | B8: {=SUM(_xlfn._xlws.FILTER('01-2024'!C$3:$C$64,'01-2024'!$B$3:$B$64=$A8), _xlfn._xlws.FILTER('02-2024'!C$3:$C$64,'02-2024'!$B$3:$B$64=$A8), _xlfn._xlws.FILTER('03-2024'!C$3:$C$64,'03-2024'!$B$3:$B$64=$A8))} -> 0 | C8: {=SUM(_xlfn._xlws.FILTER('01-2024'!D$3:$D$64,'01-2024'!$B$3:$B$64=$A8), _xlfn._xlws.FILTER('02-2024'!D$3:$D$64,'02-2024'!$B$3:$B$64=$A8), _xlfn._xlws.FILTER('03-2024'!D$3:$D$64,'03-2024'!$B$3:$B$64=$A8))} -> 0 | D8: =B8-C8 -> 0 | E8: =IFERROR(D8/C8, "-") -> - | G8: =B8 -> 0 | H8: {=SUM(_xlfn._xlws.FILTER('01-2024'!$I$3:$I$64,'01-2024'!$B$3:$B$64=$A8), _xlfn._xlws.FILTER('02-2024'!$I$3:$I$64,'02-2024'!$B$3:$B$64=$A8), _xlfn._xlws.FILTER('03-2024'!I$3:$I$64,'03-2024'!$B$3:$B$64=$A8))} -> 0 | I8: =G8-H8 -> 0 | J8: =IFERROR(I8/H8, "-") -> -
A9: NJ | B9: {=SUM(_xlfn._xlws.FILTER('01-2024'!C$3:$C$64,'01-2024'!$B$3:$B$64=$A9), _xlfn._xlws.FILTER('02-2024'!C$3:$C$64,'02-2024'!$B$3:$B$64=$A9), _xlfn._xlws.FILTER('03-2024'!C$3:$C$64,'03-2024'!$B$3:$B$64=$A9))} -> 22784.798 | C9: {=SUM(_xlfn._xlws.FILTER('01-2024'!D$3:$D$64,'01-2024'!$B$3:$B$64=$A9), _xlfn._xlws.FILTER('02-2024'!D$3:$D$64,'02-2024'!$B$3:$B$64=$A9), _xlfn._xlws.FILTER('03-2024'!D$3:$D$64,'03-2024'!$B$3:$B$64=$A9))} -> 29041.817 | D9: =B9-C9 -> -6257.0181 | E9: =IFERROR(D9/C9, "-") -> -0.21544858 | G9: =B9 -> 22784.798 | H9: {=SUM(_xlfn._xlws.FILTER('01-2024'!$I$3:$I$64,'01-2024'!$B$3:$B$64=$A9), _xlfn._xlws.FILTER('02-2024'!$I$3:$I$64,'02-2024'!$B$3:$B$64=$A9), _xlfn._xlws.FILTER('03-2024'!I$3:$I$64,'03-2024'!$B$3:$B$64=$A9))} -> 40758.549 | I9: =G9-H9 -> -17973.751 | J9: =IFERROR(I9/H9, "-") -> -0.44098112
A10: TX | B10: {=SUM(_xlfn._xlws.FILTER('01-2024'!C$3:$C$64,'01-2024'!$B$3:$B$64=$A10), _xlfn._xlws.FILTER('02-2024'!C$3:$C$64,'02-2024'!$B$3:$B$64=$A10), _xlfn._xlws.FILTER('03-2024'!C$3:$C$64,'03-2024'!$B$3:$B$64=$A10))} -> 275701.25 | C10: {=SUM(_xlfn._xlws.FILTER('01-2024'!D$3:$D$64,'01-2024'!$B$3:$B$64=$A10), _xlfn._xlws.FILTER('02-2024'!D$3:$D$64,'02-2024'!$B$3:$B$64=$A10), _xlfn._xlws.FILTER('03-2024'!D$3:$D$64,'03-2024'!$B$3:$B$64=$A10))} -> 318383.4 | D10: =B10-C10 -> -42682.15 | E10: =IFERROR(D10/C10, "-") -> -0.13405897 | G10: =B10 -> 275701.25 | H10: {=SUM(_xlfn._xlws.FILTER('01-2024'!$I$3:$I$64,'01-2024'!$B$3:$B$64=$A10), _xlfn._xlws.FILTER('02-2024'!$I$3:$I$64,'02-2024'!$B$3:$B$64=$A10), _xlfn._xlws.FILTER('03-2024'!I$3:$I$64,'03-2024'!$B$3:$B$64=$A10))} -> 427842.06 | I10: =G10-H10 -> -152140.81 | J10: =IFERROR(I10/H10, "-") -> -0.3556004
A11: Total | B11: =SUM(B3:B10) -> 434877.89 | C11: =SUM(C3:C10) -> 405850.93 | D11: =B11-C11 -> 29026.959 | E11: =IFERROR(D11/C11, "-") -> 0.071521233 | G11: =SUM(G3:G10) -> 434877.89 | H11: =SUM(H3:H10) -> 698800.05 | I11: =G11-H11 -> -263922.16 | J11: =IFERROR(I11/H11, "-") -> -0.37767909

Sheet 2nd Quarter 2024
A1: WELLS FARGO | B1: 2nd Quarter 2024 Actual v. Expected | G1: 2nd Quarter 2024 Actual v. Forecasted
A2: State | B2: Actual | C2: Expected | D2: Delta | E2: % | G2: Actual | H2: Forecasted | I2: Delta | J2: %
A3: {=_xlfn.UNIQUE(Sites[State])} -> CA | B3: {=SUM(_xlfn._xlws.FILTER('04-2024'!$C$3:$C$64,'04-2024'!$B$3:$B$64=$A3), _xlfn._xlws.FILTER('05-2024'!$C$3:$C$64,'05-2024'!$B$3:$B$64=$A3), _xlfn._xlws.FILTER('06-2024'!$C$3:$C$64,'06-2024'!$B$3:$B$64=$A3))} -> 0 | C3: {=SUM(_xlfn._xlws.FILTER('04-2024'!$D$3:$D$64,'04-2024'!$B$3:$B$64=$A3), _xlfn._xlws.FILTER('05-2024'!$D$3:$D$64,'05-2024'!$B$3:$B$64=$A3), _xlfn._xlws.FILTER('06-2024'!$D$3:$D$64,'06-2024'!$B$3:$B$64=$A3))} -> 0 | D3: =B3-C3 -> 0 | E3: =IFERROR(D3/C3, "-") -> - | G3: =B3 -> 0 | H3: {=SUM(_xlfn._xlws.FILTER('04-2024'!$I$3:$I$64,'04-2024'!$B$3:$B$64=$A3), _xlfn._xlws.FILTER('05-2024'!I$3:$I$64,'05-2024'!$B$3:$B$64=$A3), _xlfn._xlws.FILTER('06-2024'!$I$3:$I$64,'06-2024'!$B$3:$B$64=$A3))} -> 0 | I3: =G3-H3 -> 0 | J3: =IFERROR(I3/H3, "-") -> - | L3: Gold highlighted cells for Actual Production vs Expected and Forecasted values varying positive 10% or more.
A4: CO | B4: {=SUM(_xlfn._xlws.FILTER('04-2024'!$C$3:$C$64,'04-2024'!$B$3:$B$64=$A4), _xlfn._xlws.FILTER('05-2024'!$C$3:$C$64,'05-2024'!$B$3:$B$64=$A4), _xlfn._xlws.FILTER('06-2024'!$C$3:$C$64,'06-2024'!$B$3:$B$64=$A4))} -> 0 | C4: {=SUM(_xlfn._xlws.FILTER('04-2024'!$D$3:$D$64,'04-2024'!$B$3:$B$64=$A4), _xlfn._xlws.FILTER('05-2024'!$D$3:$D$64,'05-2024'!$B$3:$B$64=$A4), _xlfn._xlws.FILTER('06-2024'!$D$3:$D$64,'06-2024'!$B$3:$B$64=$A4))} -> 0 | D4: =B4-C4 -> 0 | E4: =IFERROR(D4/C4, "-") -> - | G4: =B4 -> 0 | H4: {=SUM(_xlfn._xlws.FILTER('04-2024'!$I$3:$I$64,'04-2024'!$B$3:$B$64=$A4), _xlfn._xlws.FILTER('05-2024'!I$3:$I$64,'05-2024'!$B$3:$B$64=$A4), _xlfn._xlws.FILTER('06-2024'!$I$3:$I$64,'06-2024'!$B$3:$B$64=$A4))} -> 0 | I4: =G4-H4 -> 0 | J4: =IFERROR(I4/H4, "-") -> - | L4: Red highlighted cells for Actual Production vs Expected and Forecasted values varying negative 10% or more.
A5: CT | B5: {=SUM(_xlfn._xlws.FILTER('04-2024'!$C$3:$C$64,'04-2024'!$B$3:$B$64=$A5), _xlfn._xlws.FILTER('05-2024'!$C$3:$C$64,'05-2024'!$B$3:$B$64=$A5), _xlfn._xlws.FILTER('06-2024'!$C$3:$C$64,'06-2024'!$B$3:$B$64=$A5))} -> 0 | C5: {=SUM(_xlfn._xlws.FILTER('04-2024'!$D$3:$D$64,'04-2024'!$B$3:$B$64=$A5), _xlfn._xlws.FILTER('05-2024'!$D$3:$D$64,'05-2024'!$B$3:$B$64=$A5), _xlfn._xlws.FILTER('06-2024'!$D$3:$D$64,'06-2024'!$B$3:$B$64=$A5))} -> 0 | D5: =B5-C5 -> 0 | E5: =IFERROR(D5/C5, "-") -> - | G5: =B5 -> 0 | H5: {=SUM(_xlfn._xlws.FILTER('04-2024'!$I$3:$I$64,'04-2024'!$B$3:$B$64=$A5), _xlfn._xlws.FILTER('05-2024'!I$3:$I$64,'05-2024'!$B$3:$B$64=$A5), _xlfn._xlws.FILTER('06-2024'!$I$3:$I$64,'06-2024'!$B$3:$B$64=$A5))} -> 0 | I5: =G5-H5 -> 0 | J5: =IFERROR(I5/H5, "-") -> -
A6: FL | B6: {=SUM(_xlfn._xlws.FILTER('04-2024'!$C$3:$C$64,'04-2024'!$B$3:$B$64=$A6), _xlfn._xlws.FILTER('05-2024'!$C$3:$C$64,'05-2024'!$B$3:$B$64=$A6), _xlfn._xlws.FILTER('06-2024'!$C$3:$C$64,'06-2024'!$B$3:$B$64=$A6))} -> 0 | C6: {=SUM(_xlfn._xlws.FILTER('04-2024'!$D$3:$D$64,'04-2024'!$B$3:$B$64=$A6), _xlfn._xlws.FILTER('05-2024'!$D$3:$D$64,'05-2024'!$B$3:$B$64=$A6), _xlfn._xlws.FILTER('06-2024'!$D$3:$D$64,'06-2024'!$B$3:$B$64=$A6))} -> 0 | D6: =B6-C6 -> 0 | E6: =IFERROR(D6/C6, "-") -> - | G6: =B6 -> 0 | H6: {=SUM(_xlfn._xlws.FILTER('04-2024'!$I$3:$I$64,'04-2024'!$B$3:$B$64=$A6), _xlfn._xlws.FILTER('05-2024'!I$3:$I$64,'05-2024'!$B$3:$B$64=$A6), _xlfn._xlws.FILTER('06-2024'!$I$3:$I$64,'06-2024'!$B$3:$B$64=$A6))} -> 0 | I6: =G6-H6 -> 0 | J6: =IFERROR(I6/H6, "-") -> -
A7: IA | B7: {=SUM(_xlfn._xlws.FILTER('04-2024'!$C$3:$C$64,'04-2024'!$B$3:$B$64=$A7), _xlfn._xlws.FILTER('05-2024'!$C$3:$C$64,'05-2024'!$B$3:$B$64=$A7), _xlfn._xlws.FILTER('06-2024'!$C$3:$C$64,'06-2024'!$B$3:$B$64=$A7))} -> 0 | C7: {=SUM(_xlfn._xlws.FILTER('04-2024'!$D$3:$D$64,'04-2024'!$B$3:$B$64=$A7), _xlfn._xlws.FILTER('05-2024'!$D$3:$D$64,'05-2024'!$B$3:$B$64=$A7), _xlfn._xlws.FILTER('06-2024'!$D$3:$D$64,'06-2024'!$B$3:$B$64=$A7))} -> 0 | D7: =B7-C7 -> 0 | E7: =IFERROR(D7/C7, "-") -> - | G7: =B7 -> 0 | H7: {=SUM(_xlfn._xlws.FILTER('04-2024'!$I$3:$I$64,'04-2024'!$B$3:$B$64=$A7), _xlfn._xlws.FILTER('05-2024'!I$3:$I$64,'05-2024'!$B$3:$B$64=$A7), _xlfn._xlws.FILTER('06-2024'!$I$3:$I$64,'06-2024'!$B$3:$B$64=$A7))} -> 0 | I7: =G7-H7 -> 0 | J7: =IFERROR(I7/H7, "-") -> -
A8: NC | B8: {=SUM(_xlfn._xlws.FILTER('04-2024'!$C$3:$C$64,'04-2024'!$B$3:$B$64=$A8), _xlfn._xlws.FILTER('05-2024'!$C$3:$C$64,'05-2024'!$B$3:$B$64=$A8), _xlfn._xlws.FILTER('06-2024'!$C$3:$C$64,'06-2024'!$B$3:$B$64=$A8))} -> 0 | C8: {=SUM(_xlfn._xlws.FILTER('04-2024'!$D$3:$D$64,'04-2024'!$B$3:$B$64=$A8), _xlfn._xlws.FILTER('05-2024'!$D$3:$D$64,'05-2024'!$B$3:$B$64=$A8), _xlfn._xlws.FILTER('06-2024'!$D$3:$D$64,'06-2024'!$B$3:$B$64=$A8))} -> 0 | D8: =B8-C8 -> 0 | E8: =IFERROR(D8/C8, "-") -> - | G8: =B8 -> 0 | H8: {=SUM(_xlfn._xlws.FILTER('04-2024'!$I$3:$I$64,'04-2024'!$B$3:$B$64=$A8), _xlfn._xlws.FILTER('05-2024'!I$3:$I$64,'05-2024'!$B$3:$B$64=$A8), _xlfn._xlws.FILTER('06-2024'!$I$3:$I$64,'06-2024'!$B$3:$B$64=$A8))} -> 0 | I8: =G8-H8 -> 0 | J8: =IFERROR(I8/H8, "-") -> -
A9: NJ | B9: {=SUM(_xlfn._xlws.FILTER('04-2024'!$C$3:$C$64,'04-2024'!$B$3:$B$64=$A9), _xlfn._xlws.FILTER('05-2024'!$C$3:$C$64,'05-2024'!$B$3:$B$64=$A9), _xlfn._xlws.FILTER('06-2024'!$C$3:$C$64,'06-2024'!$B$3:$B$64=$A9))} -> 0 | C9: {=SUM(_xlfn._xlws.FILTER('04-2024'!$D$3:$D$64,'04-2024'!$B$3:$B$64=$A9), _xlfn._xlws.FILTER('05-2024'!$D$3:$D$64,'05-2024'!$B$3:$B$64=$A9), _xlfn._xlws.FILTER('06-2024'!$D$3:$D$64,'06-2024'!$B$3:$B$64=$A9))} -> 0 | D9: =B9-C9 -> 0 | E9: =IFERROR(D9/C9, "-") -> - | G9: =B9 -> 0 | H9: {=SUM(_xlfn._xlws.FILTER('04-2024'!$I$3:$I$64,'04-2024'!$B$3:$B$64=$A9), _xlfn._xlws.FILTER('05-2024'!I$3:$I$64,'05-2024'!$B$3:$B$64=$A9), _xlfn._xlws.FILTER('06-2024'!$I$3:$I$64,'06-2024'!$B$3:$B$64=$A9))} -> 0 | I9: =G9-H9 -> 0 | J9: =IFERROR(I9/H9, "-") -> -
A10: TX | B10: {=SUM(_xlfn._xlws.FILTER('04-2024'!$C$3:$C$64,'04-2024'!$B$3:$B$64=$A10), _xlfn._xlws.FILTER('05-2024'!$C$3:$C$64,'05-2024'!$B$3:$B$64=$A10), _xlfn._xlws.FILTER('06-2024'!$C$3:$C$64,'06-2024'!$B$3:$B$64=$A10))} -> 0 | C10: {=SUM(_xlfn._xlws.FILTER('04-2024'!$D$3:$D$64,'04-2024'!$B$3:$B$64=$A10), _xlfn._xlws.FILTER('05-2024'!$D$3:$D$64,'05-2024'!$B$3:$B$64=$A10), _xlfn._xlws.FILTER('06-2024'!$D$3:$D$64,'06-2024'!$B$3:$B$64=$A10))} -> 0 | D10: =B10-C10 -> 0 | E10: =IFERROR(D10/C10, "-") -> - | G10: =B10 -> 0 | H10: {=SUM(_xlfn._xlws.FILTER('04-2024'!$I$3:$I$64,'04-2024'!$B$3:$B$64=$A10), _xlfn._xlws.FILTER('05-2024'!I$3:$I$64,'05-2024'!$B$3:$B$64=$A10), _xlfn._xlws.FILTER('06-2024'!$I$3:$I$64,'06-2024'!$B$3:$B$64=$A10))} -> 0 | I10: =G10-H10 -> 0 | J10: =IFERROR(I10/H10, "-") -> -
A11: Total | B11: =SUM(B3:B10) -> 0 | C11: =SUM(C3:C10) -> 0 | D11: =B11-C11 -> 0 | E11: =IFERROR(D11/C11, "-") -> - | G11: =B11 -> 0 | H11: =SUM(H3:H10) -> 0 | I11: =G11-H11 -> 0 | J11: =IFERROR(I11/H11, "-") -> -

Sheet 3rd Quarter 2024
A1: WELLS FARGO | B1: 3rd Quarter 2024 Actual v. Expected | G1: 3rd Quarter 2024 Actual v. Forecasted
A2: State | B2: Actual | C2: Expected | D2: Delta | E2: % | G2: Actual | H2: Forecasted | I2: Delta | J2: %
A3: {=_xlfn.UNIQUE(Sites[State])} -> CA | B3: {=SUM(_xlfn._xlws.FILTER('07-2024'!$C$3:$C$64,'07-2024'!$B$3:$B$64=$A3), _xlfn._xlws.FILTER('08-2024'!$C$3:$C$64,'08-2024'!$B$3:$B$64=$A3), _xlfn._xlws.FILTER('09-2024'!$C$3:$C$64,'09-2024'!$B$3:$B$64=$A3))} -> 0 | C3: {=SUM(_xlfn._xlws.FILTER('07-2024'!$D$3:$D$64,'07-2024'!$B$3:$B$64=$A3), _xlfn._xlws.FILTER('08-2024'!$D$3:$D$64,'08-2024'!$B$3:$B$64=$A3), _xlfn._xlws.FILTER('09-2024'!$D$3:$D$64,'09-2024'!$B$3:$B$64=$A3))} -> 0 | D3: =B3-C3 -> 0 | E3: =IFERROR(D3/C3, "-") -> - | G3: =B3 -> 0 | H3: {=SUM(_xlfn._xlws.FILTER('07-2024'!$I$3:$I$64,'07-2024'!$B$3:$B$64=$A3), _xlfn._xlws.FILTER('08-2024'!I$3:$I$64,'08-2024'!$B$3:$B$64=$A3), _xlfn._xlws.FILTER('09-2024'!$I$3:$I$64,'09-2024'!$B$3:$B$64=$A3))} -> 0 | I3: =G3-H3 -> 0 | J3: =IFERROR(I3/H3, "-") -> - | L3: Gold highlighted cells for Actual Production vs Expected and Forecasted values varying positive 10% or more.
A4: CO | B4: {=SUM(_xlfn._xlws.FILTER('07-2024'!$C$3:$C$64,'07-2024'!$B$3:$B$64=$A4), _xlfn._xlws.FILTER('08-2024'!$C$3:$C$64,'08-2024'!$B$3:$B$64=$A4), _xlfn._xlws.FILTER('09-2024'!$C$3:$C$64,'09-2024'!$B$3:$B$64=$A4))} -> 0 | C4: {=SUM(_xlfn._xlws.FILTER('07-2024'!$D$3:$D$64,'07-2024'!$B$3:$B$64=$A4), _xlfn._xlws.FILTER('08-2024'!$D$3:$D$64,'08-2024'!$B$3:$B$64=$A4), _xlfn._xlws.FILTER('09-2024'!$D$3:$D$64,'09-2024'!$B$3:$B$64=$A4))} -> 0 | D4: =B4-C4 -> 0 | E4: =IFERROR(D4/C4, "-") -> - | G4: =B4 -> 0 | H4: {=SUM(_xlfn._xlws.FILTER('07-2024'!$I$3:$I$64,'07-2024'!$B$3:$B$64=$A4), _xlfn._xlws.FILTER('08-2024'!I$3:$I$64,'08-2024'!$B$3:$B$64=$A4), _xlfn._xlws.FILTER('09-2024'!$I$3:$I$64,'09-2024'!$B$3:$B$64=$A4))} -> 0 | I4: =G4-H4 -> 0 | J4: =IFERROR(I4/H4, "-") -> - | L4: Red highlighted cells for Actual Production vs Expected and Forecasted values varying negative 10% or more.
A5: CT | B5: {=SUM(_xlfn._xlws.FILTER('07-2024'!$C$3:$C$64,'07-2024'!$B$3:$B$64=$A5), _xlfn._xlws.FILTER('08-2024'!$C$3:$C$64,'08-2024'!$B$3:$B$64=$A5), _xlfn._xlws.FILTER('09-2024'!$C$3:$C$64,'09-2024'!$B$3:$B$64=$A5))} -> 0 | C5: {=SUM(_xlfn._xlws.FILTER('07-2024'!$D$3:$D$64,'07-2024'!$B$3:$B$64=$A5), _xlfn._xlws.FILTER('08-2024'!$D$3:$D$64,'08-2024'!$B$3:$B$64=$A5), _xlfn._xlws.FILTER('09-2024'!$D$3:$D$64,'09-2024'!$B$3:$B$64=$A5))} -> 0 | D5: =B5-C5 -> 0 | E5: =IFERROR(D5/C5, "-") -> - | G5: =B5 -> 0 | H5: {=SUM(_xlfn._xlws.FILTER('07-2024'!$I$3:$I$64,'07-2024'!$B$3:$B$64=$A5), _xlfn._xlws.FILTER('08-2024'!I$3:$I$64,'08-2024'!$B$3:$B$64=$A5), _xlfn._xlws.FILTER('09-2024'!$I$3:$I$64,'09-2024'!$B$3:$B$64=$A5))} -> 0 | I5: =G5-H5 -> 0 | J5: =IFERROR(I5/H5, "-") -> -
A6: FL | B6: {=SUM(_xlfn._xlws.FILTER('07-2024'!$C$3:$C$64,'07-2024'!$B$3:$B$64=$A6), _xlfn._xlws.FILTER('08-2024'!$C$3:$C$64,'08-2024'!$B$3:$B$64=$A6), _xlfn._xlws.FILTER('09-2024'!$C$3:$C$64,'09-2024'!$B$3:$B$64=$A6))} -> 0 | C6: {=SUM(_xlfn._xlws.FILTER('07-2024'!$D$3:$D$64,'07-2024'!$B$3:$B$64=$A6), _xlfn._xlws.FILTER('08-2024'!$D$3:$D$64,'08-2024'!$B$3:$B$64=$A6), _xlfn._xlws.FILTER('09-2024'!$D$3:$D$64,'09-2024'!$B$3:$B$64=$A6))} -> 0 | D6: =B6-C6 -> 0 | E6: =IFERROR(D6/C6, "-") -> - | G6: =B6 -> 0 | H6: {=SUM(_xlfn._xlws.FILTER('07-2024'!$I$3:$I$64,'07-2024'!$B$3:$B$64=$A6), _xlfn._xlws.FILTER('08-2024'!I$3:$I$64,'08-2024'!$B$3:$B$64=$A6), _xlfn._xlws.FILTER('09-2024'!$I$3:$I$64,'09-2024'!$B$3:$B$64=$A6))} -> 0 | I6: =G6-H6 -> 0 | J6: =IFERROR(I6/H6, "-") -> -
A7: IA | B7: {=SUM(_xlfn._xlws.FILTER('07-2024'!$C$3:$C$64,'07-2024'!$B$3:$B$64=$A7), _xlfn._xlws.FILTER('08-2024'!$C$3:$C$64,'08-2024'!$B$3:$B$64=$A7), _xlfn._xlws.FILTER('09-2024'!$C$3:$C$64,'09-2024'!$B$3:$B$64=$A7))} -> 0 | C7: {=SUM(_xlfn._xlws.FILTER('07-2024'!$D$3:$D$64,'07-2024'!$B$3:$B$64=$A7), _xlfn._xlws.FILTER('08-2024'!$D$3:$D$64,'08-2024'!$B$3:$B$64=$A7), _xlfn._xlws.FILTER('09-2024'!$D$3:$D$64,'09-2024'!$B$3:$B$64=$A7))} -> 0 | D7: =B7-C7 -> 0 | E7: =IFERROR(D7/C7, "-") -> - | G7: =B7 -> 0 | H7: {=SUM(_xlfn._xlws.FILTER('07-2024'!$I$3:$I$64,'07-2024'!$B$3:$B$64=$A7), _xlfn._xlws.FILTER('08-2024'!I$3:$I$64,'08-2024'!$B$3:$B$64=$A7), _xlfn._xlws.FILTER('09-2024'!$I$3:$I$64,'09-2024'!$B$3:$B$64=$A7))} -> 0 | I7: =G7-H7 -> 0 | J7: =IFERROR(I7/H7, "-") -> -
A8: NC | B8: {=SUM(_xlfn._xlws.FILTER('07-2024'!$C$3:$C$64,'07-2024'!$B$3:$B$64=$A8), _xlfn._xlws.FILTER('08-2024'!$C$3:$C$64,'08-2024'!$B$3:$B$64=$A8), _xlfn._xlws.FILTER('09-2024'!$C$3:$C$64,'09-2024'!$B$3:$B$64=$A8))} -> 0 | C8: {=SUM(_xlfn._xlws.FILTER('07-2024'!$D$3:$D$64,'07-2024'!$B$3:$B$64=$A8), _xlfn._xlws.FILTER('08-2024'!$D$3:$D$64,'08-2024'!$B$3:$B$64=$A8), _xlfn._xlws.FILTER('09-2024'!$D$3:$D$64,'09-2024'!$B$3:$B$64=$A8))} -> 0 | D8: =B8-C8 -> 0 | E8: =IFERROR(D8/C8, "-") -> - | G8: =B8 -> 0 | H8: {=SUM(_xlfn._xlws.FILTER('07-2024'!$I$3:$I$64,'07-2024'!$B$3:$B$64=$A8), _xlfn._xlws.FILTER('08-2024'!I$3:$I$64,'08-2024'!$B$3:$B$64=$A8), _xlfn._xlws.FILTER('09-2024'!$I$3:$I$64,'09-2024'!$B$3:$B$64=$A8))} -> 0 | I8: =G8-H8 -> 0 | J8: =IFERROR(I8/H8, "-") -> -
A9: NJ | B9: {=SUM(_xlfn._xlws.FILTER('07-2024'!$C$3:$C$64,'07-2024'!$B$3:$B$64=$A9), _xlfn._xlws.FILTER('08-2024'!$C$3:$C$64,'08-2024'!$B$3:$B$64=$A9), _xlfn._xlws.FILTER('09-2024'!$C$3:$C$64,'09-2024'!$B$3:$B$64=$A9))} -> 0 | C9: {=SUM(_xlfn._xlws.FILTER('07-2024'!$D$3:$D$64,'07-2024'!$B$3:$B$64=$A9), _xlfn._xlws.FILTER('08-2024'!$D$3:$D$64,'08-2024'!$B$3:$B$64=$A9), _xlfn._xlws.FILTER('09-2024'!$D$3:$D$64,'09-2024'!$B$3:$B$64=$A9))} -> 0 | D9: =B9-C9 -> 0 | E9: =IFERROR(D9/C9, "-") -> - | G9: =B9 -> 0 | H9: {=SUM(_xlfn._xlws.FILTER('07-2024'!$I$3:$I$64,'07-2024'!$B$3:$B$64=$A9), _xlfn._xlws.FILTER('08-2024'!I$3:$I$64,'08-2024'!$B$3:$B$64=$A9), _xlfn._xlws.FILTER('09-2024'!$I$3:$I$64,'09-2024'!$B$3:$B$64=$A9))} -> 0 | I9: =G9-H9 -> 0 | J9: =IFERROR(I9/H9, "-") -> -
A10: TX | B10: {=SUM(_xlfn._xlws.FILTER('07-2024'!$C$3:$C$64,'07-2024'!$B$3:$B$64=$A10), _xlfn._xlws.FILTER('08-2024'!$C$3:$C$64,'08-2024'!$B$3:$B$64=$A10), _xlfn._xlws.FILTER('09-2024'!$C$3:$C$64,'09-2024'!$B$3:$B$64=$A10))} -> 0 | C10: {=SUM(_xlfn._xlws.FILTER('07-2024'!$D$3:$D$64,'07-2024'!$B$3:$B$64=$A10), _xlfn._xlws.FILTER('08-2024'!$D$3:$D$64,'08-2024'!$B$3:$B$64=$A10), _xlfn._xlws.FILTER('09-2024'!$D$3:$D$64,'09-2024'!$B$3:$B$64=$A10))} -> 0 | D10: =B10-C10 -> 0 | E10: =IFERROR(D10/C10, "-") -> - | G10: =B10 -> 0 | H10: {=SUM(_xlfn._xlws.FILTER('07-2024'!$I$3:$I$64,'07-2024'!$B$3:$B$64=$A10), _xlfn._xlws.FILTER('08-2024'!I$3:$I$64,'08-2024'!$B$3:$B$64=$A10), _xlfn._xlws.FILTER('09-2024'!$I$3:$I$64,'09-2024'!$B$3:$B$64=$A10))} -> 0 | I10: =G10-H10 -> 0 | J10: =IFERROR(I10/H10, "-") -> -
A11: Total | B11: =SUM(B3:B10) -> 0 | C11: =SUM(C3:C10) -> 0 | D11: =B11-C11 -> 0 | E11: =IFERROR(D11/C11, "-") -> - | G11: =B11 -> 0 | H11: =SUM(H3:H10) -> 0 | I11: =G11-H11 -> 0 | J11: =IFERROR(I11/H11, "-") -> -

Sheet 4th Quarter 2024
A1: WELLS FARGO | B1: 4th Quarter 2024 Actual v. Expected | G1: 4th Quarter 2024 Actual v. Forecasted
A2: State | B2: Actual | C2: Expected | D2: Delta | E2: % | G2: Actual | H2: Forecasted | I2: Delta | J2: %
A3: {=_xlfn.UNIQUE(Sites[State])} -> CA | B3: {=SUM(_xlfn._xlws.FILTER('10-2024'!$C$3:$C$64,'10-2024'!$B$3:$B$64=$A3), _xlfn._xlws.FILTER('11-2024'!$C$3:$C$64,'11-2024'!$B$3:$B$64=$A3), _xlfn._xlws.FILTER('12-2024'!$C$3:$C$64,'12-2024'!$B$3:$B$64=$A3))} -> 0 | C3: {=SUM(_xlfn._xlws.FILTER('10-2024'!$D$3:$D$64,'10-2024'!$B$3:$B$64=$A3), _xlfn._xlws.FILTER('11-2024'!$D$3:$D$64,'11-2024'!$B$3:$B$64=$A3), _xlfn._xlws.FILTER('12-2024'!$D$3:$D$64,'12-2024'!$B$3:$B$64=$A3))} -> 0 | D3: =B3-C3 -> 0 | E3: =IFERROR(D3/C3, "-") -> - | G3: =B3 -> 0 | H3: {=SUM(_xlfn._xlws.FILTER('10-2024'!$I$3:$I$64,'10-2024'!$B$3:$B$64=$A3), _xlfn._xlws.FILTER('11-2024'!I$3:$I$64,'11-2024'!$B$3:$B$64=$A3), _xlfn._xlws.FILTER('12-2024'!$I$3:$I$64,'12-2024'!$B$3:$B$64=$A3))} -> 0 | I3: =G3-H3 -> 0 | J3: =IFERROR(I3/H3, "-") -> - | L3: Gold highlighted cells for Actual Production vs Expected and Forecasted values varying positive 10% or more.
A4: CO | B4: {=SUM(_xlfn._xlws.FILTER('10-2024'!$C$3:$C$64,'10-2024'!$B$3:$B$64=$A4), _xlfn._xlws.FILTER('11-2024'!$C$3:$C$64,'11-2024'!$B$3:$B$64=$A4), _xlfn._xlws.FILTER('12-2024'!$C$3:$C$64,'12-2024'!$B$3:$B$64=$A4))} -> 0 | C4: {=SUM(_xlfn._xlws.FILTER('10-2024'!$D$3:$D$64,'10-2024'!$B$3:$B$64=$A4), _xlfn._xlws.FILTER('11-2024'!$D$3:$D$64,'11-2024'!$B$3:$B$64=$A4), _xlfn._xlws.FILTER('12-2024'!$D$3:$D$64,'12-2024'!$B$3:$B$64=$A4))} -> 0 | D4: =B4-C4 -> 0 | E4: =IFERROR(D4/C4, "-") -> - | G4: =B4 -> 0 | H4: {=SUM(_xlfn._xlws.FILTER('10-2024'!$I$3:$I$64,'10-2024'!$B$3:$B$64=$A4), _xlfn._xlws.FILTER('11-2024'!I$3:$I$64,'11-2024'!$B$3:$B$64=$A4), _xlfn._xlws.FILTER('12-2024'!$I$3:$I$64,'12-2024'!$B$3:$B$64=$A4))} -> 0 | I4: =G4-H4 -> 0 | J4: =IFERROR(I4/H4, "-") -> - | L4: Red highlighted cells for Actual Production vs Expected and Forecasted values varying negative 10% or more.
A5: CT | B5: {=SUM(_xlfn._xlws.FILTER('10-2024'!$C$3:$C$64,'10-2024'!$B$3:$B$64=$A5), _xlfn._xlws.FILTER('11-2024'!$C$3:$C$64,'11-2024'!$B$3:$B$64=$A5), _xlfn._xlws.FILTER('12-2024'!$C$3:$C$64,'12-2024'!$B$3:$B$64=$A5))} -> 0 | C5: {=SUM(_xlfn._xlws.FILTER('10-2024'!$D$3:$D$64,'10-2024'!$B$3:$B$64=$A5), _xlfn._xlws.FILTER('11-2024'!$D$3:$D$64,'11-2024'!$B$3:$B$64=$A5), _xlfn._xlws.FILTER('12-2024'!$D$3:$D$64,'12-2024'!$B$3:$B$64=$A5))} -> 0 | D5: =B5-C5 -> 0 | E5: =IFERROR(D5/C5, "-") -> - | G5: =B5 -> 0 | H5: {=SUM(_xlfn._xlws.FILTER('10-2024'!$I$3:$I$64,'10-2024'!$B$3:$B$64=$A5), _xlfn._xlws.FILTER('11-2024'!I$3:$I$64,'11-2024'!$B$3:$B$64=$A5), _xlfn._xlws.FILTER('12-2024'!$I$3:$I$64,'12-2024'!$B$3:$B$64=$A5))} -> 0 | I5: =G5-H5 -> 0 | J5: =IFERROR(I5/H5, "-") -> -
A6: FL | B6: {=SUM(_xlfn._xlws.FILTER('10-2024'!$C$3:$C$64,'10-2024'!$B$3:$B$64=$A6), _xlfn._xlws.FILTER('11-2024'!$C$3:$C$64,'11-2024'!$B$3:$B$64=$A6), _xlfn._xlws.FILTER('12-2024'!$C$3:$C$64,'12-2024'!$B$3:$B$64=$A6))} -> 0 | C6: {=SUM(_xlfn._xlws.FILTER('10-2024'!$D$3:$D$64,'10-2024'!$B$3:$B$64=$A6), _xlfn._xlws.FILTER('11-2024'!$D$3:$D$64,'11-2024'!$B$3:$B$64=$A6), _xlfn._xlws.FILTER('12-2024'!$D$3:$D$64,'12-2024'!$B$3:$B$64=$A6))} -> 0 | D6: =B6-C6 -> 0 | E6: =IFERROR(D6/C6, "-") -> - | G6: =B6 -> 0 | H6: {=SUM(_xlfn._xlws.FILTER('10-2024'!$I$3:$I$64,'10-2024'!$B$3:$B$64=$A6), _xlfn._xlws.FILTER('11-2024'!I$3:$I$64,'11-2024'!$B$3:$B$64=$A6), _xlfn._xlws.FILTER('12-2024'!$I$3:$I$64,'12-2024'!$B$3:$B$64=$A6))} -> 0 | I6: =G6-H6 -> 0 | J6: =IFERROR(I6/H6, "-") -> -
A7: IA | B7: {=SUM(_xlfn._xlws.FILTER('10-2024'!$C$3:$C$64,'10-2024'!$B$3:$B$64=$A7), _xlfn._xlws.FILTER('11-2024'!$C$3:$C$64,'11-2024'!$B$3:$B$64=$A7), _xlfn._xlws.FILTER('12-2024'!$C$3:$C$64,'12-2024'!$B$3:$B$64=$A7))} -> 0 | C7: {=SUM(_xlfn._xlws.FILTER('10-2024'!$D$3:$D$64,'10-2024'!$B$3:$B$64=$A7), _xlfn._xlws.FILTER('11-2024'!$D$3:$D$64,'11-2024'!$B$3:$B$64=$A7), _xlfn._xlws.FILTER('12-2024'!$D$3:$D$64,'12-2024'!$B$3:$B$64=$A7))} -> 0 | D7: =B7-C7 -> 0 | E7: =IFERROR(D7/C7, "-") -> - | G7: =B7 -> 0 | H7: {=SUM(_xlfn._xlws.FILTER('10-2024'!$I$3:$I$64,'10-2024'!$B$3:$B$64=$A7), _xlfn._xlws.FILTER('11-2024'!I$3:$I$64,'11-2024'!$B$3:$B$64=$A7), _xlfn._xlws.FILTER('12-2024'!$I$3:$I$64,'12-2024'!$B$3:$B$64=$A7))} -> 0 | I7: =G7-H7 -> 0 | J7: =IFERROR(I7/H7, "-") -> -
A8: NC | B8: {=SUM(_xlfn._xlws.FILTER('10-2024'!$C$3:$C$64,'10-2024'!$B$3:$B$64=$A8), _xlfn._xlws.FILTER('11-2024'!$C$3:$C$64,'11-2024'!$B$3:$B$64=$A8), _xlfn._xlws.FILTER('12-2024'!$C$3:$C$64,'12-2024'!$B$3:$B$64=$A8))} -> 0 | C8: {=SUM(_xlfn._xlws.FILTER('10-2024'!$D$3:$D$64,'10-2024'!$B$3:$B$64=$A8), _xlfn._xlws.FILTER('11-2024'!$D$3:$D$64,'11-2024'!$B$3:$B$64=$A8), _xlfn._xlws.FILTER('12-2024'!$D$3:$D$64,'12-2024'!$B$3:$B$64=$A8))} -> 0 | D8: =B8-C8 -> 0 | E8: =IFERROR(D8/C8, "-") -> - | G8: =B8 -> 0 | H8: {=SUM(_xlfn._xlws.FILTER('10-2024'!$I$3:$I$64,'10-2024'!$B$3:$B$64=$A8), _xlfn._xlws.FILTER('11-2024'!I$3:$I$64,'11-2024'!$B$3:$B$64=$A8), _xlfn._xlws.FILTER('12-2024'!$I$3:$I$64,'12-2024'!$B$3:$B$64=$A8))} -> 0 | I8: =G8-H8 -> 0 | J8: =IFERROR(I8/H8, "-") -> -
A9: NJ | B9: {=SUM(_xlfn._xlws.FILTER('10-2024'!$C$3:$C$64,'10-2024'!$B$3:$B$64=$A9), _xlfn._xlws.FILTER('11-2024'!$C$3:$C$64,'11-2024'!$B$3:$B$64=$A9), _xlfn._xlws.FILTER('12-2024'!$C$3:$C$64,'12-2024'!$B$3:$B$64=$A9))} -> 0 | C9: {=SUM(_xlfn._xlws.FILTER('10-2024'!$D$3:$D$64,'10-2024'!$B$3:$B$64=$A9), _xlfn._xlws.FILTER('11-2024'!$D$3:$D$64,'11-2024'!$B$3:$B$64=$A9), _xlfn._xlws.FILTER('12-2024'!$D$3:$D$64,'12-2024'!$B$3:$B$64=$A9))} -> 0 | D9: =B9-C9 -> 0 | E9: =IFERROR(D9/C9, "-") -> - | G9: =B9 -> 0 | H9: {=SUM(_xlfn._xlws.FILTER('10-2024'!$I$3:$I$64,'10-2024'!$B$3:$B$64=$A9), _xlfn._xlws.FILTER('11-2024'!I$3:$I$64,'11-2024'!$B$3:$B$64=$A9), _xlfn._xlws.FILTER('12-2024'!$I$3:$I$64,'12-2024'!$B$3:$B$64=$A9))} -> 0 | I9: =G9-H9 -> 0 | J9: =IFERROR(I9/H9, "-") -> -
A10: TX | B10: {=SUM(_xlfn._xlws.FILTER('10-2024'!$C$3:$C$64,'10-2024'!$B$3:$B$64=$A10), _xlfn._xlws.FILTER('11-2024'!$C$3:$C$64,'11-2024'!$B$3:$B$64=$A10), _xlfn._xlws.FILTER('12-2024'!$C$3:$C$64,'12-2024'!$B$3:$B$64=$A10))} -> 0 | C10: {=SUM(_xlfn._xlws.FILTER('10-2024'!$D$3:$D$64,'10-2024'!$B$3:$B$64=$A10), _xlfn._xlws.FILTER('11-2024'!$D$3:$D$64,'11-2024'!$B$3:$B$64=$A10), _xlfn._xlws.FILTER('12-2024'!$D$3:$D$64,'12-2024'!$B$3:$B$64=$A10))} -> 0 | D10: =B10-C10 -> 0 | E10: =IFERROR(D10/C10, "-") -> - | G10: =B10 -> 0 | H10: {=SUM(_xlfn._xlws.FILTER('10-2024'!$I$3:$I$64,'10-2024'!$B$3:$B$64=$A10), _xlfn._xlws.FILTER('11-2024'!I$3:$I$64,'11-2024'!$B$3:$B$64=$A10), _xlfn._xlws.FILTER('12-2024'!$I$3:$I$64,'12-2024'!$B$3:$B$64=$A10))} -> 0 | I10: =G10-H10 -> 0 | J10: =IFERROR(I10/H10, "-") -> -
A11: Total | B11: =SUM(B3:B10) -> 0 | C11: =SUM(C3:C10) -> 0 | D11: =B11-C11 -> 0 | E11: =IFERROR(D11/C11, "-") -> - | G11: =B11 -> 0 | H11: =SUM(H3:H10) -> 0 | I11: =G11-H11 -> 0 | J11: =IFERROR(I11/H11, "-") -> -

Sheet 01-2024
A1: WELLS FARGO | C1: 01-2024 Actual v. Expected | H1: 01-2024 Actual v. Forecasted | L1: NOTES | M1: SR
A2: Site | B2: State | C2: Actual | D2: Expected | E2: Delta | F2: % | H2: Actual | I2: Forecasted | J2: Delta | K2: %
A3: {=Sites[Site]} -> Adams & Broadway | B3: {=Sites[State]} -> CA | C3: {=IF(ISBLANK(INDIRECT("'"&$A3&"'!B6:E6")), "", INDIRECT("'"&$A3&"'!B6:E6"))} -> 668.5 | D3: 0 | E3: 668.5 | F3: - | H3: {=IF(ISBLANK(INDIRECT("'"&$A3&"'!B24:G24")), "", INDIRECT("'"&$A3&"'!B24:G24"))} -> 668.5 | I3: 660.258 | J3: 8.242 | K3: 0.012482999
A4: Otay Mesa | B4: CA | C4: {=IF(ISBLANK(INDIRECT("'"&$A4&"'!B6:E6")), "", INDIRECT("'"&$A4&"'!B6:E6"))} -> 37.789 | D4: 0 | E4: 37.789 | F4: - | H4: {=IF(ISBLANK(INDIRECT("'"&$A4&"'!B24:G24")), "", INDIRECT("'"&$A4&"'!B24:G24"))} -> 37.789 | I4: 0 | J4: 37.789 | K4: -
A5: San Leandro Ops Center | B5: CA | C5: {=IF(ISBLANK(INDIRECT("'"&$A5&"'!B6:E6")), "", INDIRECT("'"&$A5&"'!B6:E6"))} -> 18587.375 | D5: 25565.67 | E5: -6978.295 | F5: -0.27295569 | H5: {=IF(ISBLANK(INDIRECT("'"&$A5&"'!B24:G24")), "", INDIRECT("'"&$A5&"'!B24:G24"))} -> 18587.375 | I5: 22910.168 | J5: -4322.793 | K5: -0.18868447 | L5: Inverter 4 was replaced on 01/31 | M5: SR079901
A6: Van Nuys | B6: CA | C6: {=IF(ISBLANK(INDIRECT("'"&$A6&"'!B6:E6")), "", INDIRECT("'"&$A6&"'!B6:E6"))} -> 1267.6979 | D6: 0 | E6: 1267.6979 | F6: - | H6: {=IF(ISBLANK(INDIRECT("'"&$A6&"'!B24:G24")), "", INDIRECT("'"&$A6&"'!B24:G24"))} -> 1267.6979 | I6: 1339.747 | J6: -72.049072 | K6: -0.053778118
A7: 98th & Grant | B7: CO | C7: {=IF(ISBLANK(INDIRECT("'"&$A7&"'!B6:E6")), "", INDIRECT("'"&$A7&"'!B6:E6"))} -> 724.2 | D7: 0 | E7: 724.2 | F7: - | H7: {=IF(ISBLANK(INDIRECT("'"&$A7&"'!B24:G24")), "", INDIRECT("'"&$A7&"'!B24:G24"))} -> 724.2 | I7: 1165.016 | J7: -440.816 | K7: -0.37837764
A8: Arapahoe Crossings | B8: CO | C8: {=IF(ISBLANK(INDIRECT("'"&$A8&"'!B6:E6")), "", INDIRECT("'"&$A8&"'!B6:E6"))} -> 2121.2004 | D8: 0 | E8: 2121.2004 | F8: - | H8: {=IF(ISBLANK(INDIRECT("'"&$A8&"'!B24:G24")), "", INDIRECT("'"&$A8&"'!B24:G24"))} -> 2121.2004 | I8: 2132.967 | J8: -11.766622 | K8: -0.0055165513
A9: Aurora City Center | B9: CO | C9: {=IF(ISBLANK(INDIRECT("'"&$A9&"'!B6:E6")), "", INDIRECT("'"&$A9&"'!B6:E6"))} -> 1077.5 | D9: 0 | E9: 1077.5 | F9: - | H9: {=IF(ISBLANK(INDIRECT("'"&$A9&"'!B24:G24")), "", INDIRECT("'"&$A9&"'!B24:G24"))} -> 1077.5 | I9: 1040.516 | J9: 36.984 | K9: 0.035543903
A10: Dry Creek | B10: CO | C10: {=IF(ISBLANK(INDIRECT("'"&$A10&"'!B6:E6")), "", INDIRECT("'"&$A10&"'!B6:E6"))} -> -0.40201212 | D10: 0 | E10: -0.40201212 | F10: - | H10: {=IF(ISBLANK(INDIRECT("'"&$A10&"'!B24:G24")), "", INDIRECT("'"&$A10&"'!B24:G24"))} -> -0.40201212 | I10: 1258.016 | J10: -1258.418 | K10: -1.0003196 | L10: Site is offline from 05/12/2023 | M10: SR078942
A11: Havana Gardens | B11: CO | C11: {=IF(ISBLANK(INDIRECT("'"&$A11&"'!B6:E6")), "", INDIRECT("'"&$A11&"'!B6:E6"))} -> 1739.8 | D11: 0 | E11: 1739.8 | F11: - | H11: {=IF(ISBLANK(INDIRECT("'"&$A11&"'!B24:G24")), "", INDIRECT("'"&$A11&"'!B24:G24"))} -> 1739.8 | I11: 846.258 | J11: 893.542 | K11: 1.0558742 | L11: 03/01/2023 Per Kate - Do Not Pursue Weather Station
A12: Highlands Ranch South | B12: CO | C12: {=IF(ISBLANK(INDIRECT("'"&$A12&"'!B6:E6")), "", INDIRECT("'"&$A12&"'!B6:E6"))} -> 1000.7 | D12: 0 | E12: 1000.7 | F12: - | H12: {=IF(ISBLANK(INDIRECT("'"&$A12&"'!B24:G24")), "", INDIRECT("'"&$A12&"'!B24:G24"))} -> 1000.7 | I12: 1110.774 | J12: -110.074 | K12: -0.099096666
A13: Lone Tree | B13: CO | C13: {=IF(ISBLANK(INDIRECT("'"&$A13&"'!B6:E6")), "", INDIRECT("'"&$A13&"'!B6:E6"))} -> 2395.4 | D13: 0 | E13: 2395.4 | F13: - | H13: {=IF(ISBLANK(INDIRECT("'"&$A13&"'!B24:G24")), "", INDIRECT("'"&$A13&"'!B24:G24"))} -> 2395.4 | I13: 2590.419 | J13: -195.019 | K13: -0.075284732
A14: Meridian | B14: CO | C14: {=IF(ISBLANK(INDIRECT("'"&$A14&"'!B6:E6")), "", INDIRECT("'"&$A14&"'!B6:E6"))} -> 1646.1 | D14: 0 | E14: 1646.1 | F14: - | H14: {=IF(ISBLANK(INDIRECT("'"&$A14&"'!B24:G24")), "", INDIRECT("'"&$A14&"'!B24:G24"))} -> 1646.1 | I14: 1355.097 | J14: 291.003 | K14: 0.21474699
A15: Southglenn Relocation | B15: CO | C15: {=IF(ISBLANK(INDIRECT("'"&$A15&"'!B6:E6")), "", INDIRECT("'"&$A15&"'!B6:E6"))} -> 1513 | D15: 0 | E15: 1513 | F15: - | H15: {=IF(ISBLANK(INDIRECT("'"&$A15&"'!B24:G24")), "", INDIRECT("'"&$A15&"'!B24:G24"))} -> 1513 | I15: 1611.403 | J15: -98.403 | K15: -0.061066661
A16: Standley Lake | B16: CO | C16: {=IF(ISBLANK(INDIRECT("'"&$A16&"'!B6:E6")), "", INDIRECT("'"&$A16&"'!B6:E6"))} -> 2051.1 | D16: 0 | E16: 2051.1 | F16: - | H16: {=IF(ISBLANK(INDIRECT("'"&$A16&"'!B24:G24")), "", INDIRECT("'"&$A16&"'!B24:G24"))} -> 2051.1 | I16: 2170.403 | J16: -119.303 | K16: -0.054968133
A17: East Hartford | B17: CT | C17: {=IF(ISBLANK(INDIRECT("'"&$A17&"'!B6:E6")), "", INDIRECT("'"&$A17&"'!B6:E6"))} -> 119.7 | D17: 246.8964 | E17: -127.1964 | F17: -0.51518127 | H17: {=IF(ISBLANK(INDIRECT("'"&$A17&"'!B24:G24")), "", INDIRECT("'"&$A17&"'!B24:G24"))} -> 119.7 | I17: 273.275 | J17: -153.575 | K17: -0.56197969
A18: Norwalk Post Road | B18: CT | C18: {=IF(ISBLANK(INDIRECT("'"&$A18&"'!B6:E6")), "", INDIRECT("'"&$A18&"'!B6:E6"))} -> 117.74058 | D18: 417.3167 | E18: -299.57612 | F18: -0.71786277 | H18: {=IF(ISBLANK(INDIRECT("'"&$A18&"'!B24:G24")), "", INDIRECT("'"&$A18&"'!B24:G24"))} -> 117.74058 | I18: 376.757 | J18: -259.01642 | K18: -0.68748934
A19: Hialeah Gardens | B19: FL | C19: {=IF(ISBLANK(INDIRECT("'"&$A19&"'!B6:E6")), "", INDIRECT("'"&$A19&"'!B6:E6"))} -> 1428.4985 | D19: 2582.073 | E19: -1153.5745 | F19: -0.44676292 | H19: {=IF(ISBLANK(INDIRECT("'"&$A19&"'!B24:G24")), "", INDIRECT("'"&$A19&"'!B24:G24"))} -> 1428.4985 | I19: 3451.661 | J19: -2023.1625 | K19: -0.58614171
A20: HMHQ | B20: IA | C20: {=IF(ISBLANK(INDIRECT("'"&$A20&"'!B6:E6")), "", INDIRECT("'"&$A20&"'!B6:E6"))} -> 12390.938 | D20: 16455.02 | E20: -4064.0825 | F20: -0.24698132 | H20: {=IF(ISBLANK(INDIRECT("'"&$A20&"'!B24:G24")), "", INDIRECT("'"&$A20&"'!B24:G24"))} -> 12390.938 | I20: 23956.604 | J20: -11565.666 | K20: -0.48277571
A21: West Des Moines Campus East | B21: IA | C21: {=IF(ISBLANK(INDIRECT("'"&$A21&"'!B6:E6")), "", INDIRECT("'"&$A21&"'!B6:E6"))} -> 62192.5 | D21: 8477.248 | E21: 53715.252 | F21: 6.3364021 | H21: {=IF(ISBLANK(INDIRECT("'"&$A21&"'!B24:G24")), "", INDIRECT("'"&$A21&"'!B24:G24"))} -> 62192.5 | I21: 105997.32 | J21: -43804.82 | K21: -0.41326347 | L21: Expected energy was not available till 01/30 | M21: SR080333
A22: West Des Moines Campus West | B22: IA | C22: {=IF(ISBLANK(INDIRECT("'"&$A22&"'!B6:E6")), "", INDIRECT("'"&$A22&"'!B6:E6"))} -> 25312.5 | D22: 4681.486 | E22: 20631.014 | F22: 4.406937 | H22: {=IF(ISBLANK(INDIRECT("'"&$A22&"'!B24:G24")), "", INDIRECT("'"&$A22&"'!B24:G24"))} -> 25312.5 | I22: 55952.783 | J22: -30640.283 | K22: -0.54760963 | L22: Inverter 4 tripped offline on 01/31 Expected energy was not available till 01/30 | M22: SR080633 SR080334
A23: CIC | B23: NC | C23: {=IF(ISBLANK(INDIRECT("'"&$A23&"'!B6:E6")), "", INDIRECT("'"&$A23&"'!B6:E6"))} -> 0 | D23: 0 | E23: 0 | F23: - | H23: {=IF(ISBLANK(INDIRECT("'"&$A23&"'!B24:G24")), "", INDIRECT("'"&$A23&"'!B24:G24"))} -> 0 | I23: 0 | J23: 0 | K23: - | L23: Site de-energized 06/02/2023 due to TIGO investigation. | M23: SR078172
A24: DUC | B24: NC | C24: {=IF(ISBLANK(INDIRECT("'"&$A24&"'!B6:E6")), "", INDIRECT("'"&$A24&"'!B6:E6"))} -> 0 | D24: 0 | E24: 0 | F24: - | H24: {=IF(ISBLANK(INDIRECT("'"&$A24&"'!B24:G24")), "", INDIRECT("'"&$A24&"'!B24:G24"))} -> 0 | I24: 0 | J24: 0 | K24: - | L24: Site de-energized 06/02/2023 due to TIGO investigation. | M24: SR078173
A25: Barnegat Office | B25: NJ | C25: {=IF(ISBLANK(INDIRECT("'"&$A25&"'!B6:E6")), "", INDIRECT("'"&$A25&"'!B6:E6"))} -> 1678.6484 | D25: 1609.744 | E25: 68.904438 | F25: 0.042804593 | H25: {=IF(ISBLANK(INDIRECT("'"&$A25&"'!B24:G24")), "", INDIRECT("'"&$A25&"'!B24:G24"))} -> 1678.6484 | I25: 2100.114 | J25: -421.46556 | K25: -0.20068699
A26: Bayonne Office | B26: NJ | C26: {=IF(ISBLANK(INDIRECT("'"&$A26&"'!B6:E6")), "", INDIRECT("'"&$A26&"'!B6:E6"))} -> 792.7 | D26: 1075.812 | E26: -283.112 | F26: -0.26316122 | H26: {=IF(ISBLANK(INDIRECT("'"&$A26&"'!B24:G24")), "", INDIRECT("'"&$A26&"'!B24:G24"))} -> 792.7 | I26: 2010.779 | J26: -1218.079 | K26: -0.60577468
A27: Bordentown | B27: NJ | C27: {=IF(ISBLANK(INDIRECT("'"&$A27&"'!B6:E6")), "", INDIRECT("'"&$A27&"'!B6:E6"))} -> 705.7 | D27: 734.3849 | E27: -28.6849 | F27: -0.039059763 | H27: {=IF(ISBLANK(INDIRECT("'"&$A27&"'!B24:G24")), "", INDIRECT("'"&$A27&"'!B24:G24"))} -> 705.7 | I27: 1121.351 | J27: -415.651 | K27: -0.37066984
A28: Burlington Springside | B28: NJ | C28: {=IF(ISBLANK(INDIRECT("'"&$A28&"'!B6:E6")), "", INDIRECT("'"&$A28&"'!B6:E6"))} -> 720 | D28: 848.942 | E28: -128.942 | F28: -0.15188552 | H28: {=IF(ISBLANK(INDIRECT("'"&$A28&"'!B24:G24")), "", INDIRECT("'"&$A28&"'!B24:G24"))} -> 720 | I28: 1105.296 | J28: -385.296 | K28: -0.34859078
A29: Cherry Hill Short Hills | B29: NJ | C29: {=IF(ISBLANK(INDIRECT("'"&$A29&"'!B6:E6")), "", INDIRECT("'"&$A29&"'!B6:E6"))} -> 566.71484 | D29: 844.154 | E29: -277.43916 | F29: -0.32865941 | H29: {=IF(ISBLANK(INDIRECT("'"&$A29&"'!B24:G24")), "", INDIRECT("'"&$A29&"'!B24:G24"))} -> 566.71484 | I29: 928.459 | J29: -361.74416 | K29: -0.3896178
A30: Clark Office | B30: NJ | C30: {=IF(ISBLANK(INDIRECT("'"&$A30&"'!B6:E6")), "", INDIRECT("'"&$A30&"'!B6:E6"))} -> 559.8 | D30: 806.6296 | E30: -246.8296 | F30: -0.30600117 | H30: {=IF(ISBLANK(INDIRECT("'"&$A30&"'!B24:G24")), "", INDIRECT("'"&$A30&"'!B24:G24"))} -> 559.8 | I30: 953.546 | J30: -393.746 | K30: -0.41292816
A31: Clifton Office | B31: NJ | C31: {=IF(ISBLANK(INDIRECT("'"&$A31&"'!B6:E6")), "", INDIRECT("'"&$A31&"'!B6:E6"))} -> 824.29688 | D31: 1479.194 | E31: -654.89712 | F31: -0.44273917 | H31: {=IF(ISBLANK(INDIRECT("'"&$A31&"'!B24:G24")), "", INDIRECT("'"&$A31&"'!B24:G24"))} -> 824.29688 | I31: 2566.102 | J31: -1741.8051 | K31: -0.6787747
A32: Clinton Main Relo | B32: NJ | C32: {=IF(ISBLANK(INDIRECT("'"&$A32&"'!B6:E6")), "", INDIRECT("'"&$A32&"'!B6:E6"))} -> 611.73828 | D32: 1001.651 | E32: -389.91272 | F32: -0.38927003 | H32: {=IF(ISBLANK(INDIRECT("'"&$A32&"'!B24:G24")), "", INDIRECT("'"&$A32&"'!B24:G24"))} -> 611.73828 | I32: 1153.765 | J32: -542.02672 | K32: -0.46978953
A33: Closter Office | B33: NJ | C33: {=IF(ISBLANK(INDIRECT("'"&$A33&"'!B6:E6")), "", INDIRECT("'"&$A33&"'!B6:E6"))} -> 144.2 | D33: 202.6485 | E33: -58.4485 | F33: -0.28842306 | H33: {=IF(ISBLANK(INDIRECT("'"&$A33&"'!B24:G24")), "", INDIRECT("'"&$A33&"'!B24:G24"))} -> 144.2 | I33: 494.769 | J33: -350.569 | K33: -0.70855086
A34: East Windsor | B34: NJ | C34: {=IF(ISBLANK(INDIRECT("'"&$A34&"'!B6:E6")), "", INDIRECT("'"&$A34&"'!B6:E6"))} -> 234.4 | D34: 395.1954 | E34: -160.7954 | F34: -0.40687569 | H34: {=IF(ISBLANK(INDIRECT("'"&$A34&"'!B24:G24")), "", INDIRECT("'"&$A34&"'!B24:G24"))} -> 234.4 | I34: 408.178 | J34: -173.778 | K34: -0.42574073
A35: Edison Office | B35: NJ | C35: {=IF(ISBLANK(INDIRECT("'"&$A35&"'!B6:E6")), "", INDIRECT("'"&$A35&"'!B6:E6"))} -> 923 | D35: 960.8481 | E35: -37.8481 | F35: -0.039390305 | H35: {=IF(ISBLANK(INDIRECT("'"&$A35&"'!B24:G24")), "", INDIRECT("'"&$A35&"'!B24:G24"))} -> 923 | I35: 1532.135 | J35: -609.135 | K35: -0.39757267
A36: Ellisburg Circle Center | B36: NJ | C36: {=IF(ISBLANK(INDIRECT("'"&$A36&"'!B6:E6")), "", INDIRECT("'"&$A36&"'!B6:E6"))} -> 241 | D36: 385.1902 | E36: -144.1902 | F36: -0.37433507 | H36: {=IF(ISBLANK(INDIRECT("'"&$A36&"'!B24:G24")), "", INDIRECT("'"&$A36&"'!B24:G24"))} -> 241 | I36: 451.606 | J36: -210.606 | K36: -0.46634899
... A51: Rt. 22 Springfield | B51: NJ | C51: {=IF(ISBLANK(INDIRECT("'"&$A51&"'!B6:E6")), "", INDIRECT("'"&$A51&"'!B6:E6"))} -> 933.7 | D51: 1153.66 | E51: -219.96 | F51: -0.19066276 | H51: {=IF(ISBLANK(INDIRECT("'"&$A51&"'!B24:G24")), "", INDIRECT("'"&$A51&"'!B24:G24"))} -> 933.7 | I51: 1296.399 | J51: -362.699 | K51: -0.27977421
A52: Somerset | B52: NJ | C52: {=IF(ISBLANK(INDIRECT("'"&$A52&"'!B6:E6")), "", INDIRECT("'"&$A52&"'!B6:E6"))} -> 0 | D52: 0 | E52: 0 | F52: - | H52: {=IF(ISBLANK(INDIRECT("'"&$A52&"'!B24:G24")), "", INDIRECT("'"&$A52&"'!B24:G24"))} -> 0 | I52: 0 | J52: 0 | K52: - | L52: No data available
A53: South Plainfield | B53: NJ | C53: {=IF(ISBLANK(INDIRECT("'"&$A53&"'!B6:E6")), "", INDIRECT("'"&$A53&"'!B6:E6"))} -> 440.8 | D53: 493.0951 | E53: -52.2951 | F53: -0.1060548 | H53: {=IF(ISBLANK(INDIRECT("'"&$A53&"'!B24:G24")), "", INDIRECT("'"&$A53&"'!B24:G24"))} -> 440.8 | I53: 750.996 | J53: -310.196 | K53: -0.41304614
A54: West Deptford Woodbury | B54: NJ | C54: {=IF(ISBLANK(INDIRECT("'"&$A54&"'!B6:E6")), "", INDIRECT("'"&$A54&"'!B6:E6"))} -> 1385.9 | D54: 1614.307 | E54: -228.407 | F54: -0.1414892 | H54: {=IF(ISBLANK(INDIRECT("'"&$A54&"'!B24:G24")), "", INDIRECT("'"&$A54&"'!B24:G24"))} -> 1385.9 | I54: 1978.362 | J54: -592.462 | K54: -0.29947098
...

Sheet 02-2024
A1: WELLS FARGO | C1: 02-2024 Actual v. Expected | H1: 02-2024 Actual v. Forecasted | L1: NOTES | M1: SR
A2: Site | B2: State | C2: Actual | D2: Expected | E2: Delta | F2: % | H2: Actual | I2: Forecasted | J2: Delta | K2: %
A3: {=Sites[Site]} -> Adams & Broadway | B3: {=Sites[State]} -> CA | C3: {=IF(ISBLANK(INDIRECT("'"&$A3&"'!B7:E7")), "", INDIRECT("'"&$A3&"'!B7:E7"))} | E3: 0 | F3: - | H3: {=IF(ISBLANK(INDIRECT("'"&$A3&"'!B25:G25")), "", INDIRECT("'"&$A3&"'!B25:G25"))} -> 0 | J3: 0 | K3: -
A4: Otay Mesa | B4: CA | C4: {=IF(ISBLANK(INDIRECT("'"&$A4&"'!B7:E7")), "", INDIRECT("'"&$A4&"'!B7:E7"))} | E4: 0 | F4: - | H4: {=IF(ISBLANK(INDIRECT("'"&$A4&"'!B25:G25")), "", INDIRECT("'"&$A4&"'!B25:G25"))} -> 0 | J4: 0 | K4: -
A5: San Leandro Ops Center | B5: CA | C5: {=IF(ISBLANK(INDIRECT("'"&$A5&"'!B7:E7")), "", INDIRECT("'"&$A5&"'!B7:E7"))} | E5: 0 | F5: - | H5: {=IF(ISBLANK(INDIRECT("'"&$A5&"'!B25:G25")), "", INDIRECT("'"&$A5&"'!B25:G25"))} -> 0 | J5: 0 | K5: -
A6: Van Nuys | B6: CA | C6: {=IF(ISBLANK(INDIRECT("'"&$A6&"'!B7:E7")), "", INDIRECT("'"&$A6&"'!B7:E7"))} | E6: 0 | F6: - | H6: {=IF(ISBLANK(INDIRECT("'"&$A6&"'!B25:G25")), "", INDIRECT("'"&$A6&"'!B25:G25"))} -> 0 | J6: 0 | K6: -
A7: 98th & Grant | B7: CO | C7: {=IF(ISBLANK(INDIRECT("'"&$A7&"'!B7:E7")), "", INDIRECT("'"&$A7&"'!B7:E7"))} | E7: 0 | F7: - | H7: {=IF(ISBLANK(INDIRECT("'"&$A7&"'!B25:G25")), "", INDIRECT("'"&$A7&"'!B25:G25"))} -> 0 | J7: 0 | K7: -
A8: Arapahoe Crossings | B8: CO | C8: {=IF(ISBLANK(INDIRECT("'"&$A8&"'!B7:E7")), "", INDIRECT("'"&$A8&"'!B7:E7"))} | E8: 0 | F8: - | H8: {=IF(ISBLANK(INDIRECT("'"&$A8&"'!B25:G25")), "", INDIRECT("'"&$A8&"'!B25:G25"))} -> 0 | J8: 0 | K8: -
A9: Aurora City Center | B9: CO | C9: {=IF(ISBLANK(INDIRECT("'"&$A9&"'!B7:E7")), "", INDIRECT("'"&$A9&"'!B7:E7"))} | E9: 0 | F9: - | H9: {=IF(ISBLANK(INDIRECT("'"&$A9&"'!B25:G25")), "", INDIRECT("'"&$A9&"'!B25:G25"))} -> 0 | J9: 0 | K9: -
A10: Dry Creek | B10: CO | C10: {=IF(ISBLANK(INDIRECT("'"&$A10&"'!B7:E7")), "", INDIRECT("'"&$A10&"'!B7:E7"))} | E10: 0 | F10: - | H10: {=IF(ISBLANK(INDIRECT("'"&$A10&"'!B25:G25")), "", INDIRECT("'"&$A10&"'!B25:G25"))} -> 0 | J10: 0 | K10: -
A11: Havana Gardens | B11: CO | C11: {=IF(ISBLANK(INDIRECT("'"&$A11&"'!B7:E7")), "", INDIRECT("'"&$A11&"'!B7:E7"))} | E11: 0 | F11: - | H11: {=IF(ISBLANK(INDIRECT("'"&$A11&"'!B25:G25")), "", INDIRECT("'"&$A11&"'!B25:G25"))} -> 0 | J11: 0 | K11: -
A12: Highlands Ranch South | B12: CO | C12: {=IF(ISBLANK(INDIRECT("'"&$A12&"'!B7:E7")), "", INDIRECT("'"&$A12&"'!B7:E7"))} | E12: 0 | F12: - | H12: {=IF(ISBLANK(INDIRECT("'"&$A12&"'!B25:G25")), "", INDIRECT("'"&$A12&"'!B25:G25"))} -> 0 | J12: 0 | K12: -
A13: Lone Tree | B13: CO | C13: {=IF(ISBLANK(INDIRECT("'"&$A13&"'!B7:E7")), "", INDIRECT("'"&$A13&"'!B7:E7"))} | E13: 0 | F13: - | H13: {=IF(ISBLANK(INDIRECT("'"&$A13&"'!B25:G25")), "", INDIRECT("'"&$A13&"'!B25:G25"))} -> 0 | J13: 0 | K13: -
A14: Meridian | B14: CO | C14: {=IF(ISBLANK(INDIRECT("'"&$A14&"'!B7:E7")), "", INDIRECT("'"&$A14&"'!B7:E7"))} | E14: 0 | F14: - | H14: {=IF(ISBLANK(INDIRECT("'"&$A14&"'!B25:G25")), "", INDIRECT("'"&$A14&"'!B25:G25"))} -> 0 | J14: 0 | K14: -
A15: Southglenn Relocation | B15: CO | C15: {=IF(ISBLANK(INDIRECT("'"&$A15&"'!B7:E7")), "", INDIRECT("'"&$A15&"'!B7:E7"))} | E15: 0 | F15: - | H15: {=IF(ISBLANK(INDIRECT("'"&$A15&"'!B25:G25")), "", INDIRECT("'"&$A15&"'!B25:G25"))} -> 0 | J15: 0 | K15: -
... A64: GM - San Antonio Ops | B64: TX | C64: {=IF(ISBLANK(INDIRECT("'"&$A64&"'!B7:E7")), "", INDIRECT("'"&$A64&"'!B7:E7"))} | E64: 0 | F64: - | H64: {=IF(ISBLANK(INDIRECT("'"&$A64&"'!B25:G25")), "", INDIRECT("'"&$A64&"'!B25:G25"))} -> 0 | J64: 0 | K64: -
A65: Total | C65: =SUM(C3:C64) -> 0 | D65: =SUM(D3:D64) -> 0 | E65: =C65-D65 -> 0 | F65: =IFERROR(E65/D65, "-") -> - | H65: =C65 -> 0 | I65: =SUM(I3:I64) -> 0 | J65: =H65-I65 -> 0 | K65: =IFERROR(J65/I65, "-") -> -

Sheet 03-2024
A1: WELLS FARGO | C1: 03-2024 Actual v. Expected | H1: 03-2024 Actual v. Forecasted | L1: NOTES | M1: SR
A2: Site | B2: State | C2: Actual | D2: Expected | E2: Delta | F2: % | H2: Actual | I2: Forecasted | J2: Delta | K2: %
A3: {=Sites[Site]} -> Adams & Broadway | B3: {=Sites[State]} -> CA | C3: {=IF(ISBLANK(INDIRECT("'"&$A3&"'!B8:E8")), "", INDIRECT("'"&$A3&"'!B8:E8"))} | E3: 0 | F3: - | H3: {=IF(ISBLANK(INDIRECT("'"&$A3&"'!B26:G26")), "", INDIRECT("'"&$A3&"'!B26:G26"))} -> 0 | J3: 0 | K3: -
A4: Otay Mesa | B4: CA | C4: {=IF(ISBLANK(INDIRECT("'"&$A4&"'!B8:E8")), "", INDIRECT("'"&$A4&"'!B8:E8"))} | E4: 0 | F4: - | H4: {=IF(ISBLANK(INDIRECT("'"&$A4&"'!B26:G26")), "", INDIRECT("'"&$A4&"'!B26:G26"))} -> 0 | J4: 0 | K4: -
A5: San Leandro Ops Center | B5: CA | C5: {=IF(ISBLANK(INDIRECT("'"&$A5&"'!B8:E8")), "", INDIRECT("'"&$A5&"'!B8:E8"))} | E5: 0 | F5: - | H5: {=IF(ISBLANK(INDIRECT("'"&$A5&"'!B26:G26")), "", INDIRECT("'"&$A5&"'!B26:G26"))} -> 0 | J5: 0 | K5: -
A6: Van Nuys | B6: CA | C6: {=IF(ISBLANK(INDIRECT("'"&$A6&"'!B8:E8")), "", INDIRECT("'"&$A6&"'!B8:E8"))} | E6: 0 | F6: - | H6: {=IF(ISBLANK(INDIRECT("'"&$A6&"'!B26:G26")), "", INDIRECT("'"&$A6&"'!B26:G26"))} -> 0 | J6: 0 | K6: -
A7: 98th & Grant | B7: CO | C7: {=IF(ISBLANK(INDIRECT("'"&$A7&"'!B8:E8")), "", INDIRECT("'"&$A7&"'!B8:E8"))} | E7: 0 | F7: - | H7: {=IF(ISBLANK(INDIRECT("'"&$A7&"'!B26:G26")), "", INDIRECT("'"&$A7&"'!B26:G26"))} -> 0 | J7: 0 | K7: -
A8: Arapahoe Crossings | B8: CO | C8: {=IF(ISBLANK(INDIRECT("'"&$A8&"'!B8:E8")), "", INDIRECT("'"&$A8&"'!B8:E8"))} | E8: 0 | F8: - | H8: {=IF(ISBLANK(INDIRECT("'"&$A8&"'!B26:G26")), "", INDIRECT("'"&$A8&"'!B26:G26"))} -> 0 | J8: 0 | K8: -
A9: Aurora City Center | B9: CO | C9: {=IF(ISBLANK(INDIRECT("'"&$A9&"'!B8:E8")), "", INDIRECT("'"&$A9&"'!B8:E8"))} | E9: 0 | F9: - | H9: {=IF(ISBLANK(INDIRECT("'"&$A9&"'!B26:G26")), "", INDIRECT("'"&$A9&"'!B26:G26"))} -> 0 | J9: 0 | K9: -
A10: Dry Creek | B10: CO | C10: {=IF(ISBLANK(INDIRECT("'"&$A10&"'!B8:E8")), "", INDIRECT("'"&$A10&"'!B8:E8"))} | E10: 0 | F10: - | H10: {=IF(ISBLANK(INDIRECT("'"&$A10&"'!B26:G26")), "", INDIRECT("'"&$A10&"'!B26:G26"))} -> 0 | J10: 0 | K10: -
A11: Havana Gardens | B11: CO | C11: {=IF(ISBLANK(INDIRECT("'"&$A11&"'!B8:E8")), "", INDIRECT("'"&$A11&"'!B8:E8"))} | E11: 0 | F11: - | H11: {=IF(ISBLANK(INDIRECT("'"&$A11&"'!B26:G26")), "", INDIRECT("'"&$A11&"'!B26:G26"))} -> 0 | J11: 0 | K11: -
A12: Highlands Ranch South | B12: CO | C12: {=IF(ISBLANK(INDIRECT("'"&$A12&"'!B8:E8")), "", INDIRECT("'"&$A12&"'!B8:E8"))} | E12: 0 | F12: - | H12: {=IF(ISBLANK(INDIRECT("'"&$A12&"'!B26:G26")), "", INDIRECT("'"&$A12&"'!B26:G26"))} -> 0 | J12: 0 | K12: -
A13: Lone Tree | B13: CO | C13: {=IF(ISBLANK(INDIRECT("'"&$A13&"'!B8:E8")), "", INDIRECT("'"&$A13&"'!B8:E8"))} | E13: 0 | F13: - | H13: {=IF(ISBLANK(INDIRECT("'"&$A13&"'!B26:G26")), "", INDIRECT("'"&$A13&"'!B26:G26"))} -> 0 | J13: 0 | K13: -
A14: Meridian | B14: CO | C14: {=IF(ISBLANK(INDIRECT("'"&$A14&"'!B8:E8")), "", INDIRECT("'"&$A14&"'!B8:E8"))} | E14: 0 | F14: - | H14: {=IF(ISBLANK(INDIRECT("'"&$A14&"'!B26:G26")), "", INDIRECT("'"&$A14&"'!B26:G26"))} -> 0 | J14: 0 | K14: -
A15: Southglenn Relocation | B15: CO | C15: {=IF(ISBLANK(INDIRECT("'"&$A15&"'!B8:E8")), "", INDIRECT("'"&$A15&"'!B8:E8"))} | E15: 0 | F15: - | H15: {=IF(ISBLANK(INDIRECT("'"&$A15&"'!B26:G26")), "", INDIRECT("'"&$A15&"'!B26:G26"))} -> 0 | J15: 0 | K15: -
... A64: GM - San Antonio Ops | B64: TX | C64: {=IF(ISBLANK(INDIRECT("'"&$A64&"'!B8:E8")), "", INDIRECT("'"&$A64&"'!B8:E8"))} | E64: 0 | F64: - | H64: {=IF(ISBLANK(INDIRECT("'"&$A64&"'!B26:G26")), "", INDIRECT("'"&$A64&"'!B26:G26"))} -> 0 | J64: 0 | K64: -
A65: Total | C65: =SUM(C3:C64) -> 0 | D65: =SUM(D3:D64) -> 0 | E65: =C65-D65 -> 0 | F65: =IFERROR(E65/D65, "-") -> - | H65: =C65 -> 0 | I65: =SUM(I3:I64) -> 0 | J65: =H65-I65 -> 0 | K65: =IFERROR(J65/I65, "-") -> -

Sheet 04-2024
A1: WELLS FARGO | C1: 04-2024 Actual v. Expected | H1: 04-2024 Actual v. Forecasted | L1: NOTES | M1: SR
A2: Site | B2: State | C2: Actual | D2: Expected | E2: Delta | F2: % | H2: Actual | I2: Forecasted | J2: Delta | K2: %
A3: {=Sites[Site]} -> Adams & Broadway | B3: {=Sites[State]} -> CA | C3: {=IF(ISBLANK(INDIRECT("'"&$A3&"'!B9:E9")), "", INDIRECT("'"&$A3&"'!B9:E9"))} | E3: 0 | F3: - | H3: {=IF(ISBLANK(INDIRECT("'"&$A3&"'!B27:G27")), "", INDIRECT("'"&$A3&"'!B27:G27"))} -> 0 | J3: 0 | K3: -
A4: Otay Mesa | B4: CA | C4: {=IF(ISBLANK(INDIRECT("'"&$A4&"'!B9:E9")), "", INDIRECT("'"&$A4&"'!B9:E9"))} | E4: 0 | F4: - | H4: {=IF(ISBLANK(INDIRECT("'"&$A4&"'!B27:G27")), "", INDIRECT("'"&$A4&"'!B27:G27"))} -> 0 | J4: 0 | K4: -
A5: San Leandro Ops Center | B5: CA | C5: {=IF(ISBLANK(INDIRECT("'"&$A5&"'!B9:E9")), "", INDIRECT("'"&$A5&"'!B9:E9"))} | E5: 0 | F5: - | H5: {=IF(ISBLANK(INDIRECT("'"&$A5&"'!B27:G27")), "", INDIRECT("'"&$A5&"'!B27:G27"))} -> 0 | J5: 0 | K5: -
A6: Van Nuys | B6: CA | C6: {=IF(ISBLANK(INDIRECT("'"&$A6&"'!B9:E9")), "", INDIRECT("'"&$A6&"'!B9:E9"))} | E6: 0 | F6: - | H6: {=IF(ISBLANK(INDIRECT("'"&$A6&"'!B27:G27")), "", INDIRECT("'"&$A6&"'!B27:G27"))} -> 0 | J6: 0 | K6: -
A7: 98th & Grant | B7: CO | C7: {=IF(ISBLANK(INDIRECT("'"&$A7&"'!B9:E9")), "", INDIRECT("'"&$A7&"'!B9:E9"))} | E7: 0 | F7: - | H7: {=IF(ISBLANK(INDIRECT("'"&$A7&"'!B27:G27")), "", INDIRECT("'"&$A7&"'!B27:G27"))} -> 0 | J7: 0 | K7: -
A8: Arapahoe Crossings | B8: CO | C8: {=IF(ISBLANK(INDIRECT("'"&$A8&"'!B9:E9")), "", INDIRECT("'"&$A8&"'!B9:E9"))} | E8: 0 | F8: - | H8: {=IF(ISBLANK(INDIRECT("'"&$A8&"'!B27:G27")), "", INDIRECT("'"&$A8&"'!B27:G27"))} -> 0 | J8: 0 | K8: -
A9: Aurora City Center | B9: CO | C9: {=IF(ISBLANK(INDIRECT("'"&$A9&"'!B9:E9")), "", INDIRECT("'"&$A9&"'!B9:E9"))} | E9: 0 | F9: - | H9: {=IF(ISBLANK(INDIRECT("'"&$A9&"'!B27:G27")), "", INDIRECT("'"&$A9&"'!B27:G27"))} -> 0 | J9: 0 | K9: -
A10: Dry Creek | B10: CO | C10: {=IF(ISBLANK(INDIRECT("'"&$A10&"'!B9:E9")), "", INDIRECT("'"&$A10&"'!B9:E9"))} | E10: 0 | F10: - | H10: {=IF(ISBLANK(INDIRECT("'"&$A10&"'!B27:G27")), "", INDIRECT("'"&$A10&"'!B27:G27"))} -> 0 | J10: 0 | K10: -
A11: Havana Gardens | B11: CO | C11: {=IF(ISBLANK(INDIRECT("'"&$A11&"'!B9:E9")), "", INDIRECT("'"&$A11&"'!B9:E9"))} | E11: 0 | F11: - | H11: {=IF(ISBLANK(INDIRECT("'"&$A11&"'!B27:G27")), "", INDIRECT("'"&$A11&"'!B27:G27"))} -> 0 | J11: 0 | K11: -
A12: Highlands Ranch South | B12: CO | C12: {=IF(ISBLANK(INDIRECT("'"&$A12&"'!B9:E9")), "", INDIRECT("'"&$A12&"'!B9:E9"))} | E12: 0 | F12: - | H12: {=IF(ISBLANK(INDIRECT("'"&$A12&"'!B27:G27")), "", INDIRECT("'"&$A12&"'!B27:G27"))} -> 0 | J12: 0 | K12: -
A13: Lone Tree | B13: CO | C13: {=IF(ISBLANK(INDIRECT("'"&$A13&"'!B9:E9")), "", INDIRECT("'"&$A13&"'!B9:E9"))} | E13: 0 | F13: - | H13: {=IF(ISBLANK(INDIRECT("'"&$A13&"'!B27:G27")), "", INDIRECT("'"&$A13&"'!B27:G27"))} -> 0 | J13: 0 | K13: -
A14: Meridian | B14: CO | C14: {=IF(ISBLANK(INDIRECT("'"&$A14&"'!B9:E9")), "", INDIRECT("'"&$A14&"'!B9:E9"))} | E14: 0 | F14: - | H14: {=IF(ISBLANK(INDIRECT("'"&$A14&"'!B27:G27")), "", INDIRECT("'"&$A14&"'!B27:G27"))} -> 0 | J14: 0 | K14: -
A15: Southglenn Relocation | B15: CO | C15: {=IF(ISBLANK(INDIRECT("'"&$A15&"'!B9:E9")), "", INDIRECT("'"&$A15&"'!B9:E9"))} | E15: 0 | F15: - | H15: {=IF(ISBLANK(INDIRECT("'"&$A15&"'!B27:G27")), "", INDIRECT("'"&$A15&"'!B27:G27"))} -> 0 | J15: 0 | K15: -
... A64: GM - San Antonio Ops | B64: TX | C64: {=IF(ISBLANK(INDIRECT("'"&$A64&"'!B9:E9")), "", INDIRECT("'"&$A64&"'!B9:E9"))} | E64: 0 | F64: - | H64: {=IF(ISBLANK(INDIRECT("'"&$A64&"'!B27:G27")), "", INDIRECT("'"&$A64&"'!B27:G27"))} -> 0 | J64: 0 | K64: -
A65: Total | C65: =SUM(C3:C64) -> 0 | D65: =SUM(D3:D64) -> 0 | E65: =C65-D65 -> 0 | F65: =IFERROR(E65/D65, "-") -> - | H65: =C65 -> 0 | I65: =SUM(I3:I64) -> 0 | J65: =H65-I65 -> 0 | K65: =IFERROR(J65/I65, "-") -> -

Sheet 05-2024
A1: WELLS FARGO | C1: 05-2024 Actual v. Expected | H1: 05-2024 Actual v. Forecasted | L1: NOTES | M1: SR
A2: Site | B2: State | C2: Actual | D2: Expected | E2: Delta | F2: % | H2: Actual | I2: Forecasted | J2: Delta | K2: %
A3: {=Sites[Site]} -> Adams & Broadway | B3: {=Sites[State]} -> CA | C3: {=IF(ISBLANK(INDIRECT("'"&$A3&"'!B10:E10")), "", INDIRECT("'"&$A3&"'!B10:E10"))} | E3: 0 | F3: - | H3: {=IF(ISBLANK(INDIRECT("'"&$A3&"'!B28:G28")), "", INDIRECT("'"&$A3&"'!B28:G28"))} -> 0 | J3: 0 | K3: -
A4: Otay Mesa | B4: CA | C4: {=IF(ISBLANK(INDIRECT("'"&$A4&"'!B10:E10")), "", INDIRECT("'"&$A4&"'!B10:E10"))} | E4: 0 | F4: - | H4: {=IF(ISBLANK(INDIRECT("'"&$A4&"'!B28:G28")), "", INDIRECT("'"&$A4&"'!B28:G28"))} -> 0 | J4: 0 | K4: -
A5: San Leandro Ops Center | B5: CA | C5: {=IF(ISBLANK(INDIRECT("'"&$A5&"'!B10:E10")), "", INDIRECT("'"&$A5&"'!B10:E10"))} | E5: 0 | F5: - | H5: {=IF(ISBLANK(INDIRECT("'"&$A5&"'!B28:G28")), "", INDIRECT("'"&$A5&"'!B28:G28"))} -> 0 | J5: 0 | K5: -
