Workbook
Name JanActual: #REF!
Name JanActual2: #REF!
Name JanExpected: #REF!
Name JanExpectedDelta: #REF!
Name JanExpectedPercent: #REF!
Name JanExpPercent: #REF!
Name JanForecasted: #REF!
Name JanForecastedDelta: #REF!
Name JanForecastedPercent: #REF!
Name portfolio: Sites!$B$1:$B$1
Name Year: Sites!#REF!

Sheet Year to Date
A1: {=portfolio} -> Clean Capital | D1: Year to Date Actual v. Expected | G1: Year to Date Actual v. Forecasted
A2: Total | C2: =SUM(C4:C171) -> 31448037 | D2: =SUM(D4:D171) -> 18177218 | E2: =C2-D2 -> 13270819 | F2: =IFERROR(E2/D2, 0) -> 0.73007976 | G2: =SUM(G4:G171) -> 35397737 | H2: =C2-G2 -> -3949700.6 | I2: =IFERROR(H2/G2, 0) -> -0.1115806
A3: Site | B3: State | C3: Actual | D3: Expected | E3: Delta | F3: % | G3: Forecasted | H3: Delta | I3: %
A4: {=Sites[Site]} -> Lexington - Cotting School | B4: {=Sites[State]} -> MA | C4: =SUM('1st Qtr'!C4, '2nd Qtr'!C4, '3rd Qtr'!C4, '4th Qtr'!C4) -> 278107.89 | D4: =SUM('1st Qtr'!D4, '2nd Qtr'!D4, '3rd Qtr'!D4, '4th Qtr'!D4) -> 0 | E4: =IF(AND(ISNUMBER(C4),ISNUMBER(D4)), C4-D4, "") -> 278107.89 | F4: =IFERROR(E4/D4, "") | G4: =SUM('1st Qtr'!G4, '2nd Qtr'!G4, '3rd Qtr'!G4, '4th Qtr'!G4) -> 0 | H4: =SUM('1st Qtr'!H4, '2nd Qtr'!H4, '3rd Qtr'!H4, '4th Qtr'!H4) -> 18073.6 | I4: =IFERROR(H4/G4, "")
A5: Pacoima - Whiteman Airport | B5: CA | C5: =SUM('1st Qtr'!C5, '2nd Qtr'!C5, '3rd Qtr'!C5, '4th Qtr'!C5) -> 228624.1 | D5: =SUM('1st Qtr'!D5, '2nd Qtr'!D5, '3rd Qtr'!D5, '4th Qtr'!D5) -> 0 | E5: =IF(AND(ISNUMBER(C5),ISNUMBER(D5)), C5-D5, "") -> 228624.1 | F5: =IFERROR(E5/D5, "") | G5: =SUM('1st Qtr'!G5, '2nd Qtr'!G5, '3rd Qtr'!G5, '4th Qtr'!G5) -> 408267.6 | H5: =SUM('1st Qtr'!H5, '2nd Qtr'!H5, '3rd Qtr'!H5, '4th Qtr'!H5) -> -179643.5 | I5: =IFERROR(H5/G5, "") -> -0.4400141
A6: Hyannis - Sturgis Charter School | B6: MA | C6: =SUM('1st Qtr'!C6, '2nd Qtr'!C6, '3rd Qtr'!C6, '4th Qtr'!C6) -> 288864.64 | D6: =SUM('1st Qtr'!D6, '2nd Qtr'!D6, '3rd Qtr'!D6, '4th Qtr'!D6) -> 0 | E6: =IF(AND(ISNUMBER(C6),ISNUMBER(D6)), C6-D6, "") -> 288864.64 | F6: =IFERROR(E6/D6, "") | G6: =SUM('1st Qtr'!G6, '2nd Qtr'!G6, '3rd Qtr'!G6, '4th Qtr'!G6) -> 274319.08 | H6: =SUM('1st Qtr'!H6, '2nd Qtr'!H6, '3rd Qtr'!H6, '4th Qtr'!H6) -> 14545.565 | I6: =IFERROR(H6/G6, "") -> 0.053024254
A7: South Dennis - Tony Kent Arena | B7: MA | C7: =SUM('1st Qtr'!C7, '2nd Qtr'!C7, '3rd Qtr'!C7, '4th Qtr'!C7) -> 325217.18 | D7: =SUM('1st Qtr'!D7, '2nd Qtr'!D7, '3rd Qtr'!D7, '4th Qtr'!D7) -> 0 | E7: =IF(AND(ISNUMBER(C7),ISNUMBER(D7)), C7-D7, "") -> 325217.18 | F7: =IFERROR(E7/D7, "") | G7: =SUM('1st Qtr'!G7, '2nd Qtr'!G7, '3rd Qtr'!G7, '4th Qtr'!G7) -> 0 | H7: =SUM('1st Qtr'!H7, '2nd Qtr'!H7, '3rd Qtr'!H7, '4th Qtr'!H7) -> 30999.12 | I7: =IFERROR(H7/G7, "")
A8: Caropolis - Felician Sisters | B8: PA | C8: =SUM('1st Qtr'!C8, '2nd Qtr'!C8, '3rd Qtr'!C8, '4th Qtr'!C8) -> 416062.3 | D8: =SUM('1st Qtr'!D8, '2nd Qtr'!D8, '3rd Qtr'!D8, '4th Qtr'!D8) -> 0 | E8: =IF(AND(ISNUMBER(C8),ISNUMBER(D8)), C8-D8, "") -> 416062.3 | F8: =IFERROR(E8/D8, "") | G8: =SUM('1st Qtr'!G8, '2nd Qtr'!G8, '3rd Qtr'!G8, '4th Qtr'!G8) -> 0 | H8: =SUM('1st Qtr'!H8, '2nd Qtr'!H8, '3rd Qtr'!H8, '4th Qtr'!H8) -> 0 | I8: =IFERROR(H8/G8, "")
A9: Clear Lake - Eastlake Gohman | B9: MN | C9: =SUM('1st Qtr'!C9, '2nd Qtr'!C9, '3rd Qtr'!C9, '4th Qtr'!C9) -> 1328939.1 | D9: =SUM('1st Qtr'!D9, '2nd Qtr'!D9, '3rd Qtr'!D9, '4th Qtr'!D9) -> 0 | E9: =IF(AND(ISNUMBER(C9),ISNUMBER(D9)), C9-D9, "") -> 1328939.1 | F9: =IFERROR(E9/D9, "") | G9: =SUM('1st Qtr'!G9, '2nd Qtr'!G9, '3rd Qtr'!G9, '4th Qtr'!G9) -> 1455149.6 | H9: =SUM('1st Qtr'!H9, '2nd Qtr'!H9, '3rd Qtr'!H9, '4th Qtr'!H9) -> -126210.5 | I9: =IFERROR(H9/G9, "") -> -0.086733697
A10: Zumbrota - Eastlake Brenda Luhman | B10: MN | C10: =SUM('1st Qtr'!C10, '2nd Qtr'!C10, '3rd Qtr'!C10, '4th Qtr'!C10) -> 1455643.1 | D10: =SUM('1st Qtr'!D10, '2nd Qtr'!D10, '3rd Qtr'!D10, '4th Qtr'!D10) -> 0 | E10: =IF(AND(ISNUMBER(C10),ISNUMBER(D10)), C10-D10, "") -> 1455643.1 | F10: =IFERROR(E10/D10, "") | G10: =SUM('1st Qtr'!G10, '2nd Qtr'!G10, '3rd Qtr'!G10, '4th Qtr'!G10) -> 1425381.8 | H10: =SUM('1st Qtr'!H10, '2nd Qtr'!H10, '3rd Qtr'!H10, '4th Qtr'!H10) -> 30261.327 | I10: =IFERROR(H10/G10, "") -> 0.021230331
A11: Cokato - Eastlake Carlson | B11: MN | C11: =SUM('1st Qtr'!C11, '2nd Qtr'!C11, '3rd Qtr'!C11, '4th Qtr'!C11) -> 1312942.5 | D11: =SUM('1st Qtr'!D11, '2nd Qtr'!D11, '3rd Qtr'!D11, '4th Qtr'!D11) -> 0 | E11: =IF(AND(ISNUMBER(C11),ISNUMBER(D11)), C11-D11, "") -> 1312942.5 | F11: =IFERROR(E11/D11, "") | G11: =SUM('1st Qtr'!G11, '2nd Qtr'!G11, '3rd Qtr'!G11, '4th Qtr'!G11) -> 1541905.1 | H11: =SUM('1st Qtr'!H11, '2nd Qtr'!H11, '3rd Qtr'!H11, '4th Qtr'!H11) -> -228962.62 | I11: =IFERROR(H11/G11, "") -> -0.14849333
A12: North Branch - Cornille 2 | B12: MN | C12: =SUM('1st Qtr'!C12, '2nd Qtr'!C12, '3rd Qtr'!C12, '4th Qtr'!C12) -> 1331327 | D12: =SUM('1st Qtr'!D12, '2nd Qtr'!D12, '3rd Qtr'!D12, '4th Qtr'!D12) -> 0 | E12: =IF(AND(ISNUMBER(C12),ISNUMBER(D12)), C12-D12, "") -> 1331327 | F12: =IFERROR(E12/D12, "") | G12: =SUM('1st Qtr'!G12, '2nd Qtr'!G12, '3rd Qtr'!G12, '4th Qtr'!G12) -> 1465703.4 | H12: =SUM('1st Qtr'!H12, '2nd Qtr'!H12, '3rd Qtr'!H12, '4th Qtr'!H12) -> -134376.4 | I12: =IFERROR(H12/G12, "") -> -0.091680486
A13: Clear Lake - Eastlake Hammer | B13: MN | C13: =SUM('1st Qtr'!C13, '2nd Qtr'!C13, '3rd Qtr'!C13, '4th Qtr'!C13) -> 1595516 | D13: =SUM('1st Qtr'!D13, '2nd Qtr'!D13, '3rd Qtr'!D13, '4th Qtr'!D13) -> 0 | E13: =IF(AND(ISNUMBER(C13),ISNUMBER(D13)), C13-D13, "") -> 1595516 | F13: =IFERROR(E13/D13, "") | G13: =SUM('1st Qtr'!G13, '2nd Qtr'!G13, '3rd Qtr'!G13, '4th Qtr'!G13) -> 1742961.4 | H13: =SUM('1st Qtr'!H13, '2nd Qtr'!H13, '3rd Qtr'!H13, '4th Qtr'!H13) -> -147445.4 | I13: =IFERROR(H13/G13, "") -> -0.084594759
A14: Eastlake - Hertzberg CSG 1 | B14: MN | C14: =SUM('1st Qtr'!C14, '2nd Qtr'!C14, '3rd Qtr'!C14, '4th Qtr'!C14) -> 1471542 | D14: =SUM('1st Qtr'!D14, '2nd Qtr'!D14, '3rd Qtr'!D14, '4th Qtr'!D14) -> 0 | E14: =IF(AND(ISNUMBER(C14),ISNUMBER(D14)), C14-D14, "") -> 1471542 | F14: =IFERROR(E14/D14, "") | G14: =SUM('1st Qtr'!G14, '2nd Qtr'!G14, '3rd Qtr'!G14, '4th Qtr'!G14) -> 1751801.9 | H14: =SUM('1st Qtr'!H14, '2nd Qtr'!H14, '3rd Qtr'!H14, '4th Qtr'!H14) -> -280259.92 | I14: =IFERROR(H14/G14, "") -> -0.1599838
A15: Cokato - Eastlake Laurel Village | B15: MN | C15: =SUM('1st Qtr'!C15, '2nd Qtr'!C15, '3rd Qtr'!C15, '4th Qtr'!C15) -> 1605992.3 | D15: =SUM('1st Qtr'!D15, '2nd Qtr'!D15, '3rd Qtr'!D15, '4th Qtr'!D15) -> 0 | E15: =IF(AND(ISNUMBER(C15),ISNUMBER(D15)), C15-D15, "") -> 1605992.3 | F15: =IFERROR(E15/D15, "") | G15: =SUM('1st Qtr'!G15, '2nd Qtr'!G15, '3rd Qtr'!G15, '4th Qtr'!G15) -> 1763060.3 | H15: =SUM('1st Qtr'!H15, '2nd Qtr'!H15, '3rd Qtr'!H15, '4th Qtr'!H15) -> -157067.99 | I15: =IFERROR(H15/G15, "") -> -0.089088267
A16: St. Peter - Eastlake Paulson | B16: MN | C16: =SUM('1st Qtr'!C16, '2nd Qtr'!C16, '3rd Qtr'!C16, '4th Qtr'!C16) -> 1413701.5 | D16: =SUM('1st Qtr'!D16, '2nd Qtr'!D16, '3rd Qtr'!D16, '4th Qtr'!D16) -> 0 | E16: =IF(AND(ISNUMBER(C16),ISNUMBER(D16)), C16-D16, "") -> 1413701.5 | F16: =IFERROR(E16/D16, "") | G16: =SUM('1st Qtr'!G16, '2nd Qtr'!G16, '3rd Qtr'!G16, '4th Qtr'!G16) -> 1539248.4 | H16: =SUM('1st Qtr'!H16, '2nd Qtr'!H16, '3rd Qtr'!H16, '4th Qtr'!H16) -> -125546.94 | I16: =IFERROR(H16/G16, "") -> -0.081563794
... A85: NY: Rome - 7776 Tannery RD | B85: NY | C85: =SUM('1st Qtr'!C85, '2nd Qtr'!C85, '3rd Qtr'!C85, '4th Qtr'!C85) -> 1355367.8 | D85: =SUM('1st Qtr'!D85, '2nd Qtr'!D85, '3rd Qtr'!D85, '4th Qtr'!D85) -> 1483213.7 | E85: =IF(AND(ISNUMBER(C85),ISNUMBER(D85)), C85-D85, "") -> -127845.89 | F85: =IFERROR(E85/D85, "") -> -0.086195191 | G85: =SUM('1st Qtr'!G85, '2nd Qtr'!G85, '3rd Qtr'!G85, '4th Qtr'!G85) -> 1424070.8 | H85: =SUM('1st Qtr'!H85, '2nd Qtr'!H85, '3rd Qtr'!H85, '4th Qtr'!H85) -> -68702.988 | I85: =IFERROR(H85/G85, "") -> -0.048244081

Sheet 1st Qtr
A1: {=portfolio} -> Clean Capital | D1: 1st Quarter Actual v. Expected | G1: 1st Quarter Actual v. Forecasted
A2: Total | C2: =SUM(C4:C179) -> 1827946.7 | D2: =SUM(D4:D179) -> 0 | E2: =C2-D2 -> 1827946.7 | F2: =IFERROR(E2/D2, 0) -> 0 | G2: =SUM(G4:G179) -> 1530690.2 | H2: =C2-G2 -> 297256.49 | I2: =IFERROR(H2/G2, 0) -> 0.19419768
A3: Site | B3: State | C3: Actual | D3: Expected | E3: Delta | F3: % | G3: Forecasted | H3: Delta | I3: %
A4: {=Sites[Site]} -> Lexington - Cotting School | B4: {=Sites[State]} -> MA | C4: =SUM(Jan!C4, Feb!C4, Mar!C4) -> 45888.64 | D4: =SUM(Jan!D4, Feb!D4, Mar!D4) -> 0 | E4: =IF(AND(ISNUMBER(C4),ISNUMBER(D4)), C4-D4, "") -> 45888.64 | F4: =IFERROR(E4/D4, "") | G4: =SUM(Jan!G4, Feb!G4, Mar!G4) -> 0 | H4: =SUM(Jan!H4, Feb!H4, Mar!H4) -> 18073.6 | I4: =IFERROR(H4/G4, "")
A5: Pacoima - Whiteman Airport | B5: CA | C5: =SUM(Jan!C5, Feb!C5, Mar!C5) -> 58146 | D5: =SUM(Jan!D5, Feb!D5, Mar!D5) -> 0 | E5: =IF(AND(ISNUMBER(C5),ISNUMBER(D5)), C5-D5, "") -> 58146 | F5: =IFERROR(E5/D5, "") | G5: =SUM(Jan!G5, Feb!G5, Mar!G5) -> 108680 | H5: =SUM(Jan!H5, Feb!H5, Mar!H5) -> -50534 | I5: =IFERROR(H5/G5, "") -> -0.46497976
A6: Hyannis - Sturgis Charter School | B6: MA | C6: =SUM(Jan!C6, Feb!C6, Mar!C6) -> 56832.395 | D6: =SUM(Jan!D6, Feb!D6, Mar!D6) -> 0 | E6: =IF(AND(ISNUMBER(C6),ISNUMBER(D6)), C6-D6, "") -> 56832.395 | F6: =IFERROR(E6/D6, "") | G6: =SUM(Jan!G6, Feb!G6, Mar!G6) -> 54540 | H6: =SUM(Jan!H6, Feb!H6, Mar!H6) -> 2292.3948 | I6: =IFERROR(H6/G6, "") -> 0.042031441
A7: South Dennis - Tony Kent Arena | B7: MA | C7: =SUM(Jan!C7, Feb!C7, Mar!C7) -> 61513.2 | D7: =SUM(Jan!D7, Feb!D7, Mar!D7) -> 0 | E7: =IF(AND(ISNUMBER(C7),ISNUMBER(D7)), C7-D7, "") -> 61513.2 | F7: =IFERROR(E7/D7, "") | G7: =SUM(Jan!G7, Feb!G7, Mar!G7) -> 0 | H7: =SUM(Jan!H7, Feb!H7, Mar!H7) -> 30999.12 | I7: =IFERROR(H7/G7, "")
A8: Caropolis - Felician Sisters | B8: PA | C8: =SUM(Jan!C8, Feb!C8, Mar!C8) -> 51053.4 | D8: =SUM(Jan!D8, Feb!D8, Mar!D8) -> 0 | E8: =IF(AND(ISNUMBER(C8),ISNUMBER(D8)), C8-D8, "") -> 51053.4 | F8: =IFERROR(E8/D8, "") | G8: =SUM(Jan!G8, Feb!G8, Mar!G8) -> 0 | H8: =SUM(Jan!H8, Feb!H8, Mar!H8) -> 0 | I8: =IFERROR(H8/G8, "")
A9: Clear Lake - Eastlake Gohman | B9: MN | C9: =SUM(Jan!C9, Feb!C9, Mar!C9) -> 174810 | D9: =SUM(Jan!D9, Feb!D9, Mar!D9) -> 0 | E9: =IF(AND(ISNUMBER(C9),ISNUMBER(D9)), C9-D9, "") -> 174810 | F9: =IFERROR(E9/D9, "") | G9: =SUM(Jan!G9, Feb!G9, Mar!G9) -> 155938.5 | H9: =SUM(Jan!H9, Feb!H9, Mar!H9) -> 18871.5 | I9: =IFERROR(H9/G9, "") -> 0.12101886
A10: Zumbrota - Eastlake Brenda Luhman | B10: MN | C10: =SUM(Jan!C10, Feb!C10, Mar!C10) -> 179285.13 | D10: =SUM(Jan!D10, Feb!D10, Mar!D10) -> 0 | E10: =IF(AND(ISNUMBER(C10),ISNUMBER(D10)), C10-D10, "") -> 179285.13 | F10: =IFERROR(E10/D10, "") | G10: =SUM(Jan!G10, Feb!G10, Mar!G10) -> 161850.1 | H10: =SUM(Jan!H10, Feb!H10, Mar!H10) -> 17435.027 | I10: =IFERROR(H10/G10, "") -> 0.1077233
A11: Cokato - Eastlake Carlson | B11: MN | C11: =SUM(Jan!C11, Feb!C11, Mar!C11) -> 147025.48 | D11: =SUM(Jan!D11, Feb!D11, Mar!D11) -> 0 | E11: =IF(AND(ISNUMBER(C11),ISNUMBER(D11)), C11-D11, "") -> 147025.48 | F11: =IFERROR(E11/D11, "") | G11: =SUM(Jan!G11, Feb!G11, Mar!G11) -> 189506 | H11: =SUM(Jan!H11, Feb!H11, Mar!H11) -> -42480.516 | I11: =IFERROR(H11/G11, "") -> -0.22416449
A12: North Branch - Cornille 2 | B12: MN | C12: =SUM(Jan!C12, Feb!C12, Mar!C12) -> 142625 | D12: =SUM(Jan!D12, Feb!D12, Mar!D12) -> 0 | E12: =IF(AND(ISNUMBER(C12),ISNUMBER(D12)), C12-D12, "") -> 142625 | F12: =IFERROR(E12/D12, "") | G12: =SUM(Jan!G12, Feb!G12, Mar!G12) -> 156749.8 | H12: =SUM(Jan!H12, Feb!H12, Mar!H12) -> -14124.8 | I12: =IFERROR(H12/G12, "") -> -0.090110482
A13: Clear Lake - Eastlake Hammer | B13: MN | C13: =SUM(Jan!C13, Feb!C13, Mar!C13) -> 196603.03 | D13: =SUM(Jan!D13, Feb!D13, Mar!D13) -> 0 | E13: =IF(AND(ISNUMBER(C13),ISNUMBER(D13)), C13-D13, "") -> 196603.03 | F13: =IFERROR(E13/D13, "") | G13: =SUM(Jan!G13, Feb!G13, Mar!G13) -> 181153.8 | H13: =SUM(Jan!H13, Feb!H13, Mar!H13) -> 15449.233 | I13: =IFERROR(H13/G13, "") -> 0.085282409
A14: Eastlake - Hertzberg CSG 1 | B14: MN | C14: =SUM(Jan!C14, Feb!C14, Mar!C14) -> 178773.26 | D14: =SUM(Jan!D14, Feb!D14, Mar!D14) -> 0 | E14: =IF(AND(ISNUMBER(C14),ISNUMBER(D14)), C14-D14, "") -> 178773.26 | F14: =IFERROR(E14/D14, "") | G14: =SUM(Jan!G14, Feb!G14, Mar!G14) -> 179090.7 | H14: =SUM(Jan!H14, Feb!H14, Mar!H14) -> -317.4356 | I14: =IFERROR(H14/G14, "") -> -0.0017724851
A15: Cokato - Eastlake Laurel Village | B15: MN | C15: =SUM(Jan!C15, Feb!C15, Mar!C15) -> 192745.31 | D15: =SUM(Jan!D15, Feb!D15, Mar!D15) -> 0 | E15: =IF(AND(ISNUMBER(C15),ISNUMBER(D15)), C15-D15, "") -> 192745.31 | F15: =IFERROR(E15/D15, "") | G15: =SUM(Jan!G15, Feb!G15, Mar!G15) -> 177944.7 | H15: =SUM(Jan!H15, Feb!H15, Mar!H15) -> 14800.614 | I15: =IFERROR(H15/G15, "") -> 0.083175357
A16: St. Peter - Eastlake Paulson | B16: MN | C16: =SUM(Jan!C16, Feb!C16, Mar!C16) -> 167620.93 | D16: =SUM(Jan!D16, Feb!D16, Mar!D16) -> 0 | E16: =IF(AND(ISNUMBER(C16),ISNUMBER(D16)), C16-D16, "") -> 167620.93 | F16: =IFERROR(E16/D16, "") | G16: =SUM(Jan!G16, Feb!G16, Mar!G16) -> 165236.6 | H16: =SUM(Jan!H16, Feb!H16, Mar!H16) -> 2384.3295 | I16: =IFERROR(H16/G16, "") -> 0.01442979
... A75: CA: Stockton - SUSD - Peyton | B75: CA | C75: =SUM(Jan!C75, Feb!C75, Mar!C75) -> 0 | D75: =SUM(Jan!D75, Feb!D75, Mar!D75) -> 0 | E75: =IF(AND(ISNUMBER(C75),ISNUMBER(D75)), C75-D75, "") -> 0 | F75: =IFERROR(E75/D75, "") | G75: =SUM(Jan!G75, Feb!G75, Mar!G75) -> 0 | H75: =SUM(Jan!H75, Feb!H75, Mar!H75) -> 0 | I75: =IFERROR(H75/G75, "")
A76: TX: Barnhart - 42917 Ranch RD 2469 | B76: TX
A77: AZ: San Manuel - Senior & Junior HS | B77: AZ
A78: AZ: Sierra Vista - Colonel Smith MS | B78: AZ
A79: AZ: Sierra Vista - Colonel Johnston ES | B79: AZ
A80: NH: Dover - Dover HS | B80: NH
A81: MA: Somerville - 30 Inner Belt Rd | B81: MA
A82: MA: Boxborough - 1414 Massachusetts Ave | B82: MA
A83: NY: Amsterdam - 153 NY Route 67 | B83: NY
A84: CA: San Jose - GE Mobile Water | B84: CA
A85: NY: Rome - 7776 Tannery RD | B85: NY

Sheet 2nd Qtr
A1: {=portfolio} -> Clean Capital | D1: 2nd Quarter Actual v. Expected | G1: 2nd Quarter Actual v. Forecasted
A2: Total | C2: =SUM(C4:C179) -> 8113968.2 | D2: =SUM(D4:D179) -> 3491701.9 | E2: =C2-D2 -> 4622266.2 | F2: =IFERROR(E2/D2, 0) -> 1.323786 | G2: =SUM(G4:G179) -> 9641237.5 | H2: =C2-G2 -> -1527269.3 | I2: =IFERROR(H2/G2, 0) -> -0.15841009
A3: Site | B3: State | C3: Actual | D3: Expected | E3: Delta | F3: % | G3: Forecasted | H3: Delta | I3: %
A4: {=Sites[Site]} -> Lexington - Cotting School | B4: {=Sites[State]} -> MA | C4: =SUM(Apr!C4, May!C4, Jun!C4) -> 79912.248 | D4: =SUM(Apr!D4, May!D4, Jun!D4) -> 0 | E4: =IF(AND(ISNUMBER(C4),ISNUMBER(D4)), C4-D4, "") -> 79912.248 | F4: =IFERROR(E4/D4, "") | G4: =SUM(Apr!G4,May!G4,Jun!G4) -> 0 | H4: =SUM(Apr!H4, May!H4, Jun!H4) -> 0 | I4: =IFERROR(H4/G4, "")
A5: Pacoima - Whiteman Airport | B5: CA | C5: =SUM(Apr!C5, May!C5, Jun!C5) -> 74866.5 | D5: =SUM(Apr!D5, May!D5, Jun!D5) -> 0 | E5: =IF(AND(ISNUMBER(C5),ISNUMBER(D5)), C5-D5, "") -> 74866.5 | F5: =IFERROR(E5/D5, "") | G5: =SUM(Apr!G5,May!G5,Jun!G5) -> 124728.7 | H5: =SUM(Apr!H5, May!H5, Jun!H5) -> -49862.2 | I5: =IFERROR(H5/G5, "") -> -0.39976525
A6: Hyannis - Sturgis Charter School | B6: MA | C6: =SUM(Apr!C6, May!C6, Jun!C6) -> 104886.55 | D6: =SUM(Apr!D6, May!D6, Jun!D6) -> 0 | E6: =IF(AND(ISNUMBER(C6),ISNUMBER(D6)), C6-D6, "") -> 104886.55 | F6: =IFERROR(E6/D6, "") | G6: =SUM(Apr!G6,May!G6,Jun!G6) -> 100940 | H6: =SUM(Apr!H6, May!H6, Jun!H6) -> 3946.5505 | I6: =IFERROR(H6/G6, "") -> 0.039097984
A7: South Dennis - Tony Kent Arena | B7: MA | C7: =SUM(Apr!C7, May!C7, Jun!C7) -> 121443.18 | D7: =SUM(Apr!D7, May!D7, Jun!D7) -> 0 | E7: =IF(AND(ISNUMBER(C7),ISNUMBER(D7)), C7-D7, "") -> 121443.18 | F7: =IFERROR(E7/D7, "") | G7: =SUM(Apr!G7,May!G7,Jun!G7) -> 0 | H7: =SUM(Apr!H7, May!H7, Jun!H7) -> 0 | I7: =IFERROR(H7/G7, "")
A8: Caropolis - Felician Sisters | B8: PA | C8: =SUM(Apr!C8, May!C8, Jun!C8) -> 176632.5 | D8: =SUM(Apr!D8, May!D8, Jun!D8) -> 0 | E8: =IF(AND(ISNUMBER(C8),ISNUMBER(D8)), C8-D8, "") -> 176632.5 | F8: =IFERROR(E8/D8, "") | G8: =SUM(Apr!G8,May!G8,Jun!G8) -> 0 | H8: =SUM(Apr!H8, May!H8, Jun!H8) -> 0 | I8: =IFERROR(H8/G8, "")
A9: Clear Lake - Eastlake Gohman | B9: MN | C9: =SUM(Apr!C9, May!C9, Jun!C9) -> 526656 | D9: =SUM(Apr!D9, May!D9, Jun!D9) -> 0 | E9: =IF(AND(ISNUMBER(C9),ISNUMBER(D9)), C9-D9, "") -> 526656 | F9: =IFERROR(E9/D9, "") | G9: =SUM(Apr!G9+May!G9+Jun!G9) -> 570311.4 | H9: =SUM(Apr!H9, May!H9, Jun!H9) -> -43655.4 | I9: =IFERROR(H9/G9, "") -> -0.076546602
A10: Zumbrota - Eastlake Brenda Luhman | B10: MN | C10: =SUM(Apr!C10, May!C10, Jun!C10) -> 552019 | D10: =SUM(Apr!D10, May!D10, Jun!D10) -> 0 | E10: =IF(AND(ISNUMBER(C10),ISNUMBER(D10)), C10-D10, "") -> 552019 | F10: =IFERROR(E10/D10, "") | G10: =SUM(Apr!G10+May!G10+Jun!G10) -> 567651 | H10: =SUM(Apr!H10, May!H10, Jun!H10) -> -15632 | I10: =IFERROR(H10/G10, "") -> -0.027538047
A11: Cokato - Eastlake Carlson | B11: MN | C11: =SUM(Apr!C11, May!C11, Jun!C11) -> 502584 | D11: =SUM(Apr!D11, May!D11, Jun!D11) -> 0 | E11: =IF(AND(ISNUMBER(C11),ISNUMBER(D11)), C11-D11, "") -> 502584 | F11: =IFERROR(E11/D11, "") | G11: =SUM(Apr!G11+May!G11+Jun!G11) -> 605960.3 | H11: =SUM(Apr!H11, May!H11, Jun!H11) -> -103376.3 | I11: =IFERROR(H11/G11, "") -> -0.17059913
A12: North Branch - Cornille 2 | B12: MN | C12: =SUM(Apr!C12, May!C12, Jun!C12) -> 490309 | D12: =SUM(Apr!D12, May!D12, Jun!D12) -> 0 | E12: =IF(AND(ISNUMBER(C12),ISNUMBER(D12)), C12-D12, "") -> 490309 | F12: =IFERROR(E12/D12, "") | G12: =SUM(Apr!G12+May!G12+Jun!G12) -> 590753.3 | H12: =SUM(Apr!H12, May!H12, Jun!H12) -> -100444.3 | I12: =IFERROR(H12/G12, "") -> -0.17002749
A13: Clear Lake - Eastlake Hammer | B13: MN | C13: =SUM(Apr!C13, May!C13, Jun!C13) -> 637280.97 | D13: =SUM(Apr!D13, May!D13, Jun!D13) -> 0 | E13: =IF(AND(ISNUMBER(C13),ISNUMBER(D13)), C13-D13, "") -> 637280.97 | F13: =IFERROR(E13/D13, "") | G13: =SUM(Apr!G13+May!G13+Jun!G13) -> 714867.6 | H13: =SUM(Apr!H13, May!H13, Jun!H13) -> -77586.633 | I13: =IFERROR(H13/G13, "") -> -0.10853287
A14: Eastlake - Hertzberg CSG 1 | B14: MN | C14: =SUM(Apr!C14, May!C14, Jun!C14) -> 645017.74 | D14: =SUM(Apr!D14, May!D14, Jun!D14) -> 0 | E14: =IF(AND(ISNUMBER(C14),ISNUMBER(D14)), C14-D14, "") -> 645017.74 | F14: =IFERROR(E14/D14, "") | G14: =SUM(Apr!G14+May!G14+Jun!G14) -> 715062.31 | H14: =SUM(Apr!H14, May!H14, Jun!H14) -> -70044.57 | I14: =IFERROR(H14/G14, "") -> -0.097955898
A15: Cokato - Eastlake Laurel Village | B15: MN | C15: =SUM(Apr!C15, May!C15, Jun!C15) -> 659571 | D15: =SUM(Apr!D15, May!D15, Jun!D15) -> 0 | E15: =IF(AND(ISNUMBER(C15),ISNUMBER(D15)), C15-D15, "") -> 659571 | F15: =IFERROR(E15/D15, "") | G15: =SUM(Apr!G15+May!G15+Jun!G15) -> 748373 | H15: =SUM(Apr!H15, May!H15, Jun!H15) -> -88802 | I15: =IFERROR(H15/G15, "") -> -0.11866008
A16: St. Peter - Eastlake Paulson | B16: MN | C16: =SUM(Apr!C16, May!C16, Jun!C16) -> 545011.03 | D16: =SUM(Apr!D16, May!D16, Jun!D16) -> 0 | E16: =IF(AND(ISNUMBER(C16),ISNUMBER(D16)), C16-D16, "") -> 545011.03 | F16: =IFERROR(E16/D16, "") | G16: =SUM(Apr!G16+May!G16+Jun!G16) -> 610393.6 | H16: =SUM(Apr!H16, May!H16, Jun!H16) -> -65382.566 | I16: =IFERROR(H16/G16, "") -> -0.10711542
A17: Felician Sisters Convent | B17: NJ | C17: =SUM(Apr!C17, May!C17, Jun!C17) -> 53857.6 | D17: =SUM(Apr!D17, May!D17, Jun!D17) -> 0 | E17: =IF(AND(ISNUMBER(C17),ISNUMBER(D17)), C17-D17, "") -> 53857.6 | F17: =IFERROR(E17/D17, "") | G17: =SUM(Apr!G17,May!G17,Jun!G17) -> 0 | H17: =SUM(Apr!H17, May!H17, Jun!H17) -> 0 | I17: =IFERROR(H17/G17, "")
A18: Sussex County Fairgrounds | B18: NJ | C18: =SUM(Apr!C18, May!C18, Jun!C18) -> 124570.36 | D18: =SUM(Apr!D18, May!D18, Jun!D18) -> 0 | E18: =IF(AND(ISNUMBER(C18),ISNUMBER(D18)), C18-D18, "") -> 124570.36 | F18: =IFERROR(E18/D18, "") | G18: =SUM(Apr!G18,May!G18,Jun!G18) -> 0 | H18: =SUM(Apr!H18, May!H18, Jun!H18) -> 0 | I18: =IFERROR(H18/G18, "")
A19: Gateway Church | B19: NJ | C19: =SUM(Apr!C19, May!C19, Jun!C19) -> 81953 | D19: =SUM(Apr!D19, May!D19, Jun!D19) -> 0 | E19: =IF(AND(ISNUMBER(C19),ISNUMBER(D19)), C19-D19, "") -> 81953 | F19: =IFERROR(E19/D19, "") | G19: =SUM(Apr!G19,May!G19,Jun!G19) -> 0 | H19: =SUM(Apr!H19, May!H19, Jun!H19) -> 0 | I19: =IFERROR(H19/G19, "")
A20: Beaver Falls - Felician Sisters | B20: PA | C20: =SUM(Apr!C20, May!C20, Jun!C20) -> 123444 | D20: =SUM(Apr!D20, May!D20, Jun!D20) -> 0 | E20: =IF(AND(ISNUMBER(C20),ISNUMBER(D20)), C20-D20, "") -> 123444 | F20: =IFERROR(E20/D20, "") | G20: =SUM(Apr!G20,May!G20,Jun!G20) -> 0 | H20: =SUM(Apr!H20, May!H20, Jun!H20) -> 0 | I20: =IFERROR(H20/G20, "")
A21: Livonia - Felician Sisters Ground | B21: MI | C21: =SUM(Apr!C21, May!C21, Jun!C21) -> 0 | D21: =SUM(Apr!D21, May!D21, Jun!D21) -> 0 | E21: =IF(AND(ISNUMBER(C21),ISNUMBER(D21)), C21-D21, "") -> 0 | F21: =IFERROR(E21/D21, "") | G21: =SUM(Apr!G21,May!G21,Jun!G21) -> 0 | H21: =SUM(Apr!H21, May!H21, Jun!H21) -> 0 | I21: =IFERROR(H21/G21, "")
A22: Livonia - Felician Sisters Roof | B22: MI | C22: =SUM(Apr!C22, May!C22, Jun!C22) -> 50116 | D22: =SUM(Apr!D22, May!D22, Jun!D22) -> 0 | E22: =IF(AND(ISNUMBER(C22),ISNUMBER(D22)), C22-D22, "") -> 50116 | F22: =IFERROR(E22/D22, "") | G22: =SUM(Apr!G22,May!G22,Jun!G22) -> 0 | H22: =SUM(Apr!H22, May!H22, Jun!H22) -> 0 | I22: =IFERROR(H22/G22, "")
A23: Monmouth Worship Ctr | B23: NJ | C23: =SUM(Apr!C23, May!C23, Jun!C23) -> 35553.98 | D23: =SUM(Apr!D23, May!D23, Jun!D23) -> 0 | E23: =IF(AND(ISNUMBER(C23),ISNUMBER(D23)), C23-D23, "") -> 35553.98 | F23: =IFERROR(E23/D23, "") | G23: =SUM(Apr!G23,May!G23,Jun!G23) -> 0 | H23: =SUM(Apr!H23, May!H23, Jun!H23) -> 0 | I23: =IFERROR(H23/G23, "")
A24: Audubon - Senior Citizens United | B24: NJ | C24: =SUM(Apr!C24, May!C24, Jun!C24) -> 26707.475 | D24: =SUM(Apr!D24, May!D24, Jun!D24) -> 0 | E24: =IF(AND(ISNUMBER(C24),ISNUMBER(D24)), C24-D24, "") -> 26707.475 | F24: =IFERROR(E24/D24, "") | G24: =SUM(Apr!G24,May!G24,Jun!G24) -> 0 | H24: =SUM(Apr!H24, May!H24, Jun!H24) -> 0 | I24: =IFERROR(H24/G24, "")
A25: Hollister - PG&E (Enerparc) | B25: CA | C25: =SUM(Apr!C25, May!C25, Jun!C25) -> 0 | D25: =SUM(Apr!D25, May!D25, Jun!D25) -> 0 | E25: =IF(AND(ISNUMBER(C25),ISNUMBER(D25)), C25-D25, "") -> 0 | F25: =IFERROR(E25/D25, "") | G25: =SUM(Apr!G25,May!G25,Jun!G25) -> 759371.6 | H25: =SUM(Apr!H25, May!H25, Jun!H25) -> -759371.6 | I25: =IFERROR(H25/G25, "") -> -1
A26: Taos County - Kit Carson Electric Co-Op | B26: NM | C26: =SUM(Apr!C26, May!C26, Jun!C26) -> 432600 | D26: =SUM(Apr!D26, May!D26, Jun!D26) -> 508266.5 | E26: =IF(AND(ISNUMBER(C26),ISNUMBER(D26)), C26-D26, "") -> -75666.5 | F26: =IFERROR(E26/D26, "") -> -0.1488717 | G26: =SUM(Apr!G26,May!G26,Jun!G26) -> 448501.1 | H26: =SUM(Apr!H26, May!H26, Jun!H26) -> -15901.1 | I26: =IFERROR(H26/G26, "") -> -0.035453871
A27: Commerce City - Adams City HS | B27: CO | C27: =SUM(Apr!C27, May!C27, Jun!C27) -> 33504 | D27: =SUM(Apr!D27, May!D27, Jun!D27) -> 27090.29 | E27: =IF(AND(ISNUMBER(C27),ISNUMBER(D27)), C27-D27, "") -> 6413.71 | F27: =IFERROR(E27/D27, "") -> 0.23675309 | G27: =SUM(Apr!G27,May!G27,Jun!G27) -> 30650.47 | H27: =SUM(Apr!H27, May!H27, Jun!H27) -> 2853.53 | I27: =IFERROR(H27/G27, "") -> 0.093099062
A28: Commerce City - Adams City MS | B28: CO | C28: =SUM(Apr!C28, May!C28, Jun!C28) -> 27929 | D28: =SUM(Apr!D28, May!D28, Jun!D28) -> 24607.63 | E28: =IF(AND(ISNUMBER(C28),ISNUMBER(D28)), C28-D28, "") -> 3321.37 | F28: =IFERROR(E28/D28, "") -> 0.13497318 | G28: =SUM(Apr!G28,May!G28,Jun!G28) -> 26962.44 | H28: =SUM(Apr!H28, May!H28, Jun!H28) -> 966.56 | I28: =IFERROR(H28/G28, "") -> 0.035848388
... A75: CA: Stockton - SUSD - Peyton | B75: CA | C75: =SUM(Apr!C75, May!C75, Jun!C75) -> 50091 | D75: =SUM(Apr!D75, May!D75, Jun!D75) -> 56827.77 | E75: =IF(AND(ISNUMBER(C75),ISNUMBER(D75)), C75-D75, "") -> -6736.77 | F75: =IFERROR(E75/D75, "") -> -0.11854715 | G75: =SUM(Apr!G75,May!G75,Jun!G75) -> 55927.75 | H75: =SUM(Apr!H75, May!H75, Jun!H75) -> -5836.75 | I75: =IFERROR(H75/G75, "") -> -0.10436232
A76: TX: Barnhart - 42917 Ranch RD 2469 | B76: TX
A77: AZ: San Manuel - Senior & Junior HS | B77: AZ
A78: AZ: Sierra Vista - Colonel Smith MS | B78: AZ
A79: AZ: Sierra Vista - Colonel Johnston ES | B79: AZ
A80: NH: Dover - Dover HS | B80: NH
A81: MA: Somerville - 30 Inner Belt Rd | B81: MA
A82: MA: Boxborough - 1414 Massachusetts Ave | B82: MA
A83: NY: Amsterdam - 153 NY Route 67 | B83: NY
A84: CA: San Jose - GE Mobile Water | B84: CA
A85: NY: Rome - 7776 Tannery RD | B85: NY

Sheet 3rd Qtr
A1: {=portfolio} -> Clean Capital | D1: 3rd Quarter Actual v. Expected | G1: 3rd Quarter Actual v. Forecasted
A2: Total | C2: =SUM(C4:C179) -> 17176529 | D2: =SUM(D4:D179) -> 11534670 | E2: =C2-D2 -> 5641859 | F2: =IFERROR(E2/D2, 0) -> 0.48912183 | G2: =SUM(G4:G179) -> 19588978 | H2: =C2-G2 -> -2412449.2 | I2: =IFERROR(H2/G2, 0) -> -0.1231534
A3: Site | B3: State | C3: Actual | D3: Expected | E3: Delta | F3: % | G3: Forecasted | H3: Delta | I3: %
A4: {=Sites[Site]} -> Lexington - Cotting School | B4: {=Sites[State]} -> MA | C4: =SUM(Jul!C4, Aug!C4, Sep!C4) -> 125988.8 | D4: =SUM(Jul!D4, Aug!D4, Sep!D4) -> 0 | E4: =IF(AND(ISNUMBER(C4),ISNUMBER(D4)), C4-D4, "") -> 125988.8 | F4: =IFERROR(E4/D4, "") | G4: =SUM(Jul!G4,Aug!G4,Sep!G4) -> 0 | H4: =SUM(Jul!H4, Aug!H4, Sep!H4) -> 0 | I4: =IFERROR(H4/G4, "")
A5: Pacoima - Whiteman Airport | B5: CA | C5: =SUM(Jul!C5, Aug!C5, Sep!C5) -> 69837.1 | D5: =SUM(Jul!D5, Aug!D5, Sep!D5) -> 0 | E5: =IF(AND(ISNUMBER(C5),ISNUMBER(D5)), C5-D5, "") -> 69837.1 | F5: =IFERROR(E5/D5, "") | G5: =SUM(Jul!G5,Aug!G5,Sep!G5) -> 134818.9 | H5: =SUM(Jul!H5, Aug!H5, Sep!H5) -> -64981.8 | I5: =IFERROR(H5/G5, "") -> -0.48199325
A6: Hyannis - Sturgis Charter School | B6: MA | C6: =SUM(Jul!C6, Aug!C6, Sep!C6) -> 106190.1 | D6: =SUM(Jul!D6, Aug!D6, Sep!D6) -> 0 | E6: =IF(AND(ISNUMBER(C6),ISNUMBER(D6)), C6-D6, "") -> 106190.1 | F6: =IFERROR(E6/D6, "") | G6: =SUM(Jul!G6,Aug!G6,Sep!G6) -> 97999.08 | H6: =SUM(Jul!H6, Aug!H6, Sep!H6) -> 8191.0151 | I6: =IFERROR(H6/G6, "") -> 0.083582571
A7: South Dennis - Tony Kent Arena | B7: MA | C7: =SUM(Jul!C7, Aug!C7, Sep!C7) -> 120140.6 | D7: =SUM(Jul!D7, Aug!D7, Sep!D7) -> 0 | E7: =IF(AND(ISNUMBER(C7),ISNUMBER(D7)), C7-D7, "") -> 120140.6 | F7: =IFERROR(E7/D7, "") | G7: =SUM(Jul!G7,Aug!G7,Sep!G7) -> 0 | H7: =SUM(Jul!H7, Aug!H7, Sep!H7) -> 0 | I7: =IFERROR(H7/G7, "")
A8: Caropolis - Felician Sisters | B8: PA | C8: =SUM(Jul!C8, Aug!C8, Sep!C8) -> 141425.5 | D8: =SUM(Jul!D8, Aug!D8, Sep!D8) -> 0 | E8: =IF(AND(ISNUMBER(C8),ISNUMBER(D8)), C8-D8, "") -> 141425.5 | F8: =IFERROR(E8/D8, "") | G8: =SUM(Jul!G8,Aug!G8,Sep!G8) -> 0 | H8: =SUM(Jul!H8, Aug!H8, Sep!H8) -> 0 | I8: =IFERROR(H8/G8, "")
A9: Clear Lake - Eastlake Gohman | B9: MN | C9: =SUM(Jul!C9, Aug!C9, Sep!C9) -> 504186.1 | D9: =SUM(Jul!D9, Aug!D9, Sep!D9) -> 0 | E9: =IF(AND(ISNUMBER(C9),ISNUMBER(D9)), C9-D9, "") -> 504186.1 | F9: =IFERROR(E9/D9, "") | G9: =SUM(Jul!G9,Aug!G9,Sep!G9) -> 572348.9 | H9: =SUM(Jul!H9, Aug!H9, Sep!H9) -> -68162.804 | I9: =IFERROR(H9/G9, "") -> -0.1190931
A10: Zumbrota - Eastlake Brenda Luhman | B10: MN | C10: =SUM(Jul!C10, Aug!C10, Sep!C10) -> 575157 | D10: =SUM(Jul!D10, Aug!D10, Sep!D10) -> 0 | E10: =IF(AND(ISNUMBER(C10),ISNUMBER(D10)), C10-D10, "") -> 575157 | F10: =IFERROR(E10/D10, "") | G10: =SUM(Jul!G10,Aug!G10,Sep!G10) -> 556918.5 | H10: =SUM(Jul!H10, Aug!H10, Sep!H10) -> 18238.5 | I10: =IFERROR(H10/G10, "") -> 0.032748957
A11: Cokato - Eastlake Carlson | B11: MN | C11: =SUM(Jul!C11, Aug!C11, Sep!C11) -> 543099 | D11: =SUM(Jul!D11, Aug!D11, Sep!D11) -> 0 | E11: =IF(AND(ISNUMBER(C11),ISNUMBER(D11)), C11-D11, "") -> 543099 | F11: =IFERROR(E11/D11, "") | G11: =SUM(Jul!G11,Aug!G11,Sep!G11) -> 604667.2 | H11: =SUM(Jul!H11, Aug!H11, Sep!H11) -> -61568.2 | I11: =IFERROR(H11/G11, "") -> -0.10182163
A12: North Branch - Cornille 2 | B12: MN | C12: =SUM(Jul!C12, Aug!C12, Sep!C12) -> 563255 | D12: =SUM(Jul!D12, Aug!D12, Sep!D12) -> 0 | E12: =IF(AND(ISNUMBER(C12),ISNUMBER(D12)), C12-D12, "") -> 563255 | F12: =IFERROR(E12/D12, "") | G12: =SUM(Jul!G12,Aug!G12,Sep!G12) -> 570208 | H12: =SUM(Jul!H12, Aug!H12, Sep!H12) -> -6953 | I12: =IFERROR(H12/G12, "") -> -0.012193796
A13: Clear Lake - Eastlake Hammer | B13: MN | C13: =SUM(Jul!C13, Aug!C13, Sep!C13) -> 632010 | D13: =SUM(Jul!D13, Aug!D13, Sep!D13) -> 0 | E13: =IF(AND(ISNUMBER(C13),ISNUMBER(D13)), C13-D13, "") -> 632010 | F13: =IFERROR(E13/D13, "") | G13: =SUM(Jul!G13,Aug!G13,Sep!G13) -> 695386.4 | H13: =SUM(Jul!H13, Aug!H13, Sep!H13) -> -63376.4 | I13: =IFERROR(H13/G13, "") -> -0.091138394
A14: Eastlake - Hertzberg CSG 1 | B14: MN | C14: =SUM(Jul!C14, Aug!C14, Sep!C14) -> 535713.77 | D14: =SUM(Jul!D14, Aug!D14, Sep!D14) -> 0 | E14: =IF(AND(ISNUMBER(C14),ISNUMBER(D14)), C14-D14, "") -> 535713.77 | F14: =IFERROR(E14/D14, "") | G14: =SUM(Jul!G14,Aug!G14,Sep!G14) -> 702968.21 | H14: =SUM(Jul!H14, Aug!H14, Sep!H14) -> -167254.44 | I14: =IFERROR(H14/G14, "") -> -0.23792604
A15: Cokato - Eastlake Laurel Village | B15: MN | C15: =SUM(Jul!C15, Aug!C15, Sep!C15) -> 624307.95 | D15: =SUM(Jul!D15, Aug!D15, Sep!D15) -> 0 | E15: =IF(AND(ISNUMBER(C15),ISNUMBER(D15)), C15-D15, "") -> 624307.95 | F15: =IFERROR(E15/D15, "") | G15: =SUM(Jul!G15,Aug!G15,Sep!G15) -> 685835.7 | H15: =SUM(Jul!H15, Aug!H15, Sep!H15) -> -61527.75 | I15: =IFERROR(H15/G15, "") -> -0.089712084
A16: St. Peter - Eastlake Paulson | B16: MN | C16: =SUM(Jul!C16, Aug!C16, Sep!C16) -> 571528.15 | D16: =SUM(Jul!D16, Aug!D16, Sep!D16) -> 0 | E16: =IF(AND(ISNUMBER(C16),ISNUMBER(D16)), C16-D16, "") -> 571528.15 | F16: =IFERROR(E16/D16, "") | G16: =SUM(Jul!G16,Aug!G16,Sep!G16) -> 618414.4 | H16: =SUM(Jul!H16, Aug!H16, Sep!H16) -> -46886.248 | I16: =IFERROR(H16/G16, "") -> -0.075816877
... A85: NY: Rome - 7776 Tannery RD | B85: NY | C85: =SUM(Jul!C85, Aug!C85, Sep!C85) -> 1067992.5 | D85: =SUM(Jul!D85, Aug!D85, Sep!D85) -> 1175527.5 | E85: =IF(AND(ISNUMBER(C85),ISNUMBER(D85)), C85-D85, "") -> -107535 | F85: =IFERROR(E85/D85, "") -> -0.091478084 | G85: =SUM(Jul!G85,Aug!G85,Sep!G85) -> 1159047.7 | H85: =SUM(Jul!H85, Aug!H85, Sep!H85) -> -91055.203 | I85: =IFERROR(H85/G85, "") -> -0.078560359

Sheet 4th Qtr
A1: {=portfolio} -> Clean Capital | D1: 4th Quarter Actual v. Expected | G1: 4th Quarter Actual v. Forecasted
A2: Total | C2: =SUM(C4:C178) -> 4329592.5 | D2: =SUM(D4:D178) -> 3150845.6 | E2: =C2-D2 -> 1178746.9 | F2: =IFERROR(E2/D2, 0) -> 0.37410495 | G2: =SUM(G4:G178) -> 4636831.1 | H2: =C2-G2 -> -307238.54 | I2: =IFERROR(H2/G2, 0) -> -0.066260456
A3: Site | B3: State | C3: Actual | D3: Expected | E3: Delta | F3: % | G3: Forecasted | H3: Delta | I3: %
A4: {=Sites[Site]} -> Lexington - Cotting School | B4: {=Sites[State]} -> MA | C4: =SUM(Oct!C4, Nov!C4, Dec!C4) -> 26318.2 | D4: =SUM(Oct!D4, Nov!D4, Dec!D4) -> 0 | E4: =IF(AND(ISNUMBER(C4),ISNUMBER(D4)), C4-D4, "") -> 26318.2 | F4: =IFERROR(E4/D4, "") | G4: =SUM(Oct!G4,Nov!G4,Dec!G4) -> 0 | H4: =SUM(Oct!H4, Nov!H4, Dec!H4) -> 0 | I4: =IFERROR(H4/G4, "")
A5: Pacoima - Whiteman Airport | B5: CA | C5: =SUM(Oct!C5, Nov!C5, Dec!C5) -> 25774.5 | D5: =SUM(Oct!D5, Nov!D5, Dec!D5) -> 0 | E5: =IF(AND(ISNUMBER(C5),ISNUMBER(D5)), C5-D5, "") -> 25774.5 | F5: =IFERROR(E5/D5, "") | G5: =SUM(Oct!G5,Nov!G5,Dec!G5) -> 40040 | H5: =SUM(Oct!H5, Nov!H5, Dec!H5) -> -14265.5 | I5: =IFERROR(H5/G5, "") -> -0.35628122
A6: Hyannis - Sturgis Charter School | B6: MA | C6: =SUM(Oct!C6, Nov!C6, Dec!C6) -> 20955.604 | D6: =SUM(Oct!D6, Nov!D6, Dec!D6) -> 0 | E6: =IF(AND(ISNUMBER(C6),ISNUMBER(D6)), C6-D6, "") -> 20955.604 | F6: =IFERROR(E6/D6, "") | G6: =SUM(Oct!G6,Nov!G6,Dec!G6) -> 20840 | H6: =SUM(Oct!H6, Nov!H6, Dec!H6) -> 115.60413 | I6: =IFERROR(H6/G6, "") -> 0.0055472231
A7: South Dennis - Tony Kent Arena | B7: MA | C7: =SUM(Oct!C7, Nov!C7, Dec!C7) -> 22120.2 | D7: =SUM(Oct!D7, Nov!D7, Dec!D7) -> 0 | E7: =IF(AND(ISNUMBER(C7),ISNUMBER(D7)), C7-D7, "") -> 22120.2 | F7: =IFERROR(E7/D7, "") | G7: =SUM(Oct!G7,Nov!G7,Dec!G7) -> 0 | H7: =SUM(Oct!H7, Nov!H7, Dec!H7) -> 0 | I7: =IFERROR(H7/G7, "")
A8: Caropolis - Felician Sisters | B8: PA | C8: =SUM(Oct!C8, Nov!C8, Dec!C8) -> 46950.9 | D8: =SUM(Oct!D8, Nov!D8, Dec!D8) -> 0 | E8: =IF(AND(ISNUMBER(C8),ISNUMBER(D8)), C8-D8, "") -> 46950.9 | F8: =IFERROR(E8/D8, "") | G8: =SUM(Oct!G8,Nov!G8,Dec!G8) -> 0 | H8: =SUM(Oct!H8, Nov!H8, Dec!H8) -> 0 | I8: =IFERROR(H8/G8, "")
A9: Clear Lake - Eastlake Gohman | B9: MN | C9: =SUM(Oct!C9, Nov!C9, Dec!C9) -> 123287 | D9: =SUM(Oct!D9, Nov!D9, Dec!D9) -> 0 | E9: =IF(AND(ISNUMBER(C9),ISNUMBER(D9)), C9-D9, "") -> 123287 | F9: =IFERROR(E9/D9, "") | G9: =SUM(Oct!G9,Nov!G9,Dec!G9) -> 156550.8 | H9: =SUM(Oct!H9, Nov!H9, Dec!H9) -> -33263.8 | I9: =IFERROR(H9/G9, "") -> -0.21247927
A10: Zumbrota - Eastlake Brenda Luhman | B10: MN | C10: =SUM(Oct!C10, Nov!C10, Dec!C10) -> 149182 | D10: =SUM(Oct!D10, Nov!D10, Dec!D10) -> 0 | E10: =IF(AND(ISNUMBER(C10),ISNUMBER(D10)), C10-D10, "") -> 149182 | F10: =IFERROR(E10/D10, "") | G10: =SUM(Oct!G10,Nov!G10,Dec!G10) -> 138962.2 | H10: =SUM(Oct!H10, Nov!H10, Dec!H10) -> 10219.8 | I10: =IFERROR(H10/G10, "") -> 0.073543741
A11: Cokato - Eastlake Carlson | B11: MN | C11: =SUM(Oct!C11, Nov!C11, Dec!C11) -> 120234 | D11: =SUM(Oct!D11, Nov!D11, Dec!D11) -> 0 | E11: =IF(AND(ISNUMBER(C11),ISNUMBER(D11)), C11-D11, "") -> 120234 | F11: =IFERROR(E11/D11, "") | G11: =SUM(Oct!G11,Nov!G11,Dec!G11) -> 141771.6 | H11: =SUM(Oct!H11, Nov!H11, Dec!H11) -> -21537.6 | I11: =IFERROR(H11/G11, "") -> -0.15191759
A12: North Branch - Cornille 2 | B12: MN | C12: =SUM(Oct!C12, Nov!C12, Dec!C12) -> 135138 | D12: =SUM(Oct!D12, Nov!D12, Dec!D12) -> 0 | E12: =IF(AND(ISNUMBER(C12),ISNUMBER(D12)), C12-D12, "") -> 135138 | F12: =IFERROR(E12/D12, "") | G12: =SUM(Oct!G12,Nov!G12,Dec!G12) -> 147992.3 | H12: =SUM(Oct!H12, Nov!H12, Dec!H12) -> -12854.3 | I12: =IFERROR(H12/G12, "") -> -0.086857897
A13: Clear Lake - Eastlake Hammer | B13: MN | C13: =SUM(Oct!C13, Nov!C13, Dec!C13) -> 129622 | D13: =SUM(Oct!D13, Nov!D13, Dec!D13) -> 0 | E13: =IF(AND(ISNUMBER(C13),ISNUMBER(D13)), C13-D13, "") -> 129622 | F13: =IFERROR(E13/D13, "") | G13: =SUM(Oct!G13,Nov!G13,Dec!G13) -> 151553.6 | H13: =SUM(Oct!H13, Nov!H13, Dec!H13) -> -21931.6 | I13: =IFERROR(H13/G13, "") -> -0.14471184
A14: Eastlake - Hertzberg CSG 1 | B14: MN | C14: =SUM(Oct!C14, Nov!C14, Dec!C14) -> 112037.23 | D14: =SUM(Oct!D14, Nov!D14, Dec!D14) -> 0 | E14: =IF(AND(ISNUMBER(C14),ISNUMBER(D14)), C14-D14, "") -> 112037.23 | F14: =IFERROR(E14/D14, "") | G14: =SUM(Oct!G14,Nov!G14,Dec!G14) -> 154680.7 | H14: =SUM(Oct!H14, Nov!H14, Dec!H14) -> -42643.475 | I14: =IFERROR(H14/G14, "") -> -0.27568711
A15: Cokato - Eastlake Laurel Village | B15: MN | C15: =SUM(Oct!C15, Nov!C15, Dec!C15) -> 129368.05 | D15: =SUM(Oct!D15, Nov!D15, Dec!D15) -> 0 | E15: =IF(AND(ISNUMBER(C15),ISNUMBER(D15)), C15-D15, "") -> 129368.05 | F15: =IFERROR(E15/D15, "") | G15: =SUM(Oct!G15,Nov!G15,Dec!G15) -> 150906.9 | H15: =SUM(Oct!H15, Nov!H15, Dec!H15) -> -21538.85 | I15: =IFERROR(H15/G15, "") -> -0.14272939
A16: St. Peter - Eastlake Paulson | B16: MN | C16: =SUM(Oct!C16, Nov!C16, Dec!C16) -> 129541.35 | D16: =SUM(Oct!D16, Nov!D16, Dec!D16) -> 0 | E16: =IF(AND(ISNUMBER(C16),ISNUMBER(D16)), C16-D16, "") -> 129541.35 | F16: =IFERROR(E16/D16, "") | G16: =SUM(Oct!G16,Nov!G16,Dec!G16) -> 145203.8 | H16: =SUM(Oct!H16, Nov!H16, Dec!H16) -> -15662.454 | I16: =IFERROR(H16/G16, "") -> -0.10786532
... A85: NY: Rome - 7776 Tannery RD | B85: NY | C85: =SUM(Oct!C85, Nov!C85, Dec!C85) -> 287375.32 | D85: =SUM(Oct!D85, Nov!D85, Dec!D85) -> 307686.2 | E85: =IF(AND(ISNUMBER(C85),ISNUMBER(D85)), C85-D85, "") -> -20310.885 | F85: =IFERROR(E85/D85, "") -> -0.066011685 | G85: =SUM(Oct!G85,Nov!G85,Dec!G85) -> 265023.1 | H85: =SUM(Oct!H85, Nov!H85, Dec!H85) -> 22352.215 | I85: =IFERROR(H85/G85, "") -> 0.084340631

Sheet Jan
A1: {=portfolio} -> Clean Capital | D1: January Actual v. Expected | G1: January Actual v. Forecasted
A2: Total | C2: =SUM(C4:C78) -> 52388.975 | D2: =SUM(D4:D78) -> 0 | E2: =C2-D2 -> 52388.975 | F2: =IFERROR(E2/D2, 0) -> 0 | G2: =SUM(G4:G78) -> 40330 | H2: =C2-G2 -> 12058.975 | I2: =IFERROR(H2/G2, 0) -> 0.29900756 | J2: =IF(AND(TODAY()>DATE(2024, 1, 1), COUNTA(Sites[Site])<>(COUNT(C:C)-1)), "Some sites are missing actual data; if new sites were added, make sure they are aligned correctly (including prior months!)", "") -> Some sites are missing actual data; if new sites were added, make sure they are aligned correctly (including prior months!)
A3: Site | B3: State | C3: Actual | D3: Expected | E3: Delta | F3: % | G3: Forecasted | H3: Delta | I3: % | J3: Notes1 | K3: Service Requests
A4: {=Sites[Site]} -> Lexington - Cotting School | B4: {=Sites[State]} -> MA | C4: 10561.04 | D4: 0 | E4: =IF(AND(ISNUMBER(C4),ISNUMBER(D4)), C4-D4, "") -> 10561.04 | F4: =IFERROR(E4/D4, "") | G4: 0 | H4: =IF(AND(ISNUMBER(C4),ISNUMBER(G4)), C4-G4, "") -> 10561.04 | I4: =IFERROR(H4/G4, "") | J4: 1. Inverter 2 is offline from 01/01 due to several isolation errors. | K4: 1. SR095368
A5: Pacoima - Whiteman Airport | B5: CA | C5: 14475.1 | D5: 0 | E5: =IF(AND(ISNUMBER(C5),ISNUMBER(D5)), C5-D5, "") -> 14475.1 | F5: =IFERROR(E5/D5, "") | G5: 28600 | H5: =IF(AND(ISNUMBER(C5),ISNUMBER(G5)), C5-G5, "") -> -14124.9 | I5: =IFERROR(H5/G5, "") -> -0.49387762 | J5: 1. Inverters D, I, and O were offline due to arc faults, while inverters L and Q had been offline since 12/08/23, and Inverter P had been offline since 06/14/24. On 01/17, a technician visited the site, troubleshot all inverters, and brought them back online except for inverter K, which remained out of service due to a non-functional LED screen. Inverter K has been RMA’d. | K5: 1.SR095501
A6: Hyannis - Sturgis Charter School | B6: MA | C6: 13994.515 | D6: 0 | E6: =IF(AND(ISNUMBER(C6),ISNUMBER(D6)), C6-D6, "") -> 13994.515 | F6: =IFERROR(E6/D6, "") | G6: 11730 | H6: =IF(AND(ISNUMBER(C6),ISNUMBER(G6)), C6-G6, "") -> 2264.515 | I6: =IFERROR(H6/G6, "") -> 0.19305328
A7: South Dennis - Tony Kent Arena | B7: MA | C7: 13358.32 | D7: 0 | E7: =IF(AND(ISNUMBER(C7),ISNUMBER(D7)), C7-D7, "") -> 13358.32 | F7: =IFERROR(E7/D7, "") | G7: 0 | H7: =IF(AND(ISNUMBER(C7),ISNUMBER(G7)), C7-G7, "") -> 13358.32 | I7: =IFERROR(H7/G7, "") | J7: 1. Site started derated at 12:30pm and later was offline at 15:00 on 01/29 through out the month. | K7: 1.SR096179
A8: Caropolis - Felician Sisters | B8: PA
A9: Clear Lake - Eastlake Gohman | B9: MN
A10: Zumbrota - Eastlake Brenda Luhman | B10: MN
A11: Cokato - Eastlake Carlson | B11: MN
A12: North Branch - Cornille 2 | B12: MN
A13: Clear Lake - Eastlake Hammer | B13: MN
A14: Eastlake - Hertzberg CSG 1 | B14: MN
A15: Cokato - Eastlake Laurel Village | B15: MN
A16: St. Peter - Eastlake Paulson | B16: MN
A17: Felician Sisters Convent | B17: NJ
A18: Sussex County Fairgrounds | B18: NJ
A19: Gateway Church | B19: NJ
... A85: NY: Rome - 7776 Tannery RD | B85: NY

Sheet Feb
A1: {=portfolio} -> Clean Capital | D1: February Actual v. Expected | G1: February Actual v. Forecasted
A2: Total | C2: =SUM(C4:C80) -> 65342.146 | D2: =SUM(D4:D80) -> 0 | E2: =C2-D2 -> 65342.146 | F2: =IFERROR(E2/D2, 0) -> 0 | G2: =SUM(G4:G80) -> 50120 | H2: =C2-G2 -> 15222.146 | I2: =IFERROR(H2/G2, 0) -> 0.303714 | J2: =IF(AND(TODAY()>DATE(2024, 2, 1), COUNTA(Sites[Site])<>(COUNT(C:C)-1)), "Some sites are missing actual data; if new sites were added, make sure they are aligned correctly (including prior months!)", "") -> Some sites are missing actual data; if new sites were added, make sure they are aligned correctly (including prior months!)
A3: Site | B3: State | C3: Actual | D3: Expected | E3: Delta | F3: % | G3: Forecasted | H3: Delta | I3: % | K3: Service Requests
A4: {=Sites[Site]} -> Lexington - Cotting School | B4: {=Sites[State]} -> MA | C4: 7512.56 | D4: 0 | E4: =IF(AND(ISNUMBER(C4),ISNUMBER(D4)), C4-D4, "") -> 7512.56 | F4: =IFERROR(E4/D4, "") | G4: 0 | H4: =IF(AND(ISNUMBER(C4),ISNUMBER(G4)), C4-G4, "") -> 7512.56 | I4: =IFERROR(H4/G4, "") | J4: 1. Inverter 2 is offline from 01/01 due to several isolation errors. 2. Inverter 1 tripped offline since 02/25 due to insulation faults. | K4: 1.SR095368 2.SR097850 | L4: SR097850
A5: Pacoima - Whiteman Airport | B5: CA | C5: 23461.7 | D5: 0 | E5: =IF(AND(ISNUMBER(C5),ISNUMBER(D5)), C5-D5, "") -> 23461.7 | F5: =IFERROR(E5/D5, "") | G5: 34320 | H5: =IF(AND(ISNUMBER(C5),ISNUMBER(G5)), C5-G5, "") -> -10858.3 | I5: =IFERROR(H5/G5, "") -> -0.31638403 | J5: 1.Inverters L, N, P, and Q were offline, and Inverter I was reporting an ARC fault. On 02/20 upon the technician's arrival, it was found that Inverters L, P, and Q were offline, Inverter I was offline and reporting an ARC fault, while Inverter N was also reporting an ARC fault. The fault was cleared, and the inverters L, Q, I and N was power-cycled and they are back online. But Inverters N and P are out of warranty required additional troubleshoot. 2.Inverter K has been RMA’d, On 02/04, the technician brought Inverter K back online by updating its software. | K5: 1.SR096409, SR097783 2.SR095501 | L5: SR097783 | M5: SR095501
A6: Hyannis - Sturgis Charter School | B6: MA | C6: 16727.086 | D6: 0 | E6: =IF(AND(ISNUMBER(C6),ISNUMBER(D6)), C6-D6, "") -> 16727.086 | F6: =IFERROR(E6/D6, "") | G6: 15800 | H6: =IF(AND(ISNUMBER(C6),ISNUMBER(G6)), C6-G6, "") -> 927.08582 | I6: =IFERROR(H6/G6, "") -> 0.058676317
A7: South Dennis - Tony Kent Arena | B7: MA | C7: 17640.8 | D7: 0 | E7: =IF(AND(ISNUMBER(C7),ISNUMBER(D7)), C7-D7, "") -> 17640.8 | F7: =IFERROR(E7/D7, "") | G7: 0 | H7: =IF(AND(ISNUMBER(C7),ISNUMBER(G7)), C7-G7, "") -> 17640.8 | I7: =IFERROR(H7/G7, "") | J7: 1.The site has been offline since 01/29. On 02/03, upon the technician's arrival, it was found that DC strings CB1, string 10, and CB6, string 7, each had no open-circuit string voltage, even without the fuse. After isolating these strings, the inverter was re-energized, and the site was brought back online at 02:45 PM on 02/03. | K7: 1.SR096179, SR096262 | L7: SR096262
A8: Caropolis - Felician Sisters | B8: PA
A9: Clear Lake - Eastlake Gohman | B9: MN
A10: Zumbrota - Eastlake Brenda Luhman | B10: MN
A11: Cokato - Eastlake Carlson | B11: MN
A12: North Branch - Cornille 2 | B12: MN
A13: Clear Lake - Eastlake Hammer | B13: MN
A14: Eastlake - Hertzberg CSG 1 | B14: MN
A15: Cokato - Eastlake Laurel Village | B15: MN
A16: St. Peter - Eastlake Paulson | B16: MN
A17: Felician Sisters Convent | B17: NJ
A18: Sussex County Fairgrounds | B18: NJ
A19: Gateway Church | B19: NJ
... A85: NY: Rome - 7776 Tannery RD | B85: NY

Sheet Mar
A1: {=portfolio} -> Clean Capital | D1: March Actual v. Expected | G1: March Actual v. Forecasted
A2: Total | C2: =SUM(C4:C85) -> 1710215.6 | D2: =SUM(D4:D85) -> 0 | E2: =C2-D2 -> 1710215.6 | F2: =IFERROR(E2/D2, 0) -> 0 | G2: =SUM(G4:G85) -> 1440240.2 | H2: =C2-G2 -> 269975.37 | I2: =IFERROR(H2/G2, 0) -> 0.18745162 | J2: =IF(AND(TODAY()>DATE(2024, 3, 1), COUNTA(Sites[Site])<>(COUNT(C:C)-1)), "Some sites are missing actual data; if new sites were added, make sure they are aligned correctly (including prior months!)", "") -> Some sites are missing actual data; if new sites were added, make sure they are aligned correctly (including prior months!)
A3: Site | B3: State | C3: Actual | D3: Expected | E3: Delta | F3: % | G3: Forecasted | H3: Delta | I3: % | J3: Notes | K3: Service Requests
A4: {=Sites[Site]} -> Lexington - Cotting School | B4: {=Sites[State]} -> MA | C4: 27815.04 | D4: N/A | E4: =IF(AND(ISNUMBER(C4),ISNUMBER(D4)), C4-D4, "") | F4: =IFERROR(E4/D4, "") | G4: N/A | H4: =IF(AND(ISNUMBER(C4),ISNUMBER(G4)), C4-G4, "") | I4: =IFERROR(H4/G4, "") | J4: 1. Inverter 2 is offline from 01/01 due to several isolation errors. 2. Inverter 1 tripped offline on 02/25 due to insulation faults and came back online at 02:35 on 03/01. It has also gone offline multiple times throughout the month. | K4: 1.SR095368 2.SR097850 | L4: SR097850
A5: Pacoima - Whiteman Airport | B5: CA | C5: 20209.2 | D5: N/A | E5: =IF(AND(ISNUMBER(C5),ISNUMBER(D5)), C5-D5, "") | F5: =IFERROR(E5/D5, "") | G5: 45760 | H5: =IF(AND(ISNUMBER(C5),ISNUMBER(G5)), C5-G5, "") -> -25550.8 | I5: =IFERROR(H5/G5, "") -> -0.55836538 | J5: 1.Inverter L tripped offline due to Arc fault detected from 09:50AM on 03/02 through out the month. 2.Inverter I tripped offline due to an arc fault from 17:10 on 03/09 through out the month. 3.Site was offline between 9AM to 10:30Am on 03/07 due to grid fault. Again site was offline from 15:30 to 15:40 on 03/19 due to Grid undervoltage. 4.Inverter P was offline and Inverter N was offline and lost communication on multiple days through out the month. Inverters N and P require manufacturer diagnostics, but their warranties have expired—repair and shipping costs not covered. Client is considering replacing AE inverters with another brand and is seeking recommendations. | K5: 1.SR097975 2.SR097975 3.SR098262 & SR098783 4.SR097783 & SR098428 | L5: SR097975 | M5: SR098262 | N5: SR098783 | O5: SR097783 | P5: SR098428
A6: Hyannis - Sturgis Charter School | B6: MA | C6: 26110.794 | D6: N/A | E6: =IF(AND(ISNUMBER(C6),ISNUMBER(D6)), C6-D6, "") | F6: =IFERROR(E6/D6, "") | G6: 27010 | H6: =IF(AND(ISNUMBER(C6),ISNUMBER(G6)), C6-G6, "") -> -899.20606 | I6: =IFERROR(H6/G6, "") -> -0.033291598
A7: South Dennis - Tony Kent Arena | B7: MA | C7: 30514.08 | D7: N/A | E7: =IF(AND(ISNUMBER(C7),ISNUMBER(D7)), C7-D7, "") | F7: =IFERROR(E7/D7, "") | G7: N/A | H7: =IF(AND(ISNUMBER(C7),ISNUMBER(G7)), C7-G7, "") | I7: =IFERROR(H7/G7, "") | J7: 1. The inverter was tripping on and off. Upon the technician's arrival, it was found that DC strings—CB1 String 10 and CB6 String 7—had no open-circuit voltage and a broken module, even with the fuses removed. After isolating these strings, the inverter was re-energized, and the affected modules are currently pending replacement. | K7: 1. SR096262, SR099066 | L7: SR099066
A8: Caropolis - Felician Sisters | B8: PA | C8: 51053.4 | D8: N/A | E8: =IF(AND(ISNUMBER(C8),ISNUMBER(D8)), C8-D8, "") | F8: =IFERROR(E8/D8, "") | H8: =IF(AND(ISNUMBER(C8),ISNUMBER(G8)), C8-G8, "") | I8: =IFERROR(H8/G8, "") | J8: 1. Inverter 13 is underperforming by approximately 10 kW compared to its peers. | K8: 1. SR098870
A9: Clear Lake - Eastlake Gohman | B9: MN | C9: 174810 | D9: N/A | E9: =IF(AND(ISNUMBER(C9),ISNUMBER(D9)), C9-D9, "") | F9: =IFERROR(E9/D9, "") | G9: 155938.5 | H9: =IF(AND(ISNUMBER(C9),ISNUMBER(G9)), C9-G9, "") -> 18871.5 | I9: =IFERROR(H9/G9, "") -> 0.12101886
A10: Zumbrota - Eastlake Brenda Luhman | B10: MN | C10: 179285.13 | D10: N/A | E10: =IF(AND(ISNUMBER(C10),ISNUMBER(D10)), C10-D10, "") | F10: =IFERROR(E10/D10, "") | G10: 161850.1 | H10: =IF(AND(ISNUMBER(C10),ISNUMBER(G10)), C10-G10, "") -> 17435.027 | I10: =IFERROR(H10/G10, "") -> 0.1077233
A11: Cokato - Eastlake Carlson | B11: MN | C11: 147025.48 | D11: N/A | E11: =IF(AND(ISNUMBER(C11),ISNUMBER(D11)), C11-D11, "") | F11: =IFERROR(E11/D11, "") | G11: 189506 | H11: =IF(AND(ISNUMBER(C11),ISNUMBER(G11)), C11-G11, "") -> -42480.516 | I11: =IFERROR(H11/G11, "") -> -0.22416449 | J11: 1.Site has not started for the production on 03/13, technician found that the SEL realy was opened and later closed the relay the site was back online at 16:20 on 03/13. 2. Site was offline on 03/15 due to heavy stroms later technician was able to close the relay on 03/17 at 14:15. | K11: 1.SR098497 2.SR098613 | L11: SR098613
A12: North Branch - Cornille 2 | B12: MN | C12: 142625 | D12: N/A | E12: =IF(AND(ISNUMBER(C12),ISNUMBER(D12)), C12-D12, "") | F12: =IFERROR(E12/D12, "") | G12: 156749.8 | H12: =IF(AND(ISNUMBER(C12),ISNUMBER(G12)), C12-G12, "") -> -14124.8 | I12: =IFERROR(H12/G12, "") -> -0.090110482 | J12: 1.Inverter 6 is down a string from 07/30/24. 2.Site has not started for the production on 03/13, technician found that the SEL realy was opened and later closed the relay the site was back online at 14:45 on 03/13. 3.Site was offline on 03/15 due to heavy stroms later technician was able to close the relay on 03/17 at 13:15. | K12: 1.SR098046 2.SR098496 3.SR098614 | L12: SR098496 | M12: SR098614
A13: Clear Lake - Eastlake Hammer | B13: MN | C13: 196603.03 | D13: N/A | E13: =IF(AND(ISNUMBER(C13),ISNUMBER(D13)), C13-D13, "") | F13: =IFERROR(E13/D13, "") | G13: 181153.8 | H13: =IF(AND(ISNUMBER(C13),ISNUMBER(G13)), C13-G13, "") -> 15449.233 | I13: =IFERROR(H13/G13, "") -> 0.085282409 | J13: 1. Inverter 3 has been down a string since 09/09/21. Additionally, Inverter 3 tripped offline at 15:00 CDT on 03/31 and is reporting a permanent fault on the power module. After a technician checked in, it was confirmed that the inverter powerhead has been RMA’d. | K13: 1. SR098047, SR099230 | L13: SR099230
A14: Eastlake - Hertzberg CSG 1 | B14: MN | C14: 178773.26 | D14: N/A | E14: =IF(AND(ISNUMBER(C14),ISNUMBER(D14)), C14-D14, "") | F14: =IFERROR(E14/D14, "") | G14: 179090.7 | H14: =IF(AND(ISNUMBER(C14),ISNUMBER(G14)), C14-G14, "") -> -317.4356 | I14: =IFERROR(H14/G14, "") -> -0.0017724851 | J14: 1. Site was offline at 09:45am on 03/30 till end of the month due to recloser open | K14: 1.SR099167
A15: Cokato - Eastlake Laurel Village | B15: MN | C15: 192745.31 | D15: N/A | E15: =IF(AND(ISNUMBER(C15),ISNUMBER(D15)), C15-D15, "") | F15: =IFERROR(E15/D15, "") | G15: 177944.7 | H15: =IF(AND(ISNUMBER(C15),ISNUMBER(G15)), C15-G15, "") -> 14800.614 | I15: =IFERROR(H15/G15, "") -> 0.083175357 | J15: 1. Inverters B4, C2, C5 are each down 1 string. 2.Site is offline with multiple grid under frequency alerts at 09:30 on 03/30 later has reenegized the site at 12:00 on 03/31. | K15: 1.SR098048 2.SR099150 | L15: SR099150
A16: St. Peter - Eastlake Paulson | B16: MN | C16: 167620.93 | D16: N/A | E16: =IF(AND(ISNUMBER(C16),ISNUMBER(D16)), C16-D16, "") | F16: =IFERROR(E16/D16, "") | G16: 165236.6 | H16: =IF(AND(ISNUMBER(C16),ISNUMBER(G16)), C16-G16, "") -> 2384.3295 | I16: =IFERROR(H16/G16, "") -> 0.01442979
A17: Felician Sisters Convent | B17: NJ | C17: 34597.2 | D17: N/A | E17: =IF(AND(ISNUMBER(C17),ISNUMBER(D17)), C17-D17, "") | F17: =IFERROR(E17/D17, "") | H17: =IF(AND(ISNUMBER(C17),ISNUMBER(G17)), C17-G17, "") | I17: =IFERROR(H17/G17, "") | J17: 1. The college inverter 18 is offline due to an Isolation Error. | K17: 1. SR098818
A18: Sussex County Fairgrounds | B18: NJ | C18: 44370 | D18: N/A | E18: =IF(AND(ISNUMBER(C18),ISNUMBER(D18)), C18-D18, "") | F18: =IFERROR(E18/D18, "") | G18: N/A | H18: =IF(AND(ISNUMBER(C18),ISNUMBER(G18)), C18-G18, "") | I18: =IFERROR(H18/G18, "") | J18: 1. Meter A Inverters 1 through 4 went offline on 03/20 due to a power unit issue. Additionally, Meter A Inverter 12 went offline on 03/31 and is reporting an electric arc detection. | K18: 1. SR098819
A19: Gateway Church | B19: NJ | C19: 26234 | D19: N/A | E19: =IF(AND(ISNUMBER(C19),ISNUMBER(D19)), C19-D19, "") | F19: =IFERROR(E19/D19, "") | G19: N/A | H19: =IF(AND(ISNUMBER(C19),ISNUMBER(G19)), C19-G19, "") | I19: =IFERROR(H19/G19, "") | J19: 1.Inverters 12 and 15 were offline at 07:00 AM on 03/04, and inverter 15 later self-resolved at 05:50 PM on 03/27. Inverter 9 has been offline since 11/25/24. Inverter 18 has been offline since 04/27/24. 2.Inverter 5 is offline multiple days in a month. | K19: 1. SR098076 2. SR098231 | L19: SR098231
A20: Beaver Falls - Felician Sisters | B20: PA | C20: 36640 | D20: N/A | E20: =IF(AND(ISNUMBER(C20),ISNUMBER(D20)), C20-D20, "") | F20: =IFERROR(E20/D20, "") | G20: N/A | H20: =IF(AND(ISNUMBER(C20),ISNUMBER(G20)), C20-G20, "") | I20: =IFERROR(H20/G20, "")
A21: Livonia - Felician Sisters Ground | B21: MI | C21: 0 | D21: N/A | E21: =IF(AND(ISNUMBER(C21),ISNUMBER(D21)), C21-D21, "") | F21: =IFERROR(E21/D21, "") | G21: N/A | H21: =IF(AND(ISNUMBER(C21),ISNUMBER(G21)), C21-G21, "") | I21: =IFERROR(H21/G21, "") | J21: 1. Inverter 1 has been offline since the site began operations. 2. Inverter 7 is offline from 12/09/24. | K21: 1. SR098015 2. SR098016 | L21: SR098016
A22: Livonia - Felician Sisters Roof | B22: MI | C22: 12782 | D22: N/A | E22: =IF(AND(ISNUMBER(C22),ISNUMBER(D22)), C22-D22, "") | F22: =IFERROR(E22/D22, "") | G22: N/A | H22: =IF(AND(ISNUMBER(C22),ISNUMBER(G22)), C22-G22, "") | I22: =IFERROR(H22/G22, "")
A23: Monmouth Worship Ctr | B23: NJ | C23: 11687.5 | D23: N/A | E23: =IF(AND(ISNUMBER(C23),ISNUMBER(D23)), C23-D23, "") | F23: =IFERROR(E23/D23, "") | G23: N/A | H23: =IF(AND(ISNUMBER(C23),ISNUMBER(G23)), C23-G23, "") | I23: =IFERROR(H23/G23, "")
A24: Audubon - Senior Citizens United | B24: NJ | C24: 8714.2 | D24: N/A | E24: =IF(AND(ISNUMBER(C24),ISNUMBER(D24)), C24-D24, "") | F24: =IFERROR(E24/D24, "") | G24: N/A | H24: =IF(AND(ISNUMBER(C24),ISNUMBER(G24)), C24-G24, "") | I24: =IFERROR(H24/G24, "")
A25: Hollister - PG&E (Enerparc) | B25: CA
A26: Taos County - Kit Carson Electric Co-Op | B26: NM
A27: Commerce City - Adams City HS | B27: CO
A28: Commerce City - Adams City MS | B28: CO
A29: Commerce City - Central ES | B29: CO
A30: Commerce City - Dupont ES | B30: CO
A31: Commerce City - Educational Support Services | B31: CO
A32: Commerce City - Hanson ES | B32: CO
A33: Commerce City - Kemp ES | B33: CO
A34: Commerce City - Lester Arnold HS | B34: CO
A35: Commerce City - Monaco ES | B35: CO
A36: Denver - Northgate / Old Fort Logan ES | B36: CO
... A85: NY: Rome - 7776 Tannery RD | B85: NY

Sheet Apr
A1: {=portfolio} -> Clean Capital | D1: April Actual v. Expected | G1: April Actual v. Forecasted
A2: Total | C2: =SUM(C4:C85) -> 1758365.3 | D2: =SUM(D4:D85) -> 0 | E2: =C2-D2 -> 1758365.3 | F2: =IFERROR(E2/D2, 0) -> 0 | G2: =SUM(G4:G85) -> 1632050.7 | H2: =C2-G2 -> 126314.59 | I2: =IFERROR(H2/G2, 0) -> 0.07739624 | J2: =IF(AND(TODAY()>DATE(2024, 4, 1), COUNTA(Sites[Site])<>(COUNT(C:C)-1)), "Some sites are missing actual data; if new sites were added, make sure they are aligned correctly (including prior months!)", "") -> Some sites are missing actual data; if new sites were added, make sure they are aligned correctly (including prior months!)
A3: Site | B3: State | C3: Actual | D3: Expected | E3: Delta | F3: % | G3: Forecasted | H3: Delta | I3: % | J3: Notes | K3: Service Requests
A4: {=Sites[Site]} -> Lexington - Cotting School | B4: {=Sites[State]} -> MA | C4: 3263.048 | D4: N/A | E4: =IF(AND(ISNUMBER(C4),ISNUMBER(D4)), C4-D4, "") | F4: =IFERROR(E4/D4, "") | G4: N/A | H4: =IF(AND(ISNUMBER(C4),ISNUMBER(G4)), C4-G4, "") | I4: =IFERROR(H4/G4, "") | J4: 1.Inverter 1 was offline on multiple days of the month due to Insulation Fault. 2.Inverter 2 is offline from 01/01 due to Isolation fault. 3.Inverter 12 was significantly affected by shading, resulting in a 6 kW reduction in output. This issue is more likely to occur on high irradiance days throughout the month. | K4: 1.SR097850 2.SR095368 3.SR099290 | L4: SR095368 | M4: SR099290
A5: Pacoima - Whiteman Airport | B5: CA | C5: 38033.5 | D5: N/A | E5: =IF(AND(ISNUMBER(C5),ISNUMBER(D5)), C5-D5, "") | F5: =IFERROR(E5/D5, "") | G5: 57200 | H5: =IF(AND(ISNUMBER(C5),ISNUMBER(G5)), C5-G5, "") -> -19166.5 | I5: =IFERROR(H5/G5, "") -> -0.33507867 | J5: 1.Inverter L tripped offline due to Arc fault detected from 09:50AM on 03/02 and back online at 11:20AM on 04/03 after technician reset code. 2.Inverter I tripped offline at 17:10 on 03/09 due to an arc fault and back online at 11:30AM on 04/03 after technician reset code. again tripped offline from 9:00 to 16:00 on 04/08 due to arc fault. 3. Alll inverters tripped offline from 9:00 to 16:00 on 04/08 due to grid fault. 4.Inverter P was offline and Inverter N was offline and lost communication on multiple days through out the month. Inverters N and P require manufacturer diagnostics, but their warranties have expired—repair and shipping costs not covered. Client is considering replacing AE inverters with another brand and is seeking recommendations. | K5: 1.SR097975 2.SR097975 & SR099501 3.SR099508 4.SR097783 | L5: SR097975 | M5: SR099501 | N5: SR099508 | O5: SR097783
A6: Hyannis - Sturgis Charter School | B6: MA | C6: 31798.9 | D6: N/A | E6: =IF(AND(ISNUMBER(C6),ISNUMBER(D6)), C6-D6, "") | F6: =IFERROR(E6/D6, "") | G6: 32170 | H6: =IF(AND(ISNUMBER(C6),ISNUMBER(G6)), C6-G6, "") -> -371.10046 | I6: =IFERROR(H6/G6, "") -> -0.011535607
A7: South Dennis - Tony Kent Arena | B7: MA | C7: 36670.4 | D7: N/A | E7: =IF(AND(ISNUMBER(C7),ISNUMBER(D7)), C7-D7, "") | F7: =IFERROR(E7/D7, "") | G7: N/A | H7: =IF(AND(ISNUMBER(C7),ISNUMBER(G7)), C7-G7, "") | I7: =IFERROR(H7/G7, "") | J7: 1.On 03/14, Technicians identified failed modules on CB1 String 10 and CB6 String 7 causing inverter shutdown. They isolated the faulty strings, restored DC voltage, and brought the inverter back online. Site is now producing normally; module procurement and replacement are pending. | K7: 1.SR096262 & SR099066 | L7: SR099066
A8: Caropolis - Felician Sisters | B8: PA | C8: 56484 | D8: N/A | E8: =IF(AND(ISNUMBER(C8),ISNUMBER(D8)), C8-D8, "") | F8: =IFERROR(E8/D8, "") | G8: N/A | H8: =IF(AND(ISNUMBER(C8),ISNUMBER(G8)), C8-G8, "") | I8: =IFERROR(H8/G8, "") | J8: 1. Inverter 13 is underperforming by approximately 10 kW compared to its peers. 2.The weather station has experienced intermittent communication over a period of 2-3 days Since 04/05, due to an RS485 failure outside the PowerDash enclosure. While the gateway and Acuvim meter remain online, the inverters and weather station have lost connection. Additional troubleshooting is required | K8: 1.SR098870 2.SR099461 | L8: SR099461
A9: Clear Lake - Eastlake Gohman | B9: MN | C9: 166857 | D9: N/A | E9: =IF(AND(ISNUMBER(C9),ISNUMBER(D9)), C9-D9, "") | F9: =IFERROR(E9/D9, "") | G9: 175953.3 | H9: =IF(AND(ISNUMBER(C9),ISNUMBER(G9)), C9-G9, "") -> -9096.3 | I9: =IFERROR(H9/G9, "") -> -0.05169724 | J9: 1.Site remained offline from 10:15 CDT on 04/26 to 08:30 CDT on 04/29.Site came back online after technician has reset the main breaker | K9: 1.SR100445
A10: Zumbrota - Eastlake Brenda Luhman | B10: MN | C10: 171462 | D10: N/A | E10: =IF(AND(ISNUMBER(C10),ISNUMBER(D10)), C10-D10, "") | F10: =IFERROR(E10/D10, "") | G10: 177314.6 | H10: =IF(AND(ISNUMBER(C10),ISNUMBER(G10)), C10-G10, "") -> -5852.6 | I10: =IFERROR(H10/G10, "") -> -0.03300687
A11: Cokato - Eastlake Carlson | B11: MN | C11: 155585 | D11: N/A | E11: =IF(AND(ISNUMBER(C11),ISNUMBER(D11)), C11-D11, "") | F11: =IFERROR(E11/D11, "") | G11: 195439.7 | H11: =IF(AND(ISNUMBER(C11),ISNUMBER(G11)), C11-G11, "") -> -39854.7 | I11: =IFERROR(H11/G11, "") -> -0.20392326 | J11: 1.The site remained offline from 07:15 on 04/22 to 12:30 on 04/23. On 04/23, a technician reset the SEL relay and tripped breaker, that the issue could be due to poor utility power quality—harmonics or capacitor banks may need adjustment 2. Meter communications have been intermittent, with frequent losses in connectivity lasting between 45 minutes to 2 hours before self-resolving. This issue has persisted throughout the month and is affecting the accuracy of forecasted values 3.Site remained offline from 06:30 to 16:30 on 04/29.Site was back online after technician has closed in the Main Breaker | K11: 1.SR100131 2.SR100417 3.SR100617 | L11: SR100417 | M11: SR100617
A12: North Branch - Cornille 2 | B12: MN | C12: 147463 | D12: N/A | E12: =IF(AND(ISNUMBER(C12),ISNUMBER(D12)), C12-D12, "") | F12: =IFERROR(E12/D12, "") | G12: 178898.6 | H12: =IF(AND(ISNUMBER(C12),ISNUMBER(G12)), C12-G12, "") -> -31435.6 | I12: =IFERROR(H12/G12, "") -> -0.17571742 | J12: 1.Site remained offline from 12:47 on 04/05 to 12:45 on 04/07.Site came back online after the technician has reset the SEL relay and main breaker. 2.Site remained offline from 06:30 to 17:30 on 04/29.Site was back online after technician has closed in the Main Breaker 3. Inverter 6 is down 2 strings from 07/30/24. | K12: 1.SR099457 2.SR100618 3.SR098046,PM13355 | L12: SR100618 | M12: SR098046
