Workbook
Name JanActual: #REF!
Name JanActual2: #REF!
Name JanExpected: #REF!
Name JanExpectedDelta: #REF!
Name JanExpectedPercent: #REF!
Name JanExpPercent: #REF!
Name JanForecasted: #REF!
Name JanForecastedDelta: #REF!
Name JanForecastedPercent: #REF!
Name portfolio: Sites!$B$1:$B$1
Name Year: Sites!#REF!

Sheet Year to Date
A1: {=portfolio} -> MN8 KEF | D1: Year to Date Actual v. Expected | G1: Year to Date Actual v. Forecasted
A2: Total | C2: =SUM(C4:C95) -> -1373007.6 | D2: =SUM(D4:D95) -> 6064959.5 | E2: =C2-D2 -> -7437967.1 | F2: =IFERROR(E2/D2, 0) -> -1.2263836 | G2: =SUM(G4:G95) -> 12222355 | H2: =C2-G2 -> -13595362 | I2: =IFERROR(H2/G2, 0) -> -1.1123358
A3: Site | B3: State | C3: Actual | D3: Expected | E3: Delta | F3: % | G3: Forecasted | H3: Delta | I3: %
A4: {=Sites[Site]} -> Williamsburg A | B4: {=Sites[State]} -> MA | C4: =SUM('1st Qtr'!C4, '2nd Qtr'!C4, '3rd Qtr'!C4, '4th Qtr'!C4) -> 616737.78 | D4: =SUM('1st Qtr'!D4, '2nd Qtr'!D4, '3rd Qtr'!D4, '4th Qtr'!D4) -> 665354.34 | E4: =IF(AND(ISNUMBER(C4),ISNUMBER(D4)), C4-D4, "") -> -48616.563 | F4: =IFERROR(E4/D4, "") -> -0.073068679 | G4: =SUM('1st Qtr'!G4, '2nd Qtr'!G4, '3rd Qtr'!G4, '4th Qtr'!G4) -> 704509.09 | H4: =SUM('1st Qtr'!H4, '2nd Qtr'!H4, '3rd Qtr'!H4, '4th Qtr'!H4) -> -87771.313 | I4: =IFERROR(H4/G4, "") -> -0.12458507
A5: Orange A KB | B5: MA | C5: =SUM('1st Qtr'!C5, '2nd Qtr'!C5, '3rd Qtr'!C5, '4th Qtr'!C5) -> 499883.4 | D5: =SUM(Jan!D5, Feb!D5, Mar!D5) -> 258904.45 | E5: =IF(AND(ISNUMBER(C5),ISNUMBER(D5)), C5-D5, "") -> 240978.95 | F5: =IFERROR(E5/D5, "") -> 0.93076402 | G5: =SUM('1st Qtr'!G5, '2nd Qtr'!G5, '3rd Qtr'!G5, '4th Qtr'!G5) -> 568034.89 | H5: =SUM(Jan!H5, Feb!H5, Mar!H5) -> -50872.194 | I5: =IFERROR(H5/G5, "") -> -0.089558221
A6: Goshen A | B6: MA | C6: =SUM('1st Qtr'!C6, '2nd Qtr'!C6, '3rd Qtr'!C6, '4th Qtr'!C6) -> -11452933 | D6: =SUM(Jan!D6, Feb!D6, Mar!D6) -> 308555.5 | E6: =IF(AND(ISNUMBER(C6),ISNUMBER(D6)), C6-D6, "") -> -11761488 | F6: =IFERROR(E6/D6, "") -> -38.117902 | G6: =SUM('1st Qtr'!G6, '2nd Qtr'!G6, '3rd Qtr'!G6, '4th Qtr'!G6) -> 416874.56 | H6: =SUM(Jan!H6, Feb!H6, Mar!H6) -> 70756.84 | I6: =IFERROR(H6/G6, "") -> 0.16973173
A7: Phillipston A KB | B7: MA | C7: =SUM('1st Qtr'!C7, '2nd Qtr'!C7, '3rd Qtr'!C7, '4th Qtr'!C7) -> 591471 | D7: =SUM(Jan!D7, Feb!D7, Mar!D7) -> 395445.18 | E7: =IF(AND(ISNUMBER(C7),ISNUMBER(D7)), C7-D7, "") -> 196025.82 | F7: =IFERROR(E7/D7, "") -> 0.49570922 | G7: =SUM('1st Qtr'!G7, '2nd Qtr'!G7, '3rd Qtr'!G7, '4th Qtr'!G7) -> 472307.68 | H7: =SUM(Jan!H7, Feb!H7, Mar!H7) -> 63957.32 | I7: =IFERROR(H7/G7, "") -> 0.13541452
A8: Uxbridge D | B8: MA | C8: =SUM('1st Qtr'!C8, '2nd Qtr'!C8, '3rd Qtr'!C8, '4th Qtr'!C8) -> 624045 | D8: =SUM(Jan!D8, Feb!D8, Mar!D8) -> 356457.4 | E8: =IF(AND(ISNUMBER(C8),ISNUMBER(D8)), C8-D8, "") -> 267587.6 | F8: =IFERROR(E8/D8, "") -> 0.75068606 | G8: =SUM('1st Qtr'!G8, '2nd Qtr'!G8, '3rd Qtr'!G8, '4th Qtr'!G8) -> 743358.7 | H8: =SUM(Jan!H8, Feb!H8, Mar!H8) -> -77950.4 | I8: =IFERROR(H8/G8, "") -> -0.10486243
A9: West Bridgewater A&B | B9: MA | C9: =SUM('1st Qtr'!C9, '2nd Qtr'!C9, '3rd Qtr'!C9, '4th Qtr'!C9) -> 1027191.5 | D9: =SUM(Jan!D9, Feb!D9, Mar!D9) -> 566022.2 | E9: =IF(AND(ISNUMBER(C9),ISNUMBER(D9)), C9-D9, "") -> 461169.3 | F9: =IFERROR(E9/D9, "") -> 0.81475479 | G9: =SUM('1st Qtr'!G9, '2nd Qtr'!G9, '3rd Qtr'!G9, '4th Qtr'!G9) -> 1240399.7 | H9: =SUM(Jan!H9, Feb!H9, Mar!H9) -> -146117.2 | I9: =IFERROR(H9/G9, "") -> -0.11779848
A10: Sutton A | B10: MA | C10: =SUM('1st Qtr'!C10, '2nd Qtr'!C10, '3rd Qtr'!C10, '4th Qtr'!C10) -> 544401 | D10: =SUM(Jan!D10, Feb!D10, Mar!D10) -> 302395.95 | E10: =IF(AND(ISNUMBER(C10),ISNUMBER(D10)), C10-D10, "") -> 242005.05 | F10: =IFERROR(E10/D10, "") -> 0.80029197 | G10: =SUM('1st Qtr'!G10, '2nd Qtr'!G10, '3rd Qtr'!G10, '4th Qtr'!G10) -> 702461.42 | H10: =SUM(Jan!H10, Feb!H10, Mar!H10) -> -109860.32 | I10: =IFERROR(H10/G10, "") -> -0.15639339
A11: North Adams A | B11: MA | C11: =SUM('1st Qtr'!C11, '2nd Qtr'!C11, '3rd Qtr'!C11, '4th Qtr'!C11) -> 567270 | D11: =SUM(Jan!D11, Feb!D11, Mar!D11) -> 294516.74 | E11: =IF(AND(ISNUMBER(C11),ISNUMBER(D11)), C11-D11, "") -> 272753.26 | F11: =IFERROR(E11/D11, "") -> 0.92610444 | G11: =SUM('1st Qtr'!G11, '2nd Qtr'!G11, '3rd Qtr'!G11, '4th Qtr'!G11) -> 727467.16 | H11: =SUM(Jan!H11, Feb!H11, Mar!H11) -> -104920.86 | I11: =IFERROR(H11/G11, "") -> -0.14422762
A12: North Adams B | B12: MA | C12: =SUM('1st Qtr'!C12, '2nd Qtr'!C12, '3rd Qtr'!C12, '4th Qtr'!C12) -> 546983 | D12: =SUM(Jan!D12, Feb!D12, Mar!D12) -> 254351.53 | E12: =IF(AND(ISNUMBER(C12),ISNUMBER(D12)), C12-D12, "") -> 292631.47 | F12: =IFERROR(E12/D12, "") -> 1.1505001 | G12: =SUM('1st Qtr'!G12, '2nd Qtr'!G12, '3rd Qtr'!G12, '4th Qtr'!G12) -> 727467.16 | H12: =SUM(Jan!H12, Feb!H12, Mar!H12) -> -122625.86 | I12: =IFERROR(H12/G12, "") -> -0.16856549
A13: Clarksburg A | B13: MA | C13: =SUM('1st Qtr'!C13, '2nd Qtr'!C13, '3rd Qtr'!C13, '4th Qtr'!C13) -> 567692 | D13: =SUM(Jan!D13, Feb!D13, Mar!D13) -> 280640.43 | E13: =IF(AND(ISNUMBER(C13),ISNUMBER(D13)), C13-D13, "") -> 287051.57 | F13: =IFERROR(E13/D13, "") -> 1.0228447 | G13: =SUM('1st Qtr'!G13, '2nd Qtr'!G13, '3rd Qtr'!G13, '4th Qtr'!G13) -> 724163.09 | H13: =SUM(Jan!H13, Feb!H13, Mar!H13) -> -108476.99 | I13: =IFERROR(H13/G13, "") -> -0.14979635
A14: Swansea B | B14: MA | C14: =SUM('1st Qtr'!C14, '2nd Qtr'!C14, '3rd Qtr'!C14, '4th Qtr'!C14) -> 653355 | D14: =SUM(Jan!D14, Feb!D14, Mar!D14) -> 361411.34 | E14: =IF(AND(ISNUMBER(C14),ISNUMBER(D14)), C14-D14, "") -> 291943.66 | F14: =IFERROR(E14/D14, "") -> 0.80778777 | G14: =SUM('1st Qtr'!G14, '2nd Qtr'!G14, '3rd Qtr'!G14, '4th Qtr'!G14) -> 485767.91 | H14: =SUM(Jan!H14, Feb!H14, Mar!H14) -> 99719.69 | I14: =IFERROR(H14/G14, "") -> 0.20528258
A15: Wareham 2 | B15: MA | C15: =SUM('1st Qtr'!C15, '2nd Qtr'!C15, '3rd Qtr'!C15, '4th Qtr'!C15) -> 573336.45 | D15: =SUM(Jan!D15, Feb!D15, Mar!D15) -> 287011.73 | E15: =IF(AND(ISNUMBER(C15),ISNUMBER(D15)), C15-D15, "") -> 286324.72 | F15: =IFERROR(E15/D15, "") -> 0.99760633 | G15: =SUM('1st Qtr'!G15, '2nd Qtr'!G15, '3rd Qtr'!G15, '4th Qtr'!G15) -> 785231.2 | H15: =SUM(Jan!H15, Feb!H15, Mar!H15) -> -123800.45 | I15: =IFERROR(H15/G15, "") -> -0.15766114
A16: Kingston 1 KB | B16: MA | C16: =SUM('1st Qtr'!C16, '2nd Qtr'!C16, '3rd Qtr'!C16, '4th Qtr'!C16) -> 527951 | D16: =SUM(Jan!D16, Feb!D16, Mar!D16) -> 280103.39 | E16: =IF(AND(ISNUMBER(C16),ISNUMBER(D16)), C16-D16, "") -> 247847.61 | F16: =IFERROR(E16/D16, "") -> 0.88484331 | G16: =SUM('1st Qtr'!G16, '2nd Qtr'!G16, '3rd Qtr'!G16, '4th Qtr'!G16) -> 607149.89 | H16: =SUM(Jan!H16, Feb!H16, Mar!H16) -> -50948.99 | I16: =IFERROR(H16/G16, "") -> -0.083915011
... A20: Plympton A-2 | B20: MA | C20: =SUM('1st Qtr'!C20, '2nd Qtr'!C20, '3rd Qtr'!C20, '4th Qtr'!C20) -> 617151 | D20: =SUM(Jan!D20, Feb!D20, Mar!D20) -> 330404.44 | E20: =IF(AND(ISNUMBER(C20),ISNUMBER(D20)), C20-D20, "") -> 286746.56 | F20: =IFERROR(E20/D20, "") -> 0.86786533 | G20: =SUM('1st Qtr'!G20, '2nd Qtr'!G20, '3rd Qtr'!G20, '4th Qtr'!G20) -> 742497.64 | H20: =SUM(Jan!H20, Feb!H20, Mar!H20) -> -84032.24 | I20: =IFERROR(H20/G20, "") -> -0.11317509

Sheet 1st Qtr
A1: {=portfolio} -> MN8 KEF | D1: 1st Quarter Actual v. Expected | G1: 1st Quarter Actual v. Forecasted
A2: Total | C2: =SUM(C4:C95) -> 5061899 | D2: =SUM(D4:D95) -> 5742936.9 | E2: =C2-D2 -> -681037.87 | F2: =IFERROR(E2/D2, 0) -> -0.11858704 | G2: =SUM(G4:G95) -> 6132609.5 | H2: =C2-G2 -> -1070710.5 | I2: =IFERROR(H2/G2, 0) -> -0.17459297
A3: Site | B3: State | C3: Actual | D3: Expected | E3: Delta | F3: % | G3: Forecasted | H3: Delta | I3: %
A4: {=Sites[Site]} -> Williamsburg A | B4: {=Sites[State]} -> MA | C4: =SUM(Jan!C4, Feb!C4, Mar!C4) -> 299514.09 | D4: =SUM(Jan!D4, Feb!D4, Mar!D4) -> 343331.74 | E4: =IF(AND(ISNUMBER(C4),ISNUMBER(D4)), C4-D4, "") -> -43817.646 | F4: =IFERROR(E4/D4, "") -> -0.1276248 | G4: =SUM(Jan!G4, Feb!G4, Mar!G4) -> 358213.49 | H4: =SUM(Jan!H4, Feb!H4, Mar!H4) -> -58699.396 | I4: =IFERROR(H4/G4, "") -> -0.16386707
A5: Orange A KB | B5: MA | C5: =SUM(Jan!C5, Feb!C5, Mar!C5) -> 247279.7 | D5: =SUM(Jan!D5, Feb!D5, Mar!D5) -> 258904.45 | E5: =IF(AND(ISNUMBER(C5),ISNUMBER(D5)), C5-D5, "") -> -11624.754 | F5: =IFERROR(E5/D5, "") -> -0.044899786 | G5: =SUM(Jan!G5, Feb!G5, Mar!G5) -> 298151.89 | H5: =SUM(Jan!H5, Feb!H5, Mar!H5) -> -50872.194 | I5: =IFERROR(H5/G5, "") -> -0.17062509
A6: Goshen A | B6: MA | C6: =SUM(Jan!C6, Feb!C6, Mar!C6) -> 261845 | D6: =SUM(Jan!D6, Feb!D6, Mar!D6) -> 308555.5 | E6: =IF(AND(ISNUMBER(C6),ISNUMBER(D6)), C6-D6, "") -> -46710.5 | F6: =IFERROR(E6/D6, "") -> -0.15138443 | G6: =SUM(Jan!G6, Feb!G6, Mar!G6) -> 191088.16 | H6: =SUM(Jan!H6, Feb!H6, Mar!H6) -> 70756.84 | I6: =IFERROR(H6/G6, "") -> 0.37028375
A7: Phillipston A KB | B7: MA | C7: =SUM(Jan!C7, Feb!C7, Mar!C7) -> 282267 | D7: =SUM(Jan!D7, Feb!D7, Mar!D7) -> 395445.18 | E7: =IF(AND(ISNUMBER(C7),ISNUMBER(D7)), C7-D7, "") -> -113178.18 | F7: =IFERROR(E7/D7, "") -> -0.28620447 | G7: =SUM(Jan!G7, Feb!G7, Mar!G7) -> 218309.68 | H7: =SUM(Jan!H7, Feb!H7, Mar!H7) -> 63957.32 | I7: =IFERROR(H7/G7, "") -> 0.29296603
A8: Uxbridge D | B8: MA | C8: =SUM(Jan!C8, Feb!C8, Mar!C8) -> 312227 | D8: =SUM(Jan!D8, Feb!D8, Mar!D8) -> 356457.4 | E8: =IF(AND(ISNUMBER(C8),ISNUMBER(D8)), C8-D8, "") -> -44230.4 | F8: =IFERROR(E8/D8, "") -> -0.12408327 | G8: =SUM(Jan!G8, Feb!G8, Mar!G8) -> 390177.4 | H8: =SUM(Jan!H8, Feb!H8, Mar!H8) -> -77950.4 | I8: =IFERROR(H8/G8, "") -> -0.19978195
A9: West Bridgewater A&B | B9: MA | C9: =SUM(Jan!C9, Feb!C9, Mar!C9) -> 493322 | D9: =SUM(Jan!D9, Feb!D9, Mar!D9) -> 566022.2 | E9: =IF(AND(ISNUMBER(C9),ISNUMBER(D9)), C9-D9, "") -> -72700.2 | F9: =IFERROR(E9/D9, "") -> -0.12844055 | G9: =SUM(Jan!G9, Feb!G9, Mar!G9) -> 639439.2 | H9: =SUM(Jan!H9, Feb!H9, Mar!H9) -> -146117.2 | I9: =IFERROR(H9/G9, "") -> -0.22850836
A10: Sutton A | B10: MA | C10: =SUM(Jan!C10, Feb!C10, Mar!C10) -> 251473 | D10: =SUM(Jan!D10, Feb!D10, Mar!D10) -> 302395.95 | E10: =IF(AND(ISNUMBER(C10),ISNUMBER(D10)), C10-D10, "") -> -50922.95 | F10: =IFERROR(E10/D10, "") -> -0.16839825 | G10: =SUM(Jan!G10, Feb!G10, Mar!G10) -> 361333.32 | H10: =SUM(Jan!H10, Feb!H10, Mar!H10) -> -109860.32 | I10: =IFERROR(H10/G10, "") -> -0.30404149
A11: North Adams A | B11: MA | C11: =SUM(Jan!C11, Feb!C11, Mar!C11) -> 258785 | D11: =SUM(Jan!D11, Feb!D11, Mar!D11) -> 294516.74 | E11: =IF(AND(ISNUMBER(C11),ISNUMBER(D11)), C11-D11, "") -> -35731.74 | F11: =IFERROR(E11/D11, "") -> -0.12132329 | G11: =SUM(Jan!G11, Feb!G11, Mar!G11) -> 363705.86 | H11: =SUM(Jan!H11, Feb!H11, Mar!H11) -> -104920.86 | I11: =IFERROR(H11/G11, "") -> -0.28847723
A12: North Adams B | B12: MA | C12: =SUM(Jan!C12, Feb!C12, Mar!C12) -> 241080 | D12: =SUM(Jan!D12, Feb!D12, Mar!D12) -> 254351.53 | E12: =IF(AND(ISNUMBER(C12),ISNUMBER(D12)), C12-D12, "") -> -13271.53 | F12: =IFERROR(E12/D12, "") -> -0.052177905 | G12: =SUM(Jan!G12, Feb!G12, Mar!G12) -> 363705.86 | H12: =SUM(Jan!H12, Feb!H12, Mar!H12) -> -122625.86 | I12: =IFERROR(H12/G12, "") -> -0.33715668
A13: Clarksburg A | B13: MA | C13: =SUM(Jan!C13, Feb!C13, Mar!C13) -> 253576 | D13: =SUM(Jan!D13, Feb!D13, Mar!D13) -> 280640.43 | E13: =IF(AND(ISNUMBER(C13),ISNUMBER(D13)), C13-D13, "") -> -27064.43 | F13: =IFERROR(E13/D13, "") -> -0.096438101 | G13: =SUM(Jan!G13, Feb!G13, Mar!G13) -> 362052.99 | H13: =SUM(Jan!H13, Feb!H13, Mar!H13) -> -108476.99 | I13: =IFERROR(H13/G13, "") -> -0.29961634
A14: Swansea B | B14: MA | C14: =SUM(Jan!C14, Feb!C14, Mar!C14) -> 318674 | D14: =SUM(Jan!D14, Feb!D14, Mar!D14) -> 361411.34 | E14: =IF(AND(ISNUMBER(C14),ISNUMBER(D14)), C14-D14, "") -> -42737.34 | F14: =IFERROR(E14/D14, "") -> -0.11825124 | G14: =SUM(Jan!G14, Feb!G14, Mar!G14) -> 218954.31 | H14: =SUM(Jan!H14, Feb!H14, Mar!H14) -> 99719.69 | I14: =IFERROR(H14/G14, "") -> 0.45543607
A15: Wareham 2 | B15: MA | C15: =SUM(Jan!C15, Feb!C15, Mar!C15) -> 271754.25 | D15: =SUM(Jan!D15, Feb!D15, Mar!D15) -> 287011.73 | E15: =IF(AND(ISNUMBER(C15),ISNUMBER(D15)), C15-D15, "") -> -15257.48 | F15: =IFERROR(E15/D15, "") -> -0.053159779 | G15: =SUM(Jan!G15, Feb!G15, Mar!G15) -> 395554.7 | H15: =SUM(Jan!H15, Feb!H15, Mar!H15) -> -123800.45 | I15: =IFERROR(H15/G15, "") -> -0.31297934
A16: Kingston 1 KB | B16: MA | C16: =SUM(Jan!C16, Feb!C16, Mar!C16) -> 246362 | D16: =SUM(Jan!D16, Feb!D16, Mar!D16) -> 280103.39 | E16: =IF(AND(ISNUMBER(C16),ISNUMBER(D16)), C16-D16, "") -> -33741.39 | F16: =IFERROR(E16/D16, "") -> -0.12046048 | G16: =SUM(Jan!G16, Feb!G16, Mar!G16) -> 297310.99 | H16: =SUM(Jan!H16, Feb!H16, Mar!H16) -> -50948.99 | I16: =IFERROR(H16/G16, "") -> -0.17136598
... A20: Plympton A-2 | B20: MA | C20: =SUM(Jan!C20, Feb!C20, Mar!C20) -> 294169 | D20: =SUM(Jan!D20, Feb!D20, Mar!D20) -> 330404.44 | E20: =IF(AND(ISNUMBER(C20),ISNUMBER(D20)), C20-D20, "") -> -36235.44 | F20: =IFERROR(E20/D20, "") -> -0.10966995 | G20: =SUM(Jan!G20, Feb!G20, Mar!G20) -> 378201.24 | H20: =SUM(Jan!H20, Feb!H20, Mar!H20) -> -84032.24 | I20: =IFERROR(H20/G20, "") -> -0.22218922

Sheet 2nd Qtr
A1: {=portfolio} -> MN8 KEF | D1: 2nd Quarter Actual v. Expected | G1: 2nd Quarter Actual v. Forecasted
A2: Total | C2: =SUM(C4:C95) -> -6434906.7 | D2: =SUM(D4:D95) -> 5585014.8 | E2: =C2-D2 -> -12019921 | F2: =IFERROR(E2/D2, 0) -> -2.1521736 | G2: =SUM(G4:G95) -> 6089745.1 | H2: =C2-G2 -> -12524652 | I2: =IFERROR(H2/G2, 0) -> -2.0566791
A3: Site | B3: State | C3: Actual | D3: Expected | E3: Delta | F3: % | G3: Forecasted | H3: Delta | I3: %
A4: {=Sites[Site]} -> Williamsburg A | B4: {=Sites[State]} -> MA | C4: =SUM(Apr!C4, May!C4, Jun!C4) -> 317223.68 | D4: =SUM(Apr!D4, May!D4, Jun!D4) -> 322022.6 | E4: =IF(AND(ISNUMBER(C4),ISNUMBER(D4)), C4-D4, "") -> -4798.9172 | F4: =IFERROR(E4/D4, "") -> -0.014902424 | G4: =SUM(Apr!G4+May!G4+Jun!G4) -> 346295.6 | H4: =SUM(Apr!H4, May!H4, Jun!H4) -> -29071.917 | I4: =IFERROR(H4/G4, "") -> -0.08395116
A5: Orange A KB | B5: MA | C5: =SUM(Apr!C5, May!C5, Jun!C5) -> 252603.7 | D5: =SUM(Apr!D5, May!D5, Jun!D5) -> 238507 | E5: =IF(AND(ISNUMBER(C5),ISNUMBER(D5)), C5-D5, "") -> 14096.7 | F5: =IFERROR(E5/D5, "") -> 0.059103926 | G5: =SUM(Apr!G5+May!G5+Jun!G5) -> 269883 | H5: =SUM(Apr!H5, May!H5, Jun!H5) -> -17279.3 | I5: =IFERROR(H5/G5, "") -> -0.064025152
A6: Goshen A | B6: MA | C6: =SUM(Apr!C6, May!C6, Jun!C6) -> -11714778 | D6: =SUM(Apr!D6, May!D6, Jun!D6) -> 282662.5 | E6: =IF(AND(ISNUMBER(C6),ISNUMBER(D6)), C6-D6, "") -> -11997440 | F6: =IFERROR(E6/D6, "") -> -42.4444 | G6: =SUM(Apr!G6+May!G6+Jun!G6) -> 225786.4 | H6: =SUM(Apr!H6, May!H6, Jun!H6) -> -11940564 | I6: =IFERROR(H6/G6, "") -> -52.884337
A7: Phillipston A KB | B7: MA | C7: =SUM(Apr!C7, May!C7, Jun!C7) -> 309204 | D7: =SUM(Apr!D7, May!D7, Jun!D7) -> 330515 | E7: =IF(AND(ISNUMBER(C7),ISNUMBER(D7)), C7-D7, "") -> -21311 | F7: =IFERROR(E7/D7, "") -> -0.064478163 | G7: =SUM(Apr!G7+May!G7+Jun!G7) -> 253998 | H7: =SUM(Apr!H7, May!H7, Jun!H7) -> 55206 | I7: =IFERROR(H7/G7, "") -> 0.21734817
A8: Uxbridge D | B8: MA | C8: =SUM(Apr!C8, May!C8, Jun!C8) -> 311818 | D8: =SUM(Apr!D8, May!D8, Jun!D8) -> 317386.7 | E8: =IF(AND(ISNUMBER(C8),ISNUMBER(D8)), C8-D8, "") -> -5568.7 | F8: =IFERROR(E8/D8, "") -> -0.017545474 | G8: =SUM(Apr!G8+May!G8+Jun!G8) -> 353181.3 | H8: =SUM(Apr!H8, May!H8, Jun!H8) -> -41363.3 | I8: =IFERROR(H8/G8, "") -> -0.11711634
A9: West Bridgewater A&B | B9: MA | C9: =SUM(Apr!C9, May!C9, Jun!C9) -> 533869.5 | D9: =SUM(Apr!D9, May!D9, Jun!D9) -> 549836.5 | E9: =IF(AND(ISNUMBER(C9),ISNUMBER(D9)), C9-D9, "") -> -15967 | F9: =IFERROR(E9/D9, "") -> -0.029039542 | G9: =SUM(Apr!G9+May!G9+Jun!G9) -> 600960.5 | H9: =SUM(Apr!H9, May!H9, Jun!H9) -> -67091 | I9: =IFERROR(H9/G9, "") -> -0.11163962
A10: Sutton A | B10: MA | C10: =SUM(Apr!C10, May!C10, Jun!C10) -> 292928 | D10: =SUM(Apr!D10, May!D10, Jun!D10) -> 294853.4 | E10: =IF(AND(ISNUMBER(C10),ISNUMBER(D10)), C10-D10, "") -> -1925.4 | F10: =IFERROR(E10/D10, "") -> -0.0065300248 | G10: =SUM(Apr!G10+May!G10+Jun!G10) -> 341128.1 | H10: =SUM(Apr!H10, May!H10, Jun!H10) -> -48200.1 | I10: =IFERROR(H10/G10, "") -> -0.14129619
A11: North Adams A | B11: MA | C11: =SUM(Apr!C11, May!C11, Jun!C11) -> 308485 | D11: =SUM(Apr!D11, May!D11, Jun!D11) -> 313165.4 | E11: =IF(AND(ISNUMBER(C11),ISNUMBER(D11)), C11-D11, "") -> -4680.4 | F11: =IFERROR(E11/D11, "") -> -0.014945457 | G11: =SUM(Apr!G11+May!G11+Jun!G11) -> 363761.3 | H11: =SUM(Apr!H11, May!H11, Jun!H11) -> -55276.3 | I11: =IFERROR(H11/G11, "") -> -0.15195762
A12: North Adams B | B12: MA | C12: =SUM(Apr!C12, May!C12, Jun!C12) -> 305903 | D12: =SUM(Apr!D12, May!D12, Jun!D12) -> 271955.7 | E12: =IF(AND(ISNUMBER(C12),ISNUMBER(D12)), C12-D12, "") -> 33947.3 | F12: =IFERROR(E12/D12, "") -> 0.12482658 | G12: =SUM(Apr!G12+May!G12+Jun!G12) -> 363761.3 | H12: =SUM(Apr!H12, May!H12, Jun!H12) -> -57858.3 | I12: =IFERROR(H12/G12, "") -> -0.15905568
A13: Clarksburg A | B13: MA | C13: =SUM(Apr!C13, May!C13, Jun!C13) -> 314116 | D13: =SUM(Apr!D13, May!D13, Jun!D13) -> 315940 | E13: =IF(AND(ISNUMBER(C13),ISNUMBER(D13)), C13-D13, "") -> -1824 | F13: =IFERROR(E13/D13, "") -> -0.0057732481 | G13: =SUM(Apr!G13+May!G13+Jun!G13) -> 362110.1 | H13: =SUM(Apr!H13, May!H13, Jun!H13) -> -47994.1 | I13: =IFERROR(H13/G13, "") -> -0.13254008
A14: Swansea B | B14: MA | C14: =SUM(Apr!C14, May!C14, Jun!C14) -> 334681 | D14: =SUM(Apr!D14, May!D14, Jun!D14) -> 341998.9 | E14: =IF(AND(ISNUMBER(C14),ISNUMBER(D14)), C14-D14, "") -> -7317.9 | F14: =IFERROR(E14/D14, "") -> -0.021397437 | G14: =SUM(Apr!G14+May!G14+Jun!G14) -> 266813.6 | H14: =SUM(Apr!H14, May!H14, Jun!H14) -> 67867.4 | I14: =IFERROR(H14/G14, "") -> 0.2543626
A15: Wareham 2 | B15: MA | C15: =SUM(Apr!C15, May!C15, Jun!C15) -> 301582.2 | D15: =SUM(Apr!D15, May!D15, Jun!D15) -> 294326.1 | E15: =IF(AND(ISNUMBER(C15),ISNUMBER(D15)), C15-D15, "") -> 7256.1 | F15: =IFERROR(E15/D15, "") -> 0.024653267 | G15: =SUM(Apr!G15+May!G15+Jun!G15) -> 389676.5 | H15: =SUM(Apr!H15, May!H15, Jun!H15) -> -88094.3 | I15: =IFERROR(H15/G15, "") -> -0.22607034
A16: Kingston 1 KB | B16: MA | C16: =SUM(Apr!C16, May!C16, Jun!C16) -> 281589 | D16: =SUM(Apr!D16, May!D16, Jun!D16) -> 278462.7 | E16: =IF(AND(ISNUMBER(C16),ISNUMBER(D16)), C16-D16, "") -> 3126.3 | F16: =IFERROR(E16/D16, "") -> 0.011226997 | G16: =SUM(Apr!G16+May!G16+Jun!G16) -> 309838.9 | H16: =SUM(Apr!H16, May!H16, Jun!H16) -> -28249.9 | I16: =IFERROR(H16/G16, "") -> -0.091176092
... A20: Plympton A-2 | B20: MA | C20: =SUM(Apr!C20, May!C20, Jun!C20) -> 322982 | D20: =SUM(Apr!D20, May!D20, Jun!D20) -> 329600 | E20: =IF(AND(ISNUMBER(C20),ISNUMBER(D20)), C20-D20, "") -> -6618 | F20: =IFERROR(E20/D20, "") -> -0.020078883 | G20: =SUM(Apr!G20+May!G20+Jun!G20) -> 364296.4 | H20: =SUM(Apr!H20, May!H20, Jun!H20) -> -41314.4 | I20: =IFERROR(H20/G20, "") -> -0.11340875

Sheet 3rd Qtr
A1: {=portfolio} -> MN8 KEF | D1: 3rd Quarter Actual v. Expected | G1: 3rd Quarter Actual v. Forecasted
A2: Total | C2: =SUM(C4:C95) -> 0 | D2: =SUM(D4:D95) -> 0 | E2: =C2-D2 -> 0 | F2: =IFERROR(E2/D2, 0) -> 0 | G2: =SUM(G4:G95) -> 0 | H2: =C2-G2 -> 0 | I2: =IFERROR(H2/G2, 0) -> 0
A3: Site | B3: State | C3: Actual | D3: Expected | E3: Delta | F3: % | G3: Forecasted | H3: Delta | I3: %
A4: {=Sites[Site]} -> Williamsburg A | B4: {=Sites[State]} -> MA | C4: =SUM(Jul!C4, Aug!C4, Sep!C4) -> 0 | D4: =SUM(Jul!D4, Aug!D4, Sep!D4) -> 0 | E4: =IF(AND(ISNUMBER(C4),ISNUMBER(D4)), C4-D4, "") -> 0 | F4: =IFERROR(E4/D4, "") | H4: =SUM(Jul!H4, Aug!H4, Sep!H4) -> 0 | I4: =IFERROR(H4/G4, "")
A5: Orange A KB | B5: MA | C5: =SUM(Jul!C5, Aug!C5, Sep!C5) -> 0 | D5: =SUM(Jul!D5, Aug!D5, Sep!D5) -> 0 | E5: =IF(AND(ISNUMBER(C5),ISNUMBER(D5)), C5-D5, "") -> 0 | F5: =IFERROR(E5/D5, "") | H5: =SUM(Jul!H5, Aug!H5, Sep!H5) -> 0 | I5: =IFERROR(H5/G5, "")
A6: Goshen A | B6: MA | C6: =SUM(Jul!C6, Aug!C6, Sep!C6) -> 0 | D6: =SUM(Jul!D6, Aug!D6, Sep!D6) -> 0 | E6: =IF(AND(ISNUMBER(C6),ISNUMBER(D6)), C6-D6, "") -> 0 | F6: =IFERROR(E6/D6, "") | H6: =SUM(Jul!H6, Aug!H6, Sep!H6) -> 0 | I6: =IFERROR(H6/G6, "")
A7: Phillipston A KB | B7: MA | C7: =SUM(Jul!C7, Aug!C7, Sep!C7) -> 0 | D7: =SUM(Jul!D7, Aug!D7, Sep!D7) -> 0 | E7: =IF(AND(ISNUMBER(C7),ISNUMBER(D7)), C7-D7, "") -> 0 | F7: =IFERROR(E7/D7, "") | H7: =SUM(Jul!H7, Aug!H7, Sep!H7) -> 0 | I7: =IFERROR(H7/G7, "")
A8: Uxbridge D | B8: MA | C8: =SUM(Jul!C8, Aug!C8, Sep!C8) -> 0 | D8: =SUM(Jul!D8, Aug!D8, Sep!D8) -> 0 | E8: =IF(AND(ISNUMBER(C8),ISNUMBER(D8)), C8-D8, "") -> 0 | F8: =IFERROR(E8/D8, "") | H8: =SUM(Jul!H8, Aug!H8, Sep!H8) -> 0 | I8: =IFERROR(H8/G8, "")
A9: West Bridgewater A&B | B9: MA | C9: =SUM(Jul!C9, Aug!C9, Sep!C9) -> 0 | D9: =SUM(Jul!D9, Aug!D9, Sep!D9) -> 0 | E9: =IF(AND(ISNUMBER(C9),ISNUMBER(D9)), C9-D9, "") -> 0 | F9: =IFERROR(E9/D9, "") | H9: =SUM(Jul!H9, Aug!H9, Sep!H9) -> 0 | I9: =IFERROR(H9/G9, "")
A10: Sutton A | B10: MA | C10: =SUM(Jul!C10, Aug!C10, Sep!C10) -> 0 | D10: =SUM(Jul!D10, Aug!D10, Sep!D10) -> 0 | E10: =IF(AND(ISNUMBER(C10),ISNUMBER(D10)), C10-D10, "") -> 0 | F10: =IFERROR(E10/D10, "") | H10: =SUM(Jul!H10, Aug!H10, Sep!H10) -> 0 | I10: =IFERROR(H10/G10, "")
A11: North Adams A | B11: MA | C11: =SUM(Jul!C11, Aug!C11, Sep!C11) -> 0 | D11: =SUM(Jul!D11, Aug!D11, Sep!D11) -> 0 | E11: =IF(AND(ISNUMBER(C11),ISNUMBER(D11)), C11-D11, "") -> 0 | F11: =IFERROR(E11/D11, "") | H11: =SUM(Jul!H11, Aug!H11, Sep!H11) -> 0 | I11: =IFERROR(H11/G11, "")
A12: North Adams B | B12: MA | C12: =SUM(Jul!C12, Aug!C12, Sep!C12) -> 0 | D12: =SUM(Jul!D12, Aug!D12, Sep!D12) -> 0 | E12: =IF(AND(ISNUMBER(C12),ISNUMBER(D12)), C12-D12, "") -> 0 | F12: =IFERROR(E12/D12, "") | H12: =SUM(Jul!H12, Aug!H12, Sep!H12) -> 0 | I12: =IFERROR(H12/G12, "")
A13: Clarksburg A | B13: MA | C13: =SUM(Jul!C13, Aug!C13, Sep!C13) -> 0 | D13: =SUM(Jul!D13, Aug!D13, Sep!D13) -> 0 | E13: =IF(AND(ISNUMBER(C13),ISNUMBER(D13)), C13-D13, "") -> 0 | F13: =IFERROR(E13/D13, "") | H13: =SUM(Jul!H13, Aug!H13, Sep!H13) -> 0 | I13: =IFERROR(H13/G13, "")
A14: Swansea B | B14: MA | C14: =SUM(Jul!C14, Aug!C14, Sep!C14) -> 0 | D14: =SUM(Jul!D14, Aug!D14, Sep!D14) -> 0 | E14: =IF(AND(ISNUMBER(C14),ISNUMBER(D14)), C14-D14, "") -> 0 | F14: =IFERROR(E14/D14, "") | H14: =SUM(Jul!H14, Aug!H14, Sep!H14) -> 0 | I14: =IFERROR(H14/G14, "")
A15: Wareham 2 | B15: MA | C15: =SUM(Jul!C15, Aug!C15, Sep!C15) -> 0 | D15: =SUM(Jul!D15, Aug!D15, Sep!D15) -> 0 | E15: =IF(AND(ISNUMBER(C15),ISNUMBER(D15)), C15-D15, "") -> 0 | F15: =IFERROR(E15/D15, "") | H15: =SUM(Jul!H15, Aug!H15, Sep!H15) -> 0 | I15: =IFERROR(H15/G15, "")
A16: Kingston 1 KB | B16: MA | C16: =SUM(Jul!C16, Aug!C16, Sep!C16) -> 0 | D16: =SUM(Jul!D16, Aug!D16, Sep!D16) -> 0 | E16: =IF(AND(ISNUMBER(C16),ISNUMBER(D16)), C16-D16, "") -> 0 | F16: =IFERROR(E16/D16, "") | H16: =SUM(Jul!H16, Aug!H16, Sep!H16) -> 0 | I16: =IFERROR(H16/G16, "")
... A20: Plympton A-2 | B20: MA | C20: =SUM(Jul!C20, Aug!C20, Sep!C20) -> 0 | D20: =SUM(Jul!D20, Aug!D20, Sep!D20) -> 0 | E20: =IF(AND(ISNUMBER(C20),ISNUMBER(D20)), C20-D20, "") -> 0 | F20: =IFERROR(E20/D20, "") | H20: =SUM(Jul!H20, Aug!H20, Sep!H20) -> 0 | I20: =IFERROR(H20/G20, "")

Sheet 4th Qtr
A1: {=portfolio} -> MN8 KEF | D1: 4th Quarter Actual v. Expected | G1: 4th Quarter Actual v. Forecasted
A2: Total | C2: =SUM(C4:C95) -> 0 | D2: =SUM(D4:D95) -> 0 | E2: =C2-D2 -> 0 | F2: =IFERROR(E2/D2, 0) -> 0 | G2: =SUM(G4:G95) -> 0 | H2: =C2-G2 -> 0 | I2: =IFERROR(H2/G2, 0) -> 0
A3: Site | B3: State | C3: Actual | D3: Expected | E3: Delta | F3: % | G3: Forecasted | H3: Delta | I3: %
A4: {=Sites[Site]} -> Williamsburg A | B4: {=Sites[State]} -> MA | C4: =SUM(Oct!C4, Nov!C4, Dec!C4) -> 0 | D4: =SUM(Oct!D4, Nov!D4, Dec!D4) -> 0 | E4: =IF(AND(ISNUMBER(C4),ISNUMBER(D4)), C4-D4, "") -> 0 | F4: =IFERROR(E4/D4, "") | H4: =SUM(Oct!H4, Nov!H4, Dec!H4) -> 0 | I4: =IFERROR(H4/G4, "")
A5: Orange A KB | B5: MA | C5: =SUM(Oct!C5, Nov!C5, Dec!C5) -> 0 | D5: =SUM(Oct!D5, Nov!D5, Dec!D5) -> 0 | E5: =IF(AND(ISNUMBER(C5),ISNUMBER(D5)), C5-D5, "") -> 0 | F5: =IFERROR(E5/D5, "") | H5: =SUM(Oct!H5, Nov!H5, Dec!H5) -> 0 | I5: =IFERROR(H5/G5, "")
A6: Goshen A | B6: MA | C6: =SUM(Oct!C6, Nov!C6, Dec!C6) -> 0 | D6: =SUM(Oct!D6, Nov!D6, Dec!D6) -> 0 | E6: =IF(AND(ISNUMBER(C6),ISNUMBER(D6)), C6-D6, "") -> 0 | F6: =IFERROR(E6/D6, "") | H6: =SUM(Oct!H6, Nov!H6, Dec!H6) -> 0 | I6: =IFERROR(H6/G6, "")
A7: Phillipston A KB | B7: MA | C7: =SUM(Oct!C7, Nov!C7, Dec!C7) -> 0 | D7: =SUM(Oct!D7, Nov!D7, Dec!D7) -> 0 | E7: =IF(AND(ISNUMBER(C7),ISNUMBER(D7)), C7-D7, "") -> 0 | F7: =IFERROR(E7/D7, "") | H7: =SUM(Oct!H7, Nov!H7, Dec!H7) -> 0 | I7: =IFERROR(H7/G7, "")
A8: Uxbridge D | B8: MA | C8: =SUM(Oct!C8, Nov!C8, Dec!C8) -> 0 | D8: =SUM(Oct!D8, Nov!D8, Dec!D8) -> 0 | E8: =IF(AND(ISNUMBER(C8),ISNUMBER(D8)), C8-D8, "") -> 0 | F8: =IFERROR(E8/D8, "") | H8: =SUM(Oct!H8, Nov!H8, Dec!H8) -> 0 | I8: =IFERROR(H8/G8, "")
A9: West Bridgewater A&B | B9: MA | C9: =SUM(Oct!C9, Nov!C9, Dec!C9) -> 0 | D9: =SUM(Oct!D9, Nov!D9, Dec!D9) -> 0 | E9: =IF(AND(ISNUMBER(C9),ISNUMBER(D9)), C9-D9, "") -> 0 | F9: =IFERROR(E9/D9, "") | H9: =SUM(Oct!H9, Nov!H9, Dec!H9) -> 0 | I9: =IFERROR(H9/G9, "")
A10: Sutton A | B10: MA | C10: =SUM(Oct!C10, Nov!C10, Dec!C10) -> 0 | D10: =SUM(Oct!D10, Nov!D10, Dec!D10) -> 0 | E10: =IF(AND(ISNUMBER(C10),ISNUMBER(D10)), C10-D10, "") -> 0 | F10: =IFERROR(E10/D10, "") | H10: =SUM(Oct!H10, Nov!H10, Dec!H10) -> 0 | I10: =IFERROR(H10/G10, "")
A11: North Adams A | B11: MA | C11: =SUM(Oct!C11, Nov!C11, Dec!C11) -> 0 | D11: =SUM(Oct!D11, Nov!D11, Dec!D11) -> 0 | E11: =IF(AND(ISNUMBER(C11),ISNUMBER(D11)), C11-D11, "") -> 0 | F11: =IFERROR(E11/D11, "") | H11: =SUM(Oct!H11, Nov!H11, Dec!H11) -> 0 | I11: =IFERROR(H11/G11, "")
A12: North Adams B | B12: MA | C12: =SUM(Oct!C12, Nov!C12, Dec!C12) -> 0 | D12: =SUM(Oct!D12, Nov!D12, Dec!D12) -> 0 | E12: =IF(AND(ISNUMBER(C12),ISNUMBER(D12)), C12-D12, "") -> 0 | F12: =IFERROR(E12/D12, "") | H12: =SUM(Oct!H12, Nov!H12, Dec!H12) -> 0 | I12: =IFERROR(H12/G12, "")
A13: Clarksburg A | B13: MA | C13: =SUM(Oct!C13, Nov!C13, Dec!C13) -> 0 | D13: =SUM(Oct!D13, Nov!D13, Dec!D13) -> 0 | E13: =IF(AND(ISNUMBER(C13),ISNUMBER(D13)), C13-D13, "") -> 0 | F13: =IFERROR(E13/D13, "") | H13: =SUM(Oct!H13, Nov!H13, Dec!H13) -> 0 | I13: =IFERROR(H13/G13, "")
A14: Swansea B | B14: MA | C14: =SUM(Oct!C14, Nov!C14, Dec!C14) -> 0 | D14: =SUM(Oct!D14, Nov!D14, Dec!D14) -> 0 | E14: =IF(AND(ISNUMBER(C14),ISNUMBER(D14)), C14-D14, "") -> 0 | F14: =IFERROR(E14/D14, "") | H14: =SUM(Oct!H14, Nov!H14, Dec!H14) -> 0 | I14: =IFERROR(H14/G14, "")
A15: Wareham 2 | B15: MA | C15: =SUM(Oct!C15, Nov!C15, Dec!C15) -> 0 | D15: =SUM(Oct!D15, Nov!D15, Dec!D15) -> 0 | E15: =IF(AND(ISNUMBER(C15),ISNUMBER(D15)), C15-D15, "") -> 0 | F15: =IFERROR(E15/D15, "") | H15: =SUM(Oct!H15, Nov!H15, Dec!H15) -> 0 | I15: =IFERROR(H15/G15, "")
A16: Kingston 1 KB | B16: MA | C16: =SUM(Oct!C16, Nov!C16, Dec!C16) -> 0 | D16: =SUM(Oct!D16, Nov!D16, Dec!D16) -> 0 | E16: =IF(AND(ISNUMBER(C16),ISNUMBER(D16)), C16-D16, "") -> 0 | F16: =IFERROR(E16/D16, "") | H16: =SUM(Oct!H16, Nov!H16, Dec!H16) -> 0 | I16: =IFERROR(H16/G16, "")
... A20: Plympton A-2 | B20: MA | C20: =SUM(Oct!C20, Nov!C20, Dec!C20) -> 0 | D20: =SUM(Oct!D20, Nov!D20, Dec!D20) -> 0 | E20: =IF(AND(ISNUMBER(C20),ISNUMBER(D20)), C20-D20, "") -> 0 | F20: =IFERROR(E20/D20, "") | H20: =SUM(Oct!H20, Nov!H20, Dec!H20) -> 0 | I20: =IFERROR(H20/G20, "")

Sheet Jan
A1: {=portfolio} -> MN8 KEF | D1: January Actual v. Expected | G1: January Actual v. Forecasted
A2: Total | C2: =SUM(C4:C94) -> 779580.43 | D2: =SUM(D4:D94) -> 1198900 | E2: =C2-D2 -> -419319.56 | F2: =IFERROR(E2/D2, 0) -> -0.34975358 | G2: =SUM(G4:G94) -> 1598697.1 | H2: =C2-G2 -> -819116.63 | I2: =IFERROR(H2/G2, 0) -> -0.51236513 | J2: =IF(AND(TODAY()>DATE(2024, 1, 1), COUNTA(Sites[Site])<>(COUNT(C:C)-1)), "Some sites are missing actual data; if new sites were added, make sure they are aligned correctly (including prior months!)", "")
A3: Site | B3: State | C3: Actual | D3: Expected | E3: Delta | F3: % | G3: Forecasted | H3: Delta | I3: % | J3: Notes | K3: Service Requests
A4: {=Sites[Site]} -> Williamsburg A | B4: {=Sites[State]} -> MA | C4: 34976.74 | D4: 63711.84 | E4: =IF(AND(ISNUMBER(C4),ISNUMBER(D4)), C4-D4, "") -> -28735.1 | F4: =IFERROR(E4/D4, "") -> -0.45101663 | G4: 96254.79 | H4: =IF(AND(ISNUMBER(C4),ISNUMBER(G4)), C4-G4, "") -> -61278.05 | I4: =IFERROR(H4/G4, "") -> -0.63662338
A5: Orange A KB | B5: MA | C5: 36812.441 | D5: 50249.95 | E5: =IF(AND(ISNUMBER(C5),ISNUMBER(D5)), C5-D5, "") -> -13437.509 | F5: =IFERROR(E5/D5, "") -> -0.26741337 | G5: 78902.03 | H5: =IF(AND(ISNUMBER(C5),ISNUMBER(G5)), C5-G5, "") -> -42089.589 | I5: =IFERROR(H5/G5, "") -> -0.53344114 | J5: 1. Site tripped offline on 01/13 multiple times early in the morningand auto-closed shortly after | K5: 1. SR080185
A6: Goshen A | B6: MA | C6: 25506 | D6: 57487.3 | E6: =IF(AND(ISNUMBER(C6),ISNUMBER(D6)), C6-D6, "") -> -31981.3 | F6: =IFERROR(E6/D6, "") -> -0.5563194 | G6: 45574.37 | H6: =IF(AND(ISNUMBER(C6),ISNUMBER(G6)), C6-G6, "") -> -20068.37 | I6: =IFERROR(H6/G6, "") -> -0.44034333 | J6: 1. Site tripped on 01/14 at 14:30 and later back online on 01/15 at 10:00AM 2. Site tripped offline on 01/25 at 11:06AM and later back online 01/25 at 11:27AM. | K6: 1. SR080209 2. SR080465
A7: Phillipston A KB | B7: MA | C7: 28771 | D7: 81174.38 | E7: =IF(AND(ISNUMBER(C7),ISNUMBER(D7)), C7-D7, "") -> -52403.38 | F7: =IFERROR(E7/D7, "") -> -0.64556551 | G7: 48828.99 | H7: =IF(AND(ISNUMBER(C7),ISNUMBER(G7)), C7-G7, "") -> -20057.99 | I7: =IFERROR(H7/G7, "") -> -0.41078036
A8: Uxbridge D | B8: MA | C8: 42944 | D8: 75174.5 | E8: =IF(AND(ISNUMBER(C8),ISNUMBER(D8)), C8-D8, "") -> -32230.5 | F8: =IFERROR(E8/D8, "") -> -0.42874246 | G8: 103260 | H8: =IF(AND(ISNUMBER(C8),ISNUMBER(G8)), C8-G8, "") -> -60316 | I8: =IFERROR(H8/G8, "") -> -0.58411776
A9: West Bridgewater A&B | B9: MA | C9: 84322 | D9: 126671.7 | E9: =IF(AND(ISNUMBER(C9),ISNUMBER(D9)), C9-D9, "") -> -42349.7 | F9: =IFERROR(E9/D9, "") -> -0.33432645 | G9: 169067.9 | H9: =IF(AND(ISNUMBER(C9),ISNUMBER(G9)), C9-G9, "") -> -84745.9 | I9: =IFERROR(H9/G9, "") -> -0.50125364
A10: Sutton A | B10: MA | C10: 30226 | D10: 57946.25 | E10: =IF(AND(ISNUMBER(C10),ISNUMBER(D10)), C10-D10, "") -> -27720.25 | F10: =IFERROR(E10/D10, "") -> -0.47837867 | G10: 93432.82 | H10: =IF(AND(ISNUMBER(C10),ISNUMBER(G10)), C10-G10, "") -> -63206.82 | I10: =IFERROR(H10/G10, "") -> -0.67649483
A11: North Adams A | B11: MA | C11: 33659 | D11: 55008.74 | E11: =IF(AND(ISNUMBER(C11),ISNUMBER(D11)), C11-D11, "") -> -21349.74 | F11: =IFERROR(E11/D11, "") -> -0.38811542 | G11: 98462.86 | H11: =IF(AND(ISNUMBER(C11),ISNUMBER(G11)), C11-G11, "") -> -64803.86 | I11: =IFERROR(H11/G11, "") -> -0.65815537 | J11: 1. Inverter 3.3 is offline on 01/13 at 07:00AM, later back online on 01/13 at 12:45PM and tripping on and off multiple days on and off. | K11: 1. SR080193
A12: North Adams B | B12: MA | C12: 25714 | D12: 47004.33 | E12: =IF(AND(ISNUMBER(C12),ISNUMBER(D12)), C12-D12, "") -> -21290.33 | F12: =IFERROR(E12/D12, "") -> -0.45294402 | G12: 98462.86 | H12: =IF(AND(ISNUMBER(C12),ISNUMBER(G12)), C12-G12, "") -> -72748.86 | I12: =IFERROR(H12/G12, "") -> -0.73884569
A13: Clarksburg A | B13: MA | C13: 25169 | D13: 48116.73 | E13: =IF(AND(ISNUMBER(C13),ISNUMBER(D13)), C13-D13, "") -> -22947.73 | F13: =IFERROR(E13/D13, "") -> -0.4769179 | G13: 98015.59 | H13: =IF(AND(ISNUMBER(C13),ISNUMBER(G13)), C13-G13, "") -> -72846.59 | I13: =IFERROR(H13/G13, "") -> -0.74321432
A14: Swansea B | B14: MA | C14: 54645 | D14: 81330.64 | E14: =IF(AND(ISNUMBER(C14),ISNUMBER(D14)), C14-D14, "") -> -26685.64 | F14: =IFERROR(E14/D14, "") -> -0.328113 | G14: 50080.16 | H14: =IF(AND(ISNUMBER(C14),ISNUMBER(G14)), C14-G14, "") -> 4564.84 | I14: =IFERROR(H14/G14, "") -> 0.091150667 | J14: 1. Site tripped offline on 01/29 at 16:00 and later back online on 01/30 at 11:15AM. | K14: 1. SR080590
A15: Wareham 2 | B15: MA | C15: 59387.25 | D15: 65302.43 | E15: =IF(AND(ISNUMBER(C15),ISNUMBER(D15)), C15-D15, "") -> -5915.18 | F15: =IFERROR(E15/D15, "") -> -0.090581315 | G15: 103231.1 | H15: =IF(AND(ISNUMBER(C15),ISNUMBER(G15)), C15-G15, "") -> -43843.85 | I15: =IFERROR(H15/G15, "") -> -0.42471552
A16: Kingston 1 KB | B16: MA | C16: 46172 | D16: 64095.79 | E16: =IF(AND(ISNUMBER(C16),ISNUMBER(D16)), C16-D16, "") -> -17923.79 | F16: =IFERROR(E16/D16, "") -> -0.27964068 | G16: 78554.16 | H16: =IF(AND(ISNUMBER(C16),ISNUMBER(G16)), C16-G16, "") -> -32382.16 | I16: =IFERROR(H16/G16, "") -> -0.41222718 | J16: 1. Site tripped on 01/14 at 16:45 and later back online on 01/15 at 14:30. 2. Site tripped offline due to utility outage on 01/16 at 11:30AM and utility cleared outage on 01/18 at 07:45AM. | K16: 1. SR080216 2. SR080258
A17: Kingston 2 KB | B17: MA | C17: 38326 | D17: 38638.25 | E17: =IF(AND(ISNUMBER(C17),ISNUMBER(D17)), C17-D17, "") -> -312.25 | F17: =IFERROR(E17/D17, "") -> -0.0080813701 | G17: 63052.82 | H17: =IF(AND(ISNUMBER(C17),ISNUMBER(G17)), C17-G17, "") -> -24726.82 | I17: =IFERROR(H17/G17, "") -> -0.39216041 | J17: 1. Site tripped on 01/14 at 16:45 and later back online on 01/15 at 14:30. 2. Site tripped offline due to utility outage on 01/16 at 11:30AM and utility cleared outage on 01/18 at 07:45AM. | K17: 1. SR080217 2. SR080259
A18: Holliston B | B18: MA | C18: 32229 | D18: 61034.62 | E18: =IF(AND(ISNUMBER(C18),ISNUMBER(D18)), C18-D18, "") -> -28805.62 | F18: =IFERROR(E18/D18, "") -> -0.47195542 | G18: 98146.17 | H18: =IF(AND(ISNUMBER(C18),ISNUMBER(G18)), C18-G18, "") -> -65917.17 | I18: =IFERROR(H18/G18, "") -> -0.67162244
A19: Fairhaven C | B19: MA | C19: 120080 | D19: 148303.4 | E19: =IF(AND(ISNUMBER(C19),ISNUMBER(D19)), C19-D19, "") -> -28223.4 | F19: =IFERROR(E19/D19, "") -> -0.19030852 | G19: 176726.2 | H19: =IF(AND(ISNUMBER(C19),ISNUMBER(G19)), C19-G19, "") -> -56646.2 | I19: =IFERROR(H19/G19, "") -> -0.32053086 | J19: 1. Site tripped offline on 01/11 at 07:00AM and later back online on 01/12 at 07:45AM. 2. Inverter 47 was offline after site re-energize the site on 01/12 and back online on 14:15. | K19: 1. SR080149 2. SR080171
A20: Plympton A-2 | B20: MA | C20: 60641 | D20: 77649.14 | E20: =IF(AND(ISNUMBER(C20),ISNUMBER(D20)), C20-D20, "") -> -17008.14 | F20: =IFERROR(E20/D20, "") -> -0.21903836 | G20: 98644.24 | H20: =IF(AND(ISNUMBER(C20),ISNUMBER(G20)), C20-G20, "") -> -38003.24 | I20: =IFERROR(H20/G20, "") -> -0.38525554 | J20: 1. Site tripped offline on 01/10 at 03:26AM and later back online on 01/10 at 06:24AM. | K20: 1. SR080115

Sheet Feb
A1: {=portfolio} -> MN8 KEF | D1: February Actual v. Expected | G1: February Actual v. Forecasted
A2: Total | C2: =SUM(C4:C95) -> 1996105.2 | D2: =SUM(D4:D95) -> 2188725.1 | E2: =C2-D2 -> -192619.87 | F2: =IFERROR(E2/D2, 0) -> -0.088005511 | G2: =SUM(G4:G95) -> 1959995.2 | H2: =C2-G2 -> 36110.04 | I2: =IFERROR(H2/G2, 0) -> 0.018423535 | J2: =IF(AND(TODAY()>DATE(2024, 2, 1), COUNTA(Sites[Site])<>(COUNT(C:C)-1)), "Some sites are missing actual data; if new sites were added, make sure they are aligned correctly (including prior months!)", "")
A3: Site | B3: State | C3: Actual | D3: Expected | E3: Delta | F3: % | G3: Forecasted | H3: Delta | I3: % | J3: Notes | K3: Service Requests
A4: {=Sites[Site]} -> Williamsburg A | B4: {=Sites[State]} -> MA | C4: 129427.32 | D4: 137302.4 | E4: =IF(AND(ISNUMBER(C4),ISNUMBER(D4)), C4-D4, "") -> -7875.0767 | F4: =IFERROR(E4/D4, "") -> -0.057355711 | G4: 113866 | H4: =IF(AND(ISNUMBER(C4),ISNUMBER(G4)), C4-G4, "") -> 15561.323 | I4: =IFERROR(H4/G4, "") -> 0.13666348
A5: Orange A KB | B5: MA | C5: 103151.89 | D5: 104286.4 | E5: =IF(AND(ISNUMBER(C5),ISNUMBER(D5)), C5-D5, "") -> -1134.5128 | F5: =IFERROR(E5/D5, "") -> -0.010878819 | G5: 95699.56 | H5: =IF(AND(ISNUMBER(C5),ISNUMBER(G5)), C5-G5, "") -> 7452.3272 | I5: =IFERROR(H5/G5, "") -> 0.077872115 | J5: 1. Inverters 1.01 & 1.02 tripped offline on 02/28 at 10:00 AM and resolved at 11:30AM | K5: 1. SR081451
A6: Goshen A | B6: MA | C6: 115740 | D6: 124956.1 | E6: =IF(AND(ISNUMBER(C6),ISNUMBER(D6)), C6-D6, "") -> -9216.1 | F6: =IFERROR(E6/D6, "") -> -0.073754703 | G6: 59464.02 | H6: =IF(AND(ISNUMBER(C6),ISNUMBER(G6)), C6-G6, "") -> 56275.98 | I6: =IFERROR(H6/G6, "") -> 0.94638708 | J6: 1. Site offline on 02/16 at 04:45AM and back online at 10:15 2. Site offline on 02/20 at 18:30 and back online on 02/21 at 08:15AM | K6: 1. SR081034 2. SR081141
A7: Phillipston A KB | B7: MA | C7: 119297 | D7: 156008.8 | E7: =IF(AND(ISNUMBER(C7),ISNUMBER(D7)), C7-D7, "") -> -36711.8 | F7: =IFERROR(E7/D7, "") -> -0.23531878 | G7: 69074.69 | H7: =IF(AND(ISNUMBER(C7),ISNUMBER(G7)), C7-G7, "") -> 50222.31 | I7: =IFERROR(H7/G7, "") -> 0.72707254
A8: Uxbridge D | B8: MA | C8: 130995 | D8: 137973 | E8: =IF(AND(ISNUMBER(C8),ISNUMBER(D8)), C8-D8, "") -> -6978 | F8: =IFERROR(E8/D8, "") -> -0.050575113 | G8: 125233.8 | H8: =IF(AND(ISNUMBER(C8),ISNUMBER(G8)), C8-G8, "") -> 5761.2 | I8: =IFERROR(H8/G8, "") -> 0.046003555
A9: West Bridgewater A&B | B9: MA | C9: 191715 | D9: 209729.7 | E9: =IF(AND(ISNUMBER(C9),ISNUMBER(D9)), C9-D9, "") -> -18014.7 | F9: =IFERROR(E9/D9, "") -> -0.085894845 | G9: 203452.8 | H9: =IF(AND(ISNUMBER(C9),ISNUMBER(G9)), C9-G9, "") -> -11737.8 | I9: =IFERROR(H9/G9, "") -> -0.057692988
A10: Sutton A | B10: MA | C10: 95646 | D10: 114772 | E10: =IF(AND(ISNUMBER(C10),ISNUMBER(D10)), C10-D10, "") -> -19126 | F10: =IFERROR(E10/D10, "") -> -0.16664343 | G10: 115682.6 | H10: =IF(AND(ISNUMBER(C10),ISNUMBER(G10)), C10-G10, "") -> -20036.6 | I10: =IFERROR(H10/G10, "") -> -0.17320323
A11: North Adams A | B11: MA | C11: 112525 | D11: 120744.9 | E11: =IF(AND(ISNUMBER(C11),ISNUMBER(D11)), C11-D11, "") -> -8219.9 | F11: =IFERROR(E11/D11, "") -> -0.068076581 | G11: 119388.7 | H11: =IF(AND(ISNUMBER(C11),ISNUMBER(G11)), C11-G11, "") -> -6863.7 | I11: =IFERROR(H11/G11, "") -> -0.057490366 | J11: 1. Inverter 3.3 is offline on 02/02 and back online on 02/03 at 07:00AM and tripping on and off multiple days on and off. | K11: 1. SR080193
A12: North Adams B | B12: MA | C12: 107095 | D12: 104225.4 | E12: =IF(AND(ISNUMBER(C12),ISNUMBER(D12)), C12-D12, "") -> 2869.6 | F12: =IFERROR(E12/D12, "") -> 0.027532636 | G12: 119388.7 | H12: =IF(AND(ISNUMBER(C12),ISNUMBER(G12)), C12-G12, "") -> -12293.7 | I12: =IFERROR(H12/G12, "") -> -0.10297206
A13: Clarksburg A | B13: MA | C13: 116505 | D13: 117091.1 | E13: =IF(AND(ISNUMBER(C13),ISNUMBER(D13)), C13-D13, "") -> -586.1 | F13: =IFERROR(E13/D13, "") -> -0.0050055043 | G13: 118846.2 | H13: =IF(AND(ISNUMBER(C13),ISNUMBER(G13)), C13-G13, "") -> -2341.2 | I13: =IFERROR(H13/G13, "") -> -0.01969941
A14: Swansea B | B14: MA | C14: 117946 | D14: 130137.5 | E14: =IF(AND(ISNUMBER(C14),ISNUMBER(D14)), C14-D14, "") -> -12191.5 | F14: =IFERROR(E14/D14, "") -> -0.093681683 | G14: 66792.55 | H14: =IF(AND(ISNUMBER(C14),ISNUMBER(G14)), C14-G14, "") -> 51153.45 | I14: =IFERROR(H14/G14, "") -> 0.76585562
A15: Wareham 2 | B15: MA | C15: 88759 | D15: 98078.5 | E15: =IF(AND(ISNUMBER(C15),ISNUMBER(D15)), C15-D15, "") -> -9319.5 | F15: =IFERROR(E15/D15, "") -> -0.095020825 | G15: 123998.2 | H15: =IF(AND(ISNUMBER(C15),ISNUMBER(G15)), C15-G15, "") -> -35239.2 | I15: =IFERROR(H15/G15, "") -> -0.28419122 | J15: 1. Site is offline due to utility outage On 02/13 at 14:30PM and back online on 02/14 at 09:00AM | K15: 1. SR080991
A16: Kingston 1 KB | B16: MA | C16: 90493 | D16: 102655.2 | E16: =IF(AND(ISNUMBER(C16),ISNUMBER(D16)), C16-D16, "") -> -12162.2 | F16: =IFERROR(E16/D16, "") -> -0.11847622 | G16: 97249.23 | H16: =IF(AND(ISNUMBER(C16),ISNUMBER(G16)), C16-G16, "") -> -6756.23 | I16: =IFERROR(H16/G16, "") -> -0.069473352 | J16: 1. Inverter 3.3 is offline on 02/16 at 12:45 and back online on 02/20 at 06:15AM. 2. Inverter 3.3 tripped offline on 02/24 at 14:00PM and back online on 02/25 3. Inverter 3.3 tripped offline on 02/28 at 10:45AM and back online at EOD and again tripped offline at 10:15 on 02/29 | K16: 1. SR081063 2. SR081294 3. SR081405
A17: Kingston 2 KB | B17: MA | C17: 76899 | D17: 66380.18 | E17: =IF(AND(ISNUMBER(C17),ISNUMBER(D17)), C17-D17, "") -> 10518.82 | F17: =IFERROR(E17/D17, "") -> 0.15846326 | G17: 78058.62 | H17: =IF(AND(ISNUMBER(C17),ISNUMBER(G17)), C17-G17, "") -> -1159.62 | I17: =IFERROR(H17/G17, "") -> -0.014855758 | J17: 1. Inverter 5.1 tripped offline from 02/28 at 11:15 | K17: 1. SR081422
A18: Holliston B | B18: MA | C18: 111207 | D18: 124683.7 | E18: =IF(AND(ISNUMBER(C18),ISNUMBER(D18)), C18-D18, "") -> -13476.7 | F18: =IFERROR(E18/D18, "") -> -0.1080871 | G18: 121518 | H18: =IF(AND(ISNUMBER(C18),ISNUMBER(G18)), C18-G18, "") -> -10311 | I18: =IFERROR(H18/G18, "") -> -0.084851627
A19: Fairhaven C | B19: MA | C19: 187036 | D19: 219891.7 | E19: =IF(AND(ISNUMBER(C19),ISNUMBER(D19)), C19-D19, "") -> -32855.7 | F19: =IFERROR(E19/D19, "") -> -0.14941765 | G19: 212087.3 | H19: =IF(AND(ISNUMBER(C19),ISNUMBER(G19)), C19-G19, "") -> -25051.3 | I19: =IFERROR(H19/G19, "") -> -0.11811787 | J19: 1. Inverter 47 derating after 10 am on sunny days. Possible fan issue. | K19: 1. SR081128
A20: Plympton A-2 | B20: MA | C20: 101668 | D20: 119808.5 | E20: =IF(AND(ISNUMBER(C20),ISNUMBER(D20)), C20-D20, "") -> -18140.5 | F20: =IFERROR(E20/D20, "") -> -0.15141246 | G20: 120194.2 | H20: =IF(AND(ISNUMBER(C20),ISNUMBER(G20)), C20-G20, "") -> -18526.2 | I20: =IFERROR(H20/G20, "") -> -0.15413556

Sheet Mar
A1: {=portfolio} -> MN8 KEF | D1: March Actual v. Expected | G1: March Actual v. Forecasted
A2: Total | C2: =SUM(C4:C95) -> 2286213.4 | D2: =SUM(D4:D95) -> 2355311.8 | E2: =C2-D2 -> -69098.442 | F2: =IFERROR(E2/D2, 0) -> -0.02933728 | G2: =SUM(G4:G95) -> 2573917.3 | H2: =C2-G2 -> -287703.9 | I2: =IFERROR(H2/G2, 0) -> -0.11177667 | J2: =IF(AND(TODAY()>DATE(2024, 3, 1), COUNTA(Sites[Site])<>(COUNT(C:C)-1)), "Some sites are missing actual data; if new sites were added, make sure they are aligned correctly (including prior months!)", "")
A3: Site | B3: State | C3: Actual | D3: Expected | E3: Delta | F3: % | G3: Forecasted | H3: Delta | I3: % | J3: Notes | K3: Service Requests
A4: {=Sites[Site]} -> Williamsburg A | B4: {=Sites[State]} -> MA | C4: 135110.03 | D4: 142317.5 | E4: =IF(AND(ISNUMBER(C4),ISNUMBER(D4)), C4-D4, "") -> -7207.4695 | F4: =IFERROR(E4/D4, "") -> -0.050643592 | G4: 148092.7 | H4: =IF(AND(ISNUMBER(C4),ISNUMBER(G4)), C4-G4, "") -> -12982.669 | I4: =IFERROR(H4/G4, "") -> -0.08766583
A5: Orange A KB | B5: MA | C5: 107315.37 | D5: 104368.1 | E5: =IF(AND(ISNUMBER(C5),ISNUMBER(D5)), C5-D5, "") -> 2947.2672 | F5: =IFERROR(E5/D5, "") -> 0.028239157 | G5: 123550.3 | H5: =IF(AND(ISNUMBER(C5),ISNUMBER(G5)), C5-G5, "") -> -16234.933 | I5: =IFERROR(H5/G5, "") -> -0.13140343
A6: Goshen A | B6: MA | C6: 120599 | D6: 126112.1 | E6: =IF(AND(ISNUMBER(C6),ISNUMBER(D6)), C6-D6, "") -> -5513.1 | F6: =IFERROR(E6/D6, "") -> -0.043715869 | G6: 86049.77 | H6: =IF(AND(ISNUMBER(C6),ISNUMBER(G6)), C6-G6, "") -> 34549.23 | I6: =IFERROR(H6/G6, "") -> 0.40150287 | J6: 1. Relay tripped offline but voltages are available on 03/23 at 17:00 and back online at 13:00 on 03/24 | K6: 1. SR082602
A7: Phillipston A KB | B7: MA | C7: 134199 | D7: 158262 | E7: =IF(AND(ISNUMBER(C7),ISNUMBER(D7)), C7-D7, "") -> -24063 | F7: =IFERROR(E7/D7, "") -> -0.15204534 | G7: 100406 | H7: =IF(AND(ISNUMBER(C7),ISNUMBER(G7)), C7-G7, "") -> 33793 | I7: =IFERROR(H7/G7, "") -> 0.33656355 | J7: 1. The relay tripped at 6:08PM and auto-closed within five minutes. | K7: 1. SR082604
A8: Uxbridge D | B8: MA | C8: 138288 | D8: 143309.9 | E8: =IF(AND(ISNUMBER(C8),ISNUMBER(D8)), C8-D8, "") -> -5021.9 | F8: =IFERROR(E8/D8, "") -> -0.035042241 | G8: 161683.6 | H8: =IF(AND(ISNUMBER(C8),ISNUMBER(G8)), C8-G8, "") -> -23395.6 | I8: =IFERROR(H8/G8, "") -> -0.1446999
A9: West Bridgewater A&B | B9: MA | C9: 217285 | D9: 229620.8 | E9: =IF(AND(ISNUMBER(C9),ISNUMBER(D9)), C9-D9, "") -> -12335.8 | F9: =IFERROR(E9/D9, "") -> -0.053722485 | G9: 266918.5 | H9: =IF(AND(ISNUMBER(C9),ISNUMBER(G9)), C9-G9, "") -> -49633.5 | I9: =IFERROR(H9/G9, "") -> -0.18595002
A10: Sutton A | B10: MA | C10: 125601 | D10: 129677.7 | E10: =IF(AND(ISNUMBER(C10),ISNUMBER(D10)), C10-D10, "") -> -4076.7 | F10: =IFERROR(E10/D10, "") -> -0.031437171 | G10: 152217.9 | H10: =IF(AND(ISNUMBER(C10),ISNUMBER(G10)), C10-G10, "") -> -26616.9 | I10: =IFERROR(H10/G10, "") -> -0.17486051
A11: North Adams A | B11: MA | C11: 112601 | D11: 118763.1 | E11: =IF(AND(ISNUMBER(C11),ISNUMBER(D11)), C11-D11, "") -> -6162.1 | F11: =IFERROR(E11/D11, "") -> -0.051885645 | G11: 145854.3 | H11: =IF(AND(ISNUMBER(C11),ISNUMBER(G11)), C11-G11, "") -> -33253.3 | I11: =IFERROR(H11/G11, "") -> -0.22798985 | J11: 1. Inverter 3.3 is offline on 03/04 and back online at 14:00 on 03/04 and again offline on 03/05 and back online on 03/06 at 10:30am. | K11: 1. SR080193
A12: North Adams B | B12: MA | C12: 108271 | D12: 103121.8 | E12: =IF(AND(ISNUMBER(C12),ISNUMBER(D12)), C12-D12, "") -> 5149.2 | F12: =IFERROR(E12/D12, "") -> 0.049933186 | G12: 145854.3 | H12: =IF(AND(ISNUMBER(C12),ISNUMBER(G12)), C12-G12, "") -> -37583.3 | I12: =IFERROR(H12/G12, "") -> -0.25767701
A13: Clarksburg A | B13: MA | C13: 111902 | D13: 115432.6 | E13: =IF(AND(ISNUMBER(C13),ISNUMBER(D13)), C13-D13, "") -> -3530.6 | F13: =IFERROR(E13/D13, "") -> -0.030585814 | G13: 145191.2 | H13: =IF(AND(ISNUMBER(C13),ISNUMBER(G13)), C13-G13, "") -> -33289.2 | I13: =IFERROR(H13/G13, "") -> -0.22927836
A14: Swansea B | B14: MA | C14: 146083 | D14: 149943.2 | E14: =IF(AND(ISNUMBER(C14),ISNUMBER(D14)), C14-D14, "") -> -3860.2 | F14: =IFERROR(E14/D14, "") -> -0.025744415 | G14: 102081.6 | H14: =IF(AND(ISNUMBER(C14),ISNUMBER(G14)), C14-G14, "") -> 44001.4 | I14: =IFERROR(H14/G14, "") -> 0.43104144
A15: Wareham 2 | B15: MA | C15: 123608 | D15: 123630.8 | E15: =IF(AND(ISNUMBER(C15),ISNUMBER(D15)), C15-D15, "") -> -22.8 | F15: =IFERROR(E15/D15, "") -> -0.00018442006 | G15: 168325.4 | H15: =IF(AND(ISNUMBER(C15),ISNUMBER(G15)), C15-G15, "") -> -44717.4 | I15: =IFERROR(H15/G15, "") -> -0.26566044
A16: Kingston 1 KB | B16: MA | C16: 109697 | D16: 113352.4 | E16: =IF(AND(ISNUMBER(C16),ISNUMBER(D16)), C16-D16, "") -> -3655.4 | F16: =IFERROR(E16/D16, "") -> -0.032248104 | G16: 121507.6 | H16: =IF(AND(ISNUMBER(C16),ISNUMBER(G16)), C16-G16, "") -> -11810.6 | I16: =IFERROR(H16/G16, "") -> -0.097200504
A17: Kingston 2 KB | B17: MA | C17: 89967 | D17: 75090.14 | E17: =IF(AND(ISNUMBER(C17),ISNUMBER(D17)), C17-D17, "") -> 14876.86 | F17: =IFERROR(E17/D17, "") -> 0.19812002 | G17: 97530.33 | H17: =IF(AND(ISNUMBER(C17),ISNUMBER(G17)), C17-G17, "") -> -7563.33 | I17: =IFERROR(H17/G17, "") -> -0.077548492
A18: Holliston B | B18: MA | C18: 138307 | D18: 138459.5 | E18: =IF(AND(ISNUMBER(C18),ISNUMBER(D18)), C18-D18, "") -> -152.5 | F18: =IFERROR(E18/D18, "") -> -0.0011014051 | G18: 159875.6 | H18: =IF(AND(ISNUMBER(C18),ISNUMBER(G18)), C18-G18, "") -> -21568.6 | I18: =IFERROR(H18/G18, "") -> -0.13490864
A19: Fairhaven C | B19: MA | C19: 235520 | D19: 250903.4 | E19: =IF(AND(ISNUMBER(C19),ISNUMBER(D19)), C19-D19, "") -> -15383.4 | F19: =IFERROR(E19/D19, "") -> -0.061312043 | G19: 289415.4 | H19: =IF(AND(ISNUMBER(C19),ISNUMBER(G19)), C19-G19, "") -> -53895.4 | I19: =IFERROR(H19/G19, "") -> -0.1862216
A20: Plympton A-2 | B20: MA | C20: 131860 | D20: 132946.8 | E20: =IF(AND(ISNUMBER(C20),ISNUMBER(D20)), C20-D20, "") -> -1086.8 | F20: =IFERROR(E20/D20, "") -> -0.0081746985 | G20: 159362.8 | H20: =IF(AND(ISNUMBER(C20),ISNUMBER(G20)), C20-G20, "") -> -27502.8 | I20: =IFERROR(H20/G20, "") -> -0.1725798

Sheet Apr
A1: {=portfolio} -> MN8 KEF | D1: April Actual v. Expected | G1: April Actual v. Forecasted
A2: Total | C2: =SUM(C4:C95) -> 2539049 | D2: =SUM(D4:D95) -> 2586916.6 | E2: =C2-D2 -> -47867.547 | F2: =IFERROR(E2/D2, 0) -> -0.018503707 | G2: =SUM(G4:G95) -> 2858064.4 | H2: =C2-G2 -> -319015.36 | I2: =IFERROR(H2/G2, 0) -> -0.11161937 | J2: =IF(AND(TODAY()>DATE(2024, 4, 1), COUNTA(Sites[Site])<>(COUNT(C:C)-1)), "Some sites are missing actual data; if new sites were added, make sure they are aligned correctly (including prior months!)", "")
A3: Site | B3: State | C3: Actual | D3: Expected | E3: Delta | F3: % | G3: Forecasted | H3: Delta | I3: % | J3: Notes | K3: Service Requests
A4: {=Sites[Site]} -> Williamsburg A | B4: {=Sites[State]} -> MA | C4: 143258.01 | D4: 148127.5 | E4: =IF(AND(ISNUMBER(C4),ISNUMBER(D4)), C4-D4, "") -> -4869.4928 | F4: =IFERROR(E4/D4, "") -> -0.032873658 | G4: 168203.5 | H4: =IF(AND(ISNUMBER(C4),ISNUMBER(G4)), C4-G4, "") -> -24945.493 | I4: =IFERROR(H4/G4, "") -> -0.14830543 | J4: 1. Inverter 1.3 tripped offline on 04/05 at 10:24 and back online at 14:17 | K4: 1. SR083119
A5: Orange A KB | B5: MA | C5: 115631.34 | D5: 109834.3 | E5: =IF(AND(ISNUMBER(C5),ISNUMBER(D5)), C5-D5, "") -> 5797.0356 | F5: =IFERROR(E5/D5, "") -> 0.052779829 | G5: 126717.1 | H5: =IF(AND(ISNUMBER(C5),ISNUMBER(G5)), C5-G5, "") -> -11085.764 | I5: =IFERROR(H5/G5, "") -> -0.08748436 | J5: 1. Site was taken offline by technician on 04/22 between 07:45 to 08:45 | K5: 1. PM 2694
A6: Goshen A | B6: MA | C6: 129214 | D6: 130471 | E6: =IF(AND(ISNUMBER(C6),ISNUMBER(D6)), C6-D6, "") -> -1257 | F6: =IFERROR(E6/D6, "") -> -0.0096343249 | G6: 106261 | H6: =IF(AND(ISNUMBER(C6),ISNUMBER(G6)), C6-G6, "") -> 22953 | I6: =IFERROR(H6/G6, "") -> 0.21600587 | J6: 1. Site was taken offline by technician on 04/11 between 08:15am to 09:00am | K6: 1. PM 2695
A7: Phillipston A KB | B7: MA | C7: 142454 | D7: 156407.6 | E7: =IF(AND(ISNUMBER(C7),ISNUMBER(D7)), C7-D7, "") -> -13953.6 | F7: =IFERROR(E7/D7, "") -> -0.089213056 | G7: 115136.8 | H7: =IF(AND(ISNUMBER(C7),ISNUMBER(G7)), C7-G7, "") -> 27317.2 | I7: =IFERROR(H7/G7, "") -> 0.23725863 | J7: 1. Site was taken offline by technician on 04/22 between 10:00am to 11:00am | K7: 1. PM 2747
A8: Uxbridge D | B8: MA | C8: 144003 | D8: 147586.7 | E8: =IF(AND(ISNUMBER(C8),ISNUMBER(D8)), C8-D8, "") -> -3583.7 | F8: =IFERROR(E8/D8, "") -> -0.024281998 | G8: 165832.8 | H8: =IF(AND(ISNUMBER(C8),ISNUMBER(G8)), C8-G8, "") -> -21829.8 | I8: =IFERROR(H8/G8, "") -> -0.13163741 | J8: 1. Site was taken offline by technician on 04/10 between 12:00am to 12:50am | K8: 1. PM 2820
A9: West Bridgewater A&B | B9: MA | C9: 254331.5 | D9: 261902.2 | E9: =IF(AND(ISNUMBER(C9),ISNUMBER(D9)), C9-D9, "") -> -7570.7 | F9: =IFERROR(E9/D9, "") -> -0.028906592 | G9: 280666.3 | H9: =IF(AND(ISNUMBER(C9),ISNUMBER(G9)), C9-G9, "") -> -26334.8 | I9: =IFERROR(H9/G9, "") -> -0.093829576
A10: Sutton A | B10: MA | C10: 135968 | D10: 139058.2 | E10: =IF(AND(ISNUMBER(C10),ISNUMBER(D10)), C10-D10, "") -> -3090.2 | F10: =IFERROR(E10/D10, "") -> -0.02222235 | G10: 159133.1 | H10: =IF(AND(ISNUMBER(C10),ISNUMBER(G10)), C10-G10, "") -> -23165.1 | I10: =IFERROR(H10/G10, "") -> -0.14557059 | J10: 1. Site was taken offline by techinican on 04/25 between 13:00 to 14:05 | K10: 1. PM 2921
A11: North Adams A | B11: MA | C11: 133243 | D11: 136901.6 | E11: =IF(AND(ISNUMBER(C11),ISNUMBER(D11)), C11-D11, "") -> -3658.6 | F11: =IFERROR(E11/D11, "") -> -0.026724304 | G11: 169783.1 | H11: =IF(AND(ISNUMBER(C11),ISNUMBER(G11)), C11-G11, "") -> -36540.1 | I11: =IFERROR(H11/G11, "") -> -0.21521636
A12: North Adams B | B12: MA | C12: 131267 | D12: 118829.4 | E12: =IF(AND(ISNUMBER(C12),ISNUMBER(D12)), C12-D12, "") -> 12437.6 | F12: =IFERROR(E12/D12, "") -> 0.1046677 | G12: 169783.1 | H12: =IF(AND(ISNUMBER(C12),ISNUMBER(G12)), C12-G12, "") -> -38516.1 | I12: =IFERROR(H12/G12, "") -> -0.22685473
A13: Clarksburg A | B13: MA | C13: 137517 | D13: 139764.5 | E13: =IF(AND(ISNUMBER(C13),ISNUMBER(D13)), C13-D13, "") -> -2247.5 | F13: =IFERROR(E13/D13, "") -> -0.016080621 | G13: 169012.3 | H13: =IF(AND(ISNUMBER(C13),ISNUMBER(G13)), C13-G13, "") -> -31495.3 | I13: =IFERROR(H13/G13, "") -> -0.18634916
A14: Swansea B | B14: MA | C14: 157217 | D14: 159428.8 | E14: =IF(AND(ISNUMBER(C14),ISNUMBER(D14)), C14-D14, "") -> -2211.8 | F14: =IFERROR(E14/D14, "") -> -0.013873278 | G14: 123799.4 | H14: =IF(AND(ISNUMBER(C14),ISNUMBER(G14)), C14-G14, "") -> 33417.6 | I14: =IFERROR(H14/G14, "") -> 0.26993346 | J14: 1. Site was taken offline by technician on 04/10 between 08:30am to 10:15am | K14: 1. PM 2834
A15: Wareham 2 | B15: MA | C15: 140967.2 | D15: 137966 | E15: =IF(AND(ISNUMBER(C15),ISNUMBER(D15)), C15-D15, "") -> 3001.2 | F15: =IFERROR(E15/D15, "") -> 0.021753186 | G15: 186589.6 | H15: =IF(AND(ISNUMBER(C15),ISNUMBER(G15)), C15-G15, "") -> -45622.4 | I15: =IFERROR(H15/G15, "") -> -0.24450666 | J15: 1. Site was offline on 04/17 between 10:00am to 13:45 due to planned outage 2. Inverter 2.18 reading errronous values after 4:00pm feom 04/17 and offline on 04/25 & 04/26 3. Inverter 2.14 tripped offline on 04/24 at 16:00 and offline from 04/26 4. Inverter 1.1 derating on sunny days, resolved on 04/26 | K15: 1. SR082212 2. SR083576 3. SR083786 4. SR083337
A16: Kingston 1 KB | B16: MA | C16: 131349 | D16: 130566.4 | E16: =IF(AND(ISNUMBER(C16),ISNUMBER(D16)), C16-D16, "") -> 782.6 | F16: =IFERROR(E16/D16, "") -> 0.0059938851 | G16: 143795.2 | H16: =IF(AND(ISNUMBER(C16),ISNUMBER(G16)), C16-G16, "") -> -12446.2 | I16: =IFERROR(H16/G16, "") -> -0.086555045
A17: Kingston 2 KB | B17: MA | C17: 106240 | D17: 89203.59 | E17: =IF(AND(ISNUMBER(C17),ISNUMBER(D17)), C17-D17, "") -> 17036.41 | F17: =IFERROR(E17/D17, "") -> 0.19098346 | G17: 115418.7 | H17: =IF(AND(ISNUMBER(C17),ISNUMBER(G17)), C17-G17, "") -> -9178.7 | I17: =IFERROR(H17/G17, "") -> -0.079525242
A18: Holliston B | B18: MA | C18: 150997 | D18: 146964.1 | E18: =IF(AND(ISNUMBER(C18),ISNUMBER(D18)), C18-D18, "") -> 4032.9 | F18: =IFERROR(E18/D18, "") -> 0.027441396 | G18: 167145.6 | H18: =IF(AND(ISNUMBER(C18),ISNUMBER(G18)), C18-G18, "") -> -16148.6 | I18: =IFERROR(H18/G18, "") -> -0.09661397 | J18: 1. Inverters 13, 15 to 28 offline between at 09:30 to 15:30 on 04/25 | K18: 1. SR083806
A19: Fairhaven C | B19: MA | C19: 230664 | D19: 278442.5 | E19: =IF(AND(ISNUMBER(C19),ISNUMBER(D19)), C19-D19, "") -> -47778.5 | F19: =IFERROR(E19/D19, "") -> -0.17159198 | G19: 321205.9 | H19: =IF(AND(ISNUMBER(C19),ISNUMBER(G19)), C19-G19, "") -> -90541.9 | I19: =IFERROR(H19/G19, "") -> -0.28188119 | J19: 1. Site was taken offline on 04/29 at 09:45 and back online on 04/30 at 16:15 2. Site tripped offline on 04/16 and back online on 04/19 at 09:45am. Again tripped offline on 04/20 at 10:45 and back online at 16:15 3. Site tripped offline on 04/08 at 09:00am and back online at 11:15am 4. Site tripped offline on 04/07 at 12:10 and back online at 13:30 | K19: 1. SR082929 2. SR083489 3. SR083169 4. SR083160
A20: Plympton A-2 | B20: MA | C20: 154728 | D20: 155462.2 | E20: =IF(AND(ISNUMBER(C20),ISNUMBER(D20)), C20-D20, "") -> -734.2 | F20: =IFERROR(E20/D20, "") -> -0.0047226914 | G20: 169580.9 | H20: =IF(AND(ISNUMBER(C20),ISNUMBER(G20)), C20-G20, "") -> -14852.9 | I20: =IFERROR(H20/G20, "") -> -0.087585925 | J20: 1. Inverter 11 offline on 04/16, 04/18, 04/29, 04/30 | K20: 1. SR083504

Sheet May
A1: {=portfolio} -> MN8 KEF | D1: May Actual v. Expected | G1: May Actual v. Forecasted
A2: Total | C2: =SUM(C4:C95) -> -8973955.7 | D2: =SUM(D4:D95) -> 2998098.2 | E2: =C2-D2 -> -11972054 | F2: =IFERROR(E2/D2, 0) -> -3.9932161 | G2: =SUM(G4:G95) -> 3231680.7 | H2: =C2-G2 -> -12205636 | I2: =IFERROR(H2/G2, 0) -> -3.7768695 | J2: =IF(AND(TODAY()>DATE(2024, 5, 1), COUNTA(Sites[Site])<>(COUNT(C:C)-1)), "Some sites are missing actual data; if new sites were added, make sure they are aligned correctly (including prior months!)", "")
A3: Site | B3: State | C3: Actual | D3: Expected | E3: Delta | F3: % | G3: Forecasted | H3: Delta | I3: % | J3: Notes | K3: Service Requests
A4: {=Sites[Site]} -> Williamsburg A | B4: {=Sites[State]} -> MA | C4: 173965.68 | D4: 173895.1 | E4: =IF(AND(ISNUMBER(C4),ISNUMBER(D4)), C4-D4, "") -> 70.5756 | F4: =IFERROR(E4/D4, "") -> 0.00040585157 | G4: 178092.1 | H4: =IF(AND(ISNUMBER(C4),ISNUMBER(G4)), C4-G4, "") -> -4126.4244 | I4: =IFERROR(H4/G4, "") -> -0.023170171
A5: Orange A KB | B5: MA | C5: 136972.36 | D5: 128672.7 | E5: =IF(AND(ISNUMBER(C5),ISNUMBER(D5)), C5-D5, "") -> 8299.6644 | F5: =IFERROR(E5/D5, "") -> 0.064502139 | G5: 143165.9 | H5: =IF(AND(ISNUMBER(C5),ISNUMBER(G5)), C5-G5, "") -> -6193.5356 | I5: =IFERROR(H5/G5, "") -> -0.043261248
A6: Goshen A | B6: MA | C6: -11843992 | D6: 152191.5 | E6: =IF(AND(ISNUMBER(C6),ISNUMBER(D6)), C6-D6, "") -> -11996183 | F6: =IFERROR(E6/D6, "") -> -78.822952 | G6: 119525.4 | H6: =IF(AND(ISNUMBER(C6),ISNUMBER(G6)), C6-G6, "") -> -11963517 | I6: =IFERROR(H6/G6, "") -> -100.09184 | J6: 1. Inverter 3.15 tripped offline on 05/22 at 15:30 and later self resolved on 05/23 at 05:00 am. 2. Site was offline between 04:30am to 12:15pm on 05/30 3. Meter reporting errenous values and having intermittent communication. Meter being RMA'd | K6: 1. SR085031 2. SR085295 3. SR080661
A7: Phillipston A KB | B7: MA | C7: 166750 | D7: 174107.4 | E7: =IF(AND(ISNUMBER(C7),ISNUMBER(D7)), C7-D7, "") -> -7357.4 | F7: =IFERROR(E7/D7, "") -> -0.042257825 | G7: 138861.2 | H7: =IF(AND(ISNUMBER(C7),ISNUMBER(G7)), C7-G7, "") -> 27888.8 | I7: =IFERROR(H7/G7, "") -> 0.2008394 | J7: 1. Site was offline due to utility outage on 05/31 from 14:00 to 16:45. | K7: 1. SR085385
A8: Uxbridge D | B8: MA | C8: 167815 | D8: 169800 | E8: =IF(AND(ISNUMBER(C8),ISNUMBER(D8)), C8-D8, "") -> -1985 | F8: =IFERROR(E8/D8, "") -> -0.011690224 | G8: 187348.5 | H8: =IF(AND(ISNUMBER(C8),ISNUMBER(G8)), C8-G8, "") -> -19533.5 | I8: =IFERROR(H8/G8, "") -> -0.10426291
A9: West Bridgewater A&B | B9: MA | C9: 279538 | D9: 287934.3 | E9: =IF(AND(ISNUMBER(C9),ISNUMBER(D9)), C9-D9, "") -> -8396.3 | F9: =IFERROR(E9/D9, "") -> -0.029160472 | G9: 320294.2 | H9: =IF(AND(ISNUMBER(C9),ISNUMBER(G9)), C9-G9, "") -> -40756.2 | I9: =IFERROR(H9/G9, "") -> -0.12724614
A10: Sutton A | B10: MA | C10: 156960 | D10: 155795.2 | E10: =IF(AND(ISNUMBER(C10),ISNUMBER(D10)), C10-D10, "") -> 1164.8 | F10: =IFERROR(E10/D10, "") -> 0.0074764819 | G10: 181995 | H10: =IF(AND(ISNUMBER(C10),ISNUMBER(G10)), C10-G10, "") -> -25035 | I10: =IFERROR(H10/G10, "") -> -0.13755872
A11: North Adams A | B11: MA | C11: 175242 | D11: 176263.8 | E11: =IF(AND(ISNUMBER(C11),ISNUMBER(D11)), C11-D11, "") -> -1021.8 | F11: =IFERROR(E11/D11, "") -> -0.0057969929 | G11: 193978.2 | H11: =IF(AND(ISNUMBER(C11),ISNUMBER(G11)), C11-G11, "") -> -18736.2 | I11: =IFERROR(H11/G11, "") -> -0.096589204 | J11: 1. Site was offline due to SEL recloser open on 05/26 at 15:30 and later SEL recloser was remotely closed at 16:45. | K11: 1.SR085170
A12: North Adams B | B12: MA | C12: 174636 | D12: 153126.3 | E12: =IF(AND(ISNUMBER(C12),ISNUMBER(D12)), C12-D12, "") -> 21509.7 | F12: =IFERROR(E12/D12, "") -> 0.14047032 | G12: 193978.2 | H12: =IF(AND(ISNUMBER(C12),ISNUMBER(G12)), C12-G12, "") -> -19342.2 | I12: =IFERROR(H12/G12, "") -> -0.099713267 | J12: 1. Site was offline due to SEL recloser open on 05/26 at 15:30 and later SEL recloser was remotely closed at 16:45. | K12: 1. SR085169
A13: Clarksburg A | B13: MA | C13: 176599 | D13: 176175.5 | E13: =IF(AND(ISNUMBER(C13),ISNUMBER(D13)), C13-D13, "") -> 423.5 | F13: =IFERROR(E13/D13, "") -> 0.002403853 | G13: 193097.8 | H13: =IF(AND(ISNUMBER(C13),ISNUMBER(G13)), C13-G13, "") -> -16498.8 | I13: =IFERROR(H13/G13, "") -> -0.085442713
A14: Swansea B | B14: MA | C14: 177464 | D14: 182570.1 | E14: =IF(AND(ISNUMBER(C14),ISNUMBER(D14)), C14-D14, "") -> -5106.1 | F14: =IFERROR(E14/D14, "") -> -0.027967887 | G14: 143014.2 | H14: =IF(AND(ISNUMBER(C14),ISNUMBER(G14)), C14-G14, "") -> 34449.8 | I14: =IFERROR(H14/G14, "") -> 0.24088377 | J14: 1. Site was offline due to utility outage on 05/08 from 05:00 am to 11:00am. | K14: 1. SR084479
A15: Wareham 2 | B15: MA | C15: 160615 | D15: 156360.1 | E15: =IF(AND(ISNUMBER(C15),ISNUMBER(D15)), C15-D15, "") -> 4254.9 | F15: =IFERROR(E15/D15, "") -> 0.027212185 | G15: 203086.9 | H15: =IF(AND(ISNUMBER(C15),ISNUMBER(G15)), C15-G15, "") -> -42471.9 | I15: =IFERROR(H15/G15, "") -> -0.20913166 | J15: 1. Inverter1.1 was offline on 05/11, 05/26, 05/30 and 05/31. 2. Site was offline due to uitility outage on 05/30 from 13:30 to 15:15. 3. Inverter 2.1 was offline after the utility outage has cleared on 05/30 at 15:15 and later back online on 05/31. 4. Inverter 2.14 was offline due to "Over- temperature fault" from 05/01 to 05/13. | K15: 1. SR084577 2. SR085329 3. SR085332 4. SR083786
