Workbook
Name JanActual: #REF!
Name JanActual2: #REF!
Name JanExpected: #REF!
Name JanExpectedDelta: #REF!
Name JanExpectedPercent: #REF!
Name JanExpPercent: #REF!
Name JanForecasted: #REF!
Name JanForecastedDelta: #REF!
Name JanForecastedPercent: #REF!
Name portfolio: Sites!$B$1:$B$1
Name Year: Sites!#REF!

Sheet Year to Date
A1: {=portfolio} -> Silicon Ranch | D1: Year to Date Actual v. Expected | G1: Year to Date Actual v. Forecasted
A2: Total | C2: =SUM(C4:C100) -> 1674447.4 | D2: =SUM(D4:D100) -> 0 | E2: =C2-D2 -> 1674447.4 | F2: =IFERROR(E2/D2, 0) -> 0 | G2: =SUM(G4:G100) -> 4271440 | H2: =C2-G2 -> -2596992.6 | I2: =IFERROR(H2/G2, 0) -> -0.60798996
A3: Site | B3: State | C3: Actual | D3: Expected | E3: Delta | F3: % | G3: Forecasted | H3: Delta | I3: %
A4: {=Sites[Site]} -> Iron Mountain - Windsor | B4: {=Sites[State]} -> CT | C4: =SUM('1st Qtr'!C4, '2nd Qtr'!C4, '3rd Qtr'!C4, '4th Qtr'!C4) -> 113333.75 | D4: =SUM('1st Qtr'!D4, '2nd Qtr'!D4, '3rd Qtr'!D4, '4th Qtr'!D4) -> 0 | E4: =IF(AND(ISNUMBER(C4),ISNUMBER(D4)), C4-D4, "") -> 113333.75 | F4: =IFERROR(E4/D4, "") | G4: =SUM('1st Qtr'!G4, '2nd Qtr'!G4, '3rd Qtr'!G4, '4th Qtr'!G4) -> 123014.5 | H4: =SUM('1st Qtr'!H4, '2nd Qtr'!H4, '3rd Qtr'!H4, '4th Qtr'!H4) -> -9680.75 | I4: =IFERROR(H4/G4, "") -> -0.078696007
A5: Kohls - Auburn | B5: NY | C5: =SUM(Jan!C5, Feb!C5, Mar!C5) -> 44800 | D5: =SUM(Jan!D5, Feb!D5, Mar!D5) -> 0 | E5: =IF(AND(ISNUMBER(C5),ISNUMBER(D5)), C5-D5, "") -> 44800 | F5: =IFERROR(E5/D5, "") | G5: =SUM('1st Qtr'!G5, '2nd Qtr'!G5, '3rd Qtr'!G5, '4th Qtr'!G5) -> 119512.79 | H5: =SUM(Jan!H5, Feb!H5, Mar!H5) -> 5388.09 | I5: =IFERROR(H5/G5, "") -> 0.045083794
A6: Kohls - Bensalem | B6: PA | C6: =SUM(Jan!C6, Feb!C6, Mar!C6) -> 66928 | D6: =SUM(Jan!D6, Feb!D6, Mar!D6) -> 0 | E6: =IF(AND(ISNUMBER(C6),ISNUMBER(D6)), C6-D6, "") -> 66928 | F6: =IFERROR(E6/D6, "") | G6: =SUM('1st Qtr'!G6, '2nd Qtr'!G6, '3rd Qtr'!G6, '4th Qtr'!G6) -> 137653.25 | H6: =SUM(Jan!H6, Feb!H6, Mar!H6) -> 1265.98 | I6: =IFERROR(H6/G6, "") -> 0.0091968769
A7: Kohls - Brick | B7: NJ | C7: =SUM(Jan!C7, Feb!C7, Mar!C7) -> 74090 | D7: =SUM(Jan!D7, Feb!D7, Mar!D7) -> 0 | E7: =IF(AND(ISNUMBER(C7),ISNUMBER(D7)), C7-D7, "") -> 74090 | F7: =IFERROR(E7/D7, "") | G7: =SUM('1st Qtr'!G7, '2nd Qtr'!G7, '3rd Qtr'!G7, '4th Qtr'!G7) -> 163134.48 | H7: =SUM(Jan!H7, Feb!H7, Mar!H7) -> -1190.86 | I7: =IFERROR(H7/G7, "") -> -0.007299867
A8: Kohls - Buffalo | B8: NY | C8: =SUM(Jan!C8, Feb!C8, Mar!C8) -> 53909 | D8: =SUM(Jan!D8, Feb!D8, Mar!D8) -> 0 | E8: =IF(AND(ISNUMBER(C8),ISNUMBER(D8)), C8-D8, "") -> 53909 | F8: =IFERROR(E8/D8, "") | G8: =SUM('1st Qtr'!G8, '2nd Qtr'!G8, '3rd Qtr'!G8, '4th Qtr'!G8) -> 150367.43 | H8: =SUM(Jan!H8, Feb!H8, Mar!H8) -> -818.37 | I8: =IFERROR(H8/G8, "") -> -0.0054424685
A9: Kohls - Canton | B9: CT | C9: =SUM(Jan!C9, Feb!C9, Mar!C9) -> 24565 | D9: =SUM(Jan!D9, Feb!D9, Mar!D9) -> 0 | E9: =IF(AND(ISNUMBER(C9),ISNUMBER(D9)), C9-D9, "") -> 24565 | F9: =IFERROR(E9/D9, "") | G9: =SUM('1st Qtr'!G9, '2nd Qtr'!G9, '3rd Qtr'!G9, '4th Qtr'!G9) -> 53186.86 | H9: =SUM(Jan!H9, Feb!H9, Mar!H9) -> 509.95 | I9: =IFERROR(H9/G9, "") -> 0.0095878945
A10: Kohls - East Amherst | B10: NY | C10: =SUM(Jan!C10, Feb!C10, Mar!C10) -> 49240 | D10: =SUM(Jan!D10, Feb!D10, Mar!D10) -> 0 | E10: =IF(AND(ISNUMBER(C10),ISNUMBER(D10)), C10-D10, "") -> 49240 | F10: =IFERROR(E10/D10, "") | G10: =SUM('1st Qtr'!G10, '2nd Qtr'!G10, '3rd Qtr'!G10, '4th Qtr'!G10) -> 136562.08 | H10: =SUM(Jan!H10, Feb!H10, Mar!H10) -> -2308.69 | I10: =IFERROR(H10/G10, "") -> -0.016905791
A11: Kohls - East Brunswick | B11: NJ | C11: =SUM(Jan!C11, Feb!C11, Mar!C11) -> 79993 | D11: =SUM(Jan!D11, Feb!D11, Mar!D11) -> 0 | E11: =IF(AND(ISNUMBER(C11),ISNUMBER(D11)), C11-D11, "") -> 79993 | F11: =IFERROR(E11/D11, "") | G11: =SUM('1st Qtr'!G11, '2nd Qtr'!G11, '3rd Qtr'!G11, '4th Qtr'!G11) -> 212930.71 | H11: =SUM(Jan!H11, Feb!H11, Mar!H11) -> -20451.72 | I11: =IFERROR(H11/G11, "") -> -0.09604871
A12: Kohls - Edgewood | B12: MD | C12: =SUM(Jan!C12, Feb!C12, Mar!C12) -> 489062 | D12: =SUM(Jan!D12, Feb!D12, Mar!D12) -> 0 | E12: =IF(AND(ISNUMBER(C12),ISNUMBER(D12)), C12-D12, "") -> 489062 | F12: =IFERROR(E12/D12, "") | G12: =SUM('1st Qtr'!G12, '2nd Qtr'!G12, '3rd Qtr'!G12, '4th Qtr'!G12) -> 1140846.2 | H12: =SUM(Jan!H12, Feb!H12, Mar!H12) -> -55603.87 | I12: =IFERROR(H12/G12, "") -> -0.048739147
A13: Kohls - Granite Run | B13: PA | C13: =SUM(Jan!C13, Feb!C13, Mar!C13) -> 63649 | D13: =SUM(Jan!D13, Feb!D13, Mar!D13) -> 0 | E13: =IF(AND(ISNUMBER(C13),ISNUMBER(D13)), C13-D13, "") -> 63649 | F13: =IFERROR(E13/D13, "") | G13: =SUM('1st Qtr'!G13, '2nd Qtr'!G13, '3rd Qtr'!G13, '4th Qtr'!G13) -> 137717.7 | H13: =SUM(Jan!H13, Feb!H13, Mar!H13) -> -2068.16 | I13: =IFERROR(H13/G13, "") -> -0.015017387
A14: Kohls - Greece | B14: NY | C14: =SUM(Jan!C14, Feb!C14, Mar!C14) -> 40858 | D14: =SUM(Jan!D14, Feb!D14, Mar!D14) -> 0 | E14: =IF(AND(ISNUMBER(C14),ISNUMBER(D14)), C14-D14, "") -> 40858 | F14: =IFERROR(E14/D14, "") | G14: =SUM('1st Qtr'!G14, '2nd Qtr'!G14, '3rd Qtr'!G14, '4th Qtr'!G14) -> 143804.98 | H14: =SUM(Jan!H14, Feb!H14, Mar!H14) -> -11100.83 | I14: =IFERROR(H14/G14, "") -> -0.077193641
A15: Kohls - Hanover | B15: PA | C15: =SUM(Jan!C15, Feb!C15, Mar!C15) -> 64193 | D15: =SUM(Jan!D15, Feb!D15, Mar!D15) -> 0 | E15: =IF(AND(ISNUMBER(C15),ISNUMBER(D15)), C15-D15, "") -> 64193 | F15: =IFERROR(E15/D15, "") | G15: =SUM('1st Qtr'!G15, '2nd Qtr'!G15, '3rd Qtr'!G15, '4th Qtr'!G15) -> 155333.6 | H15: =SUM(Jan!H15, Feb!H15, Mar!H15) -> -9545.67 | I15: =IFERROR(H15/G15, "") -> -0.061452706
A16: Kohls - Horsehead | B16: NY | C16: =SUM(Jan!C16, Feb!C16, Mar!C16) -> 44058 | D16: =SUM(Jan!D16, Feb!D16, Mar!D16) -> 0 | E16: =IF(AND(ISNUMBER(C16),ISNUMBER(D16)), C16-D16, "") -> 44058 | F16: =IFERROR(E16/D16, "") | G16: =SUM('1st Qtr'!G16, '2nd Qtr'!G16, '3rd Qtr'!G16, '4th Qtr'!G16) -> 118664.52 | H16: =SUM(Jan!H16, Feb!H16, Mar!H16) -> -9727.88 | I16: =IFERROR(H16/G16, "") -> -0.081978
... A24: Kohls - Warminster | B24: PA | C24: =SUM(Jan!C24, Feb!C24, Mar!C24) -> 40475 | D24: =SUM(Jan!D24, Feb!D24, Mar!D24) -> 0 | E24: =IF(AND(ISNUMBER(C24),ISNUMBER(D24)), C24-D24, "") -> 40475 | F24: =IFERROR(E24/D24, "") | G24: =SUM('1st Qtr'!G24, '2nd Qtr'!G24, '3rd Qtr'!G24, '4th Qtr'!G24) -> 160563.65 | H24: =SUM(Jan!H24, Feb!H24, Mar!H24) -> -40277.78 | I24: =IFERROR(H24/G24, "") -> -0.25085242
A25: Kohls - Waterbury | B25: CT | C25: =SUM(Jan!C25, Feb!C25, Mar!C25) -> 61440 | D25: =SUM(Jan!D25, Feb!D25, Mar!D25) -> 0 | E25: =IF(AND(ISNUMBER(C25),ISNUMBER(D25)), C25-D25, "") -> 61440 | F25: =IFERROR(E25/D25, "") | G25: =Jan!G25+Feb!G25+Mar!G25+Apr!G25+May!G25 -> 142928.24 | H25: =SUM(Jan!H25, Feb!H25, Mar!H25) -> -2028.68 | I25: =IFERROR(H25/G25, "") -> -0.014193696

Sheet 1st Qtr
A1: {=portfolio} -> Silicon Ranch | D1: 1st Quarter Actual v. Expected | G1: 1st Quarter Actual v. Forecasted
A2: Total | C2: =SUM(C4:C100) -> 1611034.4 | D2: =SUM(D4:D100) -> 0 | E2: =C2-D2 -> 1611034.4 | F2: =IFERROR(E2/D2, 0) -> 0 | G2: =SUM(G4:G100) -> #REF! | H2: =C2-G2 -> #REF! | I2: =IFERROR(H2/G2, 0) -> 0
A3: Site | B3: State | C3: Actual | D3: Expected | E3: Delta | F3: % | G3: Forecasted | H3: Delta | I3: %
A4: {=Sites[Site]} -> Iron Mountain - Windsor | B4: {=Sites[State]} -> CT | C4: =SUM(Jan!C4, Feb!C4, Mar!C4) -> 49920.75 | D4: =SUM(Jan!D4, Feb!D4, Mar!D4) -> 0 | E4: =IF(AND(ISNUMBER(C4),ISNUMBER(D4)), C4-D4, "") -> 49920.75 | F4: =IFERROR(E4/D4, "") | G4: =SUM(Jan!G4, Feb!G4, Mar!G4) -> 57306.24 | H4: =SUM(Jan!H4, Feb!H4, Mar!H4) -> -7385.49 | I4: =IFERROR(H4/G4, "") -> -0.12887759
A5: Kohls - Auburn | B5: NY | C5: =SUM(Jan!C5, Feb!C5, Mar!C5) -> 44800 | D5: =SUM(Jan!D5, Feb!D5, Mar!D5) -> 0 | E5: =IF(AND(ISNUMBER(C5),ISNUMBER(D5)), C5-D5, "") -> 44800 | F5: =IFERROR(E5/D5, "") | G5: =SUM(Jan!G5, Feb!G5, Mar!G5) -> 39411.91 | H5: =SUM(Jan!H5, Feb!H5, Mar!H5) -> 5388.09 | I5: =IFERROR(H5/G5, "") -> 0.13671223
A6: Kohls - Bensalem | B6: PA | C6: =SUM(Jan!C6, Feb!C6, Mar!C6) -> 66928 | D6: =SUM(Jan!D6, Feb!D6, Mar!D6) -> 0 | E6: =IF(AND(ISNUMBER(C6),ISNUMBER(D6)), C6-D6, "") -> 66928 | F6: =IFERROR(E6/D6, "") | G6: =SUM(Jan!G6, Feb!G6, Mar!G6) -> 65662.02 | H6: =SUM(Jan!H6, Feb!H6, Mar!H6) -> 1265.98 | I6: =IFERROR(H6/G6, "") -> 0.019280248
A7: Kohls - Brick | B7: NJ | C7: =SUM(Jan!C7, Feb!C7, Mar!C7) -> 74090 | D7: =SUM(Jan!D7, Feb!D7, Mar!D7) -> 0 | E7: =IF(AND(ISNUMBER(C7),ISNUMBER(D7)), C7-D7, "") -> 74090 | F7: =IFERROR(E7/D7, "") | G7: =SUM(Jan!G7, Feb!G7, Mar!G7) -> 75280.86 | H7: =SUM(Jan!H7, Feb!H7, Mar!H7) -> -1190.86 | I7: =IFERROR(H7/G7, "") -> -0.015818895
A8: Kohls - Buffalo | B8: NY | C8: =SUM(Jan!C8, Feb!C8, Mar!C8) -> 53909 | D8: =SUM(Jan!D8, Feb!D8, Mar!D8) -> 0 | E8: =IF(AND(ISNUMBER(C8),ISNUMBER(D8)), C8-D8, "") -> 53909 | F8: =IFERROR(E8/D8, "") | G8: =SUM(Jan!G8, Feb!G8, Mar!G8) -> 54727.37 | H8: =SUM(Jan!H8, Feb!H8, Mar!H8) -> -818.37 | I8: =IFERROR(H8/G8, "") -> -0.014953578
A9: Kohls - Canton | B9: CT | C9: =SUM(Jan!C9, Feb!C9, Mar!C9) -> 24565 | D9: =SUM(Jan!D9, Feb!D9, Mar!D9) -> 0 | E9: =IF(AND(ISNUMBER(C9),ISNUMBER(D9)), C9-D9, "") -> 24565 | F9: =IFERROR(E9/D9, "") | G9: =SUM(Jan!G9, Feb!G9, Mar!G9) -> 24055.05 | H9: =SUM(Jan!H9, Feb!H9, Mar!H9) -> 509.95 | I9: =IFERROR(H9/G9, "") -> 0.021199291
A10: Kohls - East Amherst | B10: NY | C10: =SUM(Jan!C10, Feb!C10, Mar!C10) -> 49240 | D10: =SUM(Jan!D10, Feb!D10, Mar!D10) -> 0 | E10: =IF(AND(ISNUMBER(C10),ISNUMBER(D10)), C10-D10, "") -> 49240 | F10: =IFERROR(E10/D10, "") | G10: =SUM(Jan!G10, Feb!G10, Mar!G10) -> 51548.69 | H10: =SUM(Jan!H10, Feb!H10, Mar!H10) -> -2308.69 | I10: =IFERROR(H10/G10, "") -> -0.044786589
A11: Kohls - East Brunswick | B11: NJ | C11: =SUM(Jan!C11, Feb!C11, Mar!C11) -> 79993 | D11: =SUM(Jan!D11, Feb!D11, Mar!D11) -> 0 | E11: =IF(AND(ISNUMBER(C11),ISNUMBER(D11)), C11-D11, "") -> 79993 | F11: =IFERROR(E11/D11, "") | G11: =SUM(Jan!G11, Feb!G11, Mar!G11) -> 100444.72 | H11: =SUM(Jan!H11, Feb!H11, Mar!H11) -> -20451.72 | I11: =IFERROR(H11/G11, "") -> -0.2036117
A12: Kohls - Edgewood | B12: MD | C12: =SUM(Jan!C12, Feb!C12, Mar!C12) -> 489062 | D12: =SUM(Jan!D12, Feb!D12, Mar!D12) -> 0 | E12: =IF(AND(ISNUMBER(C12),ISNUMBER(D12)), C12-D12, "") -> 489062 | F12: =IFERROR(E12/D12, "") | G12: =SUM(Jan!G12, Feb!G12, Mar!G12) -> 544665.87 | H12: =SUM(Jan!H12, Feb!H12, Mar!H12) -> -55603.87 | I12: =IFERROR(H12/G12, "") -> -0.10208804
A13: Kohls - Granite Run | B13: PA | C13: =SUM(Jan!C13, Feb!C13, Mar!C13) -> 63649 | D13: =SUM(Jan!D13, Feb!D13, Mar!D13) -> 0 | E13: =IF(AND(ISNUMBER(C13),ISNUMBER(D13)), C13-D13, "") -> 63649 | F13: =IFERROR(E13/D13, "") | G13: =SUM(Jan!G13, Feb!G13, Mar!G13) -> 65717.16 | H13: =SUM(Jan!H13, Feb!H13, Mar!H13) -> -2068.16 | I13: =IFERROR(H13/G13, "") -> -0.031470624
A14: Kohls - Greece | B14: NY | C14: =SUM(Jan!C14, Feb!C14, Mar!C14) -> 40858 | D14: =SUM(Jan!D14, Feb!D14, Mar!D14) -> 0 | E14: =IF(AND(ISNUMBER(C14),ISNUMBER(D14)), C14-D14, "") -> 40858 | F14: =IFERROR(E14/D14, "") | G14: =SUM(Jan!G14, Feb!G14, Mar!G14) -> 51958.83 | H14: =SUM(Jan!H14, Feb!H14, Mar!H14) -> -11100.83 | I14: =IFERROR(H14/G14, "") -> -0.21364665
A15: Kohls - Hanover | B15: PA | C15: =SUM(Jan!C15, Feb!C15, Mar!C15) -> 64193 | D15: =SUM(Jan!D15, Feb!D15, Mar!D15) -> 0 | E15: =IF(AND(ISNUMBER(C15),ISNUMBER(D15)), C15-D15, "") -> 64193 | F15: =IFERROR(E15/D15, "") | G15: =SUM(Jan!G15, Feb!G15, Mar!G15) -> 73738.67 | H15: =SUM(Jan!H15, Feb!H15, Mar!H15) -> -9545.67 | I15: =IFERROR(H15/G15, "") -> -0.1294527
A16: Kohls - Horsehead | B16: NY | C16: =SUM(Jan!C16, Feb!C16, Mar!C16) -> 44058 | D16: =SUM(Jan!D16, Feb!D16, Mar!D16) -> 0 | E16: =IF(AND(ISNUMBER(C16),ISNUMBER(D16)), C16-D16, "") -> 44058 | F16: =IFERROR(E16/D16, "") | G16: =SUM(Jan!G16, Feb!G16, Mar!G16) -> 53785.88 | H16: =SUM(Jan!H16, Feb!H16, Mar!H16) -> -9727.88 | I16: =IFERROR(H16/G16, "") -> -0.18086308
... A22: Kohls - North Amherst | B22: NY | C22: =SUM(Jan!C22, Feb!C22, Mar!C22) -> 37771 | D22: =SUM(Jan!D22, Feb!D22, Mar!D22) -> 0 | E22: =IF(AND(ISNUMBER(C22),ISNUMBER(D22)), C22-D22, "") -> 37771 | F22: =IFERROR(E22/D22, "") | G22: =SUM(Jan!G22, Feb!G22, Mar!G22) -> 44557.45 | H22: =SUM(Jan!H22, Feb!H22, Mar!H22) -> -6786.45 | I22: =IFERROR(H22/G22, "") -> -0.15230786
A23: Kohls - Staten Island | B23: NY | C23: =SUM(Jan!C23, Feb!C23, Mar!C23) -> 59937.6 | D23: =SUM(Jan!D23, Feb!D23, Mar!D23) -> 0 | E23: =IF(AND(ISNUMBER(C23),ISNUMBER(D23)), C23-D23, "") -> 59937.6 | F23: =IFERROR(E23/D23, "") | G23: =SUM(Jan!G23, Feb!G23, Mar!G24) -> 73401.73 | H23: =SUM(Jan!H23, Feb!H23, Mar!H23) -> -8920.7 | I23: =IFERROR(H23/G23, "") -> -0.12153256
A24: Kohls - Warminster | B24: PA | C24: =SUM(Jan!C24, Feb!C24, Mar!C24) -> 40475 | D24: =SUM(Jan!D24, Feb!D24, Mar!D24) -> 0 | E24: =IF(AND(ISNUMBER(C24),ISNUMBER(D24)), C24-D24, "") -> 40475 | F24: =IFERROR(E24/D24, "") | G24: =SUM(Jan!G24, Feb!G24, Mar!G25) -> 72736.63 | H24: =SUM(Jan!H24, Feb!H24, Mar!H24) -> -40277.78 | I24: =IFERROR(H24/G24, "") -> -0.55374823
A25: Kohls - Waterbury | B25: CT | C25: =SUM(Jan!C25, Feb!C25, Mar!C25) -> 61440 | D25: =SUM(Jan!D25, Feb!D25, Mar!D25) -> 0 | E25: =IF(AND(ISNUMBER(C25),ISNUMBER(D25)), C25-D25, "") -> 61440 | F25: =IFERROR(E25/D25, "") | G25: =SUM(Jan!G25, Feb!G25, Mar!#REF!) -> #REF! | H25: =SUM(Jan!H25, Feb!H25, Mar!H25) -> -2028.68 | I25: =IFERROR(H25/G25, "")

Sheet 2nd Qtr
A1: {=portfolio} -> Silicon Ranch | D1: 2nd Quarter Actual v. Expected | G1: 2nd Quarter Actual v. Forecasted
A2: Total | C2: =SUM(C4:C100) -> 1962094.8 | D2: =SUM(D4:D100) -> 0 | E2: =C2-D2 -> 1962094.8 | F2: =IFERROR(E2/D2, 0) -> 0 | G2: =SUM(G4:G100) -> 2348284.2 | H2: =C2-G2 -> -386189.38 | I2: =IFERROR(H2/G2, 0) -> -0.16445598
A3: Site | B3: State | C3: Actual | D3: Expected | E3: Delta | F3: % | G3: Forecasted | H3: Delta | I3: %
A4: {=Sites[Site]} -> Iron Mountain - Windsor | B4: {=Sites[State]} -> CT | C4: =SUM(Apr!C4, May!C4, Jun!C4) -> 63413 | D4: =SUM(Apr!D4, May!D4, Jun!D4) -> 0 | E4: =IF(AND(ISNUMBER(C4),ISNUMBER(D4)), C4-D4, "") -> 63413 | F4: =IFERROR(E4/D4, "") | G4: =SUM(Apr!G4, May!G4, Jun!G4) -> 65708.26 | H4: =SUM(Apr!H4, May!H4, Jun!H4) -> -2295.26 | I4: =IFERROR(H4/G4, "") -> -0.034931073
A5: Kohls - Auburn | B5: NY | C5: =SUM(Apr!C5, May!C5, Jun!C5) -> 69501 | D5: =SUM(Apr!D5, May!D5, Jun!D5) -> 0 | E5: =IF(AND(ISNUMBER(C5),ISNUMBER(D5)), C5-D5, "") -> 69501 | F5: =IFERROR(E5/D5, "") | G5: =SUM(Apr!G5, May!G5, Jun!G5) -> 80100.88 | H5: =SUM(Apr!H5, May!H5, Jun!H5) -> -10599.88 | I5: =IFERROR(H5/G5, "") -> -0.13233163
A6: Kohls - Bensalem | B6: PA | C6: =SUM(Apr!C6, May!C6, Jun!C6) -> 73357 | D6: =SUM(Apr!D6, May!D6, Jun!D6) -> 0 | E6: =IF(AND(ISNUMBER(C6),ISNUMBER(D6)), C6-D6, "") -> 73357 | F6: =IFERROR(E6/D6, "") | G6: =SUM(Apr!G6, May!G6, Jun!G6) -> 71991.23 | H6: =SUM(Apr!H6, May!H6, Jun!H6) -> 1365.77 | I6: =IFERROR(H6/G6, "") -> 0.018971339
A7: Kohls - Brick | B7: NJ | C7: =SUM(Apr!C7, May!C7, Jun!C7) -> 81922 | D7: =SUM(Apr!D7, May!D7, Jun!D7) -> 0 | E7: =IF(AND(ISNUMBER(C7),ISNUMBER(D7)), C7-D7, "") -> 81922 | F7: =IFERROR(E7/D7, "") | G7: =SUM(Apr!G7, May!G7, Jun!G7) -> 87853.62 | H7: =SUM(Apr!H7, May!H7, Jun!H7) -> -5931.62 | I7: =IFERROR(H7/G7, "") -> -0.067517081
A8: Kohls - Buffalo | B8: NY | C8: =SUM(Apr!C8, May!C8, Jun!C8) -> 85537 | D8: =SUM(Apr!D8, May!D8, Jun!D8) -> 0 | E8: =IF(AND(ISNUMBER(C8),ISNUMBER(D8)), C8-D8, "") -> 85537 | F8: =IFERROR(E8/D8, "") | G8: =SUM(Apr!G8, May!G8, Jun!G8) -> 95640.06 | H8: =SUM(Apr!H8, May!H8, Jun!H8) -> -10103.06 | I8: =IFERROR(H8/G8, "") -> -0.10563628
A9: Kohls - Canton | B9: CT | C9: =SUM(Apr!C9, May!C9, Jun!C9) -> 31136 | D9: =SUM(Apr!D9, May!D9, Jun!D9) -> 0 | E9: =IF(AND(ISNUMBER(C9),ISNUMBER(D9)), C9-D9, "") -> 31136 | F9: =IFERROR(E9/D9, "") | G9: =SUM(Apr!G9, May!G9, Jun!G9) -> 29131.81 | H9: =SUM(Apr!H9, May!H9, Jun!H9) -> 2004.19 | I9: =IFERROR(H9/G9, "") -> 0.068797304
A10: Kohls - East Amherst | B10: NY | C10: =SUM(Apr!C10, May!C10, Jun!C10) -> 78995 | D10: =SUM(Apr!D10, May!D10, Jun!D10) -> 0 | E10: =IF(AND(ISNUMBER(C10),ISNUMBER(D10)), C10-D10, "") -> 78995 | F10: =IFERROR(E10/D10, "") | G10: =SUM(Apr!G10, May!G10, Jun!G10) -> 85013.39 | H10: =SUM(Apr!H10, May!H10, Jun!H10) -> -6018.39 | I10: =IFERROR(H10/G10, "") -> -0.070793436
A11: Kohls - East Brunswick | B11: NJ | C11: =SUM(Apr!C11, May!C11, Jun!C11) -> 69426 | D11: =SUM(Apr!D11, May!D11, Jun!D11) -> 0 | E11: =IF(AND(ISNUMBER(C11),ISNUMBER(D11)), C11-D11, "") -> 69426 | F11: =IFERROR(E11/D11, "") | G11: =SUM(Apr!G11, May!G11, Jun!G11) -> 112485.99 | H11: =SUM(Apr!H11, May!H11, Jun!H11) -> -43059.99 | I11: =IFERROR(H11/G11, "") -> -0.38280314
A12: Kohls - Edgewood | B12: MD | C12: =SUM(Apr!C12, May!C12, Jun!C12) -> 454758 | D12: =SUM(Apr!D12, May!D12, Jun!D12) -> 0 | E12: =IF(AND(ISNUMBER(C12),ISNUMBER(D12)), C12-D12, "") -> 454758 | F12: =IFERROR(E12/D12, "") | G12: =SUM(Apr!G12, May!G12, Jun!G12) -> 596180.32 | H12: =SUM(Apr!H12, May!H12, Jun!H12) -> -141422.32 | I12: =IFERROR(H12/G12, "") -> -0.237214
A13: Kohls - Granite Run | B13: PA | C13: =SUM(Apr!C13, May!C13, Jun!C13) -> 68212 | D13: =SUM(Apr!D13, May!D13, Jun!D13) -> 0 | E13: =IF(AND(ISNUMBER(C13),ISNUMBER(D13)), C13-D13, "") -> 68212 | F13: =IFERROR(E13/D13, "") | G13: =SUM(Apr!G13, May!G13, Jun!G13) -> 72000.54 | H13: =SUM(Apr!H13, May!H13, Jun!H13) -> -3788.54 | I13: =IFERROR(H13/G13, "") -> -0.052618216
A14: Kohls - Greece | B14: NY | C14: =SUM(Apr!C14, May!C14, Jun!C14) -> 68457 | D14: =SUM(Apr!D14, May!D14, Jun!D14) -> 0 | E14: =IF(AND(ISNUMBER(C14),ISNUMBER(D14)), C14-D14, "") -> 68457 | F14: =IFERROR(E14/D14, "") | G14: =SUM(Apr!G14, May!G14, Jun!G14) -> 91846.15 | H14: =SUM(Apr!H14, May!H14, Jun!H14) -> -23389.15 | I14: =IFERROR(H14/G14, "") -> -0.25465575
A15: Kohls - Hanover | B15: PA | C15: =SUM(Apr!C15, May!C15, Jun!C15) -> 41923 | D15: =SUM(Apr!D15, May!D15, Jun!D15) -> 0 | E15: =IF(AND(ISNUMBER(C15),ISNUMBER(D15)), C15-D15, "") -> 41923 | F15: =IFERROR(E15/D15, "") | G15: =SUM(Apr!G15, May!G15, Jun!G15) -> 81594.93 | H15: =SUM(Apr!H15, May!H15, Jun!H15) -> -39671.93 | I15: =IFERROR(H15/G15, "") -> -0.48620582
A16: Kohls - Horsehead | B16: NY | C16: =SUM(Apr!C16, May!C16, Jun!C16) -> 60704 | D16: =SUM(Apr!D16, May!D16, Jun!D16) -> 0 | E16: =IF(AND(ISNUMBER(C16),ISNUMBER(D16)), C16-D16, "") -> 60704 | F16: =IFERROR(E16/D16, "") | G16: =SUM(Apr!G16, May!G16, Jun!G16) -> 64878.64 | H16: =SUM(Apr!H16, May!H16, Jun!H16) -> -4174.64 | I16: =IFERROR(H16/G16, "") -> -0.064345369
... A25: Kohls - Waterbury | B25: CT | C25: =SUM(Apr!C25, May!C25, Jun!C25) -> 76647 | D25: =SUM(Apr!D25, May!D25, Jun!D25) -> 0 | E25: =IF(AND(ISNUMBER(C25),ISNUMBER(D25)), C25-D25, "") -> 76647 | F25: =IFERROR(E25/D25, "") | G25: =SUM(Apr!G25, May!G25, Jun!G25) -> 79459.56 | H25: =SUM(Apr!H25, May!H25, Jun!H25) -> -2812.56 | I25: =IFERROR(H25/G25, "") -> -0.035396118

Sheet 3rd Qtr
A1: {=portfolio} -> Silicon Ranch | D1: 3rd Quarter Actual v. Expected | G1: 3rd Quarter Actual v. Forecasted
A2: Total | C2: =SUM(C4:C100) -> 0 | D2: =SUM(D4:D100) -> 0 | E2: =C2-D2 -> 0 | F2: =IFERROR(E2/D2, 0) -> 0 | G2: =SUM(G4:G100) -> 0 | H2: =C2-G2 -> 0 | I2: =IFERROR(H2/G2, 0) -> 0
A3: Site | B3: State | C3: Actual | D3: Expected | E3: Delta | F3: % | G3: Forecasted | H3: Delta | I3: %
A4: {=Sites[Site]} -> Iron Mountain - Windsor | B4: {=Sites[State]} -> CT | C4: =SUM(Jul!C4, Aug!C4, Sep!C4) -> 0 | D4: =SUM(Jul!D4, Aug!D4, Sep!D4) -> 0 | E4: =IF(AND(ISNUMBER(C4),ISNUMBER(D4)), C4-D4, "") -> 0 | F4: =IFERROR(E4/D4, "") | H4: =SUM(Jul!H4, Aug!H4, Sep!H4) -> 0 | I4: =IFERROR(H4/G4, "")
A5: Kohls - Auburn | B5: NY | C5: =SUM(Jul!C5, Aug!C5, Sep!C5) -> 0 | D5: =SUM(Jul!D5, Aug!D5, Sep!D5) -> 0 | E5: =IF(AND(ISNUMBER(C5),ISNUMBER(D5)), C5-D5, "") -> 0 | F5: =IFERROR(E5/D5, "") | H5: =SUM(Jul!H5, Aug!H5, Sep!H5) -> 0 | I5: =IFERROR(H5/G5, "")
A6: Kohls - Bensalem | B6: PA | C6: =SUM(Jul!C6, Aug!C6, Sep!C6) -> 0 | D6: =SUM(Jul!D6, Aug!D6, Sep!D6) -> 0 | E6: =IF(AND(ISNUMBER(C6),ISNUMBER(D6)), C6-D6, "") -> 0 | F6: =IFERROR(E6/D6, "") | H6: =SUM(Jul!H6, Aug!H6, Sep!H6) -> 0 | I6: =IFERROR(H6/G6, "")
A7: Kohls - Brick | B7: NJ | C7: =SUM(Jul!C7, Aug!C7, Sep!C7) -> 0 | D7: =SUM(Jul!D7, Aug!D7, Sep!D7) -> 0 | E7: =IF(AND(ISNUMBER(C7),ISNUMBER(D7)), C7-D7, "") -> 0 | F7: =IFERROR(E7/D7, "") | H7: =SUM(Jul!H7, Aug!H7, Sep!H7) -> 0 | I7: =IFERROR(H7/G7, "")
A8: Kohls - Buffalo | B8: NY | C8: =SUM(Jul!C8, Aug!C8, Sep!C8) -> 0 | D8: =SUM(Jul!D8, Aug!D8, Sep!D8) -> 0 | E8: =IF(AND(ISNUMBER(C8),ISNUMBER(D8)), C8-D8, "") -> 0 | F8: =IFERROR(E8/D8, "") | H8: =SUM(Jul!H8, Aug!H8, Sep!H8) -> 0 | I8: =IFERROR(H8/G8, "")
A9: Kohls - Canton | B9: CT | C9: =SUM(Jul!C9, Aug!C9, Sep!C9) -> 0 | D9: =SUM(Jul!D9, Aug!D9, Sep!D9) -> 0 | E9: =IF(AND(ISNUMBER(C9),ISNUMBER(D9)), C9-D9, "") -> 0 | F9: =IFERROR(E9/D9, "") | H9: =SUM(Jul!H9, Aug!H9, Sep!H9) -> 0 | I9: =IFERROR(H9/G9, "")
A10: Kohls - East Amherst | B10: NY | C10: =SUM(Jul!C10, Aug!C10, Sep!C10) -> 0 | D10: =SUM(Jul!D10, Aug!D10, Sep!D10) -> 0 | E10: =IF(AND(ISNUMBER(C10),ISNUMBER(D10)), C10-D10, "") -> 0 | F10: =IFERROR(E10/D10, "") | H10: =SUM(Jul!H10, Aug!H10, Sep!H10) -> 0 | I10: =IFERROR(H10/G10, "")
A11: Kohls - East Brunswick | B11: NJ | C11: =SUM(Jul!C11, Aug!C11, Sep!C11) -> 0 | D11: =SUM(Jul!D11, Aug!D11, Sep!D11) -> 0 | E11: =IF(AND(ISNUMBER(C11),ISNUMBER(D11)), C11-D11, "") -> 0 | F11: =IFERROR(E11/D11, "") | H11: =SUM(Jul!H11, Aug!H11, Sep!H11) -> 0 | I11: =IFERROR(H11/G11, "")
A12: Kohls - Edgewood | B12: MD | C12: =SUM(Jul!C12, Aug!C12, Sep!C12) -> 0 | D12: =SUM(Jul!D12, Aug!D12, Sep!D12) -> 0 | E12: =IF(AND(ISNUMBER(C12),ISNUMBER(D12)), C12-D12, "") -> 0 | F12: =IFERROR(E12/D12, "") | H12: =SUM(Jul!H12, Aug!H12, Sep!H12) -> 0 | I12: =IFERROR(H12/G12, "")
A13: Kohls - Granite Run | B13: PA | C13: =SUM(Jul!C13, Aug!C13, Sep!C13) -> 0 | D13: =SUM(Jul!D13, Aug!D13, Sep!D13) -> 0 | E13: =IF(AND(ISNUMBER(C13),ISNUMBER(D13)), C13-D13, "") -> 0 | F13: =IFERROR(E13/D13, "") | H13: =SUM(Jul!H13, Aug!H13, Sep!H13) -> 0 | I13: =IFERROR(H13/G13, "")
A14: Kohls - Greece | B14: NY | C14: =SUM(Jul!C14, Aug!C14, Sep!C14) -> 0 | D14: =SUM(Jul!D14, Aug!D14, Sep!D14) -> 0 | E14: =IF(AND(ISNUMBER(C14),ISNUMBER(D14)), C14-D14, "") -> 0 | F14: =IFERROR(E14/D14, "") | H14: =SUM(Jul!H14, Aug!H14, Sep!H14) -> 0 | I14: =IFERROR(H14/G14, "")
A15: Kohls - Hanover | B15: PA | C15: =SUM(Jul!C15, Aug!C15, Sep!C15) -> 0 | D15: =SUM(Jul!D15, Aug!D15, Sep!D15) -> 0 | E15: =IF(AND(ISNUMBER(C15),ISNUMBER(D15)), C15-D15, "") -> 0 | F15: =IFERROR(E15/D15, "") | H15: =SUM(Jul!H15, Aug!H15, Sep!H15) -> 0 | I15: =IFERROR(H15/G15, "")
A16: Kohls - Horsehead | B16: NY | C16: =SUM(Jul!C16, Aug!C16, Sep!C16) -> 0 | D16: =SUM(Jul!D16, Aug!D16, Sep!D16) -> 0 | E16: =IF(AND(ISNUMBER(C16),ISNUMBER(D16)), C16-D16, "") -> 0 | F16: =IFERROR(E16/D16, "") | H16: =SUM(Jul!H16, Aug!H16, Sep!H16) -> 0 | I16: =IFERROR(H16/G16, "")
... A25: Kohls - Waterbury | B25: CT | C25: =SUM(Jul!C25, Aug!C25, Sep!C25) -> 0 | D25: =SUM(Jul!D25, Aug!D25, Sep!D25) -> 0 | E25: =IF(AND(ISNUMBER(C25),ISNUMBER(D25)), C25-D25, "") -> 0 | F25: =IFERROR(E25/D25, "") | H25: =SUM(Jul!H25, Aug!H25, Sep!H25) -> 0 | I25: =IFERROR(H25/G25, "")

Sheet 4th Qtr
A1: {=portfolio} -> Silicon Ranch | D1: 4th Quarter Actual v. Expected | G1: 4th Quarter Actual v. Forecasted
A2: Total | C2: =SUM(C4:C100) -> 0 | D2: =SUM(D4:D100) -> 0 | E2: =C2-D2 -> 0 | F2: =IFERROR(E2/D2, 0) -> 0 | G2: =SUM(G4:G100) -> 0 | H2: =C2-G2 -> 0 | I2: =IFERROR(H2/G2, 0) -> 0
A3: Site | B3: State | C3: Actual | D3: Expected | E3: Delta | F3: % | G3: Forecasted | H3: Delta | I3: %
A4: {=Sites[Site]} -> Iron Mountain - Windsor | B4: {=Sites[State]} -> CT | C4: =SUM(Oct!C4, Nov!C4, Dec!C4) -> 0 | D4: =SUM(Oct!D4, Nov!D4, Dec!D4) -> 0 | E4: =IF(AND(ISNUMBER(C4),ISNUMBER(D4)), C4-D4, "") -> 0 | F4: =IFERROR(E4/D4, "") | H4: =SUM(Oct!H4, Nov!H4, Dec!H4) -> 0 | I4: =IFERROR(H4/G4, "")
A5: Kohls - Auburn | B5: NY | C5: =SUM(Oct!C5, Nov!C5, Dec!C5) -> 0 | D5: =SUM(Oct!D5, Nov!D5, Dec!D5) -> 0 | E5: =IF(AND(ISNUMBER(C5),ISNUMBER(D5)), C5-D5, "") -> 0 | F5: =IFERROR(E5/D5, "") | H5: =SUM(Oct!H5, Nov!H5, Dec!H5) -> 0 | I5: =IFERROR(H5/G5, "")
A6: Kohls - Bensalem | B6: PA | C6: =SUM(Oct!C6, Nov!C6, Dec!C6) -> 0 | D6: =SUM(Oct!D6, Nov!D6, Dec!D6) -> 0 | E6: =IF(AND(ISNUMBER(C6),ISNUMBER(D6)), C6-D6, "") -> 0 | F6: =IFERROR(E6/D6, "") | H6: =SUM(Oct!H6, Nov!H6, Dec!H6) -> 0 | I6: =IFERROR(H6/G6, "")
A7: Kohls - Brick | B7: NJ | C7: =SUM(Oct!C7, Nov!C7, Dec!C7) -> 0 | D7: =SUM(Oct!D7, Nov!D7, Dec!D7) -> 0 | E7: =IF(AND(ISNUMBER(C7),ISNUMBER(D7)), C7-D7, "") -> 0 | F7: =IFERROR(E7/D7, "") | H7: =SUM(Oct!H7, Nov!H7, Dec!H7) -> 0 | I7: =IFERROR(H7/G7, "")
A8: Kohls - Buffalo | B8: NY | C8: =SUM(Oct!C8, Nov!C8, Dec!C8) -> 0 | D8: =SUM(Oct!D8, Nov!D8, Dec!D8) -> 0 | E8: =IF(AND(ISNUMBER(C8),ISNUMBER(D8)), C8-D8, "") -> 0 | F8: =IFERROR(E8/D8, "") | H8: =SUM(Oct!H8, Nov!H8, Dec!H8) -> 0 | I8: =IFERROR(H8/G8, "")
A9: Kohls - Canton | B9: CT | C9: =SUM(Oct!C9, Nov!C9, Dec!C9) -> 0 | D9: =SUM(Oct!D9, Nov!D9, Dec!D9) -> 0 | E9: =IF(AND(ISNUMBER(C9),ISNUMBER(D9)), C9-D9, "") -> 0 | F9: =IFERROR(E9/D9, "") | H9: =SUM(Oct!H9, Nov!H9, Dec!H9) -> 0 | I9: =IFERROR(H9/G9, "")
A10: Kohls - East Amherst | B10: NY | C10: =SUM(Oct!C10, Nov!C10, Dec!C10) -> 0 | D10: =SUM(Oct!D10, Nov!D10, Dec!D10) -> 0 | E10: =IF(AND(ISNUMBER(C10),ISNUMBER(D10)), C10-D10, "") -> 0 | F10: =IFERROR(E10/D10, "") | H10: =SUM(Oct!H10, Nov!H10, Dec!H10) -> 0 | I10: =IFERROR(H10/G10, "")
A11: Kohls - East Brunswick | B11: NJ | C11: =SUM(Oct!C11, Nov!C11, Dec!C11) -> 0 | D11: =SUM(Oct!D11, Nov!D11, Dec!D11) -> 0 | E11: =IF(AND(ISNUMBER(C11),ISNUMBER(D11)), C11-D11, "") -> 0 | F11: =IFERROR(E11/D11, "") | H11: =SUM(Oct!H11, Nov!H11, Dec!H11) -> 0 | I11: =IFERROR(H11/G11, "")
A12: Kohls - Edgewood | B12: MD | C12: =SUM(Oct!C12, Nov!C12, Dec!C12) -> 0 | D12: =SUM(Oct!D12, Nov!D12, Dec!D12) -> 0 | E12: =IF(AND(ISNUMBER(C12),ISNUMBER(D12)), C12-D12, "") -> 0 | F12: =IFERROR(E12/D12, "") | H12: =SUM(Oct!H12, Nov!H12, Dec!H12) -> 0 | I12: =IFERROR(H12/G12, "")
A13: Kohls - Granite Run | B13: PA | C13: =SUM(Oct!C13, Nov!C13, Dec!C13) -> 0 | D13: =SUM(Oct!D13, Nov!D13, Dec!D13) -> 0 | E13: =IF(AND(ISNUMBER(C13),ISNUMBER(D13)), C13-D13, "") -> 0 | F13: =IFERROR(E13/D13, "") | H13: =SUM(Oct!H13, Nov!H13, Dec!H13) -> 0 | I13: =IFERROR(H13/G13, "")
A14: Kohls - Greece | B14: NY | C14: =SUM(Oct!C14, Nov!C14, Dec!C14) -> 0 | D14: =SUM(Oct!D14, Nov!D14, Dec!D14) -> 0 | E14: =IF(AND(ISNUMBER(C14),ISNUMBER(D14)), C14-D14, "") -> 0 | F14: =IFERROR(E14/D14, "") | H14: =SUM(Oct!H14, Nov!H14, Dec!H14) -> 0 | I14: =IFERROR(H14/G14, "")
A15: Kohls - Hanover | B15: PA | C15: =SUM(Oct!C15, Nov!C15, Dec!C15) -> 0 | D15: =SUM(Oct!D15, Nov!D15, Dec!D15) -> 0 | E15: =IF(AND(ISNUMBER(C15),ISNUMBER(D15)), C15-D15, "") -> 0 | F15: =IFERROR(E15/D15, "") | H15: =SUM(Oct!H15, Nov!H15, Dec!H15) -> 0 | I15: =IFERROR(H15/G15, "")
A16: Kohls - Horsehead | B16: NY | C16: =SUM(Oct!C16, Nov!C16, Dec!C16) -> 0 | D16: =SUM(Oct!D16, Nov!D16, Dec!D16) -> 0 | E16: =IF(AND(ISNUMBER(C16),ISNUMBER(D16)), C16-D16, "") -> 0 | F16: =IFERROR(E16/D16, "") | H16: =SUM(Oct!H16, Nov!H16, Dec!H16) -> 0 | I16: =IFERROR(H16/G16, "")
... A25: Kohls - Waterbury | B25: CT | C25: =SUM(Oct!C25, Nov!C25, Dec!C25) -> 0 | D25: =SUM(Oct!D25, Nov!D25, Dec!D25) -> 0 | E25: =IF(AND(ISNUMBER(C25),ISNUMBER(D25)), C25-D25, "") -> 0 | F25: =IFERROR(E25/D25, "") | H25: =SUM(Oct!H25, Nov!H25, Dec!H25) -> 0 | I25: =IFERROR(H25/G25, "")

Sheet Jan
A1: {=portfolio} -> Silicon Ranch | D1: January Actual v. Expected | G1: January Actual v. Forecasted
A2: Total | C2: =SUM(C4:C99) -> 205652.6 | D2: =SUM(D4:D99) -> 0 | E2: =C2-D2 -> 205652.6 | F2: =IFERROR(E2/D2, 0) -> 0 | G2: =SUM(G4:G99) -> 444598.28 | H2: =C2-G2 -> -238945.68 | I2: =IFERROR(H2/G2, 0) -> -0.53744176 | J2: =IF(AND(TODAY()>DATE(2024, 1, 1), COUNTA(Sites[Site])<>(COUNT(C:C)-1)), "Some sites are missing actual data; if new sites were added, make sure they are aligned correctly (including prior months!)", "")
A3: Site | B3: State | C3: Actual | D3: Expected | E3: Delta | F3: % | G3: Forecasted | H3: Delta | I3: % | J3: Notes | K3: Service Requests
A4: {=Sites[Site]} -> Iron Mountain - Windsor | B4: {=Sites[State]} -> CT | C4: 6324 | D4: 0 | E4: =IF(AND(ISNUMBER(C4),ISNUMBER(D4)), C4-D4, "") -> 6324 | F4: =IFERROR(E4/D4, "") | G4: 13022.34 | H4: =IF(AND(ISNUMBER(C4),ISNUMBER(G4)), C4-G4, "") -> -6698.34 | I4: =IFERROR(H4/G4, "") -> -0.51437299
A5: Kohls - Auburn | B5: NY | C5: 4362 | D5: 0 | E5: =IF(AND(ISNUMBER(C5),ISNUMBER(D5)), C5-D5, "") -> 4362 | F5: =IFERROR(E5/D5, "") | G5: 4782 | H5: =IF(AND(ISNUMBER(C5),ISNUMBER(G5)), C5-G5, "") -> -420 | I5: =IFERROR(H5/G5, "") -> -0.08782936 | J5: 1. Site tripped offline due to a utility outage at 10pm on 01/09 and came back online at 3pm on 01/10. | K5: 1. SR080112
A6: Kohls - Bensalem | B6: PA | C6: 9630 | D6: 0 | E6: =IF(AND(ISNUMBER(C6),ISNUMBER(D6)), C6-D6, "") -> 9630 | F6: =IFERROR(E6/D6, "") | G6: 15754.4 | H6: =IF(AND(ISNUMBER(C6),ISNUMBER(G6)), C6-G6, "") -> -6124.4 | I6: =IFERROR(H6/G6, "") -> -0.38874219
A7: Kohls - Brick | B7: NJ | C7: 11393 | D7: 0 | E7: =IF(AND(ISNUMBER(C7),ISNUMBER(D7)), C7-D7, "") -> 11393 | F7: =IFERROR(E7/D7, "") | G7: 16696.5 | H7: =IF(AND(ISNUMBER(C7),ISNUMBER(G7)), C7-G7, "") -> -5303.5 | I7: =IFERROR(H7/G7, "") -> -0.31764142
A8: Kohls - Buffalo | B8: NY | C8: 3961 | D8: 0 | E8: =IF(AND(ISNUMBER(C8),ISNUMBER(D8)), C8-D8, "") -> 3961 | F8: =IFERROR(E8/D8, "") | G8: 8044.58 | H8: =IF(AND(ISNUMBER(C8),ISNUMBER(G8)), C8-G8, "") -> -4083.58 | I8: =IFERROR(H8/G8, "") -> -0.50761879
A9: Kohls - Canton | B9: CT | C9: 2979 | D9: 0 | E9: =IF(AND(ISNUMBER(C9),ISNUMBER(D9)), C9-D9, "") -> 2979 | F9: =IFERROR(E9/D9, "") | G9: 5837.36 | H9: =IF(AND(ISNUMBER(C9),ISNUMBER(G9)), C9-G9, "") -> -2858.36 | I9: =IFERROR(H9/G9, "") -> -0.48966656
A10: Kohls - East Amherst | B10: NY | C10: 2767 | D10: 0 | E10: =IF(AND(ISNUMBER(C10),ISNUMBER(D10)), C10-D10, "") -> 2767 | F10: =IFERROR(E10/D10, "") | G10: 8482.7 | H10: =IF(AND(ISNUMBER(C10),ISNUMBER(G10)), C10-G10, "") -> -5715.7 | I10: =IFERROR(H10/G10, "") -> -0.67380669
A11: Kohls - East Brunswick | B11: NJ | C11: 973 | D11: 0 | E11: =IF(AND(ISNUMBER(C11),ISNUMBER(D11)), C11-D11, "") -> 973 | F11: =IFERROR(E11/D11, "") | G11: 23294.45 | H11: =IF(AND(ISNUMBER(C11),ISNUMBER(G11)), C11-G11, "") -> -22321.45 | I11: =IFERROR(H11/G11, "") -> -0.95823039
A12: Kohls - Edgewood | B12: MD | C12: 71866 | D12: 0 | E12: =IF(AND(ISNUMBER(C12),ISNUMBER(D12)), C12-D12, "") -> 71866 | F12: =IFERROR(E12/D12, "") | G12: 136238.63 | H12: =IF(AND(ISNUMBER(C12),ISNUMBER(G12)), C12-G12, "") -> -64372.63 | I12: =IFERROR(H12/G12, "") -> -0.4724991 | J12: 1. Inverter 3 is offline from 01/01 to 01/03 | K12: 1. SR079771
A13: Kohls - Granite Run | B13: PA | C13: 9421 | D13: 0 | E13: =IF(AND(ISNUMBER(C13),ISNUMBER(D13)), C13-D13, "") -> 9421 | F13: =IFERROR(E13/D13, "") | G13: 16020.95 | H13: =IF(AND(ISNUMBER(C13),ISNUMBER(G13)), C13-G13, "") -> -6599.95 | I13: =IFERROR(H13/G13, "") -> -0.41195747
A14: Kohls - Greece | B14: NY | C14: 0 | D14: 0 | E14: =IF(AND(ISNUMBER(C14),ISNUMBER(D14)), C14-D14, "") -> 0 | F14: =IFERROR(E14/D14, "") | G14: 9424.18 | H14: =IF(AND(ISNUMBER(C14),ISNUMBER(G14)), C14-G14, "") -> -9424.18 | I14: =IFERROR(H14/G14, "") -> -1 | J14: 1. Site offline for module replacement work | K14: 1. SR078556
A15: Kohls - Hanover | B15: PA | C15: 11065 | D15: 0 | E15: =IF(AND(ISNUMBER(C15),ISNUMBER(D15)), C15-D15, "") -> 11065 | F15: =IFERROR(E15/D15, "") | G15: 18878.62 | H15: =IF(AND(ISNUMBER(C15),ISNUMBER(G15)), C15-G15, "") -> -7813.62 | I15: =IFERROR(H15/G15, "") -> -0.41388724
A16: Kohls - Horsehead | B16: NY | C16: 2351 | D16: 0 | E16: =IF(AND(ISNUMBER(C16),ISNUMBER(D16)), C16-D16, "") -> 2351 | F16: =IFERROR(E16/D16, "") | G16: 12770.65 | H16: =IF(AND(ISNUMBER(C16),ISNUMBER(G16)), C16-G16, "") -> -10419.65 | I16: =IFERROR(H16/G16, "") -> -0.815906 | J16: 1. Inverter is offline from 01/07 to 01/26 | K16: 1. SR080006
A17: Kohls - Hudson | B17: NY | C17: 197 | D17: 0 | E17: =IF(AND(ISNUMBER(C17),ISNUMBER(D17)), C17-D17, "") -> 197 | F17: =IFERROR(E17/D17, "") | G17: 12854.55 | H17: =IF(AND(ISNUMBER(C17),ISNUMBER(G17)), C17-G17, "") -> -12657.55 | I17: =IFERROR(H17/G17, "") -> -0.98467469 | J17: 1. Inverter is offline from 12/17 to 01/19. | K17: 1. SR079528
A18: Kohls - Ithaca | B18: NY | C18: 4385 | D18: 0 | E18: =IF(AND(ISNUMBER(C18),ISNUMBER(D18)), C18-D18, "") -> 4385 | F18: =IFERROR(E18/D18, "") | G18: 11913.06 | H18: =IF(AND(ISNUMBER(C18),ISNUMBER(G18)), C18-G18, "") -> -7528.06 | I18: =IFERROR(H18/G18, "") -> -0.63191657
A19: Kohls - Kingston | B19: NY | C19: 9244 | D19: 0 | E19: =IF(AND(ISNUMBER(C19),ISNUMBER(D19)), C19-D19, "") -> 9244 | F19: =IFERROR(E19/D19, "") | G19: 22381.27 | H19: =IF(AND(ISNUMBER(C19),ISNUMBER(G19)), C19-G19, "") -> -13137.27 | I19: =IFERROR(H19/G19, "") -> -0.58697607
A20: Kohls - Mechanicsburg | B20: PA | C20: 11788 | D20: 0 | E20: =IF(AND(ISNUMBER(C20),ISNUMBER(D20)), C20-D20, "") -> 11788 | F20: =IFERROR(E20/D20, "") | G20: 21618.64 | H20: =IF(AND(ISNUMBER(C20),ISNUMBER(G20)), C20-G20, "") -> -9830.64 | I20: =IFERROR(H20/G20, "") -> -0.45472981
A21: Kohls - Middletown | B21: NJ | C21: 15292 | D21: 0 | E21: =IF(AND(ISNUMBER(C21),ISNUMBER(D21)), C21-D21, "") -> 15292 | F21: =IFERROR(E21/D21, "") | G21: 29635.82 | H21: =IF(AND(ISNUMBER(C21),ISNUMBER(G21)), C21-G21, "") -> -14343.82 | I21: =IFERROR(H21/G21, "") -> -0.4840028 | J21: 1. Inverter 1 multiple times tripped offline | K21: 1. SR079062
A22: Kohls - North Amherst | B22: NY | C22: 2846 | D22: 0 | E22: =IF(AND(ISNUMBER(C22),ISNUMBER(D22)), C22-D22, "") -> 2846 | F22: =IFERROR(E22/D22, "") | G22: 6525.15 | H22: =IF(AND(ISNUMBER(C22),ISNUMBER(G22)), C22-G22, "") -> -3679.15 | I22: =IFERROR(H22/G22, "") -> -0.56384144
A23: Kohls - Staten Island | B23: NY | C23: 8661.6 | D23: 0 | E23: =IF(AND(ISNUMBER(C23),ISNUMBER(D23)), C23-D23, "") -> 8661.6 | F23: =IFERROR(E23/D23, "") | G23: 15476.69 | H23: =IF(AND(ISNUMBER(C23),ISNUMBER(G23)), C23-G23, "") -> -6815.09 | I23: =IFERROR(H23/G23, "") -> -0.44034545
A24: Kohls - Warminster | B24: PA | C24: 7770 | D24: 0 | E24: =IF(AND(ISNUMBER(C24),ISNUMBER(D24)), C24-D24, "") -> 7770 | F24: =IFERROR(E24/D24, "") | G24: 19541.34 | H24: =IF(AND(ISNUMBER(C24),ISNUMBER(G24)), C24-G24, "") -> -11771.34 | I24: =IFERROR(H24/G24, "") -> -0.60238141 | J24: 1. Inverter is frequentley offline & reporting "AC current Imbalance". | K24: 1. SR078291
A25: Kohls - Waterbury | B25: CT | C25: 8377 | D25: 0 | E25: =IF(AND(ISNUMBER(C25),ISNUMBER(D25)), C25-D25, "") -> 8377 | F25: =IFERROR(E25/D25, "") | G25: 15404.4 | H25: =IF(AND(ISNUMBER(C25),ISNUMBER(G25)), C25-G25, "") -> -7027.4 | I25: =IFERROR(H25/G25, "") -> -0.45619433

Sheet Feb
A1: {=portfolio} -> Silicon Ranch | D1: February Actual v. Expected | G1: February Actual v. Forecasted
A2: Total | C2: =SUM(C4:C100) -> 603167.75 | D2: =SUM(D4:D100) -> 0 | E2: =C2-D2 -> 603167.75 | F2: =IFERROR(E2/D2, 0) -> 0 | G2: =SUM(G4:G100) -> 584890.32 | H2: =C2-G2 -> 18277.43 | I2: =IFERROR(H2/G2, 0) -> 0.031249329 | J2: =IF(AND(TODAY()>DATE(2024, 2, 1), COUNTA(Sites[Site])<>(COUNT(C:C)-1)), "Some sites are missing actual data; if new sites were added, make sure they are aligned correctly (including prior months!)", "")
A3: Site | B3: State | C3: Actual | D3: Expected | E3: Delta | F3: % | G3: Forecasted | H3: Delta | I3: % | J3: Notes | K3: Service Requests
A4: {=Sites[Site]} -> Iron Mountain - Windsor | B4: {=Sites[State]} -> CT | C4: 16946.75 | D4: 0 | E4: =IF(AND(ISNUMBER(C4),ISNUMBER(D4)), C4-D4, "") -> 16946.75 | F4: =IFERROR(E4/D4, "") | G4: 19218 | H4: =IF(AND(ISNUMBER(C4),ISNUMBER(G4)), C4-G4, "") -> -2271.25 | I4: =IFERROR(H4/G4, "") -> -0.11818347
A5: Kohls - Auburn | B5: NY | C5: 17104 | D5: 0 | E5: =IF(AND(ISNUMBER(C5),ISNUMBER(D5)), C5-D5, "") -> 17104 | F5: =IFERROR(E5/D5, "") | G5: 10813.11 | H5: =IF(AND(ISNUMBER(C5),ISNUMBER(G5)), C5-G5, "") -> 6290.89 | I5: =IFERROR(H5/G5, "") -> 0.58178359
A6: Kohls - Bensalem | B6: PA | C6: 24318 | D6: 0 | E6: =IF(AND(ISNUMBER(C6),ISNUMBER(D6)), C6-D6, "") -> 24318 | F6: =IFERROR(E6/D6, "") | G6: 20009.19 | H6: =IF(AND(ISNUMBER(C6),ISNUMBER(G6)), C6-G6, "") -> 4308.81 | I6: =IFERROR(H6/G6, "") -> 0.21534155
A7: Kohls - Brick | B7: NJ | C7: 26352 | D7: 0 | E7: =IF(AND(ISNUMBER(C7),ISNUMBER(D7)), C7-D7, "") -> 26352 | F7: =IFERROR(E7/D7, "") | G7: 22735.46 | H7: =IF(AND(ISNUMBER(C7),ISNUMBER(G7)), C7-G7, "") -> 3616.54 | I7: =IFERROR(H7/G7, "") -> 0.15907046
A8: Kohls - Buffalo | B8: NY | C8: 21121 | D8: 0 | E8: =IF(AND(ISNUMBER(C8),ISNUMBER(D8)), C8-D8, "") -> 21121 | F8: =IFERROR(E8/D8, "") | G8: 15492.57 | H8: =IF(AND(ISNUMBER(C8),ISNUMBER(G8)), C8-G8, "") -> 5628.43 | I8: =IFERROR(H8/G8, "") -> 0.36329867 | J8: 1. Inverter 7 offline due to "Grid Contactor Open from 02/19 to 02/29 | K8: 1. SR081105
A9: Kohls - Canton | B9: CT | C9: 8146 | D9: 0 | E9: =IF(AND(ISNUMBER(C9),ISNUMBER(D9)), C9-D9, "") -> 8146 | F9: =IFERROR(E9/D9, "") | G9: 7037.82 | H9: =IF(AND(ISNUMBER(C9),ISNUMBER(G9)), C9-G9, "") -> 1108.18 | I9: =IFERROR(H9/G9, "") -> 0.15746069
A10: Kohls - East Amherst | B10: NY | C10: 20665 | D10: 0 | E10: =IF(AND(ISNUMBER(C10),ISNUMBER(D10)), C10-D10, "") -> 20665 | F10: =IFERROR(E10/D10, "") | G10: 14355.33 | H10: =IF(AND(ISNUMBER(C10),ISNUMBER(G10)), C10-G10, "") -> 6309.67 | I10: =IFERROR(H10/G10, "") -> 0.439535
A11: Kohls - East Brunswick | B11: NJ | C11: 31269 | D11: 0 | E11: =IF(AND(ISNUMBER(C11),ISNUMBER(D11)), C11-D11, "") -> 31269 | F11: =IFERROR(E11/D11, "") | G11: 30992.07 | H11: =IF(AND(ISNUMBER(C11),ISNUMBER(G11)), C11-G11, "") -> 276.93 | I11: =IFERROR(H11/G11, "") -> 0.0089355116
A12: Kohls - Edgewood | B12: MD | C12: 184974 | D12: 0 | E12: =IF(AND(ISNUMBER(C12),ISNUMBER(D12)), C12-D12, "") -> 184974 | F12: =IFERROR(E12/D12, "") | G12: 169384.2 | H12: =IF(AND(ISNUMBER(C12),ISNUMBER(G12)), C12-G12, "") -> 15589.8 | I12: =IFERROR(H12/G12, "") -> 0.0920381
A13: Kohls - Granite Run | B13: PA | C13: 22487 | D13: 0 | E13: =IF(AND(ISNUMBER(C13),ISNUMBER(D13)), C13-D13, "") -> 22487 | F13: =IFERROR(E13/D13, "") | G13: 20204.97 | H13: =IF(AND(ISNUMBER(C13),ISNUMBER(G13)), C13-G13, "") -> 2282.03 | I13: =IFERROR(H13/G13, "") -> 0.11294399
A14: Kohls - Greece | B14: NY | C14: 16874 | D14: 0 | E14: =IF(AND(ISNUMBER(C14),ISNUMBER(D14)), C14-D14, "") -> 16874 | F14: =IFERROR(E14/D14, "") | G14: 14942.59 | H14: =IF(AND(ISNUMBER(C14),ISNUMBER(G14)), C14-G14, "") -> 1931.41 | I14: =IFERROR(H14/G14, "") -> 0.12925537
A15: Kohls - Hanover | B15: PA | C15: 26512 | D15: 0 | E15: =IF(AND(ISNUMBER(C15),ISNUMBER(D15)), C15-D15, "") -> 26512 | F15: =IFERROR(E15/D15, "") | G15: 22444.04 | H15: =IF(AND(ISNUMBER(C15),ISNUMBER(G15)), C15-G15, "") -> 4067.96 | I15: =IFERROR(H15/G15, "") -> 0.18124901
A16: Kohls - Horsehead | B16: NY | C16: 18647 | D16: 0 | E16: =IF(AND(ISNUMBER(C16),ISNUMBER(D16)), C16-D16, "") -> 18647 | F16: =IFERROR(E16/D16, "") | G16: 16126.44 | H16: =IF(AND(ISNUMBER(C16),ISNUMBER(G16)), C16-G16, "") -> 2520.56 | I16: =IFERROR(H16/G16, "") -> 0.15629984
A17: Kohls - Hudson | B17: NY | C17: 6932 | D17: 0 | E17: =IF(AND(ISNUMBER(C17),ISNUMBER(D17)), C17-D17, "") -> 6932 | F17: =IFERROR(E17/D17, "") | G17: 18708.54 | H17: =IF(AND(ISNUMBER(C17),ISNUMBER(G17)), C17-G17, "") -> -11776.54 | I17: =IFERROR(H17/G17, "") -> -0.62947403
A18: Kohls - Ithaca | B18: NY | C18: 16819 | D18: 0 | E18: =IF(AND(ISNUMBER(C18),ISNUMBER(D18)), C18-D18, "") -> 16819 | F18: =IFERROR(E18/D18, "") | G18: 17888.23 | H18: =IF(AND(ISNUMBER(C18),ISNUMBER(G18)), C18-G18, "") -> -1069.23 | I18: =IFERROR(H18/G18, "") -> -0.059772823
A19: Kohls - Kingston | B19: NY | C19: 35496 | D19: 0 | E19: =IF(AND(ISNUMBER(C19),ISNUMBER(D19)), C19-D19, "") -> 35496 | F19: =IFERROR(E19/D19, "") | G19: 24776.93 | H19: =IF(AND(ISNUMBER(C19),ISNUMBER(G19)), C19-G19, "") -> 10719.07 | I19: =IFERROR(H19/G19, "") -> 0.43262301
A20: Kohls - Mechanicsburg | B20: PA | C20: 30051 | D20: 0 | E20: =IF(AND(ISNUMBER(C20),ISNUMBER(D20)), C20-D20, "") -> 30051 | F20: =IFERROR(E20/D20, "") | G20: 25384.43 | H20: =IF(AND(ISNUMBER(C20),ISNUMBER(G20)), C20-G20, "") -> 4666.57 | I20: =IFERROR(H20/G20, "") -> 0.18383592
A21: Kohls - Middletown | B21: NJ | C21: 15419 | D21: 0 | E21: =IF(AND(ISNUMBER(C21),ISNUMBER(D21)), C21-D21, "") -> 15419 | F21: =IFERROR(E21/D21, "") | G21: 36407.89 | H21: =IF(AND(ISNUMBER(C21),ISNUMBER(G21)), C21-G21, "") -> -20988.89 | I21: =IFERROR(H21/G21, "") -> -0.5764929 | J21: 1. Inverter tripping offline and reporting "Coolant temperature" for multiple days | K21: 1. SR080696
A22: Kohls - North Amherst | B22: NY | C22: 15228 | D22: 0 | E22: =IF(AND(ISNUMBER(C22),ISNUMBER(D22)), C22-D22, "") -> 15228 | F22: =IFERROR(E22/D22, "") | G22: 12491 | H22: =IF(AND(ISNUMBER(C22),ISNUMBER(G22)), C22-G22, "") -> 2737 | I22: =IFERROR(H22/G22, "") -> 0.21911776
A23: Kohls - Staten Island | B23: NY | C23: 19596 | D23: 0 | E23: =IF(AND(ISNUMBER(C23),ISNUMBER(D23)), C23-D23, "") -> 19596 | F23: =IFERROR(E23/D23, "") | G23: 21345.24 | H23: =IF(AND(ISNUMBER(C23),ISNUMBER(G23)), C23-G23, "") -> -1749.24 | I23: =IFERROR(H23/G23, "") -> -0.081949887
A24: Kohls - Warminster | B24: PA | C24: 8422 | D24: 0 | E24: =IF(AND(ISNUMBER(C24),ISNUMBER(D24)), C24-D24, "") -> 8422 | F24: =IFERROR(E24/D24, "") | G24: 24631.64 | H24: =IF(AND(ISNUMBER(C24),ISNUMBER(G24)), C24-G24, "") -> -16209.64 | I24: =IFERROR(H24/G24, "") -> -0.65808204
A25: Kohls - Waterbury | B25: CT | C25: 19789 | D25: 0 | E25: =IF(AND(ISNUMBER(C25),ISNUMBER(D25)), C25-D25, "") -> 19789 | F25: =IFERROR(E25/D25, "") | G25: 19500.63 | H25: =IF(AND(ISNUMBER(C25),ISNUMBER(G25)), C25-G25, "") -> 288.37 | I25: =IFERROR(H25/G25, "") -> 0.014787727

Sheet Mar
A1: {=portfolio} -> Silicon Ranch | D1: March Actual v. Expected | G1: March Actual v. Forecasted
A2: Total | C2: =SUM(C4:C100) -> 802214 | D2: =SUM(D4:D100) -> 0 | E2: =C2-D2 -> 802214 | F2: =IFERROR(E2/D2, 0) -> 0 | G2: =SUM(G4:G100) -> 897139.91 | H2: =C2-G2 -> -94925.909 | I2: =IFERROR(H2/G2, 0) -> -0.10580948 | J2: =IF(AND(TODAY()>DATE(2024, 3, 1), COUNTA(Sites[Site])<>(COUNT(C:C)-1)), "Some sites are missing actual data; if new sites were added, make sure they are aligned correctly (including prior months!)", "")
A3: Site | B3: State | C3: Actual | D3: Expected | E3: Delta | F3: % | G3: Forecasted | H3: Delta | I3: % | J3: Notes | K3: Service Requests
A4: {=Sites[Site]} -> Iron Mountain - Windsor | B4: {=Sites[State]} -> CT | C4: 26650 | D4: 0 | E4: =IF(AND(ISNUMBER(C4),ISNUMBER(D4)), C4-D4, "") -> 26650 | F4: =IFERROR(E4/D4, "") | G4: 25065.9 | H4: =IF(AND(ISNUMBER(C4),ISNUMBER(G4)), C4-G4, "") -> 1584.1 | I4: =IFERROR(H4/G4, "") -> 0.063197412
A5: Kohls - Auburn | B5: NY | C5: 23334 | D5: 0 | E5: =IF(AND(ISNUMBER(C5),ISNUMBER(D5)), C5-D5, "") -> 23334 | F5: =IFERROR(E5/D5, "") | G5: 23816.8 | H5: =IF(AND(ISNUMBER(C5),ISNUMBER(G5)), C5-G5, "") -> -482.8 | I5: =IFERROR(H5/G5, "") -> -0.020271405
A6: Kohls - Bensalem | B6: PA | C6: 32980 | D6: 0 | E6: =IF(AND(ISNUMBER(C6),ISNUMBER(D6)), C6-D6, "") -> 32980 | F6: =IFERROR(E6/D6, "") | G6: 29898.43 | H6: =IF(AND(ISNUMBER(C6),ISNUMBER(G6)), C6-G6, "") -> 3081.57 | I6: =IFERROR(H6/G6, "") -> 0.10306795
A7: Kohls - Brick | B7: NJ | C7: 36345 | D7: 0 | E7: =IF(AND(ISNUMBER(C7),ISNUMBER(D7)), C7-D7, "") -> 36345 | F7: =IFERROR(E7/D7, "") | G7: 35848.9 | H7: =IF(AND(ISNUMBER(C7),ISNUMBER(G7)), C7-G7, "") -> 496.1 | I7: =IFERROR(H7/G7, "") -> 0.013838639
A8: Kohls - Buffalo | B8: NY | C8: 28827 | D8: 0 | E8: =IF(AND(ISNUMBER(C8),ISNUMBER(D8)), C8-D8, "") -> 28827 | F8: =IFERROR(E8/D8, "") | G8: 31190.22 | H8: =IF(AND(ISNUMBER(C8),ISNUMBER(G8)), C8-G8, "") -> -2363.22 | I8: =IFERROR(H8/G8, "") -> -0.075767981
A9: Kohls - Canton | B9: CT | C9: 13440 | D9: 0 | E9: =IF(AND(ISNUMBER(C9),ISNUMBER(D9)), C9-D9, "") -> 13440 | F9: =IFERROR(E9/D9, "") | G9: 11179.87 | H9: =IF(AND(ISNUMBER(C9),ISNUMBER(G9)), C9-G9, "") -> 2260.13 | I9: =IFERROR(H9/G9, "") -> 0.20216067
A10: Kohls - East Amherst | B10: NY | C10: 25808 | D10: 0 | E10: =IF(AND(ISNUMBER(C10),ISNUMBER(D10)), C10-D10, "") -> 25808 | F10: =IFERROR(E10/D10, "") | G10: 28710.66 | H10: =IF(AND(ISNUMBER(C10),ISNUMBER(G10)), C10-G10, "") -> -2902.66 | I10: =IFERROR(H10/G10, "") -> -0.10110043
A11: Kohls - East Brunswick | B11: NJ | C11: 47751 | D11: 0 | E11: =IF(AND(ISNUMBER(C11),ISNUMBER(D11)), C11-D11, "") -> 47751 | F11: =IFERROR(E11/D11, "") | G11: 46158.2 | H11: =IF(AND(ISNUMBER(C11),ISNUMBER(G11)), C11-G11, "") -> 1592.8 | I11: =IFERROR(H11/G11, "") -> 0.034507411
A12: Kohls - Edgewood | B12: MD | C12: 232222 | D12: 0 | E12: =IF(AND(ISNUMBER(C12),ISNUMBER(D12)), C12-D12, "") -> 232222 | F12: =IFERROR(E12/D12, "") | G12: 239043.04 | H12: =IF(AND(ISNUMBER(C12),ISNUMBER(G12)), C12-G12, "") -> -6821.04 | I12: =IFERROR(H12/G12, "") -> -0.028534778
A13: Kohls - Granite Run | B13: PA | C13: 31741 | D13: 0 | E13: =IF(AND(ISNUMBER(C13),ISNUMBER(D13)), C13-D13, "") -> 31741 | F13: =IFERROR(E13/D13, "") | G13: 29491.24 | H13: =IF(AND(ISNUMBER(C13),ISNUMBER(G13)), C13-G13, "") -> 2249.76 | I13: =IFERROR(H13/G13, "") -> 0.076285704
A14: Kohls - Greece | B14: NY | C14: 23984 | D14: 0 | E14: =IF(AND(ISNUMBER(C14),ISNUMBER(D14)), C14-D14, "") -> 23984 | F14: =IFERROR(E14/D14, "") | G14: 27592.06 | H14: =IF(AND(ISNUMBER(C14),ISNUMBER(G14)), C14-G14, "") -> -3608.06 | I14: =IFERROR(H14/G14, "") -> -0.13076443
A15: Kohls - Hanover | B15: PA | C15: 26616 | D15: 0 | E15: =IF(AND(ISNUMBER(C15),ISNUMBER(D15)), C15-D15, "") -> 26616 | F15: =IFERROR(E15/D15, "") | G15: 32416.01 | H15: =IF(AND(ISNUMBER(C15),ISNUMBER(G15)), C15-G15, "") -> -5800.01 | I15: =IFERROR(H15/G15, "") -> -0.17892424
A16: Kohls - Horsehead | B16: NY | C16: 23060 | D16: 0 | E16: =IF(AND(ISNUMBER(C16),ISNUMBER(D16)), C16-D16, "") -> 23060 | F16: =IFERROR(E16/D16, "") | G16: 24888.79 | H16: =IF(AND(ISNUMBER(C16),ISNUMBER(G16)), C16-G16, "") -> -1828.79 | I16: =IFERROR(H16/G16, "") -> -0.073478462
... A20: Kohls - Mechanicsburg | B20: PA | C20: 41788 | D20: 0 | E20: =IF(AND(ISNUMBER(C20),ISNUMBER(D20)), C20-D20, "") -> 41788 | F20: =IFERROR(E20/D20, "") | G20: 37445.65 | H20: =IF(AND(ISNUMBER(C20),ISNUMBER(G20)), C20-G20, "") -> 4342.35 | I20: =IFERROR(H20/G20, "") -> 0.11596407
A21: Kohls - Middletown | B21: NJ | C21: 0 | D21: 0 | E21: =IF(AND(ISNUMBER(C21),ISNUMBER(D21)), C21-D21, "") -> 0 | F21: =IFERROR(E21/D21, "") | G21: 53012.75 | H21: =IF(AND(ISNUMBER(C21),ISNUMBER(G21)), C21-G21, "") -> -53012.75 | I21: =IFERROR(H21/G21, "") -> -1 | J21: 1. Inverter is offline throughout the month. | K21: 1. SR080696
A22: Kohls - North Amherst | B22: NY | C22: 19697 | D22: 0 | E22: =IF(AND(ISNUMBER(C22),ISNUMBER(D22)), C22-D22, "") -> 19697 | F22: =IFERROR(E22/D22, "") | G22: 25541.3 | H22: =IF(AND(ISNUMBER(C22),ISNUMBER(G22)), C22-G22, "") -> -5844.3 | I22: =IFERROR(H22/G22, "") -> -0.22881764
A23: Kohls - Staten Island | B23: NY | C23: 31680 | D23: 0 | E23: =IF(AND(ISNUMBER(C23),ISNUMBER(D23)), C23-D23, "") -> 31680 | F23: =IFERROR(E23/D23, "") | G23: 32036.37 | H23: =IF(AND(ISNUMBER(C23),ISNUMBER(G23)), C23-G23, "") -> -356.37 | I23: =IFERROR(H23/G23, "") -> -0.011123919
A24: Kohls - Warminster | B24: PA | C24: 24283 | D24: 0 | E24: =IF(AND(ISNUMBER(C24),ISNUMBER(D24)), C24-D24, "") -> 24283 | F24: =IFERROR(E24/D24, "") | G24: 36579.8 | H24: =IF(AND(ISNUMBER(C24),ISNUMBER(G24)), C24-G24, "") -> -12296.8 | I24: =IFERROR(H24/G24, "") -> -0.33616368 | J24: 1. Inverter was offline for multiple days. | K24: 1.SR078291
A25: Kohls - Waterbury | B25: CT | C25: 33274 | D25: 0 | E25: =IF(AND(ISNUMBER(C25),ISNUMBER(D25)), C25-D25, "") -> 33274 | F25: =IFERROR(E25/D25, "") | G25: 28563.65 | H25: =IF(AND(ISNUMBER(C25),ISNUMBER(G25)), C25-G25, "") -> 4710.35 | I25: =IFERROR(H25/G25, "") -> 0.16490715

Sheet Apr
A1: {=portfolio} -> Silicon Ranch | D1: April Actual v. Expected | G1: April Actual v. Forecasted
A2: Total | C2: =SUM(C4:C100) -> 931826.2 | D2: =SUM(D4:D100) -> 0 | E2: =C2-D2 -> 931826.2 | F2: =IFERROR(E2/D2, 0) -> 0 | G2: =SUM(G4:G100) -> 1097110.3 | H2: =C2-G2 -> -165284.09 | I2: =IFERROR(H2/G2, 0) -> -0.15065403 | J2: =IF(AND(TODAY()>DATE(2024, 4, 1), COUNTA(Sites[Site])<>(COUNT(C:C)-1)), "Some sites are missing actual data; if new sites were added, make sure they are aligned correctly (including prior months!)", "")
A3: Site | B3: State | C3: Actual | D3: Expected | E3: Delta | F3: % | G3: Forecasted | H3: Delta | I3: % | J3: Notes | K3: Service Requests
A4: {=Sites[Site]} -> Iron Mountain - Windsor | B4: {=Sites[State]} -> CT | C4: 28698 | D4: 0 | E4: =IF(AND(ISNUMBER(C4),ISNUMBER(D4)), C4-D4, "") -> 28698 | F4: =IFERROR(E4/D4, "") | G4: 31152.93 | H4: =IF(AND(ISNUMBER(C4),ISNUMBER(G4)), C4-G4, "") -> -2454.93 | I4: =IFERROR(H4/G4, "") -> -0.07880254
A5: Kohls - Auburn | B5: NY | C5: 28241 | D5: 0 | E5: =IF(AND(ISNUMBER(C5),ISNUMBER(D5)), C5-D5, "") -> 28241 | F5: =IFERROR(E5/D5, "") | G5: 34098.57 | H5: =IF(AND(ISNUMBER(C5),ISNUMBER(G5)), C5-G5, "") -> -5857.57 | I5: =IFERROR(H5/G5, "") -> -0.17178345
A6: Kohls - Bensalem | B6: PA | C6: 35384 | D6: 0 | E6: =IF(AND(ISNUMBER(C6),ISNUMBER(D6)), C6-D6, "") -> 35384 | F6: =IFERROR(E6/D6, "") | G6: 33865.77 | H6: =IF(AND(ISNUMBER(C6),ISNUMBER(G6)), C6-G6, "") -> 1518.23 | I6: =IFERROR(H6/G6, "") -> 0.044830813
A7: Kohls - Brick | B7: NJ | C7: 38934 | D7: 0 | E7: =IF(AND(ISNUMBER(C7),ISNUMBER(D7)), C7-D7, "") -> 38934 | F7: =IFERROR(E7/D7, "") | G7: 41145.59 | H7: =IF(AND(ISNUMBER(C7),ISNUMBER(G7)), C7-G7, "") -> -2211.59 | I7: =IFERROR(H7/G7, "") -> -0.053750353
A8: Kohls - Buffalo | B8: NY | C8: 34857 | D8: 0 | E8: =IF(AND(ISNUMBER(C8),ISNUMBER(D8)), C8-D8, "") -> 34857 | F8: =IFERROR(E8/D8, "") | G8: 44287.13 | H8: =IF(AND(ISNUMBER(C8),ISNUMBER(G8)), C8-G8, "") -> -9430.13 | I8: =IFERROR(H8/G8, "") -> -0.21293161
A9: Kohls - Canton | B9: CT | C9: 13928 | D9: 0 | E9: =IF(AND(ISNUMBER(C9),ISNUMBER(D9)), C9-D9, "") -> 13928 | F9: =IFERROR(E9/D9, "") | G9: 13718.25 | H9: =IF(AND(ISNUMBER(C9),ISNUMBER(G9)), C9-G9, "") -> 209.75 | I9: =IFERROR(H9/G9, "") -> 0.015289851
A10: Kohls - East Amherst | B10: NY | C10: 32595 | D10: 0 | E10: =IF(AND(ISNUMBER(C10),ISNUMBER(D10)), C10-D10, "") -> 32595 | F10: =IFERROR(E10/D10, "") | G10: 38964.47 | H10: =IF(AND(ISNUMBER(C10),ISNUMBER(G10)), C10-G10, "") -> -6369.47 | I10: =IFERROR(H10/G10, "") -> -0.16346867
A11: Kohls - East Brunswick | B11: NJ | C11: 45596 | D11: 0 | E11: =IF(AND(ISNUMBER(C11),ISNUMBER(D11)), C11-D11, "") -> 45596 | F11: =IFERROR(E11/D11, "") | G11: 52856.96 | H11: =IF(AND(ISNUMBER(C11),ISNUMBER(G11)), C11-G11, "") -> -7260.96 | I11: =IFERROR(H11/G11, "") -> -0.13736999
A12: Kohls - Edgewood | B12: MD | C12: 236845 | D12: 0 | E12: =IF(AND(ISNUMBER(C12),ISNUMBER(D12)), C12-D12, "") -> 236845 | F12: =IFERROR(E12/D12, "") | G12: 283313.49 | H12: =IF(AND(ISNUMBER(C12),ISNUMBER(G12)), C12-G12, "") -> -46468.49 | I12: =IFERROR(H12/G12, "") -> -0.16401792
A13: Kohls - Granite Run | B13: PA | C13: 32668 | D13: 0 | E13: =IF(AND(ISNUMBER(C13),ISNUMBER(D13)), C13-D13, "") -> 32668 | F13: =IFERROR(E13/D13, "") | G13: 33875.63 | H13: =IF(AND(ISNUMBER(C13),ISNUMBER(G13)), C13-G13, "") -> -1207.63 | I13: =IFERROR(H13/G13, "") -> -0.035648931
A14: Kohls - Greece | B14: NY | C14: 27098 | D14: 0 | E14: =IF(AND(ISNUMBER(C14),ISNUMBER(D14)), C14-D14, "") -> 27098 | F14: =IFERROR(E14/D14, "") | G14: 41686.39 | H14: =IF(AND(ISNUMBER(C14),ISNUMBER(G14)), C14-G14, "") -> -14588.39 | I14: =IFERROR(H14/G14, "") -> -0.3499557
A15: Kohls - Hanover | B15: PA | C15: 22308 | D15: 0 | E15: =IF(AND(ISNUMBER(C15),ISNUMBER(D15)), C15-D15, "") -> 22308 | F15: =IFERROR(E15/D15, "") | G15: 39384.11 | H15: =IF(AND(ISNUMBER(C15),ISNUMBER(G15)), C15-G15, "") -> -17076.11 | I15: =IFERROR(H15/G15, "") -> -0.43357867 | J15: 1.Inverter was offline from 04/01 to 04/03 & back online at 04/04. 2.Inverter is offline on 04/21 & continued throught the month. | K15: 1.SR083032 2.SR083661
A16: Kohls - Horsehead | B16: NY | C16: 25184 | D16: 0 | E16: =IF(AND(ISNUMBER(C16),ISNUMBER(D16)), C16-D16, "") -> 25184 | F16: =IFERROR(E16/D16, "") | G16: 28710.66 | H16: =IF(AND(ISNUMBER(C16),ISNUMBER(G16)), C16-G16, "") -> -3526.66 | I16: =IFERROR(H16/G16, "") -> -0.12283452
A17: Kohls - Hudson | B17: NY | C17: 29971 | D17: 0 | E17: =IF(AND(ISNUMBER(C17),ISNUMBER(D17)), C17-D17, "") -> 29971 | F17: =IFERROR(E17/D17, "") | G17: 32756.26 | H17: =IF(AND(ISNUMBER(C17),ISNUMBER(G17)), C17-G17, "") -> -2785.26 | I17: =IFERROR(H17/G17, "") -> -0.085029854
A18: Kohls - Ithaca | B18: NY | C18: 26588 | D18: 0 | E18: =IF(AND(ISNUMBER(C18),ISNUMBER(D18)), C18-D18, "") -> 26588 | F18: =IFERROR(E18/D18, "") | G18: 34443.47 | H18: =IF(AND(ISNUMBER(C18),ISNUMBER(G18)), C18-G18, "") -> -7855.47 | I18: =IFERROR(H18/G18, "") -> -0.22806848
A19: Kohls - Kingston | B19: NY | C19: 36617 | D19: 0 | E19: =IF(AND(ISNUMBER(C19),ISNUMBER(D19)), C19-D19, "") -> 36617 | F19: =IFERROR(E19/D19, "") | G19: 53496.911 | H19: =IF(AND(ISNUMBER(C19),ISNUMBER(G19)), C19-G19, "") -> -16879.911 | I19: =IFERROR(H19/G19, "") -> -0.31553057 | J19: 1.Site stopped comms & modem is offline from 04/27 no visibility to monitor equipment or inverter. | K19: 1.SR083320
A20: Kohls - Mechanicsburg | B20: PA | C20: 41872 | D20: 0 | E20: =IF(AND(ISNUMBER(C20),ISNUMBER(D20)), C20-D20, "") -> 41872 | F20: =IFERROR(E20/D20, "") | G20: 46002.28 | H20: =IF(AND(ISNUMBER(C20),ISNUMBER(G20)), C20-G20, "") -> -4130.28 | I20: =IFERROR(H20/G20, "") -> -0.089784245
A21: Kohls - Middletown | B21: NJ | C21: 59946 | D21: 0 | E21: =IF(AND(ISNUMBER(C21),ISNUMBER(D21)), C21-D21, "") -> 59946 | F21: =IFERROR(E21/D21, "") | G21: 60664.54 | H21: =IF(AND(ISNUMBER(C21),ISNUMBER(G21)), C21-G21, "") -> -718.54 | I21: =IFERROR(H21/G21, "") -> -0.011844481 | J21: 1.inverter is offline from 04/01 & back online on 04/05 at 10:20. | K21: 1.SR081552
A22: Kohls - North Amherst | B22: NY | C22: 24695 | D22: 0 | E22: =IF(AND(ISNUMBER(C22),ISNUMBER(D22)), C22-D22, "") -> 24695 | F22: =IFERROR(E22/D22, "") | G22: 37286.57 | H22: =IF(AND(ISNUMBER(C22),ISNUMBER(G22)), C22-G22, "") -> -12591.57 | I22: =IFERROR(H22/G22, "") -> -0.33769719
A23: Kohls - Staten Island | B23: NY | C23: 33544.2 | D23: 0 | E23: =IF(AND(ISNUMBER(C23),ISNUMBER(D23)), C23-D23, "") -> 33544.2 | F23: =IFERROR(E23/D23, "") | G23: 36840.44 | H23: =IF(AND(ISNUMBER(C23),ISNUMBER(G23)), C23-G23, "") -> -3296.24 | I23: =IFERROR(H23/G23, "") -> -0.089473416
A24: Kohls - Warminster | B24: PA | C24: 41689 | D24: 0 | E24: =IF(AND(ISNUMBER(C24),ISNUMBER(D24)), C24-D24, "") -> 41689 | F24: =IFERROR(E24/D24, "") | G24: 41345.56 | H24: =IF(AND(ISNUMBER(C24),ISNUMBER(G24)), C24-G24, "") -> 343.44 | I24: =IFERROR(H24/G24, "") -> 0.0083065751
A25: Kohls - Waterbury | B25: CT | C25: 34568 | D25: 0 | E25: =IF(AND(ISNUMBER(C25),ISNUMBER(D25)), C25-D25, "") -> 34568 | F25: =IFERROR(E25/D25, "") | G25: 37214.31 | H25: =IF(AND(ISNUMBER(C25),ISNUMBER(G25)), C25-G25, "") -> -2646.31 | I25: =IFERROR(H25/G25, "") -> -0.071110011

Sheet Jun
A1: {=portfolio} -> Silicon Ranch | D1: June Actual v. Expected | G1: June Actual v. Forecasted
A2: Total | C2: =SUM(C4:C100) -> 0 | D2: =SUM(D4:D100) -> 0 | E2: =C2-D2 -> 0 | F2: =IFERROR(E2/D2, 0) -> 0 | G2: =SUM(G4:G100) -> 0 | H2: =C2-G2 -> 0 | I2: =IFERROR(H2/G2, 0) -> 0 | J2: =IF(AND(TODAY()>DATE(2024, 6, 1), COUNTA(Sites[Site])<>(COUNT(C:C)-1)), "Some sites are missing actual data; if new sites were added, make sure they are aligned correctly (including prior months!)", "") -> Some sites are missing actual data; if new sites were added, make sure they are aligned correctly (including prior months!)
A3: Site | B3: State | C3: Actual | D3: Expected | E3: Delta | F3: % | G3: Forecasted | H3: Delta | I3: % | J3: Notes | K3: Service Requests
A4: {=Sites[Site]} -> Iron Mountain - Windsor | B4: {=Sites[State]} -> CT | E4: =IF(AND(ISNUMBER(C4),ISNUMBER(D4)), C4-D4, "") | F4: =IFERROR(E4/D4, "") | H4: =IF(AND(ISNUMBER(C4),ISNUMBER(G4)), C4-G4, "") | I4: =IFERROR(H4/G4, "")
A5: Kohls - Auburn | B5: NY | E5: =IF(AND(ISNUMBER(C5),ISNUMBER(D5)), C5-D5, "") | F5: =IFERROR(E5/D5, "") | H5: =IF(AND(ISNUMBER(C5),ISNUMBER(G5)), C5-G5, "") | I5: =IFERROR(H5/G5, "")
A6: Kohls - Bensalem | B6: PA | E6: =IF(AND(ISNUMBER(C6),ISNUMBER(D6)), C6-D6, "") | F6: =IFERROR(E6/D6, "") | H6: =IF(AND(ISNUMBER(C6),ISNUMBER(G6)), C6-G6, "") | I6: =IFERROR(H6/G6, "")
A7: Kohls - Brick | B7: NJ | E7: =IF(AND(ISNUMBER(C7),ISNUMBER(D7)), C7-D7, "") | F7: =IFERROR(E7/D7, "") | H7: =IF(AND(ISNUMBER(C7),ISNUMBER(G7)), C7-G7, "") | I7: =IFERROR(H7/G7, "")
A8: Kohls - Buffalo | B8: NY | E8: =IF(AND(ISNUMBER(C8),ISNUMBER(D8)), C8-D8, "") | F8: =IFERROR(E8/D8, "") | H8: =IF(AND(ISNUMBER(C8),ISNUMBER(G8)), C8-G8, "") | I8: =IFERROR(H8/G8, "")
A9: Kohls - Canton | B9: CT | E9: =IF(AND(ISNUMBER(C9),ISNUMBER(D9)), C9-D9, "") | F9: =IFERROR(E9/D9, "") | H9: =IF(AND(ISNUMBER(C9),ISNUMBER(G9)), C9-G9, "") | I9: =IFERROR(H9/G9, "")
A10: Kohls - East Amherst | B10: NY | E10: =IF(AND(ISNUMBER(C10),ISNUMBER(D10)), C10-D10, "") | F10: =IFERROR(E10/D10, "") | H10: =IF(AND(ISNUMBER(C10),ISNUMBER(G10)), C10-G10, "") | I10: =IFERROR(H10/G10, "")
A11: Kohls - East Brunswick | B11: NJ | E11: =IF(AND(ISNUMBER(C11),ISNUMBER(D11)), C11-D11, "") | F11: =IFERROR(E11/D11, "") | H11: =IF(AND(ISNUMBER(C11),ISNUMBER(G11)), C11-G11, "") | I11: =IFERROR(H11/G11, "")
A12: Kohls - Edgewood | B12: MD | E12: =IF(AND(ISNUMBER(C12),ISNUMBER(D12)), C12-D12, "") | F12: =IFERROR(E12/D12, "") | H12: =IF(AND(ISNUMBER(C12),ISNUMBER(G12)), C12-G12, "") | I12: =IFERROR(H12/G12, "")
A13: Kohls - Granite Run | B13: PA | E13: =IF(AND(ISNUMBER(C13),ISNUMBER(D13)), C13-D13, "") | F13: =IFERROR(E13/D13, "") | H13: =IF(AND(ISNUMBER(C13),ISNUMBER(G13)), C13-G13, "") | I13: =IFERROR(H13/G13, "")
A14: Kohls - Greece | B14: NY | E14: =IF(AND(ISNUMBER(C14),ISNUMBER(D14)), C14-D14, "") | F14: =IFERROR(E14/D14, "") | H14: =IF(AND(ISNUMBER(C14),ISNUMBER(G14)), C14-G14, "") | I14: =IFERROR(H14/G14, "")
A15: Kohls - Hanover | B15: PA | E15: =IF(AND(ISNUMBER(C15),ISNUMBER(D15)), C15-D15, "") | F15: =IFERROR(E15/D15, "") | H15: =IF(AND(ISNUMBER(C15),ISNUMBER(G15)), C15-G15, "") | I15: =IFERROR(H15/G15, "")
A16: Kohls - Horsehead | B16: NY | E16: =IF(AND(ISNUMBER(C16),ISNUMBER(D16)), C16-D16, "") | F16: =IFERROR(E16/D16, "") | H16: =IF(AND(ISNUMBER(C16),ISNUMBER(G16)), C16-G16, "") | I16: =IFERROR(H16/G16, "")
A17: Kohls - Hudson | B17: NY | E17: =IF(AND(ISNUMBER(C17),ISNUMBER(D17)), C17-D17, "") | F17: =IFERROR(E17/D17, "") | H17: =IF(AND(ISNUMBER(C17),ISNUMBER(G17)), C17-G17, "") | I17: =IFERROR(H17/G17, "")
A18: Kohls - Ithaca | B18: NY
A19: Kohls - Kingston | B19: NY
A20: Kohls - Mechanicsburg | B20: PA
A21: Kohls - Middletown | B21: NJ
A22: Kohls - North Amherst | B22: NY
A23: Kohls - Staten Island | B23: NY
A24: Kohls - Warminster | B24: PA
A25: Kohls - Waterbury | B25: CT

Sheet Jul
A1: {=portfolio} -> Silicon Ranch | D1: July Actual v. Expected | G1: July Actual v. Forecasted
A2: Total | C2: =SUM(C4:C100) -> 0 | D2: =SUM(D4:D100) -> 0 | E2: =C2-D2 -> 0 | F2: =IFERROR(E2/D2, 0) -> 0 | G2: =SUM(G4:G100) -> 0 | H2: =C2-G2 -> 0 | I2: =IFERROR(H2/G2, 0) -> 0 | J2: =IF(AND(TODAY()>DATE(2024, 7, 1), COUNTA(Sites[Site])<>(COUNT(C:C)-1)), "Some sites are missing actual data; if new sites were added, make sure they are aligned correctly (including prior months!)", "") -> Some sites are missing actual data; if new sites were added, make sure they are aligned correctly (including prior months!)
A3: Site | B3: State | C3: Actual | D3: Expected | E3: Delta | F3: % | G3: Forecasted | H3: Delta | I3: % | J3: Notes | K3: Service Requests
A4: {=Sites[Site]} -> Iron Mountain - Windsor | B4: {=Sites[State]} -> CT | E4: =IF(AND(ISNUMBER(C4),ISNUMBER(D4)), C4-D4, "") | F4: =IFERROR(E4/D4, "") | H4: =IF(AND(ISNUMBER(C4),ISNUMBER(G4)), C4-G4, "") | I4: =IFERROR(H4/G4, "")
A5: Kohls - Auburn | B5: NY | E5: =IF(AND(ISNUMBER(C5),ISNUMBER(D5)), C5-D5, "") | F5: =IFERROR(E5/D5, "") | H5: =IF(AND(ISNUMBER(C5),ISNUMBER(G5)), C5-G5, "") | I5: =IFERROR(H5/G5, "")
