Workbook
Name JanActual: #REF!
Name JanActual2: #REF!
Name JanExpected: #REF!
Name JanExpectedDelta: #REF!
Name JanExpectedPercent: #REF!
Name JanExpPercent: #REF!
Name JanForecasted: #REF!
Name JanForecastedDelta: #REF!
Name JanForecastedPercent: #REF!
Name portfolio: Sites!$B$1:$B$1
Name Year: Sites!#REF!

Sheet Year to Date
A1: {=portfolio} -> Agilitas Energy | D1: Year to Date Actual v. Expected | G1: Year to Date Actual v. Forecasted
A2: Total | C2: =SUM(C4:C80) -> 17685157 | D2: =SUM(D4:D80) -> 18152992 | E2: =C2-D2 -> -467834.75 | F2: =IFERROR(E2/D2, 0) -> -0.025771772 | G2: =SUM(G4:G80) -> 10479306 | H2: =C2-G2 -> 7205850.9 | I2: =IFERROR(H2/G2, 0) -> 0.68762674
A3: Site | B3: State | C3: Actual | D3: Expected | E3: Delta | F3: % | G3: Forecasted | H3: Delta | I3: %
A4: {=Sites[Site]} -> Rowley - Central Street Solar | B4: {=Sites[State]} -> MA | C4: =SUM('1st Qtr'!C4, '2nd Qtr'!C4, '3rd Qtr'!C4, '4th Qtr'!C4) -> 492097.48 | D4: =SUM('1st Qtr'!D4, '2nd Qtr'!D4, '3rd Qtr'!D4, '4th Qtr'!D4) -> 532819.93 | E4: =IF(AND(ISNUMBER(C4),ISNUMBER(D4)), C4-D4, "") -> -40722.455 | F4: =IFERROR(E4/D4, "") -> -0.076428175 | G4: =SUM('1st Qtr'!G4, '2nd Qtr'!G4, '3rd Qtr'!G4, '4th Qtr'!G4) -> 515132.85 | H4: =SUM('1st Qtr'!H4, '2nd Qtr'!H4, '3rd Qtr'!H4, '4th Qtr'!H4) -> -23035.375 | I4: =IFERROR(H4/G4, "") -> -0.044717348
A5: Auburn - Leicester Street Solar | B5: MA | C5: =SUM('1st Qtr'!C5, '2nd Qtr'!C5, '3rd Qtr'!C5, '4th Qtr'!C5) -> 4931549 | D5: =SUM('1st Qtr'!D5, '2nd Qtr'!D5, '3rd Qtr'!D5, '4th Qtr'!D5) -> 5994178.5 | E5: =IF(AND(ISNUMBER(C5),ISNUMBER(D5)), C5-D5, "") -> -1062629.5 | F5: =IFERROR(E5/D5, "") -> -0.17727692 | G5: =SUM('1st Qtr'!G5, '2nd Qtr'!G5, '3rd Qtr'!G5, '4th Qtr'!G5) -> 0 | H5: =SUM(Jan!H5, Feb!H5, Mar!H5) -> 1498297 | I5: =IFERROR(H5/G5, "")
A6: Rochester - Old Middleboro | B6: MA | C6: =SUM('1st Qtr'!C6, '2nd Qtr'!C6, '3rd Qtr'!C6, '4th Qtr'!C6) -> 6903631.9 | D6: =SUM('1st Qtr'!D6, '2nd Qtr'!D6, '3rd Qtr'!D6, '4th Qtr'!D6) -> 6209764 | E6: =IF(AND(ISNUMBER(C6),ISNUMBER(D6)), C6-D6, "") -> 693867.87 | F6: =IFERROR(E6/D6, "") -> 0.1117382 | G6: =SUM('1st Qtr'!G6, '2nd Qtr'!G6, '3rd Qtr'!G6, '4th Qtr'!G6) -> 4639617 | H6: =SUM('1st Qtr'!H6, '2nd Qtr'!H6, '3rd Qtr'!H6, '4th Qtr'!H6) -> 2264014.9 | I6: =IFERROR(H6/G6, "") -> 0.48797452
A7: Dover - Littleworth Road | B7: NH | C7: =SUM('1st Qtr'!C7, '2nd Qtr'!C7, '3rd Qtr'!C7, '4th Qtr'!C7) -> 212185 | D7: =SUM('1st Qtr'!D7, '2nd Qtr'!D7, '3rd Qtr'!D7, '4th Qtr'!D7) -> 0 | E7: =IF(AND(ISNUMBER(C7),ISNUMBER(D7)), C7-D7, "") -> 212185 | F7: =IFERROR(E7/D7, "") | G7: =SUM('1st Qtr'!G7, '2nd Qtr'!G7, '3rd Qtr'!G7, '4th Qtr'!G7) -> 0 | H7: =SUM(Jan!H7, Feb!H7, Mar!H7) -> 23295 | I7: =IFERROR(H7/G7, "")
A8: Milton - Landfill | B8: NH | C8: =SUM('1st Qtr'!C8, '2nd Qtr'!C8, '3rd Qtr'!C8, '4th Qtr'!C8) -> 592605 | D8: =SUM('1st Qtr'!D8, '2nd Qtr'!D8, '3rd Qtr'!D8, '4th Qtr'!D8) -> 0 | E8: =IF(AND(ISNUMBER(C8),ISNUMBER(D8)), C8-D8, "") -> 592605 | F8: =IFERROR(E8/D8, "") | G8: =SUM('1st Qtr'!G8, '2nd Qtr'!G8, '3rd Qtr'!G8, '4th Qtr'!G8) -> 0 | H8: =SUM('1st Qtr'!H8, '2nd Qtr'!H8, '3rd Qtr'!H8, '4th Qtr'!H8) -> 71381 | I8: =IFERROR(H8/G8, "")
A9: Hopkinton - 71 Frankland Rd | B9: MA | C9: =SUM('1st Qtr'!C9, '2nd Qtr'!C9, '3rd Qtr'!C9, '4th Qtr'!C9) -> 3884336 | D9: =SUM('1st Qtr'!D9, '2nd Qtr'!D9, '3rd Qtr'!D9, '4th Qtr'!D9) -> 4507652.4 | E9: =IF(AND(ISNUMBER(C9),ISNUMBER(D9)), C9-D9, "") -> -623316.4 | F9: =IFERROR(E9/D9, "") -> -0.13827961 | G9: =SUM('1st Qtr'!G9, '2nd Qtr'!G9, '3rd Qtr'!G9, '4th Qtr'!G9) -> 4581581.3 | H9: =SUM(Jan!H9, Feb!H9, Mar!H9) -> -71061.8 | I9: =IFERROR(H9/G9, "") -> -0.015510322
A10: Dedham - 100 Rustcraft Rd | B10: MA | C10: =SUM('1st Qtr'!C10, '2nd Qtr'!C10, '3rd Qtr'!C10, '4th Qtr'!C10) -> 668752.5 | D10: =SUM('1st Qtr'!D10, '2nd Qtr'!D10, '3rd Qtr'!D10, '4th Qtr'!D10) -> 908576.76 | E10: =IF(AND(ISNUMBER(C10),ISNUMBER(D10)), C10-D10, "") -> -239824.26 | F10: =IFERROR(E10/D10, "") -> -0.26395597 | G10: =SUM('1st Qtr'!G10, '2nd Qtr'!G10, '3rd Qtr'!G10, '4th Qtr'!G10) -> 742974.76 | H10: =SUM('1st Qtr'!H10, '2nd Qtr'!H10, '3rd Qtr'!H10, '4th Qtr'!H10) -> -74222.255 | I10: =IFERROR(H10/G10, "") -> -0.099898758

Sheet 1st Qtr
A1: {=portfolio} -> Agilitas Energy | D1: 1st Quarter Actual v. Expected | G1: 1st Quarter Actual v. Forecasted
A2: Total | C2: =SUM(C4:C80) -> 5534770.9 | D2: =SUM(D4:D80) -> 6757593.8 | E2: =C2-D2 -> -1222822.9 | F2: =IFERROR(E2/D2, 0) -> -0.18095537 | G2: =SUM(G4:G80) -> 3264188.2 | H2: =C2-G2 -> 2270582.7 | I2: =IFERROR(H2/G2, 0) -> 0.69560409
A3: Site | B3: State | C3: Actual | D3: Expected | E3: Delta | F3: % | G3: Forecasted | H3: Delta | I3: %
A4: {=Sites[Site]} -> Rowley - Central Street Solar | B4: {=Sites[State]} -> MA | C4: =SUM(Jan!C4, Feb!C4, Mar!C4) -> 147392.76 | D4: =SUM(Jan!D4, Feb!D4, Mar!D4) -> 185255.87 | E4: =IF(AND(ISNUMBER(C4),ISNUMBER(D4)), C4-D4, "") -> -37863.108 | F4: =IFERROR(E4/D4, "") -> -0.20438277 | G4: =SUM(Jan!G4, Feb!G4, Mar!G4) -> 166677.48 | H4: =SUM(Jan!H4, Feb!H4, Mar!H4) -> -19284.718 | I4: =IFERROR(H4/G4, "") -> -0.1157008
A5: Auburn - Leicester Street Solar | B5: MA | C5: =SUM(Jan!C5, Feb!C5, Mar!C5) -> 1498297 | D5: =SUM(Jan!D5, Feb!D5, Mar!D5) -> 2480547.2 | E5: =IF(AND(ISNUMBER(C5),ISNUMBER(D5)), C5-D5, "") -> -982250.2 | F5: =IFERROR(E5/D5, "") -> -0.39598126 | G5: =SUM(Jan!G5, Feb!G5, Mar!G5) -> 0 | H5: =SUM(Jan!H5, Feb!H5, Mar!H5) -> 1498297 | I5: =IFERROR(H5/G5, "")
A6: Rochester - Old Middleboro | B6: MA | C6: =SUM(Jan!C6, Feb!C6, Mar!C6) -> 2264045.7 | D6: =SUM(Jan!D6, Feb!D6, Mar!D6) -> 2265143.6 | E6: =IF(AND(ISNUMBER(C6),ISNUMBER(D6)), C6-D6, "") -> -1097.9293 | F6: =IFERROR(E6/D6, "") -> -0.00048470626 | G6: =SUM(Jan!G6, Feb!G6, Mar!G6) -> 1544599.3 | H6: =SUM(Jan!H6, Feb!H6, Mar!H6) -> 719446.37 | I6: =IFERROR(H6/G6, "") -> 0.46578188
A7: Dover - Littleworth Road | B7: NH | C7: =SUM(Jan!C7, Feb!C7, Mar!C7) -> 41948 | D7: =SUM(Jan!D7, Feb!D7, Mar!D7) -> 0 | E7: =IF(AND(ISNUMBER(C7),ISNUMBER(D7)), C7-D7, "") -> 41948 | F7: =IFERROR(E7/D7, "") | G7: =SUM(Jan!G7, Feb!G7, Mar!G7) -> 0 | H7: =SUM(Jan!H7, Feb!H7, Mar!H7) -> 23295 | I7: =IFERROR(H7/G7, "")
A8: Milton - Landfill | B8: NH | C8: =SUM(Jan!C8, Feb!C8, Mar!C8) -> 162763 | D8: =SUM(Jan!D8, Feb!D8, Mar!D8) -> 0 | E8: =IF(AND(ISNUMBER(C8),ISNUMBER(D8)), C8-D8, "") -> 162763 | F8: =IFERROR(E8/D8, "") | G8: =SUM(Jan!G8, Feb!G8, Mar!G8) -> 0 | H8: =SUM(Jan!H8, Feb!H8, Mar!H8) -> 71381 | I8: =IFERROR(H8/G8, "")
A9: Hopkinton - 71 Frankland Rd | B9: MA | C9: =SUM(Jan!C9, Feb!C9, Mar!C9) -> 1244562 | D9: =SUM(Jan!D9, Feb!D9, Mar!D9) -> 1525430.5 | E9: =IF(AND(ISNUMBER(C9),ISNUMBER(D9)), C9-D9, "") -> -280868.5 | F9: =IFERROR(E9/D9, "") -> -0.18412409 | G9: =SUM(Jan!G9, Feb!G9, Mar!G9) -> 1315623.8 | H9: =SUM(Jan!H9, Feb!H9, Mar!H9) -> -71061.8 | I9: =IFERROR(H9/G9, "") -> -0.054013769
A10: Dedham - 100 Rustcraft Rd | B10: MA | C10: =SUM(Jan!C10, Feb!C10, Mar!C10) -> 175762.5 | D10: =SUM(Jan!D10, Feb!D10, Mar!D10) -> 301216.66 | E10: =IF(AND(ISNUMBER(C10),ISNUMBER(D10)), C10-D10, "") -> -125454.16 | F10: =IFERROR(E10/D10, "") -> -0.41649144 | G10: =SUM(Jan!G10, Feb!G10, Mar!G10) -> 237287.65 | H10: =SUM(Jan!H10, Feb!H10, Mar!H10) -> -61525.155 | I10: =IFERROR(H10/G10, "") -> -0.25928511

Sheet 2nd Qtr
A1: {=portfolio} -> Agilitas Energy | D1: 2nd Quarter Actual v. Expected | G1: 2nd Quarter Actual v. Forecasted
A2: Total | C2: =SUM(C4:C80) -> 8945578.3 | D2: =SUM(D4:D80) -> 8273532.3 | E2: =C2-D2 -> 672045.94 | F2: =IFERROR(E2/D2, 0) -> 0.081228418 | G2: =SUM(G4:G80) -> 5270593.5 | H2: =C2-G2 -> 3674984.8 | I2: =IFERROR(H2/G2, 0) -> 0.69726205
A3: Site | B3: State | C3: Actual | D3: Expected | E3: Delta | F3: % | G3: Forecasted | H3: Delta | I3: %
A4: {=Sites[Site]} -> Rowley - Central Street Solar | B4: {=Sites[State]} -> MA | C4: =SUM(Apr!C4, May!C4, Jun!C4) -> 246963.71 | D4: =SUM(Apr!D4, May!D4, Jun!D4) -> 249300.51 | E4: =IF(AND(ISNUMBER(C4),ISNUMBER(D4)), C4-D4, "") -> -2336.7969 | F4: =IFERROR(E4/D4, "") -> -0.0093734139 | G4: =SUM(Apr!G4+May!G4+Jun!G4) -> 255303.77 | H4: =SUM(Apr!H4, May!H4, Jun!H4) -> -8340.0569 | I4: =IFERROR(H4/G4, "") -> -0.03266719
A5: Auburn - Leicester Street Solar | B5: MA | C5: =SUM(Apr!C5, May!C5, Jun!C5) -> 2449871 | D5: =SUM(Apr!D5, May!D5, Jun!D5) -> 2476127.3 | E5: =IF(AND(ISNUMBER(C5),ISNUMBER(D5)), C5-D5, "") -> -26256.3 | F5: =IFERROR(E5/D5, "") -> -0.010603776 | G5: =SUM(Apr!G5+May!G5+Jun!G5) -> 0 | H5: =SUM(Apr!H5, May!H5, Jun!H5) -> 2449871 | I5: =IFERROR(H5/G5, "")
A6: Rochester - Old Middleboro | B6: MA | C6: =SUM(Apr!C6, May!C6, Jun!C6) -> 3542039.5 | D6: =SUM(Apr!D6, May!D6, Jun!D6) -> 2974789.1 | E6: =IF(AND(ISNUMBER(C6),ISNUMBER(D6)), C6-D6, "") -> 567250.44 | F6: =IFERROR(E6/D6, "") -> 0.19068593 | G6: =SUM(Apr!G6+May!G6+Jun!G6) -> 2281942.6 | H6: =SUM(Apr!H6, May!H6, Jun!H6) -> 1260096.9 | I6: =IFERROR(H6/G6, "") -> 0.55220361
A7: Dover - Littleworth Road | B7: NH | C7: =SUM(Apr!C7, May!C7, Jun!C7) -> 125423 | D7: =SUM(Apr!D7, May!D7, Jun!D7) -> 0 | E7: =IF(AND(ISNUMBER(C7),ISNUMBER(D7)), C7-D7, "") -> 125423 | F7: =IFERROR(E7/D7, "") | G7: =SUM(Apr!G7,May!G7,Jun!G7) -> 0 | H7: =SUM(Apr!H7, May!H7, Jun!H7) -> 0 | I7: =IFERROR(H7/G7, "")
A8: Milton - Landfill | B8: NH | C8: =SUM(Apr!C8, May!C8, Jun!C8) -> 316021 | D8: =SUM(Apr!D8, May!D8, Jun!D8) -> 0 | E8: =IF(AND(ISNUMBER(C8),ISNUMBER(D8)), C8-D8, "") -> 316021 | F8: =IFERROR(E8/D8, "") | G8: =SUM(Apr!G8,May!G8,Jun!G8) -> 0 | H8: =SUM(Apr!H8, May!H8, Jun!H8) -> 0 | I8: =IFERROR(H8/G8, "")
A9: Hopkinton - 71 Frankland Rd | B9: MA | C9: =SUM(Apr!C9, May!C9, Jun!C9) -> 1912545 | D9: =SUM(Apr!D9, May!D9, Jun!D9) -> 2145162.4 | E9: =IF(AND(ISNUMBER(C9),ISNUMBER(D9)), C9-D9, "") -> -232617.4 | F9: =IFERROR(E9/D9, "") -> -0.10843813 | G9: =SUM(Apr!G9,May!G9,Jun!G9) -> 2362712.6 | H9: =SUM(Apr!H9, May!H9, Jun!H9) -> -450167.6 | I9: =IFERROR(H9/G9, "") -> -0.19052999
A10: Dedham - 100 Rustcraft Rd | B10: MA | C10: =SUM(Apr!C10, May!C10, Jun!C10) -> 352715 | D10: =SUM(Apr!D10, May!D10, Jun!D10) -> 428153 | E10: =IF(AND(ISNUMBER(C10),ISNUMBER(D10)), C10-D10, "") -> -75438 | F10: =IFERROR(E10/D10, "") -> -0.17619402 | G10: =SUM(Apr!G10+May!G10+Jun!G10) -> 370634.5 | H10: =SUM(Apr!H10, May!H10, Jun!H10) -> -17919.5 | I10: =IFERROR(H10/G10, "") -> -0.048348171

Sheet 3rd Qtr
A1: {=portfolio} -> Agilitas Energy | D1: 3rd Quarter Actual v. Expected | G1: 3rd Quarter Actual v. Forecasted
A2: Total | C2: =SUM(C4:C79) -> 3204807.7 | D2: =SUM(D4:D79) -> 3121865.5 | E2: =C2-D2 -> 82942.204 | F2: =IFERROR(E2/D2, 0) -> 0.026568155 | G2: =SUM(G4:G79) -> 1944524.2 | H2: =C2-G2 -> 1260283.5 | I2: =IFERROR(H2/G2, 0) -> 0.64811919
A3: Site | B3: State | C3: Actual | D3: Expected | E3: Delta | F3: % | G3: Forecasted | H3: Delta | I3: %
A4: {=Sites[Site]} -> Rowley - Central Street Solar | B4: {=Sites[State]} -> MA | C4: =SUM(Jul!C4, Aug!C4, Sep!C4) -> 97741 | D4: =SUM(Jul!D4, Aug!D4, Sep!D4) -> 98263.55 | E4: =IF(AND(ISNUMBER(C4),ISNUMBER(D4)), C4-D4, "") -> -522.55 | F4: =IFERROR(E4/D4, "") -> -0.0053178417 | G4: =SUM(Jul!G4,Aug!G4,Sep!G4) -> 93151.6 | H4: =SUM(Jul!H4, Aug!H4, Sep!H4) -> 4589.4 | I4: =IFERROR(H4/G4, "") -> 0.049268075
A5: Auburn - Leicester Street Solar | B5: MA | C5: =SUM(Jul!C5, Aug!C5, Sep!C5) -> 983381 | D5: =SUM(Jul!D5, Aug!D5, Sep!D5) -> 1037504 | E5: =IF(AND(ISNUMBER(C5),ISNUMBER(D5)), C5-D5, "") -> -54123 | F5: =IFERROR(E5/D5, "") -> -0.052166546 | G5: =SUM(Jul!G5,Aug!G5,Sep!G5) -> 0 | H5: =SUM(Jul!H5, Aug!H5, Sep!H5) -> 983381 | I5: =IFERROR(H5/G5, "")
A6: Rochester - Old Middleboro | B6: MA | C6: =SUM(Jul!C6, Aug!C6, Sep!C6) -> 1097546.7 | D6: =SUM(Jul!D6, Aug!D6, Sep!D6) -> 969831.3 | E6: =IF(AND(ISNUMBER(C6),ISNUMBER(D6)), C6-D6, "") -> 127715.35 | F6: =IFERROR(E6/D6, "") -> 0.13168822 | G6: =SUM(Jul!G6,Aug!G6,Sep!G6) -> 813075.1 | H6: =SUM(Jul!H6, Aug!H6, Sep!H6) -> 284471.55 | I6: =IFERROR(H6/G6, "") -> 0.34987119
A7: Dover - Littleworth Road | B7: NH | C7: =SUM(Jul!C7, Aug!C7, Sep!C7) -> 44814 | D7: =SUM(Jul!D7, Aug!D7, Sep!D7) -> 0 | E7: =IF(AND(ISNUMBER(C7),ISNUMBER(D7)), C7-D7, "") -> 44814 | F7: =IFERROR(E7/D7, "") | G7: =SUM(Jul!G7,Aug!G7,Sep!G7) -> 0 | H7: =SUM(Jul!H7, Aug!H7, Sep!H7) -> 0 | I7: =IFERROR(H7/G7, "")
A8: Milton - Landfill | B8: NH | C8: =SUM(Jul!C8, Aug!C8, Sep!C8) -> 113821 | D8: =SUM(Jul!D8, Aug!D8, Sep!D8) -> 0 | E8: =IF(AND(ISNUMBER(C8),ISNUMBER(D8)), C8-D8, "") -> 113821 | F8: =IFERROR(E8/D8, "") | G8: =SUM(Jul!G8,Aug!G8,Sep!G8) -> 0 | H8: =SUM(Jul!H8, Aug!H8, Sep!H8) -> 0 | I8: =IFERROR(H8/G8, "")
A9: Hopkinton - 71 Frankland Rd | B9: MA | C9: =SUM(Jul!C9, Aug!C9, Sep!C9) -> 727229 | D9: =SUM(Jul!D9, Aug!D9, Sep!D9) -> 837059.5 | E9: =IF(AND(ISNUMBER(C9),ISNUMBER(D9)), C9-D9, "") -> -109830.5 | F9: =IFERROR(E9/D9, "") -> -0.13120991 | G9: =SUM(Jul!G9,Aug!G9,Sep!G9) -> 903244.9 | H9: =SUM(Jul!H9, Aug!H9, Sep!H9) -> -176015.9 | I9: =IFERROR(H9/G9, "") -> -0.19487063
A10: Dedham - 100 Rustcraft Rd | B10: MA | C10: =SUM(Jul!C10, Aug!C10, Sep!C10) -> 140275 | D10: =SUM(Jul!D10, Aug!D10, Sep!D10) -> 179207.1 | E10: =IF(AND(ISNUMBER(C10),ISNUMBER(D10)), C10-D10, "") -> -38932.1 | F10: =IFERROR(E10/D10, "") -> -0.21724641 | G10: =SUM(Jul!G10,Aug!G10,Sep!G10) -> 135052.6 | H10: =SUM(Jul!H10, Aug!H10, Sep!H10) -> 5222.4 | I10: =IFERROR(H10/G10, "") -> 0.038669378

Sheet 4th Qtr
A1: {=portfolio} -> Agilitas Energy | D1: 4th Quarter Actual v. Expected | G1: 4th Quarter Actual v. Forecasted
A2: Total | C2: =SUM(C4:C80) -> 0 | D2: =SUM(D4:D80) -> 0 | E2: =C2-D2 -> 0 | F2: =IFERROR(E2/D2, 0) -> 0 | G2: =SUM(G4:G80) -> 0 | H2: =C2-G2 -> 0 | I2: =IFERROR(H2/G2, 0) -> 0
A3: Site | B3: State | C3: Actual | D3: Expected | E3: Delta | F3: % | G3: Forecasted | H3: Delta | I3: %
A4: {=Sites[Site]} -> Rowley - Central Street Solar | B4: {=Sites[State]} -> MA | C4: =SUM(Oct!C4, Nov!C4, Dec!C4) -> 0 | D4: =SUM(Oct!D4, Nov!D4, Dec!D4) -> 0 | E4: =IF(AND(ISNUMBER(C4),ISNUMBER(D4)), C4-D4, "") -> 0 | F4: =IFERROR(E4/D4, "") | G4: =SUM(Oct!G4,Nov!G4,Dec!G4) -> 0 | H4: =SUM(Oct!H4, Nov!H4, Dec!H4) -> 0 | I4: =IFERROR(H4/G4, "")
A5: Auburn - Leicester Street Solar | B5: MA | C5: =SUM(Oct!C5, Nov!C5, Dec!C5) -> 0 | D5: =SUM(Oct!D5, Nov!D5, Dec!D5) -> 0 | E5: =IF(AND(ISNUMBER(C5),ISNUMBER(D5)), C5-D5, "") -> 0 | F5: =IFERROR(E5/D5, "") | G5: =SUM(Oct!G5,Nov!G5,Dec!G5) -> 0 | H5: =SUM(Oct!H5, Nov!H5, Dec!H5) -> 0 | I5: =IFERROR(H5/G5, "")
A6: Rochester - Old Middleboro | B6: MA | C6: =SUM(Oct!C6, Nov!C6, Dec!C6) -> 0 | D6: =SUM(Oct!D6, Nov!D6, Dec!D6) -> 0 | E6: =IF(AND(ISNUMBER(C6),ISNUMBER(D6)), C6-D6, "") -> 0 | F6: =IFERROR(E6/D6, "") | G6: =SUM(Oct!G6,Nov!G6,Dec!G6) -> 0 | H6: =SUM(Oct!H6, Nov!H6, Dec!H6) -> 0 | I6: =IFERROR(H6/G6, "")
A7: Dover - Littleworth Road | B7: NH | C7: =SUM(Oct!C7, Nov!C7, Dec!C7) -> 0 | D7: =SUM(Oct!D7, Nov!D7, Dec!D7) -> 0 | E7: =IF(AND(ISNUMBER(C7),ISNUMBER(D7)), C7-D7, "") -> 0 | F7: =IFERROR(E7/D7, "") | G7: =SUM(Oct!G7,Nov!G7,Dec!G7) -> 0 | H7: =SUM(Oct!H7, Nov!H7, Dec!H7) -> 0 | I7: =IFERROR(H7/G7, "")
A8: Milton - Landfill | B8: NH | C8: =SUM(Oct!C8, Nov!C8, Dec!C8) -> 0 | D8: =SUM(Oct!D8, Nov!D8, Dec!D8) -> 0 | E8: =IF(AND(ISNUMBER(C8),ISNUMBER(D8)), C8-D8, "") -> 0 | F8: =IFERROR(E8/D8, "") | G8: =SUM(Oct!G8,Nov!G8,Dec!G8) -> 0 | H8: =SUM(Oct!H8,Nov!H8,Dec!H8) -> 0 | I8: =IFERROR(H8/G8, "")
A9: Hopkinton - 71 Frankland Rd | B9: MA | C9: =SUM(Oct!C9, Nov!C9, Dec!C9) -> 0 | D9: =SUM(Oct!D9, Nov!D9, Dec!D9) -> 0 | E9: =IF(AND(ISNUMBER(C9),ISNUMBER(D9)), C9-D9, "") -> 0 | F9: =IFERROR(E9/D9, "") | G9: =SUM(Oct!G9,Nov!G9,Dec!G9) -> 0 | H9: =SUM(Oct!H9,Nov!H9,Dec!H9) -> 0 | I9: =IFERROR(H9/G9, "")
A10: Dedham - 100 Rustcraft Rd | B10: MA | C10: =SUM(Oct!C10, Nov!C10, Dec!C10) -> 0 | D10: =SUM(Oct!D10, Nov!D10, Dec!D10) -> 0 | E10: =IF(AND(ISNUMBER(C10),ISNUMBER(D10)), C10-D10, "") -> 0 | F10: =IFERROR(E10/D10, "") | G10: =SUM(Oct!G10,Nov!G10,Dec!G10) -> 0 | H10: =SUM(Oct!H10,Nov!H10,Dec!H10) -> 0 | I10: =IFERROR(H10/G10, "")

Sheet Jan
A1: {=portfolio} -> Agilitas Energy | D1: January Actual v. Expected | G1: January Actual v. Forecasted
A2: Total | C2: =SUM(C4:C79) -> 1432705.5 | D2: =SUM(D4:D79) -> 2047587.9 | E2: =C2-D2 -> -614882.38 | F2: =IFERROR(E2/D2, 0) -> -0.30029597 | G2: =SUM(G4:G79) -> 806550.55 | H2: =C2-G2 -> 626154.92 | I2: =IFERROR(H2/G2, 0) -> 0.77633685 | J2: =IF(AND(TODAY()>DATE(2024, 1, 1), COUNTA(Sites[Site])<>(COUNT(C:C)-1)), "Some sites are missing actual data; if new sites were added, make sure they are aligned correctly (including prior months!)", "")
A3: Site | B3: State | C3: Actual | D3: Expected | E3: Delta | F3: % | G3: Forecasted | H3: Delta | I3: % | J3: Notes | K3: Service Requests
A4: {=Sites[Site]} -> Rowley - Central Street Solar | B4: {=Sites[State]} -> MA | C4: 37932.475 | D4: 55631.28 | E4: =IF(AND(ISNUMBER(C4),ISNUMBER(D4)), C4-D4, "") -> -17698.805 | F4: =IFERROR(E4/D4, "") -> -0.31814484 | G4: 41263.29 | H4: =IF(AND(ISNUMBER(C4),ISNUMBER(G4)), C4-G4, "") -> -3330.8148 | I4: =IFERROR(H4/G4, "") -> -0.080721019 | J4: 1. Fans to be replaced for inverter 13. 2. Site was offline from 10:11 to 14:12on 01/14/25 due to a planned outage. | K4: 1. SR085127 , SR093008 2. SR095541 | L4: SR093008 | M4: SR095541
A5: Auburn - Leicester Street Solar | B5: MA | C5: 403896 | D5: 787406.2 | E5: =IF(AND(ISNUMBER(C5),ISNUMBER(D5)), C5-D5, "") -> -383510.2 | F5: =IFERROR(E5/D5, "") -> -0.48705509 | G5: 0 | H5: =IF(AND(ISNUMBER(C5),ISNUMBER(G5)), C5-G5, "") -> 403896 | I5: =IFERROR(H5/G5, "") | J5: 1. Inverters 13, 14, and 15 of Pad 5 were taken offline on 01/07/25 by a technician to replace the CAN cards and back online on 01/09/25. 2. Pad 2 is tripped offline at 8:15AM on 01/26 due to an power derating and back online at 11:15AM the same day. | K5: 1. SR095250 2. SR095250 | L5: SR095250
A6: Rochester - Old Middleboro | B6: MA | C6: 611257 | D6: 702798 | E6: =IF(AND(ISNUMBER(C6),ISNUMBER(D6)), C6-D6, "") -> -91541.001 | F6: =IFERROR(E6/D6, "") -> -0.13025222 | G6: 419559.3 | H6: =IF(AND(ISNUMBER(C6),ISNUMBER(G6)), C6-G6, "") -> 191697.7 | I6: =IFERROR(H6/G6, "") -> 0.45690251 | J6: 1. Site was offline from 10:00 AM to 12:15 PM on 01/03/25 due to a brief site outage. 2. Site was tripped offline at 6:30 AM on 01/20/25 due to a fire on a pole and came back online at 3:45 PM on 01/21/25 after repairs were made to the circuit by the Eversource crew | K6: 1.SR095271 2.SR095714 | L6: SR095714
A7: Dover - Littleworth Road | B7: NH | C7: 17331 | D7: 0 | E7: =IF(AND(ISNUMBER(C7),ISNUMBER(D7)), C7-D7, "") -> 17331 | F7: =IFERROR(E7/D7, "") | G7: 0 | H7: =IF(AND(ISNUMBER(C7),ISNUMBER(G7)), C7-G7, "") -> 17331 | I7: =IFERROR(H7/G7, "")
A8: Milton - Landfill | B8: NH | C8: 54795 | D8: 0 | E8: =IF(AND(ISNUMBER(C8),ISNUMBER(D8)), C8-D8, "") -> 54795 | F8: =IFERROR(E8/D8, "") | G8: 0 | H8: =IF(AND(ISNUMBER(C8),ISNUMBER(G8)), C8-G8, "") -> 54795 | I8: =IFERROR(H8/G8, "") | J8: 1. Inverter 13 has been offline since 11/07/24. It has been RMA'd on 02/04/24, and parts need to be replaced in order to bring the inverter back online. 2. Inverter 7 has been offline since 12/18/24. It was RMA'd on 12/19/24, and parts need to be replaced in order to bring the inverter back online. 3. Inverter 11 tripped offline at 12:00 PM on 01/07/25 and back online on 01/08, again tripped offline at 12:35PM on 01/14/25 and back online on 01/15. | K8: 1. SR092635 2. SR094914 3. SR095569 | L8: SR094914 | M8: SR095569
A9: Hopkinton - 71 Frankland Rd | B9: MA | C9: 266892 | D9: 412403.2 | E9: =IF(AND(ISNUMBER(C9),ISNUMBER(D9)), C9-D9, "") -> -145511.2 | F9: =IFERROR(E9/D9, "") -> -0.35283722 | G9: 284177 | H9: =IF(AND(ISNUMBER(C9),ISNUMBER(G9)), C9-G9, "") -> -17285 | I9: =IFERROR(H9/G9, "") -> -0.060824768 | J9: 1. Inverters 3,4,5,8,10,12,19,26,29,30,31,34 and 35 tripped offline at 10:30 AM to 13:45 on 01/02 due to "Grid voltage out of range". 2. Inverter 31 tripped offline at 12:00 PM on 01/05 and back online at 07:00 AM on 01/06 due to "Inverter Over Current Fault". | K9: 1. SR095238 2. SR095323 | L9: SR095323
A10: Dedham - 100 Rustcraft Rd | B10: MA | C10: 40602 | D10: 89349.172 | E10: =IF(AND(ISNUMBER(C10),ISNUMBER(D10)), C10-D10, "") -> -48747.172 | F10: =IFERROR(E10/D10, "") -> -0.54558057 | G10: 61550.965 | H10: =IF(AND(ISNUMBER(C10),ISNUMBER(G10)), C10-G10, "") -> -20948.965 | I10: =IFERROR(H10/G10, "") -> -0.34035153 | J10: 1. Inverter 3 tripped offline at 11:36 AM on 01/04 due to a Bus Sum High fault and came back online at 7:00 AM on 01/05/25. It tripped offline again at 12:30 PM on 01/07 and came back online at 7:00 AM on 01/08/25. 2. Inverter 2 tripped offline at 8:45 AM on 01/18 due to a Steady State GFCI fault and back online at 7:00 AM on 01/19/25 . 3. Inverters 2, 5, 6, 7, 8, 9, 13, 15, 16, 18, 19, 20, and 21 tripped offline at 11:00 AM on 01/31 due to a steady-state GFCI fault throgh out the day. | K10: 1. SR095310 2. SR095696 3. SR096176 | L10: SR095696 | M10: SR096176

Sheet Feb
A1: {=portfolio} -> Agilitas Energy | D1: February Actual v. Expected | G1: February Actual v. Forecasted
A2: Total | C2: =SUM(C4:C80) -> 1420953.2 | D2: =SUM(D4:D80) -> 2079297.3 | E2: =C2-D2 -> -658344.08 | F2: =IFERROR(E2/D2, 0) -> -0.31661855 | G2: =SUM(G4:G80) -> 1031904.2 | H2: =C2-G2 -> 389048.93 | I2: =IFERROR(H2/G2, 0) -> 0.37702038 | J2: =IF(AND(TODAY()>DATE(2024, 2, 1), COUNTA(Sites[Site])<>(COUNT(C:C)-1)), "Some sites are missing actual data; if new sites were added, make sure they are aligned correctly (including prior months!)", "")
A3: Site | B3: State | C3: Actual | D3: Expected | E3: Delta | F3: % | G3: Forecasted | H3: Delta | I3: % | J3: Notes | K3: Service Requests
A4: {=Sites[Site]} -> Rowley - Central Street Solar | B4: {=Sites[State]} -> MA | C4: 37920.188 | D4: 57349.06 | E4: =IF(AND(ISNUMBER(C4),ISNUMBER(D4)), C4-D4, "") -> -19428.872 | F4: =IFERROR(E4/D4, "") -> -0.33878275 | G4: 53130.43 | H4: =IF(AND(ISNUMBER(C4),ISNUMBER(G4)), C4-G4, "") -> -15210.243 | I4: =IFERROR(H4/G4, "") -> -0.28628119 | J4: 1.Technician replaced the RMA'd fan for Inverter 13 and Inverter 9 communication board was RMAd on 02/20 . Both inverters producing in line with peers. | K4: 1.SR085127, SR093008 & SR088882. | L4: SR093008 | M4: SR088882
A5: Auburn - Leicester Street Solar | B5: MA | C5: 330277 | D5: 785932.8 | E5: =IF(AND(ISNUMBER(C5),ISNUMBER(D5)), C5-D5, "") -> -455655.8 | F5: =IFERROR(E5/D5, "") -> -0.57976433 | G5: 0 | H5: =IF(AND(ISNUMBER(C5),ISNUMBER(G5)), C5-G5, "") -> 330277 | I5: =IFERROR(H5/G5, "") | J5: 1.Inverters 4,5&6 tripped offline at 08:45AM on 02/05 due to AC disconnect fault and back online at 10:30AM after couple of resets from Solectria page on 02/05 and pad 2 inverters (4,5 &6) are having daily issues with the batteries and inverters, meaning, this pad most likely every night will have the batteries down for unknown reason and the morning times are having ground faults. Again Inverters 4,5&6 tripped offline at 09:15AM on 02/21 due to AC disconnected fault and back online at 15:15 on 02/21. 2. Inverters 13,14 &15 of Pad 5 tripped offline at 10:30AM on 02/08due to AC Disconnected fault and back online at 13:15 on 02/08. Again tripped offline from 02/09 at 14:15 due to AC disconnected fault till date. 3.Site tripped offline from 10:15 to 12:30 due to utility power outage on 02/17. Pad 5 inverters and 30 - 38 Inverters were offline on 02/18 and back online on 02/19. | K5: 1.SR096327 2.SR096327, SR095250 3.SR097185 | L5: SR096327 | M5: SR095250 | N5: SR097185
A6: Rochester - Old Middleboro | B6: MA | C6: 641846.48 | D6: 693935.9 | E6: =IF(AND(ISNUMBER(C6),ISNUMBER(D6)), C6-D6, "") -> -52089.421 | F6: =IFERROR(E6/D6, "") -> -0.075063736 | G6: 488422.1 | H6: =IF(AND(ISNUMBER(C6),ISNUMBER(G6)), C6-G6, "") -> 153424.38 | I6: =IFERROR(H6/G6, "") -> 0.31412252 | J6: 1.Site was taken offline from 10:00 to 14:30 on 02/25 due to planned outage. 2.Site was tripped offline at 03:30AM due to utility outage and after technician checked-in and closed SEL relay site back online at 08:30AM on 02/07. Again site tripped offline from 11:15 to 13:00 on 02/07 due to SEL relay open and technician re-energized the site. Site tripped offline from 08:30 to 13:15 on 02/17 due to SEL relay open later technician closed the relay. | K6: 1.SR096404 2.SR096414 | L6: SR096414
A7: Dover - Littleworth Road | B7: NH | C7: 5964 | D7: 0 | E7: =IF(AND(ISNUMBER(C7),ISNUMBER(D7)), C7-D7, "") -> 5964 | F7: =IFERROR(E7/D7, "") | G7: 0 | H7: =IF(AND(ISNUMBER(C7),ISNUMBER(G7)), C7-G7, "") -> 5964 | I7: =IFERROR(H7/G7, "")
A8: Milton - Landfill | B8: NH | C8: 16586 | D8: 0 | E8: =IF(AND(ISNUMBER(C8),ISNUMBER(D8)), C8-D8, "") -> 16586 | F8: =IFERROR(E8/D8, "") | G8: 0 | H8: =IF(AND(ISNUMBER(C8),ISNUMBER(G8)), C8-G8, "") -> 16586 | I8: =IFERROR(H8/G8, "") | J8: 1.Inverter 13 has been offline since 11/07/24. It was been RMA'd on 11/08/24 and parts need to be replaced in order to bring the inverter back online. 2.Inverter 7 has been offline since 12/18/24. It was RMA'd on 12/19/24, and parts need to be replaced in order to bring the inverter back online. 3.Inverter 11 has tripped offline at 10AM on 02/04 and back online by self-resolve on 02/05. | K8: 1.SR092635 2.SR094914 3.SR095569 | L8: SR094914 | M8: SR095569
A9: Hopkinton - 71 Frankland Rd | B9: MA | C9: 350944 | D9: 450697.4 | E9: =IF(AND(ISNUMBER(C9),ISNUMBER(D9)), C9-D9, "") -> -99753.4 | F9: =IFERROR(E9/D9, "") -> -0.22133121 | G9: 412974.3 | H9: =IF(AND(ISNUMBER(C9),ISNUMBER(G9)), C9-G9, "") -> -62030.3 | I9: =IFERROR(H9/G9, "") -> -0.15020378 | J9: 1. Inverter 28 tripped offline at 10AM on 02/04 due to Over current - Protect 0030 fault and back online on 02/05. 2.Inverter 11 tripped offline at 09:30AM on 02/05 due to Overcurrent fault and back online on 02/06. 3.Site was taken offline from 08:15 to 09:45 on 02/27 due to Agilitas checked in to work on the switch gear and other items. | K9: 1.SR096292 2.SR096335 3.SR097855 | L9: SR096335 | M9: SR097855
A10: Dedham - 100 Rustcraft Rd | B10: MA | C10: 37415.5 | D10: 91382.09 | E10: =IF(AND(ISNUMBER(C10),ISNUMBER(D10)), C10-D10, "") -> -53966.59 | F10: =IFERROR(E10/D10, "") -> -0.59055981 | G10: 77377.41 | H10: =IF(AND(ISNUMBER(C10),ISNUMBER(G10)), C10-G10, "") -> -39961.91 | I10: =IFERROR(H10/G10, "") -> -0.51645448 | J10: 1.Inverters 2,5,6-9,13,15,16,18,19-21 tripped offline at 11:15AM on 01/31 due to Steady state GFCI fault and back online on 02/01. | K10: 1.SR096176

Sheet Mar
A1: {=portfolio} -> Agilitas Energy | D1: March Actual v. Expected | G1: March Actual v. Forecasted
A2: Total | C2: =SUM(C4:C80) -> 2681112.3 | D2: =SUM(D4:D80) -> 2630708.7 | E2: =C2-D2 -> 50403.562 | F2: =IFERROR(E2/D2, 0) -> 0.019159689 | G2: =SUM(G4:G80) -> 1425733.4 | H2: =C2-G2 -> 1255378.9 | I2: =IFERROR(H2/G2, 0) -> 0.88051442 | J2: =IF(AND(TODAY()>DATE(2024, 3, 1), COUNTA(Sites[Site])<>(COUNT(C:C)-1)), "Some sites are missing actual data; if new sites were added, make sure they are aligned correctly (including prior months!)", "")
A3: Site | B3: State | C3: Actual | D3: Expected | E3: Delta | F3: % | G3: Forecasted | H3: Delta | I3: % | J3: Notes | K3: Service Requests
A4: {=Sites[Site]} -> Rowley - Central Street Solar | B4: {=Sites[State]} -> MA | C4: 71540.099 | D4: 72275.53 | E4: =IF(AND(ISNUMBER(C4),ISNUMBER(D4)), C4-D4, "") -> -735.43062 | F4: =IFERROR(E4/D4, "") -> -0.010175375 | G4: 72283.76 | H4: =IF(AND(ISNUMBER(C4),ISNUMBER(G4)), C4-G4, "") -> -743.66062 | I4: =IFERROR(H4/G4, "") -> -0.010288073
A5: Auburn - Leicester Street Solar | B5: MA | C5: 764124 | D5: 907208.2 | E5: =IF(AND(ISNUMBER(C5),ISNUMBER(D5)), C5-D5, "") -> -143084.2 | F5: =IFERROR(E5/D5, "") -> -0.15771925 | G5: 0 | H5: =IF(AND(ISNUMBER(C5),ISNUMBER(G5)), C5-G5, "") -> 764124 | I5: =IFERROR(H5/G5, "") | J5: 1. Inverters 13, 14, and 15 of Pad 5 tripped offline at 14:15 on 02/09 due to an AC disconnected fault. After troubleshooting by Agilitas and Solectria, the inverters were brought back online at 09:00 AM on 03/11. 2. Inverters 4, 5, and 6 tripped offline at 09:45 AM on 03/24 due to an AC disconnect fault and came back online at 10:30 AM after couple of resets from Solectria page on 03/24. 3. Multiple inverters have been experiencing power derating issues since 03/29, with inverters 1 to 12 being the most affected. After troubleshooting, the inverters were brought back online at 09:15 AM on 03/31. | K5: 1. SR095250 2. SR096327, SR098922 3. SR099164 | L5: SR096327 | M5: SR098922 | N5: SR099164
A6: Rochester - Old Middleboro | B6: MA | C6: 1010942.2 | D6: 868409.7 | E6: =IF(AND(ISNUMBER(C6),ISNUMBER(D6)), C6-D6, "") -> 142532.49 | F6: =IFERROR(E6/D6, "") -> 0.16413047 | G6: 636617.9 | H6: =IF(AND(ISNUMBER(C6),ISNUMBER(G6)), C6-G6, "") -> 374324.29 | I6: =IFERROR(H6/G6, "") -> 0.58798895 | J6: 1.Inverter 2 went offline at 10:00 AM on 03/07. Additionally, inverter 3 experienced multiple trippings. After a brief outage, as per the meter, the technician tried power cycling the DAS equipment, and inverters 1 and 3 came back online at 13:15 on 03/08. 2.The site tripped offline at 11:45 on 03/07 due to the grid recloser being open. After the technician re-energized the site is back online at 13:15 on 03/08. | K6: 1. SR098255 2. SR098255 | L6: SR098255
A7: Dover - Littleworth Road | B7: NH | C7: 18653 | D7: N/A | E7: =IF(AND(ISNUMBER(C7),ISNUMBER(D7)), C7-D7, "") | F7: =IFERROR(E7/D7, "") | G7: N/A | H7: =IF(AND(ISNUMBER(C7),ISNUMBER(G7)), C7-G7, "") | I7: =IFERROR(H7/G7, "") | J7: 1. Inverter 8 tripped offline at 16:25 on 03/14 due to a fault with an ARC Protect code. After the technician troubleshot the inverter, it came back online at 10:05 AM on 03/18. 2. The meter stopped communicating at 09:55 AM on 03/15 and it's under replacement. | K7: 1. SR098603, SR098617 2. SR098617 | L7: SR098617 | M7: SR098617
A8: Milton - Landfill | B8: NH | C8: 91382 | D8: N/A | E8: =IF(AND(ISNUMBER(C8),ISNUMBER(D8)), C8-D8, "") | F8: =IFERROR(E8/D8, "") | G8: N/A | H8: =IF(AND(ISNUMBER(C8),ISNUMBER(G8)), C8-G8, "") | I8: =IFERROR(H8/G8, "") | J8: 1.Inverter 13 has been offline since 11/07/24. It was been RMA'd on 11/08/24 and parts need to be replaced in order to bring the inverter back online. 2.Inverter 7 has been offline since 12/18/24. It was RMA'd on 12/19/24, and parts need to be replaced in order to bring the inverter back online. 3. The inverter (11) tripped offline at 10:10 AM on 03/07 and came back online at 07:00 AM on 03/08. It later self-resolved. 4. Inverters 4 and 21 appear to be down, as one string for both inverters dropped by 4 kW compared to peers. Additionally, inverter 22 appears to be down by two strings, with a production drop of 8 kW compared to peers. | K8: 1. SR092635 2. SR094914 3. SR095569 4. SR099233 | L8: SR094914 | M8: SR095569 | N8: SR099233
A9: Hopkinton - 71 Frankland Rd | B9: MA | C9: 626726 | D9: 662329.9 | E9: =IF(AND(ISNUMBER(C9),ISNUMBER(D9)), C9-D9, "") -> -35603.9 | F9: =IFERROR(E9/D9, "") -> -0.053755538 | G9: 618472.5 | H9: =IF(AND(ISNUMBER(C9),ISNUMBER(G9)), C9-G9, "") -> 8253.5 | I9: =IFERROR(H9/G9, "") -> 0.013344975 | J9: 1. The site tripped offline at 12:45 on 03/08, possibly due to a main breaker trip. The technician found that the recloser was in the open position. The technician immediately reset the relays and closed it. The site was then re-energized and came back online at 15:15 on 03/08. 2. Inverters 1, 13, and 21 tripped offline from 13:00 to 16:30 on 03/10 and later self-resolved. 3.Inverter 28 tripped offline at 12:00 PM on 03/15 and came back online at 06:45 AM on 03/16. 4. The site tripped offline at 14:45 on 03/19 after the client noted that the BESS recloser had tripped late this morning. While troubleshooting, the PV recloser was opened. The site came back online at 17:30 on 03/19 after the PV recloser was closed. 5.The site tripped offline at 16:00 on 03/25 due to the PV recloser being opened to test ESS capacity. After the completion of the ESS capacity test, the site came back online at 18:00 on 03/25. 6.Inverters 5 and 8 tripped offline at 14:30 on 03/27 and later self-resolved, and back online at 16:15 on 03/27. Additionally, inverters 5 and 17 tripped offline at 12:45 PM on 03/28 and later self-resolved, and back online at 03:00 PM on 03/28. | K9: 1. SR098299 2. SR098355 3. SR098616 4. SR098773 5. SR098773 6. SR099056 | L9: SR098355 | M9: SR098616 | N9: SR098773 | O9: SR098773 | P9: SR099056
A10: Dedham - 100 Rustcraft Rd | B10: MA | C10: 97745 | D10: 120485.4 | E10: =IF(AND(ISNUMBER(C10),ISNUMBER(D10)), C10-D10, "") -> -22740.4 | F10: =IFERROR(E10/D10, "") -> -0.18873988 | G10: 98359.28 | H10: =IF(AND(ISNUMBER(C10),ISNUMBER(G10)), C10-G10, "") -> -614.28 | I10: =IFERROR(H10/G10, "") -> -0.0062452674 | J10: 1. Inverter 3 tripped offline at 11:45 AM on 03/03, reporting a Bus Sum High fault. It later self-resolved and came back online at 06:45 AM on 03/04. It tripped offline again at 09:00 AM on 03/07, reporting the same Bus Sum High fault. It later self-resolved and came back online at 12:30 PM on 03/08. 2.The site was offline at 11:30 AM on 03/07. After the technician re-energized the site, it came back online at 12:30 PM on 03/08. Additionally, inverters 4 and 23 remained offline and later came back online at 06:45 AM on 03/09. 3. Inverter 3 tripped offline at 13:55 on 03/13, reporting a Bus Sum High fault (Fault 0130), and came back online at 06:45 AM on 03/14. Additionally, Inverter 4 tripped offline from 13:55 to 14:30 on 03/13 and later self-resolved. 4. Inverter 4 tripped offline from 11:45 AM to 03:00 PM on 03/21 and later self-resolved. Additionally, Inverter 3 tripped offline at 03:15 PM on 03/21, reporting a Bus Sum High fault, and later self-resolved at 06:45 AM on 03/22. | K10: 1. SR095310 2. SR098276 3. SR098520 4. SR098880 | L10: SR098276 | M10: SR098520 | N10: SR098880

Sheet Apr
A1: {=portfolio} -> Agilitas Energy | D1: April Actual v. Expected | G1: April Actual v. Forecasted
A2: Total | C2: =SUM(C4:C80) -> 2786921.3 | D2: =SUM(D4:D80) -> 2596421.5 | E2: =C2-D2 -> 190499.76 | F2: =IFERROR(E2/D2, 0) -> 0.073370121 | G2: =SUM(G4:G80) -> 1617277.2 | H2: =C2-G2 -> 1169644.1 | I2: =IFERROR(H2/G2, 0) -> 0.72321806 | J2: =IF(AND(TODAY()>DATE(2024, 4, 1), COUNTA(Sites[Site])<>(COUNT(C:C)-1)), "Some sites are missing actual data; if new sites were added, make sure they are aligned correctly (including prior months!)", "")
A3: Site | B3: State | C3: Actual | D3: Expected | E3: Delta | F3: % | G3: Forecasted | H3: Delta | I3: % | J3: Notes | K3: Service Requests
A4: {=Sites[Site]} -> Rowley - Central Street Solar | B4: {=Sites[State]} -> MA | C4: 82040.963 | D4: 82476.03 | E4: =IF(AND(ISNUMBER(C4),ISNUMBER(D4)), C4-D4, "") -> -435.06688 | F4: =IFERROR(E4/D4, "") -> -0.0052750705 | G4: 81850.41 | H4: =IF(AND(ISNUMBER(C4),ISNUMBER(G4)), C4-G4, "") -> 190.55312 | I4: =IFERROR(H4/G4, "") -> 0.0023280656
A5: Auburn - Leicester Street Solar | B5: MA | C5: 708193 | D5: 738902.9 | E5: =IF(AND(ISNUMBER(C5),ISNUMBER(D5)), C5-D5, "") -> -30709.9 | F5: =IFERROR(E5/D5, "") -> -0.041561483 | G5: 0 | H5: =IF(AND(ISNUMBER(C5),ISNUMBER(G5)), C5-G5, "") -> 708193 | I5: =IFERROR(H5/G5, "") | J5: 1. Multiple inverters have been experiencing power derating issues since 03/29, with Inverters 1 to 12 being the most affected. After Agilitas reset the inverters, all are currently producing as expected with no curtailment as of 04/01. Additionally, Inverters 16 to 18 were tripped offline between 09:15AM and 09:25AM on 04/01 due to technician activity on site. 2. The site was taken offline at 08:45 AM on 04/03 due to subcontractors working on the replacement of bushings in the transformer and cable pulling. After the new cables were installed, the site was brought back online at 14:45 on 04/10. 3. Inverters 1, 2, 3, 28, 29, and 39 went offline at 14:45 on 04/10. After Agilitas reset them, the inverters came back online at 10:45AM on 04/12. | K5: 1. SR099164 2. SR094026 3. SR099689 | L5: SR094026 | M5: SR099689
A6: Rochester - Old Middleboro | B6: MA | C6: 1100423.3 | D6: 913176.1 | E6: =IF(AND(ISNUMBER(C6),ISNUMBER(D6)), C6-D6, "") -> 187247.23 | F6: =IFERROR(E6/D6, "") -> 0.20505051 | G6: 694457.6 | H6: =IF(AND(ISNUMBER(C6),ISNUMBER(G6)), C6-G6, "") -> 405965.73 | I6: =IFERROR(H6/G6, "") -> 0.58457957 | J6: 1. Inverter 2 tripped offline at 16:00 on 04/14, reporting 'Error Error.' It later self-resolved and came back online at 16:30 on 04/14. | K6: 1. SR099783
A7: Dover - Littleworth Road | B7: NH | C7: 41468 | D7: N/A | E7: =IF(AND(ISNUMBER(C7),ISNUMBER(D7)), C7-D7, "") | F7: =IFERROR(E7/D7, "") | G7: N/A | H7: =IF(AND(ISNUMBER(C7),ISNUMBER(G7)), C7-G7, "") | I7: =IFERROR(H7/G7, "") | J7: 1. The meter stopped communicating at 09:55AM on 03/15. After a technician replaced the meter on 04/01, it has been communicating as expected. As part of this work, the site was taken offline from 10:10AM to 12:05PM while the technician was on-site to replace the meter. | K7: 1. SR098617
A8: Milton - Landfill | B8: NH | C8: 106949 | D8: N/A | E8: =IF(AND(ISNUMBER(C8),ISNUMBER(D8)), C8-D8, "") | F8: =IFERROR(E8/D8, "") | G8: N/A | H8: =IF(AND(ISNUMBER(C8),ISNUMBER(G8)), C8-G8, "") | I8: =IFERROR(H8/G8, "") | J8: 1.Inverter 13 has been offline since 11/07/24. It was been RMA'd on 11/08/24 and parts need to be replaced in order to bring the inverter back online. 2.Inverter 7 has been offline since 12/18/24. It was RMA'd on 12/19/24, and parts need to be replaced in order to bring the inverter back online. 3. Inverters 4 and 21 appear to be down, as one string for both inverters dropped by 4 kW compared to peers. Additionally, inverter 22 appears to be down by two strings, with a production drop of 8 kW compared to peers. After a technician checked the site and replaced the faulty fuses in Inverters 4 and 21, both inverters came back online and have been producing in line with their peers as of 04/01. | K8: 1. SR092635, SR100128 2. SR094914, SR100127 3. SR099233 | L8: SR100128 | M8: SR094914 | N8: SR100127 | O8: SR099233
A9: Hopkinton - 71 Frankland Rd | B9: MA | C9: 629515 | D9: 718867.3 | E9: =IF(AND(ISNUMBER(C9),ISNUMBER(D9)), C9-D9, "") -> -89352.3 | F9: =IFERROR(E9/D9, "") -> -0.12429596 | G9: 724526.6 | H9: =IF(AND(ISNUMBER(C9),ISNUMBER(G9)), C9-G9, "") -> -95011.6 | I9: =IFERROR(H9/G9, "") -> -0.13113611 | J9: 1. Inverter 17 tripped offline at 12:15PM on 04/17, later self-resolved, and back online at 17:15 on 04/17. It tripped offline again at 11:45AM on 04/18 and later self-resolved, coming back online at 16:30 on 04/18.Tripping issue was occuring during high irradiance days. 2. The site tripped offline at 13:45 on 04/27, possibly due to a main breaker trip. Eversource visited the site and discovered an unknown issue on the circuit, which was resolved. The site came back online at 12:00PM on 04/28. 3. Inverters 13 and 14 tripped offline at 13:30 on 04/28, later self-resolved, and came back online at 16:00 on 04/28. Inverter 14 tripped offline again at 10:15AM on 04/29 and self-resolved by 16:00 on 04/29. These inverters have been intermittently tripping frequently. A technician checked the site, updated the firmware on Inverters 13 and 14, and collected fault logs. Both inverters are currently online and producing as expected. | K9: 1. SR099955 2. SR100465 3. SR100579 | L9: SR100465 | M9: SR100579
A10: Dedham - 100 Rustcraft Rd | B10: MA | C10: 118332 | D10: 142999.2 | E10: =IF(AND(ISNUMBER(C10),ISNUMBER(D10)), C10-D10, "") -> -24667.2 | F10: =IFERROR(E10/D10, "") -> -0.17249887 | G10: 116442.6 | H10: =IF(AND(ISNUMBER(C10),ISNUMBER(G10)), C10-G10, "") -> 1889.4 | I10: =IFERROR(H10/G10, "") -> 0.01622602 | J10: 1.Inverter 3 tripped offline at 15:00 on 04/08, reporting a 'Bus Sum High Fault.' It self-resolved and came back online at 6:00AM on 04/09. The inverter tripped again at 10:15AM on 04/09 and once again self-resolved, returning online at 6:00AM on 04/10. A technician visited the site on 04/15, replaced the failed LCD screen, and placed the inverter in independent mode as recommended by the manufacturer. The inverter is currently producing as expected 2. Inverters 3 & 4 are underperforming approximately 6kW each compared with inverter 11 of same capacity from 04/16 at 09:30AM. | K10: 1. SR095310 2. SR100683 | L10: SR100683

Sheet May
A1: {=portfolio} -> Agilitas Energy | D1: May Actual v. Expected | G1: May Actual v. Forecasted
A2: Total | C2: =SUM(C4:C80) -> 2888611.3 | D2: =SUM(D4:D80) -> 2665133.7 | E2: =C2-D2 -> 223477.54 | F2: =IFERROR(E2/D2, 0) -> 0.083852282 | G2: =SUM(G4:G80) -> 1809259.6 | H2: =C2-G2 -> 1079351.6 | I2: =IFERROR(H2/G2, 0) -> 0.59657088 | J2: =IF(AND(TODAY()>DATE(2024, 5, 1), COUNTA(Sites[Site])<>(COUNT(C:C)-1)), "Some sites are missing actual data; if new sites were added, make sure they are aligned correctly (including prior months!)", "")
A3: Site | B3: State | C3: Actual | D3: Expected | E3: Delta | F3: % | G3: Forecasted | H3: Delta | I3: % | J3: Notes | K3: Service Requests
A4: {=Sites[Site]} -> Rowley - Central Street Solar | B4: {=Sites[State]} -> MA | C4: 77791.375 | D4: 78899.62 | E4: =IF(AND(ISNUMBER(C4),ISNUMBER(D4)), C4-D4, "") -> -1108.245 | F4: =IFERROR(E4/D4, "") -> -0.014046265 | G4: 88286.95 | H4: =IF(AND(ISNUMBER(C4),ISNUMBER(G4)), C4-G4, "") -> -10495.575 | I4: =IFERROR(H4/G4, "") -> -0.11888025 | J4: 1. Site was offline from 16:00 on 05/28 until 00:15 on 05/29 due to a brief outage. | K4: 1.SR102063
A5: Auburn - Leicester Street Solar | B5: MA | C5: 787814 | D5: 792633.2 | E5: =IF(AND(ISNUMBER(C5),ISNUMBER(D5)), C5-D5, "") -> -4819.2 | F5: =IFERROR(E5/D5, "") -> -0.0060799876 | G5: 0 | H5: =IF(AND(ISNUMBER(C5),ISNUMBER(G5)), C5-G5, "") -> 787814 | I5: =IFERROR(H5/G5, "") | J5: 1. Inverters 22, 23, and 24 were barely producing, and inverter 22 reported 'Power derating – customer command AC disconnected' on 05/03. It started producing as expected from 05/04, and the issue resolved itself. | K5: 1. SR100953
A6: Rochester - Old Middleboro | B6: MA | C6: 1174443.9 | D6: 1006086 | E6: =IF(AND(ISNUMBER(C6),ISNUMBER(D6)), C6-D6, "") -> 168357.89 | F6: =IFERROR(E6/D6, "") -> 0.16733946 | G6: 788377.3 | H6: =IF(AND(ISNUMBER(C6),ISNUMBER(G6)), C6-G6, "") -> 386066.59 | I6: =IFERROR(H6/G6, "") -> 0.48969775 | J6: 1. Inverter 2 tripped offline at 15:15 on 05/03, reporting 'Error Error.' It self-resolved and came back online at 10:30 on 05/04. It went offline again from 17:00 to 18:15 on 05/07, and it again tripped offline at 11:30 on 05/08 and back online at 12:30 the same day. | K6: 1. SR100978
A7: Dover - Littleworth Road | B7: NH | C7: 39141 | D7: N/A | E7: =IF(AND(ISNUMBER(C7),ISNUMBER(D7)), C7-D7, "") | F7: =IFERROR(E7/D7, "") | G7: N/A | H7: =IF(AND(ISNUMBER(C7),ISNUMBER(G7)), C7-G7, "") | I7: =IFERROR(H7/G7, "")
A8: Milton - Landfill | B8: NH | C8: 95251 | D8: N/A | E8: =IF(AND(ISNUMBER(C8),ISNUMBER(D8)), C8-D8, "") | F8: =IFERROR(E8/D8, "") | G8: N/A | H8: =IF(AND(ISNUMBER(C8),ISNUMBER(G8)), C8-G8, "") | I8: =IFERROR(H8/G8, "") | J8: 1.Inverter 13 has been offline since 11/07/24. It was been RMA'd on 11/08/24 and parts need to be replaced in order to bring the inverter back online. 2.Inverter 7 has been offline since 12/18/24. It was RMA'd on 12/19/24, and parts need to be replaced in order to bring the inverter back online. | K8: 1. SR092635, SR100128 2. SR094914, SR100127 | L8: SR100128 | M8: SR094914 | N8: SR100127
A9: Hopkinton - 71 Frankland Rd | B9: MA | C9: 597928 | D9: 648303.8 | E9: =IF(AND(ISNUMBER(C9),ISNUMBER(D9)), C9-D9, "") -> -50375.8 | F9: =IFERROR(E9/D9, "") -> -0.077704002 | G9: 808954.2 | H9: =IF(AND(ISNUMBER(C9),ISNUMBER(G9)), C9-G9, "") -> -211026.2 | I9: =IFERROR(H9/G9, "") -> -0.26086298 | J9: 1. Inverter 11 tripped offline at 11:30 on 05/03 due to 'Fault Inverter Over Current,' self-resolved, and came back online at 06:00 on 05/04. It went offline again at 14:45 on 05/12 and recovered by 06:00 on 05/13. It tripped once more at 09:45 on 05/18 and came back online on 05/19. A technician found grid-related faults. After following Chint’s troubleshooting steps, the inverter failed to exit standby. Photos and inverter details were sent to Chint for the RMA process 2. Inverters 13 and 14 have been producing as expected since the technician updated the firmware on 05/01. | K9: 1. SR100959 2. SR100579 | L9: SR100579
A10: Dedham - 100 Rustcraft Rd | B10: MA | C10: 116242 | D10: 139211.1 | E10: =IF(AND(ISNUMBER(C10),ISNUMBER(D10)), C10-D10, "") -> -22969.1 | F10: =IFERROR(E10/D10, "") -> -0.16499475 | G10: 123641.2 | H10: =IF(AND(ISNUMBER(C10),ISNUMBER(G10)), C10-G10, "") -> -7399.2 | I10: =IFERROR(H10/G10, "") -> -0.05984413 | J10: 1. Inverters 2, 3, 4, 7, 8, 11, and 17 had been underperforming since 04/16 but have been producing as expected since the technician replaced the LCD screens and performed troubleshooting on 05/20. | K10: 1. SR100683

Sheet Jun
A1: {=portfolio} -> Agilitas Energy | D1: June Actual v. Expected | G1: June Actual v. Forecasted
A2: Total | C2: =SUM(C4:C80) -> 3270045.7 | D2: =SUM(D4:D80) -> 3011977.1 | E2: =C2-D2 -> 258068.64 | F2: =IFERROR(E2/D2, 0) -> 0.085680812 | G2: =SUM(G4:G80) -> 1844056.6 | H2: =C2-G2 -> 1425989.1 | I2: =IFERROR(H2/G2, 0) -> 0.77328922 | J2: =IF(AND(TODAY()>DATE(2024, 6, 1), COUNTA(Sites[Site])<>(COUNT(C:C)-1)), "Some sites are missing actual data; if new sites were added, make sure they are aligned correctly (including prior months!)", "")
A3: Site | B3: State | C3: Actual | D3: Expected | E3: Delta | F3: % | G3: Forecasted | H3: Delta | I3: % | J3: Notes | K3: Service Requests
A4: {=Sites[Site]} -> Rowley - Central Street Solar | B4: {=Sites[State]} -> MA | C4: 87131.375 | D4: 87924.86 | E4: =IF(AND(ISNUMBER(C4),ISNUMBER(D4)), C4-D4, "") -> -793.485 | F4: =IFERROR(E4/D4, "") -> -0.0090245808 | G4: 85166.41 | H4: =IF(AND(ISNUMBER(C4),ISNUMBER(G4)), C4-G4, "") -> 1964.965 | I4: =IFERROR(H4/G4, "") -> 0.023072066
A5: Auburn - Leicester Street Solar | B5: MA | C5: 953864 | D5: 944591.2 | E5: =IF(AND(ISNUMBER(C5),ISNUMBER(D5)), C5-D5, "") -> 9272.8 | F5: =IFERROR(E5/D5, "") -> 0.0098167334 | G5: 0 | H5: =IF(AND(ISNUMBER(C5),ISNUMBER(G5)), C5-G5, "") -> 953864 | I5: =IFERROR(H5/G5, "")
A6: Rochester - Old Middleboro | B6: MA | C6: 1267172.3 | D6: 1055527 | E6: =IF(AND(ISNUMBER(C6),ISNUMBER(D6)), C6-D6, "") -> 211645.32 | F6: =IFERROR(E6/D6, "") -> 0.20051152 | G6: 799107.7 | H6: =IF(AND(ISNUMBER(C6),ISNUMBER(G6)), C6-G6, "") -> 468064.62 | I6: =IFERROR(H6/G6, "") -> 0.58573409
A7: Dover - Littleworth Road | B7: NH | C7: 44814 | D7: N/A | E7: =IF(AND(ISNUMBER(C7),ISNUMBER(D7)), C7-D7, "") | F7: =IFERROR(E7/D7, "") | G7: N/A | H7: =IF(AND(ISNUMBER(C7),ISNUMBER(G7)), C7-G7, "") | I7: =IFERROR(H7/G7, "")
A8: Milton - Landfill | B8: NH | C8: 113821 | D8: N/A | E8: =IF(AND(ISNUMBER(C8),ISNUMBER(D8)), C8-D8, "") | F8: =IFERROR(E8/D8, "") | G8: N/A | H8: =IF(AND(ISNUMBER(C8),ISNUMBER(G8)), C8-G8, "") | I8: =IFERROR(H8/G8, "") | J8: 1. Inverter 7 was offline for whole month and being RMA'd. 2. Inverter 13 was offline for whole month and being RMA'd. | K8: 1. SR100127 2. SR100128 | L8: SR100128
A9: Hopkinton - 71 Frankland Rd | B9: MA | C9: 685102 | D9: 777991.3 | E9: =IF(AND(ISNUMBER(C9),ISNUMBER(D9)), C9-D9, "") -> -92889.3 | F9: =IFERROR(E9/D9, "") -> -0.11939632 | G9: 829231.8 | H9: =IF(AND(ISNUMBER(C9),ISNUMBER(G9)), C9-G9, "") -> -144129.8 | I9: =IFERROR(H9/G9, "") -> -0.17381123 | J9: 1. Inverter 35 has been left offline from 06/16 to end of the month due to thermal damage on combiner box. 2. Inverter 11 was offline from 15:00 on 06/11 to 13:00 on 06/20. 3. Inverter 31 tripped offline on 06/02 at 15:00 and back online on 06/03 at 07:00. | K9: 1. SR103034 2. SR100959 3. SR102318 | L9: SR100959 | M9: SR102318
A10: Dedham - 100 Rustcraft Rd | B10: MA | C10: 118141 | D10: 145942.7 | E10: =IF(AND(ISNUMBER(C10),ISNUMBER(D10)), C10-D10, "") -> -27801.7 | F10: =IFERROR(E10/D10, "") -> -0.19049737 | G10: 130550.7 | H10: =IF(AND(ISNUMBER(C10),ISNUMBER(G10)), C10-G10, "") -> -12409.7 | I10: =IFERROR(H10/G10, "") -> -0.095056557 | J10: 1. Inverter 16 was underproduced by 6kW compared to peers from 06/02 after replacing fuse on string 6 the inverter started to produce as expected. 2. Inverter 15 waas tripped offline on 06/11 at 18:45 due to Arc protection fault and back online at 13:30 on 06/12. 3. Site was offline from 15:30 on 06/12 to 08:30 on 06/16 4. Inverter 4 was offline from 17:00 on 06/03 to through out the month and comms board being RMA'd. | K10: 1. SR102869 2. SR102863 3. SR102972 4. SR102438 | L10: SR102863 | M10: SR102972 | N10: SR102438

Sheet Jul
A1: {=portfolio} -> Agilitas Energy | D1: July Actual v. Expected | G1: July Actual v. Forecasted
A2: Total | C2: =SUM(C4:C80) -> 3204807.7 | D2: =SUM(D4:D80) -> 3121865.5 | E2: =C2-D2 -> 82942.204 | F2: =IFERROR(E2/D2, 0) -> 0.026568155 | G2: =SUM(G4:G80) -> 1944524.2 | H2: =C2-G2 -> 1260283.5 | I2: =IFERROR(H2/G2, 0) -> 0.64811919 | J2: =IF(AND(TODAY()>DATE(2024, 7, 1), COUNTA(Sites[Site])<>(COUNT(C:C)-1)), "Some sites are missing actual data; if new sites were added, make sure they are aligned correctly (including prior months!)", "")
A3: Site | B3: State | C3: Actual | D3: Expected | E3: Delta | F3: % | G3: Forecasted | H3: Delta | I3: % | J3: Notes | K3: Service Requests
A4: {=Sites[Site]} -> Rowley - Central Street Solar | B4: {=Sites[State]} -> MA | C4: 97741 | D4: 98263.55 | E4: =IF(AND(ISNUMBER(C4),ISNUMBER(D4)), C4-D4, "") -> -522.55 | F4: =IFERROR(E4/D4, "") -> -0.0053178417 | G4: 93151.6 | H4: =IF(AND(ISNUMBER(C4),ISNUMBER(G4)), C4-G4, "") -> 4589.4 | I4: =IFERROR(H4/G4, "") -> 0.049268075 | J4: 1. Inverter 6 tripped offline at 11:24 on 07/28 and back online at 18:00 on 07/28. | K4: 1. SR105168
A5: Auburn - Leicester Street Solar | B5: MA | C5: 983381 | D5: 1037504 | E5: =IF(AND(ISNUMBER(C5),ISNUMBER(D5)), C5-D5, "") -> -54123 | F5: =IFERROR(E5/D5, "") -> -0.052166546 | G5: 0 | H5: =IF(AND(ISNUMBER(C5),ISNUMBER(G5)), C5-G5, "") -> 983381 | I5: =IFERROR(H5/G5, "") | J5: 1.The site was offline from 08:00 to 13:15 on 07/01 due to USNE transformer repairs 2. Site tripped offline at 19:15 on 07/08 and came back online at 08:45 on 07/09 | K5: 1.SR102892 2.SR104167 | L5: SR104167
A6: Rochester - Old Middleboro | B6: MA | C6: 1097546.7 | D6: 969831.3 | E6: =IF(AND(ISNUMBER(C6),ISNUMBER(D6)), C6-D6, "") -> 127715.35 | F6: =IFERROR(E6/D6, "") -> 0.13168822 | G6: 813075.1 | H6: =IF(AND(ISNUMBER(C6),ISNUMBER(G6)), C6-G6, "") -> 284471.55 | I6: =IFERROR(H6/G6, "") -> 0.34987119 | J6: 1.Site tripped offline at 19:45 on 07/03 due to utility outage and it came back online on 07/08 at 07:00 | K6: 1.SR103997
A7: Dover - Littleworth Road | B7: NH | C7: 44814 | D7: N/A | E7: =IF(AND(ISNUMBER(C7),ISNUMBER(D7)), C7-D7, "") | F7: =IFERROR(E7/D7, "") | G7: N/A | H7: =IF(AND(ISNUMBER(C7),ISNUMBER(G7)), C7-G7, "") | I7: =IFERROR(H7/G7, "")
A8: Milton - Landfill | B8: NH | C8: 113821 | D8: N/A | E8: =IF(AND(ISNUMBER(C8),ISNUMBER(D8)), C8-D8, "") | F8: =IFERROR(E8/D8, "") | G8: N/A | H8: =IF(AND(ISNUMBER(C8),ISNUMBER(G8)), C8-G8, "") | I8: =IFERROR(H8/G8, "") | J8: 1. Inverter 7 was offline for whole month and being RMA'd. 2. Inverter 13 was offline for whole month and being RMA'd. 3. Inverter 2 tripped offline at 12:35 on 07/30 and offline for end of month. | K8: 1. SR100127 2. SR100128 3. SR105359 | L8: SR100128 | M8: SR105359
A9: Hopkinton - 71 Frankland Rd | B9: MA | C9: 727229 | D9: 837059.5 | E9: =IF(AND(ISNUMBER(C9),ISNUMBER(D9)), C9-D9, "") -> -109830.5 | F9: =IFERROR(E9/D9, "") -> -0.13120991 | G9: 903244.9 | H9: =IF(AND(ISNUMBER(C9),ISNUMBER(G9)), C9-G9, "") -> -176015.9 | I9: =IFERROR(H9/G9, "") -> -0.19487063 | J9: 1. Inverter 35 has been left offline from 06/16 due to thermal damage on combiner box. 2.Inverter 31 tripped offline at 12:30 on 07/01 and came back online at 08:00 on 07/08 | K9: 1.SR103034 2.SR103844 | L9: SR103844
A10: Dedham - 100 Rustcraft Rd | B10: MA | C10: 140275 | D10: 179207.1 | E10: =IF(AND(ISNUMBER(C10),ISNUMBER(D10)), C10-D10, "") -> -38932.1 | F10: =IFERROR(E10/D10, "") -> -0.21724641 | G10: 135052.6 | H10: =IF(AND(ISNUMBER(C10),ISNUMBER(G10)), C10-G10, "") -> 5222.4 | I10: =IFERROR(H10/G10, "") -> 0.038669378 | J10: 1.Inverter 4 was offline from 17:00 on 06/03 to through out the month and comms board being RMA'd. | K10: 1. SR102438

Sheet Aug
A1: {=portfolio} -> Agilitas Energy | D1: August Actual v. Expected | G1: August Actual v. Forecasted
A2: Total | C2: =SUM(C4:C80) -> 0 | D2: =SUM(D4:D80) -> 0 | E2: =C2-D2 -> 0 | F2: =IFERROR(E2/D2, 0) -> 0 | G2: =SUM(G4:G80) -> 0 | H2: =C2-G2 -> 0 | I2: =IFERROR(H2/G2, 0) -> 0 | J2: =IF(AND(TODAY()>DATE(2024, 8, 1), COUNTA(Sites[Site])<>(COUNT(C:C)-1)), "Some sites are missing actual data; if new sites were added, make sure they are aligned correctly (including prior months!)", "") -> Some sites are missing actual data; if new sites were added, make sure they are aligned correctly (including prior months!)
A3: Site | B3: State | C3: Actual | D3: Expected | E3: Delta | F3: % | G3: Forecasted | H3: Delta | I3: % | J3: Notes | K3: Service Requests
A4: {=Sites[Site]} -> Rowley - Central Street Solar | B4: {=Sites[State]} -> MA | E4: =IF(AND(ISNUMBER(C4),ISNUMBER(D4)), C4-D4, "") | F4: =IFERROR(E4/D4, "") | H4: =IF(AND(ISNUMBER(C4),ISNUMBER(G4)), C4-G4, "") | I4: =IFERROR(H4/G4, "")
A5: Auburn - Leicester Street Solar | B5: MA | E5: =IF(AND(ISNUMBER(C5),ISNUMBER(D5)), C5-D5, "") | F5: =IFERROR(E5/D5, "") | H5: =IF(AND(ISNUMBER(C5),ISNUMBER(G5)), C5-G5, "") | I5: =IFERROR(H5/G5, "")
A6: Rochester - Old Middleboro | B6: MA | E6: =IF(AND(ISNUMBER(C6),ISNUMBER(D6)), C6-D6, "") | F6: =IFERROR(E6/D6, "") | H6: =IF(AND(ISNUMBER(C6),ISNUMBER(G6)), C6-G6, "") | I6: =IFERROR(H6/G6, "")
A7: Dover - Littleworth Road | B7: NH | E7: =IF(AND(ISNUMBER(C7),ISNUMBER(D7)), C7-D7, "") | F7: =IFERROR(E7/D7, "") | H7: =IF(AND(ISNUMBER(C7),ISNUMBER(G7)), C7-G7, "") | I7: =IFERROR(H7/G7, "")
A8: Milton - Landfill | B8: NH | E8: =IF(AND(ISNUMBER(C8),ISNUMBER(D8)), C8-D8, "") | F8: =IFERROR(E8/D8, "") | H8: =IF(AND(ISNUMBER(C8),ISNUMBER(G8)), C8-G8, "") | I8: =IFERROR(H8/G8, "")
A9: Hopkinton - 71 Frankland Rd | B9: MA
A10: Dedham - 100 Rustcraft Rd | B10: MA

Sheet Sep
A1: {=portfolio} -> Agilitas Energy | D1: September Actual v. Expected | G1: September Actual v. Forecasted
A2: Total | C2: =SUM(C4:C80) -> 0 | D2: =SUM(D4:D80) -> 0 | E2: =C2-D2 -> 0 | F2: =IFERROR(E2/D2, 0) -> 0 | G2: =SUM(G4:G80) -> 0 | H2: =C2-G2 -> 0 | I2: =IFERROR(H2/G2, 0) -> 0 | J2: =IF(AND(TODAY()>DATE(2024, 9, 1), COUNTA(Sites[Site])<>(COUNT(C:C)-1)), "Some sites are missing actual data; if new sites were added, make sure they are aligned correctly (including prior months!)", "") -> Some sites are missing actual data; if new sites were added, make sure they are aligned correctly (including prior months!)
A3: Site | B3: State | C3: Actual | D3: Expected | E3: Delta | F3: % | G3: Forecasted | H3: Delta | I3: % | J3: Notes | K3: Service Requests
A4: {=Sites[Site]} -> Rowley - Central Street Solar | B4: {=Sites[State]} -> MA | E4: =IF(AND(ISNUMBER(C4),ISNUMBER(D4)), C4-D4, "") | F4: =IFERROR(E4/D4, "") | H4: =IF(AND(ISNUMBER(C4),ISNUMBER(G4)), C4-G4, "") | I4: =IFERROR(H4/G4, "")
A5: Auburn - Leicester Street Solar | B5: MA | E5: =IF(AND(ISNUMBER(C5),ISNUMBER(D5)), C5-D5, "") | F5: =IFERROR(E5/D5, "") | H5: =IF(AND(ISNUMBER(C5),ISNUMBER(G5)), C5-G5, "") | I5: =IFERROR(H5/G5, "")
A6: Rochester - Old Middleboro | B6: MA | E6: =IF(AND(ISNUMBER(C6),ISNUMBER(D6)), C6-D6, "") | F6: =IFERROR(E6/D6, "") | H6: =IF(AND(ISNUMBER(C6),ISNUMBER(G6)), C6-G6, "") | I6: =IFERROR(H6/G6, "")
A7: Dover - Littleworth Road | B7: NH | E7: =IF(AND(ISNUMBER(C7),ISNUMBER(D7)), C7-D7, "") | F7: =IFERROR(E7/D7, "") | H7: =IF(AND(ISNUMBER(C7),ISNUMBER(G7)), C7-G7, "") | I7: =IFERROR(H7/G7, "")
A8: Milton - Landfill | B8: NH | E8: =IF(AND(ISNUMBER(C8),ISNUMBER(D8)), C8-D8, "") | F8: =IFERROR(E8/D8, "") | H8: =IF(AND(ISNUMBER(C8),ISNUMBER(G8)), C8-G8, "") | I8: =IFERROR(H8/G8, "")
A9: Hopkinton - 71 Frankland Rd | B9: MA | E9: =IF(AND(ISNUMBER(C9),ISNUMBER(D9)), C9-D9, "") | F9: =IFERROR(E9/D9, "") | H9: =IF(AND(ISNUMBER(C9),ISNUMBER(G9)), C9-G9, "") | I9: =IFERROR(H9/G9, "")
A10: Dedham - 100 Rustcraft Rd | B10: MA

Sheet Oct
A1: {=portfolio} -> Agilitas Energy | D1: October Actual v. Expected | G1: October Actual v. Forecasted
A2: Total | C2: =SUM(C4:C80) -> 0 | D2: =SUM(D4:D80) -> 0 | E2: =C2-D2 -> 0 | F2: =IFERROR(E2/D2, 0) -> 0 | G2: =SUM(G4:G80) -> 0 | H2: =C2-G2 -> 0 | I2: =IFERROR(H2/G2, 0) -> 0 | J2: =IF(AND(TODAY()>DATE(2024, 10, 1), COUNTA(Sites[Site])<>(COUNT(C:C)-1)), "Some sites are missing actual data; if new sites were added, make sure they are aligned correctly (including prior months!)", "") -> Some sites are missing actual data; if new sites were added, make sure they are aligned correctly (including prior months!)
A3: Site | B3: State | C3: Actual | D3: Expected | E3: Delta | F3: % | G3: Forecasted | H3: Delta | I3: % | J3: Notes | K3: Service Requests
A4: {=Sites[Site]} -> Rowley - Central Street Solar | B4: {=Sites[State]} -> MA | E4: =IF(AND(ISNUMBER(C4),ISNUMBER(D4)), C4-D4, "") | F4: =IFERROR(E4/D4, "") | I4: =IFERROR(H4/G4, "")
A5: Auburn - Leicester Street Solar | B5: MA | E5: =IF(AND(ISNUMBER(C5),ISNUMBER(D5)), C5-D5, "") | F5: =IFERROR(E5/D5, "") | H5: =IF(AND(ISNUMBER(C5),ISNUMBER(G5)), C5-G5, "") | I5: =IFERROR(H5/G6, "")
A6: Rochester - Old Middleboro | B6: MA | E6: =IF(AND(ISNUMBER(C6),ISNUMBER(D6)), C6-D6, "") | F6: =IFERROR(E6/D6, "") | I6: =IFERROR(H6/G6, "")
A7: Dover - Littleworth Road | B7: NH | E7: =IF(AND(ISNUMBER(C7),ISNUMBER(D7)), C7-D7, "") | F7: =IFERROR(E7/D7, "") | H7: =IF(AND(ISNUMBER(C7),ISNUMBER(G7)), C7-G7, "") | I7: =IFERROR(H7/G8, "")
A8: Milton - Landfill | B8: NH | E8: =IF(AND(ISNUMBER(C8),ISNUMBER(D8)), C8-D8, "") | F8: =IFERROR(E8/D8, "") | I8: =IFERROR(H8/G8, "")
A9: Hopkinton - 71 Frankland Rd | B9: MA | E9: =IF(AND(ISNUMBER(C9),ISNUMBER(D9)), C9-D9, "") | F9: =IFERROR(E9/D9, "") | H9: =IF(AND(ISNUMBER(C9),ISNUMBER(G9)), C9-G9, "") | I9: =IFERROR(H9/G9, "")
A10: Dedham - 100 Rustcraft Rd | B10: MA

Sheet Nov
A1: {=portfolio} -> Agilitas Energy | D1: November Actual v. Expected | G1: November Actual v. Forecasted
A2: Total | C2: =SUM(C4:C80) -> 0 | D2: =SUM(D4:D80) -> 0 | E2: =C2-D2 -> 0 | F2: =IFERROR(E2/D2, 0) -> 0 | G2: =SUM(G4:G80) -> 0 | H2: =C2-G2 -> 0 | I2: =IFERROR(H2/G2, 0) -> 0 | J2: =IF(AND(TODAY()>DATE(2024, 11, 1), COUNTA(Sites[Site])<>(COUNT(C:C)-1)), "Some sites are missing actual data; if new sites were added, make sure they are aligned correctly (including prior months!)", "") -> Some sites are missing actual data; if new sites were added, make sure they are aligned correctly (including prior months!)
A3: Site | B3: State | C3: Actual | D3: Expected | E3: Delta | F3: % | G3: Forecasted | H3: Delta | I3: % | J3: Notes | K3: Service Requests
A4: {=Sites[Site]} -> Rowley - Central Street Solar | B4: {=Sites[State]} -> MA | E4: =IF(AND(ISNUMBER(C4),ISNUMBER(D4)), C4-D4, "") | F4: =IFERROR(E4/D4, "") | H4: =IF(AND(ISNUMBER(C4),ISNUMBER(G4)), C4-G4, "") | I4: =IFERROR(H4/G4, "")
A5: Auburn - Leicester Street Solar | B5: MA | E5: =IF(AND(ISNUMBER(C5),ISNUMBER(D5)), C5-D5, "") | F5: =IFERROR(E5/D5, "") | H5: =IF(AND(ISNUMBER(C5),ISNUMBER(G5)), C5-G5, "") | I5: =IFERROR(H5/G5, "")
A6: Rochester - Old Middleboro | B6: MA | E6: =IF(AND(ISNUMBER(C6),ISNUMBER(D6)), C6-D6, "") | F6: =IFERROR(E6/D6, "") | H6: =IF(AND(ISNUMBER(C6),ISNUMBER(G6)), C6-G6, "") | I6: =IFERROR(H6/G6, "")
A7: Dover - Littleworth Road | B7: NH | E7: =IF(AND(ISNUMBER(C7),ISNUMBER(D7)), C7-D7, "") | F7: =IFERROR(E7/D7, "") | H7: =IF(AND(ISNUMBER(C7),ISNUMBER(G7)), C7-G7, "") | I7: =IFERROR(H7/G7, "")
A8: Milton - Landfill | B8: NH | E8: =IF(AND(ISNUMBER(C8),ISNUMBER(D8)), C8-D8, "") | F8: =IFERROR(E8/D8, "") | H8: =IF(AND(ISNUMBER(C8),ISNUMBER(G8)), C8-G8, "") | I8: =IFERROR(H8/G8, "")
A9: Hopkinton - 71 Frankland Rd | B9: MA | E9: =IF(AND(ISNUMBER(C9),ISNUMBER(D9)), C9-D9, "") | F9: =IFERROR(E9/D9, "") | H9: =IF(AND(ISNUMBER(C9),ISNUMBER(G9)), C9-G9, "") | I9: =IFERROR(H9/G9, "")
A10: Dedham - 100 Rustcraft Rd | B10: MA

Sheet Dec
