Workbook
Name JanActual: #REF!
Name JanActual2: #REF!
Name JanExpected: #REF!
Name JanExpectedDelta: #REF!
Name JanExpectedPercent: #REF!
Name JanExpPercent: #REF!
Name JanForecasted: #REF!
Name JanForecastedDelta: #REF!
Name JanForecastedPercent: #REF!
Name portfolio: Sites!$B$1:$B$1
Name Year: Sites!#REF!

Sheet Year to Date
A1: {=portfolio} -> CBRE | D1: Year to Date Actual v. Expected | G1: Year to Date Actual v. Forecasted
A2: Total | C2: =SUM(C4:C87) -> 216340.8 | D2: =SUM(D4:D87) -> 0 | E2: =C2-D2 -> 216340.8 | F2: =IFERROR(E2/D2, 0) -> 0 | G2: =SUM(G4:G87) -> 0 | H2: =C2-G2 -> 216340.8 | I2: =IFERROR(H2/G2, 0) -> 0
A3: Site | B3: State | C3: Actual | D3: Expected | E3: Delta | F3: % | G3: Forecasted | H3: Delta | I3: %
A4: {=Sites[Site]} -> East Hartford - BA | B4: {=Sites[State]} -> CT | C4: =SUM('1st Qtr'!C4, '2nd Qtr'!C4, '3rd Qtr'!C4, '4th Qtr'!C4) -> 15665.238 | D4: =SUM('1st Qtr'!D4, '2nd Qtr'!D4, '3rd Qtr'!D4, '4th Qtr'!D4) -> 0 | E4: =IF(AND(ISNUMBER(C4),ISNUMBER(D4)), C4-D4, "") -> 15665.238 | F4: =IFERROR(E4/D4, "") | G4: =SUM('1st Qtr'!G4, '2nd Qtr'!G4, '3rd Qtr'!G4, '4th Qtr'!G4) -> 0 | H4: =SUM('1st Qtr'!H4, '2nd Qtr'!H4, '3rd Qtr'!H4, '4th Qtr'!H4) -> 0 | I4: =IFERROR(H4/G4, "")
A5: Indianapolis - BA Speedway | B5: IN | C5: =SUM('1st Qtr'!C5, '2nd Qtr'!C5, '3rd Qtr'!C5, '4th Qtr'!C5) -> 9163.889 | D5: =SUM('1st Qtr'!D5, '2nd Qtr'!D5, '3rd Qtr'!D5, '4th Qtr'!D5) -> 0 | E5: =IF(AND(ISNUMBER(C5),ISNUMBER(D5)), C5-D5, "") -> 9163.889 | F5: =IFERROR(E5/D5, "") | G5: =SUM('1st Qtr'!G5, '2nd Qtr'!G5, '3rd Qtr'!G5, '4th Qtr'!G5) -> 0 | H5: =SUM(Jan!H5, Feb!H5, Mar!H5) -> 0 | I5: =IFERROR(H5/G5, "")
A6: Greenwood - BA | B6: IN | C6: =SUM('1st Qtr'!C6, '2nd Qtr'!C6, '3rd Qtr'!C6, '4th Qtr'!C6) -> 4027.729 | D6: =SUM('1st Qtr'!D6, '2nd Qtr'!D6, '3rd Qtr'!D6, '4th Qtr'!D6) -> 0 | E6: =IF(AND(ISNUMBER(C6),ISNUMBER(D6)), C6-D6, "") -> 4027.729 | F6: =IFERROR(E6/D6, "") | G6: =SUM('1st Qtr'!G6, '2nd Qtr'!G6, '3rd Qtr'!G6, '4th Qtr'!G6) -> 0 | H6: =SUM(Jan!H6, Feb!H6, Mar!H6) -> 0 | I6: =IFERROR(H6/G6, "")
A7: West Chester - BA | B7: OH | C7: =SUM('1st Qtr'!C7, '2nd Qtr'!C7, '3rd Qtr'!C7, '4th Qtr'!C7) -> 8879.482 | D7: =SUM('1st Qtr'!D7, '2nd Qtr'!D7, '3rd Qtr'!D7, '4th Qtr'!D7) -> 0 | E7: =IF(AND(ISNUMBER(C7),ISNUMBER(D7)), C7-D7, "") -> 8879.482 | F7: =IFERROR(E7/D7, "") | G7: =SUM('1st Qtr'!G7, '2nd Qtr'!G7, '3rd Qtr'!G7, '4th Qtr'!G7) -> 0 | H7: =SUM(Jan!H7, Feb!H7, Mar!H7) -> 0 | I7: =IFERROR(H7/G7, "")
A8: Cincinnati - BA MLK and Burnet | B8: OH | C8: =SUM('1st Qtr'!C8, '2nd Qtr'!C8, '3rd Qtr'!C8, '4th Qtr'!C8) -> 12109.192 | D8: =SUM('1st Qtr'!D8, '2nd Qtr'!D8, '3rd Qtr'!D8, '4th Qtr'!D8) -> 0 | E8: =IF(AND(ISNUMBER(C8),ISNUMBER(D8)), C8-D8, "") -> 12109.192 | F8: =IFERROR(E8/D8, "") | G8: =SUM('1st Qtr'!G8, '2nd Qtr'!G8, '3rd Qtr'!G8, '4th Qtr'!G8) -> 0 | H8: =SUM(Jan!H8, Feb!H8, Mar!H8) -> 0 | I8: =IFERROR(H8/G8, "")
A9: Columbus - BA Harrisburg Pike | B9: OH | C9: =SUM('1st Qtr'!C9, '2nd Qtr'!C9, '3rd Qtr'!C9, '4th Qtr'!C9) -> 10286.097 | D9: =SUM('1st Qtr'!D9, '2nd Qtr'!D9, '3rd Qtr'!D9, '4th Qtr'!D9) -> 0 | E9: =IF(AND(ISNUMBER(C9),ISNUMBER(D9)), C9-D9, "") -> 10286.097 | F9: =IFERROR(E9/D9, "") | G9: =SUM('1st Qtr'!G9, '2nd Qtr'!G9, '3rd Qtr'!G9, '4th Qtr'!G9) -> 0 | H9: =SUM(Jan!H9, Feb!H9, Mar!H9) -> 0 | I9: =IFERROR(H9/G9, "")
A10: Cincinnati - BA Hyde Pk Plaza | B10: OH | C10: =SUM('1st Qtr'!C10, '2nd Qtr'!C10, '3rd Qtr'!C10, '4th Qtr'!C10) -> 12174.584 | D10: =SUM('1st Qtr'!D10, '2nd Qtr'!D10, '3rd Qtr'!D10, '4th Qtr'!D10) -> 0 | E10: =IF(AND(ISNUMBER(C10),ISNUMBER(D10)), C10-D10, "") -> 12174.584 | F10: =IFERROR(E10/D10, "") | G10: =SUM('1st Qtr'!G10, '2nd Qtr'!G10, '3rd Qtr'!G10, '4th Qtr'!G10) -> 0 | H10: =SUM(Jan!H10, Feb!H10, Mar!H10) -> 0 | I10: =IFERROR(H10/G10, "")
A11: Cleveland - BA Carnegie & 79th | B11: OH | C11: =SUM('1st Qtr'!C11, '2nd Qtr'!C11, '3rd Qtr'!C11, '4th Qtr'!C11) -> 9347.981 | D11: =SUM('1st Qtr'!D11, '2nd Qtr'!D11, '3rd Qtr'!D11, '4th Qtr'!D11) -> 0 | E11: =IF(AND(ISNUMBER(C11),ISNUMBER(D11)), C11-D11, "") -> 9347.981 | F11: =IFERROR(E11/D11, "") | G11: =SUM('1st Qtr'!G11, '2nd Qtr'!G11, '3rd Qtr'!G11, '4th Qtr'!G11) -> 0 | H11: =SUM(Jan!H11, Feb!H11, Mar!H11) -> 0 | I11: =IFERROR(H11/G11, "")
A12: Cincinnati - BA Sharonville | B12: OH | C12: =SUM('1st Qtr'!C12, '2nd Qtr'!C12, '3rd Qtr'!C12, '4th Qtr'!C12) -> 9427.321 | D12: =SUM('1st Qtr'!D12, '2nd Qtr'!D12, '3rd Qtr'!D12, '4th Qtr'!D12) -> 0 | E12: =IF(AND(ISNUMBER(C12),ISNUMBER(D12)), C12-D12, "") -> 9427.321 | F12: =IFERROR(E12/D12, "") | G12: =SUM('1st Qtr'!G12, '2nd Qtr'!G12, '3rd Qtr'!G12, '4th Qtr'!G12) -> 0 | H12: =SUM(Jan!H12, Feb!H12, Mar!H12) -> 0 | I12: =IFERROR(H12/G12, "")
A13: Zionsville - BA | B13: IN | C13: =SUM('1st Qtr'!C13, '2nd Qtr'!C13, '3rd Qtr'!C13, '4th Qtr'!C13) -> 16874.273 | D13: =SUM('1st Qtr'!D13, '2nd Qtr'!D13, '3rd Qtr'!D13, '4th Qtr'!D13) -> 0 | E13: =IF(AND(ISNUMBER(C13),ISNUMBER(D13)), C13-D13, "") -> 16874.273 | F13: =IFERROR(E13/D13, "") | G13: =SUM('1st Qtr'!G13, '2nd Qtr'!G13, '3rd Qtr'!G13, '4th Qtr'!G13) -> 0 | H13: =SUM(Jan!H13, Feb!H13, Mar!H13) -> 0 | I13: =IFERROR(H13/G13, "")
A14: Columbus - BA Eastgate | B14: OH | C14: =SUM('1st Qtr'!C14, '2nd Qtr'!C14, '3rd Qtr'!C14, '4th Qtr'!C14) -> 8494.673 | D14: =SUM('1st Qtr'!D14, '2nd Qtr'!D14, '3rd Qtr'!D14, '4th Qtr'!D14) -> 0 | E14: =IF(AND(ISNUMBER(C14),ISNUMBER(D14)), C14-D14, "") -> 8494.673 | F14: =IFERROR(E14/D14, "") | G14: =SUM('1st Qtr'!G14, '2nd Qtr'!G14, '3rd Qtr'!G14, '4th Qtr'!G14) -> 0 | H14: =SUM(Jan!H14, Feb!H14, Mar!H14) -> 0 | I14: =IFERROR(H14/G14, "")
A15: Columbus - BA Eastmoor | B15: OH | C15: =SUM('1st Qtr'!C15, '2nd Qtr'!C15, '3rd Qtr'!C15, '4th Qtr'!C15) -> 14490.687 | D15: =SUM('1st Qtr'!D15, '2nd Qtr'!D15, '3rd Qtr'!D15, '4th Qtr'!D15) -> 0 | E15: =IF(AND(ISNUMBER(C15),ISNUMBER(D15)), C15-D15, "") -> 14490.687 | F15: =IFERROR(E15/D15, "") | G15: =SUM('1st Qtr'!G15, '2nd Qtr'!G15, '3rd Qtr'!G15, '4th Qtr'!G15) -> 0 | H15: =SUM(Jan!H15, Feb!H15, Mar!H15) -> 0 | I15: =IFERROR(H15/G15, "")
A16: Brooklyn - BA Canarsie | B16: NY | C16: =SUM('1st Qtr'!C16, '2nd Qtr'!C16, '3rd Qtr'!C16, '4th Qtr'!C16) -> 0 | D16: =SUM('1st Qtr'!D16, '2nd Qtr'!D16, '3rd Qtr'!D16, '4th Qtr'!D16) -> 0 | E16: =IF(AND(ISNUMBER(C16),ISNUMBER(D16)), C16-D16, "") -> 0 | F16: =IFERROR(E16/D16, "") | G16: =SUM('1st Qtr'!G16, '2nd Qtr'!G16, '3rd Qtr'!G16, '4th Qtr'!G16) -> 0 | H16: =SUM(Jan!H16, Feb!H16, Mar!H16) -> 0 | I16: =IFERROR(H16/G16, "")
... A27: Woodbridge - BA ATM | B27: VA | C27: =SUM('1st Qtr'!C27, '2nd Qtr'!C27, '3rd Qtr'!C27, '4th Qtr'!C27) -> 524.616 | D27: =SUM('1st Qtr'!D27, '2nd Qtr'!D27, '3rd Qtr'!D27, '4th Qtr'!D27) -> 0 | E27: =IF(AND(ISNUMBER(C27),ISNUMBER(D27)), C27-D27, "") -> 524.616 | F27: =IFERROR(E27/D27, "") | G27: =SUM('1st Qtr'!G27, '2nd Qtr'!G27, '3rd Qtr'!G27, '4th Qtr'!G27) -> 0 | H27: =SUM(Jan!H27, Feb!H27, Mar!H27) -> 0 | I27: =IFERROR(H27/G27, "")

Sheet 1st Qtr
A1: {=portfolio} -> CBRE | D1: 1st Quarter Actual v. Expected | G1: 1st Quarter Actual v. Forecasted
A2: Total | C2: =SUM(C4:C87) -> 57970.9 | D2: =SUM(D4:D87) -> 0 | E2: =C2-D2 -> 57970.9 | F2: =IFERROR(E2/D2, 0) -> 0 | G2: =SUM(G4:G87) -> 0 | H2: =C2-G2 -> 57970.9 | I2: =IFERROR(H2/G2, 0) -> 0
A3: Site | B3: State | C3: Actual | D3: Expected | E3: Delta | F3: % | G3: Forecasted | H3: Delta | I3: %
A4: {=Sites[Site]} -> East Hartford - BA | B4: {=Sites[State]} -> CT | C4: =SUM(Jan!C4, Feb!C4, Mar!C4) -> 4024.1 | D4: =SUM(Jan!D4, Feb!D4, Mar!D4) -> 0 | E4: =IF(AND(ISNUMBER(C4),ISNUMBER(D4)), C4-D4, "") -> 4024.1 | F4: =IFERROR(E4/D4, "") | G4: =SUM(Jan!G4, Feb!G4, Mar!G4) -> 0 | H4: =SUM(Jan!H4, Feb!H4, Mar!H4) -> 0 | I4: =IFERROR(H4/G4, "")
A5: Indianapolis - BA Speedway | B5: IN | C5: =SUM(Jan!C5, Feb!C5, Mar!C5) -> 2628.6 | D5: =SUM(Jan!D5, Feb!D5, Mar!D5) -> 0 | E5: =IF(AND(ISNUMBER(C5),ISNUMBER(D5)), C5-D5, "") -> 2628.6 | F5: =IFERROR(E5/D5, "") | G5: =SUM(Jan!G5, Feb!G5, Mar!G5) -> 0 | H5: =SUM(Jan!H5, Feb!H5, Mar!H5) -> 0 | I5: =IFERROR(H5/G5, "")
A6: Greenwood - BA | B6: IN | C6: =SUM(Jan!C6, Feb!C6, Mar!C6) -> 1105.5 | D6: =SUM(Jan!D6, Feb!D6, Mar!D6) -> 0 | E6: =IF(AND(ISNUMBER(C6),ISNUMBER(D6)), C6-D6, "") -> 1105.5 | F6: =IFERROR(E6/D6, "") | G6: =SUM(Jan!G6, Feb!G6, Mar!G6) -> 0 | H6: =SUM(Jan!H6, Feb!H6, Mar!H6) -> 0 | I6: =IFERROR(H6/G6, "")
A7: West Chester - BA | B7: OH | C7: =SUM(Jan!C7, Feb!C7, Mar!C7) -> 2681.6 | D7: =SUM(Jan!D7, Feb!D7, Mar!D7) -> 0 | E7: =IF(AND(ISNUMBER(C7),ISNUMBER(D7)), C7-D7, "") -> 2681.6 | F7: =IFERROR(E7/D7, "") | G7: =SUM(Jan!G7, Feb!G7, Mar!G7) -> 0 | H7: =SUM(Jan!H7, Feb!H7, Mar!H7) -> 0 | I7: =IFERROR(H7/G7, "")
A8: Cincinnati - BA MLK and Burnet | B8: OH | C8: =SUM(Jan!C8, Feb!C8, Mar!C8) -> 3320.2 | D8: =SUM(Jan!D8, Feb!D8, Mar!D8) -> 0 | E8: =IF(AND(ISNUMBER(C8),ISNUMBER(D8)), C8-D8, "") -> 3320.2 | F8: =IFERROR(E8/D8, "") | G8: =SUM(Jan!G8, Feb!G8, Mar!G8) -> 0 | H8: =SUM(Jan!H8, Feb!H8, Mar!H8) -> 0 | I8: =IFERROR(H8/G8, "")
A9: Columbus - BA Harrisburg Pike | B9: OH | C9: =SUM(Jan!C9, Feb!C9, Mar!C9) -> 2862.2 | D9: =SUM(Jan!D9, Feb!D9, Mar!D9) -> 0 | E9: =IF(AND(ISNUMBER(C9),ISNUMBER(D9)), C9-D9, "") -> 2862.2 | F9: =IFERROR(E9/D9, "") | G9: =SUM(Jan!G9, Feb!G9, Mar!G9) -> 0 | H9: =SUM(Jan!H9, Feb!H9, Mar!H9) -> 0 | I9: =IFERROR(H9/G9, "")
A10: Cincinnati - BA Hyde Pk Plaza | B10: OH | C10: =SUM(Jan!C10, Feb!C10, Mar!C10) -> 3350.3 | D10: =SUM(Jan!D10, Feb!D10, Mar!D10) -> 0 | E10: =IF(AND(ISNUMBER(C10),ISNUMBER(D10)), C10-D10, "") -> 3350.3 | F10: =IFERROR(E10/D10, "") | G10: =SUM(Jan!G10, Feb!G10, Mar!G10) -> 0 | H10: =SUM(Jan!H10, Feb!H10, Mar!H10) -> 0 | I10: =IFERROR(H10/G10, "")
A11: Cleveland - BA Carnegie & 79th | B11: OH | C11: =SUM(Jan!C11, Feb!C11, Mar!C11) -> 2717.9 | D11: =SUM(Jan!D11, Feb!D11, Mar!D11) -> 0 | E11: =IF(AND(ISNUMBER(C11),ISNUMBER(D11)), C11-D11, "") -> 2717.9 | F11: =IFERROR(E11/D11, "") | G11: =SUM(Jan!G11, Feb!G11, Mar!G11) -> 0 | H11: =SUM(Jan!H11, Feb!H11, Mar!H11) -> 0 | I11: =IFERROR(H11/G11, "")
A12: Cincinnati - BA Sharonville | B12: OH | C12: =SUM(Jan!C12, Feb!C12, Mar!C12) -> 2719.1 | D12: =SUM(Jan!D12, Feb!D12, Mar!D12) -> 0 | E12: =IF(AND(ISNUMBER(C12),ISNUMBER(D12)), C12-D12, "") -> 2719.1 | F12: =IFERROR(E12/D12, "") | G12: =SUM(Jan!G12, Feb!G12, Mar!G12) -> 0 | H12: =SUM(Jan!H12, Feb!H12, Mar!H12) -> 0 | I12: =IFERROR(H12/G12, "")
A13: Zionsville - BA | B13: IN | C13: =SUM(Jan!C13, Feb!C13, Mar!C13) -> 4872.3 | D13: =SUM(Jan!D13, Feb!D13, Mar!D13) -> 0 | E13: =IF(AND(ISNUMBER(C13),ISNUMBER(D13)), C13-D13, "") -> 4872.3 | F13: =IFERROR(E13/D13, "") | G13: =SUM(Jan!G13, Feb!G13, Mar!G13) -> 0 | H13: =SUM(Jan!H13, Feb!H13, Mar!H13) -> 0 | I13: =IFERROR(H13/G13, "")
A14: Columbus - BA Eastgate | B14: OH | C14: =SUM(Jan!C14, Feb!C14, Mar!C14) -> 1927 | D14: =SUM(Jan!D14, Feb!D14, Mar!D14) -> 0 | E14: =IF(AND(ISNUMBER(C14),ISNUMBER(D14)), C14-D14, "") -> 1927 | F14: =IFERROR(E14/D14, "") | G14: =SUM(Jan!G14, Feb!G14, Mar!G14) -> 0 | H14: =SUM(Jan!H14, Feb!H14, Mar!H14) -> 0 | I14: =IFERROR(H14/G14, "")
A15: Columbus - BA Eastmoor | B15: OH | C15: =SUM(Jan!C15, Feb!C15, Mar!C15) -> 3740.7 | D15: =SUM(Jan!D15, Feb!D15, Mar!D15) -> 0 | E15: =IF(AND(ISNUMBER(C15),ISNUMBER(D15)), C15-D15, "") -> 3740.7 | F15: =IFERROR(E15/D15, "") | G15: =SUM(Jan!G15, Feb!G15, Mar!G15) -> 0 | H15: =SUM(Jan!H15, Feb!H15, Mar!H15) -> 0 | I15: =IFERROR(H15/G15, "")
A16: Brooklyn - BA Canarsie | B16: NY | C16: =SUM(Jan!C16, Feb!C16, Mar!C16) -> 0 | D16: =SUM(Jan!D16, Feb!D16, Mar!D16) -> 0 | E16: =IF(AND(ISNUMBER(C16),ISNUMBER(D16)), C16-D16, "") -> 0 | F16: =IFERROR(E16/D16, "") | G16: =SUM(Jan!G16, Feb!G16, Mar!G16) -> 0 | H16: =SUM(Jan!H16, Feb!H16, Mar!H16) -> 0 | I16: =IFERROR(H16/G16, "")
... A27: Woodbridge - BA ATM | B27: VA | C27: =SUM(Jan!C27, Feb!C27, Mar!C27) -> 134.1 | D27: =SUM(Jan!D27, Feb!D27, Mar!D27) -> 0 | E27: =IF(AND(ISNUMBER(C27),ISNUMBER(D27)), C27-D27, "") -> 134.1 | F27: =IFERROR(E27/D27, "") | G27: =SUM(Jan!G27, Feb!G27, Mar!G27) -> 0 | H27: =SUM(Jan!H27, Feb!H27, Mar!H27) -> 0 | I27: =IFERROR(H27/G27, "")

Sheet 2nd Qtr
A1: {=portfolio} -> CBRE | D1: 2nd Quarter Actual v. Expected | G1: 2nd Quarter Actual v. Forecasted
A2: Total | C2: =SUM(C4:C86) -> 114284.3 | D2: =SUM(D4:D86) -> 0 | E2: =C2-D2 -> 114284.3 | F2: =IFERROR(E2/D2, 0) -> 0 | G2: =SUM(G4:G86) -> 0 | H2: =C2-G2 -> 114284.3 | I2: =IFERROR(H2/G2, 0) -> 0
A3: Site | B3: State | C3: Actual | D3: Expected | E3: Delta | F3: % | G3: Forecasted | H3: Delta | I3: %
A4: {=Sites[Site]} -> East Hartford - BA | B4: {=Sites[State]} -> CT | C4: =SUM(Apr!C4, May!C4, Jun!C4) -> 8329.6 | D4: =SUM(Apr!D4, May!D4, Jun!D4) -> 0 | E4: =IF(AND(ISNUMBER(C4),ISNUMBER(D4)), C4-D4, "") -> 8329.6 | F4: =IFERROR(E4/D4, "") | G4: =SUM(Apr!G4, May!G4, Jun!G4) -> 0 | H4: =SUM(Apr!H4, May!H4, Jun!H4) -> 0 | I4: =IFERROR(H4/G4, "")
A5: Indianapolis - BA Speedway | B5: IN | C5: =SUM(Apr!C5, May!C5, Jun!C5) -> 4814.1 | D5: =SUM(Apr!D5, May!D5, Jun!D5) -> 0 | E5: =IF(AND(ISNUMBER(C5),ISNUMBER(D5)), C5-D5, "") -> 4814.1 | F5: =IFERROR(E5/D5, "") | G5: =SUM(Apr!G5, May!G5, Jun!G5) -> 0 | H5: =SUM(Apr!H5, May!H5, Jun!H5) -> 0 | I5: =IFERROR(H5/G5, "")
A6: Greenwood - BA | B6: IN | C6: =SUM(Apr!C6, May!C6, Jun!C6) -> 2135.5 | D6: =SUM(Apr!D6, May!D6, Jun!D6) -> 0 | E6: =IF(AND(ISNUMBER(C6),ISNUMBER(D6)), C6-D6, "") -> 2135.5 | F6: =IFERROR(E6/D6, "") | G6: =SUM(Apr!G6, May!G6, Jun!G6) -> 0 | H6: =SUM(Apr!H6, May!H6, Jun!H6) -> 0 | I6: =IFERROR(H6/G6, "")
A7: West Chester - BA | B7: OH | C7: =SUM(Apr!C7, May!C7, Jun!C7) -> 4520.3 | D7: =SUM(Apr!D7, May!D7, Jun!D7) -> 0 | E7: =IF(AND(ISNUMBER(C7),ISNUMBER(D7)), C7-D7, "") -> 4520.3 | F7: =IFERROR(E7/D7, "") | G7: =SUM(Apr!G7, May!G7, Jun!G7) -> 0 | H7: =SUM(Apr!H7, May!H7, Jun!H7) -> 0 | I7: =IFERROR(H7/G7, "")
A8: Cincinnati - BA MLK and Burnet | B8: OH | C8: =SUM(Apr!C8, May!C8, Jun!C8) -> 6404.6 | D8: =SUM(Apr!D8, May!D8, Jun!D8) -> 0 | E8: =IF(AND(ISNUMBER(C8),ISNUMBER(D8)), C8-D8, "") -> 6404.6 | F8: =IFERROR(E8/D8, "") | G8: =SUM(Apr!G8, May!G8, Jun!G8) -> 0 | H8: =SUM(Apr!H8, May!H8, Jun!H8) -> 0 | I8: =IFERROR(H8/G8, "")
A9: Columbus - BA Harrisburg Pike | B9: OH | C9: =SUM(Apr!C9, May!C9, Jun!C9) -> 5428.4 | D9: =SUM(Apr!D9, May!D9, Jun!D9) -> 0 | E9: =IF(AND(ISNUMBER(C9),ISNUMBER(D9)), C9-D9, "") -> 5428.4 | F9: =IFERROR(E9/D9, "") | G9: =SUM(Apr!G9, May!G9, Jun!G9) -> 0 | H9: =SUM(Apr!H9, May!H9, Jun!H9) -> 0 | I9: =IFERROR(H9/G9, "")
A10: Cincinnati - BA Hyde Pk Plaza | B10: OH | C10: =SUM(Apr!C10, May!C10, Jun!C10) -> 6473.5 | D10: =SUM(Apr!D10, May!D10, Jun!D10) -> 0 | E10: =IF(AND(ISNUMBER(C10),ISNUMBER(D10)), C10-D10, "") -> 6473.5 | F10: =IFERROR(E10/D10, "") | G10: =SUM(Apr!G10, May!G10, Jun!G10) -> 0 | H10: =SUM(Apr!H10, May!H10, Jun!H10) -> 0 | I10: =IFERROR(H10/G10, "")
A11: Cleveland - BA Carnegie & 79th | B11: OH | C11: =SUM(Apr!C11, May!C11, Jun!C11) -> 4824.9 | D11: =SUM(Apr!D11, May!D11, Jun!D11) -> 0 | E11: =IF(AND(ISNUMBER(C11),ISNUMBER(D11)), C11-D11, "") -> 4824.9 | F11: =IFERROR(E11/D11, "") | G11: =SUM(Apr!G11, May!G11, Jun!G11) -> 0 | H11: =SUM(Apr!H11, May!H11, Jun!H11) -> 0 | I11: =IFERROR(H11/G11, "")
A12: Cincinnati - BA Sharonville | B12: OH | C12: =SUM(Apr!C12, May!C12, Jun!C12) -> 4895.7 | D12: =SUM(Apr!D12, May!D12, Jun!D12) -> 0 | E12: =IF(AND(ISNUMBER(C12),ISNUMBER(D12)), C12-D12, "") -> 4895.7 | F12: =IFERROR(E12/D12, "") | G12: =SUM(Apr!G12, May!G12, Jun!G12) -> 0 | H12: =SUM(Apr!H12, May!H12, Jun!H12) -> 0 | I12: =IFERROR(H12/G12, "")
A13: Zionsville - BA | B13: IN | C13: =SUM(Apr!C13, May!C13, Jun!C13) -> 8780.3 | D13: =SUM(Apr!D13, May!D13, Jun!D13) -> 0 | E13: =IF(AND(ISNUMBER(C13),ISNUMBER(D13)), C13-D13, "") -> 8780.3 | F13: =IFERROR(E13/D13, "") | G13: =SUM(Apr!G13, May!G13, Jun!G13) -> 0 | H13: =SUM(Apr!H13, May!H13, Jun!H13) -> 0 | I13: =IFERROR(H13/G13, "")
A14: Columbus - BA Eastgate | B14: OH | C14: =SUM(Apr!C14, May!C14, Jun!C14) -> 4737.1 | D14: =SUM(Apr!D14, May!D14, Jun!D14) -> 0 | E14: =IF(AND(ISNUMBER(C14),ISNUMBER(D14)), C14-D14, "") -> 4737.1 | F14: =IFERROR(E14/D14, "") | G14: =SUM(Apr!G14, May!G14, Jun!G14) -> 0 | H14: =SUM(Apr!H14, May!H14, Jun!H14) -> 0 | I14: =IFERROR(H14/G14, "")
A15: Columbus - BA Eastmoor | B15: OH | C15: =SUM(Apr!C15, May!C15, Jun!C15) -> 7828.5 | D15: =SUM(Apr!D15, May!D15, Jun!D15) -> 0 | E15: =IF(AND(ISNUMBER(C15),ISNUMBER(D15)), C15-D15, "") -> 7828.5 | F15: =IFERROR(E15/D15, "") | G15: =SUM(Apr!G15, May!G15, Jun!G15) -> 0 | H15: =SUM(Apr!H15, May!H15, Jun!H15) -> 0 | I15: =IFERROR(H15/G15, "")
A16: Brooklyn - BA Canarsie | B16: NY | C16: =SUM(Apr!C16, May!C16, Jun!C16) -> 0 | D16: =SUM(Apr!D16, May!D16, Jun!D16) -> 0 | E16: =IF(AND(ISNUMBER(C16),ISNUMBER(D16)), C16-D16, "") -> 0 | F16: =IFERROR(E16/D16, "") | G16: =SUM(Apr!G16, May!G16, Jun!G16) -> 0 | H16: =SUM(Apr!H16, May!H16, Jun!H16) -> 0 | I16: =IFERROR(H16/G16, "")
... A27: Woodbridge - BA ATM | B27: VA | C27: =SUM(Apr!C27, May!C27, Jun!C27) -> 272.2 | D27: =SUM(Apr!D27, May!D27, Jun!D27) -> 0 | E27: =IF(AND(ISNUMBER(C27),ISNUMBER(D27)), C27-D27, "") -> 272.2 | F27: =IFERROR(E27/D27, "") | G27: =SUM(Apr!G27, May!G27, Jun!G27) -> 0 | H27: =SUM(Apr!H27, May!H27, Jun!H27) -> 0 | I27: =IFERROR(H27/G27, "")

Sheet 3rd Qtr
A1: {=portfolio} -> CBRE | D1: 3rd Quarter Actual v. Expected | G1: 3rd Quarter Actual v. Forecasted
A2: Total | C2: =SUM(C4:C85) -> 44085.604 | D2: =SUM(D4:D85) -> 0 | E2: =C2-D2 -> 44085.604 | F2: =IFERROR(E2/D2, 0) -> 0 | G2: =SUM(G4:G85) -> 0 | H2: =C2-G2 -> 44085.604 | I2: =IFERROR(H2/G2, 0) -> 0
A3: Site | B3: State | C3: Actual | D3: Expected | E3: Delta | F3: % | G3: Forecasted | H3: Delta | I3: %
A4: {=Sites[Site]} -> East Hartford - BA | B4: {=Sites[State]} -> CT | C4: =SUM(Jul!C4, Aug!C4, Sep!C4) -> 3311.538 | D4: =SUM(Jul!D4, Aug!D4, Sep!D4) -> 0 | E4: =IF(AND(ISNUMBER(C4),ISNUMBER(D4)), C4-D4, "") -> 3311.538 | F4: =IFERROR(E4/D4, "") | G4: =SUM(Jul!G4, Aug!G4, Sep!G4) -> 0 | H4: =SUM(Jul!H4, Aug!H4, Sep!H4) -> 0 | I4: =IFERROR(H4/G4, "")
A5: Indianapolis - BA Speedway | B5: IN | C5: =SUM(Jul!C5, Aug!C5, Sep!C5) -> 1721.189 | D5: =SUM(Jul!D5, Aug!D5, Sep!D5) -> 0 | E5: =IF(AND(ISNUMBER(C5),ISNUMBER(D5)), C5-D5, "") -> 1721.189 | F5: =IFERROR(E5/D5, "") | G5: =SUM(Jul!G5, Aug!G5, Sep!G5) -> 0 | H5: =SUM(Jul!H5, Aug!H5, Sep!H5) -> 0 | I5: =IFERROR(H5/G5, "")
A6: Greenwood - BA | B6: IN | C6: =SUM(Jul!C6, Aug!C6, Sep!C6) -> 786.729 | D6: =SUM(Jul!D6, Aug!D6, Sep!D6) -> 0 | E6: =IF(AND(ISNUMBER(C6),ISNUMBER(D6)), C6-D6, "") -> 786.729 | F6: =IFERROR(E6/D6, "") | G6: =SUM(Jul!G6, Aug!G6, Sep!G6) -> 0 | H6: =SUM(Jul!H6, Aug!H6, Sep!H6) -> 0 | I6: =IFERROR(H6/G6, "")
A7: West Chester - BA | B7: OH | C7: =SUM(Jul!C7, Aug!C7, Sep!C7) -> 1677.582 | D7: =SUM(Jul!D7, Aug!D7, Sep!D7) -> 0 | E7: =IF(AND(ISNUMBER(C7),ISNUMBER(D7)), C7-D7, "") -> 1677.582 | F7: =IFERROR(E7/D7, "") | G7: =SUM(Jul!G7, Aug!G7, Sep!G7) -> 0 | H7: =SUM(Jul!H7, Aug!H7, Sep!H7) -> 0 | I7: =IFERROR(H7/G7, "")
A8: Cincinnati - BA MLK and Burnet | B8: OH | C8: =SUM(Jul!C8, Aug!C8, Sep!C8) -> 2384.392 | D8: =SUM(Jul!D8, Aug!D8, Sep!D8) -> 0 | E8: =IF(AND(ISNUMBER(C8),ISNUMBER(D8)), C8-D8, "") -> 2384.392 | F8: =IFERROR(E8/D8, "") | G8: =SUM(Jul!G8, Aug!G8, Sep!G8) -> 0 | H8: =SUM(Jul!H8, Aug!H8, Sep!H8) -> 0 | I8: =IFERROR(H8/G8, "")
A9: Columbus - BA Harrisburg Pike | B9: OH | C9: =SUM(Jul!C9, Aug!C9, Sep!C9) -> 1995.497 | D9: =SUM(Jul!D9, Aug!D9, Sep!D9) -> 0 | E9: =IF(AND(ISNUMBER(C9),ISNUMBER(D9)), C9-D9, "") -> 1995.497 | F9: =IFERROR(E9/D9, "") | G9: =SUM(Jul!G9, Aug!G9, Sep!G9) -> 0 | H9: =SUM(Jul!H9, Aug!H9, Sep!H9) -> 0 | I9: =IFERROR(H9/G9, "")
A10: Cincinnati - BA Hyde Pk Plaza | B10: OH | C10: =SUM(Jul!C10, Aug!C10, Sep!C10) -> 2350.784 | D10: =SUM(Jul!D10, Aug!D10, Sep!D10) -> 0 | E10: =IF(AND(ISNUMBER(C10),ISNUMBER(D10)), C10-D10, "") -> 2350.784 | F10: =IFERROR(E10/D10, "") | G10: =SUM(Jul!G10, Aug!G10, Sep!G10) -> 0 | H10: =SUM(Jul!H10, Aug!H10, Sep!H10) -> 0 | I10: =IFERROR(H10/G10, "")
A11: Cleveland - BA Carnegie & 79th | B11: OH | C11: =SUM(Jul!C11, Aug!C11, Sep!C11) -> 1805.181 | D11: =SUM(Jul!D11, Aug!D11, Sep!D11) -> 0 | E11: =IF(AND(ISNUMBER(C11),ISNUMBER(D11)), C11-D11, "") -> 1805.181 | F11: =IFERROR(E11/D11, "") | G11: =SUM(Jul!G11, Aug!G11, Sep!G11) -> 0 | H11: =SUM(Jul!H11, Aug!H11, Sep!H11) -> 0 | I11: =IFERROR(H11/G11, "")
A12: Cincinnati - BA Sharonville | B12: OH | C12: =SUM(Jul!C12, Aug!C12, Sep!C12) -> 1812.521 | D12: =SUM(Jul!D12, Aug!D12, Sep!D12) -> 0 | E12: =IF(AND(ISNUMBER(C12),ISNUMBER(D12)), C12-D12, "") -> 1812.521 | F12: =IFERROR(E12/D12, "") | G12: =SUM(Jul!G12, Aug!G12, Sep!G12) -> 0 | H12: =SUM(Jul!H12, Aug!H12, Sep!H12) -> 0 | I12: =IFERROR(H12/G12, "")
A13: Zionsville - BA | B13: IN | C13: =SUM(Jul!C13, Aug!C13, Sep!C13) -> 3221.673 | D13: =SUM(Jul!D13, Aug!D13, Sep!D13) -> 0 | E13: =IF(AND(ISNUMBER(C13),ISNUMBER(D13)), C13-D13, "") -> 3221.673 | F13: =IFERROR(E13/D13, "") | G13: =SUM(Jul!G13, Aug!G13, Sep!G13) -> 0 | H13: =SUM(Jul!H13, Aug!H13, Sep!H13) -> 0 | I13: =IFERROR(H13/G13, "")
A14: Columbus - BA Eastgate | B14: OH | C14: =SUM(Jul!C14, Aug!C14, Sep!C14) -> 1830.573 | D14: =SUM(Jul!D14, Aug!D14, Sep!D14) -> 0 | E14: =IF(AND(ISNUMBER(C14),ISNUMBER(D14)), C14-D14, "") -> 1830.573 | F14: =IFERROR(E14/D14, "") | G14: =SUM(Jul!G14, Aug!G14, Sep!G14) -> 0 | H14: =SUM(Jul!H14, Aug!H14, Sep!H14) -> 0 | I14: =IFERROR(H14/G14, "")
A15: Columbus - BA Eastmoor | B15: OH | C15: =SUM(Jul!C15, Aug!C15, Sep!C15) -> 2921.487 | D15: =SUM(Jul!D15, Aug!D15, Sep!D15) -> 0 | E15: =IF(AND(ISNUMBER(C15),ISNUMBER(D15)), C15-D15, "") -> 2921.487 | F15: =IFERROR(E15/D15, "") | G15: =SUM(Jul!G15, Aug!G15, Sep!G15) -> 0 | H15: =SUM(Jul!H15, Aug!H15, Sep!H15) -> 0 | I15: =IFERROR(H15/G15, "")
A16: Brooklyn - BA Canarsie | B16: NY | C16: =SUM(Jul!C16, Aug!C16, Sep!C16) -> 0 | D16: =SUM(Jul!D16, Aug!D16, Sep!D16) -> 0 | E16: =IF(AND(ISNUMBER(C16),ISNUMBER(D16)), C16-D16, "") -> 0 | F16: =IFERROR(E16/D16, "") | G16: =SUM(Jul!G16, Aug!G16, Sep!G16) -> 0 | H16: =SUM(Jul!H16, Aug!H16, Sep!H16) -> 0 | I16: =IFERROR(H16/G16, "")
... A23: Brooklyn - BA North 4th & Berry | B23: NY | C23: =SUM(Jul!C23, Aug!C23, Sep!C23) -> 2949.708 | D23: =SUM(Jul!D23, Aug!D23, Sep!D23) -> 0 | E23: =IF(AND(ISNUMBER(C23),ISNUMBER(D23)), C23-D23, "") -> 2949.708 | F23: =IFERROR(E23/D23, "") | G23: =SUM(Jul!G23, Aug!G23, Sep!G23) -> 0 | H23: =SUM(Jul!H23, Aug!H23, Sep!H23) -> 0 | I23: =IFERROR(H23/G23, "")
A24: Midlothian - BA Brandermill | B24: VA | C24: =SUM(Jul!C24, Jul!C24, Sep!C24) -> 3273.266 | D24: =SUM(Jul!D24, Aug!D24, Sep!D24) -> 0 | E24: =IF(AND(ISNUMBER(C24),ISNUMBER(D24)), C24-D24, "") -> 3273.266 | F24: =IFERROR(E24/D24, "") | G24: =SUM(Jul!G24, Aug!G24, Sep!G24) -> 0 | H24: =SUM(Jul!H24, Aug!H24, Sep!H24) -> 0 | I24: =IFERROR(H24/G24, "")
A25: Lexington - BA North Park | B25: KY | C25: =SUM(Jul!C25, Aug!C25, Sep!C25) -> 1624.913 | D25: =SUM(Jul!D25, Aug!D25, Sep!D25) -> 0 | E25: =IF(AND(ISNUMBER(C25),ISNUMBER(D25)), C25-D25, "") -> 1624.913 | F25: =IFERROR(E25/D25, "") | G25: =SUM(Jul!G25, Aug!G25, Sep!G25) -> 0 | H25: =SUM(Jul!H25, Aug!H25, Sep!H25) -> 0 | I25: =IFERROR(H25/G25, "")
A26: Coventry - BA ATM | B26: RI | C26: =SUM(Jul!C26, Jul!C26, Sep!C26) -> 253.662 | D26: =SUM(Jul!D26, Aug!D26, Sep!D26) -> 0 | E26: =IF(AND(ISNUMBER(C26),ISNUMBER(D26)), C26-D26, "") -> 253.662 | F26: =IFERROR(E26/D26, "") | G26: =SUM(Jul!G26, Aug!G26, Sep!G26) -> 0 | H26: =SUM(Jul!H26, Aug!H26, Sep!H26) -> 0 | I26: =IFERROR(H26/G26, "")
A27: Woodbridge - BA ATM | B27: VA | C27: =SUM(Jul!C27, Aug!C27, Sep!C27) -> 118.316 | D27: =SUM(Jul!D27, Aug!D27, Sep!D27) -> 0 | E27: =IF(AND(ISNUMBER(C27),ISNUMBER(D27)), C27-D27, "") -> 118.316 | F27: =IFERROR(E27/D27, "") | G27: =SUM(Jul!G27, Aug!G27, Sep!G27) -> 0 | H27: =SUM(Jul!H27, Aug!H27, Sep!H27) -> 0 | I27: =IFERROR(H27/G27, "")

Sheet 4th Qtr
A1: {=portfolio} -> CBRE | D1: 4th Quarter Actual v. Expected | G1: 4th Quarter Actual v. Forecasted
A2: Total | C2: =SUM(C4:C86) -> 0 | D2: =SUM(D4:D86) -> 0 | E2: =C2-D2 -> 0 | F2: =IFERROR(E2/D2, 0) -> 0 | G2: =SUM(G4:G86) -> 0 | H2: =C2-G2 -> 0 | I2: =IFERROR(H2/G2, 0) -> 0
A3: Site | B3: State | C3: Actual | D3: Expected | E3: Delta | F3: % | G3: Forecasted | H3: Delta | I3: %
A4: {=Sites[Site]} -> East Hartford - BA | B4: {=Sites[State]} -> CT | C4: =SUM(Oct!C4, Nov!C4, Dec!C4) -> 0 | D4: =SUM(Oct!D4, Nov!D4, Dec!D4) -> 0 | E4: =IF(AND(ISNUMBER(C4),ISNUMBER(D4)), C4-D4, "") -> 0 | F4: =IFERROR(E4/D4, "") | G4: =SUM(Oct!G4, Nov!G4, Dec!G4) -> 0 | H4: =SUM(Oct!H4, Nov!H4, Dec!H4) -> 0 | I4: =IFERROR(H4/G4, "")
A5: Indianapolis - BA Speedway | B5: IN | C5: =SUM(Oct!C5, Nov!C5, Dec!C5) -> 0 | D5: =SUM(Oct!D5, Nov!D5, Dec!D5) -> 0 | E5: =IF(AND(ISNUMBER(C5),ISNUMBER(D5)), C5-D5, "") -> 0 | F5: =IFERROR(E5/D5, "") | G5: =SUM(Oct!G5, Nov!G5, Dec!G5) -> 0 | H5: =SUM(Oct!H5, Nov!H5, Dec!H5) -> 0 | I5: =IFERROR(H5/G5, "")
A6: Greenwood - BA | B6: IN | C6: =SUM(Oct!C6, Nov!C6, Dec!C6) -> 0 | D6: =SUM(Oct!D6, Nov!D6, Dec!D6) -> 0 | E6: =IF(AND(ISNUMBER(C6),ISNUMBER(D6)), C6-D6, "") -> 0 | F6: =IFERROR(E6/D6, "") | G6: =SUM(Oct!G6, Nov!G6, Dec!G6) -> 0 | H6: =SUM(Oct!H6, Nov!H6, Dec!H6) -> 0 | I6: =IFERROR(H6/G6, "")
A7: West Chester - BA | B7: OH | C7: =SUM(Oct!C7, Nov!C7, Dec!C7) -> 0 | D7: =SUM(Oct!D7, Nov!D7, Dec!D7) -> 0 | E7: =IF(AND(ISNUMBER(C7),ISNUMBER(D7)), C7-D7, "") -> 0 | F7: =IFERROR(E7/D7, "") | G7: =SUM(Oct!G7, Nov!G7, Dec!G7) -> 0 | H7: =SUM(Oct!H7, Nov!H7, Dec!H7) -> 0 | I7: =IFERROR(H7/G7, "")
A8: Cincinnati - BA MLK and Burnet | B8: OH | C8: =SUM(Oct!C8, Nov!C8, Dec!C8) -> 0 | D8: =SUM(Oct!D8, Nov!D8, Dec!D8) -> 0 | E8: =IF(AND(ISNUMBER(C8),ISNUMBER(D8)), C8-D8, "") -> 0 | F8: =IFERROR(E8/D8, "") | G8: =SUM(Oct!G8, Nov!G8, Dec!G8) -> 0 | H8: =SUM(Oct!H8, Nov!H8, Dec!H8) -> 0 | I8: =IFERROR(H8/G8, "")
A9: Columbus - BA Harrisburg Pike | B9: OH | C9: =SUM(Oct!C9, Nov!C9, Dec!C9) -> 0 | D9: =SUM(Oct!D9, Nov!D9, Dec!D9) -> 0 | E9: =IF(AND(ISNUMBER(C9),ISNUMBER(D9)), C9-D9, "") -> 0 | F9: =IFERROR(E9/D9, "") | G9: =SUM(Oct!G9, Nov!G9, Dec!G9) -> 0 | H9: =SUM(Oct!H9, Nov!H9, Dec!H9) -> 0 | I9: =IFERROR(H9/G9, "")
A10: Cincinnati - BA Hyde Pk Plaza | B10: OH | C10: =SUM(Oct!C10, Nov!C10, Dec!C10) -> 0 | D10: =SUM(Oct!D10, Nov!D10, Dec!D10) -> 0 | E10: =IF(AND(ISNUMBER(C10),ISNUMBER(D10)), C10-D10, "") -> 0 | F10: =IFERROR(E10/D10, "") | G10: =SUM(Oct!G10, Nov!G10, Dec!G10) -> 0 | H10: =SUM(Oct!H10, Nov!H10, Dec!H10) -> 0 | I10: =IFERROR(H10/G10, "")
A11: Cleveland - BA Carnegie & 79th | B11: OH | C11: =SUM(Oct!C11, Nov!C11, Dec!C11) -> 0 | D11: =SUM(Oct!D11, Nov!D11, Dec!D11) -> 0 | E11: =IF(AND(ISNUMBER(C11),ISNUMBER(D11)), C11-D11, "") -> 0 | F11: =IFERROR(E11/D11, "") | G11: =SUM(Oct!G11, Nov!G11, Dec!G11) -> 0 | H11: =SUM(Oct!H11, Nov!H11, Dec!H11) -> 0 | I11: =IFERROR(H11/G11, "")
A12: Cincinnati - BA Sharonville | B12: OH | C12: =SUM(Oct!C12, Nov!C12, Dec!C12) -> 0 | D12: =SUM(Oct!D12, Nov!D12, Dec!D12) -> 0 | E12: =IF(AND(ISNUMBER(C12),ISNUMBER(D12)), C12-D12, "") -> 0 | F12: =IFERROR(E12/D12, "") | G12: =SUM(Oct!G12, Nov!G12, Dec!G12) -> 0 | H12: =SUM(Oct!H12, Nov!H12, Dec!H12) -> 0 | I12: =IFERROR(H12/G12, "")
A13: Zionsville - BA | B13: IN | C13: =SUM(Oct!C13, Nov!C13, Dec!C13) -> 0 | D13: =SUM(Oct!D13, Nov!D13, Dec!D13) -> 0 | E13: =IF(AND(ISNUMBER(C13),ISNUMBER(D13)), C13-D13, "") -> 0 | F13: =IFERROR(E13/D13, "") | G13: =SUM(Oct!G13, Nov!G13, Dec!G13) -> 0 | H13: =SUM(Oct!H13, Nov!H13, Dec!H13) -> 0 | I13: =IFERROR(H13/G13, "")
A14: Columbus - BA Eastgate | B14: OH | C14: =SUM(Oct!C14, Nov!C14, Dec!C14) -> 0 | D14: =SUM(Oct!D14, Nov!D14, Dec!D14) -> 0 | E14: =IF(AND(ISNUMBER(C14),ISNUMBER(D14)), C14-D14, "") -> 0 | F14: =IFERROR(E14/D14, "") | G14: =SUM(Oct!G14, Nov!G14, Dec!G14) -> 0 | H14: =SUM(Oct!H14, Nov!H14, Dec!H14) -> 0 | I14: =IFERROR(H14/G14, "")
A15: Columbus - BA Eastmoor | B15: OH | C15: =SUM(Oct!C7, Nov!C7, Dec!C15) -> 0 | D15: =SUM(Oct!D15, Nov!D15, Dec!D15) -> 0 | E15: =IF(AND(ISNUMBER(C15),ISNUMBER(D15)), C15-D15, "") -> 0 | F15: =IFERROR(E15/D15, "") | G15: =SUM(Oct!G15, Nov!G15, Dec!G15) -> 0 | H15: =SUM(Oct!H15, Nov!H15, Dec!H15) -> 0 | I15: =IFERROR(H15/G15, "")
A16: Brooklyn - BA Canarsie | B16: NY | C16: =SUM(Oct!C16, Nov!C16, Dec!C16) -> 0 | D16: =SUM(Oct!D16, Nov!D16, Dec!D16) -> 0 | E16: =IF(AND(ISNUMBER(C16),ISNUMBER(D16)), C16-D16, "") -> 0 | F16: =IFERROR(E16/D16, "") | G16: =SUM(Oct!G16, Nov!G16, Dec!G16) -> 0 | H16: =SUM(Oct!H16, Nov!H16, Dec!H16) -> 0 | I16: =IFERROR(H16/G16, "")
A17: Pittsburg - BA Fox Chapel | B17: PA | C17: =SUM(Oct!C17, Nov!C17, Dec!C17) -> 0 | D17: =SUM(Oct!D17, Nov!D17, Dec!D17) -> 0 | E17: =IF(AND(ISNUMBER(C17),ISNUMBER(D17)), C17-D17, "") -> 0 | F17: =IFERROR(E17/D17, "") | G17: =SUM(Oct!G17, Nov!G17, Dec!G17) -> 0 | H17: =SUM(Oct!H17, Nov!H17, Dec!H17) -> 0 | I17: =IFERROR(H17/G17, "")
A18: New York - BA Two Bryant Pk | B18: NY | C18: =SUM(Oct!C18, Nov!C18, Dec!C18) -> 0 | D18: =SUM(Oct!D18, Nov!D18, Dec!D18) -> 0 | E18: =IF(AND(ISNUMBER(C18),ISNUMBER(D18)), C18-D18, "") -> 0 | F18: =IFERROR(E18/D18, "") | G18: =SUM(Oct!G18, Nov!G18, Dec!G18) -> 0 | H18: =SUM(Oct!H18, Nov!H18, Dec!H18) -> 0 | I18: =IFERROR(H18/G18, "")
A19: Baltimore - BA Sudbrook Lane | B19: MD | C19: =SUM(Oct!C19, Nov!C19, Dec!C19) -> 0 | D19: =SUM(Oct!D19, Nov!D19, Dec!D19) -> 0 | E19: =IF(AND(ISNUMBER(C19),ISNUMBER(D19)), C19-D19, "") -> 0 | F19: =IFERROR(E19/D19, "") | G19: =SUM(Oct!G19, Nov!G19, Dec!G19) -> 0 | H19: =SUM(Oct!H19, Nov!H19, Dec!H19) -> 0 | I19: =IFERROR(H19/G19, "")
A20: Stamford - BA West Stamford | B20: CT | C20: =SUM(Oct!C20, Nov!C20, Dec!C20) -> 0 | D20: =SUM(Oct!D20, Nov!D20, Dec!D20) -> 0 | E20: =IF(AND(ISNUMBER(C20),ISNUMBER(D20)), C20-D20, "") -> 0 | F20: =IFERROR(E20/D20, "") | G20: =SUM(Oct!G20, Nov!G20, Dec!G20) -> 0 | H20: =SUM(Oct!H20, Nov!H20, Dec!H20) -> 0 | I20: =IFERROR(H20/G20, "")
A21: Hanover - BA Arundel Mills | B21: MD | C21: =SUM(Oct!C21, Nov!C21, Dec!C21) -> 0 | D21: =SUM(Oct!D21, Nov!D21, Dec!D21) -> 0 | E21: =IF(AND(ISNUMBER(C21),ISNUMBER(D21)), C21-D21, "") -> 0 | F21: =IFERROR(E21/D21, "") | G21: =SUM(Oct!G21, Nov!G21, Dec!G21) -> 0 | H21: =SUM(Oct!H21, Nov!H21, Dec!H21) -> 0 | I21: =IFERROR(H21/G21, "")
A22: Glen Cove - BA Forest Ave | B22: NY | C22: =SUM(Oct!C22, Nov!C22, Dec!C22) -> 0 | D22: =SUM(Oct!D22, Nov!D22, Dec!D22) -> 0 | E22: =IF(AND(ISNUMBER(C22),ISNUMBER(D22)), C22-D22, "") -> 0 | F22: =IFERROR(E22/D22, "") | G22: =SUM(Oct!G22, Nov!G22, Dec!G22) -> 0 | H22: =SUM(Oct!H22, Nov!H22, Dec!H22) -> 0 | I22: =IFERROR(H22/G22, "")
A23: Brooklyn - BA North 4th & Berry | B23: NY | C23: =SUM(Oct!C23, Nov!C23, Dec!C23) -> 0 | D23: =SUM(Oct!D23, Nov!D23, Dec!D23) -> 0 | E23: =IF(AND(ISNUMBER(C23),ISNUMBER(D23)), C23-D23, "") -> 0 | F23: =IFERROR(E23/D23, "") | G23: =SUM(Oct!G23, Nov!G23, Dec!G23) -> 0 | H23: =SUM(Oct!H23, Nov!H23, Dec!H23) -> 0 | I23: =IFERROR(H23/G23, "")
A24: Midlothian - BA Brandermill | B24: VA | C24: =SUM(Oct!C24, Oct!C24, Dec!C24) -> 0 | D24: =SUM(Oct!D24, Nov!D24, Dec!D24) -> 0 | E24: =IF(AND(ISNUMBER(C24),ISNUMBER(D24)), C24-D24, "") -> 0 | F24: =IFERROR(E24/D24, "") | G24: =SUM(Oct!G24, Nov!G24, Dec!G24) -> 0 | H24: =SUM(Oct!H24, Nov!H24, Dec!H24) -> 0 | I24: =IFERROR(H24/G24, "")
A25: Lexington - BA North Park | B25: KY | C25: =SUM(Oct!C25, Nov!C25, Dec!C25) -> 0 | D25: =SUM(Oct!D25, Nov!D25, Dec!D25) -> 0 | E25: =IF(AND(ISNUMBER(C25),ISNUMBER(D26)), C25-D26, "") -> 0 | F25: =IFERROR(E25/D26, "") | G25: =SUM(Oct!G25, Nov!G25, Dec!G25) -> 0 | H25: =SUM(Oct!H25, Nov!H25, Dec!H25) -> 0 | I25: =IFERROR(H25/G25, "")
A26: Coventry - BA ATM | B26: RI | C26: =SUM(Oct!C26, Oct!C26, Dec!C26) -> 0 | D26: =SUM(Oct!D26, Nov!D26, Dec!D26) -> 0 | E26: =IF(AND(ISNUMBER(C26),ISNUMBER(D26)), C26-D26, "") -> 0 | G26: =SUM(Oct!G26, Nov!G26, Dec!G26) -> 0 | H26: =SUM(Oct!H26, Nov!H26, Dec!H26) -> 0
A27: Woodbridge - BA ATM | B27: VA | C27: =SUM(Oct!C27, Nov!C27, Dec!C27) -> 0 | D27: =SUM(Oct!D27, Nov!D27, Dec!D27) -> 0 | E27: =IF(AND(ISNUMBER(C27),ISNUMBER(D27)), C27-D27, "") -> 0 | G27: =SUM(Oct!G27, Nov!G27, Dec!G27) -> 0 | H27: =SUM(Oct!H27, Nov!H27, Dec!H27) -> 0

Sheet Jan
A1: {=portfolio} -> CBRE | D1: January Actual v. Expected | G1: January Actual v. Forecasted
A2: Total | C2: =SUM(C4:C85) -> 11574.8 | D2: =SUM(D4:D85) -> 0 | E2: =C2-D2 -> 11574.8 | F2: =IFERROR(E2/D2, 0) -> 0 | G2: =SUM(G4:G85) -> 0 | H2: =C2-G2 -> 11574.8 | I2: =IFERROR(H2/G2, 0) -> 0 | J2: =IF(AND(TODAY()>DATE(2024, 1, 1), COUNTA(Sites[Site])<>(COUNT(C:C)-1)), "Some sites are missing actual data; if new sites were added, make sure they are aligned correctly (including prior months!)", "")
A3: Site | B3: State | C3: Actual | D3: Expected | E3: Delta | F3: % | G3: Forecasted | H3: Delta | I3: % | J3: Notes | K3: Service Requests
A4: {=Sites[Site]} -> East Hartford - BA | B4: {=Sites[State]} -> CT | C4: 975.3 | D4: N/A | E4: =IF(AND(ISNUMBER(C4),ISNUMBER(D4)), C4-D4, "") | F4: =IFERROR(E4/D4, "") | G4: N/A | H4: =IF(AND(ISNUMBER(C4),ISNUMBER(G4)), C4-G4, "") | I4: =IFERROR(H4/G4, "")
A5: Indianapolis - BA Speedway | B5: IN | C5: 545.8 | D5: N/A | E5: =IF(AND(ISNUMBER(C5),ISNUMBER(D5)), C5-D5, "") | F5: =IFERROR(E5/D5, "") | G5: N/A | H5: =IF(AND(ISNUMBER(C5),ISNUMBER(G5)), C5-G5, "") | I5: =IFERROR(H5/G5, "") | J5: 1. 14 Microinverters not started for production on 01/17/25 due to a Residual snow event issues and back online on 01/21/25 after the snow event. | K5: 1. SR095676
A6: Greenwood - BA | B6: IN | C6: 219.1 | D6: N/A | E6: =IF(AND(ISNUMBER(C6),ISNUMBER(D6)), C6-D6, "") | F6: =IFERROR(E6/D6, "") | G6: N/A | H6: =IF(AND(ISNUMBER(C6),ISNUMBER(G6)), C6-G6, "") | I6: =IFERROR(H6/G6, "") | J6: 1. 4 Micro inverters are offline from 01/16/25 due to Residual snow event issues and back online on 01/21/25 after the snow event. | K6: 1. SR095625
A7: West Chester - BA | B7: OH | C7: 658.6 | D7: N/A | E7: =IF(AND(ISNUMBER(C7),ISNUMBER(D7)), C7-D7, "") | F7: =IFERROR(E7/D7, "") | G7: N/A | H7: =IF(AND(ISNUMBER(C7),ISNUMBER(G7)), C7-G7, "") | I7: =IFERROR(H7/G7, "")
A8: Cincinnati - BA MLK and Burnet | B8: OH | C8: 667.3 | D8: N/A | E8: =IF(AND(ISNUMBER(C8),ISNUMBER(D8)), C8-D8, "") | F8: =IFERROR(E8/D8, "") | G8: N/A | H8: =IF(AND(ISNUMBER(C8),ISNUMBER(G8)), C8-G8, "") | I8: =IFERROR(H8/G8, "")
A9: Columbus - BA Harrisburg Pike | B9: OH | C9: 472.4 | D9: N/A | E9: =IF(AND(ISNUMBER(C9),ISNUMBER(D9)), C9-D9, "") | F9: =IFERROR(E9/D9, "") | G9: N/A | H9: =IF(AND(ISNUMBER(C9),ISNUMBER(G9)), C9-G9, "") | I9: =IFERROR(H9/G9, "")
A10: Cincinnati - BA Hyde Pk Plaza | B10: OH | C10: 628.2 | D10: N/A | E10: =IF(AND(ISNUMBER(C10),ISNUMBER(D10)), C10-D10, "") | F10: =IFERROR(E10/D10, "") | G10: N/A | H10: =IF(AND(ISNUMBER(C10),ISNUMBER(G10)), C10-G10, "") | I10: =IFERROR(H10/G10, "")
A11: Cleveland - BA Carnegie & 79th | B11: OH | C11: 537.2 | D11: N/A | E11: =IF(AND(ISNUMBER(C11),ISNUMBER(D11)), C11-D11, "") | F11: =IFERROR(E11/D11, "") | G11: N/A | H11: =IF(AND(ISNUMBER(C11),ISNUMBER(G11)), C11-G11, "") | I11: =IFERROR(H11/G11, "")
A12: Cincinnati - BA Sharonville | B12: OH | C12: 540.1 | D12: N/A | E12: =IF(AND(ISNUMBER(C12),ISNUMBER(D12)), C12-D12, "") | F12: =IFERROR(E12/D12, "") | G12: N/A | H12: =IF(AND(ISNUMBER(C12),ISNUMBER(G12)), C12-G12, "") | I12: =IFERROR(H12/G12, "")
A13: Zionsville - BA | B13: IN | C13: 1062 | D13: N/A | E13: =IF(AND(ISNUMBER(C13),ISNUMBER(D13)), C13-D13, "") | F13: =IFERROR(E13/D13, "") | G13: N/A | H13: =IF(AND(ISNUMBER(C13),ISNUMBER(G13)), C13-G13, "") | I13: =IFERROR(H13/G13, "") | J13: 1. 16 microinverters are offline from 01/15/25 due to a Residual snow event issues and back online on 01/21/25 after the snow event. | K13: 1. SR095602
A14: Columbus - BA Eastgate | B14: OH | C14: 244.3 | D14: N/A | E14: =IF(AND(ISNUMBER(C14),ISNUMBER(D14)), C14-D14, "") | F14: =IFERROR(E14/D14, "") | G14: N/A | H14: =IF(AND(ISNUMBER(C14),ISNUMBER(G14)), C14-G14, "") | I14: =IFERROR(H14/G14, "") | J14: 1. 31 microinverters are failed to report on 01/06/25 due to a Residual snow event issues and back online on 01/21/25 after the snow event. | K14: 1. SR095334
A15: Columbus - BA Eastmoor | B15: OH | C15: 543.5 | D15: N/A | E15: =IF(AND(ISNUMBER(C15),ISNUMBER(D15)), C15-D15, "") | F15: =IFERROR(E15/D15, "") | G15: N/A | H15: =IF(AND(ISNUMBER(C15),ISNUMBER(G15)), C15-G15, "") | I15: =IFERROR(H15/G15, "") | J15: 1. 51 microinverters are offline from 01/06/25 due to a Residual snow event issues and all microinverters back online on 01/21/25 after the snow event. 2. One microinverter offline since 12/26 and was RMA'd on 12/30, remaining offline throughout the month. | K15: 1. SR095335 2. SR095094, SR095335 | L15: SR095094 | M15: SR095335
A16: Brooklyn - BA Canarsie | B16: NY | C16: 0 | D16: N/A | E16: =IF(AND(ISNUMBER(C16),ISNUMBER(D16)), C16-D16, "") | F16: =IFERROR(E16/D16, "") | G16: N/A | H16: =IF(AND(ISNUMBER(C16),ISNUMBER(G16)), C16-G16, "") | I16: =IFERROR(H16/G16, "")
A17: Pittsburg - BA Fox Chapel | B17: PA | C17: 411.6 | D17: N/A | E17: =IF(AND(ISNUMBER(C17),ISNUMBER(D17)), C17-D17, "") | F17: =IFERROR(E17/D17, "") | G17: N/A | H17: =IF(AND(ISNUMBER(C17),ISNUMBER(G17)), C17-G17, "") | I17: =IFERROR(H17/G17, "")
A18: New York - BA Two Bryant Pk | B18: NY | C18: 0 | D18: N/A | E18: =IF(AND(ISNUMBER(C18),ISNUMBER(D18)), C18-D18, "") | F18: =IFERROR(E18/D18, "") | G18: N/A | H18: =IF(AND(ISNUMBER(C18),ISNUMBER(G18)), C18-G18, "") | I18: =IFERROR(H18/G18, "")
A19: Baltimore - BA Sudbrook Lane | B19: MD | C19: 278.5 | D19: N/A | E19: =IF(AND(ISNUMBER(C19),ISNUMBER(D19)), C19-D19, "") | F19: =IFERROR(E19/D19, "") | G19: N/A | H19: =IF(AND(ISNUMBER(C19),ISNUMBER(G19)), C19-G19, "") | I19: =IFERROR(H19/G19, "") | J19: 1. 11 microinverters are offline from 01/14/25 due to a Residual snow event issues and all microinverters back online on 01/21/25 after the snow event. | K19: 1. SR095548
A20: Stamford - BA West Stamford | B20: CT | C20: 782 | D20: N/A | E20: =IF(AND(ISNUMBER(C20),ISNUMBER(D20)), C20-D20, "") | F20: =IFERROR(E20/D20, "") | G20: N/A | H20: =IF(AND(ISNUMBER(C20),ISNUMBER(G20)), C20-G20, "") | I20: =IFERROR(H20/G20, "")
A21: Hanover - BA Arundel Mills | B21: MD | C21: 719.2 | D21: N/A | E21: =IF(AND(ISNUMBER(C21),ISNUMBER(D21)), C21-D21, "") | F21: =IFERROR(E21/D21, "") | G21: N/A | H21: =IF(AND(ISNUMBER(C21),ISNUMBER(G21)), C21-G21, "") | I21: =IFERROR(H21/G21, "")
A22: Glen Cove - BA Forest Ave | B22: NY | C22: 0 | D22: N/A | E22: =IF(AND(ISNUMBER(C22),ISNUMBER(D22)), C22-D22, "") | F22: =IFERROR(E22/D22, "") | G22: N/A | H22: =IF(AND(ISNUMBER(C22),ISNUMBER(G22)), C22-G22, "") | I22: =IFERROR(H22/G22, "")
A23: Brooklyn - BA North 4th & Berry | B23: NY | C23: 911.3 | D23: N/A | E23: =IF(AND(ISNUMBER(C23),ISNUMBER(D23)), C23-D23, "") | F23: =IFERROR(E23/D23, "") | G23: N/A | H23: =IF(AND(ISNUMBER(C23),ISNUMBER(G23)), C23-G23, "") | I23: =IFERROR(H23/G23, "")
A24: Midlothian - BA Brandermill | B24: VA | C24: 895.7 | D24: N/A | E24: =IF(AND(ISNUMBER(C24),ISNUMBER(D24)), C24-D24, "") | F24: =IFERROR(E24/D24, "") | G24: N/A | H24: =IF(AND(ISNUMBER(C24),ISNUMBER(G24)), C24-G24, "") | I24: =IFERROR(H24/G24, "") | J24: 1. One microinverter 202036040228 is not reporting from 4/15/23. | K24: 1. SR088366
A25: Lexington - BA North Park | B25: KY | C25: 372.4 | D25: N/A | E25: =IF(AND(ISNUMBER(C25),ISNUMBER(D25)), C25-D25, "") | F25: =IFERROR(E25/D25, "") | G25: N/A | H25: =IF(AND(ISNUMBER(C25),ISNUMBER(G25)), C25-G25, "") | I25: =IFERROR(H25/G25, "") | J25: 1. 3 microinverters are not producing from 01/16/25 due to a Residual snow event issues and all microinverters back online on 01/21/25 after the snow event. | K25: 1. SR095626
A26: Coventry - BA ATM | B26: RI | C26: 55.4 | D26: N/A | E26: =IF(AND(ISNUMBER(C26),ISNUMBER(D26)), C26-D26, "") | G26: N/A | H26: =IF(AND(ISNUMBER(C26),ISNUMBER(G26)), C26-G26, "") | J26: 1. 2 microinverters are currently not reporting from 12/18/24 | K26: 1.SR094910
A27: Woodbridge - BA ATM | B27: VA | C27: 54.9 | D27: N/A | E27: =IF(AND(ISNUMBER(C27),ISNUMBER(D27)), C27-D27, "") | G27: N/A | H27: =IF(AND(ISNUMBER(C27),ISNUMBER(G27)), C27-G27, "")

Sheet Feb
A1: {=portfolio} -> CBRE | D1: February Actual v. Expected | G1: February Actual v. Forecasted
A2: Total | C2: =SUM(C4:C86) -> 16905 | D2: =SUM(D4:D86) -> 0 | E2: =C2-D2 -> 16905 | F2: =IFERROR(E2/D2, 0) -> 0 | G2: =SUM(G4:G86) -> 0 | H2: =C2-G2 -> 16905 | I2: =IFERROR(H2/G2, 0) -> 0 | J2: =IF(AND(TODAY()>DATE(2024, 2, 1), COUNTA(Sites[Site])<>(COUNT(C:C)-1)), "Some sites are missing actual data; if new sites were added, make sure they are aligned correctly (including prior months!)", "")
A3: Site | B3: State | C3: Actual | D3: Expected | E3: Delta | F3: % | G3: Forecasted | H3: Delta | I3: % | J3: Notes | K3: Service Requests
A4: {=Sites[Site]} -> East Hartford - BA | B4: {=Sites[State]} -> CT | C4: 705 | D4: N/A | E4: =IF(AND(ISNUMBER(C4),ISNUMBER(D4)), C4-D4, "") | F4: =IFERROR(E4/D4, "") | G4: N/A | H4: =IF(AND(ISNUMBER(C4),ISNUMBER(G4)), C4-G4, "") | I4: =IFERROR(H4/G4, "")
A5: Indianapolis - BA Speedway | B5: IN | C5: 803 | D5: N/A | E5: =IF(AND(ISNUMBER(C5),ISNUMBER(D5)), C5-D5, "") | F5: =IFERROR(E5/D5, "") | G5: N/A | H5: =IF(AND(ISNUMBER(C5),ISNUMBER(G5)), C5-G5, "") | I5: =IFERROR(H5/G5, "")
A6: Greenwood - BA | B6: IN | C6: 330 | D6: N/A | E6: =IF(AND(ISNUMBER(C6),ISNUMBER(D6)), C6-D6, "") | F6: =IFERROR(E6/D6, "") | G6: N/A | H6: =IF(AND(ISNUMBER(C6),ISNUMBER(G6)), C6-G6, "") | I6: =IFERROR(H6/G6, "")
A7: West Chester - BA | B7: OH | C7: 781 | D7: N/A | E7: =IF(AND(ISNUMBER(C7),ISNUMBER(D7)), C7-D7, "") | F7: =IFERROR(E7/D7, "") | G7: N/A | H7: =IF(AND(ISNUMBER(C7),ISNUMBER(G7)), C7-G7, "") | I7: =IFERROR(H7/G7, "")
A8: Cincinnati - BA MLK and Burnet | B8: OH | C8: 883 | D8: N/A | E8: =IF(AND(ISNUMBER(C8),ISNUMBER(D8)), C8-D8, "") | F8: =IFERROR(E8/D8, "") | G8: N/A | H8: =IF(AND(ISNUMBER(C8),ISNUMBER(G8)), C8-G8, "") | I8: =IFERROR(H8/G8, "")
A9: Columbus - BA Harrisburg Pike | B9: OH | C9: 875 | D9: N/A | E9: =IF(AND(ISNUMBER(C9),ISNUMBER(D9)), C9-D9, "") | F9: =IFERROR(E9/D9, "") | G9: N/A | H9: =IF(AND(ISNUMBER(C9),ISNUMBER(G9)), C9-G9, "") | I9: =IFERROR(H9/G9, "")
A10: Cincinnati - BA Hyde Pk Plaza | B10: OH | C10: 976 | D10: N/A | E10: =IF(AND(ISNUMBER(C10),ISNUMBER(D10)), C10-D10, "") | F10: =IFERROR(E10/D10, "") | G10: N/A | H10: =IF(AND(ISNUMBER(C10),ISNUMBER(G10)), C10-G10, "") | I10: =IFERROR(H10/G10, "") | J10: 1. One microinverter is offline on 02/14 and later self resolved. | K10: 1.SR097110
A11: Cleveland - BA Carnegie & 79th | B11: OH | C11: 855 | D11: N/A | E11: =IF(AND(ISNUMBER(C11),ISNUMBER(D11)), C11-D11, "") | F11: =IFERROR(E11/D11, "") | G11: N/A | H11: =IF(AND(ISNUMBER(C11),ISNUMBER(G11)), C11-G11, "") | I11: =IFERROR(H11/G11, "")
A12: Cincinnati - BA Sharonville | B12: OH | C12: 819 | D12: N/A | E12: =IF(AND(ISNUMBER(C12),ISNUMBER(D12)), C12-D12, "") | F12: =IFERROR(E12/D12, "") | G12: N/A | H12: =IF(AND(ISNUMBER(C12),ISNUMBER(G12)), C12-G12, "") | I12: =IFERROR(H12/G12, "")
A13: Zionsville - BA | B13: IN | C13: 1508 | D13: N/A | E13: =IF(AND(ISNUMBER(C13),ISNUMBER(D13)), C13-D13, "") | F13: =IFERROR(E13/D13, "") | G13: N/A | H13: =IF(AND(ISNUMBER(C13),ISNUMBER(G13)), C13-G13, "") | I13: =IFERROR(H13/G13, "")
A14: Columbus - BA Eastgate | B14: OH | C14: 427 | D14: N/A | E14: =IF(AND(ISNUMBER(C14),ISNUMBER(D14)), C14-D14, "") | F14: =IFERROR(E14/D14, "") | G14: N/A | H14: =IF(AND(ISNUMBER(C14),ISNUMBER(G14)), C14-G14, "") | I14: =IFERROR(H14/G14, "")
A15: Columbus - BA Eastmoor | B15: OH | C15: 967 | D15: N/A | E15: =IF(AND(ISNUMBER(C15),ISNUMBER(D15)), C15-D15, "") | F15: =IFERROR(E15/D15, "") | G15: N/A | H15: =IF(AND(ISNUMBER(C15),ISNUMBER(G15)), C15-G15, "") | I15: =IFERROR(H15/G15, "") | J15: 1. One microinverter offline since 12/26 and was RMA'd on 12/30, remaining offline throughout the month. | K15: 1. SR095094, SR095335 | L15: SR095335
A16: Brooklyn - BA Canarsie | B16: NY | C16: 0 | D16: N/A | E16: =IF(AND(ISNUMBER(C16),ISNUMBER(D16)), C16-D16, "") | F16: =IFERROR(E16/D16, "") | G16: N/A | H16: =IF(AND(ISNUMBER(C16),ISNUMBER(G16)), C16-G16, "") | I16: =IFERROR(H16/G16, "")
A17: Pittsburg - BA Fox Chapel | B17: PA | C17: 933 | D17: N/A | E17: =IF(AND(ISNUMBER(C17),ISNUMBER(D17)), C17-D17, "") | F17: =IFERROR(E17/D17, "") | G17: N/A | H17: =IF(AND(ISNUMBER(C17),ISNUMBER(G17)), C17-G17, "") | I17: =IFERROR(H17/G17, "")
A18: New York - BA Two Bryant Pk | B18: NY | C18: 0 | D18: N/A | E18: =IF(AND(ISNUMBER(C18),ISNUMBER(D18)), C18-D18, "") | F18: =IFERROR(E18/D18, "") | G18: N/A | H18: =IF(AND(ISNUMBER(C18),ISNUMBER(G18)), C18-G18, "") | I18: =IFERROR(H18/G18, "")
A19: Baltimore - BA Sudbrook Lane | B19: MD | C19: 986 | D19: N/A | E19: =IF(AND(ISNUMBER(C19),ISNUMBER(D19)), C19-D19, "") | F19: =IFERROR(E19/D19, "") | G19: N/A | H19: =IF(AND(ISNUMBER(C19),ISNUMBER(G19)), C19-G19, "") | I19: =IFERROR(H19/G19, "")
A20: Stamford - BA West Stamford | B20: CT | C20: 1010 | D20: N/A | E20: =IF(AND(ISNUMBER(C20),ISNUMBER(D20)), C20-D20, "") | F20: =IFERROR(E20/D20, "") | G20: N/A | H20: =IF(AND(ISNUMBER(C20),ISNUMBER(G20)), C20-G20, "") | I20: =IFERROR(H20/G20, "")
A21: Hanover - BA Arundel Mills | B21: MD | C21: 1190 | D21: N/A | E21: =IF(AND(ISNUMBER(C21),ISNUMBER(D21)), C21-D21, "") | F21: =IFERROR(E21/D21, "") | G21: N/A | H21: =IF(AND(ISNUMBER(C21),ISNUMBER(G21)), C21-G21, "") | I21: =IFERROR(H21/G21, "")
A22: Glen Cove - BA Forest Ave | B22: NY | C22: 0 | D22: N/A | E22: =IF(AND(ISNUMBER(C22),ISNUMBER(D22)), C22-D22, "") | F22: =IFERROR(E22/D22, "") | G22: N/A | H22: =IF(AND(ISNUMBER(C22),ISNUMBER(G22)), C22-G22, "") | I22: =IFERROR(H22/G22, "")
A23: Brooklyn - BA North 4th & Berry | B23: NY | C23: 1275 | D23: N/A | E23: =IF(AND(ISNUMBER(C23),ISNUMBER(D23)), C23-D23, "") | F23: =IFERROR(E23/D23, "") | G23: N/A | H23: =IF(AND(ISNUMBER(C23),ISNUMBER(G23)), C23-G23, "") | I23: =IFERROR(H23/G23, "") | J23: 1. Site was offline from 02/10/25 and back online at 15:15 on 02/11 due to a Residual snow event issue. | K23: 1. SR096673
A24: Midlothian - BA Brandermill | B24: VA | C24: 894 | D24: N/A | E24: =IF(AND(ISNUMBER(C24),ISNUMBER(D24)), C24-D24, "") | F24: =IFERROR(E24/D24, "") | G24: N/A | H24: =IF(AND(ISNUMBER(C24),ISNUMBER(G24)), C24-G24, "") | I24: =IFERROR(H24/G24, "") | J24: 1. One microinverter 202036040228 is not reporting from 4/15/23 and being RMA'd on 02/18/25. | K24: 1. SR088366
A25: Lexington - BA North Park | B25: KY | C25: 587 | D25: N/A | E25: =IF(AND(ISNUMBER(C25),ISNUMBER(D25)), C25-D25, "") | F25: =IFERROR(E25/D25, "") | G25: N/A | H25: =IF(AND(ISNUMBER(C25),ISNUMBER(G25)), C25-G25, "") | I25: =IFERROR(H25/G25, "")
A26: Coventry - BA ATM | B26: RI | C26: 64 | D26: N/A | E26: =IF(AND(ISNUMBER(C26),ISNUMBER(D26)), C26-D26, "") | F26: =IFERROR(E26/D26, "") | G26: N/A | H26: =IF(AND(ISNUMBER(C26),ISNUMBER(G26)), C26-G26, "") | I26: =IFERROR(H26/G26, "") | J26: 1. 2 microinverters are currently not reporting from 12/18/24 | K26: 1. SR094910
A27: Woodbridge - BA ATM | B27: VA | C27: 37 | D27: N/A | E27: =IF(AND(ISNUMBER(C27),ISNUMBER(D27)), C27-D27, "") | F27: =IFERROR(E27/D27, "") | G27: N/A | H27: =IF(AND(ISNUMBER(C27),ISNUMBER(G27)), C27-G27, "") | I27: =IFERROR(H27/G27, "")

Sheet Mar
A1: {=portfolio} -> CBRE | D1: March Actual v. Expected | G1: March Actual v. Forecasted
A2: Total | C2: =SUM(C4:C85) -> 29491.1 | D2: =SUM(D4:D85) -> 0 | E2: =C2-D2 -> 29491.1 | F2: =IFERROR(E2/D2, 0) -> 0 | G2: =SUM(G4:G85) -> 0 | H2: =C2-G2 -> 29491.1 | I2: =IFERROR(H2/G2, 0) -> 0 | J2: =IF(AND(TODAY()>DATE(2024, 3, 1), COUNTA(Sites[Site])<>(COUNT(C:C)-1)), "Some sites are missing actual data; if new sites were added, make sure they are aligned correctly (including prior months!)", "")
A3: Site | B3: State | C3: Actual | D3: Expected | E3: Delta | F3: % | G3: Forecasted | H3: Delta | I3: % | J3: Notes | K3: Service Requests
A4: {=Sites[Site]} -> East Hartford - BA | B4: {=Sites[State]} -> CT | C4: 2343.8 | D4: N/A | E4: =IF(AND(ISNUMBER(C4),ISNUMBER(D4)), C4-D4, "") | F4: =IFERROR(E4/D4, "") | G4: N/A | H4: =IF(AND(ISNUMBER(C4),ISNUMBER(G4)), C4-G4, "") | I4: =IFERROR(H4/G4, "")
A5: Indianapolis - BA Speedway | B5: IN | C5: 1279.8 | D5: N/A | E5: =IF(AND(ISNUMBER(C5),ISNUMBER(D5)), C5-D5, "") | F5: =IFERROR(E5/D5, "") | G5: N/A | H5: =IF(AND(ISNUMBER(C5),ISNUMBER(G5)), C5-G5, "") | I5: =IFERROR(H5/G5, "")
A6: Greenwood - BA | B6: IN | C6: 556.4 | D6: N/A | E6: =IF(AND(ISNUMBER(C6),ISNUMBER(D6)), C6-D6, "") | F6: =IFERROR(E6/D6, "") | G6: N/A | H6: =IF(AND(ISNUMBER(C6),ISNUMBER(G6)), C6-G6, "") | I6: =IFERROR(H6/G6, "")
A7: West Chester - BA | B7: OH | C7: 1242 | D7: N/A | E7: =IF(AND(ISNUMBER(C7),ISNUMBER(D7)), C7-D7, "") | F7: =IFERROR(E7/D7, "") | G7: N/A | H7: =IF(AND(ISNUMBER(C7),ISNUMBER(G7)), C7-G7, "") | I7: =IFERROR(H7/G7, "")
A8: Cincinnati - BA MLK and Burnet | B8: OH | C8: 1769.9 | D8: N/A | E8: =IF(AND(ISNUMBER(C8),ISNUMBER(D8)), C8-D8, "") | F8: =IFERROR(E8/D8, "") | G8: N/A | H8: =IF(AND(ISNUMBER(C8),ISNUMBER(G8)), C8-G8, "") | I8: =IFERROR(H8/G8, "")
A9: Columbus - BA Harrisburg Pike | B9: OH | C9: 1514.8 | D9: N/A | E9: =IF(AND(ISNUMBER(C9),ISNUMBER(D9)), C9-D9, "") | F9: =IFERROR(E9/D9, "") | G9: N/A | H9: =IF(AND(ISNUMBER(C9),ISNUMBER(G9)), C9-G9, "") | I9: =IFERROR(H9/G9, "")
A10: Cincinnati - BA Hyde Pk Plaza | B10: OH | C10: 1746.1 | D10: N/A | E10: =IF(AND(ISNUMBER(C10),ISNUMBER(D10)), C10-D10, "") | F10: =IFERROR(E10/D10, "") | G10: N/A | H10: =IF(AND(ISNUMBER(C10),ISNUMBER(G10)), C10-G10, "") | I10: =IFERROR(H10/G10, "")
A11: Cleveland - BA Carnegie & 79th | B11: OH | C11: 1325.7 | D11: N/A | E11: =IF(AND(ISNUMBER(C11),ISNUMBER(D11)), C11-D11, "") | F11: =IFERROR(E11/D11, "") | G11: N/A | H11: =IF(AND(ISNUMBER(C11),ISNUMBER(G11)), C11-G11, "") | I11: =IFERROR(H11/G11, "")
A12: Cincinnati - BA Sharonville | B12: OH | C12: 1360 | D12: N/A | E12: =IF(AND(ISNUMBER(C12),ISNUMBER(D12)), C12-D12, "") | F12: =IFERROR(E12/D12, "") | G12: N/A | H12: =IF(AND(ISNUMBER(C12),ISNUMBER(G12)), C12-G12, "") | I12: =IFERROR(H12/G12, "")
A13: Zionsville - BA | B13: IN | C13: 2302.3 | D13: N/A | E13: =IF(AND(ISNUMBER(C13),ISNUMBER(D13)), C13-D13, "") | F13: =IFERROR(E13/D13, "") | G13: N/A | H13: =IF(AND(ISNUMBER(C13),ISNUMBER(G13)), C13-G13, "") | I13: =IFERROR(H13/G13, "")
A14: Columbus - BA Eastgate | B14: OH | C14: 1255.7 | D14: N/A | E14: =IF(AND(ISNUMBER(C14),ISNUMBER(D14)), C14-D14, "") | F14: =IFERROR(E14/D14, "") | G14: N/A | H14: =IF(AND(ISNUMBER(C14),ISNUMBER(G14)), C14-G14, "") | I14: =IFERROR(H14/G14, "")
A15: Columbus - BA Eastmoor | B15: OH | C15: 2230.2 | D15: N/A | E15: =IF(AND(ISNUMBER(C15),ISNUMBER(D15)), C15-D15, "") | F15: =IFERROR(E15/D15, "") | G15: N/A | H15: =IF(AND(ISNUMBER(C15),ISNUMBER(G15)), C15-G15, "") | I15: =IFERROR(H15/G15, "") | J15: 1. One microinverter offline since 12/26 and was RMA'd on 12/30, remaining offline throughout the month. | K15: 1. SR095094, SR095335
A16: Brooklyn - BA Canarsie | B16: NY | C16: 0 | D16: N/A | E16: =IF(AND(ISNUMBER(C16),ISNUMBER(D16)), C16-D16, "") | F16: =IFERROR(E16/D16, "") | G16: N/A | H16: =IF(AND(ISNUMBER(C16),ISNUMBER(G16)), C16-G16, "") | I16: =IFERROR(H16/G16, "")
A17: Pittsburg - BA Fox Chapel | B17: PA | C17: 234.2 | D17: N/A | E17: =IF(AND(ISNUMBER(C17),ISNUMBER(D17)), C17-D17, "") | F17: =IFERROR(E17/D17, "") | G17: N/A | H17: =IF(AND(ISNUMBER(C17),ISNUMBER(G17)), C17-G17, "") | I17: =IFERROR(H17/G17, "") | J17: 1. Site was de-energized at 02:45 on 03/05 as per the customer’s request. The technician de-energized the system for 2 months as a test to rule out the solar system’s contribution to the iC3 communication issues being experienced on-site. The site remained offline throughout the month. | K17: 1. SR097860
A18: New York - BA Two Bryant Pk | B18: NY | C18: 0 | D18: N/A | E18: =IF(AND(ISNUMBER(C18),ISNUMBER(D18)), C18-D18, "") | F18: =IFERROR(E18/D18, "") | G18: N/A | H18: =IF(AND(ISNUMBER(C18),ISNUMBER(G18)), C18-G18, "") | I18: =IFERROR(H18/G18, "")
A19: Baltimore - BA Sudbrook Lane | B19: MD | C19: 1672.6 | D19: N/A | E19: =IF(AND(ISNUMBER(C19),ISNUMBER(D19)), C19-D19, "") | F19: =IFERROR(E19/D19, "") | G19: N/A | H19: =IF(AND(ISNUMBER(C19),ISNUMBER(G19)), C19-G19, "") | I19: =IFERROR(H19/G19, "")
A20: Stamford - BA West Stamford | B20: CT | C20: 1624.3 | D20: N/A | E20: =IF(AND(ISNUMBER(C20),ISNUMBER(D20)), C20-D20, "") | F20: =IFERROR(E20/D20, "") | G20: N/A | H20: =IF(AND(ISNUMBER(C20),ISNUMBER(G20)), C20-G20, "") | I20: =IFERROR(H20/G20, "")
A21: Hanover - BA Arundel Mills | B21: MD | C21: 2087.9 | D21: N/A | E21: =IF(AND(ISNUMBER(C21),ISNUMBER(D21)), C21-D21, "") | F21: =IFERROR(E21/D21, "") | G21: N/A | H21: =IF(AND(ISNUMBER(C21),ISNUMBER(G21)), C21-G21, "") | I21: =IFERROR(H21/G21, "")
A22: Glen Cove - BA Forest Ave | B22: NY | C22: 0 | D22: N/A | E22: =IF(AND(ISNUMBER(C22),ISNUMBER(D22)), C22-D22, "") | F22: =IFERROR(E22/D22, "") | G22: N/A | H22: =IF(AND(ISNUMBER(C22),ISNUMBER(G22)), C22-G22, "") | I22: =IFERROR(H22/G22, "")
A23: Brooklyn - BA North 4th & Berry | B23: NY | C23: 2201.5 | D23: N/A | E23: =IF(AND(ISNUMBER(C23),ISNUMBER(D23)), C23-D23, "") | F23: =IFERROR(E23/D23, "") | G23: N/A | H23: =IF(AND(ISNUMBER(C23),ISNUMBER(G23)), C23-G23, "") | I23: =IFERROR(H23/G23, "")
A24: Midlothian - BA Brandermill | B24: VA | C24: 1413.8 | D24: N/A | E24: =IF(AND(ISNUMBER(C24),ISNUMBER(D24)), C24-D24, "") | F24: =IFERROR(E24/D24, "") | G24: N/A | H24: =IF(AND(ISNUMBER(C24),ISNUMBER(G24)), C24-G24, "") | I24: =IFERROR(H24/G24, "") | J24: 1. One microinverter 202036040228 is not reporting from 4/15/23 and being RMA'd on 02/18/25. | K24: 1. SR088366
A25: Lexington - BA North Park | B25: KY | C25: 1192.3 | D25: N/A | E25: =IF(AND(ISNUMBER(C25),ISNUMBER(D25)), C25-D25, "") | F25: =IFERROR(E25/D25, "") | G25: N/A | H25: =IF(AND(ISNUMBER(C25),ISNUMBER(G25)), C25-G25, "") | I25: =IFERROR(H25/G25, "")
A26: Coventry - BA ATM | B26: RI | C26: 95.6 | D26: N/A | E26: =IF(AND(ISNUMBER(C26),ISNUMBER(D26)), C26-D26, "") | G26: N/A | H26: =IF(AND(ISNUMBER(C26),ISNUMBER(G26)), C26-G26, "") | J26: 1. 2 microinverters are currently not reporting from 12/18/24 | K26: 1. SR094910
A27: Woodbridge - BA ATM | B27: VA | C27: 42.2 | D27: N/A | E27: =IF(AND(ISNUMBER(C27),ISNUMBER(D27)), C27-D27, "") | G27: N/A | H27: =IF(AND(ISNUMBER(C27),ISNUMBER(G27)), C27-G27, "")

Sheet Apr
A1: {=portfolio} -> CBRE | D1: April Actual v. Expected | G1: April Actual v. Forecasted
A2: Total | C2: =SUM(C4:C85) -> 32389 | D2: =SUM(D4:D85) -> 0 | E2: =C2-D2 -> 32389 | F2: =IFERROR(E2/D2, 0) -> 0 | G2: =SUM(G4:G85) -> 0 | H2: =C2-G2 -> 32389 | I2: =IFERROR(H2/G2, 0) -> 0 | J2: =IF(AND(TODAY()>DATE(2024, 4, 1), COUNTA(Sites[Site])<>(COUNT(C:C)-1)), "Some sites are missing actual data; if new sites were added, make sure they are aligned correctly (including prior months!)", "") -> Some sites are missing actual data; if new sites were added, make sure they are aligned correctly (including prior months!)
A3: Site | B3: State | C3: Actual | D3: Expected | E3: Delta | F3: % | G3: Forecasted | H3: Delta | I3: % | J3: Notes | K3: Service Requests
A4: {=Sites[Site]} -> East Hartford - BA | B4: {=Sites[State]} -> CT | C4: 2711.3 | D4: N/A | E4: =IF(AND(ISNUMBER(C4),ISNUMBER(D4)), C4-D4, "") | F4: =IFERROR(E4/D4, "") | G4: N/A | H4: =IF(AND(ISNUMBER(C4),ISNUMBER(G4)), C4-G4, "") | I4: =IFERROR(H4/G4, "")
A5: Indianapolis - BA Speedway | B5: IN | C5: 1434.1 | D5: N/A | E5: =IF(AND(ISNUMBER(C5),ISNUMBER(D5)), C5-D5, "") | F5: =IFERROR(E5/D5, "") | G5: N/A | H5: =IF(AND(ISNUMBER(C5),ISNUMBER(G5)), C5-G5, "") | I5: =IFERROR(H5/G5, "") | J5: 1.Site remained offline from 15:00 to 17:00 on 04/10 | K5: 1.PM9694
A6: Greenwood - BA | B6: IN | C6: 649.3 | D6: N/A | E6: =IF(AND(ISNUMBER(C6),ISNUMBER(D6)), C6-D6, "") | F6: =IFERROR(E6/D6, "") | G6: N/A | H6: =IF(AND(ISNUMBER(C6),ISNUMBER(G6)), C6-G6, "") | I6: =IFERROR(H6/G6, "")
A7: West Chester - BA | B7: OH | C7: 1386.3 | D7: N/A | E7: =IF(AND(ISNUMBER(C7),ISNUMBER(D7)), C7-D7, "") | F7: =IFERROR(E7/D7, "") | G7: N/A | H7: =IF(AND(ISNUMBER(C7),ISNUMBER(G7)), C7-G7, "") | I7: =IFERROR(H7/G7, "")
A8: Cincinnati - BA MLK and Burnet | B8: OH | C8: 1955.9 | D8: N/A | E8: =IF(AND(ISNUMBER(C8),ISNUMBER(D8)), C8-D8, "") | F8: =IFERROR(E8/D8, "") | G8: N/A | H8: =IF(AND(ISNUMBER(C8),ISNUMBER(G8)), C8-G8, "") | I8: =IFERROR(H8/G8, "")
A9: Columbus - BA Harrisburg Pike | B9: OH | C9: 1738.3 | D9: N/A | E9: =IF(AND(ISNUMBER(C9),ISNUMBER(D9)), C9-D9, "") | F9: =IFERROR(E9/D9, "") | G9: N/A | H9: =IF(AND(ISNUMBER(C9),ISNUMBER(G9)), C9-G9, "") | I9: =IFERROR(H9/G9, "")
A10: Cincinnati - BA Hyde Pk Plaza | B10: OH | C10: 1967.8 | D10: N/A | E10: =IF(AND(ISNUMBER(C10),ISNUMBER(D10)), C10-D10, "") | F10: =IFERROR(E10/D10, "") | G10: N/A | H10: =IF(AND(ISNUMBER(C10),ISNUMBER(G10)), C10-G10, "") | I10: =IFERROR(H10/G10, "") | J10: 1.One microinverter (SN: 202315108645) remained offline throughout the month, and an RMA for the unit was requested | K10: 1.SR097110
A11: Cleveland - BA Carnegie & 79th | B11: OH | C11: 1467.8 | D11: N/A | E11: =IF(AND(ISNUMBER(C11),ISNUMBER(D11)), C11-D11, "") | F11: =IFERROR(E11/D11, "") | G11: N/A | H11: =IF(AND(ISNUMBER(C11),ISNUMBER(G11)), C11-G11, "") | I11: =IFERROR(H11/G11, "")
A12: Cincinnati - BA Sharonville | B12: OH | C12: 1505.6 | D12: N/A | E12: =IF(AND(ISNUMBER(C12),ISNUMBER(D12)), C12-D12, "") | F12: =IFERROR(E12/D12, "") | G12: N/A | H12: =IF(AND(ISNUMBER(C12),ISNUMBER(G12)), C12-G12, "") | I12: =IFERROR(H12/G12, "")
A13: Zionsville - BA | B13: IN | C13: 2677.6 | D13: N/A | E13: =IF(AND(ISNUMBER(C13),ISNUMBER(D13)), C13-D13, "") | F13: =IFERROR(E13/D13, "") | G13: N/A | H13: =IF(AND(ISNUMBER(C13),ISNUMBER(G13)), C13-G13, "") | I13: =IFERROR(H13/G13, "")
A14: Columbus - BA Eastgate | B14: OH | C14: 1418.2 | D14: N/A | E14: =IF(AND(ISNUMBER(C14),ISNUMBER(D14)), C14-D14, "") | F14: =IFERROR(E14/D14, "") | G14: N/A | H14: =IF(AND(ISNUMBER(C14),ISNUMBER(G14)), C14-G14, "") | I14: =IFERROR(H14/G14, "")
A15: Columbus - BA Eastmoor | B15: OH | C15: 2500.7 | D15: N/A | E15: =IF(AND(ISNUMBER(C15),ISNUMBER(D15)), C15-D15, "") | F15: =IFERROR(E15/D15, "") | G15: N/A | H15: =IF(AND(ISNUMBER(C15),ISNUMBER(G15)), C15-G15, "") | I15: =IFERROR(H15/G15, "") | J15: 1.One microinverter (device # 202305095896) remained offline throughout the month and the inverter is being RMA'D | K15: 1.SR095094,SR095335 | L15: SR095335
A16: Brooklyn - BA Canarsie | B16: NY | D16: N/A | G16: N/A | I16: =IFERROR(H16/G16, "")
A17: Pittsburg - BA Fox Chapel | B17: PA | C17: 0 | D17: N/A | E17: =IF(AND(ISNUMBER(C17),ISNUMBER(D17)), C17-D17, "") | F17: =IFERROR(E17/D17, "") | G17: N/A | H17: =IF(AND(ISNUMBER(C17),ISNUMBER(G17)), C17-G17, "") | I17: =IFERROR(H17/G17, "") | J17: 1.Site remained offline throughout the month.Dispatch to be scheduled in the next month. | K17: 1.SR101229
A18: New York - BA Two Bryant Pk | B18: NY | C18: 0 | D18: N/A | E18: =IF(AND(ISNUMBER(C18),ISNUMBER(D18)), C18-D18, "") | F18: =IFERROR(E18/D18, "") | G18: N/A | H18: =IF(AND(ISNUMBER(C18),ISNUMBER(G18)), C18-G18, "") | I18: =IFERROR(H18/G18, "")
A19: Baltimore - BA Sudbrook Lane | B19: MD | C19: 1690 | D19: N/A | E19: =IF(AND(ISNUMBER(C19),ISNUMBER(D19)), C19-D19, "") | F19: =IFERROR(E19/D19, "") | G19: N/A | H19: =IF(AND(ISNUMBER(C19),ISNUMBER(G19)), C19-G19, "") | I19: =IFERROR(H19/G19, "") | J19: 1.All the microinverters tripped offline at 15:15 on 04/11.Once they are back online at 06:30 on 04/13,but constantly produced at 6.04kW up to 15:30 and later on production was normalized. | K19: 1.SR099702
A20: Stamford - BA West Stamford | B20: CT | C20: 1721.4 | D20: N/A | E20: =IF(AND(ISNUMBER(C20),ISNUMBER(D20)), C20-D20, "") | F20: =IFERROR(E20/D20, "") | G20: N/A | H20: =IF(AND(ISNUMBER(C20),ISNUMBER(G20)), C20-G20, "") | I20: =IFERROR(H20/G20, "")
A21: Hanover - BA Arundel Mills | B21: MD | C21: 2198.9 | D21: N/A | E21: =IF(AND(ISNUMBER(C21),ISNUMBER(D21)), C21-D21, "") | F21: =IFERROR(E21/D21, "") | G21: N/A | H21: =IF(AND(ISNUMBER(C21),ISNUMBER(G21)), C21-G21, "") | I21: =IFERROR(H21/G21, "")
A22: Glen Cove - BA Forest Ave | B22: NY | D22: N/A | E22: =IF(AND(ISNUMBER(C22),ISNUMBER(D22)), C22-D22, "") | F22: =IFERROR(E22/D22, "") | G22: N/A | H22: =IF(AND(ISNUMBER(C22),ISNUMBER(G22)), C22-G22, "") | I22: =IFERROR(H22/G22, "")
