Workbook
Name JanActual: #REF!
Name JanActual2: #REF!
Name JanExpected: #REF!
Name JanExpectedDelta: #REF!
Name JanExpectedPercent: #REF!
Name JanExpPercent: #REF!
Name JanForecasted: #REF!
Name JanForecastedDelta: #REF!
Name JanForecastedPercent: #REF!
Name portfolio: Sites!$B$1:$B$1
Name Year: Sites!#REF!

Sheet Year to Date
A1: {=portfolio} -> GoodFinch | D1: Year to Date Actual v. Expected | G1: Year to Date Actual v. Forecasted
A2: Total | C2: =SUM(C4:C80) -> 1539597.8 | D2: =SUM(D4:D80) -> 1456547.2 | E2: =C2-D2 -> 83050.532 | F2: =IFERROR(E2/D2, 0) -> 0.05701877 | G2: =SUM(G4:G80) -> 2267383.5 | H2: =C2-G2 -> -727785.72 | I2: =IFERROR(H2/G2, 0) -> -0.32098043
A3: Site | B3: State | C3: Actual | D3: Expected | E3: Delta | F3: % | G3: Forecasted | H3: Delta | I3: %
A4: {=Sites[Site]} -> AZ: Tempe - ASU - Farmer | B4: {=Sites[State]} -> AZ | C4: =SUM('1st Qtr'!C4, '2nd Qtr'!C4, '3rd Qtr'!C4, '4th Qtr'!C4) -> 13735.336 | D4: =SUM('1st Qtr'!D4, '2nd Qtr'!D4, '3rd Qtr'!D4, '4th Qtr'!D4) -> 8816.846 | E4: =IF(AND(ISNUMBER(C4),ISNUMBER(D4)), C4-D4, "") -> 4918.4897 | F4: =IFERROR(E4/D4, "") -> 0.55785138 | G4: =SUM('1st Qtr'!G4, '2nd Qtr'!G4, '3rd Qtr'!G4, '4th Qtr'!G4) -> 13564.61 | H4: =SUM('1st Qtr'!H4, '2nd Qtr'!H4, '3rd Qtr'!H4, '4th Qtr'!H4) -> 170.72569 | I4: =IFERROR(H4/G4, "") -> 0.012586112
A5: AZ: Tempe - ASU - Fulton | B5: AZ | C5: =SUM('1st Qtr'!C5, '2nd Qtr'!C5, '3rd Qtr'!C5, '4th Qtr'!C5) -> 51105 | D5: =SUM('1st Qtr'!D5, '2nd Qtr'!D5, '3rd Qtr'!D5, '4th Qtr'!D5) -> 60589.7 | E5: =IF(AND(ISNUMBER(C5),ISNUMBER(D5)), C5-D5, "") -> -9484.7 | F5: =IFERROR(E5/D5, "") -> -0.15653981 | G5: =SUM('1st Qtr'!G5, '2nd Qtr'!G5, '3rd Qtr'!G5, '4th Qtr'!G5) -> 68756 | H5: =SUM(Jan!I5, Feb!H5, Mar!H5) -> 0 | I5: =IFERROR(H5/G5, "") -> 0
A6: AZ: Superior - JFK Elementary | B6: AZ | C6: =SUM('1st Qtr'!C6, '2nd Qtr'!C6, '3rd Qtr'!C6, '4th Qtr'!C6) -> 12132.18 | D6: =SUM('1st Qtr'!D6, '2nd Qtr'!D6, '3rd Qtr'!D6, '4th Qtr'!D6) -> 0 | E6: =IF(AND(ISNUMBER(C6),ISNUMBER(D6)), C6-D6, "") -> 12132.18 | F6: =IFERROR(E6/D6, "") | G6: =SUM('1st Qtr'!G6, '2nd Qtr'!G6, '3rd Qtr'!G6, '4th Qtr'!G6) -> 18696 | H6: =SUM('1st Qtr'!H6, '2nd Qtr'!H6, '3rd Qtr'!H6, '4th Qtr'!H6) -> -6563.8203 | I6: =IFERROR(H6/G6, "") -> -0.35108153
A7: AZ: Tempe - ASU - Noble | B7: AZ | C7: =SUM('1st Qtr'!C7, '2nd Qtr'!C7, '3rd Qtr'!C7, '4th Qtr'!C7) -> 12583.462 | D7: =SUM('1st Qtr'!D7, '2nd Qtr'!D7, '3rd Qtr'!D7, '4th Qtr'!D7) -> 15025.43 | E7: =IF(AND(ISNUMBER(C7),ISNUMBER(D7)), C7-D7, "") -> -2441.9685 | F7: =IFERROR(E7/D7, "") -> -0.16252237 | G7: =SUM('1st Qtr'!G7, '2nd Qtr'!G7, '3rd Qtr'!G7, '4th Qtr'!G7) -> 15254.26 | H7: =SUM(Jan!I7, Feb!H7, Mar!H7) -> 0 | I7: =IFERROR(H7/G7, "") -> 0
A8: AZ: Tempe - ASU - Parking #3 | B8: AZ | C8: =SUM('1st Qtr'!C8, '2nd Qtr'!C8, '3rd Qtr'!C8, '4th Qtr'!C8) -> 34337.612 | D8: =SUM('1st Qtr'!D8, '2nd Qtr'!D8, '3rd Qtr'!D8, '4th Qtr'!D8) -> 35477.84 | E8: =IF(AND(ISNUMBER(C8),ISNUMBER(D8)), C8-D8, "") -> -1140.2275 | F8: =IFERROR(E8/D8, "") -> -0.032139147 | G8: =SUM('1st Qtr'!G8, '2nd Qtr'!G8, '3rd Qtr'!G8, '4th Qtr'!G8) -> 31619.08 | H8: =SUM('1st Qtr'!H8, '2nd Qtr'!H8, '3rd Qtr'!H8, '4th Qtr'!H8) -> 2718.5325 | I8: =IFERROR(H8/G8, "") -> 0.085977596
A9: AZ: Tempe - ASU - PE East | B9: AZ | C9: =SUM('1st Qtr'!C9, '2nd Qtr'!C9, '3rd Qtr'!C9, '4th Qtr'!C9) -> 30211.908 | D9: =SUM('1st Qtr'!D9, '2nd Qtr'!D9, '3rd Qtr'!D9, '4th Qtr'!D9) -> 25952.9 | E9: =IF(AND(ISNUMBER(C9),ISNUMBER(D9)), C9-D9, "") -> 4259.0078 | F9: =IFERROR(E9/D9, "") -> 0.16410528 | G9: =SUM('1st Qtr'!G9, '2nd Qtr'!G9, '3rd Qtr'!G9, '4th Qtr'!G9) -> 31934.71 | H9: =SUM(Jan!I9, Feb!H9, Mar!H9) -> 0 | I9: =IFERROR(H9/G9, "") -> 0
A10: AZ: Tempe - ASU - Schwada | B10: AZ | C10: =SUM('1st Qtr'!C10, '2nd Qtr'!C10, '3rd Qtr'!C10, '4th Qtr'!C10) -> 9176.8897 | D10: =SUM('1st Qtr'!D10, '2nd Qtr'!D10, '3rd Qtr'!D10, '4th Qtr'!D10) -> 10685.01 | E10: =IF(AND(ISNUMBER(C10),ISNUMBER(D10)), C10-D10, "") -> -1508.1203 | F10: =IFERROR(E10/D10, "") -> -0.14114356 | G10: =SUM('1st Qtr'!G10, '2nd Qtr'!G10, '3rd Qtr'!G10, '4th Qtr'!G10) -> 13894 | H10: =SUM('1st Qtr'!H10, '2nd Qtr'!H10, '3rd Qtr'!H10, '4th Qtr'!H10) -> -4717.1103 | I10: =IFERROR(H10/G10, "") -> -0.33950701
A11: AZ: Phoenix - Starshine Academy | B11: AZ | C11: =SUM('1st Qtr'!C11, '2nd Qtr'!C11, '3rd Qtr'!C11, '4th Qtr'!C11) -> 6047.8 | D11: =SUM('1st Qtr'!D11, '2nd Qtr'!D11, '3rd Qtr'!D11, '4th Qtr'!D11) -> 0 | E11: =IF(AND(ISNUMBER(C11),ISNUMBER(D11)), C11-D11, "") -> 6047.8 | F11: =IFERROR(E11/D11, "") | G11: =SUM('1st Qtr'!G11, '2nd Qtr'!G11, '3rd Qtr'!G11, '4th Qtr'!G11) -> 11002 | H11: =SUM(Jan!I11, Feb!H11, Mar!H11) -> 0 | I11: =IFERROR(H11/G11, "") -> 0
A12: AZ: Yuma Airport | B12: AZ | C12: =SUM('1st Qtr'!C12, '2nd Qtr'!C12, '3rd Qtr'!C12, '4th Qtr'!C12) -> 66601 | D12: =SUM('1st Qtr'!D12, '2nd Qtr'!D12, '3rd Qtr'!D12, '4th Qtr'!D12) -> 94129.73 | E12: =IF(AND(ISNUMBER(C12),ISNUMBER(D12)), C12-D12, "") -> -27528.73 | F12: =IFERROR(E12/D12, "") -> -0.29245521 | G12: =SUM('1st Qtr'!G12, '2nd Qtr'!G12, '3rd Qtr'!G12, '4th Qtr'!G12) -> 82137 | H12: =SUM('1st Qtr'!H12, '2nd Qtr'!H12, '3rd Qtr'!H12, '4th Qtr'!H12) -> -15536 | I12: =IFERROR(H12/G12, "") -> -0.1891474
A13: AZ: Globe - Gila CC | B13: AZ | C13: =SUM('1st Qtr'!C13, '2nd Qtr'!C13, '3rd Qtr'!C13, '4th Qtr'!C13) -> 20373.375 | D13: =SUM('1st Qtr'!D13, '2nd Qtr'!D13, '3rd Qtr'!D13, '4th Qtr'!D13) -> 0 | E13: =IF(AND(ISNUMBER(C13),ISNUMBER(D13)), C13-D13, "") -> 20373.375 | F13: =IFERROR(E13/D13, "") | G13: =SUM('1st Qtr'!G13, '2nd Qtr'!G13, '3rd Qtr'!G13, '4th Qtr'!G13) -> 18652 | H13: =SUM(Jan!I13, Feb!H13, Mar!H13) -> 0 | I13: =IFERROR(H13/G13, "") -> 0
A14: AZ: Payson - Gila CC | B14: AZ | C14: =SUM('1st Qtr'!C14, '2nd Qtr'!C14, '3rd Qtr'!C14, '4th Qtr'!C14) -> 15205.885 | D14: =SUM('1st Qtr'!D14, '2nd Qtr'!D14, '3rd Qtr'!D14, '4th Qtr'!D14) -> 6558.912 | E14: =IF(AND(ISNUMBER(C14),ISNUMBER(D14)), C14-D14, "") -> 8646.9725 | F14: =IFERROR(E14/D14, "") -> 1.3183547 | G14: =SUM('1st Qtr'!G14, '2nd Qtr'!G14, '3rd Qtr'!G14, '4th Qtr'!G14) -> 15449 | H14: =SUM('1st Qtr'!H14, '2nd Qtr'!H14, '3rd Qtr'!H14, '4th Qtr'!H14) -> -243.11545 | I14: =IFERROR(H14/G14, "") -> -0.015736647
A15: AZ: Mesa - Sequoia Charter School | B15: AZ | C15: =SUM('1st Qtr'!C15, '2nd Qtr'!C15, '3rd Qtr'!C15, '4th Qtr'!C15) -> 32820.18 | D15: =SUM('1st Qtr'!D15, '2nd Qtr'!D15, '3rd Qtr'!D15, '4th Qtr'!D15) -> 0 | E15: =IF(AND(ISNUMBER(C15),ISNUMBER(D15)), C15-D15, "") -> 32820.18 | F15: =IFERROR(E15/D15, "") | G15: =SUM('1st Qtr'!G15, '2nd Qtr'!G15, '3rd Qtr'!G15, '4th Qtr'!G15) -> 52037 | H15: =SUM(Jan!I15, Feb!H15, Mar!H15) -> 0 | I15: =IFERROR(H15/G15, "") -> 0
A16: AZ: Tempe - SCNM | B16: AZ | C16: =SUM('1st Qtr'!C16, '2nd Qtr'!C16, '3rd Qtr'!C16, '4th Qtr'!C16) -> 67507.749 | D16: =SUM('1st Qtr'!D16, '2nd Qtr'!D16, '3rd Qtr'!D16, '4th Qtr'!D16) -> 49080.48 | E16: =IF(AND(ISNUMBER(C16),ISNUMBER(D16)), C16-D16, "") -> 18427.269 | F16: =IFERROR(E16/D16, "") -> 0.37545007 | G16: =SUM('1st Qtr'!G16, '2nd Qtr'!G16, '3rd Qtr'!G16, '4th Qtr'!G16) -> 91007 | H16: =SUM('1st Qtr'!H16, '2nd Qtr'!H16, '3rd Qtr'!H16, '4th Qtr'!H16) -> -23499.251 | I16: =IFERROR(H16/G16, "") -> -0.25821366
A17: DE: Newark - Clayton Hall | B17: DE | C17: =SUM('1st Qtr'!C17, '2nd Qtr'!C17, '3rd Qtr'!C17, '4th Qtr'!C17) -> 21726 | D17: =SUM('1st Qtr'!D17, '2nd Qtr'!D17, '3rd Qtr'!D17, '4th Qtr'!D17) -> 23826.591 | E17: =IF(AND(ISNUMBER(C17),ISNUMBER(D17)), C17-D17, "") -> -2100.591 | F17: =IFERROR(E17/D17, "") -> -0.088161626 | G17: =SUM('1st Qtr'!G17, '2nd Qtr'!G17, '3rd Qtr'!G17, '4th Qtr'!G17) -> 20228.258 | H17: =SUM(Jan!I17, Feb!H17, Mar!H17) -> 0 | I17: =IFERROR(H17/G17, "") -> 0
A18: DE: Newark - UOD Field House | B18: DE | C18: =SUM('1st Qtr'!C18, '2nd Qtr'!C18, '3rd Qtr'!C18, '4th Qtr'!C18) -> 55764 | D18: =SUM('1st Qtr'!D18, '2nd Qtr'!D18, '3rd Qtr'!D18, '4th Qtr'!D18) -> 0 | E18: =IF(AND(ISNUMBER(C18),ISNUMBER(D18)), C18-D18, "") -> 55764 | F18: =IFERROR(E18/D18, "") | G18: =SUM('1st Qtr'!G18, '2nd Qtr'!G18, '3rd Qtr'!G18, '4th Qtr'!G18) -> 49697 | H18: =SUM('1st Qtr'!H18, '2nd Qtr'!H18, '3rd Qtr'!H18, '4th Qtr'!H18) -> 6067 | I18: =IFERROR(H18/G18, "") -> 0.1220798
A19: DE: Newark - UOD 461 Wyoming | B19: DE | C19: =SUM('1st Qtr'!C19, '2nd Qtr'!C19, '3rd Qtr'!C19, '4th Qtr'!C19) -> 0 | D19: =SUM('1st Qtr'!D19, '2nd Qtr'!D19, '3rd Qtr'!D19, '4th Qtr'!D19) -> 36216.917 | E19: =IF(AND(ISNUMBER(C19),ISNUMBER(D19)), C19-D19, "") -> -36216.917 | F19: =IFERROR(E19/D19, "") -> -1 | G19: =SUM('1st Qtr'!G19, '2nd Qtr'!G19, '3rd Qtr'!G19, '4th Qtr'!G19) -> 37582.678 | H19: =SUM(Jan!I19, Feb!H19, Mar!H19) -> 0 | I19: =IFERROR(H19/G19, "") -> 0
A20: HI: Waipahu - 94-246 Leoku St - E.F.G. | B20: HI | C20: =SUM('1st Qtr'!C20, '2nd Qtr'!C20, '3rd Qtr'!C20, '4th Qtr'!C20) -> 10048 | D20: =SUM('1st Qtr'!D20, '2nd Qtr'!D20, '3rd Qtr'!D20, '4th Qtr'!D20) -> 13191.17 | E20: =IF(AND(ISNUMBER(C20),ISNUMBER(D20)), C20-D20, "") -> -3143.17 | F20: =IFERROR(E20/D20, "") -> -0.23827833 | G20: =SUM('1st Qtr'!G20, '2nd Qtr'!G20, '3rd Qtr'!G20, '4th Qtr'!G20) -> 13676.54 | H20: =SUM('1st Qtr'!H20, '2nd Qtr'!H20, '3rd Qtr'!H20, '4th Qtr'!H20) -> -3628.54 | I20: =IFERROR(H20/G20, "") -> -0.26531126
A21: HI: Waipahu - 94-099 Waipahu St - PV | B21: HI | C21: =SUM('1st Qtr'!C21, '2nd Qtr'!C21, '3rd Qtr'!C21, '4th Qtr'!C21) -> 14836 | D21: =SUM('1st Qtr'!D21, '2nd Qtr'!D21, '3rd Qtr'!D21, '4th Qtr'!D21) -> 11475.55 | E21: =IF(AND(ISNUMBER(C21),ISNUMBER(D21)), C21-D21, "") -> 3360.45 | F21: =IFERROR(E21/D21, "") -> 0.29283564 | G21: =SUM('1st Qtr'!G21, '2nd Qtr'!G21, '3rd Qtr'!G21, '4th Qtr'!G21) -> 13669.23 | H21: =SUM(Jan!I21, Feb!H21, Mar!H21) -> 0 | I21: =IFERROR(H21/G21, "") -> 0
A22: MD: Presston - Bird-in-Hand | B22: MD | C22: =SUM('1st Qtr'!C22, '2nd Qtr'!C22, '3rd Qtr'!C22, '4th Qtr'!C22) -> 145779 | D22: =SUM('1st Qtr'!D22, '2nd Qtr'!D22, '3rd Qtr'!D22, '4th Qtr'!D22) -> 144638.7 | E22: =IF(AND(ISNUMBER(C22),ISNUMBER(D22)), C22-D22, "") -> 1140.3 | F22: =IFERROR(E22/D22, "") -> 0.0078837821 | G22: =SUM('1st Qtr'!G22, '2nd Qtr'!G22, '3rd Qtr'!G22, '4th Qtr'!G22) -> 179658.6 | H22: =SUM('1st Qtr'!H22, '2nd Qtr'!H22, '3rd Qtr'!H22, '4th Qtr'!H22) -> -33879.6 | I22: =IFERROR(H22/G22, "") -> -0.18857767
A23: MD: Easton - Shortall | B23: MD | C23: =SUM('1st Qtr'!C23, '2nd Qtr'!C23, '3rd Qtr'!C23, '4th Qtr'!C23) -> 188462 | D23: =SUM('1st Qtr'!D23, '2nd Qtr'!D23, '3rd Qtr'!D23, '4th Qtr'!D23) -> 193996.5 | E23: =IF(AND(ISNUMBER(C23),ISNUMBER(D23)), C23-D23, "") -> -5534.5 | F23: =IFERROR(E23/D23, "") -> -0.028528865 | G23: =SUM('1st Qtr'!G23, '2nd Qtr'!G23, '3rd Qtr'!G23, '4th Qtr'!G23) -> 158875.9 | H23: =SUM(Jan!I23, Feb!H23, Mar!H23) -> 0 | I23: =IFERROR(H23/G23, "") -> 0
A24: MA: Boston - Seaport Solar | B24: MA | C24: =SUM('1st Qtr'!C24, '2nd Qtr'!C24, '3rd Qtr'!C24, '4th Qtr'!C24) -> 85397.5 | D24: =SUM('1st Qtr'!D24, '2nd Qtr'!D24, '3rd Qtr'!D24, '4th Qtr'!D24) -> 14365.66 | E24: =IF(AND(ISNUMBER(C24),ISNUMBER(D24)), C24-D24, "") -> 71031.84 | F24: =IFERROR(E24/D24, "") -> 4.9445581 | G24: =SUM('1st Qtr'!G24, '2nd Qtr'!G24, '3rd Qtr'!G24, '4th Qtr'!G24) -> 86009.04 | H24: =SUM('1st Qtr'!H24, '2nd Qtr'!H24, '3rd Qtr'!H24, '4th Qtr'!H24) -> -611.54 | I24: =IFERROR(H24/G24, "") -> -0.0071101828
A25: MA: Dedham - Sprague Street | B25: MA | C25: =SUM('1st Qtr'!C25, '2nd Qtr'!C25, '3rd Qtr'!C25, '4th Qtr'!C25) -> 185825 | D25: =SUM('1st Qtr'!D25, '2nd Qtr'!D25, '3rd Qtr'!D25, '4th Qtr'!D25) -> 0 | E25: =IF(AND(ISNUMBER(C25),ISNUMBER(D25)), C25-D25, "") -> 185825 | F25: =IFERROR(E25/D25, "") | G25: =SUM('1st Qtr'!G25, '2nd Qtr'!G25, '3rd Qtr'!G25, '4th Qtr'!G25) -> 193250.7 | H25: =SUM(Jan!I25, Feb!H25, Mar!H25) -> 0 | I25: =IFERROR(H25/G25, "") -> 0
A26: MA: Boston - Summer Street | B26: MA | C26: =SUM('1st Qtr'!C26, '2nd Qtr'!C26, '3rd Qtr'!C26, '4th Qtr'!C26) -> 0 | D26: =SUM('1st Qtr'!D26, '2nd Qtr'!D26, '3rd Qtr'!D26, '4th Qtr'!D26) -> 64247.81 | E26: =IF(AND(ISNUMBER(C26),ISNUMBER(D26)), C26-D26, "") -> -64247.81 | F26: =IFERROR(E26/D26, "") -> -1 | G26: =SUM('1st Qtr'!G26, '2nd Qtr'!G26, '3rd Qtr'!G26, '4th Qtr'!G26) -> 409224.3 | H26: =SUM('1st Qtr'!H26, '2nd Qtr'!H26, '3rd Qtr'!H26, '4th Qtr'!H26) -> -409224.3 | I26: =IFERROR(H26/G26, "") -> -1
A27: MA: Leominster - Spectro Coatings | B27: MA | C27: =SUM('1st Qtr'!C27, '2nd Qtr'!C27, '3rd Qtr'!C27, '4th Qtr'!C27) -> 38126.625 | D27: =SUM('1st Qtr'!D27, '2nd Qtr'!D27, '3rd Qtr'!D27, '4th Qtr'!D27) -> 39199.727 | E27: =IF(AND(ISNUMBER(C27),ISNUMBER(D27)), C27-D27, "") -> -1073.102 | F27: =IFERROR(E27/D27, "") -> -0.027375242 | G27: =SUM('1st Qtr'!G27, '2nd Qtr'!G27, '3rd Qtr'!G27, '4th Qtr'!G27) -> 38210.937 | H27: =SUM(Jan!I27, Feb!H27, Mar!H27) -> 0 | I27: =IFERROR(H27/G27, "") -> 0
A28: MA: Braintree - RCAB | B28: MA | C28: =SUM('1st Qtr'!C28, '2nd Qtr'!C28, '3rd Qtr'!C28, '4th Qtr'!C28) -> 147058 | D28: =SUM('1st Qtr'!D28, '2nd Qtr'!D28, '3rd Qtr'!D28, '4th Qtr'!D28) -> 182019.3 | E28: =IF(AND(ISNUMBER(C28),ISNUMBER(D28)), C28-D28, "") -> -34961.3 | F28: =IFERROR(E28/D28, "") -> -0.19207469 | G28: =SUM('1st Qtr'!G28, '2nd Qtr'!G28, '3rd Qtr'!G28, '4th Qtr'!G28) -> 146482.8 | H28: =SUM('1st Qtr'!H28, '2nd Qtr'!H28, '3rd Qtr'!H28, '4th Qtr'!H28) -> 575.2 | I28: =IFERROR(H28/G28, "") -> 0.0039267409
A29: NH: Rochester - Portland Street | B29: NH | C29: =SUM('1st Qtr'!C29, '2nd Qtr'!C29, '3rd Qtr'!C29, '4th Qtr'!C29) -> 11535.627 | D29: =SUM('1st Qtr'!D29, '2nd Qtr'!D29, '3rd Qtr'!D29, '4th Qtr'!D29) -> 8215.936 | E29: =IF(AND(ISNUMBER(C29),ISNUMBER(D29)), C29-D29, "") -> 3319.691 | F29: =IFERROR(E29/D29, "") -> 0.40405512 | G29: =SUM('1st Qtr'!G29, '2nd Qtr'!G29, '3rd Qtr'!G29, '4th Qtr'!G29) -> 9368.774 | H29: =SUM(Jan!I29, Feb!H29, Mar!H29) -> 0 | I29: =IFERROR(H29/G29, "") -> 0
A30: NH: Portsmouth - Portsmouth HS | B30: NH | C30: =SUM('1st Qtr'!C30, '2nd Qtr'!C30, '3rd Qtr'!C30, '4th Qtr'!C30) -> 44411.625 | D30: =SUM('1st Qtr'!D30, '2nd Qtr'!D30, '3rd Qtr'!D30, '4th Qtr'!D30) -> 0 | E30: =IF(AND(ISNUMBER(C30),ISNUMBER(D30)), C30-D30, "") -> 44411.625 | F30: =IFERROR(E30/D30, "") | G30: =SUM('1st Qtr'!G30, '2nd Qtr'!G30, '3rd Qtr'!G30, '4th Qtr'!G30) -> 35518.29 | H30: =SUM('1st Qtr'!H30, '2nd Qtr'!H30, '3rd Qtr'!H30, '4th Qtr'!H30) -> 8893.335 | I30: =IFERROR(H30/G30, "") -> 0.25038748
A31: NH: Portsmouth - Portsmouth WTP | B31: NH | C31: =SUM('1st Qtr'!C31, '2nd Qtr'!C31, '3rd Qtr'!C31, '4th Qtr'!C31) -> 0 | D31: =SUM('1st Qtr'!D31, '2nd Qtr'!D31, '3rd Qtr'!D31, '4th Qtr'!D31) -> 0 | E31: =IF(AND(ISNUMBER(C31),ISNUMBER(D31)), C31-D31, "") -> 0 | F31: =IFERROR(E31/D31, "") | G31: =SUM('1st Qtr'!G31, '2nd Qtr'!G31, '3rd Qtr'!G31, '4th Qtr'!G31) -> 0 | H31: =SUM(Jan!I31, Feb!H31, Mar!H31) -> 0 | I31: =IFERROR(H31/G31, "")
A32: NH: Rochester - Rochester MS | B32: NH | C32: =SUM('1st Qtr'!C32, '2nd Qtr'!C32, '3rd Qtr'!C32, '4th Qtr'!C32) -> 38047.617 | D32: =SUM('1st Qtr'!D32, '2nd Qtr'!D32, '3rd Qtr'!D32, '4th Qtr'!D32) -> 40396.32 | E32: =IF(AND(ISNUMBER(C32),ISNUMBER(D32)), C32-D32, "") -> -2348.7026 | F32: =IFERROR(E32/D32, "") -> -0.0581415 | G32: =SUM('1st Qtr'!G32, '2nd Qtr'!G32, '3rd Qtr'!G32, '4th Qtr'!G32) -> 30355.12 | H32: =SUM('1st Qtr'!H32, '2nd Qtr'!H32, '3rd Qtr'!H32, '4th Qtr'!H32) -> 7692.4974 | I32: =IFERROR(H32/G32, "") -> 0.2534168
A33: NH Rochester - Spaulding HS | B33: NH | C33: =SUM('1st Qtr'!C33, '2nd Qtr'!C33, '3rd Qtr'!C33, '4th Qtr'!C33) -> 19594.5 | D33: =SUM('1st Qtr'!D33, '2nd Qtr'!D33, '3rd Qtr'!D33, '4th Qtr'!D33) -> 16446 | E33: =IF(AND(ISNUMBER(C33),ISNUMBER(D33)), C33-D33, "") -> 3148.5 | F33: =IFERROR(E33/D33, "") -> 0.19144473 | G33: =SUM('1st Qtr'!G33, '2nd Qtr'!G33, '3rd Qtr'!G33, '4th Qtr'!G33) -> 15033.3 | H33: =SUM(Jan!I33, Feb!H33, Mar!H33) -> 0 | I33: =IFERROR(H33/G33, "") -> 0
A34: NH: Rochester - McClelland ES | B34: NH | C34: =SUM('1st Qtr'!C34, '2nd Qtr'!C34, '3rd Qtr'!C34, '4th Qtr'!C34) -> 13246.875 | D34: =SUM('1st Qtr'!D34, '2nd Qtr'!D34, '3rd Qtr'!D34, '4th Qtr'!D34) -> 13989 | E34: =IF(AND(ISNUMBER(C34),ISNUMBER(D34)), C34-D34, "") -> -742.125 | F34: =IFERROR(E34/D34, "") -> -0.053050611 | G34: =SUM('1st Qtr'!G34, '2nd Qtr'!G34, '3rd Qtr'!G34, '4th Qtr'!G34) -> 9803.669 | H34: =SUM('1st Qtr'!H34, '2nd Qtr'!H34, '3rd Qtr'!H34, '4th Qtr'!H34) -> 3443.206 | I34: =IFERROR(H34/G34, "") -> 0.35121606
A35: NH: Rochester - Brock St Vocational | B35: NH | C35: =SUM('1st Qtr'!C35, '2nd Qtr'!C35, '3rd Qtr'!C35, '4th Qtr'!C35) -> 17978.129 | D35: =SUM('1st Qtr'!D35, '2nd Qtr'!D35, '3rd Qtr'!D35, '4th Qtr'!D35) -> 17518.42 | E35: =IF(AND(ISNUMBER(C35),ISNUMBER(D35)), C35-D35, "") -> 459.70907 | F35: =IFERROR(E35/D35, "") -> 0.026241469 | G35: =SUM('1st Qtr'!G35, '2nd Qtr'!G35, '3rd Qtr'!G35, '4th Qtr'!G35) -> 13220.3 | H35: =SUM(Jan!I35, Feb!H35, Mar!H35) -> 0 | I35: =IFERROR(H35/G35, "") -> 0
A36: OH: Cleveland - CV Kinsman | B36: OH | C36: =SUM('1st Qtr'!C36, '2nd Qtr'!C36, '3rd Qtr'!C36, '4th Qtr'!C36) -> 714.07031 | D36: =SUM('1st Qtr'!D36, '2nd Qtr'!D36, '3rd Qtr'!D36, '4th Qtr'!D36) -> 138037.1 | E36: =IF(AND(ISNUMBER(C36),ISNUMBER(D36)), C36-D36, "") -> -137323.03 | F36: =IFERROR(E36/D36, "") -> -0.99482697 | G36: =SUM('1st Qtr'!G36, '2nd Qtr'!G36, '3rd Qtr'!G36, '4th Qtr'!G36) -> 133750 | H36: =SUM('1st Qtr'!H36, '2nd Qtr'!H36, '3rd Qtr'!H36, '4th Qtr'!H36) -> -133035.93 | I36: =IFERROR(H36/G36, "") -> -0.99466116
A37: OH: Cleveland - CV Wooster | B37: OH | C37: =SUM('1st Qtr'!C37, '2nd Qtr'!C37, '3rd Qtr'!C37, '4th Qtr'!C37) -> 21528 | D37: =SUM('1st Qtr'!D37, '2nd Qtr'!D37, '3rd Qtr'!D37, '4th Qtr'!D37) -> 0 | E37: =IF(AND(ISNUMBER(C37),ISNUMBER(D37)), C37-D37, "") -> 21528 | F37: =IFERROR(E37/D37, "") | G37: =SUM('1st Qtr'!G37, '2nd Qtr'!G37, '3rd Qtr'!G37, '4th Qtr'!G37) -> 32092 | H37: =SUM(Jan!I37, Feb!H37, Mar!H37) -> 0 | I37: =IFERROR(H37/G37, "") -> 0
A38: PR: Aguadilla - Coca Cola | B38: PR | C38: =SUM('1st Qtr'!C38, '2nd Qtr'!C38, '3rd Qtr'!C38, '4th Qtr'!C38) -> 15714 | D38: =SUM('1st Qtr'!D38, '2nd Qtr'!D38, '3rd Qtr'!D38, '4th Qtr'!D38) -> 20085.89 | E38: =IF(AND(ISNUMBER(C38),ISNUMBER(D38)), C38-D38, "") -> -4371.89 | F38: =IFERROR(E38/D38, "") -> -0.21765976 | G38: =SUM('1st Qtr'!G38, '2nd Qtr'!G38, '3rd Qtr'!G38, '4th Qtr'!G38) -> 23213 | H38: =SUM('1st Qtr'!H38, '2nd Qtr'!H38, '3rd Qtr'!H38, '4th Qtr'!H38) -> -7499 | I38: =IFERROR(H38/G38, "") -> -0.32305174
A39: PR: Bayamon - Coca Cola | B39: PR | C39: =SUM('1st Qtr'!C39, '2nd Qtr'!C39, '3rd Qtr'!C39, '4th Qtr'!C39) -> 53577 | D39: =SUM('1st Qtr'!D39, '2nd Qtr'!D39, '3rd Qtr'!D39, '4th Qtr'!D39) -> 82116.61 | E39: =IF(AND(ISNUMBER(C39),ISNUMBER(D39)), C39-D39, "") -> -28539.61 | F39: =IFERROR(E39/D39, "") -> -0.34754978 | G39: =SUM('1st Qtr'!G39, '2nd Qtr'!G39, '3rd Qtr'!G39, '4th Qtr'!G39) -> 86974 | H39: =SUM(Jan!I39, Feb!H39, Mar!H39) -> 0 | I39: =IFERROR(H39/G39, "") -> 0
A40: PR: Carolina - St. Francis | B40: PR | C40: =SUM('1st Qtr'!C40, '2nd Qtr'!C40, '3rd Qtr'!C40, '4th Qtr'!C40) -> 18667 | D40: =SUM('1st Qtr'!D40, '2nd Qtr'!D40, '3rd Qtr'!D40, '4th Qtr'!D40) -> 64278.93 | E40: =IF(AND(ISNUMBER(C40),ISNUMBER(D40)), C40-D40, "") -> -45611.93 | F40: =IFERROR(E40/D40, "") -> -0.7095938 | G40: =SUM('1st Qtr'!G40, '2nd Qtr'!G40, '3rd Qtr'!G40, '4th Qtr'!G40) -> 44155 | H40: =SUM('1st Qtr'!H40, '2nd Qtr'!H40, '3rd Qtr'!H40, '4th Qtr'!H40) -> -25488 | I40: =IFERROR(H40/G40, "") -> -0.57723927
...

Sheet 1st Qtr
A1: {=portfolio} -> GoodFinch | D1: 1st Quarter Actual v. Expected | G1: 1st Quarter Actual v. Forecasted
A2: Total | C2: =SUM(C4:C80) -> 0 | D2: =SUM(D4:D80) -> 0 | E2: =C2-D2 -> 0 | F2: =IFERROR(E2/D2, 0) -> 0 | G2: =SUM(G4:G80) -> 0 | H2: =C2-G2 -> 0 | I2: =IFERROR(H2/G2, 0) -> 0
A3: Site | B3: State | C3: Actual | D3: Expected | E3: Delta | F3: % | G3: Forecasted | H3: Delta | I3: %
A4: {=Sites[Site]} -> AZ: Tempe - ASU - Farmer | B4: {=Sites[State]} -> AZ | C4: =SUM(Jan!D4, Feb!C4, Mar!C4) -> 0 | D4: =SUM(Jan!E4, Feb!D4, Mar!D4) -> 0 | E4: =IF(AND(ISNUMBER(C4),ISNUMBER(D4)), C4-D4, "") -> 0 | F4: =IFERROR(E4/D4, "") | G4: =SUM(Jan!H4, Feb!G4, Mar!G4) -> 0 | H4: =SUM(Jan!I4, Feb!H4, Mar!H4) -> 0 | I4: =IFERROR(H4/G4, "")
A5: AZ: Tempe - ASU - Fulton | B5: AZ | C5: =SUM(Jan!D5, Feb!C5, Mar!C5) -> 0 | D5: =SUM(Jan!E5, Feb!D5, Mar!D5) -> 0 | E5: =IF(AND(ISNUMBER(C5),ISNUMBER(D5)), C5-D5, "") -> 0 | F5: =IFERROR(E5/D5, "") | G5: =SUM(Jan!H5, Feb!G5, Mar!G5) -> 0 | H5: =SUM(Jan!I5, Feb!H5, Mar!H5) -> 0 | I5: =IFERROR(H5/G5, "")
A6: AZ: Superior - JFK Elementary | B6: AZ | C6: =SUM(Jan!D6, Feb!C6, Mar!C6) -> 0 | D6: =SUM(Jan!E6, Feb!D6, Mar!D6) -> 0 | E6: =IF(AND(ISNUMBER(C6),ISNUMBER(D6)), C6-D6, "") -> 0 | F6: =IFERROR(E6/D6, "") | G6: =SUM(Jan!H6, Feb!G6, Mar!G6) -> 0 | H6: =SUM(Jan!I6, Feb!H6, Mar!H6) -> 0 | I6: =IFERROR(H6/G6, "")
A7: AZ: Tempe - ASU - Noble | B7: AZ | C7: =SUM(Jan!D7, Feb!C7, Mar!C7) -> 0 | D7: =SUM(Jan!E7, Feb!D7, Mar!D7) -> 0 | E7: =IF(AND(ISNUMBER(C7),ISNUMBER(D7)), C7-D7, "") -> 0 | F7: =IFERROR(E7/D7, "") | G7: =SUM(Jan!H7, Feb!G7, Mar!G7) -> 0 | H7: =SUM(Jan!I7, Feb!H7, Mar!H7) -> 0 | I7: =IFERROR(H7/G7, "")
A8: AZ: Tempe - ASU - Parking #3 | B8: AZ | C8: =SUM(Jan!D8, Feb!C8, Mar!C8) -> 0 | D8: =SUM(Jan!E8, Feb!D8, Mar!D8) -> 0 | E8: =IF(AND(ISNUMBER(C8),ISNUMBER(D8)), C8-D8, "") -> 0 | F8: =IFERROR(E8/D8, "") | G8: =SUM(Jan!H8, Feb!G8, Mar!G8) -> 0 | H8: =SUM(Jan!I8, Feb!H8, Mar!H8) -> 0 | I8: =IFERROR(H8/G8, "")
A9: AZ: Tempe - ASU - PE East | B9: AZ | C9: =SUM(Jan!D9, Feb!C9, Mar!C9) -> 0 | D9: =SUM(Jan!E9, Feb!D9, Mar!D9) -> 0 | E9: =IF(AND(ISNUMBER(C9),ISNUMBER(D9)), C9-D9, "") -> 0 | F9: =IFERROR(E9/D9, "") | G9: =SUM(Jan!H9, Feb!G9, Mar!G9) -> 0 | H9: =SUM(Jan!I9, Feb!H9, Mar!H9) -> 0 | I9: =IFERROR(H9/G9, "")
A10: AZ: Tempe - ASU - Schwada | B10: AZ | C10: =SUM(Jan!D10, Feb!C10, Mar!C10) -> 0 | D10: =SUM(Jan!E10, Feb!D10, Mar!D10) -> 0 | E10: =IF(AND(ISNUMBER(C10),ISNUMBER(D10)), C10-D10, "") -> 0 | F10: =IFERROR(E10/D10, "") | G10: =SUM(Jan!H10, Feb!G10, Mar!G10) -> 0 | H10: =SUM(Jan!I10, Feb!H10, Mar!H10) -> 0 | I10: =IFERROR(H10/G10, "")
A11: AZ: Phoenix - Starshine Academy | B11: AZ | C11: =SUM(Jan!D11, Feb!C11, Mar!C11) -> 0 | D11: =SUM(Jan!E11, Feb!D11, Mar!D11) -> 0 | E11: =IF(AND(ISNUMBER(C11),ISNUMBER(D11)), C11-D11, "") -> 0 | F11: =IFERROR(E11/D11, "") | G11: =SUM(Jan!H11, Feb!G11, Mar!G11) -> 0 | H11: =SUM(Jan!I11, Feb!H11, Mar!H11) -> 0 | I11: =IFERROR(H11/G11, "")
A12: AZ: Yuma Airport | B12: AZ | C12: =SUM(Jan!D12, Feb!C12, Mar!C12) -> 0 | D12: =SUM(Jan!E12, Feb!D12, Mar!D12) -> 0 | E12: =IF(AND(ISNUMBER(C12),ISNUMBER(D12)), C12-D12, "") -> 0 | F12: =IFERROR(E12/D12, "") | G12: =SUM(Jan!H12, Feb!G12, Mar!G12) -> 0 | H12: =SUM(Jan!I12, Feb!H12, Mar!H12) -> 0 | I12: =IFERROR(H12/G12, "")
A13: AZ: Globe - Gila CC | B13: AZ | C13: =SUM(Jan!D13, Feb!C13, Mar!C13) -> 0 | D13: =SUM(Jan!E13, Feb!D13, Mar!D13) -> 0 | E13: =IF(AND(ISNUMBER(C13),ISNUMBER(D13)), C13-D13, "") -> 0 | F13: =IFERROR(E13/D13, "") | G13: =SUM(Jan!H13, Feb!G13, Mar!G13) -> 0 | H13: =SUM(Jan!I13, Feb!H13, Mar!H13) -> 0 | I13: =IFERROR(H13/G13, "")
A14: AZ: Payson - Gila CC | B14: AZ | C14: =SUM(Jan!D14, Feb!C14, Mar!C14) -> 0 | D14: =SUM(Jan!E14, Feb!D14, Mar!D14) -> 0 | E14: =IF(AND(ISNUMBER(C14),ISNUMBER(D14)), C14-D14, "") -> 0 | F14: =IFERROR(E14/D14, "") | G14: =SUM(Jan!H14, Feb!G14, Mar!G14) -> 0 | H14: =SUM(Jan!I14, Feb!H14, Mar!H14) -> 0 | I14: =IFERROR(H14/G14, "")
A15: AZ: Mesa - Sequoia Charter School | B15: AZ | C15: =SUM(Jan!D15, Feb!C15, Mar!C15) -> 0 | D15: =SUM(Jan!E15, Feb!D15, Mar!D15) -> 0 | E15: =IF(AND(ISNUMBER(C15),ISNUMBER(D15)), C15-D15, "") -> 0 | F15: =IFERROR(E15/D15, "") | G15: =SUM(Jan!H15, Feb!G15, Mar!G15) -> 0 | H15: =SUM(Jan!I15, Feb!H15, Mar!H15) -> 0 | I15: =IFERROR(H15/G15, "")
A16: AZ: Tempe - SCNM | B16: AZ | C16: =SUM(Jan!D16, Feb!C16, Mar!C16) -> 0 | D16: =SUM(Jan!E16, Feb!D16, Mar!D16) -> 0 | E16: =IF(AND(ISNUMBER(C16),ISNUMBER(D16)), C16-D16, "") -> 0 | F16: =IFERROR(E16/D16, "") | G16: =SUM(Jan!H16, Feb!G16, Mar!G16) -> 0 | H16: =SUM(Jan!I16, Feb!H16, Mar!H16) -> 0 | I16: =IFERROR(H16/G16, "")
... A45: DC: Washington - Weinberg 3 | B45: DC | C45: =SUM(Jan!D45, Feb!C45, Mar!C45) -> 0 | D45: =SUM(Jan!E45, Feb!D45, Mar!D45) -> 0 | E45: =IF(AND(ISNUMBER(C45),ISNUMBER(D45)), C45-D45, "") -> 0 | F45: =IFERROR(E45/D45, "") | G45: =SUM(Jan!H45, Feb!G45, Mar!G45) -> 0 | H45: =SUM(Jan!I45, Feb!H45, Mar!H45) -> 0 | I45: =IFERROR(H45/G45, "")

Sheet 2nd Qtr
A1: {=portfolio} -> GoodFinch | D1: 2nd Quarter Actual v. Expected | G1: 2nd Quarter Actual v. Forecasted
A2: Total | C2: =SUM(C4:C80) -> 0 | D2: =SUM(D4:D80) -> 0 | E2: =C2-D2 -> 0 | F2: =IFERROR(E2/D2, 0) -> 0 | G2: =SUM(G4:G80) -> 0 | H2: =C2-G2 -> 0 | I2: =IFERROR(H2/G2, 0) -> 0
A3: Site | B3: State | C3: Actual | D3: Expected | E3: Delta | F3: % | G3: Forecasted | H3: Delta | I3: %
A4: {=Sites[Site]} -> AZ: Tempe - ASU - Farmer | B4: {=Sites[State]} -> AZ | C4: =SUM(Apr!C4, May!C4, Jun!C4) -> 0 | D4: =SUM(Apr!D4, May!D4, Jun!D4) -> 0 | E4: =IF(AND(ISNUMBER(C4),ISNUMBER(D4)), C4-D4, "") -> 0 | F4: =IFERROR(E4/D4, "") | G4: =SUM(Apr!G4+May!G4+Jun!G4) -> 0 | H4: =SUM(Apr!H4, May!H4, Jun!H4) -> 0 | I4: =IFERROR(H4/G4, "")
A5: AZ: Tempe - ASU - Fulton | B5: AZ | C5: =SUM(Apr!C5, May!C5, Jun!C5) -> 0 | D5: =SUM(Apr!D5, May!D5, Jun!D5) -> 0 | E5: =IF(AND(ISNUMBER(C5),ISNUMBER(D5)), C5-D5, "") -> 0 | F5: =IFERROR(E5/D5, "") | G5: =SUM(Apr!G5+May!G5+Jun!G5) -> 0 | H5: =SUM(Apr!H5, May!H5, Jun!H5) -> 0 | I5: =IFERROR(H5/G5, "")
A6: AZ: Superior - JFK Elementary | B6: AZ | C6: =SUM(Apr!C6, May!C6, Jun!C6) -> 0 | D6: =SUM(Apr!D6, May!D6, Jun!D6) -> 0 | E6: =IF(AND(ISNUMBER(C6),ISNUMBER(D6)), C6-D6, "") -> 0 | F6: =IFERROR(E6/D6, "") | G6: =SUM(Apr!G6+May!G6+Jun!G6) -> 0 | H6: =SUM(Apr!H6, May!H6, Jun!H6) -> 0 | I6: =IFERROR(H6/G6, "")
A7: AZ: Tempe - ASU - Noble | B7: AZ | C7: =SUM(Apr!C7, May!C7, Jun!C7) -> 0 | D7: =SUM(Apr!D7, May!D7, Jun!D7) -> 0 | E7: =IF(AND(ISNUMBER(C7),ISNUMBER(D7)), C7-D7, "") -> 0 | F7: =IFERROR(E7/D7, "") | G7: =SUM(Apr!G7,May!G7,Jun!G7) -> 0 | H7: =SUM(Apr!H7, May!H7, Jun!H7) -> 0 | I7: =IFERROR(H7/G7, "")
A8: AZ: Tempe - ASU - Parking #3 | B8: AZ | C8: =SUM(Apr!C8, May!C8, Jun!C8) -> 0 | D8: =SUM(Apr!D8, May!D8, Jun!D8) -> 0 | E8: =IF(AND(ISNUMBER(C8),ISNUMBER(D8)), C8-D8, "") -> 0 | F8: =IFERROR(E8/D8, "") | G8: =SUM(Apr!G8,May!G8,Jun!G8) -> 0 | H8: =SUM(Apr!H8, May!H8, Jun!H8) -> 0 | I8: =IFERROR(H8/G8, "")
A9: AZ: Tempe - ASU - PE East | B9: AZ | C9: =SUM(Apr!C9, May!C9, Jun!C9) -> 0 | D9: =SUM(Apr!D9, May!D9, Jun!D9) -> 0 | E9: =IF(AND(ISNUMBER(C9),ISNUMBER(D9)), C9-D9, "") -> 0 | F9: =IFERROR(E9/D9, "") | G9: =SUM(Apr!G9,May!G9,Jun!G9) -> 0 | H9: =SUM(Apr!H9, May!H9, Jun!H9) -> 0 | I9: =IFERROR(H9/G9, "")
A10: AZ: Tempe - ASU - Schwada | B10: AZ | C10: =SUM(Apr!C10, May!C10, Jun!C10) -> 0 | D10: =SUM(Apr!D10, May!D10, Jun!D10) -> 0 | E10: =IF(AND(ISNUMBER(C10),ISNUMBER(D10)), C10-D10, "") -> 0 | F10: =IFERROR(E10/D10, "") | G10: =SUM(Apr!G10+May!G10+Jun!G10) -> 0 | H10: =SUM(Apr!H10, May!H10, Jun!H10) -> 0 | I10: =IFERROR(H10/G10, "")
A11: AZ: Phoenix - Starshine Academy | B11: AZ | C11: =SUM(Apr!C11, May!C11, Jun!C11) -> 0 | D11: =SUM(Apr!D11, May!D11, Jun!D11) -> 0 | E11: =IF(AND(ISNUMBER(C11),ISNUMBER(D11)), C11-D11, "") -> 0 | F11: =IFERROR(E11/D11, "") | G11: =SUM(Apr!G11,May!G11,Jun!G11) -> 0 | H11: =SUM(Apr!H11, May!H11, Jun!H11) -> 0 | I11: =IFERROR(H11/G11, "")
A12: AZ: Yuma Airport | B12: AZ | C12: =SUM(Apr!C12, May!C12, Jun!C12) -> 0 | D12: =SUM(Apr!D12, May!D12, Jun!D12) -> 0 | E12: =IF(AND(ISNUMBER(C12),ISNUMBER(D12)), C12-D12, "") -> 0 | F12: =IFERROR(E12/D12, "") | G12: =SUM(Apr!G12+May!G12+Jun!G12) -> 0 | H12: =SUM(Apr!H12, May!H12, Jun!H12) -> 0 | I12: =IFERROR(H12/G12, "")
A13: AZ: Globe - Gila CC | B13: AZ | C13: =SUM(Apr!C13, May!C13, Jun!C13) -> 0 | D13: =SUM(Apr!D13, May!D13, Jun!D13) -> 0 | E13: =IF(AND(ISNUMBER(C13),ISNUMBER(D13)), C13-D13, "") -> 0 | F13: =IFERROR(E13/D13, "") | G13: =SUM(Apr!G13,May!G13,Jun!G13) -> 0 | H13: =SUM(Apr!H13, May!H13, Jun!H13) -> 0 | I13: =IFERROR(H13/G13, "")
A14: AZ: Payson - Gila CC | B14: AZ | C14: =SUM(Apr!C14, May!C14, Jun!C14) -> 0 | D14: =SUM(Apr!D14, May!D14, Jun!D14) -> 0 | E14: =IF(AND(ISNUMBER(C14),ISNUMBER(D14)), C14-D14, "") -> 0 | F14: =IFERROR(E14/D14, "") | G14: =SUM(Apr!G14+May!G14+Jun!G14) -> 0 | H14: =SUM(Apr!H14, May!H14, Jun!H14) -> 0 | I14: =IFERROR(H14/G14, "")
A15: AZ: Mesa - Sequoia Charter School | B15: AZ | C15: =SUM(Apr!C15, May!C15, Jun!C15) -> 0 | D15: =SUM(Apr!D15, May!D15, Jun!D15) -> 0 | E15: =IF(AND(ISNUMBER(C15),ISNUMBER(D15)), C15-D15, "") -> 0 | F15: =IFERROR(E15/D15, "") | G15: =SUM(Apr!G15,May!G15,Jun!G15) -> 0 | H15: =SUM(Apr!H15, May!H15, Jun!H15) -> 0 | I15: =IFERROR(H15/G15, "")
A16: AZ: Tempe - SCNM | B16: AZ | C16: =SUM(Apr!C16, May!C16, Jun!C16) -> 0 | D16: =SUM(Apr!D16, May!D16, Jun!D16) -> 0 | E16: =IF(AND(ISNUMBER(C16),ISNUMBER(D16)), C16-D16, "") -> 0 | F16: =IFERROR(E16/D16, "") | G16: =SUM(Apr!G16+May!G16+Jun!G16) -> 0 | H16: =SUM(Apr!H16, May!H16, Jun!H16) -> 0 | I16: =IFERROR(H16/G16, "")
A17: DE: Newark - Clayton Hall | B17: DE | C17: =SUM(Apr!C17, May!C17, Jun!C17) -> 0 | D17: =SUM(Apr!D17, May!D17, Jun!D17) -> 0 | E17: =IF(AND(ISNUMBER(C17),ISNUMBER(D17)), C17-D17, "") -> 0 | F17: =IFERROR(E17/D17, "") | G17: =SUM(Apr!G17,May!G17,Jun!G17) -> 0 | H17: =SUM(Apr!H17, May!H17, Jun!H17) -> 0 | I17: =IFERROR(H17/G17, "")
A18: DE: Newark - UOD Field House | B18: DE | C18: =SUM(Apr!C18, May!C18, Jun!C18) -> 0 | D18: =SUM(Apr!D18, May!D18, Jun!D18) -> 0 | E18: =IF(AND(ISNUMBER(C18),ISNUMBER(D18)), C18-D18, "") -> 0 | F18: =IFERROR(E18/D18, "") | G18: =SUM(Apr!G18+May!G18+Jun!G18) -> 0 | H18: =SUM(Apr!H18, May!H18, Jun!H18) -> 0 | I18: =IFERROR(H18/G18, "")
A19: DE: Newark - UOD 461 Wyoming | B19: DE | C19: =SUM(Apr!C19, May!C19, Jun!C19) -> 0 | D19: =SUM(Apr!D19, May!D19, Jun!D19) -> 0 | E19: =IF(AND(ISNUMBER(C19),ISNUMBER(D19)), C19-D19, "") -> 0 | F19: =IFERROR(E19/D19, "") | G19: =SUM(Apr!G19,May!G19,Jun!G19) -> 0 | H19: =SUM(Apr!H19, May!H19, Jun!H19) -> 0 | I19: =IFERROR(H19/G19, "")
A20: HI: Waipahu - 94-246 Leoku St - E.F.G. | B20: HI | C20: =SUM(Apr!C20, May!C20, Jun!C20) -> 0 | D20: =SUM(Apr!D20, May!D20, Jun!D20) -> 0 | E20: =IF(AND(ISNUMBER(C20),ISNUMBER(D20)), C20-D20, "") -> 0 | F20: =IFERROR(E20/D20, "") | G20: =SUM(Apr!G20+May!G20+Jun!G20) -> 0 | H20: =SUM(Apr!H20, May!H20, Jun!H20) -> 0 | I20: =IFERROR(H20/G20, "")
A21: HI: Waipahu - 94-099 Waipahu St - PV | B21: HI | C21: =SUM(Apr!C21, May!C21, Jun!C21) -> 0 | D21: =SUM(Apr!D21, May!D21, Jun!D21) -> 0 | E21: =IF(AND(ISNUMBER(C21),ISNUMBER(D21)), C21-D21, "") -> 0 | F21: =IFERROR(E21/D21, "") | G21: =SUM(Apr!G21,May!G21,Jun!G21) -> 0 | H21: =SUM(Apr!H21, May!H21, Jun!H21) -> 0 | I21: =IFERROR(H21/G21, "")
A22: MD: Presston - Bird-in-Hand | B22: MD | C22: =SUM(Apr!C22, May!C22, Jun!C22) -> 0 | D22: =SUM(Apr!D22, May!D22, Jun!D22) -> 0 | E22: =IF(AND(ISNUMBER(C22),ISNUMBER(D22)), C22-D22, "") -> 0 | F22: =IFERROR(E22/D22, "") | G22: =SUM(Apr!G22+May!G22+Jun!G22) -> 0 | H22: =SUM(Apr!H22, May!H22, Jun!H22) -> 0 | I22: =IFERROR(H22/G22, "")
A23: MD: Easton - Shortall | B23: MD | C23: =SUM(Apr!C23, May!C23, Jun!C23) -> 0 | D23: =SUM(Apr!D23, May!D23, Jun!D23) -> 0 | E23: =IF(AND(ISNUMBER(C23),ISNUMBER(D23)), C23-D23, "") -> 0 | F23: =IFERROR(E23/D23, "") | G23: =SUM(Apr!G23,May!G23,Jun!G23) -> 0 | H23: =SUM(Apr!H23, May!H23, Jun!H23) -> 0 | I23: =IFERROR(H23/G23, "")
A24: MA: Boston - Seaport Solar | B24: MA | C24: =SUM(Apr!C24, May!C24, Jun!C24) -> 0 | D24: =SUM(Apr!D24, May!D24, Jun!D24) -> 0 | E24: =IF(AND(ISNUMBER(C24),ISNUMBER(D24)), C24-D24, "") -> 0 | F24: =IFERROR(E24/D24, "") | G24: =SUM(Apr!G24+May!G24+Jun!G24) -> 0 | H24: =SUM(Apr!H24, May!H24, Jun!H24) -> 0 | I24: =IFERROR(H24/G24, "")
A25: MA: Dedham - Sprague Street | B25: MA | C25: =SUM(Apr!C25, May!C25, Jun!C25) -> 0 | D25: =SUM(Apr!D25, May!D25, Jun!D25) -> 0 | E25: =IF(AND(ISNUMBER(C25),ISNUMBER(D25)), C25-D25, "") -> 0 | F25: =IFERROR(E25/D25, "") | G25: =SUM(Apr!G25,May!G25,Jun!G25) -> 0 | H25: =SUM(Apr!H25, May!H25, Jun!H25) -> 0 | I25: =IFERROR(H25/G25, "")
A26: MA: Boston - Summer Street | B26: MA | C26: =SUM(Apr!C26, May!C26, Jun!C26) -> 0 | D26: =SUM(Apr!D26, May!D26, Jun!D26) -> 0 | E26: =IF(AND(ISNUMBER(C26),ISNUMBER(D26)), C26-D26, "") -> 0 | F26: =IFERROR(E26/D26, "") | G26: =SUM(Apr!G26+May!G26+Jun!G26) -> 0 | H26: =SUM(Apr!H26, May!H26, Jun!H26) -> 0 | I26: =IFERROR(H26/G26, "")
A27: MA: Leominster - Spectro Coatings | B27: MA | C27: =SUM(Apr!C27, May!C27, Jun!C27) -> 0 | D27: =SUM(Apr!D27, May!D27, Jun!D27) -> 0 | E27: =IF(AND(ISNUMBER(C27),ISNUMBER(D27)), C27-D27, "") -> 0 | F27: =IFERROR(E27/D27, "") | G27: =SUM(Apr!G27,May!G27,Jun!G27) -> 0 | H27: =SUM(Apr!H27, May!H27, Jun!H27) -> 0 | I27: =IFERROR(H27/G27, "")
A28: MA: Braintree - RCAB | B28: MA | C28: =SUM(Apr!C28, May!C28, Jun!C28) -> 0 | D28: =SUM(Apr!D28, May!D28, Jun!D28) -> 0 | E28: =IF(AND(ISNUMBER(C28),ISNUMBER(D28)), C28-D28, "") -> 0 | F28: =IFERROR(E28/D28, "") | G28: =SUM(Apr!G28+May!G28+Jun!G28) -> 0 | H28: =SUM(Apr!H28, May!H28, Jun!H28) -> 0 | I28: =IFERROR(H28/G28, "")
A29: NH: Rochester - Portland Street | B29: NH | C29: =SUM(Apr!C29, May!C29, Jun!C29) -> 0 | D29: =SUM(Apr!D29, May!D29, Jun!D29) -> 0 | E29: =IF(AND(ISNUMBER(C29),ISNUMBER(D29)), C29-D29, "") -> 0 | F29: =IFERROR(E29/D29, "") | G29: =SUM(Apr!G29,May!G29,Jun!G29) -> 0 | H29: =SUM(Apr!H29, May!H29, Jun!H29) -> 0 | I29: =IFERROR(H29/G29, "")
A30: NH: Portsmouth - Portsmouth HS | B30: NH | C30: =SUM(Apr!C30, May!C30, Jun!C30) -> 0 | D30: =SUM(Apr!D30, May!D30, Jun!D30) -> 0 | E30: =IF(AND(ISNUMBER(C30),ISNUMBER(D30)), C30-D30, "") -> 0 | F30: =IFERROR(E30/D30, "") | G30: =SUM(Apr!G30+May!G30+Jun!G30) -> 0 | H30: =SUM(Apr!H30, May!H30, Jun!H30) -> 0 | I30: =IFERROR(H30/G30, "")
A31: NH: Portsmouth - Portsmouth WTP | B31: NH | C31: =SUM(Apr!C31, May!C31, Jun!C31) -> 0 | D31: =SUM(Apr!D31, May!D31, Jun!D31) -> 0 | E31: =IF(AND(ISNUMBER(C31),ISNUMBER(D31)), C31-D31, "") -> 0 | F31: =IFERROR(E31/D31, "") | G31: =SUM(Apr!G31,May!G31,Jun!G31) -> 0 | H31: =SUM(Apr!H31, May!H31, Jun!H31) -> 0 | I31: =IFERROR(H31/G31, "")
A32: NH: Rochester - Rochester MS | B32: NH | C32: =SUM(Apr!C32, May!C32, Jun!C32) -> 0 | D32: =SUM(Apr!D32, May!D32, Jun!D32) -> 0 | E32: =IF(AND(ISNUMBER(C32),ISNUMBER(D32)), C32-D32, "") -> 0 | F32: =IFERROR(E32/D32, "") | G32: =SUM(Apr!G32+May!G32+Jun!G32) -> 0 | H32: =SUM(Apr!H32, May!H32, Jun!H32) -> 0 | I32: =IFERROR(H32/G32, "")
A33: NH Rochester - Spaulding HS | B33: NH | C33: =SUM(Apr!C33, May!C33, Jun!C33) -> 0 | D33: =SUM(Apr!D33, May!D33, Jun!D33) -> 0 | E33: =IF(AND(ISNUMBER(C33),ISNUMBER(D33)), C33-D33, "") -> 0 | F33: =IFERROR(E33/D33, "") | G33: =SUM(Apr!G33,May!G33,Jun!G33) -> 0 | H33: =SUM(Apr!H33, May!H33, Jun!H33) -> 0 | I33: =IFERROR(H33/G33, "")
A34: NH: Rochester - McClelland ES | B34: NH | C34: =SUM(Apr!C34, May!C34, Jun!C34) -> 0 | D34: =SUM(Apr!D34, May!D34, Jun!D34) -> 0 | E34: =IF(AND(ISNUMBER(C34),ISNUMBER(D34)), C34-D34, "") -> 0 | F34: =IFERROR(E34/D34, "") | G34: =SUM(Apr!G34+May!G34+Jun!G34) -> 0 | H34: =SUM(Apr!H34, May!H34, Jun!H34) -> 0 | I34: =IFERROR(H34/G34, "")
A35: NH: Rochester - Brock St Vocational | B35: NH | C35: =SUM(Apr!C35, May!C35, Jun!C35) -> 0 | D35: =SUM(Apr!D35, May!D35, Jun!D35) -> 0 | E35: =IF(AND(ISNUMBER(C35),ISNUMBER(D35)), C35-D35, "") -> 0 | F35: =IFERROR(E35/D35, "") | G35: =SUM(Apr!G35,May!G35,Jun!G35) -> 0 | H35: =SUM(Apr!H35, May!H35, Jun!H35) -> 0 | I35: =IFERROR(H35/G35, "")
A36: OH: Cleveland - CV Kinsman | B36: OH | C36: =SUM(Apr!C36, May!C36, Jun!C36) -> 0 | D36: =SUM(Apr!D36, May!D36, Jun!D36) -> 0 | E36: =IF(AND(ISNUMBER(C36),ISNUMBER(D36)), C36-D36, "") -> 0 | F36: =IFERROR(E36/D36, "") | G36: =SUM(Apr!G36+May!G36+Jun!G36) -> 0 | H36: =SUM(Apr!H36, May!H36, Jun!H36) -> 0 | I36: =IFERROR(H36/G36, "")
A37: OH: Cleveland - CV Wooster | B37: OH | C37: =SUM(Apr!C37, May!C37, Jun!C37) -> 0 | D37: =SUM(Apr!D37, May!D37, Jun!D37) -> 0 | E37: =IF(AND(ISNUMBER(C37),ISNUMBER(D37)), C37-D37, "") -> 0 | F37: =IFERROR(E37/D37, "") | G37: =SUM(Apr!G37,May!G37,Jun!G37) -> 0 | H37: =SUM(Apr!H37, May!H37, Jun!H37) -> 0 | I37: =IFERROR(H37/G37, "")
A38: PR: Aguadilla - Coca Cola | B38: PR | C38: =SUM(Apr!C38, May!C38, Jun!C38) -> 0 | D38: =SUM(Apr!D38, May!D38, Jun!D38) -> 0 | E38: =IF(AND(ISNUMBER(C38),ISNUMBER(D38)), C38-D38, "") -> 0 | F38: =IFERROR(E38/D38, "") | G38: =SUM(Apr!G38+May!G38+Jun!G38) -> 0 | H38: =SUM(Apr!H38, May!H38, Jun!H38) -> 0 | I38: =IFERROR(H38/G38, "")
A39: PR: Bayamon - Coca Cola | B39: PR | C39: =SUM(Apr!C39, May!C39, Jun!C39) -> 0 | D39: =SUM(Apr!D39, May!D39, Jun!D39) -> 0 | E39: =IF(AND(ISNUMBER(C39),ISNUMBER(D39)), C39-D39, "") -> 0 | F39: =IFERROR(E39/D39, "") | G39: =SUM(Apr!G39,May!G39,Jun!G39) -> 0 | H39: =SUM(Apr!H39, May!H39, Jun!H39) -> 0 | I39: =IFERROR(H39/G39, "")
A40: PR: Carolina - St. Francis | B40: PR | C40: =SUM(Apr!C40, May!C40, Jun!C40) -> 0 | D40: =SUM(Apr!D40, May!D40, Jun!D40) -> 0 | E40: =IF(AND(ISNUMBER(C40),ISNUMBER(D40)), C40-D40, "") -> 0 | F40: =IFERROR(E40/D40, "") | G40: =SUM(Apr!G40+May!G40+Jun!G40) -> 0 | H40: =SUM(Apr!H40, May!H40, Jun!H40) -> 0 | I40: =IFERROR(H40/G40, "")
...

Sheet 3rd Qtr
A1: {=portfolio} -> GoodFinch | D1: 3rd Quarter Actual v. Expected | G1: 3rd Quarter Actual v. Forecasted
A2: Total | C2: =SUM(C4:C79) -> 1539597.8 | D2: =SUM(D4:D79) -> 1456547.2 | E2: =C2-D2 -> 83050.532 | F2: =IFERROR(E2/D2, 0) -> 0.05701877 | G2: =SUM(G4:G79) -> 2267383.5 | H2: =C2-G2 -> -727785.72 | I2: =IFERROR(H2/G2, 0) -> -0.32098043
A3: Site | B3: State | C3: Actual | D3: Expected | E3: Delta | F3: % | G3: Forecasted | H3: Delta | I3: %
A4: {=Sites[Site]} -> AZ: Tempe - ASU - Farmer | B4: {=Sites[State]} -> AZ | C4: =SUM(Jul!C4, Aug!C4, Sep!C4) -> 13735.336 | D4: =SUM(Jul!D4, Aug!D4, Sep!D4) -> 8816.846 | E4: =IF(AND(ISNUMBER(C4),ISNUMBER(D4)), C4-D4, "") -> 4918.4897 | F4: =IFERROR(E4/D4, "") -> 0.55785138 | G4: =SUM(Jul!G4,Aug!G4,Sep!G4) -> 13564.61 | H4: =SUM(Jul!H4, Aug!H4, Sep!H4) -> 170.72569 | I4: =IFERROR(H4/G4, "") -> 0.012586112
A5: AZ: Tempe - ASU - Fulton | B5: AZ | C5: =SUM(Jul!C5, Aug!C5, Sep!C5) -> 51105 | D5: =SUM(Jul!D5, Aug!D5, Sep!D5) -> 60589.7 | E5: =IF(AND(ISNUMBER(C5),ISNUMBER(D5)), C5-D5, "") -> -9484.7 | F5: =IFERROR(E5/D5, "") -> -0.15653981 | G5: =SUM(Jul!G5,Aug!G5,Sep!G5) -> 68756 | H5: =SUM(Jul!H5, Aug!H5, Sep!H5) -> -17651 | I5: =IFERROR(H5/G5, "") -> -0.25671941
A6: AZ: Superior - JFK Elementary | B6: AZ | C6: =SUM(Jul!C6, Aug!C6, Sep!C6) -> 12132.18 | D6: =SUM(Jul!D6, Aug!D6, Sep!D6) -> 0 | E6: =IF(AND(ISNUMBER(C6),ISNUMBER(D6)), C6-D6, "") -> 12132.18 | F6: =IFERROR(E6/D6, "") | G6: =SUM(Jul!G6,Aug!G6,Sep!G6) -> 18696 | H6: =SUM(Jul!H6, Aug!H6, Sep!H6) -> -6563.8203 | I6: =IFERROR(H6/G6, "") -> -0.35108153
A7: AZ: Tempe - ASU - Noble | B7: AZ | C7: =SUM(Jul!C7, Aug!C7, Sep!C7) -> 12583.462 | D7: =SUM(Jul!D7, Aug!D7, Sep!D7) -> 15025.43 | E7: =IF(AND(ISNUMBER(C7),ISNUMBER(D7)), C7-D7, "") -> -2441.9685 | F7: =IFERROR(E7/D7, "") -> -0.16252237 | G7: =SUM(Jul!G7,Aug!G7,Sep!G7) -> 15254.26 | H7: =SUM(Jul!H7, Aug!H7, Sep!H7) -> -2670.7985 | I7: =IFERROR(H7/G7, "") -> -0.17508542
A8: AZ: Tempe - ASU - Parking #3 | B8: AZ | C8: =SUM(Jul!C8, Aug!C8, Sep!C8) -> 34337.612 | D8: =SUM(Jul!D8, Aug!D8, Sep!D8) -> 35477.84 | E8: =IF(AND(ISNUMBER(C8),ISNUMBER(D8)), C8-D8, "") -> -1140.2275 | F8: =IFERROR(E8/D8, "") -> -0.032139147 | G8: =SUM(Jul!G8,Aug!G8,Sep!G8) -> 31619.08 | H8: =SUM(Jul!H8, Aug!H8, Sep!H8) -> 2718.5325 | I8: =IFERROR(H8/G8, "") -> 0.085977596
A9: AZ: Tempe - ASU - PE East | B9: AZ | C9: =SUM(Jul!C9, Aug!C9, Sep!C9) -> 30211.908 | D9: =SUM(Jul!D9, Aug!D9, Sep!D9) -> 25952.9 | E9: =IF(AND(ISNUMBER(C9),ISNUMBER(D9)), C9-D9, "") -> 4259.0078 | F9: =IFERROR(E9/D9, "") -> 0.16410528 | G9: =SUM(Jul!G9,Aug!G9,Sep!G9) -> 31934.71 | H9: =SUM(Jul!H9, Aug!H9, Sep!H9) -> -1722.8022 | I9: =IFERROR(H9/G9, "") -> -0.053947638
A10: AZ: Tempe - ASU - Schwada | B10: AZ | C10: =SUM(Jul!C10, Aug!C10, Sep!C10) -> 9176.8897 | D10: =SUM(Jul!D10, Aug!D10, Sep!D10) -> 10685.01 | E10: =IF(AND(ISNUMBER(C10),ISNUMBER(D10)), C10-D10, "") -> -1508.1203 | F10: =IFERROR(E10/D10, "") -> -0.14114356 | G10: =SUM(Jul!G10,Aug!G10,Sep!G10) -> 13894 | H10: =SUM(Jul!H10, Aug!H10, Sep!H10) -> -4717.1103
A11: AZ: Phoenix - Starshine Academy | B11: AZ | C11: =SUM(Jul!C11, Aug!C11, Sep!C11) -> 6047.8 | D11: =SUM(Jul!D11, Aug!D11, Sep!D11) -> 0 | E11: =IF(AND(ISNUMBER(C11),ISNUMBER(D11)), C11-D11, "") -> 6047.8 | F11: =IFERROR(E11/D11, "") | G11: =SUM(Jul!G11,Aug!G11,Sep!G11) -> 11002 | H11: =SUM(Jul!H11, Aug!H11, Sep!H11) -> -4954.2 | I11: =IFERROR(H11/G11, "") -> -0.45029995
A12: AZ: Yuma Airport | B12: AZ | C12: =SUM(Jul!C12, Aug!C12, Sep!C12) -> 66601 | D12: =SUM(Jul!D12, Aug!D12, Sep!D12) -> 94129.73 | E12: =IF(AND(ISNUMBER(C12),ISNUMBER(D12)), C12-D12, "") -> -27528.73 | F12: =IFERROR(E12/D12, "") -> -0.29245521 | G12: =SUM(Jul!G12,Aug!G12,Sep!G12) -> 82137 | H12: =SUM(Jul!H12, Aug!H12, Sep!H12) -> -15536
A13: AZ: Globe - Gila CC | B13: AZ | C13: =SUM(Jul!C13, Aug!C13, Sep!C13) -> 20373.375 | D13: =SUM(Jul!D13, Aug!D13, Sep!D13) -> 0 | E13: =IF(AND(ISNUMBER(C13),ISNUMBER(D13)), C13-D13, "") -> 20373.375 | F13: =IFERROR(E13/D13, "") | G13: =SUM(Jul!G13,Aug!G13,Sep!G13) -> 18652 | H13: =SUM(Jul!H13, Aug!H13, Sep!H13) -> 1721.3752 | I13: =IFERROR(H13/G13, "") -> 0.092289043
A14: AZ: Payson - Gila CC | B14: AZ | C14: =SUM(Jul!C14, Aug!C14, Sep!C14) -> 15205.885 | D14: =SUM(Jul!D14, Aug!D14, Sep!D14) -> 6558.912 | E14: =IF(AND(ISNUMBER(C14),ISNUMBER(D14)), C14-D14, "") -> 8646.9725 | F14: =IFERROR(E14/D14, "") -> 1.3183547 | G14: =SUM(Jul!G14,Aug!G14,Sep!G14) -> 15449 | H14: =SUM(Jul!H14, Aug!H14, Sep!H14) -> -243.11545
A15: AZ: Mesa - Sequoia Charter School | B15: AZ | C15: =SUM(Jul!C15, Aug!C15, Sep!C15) -> 32820.18 | D15: =SUM(Jul!D15, Aug!D15, Sep!D15) -> 0 | E15: =IF(AND(ISNUMBER(C15),ISNUMBER(D15)), C15-D15, "") -> 32820.18 | F15: =IFERROR(E15/D15, "") | G15: =SUM(Jul!G15,Aug!G15,Sep!G15) -> 52037 | H15: =SUM(Jul!H15, Aug!H15, Sep!H15) -> -19216.82 | I15: =IFERROR(H15/G15, "") -> -0.36929147
A16: AZ: Tempe - SCNM | B16: AZ | C16: =SUM(Jul!C16, Aug!C16, Sep!C16) -> 67507.749 | D16: =SUM(Jul!D16, Aug!D16, Sep!D16) -> 49080.48 | E16: =IF(AND(ISNUMBER(C16),ISNUMBER(D16)), C16-D16, "") -> 18427.269 | F16: =IFERROR(E16/D16, "") -> 0.37545007 | G16: =SUM(Jul!G16,Aug!G16,Sep!G16) -> 91007 | H16: =SUM(Jul!H16, Aug!H16, Sep!H16) -> -23499.251
A17: DE: Newark - Clayton Hall | B17: DE | C17: =SUM(Jul!C17, Aug!C17, Sep!C17) -> 21726 | D17: =SUM(Jul!D17, Aug!D17, Sep!D17) -> 23826.591 | E17: =IF(AND(ISNUMBER(C17),ISNUMBER(D17)), C17-D17, "") -> -2100.591 | F17: =IFERROR(E17/D17, "") -> -0.088161626 | G17: =SUM(Jul!G17,Aug!G17,Sep!G17) -> 20228.258 | H17: =SUM(Jul!H17, Aug!H17, Sep!H17) -> 1497.742 | I17: =IFERROR(H17/G17, "") -> 0.074042065
A18: DE: Newark - UOD Field House | B18: DE | C18: =SUM(Jul!C18, Aug!C18, Sep!C18) -> 55764 | D18: =SUM(Jul!D18, Aug!D18, Sep!D18) -> 0 | E18: =IF(AND(ISNUMBER(C18),ISNUMBER(D18)), C18-D18, "") -> 55764 | F18: =IFERROR(E18/D18, "") | G18: =SUM(Jul!G18,Aug!G18,Sep!G18) -> 49697 | H18: =SUM(Jul!H18, Aug!H18, Sep!H18) -> 6067
A19: DE: Newark - UOD 461 Wyoming | B19: DE | C19: =SUM(Jul!C19, Aug!C19, Sep!C19) -> 0 | D19: =SUM(Jul!D19, Aug!D19, Sep!D19) -> 36216.917 | E19: =IF(AND(ISNUMBER(C19),ISNUMBER(D19)), C19-D19, "") -> -36216.917 | F19: =IFERROR(E19/D19, "") -> -1 | G19: =SUM(Jul!G19,Aug!G19,Sep!G19) -> 37582.678 | H19: =SUM(Jul!H19, Aug!H19, Sep!H19) -> -37582.678 | I19: =IFERROR(H19/G19, "") -> -1
A20: HI: Waipahu - 94-246 Leoku St - E.F.G. | B20: HI | C20: =SUM(Jul!C20, Aug!C20, Sep!C20) -> 10048 | D20: =SUM(Jul!D20, Aug!D20, Sep!D20) -> 13191.17 | E20: =IF(AND(ISNUMBER(C20),ISNUMBER(D20)), C20-D20, "") -> -3143.17 | F20: =IFERROR(E20/D20, "") -> -0.23827833 | G20: =SUM(Jul!G20,Aug!G20,Sep!G20) -> 13676.54 | H20: =SUM(Jul!H20, Aug!H20, Sep!H20) -> -3628.54
A21: HI: Waipahu - 94-099 Waipahu St - PV | B21: HI | C21: =SUM(Jul!C21, Aug!C21, Sep!C21) -> 14836 | D21: =SUM(Jul!D21, Aug!D21, Sep!D21) -> 11475.55 | E21: =IF(AND(ISNUMBER(C21),ISNUMBER(D21)), C21-D21, "") -> 3360.45 | F21: =IFERROR(E21/D21, "") -> 0.29283564 | G21: =SUM(Jul!G21,Aug!G21,Sep!G21) -> 13669.23 | H21: =SUM(Jul!H21, Aug!H21, Sep!H21) -> 1166.77 | I21: =IFERROR(H21/G21, "") -> 0.085357405
A22: MD: Presston - Bird-in-Hand | B22: MD | C22: =SUM(Jul!C22, Aug!C22, Sep!C22) -> 145779 | D22: =SUM(Jul!D22, Aug!D22, Sep!D22) -> 144638.7 | E22: =IF(AND(ISNUMBER(C22),ISNUMBER(D22)), C22-D22, "") -> 1140.3 | F22: =IFERROR(E22/D22, "") -> 0.0078837821 | G22: =SUM(Jul!G22,Aug!G22,Sep!G22) -> 179658.6 | H22: =SUM(Jul!H22, Aug!H22, Sep!H22) -> -33879.6
A23: MD: Easton - Shortall | B23: MD | C23: =SUM(Jul!C23, Aug!C23, Sep!C23) -> 188462 | D23: =SUM(Jul!D23, Aug!D23, Sep!D23) -> 193996.5 | E23: =IF(AND(ISNUMBER(C23),ISNUMBER(D23)), C23-D23, "") -> -5534.5 | F23: =IFERROR(E23/D23, "") -> -0.028528865 | G23: =SUM(Jul!G23,Aug!G23,Sep!G23) -> 158875.9 | H23: =SUM(Jul!H23, Aug!H23, Sep!H23) -> 29586.1 | I23: =IFERROR(H23/G23, "") -> 0.18622145
A24: MA: Boston - Seaport Solar | B24: MA | C24: =SUM(Jul!C24, Aug!C24, Sep!C24) -> 85397.5 | D24: =SUM(Jul!D24, Aug!D24, Sep!D24) -> 14365.66 | E24: =IF(AND(ISNUMBER(C24),ISNUMBER(D24)), C24-D24, "") -> 71031.84 | F24: =IFERROR(E24/D24, "") -> 4.9445581 | G24: =SUM(Jul!G24,Aug!G24,Sep!G24) -> 86009.04 | H24: =SUM(Jul!H24, Aug!H24, Sep!H24) -> -611.54
A25: MA: Dedham - Sprague Street | B25: MA | C25: =SUM(Jul!C25, Aug!C25, Sep!C25) -> 185825 | D25: =SUM(Jul!D25, Aug!D25, Sep!D25) -> 0 | E25: =IF(AND(ISNUMBER(C25),ISNUMBER(D25)), C25-D25, "") -> 185825 | F25: =IFERROR(E25/D25, "") | G25: =SUM(Jul!G25,Aug!G25,Sep!G25) -> 193250.7 | H25: =SUM(Jul!H25, Aug!H25, Sep!H25) -> -7425.7 | I25: =IFERROR(H25/G25, "") -> -0.038425217
A26: MA: Boston - Summer Street | B26: MA | C26: =SUM(Jul!C26, Aug!C26, Sep!C26) -> 0 | D26: =SUM(Jul!D26, Aug!D26, Sep!D26) -> 64247.81 | E26: =IF(AND(ISNUMBER(C26),ISNUMBER(D26)), C26-D26, "") -> -64247.81 | F26: =IFERROR(E26/D26, "") -> -1 | G26: =SUM(Jul!G26,Aug!G26,Sep!G26) -> 409224.3 | H26: =SUM(Jul!H26, Aug!H26, Sep!H26) -> -409224.3
A27: MA: Leominster - Spectro Coatings | B27: MA | C27: =SUM(Jul!C27, Aug!C27, Sep!C27) -> 38126.625 | D27: =SUM(Jul!D27, Aug!D27, Sep!D27) -> 39199.727 | E27: =IF(AND(ISNUMBER(C27),ISNUMBER(D27)), C27-D27, "") -> -1073.102 | F27: =IFERROR(E27/D27, "") -> -0.027375242 | G27: =SUM(Jul!G27,Aug!G27,Sep!G27) -> 38210.937 | H27: =SUM(Jul!H27, Aug!H27, Sep!H27) -> -84.312 | I27: =IFERROR(H27/G27, "") -> -0.0022064887
A28: MA: Braintree - RCAB | B28: MA | C28: =SUM(Jul!C28, Aug!C28, Sep!C28) -> 147058 | D28: =SUM(Jul!D28, Aug!D28, Sep!D28) -> 182019.3 | E28: =IF(AND(ISNUMBER(C28),ISNUMBER(D28)), C28-D28, "") -> -34961.3 | F28: =IFERROR(E28/D28, "") -> -0.19207469 | G28: =SUM(Jul!G28,Aug!G28,Sep!G28) -> 146482.8 | H28: =SUM(Jul!H28, Aug!H28, Sep!H28) -> 575.2
A29: NH: Rochester - Portland Street | B29: NH | C29: =SUM(Jul!C29, Aug!C29, Sep!C29) -> 11535.627 | D29: =SUM(Jul!D29, Aug!D29, Sep!D29) -> 8215.936 | E29: =IF(AND(ISNUMBER(C29),ISNUMBER(D29)), C29-D29, "") -> 3319.691 | F29: =IFERROR(E29/D29, "") -> 0.40405512 | G29: =SUM(Jul!G29,Aug!G29,Sep!G29) -> 9368.774 | H29: =SUM(Jul!H29, Aug!H29, Sep!H29) -> 2166.853 | I29: =IFERROR(H29/G29, "") -> 0.23128458
A30: NH: Portsmouth - Portsmouth HS | B30: NH | C30: =SUM(Jul!C30, Aug!C30, Sep!C30) -> 44411.625 | D30: =SUM(Jul!D30, Aug!D30, Sep!D30) -> 0 | E30: =IF(AND(ISNUMBER(C30),ISNUMBER(D30)), C30-D30, "") -> 44411.625 | F30: =IFERROR(E30/D30, "") | G30: =SUM(Jul!G30,Aug!G30,Sep!G30) -> 35518.29 | H30: =SUM(Jul!H30, Aug!H30, Sep!H30) -> 8893.335
A31: NH: Portsmouth - Portsmouth WTP | B31: NH | C31: =SUM(Jul!C31, Aug!C31, Sep!C31) -> 0 | D31: =SUM(Jul!D31, Aug!D31, Sep!D31) -> 0 | E31: =IF(AND(ISNUMBER(C31),ISNUMBER(D31)), C31-D31, "") -> 0 | F31: =IFERROR(E31/D31, "") | G31: =SUM(Jul!G31,Aug!G31,Sep!G31) -> 0 | H31: =SUM(Jul!H31, Aug!H31, Sep!H31) -> 0 | I31: =IFERROR(H31/G31, "")
A32: NH: Rochester - Rochester MS | B32: NH | C32: =SUM(Jul!C32, Aug!C32, Sep!C32) -> 38047.617 | D32: =SUM(Jul!D32, Aug!D32, Sep!D32) -> 40396.32 | E32: =IF(AND(ISNUMBER(C32),ISNUMBER(D32)), C32-D32, "") -> -2348.7026 | F32: =IFERROR(E32/D32, "") -> -0.0581415 | G32: =SUM(Jul!G32,Aug!G32,Sep!G32) -> 30355.12 | H32: =SUM(Jul!H32, Aug!H32, Sep!H32) -> 7692.4974
A33: NH Rochester - Spaulding HS | B33: NH | C33: =SUM(Jul!C33, Aug!C33, Sep!C33) -> 19594.5 | D33: =SUM(Jul!D33, Aug!D33, Sep!D33) -> 16446 | E33: =IF(AND(ISNUMBER(C33),ISNUMBER(D33)), C33-D33, "") -> 3148.5 | F33: =IFERROR(E33/D33, "") -> 0.19144473 | G33: =SUM(Jul!G33,Aug!G33,Sep!G33) -> 15033.3 | H33: =SUM(Jul!H33, Aug!H33, Sep!H33) -> 4561.2 | I33: =IFERROR(H33/G33, "") -> 0.30340644
A34: NH: Rochester - McClelland ES | B34: NH | C34: =SUM(Jul!C34, Aug!C34, Sep!C34) -> 13246.875 | D34: =SUM(Jul!D34, Aug!D34, Sep!D34) -> 13989 | E34: =IF(AND(ISNUMBER(C34),ISNUMBER(D34)), C34-D34, "") -> -742.125 | F34: =IFERROR(E34/D34, "") -> -0.053050611 | G34: =SUM(Jul!G34,Aug!G34,Sep!G34) -> 9803.669 | H34: =SUM(Jul!H34, Aug!H34, Sep!H34) -> 3443.206
A35: NH: Rochester - Brock St Vocational | B35: NH | C35: =SUM(Jul!C35, Aug!C35, Sep!C35) -> 17978.129 | D35: =SUM(Jul!D35, Aug!D35, Sep!D35) -> 17518.42 | E35: =IF(AND(ISNUMBER(C35),ISNUMBER(D35)), C35-D35, "") -> 459.70907 | F35: =IFERROR(E35/D35, "") -> 0.026241469 | G35: =SUM(Jul!G35,Aug!G35,Sep!G35) -> 13220.3 | H35: =SUM(Jul!H35, Aug!H35, Sep!H35) -> 4757.8291 | I35: =IFERROR(H35/G35, "") -> 0.35988813
A36: OH: Cleveland - CV Kinsman | B36: OH | C36: =SUM(Jul!C36, Aug!C36, Sep!C36) -> 714.07031 | D36: =SUM(Jul!D36, Aug!D36, Sep!D36) -> 138037.1 | E36: =IF(AND(ISNUMBER(C36),ISNUMBER(D36)), C36-D36, "") -> -137323.03 | F36: =IFERROR(E36/D36, "") -> -0.99482697 | G36: =SUM(Jul!G36,Aug!G36,Sep!G36) -> 133750 | H36: =SUM(Jul!H36, Aug!H36, Sep!H36) -> -133035.93
A37: OH: Cleveland - CV Wooster | B37: OH | C37: =SUM(Jul!C37, Aug!C37, Sep!C37) -> 21528 | D37: =SUM(Jul!D37, Aug!D37, Sep!D37) -> 0 | E37: =IF(AND(ISNUMBER(C37),ISNUMBER(D37)), C37-D37, "") -> 21528 | F37: =IFERROR(E37/D37, "") | G37: =SUM(Jul!G37,Aug!G37,Sep!G37) -> 32092 | H37: =SUM(Jul!H37, Aug!H37, Sep!H37) -> -10564 | I37: =IFERROR(H37/G37, "") -> -0.32917861
A38: PR: Aguadilla - Coca Cola | B38: PR | C38: =SUM(Jul!C38, Aug!C38, Sep!C38) -> 15714 | D38: =SUM(Jul!D38, Aug!D38, Sep!D38) -> 20085.89 | E38: =IF(AND(ISNUMBER(C38),ISNUMBER(D38)), C38-D38, "") -> -4371.89 | F38: =IFERROR(E38/D38, "") -> -0.21765976 | G38: =SUM(Jul!G38,Aug!G38,Sep!G38) -> 23213 | H38: =SUM(Jul!H38, Aug!H38, Sep!H38) -> -7499
A39: PR: Bayamon - Coca Cola | B39: PR | C39: =SUM(Jul!C39, Aug!C39, Sep!C39) -> 53577 | D39: =SUM(Jul!D39, Aug!D39, Sep!D39) -> 82116.61 | E39: =IF(AND(ISNUMBER(C39),ISNUMBER(D39)), C39-D39, "") -> -28539.61 | F39: =IFERROR(E39/D39, "") -> -0.34754978 | G39: =SUM(Jul!G39,Aug!G39,Sep!G39) -> 86974 | H39: =SUM(Jul!H39, Aug!H39, Sep!H39) -> -33397 | I39: =IFERROR(H39/G39, "") -> -0.38398832
A40: PR: Carolina - St. Francis | B40: PR | C40: =SUM(Jul!C40, Aug!C40, Sep!C40) -> 18667 | D40: =SUM(Jul!D40, Aug!D40, Sep!D40) -> 64278.93 | E40: =IF(AND(ISNUMBER(C40),ISNUMBER(D40)), C40-D40, "") -> -45611.93 | F40: =IFERROR(E40/D40, "") -> -0.7095938 | G40: =SUM(Jul!G40,Aug!G40,Sep!G40) -> 44155 | H40: =SUM(Jul!H40, Aug!H40, Sep!H40) -> -25488
...

Sheet 4th Qtr
A1: {=portfolio} -> GoodFinch | D1: 4th Quarter Actual v. Expected | G1: 4th Quarter Actual v. Forecasted
A2: Total | C2: =SUM(C4:C80) -> 0 | D2: =SUM(D4:D80) -> 0 | E2: =C2-D2 -> 0 | F2: =IFERROR(E2/D2, 0) -> 0 | G2: =SUM(G4:G80) -> 0 | H2: =C2-G2 -> 0 | I2: =IFERROR(H2/G2, 0) -> 0
A3: Site | B3: State | C3: Actual | D3: Expected | E3: Delta | F3: % | G3: Forecasted | H3: Delta | I3: %
A4: {=Sites[Site]} -> AZ: Tempe - ASU - Farmer | B4: {=Sites[State]} -> AZ | C4: =SUM(Oct!C4, Nov!C4, Dec!C4) -> 0 | D4: =SUM(Oct!D4, Nov!D4, Dec!D4) -> 0 | E4: =IF(AND(ISNUMBER(C4),ISNUMBER(D4)), C4-D4, "") -> 0 | F4: =IFERROR(E4/D4, "") | G4: =SUM(Oct!G4,Nov!G4,Dec!G4) -> 0 | H4: =SUM(Oct!H4, Nov!H4, Dec!H4) -> 0 | I4: =IFERROR(H4/G4, "")
A5: AZ: Tempe - ASU - Fulton | B5: AZ | C5: =SUM(Oct!C5, Nov!C5, Dec!C5) -> 0 | D5: =SUM(Oct!D5, Nov!D5, Dec!D5) -> 0 | E5: =IF(AND(ISNUMBER(C5),ISNUMBER(D5)), C5-D5, "") -> 0 | F5: =IFERROR(E5/D5, "") | G5: =SUM(Oct!G5,Nov!G5,Dec!G5) -> 0 | H5: =SUM(Oct!H5, Nov!H5, Dec!H5) -> 0 | I5: =IFERROR(H5/G5, "")
A6: AZ: Superior - JFK Elementary | B6: AZ | C6: =SUM(Oct!C6, Nov!C6, Dec!C6) -> 0 | D6: =SUM(Oct!D6, Nov!D6, Dec!D6) -> 0 | E6: =IF(AND(ISNUMBER(C6),ISNUMBER(D6)), C6-D6, "") -> 0 | F6: =IFERROR(E6/D6, "") | G6: =SUM(Oct!G6,Nov!G6,Dec!G6) -> 0 | H6: =SUM(Oct!H6, Nov!H6, Dec!H6) -> 0 | I6: =IFERROR(H6/G6, "")
A7: AZ: Tempe - ASU - Noble | B7: AZ | C7: =SUM(Oct!C7, Nov!C7, Dec!C7) -> 0 | D7: =SUM(Oct!D7, Nov!D7, Dec!D7) -> 0 | E7: =IF(AND(ISNUMBER(C7),ISNUMBER(D7)), C7-D7, "") -> 0 | F7: =IFERROR(E7/D7, "") | G7: =SUM(Oct!G7,Nov!G7,Dec!G7) -> 0 | H7: =SUM(Oct!H7, Nov!H7, Dec!H7) -> 0 | I7: =IFERROR(H7/G7, "")
A8: AZ: Tempe - ASU - Parking #3 | B8: AZ | C8: =SUM(Oct!C8, Nov!C8, Dec!C8) -> 0 | D8: =SUM(Oct!D8, Nov!D8, Dec!D8) -> 0 | E8: =IF(AND(ISNUMBER(C8),ISNUMBER(D8)), C8-D8, "") -> 0 | F8: =IFERROR(E8/D8, "") | G8: =SUM(Oct!G8,Nov!G8,Dec!G8) -> 0 | H8: =SUM(Oct!H8,Nov!H8,Dec!H8) -> 0 | I8: =IFERROR(H8/G8, "")
A9: AZ: Tempe - ASU - PE East | B9: AZ | C9: =SUM(Oct!C9, Nov!C9, Dec!C9) -> 0 | D9: =SUM(Oct!D9, Nov!D9, Dec!D9) -> 0 | E9: =IF(AND(ISNUMBER(C9),ISNUMBER(D9)), C9-D9, "") -> 0 | F9: =IFERROR(E9/D9, "") | G9: =SUM(Oct!G9,Nov!G9,Dec!G9) -> 0 | H9: =SUM(Oct!H9,Nov!H9,Dec!H9) -> 0 | I9: =IFERROR(H9/G9, "")
A10: AZ: Tempe - ASU - Schwada | B10: AZ | C10: =SUM(Oct!C10, Nov!C10, Dec!C10) -> 0 | D10: =SUM(Oct!D10, Nov!D10, Dec!D10) -> 0 | E10: =IF(AND(ISNUMBER(C10),ISNUMBER(D10)), C10-D10, "") -> 0 | F10: =IFERROR(E10/D10, "") | G10: =SUM(Oct!G10,Nov!G10,Dec!G10) -> 0 | H10: =SUM(Oct!H10,Nov!H10,Dec!H10) -> 0 | I10: =IFERROR(H10/G10, "")
A11: AZ: Phoenix - Starshine Academy | B11: AZ | C11: =SUM(Oct!C11, Nov!C11, Dec!C11) -> 0 | D11: =SUM(Oct!D11, Nov!D11, Dec!D11) -> 0 | E11: =IF(AND(ISNUMBER(C11),ISNUMBER(D11)), C11-D11, "") -> 0 | F11: =IFERROR(E11/D11, "") | G11: =SUM(Oct!G11,Nov!G11,Dec!G11) -> 0 | H11: =SUM(Oct!H11,Nov!H11,Dec!H11) -> 0 | I11: =IFERROR(H11/G11, "")
A12: AZ: Yuma Airport | B12: AZ | C12: =SUM(Oct!C12, Nov!C12, Dec!C12) -> 0 | D12: =SUM(Oct!D12, Nov!D12, Dec!D12) -> 0 | E12: =IF(AND(ISNUMBER(C12),ISNUMBER(D12)), C12-D12, "") -> 0 | F12: =IFERROR(E12/D12, "") | G12: =SUM(Oct!G12,Nov!G12,Dec!G12) -> 0 | H12: =SUM(Oct!H12,Nov!H12,Dec!H12) -> 0 | I12: =IFERROR(H12/G12, "")
A13: AZ: Globe - Gila CC | B13: AZ | C13: =SUM(Oct!C13, Nov!C13, Dec!C13) -> 0 | D13: =SUM(Oct!D13, Nov!D13, Dec!D13) -> 0 | E13: =IF(AND(ISNUMBER(C13),ISNUMBER(D13)), C13-D13, "") -> 0 | F13: =IFERROR(E13/D13, "") | G13: =SUM(Oct!G13,Nov!G13,Dec!G13) -> 0 | H13: =SUM(Oct!H13,Nov!H13,Dec!H13) -> 0 | I13: =IFERROR(H13/G13, "")
A14: AZ: Payson - Gila CC | B14: AZ | C14: =SUM(Oct!C14, Nov!C14, Dec!C14) -> 0 | D14: =SUM(Oct!D14, Nov!D14, Dec!D14) -> 0 | E14: =IF(AND(ISNUMBER(C14),ISNUMBER(D14)), C14-D14, "") -> 0 | F14: =IFERROR(E14/D14, "") | G14: =SUM(Oct!G14,Nov!G14,Dec!G14) -> 0 | H14: =SUM(Oct!H14,Nov!H14,Dec!H14) -> 0 | I14: =IFERROR(H14/G14, "")
A15: AZ: Mesa - Sequoia Charter School | B15: AZ | C15: =SUM(Oct!C15, Nov!C15, Dec!C15) -> 0 | D15: =SUM(Oct!D15, Nov!D15, Dec!D15) -> 0 | E15: =IF(AND(ISNUMBER(C15),ISNUMBER(D15)), C15-D15, "") -> 0 | F15: =IFERROR(E15/D15, "") | G15: =SUM(Oct!G15,Nov!G15,Dec!G15) -> 0 | H15: =SUM(Oct!H15,Nov!H15,Dec!H15) -> 0 | I15: =IFERROR(H15/G15, "")
A16: AZ: Tempe - SCNM | B16: AZ | C16: =SUM(Oct!C16, Nov!C16, Dec!C16) -> 0 | D16: =SUM(Oct!D16, Nov!D16, Dec!D16) -> 0 | E16: =IF(AND(ISNUMBER(C16),ISNUMBER(D16)), C16-D16, "") -> 0 | F16: =IFERROR(E16/D16, "") | G16: =SUM(Oct!G16,Nov!G16,Dec!G16) -> 0 | H16: =SUM(Oct!H16,Nov!H16,Dec!H16) -> 0 | I16: =IFERROR(H16/G16, "")
A17: DE: Newark - Clayton Hall | B17: DE | C17: =SUM(Oct!C17, Nov!C17, Dec!C17) -> 0 | D17: =SUM(Oct!D17, Nov!D17, Dec!D17) -> 0 | E17: =IF(AND(ISNUMBER(C17),ISNUMBER(D17)), C17-D17, "") -> 0 | F17: =IFERROR(E17/D17, "") | G17: =SUM(Oct!G17,Nov!G17,Dec!G17) -> 0 | H17: =SUM(Oct!H17,Nov!H17,Dec!H17) -> 0 | I17: =IFERROR(H17/G17, "")
A18: DE: Newark - UOD Field House | B18: DE | C18: =SUM(Oct!C18, Nov!C18, Dec!C18) -> 0 | D18: =SUM(Oct!D18, Nov!D18, Dec!D18) -> 0 | E18: =IF(AND(ISNUMBER(C18),ISNUMBER(D18)), C18-D18, "") -> 0 | F18: =IFERROR(E18/D18, "") | G18: =SUM(Oct!G18,Nov!G18,Dec!G18) -> 0 | H18: =SUM(Oct!H18,Nov!H18,Dec!H18) -> 0 | I18: =IFERROR(H18/G18, "")
A19: DE: Newark - UOD 461 Wyoming | B19: DE | C19: =SUM(Oct!C19, Nov!C19, Dec!C19) -> 0 | D19: =SUM(Oct!D19, Nov!D19, Dec!D19) -> 0 | E19: =IF(AND(ISNUMBER(C19),ISNUMBER(D19)), C19-D19, "") -> 0 | F19: =IFERROR(E19/D19, "") | G19: =SUM(Oct!G19,Nov!G19,Dec!G19) -> 0 | H19: =SUM(Oct!H19,Nov!H19,Dec!H19) -> 0 | I19: =IFERROR(H19/G19, "")
... A45: DC: Washington - Weinberg 3 | B45: DC | C45: =SUM(Oct!C45, Nov!C45, Dec!C45) -> 0 | D45: =SUM(Oct!D45, Nov!D45, Dec!D45) -> 0 | E45: =IF(AND(ISNUMBER(C45),ISNUMBER(D45)), C45-D45, "") -> 0 | F45: =IFERROR(E45/D45, "") | G45: =SUM(Oct!G45,Nov!G45,Dec!G45) -> 0 | H45: =SUM(Oct!H45,Nov!H45,Dec!H45) -> 0 | I45: =IFERROR(H45/G45, "")

Sheet Jan
A1: {=portfolio} -> GoodFinch | E1: January Actual v. Expected | H1: January Actual v. Forecasted
A2: Total | D2: =SUM(D4:D79) -> 0 | E2: =SUM(E4:E79) -> 0 | F2: =D2-E2 -> 0 | G2: =IFERROR(F2/E2, 0) -> 0 | H2: =SUM(H4:H79) -> 0 | I2: =D2-H2 -> 0 | J2: =IFERROR(I2/H2, 0) -> 0 | K2: =IF(AND(TODAY()>DATE(2024, 1, 1), COUNTA(Sites[Site])<>(COUNT(D:D)-1)), "Some sites are missing actual data; if new sites were added, make sure they are aligned correctly (including prior months!)", "") -> Some sites are missing actual data; if new sites were added, make sure they are aligned correctly (including prior months!)
A3: Site | B3: State | C3: SOL# | D3: Actual | E3: Expected | F3: Delta | G3: % | H3: Forecasted | I3: Delta | J3: % | K3: Notes | L3: Service Requests
A4: {=Sites[Site]} -> AZ: Tempe - ASU - Farmer | B4: {=Sites[State]} -> AZ | F4: =IF(AND(ISNUMBER(D4),ISNUMBER(E4)), D4-E4, "") | G4: =IFERROR(F4/E4, "") | I4: =IF(AND(ISNUMBER(D4),ISNUMBER(H4)), D4-H4, "") | J4: =IFERROR(I4/H4, "")
A5: AZ: Tempe - ASU - Fulton | B5: AZ | F5: =IF(AND(ISNUMBER(D5),ISNUMBER(E5)), D5-E5, "") | G5: =IFERROR(F5/E5, "") | I5: =IF(AND(ISNUMBER(D5),ISNUMBER(H5)), D5-H5, "") | J5: =IFERROR(I5/H5, "")
A6: AZ: Superior - JFK Elementary | B6: AZ | F6: =IF(AND(ISNUMBER(D6),ISNUMBER(E6)), D6-E6, "") | G6: =IFERROR(F6/E6, "") | I6: =IF(AND(ISNUMBER(D6),ISNUMBER(H6)), D6-H6, "") | J6: =IFERROR(I6/H6, "")
A7: AZ: Tempe - ASU - Noble | B7: AZ | F7: =IF(AND(ISNUMBER(D7),ISNUMBER(E7)), D7-E7, "") | G7: =IFERROR(F7/E7, "") | I7: =IF(AND(ISNUMBER(D7),ISNUMBER(H7)), D7-H7, "") | J7: =IFERROR(I7/H7, "")
A8: AZ: Tempe - ASU - Parking #3 | B8: AZ | F8: =IF(AND(ISNUMBER(D8),ISNUMBER(E8)), D8-E8, "") | G8: =IFERROR(F8/E8, "") | I8: =IF(AND(ISNUMBER(D8),ISNUMBER(H8)), D8-H8, "") | J8: =IFERROR(I8/H8, "")
A9: AZ: Tempe - ASU - PE East | B9: AZ | F9: =IF(AND(ISNUMBER(D9),ISNUMBER(E9)), D9-E9, "") | G9: =IFERROR(F9/E9, "") | I9: =IF(AND(ISNUMBER(D9),ISNUMBER(H9)), D9-H9, "") | J9: =IFERROR(I9/H9, "")
A10: AZ: Tempe - ASU - Schwada | B10: AZ | F10: =IF(AND(ISNUMBER(D10),ISNUMBER(E10)), D10-E10, "") | G10: =IFERROR(F10/E10, "") | I10: =IF(AND(ISNUMBER(D10),ISNUMBER(H10)), D10-H10, "") | J10: =IFERROR(I10/H10, "")
A11: AZ: Phoenix - Starshine Academy | B11: AZ | F11: =IF(AND(ISNUMBER(D11),ISNUMBER(E11)), D11-E11, "") | G11: =IFERROR(F11/E11, "") | I11: =IF(AND(ISNUMBER(D11),ISNUMBER(H11)), D11-H11, "") | J11: =IFERROR(I11/H11, "")
A12: AZ: Yuma Airport | B12: AZ | F12: =IF(AND(ISNUMBER(D12),ISNUMBER(E12)), D12-E12, "") | G12: =IFERROR(F12/E12, "") | I12: =IF(AND(ISNUMBER(D12),ISNUMBER(H12)), D12-H12, "") | J12: =IFERROR(I12/H12, "")
A13: AZ: Globe - Gila CC | B13: AZ | F13: =IF(AND(ISNUMBER(D13),ISNUMBER(E13)), D13-E13, "") | G13: =IFERROR(F13/E13, "") | I13: =IF(AND(ISNUMBER(D13),ISNUMBER(H13)), D13-H13, "") | J13: =IFERROR(I13/H13, "")
