Workbook
Name JanActual: #REF!
Name JanActual2: #REF!
Name JanExpected: #REF!
Name JanExpectedDelta: #REF!
Name JanExpectedPercent: #REF!
Name JanExpPercent: #REF!
Name JanForecasted: #REF!
Name JanForecastedDelta: #REF!
Name JanForecastedPercent: #REF!
Name portfolio: Sites!$B$1:$B$1
Name Year: Sites!#REF!

Sheet Year to Date
A1: {=portfolio} -> Generate Capital | E1: Year to Date Actual v. Expected | H1: Year to Date Actual v. Forecasted
A2: Total | D2: =SUM(D4:D160) -> 2.4723902e+08 | E2: =SUM(E4:E160) -> 1.2967e+08 | F2: =D2-E2 -> 1.1756901e+08 | G2: =IFERROR(F2/E2, 0) -> 0.90667857 | H2: =SUM(H4:H160) -> 2.7116999e+08 | I2: =D2-H2 -> -23930978 | J2: =IFERROR(I2/H2, 0) -> -0.088250835
A3: Site | B3: State | C3: SOL# | D3: Actual | E3: Expected | F3: Delta | G3: % | H3: Forecasted | I3: Delta | J3: %
A4: {=Sites[Site]} -> K026 | B4: {=Sites[State]} -> NY | C4: =Sites[[#This Row],[SOL'#]] -> SOL-10356 | D4: =SUM('1st Qtr'!D4,'2nd Qtr'!D4,'3rd Qtr'!D4,'4th Qtr'!D4) -> 149928.75 | E4: =SUM('1st Qtr'!E4, '2nd Qtr'!E4, '3rd Qtr'!E4, '4th Qtr'!E4) -> 221211.41 | F4: =IF(AND(ISNUMBER(D4),ISNUMBER(E4)), D4-E4, "") -> -71282.66 | G4: =IFERROR(F4/E4, "") -> -0.32223772 | H4: =SUM('1st Qtr'!H4,'2nd Qtr'!H4,'3rd Qtr'!H4,'4th Qtr'!H4) -> 200186.5 | I4: =SUM('1st Qtr'!I4, '2nd Qtr'!I4, '3rd Qtr'!I4, '4th Qtr'!I4) -> -50257.75 | J4: =IFERROR(I4/H4, "") -> -0.25105464
A5: K041 | B5: NY | C5: =Sites[[#This Row],[SOL'#]] -> SOL-10357 | D5: =SUM('1st Qtr'!D5,'2nd Qtr'!D5,'3rd Qtr'!D5,'4th Qtr'!D5) -> 151796.16 | E5: =SUM('1st Qtr'!E5, '2nd Qtr'!E5, '3rd Qtr'!E5, '4th Qtr'!E5) -> 178168.56 | F5: =IF(AND(ISNUMBER(D5),ISNUMBER(E5)), D5-E5, "") -> -26372.404 | G5: =IFERROR(F5/E5, "") -> -0.1480194 | H5: =SUM('1st Qtr'!H5,'2nd Qtr'!H5,'3rd Qtr'!H5,'4th Qtr'!H5) -> 167391 | I5: =SUM('1st Qtr'!I5, '2nd Qtr'!I5, '3rd Qtr'!I5, '4th Qtr'!I5) -> -15594.844 | J5: =IFERROR(I5/H5, "") -> -0.093164171
A6: K043 | B6: NY | C6: =Sites[[#This Row],[SOL'#]] -> SOL-10358 | D6: =SUM('1st Qtr'!D6,'2nd Qtr'!D6,'3rd Qtr'!D6,'4th Qtr'!D6) -> 180969.84 | E6: =SUM('1st Qtr'!E6, '2nd Qtr'!E6, '3rd Qtr'!E6, '4th Qtr'!E6) -> 197536.27 | F6: =IF(AND(ISNUMBER(D6),ISNUMBER(E6)), D6-E6, "") -> -16566.425 | G6: =IFERROR(F6/E6, "") -> -0.083865231 | H6: =SUM('1st Qtr'!H6,'2nd Qtr'!H6,'3rd Qtr'!H6,'4th Qtr'!H6) -> 36825.423 | I6: =SUM('1st Qtr'!I6, '2nd Qtr'!I6, '3rd Qtr'!I6, '4th Qtr'!I6) -> 144144.42 | J6: =IFERROR(I6/H6, "") -> 3.9142638
A7: K058 | B7: NY | C7: =Sites[[#This Row],[SOL'#]] -> SOL-10360 | D7: =SUM('1st Qtr'!D7,'2nd Qtr'!D7,'3rd Qtr'!D7,'4th Qtr'!D7) -> 12634.75 | E7: =SUM('1st Qtr'!E7, '2nd Qtr'!E7, '3rd Qtr'!E7, '4th Qtr'!E7) -> 22177.693 | F7: =IF(AND(ISNUMBER(D7),ISNUMBER(E7)), D7-E7, "") -> -9542.943 | G7: =IFERROR(F7/E7, "") -> -0.43029467 | H7: =SUM('1st Qtr'!H7,'2nd Qtr'!H7,'3rd Qtr'!H7,'4th Qtr'!H7) -> 128228.25 | I7: =SUM('1st Qtr'!I7, '2nd Qtr'!I7, '3rd Qtr'!I7, '4th Qtr'!I7) -> -115593.5 | J7: =IFERROR(I7/H7, "") -> -0.90146672
A8: K115 | B8: NY | C8: =Sites[[#This Row],[SOL'#]] -> SOL-10361 | D8: =SUM('1st Qtr'!D8,'2nd Qtr'!D8,'3rd Qtr'!D8,'4th Qtr'!D8) -> 35343.289 | E8: =SUM('1st Qtr'!E8, '2nd Qtr'!E8, '3rd Qtr'!E8, '4th Qtr'!E8) -> 75921.396 | F8: =IF(AND(ISNUMBER(D8),ISNUMBER(E8)), D8-E8, "") -> -40578.107 | G8: =IFERROR(F8/E8, "") -> -0.53447525 | H8: =SUM('1st Qtr'!H8,'2nd Qtr'!H8,'3rd Qtr'!H8,'4th Qtr'!H8) -> 94992.734 | I8: =SUM('1st Qtr'!I8, '2nd Qtr'!I8, '3rd Qtr'!I8, '4th Qtr'!I8) -> -59649.445 | J8: =IFERROR(I8/H8, "") -> -0.62793692
A9: K152 | B9: NY | C9: =Sites[[#This Row],[SOL'#]] -> SOL-10362 | D9: =SUM('1st Qtr'!D9,'2nd Qtr'!D9,'3rd Qtr'!D9,'4th Qtr'!D9) -> 55565.938 | E9: =SUM('1st Qtr'!E9, '2nd Qtr'!E9, '3rd Qtr'!E9, '4th Qtr'!E9) -> 59673.301 | F9: =IF(AND(ISNUMBER(D9),ISNUMBER(E9)), D9-E9, "") -> -4107.3635 | G9: =IFERROR(F9/E9, "") -> -0.068830841 | H9: =SUM('1st Qtr'!H9,'2nd Qtr'!H9,'3rd Qtr'!H9,'4th Qtr'!H9) -> 58322 | I9: =SUM('1st Qtr'!I9, '2nd Qtr'!I9, '3rd Qtr'!I9, '4th Qtr'!I9) -> -2756.0625 | J9: =IFERROR(I9/H9, "") -> -0.047255967
A10: K166 | B10: NY | C10: =Sites[[#This Row],[SOL'#]] -> SOL-10363 | D10: =SUM('1st Qtr'!D10,'2nd Qtr'!D10,'3rd Qtr'!D10,'4th Qtr'!D10) -> 203766.62 | E10: =SUM('1st Qtr'!E10, '2nd Qtr'!E10, '3rd Qtr'!E10, '4th Qtr'!E10) -> 227379.3 | F10: =IF(AND(ISNUMBER(D10),ISNUMBER(E10)), D10-E10, "") -> -23612.675 | G10: =IFERROR(F10/E10, "") -> -0.10384707 | H10: =SUM('1st Qtr'!H10,'2nd Qtr'!H10,'3rd Qtr'!H10,'4th Qtr'!H10) -> 211999.74 | I10: =SUM('1st Qtr'!I10, '2nd Qtr'!I10, '3rd Qtr'!I10, '4th Qtr'!I10) -> -8233.115 | J10: =IFERROR(I10/H10, "") -> -0.038835496
A11: K206 | B11: NY | C11: =Sites[[#This Row],[SOL'#]] -> SOL-10927 | D11: =SUM('1st Qtr'!D11,'2nd Qtr'!D11,'3rd Qtr'!D11,'4th Qtr'!D11) -> 121718.82 | E11: =SUM('1st Qtr'!E11, '2nd Qtr'!E11, '3rd Qtr'!E11, '4th Qtr'!E11) -> 125569.42 | F11: =IF(AND(ISNUMBER(D11),ISNUMBER(E11)), D11-E11, "") -> -3850.596 | G11: =IFERROR(F11/E11, "") -> -0.030665078 | H11: =SUM('1st Qtr'!H11,'2nd Qtr'!H11,'3rd Qtr'!H11,'4th Qtr'!H11) -> 122542 | I11: =SUM('1st Qtr'!I11, '2nd Qtr'!I11, '3rd Qtr'!I11, '4th Qtr'!I11) -> -823.17602 | J11: =IFERROR(I11/H11, "") -> -0.0067175011
A12: K251 | B12: NY | C12: =Sites[[#This Row],[SOL'#]] -> SOL-10365 | D12: =SUM('1st Qtr'!D12,'2nd Qtr'!D12,'3rd Qtr'!D12,'4th Qtr'!D12) -> 115075.75 | E12: =SUM('1st Qtr'!E12, '2nd Qtr'!E12, '3rd Qtr'!E12, '4th Qtr'!E12) -> 0 | F12: =IF(AND(ISNUMBER(D12),ISNUMBER(E12)), D12-E12, "") -> 115075.75 | G12: =IFERROR(F12/E12, "") | H12: =SUM('1st Qtr'!H12,'2nd Qtr'!H12,'3rd Qtr'!H12,'4th Qtr'!H12) -> 135807.2 | I12: =SUM('1st Qtr'!I12, '2nd Qtr'!I12, '3rd Qtr'!I12, '4th Qtr'!I12) -> -20731.452 | J12: =IFERROR(I12/H12, "") -> -0.15265355
A13: K269 | B13: NY | C13: =Sites[[#This Row],[SOL'#]] -> SOL-10366 | D13: =SUM('1st Qtr'!D13,'2nd Qtr'!D13,'3rd Qtr'!D13,'4th Qtr'!D13) -> 120744.44 | E13: =SUM('1st Qtr'!E13, '2nd Qtr'!E13, '3rd Qtr'!E13, '4th Qtr'!E13) -> 146697.03 | F13: =IF(AND(ISNUMBER(D13),ISNUMBER(E13)), D13-E13, "") -> -25952.592 | G13: =IFERROR(F13/E13, "") -> -0.17691287 | H13: =SUM('1st Qtr'!H13,'2nd Qtr'!H13,'3rd Qtr'!H13,'4th Qtr'!H13) -> 131529.77 | I13: =SUM('1st Qtr'!I13, '2nd Qtr'!I13, '3rd Qtr'!I13, '4th Qtr'!I13) -> -10785.334 | J13: =IFERROR(I13/H13, "") -> -0.081999188
A14: K273 | B14: NY | C14: =Sites[[#This Row],[SOL'#]] -> SOL-10367 | D14: =SUM('1st Qtr'!D14,'2nd Qtr'!D14,'3rd Qtr'!D14,'4th Qtr'!D14) -> 120161.06 | E14: =SUM('1st Qtr'!E14, '2nd Qtr'!E14, '3rd Qtr'!E14, '4th Qtr'!E14) -> 0 | F14: =IF(AND(ISNUMBER(D14),ISNUMBER(E14)), D14-E14, "") -> 120161.06 | G14: =IFERROR(F14/E14, "") | H14: =SUM('1st Qtr'!H14,'2nd Qtr'!H14,'3rd Qtr'!H14,'4th Qtr'!H14) -> 162684 | I14: =SUM('1st Qtr'!I14, '2nd Qtr'!I14, '3rd Qtr'!I14, '4th Qtr'!I14) -> -42522.938 | J14: =IFERROR(I14/H14, "") -> -0.26138365
A15: K287 | B15: NY | C15: =Sites[[#This Row],[SOL'#]] -> SOL-10919 | D15: =SUM('1st Qtr'!D15,'2nd Qtr'!D15,'3rd Qtr'!D15,'4th Qtr'!D15) -> 106034.62 | E15: =SUM('1st Qtr'!E15, '2nd Qtr'!E15, '3rd Qtr'!E15, '4th Qtr'!E15) -> 96143.305 | F15: =IF(AND(ISNUMBER(D15),ISNUMBER(E15)), D15-E15, "") -> 9891.32 | G15: =IFERROR(F15/E15, "") -> 0.10288101 | H15: =SUM('1st Qtr'!H15,'2nd Qtr'!H15,'3rd Qtr'!H15,'4th Qtr'!H15) -> 115436 | I15: =SUM('1st Qtr'!I15, '2nd Qtr'!I15, '3rd Qtr'!I15, '4th Qtr'!I15) -> -9401.375 | J15: =IFERROR(I15/H15, "") -> -0.081442314
A16: K298 | B16: NY | C16: =Sites[[#This Row],[SOL'#]] -> SOL-10368 | D16: =SUM('1st Qtr'!D16,'2nd Qtr'!D16,'3rd Qtr'!D16,'4th Qtr'!D16) -> 112198.84 | E16: =SUM('1st Qtr'!E16, '2nd Qtr'!E16, '3rd Qtr'!E16, '4th Qtr'!E16) -> 126595.69 | F16: =IF(AND(ISNUMBER(D16),ISNUMBER(E16)), D16-E16, "") -> -14396.846 | G16: =IFERROR(F16/E16, "") -> -0.11372304 | H16: =SUM('1st Qtr'!H16,'2nd Qtr'!H16,'3rd Qtr'!H16,'4th Qtr'!H16) -> 128708 | I16: =SUM('1st Qtr'!I16, '2nd Qtr'!I16, '3rd Qtr'!I16, '4th Qtr'!I16) -> -16509.156 | J16: =IFERROR(I16/H16, "") -> -0.1282683
... A158: Wellsville - Chenunda Creek | B158: NY | C158: =Sites[[#This Row],[SOL'#]] -> SOL-11187 | D158: =SUM('1st Qtr'!D158,'2nd Qtr'!D158,'3rd Qtr'!D158,'4th Qtr'!D158) -> 1990664.7 | E158: =SUM('1st Qtr'!E158, '2nd Qtr'!E158, '3rd Qtr'!E158, '4th Qtr'!E158) -> 619787 | F158: =IF(AND(ISNUMBER(D158),ISNUMBER(E158)), D158-E158, "") -> 1370877.7 | G158: =IFERROR(F158/E158, "") -> 2.2118529 | H158: =SUM('1st Qtr'!H158,'2nd Qtr'!H158,'3rd Qtr'!H158,'4th Qtr'!H158) -> 381833 | I158: =SUM('1st Qtr'!I158, '2nd Qtr'!I158, '3rd Qtr'!I158, '4th Qtr'!I158) -> 167439.8 | J158: =IFERROR(I158/H158, "") -> 0.43851579

Sheet 1st Qtr
A1: {=portfolio} -> Generate Capital | E1: 1st Quarter Actual v. Expected | H1: 1st Quarter Actual v. Forecasted
A2: Total | D2: =SUM(D4:D160) -> 73117123 | E2: =SUM(E4:E160) -> 31548905 | F2: =D2-E2 -> 41568218 | G2: =IFERROR(F2/E2, 0) -> 1.3175804 | H2: =SUM(H4:H196) -> 79089883 | I2: =D2-H2 -> -5972759.7 | J2: =IFERROR(I2/H2, 0) -> -0.075518631
A3: Site | B3: State | C3: SOL# | D3: Actual | E3: Expected | F3: Delta | G3: % | H3: Forecasted | I3: Delta | J3: %
A4: {=Sites[Site]} -> K026 | B4: {=Sites[State]} -> NY | C4: =Sites[[#This Row],[SOL'#]] -> SOL-10356 | D4: =SUM(Jan!D4,Feb!D4,Mar!D4) -> 59541.5 | E4: =SUM(Jan!E4,Feb!E4,Mar!E4) -> 72002.03 | F4: =IF(AND(ISNUMBER(D4),ISNUMBER(E4)), D4-E4, "") -> -12460.53 | G4: =IFERROR(F4/E4, "") -> -0.17305804 | H4: =SUM(Jan!H4,Feb!H4,Mar!H4) -> 50886.23 | I4: =SUM(Jan!I4,Feb!I4,Mar!I4) -> 8655.27 | J4: =IFERROR(I4/H4, "") -> 0.17009061
A5: K041 | B5: NY | C5: =Sites[[#This Row],[SOL'#]] -> SOL-10357 | D5: =SUM(Jan!D5,Feb!D5,Mar!D5) -> 45035.969 | E5: =SUM(Jan!E5,Feb!E5,Mar!E5) -> 56199.33 | F5: =IF(AND(ISNUMBER(D5),ISNUMBER(E5)), D5-E5, "") -> -11163.361 | G5: =IFERROR(F5/E5, "") -> -0.19863869 | H5: =SUM(Jan!H5,Feb!H5,Mar!H5) -> 46068 | I5: =SUM(Jan!I5,Feb!I5,Mar!I5) -> -1032.0312 | J5: =IFERROR(I5/H5, "") -> -0.022402345
A6: K043 | B6: NY | C6: =Sites[[#This Row],[SOL'#]] -> SOL-10358 | D6: =SUM(Jan!D6,Feb!D6,Mar!D6) -> 53077.094 | E6: =SUM(Jan!E6,Feb!E6,Mar!E6) -> 62413.61 | F6: =IF(AND(ISNUMBER(D6),ISNUMBER(E6)), D6-E6, "") -> -9336.5163 | G6: =IFERROR(F6/E6, "") -> -0.14959103 | H6: =SUM(Jan!H6,Feb!H6,Mar!H6) -> 10325 | I6: =SUM(Jan!I6,Feb!I6,Mar!I6) -> 42752.094 | J6: =IFERROR(I6/H6, "") -> 4.1406386
A7: K058 | B7: NY | C7: =Sites[[#This Row],[SOL'#]] -> SOL-10360 | D7: =SUM(Jan!D7,Feb!D7,Mar!D7) -> 12634.75 | E7: =SUM(Jan!E7,Feb!E7,Mar!E7) -> 22177.693 | F7: =IF(AND(ISNUMBER(D7),ISNUMBER(E7)), D7-E7, "") -> -9542.943 | G7: =IFERROR(F7/E7, "") -> -0.43029467 | H7: =SUM(Jan!H7,Feb!H7,Mar!H7) -> 39956.249 | I7: =SUM(Jan!I7,Feb!I7,Mar!I7) -> -27321.499 | J7: =IFERROR(I7/H7, "") -> -0.68378538
A8: K115 | B8: NY | C8: =Sites[[#This Row],[SOL'#]] -> SOL-10361 | D8: =SUM(Jan!D8,Feb!D8,Mar!D8) -> 11799.117 | E8: =SUM(Jan!E8,Feb!E8,Mar!E8) -> 26169.976 | F8: =IF(AND(ISNUMBER(D8),ISNUMBER(E8)), D8-E8, "") -> -14370.859 | G8: =IFERROR(F8/E8, "") -> -0.54913535 | H8: =SUM(Jan!H8,Feb!H8,Mar!H8) -> 25362.094 | I8: =SUM(Jan!I8,Feb!I8,Mar!I8) -> -13562.977 | J8: =IFERROR(I8/H8, "") -> -0.53477354
A9: K152 | B9: NY | C9: =Sites[[#This Row],[SOL'#]] -> SOL-10362 | D9: =SUM(Jan!D9,Feb!D9,Mar!D9) -> 16402.188 | E9: =SUM(Jan!E9,Feb!E9,Mar!E9) -> 18944.047 | F9: =IF(AND(ISNUMBER(D9),ISNUMBER(E9)), D9-E9, "") -> -2541.8595 | G9: =IFERROR(F9/E9, "") -> -0.13417722 | H9: =SUM(Jan!H9,Feb!H9,Mar!H9) -> 15415 | I9: =SUM(Jan!I9,Feb!I9,Mar!I9) -> 987.1875 | J9: =IFERROR(I9/H9, "") -> 0.064040707
A10: K166 | B10: NY | C10: =Sites[[#This Row],[SOL'#]] -> SOL-10363 | D10: =SUM(Jan!D10,Feb!D10,Mar!D10) -> 58816.625 | E10: =SUM(Jan!E10,Feb!E10,Mar!E10) -> 71150.65 | F10: =IF(AND(ISNUMBER(D10),ISNUMBER(E10)), D10-E10, "") -> -12334.025 | G10: =IFERROR(F10/E10, "") -> -0.17335084 | H10: =SUM(Jan!H10,Feb!H10,Mar!H10) -> 54476.13 | I10: =SUM(Jan!I10,Feb!I10,Mar!I10) -> 4340.495 | J10: =IFERROR(I10/H10, "") -> 0.079677007
A11: K206 | B11: NY | C11: =Sites[[#This Row],[SOL'#]] -> SOL-10927 | D11: =SUM(Jan!D11,Feb!D11,Mar!D11) -> 35230.824 | E11: =SUM(Jan!E11,Feb!E11,Mar!E11) -> 42404.21 | F11: =IF(AND(ISNUMBER(D11),ISNUMBER(E11)), D11-E11, "") -> -7173.386 | G11: =IFERROR(F11/E11, "") -> -0.16916684 | H11: =SUM(Jan!H11,Feb!H11,Mar!H11) -> 32033 | I11: =SUM(Jan!I11,Feb!I11,Mar!I11) -> 3197.824 | J11: =IFERROR(I11/H11, "") -> 0.099829051
A12: K251 | B12: NY | C12: =Sites[[#This Row],[SOL'#]] -> SOL-10365 | D12: =SUM(Jan!D12,Feb!D12,Mar!D12) -> 39545.375 | E12: =SUM(Jan!E12,Feb!E12,Mar!E12) -> 0 | F12: =IF(AND(ISNUMBER(D12),ISNUMBER(E12)), D12-E12, "") -> 39545.375 | G12: =IFERROR(F12/E12, "") | H12: =SUM(Jan!H12,Feb!H12,Mar!H12) -> 36320.712 | I12: =SUM(Jan!I12,Feb!I12,Mar!I12) -> 3224.663 | J12: =IFERROR(I12/H12, "") -> 0.088783034
A13: K269 | B13: NY | C13: =Sites[[#This Row],[SOL'#]] -> SOL-10366 | D13: =SUM(Jan!D13,Feb!D13,Mar!D13) -> 35207.875 | E13: =SUM(Jan!E13,Feb!E13,Mar!E13) -> 46926.1 | F13: =IF(AND(ISNUMBER(D13),ISNUMBER(E13)), D13-E13, "") -> -11718.225 | G13: =IFERROR(F13/E13, "") -> -0.24971658 | H13: =SUM(Jan!H13,Feb!H13,Mar!H13) -> 35757.562 | I13: =SUM(Jan!I13,Feb!I13,Mar!I13) -> -549.687 | J13: =IFERROR(I13/H13, "") -> -0.015372608
A14: K273 | B14: NY | C14: =Sites[[#This Row],[SOL'#]] -> SOL-10367 | D14: =SUM(Jan!D14,Feb!D14,Mar!D14) -> 37234.688 | E14: =SUM(Jan!E14,Feb!E14,Mar!E14) -> 0 | F14: =IF(AND(ISNUMBER(D14),ISNUMBER(E14)), D14-E14, "") -> 37234.688 | G14: =IFERROR(F14/E14, "") | H14: =SUM(Jan!H14,Feb!H14,Mar!H14) -> 42215 | I14: =SUM(Jan!I14,Feb!I14,Mar!I14) -> -4980.3125 | J14: =IFERROR(I14/H14, "") -> -0.11797495
A15: K287 | B15: NY | C15: =Sites[[#This Row],[SOL'#]] -> SOL-10919 | D15: =SUM(Jan!D15,Feb!D15,Mar!D15) -> 31794.094 | E15: =SUM(Jan!E15,Feb!E15,Mar!E15) -> 31809.195 | F15: =IF(AND(ISNUMBER(D15),ISNUMBER(E15)), D15-E15, "") -> -15.10125 | G15: =IFERROR(F15/E15, "") -> -0.0004747448 | H15: =SUM(Jan!H15,Feb!H15,Mar!H15) -> 31948 | I15: =SUM(Jan!I15,Feb!I15,Mar!I15) -> -153.90625 | J15: =IFERROR(I15/H15, "") -> -0.0048173986
A16: K298 | B16: NY | C16: =Sites[[#This Row],[SOL'#]] -> SOL-10368 | D16: =SUM(Jan!D16,Feb!D16,Mar!D16) -> 30988.312 | E16: =SUM(Jan!E16,Feb!E16,Mar!E16) -> 41019.48 | F16: =IF(AND(ISNUMBER(D16),ISNUMBER(E16)), D16-E16, "") -> -10031.168 | G16: =IFERROR(F16/E16, "") -> -0.24454643 | H16: =SUM(Jan!H16,Feb!H16,Mar!H16) -> 32201 | I16: =SUM(Jan!I16,Feb!I16,Mar!I16) -> -1212.6875 | J16: =IFERROR(I16/H16, "") -> -0.037659933
... A158: Wellsville - Chenunda Creek | B158: NY | C158: =Sites[[#This Row],[SOL'#]] -> SOL-11187 | D158: =SUM(Jan!D158,Feb!D158,Mar!D158) -> 367949.8 | E158: =SUM(Jan!E158,Feb!E158,Mar!E158) -> 0 | F158: =IF(AND(ISNUMBER(D158),ISNUMBER(E158)), D158-E158, "") -> 367949.8 | G158: =IFERROR(F158/E158, "") | H158: =SUM(Jan!H158,Feb!H158,Mar!H158) -> 0 | I158: =SUM(Jan!I158,Feb!I158,Mar!I158) -> 367949.8 | J158: =IFERROR(I158/H158, "")

Sheet 2nd Qtr
A1: {=portfolio} -> Generate Capital | E1: 2nd Quarter Actual v. Expected | H1: 2nd Quarter Actual v. Forecasted
A2: Total | D2: =SUM(D4:D158) -> 1.2092887e+08 | E2: =SUM(E4:E160) -> 46591752 | F2: =D2-E2 -> 74337118 | G2: =IFERROR(F2/E2, 0) -> 1.5954995 | H2: =SUM(H4:H158) -> 1.4154025e+08 | I2: =D2-H2 -> -20611383 | J2: =IFERROR(I2/H2, 0) -> -0.14562206
A3: Site | B3: State | C3: SOL# | D3: Actual | E3: Expected | F3: Delta | G3: % | H3: Forecasted | I3: Delta | J3: %
A4: {=Sites[Site]} -> K026 | B4: {=Sites[State]} -> NY | C4: =Sites[[#This Row],[SOL'#]] -> SOL-10356 | D4: =SUM(Apr!D4,May!D4,Jun!D4) -> 68306.5 | E4: =SUM(Apr!E4,May!E4,Jun!E4) -> 106688.99 | F4: =IF(AND(ISNUMBER(D4),ISNUMBER(E4)), D4-E4, "") -> -38382.49 | G4: =IFERROR(F4/E4, "") -> -0.35976055 | H4: =SUM(Apr!H4,May!H4,Jun!H4) -> 111665.88 | I4: =SUM(Apr!I4,May!I4,Jun!I4) -> -43359.38 | J4: =IFERROR(I4/H4, "") -> -0.38829569
A5: K041 | B5: NY | C5: =Sites[[#This Row],[SOL'#]] -> SOL-10357 | D5: =SUM(Apr!D5,May!D5,Jun!D5) -> 75953.406 | E5: =SUM(Apr!E5,May!E5,Jun!E5) -> 86786.34 | F5: =IF(AND(ISNUMBER(D5),ISNUMBER(E5)), D5-E5, "") -> -10832.934 | G5: =IFERROR(F5/E5, "") -> -0.12482303 | H5: =SUM(Apr!H5,May!H5,Jun!H5) -> 88785 | I5: =SUM(Apr!I5,May!I5,Jun!I5) -> -12831.594 | J5: =IFERROR(I5/H5, "") -> -0.14452434
A6: K043 | B6: NY | C6: =Sites[[#This Row],[SOL'#]] -> SOL-10358 | D6: =SUM(Apr!D6,May!D6,Jun!D6) -> 92752.25 | E6: =SUM(Apr!E6,May!E6,Jun!E6) -> 95284.617 | F6: =IF(AND(ISNUMBER(D6),ISNUMBER(E6)), D6-E6, "") -> -2532.3665 | G6: =IFERROR(F6/E6, "") -> -0.026576866 | H6: =SUM(Apr!H6,May!H6,Jun!H6) -> 19497.39 | I6: =SUM(Apr!I6,May!I6,Jun!I6) -> 73254.86 | J6: =IFERROR(I6/H6, "") -> 3.7571624
A7: K058 | B7: NY | C7: =Sites[[#This Row],[SOL'#]] -> SOL-10360 | D7: =SUM(Apr!D7,May!D7,Jun!D7) -> 0 | E7: =SUM(Apr!E7,May!E7,Jun!E7) -> 0 | F7: =IF(AND(ISNUMBER(D7),ISNUMBER(E7)), D7-E7, "") -> 0 | G7: =IFERROR(F7/E7, "") | H7: =SUM(Apr!H7,May!H7,Jun!H7) -> 59563 | I7: =SUM(Apr!I7,May!I7,Jun!I7) -> -59563 | J7: =IFERROR(I7/H7, "") -> -1
A8: K115 | B8: NY | C8: =Sites[[#This Row],[SOL'#]] -> SOL-10361 | D8: =SUM(Apr!D8,May!D8,Jun!D8) -> 17549.203 | E8: =SUM(Apr!E8,May!E8,Jun!E8) -> 33770.05 | F8: =IF(AND(ISNUMBER(D8),ISNUMBER(E8)), D8-E8, "") -> -16220.847 | G8: =IFERROR(F8/E8, "") -> -0.48033233 | H8: =SUM(Apr!H8,May!H8,Jun!H8) -> 50850.15 | I8: =SUM(Apr!I8,May!I8,Jun!I8) -> -33300.947 | J8: =IFERROR(I8/H8, "") -> -0.65488395
A9: K152 | B9: NY | C9: =Sites[[#This Row],[SOL'#]] -> SOL-10362 | D9: =SUM(Apr!D9,May!D9,Jun!D9) -> 27928.25 | E9: =SUM(Apr!E9,May!E9,Jun!E9) -> 29089.714 | F9: =IF(AND(ISNUMBER(D9),ISNUMBER(E9)), D9-E9, "") -> -1161.464 | G9: =IFERROR(F9/E9, "") -> -0.039926965 | H9: =SUM(Apr!H9,May!H9,Jun!H9) -> 32067 | I9: =SUM(Apr!I9,May!I9,Jun!I9) -> -4138.75 | J9: =IFERROR(I9/H9, "") -> -0.12906571
A10: K166 | B10: NY | C10: =Sites[[#This Row],[SOL'#]] -> SOL-10363 | D10: =SUM(Apr!D10,May!D10,Jun!D10) -> 102875.5 | E10: =SUM(Apr!E10,May!E10,Jun!E10) -> 110758.07 | F10: =IF(AND(ISNUMBER(D10),ISNUMBER(E10)), D10-E10, "") -> -7882.57 | G10: =IFERROR(F10/E10, "") -> -0.071169261 | H10: =SUM(Apr!H10,May!H10,Jun!H10) -> 117571.05 | I10: =SUM(Apr!I10,May!I10,Jun!I10) -> -14695.55 | J10: =IFERROR(I10/H10, "") -> -0.12499293
A11: K206 | B11: NY | C11: =Sites[[#This Row],[SOL'#]] -> SOL-10927 | D11: =SUM(Apr!D11,May!D11,Jun!D11) -> 60686.781 | E11: =SUM(Apr!E11,May!E11,Jun!E11) -> 58984.7 | F11: =IF(AND(ISNUMBER(D11),ISNUMBER(E11)), D11-E11, "") -> 1702.0813 | G11: =IFERROR(F11/E11, "") -> 0.028856318 | H11: =SUM(Apr!H11,May!H11,Jun!H11) -> 65939 | I11: =SUM(Apr!I11,May!I11,Jun!I11) -> -5252.2188 | J11: =IFERROR(I11/H11, "") -> -0.07965269
A12: K251 | B12: NY | C12: =Sites[[#This Row],[SOL'#]] -> SOL-10365 | D12: =SUM(Apr!D12,May!D12,Jun!D12) -> 55076 | E12: =SUM(Apr!E12,May!E12,Jun!E12) -> 0 | F12: =IF(AND(ISNUMBER(D12),ISNUMBER(E12)), D12-E12, "") -> 55076 | G12: =IFERROR(F12/E12, "") | H12: =SUM(Apr!H12,May!H12,Jun!H12) -> 74161.86 | I12: =SUM(Apr!I12,May!I12,Jun!I12) -> -19085.86 | J12: =IFERROR(I12/H12, "") -> -0.25735412
A13: K269 | B13: NY | C13: =Sites[[#This Row],[SOL'#]] -> SOL-10366 | D13: =SUM(Apr!D13,May!D13,Jun!D13) -> 60935.25 | E13: =SUM(Apr!E13,May!E13,Jun!E13) -> 70904.83 | F13: =IF(AND(ISNUMBER(D13),ISNUMBER(E13)), D13-E13, "") -> -9969.58 | G13: =IFERROR(F13/E13, "") -> -0.14060509 | H13: =SUM(Apr!H13,May!H13,Jun!H13) -> 69988.55 | I13: =SUM(Apr!I13,May!I13,Jun!I13) -> -9053.3 | J13: =IFERROR(I13/H13, "") -> -0.12935402
A14: K273 | B14: NY | C14: =Sites[[#This Row],[SOL'#]] -> SOL-10367 | D14: =SUM(Apr!D14,May!D14,Jun!D14) -> 62937.188 | E14: =SUM(Apr!E14,May!E14,Jun!E14) -> 0 | F14: =IF(AND(ISNUMBER(D14),ISNUMBER(E14)), D14-E14, "") -> 62937.188 | G14: =IFERROR(F14/E14, "") | H14: =SUM(Apr!H14,May!H14,Jun!H14) -> 89807 | I14: =SUM(Apr!I14,May!I14,Jun!I14) -> -26869.812 | J14: =IFERROR(I14/H14, "") -> -0.29919508
A15: K287 | B15: NY | C15: =Sites[[#This Row],[SOL'#]] -> SOL-10919 | D15: =SUM(Apr!D15,May!D15,Jun!D15) -> 52962.812 | E15: =SUM(Apr!E15,May!E15,Jun!E15) -> 46110.94 | F15: =IF(AND(ISNUMBER(D15),ISNUMBER(E15)), D15-E15, "") -> 6851.8725 | G15: =IFERROR(F15/E15, "") -> 0.14859538 | H15: =SUM(Apr!H15,May!H15,Jun!H15) -> 61335 | I15: =SUM(Apr!I15,May!I15,Jun!I15) -> -8372.1875 | J15: =IFERROR(I15/H15, "") -> -0.13649935
A16: K298 | B16: NY | C16: =Sites[[#This Row],[SOL'#]] -> SOL-10368 | D16: =SUM(Apr!D16,May!D16,Jun!D16) -> 57863.906 | E16: =SUM(Apr!E16,May!E16,Jun!E16) -> 60971.71 | F16: =IF(AND(ISNUMBER(D16),ISNUMBER(E16)), D16-E16, "") -> -3107.8038 | G16: =IFERROR(F16/E16, "") -> -0.050971241 | H16: =SUM(Apr!H16,May!H16,Jun!H16) -> 70465 | I16: =SUM(Apr!I16,May!I16,Jun!I16) -> -12601.094 | J16: =IFERROR(I16/H16, "") -> -0.1788277
... A158: Wellsville - Chenunda Creek | B158: NY | C158: =Sites[[#This Row],[SOL'#]] -> SOL-11187 | D158: =SUM(Apr!D158,May!D158,Jun!D158) -> 1001224.9 | E158: =SUM(Apr!E158,May!E158,Jun!E158) -> 0 | F158: =IF(AND(ISNUMBER(D158),ISNUMBER(E158)), D158-E158, "") -> 1001224.9 | G158: =IFERROR(F158/E158, "") | H158: =SUM(Apr!H158,May!H158,Jun!H158) -> 381833 | I158: =SUM(Apr!I158,May!I158,Jun!I158) -> -200510 | J158: =IFERROR(I158/H158, "") -> -0.52512486
J201: =IFERROR(I201/H201, "")

Sheet 3rd Qtr
A1: {=portfolio} -> Generate Capital | E1: 3rd Quarter Actual v. Expected | H1: 3rd Quarter Actual v. Forecasted
A2: Total | D2: =SUM(D4:D158) -> 53193022 | E2: =SUM(E4:E183) -> 51529346 | F2: =D2-E2 -> 1663676.3 | G2: =IFERROR(F2/E2, 0) -> 0.032285997 | H2: =SUM(H4:H158) -> 50539858 | I2: =D2-H2 -> 2653164.1 | J2: =IFERROR(I2/H2, 0) -> 0.052496469
A3: Site | B3: State | C3: SOL# | D3: Actual | E3: Expected | F3: Delta | G3: % | H3: Forecasted | I3: Delta | J3: %
A4: {=Sites[Site]} -> K026 | B4: {=Sites[State]} -> NY | C4: =Sites[[#This Row],[SOL'#]] -> SOL-10356 | D4: =SUM(Jul!D4, Aug!D4, Sep!D4) -> 22080.75 | E4: =SUM(Jul!E4, Aug!E4, Sep!E4) -> 42520.39 | F4: =IF(AND(ISNUMBER(D4),ISNUMBER(E4)), D4-E4, "") -> -20439.64 | G4: =IFERROR(F4/E4, "") -> -0.48070208 | H4: =SUM(Jul!H4,Aug!H4,Sep!H4) -> 37634.39 | I4: =SUM(Jul!I4, Aug!I4, Sep!I4) -> -15553.64 | J4: =IFERROR(I4/H4, "") -> -0.41328264
A5: K041 | B5: NY | C5: =Sites[[#This Row],[SOL'#]] -> SOL-10357 | D5: =SUM(Jul!D5, Aug!D5, Sep!D5) -> 30806.781 | E5: =SUM(Jul!E5, Aug!E5, Sep!E5) -> 35182.89 | F5: =IF(AND(ISNUMBER(D5),ISNUMBER(E5)), D5-E5, "") -> -4376.1087 | G5: =IFERROR(F5/E5, "") -> -0.12438173 | H5: =SUM(Jul!H5,Aug!H5,Sep!H5) -> 32538 | I5: =SUM(Jul!I5, Aug!I5, Sep!I5) -> -1731.2188 | J5: =IFERROR(I5/H5, "") -> -0.053206059
A6: K043 | B6: NY | C6: =Sites[[#This Row],[SOL'#]] -> SOL-10358 | D6: =SUM(Jul!D6, Aug!D6, Sep!D6) -> 35140.5 | E6: =SUM(Jul!E6, Aug!E6, Sep!E6) -> 39838.042 | F6: =IF(AND(ISNUMBER(D6),ISNUMBER(E6)), D6-E6, "") -> -4697.542 | G6: =IFERROR(F6/E6, "") -> -0.11791599 | H6: =SUM(Jul!H6,Aug!H6,Sep!H6) -> 7003.033 | I6: =SUM(Jul!I6, Aug!I6, Sep!I6) -> 28137.467 | J6: =IFERROR(I6/H6, "") -> 4.0178972
A7: K058 | B7: NY | C7: =Sites[[#This Row],[SOL'#]] -> SOL-10360 | D7: =SUM(Jul!D7, Aug!D7, Sep!D7) -> 0 | E7: =SUM(Jul!E7, Aug!E7, Sep!E7) -> 0 | F7: =IF(AND(ISNUMBER(D7),ISNUMBER(E7)), D7-E7, "") -> 0 | G7: =IFERROR(F7/E7, "") | H7: =SUM(Jul!H7,Aug!H7,Sep!H7) -> 28709 | I7: =SUM(Jul!I7, Aug!I7, Sep!I7) -> -28709 | J7: =IFERROR(I7/H7, "") -> -1
A8: K115 | B8: NY | C8: =Sites[[#This Row],[SOL'#]] -> SOL-10361 | D8: =SUM(Jul!D8, Aug!D8, Sep!D8) -> 5994.9688 | E8: =SUM(Jul!E8, Aug!E8, Sep!E8) -> 15981.37 | F8: =IF(AND(ISNUMBER(D8),ISNUMBER(E8)), D8-E8, "") -> -9986.4013 | G8: =IFERROR(F8/E8, "") -> -0.62487767 | H8: =SUM(Jul!H8,Aug!H8,Sep!H8) -> 18780.49 | I8: =SUM(Jul!I8, Aug!I8, Sep!I8) -> -12785.521 | J8: =IFERROR(I8/H8, "") -> -0.68078742
A9: K152 | B9: NY | C9: =Sites[[#This Row],[SOL'#]] -> SOL-10362 | D9: =SUM(Jul!D9, Aug!D9, Sep!D9) -> 11235.5 | E9: =SUM(Jul!E9, Aug!E9, Sep!E9) -> 11639.54 | F9: =IF(AND(ISNUMBER(D9),ISNUMBER(E9)), D9-E9, "") -> -404.04 | G9: =IFERROR(F9/E9, "") -> -0.034712712 | H9: =SUM(Jul!H9,Aug!H9,Sep!H9) -> 10840 | I9: =SUM(Jul!I9, Aug!I9, Sep!I9) -> 395.5 | J9: =IFERROR(I9/H9, "") -> 0.03648524
A10: K166 | B10: NY | C10: =Sites[[#This Row],[SOL'#]] -> SOL-10363 | D10: =SUM(Jul!D10, Aug!D10, Sep!D10) -> 42074.5 | E10: =SUM(Jul!E10, Aug!E10, Sep!E10) -> 45470.58 | F10: =IF(AND(ISNUMBER(D10),ISNUMBER(E10)), D10-E10, "") -> -3396.08 | G10: =IFERROR(F10/E10, "") -> -0.074687413 | H10: =SUM(Jul!H10,Aug!H10,Sep!H10) -> 39952.56 | I10: =SUM(Jul!I10, Aug!I10, Sep!I10) -> 2121.94 | J10: =IFERROR(I10/H10, "") -> 0.05311149
A11: K206 | B11: NY | C11: =Sites[[#This Row],[SOL'#]] -> SOL-10927 | D11: =SUM(Jul!D11, Aug!D11, Sep!D11) -> 25801.219 | E11: =SUM(Jul!E11, Aug!E11, Sep!E11) -> 24180.51 | F11: =IF(AND(ISNUMBER(D11),ISNUMBER(E11)), D11-E11, "") -> 1620.7088 | G11: =IFERROR(F11/E11, "") -> 0.067025416 | H11: =SUM(Jul!H11,Aug!H11,Sep!H11) -> 24570 | I11: =SUM(Jul!I11, Aug!I11, Sep!I11) -> 1231.2188 | J11: =IFERROR(I11/H11, "") -> 0.050110653
A12: K251 | B12: NY | C12: =Sites[[#This Row],[SOL'#]] -> SOL-10365 | D12: =SUM(Jul!D12, Aug!D12, Sep!D12) -> 20454.375 | E12: =SUM(Jul!E12, Aug!E12, Sep!E12) -> 0 | F12: =IF(AND(ISNUMBER(D12),ISNUMBER(E12)), D12-E12, "") -> 20454.375 | G12: =IFERROR(F12/E12, "") | H12: =SUM(Jul!H12,Aug!H12,Sep!H12) -> 25324.63 | I12: =SUM(Jul!I12, Aug!I12, Sep!I12) -> -4870.255 | J12: =IFERROR(I12/H12, "") -> -0.19231298
A13: K269 | B13: NY | C13: =Sites[[#This Row],[SOL'#]] -> SOL-10366 | D13: =SUM(Jul!D13, Aug!D13, Sep!D13) -> 24601.312 | E13: =SUM(Jul!E13, Aug!E13, Sep!E13) -> 28866.1 | F13: =IF(AND(ISNUMBER(D13),ISNUMBER(E13)), D13-E13, "") -> -4264.7875 | G13: =IFERROR(F13/E13, "") -> -0.14774381 | H13: =SUM(Jul!H13,Aug!H13,Sep!H13) -> 25783.66 | I13: =SUM(Jul!I13, Aug!I13, Sep!I13) -> -1182.3475 | J13: =IFERROR(I13/H13, "") -> -0.045856465
A14: K273 | B14: NY | C14: =Sites[[#This Row],[SOL'#]] -> SOL-10367 | D14: =SUM(Jul!D14, Aug!D14, Sep!D14) -> 19989.188 | E14: =SUM(Jul!E14, Aug!E14, Sep!E14) -> 0 | F14: =IF(AND(ISNUMBER(D14),ISNUMBER(E14)), D14-E14, "") -> 19989.188 | G14: =IFERROR(F14/E14, "") | H14: =SUM(Jul!H14,Aug!H14,Sep!H14) -> 30662 | I14: =SUM(Jul!I14, Aug!I14, Sep!I14) -> -10672.812 | J14: =IFERROR(I14/H14, "") -> -0.34807946
A15: K287 | B15: NY | C15: =Sites[[#This Row],[SOL'#]] -> SOL-10919 | D15: =SUM(Jul!D15, Aug!D15, Sep!D15) -> 21277.719 | E15: =SUM(Jul!E15, Aug!E15, Sep!E15) -> 18223.17 | F15: =IF(AND(ISNUMBER(D15),ISNUMBER(E15)), D15-E15, "") -> 3054.5488 | G15: =IFERROR(F15/E15, "") -> 0.16761896 | H15: =SUM(Jul!H15,Aug!H15,Sep!H15) -> 22153 | I15: =SUM(Jul!I15, Aug!I15, Sep!I15) -> -875.28125 | J15: =IFERROR(I15/H15, "") -> -0.039510732
A16: K298 | B16: NY | C16: =Sites[[#This Row],[SOL'#]] -> SOL-10368 | D16: =SUM(Jul!D16, Aug!D16, Sep!D16) -> 23346.625 | E16: =SUM(Jul!E16, Aug!E16, Sep!E16) -> 24604.5 | F16: =IF(AND(ISNUMBER(D16),ISNUMBER(E16)), D16-E16, "") -> -1257.875 | G16: =IFERROR(F16/E16, "") -> -0.051123778 | H16: =SUM(Jul!H16,Aug!H16,Sep!H16) -> 26042 | I16: =SUM(Jul!I16, Aug!I16, Sep!I16) -> -2695.375 | J16: =IFERROR(I16/H16, "") -> -0.10350108
... A158: Wellsville - Chenunda Creek | B158: NY | C158: =Sites[[#This Row],[SOL'#]] -> SOL-11187 | D158: =SUM(Jul!D158, Aug!D158, Sep!D158) -> 621490 | E158: =SUM(Jul!E158, Aug!E158, Sep!E158) -> 619787 | F158: =IF(AND(ISNUMBER(D158),ISNUMBER(E158)), D158-E158, "") -> 1703 | G158: =IFERROR(F158/E158, "") -> 0.0027477182 | H158: =SUM(Jul!H158,Aug!H158,Sep!H158) -> 0 | I158: =SUM(Jul!I158, Aug!I158, Sep!I158) -> 0 | J158: =IFERROR(I158/H158, "")

Sheet 4th Qtr
A1: {=portfolio} -> Generate Capital | E1: 4th Quarter Actual v. Expected | H1: 4th Quarter Actual v. Forecasted
A2: Total | D2: =SUM(D4:D158) -> 0 | E2: =SUM(E4:E183) -> 0 | F2: =D2-E2 -> 0 | G2: =IFERROR(F2/E2, 0) -> 0 | H2: =SUM(H4:H158) -> 0 | I2: =D2-H2 -> 0 | J2: =IFERROR(I2/H2, 0) -> 0
A3: Site | B3: State | C3: SOL# | D3: Actual | E3: Expected | F3: Delta | G3: % | H3: Forecasted | I3: Delta | J3: %
A4: {=Sites[Site]} -> K026 | B4: {=Sites[State]} -> NY | C4: =Sites[[#This Row],[SOL'#]] -> SOL-10356 | D4: =SUM(Oct!D21, Nov!D21, Dec!D21) -> 0 | E4: =SUM(Oct!E21, Nov!E21, Dec!E21) -> 0 | F4: =IF(AND(ISNUMBER(D4),ISNUMBER(E4)), D4-E4, "") -> 0 | G4: =IFERROR(F4/E4, "") | H4: =SUM(Oct!H21,Nov!H21,Dec!H21) -> 0 | I4: =SUM(Oct!I21, Nov!I21, Dec!I21) -> 0 | J4: =IFERROR(I4/H4, "")
A5: K041 | B5: NY | C5: =Sites[[#This Row],[SOL'#]] -> SOL-10357 | D5: =SUM(Oct!D22, Nov!D22, Dec!D22) -> 0 | E5: =SUM(Oct!E22, Nov!E22, Dec!E22) -> 0 | F5: =IF(AND(ISNUMBER(D5),ISNUMBER(E5)), D5-E5, "") -> 0 | G5: =IFERROR(F5/E5, "") | H5: =SUM(Oct!H22,Nov!H22,Dec!H22) -> 0 | I5: =SUM(Oct!I22, Nov!I22, Dec!I22) -> 0 | J5: =IFERROR(I5/H5, "")
A6: K043 | B6: NY | C6: =Sites[[#This Row],[SOL'#]] -> SOL-10358 | D6: =SUM(Oct!D23, Nov!D23, Dec!D23) -> 0 | E6: =SUM(Oct!E23, Nov!E23, Dec!E23) -> 0 | F6: =IF(AND(ISNUMBER(D6),ISNUMBER(E6)), D6-E6, "") -> 0 | G6: =IFERROR(F6/E6, "") | H6: =SUM(Oct!H23,Nov!H23,Dec!H23) -> 0 | I6: =SUM(Oct!I23, Nov!I23, Dec!I23) -> 0 | J6: =IFERROR(I6/H6, "")
A7: K058 | B7: NY | C7: =Sites[[#This Row],[SOL'#]] -> SOL-10360 | D7: =SUM(Oct!D24, Nov!D24, Dec!D24) -> 0 | E7: =SUM(Oct!E24, Nov!E24, Dec!E24) -> 0 | F7: =IF(AND(ISNUMBER(D7),ISNUMBER(E7)), D7-E7, "") -> 0 | G7: =IFERROR(F7/E7, "") | H7: =SUM(Oct!H24,Nov!H24,Dec!H24) -> 0 | I7: =SUM(Oct!I24, Nov!I24, Dec!I24) -> 0 | J7: =IFERROR(I7/H7, "")
A8: K115 | B8: NY | C8: =Sites[[#This Row],[SOL'#]] -> SOL-10361 | D8: =SUM(Oct!D25, Nov!D25, Dec!D25) -> 0 | E8: =SUM(Oct!E25, Nov!E25, Dec!E25) -> 0 | F8: =IF(AND(ISNUMBER(D8),ISNUMBER(E8)), D8-E8, "") -> 0 | G8: =IFERROR(F8/E8, "") | H8: =SUM(Oct!H25,Nov!H25,Dec!H25) -> 0 | I8: =SUM(Oct!I25, Nov!I25, Dec!I25) -> 0 | J8: =IFERROR(I8/H8, "")
A9: K152 | B9: NY | C9: =Sites[[#This Row],[SOL'#]] -> SOL-10362 | D9: =SUM(Oct!D26, Nov!D26, Dec!D26) -> 0 | E9: =SUM(Oct!E26, Nov!E26, Dec!E26) -> 0 | F9: =IF(AND(ISNUMBER(D9),ISNUMBER(E9)), D9-E9, "") -> 0 | G9: =IFERROR(F9/E9, "") | H9: =SUM(Oct!H26,Nov!H26,Dec!H26) -> 0 | I9: =SUM(Oct!I26, Nov!I26, Dec!I26) -> 0 | J9: =IFERROR(I9/H9, "")
A10: K166 | B10: NY | C10: =Sites[[#This Row],[SOL'#]] -> SOL-10363 | D10: =SUM(Oct!D27, Nov!D27, Dec!D27) -> 0 | E10: =SUM(Oct!E27, Nov!E27, Dec!E27) -> 0 | F10: =IF(AND(ISNUMBER(D10),ISNUMBER(E10)), D10-E10, "") -> 0 | G10: =IFERROR(F10/E10, "") | H10: =SUM(Oct!H27,Nov!H27,Dec!H27) -> 0 | I10: =SUM(Oct!I27, Nov!I27, Dec!I27) -> 0 | J10: =IFERROR(I10/H10, "")
A11: K206 | B11: NY | C11: =Sites[[#This Row],[SOL'#]] -> SOL-10927 | D11: =SUM(Oct!D28, Nov!D28, Dec!D28) -> 0 | E11: =SUM(Oct!E28, Nov!E28, Dec!E28) -> 0 | F11: =IF(AND(ISNUMBER(D11),ISNUMBER(E11)), D11-E11, "") -> 0 | G11: =IFERROR(F11/E11, "") | H11: =SUM(Oct!H28,Nov!H28,Dec!H28) -> 0 | I11: =SUM(Oct!I28, Nov!I28, Dec!I28) -> 0 | J11: =IFERROR(I11/H11, "")
A12: K251 | B12: NY | C12: =Sites[[#This Row],[SOL'#]] -> SOL-10365 | D12: =SUM(Oct!D29, Nov!D29, Dec!D29) -> 0 | E12: =SUM(Oct!E29, Nov!E29, Dec!E29) -> 0 | F12: =IF(AND(ISNUMBER(D12),ISNUMBER(E12)), D12-E12, "") -> 0 | G12: =IFERROR(F12/E12, "") | H12: =SUM(Oct!H29,Nov!H29,Dec!H29) -> 0 | I12: =SUM(Oct!I29, Nov!I29, Dec!I29) -> 0 | J12: =IFERROR(I12/H12, "")
A13: K269 | B13: NY | C13: =Sites[[#This Row],[SOL'#]] -> SOL-10366 | D13: =SUM(Oct!D30, Nov!D30, Dec!D30) -> 0 | E13: =SUM(Oct!E30, Nov!E30, Dec!E30) -> 0 | F13: =IF(AND(ISNUMBER(D13),ISNUMBER(E13)), D13-E13, "") -> 0 | G13: =IFERROR(F13/E13, "") | H13: =SUM(Oct!H30,Nov!H30,Dec!H30) -> 0 | I13: =SUM(Oct!I30, Nov!I30, Dec!I30) -> 0 | J13: =IFERROR(I13/H13, "")
A14: K273 | B14: NY | C14: =Sites[[#This Row],[SOL'#]] -> SOL-10367 | D14: =SUM(Oct!D31, Nov!D31, Dec!D31) -> 0 | E14: =SUM(Oct!E31, Nov!E31, Dec!E31) -> 0 | F14: =IF(AND(ISNUMBER(D14),ISNUMBER(E14)), D14-E14, "") -> 0 | G14: =IFERROR(F14/E14, "") | H14: =SUM(Oct!H31,Nov!H31,Dec!H31) -> 0 | I14: =SUM(Oct!I31, Nov!I31, Dec!I31) -> 0 | J14: =IFERROR(I14/H14, "")
A15: K287 | B15: NY | C15: =Sites[[#This Row],[SOL'#]] -> SOL-10919 | D15: =SUM(Oct!D32, Nov!D32, Dec!D32) -> 0 | E15: =SUM(Oct!E32, Nov!E32, Dec!E32) -> 0 | F15: =IF(AND(ISNUMBER(D15),ISNUMBER(E15)), D15-E15, "") -> 0 | G15: =IFERROR(F15/E15, "") | H15: =SUM(Oct!H32,Nov!H32,Dec!H32) -> 0 | I15: =SUM(Oct!I32, Nov!I32, Dec!I32) -> 0 | J15: =IFERROR(I15/H15, "")
A16: K298 | B16: NY | C16: =Sites[[#This Row],[SOL'#]] -> SOL-10368 | D16: =SUM(Oct!D33, Nov!D33, Dec!D33) -> 0 | E16: =SUM(Oct!E33, Nov!E33, Dec!E33) -> 0 | F16: =IF(AND(ISNUMBER(D16),ISNUMBER(E16)), D16-E16, "") -> 0 | G16: =IFERROR(F16/E16, "") | H16: =SUM(Oct!H33,Nov!H33,Dec!H33) -> 0 | I16: =SUM(Oct!I33, Nov!I33, Dec!I33) -> 0 | J16: =IFERROR(I16/H16, "")
... A95: Rivard 2 | B95: NY | C95: =Sites[[#This Row],[SOL'#]] -> SOL-11012 | D95: =SUM(Oct!D112, Nov!D112, Dec!D112) -> 0 | E95: =SUM(Oct!E112, Nov!E112, Dec!E112) -> 0 | F95: =IF(AND(ISNUMBER(D95),ISNUMBER(E95)), D95-E95, "") -> 0 | G95: =IFERROR(F95/E95, "") | H95: =SUM(Oct!H112,Nov!H112,Dec!H112) -> 0 | I95: =SUM(Oct!I112, Nov!I112, Dec!I112) -> 0 | J95: =IFERROR(I95/H95, "")
A96: Ridgeway #2 | B96: NY | C96: =Sites[[#This Row],[SOL'#]] -> SOL-11027 | D96: =SUM(Oct!D138, Nov!D138, Dec!D138) -> 0 | E96: =SUM(Oct!E138, Nov!E138, Dec!E138) -> 0 | F96: =IF(AND(ISNUMBER(D96),ISNUMBER(E96)), D96-E96, "") -> 0 | G96: =IFERROR(F96/E96, "") | H96: =SUM(Oct!H138,Nov!H138,Dec!H138) -> 0 | I96: =SUM(Oct!I138, Nov!I138, Dec!I138) -> 0 | J96: =IFERROR(I96/H96, "")
A97: Spencer | B97: NY | C97: =Sites[[#This Row],[SOL'#]] -> SOL-11017 | D97: =SUM(Oct!D139, Nov!D139, Dec!D139) -> 0 | E97: =SUM(Oct!E139, Nov!E139, Dec!E139) -> 0 | F97: =IF(AND(ISNUMBER(D97),ISNUMBER(E97)), D97-E97, "") -> 0 | G97: =IFERROR(F97/E97, "") | H97: =SUM(Oct!H139,Nov!H139,Dec!H139) -> 0 | I97: =SUM(Oct!I139, Nov!I139, Dec!I139) -> 0 | J97: =IFERROR(I97/H97, "")
A98: Reisender | B98: NY | C98: =Sites[[#This Row],[SOL'#]] -> SOL-10886 | D98: =SUM(Oct!D140, Nov!D140, Dec!D140) -> 0 | E98: =SUM(Oct!E140, Nov!E140, Dec!E140) -> 0 | F98: =IF(AND(ISNUMBER(D98),ISNUMBER(E98)), D98-E98, "") -> 0 | G98: =IFERROR(F98/E98, "") | H98: =SUM(Oct!H140,Nov!H140,Dec!H140) -> 0 | I98: =SUM(Oct!I140, Nov!I140, Dec!I140) -> 0 | J98: =IFERROR(I98/H98, "")
A99: Finney | B99: NY | C99: =Sites[[#This Row],[SOL'#]] -> SOL-10999 | D99: =SUM(Oct!D141, Nov!D141, Dec!D141) -> 0 | E99: =SUM(Oct!E141, Nov!E141, Dec!E141) -> 0 | F99: =IF(AND(ISNUMBER(D99),ISNUMBER(E99)), D99-E99, "") -> 0 | G99: =IFERROR(F99/E99, "") | H99: =SUM(Oct!H141,Nov!H141,Dec!H141) -> 0 | I99: =SUM(Oct!I141, Nov!I141, Dec!I141) -> 0 | J99: =IFERROR(I99/H99, "")
A100: Davis Solar | B100: NY | C100: =Sites[[#This Row],[SOL'#]] -> SOL-10958 | D100: =SUM(Oct!D142, Nov!D142, Dec!D142) -> 0 | E100: =SUM(Oct!E142, Nov!E142, Dec!E142) -> 0 | F100: =IF(AND(ISNUMBER(D100),ISNUMBER(E100)), D100-E100, "") -> 0 | G100: =IFERROR(F100/E100, "") | H100: =SUM(Oct!H142,Nov!H142,Dec!H142) -> 0 | I100: =SUM(Oct!I142, Nov!I142, Dec!I142) -> 0 | J100: =IFERROR(I100/H100, "")
A101: Genesee | B101: NY | C101: =Sites[[#This Row],[SOL'#]] -> SOL-10951 | D101: =SUM(Oct!D143, Nov!D143, Dec!D143) -> 0 | E101: =SUM(Oct!E143, Nov!E143, Dec!E143) -> 0 | F101: =IF(AND(ISNUMBER(D101),ISNUMBER(E101)), D101-E101, "") -> 0 | G101: =IFERROR(F101/E101, "") | H101: =SUM(Oct!H143,Nov!H143,Dec!H143) -> 0 | I101: =SUM(Oct!I143, Nov!I143, Dec!I143) -> 0 | J101: =IFERROR(I101/H101, "")
A102: Landau I | B102: NY | C102: =Sites[[#This Row],[SOL'#]] -> SOL-10891 | D102: =SUM(Oct!D144, Nov!D144, Dec!D144) -> 0 | E102: =SUM(Oct!E144, Nov!E144, Dec!E144) -> 0 | F102: =IF(AND(ISNUMBER(D102),ISNUMBER(E102)), D102-E102, "") -> 0 | G102: =IFERROR(F102/E102, "") | H102: =SUM(Oct!H144,Nov!H144,Dec!H144) -> 0 | I102: =SUM(Oct!I144, Nov!I144, Dec!I144) -> 0 | J102: =IFERROR(I102/H102, "")
A103: Landau II | B103: NY | C103: =Sites[[#This Row],[SOL'#]] -> SOL-10895 | D103: =SUM(Oct!D145, Nov!D145, Dec!D145) -> 0 | E103: =SUM(Oct!E145, Nov!E145, Dec!E145) -> 0 | F103: =IF(AND(ISNUMBER(D103),ISNUMBER(E103)), D103-E103, "") -> 0 | G103: =IFERROR(F103/E103, "") | H103: =SUM(Oct!H145,Nov!H145,Dec!H145) -> 0 | I103: =SUM(Oct!I145, Nov!I145, Dec!I145) -> 0 | J103: =IFERROR(I103/H103, "")
A104: New Beginnings | B104: NY | C104: =Sites[[#This Row],[SOL'#]] -> SOL-10890 | D104: =SUM(Oct!D146, Nov!D146, Dec!D146) -> 0 | E104: =SUM(Oct!E146, Nov!E146, Dec!E146) -> 0 | F104: =IF(AND(ISNUMBER(D104),ISNUMBER(E104)), D104-E104, "") -> 0 | G104: =IFERROR(F104/E104, "") | H104: =SUM(Oct!H146,Nov!H146,Dec!H146) -> 0 | I104: =SUM(Oct!I146, Nov!I146, Dec!I146) -> 0 | J104: =IFERROR(I104/H104, "")
A105: Bullitt Farm Solar, LLC | B105: NY | C105: =Sites[[#This Row],[SOL'#]] -> SOL-10998 | D105: =SUM(Oct!D147, Nov!D147, Dec!D147) -> 0 | E105: =SUM(Oct!E147, Nov!E147, Dec!E147) -> 0 | F105: =IF(AND(ISNUMBER(D105),ISNUMBER(E105)), D105-E105, "") -> 0 | G105: =IFERROR(F105/E105, "") | H105: =SUM(Oct!H147,Nov!H147,Dec!H147) -> 0 | I105: =SUM(Oct!I147, Nov!I147, Dec!I147) -> 0 | J105: =IFERROR(I105/H105, "")
A106: Brodhead Solar, LLC | B106: NY | C106: =Sites[[#This Row],[SOL'#]] -> SOL-10899 | D106: =SUM(Oct!D148, Nov!D148, Dec!D148) -> 0 | E106: =SUM(Oct!E148, Nov!E148, Dec!E148) -> 0 | F106: =IF(AND(ISNUMBER(D106),ISNUMBER(E106)), D106-E106, "") -> 0 | G106: =IFERROR(F106/E106, "") | H106: =SUM(Oct!H148,Nov!H148,Dec!H148) -> 0 | I106: =SUM(Oct!I148, Nov!I148, Dec!I148) -> 0 | J106: =IFERROR(I106/H106, "")
A107: Svenski | B107: NY | C107: =Sites[[#This Row],[SOL'#]] -> SOL-10894 | D107: =SUM(Oct!D149, Nov!D149, Dec!D149) -> 0 | E107: =SUM(Oct!E149, Nov!E149, Dec!E149) -> 0 | F107: =IF(AND(ISNUMBER(D107),ISNUMBER(E107)), D107-E107, "") -> 0 | G107: =IFERROR(F107/E107, "") | H107: =SUM(Oct!H149,Nov!H149,Dec!H149) -> 0 | I107: =SUM(Oct!I149, Nov!I149, Dec!I149) -> 0 | J107: =IFERROR(I107/H107, "")
... A143: BK16 | B143: NY | C143: =Sites[[#This Row],[SOL'#]] -> SOL-11093 | D143: =SUM(Oct!D185, Nov!D185, Dec!D185) -> 0 | E143: =SUM(Oct!E185, Nov!E185, Dec!E185) -> 0 | F143: =IF(AND(ISNUMBER(D143),ISNUMBER(E143)), D143-E143, "") -> 0 | G143: =IFERROR(F143/E143, "") | H143: =SUM(Oct!H185,Nov!H185,Dec!H185) -> 0 | I143: =SUM(Oct!I185, Nov!I185, Dec!I185) -> 0 | J143: =IFERROR(I143/H143, "")
A144: Trenton - Trenton East | B144: IL | C144: =Sites[[#This Row],[SOL'#]] -> SOL-11060 | D144: =SUM(Oct!D186, Nov!D186, Dec!D186) -> 0 | E144: =SUM(Oct!E186, Nov!E186, Dec!E186) -> 0 | F144: =IF(AND(ISNUMBER(D144),ISNUMBER(E144)), D144-E144, "") -> 0 | H144: =SUM(Oct!H186,Nov!H186,Dec!H186) -> 0 | I144: =SUM(Oct!I186, Nov!I186, Dec!I186) -> 0
A145: Trenton - Trenton West | B145: IL | C145: =Sites[[#This Row],[SOL'#]] -> SOL-11061 | D145: =SUM(Oct!D187, Nov!D187, Dec!D187) -> 0 | E145: =SUM(Oct!E187, Nov!E187, Dec!E187) -> 0 | F145: =IF(AND(ISNUMBER(D145),ISNUMBER(E145)), D145-E145, "") -> 0 | H145: =SUM(Oct!H187,Nov!H187,Dec!H187) -> 0 | I145: =SUM(Oct!I187, Nov!I187, Dec!I187) -> 0
A146: Dakota - Dakota Solar 1 | B146: IL | C146: =Sites[[#This Row],[SOL'#]] -> SOL-11113 | D146: =SUM(Oct!D188, Nov!D188, Dec!D188) -> 0 | E146: =SUM(Oct!E188, Nov!E188, Dec!E188) -> 0 | F146: =IF(AND(ISNUMBER(D146),ISNUMBER(E146)), D146-E146, "") -> 0 | H146: =SUM(Oct!H188,Nov!H188,Dec!H188) -> 0 | I146: =SUM(Oct!I188, Nov!I188, Dec!I188) -> 0
A147: X018 | B147: NY | C147: =Sites[[#This Row],[SOL'#]] -> SOL-10418 | D147: =SUM(Oct!D189, Nov!D189, Dec!D189) -> 0 | E147: =SUM(Oct!E189, Nov!E189, Dec!E189) -> 0 | F147: =IF(AND(ISNUMBER(D147),ISNUMBER(E147)), D147-E147, "") -> 0 | H147: =SUM(Oct!H189,Nov!H189,Dec!H189) -> 0 | I147: =SUM(Oct!I189, Nov!I189, Dec!I189) -> 0
A148: Janiak Solar | B148: NY | C148: =Sites[[#This Row],[SOL'#]] -> SOL-10898 | D148: =SUM(Oct!D190, Nov!D190, Dec!D190) -> 0 | E148: =SUM(Oct!E190, Nov!E190, Dec!E190) -> 0 | F148: =IF(AND(ISNUMBER(D148),ISNUMBER(E148)), D148-E148, "") -> 0 | H148: =SUM(Oct!H190,Nov!H190,Dec!H190) -> 0 | I148: =SUM(Oct!I190, Nov!I190, Dec!I190) -> 0
A149: County Route 11B | B149: NY | C149: =Sites[[#This Row],[SOL'#]] -> SOL-10983 | D149: =SUM(Oct!D191, Nov!D191, Dec!D191) -> 0 | E149: =SUM(Oct!E191, Nov!E191, Dec!E191) -> 0 | F149: =IF(AND(ISNUMBER(D149),ISNUMBER(E149)), D149-E149, "") -> 0 | H149: =SUM(Oct!H191,Nov!H191,Dec!H191) -> 0 | I149: =SUM(Oct!I191, Nov!I191, Dec!I191) -> 0
A150: Barone | B150: NY | C150: =Sites[[#This Row],[SOL'#]] -> SOL-11034 | D150: =SUM(Oct!D192, Nov!D192, Dec!D192) -> 0 | E150: =SUM(Oct!E192, Nov!E192, Dec!E192) -> 0 | F150: =IF(AND(ISNUMBER(D150),ISNUMBER(E150)), D150-E150, "") -> 0 | H150: =SUM(Oct!H192,Nov!H192,Dec!H192) -> 0 | I150: =SUM(Oct!I192, Nov!I192, Dec!I192) -> 0
A151: Cedarville | B151: IL | C151: =Sites[[#This Row],[SOL'#]] -> SOL-11069 | D151: =SUM(Oct!D193, Nov!D193, Dec!D193) -> 0 | E151: =SUM(Oct!E193, Nov!E193, Dec!E193) -> 0 | F151: =IF(AND(ISNUMBER(D151),ISNUMBER(E151)), D151-E151, "") -> 0 | H151: =SUM(Oct!H193,Nov!H193,Dec!H193) -> 0 | I151: =SUM(Oct!I193, Nov!I193, Dec!I193) -> 0
A152: O'Brien Hill #1 | B152: NY | C152: =Sites[[#This Row],[SOL'#]] -> SOL-11098 | D152: =SUM(Oct!D194, Nov!D194, Dec!D194) -> 0 | E152: =SUM(Oct!E194, Nov!E194, Dec!E194) -> 0 | F152: =IF(AND(ISNUMBER(D152),ISNUMBER(E152)), D152-E152, "") -> 0 | H152: =SUM(Oct!H194,Nov!H194,Dec!H194) -> 0 | I152: =SUM(Oct!I194, Nov!I194, Dec!I194) -> 0
A153: O'Brien Hill #2 | B153: NY | C153: =Sites[[#This Row],[SOL'#]] -> SOL-11099 | D153: =SUM(Oct!D195, Nov!D195, Dec!D195) -> 0 | E153: =SUM(Oct!E195, Nov!E195, Dec!E195) -> 0 | F153: =IF(AND(ISNUMBER(D153),ISNUMBER(E153)), D153-E153, "") -> 0 | H153: =SUM(Oct!H195,Nov!H195,Dec!H195) -> 0 | I153: =SUM(Oct!I195, Nov!I195, Dec!I195) -> 0
...

Sheet Jan
A1: {=portfolio} -> Generate Capital | E1: January Actual v. Expected | H1: January Actual v. Forecasted
A2: Total | D2: =SUM(D4:D95) -> 8302287.9 | E2: =SUM(E4:E95) -> 4150358 | F2: =D2-E2 -> 4151929.9 | G2: =IFERROR(F2/E2, 0) -> 1.0003787 | H2: =SUM(H4:H95) -> 10397498 | I2: =D2-H2 -> -2095209.9 | J2: =IFERROR(I2/H2, 0) -> -0.20151097 | K2: =IF(AND(TODAY()>DATE(2024, 1, 1), COUNTA(Sites[Site])<>(COUNT(D:D)-1)), "Some sites are missing actual data; if new sites were added, make sure they are aligned correctly (including prior months!)", "") -> Some sites are missing actual data; if new sites were added, make sure they are aligned correctly (including prior months!)
A3: Site | B3: State | C3: SOL# | D3: Actual | E3: Expected | F3: Delta | G3: % | H3: Forecasted | I3: Delta | J3: % | K3: Notes | L3: Service Requests
A4: {=Sites[Site]} -> K026 | B4: {=Sites[State]} -> NY | C4: =Sites[[#This Row],[SOL'#]] -> SOL-10356 | D4: 11980.125 | E4: 18586.79 | F4: =IF(AND(ISNUMBER(D4),ISNUMBER(E4)), D4-E4, "") -> -6606.665 | G4: =IFERROR(F4/E4, "") -> -0.35544949 | H4: 11111.47 | I4: =IF(AND(ISNUMBER(D4),ISNUMBER(H4)), D4-H4, "") -> 868.655 | J4: =IFERROR(I4/H4, "") -> 0.078176425
A5: K041 | B5: NY | C5: =Sites[[#This Row],[SOL'#]] -> SOL-10357 | D5: 8842.5469 | E5: 13490.72 | F5: =IF(AND(ISNUMBER(D5),ISNUMBER(E5)), D5-E5, "") -> -4648.1731 | G5: =IFERROR(F5/E5, "") -> -0.34454596 | H5: 9924 | I5: =IF(AND(ISNUMBER(D5),ISNUMBER(H5)), D5-H5, "") -> -1081.4531 | J5: =IFERROR(I5/H5, "") -> -0.10897351
A6: K043 | B6: NY | C6: =Sites[[#This Row],[SOL'#]] -> SOL-10358 | D6: 10563.688 | E6: 15508.68 | F6: =IF(AND(ISNUMBER(D6),ISNUMBER(E6)), D6-E6, "") -> -4944.9925 | G6: =IFERROR(F6/E6, "") -> -0.31885322 | H6: 2303 | I6: =IF(AND(ISNUMBER(D6),ISNUMBER(H6)), D6-H6, "") -> 8260.6875 | J6: =IFERROR(I6/H6, "") -> 3.5869247 | K6: 1.Estimated values are low in AE we have also verified the file which was given GC
A7: K058 | B7: NY | C7: =Sites[[#This Row],[SOL'#]] -> SOL-10360 | D7: 8472.1875 | E7: 12896.51 | F7: =IF(AND(ISNUMBER(D7),ISNUMBER(E7)), D7-E7, "") -> -4424.3225 | G7: =IFERROR(F7/E7, "") -> -0.34306355 | H7: 9147.029 | I7: =IF(AND(ISNUMBER(D7),ISNUMBER(H7)), D7-H7, "") -> -674.8415 | J7: =IFERROR(I7/H7, "") -> -0.073777125
A8: K115 | B8: NY | C8: =Sites[[#This Row],[SOL'#]] -> SOL-10361 | D8: 2497.5194 | E8: 7565.845 | F8: =IF(AND(ISNUMBER(D8),ISNUMBER(E8)), D8-E8, "") -> -5068.3256 | G8: =IFERROR(F8/E8, "") -> -0.66989551 | H8: 5593.833 | I8: =IF(AND(ISNUMBER(D8),ISNUMBER(H8)), D8-H8, "") -> -3096.3136 | J8: =IFERROR(I8/H8, "") -> -0.55352271 | K8: 1. 96 optimizers are down for site construction. | L8: 1.SR093291
A9: K152 | B9: NY | C9: =Sites[[#This Row],[SOL'#]] -> SOL-10362 | D9: 3001 | E9: 4499.147 | F9: =IF(AND(ISNUMBER(D9),ISNUMBER(E9)), D9-E9, "") -> -1498.147 | G9: =IFERROR(F9/E9, "") -> -0.33298467 | H9: 3567 | I9: =IF(AND(ISNUMBER(D9),ISNUMBER(H9)), D9-H9, "") -> -566 | J9: =IFERROR(I9/H9, "") -> -0.15867676 | K9: 1. Low generation due to weather/snow.
A10: K166 | B10: NY | C10: =Sites[[#This Row],[SOL'#]] -> SOL-10363 | D10: 10743.5 | E10: 17382.57 | F10: =IF(AND(ISNUMBER(D10),ISNUMBER(E10)), D10-E10, "") -> -6639.07 | G10: =IFERROR(F10/E10, "") -> -0.38193834 | H10: 12125.14 | I10: =IF(AND(ISNUMBER(D10),ISNUMBER(H10)), D10-H10, "") -> -1381.64 | J10: =IFERROR(I10/H10, "") -> -0.11394838 | K10: 1. Low generation due to weather/snow.
A11: K206 | B11: NY | C11: =Sites[[#This Row],[SOL'#]] -> SOL-10927 | D11: 7155.1976 | E11: 11256.59 | F11: =IF(AND(ISNUMBER(D11),ISNUMBER(E11)), D11-E11, "") -> -4101.3924 | G11: =IFERROR(F11/E11, "") -> -0.36435478 | H11: 6894 | I11: =IF(AND(ISNUMBER(D11),ISNUMBER(H11)), D11-H11, "") -> 261.19765 | J11: =IFERROR(I11/H11, "") -> 0.037887678
A12: K251 | B12: NY | C12: =Sites[[#This Row],[SOL'#]] -> SOL-10365 | D12: 7964.375 | E12: 0 | F12: =IF(AND(ISNUMBER(D12),ISNUMBER(E12)), D12-E12, "") -> 7964.375 | G12: =IFERROR(F12/E12, "") | H12: 8525.692 | I12: =IF(AND(ISNUMBER(D12),ISNUMBER(H12)), D12-H12, "") -> -561.317 | J12: =IFERROR(I12/H12, "") -> -0.065838292 | K12: 1.Weather station is not communicating since 11/22/2024. | L12: 1.SR093633
A13: K269 | B13: NY | C13: =Sites[[#This Row],[SOL'#]] -> SOL-10366 | D13: 6631 | E13: 11493.23 | F13: =IF(AND(ISNUMBER(D13),ISNUMBER(E13)), D13-E13, "") -> -4862.23 | G13: =IFERROR(F13/E13, "") -> -0.42305166 | H13: 7761.932 | I13: =IF(AND(ISNUMBER(D13),ISNUMBER(H13)), D13-H13, "") -> -1130.932 | J13: =IFERROR(I13/H13, "") -> -0.14570238
A14: K273 | B14: NY | C14: =Sites[[#This Row],[SOL'#]] -> SOL-10367 | D14: 6884.75 | E14: 0 | F14: =IF(AND(ISNUMBER(D14),ISNUMBER(E14)), D14-E14, "") -> 6884.75 | G14: =IFERROR(F14/E14, "") | H14: 9546 | I14: =IF(AND(ISNUMBER(D14),ISNUMBER(H14)), D14-H14, "") -> -2661.25 | J14: =IFERROR(I14/H14, "") -> -0.27878169 | K14: 1. Weather station is not communicating since 06/30/2024. 2. 26 optimizers are down for roof repair. | L14: 1.SR086842 2.SR093294 | M14: SR093294
A15: K287 | B15: NY | C15: =Sites[[#This Row],[SOL'#]] -> SOL-10919 | D15: 6469.9062 | E15: 8103.888 | F15: =IF(AND(ISNUMBER(D15),ISNUMBER(E15)), D15-E15, "") -> -1633.9817 | G15: =IFERROR(F15/E15, "") -> -0.20162936 | H15: 7303 | I15: =IF(AND(ISNUMBER(D15),ISNUMBER(H15)), D15-H15, "") -> -833.09375 | J15: =IFERROR(I15/H15, "") -> -0.11407555
A16: K298 | B16: NY | C16: =Sites[[#This Row],[SOL'#]] -> SOL-10368 | D16: 4878.3438 | E16: 10470.4 | F16: =IF(AND(ISNUMBER(D16),ISNUMBER(E16)), D16-E16, "") -> -5592.0562 | G16: =IFERROR(F16/E16, "") -> -0.53408239 | H16: 6119 | I16: =IF(AND(ISNUMBER(D16),ISNUMBER(H16)), D16-H16, "") -> -1240.6562 | J16: =IFERROR(I16/H16, "") -> -0.20275474 | K16: 1. Low generation due to weather/snow.
A17: K335 | B17: NY | C17: =Sites[[#This Row],[SOL'#]] -> SOL-10370 | D17: 6585.9375 | E17: 11111.72 | F17: =IF(AND(ISNUMBER(D17),ISNUMBER(E17)), D17-E17, "") -> -4525.7825 | G17: =IFERROR(F17/E17, "") -> -0.40729811 | H17: 8179 | I17: =IF(AND(ISNUMBER(D17),ISNUMBER(H17)), D17-H17, "") -> -1593.0625 | J17: =IFERROR(I17/H17, "") -> -0.19477473
A18: K345 | B18: NY | C18: =Sites[[#This Row],[SOL'#]] -> SOL-10920 | D18: 7617.6813 | E18: 8115.26 | F18: =IF(AND(ISNUMBER(D18),ISNUMBER(E18)), D18-E18, "") -> -497.57867 | G18: =IFERROR(F18/E18, "") -> -0.061313953 | H18: 6910 | I18: =IF(AND(ISNUMBER(D18),ISNUMBER(H18)), D18-H18, "") -> 707.68133 | J18: =IFERROR(I18/H18, "") -> 0.10241409
A19: K445 | B19: NY | C19: =Sites[[#This Row],[SOL'#]] -> SOL-10373 | D19: 7247.9688 | E19: 11595.77 | F19: =IF(AND(ISNUMBER(D19),ISNUMBER(E19)), D19-E19, "") -> -4347.8013 | G19: =IFERROR(F19/E19, "") -> -0.37494718 | H19: 6816.675 | I19: =IF(AND(ISNUMBER(D19),ISNUMBER(H19)), D19-H19, "") -> 431.29375 | J19: =IFERROR(I19/H19, "") -> 0.063270399
A20: K495 | B20: NY | C20: =Sites[[#This Row],[SOL'#]] -> SOL-10374 | D20: 0 | E20: 32841.14 | F20: =IF(AND(ISNUMBER(D20),ISNUMBER(E20)), D20-E20, "") -> -32841.14 | G20: =IFERROR(F20/E20, "") -> -1 | H20: 33557 | I20: =IF(AND(ISNUMBER(D20),ISNUMBER(H20)), D20-H20, "") -> -33557 | J20: =IFERROR(I20/H20, "") -> -1 | K20: 1.Due to shunt trips of the switchgear and overcurrent faults site is offline since 11/20/2024. | L20: 1.SR093196
A21: M020 | B21: NY | C21: =Sites[[#This Row],[SOL'#]] -> SOL-10380 | D21: 7114.6562 | E21: 10428.83 | F21: =IF(AND(ISNUMBER(D21),ISNUMBER(E21)), D21-E21, "") -> -3314.1737 | G21: =IFERROR(F21/E21, "") -> -0.3177896 | H21: 9125 | I21: =IF(AND(ISNUMBER(D21),ISNUMBER(H21)), D21-H21, "") -> -2010.3438 | J21: =IFERROR(I21/H21, "") -> -0.22031164 | K21: 1. Low generation due to weather/snow.
A22: M092 | B22: NY | C22: =Sites[[#This Row],[SOL'#]] -> SOL-10383 | D22: 7110.6875 | E22: 11229.76 | F22: =IF(AND(ISNUMBER(D22),ISNUMBER(E22)), D22-E22, "") -> -4119.0725 | G22: =IFERROR(F22/E22, "") -> -0.36679969 | H22: 8178.46 | I22: =IF(AND(ISNUMBER(D22),ISNUMBER(H22)), D22-H22, "") -> -1067.7725 | J22: =IFERROR(I22/H22, "") -> -0.13055912 | K22: 1. Low generation due to weather/snow.
A23: M143 | B23: NY | C23: =Sites[[#This Row],[SOL'#]] -> SOL-10384 | D23: 7303.2812 | E23: 10937.18 | F23: =IF(AND(ISNUMBER(D23),ISNUMBER(E23)), D23-E23, "") -> -3633.8988 | G23: =IFERROR(F23/E23, "") -> -0.33225189 | H23: 8702.744 | I23: =IF(AND(ISNUMBER(D23),ISNUMBER(H23)), D23-H23, "") -> -1399.4628 | J23: =IFERROR(I23/H23, "") -> -0.16080707 | K23: 1. Low generation due to weather/snow.
A24: M144 | B24: NY | C24: =Sites[[#This Row],[SOL'#]] -> SOL-10385 | D24: 12171.125 | E24: 0 | F24: =IF(AND(ISNUMBER(D24),ISNUMBER(E24)), D24-E24, "") -> 12171.125 | G24: =IFERROR(F24/E24, "") | H24: 13644 | I24: =IF(AND(ISNUMBER(D24),ISNUMBER(H24)), D24-H24, "") -> -1472.875 | J24: =IFERROR(I24/H24, "") -> -0.10795038 | K24: 1. Low generation due to weather/snow.
A25: M167 | B25: NY | C25: =Sites[[#This Row],[SOL'#]] -> SOL-10386 | D25: 6736.5 | E25: 8426.056 | F25: =IF(AND(ISNUMBER(D25),ISNUMBER(E25)), D25-E25, "") -> -1689.556 | G25: =IFERROR(F25/E25, "") -> -0.20051564 | H25: 8106.211 | I25: =IF(AND(ISNUMBER(D25),ISNUMBER(H25)), D25-H25, "") -> -1369.711 | J25: =IFERROR(I25/H25, "") -> -0.16897056 | K25: 1. Low generation due to weather/snow.
A26: M188 | B26: NY | C26: =Sites[[#This Row],[SOL'#]] -> SOL-10387 | D26: 6676.8125 | E26: 0 | F26: =IF(AND(ISNUMBER(D26),ISNUMBER(E26)), D26-E26, "") -> 6676.8125 | G26: =IFERROR(F26/E26, "") | H26: 6981 | I26: =IF(AND(ISNUMBER(D26),ISNUMBER(H26)), D26-H26, "") -> -304.1875 | J26: =IFERROR(I26/H26, "") -> -0.043573628
A27: EMHC | B27: NY | C27: =Sites[[#This Row],[SOL'#]] -> SOL-10351 | D27: 1958.0469 | E27: 2171.019 | F27: =IF(AND(ISNUMBER(D27),ISNUMBER(E27)), D27-E27, "") -> -212.97212 | G27: =IFERROR(F27/E27, "") -> -0.098097771 | H27: 2319.395 | I27: =IF(AND(ISNUMBER(D27),ISNUMBER(H27)), D27-H27, "") -> -361.34812 | J27: =IFERROR(I27/H27, "") -> -0.15579413
A28: Q008 | B28: NY | C28: =Sites[[#This Row],[SOL'#]] -> SOL-10397 | D28: 11304.469 | E28: 16377.23 | F28: =IF(AND(ISNUMBER(D28),ISNUMBER(E28)), D28-E28, "") -> -5072.7612 | G28: =IFERROR(F28/E28, "") -> -0.30974476 | H28: 10992 | I28: =IF(AND(ISNUMBER(D28),ISNUMBER(H28)), D28-H28, "") -> 312.46875 | J28: =IFERROR(I28/H28, "") -> 0.028426924 | K28: 1. Low generation due to weather/snow.
A29: Q018 | B29: NY | C29: =Sites[[#This Row],[SOL'#]] -> SOL-10398 | D29: 6700.6875 | E29: 8361.302 | F29: =IF(AND(ISNUMBER(D29),ISNUMBER(E29)), D29-E29, "") -> -1660.6145 | G29: =IFERROR(F29/E29, "") -> -0.19860717 | H29: 6682.311 | I29: =IF(AND(ISNUMBER(D29),ISNUMBER(H29)), D29-H29, "") -> 18.3765 | J29: =IFERROR(I29/H29, "") -> 0.0027500217 | K29: 1. Low generation due to weather/snow.
A30: Q021 | B30: NY | C30: =Sites[[#This Row],[SOL'#]] -> SOL-10399 | D30: 5780.4062 | E30: 9454.255 | F30: =IF(AND(ISNUMBER(D30),ISNUMBER(E30)), D30-E30, "") -> -3673.8487 | G30: =IFERROR(F30/E30, "") -> -0.38859209 | H30: 5223.647 | I30: =IF(AND(ISNUMBER(D30),ISNUMBER(H30)), D30-H30, "") -> 556.75925 | J30: =IFERROR(I30/H30, "") -> 0.10658439 | K30: 1. Low generation due to weather/snow.
A31: Q025 | B31: NY | C31: =Sites[[#This Row],[SOL'#]] -> SOL-10400 | D31: 9494.875 | E31: 13415.23 | F31: =IF(AND(ISNUMBER(D31),ISNUMBER(E31)), D31-E31, "") -> -3920.355 | G31: =IFERROR(F31/E31, "") -> -0.29223167 | H31: 7767 | I31: =IF(AND(ISNUMBER(D31),ISNUMBER(H31)), D31-H31, "") -> 1727.875 | J31: =IFERROR(I31/H31, "") -> 0.22246363 | K31: 1. Low generation due to weather/snow.
A32: Q074 | B32: NY | C32: =Sites[[#This Row],[SOL'#]] -> SOL-10402 | D32: 5694.625 | E32: 7433.287 | F32: =IF(AND(ISNUMBER(D32),ISNUMBER(E32)), D32-E32, "") -> -1738.662 | G32: =IFERROR(F32/E32, "") -> -0.23390218 | H32: 6035.102 | I32: =IF(AND(ISNUMBER(D32),ISNUMBER(H32)), D32-H32, "") -> -340.477 | J32: =IFERROR(I32/H32, "") -> -0.056416114 | K32: 1. Site was taken offline from 12/31/24 due to ConEd shut site off for tranformer work and later back online on 01/02 at 09:30 | L32: 1. SR095201
A33: Q115 | B33: NY | C33: =Sites[[#This Row],[SOL'#]] -> SOL-10872 | D33: 7869.5625 | E33: 12376.31 | F33: =IF(AND(ISNUMBER(D33),ISNUMBER(E33)), D33-E33, "") -> -4506.7475 | G33: =IFERROR(F33/E33, "") -> -0.36414307 | H33: 8154.507 | I33: =IF(AND(ISNUMBER(D33),ISNUMBER(H33)), D33-H33, "") -> -284.9445 | J33: =IFERROR(I33/H33, "") -> -0.034943192
A34: Q139 | B34: NY | C34: =Sites[[#This Row],[SOL'#]] -> SOL-10403 | D34: 5074.7187 | E34: 6806.319 | F34: =IF(AND(ISNUMBER(D34),ISNUMBER(E34)), D34-E34, "") -> -1731.6003 | G34: =IFERROR(F34/E34, "") -> -0.25441068 | H34: 5168 | I34: =IF(AND(ISNUMBER(D34),ISNUMBER(H34)), D34-H34, "") -> -93.28125 | J34: =IFERROR(I34/H34, "") -> -0.018049777
A35: Q157 | B35: NY | C35: =Sites[[#This Row],[SOL'#]] -> SOL-10404 | D35: 7985.125 | E35: 13511.83 | F35: =IF(AND(ISNUMBER(D35),ISNUMBER(E35)), D35-E35, "") -> -5526.705 | G35: =IFERROR(F35/E35, "") -> -0.40902713 | H35: 9200.271 | I35: =IF(AND(ISNUMBER(D35),ISNUMBER(H35)), D35-H35, "") -> -1215.146 | J35: =IFERROR(I35/H35, "") -> -0.1320772 | K35: 1.Inverter 3 offline mulptiple days due to parts RMAD 2.Inverter 4 is offline due to "Isolation Fault" from 01/3 | L35: 1. SR094206 2. SR096202 | M35: SR096202
A36: Q192 | B36: NY | C36: =Sites[[#This Row],[SOL'#]] -> SOL-10406 | D36: 13490.125 | E36: 19580.54 | F36: =IF(AND(ISNUMBER(D36),ISNUMBER(E36)), D36-E36, "") -> -6090.415 | G36: =IFERROR(F36/E36, "") -> -0.31104428 | H36: 13910.41 | I36: =IF(AND(ISNUMBER(D36),ISNUMBER(H36)), D36-H36, "") -> -420.285 | J36: =IFERROR(I36/H36, "") -> -0.030213703
A37: Q210 | B37: NY | C37: =Sites[[#This Row],[SOL'#]] -> SOL-10407 | D37: 11766.375 | E37: 14293.21 | F37: =IF(AND(ISNUMBER(D37),ISNUMBER(E37)), D37-E37, "") -> -2526.835 | G37: =IFERROR(F37/E37, "") -> -0.17678569 | H37: 11622 | I37: =IF(AND(ISNUMBER(D37),ISNUMBER(H37)), D37-H37, "") -> 144.375 | J37: =IFERROR(I37/H37, "") -> 0.012422561
A38: Q229 | B38: NY | C38: =Sites[[#This Row],[SOL'#]] -> SOL-10408 | D38: 4152.5312 | E38: 7352.509 | F38: =IF(AND(ISNUMBER(D38),ISNUMBER(E38)), D38-E38, "") -> -3199.9778 | G38: =IFERROR(F38/E38, "") -> -0.43522255 | H38: 3687.114 | I38: =IF(AND(ISNUMBER(D38),ISNUMBER(H38)), D38-H38, "") -> 465.41725 | J38: =IFERROR(I38/H38, "") -> 0.12622806
A39: Q231 | B39: NY | C39: =Sites[[#This Row],[SOL'#]] -> SOL-10870 | D39: 17624.25 | E39: 30638.85 | F39: =IF(AND(ISNUMBER(D39),ISNUMBER(E39)), D39-E39, "") -> -13014.6 | G39: =IFERROR(F39/E39, "") -> -0.42477443 | H39: 16899 | I39: =IF(AND(ISNUMBER(D39),ISNUMBER(H39)), D39-H39, "") -> 725.25 | J39: =IFERROR(I39/H39, "") -> 0.042916741
A40: Q405 | B40: NY | C40: =Sites[[#This Row],[SOL'#]] -> SOL-10409 | D40: 21223.625 | E40: 28842.48 | F40: =IF(AND(ISNUMBER(D40),ISNUMBER(E40)), D40-E40, "") -> -7618.855 | G40: =IFERROR(F40/E40, "") -> -0.26415395 | H40: 20777.84 | I40: =IF(AND(ISNUMBER(D40),ISNUMBER(H40)), D40-H40, "") -> 445.785 | J40: =IFERROR(I40/H40, "") -> 0.021454829
...

Sheet Feb
A1: {=portfolio} -> Generate Capital | E1: February Actual v. Expected | H1: February Actual v. Forecasted
A2: Total | D2: =SUM(D4:D95) -> 9904560.4 | E2: =SUM(E4:E95) -> 4894424.5 | F2: =D2-E2 -> 5010135.8 | G2: =IFERROR(F2/E2, 0) -> 1.0236415 | H2: =SUM(H4:H95) -> 15070075 | I2: =D2-H2 -> -5165514.5 | J2: =IFERROR(I2/H2, 0) -> -0.34276635 | K2: =IF(AND(TODAY()>DATE(2024, 2, 1), COUNTA(Sites[Site])<>(COUNT(D:D)-1)), "Some sites are missing actual data; if new sites were added, make sure they are aligned correctly (including prior months!)", "") -> Some sites are missing actual data; if new sites were added, make sure they are aligned correctly (including prior months!)
A3: Site | B3: State | C3: SOL# | D3: Actual | E3: Expected | F3: Delta | G3: % | H3: Forecasted | I3: Delta | J3: % | K3: Notes | L3: Service Requests
A4: {=Sites[Site]} -> K026 | B4: {=Sites[State]} -> NY | C4: =Sites[[#This Row],[SOL'#]] -> SOL-10356 | D4: 17315.75 | E4: 21363.42 | F4: =IF(AND(ISNUMBER(D4),ISNUMBER(E4)), D4-E4, "") -> -4047.67 | G4: =IFERROR(F4/E4, "") -> -0.18946732 | H4: 15170.88 | I4: =IF(AND(ISNUMBER(D4),ISNUMBER(H4)), D4-H4, "") -> 2144.87 | J4: =IFERROR(I4/H4, "") -> 0.14138072 | K4: 1.Low generation due to weather/snow.
A5: K041 | B5: NY | C5: =Sites[[#This Row],[SOL'#]] -> SOL-10357 | D5: 13320.781 | E5: 17186.99 | F5: =IF(AND(ISNUMBER(D5),ISNUMBER(E5)), D5-E5, "") -> -3866.2088 | G5: =IFERROR(F5/E5, "") -> -0.22494973 | H5: 13859 | I5: =IF(AND(ISNUMBER(D5),ISNUMBER(H5)), D5-H5, "") -> -538.21875 | J5: =IFERROR(I5/H5, "") -> -0.038835324 | K5: 1.Low generation due to weather/snow.
A6: K043 | B6: NY | C6: =Sites[[#This Row],[SOL'#]] -> SOL-10358 | D6: 15518.344 | E6: 18500.95 | F6: =IF(AND(ISNUMBER(D6),ISNUMBER(E6)), D6-E6, "") -> -2982.6063 | G6: =IFERROR(F6/E6, "") -> -0.16121368 | H6: 3061 | I6: =IF(AND(ISNUMBER(D6),ISNUMBER(H6)), D6-H6, "") -> 12457.344 | J6: =IFERROR(I6/H6, "") -> 4.0696974 | K6: 1.Estimated values are low in AE we have also verified the file which was given GC
A7: K058 | B7: NY | C7: =Sites[[#This Row],[SOL'#]] -> SOL-10360 | D7: 4162.5625 | E7: 9281.183 | F7: =IF(AND(ISNUMBER(D7),ISNUMBER(E7)), D7-E7, "") -> -5118.6205 | G7: =IFERROR(F7/E7, "") -> -0.55150518 | H7: 12005.22 | I7: =IF(AND(ISNUMBER(D7),ISNUMBER(H7)), D7-H7, "") -> -7842.6575 | J7: =IFERROR(I7/H7, "") -> -0.65327062 | K7: 1.The inverters experienced multiple tripping events on 02/14,17,18,19,20 due to intermittent voltage on phase B. The site tripped offline at 08:52 AM on 02/21. The technician arrived and stated that the cause was a blown phase C fuse and thermal damage to the AC disconnect. The site will remain offline until the parts are replaced. | L7: 1.SR097569
A8: K115 | B8: NY | C8: =Sites[[#This Row],[SOL'#]] -> SOL-10361 | D8: 3372.4181 | E8: 7965.901 | F8: =IF(AND(ISNUMBER(D8),ISNUMBER(E8)), D8-E8, "") -> -4593.4829 | G8: =IFERROR(F8/E8, "") -> -0.57664323 | H8: 7488.091 | I8: =IF(AND(ISNUMBER(D8),ISNUMBER(H8)), D8-H8, "") -> -4115.6729 | J8: =IFERROR(I8/H8, "") -> -0.54962913 | K8: 1. 96 optimizers are down for site construction. 2. Low generation due to weather/snow. | L8: 1.SR093291
A9: K152 | B9: NY | C9: =Sites[[#This Row],[SOL'#]] -> SOL-10362 | D9: 4885.5938 | E9: 5681.248 | F9: =IF(AND(ISNUMBER(D9),ISNUMBER(E9)), D9-E9, "") -> -795.65425 | G9: =IFERROR(F9/E9, "") -> -0.1400492 | H9: 4676 | I9: =IF(AND(ISNUMBER(D9),ISNUMBER(H9)), D9-H9, "") -> 209.59375 | J9: =IFERROR(I9/H9, "") -> 0.0448233 | K9: 1. Low generation due to weather/snow.
A10: K166 | B10: NY | C10: =Sites[[#This Row],[SOL'#]] -> SOL-10363 | D10: 17203.5 | E10: 21280.06 | F10: =IF(AND(ISNUMBER(D10),ISNUMBER(E10)), D10-E10, "") -> -4076.56 | G10: =IFERROR(F10/E10, "") -> -0.19156713 | H10: 16417.23 | I10: =IF(AND(ISNUMBER(D10),ISNUMBER(H10)), D10-H10, "") -> 786.27 | J10: =IFERROR(I10/H10, "") -> 0.047892976 | K10: 1. Low generation due to weather/snow.
