Workbook
Name JanActual: #REF!
Name JanActual2: #REF!
Name JanExpected: #REF!
Name JanExpectedDelta: #REF!
Name JanExpectedPercent: #REF!
Name JanExpPercent: #REF!
Name JanForecasted: #REF!
Name JanForecastedDelta: #REF!
Name JanForecastedPercent: #REF!
Name portfolio: Sites!$B$1:$B$1
Name Year: Sites!#REF!

Sheet Year to Date
A1: {=portfolio} -> Generate Capital | E1: Year to Date Actual v. Expected | H1: Year to Date Actual v. Forecasted
A2: Total | D2: =SUM(D4:D200) -> 36184982 | E2: =SUM(E4:E200) -> 19415999 | F2: =D2-E2 -> 16768983 | G2: =IFERROR(F2/E2, 0) -> 0.86366829 | H2: =SUM(H4:H200) -> 44326916 | I2: =D2-H2 -> -8141933.2 | J2: =IFERROR(I2/H2, 0) -> -0.18367922
A3: Site | B3: State | C3: SOL# | D3: Actual | E3: Expected | F3: Delta | G3: % | H3: Forecasted | I3: Delta | J3: %
A4: {=Sites[Site]} -> Farmer | B4: {=Sites[State]} -> AZ | C4: =Sites[[#This Row],[SOL'#]] -> SOL-10748 | D4: =SUM('1st Qtr'!D4, '2nd Qtr'!D4, '3rd Qtr'!D4, '4th Qtr'!D4) -> 20596.299 | E4: =SUM('1st Qtr'!E4, '2nd Qtr'!E4, '3rd Qtr'!E4, '4th Qtr'!E4) -> 15241.424 | F4: =IF(AND(ISNUMBER(D4),ISNUMBER(E4)), D4-E4, "") -> 5354.8755 | G4: =IFERROR(F4/E4, "") -> 0.35133695 | H4: =SUM('1st Qtr'!H4+'2nd Qtr'!H4+'3rd Qtr'!H4+'4th Qtr'!H4) -> 18595.628 | I4: =SUM('1st Qtr'!I4, '2nd Qtr'!I4, '3rd Qtr'!I4, '4th Qtr'!I4) -> 2000.6715 | J4: =IFERROR(I4/H4, "") -> 0.10758827
A5: Fulton | B5: AZ | C5: =Sites[[#This Row],[SOL'#]] -> SOL-10749 | D5: =SUM('1st Qtr'!D5, '2nd Qtr'!D5, '3rd Qtr'!D5, '4th Qtr'!D5) -> 57128.5 | E5: =SUM('1st Qtr'!E5, '2nd Qtr'!E5, '3rd Qtr'!E5, '4th Qtr'!E5) -> 75239.48 | F5: =IF(AND(ISNUMBER(D5),ISNUMBER(E5)), D5-E5, "") -> -18110.98 | G5: =IFERROR(F5/E5, "") -> -0.24071113 | H5: =SUM('1st Qtr'!H5+'2nd Qtr'!H5+'3rd Qtr'!H5+'4th Qtr'!H5) -> 74528.36 | I5: =SUM('1st Qtr'!I5, '2nd Qtr'!I5, '3rd Qtr'!I5, '4th Qtr'!I5) -> -17399.86 | J5: =IFERROR(I5/H5, "") -> -0.23346629
A6: JFK Elementary | B6: AZ | C6: =Sites[[#This Row],[SOL'#]] -> SOL-10758 | D6: =SUM('1st Qtr'!D6, '2nd Qtr'!D6, '3rd Qtr'!D6, '4th Qtr'!D6) -> 34707.198 | E6: =SUM('1st Qtr'!E6, '2nd Qtr'!E6, '3rd Qtr'!E6, '4th Qtr'!E6) -> 0 | F6: =IF(AND(ISNUMBER(D6),ISNUMBER(E6)), D6-E6, "") -> 34707.198 | G6: =IFERROR(F6/E6, "") | H6: =SUM('1st Qtr'!H6+'2nd Qtr'!H6+'3rd Qtr'!H6+'4th Qtr'!H6) -> 30463 | I6: =SUM('1st Qtr'!I6, '2nd Qtr'!I6, '3rd Qtr'!I6, '4th Qtr'!I6) -> 4244.198 | J6: =IFERROR(I6/H6, "") -> 0.13932305
A7: Noble | B7: AZ | C7: =Sites[[#This Row],[SOL'#]] -> SOL-10750 | D7: =SUM('1st Qtr'!D7, '2nd Qtr'!D7, '3rd Qtr'!D7, '4th Qtr'!D7) -> 19862.485 | E7: =SUM('1st Qtr'!E7, '2nd Qtr'!E7, '3rd Qtr'!E7, '4th Qtr'!E7) -> 25711.63 | F7: =IF(AND(ISNUMBER(D7),ISNUMBER(E7)), D7-E7, "") -> -5849.1445 | G7: =IFERROR(F7/E7, "") -> -0.22749023 | H7: =SUM('1st Qtr'!H7+'2nd Qtr'!H7+'3rd Qtr'!H7+'4th Qtr'!H7) -> 20305.238 | I7: =SUM('1st Qtr'!I7, '2nd Qtr'!I7, '3rd Qtr'!I7, '4th Qtr'!I7) -> -442.75251 | J7: =IFERROR(I7/H7, "") -> -0.021804842
A8: Parking 3 | B8: AZ | C8: =Sites[[#This Row],[SOL'#]] -> SOL-10751 | D8: =SUM('1st Qtr'!D8, '2nd Qtr'!D8, '3rd Qtr'!D8, '4th Qtr'!D8) -> 52632.387 | E8: =SUM('1st Qtr'!E8, '2nd Qtr'!E8, '3rd Qtr'!E8, '4th Qtr'!E8) -> 36461.69 | F8: =IF(AND(ISNUMBER(D8),ISNUMBER(E8)), D8-E8, "") -> 16170.697 | G8: =IFERROR(F8/E8, "") -> 0.4434983 | H8: =SUM('1st Qtr'!H8+'2nd Qtr'!H8+'3rd Qtr'!H8+'4th Qtr'!H8) -> 45223.83 | I8: =SUM('1st Qtr'!I8, '2nd Qtr'!I8, '3rd Qtr'!I8, '4th Qtr'!I8) -> 7408.5575 | J8: =IFERROR(I8/H8, "") -> 0.16381977
A9: PE East | B9: AZ | C9: =Sites[[#This Row],[SOL'#]] -> SOL-10752 | D9: =SUM('1st Qtr'!D9, '2nd Qtr'!D9, '3rd Qtr'!D9, '4th Qtr'!D9) -> 45253.447 | E9: =SUM('1st Qtr'!E9, '2nd Qtr'!E9, '3rd Qtr'!E9, '4th Qtr'!E9) -> 28727.75 | F9: =IF(AND(ISNUMBER(D9),ISNUMBER(E9)), D9-E9, "") -> 16525.697 | G9: =IFERROR(F9/E9, "") -> 0.57525205 | H9: =SUM('1st Qtr'!H9+'2nd Qtr'!H9+'3rd Qtr'!H9+'4th Qtr'!H9) -> 45859.64 | I9: =SUM('1st Qtr'!I9, '2nd Qtr'!I9, '3rd Qtr'!I9, '4th Qtr'!I9) -> -606.19288 | J9: =IFERROR(I9/H9, "") -> -0.01321844
A10: Schwada | B10: AZ | C10: =Sites[[#This Row],[SOL'#]] -> SOL-10753 | D10: =SUM('1st Qtr'!D10, '2nd Qtr'!D10, '3rd Qtr'!D10, '4th Qtr'!D10) -> 20748.02 | E10: =SUM('1st Qtr'!E10, '2nd Qtr'!E10, '3rd Qtr'!E10, '4th Qtr'!E10) -> 11827.436 | F10: =IF(AND(ISNUMBER(D10),ISNUMBER(E10)), D10-E10, "") -> 8920.584 | G10: =IFERROR(F10/E10, "") -> 0.75422805 | H10: =SUM('1st Qtr'!H10+'2nd Qtr'!H10+'3rd Qtr'!H10+'4th Qtr'!H10) -> 20246 | I10: =SUM('1st Qtr'!I10, '2nd Qtr'!I10, '3rd Qtr'!I10, '4th Qtr'!I10) -> 502.02 | J10: =IFERROR(I10/H10, "") -> 0.024796009
A11: Starshine | B11: AZ | C11: =Sites[[#This Row],[SOL'#]] -> SOL-10757 | D11: =SUM('1st Qtr'!D11, '2nd Qtr'!D11, '3rd Qtr'!D11, '4th Qtr'!D11) -> 10857.091 | E11: =SUM('1st Qtr'!E11, '2nd Qtr'!E11, '3rd Qtr'!E11, '4th Qtr'!E11) -> 0 | F11: =IF(AND(ISNUMBER(D11),ISNUMBER(E11)), D11-E11, "") -> 10857.091 | G11: =IFERROR(F11/E11, "") | H11: =SUM('1st Qtr'!H11+'2nd Qtr'!H11+'3rd Qtr'!H11+'4th Qtr'!H11) -> 11996 | I11: =SUM('1st Qtr'!I11, '2nd Qtr'!I11, '3rd Qtr'!I11, '4th Qtr'!I11) -> -1138.9093 | J11: =IFERROR(I11/H11, "") -> -0.094940753
A12: Yuma Airport | B12: AZ | C12: =Sites[[#This Row],[SOL'#]] -> SOL-10754 | D12: =SUM('1st Qtr'!D12, '2nd Qtr'!D12, '3rd Qtr'!D12, '4th Qtr'!D12) -> 119103 | E12: =SUM('1st Qtr'!E12, '2nd Qtr'!E12, '3rd Qtr'!E12, '4th Qtr'!E12) -> 154498.15 | F12: =IF(AND(ISNUMBER(D12),ISNUMBER(E12)), D12-E12, "") -> -35395.15 | G12: =IFERROR(F12/E12, "") -> -0.22909757 | H12: =SUM('1st Qtr'!H12+'2nd Qtr'!H12+'3rd Qtr'!H12+'4th Qtr'!H12) -> 122174 | I12: =SUM('1st Qtr'!I12, '2nd Qtr'!I12, '3rd Qtr'!I12, '4th Qtr'!I12) -> -3071 | J12: =IFERROR(I12/H12, "") -> -0.025136281
A13: Kinsman | B13: OH | C13: =Sites[[#This Row],[SOL'#]] -> SOL-10762 | D13: =SUM('1st Qtr'!D13, '2nd Qtr'!D13, '3rd Qtr'!D13, '4th Qtr'!D13) -> 50758.688 | E13: =SUM('1st Qtr'!E13, '2nd Qtr'!E13, '3rd Qtr'!E13, '4th Qtr'!E13) -> 113273.04 | F13: =IF(AND(ISNUMBER(D13),ISNUMBER(E13)), D13-E13, "") -> -62514.353 | G13: =IFERROR(F13/E13, "") -> -0.55189083 | H13: =SUM('1st Qtr'!H13+'2nd Qtr'!H13+'3rd Qtr'!H13+'4th Qtr'!H13) -> 114870 | I13: =SUM('1st Qtr'!I13, '2nd Qtr'!I13, '3rd Qtr'!I13, '4th Qtr'!I13) -> -64111.312 | J13: =IFERROR(I13/H13, "") -> -0.55812059
A14: Wooster | B14: OH | C14: =Sites[[#This Row],[SOL'#]] -> SOL-10763 | D14: =SUM('1st Qtr'!D14, '2nd Qtr'!D14, '3rd Qtr'!D14, '4th Qtr'!D14) -> 14987 | E14: =SUM('1st Qtr'!E14, '2nd Qtr'!E14, '3rd Qtr'!E14, '4th Qtr'!E14) -> 0 | F14: =IF(AND(ISNUMBER(D14),ISNUMBER(E14)), D14-E14, "") -> 14987 | G14: =IFERROR(F14/E14, "") | H14: =SUM('1st Qtr'!H14+'2nd Qtr'!H14+'3rd Qtr'!H14+'4th Qtr'!H14) -> 25006 | I14: =SUM('1st Qtr'!I14, '2nd Qtr'!I14, '3rd Qtr'!I14, '4th Qtr'!I14) -> -10019 | J14: =IFERROR(I14/H14, "") -> -0.40066384
A15: Globe Gila CC | B15: AZ | C15: =Sites[[#This Row],[SOL'#]] -> SOL-10755 | D15: =SUM('1st Qtr'!D15, '2nd Qtr'!D15, '3rd Qtr'!D15, '4th Qtr'!D15) -> 25524.33 | E15: =SUM('1st Qtr'!E15, '2nd Qtr'!E15, '3rd Qtr'!E15, '4th Qtr'!E15) -> 0 | F15: =IF(AND(ISNUMBER(D15),ISNUMBER(E15)), D15-E15, "") -> 25524.33 | G15: =IFERROR(F15/E15, "") | H15: =SUM('1st Qtr'!H15+'2nd Qtr'!H15+'3rd Qtr'!H15+'4th Qtr'!H15) -> 21672 | I15: =SUM('1st Qtr'!I15, '2nd Qtr'!I15, '3rd Qtr'!I15, '4th Qtr'!I15) -> 3852.3303 | J15: =IFERROR(I15/H15, "") -> 0.1777561
A16: Payson Gila CC | B16: AZ | C16: =Sites[[#This Row],[SOL'#]] -> SOL-10756 | D16: =SUM('1st Qtr'!D16, '2nd Qtr'!D16, '3rd Qtr'!D16, '4th Qtr'!D16) -> 18140.739 | E16: =SUM('1st Qtr'!E16, '2nd Qtr'!E16, '3rd Qtr'!E16, '4th Qtr'!E16) -> 8276.633 | F16: =IF(AND(ISNUMBER(D16),ISNUMBER(E16)), D16-E16, "") -> 9864.1058 | G16: =IFERROR(F16/E16, "") -> 1.1918018 | H16: =SUM('1st Qtr'!H16+'2nd Qtr'!H16+'3rd Qtr'!H16+'4th Qtr'!H16) -> 16910 | I16: =SUM('1st Qtr'!I16, '2nd Qtr'!I16, '3rd Qtr'!I16, '4th Qtr'!I16) -> 1230.7388 | J16: =IFERROR(I16/H16, "") -> 0.072781718
... A139: Spencer | B139: NY | C139: =Sites[[#This Row],[SOL'#]] -> SOL-11017 | D139: =SUM('1st Qtr'!D139, '2nd Qtr'!D139, '3rd Qtr'!D139, '4th Qtr'!D139) -> 920437 | E139: =SUM('1st Qtr'!E139, '2nd Qtr'!E139, '3rd Qtr'!E139, '4th Qtr'!E139) -> 0 | F139: =IF(AND(ISNUMBER(D139),ISNUMBER(E139)), D139-E139, "") -> 920437 | G139: =IFERROR(F139/E139, "") | H139: =SUM('1st Qtr'!H139+'2nd Qtr'!H139+'3rd Qtr'!H139+'4th Qtr'!H139) -> 946790.6 | I139: =SUM('1st Qtr'!I139, '2nd Qtr'!I139, '3rd Qtr'!I139, '4th Qtr'!I139) -> -26353.6 | J139: =IFERROR(I139/H139, "") -> -0.027834666
A140: Reisender | B140: NY | C140: ='1st Qtr'!C140 -> SOL-10886 | D140: =SUM('1st Qtr'!D140, '2nd Qtr'!D140, '3rd Qtr'!D140, '4th Qtr'!D140) -> 268510 | E140: =SUM('1st Qtr'!E140, '2nd Qtr'!E140, '3rd Qtr'!E140, '4th Qtr'!E140) -> 398487.05 | F140: =IF(AND(ISNUMBER(D140),ISNUMBER(E140)), D140-E140, "") -> -129977.05 | G140: =IFERROR(F140/E140, "") -> -0.32617635 | H140: =SUM('1st Qtr'!H140+'2nd Qtr'!H140+'3rd Qtr'!H140+'4th Qtr'!H140) -> 341969.8 | I140: =SUM('1st Qtr'!I140, '2nd Qtr'!I140, '3rd Qtr'!I140, '4th Qtr'!I140) -> -73459.8 | J140: =IFERROR(I140/H140, "") -> -0.21481371
A141: Finney | B141: NY | C141: =Sites[[#This Row],[SOL'#]] -> SOL-10999 | D141: =SUM('1st Qtr'!D141, '2nd Qtr'!D141, '3rd Qtr'!D141, '4th Qtr'!D141) -> 923020 | E141: =SUM('1st Qtr'!E141, '2nd Qtr'!E141, '3rd Qtr'!E141, '4th Qtr'!E141) -> 0 | F141: =IF(AND(ISNUMBER(D141),ISNUMBER(E141)), D141-E141, "") -> 923020 | G141: =IFERROR(F141/E141, "") | H141: =SUM('1st Qtr'!H141+'2nd Qtr'!H141+'3rd Qtr'!H141+'4th Qtr'!H141) -> 1054503.1 | I141: =SUM('1st Qtr'!I141, '2nd Qtr'!I141, '3rd Qtr'!I141, '4th Qtr'!I141) -> -131483.14 | J141: =IFERROR(I141/H141, "") -> -0.12468729
A142: Davis Solar | B142: NY | C142: =Sites[[#This Row],[SOL'#]] -> SOL-10958 | D142: =SUM('1st Qtr'!D142, '2nd Qtr'!D142, '3rd Qtr'!D142, '4th Qtr'!D142) -> 310390 | E142: =SUM('1st Qtr'!E142, '2nd Qtr'!E142, '3rd Qtr'!E142, '4th Qtr'!E142) -> 475110 | F142: =IF(AND(ISNUMBER(D142),ISNUMBER(E142)), D142-E142, "") -> -164720 | G142: =IFERROR(F142/E142, "") -> -0.34669866 | H142: =SUM('1st Qtr'!H142+'2nd Qtr'!H142+'3rd Qtr'!H142+'4th Qtr'!H142) -> 432046 | I142: =SUM('1st Qtr'!I142, '2nd Qtr'!I142, '3rd Qtr'!I142, '4th Qtr'!I142) -> -121656 | J142: =IFERROR(I142/H142, "") -> -0.28158113
A143: Genesee | B143: NY | C143: =Sites[[#This Row],[SOL'#]] -> SOL-10951 | D143: =SUM('1st Qtr'!D143, '2nd Qtr'!D143, '3rd Qtr'!D143, '4th Qtr'!D143) -> 399382.4 | E143: =SUM('1st Qtr'!E143, '2nd Qtr'!E143, '3rd Qtr'!E143, '4th Qtr'!E143) -> 0 | F143: =IF(AND(ISNUMBER(D143),ISNUMBER(E143)), D143-E143, "") -> 399382.4 | G143: =IFERROR(F143/E143, "") | H143: =SUM('1st Qtr'!H143+'2nd Qtr'!H143+'3rd Qtr'!H143+'4th Qtr'!H143) -> 588274 | I143: =SUM('1st Qtr'!I143, '2nd Qtr'!I143, '3rd Qtr'!I143, '4th Qtr'!I143) -> -188891.6 | J143: =IFERROR(I143/H143, "") -> -0.32109459
A144: Landau I | B144: NY | C144: =Sites[[#This Row],[SOL'#]] -> SOL-10891 | D144: =SUM('1st Qtr'!D144, '2nd Qtr'!D144, '3rd Qtr'!D144, '4th Qtr'!D144) -> 338750 | E144: =SUM('1st Qtr'!E144, '2nd Qtr'!E144, '3rd Qtr'!E144, '4th Qtr'!E144) -> 0 | F144: =IF(AND(ISNUMBER(D144),ISNUMBER(E144)), D144-E144, "") -> 338750 | G144: =IFERROR(F144/E144, "") | H144: =SUM('1st Qtr'!H144+'2nd Qtr'!H144+'3rd Qtr'!H144+'4th Qtr'!H144) -> 432107.5 | I144: =SUM('1st Qtr'!I144, '2nd Qtr'!I144, '3rd Qtr'!I144, '4th Qtr'!I144) -> -93357.5 | J144: =IFERROR(I144/H144, "") -> -0.21605156
A145: Landau II | B145: NY | C145: =Sites[[#This Row],[SOL'#]] -> SOL-10895 | D145: =SUM('1st Qtr'!D145, '2nd Qtr'!D145, '3rd Qtr'!D145, '4th Qtr'!D145) -> 664540 | E145: =SUM('1st Qtr'!E145, '2nd Qtr'!E145, '3rd Qtr'!E145, '4th Qtr'!E145) -> 0 | F145: =IF(AND(ISNUMBER(D145),ISNUMBER(E145)), D145-E145, "") -> 664540 | G145: =IFERROR(F145/E145, "") | H145: =SUM('1st Qtr'!H145+'2nd Qtr'!H145+'3rd Qtr'!H145+'4th Qtr'!H145) -> 875046.31 | I145: =SUM('1st Qtr'!I145, '2nd Qtr'!I145, '3rd Qtr'!I145, '4th Qtr'!I145) -> -210506.31 | J145: =IFERROR(I145/H145, "") -> -0.24056591
A146: New Beginnings | B146: NY | C146: =Sites[[#This Row],[SOL'#]] -> SOL-10890 | D146: =SUM('1st Qtr'!D146, '2nd Qtr'!D146, '3rd Qtr'!D146, '4th Qtr'!D146) -> 330300 | E146: =SUM('1st Qtr'!E146, '2nd Qtr'!E146, '3rd Qtr'!E146, '4th Qtr'!E146) -> 501850.24 | F146: =IF(AND(ISNUMBER(D146),ISNUMBER(E146)), D146-E146, "") -> -171550.24 | G146: =IFERROR(F146/E146, "") -> -0.34183552 | H146: =SUM('1st Qtr'!H146+'2nd Qtr'!H146+'3rd Qtr'!H146+'4th Qtr'!H146) -> 430987.04 | I146: =SUM('1st Qtr'!I146, '2nd Qtr'!I146, '3rd Qtr'!I146, '4th Qtr'!I146) -> -100687.04 | J146: =IFERROR(I146/H146, "") -> -0.23361965
A147: Guilin Farm Solar | B147: NY | C147: =Sites[[#This Row],[SOL'#]] -> SOL-10998 | D147: =SUM('1st Qtr'!D147, '2nd Qtr'!D147, '3rd Qtr'!D147, '4th Qtr'!D147) -> 472982 | E147: =SUM('1st Qtr'!E147, '2nd Qtr'!E147, '3rd Qtr'!E147, '4th Qtr'!E147) -> 782733.28 | F147: =IF(AND(ISNUMBER(D147),ISNUMBER(E147)), D147-E147, "") -> -309751.28 | G147: =IFERROR(F147/E147, "") -> -0.39573031 | H147: =SUM('1st Qtr'!H147+'2nd Qtr'!H147+'3rd Qtr'!H147+'4th Qtr'!H147) -> 919749.1 | I147: =SUM('1st Qtr'!I147, '2nd Qtr'!I147, '3rd Qtr'!I147, '4th Qtr'!I147) -> -446767.1 | J147: =IFERROR(I147/H147, "") -> -0.48574889
A148: Brodhead Solar | B148: NY | C148: =Sites[[#This Row],[SOL'#]] -> SOL-10899 | D148: =SUM('1st Qtr'!D148, '2nd Qtr'!D148, '3rd Qtr'!D148, '4th Qtr'!D148) -> 465667 | E148: =SUM('1st Qtr'!E148, '2nd Qtr'!E148, '3rd Qtr'!E148, '4th Qtr'!E148) -> 511711.59 | F148: =IF(AND(ISNUMBER(D148),ISNUMBER(E148)), D148-E148, "") -> -46044.59 | G148: =IFERROR(F148/E148, "") -> -0.089981527 | H148: =SUM('1st Qtr'!H148+'2nd Qtr'!H148+'3rd Qtr'!H148+'4th Qtr'!H148) -> 484125.64 | I148: =SUM('1st Qtr'!I148, '2nd Qtr'!I148, '3rd Qtr'!I148, '4th Qtr'!I148) -> -18458.64 | J148: =IFERROR(I148/H148, "") -> -0.038127788
A149: Svenski | B149: NY | C149: =Sites[[#This Row],[SOL'#]] -> SOL-10894 | D149: =SUM('1st Qtr'!D149, '2nd Qtr'!D149, '3rd Qtr'!D149, '4th Qtr'!D149) -> 300639 | E149: =SUM('1st Qtr'!E149, '2nd Qtr'!E149, '3rd Qtr'!E149, '4th Qtr'!E149) -> 0 | F149: =IF(AND(ISNUMBER(D149),ISNUMBER(E149)), D149-E149, "") -> 300639 | G149: =IFERROR(F149/E149, "") | H149: =SUM('1st Qtr'!H149+'2nd Qtr'!H149+'3rd Qtr'!H149+'4th Qtr'!H149) -> 382839.93 | I149: =SUM('1st Qtr'!I149, '2nd Qtr'!I149, '3rd Qtr'!I149, '4th Qtr'!I149) -> -82200.93 | J149: =IFERROR(I149/H149, "") -> -0.21471357
A150: Bantam | B150: NY | C150: =Sites[[#This Row],[SOL'#]] -> SOL-10986 | D150: =SUM('1st Qtr'!D150, '2nd Qtr'!D150, '3rd Qtr'!D150, '4th Qtr'!D150) -> 179360 | E150: =SUM('1st Qtr'!E150, '2nd Qtr'!E150, '3rd Qtr'!E150, '4th Qtr'!E150) -> 0 | F150: =IF(AND(ISNUMBER(D150),ISNUMBER(E150)), D150-E150, "") -> 179360 | G150: =IFERROR(F150/E150, "") | H150: =SUM('1st Qtr'!H150+'2nd Qtr'!H150+'3rd Qtr'!H150+'4th Qtr'!H150) -> 574351.3 | I150: =SUM('1st Qtr'!I150, '2nd Qtr'!I150, '3rd Qtr'!I150, '4th Qtr'!I150) -> -501581.3 | J150: =IFERROR(I150/H150, "") -> -0.87330054
A151: Bogart | B151: NY | C151: =Sites[[#This Row],[SOL'#]] -> SOL-10887 | D151: =SUM('1st Qtr'!D151, '2nd Qtr'!D151, '3rd Qtr'!D151, '4th Qtr'!D151) -> 375590 | E151: =SUM('1st Qtr'!E151, '2nd Qtr'!E151, '3rd Qtr'!E151, '4th Qtr'!E151) -> 458994.12 | F151: =IF(AND(ISNUMBER(D151),ISNUMBER(E151)), D151-E151, "") -> -83404.119 | G151: =IFERROR(F151/E151, "") -> -0.18171065 | H151: =SUM('1st Qtr'!H151+'2nd Qtr'!H151+'3rd Qtr'!H151+'4th Qtr'!H151) -> 395223.1 | I151: =SUM('1st Qtr'!I151, '2nd Qtr'!I151, '3rd Qtr'!I151, '4th Qtr'!I151) -> -19633.1 | J151: =IFERROR(I151/H151, "") -> -0.049675993
A152: Dubois | B152: NY | C152: =Sites[[#This Row],[SOL'#]] -> SOL-10892 | D152: =SUM('1st Qtr'!D152, '2nd Qtr'!D152, '3rd Qtr'!D152, '4th Qtr'!D152) -> 302008.49 | E152: =SUM('1st Qtr'!E152, '2nd Qtr'!E152, '3rd Qtr'!E152, '4th Qtr'!E152) -> 0 | F152: =IF(AND(ISNUMBER(D152),ISNUMBER(E152)), D152-E152, "") -> 302008.49 | G152: =IFERROR(F152/E152, "") | H152: =SUM('1st Qtr'!H152+'2nd Qtr'!H152+'3rd Qtr'!H152+'4th Qtr'!H152) -> 0 | I152: =SUM('1st Qtr'!I152, '2nd Qtr'!I152, '3rd Qtr'!I152, '4th Qtr'!I152) -> 0 | J152: =IFERROR(I152/H152, "")
... A195: O'Brien Hill #2 | B195: NY | C195: =Sites[[#This Row],[SOL'#]] -> SOL-11099 | D195: =SUM('1st Qtr'!D195, '2nd Qtr'!D195, '3rd Qtr'!D195, '4th Qtr'!D195) -> 679007 | E195: =SUM('1st Qtr'!E195, '2nd Qtr'!E195, '3rd Qtr'!E195, '4th Qtr'!E195) -> 0 | F195: =IF(AND(ISNUMBER(D195),ISNUMBER(E195)), D195-E195, "") -> 679007 | G195: =IFERROR(F195/E195, "") | H195: =SUM('1st Qtr'!H195+'2nd Qtr'!H195+'3rd Qtr'!H195+'4th Qtr'!H195) -> 0 | I195: =SUM('1st Qtr'!I195, '2nd Qtr'!I195, '3rd Qtr'!I195, '4th Qtr'!I195) -> 679007 | J195: =IFERROR(I195/H195, "")
A196: Trinity - Freeport | B196: IL
A197: Ransom | B197: NY
A198: Horseheads - Wedge | B198: NY
A199: Otisville - Shoddy Hollow | B199: NY
A200: Wellsville - Chenunda Creek | B200: NY

Sheet 1st Qtr
A1: {=portfolio} -> Generate Capital | E1: 1st Quarter Actual v. Expected | H1: 1st Quarter Actual v. Forecasted
A2: Total | D2: =SUM(D4:D238) -> 36184982 | E2: =SUM(E4:E138) -> 11083899 | F2: =D2-E2 -> 25101083 | G2: =IFERROR(F2/E2, 0) -> 2.2646438 | H2: =SUM(H4:H238) -> 44326916 | I2: =D2-H2 -> -8141933.2 | J2: =IFERROR(I2/H2, 0) -> -0.18367922
A3: Site | B3: State | C3: SOL# | D3: Actual | E3: Expected | F3: Delta | G3: % | H3: Forecasted | I3: Delta | J3: %
A4: {=Sites[Site]} -> Farmer | B4: {=Sites[State]} -> AZ | C4: =Sites[[#This Row],[SOL'#]] -> SOL-10748 | D4: =SUM(Jan!D4, Feb!D4, Mar!D4) -> 20596.299 | E4: =SUM(Jan!E4, Feb!E4, Mar!E4) -> 15241.424 | F4: =IF(AND(ISNUMBER(D4),ISNUMBER(E4)), D4-E4, "") -> 5354.8755 | G4: =IFERROR(F4/E4, "") -> 0.35133695 | H4: =SUM(Jan!H4, Feb!H4, Mar!H4) -> 18595.628 | I4: =SUM(Jan!I4, Feb!I4, Mar!I4) -> 2000.6715 | J4: =IFERROR(I4/H4, "") -> 0.10758827
A5: Fulton | B5: AZ | C5: =Sites[[#This Row],[SOL'#]] -> SOL-10749 | D5: =SUM(Jan!D5, Feb!D5, Mar!D5) -> 57128.5 | E5: =SUM(Jan!E5, Feb!E5, Mar!E5) -> 75239.48 | F5: =IF(AND(ISNUMBER(D5),ISNUMBER(E5)), D5-E5, "") -> -18110.98 | G5: =IFERROR(F5/E5, "") -> -0.24071113 | H5: =SUM(Jan!H5, Feb!H5, Mar!H5) -> 74528.36 | I5: =SUM(Jan!I5, Feb!I5, Mar!I5) -> -17399.86 | J5: =IFERROR(I5/H5, "") -> -0.23346629
A6: JFK Elementary | B6: AZ | C6: =Sites[[#This Row],[SOL'#]] -> SOL-10758 | D6: =SUM(Jan!D6, Feb!D6, Mar!D6) -> 34707.198 | E6: =SUM(Jan!E6, Feb!E6, Mar!E6) -> 0 | F6: =IF(AND(ISNUMBER(D6),ISNUMBER(E6)), D6-E6, "") -> 34707.198 | G6: =IFERROR(F6/E6, "") | H6: =SUM(Jan!H6, Feb!H6, Mar!H6) -> 30463 | I6: =SUM(Jan!I6, Feb!I6, Mar!I6) -> 4244.198 | J6: =IFERROR(I6/H6, "") -> 0.13932305
A7: Noble | B7: AZ | C7: =Sites[[#This Row],[SOL'#]] -> SOL-10750 | D7: =SUM(Jan!D7, Feb!D7, Mar!D7) -> 19862.485 | E7: =SUM(Jan!E7, Feb!E7, Mar!E7) -> 25711.63 | F7: =IF(AND(ISNUMBER(D7),ISNUMBER(E7)), D7-E7, "") -> -5849.1445 | G7: =IFERROR(F7/E7, "") -> -0.22749023 | H7: =SUM(Jan!H7, Feb!H7, Mar!H7) -> 20305.238 | I7: =SUM(Jan!I7, Feb!I7, Mar!I7) -> -442.75251 | J7: =IFERROR(I7/H7, "") -> -0.021804842
A8: Parking 3 | B8: AZ | C8: =Sites[[#This Row],[SOL'#]] -> SOL-10751 | D8: =SUM(Jan!D8, Feb!D8, Mar!D8) -> 52632.387 | E8: =SUM(Jan!E8, Feb!E8, Mar!E8) -> 36461.69 | F8: =IF(AND(ISNUMBER(D8),ISNUMBER(E8)), D8-E8, "") -> 16170.697 | G8: =IFERROR(F8/E8, "") -> 0.4434983 | H8: =SUM(Jan!H8, Feb!H8, Mar!H8) -> 45223.83 | I8: =SUM(Jan!I8, Feb!I8, Mar!I8) -> 7408.5575 | J8: =IFERROR(I8/H8, "") -> 0.16381977
A9: PE East | B9: AZ | C9: =Sites[[#This Row],[SOL'#]] -> SOL-10752 | D9: =SUM(Jan!D9, Feb!D9, Mar!D9) -> 45253.447 | E9: =SUM(Jan!E9, Feb!E9, Mar!E9) -> 28727.75 | F9: =IF(AND(ISNUMBER(D9),ISNUMBER(E9)), D9-E9, "") -> 16525.697 | G9: =IFERROR(F9/E9, "") -> 0.57525205 | H9: =SUM(Jan!H9, Feb!H9, Mar!H9) -> 45859.64 | I9: =SUM(Jan!I9, Feb!I9, Mar!I9) -> -606.19288 | J9: =IFERROR(I9/H9, "") -> -0.01321844
A10: Schwada | B10: AZ | C10: =Sites[[#This Row],[SOL'#]] -> SOL-10753 | D10: =SUM(Jan!D10, Feb!D10, Mar!D10) -> 20748.02 | E10: =SUM(Jan!E10, Feb!E10, Mar!E10) -> 11827.436 | F10: =IF(AND(ISNUMBER(D10),ISNUMBER(E10)), D10-E10, "") -> 8920.584 | G10: =IFERROR(F10/E10, "") -> 0.75422805 | H10: =SUM(Jan!H10, Feb!H10, Mar!H10) -> 20246 | I10: =SUM(Jan!I10, Feb!I10, Mar!I10) -> 502.02 | J10: =IFERROR(I10/H10, "") -> 0.024796009
A11: Starshine | B11: AZ | C11: =Sites[[#This Row],[SOL'#]] -> SOL-10757 | D11: =SUM(Jan!D11, Feb!D11, Mar!D11) -> 10857.091 | E11: =SUM(Jan!E11, Feb!E11, Mar!E11) -> 0 | F11: =IF(AND(ISNUMBER(D11),ISNUMBER(E11)), D11-E11, "") -> 10857.091 | G11: =IFERROR(F11/E11, "") | H11: =SUM(Jan!H11, Feb!H11, Mar!H11) -> 11996 | I11: =SUM(Jan!I11, Feb!I11, Mar!I11) -> -1138.9093 | J11: =IFERROR(I11/H11, "") -> -0.094940753
A12: Yuma Airport | B12: AZ | C12: =Sites[[#This Row],[SOL'#]] -> SOL-10754 | D12: =SUM(Jan!D12, Feb!D12, Mar!D12) -> 119103 | E12: =SUM(Jan!E12, Feb!E12, Mar!E12) -> 154498.15 | F12: =IF(AND(ISNUMBER(D12),ISNUMBER(E12)), D12-E12, "") -> -35395.15 | G12: =IFERROR(F12/E12, "") -> -0.22909757 | H12: =SUM(Jan!H12, Feb!H12, Mar!H12) -> 122174 | I12: =SUM(Jan!I12, Feb!I12, Mar!I12) -> -3071 | J12: =IFERROR(I12/H12, "") -> -0.025136281
A13: Kinsman | B13: OH | C13: =Sites[[#This Row],[SOL'#]] -> SOL-10762 | D13: =SUM(Jan!D13, Feb!D13, Mar!D13) -> 50758.688 | E13: =SUM(Jan!E13, Feb!E13, Mar!E13) -> 113273.04 | F13: =IF(AND(ISNUMBER(D13),ISNUMBER(E13)), D13-E13, "") -> -62514.353 | G13: =IFERROR(F13/E13, "") -> -0.55189083 | H13: =SUM(Jan!H13, Feb!H13, Mar!H13) -> 114870 | I13: =SUM(Jan!I13, Feb!I13, Mar!I13) -> -64111.312 | J13: =IFERROR(I13/H13, "") -> -0.55812059
A14: Wooster | B14: OH | C14: =Sites[[#This Row],[SOL'#]] -> SOL-10763 | D14: =SUM(Jan!D14, Feb!D14, Mar!D14) -> 14987 | E14: =SUM(Jan!E14, Feb!E14, Mar!E14) -> 0 | F14: =IF(AND(ISNUMBER(D14),ISNUMBER(E14)), D14-E14, "") -> 14987 | G14: =IFERROR(F14/E14, "") | H14: =SUM(Jan!H14, Feb!H14, Mar!H14) -> 25006 | I14: =SUM(Jan!I14, Feb!I14, Mar!I14) -> -10019 | J14: =IFERROR(I14/H14, "") -> -0.40066384
A15: Globe Gila CC | B15: AZ | C15: =Sites[[#This Row],[SOL'#]] -> SOL-10755 | D15: =SUM(Jan!D15, Feb!D15, Mar!D15) -> 25524.33 | E15: =SUM(Jan!E15, Feb!E15, Mar!E15) -> 0 | F15: =IF(AND(ISNUMBER(D15),ISNUMBER(E15)), D15-E15, "") -> 25524.33 | G15: =IFERROR(F15/E15, "") | H15: =SUM(Jan!H15, Feb!H15, Mar!H15) -> 21672 | I15: =SUM(Jan!I15, Feb!I15, Mar!I15) -> 3852.3303 | J15: =IFERROR(I15/H15, "") -> 0.1777561
A16: Payson Gila CC | B16: AZ | C16: =Sites[[#This Row],[SOL'#]] -> SOL-10756 | D16: =SUM(Jan!D16, Feb!D16, Mar!D16) -> 18140.739 | E16: =SUM(Jan!E16, Feb!E16, Mar!E16) -> 8276.633 | F16: =IF(AND(ISNUMBER(D16),ISNUMBER(E16)), D16-E16, "") -> 9864.1058 | G16: =IFERROR(F16/E16, "") -> 1.1918018 | H16: =SUM(Jan!H16, Feb!H16, Mar!H16) -> 16910 | I16: =SUM(Jan!I16, Feb!I16, Mar!I16) -> 1230.7388 | J16: =IFERROR(I16/H16, "") -> 0.072781718
... A63: X024 | B63: NY | C63: =Sites[[#This Row],[SOL'#]] -> SOL-10419 | D63: =SUM(Jan!D63, Feb!D63, Mar!D63) -> 21164.125 | E63: =SUM(Jan!E63, Feb!E63, Mar!E63) -> 32847.53 | F63: =IF(AND(ISNUMBER(D63),ISNUMBER(E63)), D63-E63, "") -> -11683.405 | G63: =IFERROR(F63/E63, "") -> -0.35568595 | H63: =SUM(Jan!H63, Feb!H63, Mar!H63) -> 20185 | I63: =SUM(Jan!I63, Feb!I63, Mar!I63) -> 979.125 | J63: =IFERROR(I63/H63, "") -> 0.048507555
A64: X026 | B64: NY | C64: =Sites[[#This Row],[SOL'#]] -> SOL-10420 | D64: =SUM(Jan!D65, Feb!D64, Mar!D64) -> 18474.694 | E64: =SUM(Jan!E64, Feb!E64, Mar!E64) -> 25086.2 | F64: =IF(AND(ISNUMBER(D64),ISNUMBER(E64)), D64-E64, "") -> -6611.5063 | G64: =IFERROR(F64/E64, "") -> -0.26355152 | H64: =SUM(Jan!H64, Feb!H64, Mar!H64) -> 26320.25 | I64: =SUM(Jan!I64, Feb!I64, Mar!I64) -> -8932.35 | J64: =IFERROR(I64/H64, "") -> -0.33937178
A65: X090 | B65: NY | C65: =Sites[[#This Row],[SOL'#]] -> SOL-10925 | D65: =SUM(Jan!D65, Feb!D65, Mar!D65) -> 18352.969 | E65: =SUM(Jan!E65, Feb!E65, Mar!E65) -> 15767.785 | F65: =IF(AND(ISNUMBER(D65),ISNUMBER(E65)), D65-E65, "") -> 2585.1838 | G65: =IFERROR(F65/E65, "") -> 0.16395351 | H65: =SUM(Jan!H65, Feb!H65, Mar!H65) -> 17306 | I65: =SUM(Jan!I65, Feb!I65, Mar!I65) -> 1046.9688 | J65: =IFERROR(I65/H65, "") -> 0.060497443
A66: X117 | B66: NY | C66: =Sites[[#This Row],[SOL'#]] -> SOL-10422 | D66: =SUM(Jan!D66, Feb!D66, Mar!D66) -> 13593.7 | E66: =SUM(Jan!E66, Feb!E66, Mar!E66) -> 21112.797 | F66: =IF(AND(ISNUMBER(D66),ISNUMBER(E66)), D66-E66, "") -> -7519.097 | G66: =IFERROR(F66/E66, "") -> -0.35613931 | H66: =SUM(Jan!H66, Feb!H66, Mar!H66) -> 15200.449 | I66: =SUM(Jan!I66, Feb!I66, Mar!I66) -> -1606.749 | J66: =IFERROR(I66/H66, "") -> -0.10570405
A67: X125 | B67: NY | C67: =Sites[[#This Row],[SOL'#]] -> SOL-10423 | D67: =SUM(Jan!D67, Feb!D67, Mar!D67) -> 27862.875 | E67: =SUM(Jan!E67, Feb!E67, Mar!E67) -> 35839.7 | F67: =IF(AND(ISNUMBER(D67),ISNUMBER(E67)), D67-E67, "") -> -7976.825 | G67: =IFERROR(F67/E67, "") -> -0.22256952 | H67: =SUM(Jan!H67, Feb!H67, Mar!H67) -> 27441.48 | I67: =SUM(Jan!I67, Feb!I67, Mar!I67) -> 421.395 | J67: =IFERROR(I67/H67, "") -> 0.015356132
A68: X134 | B68: NY | C68: =Sites[[#This Row],[SOL'#]] -> SOL-10424 | D68: =SUM(Jan!D68, Feb!D68, Mar!D68) -> 25520.719 | E68: =SUM(Jan!E68, Feb!E68, Mar!E68) -> 0 | F68: =IF(AND(ISNUMBER(D68),ISNUMBER(E68)), D68-E68, "") -> 25520.719 | G68: =IFERROR(F68/E68, "") | H68: =SUM(Jan!H68, Feb!H68, Mar!H68) -> 25319 | I68: =SUM(Jan!I68, Feb!I68, Mar!I68) -> 201.71875 | J68: =IFERROR(I68/H68, "") -> 0.0079670899
A69: X135 | B69: NY | C69: =Sites[[#This Row],[SOL'#]] -> SOL-10425 | D69: =SUM(Jan!D69, Feb!D69, Mar!D69) -> 22640.875 | E69: =SUM(Jan!E69, Feb!E69, Mar!E69) -> 30416.89 | F69: =IF(AND(ISNUMBER(D69),ISNUMBER(E69)), D69-E69, "") -> -7776.015 | G69: =IFERROR(F69/E69, "") -> -0.25564793 | H69: =SUM(Jan!H69, Feb!H69, Mar!H69) -> 22942 | I69: =SUM(Jan!I69, Feb!I69, Mar!I69) -> -301.125 | J69: =IFERROR(I69/H69, "") -> -0.01312549
A70: X139 JHS 222 | B70: NY | C70: =Sites[[#This Row],[SOL'#]] -> SOL-10426 | D70: =SUM(Jan!D70, Feb!D70, Mar!D70) -> 31836.042 | E70: =SUM(Jan!E70, Feb!E70, Mar!E70) -> 38745.4 | F70: =IF(AND(ISNUMBER(D70),ISNUMBER(E70)), D70-E70, "") -> -6909.3577 | G70: =IFERROR(F70/E70, "") -> -0.17832717 | H70: =SUM(Jan!H70, Feb!H70, Mar!H70) -> 30060 | I70: =SUM(Jan!I70, Feb!I70, Mar!I70) -> 1776.0423 | J70: =IFERROR(I70/H70, "") -> 0.059083243
A71: X140 | B71: NY | C71: =Sites[[#This Row],[SOL'#]] -> SOL-10926 | D71: =SUM(Jan!D71, Feb!D71, Mar!D71) -> 20066.062 | E71: =SUM(Jan!E71, Feb!E71, Mar!E71) -> 19323.734 | F71: =IF(AND(ISNUMBER(D71),ISNUMBER(E71)), D71-E71, "") -> 742.3285 | G71: =IFERROR(F71/E71, "") -> 0.038415376 | H71: =SUM(Jan!H71, Feb!H71, Mar!H71) -> 19179 | I71: =SUM(Jan!I71, Feb!I71, Mar!I71) -> 887.0625 | J71: =IFERROR(I71/H71, "") -> 0.04625176
A72: X166 | B72: NY | C72: =Sites[[#This Row],[SOL'#]] -> SOL-10427 | D72: =SUM(Jan!D72, Feb!D72, Mar!D72) -> 19802.7 | E72: =SUM(Jan!E72, Feb!E72, Mar!E72) -> 27535.22 | F72: =IF(AND(ISNUMBER(D72),ISNUMBER(E72)), D72-E72, "") -> -7732.52 | G72: =IFERROR(F72/E72, "") -> -0.28082289 | H72: =SUM(Jan!H72, Feb!H72, Mar!H72) -> 18312 | I72: =SUM(Jan!I72, Feb!I72, Mar!I72) -> 1490.7 | J72: =IFERROR(I72/H72, "") -> 0.081405636
A73: Murphy | B73: MN | C73: =Sites[[#This Row],[SOL'#]] -> SOL-10094 | D73: =SUM(Jan!D73, Feb!D73, Mar!D73) -> 972550 | E73: =SUM(Jan!E73, Feb!E73, Mar!E73) -> 1403405.5 | F73: =IF(AND(ISNUMBER(D73),ISNUMBER(E73)), D73-E73, "") -> -430855.5 | G73: =IFERROR(F73/E73, "") -> -0.30700713 | H73: =SUM(Jan!H73, Feb!H73, Mar!H73) -> 1182420.3 | I73: =SUM(Jan!I73, Feb!I73, Mar!I73) -> -209870.3 | J73: =IFERROR(I73/H73, "") -> -0.17749213
A74: Terning | B74: MN | C74: =Sites[[#This Row],[SOL'#]] -> SOL-10093 | D74: =SUM(Jan!D74, Feb!D74, Mar!D74) -> 876363 | E74: =SUM(Jan!E74, Feb!E74, Mar!E74) -> 1389458.1 | F74: =IF(AND(ISNUMBER(D74),ISNUMBER(E74)), D74-E74, "") -> -513095.1 | G74: =IFERROR(F74/E74, "") -> -0.36927713 | H74: =SUM(Jan!H74, Feb!H74, Mar!H74) -> 1096712.8 | I74: =SUM(Jan!I74, Feb!I74, Mar!I74) -> -220349.8 | J74: =IFERROR(I74/H74, "") -> -0.20091842
A75: Boas Road 04 | B75: NY | C75: =Sites[[#This Row],[SOL'#]] -> SOL-10908 | D75: =SUM(Jan!D75, Feb!D75, Mar!D75) -> 266506 | E75: =SUM(Jan!E75, Feb!E75, Mar!E75) -> 431942.94 | F75: =IF(AND(ISNUMBER(D75),ISNUMBER(E75)), D75-E75, "") -> -165436.94 | G75: =IFERROR(F75/E75, "") -> -0.38300647 | H75: =SUM(Jan!H75, Feb!H75, Mar!H75) -> 376445.96 | I75: =SUM(Jan!I75, Feb!I75, Mar!I75) -> -109939.96 | J75: =IFERROR(I75/H75, "") -> -0.29204712
A76: Kelly Bridge Farm | B76: NY | C76: =Sites[[#This Row],[SOL'#]] -> SOL-10911 | D76: =SUM(Jan!D76, Feb!D76, Mar!D76) -> 235022 | E76: =SUM(Jan!E76, Feb!E76, Mar!E76) -> 414631.51 | F76: =IF(AND(ISNUMBER(D76),ISNUMBER(E76)), D76-E76, "") -> -179609.51 | G76: =IFERROR(F76/E76, "") -> -0.43317862 | H76: =SUM(Jan!H76, Feb!H76, Mar!H76) -> 354015.2 | I76: =SUM(Jan!I76, Feb!I76, Mar!I76) -> -118993.2 | J76: =IFERROR(I76/H76, "") -> -0.33612455
... A123: Bird in Hand | B123: MD | C123: =Sites[[#This Row],[SOL'#]] -> SOL-10092 | D123: =SUM(Jan!D123, Feb!D123, Mar!D123) -> 214303 | E123: =SUM(Jan!E123, Feb!E123, Mar!E123) -> 243641.1 | F123: =IF(AND(ISNUMBER(D123),ISNUMBER(E123)), D123-E123, "") -> -29338.1 | G123: =IFERROR(F123/E123, "") -> -0.12041523 | H123: =SUM(Jan!H123, Feb!H123, Mar!H123) -> 182082.81 | I123: =SUM(Jan!I123, Feb!I123, Mar!I123) -> 32220.19 | J123: =IFERROR(I123/H123, "") -> 0.1769535
A124: Shortal | B124: MD | C124: =Sites[[#This Row],[SOL'#]] -> SOL-10091 | D124: =SUM(Jan!D124, Feb!D125, Mar!D124) -> 115755 | E124: =SUM(Jan!E124, Feb!E124, Mar!E124) -> 173008.45 | F124: =IF(AND(ISNUMBER(D124),ISNUMBER(E124)), D124-E124, "") -> -57253.45 | G124: =IFERROR(F124/E124, "") -> -0.33092863 | H124: =SUM(Jan!H124, Feb!H124, Mar!H124) -> 267045.6 | I124: =SUM(Jan!I124, Feb!I124, Mar!I124) -> -151290.6 | J124: =IFERROR(I124/H124, "") -> -0.5665347
A125: Aguadilla | B125: PR | C125: =Sites[[#This Row],[SOL'#]] -> SOL-10072 | D125: =SUM(Jan!D125, Feb!D125, Mar!D125) -> 26593 | E125: =SUM(Jan!E125, Feb!E125, Mar!E125) -> 31201.53 | F125: =IF(AND(ISNUMBER(D125),ISNUMBER(E125)), D125-E125, "") -> -4608.53 | G125: =IFERROR(F125/E125, "") -> -0.14770205 | H125: =SUM(Jan!H125, Feb!H125, Mar!H125) -> 35161 | I125: =SUM(Jan!I125, Feb!I125, Mar!I125) -> -8568 | J125: =IFERROR(I125/H125, "") -> -0.24367908
A126: Bayamon | B126: PR | C126: =Sites[[#This Row],[SOL'#]] -> SOL-10073 | D126: =SUM(Jan!D126, Feb!D126, Mar!D126) -> 99947 | E126: =SUM(Jan!E126, Feb!E126, Mar!E126) -> 123259.5 | F126: =IF(AND(ISNUMBER(D126),ISNUMBER(E126)), D126-E126, "") -> -23312.5 | G126: =IFERROR(F126/E126, "") -> -0.18913349 | H126: =SUM(Jan!H126, Feb!H126, Mar!H126) -> 139016 | I126: =SUM(Jan!I126, Feb!I126, Mar!I126) -> -39069 | J126: =IFERROR(I126/H126, "") -> -0.28103959
A127: St Francis | B127: PR | C127: =Sites[[#This Row],[SOL'#]] -> SOL-10034 | D127: =SUM(Jan!D127, Feb!D127, Mar!D127) -> 35492.75 | E127: =SUM(Jan!E127, Feb!E127, Mar!E127) -> 72649 | F127: =IF(AND(ISNUMBER(D127),ISNUMBER(E127)), D127-E127, "") -> -37156.25 | G127: =IFERROR(F127/E127, "") -> -0.51144888 | H127: =SUM(Jan!H127, Feb!H127, Mar!H127) -> 66619 | I127: =SUM(Jan!I127, Feb!I127, Mar!I127) -> -31126.25 | J127: =IFERROR(I127/H127, "") -> -0.46722782
A128: Seaport | B128: MA | C128: =Sites[[#This Row],[SOL'#]] -> SOL-10772 | D128: =SUM(Jan!D128, Feb!D128, Mar!D128) -> 51453.5 | E128: =SUM(Jan!E128, Feb!E128, Mar!E128) -> 1797.3565 | F128: =IF(AND(ISNUMBER(D128),ISNUMBER(E128)), D128-E128, "") -> 49656.143 | G128: =IFERROR(F128/E128, "") -> 27.62732 | H128: =SUM(Jan!H128, Feb!H128, Mar!H128) -> 57498.41 | I128: =SUM(Jan!I128, Feb!I128, Mar!I128) -> -6044.91 | J128: =IFERROR(I128/H128, "") -> -0.10513178
A129: Sprague St | B129: MA | C129: =Sites[[#This Row],[SOL'#]] -> SOL-10773 | D129: =SUM(Jan!D129, Feb!D129, Mar!D129) -> 98861 | E129: =SUM(Jan!E129, Feb!E129, Mar!E129) -> 154465.14 | F129: =IF(AND(ISNUMBER(D129),ISNUMBER(E129)), D129-E129, "") -> -55604.14 | G129: =IFERROR(F129/E129, "") -> -0.35997857 | H129: =SUM(Jan!H129, Feb!H129, Mar!H129) -> 120158.58 | I129: =SUM(Jan!I129, Feb!I129, Mar!I129) -> -21297.58 | J129: =IFERROR(I129/H129, "") -> -0.1772456
A130: Summer St | B130: MA | C130: =Sites[[#This Row],[SOL'#]] -> SOL-10764 | D130: =SUM(Jan!D130, Feb!D130, Mar!D130) -> 242424 | E130: =SUM(Jan!E130, Feb!E130, Mar!E130) -> 327994.5 | F130: =IF(AND(ISNUMBER(D130),ISNUMBER(E130)), D130-E130, "") -> -85570.5 | G130: =IFERROR(F130/E130, "") -> -0.26089005 | H130: =SUM(Jan!H130, Feb!H130, Mar!H130) -> 292189.9 | I130: =SUM(Jan!I130, Feb!I130, Mar!I130) -> -49765.9 | J130: =IFERROR(I130/H130, "") -> -0.1703204
A131: Brock St Vocational | B131: NH | C131: =Sites[[#This Row],[SOL'#]] -> SOL-10768 | D131: =SUM(Jan!D131, Feb!D131, Mar!D131) -> 2937.8792 | E131: =SUM(Jan!E131, Feb!E131, Mar!E131) -> 10561.221 | F131: =IF(AND(ISNUMBER(D131),ISNUMBER(E131)), D131-E131, "") -> -7623.3418 | G131: =IFERROR(F131/E131, "") -> -0.7218239 | H131: =SUM(Jan!H131, Feb!H131, Mar!H131) -> 10594.157 | I131: =SUM(Jan!I131, Feb!I131, Mar!I131) -> -7656.2778 | J131: =IFERROR(I131/H131, "") -> -0.72268872
A132: McClelland ES | B132: NH | C132: =Sites[[#This Row],[SOL'#]] -> SOL-10766 | D132: =SUM(Jan!D132, Feb!D132, Mar!D132) -> 3996.7186 | E132: =SUM(Jan!E132, Feb!E132, Mar!E132) -> 14026.048 | F132: =IF(AND(ISNUMBER(D132),ISNUMBER(E132)), D132-E132, "") -> -10029.329 | G132: =IFERROR(F132/E132, "") -> -0.71505027 | H132: =SUM(Jan!H132, Feb!H132, Mar!H132) -> 7871.903 | I132: =SUM(Jan!I132, Feb!I132, Mar!I132) -> -3875.1844 | J132: =IFERROR(I132/H132, "") -> -0.49228051
...

Sheet 2nd Qtr
A1: {=portfolio} -> Generate Capital | E1: 2nd Quarter Actual v. Expected | H1: 2nd Quarter Actual v. Forecasted
A2: Total | D2: =SUM(D4:D200) -> 0 | E2: =SUM(E4:E100) -> 0 | F2: =D2-E2 -> 0 | G2: =IFERROR(F2/E2, 0) -> 0 | H2: =SUM(H4:H200) -> 0 | I2: =D2-H2 -> 0 | J2: =IFERROR(I2/H2, 0) -> 0
A3: Site | B3: State | C3: SOL# | D3: Actual | E3: Expected | F3: Delta | G3: % | H3: Forecasted | I3: Delta | J3: %
A4: {=Sites[Site]} -> Farmer | B4: {=Sites[State]} -> AZ | C4: =Sites[[#This Row],[SOL'#]] -> SOL-10748 | D4: =SUM(Apr!D4, May!D4, Jun!D4) -> 0 | E4: =SUM(Apr!E4, May!E4, Jun!E4) -> 0 | F4: =IF(AND(ISNUMBER(D4),ISNUMBER(E4)), D4-E4, "") -> 0 | G4: =IFERROR(F4/E4, "") | H4: =SUM(Apr!H4, May!H4, Jun!H4) -> 0 | I4: =SUM(Apr!I4, May!I4, Jun!I4) -> 0 | J4: =IFERROR(I4/H4, "")
A5: Fulton | B5: AZ | C5: =Sites[[#This Row],[SOL'#]] -> SOL-10749 | D5: =SUM(Apr!D5, May!D5, Jun!D5) -> 0 | E5: =SUM(Apr!E5, May!E5, Jun!E5) -> 0 | F5: =IF(AND(ISNUMBER(D5),ISNUMBER(E5)), D5-E5, "") -> 0 | G5: =IFERROR(F5/E5, "") | H5: =SUM(Apr!H5, May!H5, Jun!H5) -> 0 | I5: =SUM(Apr!I5, May!I5, Jun!I5) -> 0 | J5: =IFERROR(I5/H5, "")
A6: JFK Elementary | B6: AZ | C6: =Sites[[#This Row],[SOL'#]] -> SOL-10758 | D6: =SUM(Apr!D6, May!D6, Jun!D6) -> 0 | E6: =SUM(Apr!E6, May!E6, Jun!E6) -> 0 | F6: =IF(AND(ISNUMBER(D6),ISNUMBER(E6)), D6-E6, "") -> 0 | G6: =IFERROR(F6/E6, "") | H6: =SUM(Apr!H6, May!H6, Jun!H6) -> 0 | I6: =SUM(Apr!I6, May!I6, Jun!I6) -> 0 | J6: =IFERROR(I6/H6, "")
A7: Noble | B7: AZ | C7: =Sites[[#This Row],[SOL'#]] -> SOL-10750 | D7: =SUM(Apr!D7, May!D7, Jun!D7) -> 0 | E7: =SUM(Apr!E7, May!E7, Jun!E7) -> 0 | F7: =IF(AND(ISNUMBER(D7),ISNUMBER(E7)), D7-E7, "") -> 0 | G7: =IFERROR(F7/E7, "") | H7: =SUM(Apr!H7, May!H7, Jun!H7) -> 0 | I7: =SUM(Apr!I7, May!I7, Jun!I7) -> 0 | J7: =IFERROR(I7/H7, "")
A8: Parking 3 | B8: AZ | C8: =Sites[[#This Row],[SOL'#]] -> SOL-10751 | D8: =SUM(Apr!D8, May!D8, Jun!D8) -> 0 | E8: =SUM(Apr!E8, May!E8, Jun!E8) -> 0 | F8: =IF(AND(ISNUMBER(D8),ISNUMBER(E8)), D8-E8, "") -> 0 | G8: =IFERROR(F8/E8, "") | H8: =SUM(Apr!H8, May!H8, Jun!H8) -> 0 | I8: =SUM(Apr!I8, May!I8, Jun!I8) -> 0 | J8: =IFERROR(I8/H8, "")
A9: PE East | B9: AZ | C9: =Sites[[#This Row],[SOL'#]] -> SOL-10752 | D9: =SUM(Apr!D9, May!D9, Jun!D9) -> 0 | E9: =SUM(Apr!E9, May!E9, Jun!E9) -> 0 | F9: =IF(AND(ISNUMBER(D9),ISNUMBER(E9)), D9-E9, "") -> 0 | G9: =IFERROR(F9/E9, "") | H9: =SUM(Apr!H9, May!H9, Jun!H9) -> 0 | I9: =SUM(Apr!I9, May!I9, Jun!I9) -> 0 | J9: =IFERROR(I9/H9, "")
A10: Schwada | B10: AZ | C10: =Sites[[#This Row],[SOL'#]] -> SOL-10753 | D10: =SUM(Apr!D10, May!D10, Jun!D10) -> 0 | E10: =SUM(Apr!E10, May!E10, Jun!E10) -> 0 | F10: =IF(AND(ISNUMBER(D10),ISNUMBER(E10)), D10-E10, "") -> 0 | G10: =IFERROR(F10/E10, "") | H10: =SUM(Apr!H10, May!H10, Jun!H10) -> 0 | I10: =SUM(Apr!I10, May!I10, Jun!I10) -> 0 | J10: =IFERROR(I10/H10, "")
A11: Starshine | B11: AZ | C11: =Sites[[#This Row],[SOL'#]] -> SOL-10757 | D11: =SUM(Apr!D11, May!D11, Jun!D11) -> 0 | E11: =SUM(Apr!E11, May!E11, Jun!E11) -> 0 | F11: =IF(AND(ISNUMBER(D11),ISNUMBER(E11)), D11-E11, "") -> 0 | G11: =IFERROR(F11/E11, "") | H11: =SUM(Apr!H11, May!H11, Jun!H11) -> 0 | I11: =SUM(Apr!I11, May!I11, Jun!I11) -> 0 | J11: =IFERROR(I11/H11, "")
A12: Yuma Airport | B12: AZ | C12: =Sites[[#This Row],[SOL'#]] -> SOL-10754 | D12: =SUM(Apr!D12, May!D12, Jun!D12) -> 0 | E12: =SUM(Apr!E12, May!E12, Jun!E12) -> 0 | F12: =IF(AND(ISNUMBER(D12),ISNUMBER(E12)), D12-E12, "") -> 0 | G12: =IFERROR(F12/E12, "") | H12: =SUM(Apr!H12, May!H12, Jun!H12) -> 0 | I12: =SUM(Apr!I12, May!I12, Jun!I12) -> 0 | J12: =IFERROR(I12/H12, "")
A13: Kinsman | B13: OH | C13: =Sites[[#This Row],[SOL'#]] -> SOL-10762 | D13: =SUM(Apr!D13, May!D13, Jun!D13) -> 0 | E13: =SUM(Apr!E13, May!E13, Jun!E13) -> 0 | F13: =IF(AND(ISNUMBER(D13),ISNUMBER(E13)), D13-E13, "") -> 0 | G13: =IFERROR(F13/E13, "") | H13: =SUM(Apr!H13, May!H13, Jun!H13) -> 0 | I13: =SUM(Apr!I13, May!I13, Jun!I13) -> 0 | J13: =IFERROR(I13/H13, "")
A14: Wooster | B14: OH | C14: =Sites[[#This Row],[SOL'#]] -> SOL-10763 | D14: =SUM(Apr!D14, May!D14, Jun!D14) -> 0 | E14: =SUM(Apr!E14, May!E14, Jun!E14) -> 0 | F14: =IF(AND(ISNUMBER(D14),ISNUMBER(E14)), D14-E14, "") -> 0 | G14: =IFERROR(F14/E14, "") | H14: =SUM(Apr!H14, May!H14, Jun!H14) -> 0 | I14: =SUM(Apr!I14, May!I14, Jun!I14) -> 0 | J14: =IFERROR(I14/H14, "")
A15: Globe Gila CC | B15: AZ | C15: =Sites[[#This Row],[SOL'#]] -> SOL-10755 | D15: =SUM(Apr!D15, May!D15, Jun!D15) -> 0 | E15: =SUM(Apr!E15, May!E15, Jun!E15) -> 0 | F15: =IF(AND(ISNUMBER(D15),ISNUMBER(E15)), D15-E15, "") -> 0 | G15: =IFERROR(F15/E15, "") | H15: =SUM(Apr!H15, May!H15, Jun!H15) -> 0 | I15: =SUM(Apr!I15, May!I15, Jun!I15) -> 0 | J15: =IFERROR(I15/H15, "")
A16: Payson Gila CC | B16: AZ | C16: =Sites[[#This Row],[SOL'#]] -> SOL-10756 | D16: =SUM(Apr!D16, May!D16, Jun!D16) -> 0 | E16: =SUM(Apr!E16, May!E16, Jun!E16) -> 0 | F16: =IF(AND(ISNUMBER(D16),ISNUMBER(E16)), D16-E16, "") -> 0 | G16: =IFERROR(F16/E16, "") | H16: =SUM(Apr!H16, May!H16, Jun!H16) -> 0 | I16: =SUM(Apr!I16, May!I16, Jun!I16) -> 0 | J16: =IFERROR(I16/H16, "")
... A185: BK16 | B185: NY | C185: =Sites[[#This Row],[SOL'#]] -> SOL-11093 | D185: =SUM(Apr!D185, May!D185, Jun!D185) -> 0 | E185: =SUM(Apr!E185, May!E185, Jun!E185) -> 0 | F185: =IF(AND(ISNUMBER(D185),ISNUMBER(E185)), D185-E185, "") -> 0 | G185: =IFERROR(F185/E185, "") | H185: =SUM(Apr!H185, May!H185, Jun!H185) -> 0 | I185: =SUM(Apr!I185, May!I185, Jun!I185) -> 0 | J185: =IFERROR(I185/H185, "")
A186: Trenton - Trenton East | B186: IL | C186: =Sites[[#This Row],[SOL'#]] -> SOL-11060 | D186: =SUM(Apr!D186, May!D186, Jun!D186) -> 0 | E186: =SUM(Apr!E186, May!E186, Jun!E186) -> 0 | F186: =IF(AND(ISNUMBER(D186),ISNUMBER(E186)), D186-E186, "") -> 0 | H186: =SUM(Apr!H186, May!H186, Jun!H186) -> 0 | I186: =SUM(Apr!I186, May!I186, Jun!I186) -> 0
A187: Trenton - Trenton West | B187: IL | C187: =Sites[[#This Row],[SOL'#]] -> SOL-11061 | D187: =SUM(Apr!D187, May!D187, Jun!D187) -> 0 | E187: =SUM(Apr!E187, May!E187, Jun!E187) -> 0 | F187: =IF(AND(ISNUMBER(D187),ISNUMBER(E187)), D187-E187, "") -> 0 | H187: =SUM(Apr!H187, May!H187, Jun!H187) -> 0 | I187: =SUM(Apr!I187, May!I187, Jun!I187) -> 0
A188: Dakota - Dakota Solar 1 | B188: IL | C188: =Sites[[#This Row],[SOL'#]] -> SOL-11113 | D188: =SUM(Apr!D188, May!D188, Jun!D188) -> 0 | E188: =SUM(Apr!E188, May!E188, Jun!E188) -> 0 | F188: =IF(AND(ISNUMBER(D188),ISNUMBER(E188)), D188-E188, "") -> 0 | H188: =SUM(Apr!H188, May!H188, Jun!H188) -> 0 | I188: =SUM(Apr!I188, May!I188, Jun!I188) -> 0
A189: X018 | B189: NY | C189: =Sites[[#This Row],[SOL'#]] -> SOL-10418 | D189: =SUM(Apr!D189, May!D189, Jun!D189) -> 0 | E189: =SUM(Apr!E189, May!E189, Jun!E189) -> 0 | F189: =IF(AND(ISNUMBER(D189),ISNUMBER(E189)), D189-E189, "") -> 0 | H189: =SUM(Apr!H189, May!H189, Jun!H189) -> 0 | I189: =SUM(Apr!I189, May!I189, Jun!I189) -> 0
A190: Janiak Solar | B190: NY | C190: =Sites[[#This Row],[SOL'#]] -> SOL-10898 | D190: =SUM(Apr!D190, May!D190, Jun!D190) -> 0 | E190: =SUM(Apr!E190, May!E190, Jun!E190) -> 0 | F190: =IF(AND(ISNUMBER(D190),ISNUMBER(E190)), D190-E190, "") -> 0 | H190: =SUM(Apr!H190, May!H190, Jun!H190) -> 0 | I190: =SUM(Apr!I190, May!I190, Jun!I190) -> 0
A191: County Route 11B | B191: NY | C191: =Sites[[#This Row],[SOL'#]] -> SOL-10983 | D191: =SUM(Apr!D191, May!D191, Jun!D191) -> 0 | E191: =SUM(Apr!E191, May!E191, Jun!E191) -> 0 | F191: =IF(AND(ISNUMBER(D191),ISNUMBER(E191)), D191-E191, "") -> 0 | H191: =SUM(Apr!H191, May!H191, Jun!H191) -> 0 | I191: =SUM(Apr!I191, May!I191, Jun!I191) -> 0
A192: Barone | B192: NY | C192: =Sites[[#This Row],[SOL'#]] -> SOL-11034 | D192: =SUM(Apr!D192, May!D192, Jun!D192) -> 0 | E192: =SUM(Apr!E192, May!E192, Jun!E192) -> 0 | F192: =IF(AND(ISNUMBER(D192),ISNUMBER(E192)), D192-E192, "") -> 0 | H192: =SUM(Apr!H192, May!H192, Jun!H192) -> 0 | I192: =SUM(Apr!I192, May!I192, Jun!I192) -> 0
A193: Cedarville | B193: IL | C193: =Sites[[#This Row],[SOL'#]] -> SOL-11069 | D193: =SUM(Apr!D193, May!D193, Jun!D193) -> 0 | E193: =SUM(Apr!E193, May!E193, Jun!E193) -> 0 | F193: =IF(AND(ISNUMBER(D193),ISNUMBER(E193)), D193-E193, "") -> 0 | H193: =SUM(Apr!H193, May!H193, Jun!H193) -> 0 | I193: =SUM(Apr!I193, May!I193, Jun!I193) -> 0
A194: O'Brien Hill #1 | B194: NY | C194: =Sites[[#This Row],[SOL'#]] -> SOL-11098 | D194: =SUM(Apr!D194, May!D194, Jun!D194) -> 0 | E194: =SUM(Apr!E194, May!E194, Jun!E194) -> 0 | F194: =IF(AND(ISNUMBER(D194),ISNUMBER(E194)), D194-E194, "") -> 0 | H194: =SUM(Apr!H194, May!H194, Jun!H194) -> 0 | I194: =SUM(Apr!I194, May!I194, Jun!I194) -> 0
A195: O'Brien Hill #2 | B195: NY | C195: =Sites[[#This Row],[SOL'#]] -> SOL-11099 | D195: =SUM(Apr!D195, May!D195, Jun!D195) -> 0 | E195: =SUM(Apr!E195, May!E195, Jun!E195) -> 0 | F195: =IF(AND(ISNUMBER(D195),ISNUMBER(E195)), D195-E195, "") -> 0 | H195: =SUM(Apr!H195, May!H195, Jun!H195) -> 0 | I195: =SUM(Apr!I195, May!I195, Jun!I195) -> 0
A196: Trinity - Freeport | B196: IL
A197: Ransom | B197: NY
A198: Horseheads - Wedge | B198: NY
A199: Otisville - Shoddy Hollow | B199: NY
A200: Wellsville - Chenunda Creek | B200: NY

Sheet 3rd Qtr
A1: {=portfolio} -> Generate Capital | E1: 3rd Quarter Actual v. Expected | H1: 3rd Quarter Actual v. Forecasted
A2: Total | D2: =SUM(D4:D200) -> 0 | E2: =SUM(E4:E100) -> 0 | F2: =D2-E2 -> 0 | G2: =IFERROR(F2/E2, 0) -> 0 | H2: =SUM(H4:H200) -> 0 | I2: =D2-H2 -> 0 | J2: =IFERROR(I2/H2, 0) -> 0
A3: Site | B3: State | C3: SOL# | D3: Actual | E3: Expected | F3: Delta | G3: % | H3: Forecasted | I3: Delta | J3: %
A4: {=Sites[Site]} -> Farmer | B4: {=Sites[State]} -> AZ | C4: =Sites[[#This Row],[SOL'#]] -> SOL-10748 | D4: =SUM(Jul!D4, Aug!D4, Sep!D4) -> 0 | E4: =SUM(Jul!E4, Aug!E4, Sep!E4) -> 0 | F4: =IF(AND(ISNUMBER(D4),ISNUMBER(E4)), D4-E4, "") -> 0 | G4: =IFERROR(F4/E4, "") | H4: =SUM(Jul!H4,Aug!H4,Sep!H4) -> 0 | I4: =SUM(Jul!I4, Aug!I4, Sep!I4) -> 0 | J4: =IFERROR(I4/H4, "")
A5: Fulton | B5: AZ | C5: =Sites[[#This Row],[SOL'#]] -> SOL-10749 | D5: =SUM(Jul!D5, Aug!D5, Sep!D5) -> 0 | E5: =SUM(Jul!E5, Aug!E5, Sep!E5) -> 0 | F5: =IF(AND(ISNUMBER(D5),ISNUMBER(E5)), D5-E5, "") -> 0 | G5: =IFERROR(F5/E5, "") | H5: =SUM(Jul!H5,Aug!H5,Sep!H5) -> 0 | I5: =SUM(Jul!I5, Aug!I5, Sep!I5) -> 0 | J5: =IFERROR(I5/H5, "")
A6: JFK Elementary | B6: AZ | C6: =Sites[[#This Row],[SOL'#]] -> SOL-10758 | D6: =SUM(Jul!D6, Aug!D6, Sep!D6) -> 0 | E6: =SUM(Jul!E6, Aug!E6, Sep!E6) -> 0 | F6: =IF(AND(ISNUMBER(D6),ISNUMBER(E6)), D6-E6, "") -> 0 | G6: =IFERROR(F6/E6, "") | H6: =SUM(Jul!H6,Aug!H6,Sep!H6) -> 0 | I6: =SUM(Jul!I6, Aug!I6, Sep!I6) -> 0 | J6: =IFERROR(I6/H6, "")
A7: Noble | B7: AZ | C7: =Sites[[#This Row],[SOL'#]] -> SOL-10750 | D7: =SUM(Jul!D7, Aug!D7, Sep!D7) -> 0 | E7: =SUM(Jul!E7, Aug!E7, Sep!E7) -> 0 | F7: =IF(AND(ISNUMBER(D7),ISNUMBER(E7)), D7-E7, "") -> 0 | G7: =IFERROR(F7/E7, "") | H7: =SUM(Jul!H7,Aug!H7,Sep!H7) -> 0 | I7: =SUM(Jul!I7, Aug!I7, Sep!I7) -> 0 | J7: =IFERROR(I7/H7, "")
A8: Parking 3 | B8: AZ | C8: =Sites[[#This Row],[SOL'#]] -> SOL-10751 | D8: =SUM(Jul!D8, Aug!D8, Sep!D8) -> 0 | E8: =SUM(Jul!E8, Aug!E8, Sep!E8) -> 0 | F8: =IF(AND(ISNUMBER(D8),ISNUMBER(E8)), D8-E8, "") -> 0 | G8: =IFERROR(F8/E8, "") | H8: =SUM(Jul!H8,Aug!H8,Sep!H8) -> 0 | I8: =SUM(Jul!I8, Aug!I8, Sep!I8) -> 0 | J8: =IFERROR(I8/H8, "")
A9: PE East | B9: AZ | C9: =Sites[[#This Row],[SOL'#]] -> SOL-10752 | D9: =SUM(Jul!D9, Aug!D9, Sep!D9) -> 0 | E9: =SUM(Jul!E9, Aug!E9, Sep!E9) -> 0 | F9: =IF(AND(ISNUMBER(D9),ISNUMBER(E9)), D9-E9, "") -> 0 | G9: =IFERROR(F9/E9, "") | H9: =SUM(Jul!H9,Aug!H9,Sep!H9) -> 0 | I9: =SUM(Jul!I9, Aug!I9, Sep!I9) -> 0 | J9: =IFERROR(I9/H9, "")
A10: Schwada | B10: AZ | C10: =Sites[[#This Row],[SOL'#]] -> SOL-10753 | D10: =SUM(Jul!D10, Aug!D10, Sep!D10) -> 0 | E10: =SUM(Jul!E10, Aug!E10, Sep!E10) -> 0 | F10: =IF(AND(ISNUMBER(D10),ISNUMBER(E10)), D10-E10, "") -> 0 | G10: =IFERROR(F10/E10, "") | H10: =SUM(Jul!H10,Aug!H10,Sep!H10) -> 0 | I10: =SUM(Jul!I10, Aug!I10, Sep!I10) -> 0 | J10: =IFERROR(I10/H10, "")
A11: Starshine | B11: AZ | C11: =Sites[[#This Row],[SOL'#]] -> SOL-10757 | D11: =SUM(Jul!D11, Aug!D11, Sep!D11) -> 0 | E11: =SUM(Jul!E11, Aug!E11, Sep!E11) -> 0 | F11: =IF(AND(ISNUMBER(D11),ISNUMBER(E11)), D11-E11, "") -> 0 | G11: =IFERROR(F11/E11, "") | H11: =SUM(Jul!H11,Aug!H11,Sep!H11) -> 0 | I11: =SUM(Jul!I11, Aug!I11, Sep!I11) -> 0 | J11: =IFERROR(I11/H11, "")
A12: Yuma Airport | B12: AZ | C12: =Sites[[#This Row],[SOL'#]] -> SOL-10754 | D12: =SUM(Jul!D12, Aug!D12, Sep!D12) -> 0 | E12: =SUM(Jul!E12, Aug!E12, Sep!E12) -> 0 | F12: =IF(AND(ISNUMBER(D12),ISNUMBER(E12)), D12-E12, "") -> 0 | G12: =IFERROR(F12/E12, "") | H12: =SUM(Jul!H12,Aug!H12,Sep!H12) -> 0 | I12: =SUM(Jul!I12, Aug!I12, Sep!I12) -> 0 | J12: =IFERROR(I12/H12, "")
A13: Kinsman | B13: OH | C13: =Sites[[#This Row],[SOL'#]] -> SOL-10762 | D13: =SUM(Jul!D13, Aug!D13, Sep!D13) -> 0 | E13: =SUM(Jul!E13, Aug!E13, Sep!E13) -> 0 | F13: =IF(AND(ISNUMBER(D13),ISNUMBER(E13)), D13-E13, "") -> 0 | G13: =IFERROR(F13/E13, "") | H13: =SUM(Jul!H13,Aug!H13,Sep!H13) -> 0 | I13: =SUM(Jul!I13, Aug!I13, Sep!I13) -> 0 | J13: =IFERROR(I13/H13, "")
A14: Wooster | B14: OH | C14: =Sites[[#This Row],[SOL'#]] -> SOL-10763 | D14: =SUM(Jul!D14, Aug!D14, Sep!D14) -> 0 | E14: =SUM(Jul!E14, Aug!E14, Sep!E14) -> 0 | F14: =IF(AND(ISNUMBER(D14),ISNUMBER(E14)), D14-E14, "") -> 0 | G14: =IFERROR(F14/E14, "") | H14: =SUM(Jul!H14,Aug!H14,Sep!H14) -> 0 | I14: =SUM(Jul!I14, Aug!I14, Sep!I14) -> 0 | J14: =IFERROR(I14/H14, "")
A15: Globe Gila CC | B15: AZ | C15: =Sites[[#This Row],[SOL'#]] -> SOL-10755 | D15: =SUM(Jul!D15, Aug!D15, Sep!D15) -> 0 | E15: =SUM(Jul!E15, Aug!E15, Sep!E15) -> 0 | F15: =IF(AND(ISNUMBER(D15),ISNUMBER(E15)), D15-E15, "") -> 0 | G15: =IFERROR(F15/E15, "") | H15: =SUM(Jul!H15,Aug!H15,Sep!H15) -> 0 | I15: =SUM(Jul!I15, Aug!I15, Sep!I15) -> 0 | J15: =IFERROR(I15/H15, "")
A16: Payson Gila CC | B16: AZ | C16: =Sites[[#This Row],[SOL'#]] -> SOL-10756 | D16: =SUM(Jul!D16, Aug!D16, Sep!D16) -> 0 | E16: =SUM(Jul!E16, Aug!E16, Sep!E16) -> 0 | F16: =IF(AND(ISNUMBER(D16),ISNUMBER(E16)), D16-E16, "") -> 0 | G16: =IFERROR(F16/E16, "") | H16: =SUM(Jul!H16,Aug!H16,Sep!H16) -> 0 | I16: =SUM(Jul!I16, Aug!I16, Sep!I16) -> 0 | J16: =IFERROR(I16/H16, "")
... A185: BK16 | B185: NY | C185: =Sites[[#This Row],[SOL'#]] -> SOL-11093 | D185: =SUM(Jul!D185, Aug!D185, Sep!D185) -> 0 | E185: =SUM(Jul!E185, Aug!E185, Sep!E185) -> 0 | F185: =IF(AND(ISNUMBER(D185),ISNUMBER(E185)), D185-E185, "") -> 0 | G185: =IFERROR(F185/E185, "") | H185: =SUM(Jul!H185,Aug!H185,Sep!H185) -> 0 | I185: =SUM(Jul!I185, Aug!I185, Sep!I185) -> 0 | J185: =IFERROR(I185/H185, "")
A186: Trenton - Trenton East | B186: IL | C186: =Sites[[#This Row],[SOL'#]] -> SOL-11060 | D186: =SUM(Jul!D186, Aug!D186, Sep!D186) -> 0 | E186: =SUM(Jul!E186, Aug!E186, Sep!E186) -> 0 | F186: =IF(AND(ISNUMBER(D186),ISNUMBER(E186)), D186-E186, "") -> 0 | H186: =SUM(Jul!H186,Aug!H186,Sep!H186) -> 0 | I186: =SUM(Jul!I186, Aug!I186, Sep!I186) -> 0
A187: Trenton - Trenton West | B187: IL | C187: =Sites[[#This Row],[SOL'#]] -> SOL-11061 | D187: =SUM(Jul!D187, Aug!D187, Sep!D187) -> 0 | E187: =SUM(Jul!E187, Aug!E187, Sep!E187) -> 0 | F187: =IF(AND(ISNUMBER(D187),ISNUMBER(E187)), D187-E187, "") -> 0 | H187: =SUM(Jul!H187,Aug!H187,Sep!H187) -> 0 | I187: =SUM(Jul!I187, Aug!I187, Sep!I187) -> 0
A188: Dakota - Dakota Solar 1 | B188: IL | C188: =Sites[[#This Row],[SOL'#]] -> SOL-11113 | D188: =SUM(Jul!D188, Aug!D188, Sep!D188) -> 0 | E188: =SUM(Jul!E188, Aug!E188, Sep!E188) -> 0 | F188: =IF(AND(ISNUMBER(D188),ISNUMBER(E188)), D188-E188, "") -> 0 | H188: =SUM(Jul!H188,Aug!H188,Sep!H188) -> 0 | I188: =SUM(Jul!I188, Aug!I188, Sep!I188) -> 0
A189: X018 | B189: NY | C189: =Sites[[#This Row],[SOL'#]] -> SOL-10418 | D189: =SUM(Jul!D189, Aug!D189, Sep!D189) -> 0 | E189: =SUM(Jul!E189, Aug!E189, Sep!E189) -> 0 | F189: =IF(AND(ISNUMBER(D189),ISNUMBER(E189)), D189-E189, "") -> 0 | H189: =SUM(Jul!H189,Aug!H189,Sep!H189) -> 0 | I189: =SUM(Jul!I189, Aug!I189, Sep!I189) -> 0
A190: Janiak Solar | B190: NY | C190: =Sites[[#This Row],[SOL'#]] -> SOL-10898 | D190: =SUM(Jul!D190, Aug!D190, Sep!D190) -> 0 | E190: =SUM(Jul!E190, Aug!E190, Sep!E190) -> 0 | F190: =IF(AND(ISNUMBER(D190),ISNUMBER(E190)), D190-E190, "") -> 0 | H190: =SUM(Jul!H190,Aug!H190,Sep!H190) -> 0 | I190: =SUM(Jul!I190, Aug!I190, Sep!I190) -> 0
A191: County Route 11B | B191: NY | C191: =Sites[[#This Row],[SOL'#]] -> SOL-10983 | D191: =SUM(Jul!D191, Aug!D191, Sep!D191) -> 0 | E191: =SUM(Jul!E191, Aug!E191, Sep!E191) -> 0 | F191: =IF(AND(ISNUMBER(D191),ISNUMBER(E191)), D191-E191, "") -> 0 | H191: =SUM(Jul!H191,Aug!H191,Sep!H191) -> 0 | I191: =SUM(Jul!I191, Aug!I191, Sep!I191) -> 0
A192: Barone | B192: NY | C192: =Sites[[#This Row],[SOL'#]] -> SOL-11034 | D192: =SUM(Jul!D192, Aug!D192, Sep!D192) -> 0 | E192: =SUM(Jul!E192, Aug!E192, Sep!E192) -> 0 | F192: =IF(AND(ISNUMBER(D192),ISNUMBER(E192)), D192-E192, "") -> 0 | H192: =SUM(Jul!H192,Aug!H192,Sep!H192) -> 0 | I192: =SUM(Jul!I192, Aug!I192, Sep!I192) -> 0
A193: Cedarville | B193: IL | C193: =Sites[[#This Row],[SOL'#]] -> SOL-11069 | D193: =SUM(Jul!D193, Aug!D193, Sep!D193) -> 0 | E193: =SUM(Jul!E193, Aug!E193, Sep!E193) -> 0 | F193: =IF(AND(ISNUMBER(D193),ISNUMBER(E193)), D193-E193, "") -> 0 | H193: =SUM(Jul!H193,Aug!H193,Sep!H193) -> 0 | I193: =SUM(Jul!I193, Aug!I193, Sep!I193) -> 0
A194: O'Brien Hill #1 | B194: NY | C194: =Sites[[#This Row],[SOL'#]] -> SOL-11098 | D194: =SUM(Jul!D194, Aug!D194, Sep!D194) -> 0 | E194: =SUM(Jul!E194, Aug!E194, Sep!E194) -> 0 | F194: =IF(AND(ISNUMBER(D194),ISNUMBER(E194)), D194-E194, "") -> 0 | H194: =SUM(Jul!H194,Aug!H194,Sep!H194) -> 0 | I194: =SUM(Jul!I194, Aug!I194, Sep!I194) -> 0
A195: O'Brien Hill #2 | B195: NY | C195: =Sites[[#This Row],[SOL'#]] -> SOL-11099 | D195: =SUM(Jul!D195, Aug!D195, Sep!D195) -> 0 | E195: =SUM(Jul!E195, Aug!E195, Sep!E195) -> 0 | F195: =IF(AND(ISNUMBER(D195),ISNUMBER(E195)), D195-E195, "") -> 0 | H195: =SUM(Jul!H195,Aug!H195,Sep!H195) -> 0 | I195: =SUM(Jul!I195, Aug!I195, Sep!I195) -> 0
A196: Trinity - Freeport | B196: IL
A197: Ransom | B197: NY
A198: Horseheads - Wedge | B198: NY
A199: Otisville - Shoddy Hollow | B199: NY
A200: Wellsville - Chenunda Creek | B200: NY

Sheet 4th Qtr
A1: {=portfolio} -> Generate Capital | E1: 4th Quarter Actual v. Expected | H1: 4th Quarter Actual v. Forecasted
A2: Total | D2: =SUM(D4:D200) -> 0 | E2: =SUM(E4:E100) -> 0 | F2: =D2-E2 -> 0 | G2: =IFERROR(F2/E2, 0) -> 0 | H2: =SUM(H4:H200) -> 0 | I2: =D2-H2 -> 0 | J2: =IFERROR(I2/H2, 0) -> 0
A3: Site | B3: State | C3: SOL# | D3: Actual | E3: Expected | F3: Delta | G3: % | H3: Forecasted | I3: Delta | J3: %
A4: {=Sites[Site]} -> Farmer | B4: {=Sites[State]} -> AZ | C4: =Sites[[#This Row],[SOL'#]] -> SOL-10748 | D4: =SUM(Oct!D4, Nov!D4, Dec!D4) -> 0 | E4: =SUM(Oct!E4, Nov!E4, Dec!E4) -> 0 | F4: =IF(AND(ISNUMBER(D4),ISNUMBER(E4)), D4-E4, "") -> 0 | G4: =IFERROR(F4/E4, "") | H4: =SUM(Oct!H4,Nov!H4,Dec!H4) -> 0 | I4: =SUM(Oct!I4, Nov!I4, Dec!I4) -> 0 | J4: =IFERROR(I4/H4, "")
A5: Fulton | B5: AZ | C5: =Sites[[#This Row],[SOL'#]] -> SOL-10749 | D5: =SUM(Oct!D5, Nov!D5, Dec!D5) -> 0 | E5: =SUM(Oct!E5, Nov!E5, Dec!E5) -> 0 | F5: =IF(AND(ISNUMBER(D5),ISNUMBER(E5)), D5-E5, "") -> 0 | G5: =IFERROR(F5/E5, "") | H5: =SUM(Oct!H5,Nov!H5,Dec!H5) -> 0 | I5: =SUM(Oct!I5, Nov!I5, Dec!I5) -> 0 | J5: =IFERROR(I5/H5, "")
A6: JFK Elementary | B6: AZ | C6: =Sites[[#This Row],[SOL'#]] -> SOL-10758 | D6: =SUM(Oct!D6, Nov!D6, Dec!D6) -> 0 | E6: =SUM(Oct!E6, Nov!E6, Dec!E6) -> 0 | F6: =IF(AND(ISNUMBER(D6),ISNUMBER(E6)), D6-E6, "") -> 0 | G6: =IFERROR(F6/E6, "") | H6: =SUM(Oct!H6,Nov!H6,Dec!H6) -> 0 | I6: =SUM(Oct!I6, Nov!I6, Dec!I6) -> 0 | J6: =IFERROR(I6/H6, "")
A7: Noble | B7: AZ | C7: =Sites[[#This Row],[SOL'#]] -> SOL-10750 | D7: =SUM(Oct!D7, Nov!D7, Dec!D7) -> 0 | E7: =SUM(Oct!E7, Nov!E7, Dec!E7) -> 0 | F7: =IF(AND(ISNUMBER(D7),ISNUMBER(E7)), D7-E7, "") -> 0 | G7: =IFERROR(F7/E7, "") | H7: =SUM(Oct!H7,Nov!H7,Dec!H7) -> 0 | I7: =SUM(Oct!I7, Nov!I7, Dec!I7) -> 0 | J7: =IFERROR(I7/H7, "")
A8: Parking 3 | B8: AZ | C8: =Sites[[#This Row],[SOL'#]] -> SOL-10751 | D8: =SUM(Oct!D8, Nov!D8, Dec!D8) -> 0 | E8: =SUM(Oct!E8, Nov!E8, Dec!E8) -> 0 | F8: =IF(AND(ISNUMBER(D8),ISNUMBER(E8)), D8-E8, "") -> 0 | G8: =IFERROR(F8/E8, "") | H8: =SUM(Oct!H8,Nov!H8,Dec!H8) -> 0 | I8: =SUM(Oct!I8, Nov!I8, Dec!I8) -> 0 | J8: =IFERROR(I8/H8, "")
A9: PE East | B9: AZ | C9: =Sites[[#This Row],[SOL'#]] -> SOL-10752 | D9: =SUM(Oct!D9, Nov!D9, Dec!D9) -> 0 | E9: =SUM(Oct!E9, Nov!E9, Dec!E9) -> 0 | F9: =IF(AND(ISNUMBER(D9),ISNUMBER(E9)), D9-E9, "") -> 0 | G9: =IFERROR(F9/E9, "") | H9: =SUM(Oct!H9,Nov!H9,Dec!H9) -> 0 | I9: =SUM(Oct!I9, Nov!I9, Dec!I9) -> 0 | J9: =IFERROR(I9/H9, "")
A10: Schwada | B10: AZ | C10: =Sites[[#This Row],[SOL'#]] -> SOL-10753 | D10: =SUM(Oct!D10, Nov!D10, Dec!D10) -> 0 | E10: =SUM(Oct!E10, Nov!E10, Dec!E10) -> 0 | F10: =IF(AND(ISNUMBER(D10),ISNUMBER(E10)), D10-E10, "") -> 0 | G10: =IFERROR(F10/E10, "") | H10: =SUM(Oct!H10,Nov!H10,Dec!H10) -> 0 | I10: =SUM(Oct!I10, Nov!I10, Dec!I10) -> 0 | J10: =IFERROR(I10/H10, "")
A11: Starshine | B11: AZ | C11: =Sites[[#This Row],[SOL'#]] -> SOL-10757 | D11: =SUM(Oct!D11, Nov!D11, Dec!D11) -> 0 | E11: =SUM(Oct!E11, Nov!E11, Dec!E11) -> 0 | F11: =IF(AND(ISNUMBER(D11),ISNUMBER(E11)), D11-E11, "") -> 0 | G11: =IFERROR(F11/E11, "") | H11: =SUM(Oct!H11,Nov!H11,Dec!H11) -> 0 | I11: =SUM(Oct!I11, Nov!I11, Dec!I11) -> 0 | J11: =IFERROR(I11/H11, "")
A12: Yuma Airport | B12: AZ | C12: =Sites[[#This Row],[SOL'#]] -> SOL-10754 | D12: =SUM(Oct!D12, Nov!D12, Dec!D12) -> 0 | E12: =SUM(Oct!E12, Nov!E12, Dec!E12) -> 0 | F12: =IF(AND(ISNUMBER(D12),ISNUMBER(E12)), D12-E12, "") -> 0 | G12: =IFERROR(F12/E12, "") | H12: =SUM(Oct!H12,Nov!H12,Dec!H12) -> 0 | I12: =SUM(Oct!I12, Nov!I12, Dec!I12) -> 0 | J12: =IFERROR(I12/H12, "")
A13: Kinsman | B13: OH | C13: =Sites[[#This Row],[SOL'#]] -> SOL-10762 | D13: =SUM(Oct!D13, Nov!D13, Dec!D13) -> 0 | E13: =SUM(Oct!E13, Nov!E13, Dec!E13) -> 0 | F13: =IF(AND(ISNUMBER(D13),ISNUMBER(E13)), D13-E13, "") -> 0 | G13: =IFERROR(F13/E13, "") | H13: =SUM(Oct!H13,Nov!H13,Dec!H13) -> 0 | I13: =SUM(Oct!I13, Nov!I13, Dec!I13) -> 0 | J13: =IFERROR(I13/H13, "")
A14: Wooster | B14: OH | C14: =Sites[[#This Row],[SOL'#]] -> SOL-10763 | D14: =SUM(Oct!D14, Nov!D14, Dec!D14) -> 0 | E14: =SUM(Oct!E14, Nov!E14, Dec!E14) -> 0 | F14: =IF(AND(ISNUMBER(D14),ISNUMBER(E14)), D14-E14, "") -> 0 | G14: =IFERROR(F14/E14, "") | H14: =SUM(Oct!H14,Nov!H14,Dec!H14) -> 0 | I14: =SUM(Oct!I14, Nov!I14, Dec!I14) -> 0 | J14: =IFERROR(I14/H14, "")
A15: Globe Gila CC | B15: AZ | C15: =Sites[[#This Row],[SOL'#]] -> SOL-10755 | D15: =SUM(Oct!D15, Nov!D15, Dec!D15) -> 0 | E15: =SUM(Oct!E15, Nov!E15, Dec!E15) -> 0 | F15: =IF(AND(ISNUMBER(D15),ISNUMBER(E15)), D15-E15, "") -> 0 | G15: =IFERROR(F15/E15, "") | H15: =SUM(Oct!H15,Nov!H15,Dec!H15) -> 0 | I15: =SUM(Oct!I15, Nov!I15, Dec!I15) -> 0 | J15: =IFERROR(I15/H15, "")
A16: Payson Gila CC | B16: AZ | C16: =Sites[[#This Row],[SOL'#]] -> SOL-10756 | D16: =SUM(Oct!D16, Nov!D16, Dec!D16) -> 0 | E16: =SUM(Oct!E16, Nov!E16, Dec!E16) -> 0 | F16: =IF(AND(ISNUMBER(D16),ISNUMBER(E16)), D16-E16, "") -> 0 | G16: =IFERROR(F16/E16, "") | H16: =SUM(Oct!H16,Nov!H16,Dec!H16) -> 0 | I16: =SUM(Oct!I16, Nov!I16, Dec!I16) -> 0 | J16: =IFERROR(I16/H16, "")
... A185: BK16 | B185: NY | C185: =Sites[[#This Row],[SOL'#]] -> SOL-11093 | D185: =SUM(Oct!D185, Nov!D185, Dec!D185) -> 0 | E185: =SUM(Oct!E185, Nov!E185, Dec!E185) -> 0 | F185: =IF(AND(ISNUMBER(D185),ISNUMBER(E185)), D185-E185, "") -> 0 | G185: =IFERROR(F185/E185, "") | H185: =SUM(Oct!H185,Nov!H185,Dec!H185) -> 0 | I185: =SUM(Oct!I185, Nov!I185, Dec!I185) -> 0 | J185: =IFERROR(I185/H185, "")
A186: Trenton - Trenton East | B186: IL | C186: =Sites[[#This Row],[SOL'#]] -> SOL-11060 | D186: =SUM(Oct!D186, Nov!D186, Dec!D186) -> 0 | E186: =SUM(Oct!E186, Nov!E186, Dec!E186) -> 0 | F186: =IF(AND(ISNUMBER(D186),ISNUMBER(E186)), D186-E186, "") -> 0 | H186: =SUM(Oct!H186,Nov!H186,Dec!H186) -> 0 | I186: =SUM(Oct!I186, Nov!I186, Dec!I186) -> 0
A187: Trenton - Trenton West | B187: IL | C187: =Sites[[#This Row],[SOL'#]] -> SOL-11061 | D187: =SUM(Oct!D187, Nov!D187, Dec!D187) -> 0 | E187: =SUM(Oct!E187, Nov!E187, Dec!E187) -> 0 | F187: =IF(AND(ISNUMBER(D187),ISNUMBER(E187)), D187-E187, "") -> 0 | H187: =SUM(Oct!H187,Nov!H187,Dec!H187) -> 0 | I187: =SUM(Oct!I187, Nov!I187, Dec!I187) -> 0
A188: Dakota - Dakota Solar 1 | B188: IL | C188: =Sites[[#This Row],[SOL'#]] -> SOL-11113 | D188: =SUM(Oct!D188, Nov!D188, Dec!D188) -> 0 | E188: =SUM(Oct!E188, Nov!E188, Dec!E188) -> 0 | F188: =IF(AND(ISNUMBER(D188),ISNUMBER(E188)), D188-E188, "") -> 0 | H188: =SUM(Oct!H188,Nov!H188,Dec!H188) -> 0 | I188: =SUM(Oct!I188, Nov!I188, Dec!I188) -> 0
A189: X018 | B189: NY | C189: =Sites[[#This Row],[SOL'#]] -> SOL-10418 | D189: =SUM(Oct!D189, Nov!D189, Dec!D189) -> 0 | E189: =SUM(Oct!E189, Nov!E189, Dec!E189) -> 0 | F189: =IF(AND(ISNUMBER(D189),ISNUMBER(E189)), D189-E189, "") -> 0 | H189: =SUM(Oct!H189,Nov!H189,Dec!H189) -> 0 | I189: =SUM(Oct!I189, Nov!I189, Dec!I189) -> 0
A190: Janiak Solar | B190: NY | C190: =Sites[[#This Row],[SOL'#]] -> SOL-10898 | D190: =SUM(Oct!D190, Nov!D190, Dec!D190) -> 0 | E190: =SUM(Oct!E190, Nov!E190, Dec!E190) -> 0 | F190: =IF(AND(ISNUMBER(D190),ISNUMBER(E190)), D190-E190, "") -> 0 | H190: =SUM(Oct!H190,Nov!H190,Dec!H190) -> 0 | I190: =SUM(Oct!I190, Nov!I190, Dec!I190) -> 0
A191: County Route 11B | B191: NY | C191: =Sites[[#This Row],[SOL'#]] -> SOL-10983 | D191: =SUM(Oct!D191, Nov!D191, Dec!D191) -> 0 | E191: =SUM(Oct!E191, Nov!E191, Dec!E191) -> 0 | F191: =IF(AND(ISNUMBER(D191),ISNUMBER(E191)), D191-E191, "") -> 0 | H191: =SUM(Oct!H191,Nov!H191,Dec!H191) -> 0 | I191: =SUM(Oct!I191, Nov!I191, Dec!I191) -> 0
A192: Barone | B192: NY | C192: =Sites[[#This Row],[SOL'#]] -> SOL-11034 | D192: =SUM(Oct!D192, Nov!D192, Dec!D192) -> 0 | E192: =SUM(Oct!E192, Nov!E192, Dec!E192) -> 0 | F192: =IF(AND(ISNUMBER(D192),ISNUMBER(E192)), D192-E192, "") -> 0 | H192: =SUM(Oct!H192,Nov!H192,Dec!H192) -> 0 | I192: =SUM(Oct!I192, Nov!I192, Dec!I192) -> 0
A193: Cedarville | B193: IL | C193: =Sites[[#This Row],[SOL'#]] -> SOL-11069 | D193: =SUM(Oct!D193, Nov!D193, Dec!D193) -> 0 | E193: =SUM(Oct!E193, Nov!E193, Dec!E193) -> 0 | F193: =IF(AND(ISNUMBER(D193),ISNUMBER(E193)), D193-E193, "") -> 0 | H193: =SUM(Oct!H193,Nov!H193,Dec!H193) -> 0 | I193: =SUM(Oct!I193, Nov!I193, Dec!I193) -> 0
