Workbook

Sheet Glossary
A1: Terminology | F1: Definition
A2: Total Actual Production (kWh): | F2: total monthly production
A3: Total Modeled Production (kWh): | F3: total performance predicted monthly produciton
A4: Total Actual Insolation (Wh/m2): | F4: total monthly insolation received on site
A5: Total Modeled Insolation (Wh/m2): | F5: total predicted monthly insolation on site
A6: Total Outage Adjusted Production (kWh): | F6: expected energy production based off plant configuration specifications and measured environmental data. Calculated using actual weather data collected on the site throughout the month. A more accurate and refined version of the Weather-Adjusted Performance metric.
A7: Outage-Adjusted Performance: | F7: the actual production divided by the outage adjusted expected production for a PV system.
A8: Weather-Adjusted Performance: | F8: total actual production versus the weather-adjusted expected production
A9: Actual vs Modeled Production: | F9: total actual production versus the adjusted modeled production
A10: Monthly PV System Availability: | F10: calculates the percentage in which equipment is online and producing when irradiance exceeds a predetermined threshold.
A11: YTD PV System Availability: | F11: system availability since the beginning of the year to present time

Sheet Merrimack
E1: Merrimack
E2: Monthly Operating Report
E3: November' 2024
C5: Monthly Total Performance
E6: Total Actual Production (kWh): | J6: =SUM(G32:G61) -> 220608
E7: Total Modeled Production (kWh): | J7: ='Predicted Data'!D26 -> 287672
E8: Total Actual Insolation (Wh/m2): | J8: =SUM(H32:H61) -> 102440.56
E9: Total Modeled Insolation (Wh/m2):
E10: Total Outage Adjusted Production (kWh): | J10: ='Plant Health'!H88 -> 303095
E11: Outage-Adjusted Performance: | J11: =J6/J10 -> 0.727851
E12: Actual vs Modeled Production: | J12: =J6/J7 -> 0.76687338
E13: Monthly PV System Availability: | J13: =Availability!E47 -> 1
E14: YTD PV System Availability: | J14: =Availability!E50 -> 0.99866
C16: Chart of Daily Irradiance vs. Production
F30: Day-by-Day Performance
F31: Date | G31: Energy Produced (kWh) | H31: Radiation Yield (Wh/m2) | I31: Max Ambient Temp (°F)
F32: 45597 | G32: 7464 | H32: 3549.07 | I32: 57 | K32: Note: The production meter has been reporting erroneous values overnight throughout the entire month. We reached out to AlsoEnergy( #529959 )and manually corrected the data by considering 6:00 AM to 7:00 PM as the production hours.
F33: 45598 | G33: 7259 | H33: 3205.401 | I33: 56
F34: 45599 | G34: 12163 | H34: 5568.037 | I34: 59
F35: 45600 | G35: 3488 | H35: 1445.636 | I35: 59
F36: 45601 | G36: 8146 | H36: 3726.902 | I36: 59
F37: 45602 | G37: 8177 | H37: 3708.138 | I37: 53
F38: 45603 | G38: 6163 | H38: 2945.38 | I38: 55
F39: 45604 | G39: 10520 | H39: 4672.393 | I39: 50
F40: 45605 | G40: 11407 | H40: 5235.912 | I40: 51
F41: 45606 | G41: 8091 | H41: 3583.511 | I41: 50
F42: 45607 | G42: 7504 | H42: 3479.579 | I42: 51
F43: 45608 | G43: 4763 | H43: 2170.134 | I43: 55
F44: 45609 | G44: 10987 | H44: 5138.202 | I44: 42
... F61: 45626 | G61: 7993 | H61: 3876.62 | I61: 52
C64: O&M Activity
C69: Performance Notes

Sheet Smithfield
E1: Smithfield
E2: Monthly Operating Report
E3: November' 2024
C5: Monthly Total Performance
E6: Total Actual Production (kWh): | J6: =SUM(G32:G61) -> 286999.5
E7: Total Modeled Production (kWh): | J7: ='Predicted Data'!D15 -> 204482.1
E8: Total Actual Insolation (Wh/m2): | J8: =SUM(H32:H61) -> 89500.105
E9: Total Modeled Insolation (Wh/m2):
E10: Total Outage Adjusted Production (kWh): | J10: ='Plant Health'!E89 -> 263489.48
E11: Outage-Adjusted Performance: | J11: =J6/J10 -> 1.0892256
E12: Actual vs Modeled Production: | J12: =J6/J7 -> 1.4035434
E13: Monthly PV System Availability: | J13: =Availability!D48 -> 1
E14: YTD PV System Availability: | J14: =Availability!D50 -> 0.99886364
C16: Chart of Daily Irradiance vs. Production
F30: Day-by-Day Performance
F31: Date | G31: Energy Produced (kWh) | H31: Radiation Yield (Wh/m2) | I31: Max Ambient Temp (°F)
F32: 45597 | G32: 8225.75 | H32: 2552.165 | I32: 65.7874
F33: 45598 | G33: 8518 | H33: 2541.949 | I33: 48.32277
F34: 45599 | G34: 14295.5 | H34: 4366.127 | I34: 35.93828
F35: 45600 | G35: 5464 | H35: 1586.546 | I35: 40.99151
F36: 45601 | G36: 12138.25 | H36: 3763.787 | I36: 60.27082
F37: 45602 | G37: 12036.75 | H37: 3805.182 | I37: 67.72247
F38: 45603 | G38: 10599 | H38: 3383.171 | I38: 57.33466
F39: 45604 | G39: 13090.25 | H39: 4113.696 | I39: 49.83152
F40: 45605 | G40: 13648 | H40: 4235.766 | I40: 41.96741
F41: 45606 | G41: 10156.25 | H41: 3098.935 | I41: 44.23942
F42: 45607 | G42: 8234.75 | H42: 2653.844 | I42: 56.52862
F43: 45608 | G43: 11844 | H43: 3786.786 | I43: 44.12218
... F61: 45626 | G61: 10486.25 | H61: 3295.958 | I61: 29.27806
C64: O&M Activity
C69: Performance Notes

Sheet Westlake
E1: Westlake
E2: Monthly Operating Report
E3: November 2024
C5: Monthly Total Performance
E6: Total Actual Production (kWh): | J6: =SUM(G32:G61) -> 330561
E7: Total Modeled Production (kWh): | J7: ='Predicted Data'!D39 -> 378158
E8: Total Actual Insolation (Wh/m2): | J8: =SUM(H32:H61) -> 113047.57
E9: Total Modeled Insolation (Wh/m2):
E10: Total Outage Adjusted Production (kWh): | J10: ='Plant Health'!K89 -> 301310.37
E11: Outage-Adjusted Performance: | J11: =J6/J10 -> 1.0970781
E12: Actual vs Modeled Production: | J12: =J6/J7 -> 0.87413462
E13: Monthly PV System Availability: | J13: =Availability!F48 -> 0.9911
E14: YTD PV System Availability: | J14: =Availability!F50 -> 0.99623636
C16: Chart of Daily Irradiance vs. Production
F30: Day-by-Day Performance
F31: Date | G31: Energy Produced (kWh) | H31: Radiation Yield (Wh/m2) | I31: Max Ambient Temp (°F)
F32: 45597 | G32: 4032 | H32: 974.5209 | I32: 64.84945
F33: 45598 | G33: 2938 | H33: 583.3183 | I33: 72.23987
F34: 45599 | G34: 3335 | H34: 723.449 | I34: 73.68147
F35: 45600 | G35: 3745 | H35: 979.6505 | I35: 71.23531
F36: 45601 | G36: 14598 | H36: 5150.689 | I36: 59.7782
F37: 45602 | G37: 16559 | H37: 5757.145 | I37: 58.22237
F38: 45603 | G38: 2959 | H38: 625.7874 | I38: 63.64947
F39: 45604 | G39: 1811 | H39: 248.1796 | I39: 66.61014
F40: 45605 | G40: 16164 | H40: 5669.208 | I40: 58.09241
F41: 45606 | G41: 15472 | H41: 5453.625 | I41: 61.12967
F42: 45607 | G42: 15250 | H42: 5261.389 | I42: 59.30663
F43: 45608 | G43: 15056 | H43: 5177.035 | I43: 60.54892
... F61: 45626 | G61: 14141 | H61: 4909.412 | I61: 44.63426
C64: O&M Activity
C69: Performance Notes

Sheet Availability
C4: 2020 YTD Availability | G4: 2022 YTD Availability
D5: Smithfield | E5: Merrimack | H5: Smithfield | I5: Merrimack
C6: January | G6: January | H6: 0.99899 | I6: 0.99677
C7: February | G7: February | H7: 0.99977 | I7: 0.96015
C8: March | G8: March | H8: 0.99835 | I8: 0.99973
C9: April | G9: April | H9: 1 | I9: 1
C10: May | G10: May | H10: 1 | I10: 1
C11: June | G11: June | H11: 1 | I11: 0.9991
C12: July | D12: 0.98024 | E12: 1 | G12: July | H12: 1 | I12: 1
C13: August | D13: 0.98094 | E13: 1 | G13: August | H13: 0.998 | I13: 1
C14: September | D14: 0.97178 | E14: 1 | G14: September | H14: 1 | I14: 0.9793
C15: October | D15: 0.99821 | E15: 0.99462 | G15: October | H15: 1 | I15: 1
C16: November | D16: 1 | E16: 1 | G16: November | H16: 1 | I16: 0.985
C17: December | D17: 1 | E17: 0.99821 | G17: December | H17: 0.98167 | I17: 1
C18: YTD Average | D18: =AVERAGE(D6:D17) -> 0.98852833 | E18: =AVERAGE(E6:E17) -> 0.998805 | G18: YTD Average | H18: =AVERAGE(H6:H17) -> 0.998065 | I18: =AVERAGE(I6:I17) -> 0.9933375
C20: 2021 YTD Availability | G20: 2023 YTD Availability | K20: 2023 YTD Availability
D21: Smithfield | E21: Merrimack | H21: Smithfield | I21: Merrimack | L21: Westlake
C22: January | D22: 1 | E22: 1 | G22: January | H22: 1 | I22: 0.9986 | K22: January | L22: 0.9647
C23: February | D23: 1 | E23: 0.99867 | G23: February | H23: 1 | I23: 0.9996 | K23: February | L23: 0.8214
C24: March | D24: 1 | E24: 1 | G24: March | H24: 1 | I24: 1 | K24: March | L24: 1
C25: April | D25: 1 | E25: 1 | G25: April | H25: 1 | I25: 1 | K25: April | L25: 1
C26: May | D26: 0.99954 | E26: 0.99919 | G26: May | H26: 1 | I26: 1 | K26: May | L26: 1
C27: June | D27: 1 | E27: 1 | G27: June | H27: 1 | I27: 0.8814 | K27: June | L27: 1
C28: July | D28: 1 | E28: 1 | G28: July | H28: 0.99545 | I28: 1 | K28: July | L28: 1
C29: August | D29: 1 | E29: 0.99943 | G29: August | H29: 1 | I29: 1 | K29: August | L29: 0.98
C30: September | D30: 1 | E30: 1 | G30: September | H30: 1 | I30: 1 | K30: September | L30: 1
C31: October | D31: 1 | E31: 0.99968 | G31: October | H31: 0.9995 | I31: 1 | K31: October | L31: 1
C32: November | D32: 1 | E32: 0.99952 | G32: November | H32: 1 | I32: 99.8%% | K32: November | L32: 0.96
C33: December | D33: 1 | E33: 1 | G33: December | H33: 1 | I33: 1 | K33: December | L33: 1
C34: YTD Average | D34: =AVERAGE(D22:D33) -> 0.99996167 | E34: =AVERAGE(E22:E33) -> 0.9997075 | G34: YTD Average | H34: =AVERAGE(H22:H33) -> 0.99957917 | I34: =AVERAGE(I22:I33) -> 0.98905455 | K34: YTD Average | L34: =AVERAGE(L22:L33) -> 0.977175
C36: 2024 YTD Availability
D37: Smithfield | E37: Merrimack | F37: Westlake
C38: January | D38: 1 | E38: 0.9866 | F38: 1
C39: February | D39: 0.9997 | E39: 1 | F39: 0.9981
C40: March | D40: 1 | E40: 1 | F40: 0.9975
C41: April | D41: 1 | E41: 1 | F41: 1
C42: May | D42: 1 | E42: 1 | F42: 1
C43: June | D43: 1 | E43: 1 | F43: 1
C44: July | D44: 1 | E44: 1 | F44: 1
C45: August | D45: 0.9878 | E45: 1 | F45: 1
...

Sheet Plant Health
C4: 2020 Plant Health Data
D5: Smithfield | G5: Merrimack | J5: Portfolio
D6: Actual | E6: Adjusted | F6: % | G6: Actual | H6: Adjusted | I6: % | J6: Actual | K6: Adjusted | L6: %
C7: January | D7: - | E7: - | F7: - | G7: - | H7: - | I7: - | J7: - | K7: - | L7: -
C8: February | D8: - | E8: - | F8: - | G8: - | H8: - | I8: - | J8: - | K8: - | L8: -
C9: March | D9: - | E9: - | F9: - | G9: - | H9: - | I9: - | J9: - | K9: - | L9: -
C10: April | D10: - | E10: - | F10: - | G10: - | H10: - | I10: - | J10: - | K10: - | L10: -
C11: May | D11: - | E11: - | F11: - | G11: - | H11: - | I11: - | J11: - | K11: - | L11: -
C12: June | D12: - | E12: - | F12: - | G12: - | H12: - | I12: - | J12: - | K12: - | L12: -
C13: July | D13: 116911.2 | E13: 261526.7 | F13: =D13/E13 -> 0.44703352 | G13: 424573 | H13: 269641.8 | I13: =G13/H13 -> 1.5745815 | J13: =SUM(D13,G13) -> 541484.2 | K13: =SUM(E13,H13) -> 531168.5 | L13: =J13/K13 -> 1.0194208
C14: August | D14: 140722.4 | E14: 498528.6 | F14: =D14/E14 -> 0.28227548 | G14: 438642 | H14: 0.001 | I14: - | J14: =SUM(D14,G14) -> 579364.4 | K14: =SUM(E14,H14) -> 498528.6 | L14: =J14/K14 -> 1.1621488
C15: September | D15: 110264.4 | E15: 425599.2 | F15: =D15/E15 -> 0.25908037 | G15: 381452 | H15: 0.001 | I15: - | J15: =SUM(D15,G15) -> 491716.4 | K15: =SUM(E15,H15) -> 425599.2 | L15: =J15/K15 -> 1.1553509
C16: October | D16: 56659.41 | E16: 143112.1 | F16: =D16/E16 -> 0.39590929 | G16: 252863 | H16: 213893.1 | I16: =G16/H16 -> 1.1821933 | J16: =SUM(D16,G16) -> 309522.41 | K16: =SUM(E16,H16) -> 357005.2 | L16: =J16/K16 -> 0.86699692
C17: November | D17: 240103.9 | E17: 256321.4 | F17: =D17/E17 -> 0.93672982 | G17: 201336 | H17: 218336.2 | I17: =G17/H17 -> 0.92213751 | J17: =SUM(D17,G17) -> 441439.9 | K17: =SUM(E17,H17) -> 474657.6 | L17: =J17/K17 -> 0.93001755
C18: December | D18: 156599.8 | E18: 200907.8 | F18: =D18/E18 -> 0.77946103 | G18: 112849 | H18: 155562.4 | I18: =G18/H18 -> 0.72542594 | J18: =SUM(D18,G18) -> 269448.8 | K18: =SUM(E18,H18) -> 356470.2 | L18: =J18/K18 -> 0.7558803
C19: Annual | D19: =SUM(D7:D18) -> 821261.11 | E19: =SUM(E7:E18) -> 1785995.8 | F19: =D19/E19 -> 0.45983373 | G19: =SUM(G7:G18) -> 1811715 | H19: =SUM(H7:H18) -> 857433.5 | I19: =G19/H19 -> 2.112951 | J19: =SUM(D19,G19) -> 2632976.1 | K19: =SUM(E19,H19) -> 2643429.3 | L19: =J19/K19 -> 0.99604559
C22: 2021 Plant Health Data
D23: Smithfield | G23: Merrimack | J23: Portfolio
D24: Actual | E24: Adjusted | F24: % | G24: Actual | H24: Adjusted | I24: % | J24: Actual | K24: Adjusted | L24: %
C25: January | D25: 227679.5 | E25: 257471.3 | F25: =D25/E25 -> 0.88429079 | G25: 183752 | H25: 225537.8 | I25: =G25/H25 -> 0.81472817 | J25: =SUM(D25,G25) -> 411431.5 | K25: =SUM(E25,H25) -> 483009.1 | L25: =J25/K25 -> 0.851809
C26: February | D26: 143871.8 | E26: 255271 | F26: =D26/E26 -> 0.56360417 | G26: 126222 | H26: 205320.8 | I26: =G26/H26 -> 0.61475506 | J26: =SUM(D26,G26) -> 270093.8 | K26: =SUM(E26,H26) -> 460591.8 | L26: =J26/K26 -> 0.58640601
C27: March | D27: 492310.9 | E27: 494013.2 | F27: =D27/E27 -> 0.99655414 | G27: 437625 | H27: 445515.7 | I27: =G27/H27 -> 0.98228862 | J27: =SUM(D27,G27) -> 929935.9 | K27: =SUM(E27,H27) -> 939528.9 | L27: =J27/K27 -> 0.98978956
C28: April | D28: 439047 | E28: 448567.2 | F28: =D28/E28 -> 0.97877642 | G28: 367530 | H28: 372152.7 | I28: =G28/H28 -> 0.98757849 | J28: =SUM(D28,G28) -> 806577 | K28: =SUM(E28,H28) -> 820719.9 | L28: =J28/K28 -> 0.98276769
C29: May | D29: 501618.9 | E29: 514260.1 | F29: =D29/E29 -> 0.97541866 | G29: 436580 | H29: 440019.8 | I29: =G29/H29 -> 0.99218262 | J29: =SUM(D29,G29) -> 938198.9 | K29: =SUM(E29,H29) -> 954279.9 | L29: =J29/K29 -> 0.98314855
C30: June | D30: 543264.6 | E30: 552014.8 | F30: =D30/E30 -> 0.98414861 | G30: 459791 | H30: 460611.1 | I30: =G30/H30 -> 0.99821954 | J30: =SUM(D30,G30) -> 1003055.6 | K30: =SUM(E30,H30) -> 1012625.9 | L30: =J30/K30 -> 0.99054903
C31: July | D31: 420906.1 | E31: 429467.7 | F31: =D31/E31 -> 0.98006462 | G31: 350714 | H31: 355421.8 | I31: =G31/H31 -> 0.98675433 | J31: =SUM(D31,G31) -> 771620.1 | K31: =SUM(E31,H31) -> 784889.5 | L31: =J31/K31 -> 0.98309393
C32: August | D32: 441017.5 | E32: 449526.7 | F32: =D32/E32 -> 0.98107076 | G32: 367845 | H32: 379397.1 | I32: =G32/H32 -> 0.96955143 | J32: =SUM(D32,G32) -> 808862.5 | K32: =SUM(E32,H32) -> 828923.8 | L32: =J32/K32 -> 0.97579838
C33: September | D33: 385420.2 | E33: 394461.6 | F33: =D33/E33 -> 0.97707914 | G33: 326443 | H33: 350030.6 | I33: =G33/H33 -> 0.93261275 | J33: =SUM(D33,G33) -> 711863.2 | K33: =SUM(E33,H33) -> 744492.2 | L33: =J33/K33 -> 0.95617281
C34: October | D34: 305337.1 | E34: 312573.2 | F34: =D34/E34 -> 0.9768499 | G34: 249653 | H34: 271991.8 | I34: =G34/H34 -> 0.91786958 | J34: =SUM(D34,G34) -> 554990.1 | K34: =SUM(E34,H34) -> 584565 | L34: =J34/K34 -> 0.94940699
C35: November | D35: 303576.1 | E35: 303145.1 | F35: =D35/E35 -> 1.0014218 | G35: 251687.7 | H35: 281496.9 | I35: =G35/H35 -> 0.8941047 | J35: =SUM(D35,G35) -> 555263.8 | K35: =SUM(E35,H35) -> 584642 | L35: =J35/K35 -> 0.9497501
C36: December | D36: 161260.8 | E36: 178274.2 | F36: =D36/E36 -> 0.90456611 | G36: 126900.7 | H36: 166144.7 | I36: =G36/H36 -> 0.76379626 | J36: =SUM(D36,G36) -> 288161.5 | K36: =SUM(E36,H36) -> 344418.9 | L36: =J36/K36 -> 0.83665995
C37: Annual | D37: =SUM(D25:D36) -> 4365310.5 | E37: =SUM(E25:E36) -> 4589046.1 | F37: =D37/E37 -> 0.95124573 | G37: =SUM(G25:G36) -> 3684743.4 | H37: =SUM(H25:H36) -> 3953640.8 | I37: =G37/H37 -> 0.9319874 | J37: =SUM(D37,G37) -> 8050053.9 | K37: =SUM(E37,H37) -> 8542686.9 | L37: =J37/K37 -> 0.94233278
C40: 2022 Plant Health Data
D41: Smithfield | G41: Merrimack | J41: Portfolio
D42: Actual | E42: Adjusted | F42: % | G42: Actual | H42: Adjusted | I42: % | J42: Actual | K42: Adjusted | L42: %
C43: January | D43: 202947.9 | E43: 251246.2 | F43: =D43/E43 -> 0.80776505 | G43: 186214.4 | H43: 234624.4 | I43: =G43/H43 -> 0.79367022 | J43: =SUM(D43,G43) -> 389162.3 | K43: =SUM(E43,H43) -> 485870.6 | L43: =J43/K43 -> 0.80095873
C44: February | D44: 200639.6 | E44: 292574.9 | F44: =D44/E44 -> 0.68577175 | G44: 188160.6 | H44: 272070.1 | I44: =G44/H44 -> 0.69158868 | J44: =SUM(D44,G44) -> 388800.2 | K44: =SUM(E44,H44) -> 564645 | L44: =J44/K44 -> 0.68857459
C45: March | D45: 402985 | E45: 413695.1 | F45: =D45/E45 -> 0.97411113 | G45: 340534.4 | H45: 359950.5 | I45: =G45/H45 -> 0.94605897 | J45: =SUM(D45,G45) -> 743519.4 | K45: =SUM(E45,H45) -> 773645.6 | L45: =J45/K45 -> 0.96105943
C46: April | D46: 481629 | E46: 485708.5 | F46: =D46/E46 -> 0.99160093 | G46: 376650 | H46: 377357.3 | I46: =G46/H46 -> 0.99812565 | J46: =SUM(D46,G46) -> 858279 | K46: =SUM(E46,H46) -> 863065.8 | L46: =J46/K46 -> 0.99445373
C47: May | D47: 518502.9 | E47: 533788.3 | F47: =D47/E47 -> 0.9713643 | G47: 478677.5 | H47: 472852.1 | I47: =G47/H47 -> 1.0123197 | J47: =SUM(D47,G47) -> 997180.4 | K47: =SUM(E47,H47) -> 1006640.4 | L47: =J47/K47 -> 0.9906024
...

Sheet Predicted Data
A4: Site Name | B4: Month | C4: Year | D4: Total Modeled Production (kWh): | E4: Total Modeled Insolation (Wh/m2):
A5: Smithfield | B5: 1 | C5: =2024 -> 2024 | D5: 173872.6
A6: Smithfield | B6: 2 | C6: =2024 -> 2024 | D6: 223465.4
A7: Smithfield | B7: 3 | C7: =2024 -> 2024 | D7: 344525.3
A8: Smithfield | B8: 4 | C8: =2024 -> 2024 | D8: 439674.5
A9: Smithfield | B9: 5 | C9: =2024 -> 2024 | D9: 455091.2
A10: Smithfield | B10: 6 | C10: =2024 -> 2024 | D10: 491177.6
A11: Smithfield | B11: 7 | C11: =2024 -> 2024 | D11: 524395
A12: Smithfield | B12: 8 | C12: =2024 -> 2024 | D12: 488163.4
A13: Smithfield | B13: 9 | C13: =2024 -> 2024 | D13: 412507.2
A14: Smithfield | B14: 10 | C14: =2024 -> 2024 | D14: 292225.1
A15: Smithfield | B15: 11 | C15: =2024 -> 2024 | D15: 204482.1
A16: Smithfield | B16: 12 | C16: =2024 -> 2024 | D16: 160442.8
... A40: Westlake | B40: 12 | C40: =2024 -> 2024 | D40: 357864

Sheet Ashley Config
A1: Field | B1: E_Grid | C1: GlobInc | H1: Ashley kWh | Q1: Ashley Insolation (Wh/m^2)
A2: Units | B2: kWh | C2: Wh/m2 | H2: 2015 | I2: 2016 | J2: 2017 | K2: 2018 | L2: 2019 | M2: 2020 | N2: 2021 | O2: 2022 | Q2: 2022
A3: 42005 | B3: 430600 | C3: 88900 | G3: January | H3: 430600 | I3: 430600 | J3: =I3*0.995 -> 428447 | K3: =J3*0.995 -> 426304.77 | L3: =K3*0.995 -> 424173.24 | M3: =L3*0.995 -> 422052.37 | N3: =M3*0.995 -> 419942.11 | O3: =N3*0.995 -> 417842.4 | Q3: 99200
A4: 42036 | B4: 472000 | C4: 99800 | G4: February | H4: 472000 | I4: 472000 | J4: =I4*0.995 -> 469640 | K4: =J4*0.995 -> 467291.8 | L4: =K4*0.995 -> 464955.34 | M4: =L4*0.995 -> 462630.56 | N4: =M4*0.995 -> 460317.41 | O4: =N4*0.995 -> 458015.82 | Q4: 108300
A5: 42064 | B5: 637500 | C5: 138300 | D5: PIS Month | G5: March | H5: 637500 | I5: =H5*0.995 -> 634312.5 | J5: =I5*0.995 -> 631140.94 | K5: =J5*0.995 -> 627985.23 | L5: =K5*0.995 -> 624845.31 | M5: =L5*0.995 -> 621721.08 | N5: =M5*0.995 -> 618612.47 | O5: =N5*0.995 -> 615519.41 | Q5: 150000
A6: 42095 | B6: 719700 | C6: 158700 | G6: April | H6: 719700 | I6: =H6*0.995 -> 716101.5 | J6: =I6*0.995 -> 712520.99 | K6: =J6*0.995 -> 708958.39 | L6: =K6*0.995 -> 705413.6 | M6: =L6*0.995 -> 701886.53 | N6: =M6*0.995 -> 698377.09 | O6: =N6*0.995 -> 694885.21 | Q6: 171200
A7: 42125 | B7: 729800 | C7: 162100 | G7: May | H7: 729800 | I7: =H7*0.995 -> 726151 | J7: =I7*0.995 -> 722520.24 | K7: =J7*0.995 -> 718907.64 | L7: =K7*0.995 -> 715313.11 | M7: =L7*0.995 -> 711736.54 | N7: =M7*0.995 -> 708177.86 | O7: =N7*0.995 -> 704636.97 | Q7: 174100
A8: 42156 | B8: 764800 | C8: 172600 | G8: June | H8: 764800 | I8: =H8*0.995 -> 760976 | J8: =I8*0.995 -> 757171.12 | K8: =J8*0.995 -> 753385.26 | L8: =K8*0.995 -> 749618.34 | M8: =L8*0.995 -> 745870.25 | N8: =M8*0.995 -> 742140.9 | O8: =N8*0.995 -> 738430.19 | Q8: 182400
A9: 42186 | B9: 773600 | C9: 175600 | G9: July | H9: 773600 | I9: =H9*0.995 -> 769732 | J9: =I9*0.995 -> 765883.34 | K9: =J9*0.995 -> 762053.92 | L9: =K9*0.995 -> 758243.65 | M9: =L9*0.995 -> 754452.44 | N9: =M9*0.995 -> 750680.17 | O9: =N9*0.995 -> 746926.77 | Q9: 185100
A10: 42217 | B10: 753100 | C10: 170100 | G10: August | H10: 753100 | I10: =H10*0.995 -> 749334.5 | J10: =I10*0.995 -> 745587.83 | K10: =J10*0.995 -> 741859.89 | L10: =K10*0.995 -> 738150.59 | M10: =L10*0.995 -> 734459.84 | N10: =M10*0.995 -> 730787.54 | O10: =N10*0.995 -> 727133.6 | Q10: 178400
A11: 42248 | B11: 622300 | C11: 138000 | G11: September | H11: 622300 | I11: =H11*0.995 -> 619188.5 | J11: =I11*0.995 -> 616092.56 | K11: =J11*0.995 -> 613012.09 | L11: =K11*0.995 -> 609947.03 | M11: =L11*0.995 -> 606897.3 | N11: =M11*0.995 -> 603862.81 | O11: =N11*0.995 -> 600843.5 | Q11: 146600
A12: 42278 | B12: 572800 | C12: 124400 | G12: October | H12: 572800 | I12: =H12*0.995 -> 569936 | J12: =I12*0.995 -> 567086.32 | K12: =J12*0.995 -> 564250.89 | L12: =K12*0.995 -> 561429.63 | M12: =L12*0.995 -> 558622.49 | N12: =M12*0.995 -> 555829.37 | O12: =N12*0.995 -> 553050.23 | Q12: 133800
A13: 42309 | B13: 413200 | C13: 88700 | G13: November | H13: 413200 | I13: =H13*0.995 -> 411134 | J13: =I13*0.995 -> 409078.33 | K13: =J13*0.995 -> 407032.94 | L13: =K13*0.995 -> 404997.77 | M13: =L13*0.995 -> 402972.78 | N13: =M13*0.995 -> 400957.92 | O13: =N13*0.995 -> 398953.13 | Q13: 96000
A14: 42339 | B14: 420700 | C14: 88000 | G14: December | H14: 420700 | I14: =H14*0.995 -> 418596.5 | J14: =I14*0.995 -> 416503.52 | K14: =J14*0.995 -> 414421 | L14: =K14*0.995 -> 412348.89 | M14: =L14*0.995 -> 410287.15 | N14: =M14*0.995 -> 408235.71 | O14: =N14*0.995 -> 406194.54 | Q14: 98000
A15: 42370 | B15: 430600 | C15: 88900
A16: 42401 | B16: 472000 | C16: 99800
A17: 42430 | B17: =B5*0.995 -> 634312.5 | C17: 138300
A18: 42461 | B18: =B6*0.995 -> 716101.5 | C18: 158700
A19: 42491 | B19: =B7*0.995 -> 726151 | C19: 162100
A20: 42522 | B20: =B8*0.995 -> 760976 | C20: 172600
A21: 42552 | B21: =B9*0.995 -> 769732 | C21: 175600
A22: 42583 | B22: =B10*0.995 -> 749334.5 | C22: 170100
A23: 42614 | B23: =B11*0.995 -> 619188.5 | C23: 138000
A24: 42644 | B24: =B12*0.995 -> 569936 | C24: 124400
A25: 42675 | B25: =B13*0.995 -> 411134 | C25: 88700
A26: 42705 | B26: =B14*0.995 -> 418596.5 | C26: 88000
A27: 42736 | B27: =B3*0.995 -> 428447 | C27: 88900
A28: 42767 | B28: =B4*0.995 -> 469640 | C28: 99800
A29: 42795 | B29: =B5*0.99 -> 631125 | C29: 138300
A30: 42826 | B30: =B6*0.99 -> 712503 | C30: 158700
A31: 42856 | B31: =B7*0.99 -> 722502 | C31: 162100
A32: 42887 | B32: =B8*0.99 -> 757152 | C32: 172600
A33: 42917 | B33: =B9*0.99 -> 765864 | C33: 175600
A34: 42948 | B34: =B10*0.99 -> 745569 | C34: 170100
A35: 42979 | B35: =B11*0.99 -> 616077 | C35: 138000
A36: 43009 | B36: =B12*0.99 -> 567072 | C36: 124400
A37: 43040 | B37: =B13*0.99 -> 409068 | C37: 88700
A38: 43070 | B38: =B14*0.99 -> 416493 | C38: 88000
A39: 43101 | B39: =B3*0.99 -> 426294 | C39: 88900
A40: 43132 | B40: =B4*0.99 -> 467280 | C40: 99800
...

Sheet Lang Config
A1: Field | B1: E_Grid | C1: GlobInc | G1: Lang kWh | P1: Lang Insolation (Wh/m^2)
A2: Units | B2: kWh | C2: Wh/m2 | G2: 2015 | H2: 2016 | I2: 2017 | J2: 2018 | K2: 2019 | L2: 2020 | M2: 2021 | N2: 2022 | P2: 2022
A3: 42005 | B3: 558000 | C3: 89800 | F3: January | G3: 558000 | H3: 558000 | I3: 555210 | J3: 552433.95 | K3: 549671.78 | L3: 546923.42 | M3: 544188.8 | N3: 541467.86 | P3: 99500
A4: 42036 | B4: 618000 | C4: 100200 | F4: February | G4: 618000 | H4: 618000 | I4: 614910 | J4: 611835.45 | K4: 608776.27 | L4: 605732.39 | M4: 602703.73 | N4: 599690.21 | P4: 110300
A5: 42064 | B5: 832000 | C5: 140000 | F5: March | G5: 832000 | H5: 832000 | I5: 827840 | J5: 823700.8 | K5: 819582.3 | L5: 815484.38 | M5: 811406.96 | N5: 807349.93 | P5: 152700
A6: 42095 | B6: 960000 | C6: 164500 | F6: April | G6: 960000 | H6: 960000 | I6: 955200 | J6: 950424 | K6: 945671.88 | L6: 940943.52 | M6: 936238.8 | N6: 931557.61 | P6: 177600
A7: 42125 | B7: 965000 | C7: 166700 | F7: May | G7: 965000 | H7: 965000 | I7: 960175 | J7: 955374.12 | K7: 950597.25 | L7: 945844.27 | M7: 941115.05 | N7: 936409.47 | P7: 178000
A8: 42156 | B8: 1010000 | C8: 175600 | F8: June | G8: 1010000 | H8: 1010000 | I8: 1004950 | J8: 999925.25 | K8: 994925.62 | L8: 989951 | M8: 985001.24 | N8: 980076.23 | P8: 186200
A9: 42186 | B9: 1006000 | C9: 175400 | F9: July | G9: 1006000 | H9: 1006000 | I9: 1000970 | J9: 995965.15 | K9: 990985.32 | L9: 986030.4 | M9: 981100.25 | N9: 976194.74 | P9: 184400
A10: 42217 | B10: 958000 | C10: 166400 | F10: August | G10: 958000 | H10: 958000 | I10: 953210 | J10: 948443.95 | K10: 943701.73 | L10: 938983.22 | M10: 934288.31 | N10: 929616.86 | P10: 176400
A11: 42248 | B11: 804000 | C11: 138400 | F11: September | G11: 804000 | H11: 804000 | I11: 799980 | J11: 795980.1 | K11: 792000.2 | L11: 788040.2 | M11: 784100 | N11: 780179.5 | P11: 147200
A12: 42278 | B12: 772000 | C12: 129600 | D12: PIS date | F12: October | G12: 772000 | H12: 768140 | I12: 764299.3 | J12: 760477.8 | K12: 756675.41 | L12: 752892.04 | M12: 749127.58 | N12: 745381.94 | P12: 139100
A13: 42309 | B13: 546000 | C13: 90200 | F13: November | G13: 546000 | H13: 543270 | I13: 540553.65 | J13: 537850.88 | K13: 535161.63 | L13: 532485.82 | M13: 529823.39 | N13: 527174.27 | P13: 97900
A14: 42339 | B14: 546000 | C14: 88300 | F14: December | G14: 546000 | H14: 543270 | I14: 540553.65 | J14: 537850.88 | K14: 535161.63 | L14: 532485.82 | M14: 529823.39 | N14: 527174.27 | P14: 97800
A15: 42370 | B15: 558000 | C15: 89800
A16: 42401 | B16: 618000 | C16: 100200
A17: 42430 | B17: 832000 | C17: 140000
A18: 42461 | B18: 960000 | C18: 164500
A19: 42491 | B19: 965000 | C19: 166700
A20: 42522 | B20: 1010000 | C20: 175600
A21: 42552 | B21: 1006000 | C21: 175400
A22: 42583 | B22: 958000 | C22: 166400
A23: 42614 | B23: 804000 | C23: 138400
A24: 42644 | B24: =B12*0.995 -> 768140 | C24: 129600
A25: 42675 | B25: =B13*0.995 -> 543270 | C25: 90200
A26: 42705 | B26: =B14*0.995 -> 543270 | C26: 88300
A27: 42736 | B27: =B15*0.995 -> 555210 | C27: 89800
A28: 42767 | B28: =B16*0.995 -> 614910 | C28: 100200
A29: 42795 | B29: =B17*0.995 -> 827840 | C29: 140000
A30: 42826 | B30: =B18*0.995 -> 955200 | C30: 164500
A31: 42856 | B31: =B19*0.995 -> 960175 | C31: 166700
A32: 42887 | B32: =B20*0.995 -> 1004950 | C32: 175600
A33: 42917 | B33: =B21*0.995 -> 1000970 | C33: 175400
A34: 42948 | B34: =B22*0.995 -> 953210 | C34: 166400
A35: 42979 | B35: =B23*0.995 -> 799980 | C35: 138400
A36: 43009 | B36: =B12*0.99 -> 764280 | C36: 129600
A37: 43040 | B37: =B13*0.99 -> 540540 | C37: 90200
A38: 43070 | B38: =B14*0.99 -> 540540 | C38: 88300
A39: 43101 | B39: =B15*0.99 -> 552420 | C39: 89800
A40: 43132 | B40: =B16*0.99 -> 611820 | C40: 100200
...

Sheet Stikeleather Config
A1: Field | B1: E_Grid | C1: GlobInc | G1: Stikeleather kWh | P1: Stikeleather Insolation (Wh/m^2)
A2: Units | B2: kWh | C2: Wh/m2 | G2: 2015 | H2: 2016 | I2: 2017 | J2: 2018 | K2: 2019 | L2: 2020 | M2: 2021 | N2: 2022 | P2: 2022
A3: 42005 | B3: 596000 | C3: 95500 | F3: January | G3: 596000 | H3: 596000 | I3: =H3*0.995 -> 593020 | J3: =I3*0.995 -> 590054.9 | K3: =J3*0.995 -> 587104.63 | L3: =K3*0.995 -> 584169.1 | M3: =L3*0.995 -> 581248.26 | N3: =M3*0.995 -> 578342.02 | P3: 102800
A4: 42036 | B4: 602000 | C4: 98900 | F4: February | G4: 602000 | H4: 602000 | I4: =H4*0.995 -> 598990 | J4: =I4*0.995 -> 595995.05 | K4: =J4*0.995 -> 593015.07 | L4: =K4*0.995 -> 590050 | M4: =L4*0.995 -> 587099.75 | N4: =M4*0.995 -> 584164.25 | P4: 106600
A5: 42064 | B5: 866000 | C5: 144000 | F5: March | G5: 866000 | H5: 866000 | I5: =H5*0.995 -> 861670 | J5: =I5*0.995 -> 857361.65 | K5: =J5*0.995 -> 853074.84 | L5: =K5*0.995 -> 848809.47 | M5: =L5*0.995 -> 844565.42 | N5: =M5*0.995 -> 840342.59 | P5: 156000
A6: 42095 | B6: 967000 | C6: 164800 | F6: April | G6: 967000 | H6: 967000 | I6: =H6*0.995 -> 962165 | J6: =I6*0.995 -> 957354.18 | K6: =J6*0.995 -> 952567.4 | L6: =K6*0.995 -> 947804.57 | M6: =L6*0.995 -> 943065.54 | N6: =M6*0.995 -> 938350.22 | P6: 176800
A7: 42125 | B7: 1006000 | C7: 172700 | F7: May | G7: 1006000 | H7: 1006000 | I7: =H7*0.995 -> 1000970 | J7: =I7*0.995 -> 995965.15 | K7: =J7*0.995 -> 990985.32 | L7: =K7*0.995 -> 986030.4 | M7: =L7*0.995 -> 981100.25 | N7: =M7*0.995 -> 976194.74 | P7: 183300
A8: 42156 | B8: 1031000 | C8: 178800 | F8: June | G8: 1031000 | H8: 1031000 | I8: =H8*0.995 -> 1025845 | J8: =I8*0.995 -> 1020715.8 | K8: =J8*0.995 -> 1015612.2 | L8: =K8*0.995 -> 1010534.1 | M8: =L8*0.995 -> 1005481.5 | N8: =M8*0.995 -> 1000454.1 | P8: 188600
A9: 42186 | B9: 1045000 | C9: 182100 | F9: July | G9: 1045000 | H9: 1045000 | I9: =H9*0.995 -> 1039775 | J9: =I9*0.995 -> 1034576.1 | K9: =J9*0.995 -> 1029403.2 | L9: =K9*0.995 -> 1024256.2 | M9: =L9*0.995 -> 1019134.9 | N9: =M9*0.995 -> 1014039.3 | P9: 189200
A10: 42217 | B10: 967000 | C10: 168000 | F10: August | G10: 967000 | H10: 967000 | I10: =H10*0.995 -> 962165 | J10: =I10*0.995 -> 957354.18 | K10: =J10*0.995 -> 952567.4 | L10: =K10*0.995 -> 947804.57 | M10: =L10*0.995 -> 943065.54 | N10: =M10*0.995 -> 938350.22 | P10: 175100
A11: 42248 | B11: 845000 | C11: 145300 | D11: PIS DATE | F11: September | G11: 845000 | H11: =G11*0.995 -> 840775 | I11: =H11*0.995 -> 836571.12 | J11: =I11*0.995 -> 832388.27 | K11: =J11*0.995 -> 828226.33 | L11: =K11*0.995 -> 824085.2 | M11: =L11*0.995 -> 819964.77 | N11: =M11*0.995 -> 815864.95 | P11: 153100
A12: 42278 | B12: 862000 | C12: 144600 | F12: October | G12: 862000 | H12: =G12*0.995 -> 857690 | I12: =H12*0.995 -> 853401.55 | J12: =I12*0.995 -> 849134.54 | K12: =J12*0.995 -> 844888.87 | L12: =K12*0.995 -> 840664.43 | M12: =L12*0.995 -> 836461.1 | N12: =M12*0.995 -> 832278.8 | P12: 153800
A13: 42309 | B13: 629000 | C13: 103400 | F13: November | G13: 629000 | H13: =G13*0.995 -> 625855 | I13: =H13*0.995 -> 622725.72 | J13: =I13*0.995 -> 619612.1 | K13: =J13*0.995 -> 616514.04 | L13: =K13*0.995 -> 613431.47 | M13: =L13*0.995 -> 610364.31 | N13: =M13*0.995 -> 607312.49 | P13: 111400
A14: 42339 | B14: 582000 | C14: 94000 | F14: December | G14: 582000 | H14: =G14*0.995 -> 579090 | I14: =H14*0.995 -> 576194.55 | J14: =I14*0.995 -> 573313.58 | K14: =J14*0.995 -> 570447.01 | L14: =K14*0.995 -> 567594.77 | M14: =L14*0.995 -> 564756.8 | N14: =M14*0.995 -> 561933.02 | P14: 103100
A15: 42370 | B15: 596000 | C15: 95500
A16: 42401 | B16: 602000 | C16: 98900
A17: 42430 | B17: 866000 | C17: 144000
A18: 42461 | B18: 967000 | C18: 164800
A19: 42491 | B19: 1006000 | C19: 172700
A20: 42522 | B20: 1031000 | C20: 178800
A21: 42552 | B21: 1045000 | C21: 182100
A22: 42583 | B22: 967000 | C22: 168000
A23: 42614 | B23: =B11*0.995 -> 840775 | C23: 145300
A24: 42644 | B24: =B12*0.995 -> 857690 | C24: 144600
A25: 42675 | B25: =B13*0.995 -> 625855 | C25: 103400
A26: 42705 | B26: =B14*0.995 -> 579090 | C26: 94000
A27: 42736 | B27: =B15*0.995 -> 593020 | C27: 95500
A28: 42767 | B28: =B16*0.995 -> 598990 | C28: 98900
A29: 42795 | B29: =B17*0.995 -> 861670 | C29: 144000
A30: 42826 | B30: =B18*0.995 -> 962165 | C30: 164800
A31: 42856 | B31: =B19*0.995 -> 1000970 | C31: 172700
A32: 42887 | B32: =B20*0.995 -> 1025845 | C32: 178800
A33: 42917 | B33: =B21*0.995 -> 1039775 | C33: 182100
A34: 42948 | B34: =B22*0.995 -> 962165 | C34: 168000
A35: 42979 | B35: =B11*0.99 -> 836550 | C35: 145300
A36: 43009 | B36: =B12*0.99 -> 853380 | C36: 144600
A37: 43040 | B37: =B13*0.99 -> 622710 | C37: 103400
A38: 43070 | B38: =B14*0.99 -> 576180 | C38: 94000
A39: 43101 | B39: =B15*0.99 -> 590040 | C39: 95500
A40: 43132 | B40: =B16*0.99 -> 595980 | C40: 98900
...

Sheet Yadkin Config
A1: Field | B1: E_Grid | C1: GlobInc | G1: Yadkin 601 kWh | P1: Yadkin 601 Insolation (Wh/m^2)
A2: Units | B2: kWh | C2: Wh/m2 | G2: 2015 | H2: 2016 | I2: 2017 | J2: 2018 | K2: 2019 | L2: 2020 | M2: 2021 | N2: 2022 | P2: 2022
A3: 42005 | B3: 349000 | C3: 90100 | F3: January | G3: 349000 | H3: 349000 | I3: =H3*0.995 -> 347255 | J3: =I3*0.995 -> 345518.72 | K3: =J3*0.995 -> 343791.13 | L3: =K3*0.995 -> 342072.18 | M3: =L3*0.995 -> 340361.81 | N3: =M3*0.995 -> 338660.01 | P3: 99200
A4: 42036 | B4: 379200 | C4: 100800 | F4: February | G4: 379200 | H4: 379200 | I4: =H4*0.995 -> 377304 | J4: =I4*0.995 -> 375417.48 | K4: =J4*0.995 -> 373540.39 | L4: =K4*0.995 -> 371672.69 | M4: =L4*0.995 -> 369814.33 | N4: =M4*0.995 -> 367965.26 | P4: 108300
A5: 42064 | B5: 508200 | C5: 139500 | F5: March | G5: 508200 | H5: 508200 | I5: =H5*0.995 -> 505659 | J5: =I5*0.995 -> 503130.71 | K5: =J5*0.995 -> 500615.05 | L5: =K5*0.995 -> 498111.98 | M5: =L5*0.995 -> 495621.42 | N5: =M5*0.995 -> 493143.31 | P5: 150000
A6: 42095 | B6: 571100 | C6: 159800 | F6: April | G6: 571100 | H6: 571100 | I6: =H6*0.995 -> 568244.5 | J6: =I6*0.995 -> 565403.28 | K6: =J6*0.995 -> 562576.26 | L6: =K6*0.995 -> 559763.38 | M6: =L6*0.995 -> 556964.56 | N6: =M6*0.995 -> 554179.74 | P6: 171200
A7: 42125 | B7: 581500 | C7: 163300 | F7: May | G7: 581500 | H7: 581500 | I7: =H7*0.995 -> 578592.5 | J7: =I7*0.995 -> 575699.54 | K7: =J7*0.995 -> 572821.04 | L7: =K7*0.995 -> 569956.93 | M7: =L7*0.995 -> 567107.15 | N7: =M7*0.995 -> 564271.61 | P7: 174100
A8: 42156 | B8: 613000 | C8: 173900 | F8: June | G8: 613000 | H8: 613000 | I8: =H8*0.995 -> 609935 | J8: =I8*0.995 -> 606885.32 | K8: =J8*0.995 -> 603850.9 | L8: =K8*0.995 -> 600831.64 | M8: =L8*0.995 -> 597827.49 | N8: =M8*0.995 -> 594838.35 | P8: 182400
A9: 42186 | B9: 621300 | C9: 176800 | F9: July | G9: 621300 | H9: 621300 | I9: =H9*0.995 -> 618193.5 | J9: =I9*0.995 -> 615102.53 | K9: =J9*0.995 -> 612027.02 | L9: =K9*0.995 -> 608966.88 | M9: =L9*0.995 -> 605922.05 | N9: =M9*0.995 -> 602892.44 | P9: 185100
A10: 42217 | B10: 605900 | C10: 171400 | F10: August | G10: 605900 | H10: 605900 | I10: =H10*0.995 -> 602870.5 | J10: =I10*0.995 -> 599856.15 | K10: =J10*0.995 -> 596856.87 | L10: =K10*0.995 -> 593872.58 | M10: =L10*0.995 -> 590903.22 | N10: =M10*0.995 -> 587948.7 | P10: 178400
A11: 42248 | B11: 500600 | C11: 139100 | D11: PIS Date | F11: September | G11: 500600 | H11: =G11*0.995 -> 498097 | I11: =H11*0.995 -> 495606.52 | J11: =I11*0.995 -> 493128.48 | K11: =J11*0.995 -> 490662.84 | L11: =K11*0.995 -> 488209.53 | M11: =L11*0.995 -> 485768.48 | N11: =M11*0.995 -> 483339.64 | P11: 146600
A12: 42278 | B12: 460400 | C12: 125500 | F12: October | G12: 460400 | H12: =G12*0.995 -> 458098 | I12: =H12*0.995 -> 455807.51 | J12: =I12*0.995 -> 453528.47 | K12: =J12*0.995 -> 451260.83 | L12: =K12*0.995 -> 449004.53 | M12: =L12*0.995 -> 446759.5 | N12: =M12*0.995 -> 444525.71 | P12: 133800
A13: 42309 | B13: 335300 | C13: 89900 | F13: November | G13: 335300 | H13: =G13*0.995 -> 333623.5 | I13: =H13*0.995 -> 331955.38 | J13: =I13*0.995 -> 330295.61 | K13: =J13*0.995 -> 328644.13 | L13: =K13*0.995 -> 327000.91 | M13: =L13*0.995 -> 325365.9 | N13: =M13*0.995 -> 323739.07 | P13: 96000
A14: 42339 | B14: 342700 | C14: 89600 | F14: December | G14: 342700 | H14: =G14*0.995 -> 340986.5 | I14: =H14*0.995 -> 339281.57 | J14: =I14*0.995 -> 337585.16 | K14: =J14*0.995 -> 335897.23 | L14: =K14*0.995 -> 334217.75 | M14: =L14*0.995 -> 332546.66 | N14: =M14*0.995 -> 330883.93 | P14: 98100
A15: 42370 | B15: 349000 | C15: 90100
A16: 42401 | B16: 379200 | C16: 100800
A17: 42430 | B17: 508200 | C17: 139500
A18: 42461 | B18: 571100 | C18: 159800
A19: 42491 | B19: 581500 | C19: 163300
A20: 42522 | B20: 613000 | C20: 173900
A21: 42552 | B21: 621300 | C21: 176800
A22: 42583 | B22: 605900 | C22: 171400
A23: 42614 | B23: =B11*0.995 -> 498097 | C23: 139100
A24: 42644 | B24: =B12*0.995 -> 458098 | C24: 125500
A25: 42675 | B25: =B13*0.995 -> 333623.5 | C25: 89900
A26: 42705 | B26: =B14*0.995 -> 340986.5 | C26: 89600
A27: 42736 | B27: =B15*0.995 -> 347255 | C27: 90100
A28: 42767 | B28: =B16*0.995 -> 377304 | C28: 100800
A29: 42795 | B29: =B17*0.995 -> 505659 | C29: 139500
A30: 42826 | B30: =B18*0.995 -> 568244.5 | C30: 159800
A31: 42856 | B31: =B19*0.995 -> 578592.5 | C31: 163300
A32: 42887 | B32: =B20*0.995 -> 609935 | C32: 173900
A33: 42917 | B33: =B21*0.995 -> 618193.5 | C33: 176800
A34: 42948 | B34: =B22*0.995 -> 602870.5 | C34: 171400
A35: 42979 | B35: =B11*0.99 -> 495594 | C35: 139100
A36: 43009 | B36: =B12*0.99 -> 455796 | C36: 125500
A37: 43040 | B37: =B13*0.99 -> 331947 | C37: 89900
A38: 43070 | B38: =B14*0.99 -> 339273 | C38: 89600
A39: 43101 | B39: =B15*0.99 -> 345510 | C39: 90100
A40: 43132 | B40: =B16*0.99 -> 375408 | C40: 100800
...
