Workbook
Name JanActual: #REF!
Name JanActual2: #REF!
Name JanExpected: #REF!
Name JanExpectedDelta: #REF!
Name JanExpectedPercent: #REF!
Name JanExpPercent: #REF!
Name JanForecasted: #REF!
Name JanForecastedDelta: #REF!
Name JanForecastedPercent: #REF!
Name portfolio: Sites!$B$1:$B$1
Name Year: Sites!#REF!

Sheet Year to Date
A1: {=portfolio} -> Wells Fargo | C1: Year to Date Actual v. Expected | F1: Year to Date Actual v. Forecasted
A2: Total | B2: =SUM(B4:B94) -> 2022284.6 | C2: =SUM(C4:C94) -> 2259425.3 | D2: =B2-C2 -> -237140.61 | E2: =IFERROR(D2/C2, 0) -> -0.10495616 | F2: =SUM(F4:F94) -> 3056274.5 | G2: =B2-F2 -> -1033989.9 | H2: =IFERROR(G2/F2, 0) -> -0.33831709
A3: Site | B3: Actual | C3: Expected | D3: Delta | E3: % | F3: Forecasted | G3: Delta | H3: %
A4: {=_xlfn.UNIQUE(Sites[State])} -> CA | B4: =SUM('1st Qtr'!B4, '2nd Qtr'!B4, '3rd Qtr'!B4, '4th Qtr'!B4) -> 96460.874 | C4: =SUM('1st Qtr'!C4, '2nd Qtr'!C4, '3rd Qtr'!C4, '4th Qtr'!C4) -> 98630.98 | D4: =IF(AND(ISNUMBER($B4),ISNUMBER(C4)), $B4-C4, "") -> -2170.1058 | E4: =IFERROR(D4/C4, "") -> -0.022002274 | F4: =SUM('1st Qtr'!F4, '2nd Qtr'!F4, '3rd Qtr'!F4, '4th Qtr'!F4) -> 92937.79 | G4: =IF(AND(ISNUMBER($B4),ISNUMBER(F4)), $B4-F4, "") -> 3523.0842 | H4: =IFERROR(G4/F4, "") -> 0.037907983
A5: CO | B5: =SUM('1st Qtr'!B5, '2nd Qtr'!B5, '3rd Qtr'!B5, '4th Qtr'!B5) -> 49254.6 | C5: =SUM('1st Qtr'!C5, '2nd Qtr'!C5, '3rd Qtr'!C5, '4th Qtr'!C5) -> 0 | D5: =IF(AND(ISNUMBER($B5),ISNUMBER(C5)), $B5-C5, "") -> 49254.6 | E5: =IFERROR(D5/C5, "") | F5: =SUM('1st Qtr'!F5, '2nd Qtr'!F5, '3rd Qtr'!F5, '4th Qtr'!F5) -> 58983.135 | G5: =IF(AND(ISNUMBER($B5),ISNUMBER(F5)), $B5-F5, "") -> -9728.5346 | H5: =IFERROR(G5/F5, "") -> -0.16493756
A6: CT | B6: =SUM('1st Qtr'!B6, '2nd Qtr'!B6, '3rd Qtr'!B6, '4th Qtr'!B6) -> 1437.1503 | C6: =SUM('1st Qtr'!C6, '2nd Qtr'!C6, '3rd Qtr'!C6, '4th Qtr'!C6) -> 3198.4033 | D6: =IF(AND(ISNUMBER($B6),ISNUMBER(C6)), $B6-C6, "") -> -1761.253 | E6: =IFERROR(D6/C6, "") -> -0.55066634 | F6: =SUM('1st Qtr'!F6, '2nd Qtr'!F6, '3rd Qtr'!F6, '4th Qtr'!F6) -> 2904.6053 | G6: =IF(AND(ISNUMBER($B6),ISNUMBER(F6)), $B6-F6, "") -> -1467.455 | H6: =IFERROR(G6/F6, "") -> -0.50521667
A7: FL | B7: =SUM('1st Qtr'!B7, '2nd Qtr'!B7, '3rd Qtr'!B7, '4th Qtr'!B7) -> 3427.8035 | C7: =SUM('1st Qtr'!C7, '2nd Qtr'!C7, '3rd Qtr'!C7, '4th Qtr'!C7) -> 9472.91 | D7: =IF(AND(ISNUMBER($B7),ISNUMBER(C7)), $B7-C7, "") -> -6045.1065 | E7: =IFERROR(D7/C7, "") -> -0.63814673 | F7: =SUM('1st Qtr'!F7, '2nd Qtr'!F7, '3rd Qtr'!F7, '4th Qtr'!F7) -> 12229.661 | G7: =IF(AND(ISNUMBER($B7),ISNUMBER(F7)), $B7-F7, "") -> -8801.8575 | H7: =IFERROR(G7/F7, "") -> -0.71971394
A8: IA | B8: =SUM('1st Qtr'!B8, '2nd Qtr'!B8, '3rd Qtr'!B8, '4th Qtr'!B8) -> 600256.94 | C8: =SUM('1st Qtr'!C8, '2nd Qtr'!C8, '3rd Qtr'!C8, '4th Qtr'!C8) -> 573354.79 | D8: =IF(AND(ISNUMBER($B8),ISNUMBER(C8)), $B8-C8, "") -> 26902.144 | E8: =IFERROR(D8/C8, "") -> 0.046920587 | F8: =SUM('1st Qtr'!F8, '2nd Qtr'!F8, '3rd Qtr'!F8, '4th Qtr'!F8) -> 641026.39 | G8: =IF(AND(ISNUMBER($B8),ISNUMBER(F8)), $B8-F8, "") -> -40769.449 | H8: =IFERROR(G8/F8, "") -> -0.063600267
A9: NC | B9: =SUM('1st Qtr'!B9, '2nd Qtr'!B9, '3rd Qtr'!B9, '4th Qtr'!B9) -> 102107 | C9: =SUM('1st Qtr'!C9, '2nd Qtr'!C9, '3rd Qtr'!C9, '4th Qtr'!C9) -> 266710 | D9: =IF(AND(ISNUMBER($B9),ISNUMBER(C9)), $B9-C9, "") -> -164603 | E9: =IFERROR(D9/C9, "") -> -0.61716096 | F9: =SUM('1st Qtr'!F9, '2nd Qtr'!F9, '3rd Qtr'!F9, '4th Qtr'!F9) -> 336745 | G9: =IF(AND(ISNUMBER($B9),ISNUMBER(F9)), $B9-F9, "") -> -234638 | H9: =IFERROR(G9/F9, "") -> -0.69678243
A10: NJ | B10: =SUM('1st Qtr'!B10, '2nd Qtr'!B10, '3rd Qtr'!B10, '4th Qtr'!B10) -> 152779.9 | C10: =SUM('1st Qtr'!C10, '2nd Qtr'!C10, '3rd Qtr'!C10, '4th Qtr'!C10) -> 157231.97 | D10: =IF(AND(ISNUMBER($B10),ISNUMBER(C10)), $B10-C10, "") -> -4452.0682 | E10: =IFERROR(D10/C10, "") -> -0.028315286 | F10: =SUM('1st Qtr'!F10, '2nd Qtr'!F10, '3rd Qtr'!F10, '4th Qtr'!F10) -> 166141.62 | G10: =IF(AND(ISNUMBER($B10),ISNUMBER(F10)), $B10-F10, "") -> -13361.72 | H10: =IFERROR(G10/F10, "") -> -0.080423674
A11: TX | B11: =SUM('1st Qtr'!B11, '2nd Qtr'!B11, '3rd Qtr'!B11, '4th Qtr'!B11) -> 1016560.4 | C11: =SUM('1st Qtr'!C11, '2nd Qtr'!C11, '3rd Qtr'!C11, '4th Qtr'!C11) -> 1150826.2 | D11: =IF(AND(ISNUMBER($B11),ISNUMBER(C11)), $B11-C11, "") -> -134265.82 | E11: =IFERROR(D11/C11, "") -> -0.11666907 | F11: =SUM('1st Qtr'!F11, '2nd Qtr'!F11, '3rd Qtr'!F11, '4th Qtr'!F11) -> 1745306.3 | G11: =IF(AND(ISNUMBER($B11),ISNUMBER(F11)), $B11-F11, "") -> -728745.97 | H11: =IFERROR(G11/F11, "") -> -0.41754616

Sheet 1st Qtr
A1: {=portfolio} -> Wells Fargo | C1: 1st Quarter Actual v. Expected | F1: 1st Quarter Actual v. Forecasted
A2: Total | B2: =SUM(B4:B90) -> 2022284.6 | C2: =SUM(C4:C90) -> 2259425.3 | D2: =B2-C2 -> -237140.61 | E2: =IFERROR(D2/C2, 0) -> -0.10495616 | F2: =SUM(F4:F90) -> 3056274.5 | G2: =B2-F2 -> -1033989.9 | H2: =IFERROR(G2/F2, 0) -> -0.33831709
A3: State | B3: Actual | C3: Expected | D3: Delta | E3: % | F3: Forecasted | G3: Delta | H3: %
A4: {=_xlfn.UNIQUE(Sites[State])} -> CA | B4: =SUM(SUMIF(_xlfn.ANCHORARRAY(Jan!$B$4), $A4, Jan!C$4:C$65), SUMIF(_xlfn.ANCHORARRAY(Feb!$B$4), $A4, Feb!C$4:C$78), SUMIF(_xlfn.ANCHORARRAY(Mar!$B$4), $A4, Mar!C$4:C$65)) -> 96460.874 | C4: =SUM(SUMIF(_xlfn.ANCHORARRAY(Jan!$B$4), $A4, Jan!D$4:D$65), SUMIF(_xlfn.ANCHORARRAY(Feb!$B$4), $A4, Feb!D$4:D$78), SUMIF(_xlfn.ANCHORARRAY(Mar!$B$4), $A4, Mar!D$4:D$65)) -> 98630.98 | D4: =IF(AND(ISNUMBER(B4),ISNUMBER(C4)), B4-C4, "") -> -2170.1058 | E4: =IFERROR(D4/C4, "") -> -0.022002274 | F4: =SUM(SUMIF(_xlfn.ANCHORARRAY(Jan!$B$4), $A4, Jan!G$4:G$65), SUMIF(_xlfn.ANCHORARRAY(Feb!$B$4), $A4, Feb!G$4:G$78), SUMIF(_xlfn.ANCHORARRAY(Mar!$B$4), $A4, Mar!G$4:G$65)) -> 92937.79 | G4: =IF(AND(ISNUMBER(B4),ISNUMBER(F4)), B4-F4, "") -> 3523.0842 | H4: =IFERROR(G4/F4, "") -> 0.037907983
A5: CO | B5: =SUM(SUMIF(_xlfn.ANCHORARRAY(Jan!$B$4), $A5, Jan!C$4:C$65), SUMIF(_xlfn.ANCHORARRAY(Feb!$B$4), $A5, Feb!C$4:C$78), SUMIF(_xlfn.ANCHORARRAY(Mar!$B$4), $A5, Mar!C$4:C$65)) -> 49254.6 | C5: =SUM(SUMIF(_xlfn.ANCHORARRAY(Jan!$B$4), $A5, Jan!D$4:D$65), SUMIF(_xlfn.ANCHORARRAY(Feb!$B$4), $A5, Feb!D$4:D$78), SUMIF(_xlfn.ANCHORARRAY(Mar!$B$4), $A5, Mar!D$4:D$65)) -> 0 | D5: =IF(AND(ISNUMBER(B5),ISNUMBER(C5)), B5-C5, "") -> 49254.6 | E5: =IFERROR(D5/C5, "") | F5: =SUM(SUMIF(_xlfn.ANCHORARRAY(Jan!$B$4), $A5, Jan!G$4:G$65), SUMIF(_xlfn.ANCHORARRAY(Feb!$B$4), $A5, Feb!G$4:G$78), SUMIF(_xlfn.ANCHORARRAY(Mar!$B$4), $A5, Mar!G$4:G$65)) -> 58983.135 | G5: =IF(AND(ISNUMBER(B5),ISNUMBER(F5)), B5-F5, "") -> -9728.5346 | H5: =IFERROR(G5/F5, "") -> -0.16493756
A6: CT | B6: =SUM(SUMIF(_xlfn.ANCHORARRAY(Jan!$B$4), $A6, Jan!C$4:C$65), SUMIF(_xlfn.ANCHORARRAY(Feb!$B$4), $A6, Feb!C$4:C$78), SUMIF(_xlfn.ANCHORARRAY(Mar!$B$4), $A6, Mar!C$4:C$65)) -> 1437.1503 | C6: =SUM(SUMIF(_xlfn.ANCHORARRAY(Jan!$B$4), $A6, Jan!D$4:D$65), SUMIF(_xlfn.ANCHORARRAY(Feb!$B$4), $A6, Feb!D$4:D$78), SUMIF(_xlfn.ANCHORARRAY(Mar!$B$4), $A6, Mar!D$4:D$65)) -> 3198.4033 | D6: =IF(AND(ISNUMBER(B6),ISNUMBER(C6)), B6-C6, "") -> -1761.253 | E6: =IFERROR(D6/C6, "") -> -0.55066634 | F6: =SUM(SUMIF(_xlfn.ANCHORARRAY(Jan!$B$4), $A6, Jan!G$4:G$65), SUMIF(_xlfn.ANCHORARRAY(Feb!$B$4), $A6, Feb!G$4:G$78), SUMIF(_xlfn.ANCHORARRAY(Mar!$B$4), $A6, Mar!G$4:G$65)) -> 2904.6053 | G6: =IF(AND(ISNUMBER(B6),ISNUMBER(F6)), B6-F6, "") -> -1467.455 | H6: =IFERROR(G6/F6, "") -> -0.50521667
A7: FL | B7: =SUM(SUMIF(_xlfn.ANCHORARRAY(Jan!$B$4), $A7, Jan!C$4:C$65), SUMIF(_xlfn.ANCHORARRAY(Feb!$B$4), $A7, Feb!C$4:C$78), SUMIF(_xlfn.ANCHORARRAY(Mar!$B$4), $A7, Mar!C$4:C$65)) -> 3427.8035 | C7: =SUM(SUMIF(_xlfn.ANCHORARRAY(Jan!$B$4), $A7, Jan!D$4:D$65), SUMIF(_xlfn.ANCHORARRAY(Feb!$B$4), $A7, Feb!D$4:D$78), SUMIF(_xlfn.ANCHORARRAY(Mar!$B$4), $A7, Mar!D$4:D$65)) -> 9472.91 | D7: =IF(AND(ISNUMBER(B7),ISNUMBER(C7)), B7-C7, "") -> -6045.1065 | E7: =IFERROR(D7/C7, "") -> -0.63814673 | F7: =SUM(SUMIF(_xlfn.ANCHORARRAY(Jan!$B$4), $A7, Jan!G$4:G$65), SUMIF(_xlfn.ANCHORARRAY(Feb!$B$4), $A7, Feb!G$4:G$78), SUMIF(_xlfn.ANCHORARRAY(Mar!$B$4), $A7, Mar!G$4:G$65)) -> 12229.661 | G7: =IF(AND(ISNUMBER(B7),ISNUMBER(F7)), B7-F7, "") -> -8801.8575 | H7: =IFERROR(G7/F7, "") -> -0.71971394
A8: IA | B8: =SUM(SUMIF(_xlfn.ANCHORARRAY(Jan!$B$4), $A8, Jan!C$4:C$65), SUMIF(_xlfn.ANCHORARRAY(Feb!$B$4), $A8, Feb!C$4:C$78), SUMIF(_xlfn.ANCHORARRAY(Mar!$B$4), $A8, Mar!C$4:C$65)) -> 600256.94 | C8: =SUM(SUMIF(_xlfn.ANCHORARRAY(Jan!$B$4), $A8, Jan!D$4:D$65), SUMIF(_xlfn.ANCHORARRAY(Feb!$B$4), $A8, Feb!D$4:D$78), SUMIF(_xlfn.ANCHORARRAY(Mar!$B$4), $A8, Mar!D$4:D$65)) -> 573354.79 | D8: =IF(AND(ISNUMBER(B8),ISNUMBER(C8)), B8-C8, "") -> 26902.144 | E8: =IFERROR(D8/C8, "") -> 0.046920587 | F8: =SUM(SUMIF(_xlfn.ANCHORARRAY(Jan!$B$4), $A8, Jan!G$4:G$65), SUMIF(_xlfn.ANCHORARRAY(Feb!$B$4), $A8, Feb!G$4:G$78), SUMIF(_xlfn.ANCHORARRAY(Mar!$B$4), $A8, Mar!G$4:G$65)) -> 641026.39 | G8: =IF(AND(ISNUMBER(B8),ISNUMBER(F8)), B8-F8, "") -> -40769.449 | H8: =IFERROR(G8/F8, "") -> -0.063600267
A9: NC | B9: =SUM(SUMIF(_xlfn.ANCHORARRAY(Jan!$B$4), $A9, Jan!C$4:C$65), SUMIF(_xlfn.ANCHORARRAY(Feb!$B$4), $A9, Feb!C$4:C$78), SUMIF(_xlfn.ANCHORARRAY(Mar!$B$4), $A9, Mar!C$4:C$65)) -> 102107 | C9: =SUM(SUMIF(_xlfn.ANCHORARRAY(Jan!$B$4), $A9, Jan!D$4:D$65), SUMIF(_xlfn.ANCHORARRAY(Feb!$B$4), $A9, Feb!D$4:D$78), SUMIF(_xlfn.ANCHORARRAY(Mar!$B$4), $A9, Mar!D$4:D$65)) -> 266710 | D9: =IF(AND(ISNUMBER(B9),ISNUMBER(C9)), B9-C9, "") -> -164603 | E9: =IFERROR(D9/C9, "") -> -0.61716096 | F9: =SUM(SUMIF(_xlfn.ANCHORARRAY(Jan!$B$4), $A9, Jan!G$4:G$65), SUMIF(_xlfn.ANCHORARRAY(Feb!$B$4), $A9, Feb!G$4:G$78), SUMIF(_xlfn.ANCHORARRAY(Mar!$B$4), $A9, Mar!G$4:G$65)) -> 336745 | G9: =IF(AND(ISNUMBER(B9),ISNUMBER(F9)), B9-F9, "") -> -234638 | H9: =IFERROR(G9/F9, "") -> -0.69678243
A10: NJ | B10: =SUM(SUMIF(_xlfn.ANCHORARRAY(Jan!$B$4), $A10, Jan!C$4:C$65), SUMIF(_xlfn.ANCHORARRAY(Feb!$B$4), $A10, Feb!C$4:C$78), SUMIF(_xlfn.ANCHORARRAY(Mar!$B$4), $A10, Mar!C$4:C$65)) -> 152779.9 | C10: =SUM(SUMIF(_xlfn.ANCHORARRAY(Jan!$B$4), $A10, Jan!D$4:D$65), SUMIF(_xlfn.ANCHORARRAY(Feb!$B$4), $A10, Feb!D$4:D$78), SUMIF(_xlfn.ANCHORARRAY(Mar!$B$4), $A10, Mar!D$4:D$65)) -> 157231.97 | D10: =IF(AND(ISNUMBER(B10),ISNUMBER(C10)), B10-C10, "") -> -4452.0682 | E10: =IFERROR(D10/C10, "") -> -0.028315286 | F10: =SUM(SUMIF(_xlfn.ANCHORARRAY(Jan!$B$4), $A10, Jan!G$4:G$65), SUMIF(_xlfn.ANCHORARRAY(Feb!$B$4), $A10, Feb!G$4:G$78), SUMIF(_xlfn.ANCHORARRAY(Mar!$B$4), $A10, Mar!G$4:G$65)) -> 166141.62 | G10: =IF(AND(ISNUMBER(B10),ISNUMBER(F10)), B10-F10, "") -> -13361.72 | H10: =IFERROR(G10/F10, "") -> -0.080423674
A11: TX | B11: =SUM(SUMIF(_xlfn.ANCHORARRAY(Jan!$B$4), $A11, Jan!C$4:C$65), SUMIF(_xlfn.ANCHORARRAY(Feb!$B$4), $A11, Feb!C$4:C$78), SUMIF(_xlfn.ANCHORARRAY(Mar!$B$4), $A11, Mar!C$4:C$65)) -> 1016560.4 | C11: =SUM(SUMIF(_xlfn.ANCHORARRAY(Jan!$B$4), $A11, Jan!D$4:D$65), SUMIF(_xlfn.ANCHORARRAY(Feb!$B$4), $A11, Feb!D$4:D$78), SUMIF(_xlfn.ANCHORARRAY(Mar!$B$4), $A11, Mar!D$4:D$65)) -> 1150826.2 | D11: =IF(AND(ISNUMBER(B11),ISNUMBER(C11)), B11-C11, "") -> -134265.82 | E11: =IFERROR(D11/C11, "") -> -0.11666907 | F11: =SUM(SUMIF(_xlfn.ANCHORARRAY(Jan!$B$4), $A11, Jan!G$4:G$65), SUMIF(_xlfn.ANCHORARRAY(Feb!$B$4), $A11, Feb!G$4:G$78), SUMIF(_xlfn.ANCHORARRAY(Mar!$B$4), $A11, Mar!G$4:G$65)) -> 1745306.3 | G11: =IF(AND(ISNUMBER(B11),ISNUMBER(F11)), B11-F11, "") -> -728745.97 | H11: =IFERROR(G11/F11, "") -> -0.41754616

Sheet 2nd Qtr
A1: {=portfolio} -> Wells Fargo | C1: 2nd Quarter Actual v. Expected | F1: 2nd Quarter Actual v. Forecasted
A2: Total | B2: =SUM(B4:B85) -> 0 | C2: =SUM(C4:C85) -> 0 | D2: =B2-C2 -> 0 | E2: =IFERROR(D2/C2, 0) -> 0 | F2: =SUM(F4:F85) -> 0 | G2: =B2-F2 -> 0 | H2: =IFERROR(G2/F2, 0) -> 0
A3: State | B3: Actual | C3: Expected | D3: Delta | E3: % | F3: Forecasted | G3: Delta | H3: %
A4: {=_xlfn.UNIQUE(Sites[State])} -> CA | B4: =SUM(SUMIF(_xlfn.ANCHORARRAY(Apr!$B$4), $A4, Apr!C$4:C$78), SUMIF(_xlfn.ANCHORARRAY(May!$B$4), $A4, May!C$4:C$78), SUMIF(_xlfn.ANCHORARRAY(Jun!$B$4), $A4, Jun!C$4:C$78)) -> 0 | C4: =SUM(SUMIF(_xlfn.ANCHORARRAY(Apr!$B$4), $A4, Apr!D$4:D$78), SUMIF(_xlfn.ANCHORARRAY(May!$B$4), $A4, May!D$4:D$78), SUMIF(_xlfn.ANCHORARRAY(Jun!$B$4), $A4, Jun!D$4:D$78)) -> 0 | D4: =IF(AND(ISNUMBER(B4),ISNUMBER(C4)), B4-C4, "") -> 0 | E4: =IFERROR(D4/C4, "") | F4: =SUM(SUMIF(_xlfn.ANCHORARRAY(Apr!$B$4), $A4, Apr!G$4:G$78), SUMIF(_xlfn.ANCHORARRAY(May!$B$4), $A4, May!G$4:G$78), SUMIF(_xlfn.ANCHORARRAY(Jun!$B$4), $A4, Jun!G$4:G$78)) -> 0 | G4: =IF(AND(ISNUMBER(B4),ISNUMBER(F4)), B4-F4, "") -> 0 | H4: =IFERROR(G4/F4, "")
A5: CO | B5: =SUM(SUMIF(_xlfn.ANCHORARRAY(Apr!$B$4), $A5, Apr!C$4:C$78), SUMIF(_xlfn.ANCHORARRAY(May!$B$4), $A5, May!C$4:C$78), SUMIF(_xlfn.ANCHORARRAY(Jun!$B$4), $A5, Jun!C$4:C$78)) -> 0 | C5: =SUM(SUMIF(_xlfn.ANCHORARRAY(Apr!$B$4), $A5, Apr!D$4:D$78), SUMIF(_xlfn.ANCHORARRAY(May!$B$4), $A5, May!D$4:D$78), SUMIF(_xlfn.ANCHORARRAY(Jun!$B$4), $A5, Jun!D$4:D$78)) -> 0 | D5: =IF(AND(ISNUMBER(B5),ISNUMBER(C5)), B5-C5, "") -> 0 | E5: =IFERROR(D5/C5, "") | F5: =SUM(SUMIF(_xlfn.ANCHORARRAY(Apr!$B$4), $A5, Apr!G$4:G$78), SUMIF(_xlfn.ANCHORARRAY(May!$B$4), $A5, May!G$4:G$78), SUMIF(_xlfn.ANCHORARRAY(Jun!$B$4), $A5, Jun!G$4:G$78)) -> 0 | G5: =IF(AND(ISNUMBER(B5),ISNUMBER(F5)), B5-F5, "") -> 0 | H5: =IFERROR(G5/F5, "")
A6: CT | B6: =SUM(SUMIF(_xlfn.ANCHORARRAY(Apr!$B$4), $A6, Apr!C$4:C$78), SUMIF(_xlfn.ANCHORARRAY(May!$B$4), $A6, May!C$4:C$78), SUMIF(_xlfn.ANCHORARRAY(Jun!$B$4), $A6, Jun!C$4:C$78)) -> 0 | C6: =SUM(SUMIF(_xlfn.ANCHORARRAY(Apr!$B$4), $A6, Apr!D$4:D$78), SUMIF(_xlfn.ANCHORARRAY(May!$B$4), $A6, May!D$4:D$78), SUMIF(_xlfn.ANCHORARRAY(Jun!$B$4), $A6, Jun!D$4:D$78)) -> 0 | D6: =IF(AND(ISNUMBER(B6),ISNUMBER(C6)), B6-C6, "") -> 0 | E6: =IFERROR(D6/C6, "") | F6: =SUM(SUMIF(_xlfn.ANCHORARRAY(Apr!$B$4), $A6, Apr!G$4:G$78), SUMIF(_xlfn.ANCHORARRAY(May!$B$4), $A6, May!G$4:G$78), SUMIF(_xlfn.ANCHORARRAY(Jun!$B$4), $A6, Jun!G$4:G$78)) -> 0 | G6: =IF(AND(ISNUMBER(B6),ISNUMBER(F6)), B6-F6, "") -> 0 | H6: =IFERROR(G6/F6, "")
A7: FL | B7: =SUM(SUMIF(_xlfn.ANCHORARRAY(Apr!$B$4), $A7, Apr!C$4:C$78), SUMIF(_xlfn.ANCHORARRAY(May!$B$4), $A7, May!C$4:C$78), SUMIF(_xlfn.ANCHORARRAY(Jun!$B$4), $A7, Jun!C$4:C$78)) -> 0 | C7: =SUM(SUMIF(_xlfn.ANCHORARRAY(Apr!$B$4), $A7, Apr!D$4:D$78), SUMIF(_xlfn.ANCHORARRAY(May!$B$4), $A7, May!D$4:D$78), SUMIF(_xlfn.ANCHORARRAY(Jun!$B$4), $A7, Jun!D$4:D$78)) -> 0 | D7: =IF(AND(ISNUMBER(B7),ISNUMBER(C7)), B7-C7, "") -> 0 | E7: =IFERROR(D7/C7, "") | F7: =SUM(SUMIF(_xlfn.ANCHORARRAY(Apr!$B$4), $A7, Apr!G$4:G$78), SUMIF(_xlfn.ANCHORARRAY(May!$B$4), $A7, May!G$4:G$78), SUMIF(_xlfn.ANCHORARRAY(Jun!$B$4), $A7, Jun!G$4:G$78)) -> 0 | G7: =IF(AND(ISNUMBER(B7),ISNUMBER(F7)), B7-F7, "") -> 0 | H7: =IFERROR(G7/F7, "")
A8: IA | B8: =SUM(SUMIF(_xlfn.ANCHORARRAY(Apr!$B$4), $A8, Apr!C$4:C$78), SUMIF(_xlfn.ANCHORARRAY(May!$B$4), $A8, May!C$4:C$78), SUMIF(_xlfn.ANCHORARRAY(Jun!$B$4), $A8, Jun!C$4:C$78)) -> 0 | C8: =SUM(SUMIF(_xlfn.ANCHORARRAY(Apr!$B$4), $A8, Apr!D$4:D$78), SUMIF(_xlfn.ANCHORARRAY(May!$B$4), $A8, May!D$4:D$78), SUMIF(_xlfn.ANCHORARRAY(Jun!$B$4), $A8, Jun!D$4:D$78)) -> 0 | D8: =IF(AND(ISNUMBER(B8),ISNUMBER(C8)), B8-C8, "") -> 0 | E8: =IFERROR(D8/C8, "") | F8: =SUM(SUMIF(_xlfn.ANCHORARRAY(Apr!$B$4), $A8, Apr!G$4:G$78), SUMIF(_xlfn.ANCHORARRAY(May!$B$4), $A8, May!G$4:G$78), SUMIF(_xlfn.ANCHORARRAY(Jun!$B$4), $A8, Jun!G$4:G$78)) -> 0 | G8: =IF(AND(ISNUMBER(B8),ISNUMBER(F8)), B8-F8, "") -> 0 | H8: =IFERROR(G8/F8, "")
A9: NC | B9: =SUM(SUMIF(_xlfn.ANCHORARRAY(Apr!$B$4), $A9, Apr!C$4:C$78), SUMIF(_xlfn.ANCHORARRAY(May!$B$4), $A9, May!C$4:C$78), SUMIF(_xlfn.ANCHORARRAY(Jun!$B$4), $A9, Jun!C$4:C$78)) -> 0 | C9: =SUM(SUMIF(_xlfn.ANCHORARRAY(Apr!$B$4), $A9, Apr!D$4:D$78), SUMIF(_xlfn.ANCHORARRAY(May!$B$4), $A9, May!D$4:D$78), SUMIF(_xlfn.ANCHORARRAY(Jun!$B$4), $A9, Jun!D$4:D$78)) -> 0 | D9: =IF(AND(ISNUMBER(B9),ISNUMBER(C9)), B9-C9, "") -> 0 | E9: =IFERROR(D9/C9, "") | F9: =SUM(SUMIF(_xlfn.ANCHORARRAY(Apr!$B$4), $A9, Apr!G$4:G$78), SUMIF(_xlfn.ANCHORARRAY(May!$B$4), $A9, May!G$4:G$78), SUMIF(_xlfn.ANCHORARRAY(Jun!$B$4), $A9, Jun!G$4:G$78)) -> 0 | G9: =IF(AND(ISNUMBER(B9),ISNUMBER(F9)), B9-F9, "") -> 0 | H9: =IFERROR(G9/F9, "")
A10: NJ | B10: =SUM(SUMIF(_xlfn.ANCHORARRAY(Apr!$B$4), $A10, Apr!C$4:C$78), SUMIF(_xlfn.ANCHORARRAY(May!$B$4), $A10, May!C$4:C$78), SUMIF(_xlfn.ANCHORARRAY(Jun!$B$4), $A10, Jun!C$4:C$78)) -> 0 | C10: =SUM(SUMIF(_xlfn.ANCHORARRAY(Apr!$B$4), $A10, Apr!D$4:D$78), SUMIF(_xlfn.ANCHORARRAY(May!$B$4), $A10, May!D$4:D$78), SUMIF(_xlfn.ANCHORARRAY(Jun!$B$4), $A10, Jun!D$4:D$78)) -> 0 | D10: =IF(AND(ISNUMBER(B10),ISNUMBER(C10)), B10-C10, "") -> 0 | E10: =IFERROR(D10/C10, "") | F10: =SUM(SUMIF(_xlfn.ANCHORARRAY(Apr!$B$4), $A10, Apr!G$4:G$78), SUMIF(_xlfn.ANCHORARRAY(May!$B$4), $A10, May!G$4:G$78), SUMIF(_xlfn.ANCHORARRAY(Jun!$B$4), $A10, Jun!G$4:G$78)) -> 0 | G10: =IF(AND(ISNUMBER(B10),ISNUMBER(F10)), B10-F10, "") -> 0 | H10: =IFERROR(G10/F10, "")
A11: TX | B11: =SUM(SUMIF(_xlfn.ANCHORARRAY(Apr!$B$4), $A11, Apr!C$4:C$78), SUMIF(_xlfn.ANCHORARRAY(May!$B$4), $A11, May!C$4:C$78), SUMIF(_xlfn.ANCHORARRAY(Jun!$B$4), $A11, Jun!C$4:C$78)) -> 0 | C11: =SUM(SUMIF(_xlfn.ANCHORARRAY(Apr!$B$4), $A11, Apr!D$4:D$78), SUMIF(_xlfn.ANCHORARRAY(May!$B$4), $A11, May!D$4:D$78), SUMIF(_xlfn.ANCHORARRAY(Jun!$B$4), $A11, Jun!D$4:D$78)) -> 0 | D11: =IF(AND(ISNUMBER(B11),ISNUMBER(C11)), B11-C11, "") -> 0 | E11: =IFERROR(D11/C11, "") | F11: =SUM(SUMIF(_xlfn.ANCHORARRAY(Apr!$B$4), $A11, Apr!G$4:G$78), SUMIF(_xlfn.ANCHORARRAY(May!$B$4), $A11, May!G$4:G$78), SUMIF(_xlfn.ANCHORARRAY(Jun!$B$4), $A11, Jun!G$4:G$78)) -> 0 | G11: =IF(AND(ISNUMBER(B11),ISNUMBER(F11)), B11-F11, "") -> 0 | H11: =IFERROR(G11/F11, "")

Sheet 3rd Qtr
A1: {=portfolio} -> Wells Fargo | C1: 3rd Quarter Actual v. Expected | F1: 3rd Quarter Actual v. Forecasted
A2: Total | B2: =SUM(B4:B90) -> 0 | C2: =SUM(C4:C90) -> 0 | D2: =B2-C2 -> 0 | E2: =IFERROR(D2/C2, 0) -> 0 | F2: =SUM(F4:F90) -> 0 | G2: =B2-F2 -> 0 | H2: =IFERROR(G2/F2, 0) -> 0
A3: State | B3: Actual | C3: Expected | D3: Delta | E3: % | F3: Forecasted | G3: Delta | H3: %
A4: {=_xlfn.UNIQUE(Sites[State])} -> CA | B4: =SUM(SUMIF(_xlfn.ANCHORARRAY(Jul!$B$4), $A4, Jul!C$4:C$78), SUMIF(_xlfn.ANCHORARRAY(Aug!$B$4), $A4, Aug!C$4:C$78), SUMIF(_xlfn.ANCHORARRAY(Sep!$B$4), $A4, Sep!C$4:C$78)) -> 0 | C4: =SUM(SUMIF(_xlfn.ANCHORARRAY(Jul!$B$4), $A4, Jul!D$4:D$78), SUMIF(_xlfn.ANCHORARRAY(Aug!$B$4), $A4, Aug!D$4:D$78), SUMIF(_xlfn.ANCHORARRAY(Sep!$B$4), $A4, Sep!D$4:D$78)) -> 0 | D4: =IF(AND(ISNUMBER(B4),ISNUMBER(C4)), B4-C4, "") -> 0 | E4: =IFERROR(D4/C4, "") | F4: =SUM(SUMIF(_xlfn.ANCHORARRAY(Jul!$B$4), $A4, Jul!G$4:G$78), SUMIF(_xlfn.ANCHORARRAY(Aug!$B$4), $A4, Aug!G$4:G$78), SUMIF(_xlfn.ANCHORARRAY(Sep!$B$4), $A4, Sep!G$4:G$78)) -> 0 | G4: =IF(AND(ISNUMBER(B4),ISNUMBER(F4)), B4-F4, "") -> 0 | H4: =IFERROR(G4/F4, "")
A5: CO | B5: =SUM(SUMIF(_xlfn.ANCHORARRAY(Jul!$B$4), $A5, Jul!C$4:C$78), SUMIF(_xlfn.ANCHORARRAY(Aug!$B$4), $A5, Aug!C$4:C$78), SUMIF(_xlfn.ANCHORARRAY(Sep!$B$4), $A5, Sep!C$4:C$78)) -> 0 | C5: =SUM(SUMIF(_xlfn.ANCHORARRAY(Jul!$B$4), $A5, Jul!D$4:D$78), SUMIF(_xlfn.ANCHORARRAY(Aug!$B$4), $A5, Aug!D$4:D$78), SUMIF(_xlfn.ANCHORARRAY(Sep!$B$4), $A5, Sep!D$4:D$78)) -> 0 | D5: =IF(AND(ISNUMBER(B5),ISNUMBER(C5)), B5-C5, "") -> 0 | E5: =IFERROR(D5/C5, "") | F5: =SUM(SUMIF(_xlfn.ANCHORARRAY(Jul!$B$4), $A5, Jul!G$4:G$78), SUMIF(_xlfn.ANCHORARRAY(Aug!$B$4), $A5, Aug!G$4:G$78), SUMIF(_xlfn.ANCHORARRAY(Sep!$B$4), $A5, Sep!G$4:G$78)) -> 0 | G5: =IF(AND(ISNUMBER(B5),ISNUMBER(F5)), B5-F5, "") -> 0 | H5: =IFERROR(G5/F5, "")
A6: CT | B6: =SUM(SUMIF(_xlfn.ANCHORARRAY(Jul!$B$4), $A6, Jul!C$4:C$78), SUMIF(_xlfn.ANCHORARRAY(Aug!$B$4), $A6, Aug!C$4:C$78), SUMIF(_xlfn.ANCHORARRAY(Sep!$B$4), $A6, Sep!C$4:C$78)) -> 0 | C6: =SUM(SUMIF(_xlfn.ANCHORARRAY(Jul!$B$4), $A6, Jul!D$4:D$78), SUMIF(_xlfn.ANCHORARRAY(Aug!$B$4), $A6, Aug!D$4:D$78), SUMIF(_xlfn.ANCHORARRAY(Sep!$B$4), $A6, Sep!D$4:D$78)) -> 0 | D6: =IF(AND(ISNUMBER(B6),ISNUMBER(C6)), B6-C6, "") -> 0 | E6: =IFERROR(D6/C6, "") | F6: =SUM(SUMIF(_xlfn.ANCHORARRAY(Jul!$B$4), $A6, Jul!G$4:G$78), SUMIF(_xlfn.ANCHORARRAY(Aug!$B$4), $A6, Aug!G$4:G$78), SUMIF(_xlfn.ANCHORARRAY(Sep!$B$4), $A6, Sep!G$4:G$78)) -> 0 | G6: =IF(AND(ISNUMBER(B6),ISNUMBER(F6)), B6-F6, "") -> 0 | H6: =IFERROR(G6/F6, "")
A7: FL | B7: =SUM(SUMIF(_xlfn.ANCHORARRAY(Jul!$B$4), $A7, Jul!C$4:C$78), SUMIF(_xlfn.ANCHORARRAY(Aug!$B$4), $A7, Aug!C$4:C$78), SUMIF(_xlfn.ANCHORARRAY(Sep!$B$4), $A7, Sep!C$4:C$78)) -> 0 | C7: =SUM(SUMIF(_xlfn.ANCHORARRAY(Jul!$B$4), $A7, Jul!D$4:D$78), SUMIF(_xlfn.ANCHORARRAY(Aug!$B$4), $A7, Aug!D$4:D$78), SUMIF(_xlfn.ANCHORARRAY(Sep!$B$4), $A7, Sep!D$4:D$78)) -> 0 | D7: =IF(AND(ISNUMBER(B7),ISNUMBER(C7)), B7-C7, "") -> 0 | E7: =IFERROR(D7/C7, "") | F7: =SUM(SUMIF(_xlfn.ANCHORARRAY(Jul!$B$4), $A7, Jul!G$4:G$78), SUMIF(_xlfn.ANCHORARRAY(Aug!$B$4), $A7, Aug!G$4:G$78), SUMIF(_xlfn.ANCHORARRAY(Sep!$B$4), $A7, Sep!G$4:G$78)) -> 0 | G7: =IF(AND(ISNUMBER(B7),ISNUMBER(F7)), B7-F7, "") -> 0 | H7: =IFERROR(G7/F7, "")
A8: IA | B8: =SUM(SUMIF(_xlfn.ANCHORARRAY(Jul!$B$4), $A8, Jul!C$4:C$78), SUMIF(_xlfn.ANCHORARRAY(Aug!$B$4), $A8, Aug!C$4:C$78), SUMIF(_xlfn.ANCHORARRAY(Sep!$B$4), $A8, Sep!C$4:C$78)) -> 0 | C8: =SUM(SUMIF(_xlfn.ANCHORARRAY(Jul!$B$4), $A8, Jul!D$4:D$78), SUMIF(_xlfn.ANCHORARRAY(Aug!$B$4), $A8, Aug!D$4:D$78), SUMIF(_xlfn.ANCHORARRAY(Sep!$B$4), $A8, Sep!D$4:D$78)) -> 0 | D8: =IF(AND(ISNUMBER(B8),ISNUMBER(C8)), B8-C8, "") -> 0 | E8: =IFERROR(D8/C8, "") | F8: =SUM(SUMIF(_xlfn.ANCHORARRAY(Jul!$B$4), $A8, Jul!G$4:G$78), SUMIF(_xlfn.ANCHORARRAY(Aug!$B$4), $A8, Aug!G$4:G$78), SUMIF(_xlfn.ANCHORARRAY(Sep!$B$4), $A8, Sep!G$4:G$78)) -> 0 | G8: =IF(AND(ISNUMBER(B8),ISNUMBER(F8)), B8-F8, "") -> 0 | H8: =IFERROR(G8/F8, "")
A9: NC | B9: =SUM(SUMIF(_xlfn.ANCHORARRAY(Jul!$B$4), $A9, Jul!C$4:C$78), SUMIF(_xlfn.ANCHORARRAY(Aug!$B$4), $A9, Aug!C$4:C$78), SUMIF(_xlfn.ANCHORARRAY(Sep!$B$4), $A9, Sep!C$4:C$78)) -> 0 | C9: =SUM(SUMIF(_xlfn.ANCHORARRAY(Jul!$B$4), $A9, Jul!D$4:D$78), SUMIF(_xlfn.ANCHORARRAY(Aug!$B$4), $A9, Aug!D$4:D$78), SUMIF(_xlfn.ANCHORARRAY(Sep!$B$4), $A9, Sep!D$4:D$78)) -> 0 | D9: =IF(AND(ISNUMBER(B9),ISNUMBER(C9)), B9-C9, "") -> 0 | E9: =IFERROR(D9/C9, "") | F9: =SUM(SUMIF(_xlfn.ANCHORARRAY(Jul!$B$4), $A9, Jul!G$4:G$78), SUMIF(_xlfn.ANCHORARRAY(Aug!$B$4), $A9, Aug!G$4:G$78), SUMIF(_xlfn.ANCHORARRAY(Sep!$B$4), $A9, Sep!G$4:G$78)) -> 0 | G9: =IF(AND(ISNUMBER(B9),ISNUMBER(F9)), B9-F9, "") -> 0 | H9: =IFERROR(G9/F9, "")
A10: NJ | B10: =SUM(SUMIF(_xlfn.ANCHORARRAY(Jul!$B$4), $A10, Jul!C$4:C$78), SUMIF(_xlfn.ANCHORARRAY(Aug!$B$4), $A10, Aug!C$4:C$78), SUMIF(_xlfn.ANCHORARRAY(Sep!$B$4), $A10, Sep!C$4:C$78)) -> 0 | C10: =SUM(SUMIF(_xlfn.ANCHORARRAY(Jul!$B$4), $A10, Jul!D$4:D$78), SUMIF(_xlfn.ANCHORARRAY(Aug!$B$4), $A10, Aug!D$4:D$78), SUMIF(_xlfn.ANCHORARRAY(Sep!$B$4), $A10, Sep!D$4:D$78)) -> 0 | D10: =IF(AND(ISNUMBER(B10),ISNUMBER(C10)), B10-C10, "") -> 0 | E10: =IFERROR(D10/C10, "") | F10: =SUM(SUMIF(_xlfn.ANCHORARRAY(Jul!$B$4), $A10, Jul!G$4:G$78), SUMIF(_xlfn.ANCHORARRAY(Aug!$B$4), $A10, Aug!G$4:G$78), SUMIF(_xlfn.ANCHORARRAY(Sep!$B$4), $A10, Sep!G$4:G$78)) -> 0 | G10: =IF(AND(ISNUMBER(B10),ISNUMBER(F10)), B10-F10, "") -> 0 | H10: =IFERROR(G10/F10, "")
A11: TX | B11: =SUM(SUMIF(_xlfn.ANCHORARRAY(Jul!$B$4), $A11, Jul!C$4:C$78), SUMIF(_xlfn.ANCHORARRAY(Aug!$B$4), $A11, Aug!C$4:C$78), SUMIF(_xlfn.ANCHORARRAY(Sep!$B$4), $A11, Sep!C$4:C$78)) -> 0 | C11: =SUM(SUMIF(_xlfn.ANCHORARRAY(Jul!$B$4), $A11, Jul!D$4:D$78), SUMIF(_xlfn.ANCHORARRAY(Aug!$B$4), $A11, Aug!D$4:D$78), SUMIF(_xlfn.ANCHORARRAY(Sep!$B$4), $A11, Sep!D$4:D$78)) -> 0 | D11: =IF(AND(ISNUMBER(B11),ISNUMBER(C11)), B11-C11, "") -> 0 | E11: =IFERROR(D11/C11, "") | F11: =SUM(SUMIF(_xlfn.ANCHORARRAY(Jul!$B$4), $A11, Jul!G$4:G$78), SUMIF(_xlfn.ANCHORARRAY(Aug!$B$4), $A11, Aug!G$4:G$78), SUMIF(_xlfn.ANCHORARRAY(Sep!$B$4), $A11, Sep!G$4:G$78)) -> 0 | G11: =IF(AND(ISNUMBER(B11),ISNUMBER(F11)), B11-F11, "") -> 0 | H11: =IFERROR(G11/F11, "")

Sheet 4th Qtr
A1: {=portfolio} -> Wells Fargo | C1: 4th Quarter Actual v. Expected | F1: 4th Quarter Actual v. Forecasted
A2: Total | B2: =SUM(B4:B90) -> 0 | C2: =SUM(C4:C90) -> 0 | D2: =B2-C2 -> 0 | E2: =IFERROR(D2/C2, 0) -> 0 | F2: =SUM(F4:F90) -> 0 | G2: =B2-F2 -> 0 | H2: =IFERROR(G2/F2, 0) -> 0
A3: State | B3: Actual | C3: Expected | D3: Delta | E3: % | F3: Forecasted | G3: Delta | H3: %
A4: {=_xlfn.UNIQUE(Sites[State])} -> CA | B4: =SUM(SUMIF(_xlfn.ANCHORARRAY(Oct!$B$4), $A4, Oct!C$4:C$78), SUMIF(_xlfn.ANCHORARRAY(Nov!$B$4), $A4, Nov!C$4:C$78), SUMIF(_xlfn.ANCHORARRAY(Dec!$B$4), $A4, Dec!C$4:C$78)) -> 0 | C4: =SUM(SUMIF(_xlfn.ANCHORARRAY(Oct!$B$4), $A4, Oct!D$4:D$78), SUMIF(_xlfn.ANCHORARRAY(Nov!$B$4), $A4, Nov!D$4:D$78), SUMIF(_xlfn.ANCHORARRAY(Dec!$B$4), $A4, Dec!D$4:D$78)) -> 0 | D4: =IF(AND(ISNUMBER(B4),ISNUMBER(C4)), B4-C4, "") -> 0 | E4: =IFERROR(D4/C4, "") | F4: =SUM(SUMIF(_xlfn.ANCHORARRAY(Oct!$B$4), $A4, Oct!G$4:G$78), SUMIF(_xlfn.ANCHORARRAY(Nov!$B$4), $A4, Nov!G$4:G$78), SUMIF(_xlfn.ANCHORARRAY(Dec!$B$4), $A4, Dec!G$4:G$78)) -> 0 | G4: =IF(AND(ISNUMBER(B4),ISNUMBER(F4)), B4-F4, "") -> 0 | H4: =IFERROR(G4/F4, "")
A5: CO | B5: =SUM(SUMIF(_xlfn.ANCHORARRAY(Oct!$B$4), $A5, Oct!C$4:C$78), SUMIF(_xlfn.ANCHORARRAY(Nov!$B$4), $A5, Nov!C$4:C$78), SUMIF(_xlfn.ANCHORARRAY(Dec!$B$4), $A5, Dec!C$4:C$78)) -> 0 | C5: =SUM(SUMIF(_xlfn.ANCHORARRAY(Oct!$B$4), $A5, Oct!D$4:D$78), SUMIF(_xlfn.ANCHORARRAY(Nov!$B$4), $A5, Nov!D$4:D$78), SUMIF(_xlfn.ANCHORARRAY(Dec!$B$4), $A5, Dec!D$4:D$78)) -> 0 | D5: =IF(AND(ISNUMBER(B5),ISNUMBER(C5)), B5-C5, "") -> 0 | E5: =IFERROR(D5/C5, "") | F5: =SUM(SUMIF(_xlfn.ANCHORARRAY(Oct!$B$4), $A5, Oct!G$4:G$78), SUMIF(_xlfn.ANCHORARRAY(Nov!$B$4), $A5, Nov!G$4:G$78), SUMIF(_xlfn.ANCHORARRAY(Dec!$B$4), $A5, Dec!G$4:G$78)) -> 0 | G5: =IF(AND(ISNUMBER(B5),ISNUMBER(F5)), B5-F5, "") -> 0 | H5: =IFERROR(G5/F5, "")
A6: CT | B6: =SUM(SUMIF(_xlfn.ANCHORARRAY(Oct!$B$4), $A6, Oct!C$4:C$78), SUMIF(_xlfn.ANCHORARRAY(Nov!$B$4), $A6, Nov!C$4:C$78), SUMIF(_xlfn.ANCHORARRAY(Dec!$B$4), $A6, Dec!C$4:C$78)) -> 0 | C6: =SUM(SUMIF(_xlfn.ANCHORARRAY(Oct!$B$4), $A6, Oct!D$4:D$78), SUMIF(_xlfn.ANCHORARRAY(Nov!$B$4), $A6, Nov!D$4:D$78), SUMIF(_xlfn.ANCHORARRAY(Dec!$B$4), $A6, Dec!D$4:D$78)) -> 0 | D6: =IF(AND(ISNUMBER(B6),ISNUMBER(C6)), B6-C6, "") -> 0 | E6: =IFERROR(D6/C6, "") | F6: =SUM(SUMIF(_xlfn.ANCHORARRAY(Oct!$B$4), $A6, Oct!G$4:G$78), SUMIF(_xlfn.ANCHORARRAY(Nov!$B$4), $A6, Nov!G$4:G$78), SUMIF(_xlfn.ANCHORARRAY(Dec!$B$4), $A6, Dec!G$4:G$78)) -> 0 | G6: =IF(AND(ISNUMBER(B6),ISNUMBER(F6)), B6-F6, "") -> 0 | H6: =IFERROR(G6/F6, "")
A7: FL | B7: =SUM(SUMIF(_xlfn.ANCHORARRAY(Oct!$B$4), $A7, Oct!C$4:C$78), SUMIF(_xlfn.ANCHORARRAY(Nov!$B$4), $A7, Nov!C$4:C$78), SUMIF(_xlfn.ANCHORARRAY(Dec!$B$4), $A7, Dec!C$4:C$78)) -> 0 | C7: =SUM(SUMIF(_xlfn.ANCHORARRAY(Oct!$B$4), $A7, Oct!D$4:D$78), SUMIF(_xlfn.ANCHORARRAY(Nov!$B$4), $A7, Nov!D$4:D$78), SUMIF(_xlfn.ANCHORARRAY(Dec!$B$4), $A7, Dec!D$4:D$78)) -> 0 | D7: =IF(AND(ISNUMBER(B7),ISNUMBER(C7)), B7-C7, "") -> 0 | E7: =IFERROR(D7/C7, "") | F7: =SUM(SUMIF(_xlfn.ANCHORARRAY(Oct!$B$4), $A7, Oct!G$4:G$78), SUMIF(_xlfn.ANCHORARRAY(Nov!$B$4), $A7, Nov!G$4:G$78), SUMIF(_xlfn.ANCHORARRAY(Dec!$B$4), $A7, Dec!G$4:G$78)) -> 0 | G7: =IF(AND(ISNUMBER(B7),ISNUMBER(F7)), B7-F7, "") -> 0 | H7: =IFERROR(G7/F7, "")
A8: IA | B8: =SUM(SUMIF(_xlfn.ANCHORARRAY(Oct!$B$4), $A8, Oct!C$4:C$78), SUMIF(_xlfn.ANCHORARRAY(Nov!$B$4), $A8, Nov!C$4:C$78), SUMIF(_xlfn.ANCHORARRAY(Dec!$B$4), $A8, Dec!C$4:C$78)) -> 0 | C8: =SUM(SUMIF(_xlfn.ANCHORARRAY(Oct!$B$4), $A8, Oct!D$4:D$78), SUMIF(_xlfn.ANCHORARRAY(Nov!$B$4), $A8, Nov!D$4:D$78), SUMIF(_xlfn.ANCHORARRAY(Dec!$B$4), $A8, Dec!D$4:D$78)) -> 0 | D8: =IF(AND(ISNUMBER(B8),ISNUMBER(C8)), B8-C8, "") -> 0 | E8: =IFERROR(D8/C8, "") | F8: =SUM(SUMIF(_xlfn.ANCHORARRAY(Oct!$B$4), $A8, Oct!G$4:G$78), SUMIF(_xlfn.ANCHORARRAY(Nov!$B$4), $A8, Nov!G$4:G$78), SUMIF(_xlfn.ANCHORARRAY(Dec!$B$4), $A8, Dec!G$4:G$78)) -> 0 | G8: =IF(AND(ISNUMBER(B8),ISNUMBER(F8)), B8-F8, "") -> 0 | H8: =IFERROR(G8/F8, "")
A9: NC | B9: =SUM(SUMIF(_xlfn.ANCHORARRAY(Oct!$B$4), $A9, Oct!C$4:C$78), SUMIF(_xlfn.ANCHORARRAY(Nov!$B$4), $A9, Nov!C$4:C$78), SUMIF(_xlfn.ANCHORARRAY(Dec!$B$4), $A9, Dec!C$4:C$78)) -> 0 | C9: =SUM(SUMIF(_xlfn.ANCHORARRAY(Oct!$B$4), $A9, Oct!D$4:D$78), SUMIF(_xlfn.ANCHORARRAY(Nov!$B$4), $A9, Nov!D$4:D$78), SUMIF(_xlfn.ANCHORARRAY(Dec!$B$4), $A9, Dec!D$4:D$78)) -> 0 | D9: =IF(AND(ISNUMBER(B9),ISNUMBER(C9)), B9-C9, "") -> 0 | E9: =IFERROR(D9/C9, "") | F9: =SUM(SUMIF(_xlfn.ANCHORARRAY(Oct!$B$4), $A9, Oct!G$4:G$78), SUMIF(_xlfn.ANCHORARRAY(Nov!$B$4), $A9, Nov!G$4:G$78), SUMIF(_xlfn.ANCHORARRAY(Dec!$B$4), $A9, Dec!G$4:G$78)) -> 0 | G9: =IF(AND(ISNUMBER(B9),ISNUMBER(F9)), B9-F9, "") -> 0 | H9: =IFERROR(G9/F9, "")
A10: NJ | B10: =SUM(SUMIF(_xlfn.ANCHORARRAY(Oct!$B$4), $A10, Oct!C$4:C$78), SUMIF(_xlfn.ANCHORARRAY(Nov!$B$4), $A10, Nov!C$4:C$78), SUMIF(_xlfn.ANCHORARRAY(Dec!$B$4), $A10, Dec!C$4:C$78)) -> 0 | C10: =SUM(SUMIF(_xlfn.ANCHORARRAY(Oct!$B$4), $A10, Oct!D$4:D$78), SUMIF(_xlfn.ANCHORARRAY(Nov!$B$4), $A10, Nov!D$4:D$78), SUMIF(_xlfn.ANCHORARRAY(Dec!$B$4), $A10, Dec!D$4:D$78)) -> 0 | D10: =IF(AND(ISNUMBER(B10),ISNUMBER(C10)), B10-C10, "") -> 0 | E10: =IFERROR(D10/C10, "") | F10: =SUM(SUMIF(_xlfn.ANCHORARRAY(Oct!$B$4), $A10, Oct!G$4:G$78), SUMIF(_xlfn.ANCHORARRAY(Nov!$B$4), $A10, Nov!G$4:G$78), SUMIF(_xlfn.ANCHORARRAY(Dec!$B$4), $A10, Dec!G$4:G$78)) -> 0 | G10: =IF(AND(ISNUMBER(B10),ISNUMBER(F10)), B10-F10, "") -> 0 | H10: =IFERROR(G10/F10, "")
A11: TX | B11: =SUM(SUMIF(_xlfn.ANCHORARRAY(Oct!$B$4), $A11, Oct!C$4:C$78), SUMIF(_xlfn.ANCHORARRAY(Nov!$B$4), $A11, Nov!C$4:C$78), SUMIF(_xlfn.ANCHORARRAY(Dec!$B$4), $A11, Dec!C$4:C$78)) -> 0 | C11: =SUM(SUMIF(_xlfn.ANCHORARRAY(Oct!$B$4), $A11, Oct!D$4:D$78), SUMIF(_xlfn.ANCHORARRAY(Nov!$B$4), $A11, Nov!D$4:D$78), SUMIF(_xlfn.ANCHORARRAY(Dec!$B$4), $A11, Dec!D$4:D$78)) -> 0 | D11: =IF(AND(ISNUMBER(B11),ISNUMBER(C11)), B11-C11, "") -> 0 | E11: =IFERROR(D11/C11, "") | F11: =SUM(SUMIF(_xlfn.ANCHORARRAY(Oct!$B$4), $A11, Oct!G$4:G$78), SUMIF(_xlfn.ANCHORARRAY(Nov!$B$4), $A11, Nov!G$4:G$78), SUMIF(_xlfn.ANCHORARRAY(Dec!$B$4), $A11, Dec!G$4:G$78)) -> 0 | G11: =IF(AND(ISNUMBER(B11),ISNUMBER(F11)), B11-F11, "") -> 0 | H11: =IFERROR(G11/F11, "")

Sheet Jan
A1: {=portfolio} -> Wells Fargo | D1: January Actual v. Expected | G1: January Actual v. Forecasted
A2: Total | C2: =SUM(C4:C65) -> 434853.64 | D2: =SUM(D4:D65) -> 405850.93 | E2: =C2-D2 -> 29002.709 | F2: =IFERROR(E2/D2, 0) -> 0.071461482 | G2: =SUM(G4:G65) -> 698800.05 | H2: =C2-G2 -> -263946.41 | I2: =IFERROR(H2/G2, 0) -> -0.37771379 | J2: =IF(AND(TODAY()>DATE(2024, 1, 1), COUNTA(Sites[Site])<>(COUNT(C:C)-1)), "Some sites are missing actual data; if new sites were added, make sure they are aligned correctly (including prior months!)", "")
A3: Site | B3: State | C3: Actual | D3: Expected | E3: Delta | F3: % | G3: Forecasted | H3: Delta | I3: % | J3: Notes | K3: Service Requests
A4: {=Sites[Site]} -> Adams & Broadway | B4: {=Sites[State]} -> CA | C4: 668.5 | D4: 0 | E4: =IF(AND(ISNUMBER(C4),ISNUMBER(D4)), C4-D4, "") -> 668.5 | F4: =IFERROR(E4/D4, "") | G4: 660.258 | H4: =IF(AND(ISNUMBER(C4),ISNUMBER(G4)), C4-G4, "") -> 8.242 | I4: =IFERROR(H4/G4, "") -> 0.012482999
A5: Otay Mesa | B5: CA | C5: 37.789 | D5: 0 | E5: =IF(AND(ISNUMBER(C5),ISNUMBER(D5)), C5-D5, "") -> 37.789 | F5: =IFERROR(E5/D5, "") | G5: 0 | H5: =IF(AND(ISNUMBER(C5),ISNUMBER(G5)), C5-G5, "") -> 37.789 | I5: =IFERROR(H5/G5, "")
A6: San Leandro | B6: CA | C6: 18587.375 | D6: 25565.67 | E6: =IF(AND(ISNUMBER(C6),ISNUMBER(D6)), C6-D6, "") -> -6978.295 | F6: =IFERROR(E6/D6, "") -> -0.27295569 | G6: 22910.168 | H6: =IF(AND(ISNUMBER(C6),ISNUMBER(G6)), C6-G6, "") -> -4322.793 | I6: =IFERROR(H6/G6, "") -> -0.18868447 | J6: 1. Inverter 4 was replaced on 01/31 | K6: 1. SR079901
A7: Van Nuys | B7: CA | C7: 1267.6979 | D7: 0 | E7: =IF(AND(ISNUMBER(C7),ISNUMBER(D7)), C7-D7, "") -> 1267.6979 | F7: =IFERROR(E7/D7, "") | G7: 1339.747 | H7: =IF(AND(ISNUMBER(C7),ISNUMBER(G7)), C7-G7, "") -> -72.049072 | I7: =IFERROR(H7/G7, "") -> -0.053778118
A8: 98th & Grant | B8: CO | C8: 724.2 | D8: 0 | E8: =IF(AND(ISNUMBER(C8),ISNUMBER(D8)), C8-D8, "") -> 724.2 | F8: =IFERROR(E8/D8, "") | G8: 1165.016 | H8: =IF(AND(ISNUMBER(C8),ISNUMBER(G8)), C8-G8, "") -> -440.816 | I8: =IFERROR(H8/G8, "") -> -0.37837764
A9: Arapahoe Crossings | B9: CO | C9: 2121.2004 | D9: 0 | E9: =IF(AND(ISNUMBER(C9),ISNUMBER(D9)), C9-D9, "") -> 2121.2004 | F9: =IFERROR(E9/D9, "") | G9: 2132.967 | H9: =IF(AND(ISNUMBER(C9),ISNUMBER(G9)), C9-G9, "") -> -11.766622 | I9: =IFERROR(H9/G9, "") -> -0.0055165513
A10: Aurora City Center | B10: CO | C10: 1077.5 | D10: 0 | E10: =IF(AND(ISNUMBER(C10),ISNUMBER(D10)), C10-D10, "") -> 1077.5 | F10: =IFERROR(E10/D10, "") | G10: 1040.516 | H10: =IF(AND(ISNUMBER(C10),ISNUMBER(G10)), C10-G10, "") -> 36.984 | I10: =IFERROR(H10/G10, "") -> 0.035543903
A11: Dry Creek | B11: CO | C11: -0.40201212 | D11: 0 | E11: =IF(AND(ISNUMBER(C11),ISNUMBER(D11)), C11-D11, "") -> -0.40201212 | F11: =IFERROR(E11/D11, "") | G11: 1258.016 | H11: =IF(AND(ISNUMBER(C11),ISNUMBER(G11)), C11-G11, "") -> -1258.418 | I11: =IFERROR(H11/G11, "") -> -1.0003196 | J11: 1. Site is offline from 05/12/2023 | K11: 1. SR078942
A12: Highlands Ranch S. | B12: CO | C12: 1000.7 | D12: 0 | E12: =IF(AND(ISNUMBER(C12),ISNUMBER(D12)), C12-D12, "") -> 1000.7 | F12: =IFERROR(E12/D12, "") | G12: 1110.774 | H12: =IF(AND(ISNUMBER(C12),ISNUMBER(G12)), C12-G12, "") -> -110.074 | I12: =IFERROR(H12/G12, "") -> -0.099096666
A13: Lone Tree | B13: CO | C13: 2395.4 | D13: 0 | E13: =IF(AND(ISNUMBER(C13),ISNUMBER(D13)), C13-D13, "") -> 2395.4 | F13: =IFERROR(E13/D13, "") | G13: 2590.419 | H13: =IF(AND(ISNUMBER(C13),ISNUMBER(G13)), C13-G13, "") -> -195.019 | I13: =IFERROR(H13/G13, "") -> -0.075284732
A14: Meridian | B14: CO | C14: 1646.1 | D14: 0 | E14: =IF(AND(ISNUMBER(C14),ISNUMBER(D14)), C14-D14, "") -> 1646.1 | F14: =IFERROR(E14/D14, "") | G14: 1355.097 | H14: =IF(AND(ISNUMBER(C14),ISNUMBER(G14)), C14-G14, "") -> 291.003 | I14: =IFERROR(H14/G14, "") -> 0.21474699
A15: Southglenn | B15: CO | C15: 1513 | D15: 0 | E15: =IF(AND(ISNUMBER(C15),ISNUMBER(D15)), C15-D15, "") -> 1513 | F15: =IFERROR(E15/D15, "") | G15: 1611.403 | H15: =IF(AND(ISNUMBER(C15),ISNUMBER(G15)), C15-G15, "") -> -98.403 | I15: =IFERROR(H15/G15, "") -> -0.061066661
A16: Standley Lake | B16: CO | C16: 2051.1 | D16: 0 | E16: =IF(AND(ISNUMBER(C16),ISNUMBER(D16)), C16-D16, "") -> 2051.1 | F16: =IFERROR(E16/D16, "") | G16: 2170.403 | H16: =IF(AND(ISNUMBER(C16),ISNUMBER(G16)), C16-G16, "") -> -119.303 | I16: =IFERROR(H16/G16, "") -> -0.054968133
A17: Havana Gardens | B17: CO | C17: 1739.8 | D17: 0 | E17: =IF(AND(ISNUMBER(C17),ISNUMBER(D17)), C17-D17, "") -> 1739.8 | F17: =IFERROR(E17/D17, "") | G17: 846.258 | H17: =IF(AND(ISNUMBER(C17),ISNUMBER(G17)), C17-G17, "") -> 893.542 | I17: =IFERROR(H17/G17, "") -> 1.0558742 | J17: 03/01/2023 Per Kate - Do Not Pursue Weather Station
A18: East Hartford | B18: CT | C18: 119.7 | D18: 246.8964 | E18: =IF(AND(ISNUMBER(C18),ISNUMBER(D18)), C18-D18, "") -> -127.1964 | F18: =IFERROR(E18/D18, "") -> -0.51518127 | G18: 273.275 | H18: =IF(AND(ISNUMBER(C18),ISNUMBER(G18)), C18-G18, "") -> -153.575 | I18: =IFERROR(H18/G18, "") -> -0.56197969
A19: Norwalk | B19: CT | C19: 117.74058 | D19: 417.3167 | E19: =IF(AND(ISNUMBER(C19),ISNUMBER(D19)), C19-D19, "") -> -299.57612 | F19: =IFERROR(E19/D19, "") -> -0.71786277 | G19: 376.757 | H19: =IF(AND(ISNUMBER(C19),ISNUMBER(G19)), C19-G19, "") -> -259.01642 | I19: =IFERROR(H19/G19, "") -> -0.68748934
A20: Hialeah Gardens | B20: FL | C20: 1428.4985 | D20: 2582.073 | E20: =IF(AND(ISNUMBER(C20),ISNUMBER(D20)), C20-D20, "") -> -1153.5745 | F20: =IFERROR(E20/D20, "") -> -0.44676292 | G20: 3451.661 | H20: =IF(AND(ISNUMBER(C20),ISNUMBER(G20)), C20-G20, "") -> -2023.1625 | I20: =IFERROR(H20/G20, "") -> -0.58614171
A21: West Des Moines - HMHQ | B21: IA | C21: 12390.938 | D21: 16455.02 | E21: =IF(AND(ISNUMBER(C21),ISNUMBER(D21)), C21-D21, "") -> -4064.0825 | F21: =IFERROR(E21/D21, "") -> -0.24698132 | G21: 23956.604 | H21: =IF(AND(ISNUMBER(C21),ISNUMBER(G21)), C21-G21, "") -> -11565.666 | I21: =IFERROR(H21/G21, "") -> -0.48277571
A22: W. Des Moines Campus EAST | B22: IA | C22: 62192.5 | D22: 8477.248 | E22: =IF(AND(ISNUMBER(C22),ISNUMBER(D22)), C22-D22, "") -> 53715.252 | F22: =IFERROR(E22/D22, "") -> 6.3364021 | G22: 105997.32 | H22: =IF(AND(ISNUMBER(C22),ISNUMBER(G22)), C22-G22, "") -> -43804.82 | I22: =IFERROR(H22/G22, "") -> -0.41326347 | J22: 1. Expected energy was not available till 01/30 | K22: 1. SR080333
A23: W. Des Moines Campus SW | B23: IA | C23: 25312.5 | D23: 4681.486 | E23: =IF(AND(ISNUMBER(C23),ISNUMBER(D23)), C23-D23, "") -> 20631.014 | F23: =IFERROR(E23/D23, "") -> 4.406937 | G23: 55952.783 | H23: =IF(AND(ISNUMBER(C23),ISNUMBER(G23)), C23-G23, "") -> -30640.283 | I23: =IFERROR(H23/G23, "") -> -0.54760963 | J23: 1. Inverter 4 tripped offline on 01/31 2. Expected energy was not available till 01/30 | K23: 1. SR080633 2. SR080334
A24: WF - CIC | B24: NC | C24: 0 | D24: 0 | E24: =IF(AND(ISNUMBER(C24),ISNUMBER(D24)), C24-D24, "") -> 0 | F24: =IFERROR(E24/D24, "") | G24: 0 | H24: =IF(AND(ISNUMBER(C24),ISNUMBER(G24)), C24-G24, "") -> 0 | I24: =IFERROR(H24/G24, "") | J24: 1. Site de-energized 06/02/2023 due to TIGO investigation. | K24: 1. SR078172
A25: Charlotte - Wells Fargo - DUC | B25: NC | C25: 0 | D25: 0 | E25: =IF(AND(ISNUMBER(C25),ISNUMBER(D25)), C25-D25, "") -> 0 | F25: =IFERROR(E25/D25, "") | G25: 0 | H25: =IF(AND(ISNUMBER(C25),ISNUMBER(G25)), C25-G25, "") -> 0 | I25: =IFERROR(H25/G25, "") | J25: 1. Site de-energized 06/02/2023 due to TIGO investigation. | K25: 1. SR078173
A26: East Windsor | B26: NJ | C26: 234.4 | D26: 395.1954 | E26: =IF(AND(ISNUMBER(C26),ISNUMBER(D26)), C26-D26, "") -> -160.7954 | F26: =IFERROR(E26/D26, "") -> -0.40687569 | G26: 408.178 | H26: =IF(AND(ISNUMBER(C26),ISNUMBER(G26)), C26-G26, "") -> -173.778 | I26: =IFERROR(H26/G26, "") -> -0.42574073
A27: Burlington | B27: NJ | C27: 720 | D27: 848.942 | E27: =IF(AND(ISNUMBER(C27),ISNUMBER(D27)), C27-D27, "") -> -128.942 | F27: =IFERROR(E27/D27, "") -> -0.15188552 | G27: 1105.296 | H27: =IF(AND(ISNUMBER(C27),ISNUMBER(G27)), C27-G27, "") -> -385.296 | I27: =IFERROR(H27/G27, "") -> -0.34859078
A28: Bayonne | B28: NJ | C28: 792.7 | D28: 1075.812 | E28: =IF(AND(ISNUMBER(C28),ISNUMBER(D28)), C28-D28, "") -> -283.112 | F28: =IFERROR(E28/D28, "") -> -0.26316122 | G28: 2010.779 | H28: =IF(AND(ISNUMBER(C28),ISNUMBER(G28)), C28-G28, "") -> -1218.079 | I28: =IFERROR(H28/G28, "") -> -0.60577468
A29: Clifton | B29: NJ | C29: 824.29688 | D29: 1479.194 | E29: =IF(AND(ISNUMBER(C29),ISNUMBER(D29)), C29-D29, "") -> -654.89712 | F29: =IFERROR(E29/D29, "") -> -0.44273917 | G29: 2566.102 | H29: =IF(AND(ISNUMBER(C29),ISNUMBER(G29)), C29-G29, "") -> -1741.8051 | I29: =IFERROR(H29/G29, "") -> -0.6787747
A30: North Elizabeth | B30: NJ | C30: 784.1 | D30: 751.989 | E30: =IF(AND(ISNUMBER(C30),ISNUMBER(D30)), C30-D30, "") -> 32.111 | F30: =IFERROR(E30/D30, "") -> 0.042701422 | G30: 1413.128 | H30: =IF(AND(ISNUMBER(C30),ISNUMBER(G30)), C30-G30, "") -> -629.028 | I30: =IFERROR(H30/G30, "") -> -0.44513165
A31: Haddon Westmont Plaza | B31: NJ | C31: 494.2 | D31: 789.4208 | E31: =IF(AND(ISNUMBER(C31),ISNUMBER(D31)), C31-D31, "") -> -295.2208 | F31: =IFERROR(E31/D31, "") -> -0.3739714 | G31: 999.193 | H31: =IF(AND(ISNUMBER(C31),ISNUMBER(G31)), C31-G31, "") -> -504.993 | I31: =IFERROR(H31/G31, "") -> -0.50540086
A32: Parsippany | B32: NJ | C32: 583.8 | D32: 1291.575 | E32: =IF(AND(ISNUMBER(C32),ISNUMBER(D32)), C32-D32, "") -> -707.775 | F32: =IFERROR(E32/D32, "") -> -0.54799373 | G32: 1156.298 | H32: =IF(AND(ISNUMBER(C32),ISNUMBER(G32)), C32-G32, "") -> -572.498 | I32: =IFERROR(H32/G32, "") -> -0.49511285
A33: Clark | B33: NJ | C33: 559.8 | D33: 806.6296 | E33: =IF(AND(ISNUMBER(C33),ISNUMBER(D33)), C33-D33, "") -> -246.8296 | F33: =IFERROR(E33/D33, "") -> -0.30600117 | G33: 953.546 | H33: =IF(AND(ISNUMBER(C33),ISNUMBER(G33)), C33-G33, "") -> -393.746 | I33: =IFERROR(H33/G33, "") -> -0.41292816
A34: Closter | B34: NJ | C34: 144.2 | D34: 202.6485 | E34: =IF(AND(ISNUMBER(C34),ISNUMBER(D34)), C34-D34, "") -> -58.4485 | F34: =IFERROR(E34/D34, "") -> -0.28842306 | G34: 494.769 | H34: =IF(AND(ISNUMBER(C34),ISNUMBER(G34)), C34-G34, "") -> -350.569 | I34: =IFERROR(H34/G34, "") -> -0.70855086
A35: Holmdel | B35: NJ | C35: 450.3 | D35: 643.0844 | E35: =IF(AND(ISNUMBER(C35),ISNUMBER(D35)), C35-D35, "") -> -192.7844 | F35: =IFERROR(E35/D35, "") -> -0.29978087 | G35: 809.704 | H35: =IF(AND(ISNUMBER(C35),ISNUMBER(G35)), C35-G35, "") -> -359.404 | I35: =IFERROR(H35/G35, "") -> -0.44387085
A36: Ellisburg Circle Center | B36: NJ | C36: 241 | D36: 385.1902 | E36: =IF(AND(ISNUMBER(C36),ISNUMBER(D36)), C36-D36, "") -> -144.1902 | F36: =IFERROR(E36/D36, "") -> -0.37433507 | G36: 451.606 | H36: =IF(AND(ISNUMBER(C36),ISNUMBER(G36)), C36-G36, "") -> -210.606 | I36: =IFERROR(H36/G36, "") -> -0.46634899
A37: Nutley | B37: NJ | C37: 770.9 | D37: 1199.326 | E37: =IF(AND(ISNUMBER(C37),ISNUMBER(D37)), C37-D37, "") -> -428.426 | F37: =IFERROR(E37/D37, "") -> -0.35722231 | G37: 1734.511 | H37: =IF(AND(ISNUMBER(C37),ISNUMBER(G37)), C37-G37, "") -> -963.611 | I37: =IFERROR(H37/G37, "") -> -0.55555197
... A51: South Plainfield | B51: NJ | C51: 440.8 | D51: 493.0951 | E51: =IF(AND(ISNUMBER(C51),ISNUMBER(D51)), C51-D51, "") -> -52.2951 | F51: =IFERROR(E51/D51, "") -> -0.1060548 | G51: 750.996 | H51: =IF(AND(ISNUMBER(C51),ISNUMBER(G51)), C51-G51, "") -> -310.196 | I51: =IFERROR(H51/G51, "") -> -0.41304614
A52: Somerset | B52: NJ | C52: 0 | D52: 0 | E52: =IF(AND(ISNUMBER(C52),ISNUMBER(D52)), C52-D52, "") -> 0 | F52: =IFERROR(E52/D52, "") | G52: 0 | H52: =IF(AND(ISNUMBER(C52),ISNUMBER(G52)), C52-G52, "") -> 0 | I52: =IFERROR(H52/G52, "") | J52: No data available
A53: Clinton Main Relo | B53: NJ | C53: 611.73828 | D53: 1001.651 | E53: =IF(AND(ISNUMBER(C53),ISNUMBER(D53)), C53-D53, "") -> -389.91272 | F53: =IFERROR(E53/D53, "") -> -0.38927003 | G53: 1153.765 | H53: =IF(AND(ISNUMBER(C53),ISNUMBER(G53)), C53-G53, "") -> -542.02672 | I53: =IFERROR(H53/G53, "") -> -0.46978953
...

Sheet Feb
A1: {=portfolio} -> Wells Fargo | D1: February Actual v. Expected | G1: February Actual v. Forecasted
A2: Total | C2: =SUM(C4:C100) -> 650956.61 | D2: =SUM(D4:D100) -> 702151.33 | E2: =C2-D2 -> -51194.722 | F2: =IFERROR(E2/D2, 0) -> -0.072911237 | G2: =SUM(G4:G100) -> 903765.69 | H2: =C2-G2 -> -252809.08 | I2: =IFERROR(H2/G2, 0) -> -0.27972857 | J2: =IF(AND(TODAY()>DATE(2024, 2, 1), COUNTA(Sites[Site])<>(COUNT(C:C)-1)), "Some sites are missing actual data; if new sites were added, make sure they are aligned correctly (including prior months!)", "")
A3: Site | B3: State | C3: Actual | D3: Expected | E3: Delta | F3: % | G3: Forecasted | H3: Delta | I3: % | J3: Notes | K3: Service Requests
A4: {=Sites[Site]} -> Adams & Broadway | B4: {=Sites[State]} -> CA | C4: 675.2 | D4: 0 | E4: =IF(AND(ISNUMBER(C4),ISNUMBER(D4)), C4-D4, "") -> 675.2 | F4: =IFERROR(E4/D4, "") | G4: 746.37 | H4: =IF(AND(ISNUMBER(C4),ISNUMBER(G4)), C4-G4, "") -> -71.17 | I4: =IFERROR(H4/G4, "") -> -0.095354851
A5: Otay Mesa | B5: CA | C5: 0 | D5: 0 | E5: =IF(AND(ISNUMBER(C5),ISNUMBER(D5)), C5-D5, "") -> 0 | F5: =IFERROR(E5/D5, "") | G5: 0 | H5: =IF(AND(ISNUMBER(C5),ISNUMBER(G5)), C5-G5, "") -> 0 | I5: =IFERROR(H5/G5, "")
A6: San Leandro | B6: CA | C6: 27875.812 | D6: 31129.31 | E6: =IF(AND(ISNUMBER(C6),ISNUMBER(D6)), C6-D6, "") -> -3253.4975 | F6: =IFERROR(E6/D6, "") -> -0.10451557 | G6: 25298.6 | H6: =IF(AND(ISNUMBER(C6),ISNUMBER(G6)), C6-G6, "") -> 2577.2125 | I6: =IFERROR(H6/G6, "") -> 0.10187174 | J6: 1. Inverter 4 tripped offline on 02/12 and 02/24. Inverter being RMA'd | K6: 1. SR080945
A7: Van Nuys | B7: CA | C7: 1221.4997 | D7: 0 | E7: =IF(AND(ISNUMBER(C7),ISNUMBER(D7)), C7-D7, "") -> 1221.4997 | F7: =IFERROR(E7/D7, "") | G7: 1486.647 | H7: =IF(AND(ISNUMBER(C7),ISNUMBER(G7)), C7-G7, "") -> -265.14726 | I7: =IFERROR(H7/G7, "") -> -0.17835253
A8: 98th & Grant | B8: CO | C8: 884 | D8: 0 | E8: =IF(AND(ISNUMBER(C8),ISNUMBER(D8)), C8-D8, "") -> 884 | F8: =IFERROR(E8/D8, "") | G8: 1280 | H8: =IF(AND(ISNUMBER(C8),ISNUMBER(G8)), C8-G8, "") -> -396 | I8: =IFERROR(H8/G8, "") -> -0.309375
A9: Arapahoe Crossings | B9: CO | C9: 2267.1002 | D9: 0 | E9: =IF(AND(ISNUMBER(C9),ISNUMBER(D9)), C9-D9, "") -> 2267.1002 | F9: =IFERROR(E9/D9, "") | G9: 2339.458 | H9: =IF(AND(ISNUMBER(C9),ISNUMBER(G9)), C9-G9, "") -> -72.357792 | I9: =IFERROR(H9/G9, "") -> -0.030929297
A10: Aurora City Center | B10: CO | C10: 1176.7 | D10: 0 | E10: =IF(AND(ISNUMBER(C10),ISNUMBER(D10)), C10-D10, "") -> 1176.7 | F10: =IFERROR(E10/D10, "") | G10: 1140 | H10: =IF(AND(ISNUMBER(C10),ISNUMBER(G10)), C10-G10, "") -> 36.7 | I10: =IFERROR(H10/G10, "") -> 0.032192982
A11: Dry Creek | B11: CO | C11: -3.9020056 | D11: 0 | E11: =IF(AND(ISNUMBER(C11),ISNUMBER(D11)), C11-D11, "") -> -3.9020056 | F11: =IFERROR(E11/D11, "") | G11: 1386 | H11: =IF(AND(ISNUMBER(C11),ISNUMBER(G11)), C11-G11, "") -> -1389.902 | I11: =IFERROR(H11/G11, "") -> -1.0028153 | J11: 1. Site not reporting prodcution from 05/12/2023 | K11: 1. SR078942
A12: Highlands Ranch S. | B12: CO | C12: 1075.3 | D12: 0 | E12: =IF(AND(ISNUMBER(C12),ISNUMBER(D12)), C12-D12, "") -> 1075.3 | F12: =IFERROR(E12/D12, "") | G12: 1265 | H12: =IF(AND(ISNUMBER(C12),ISNUMBER(G12)), C12-G12, "") -> -189.7 | I12: =IFERROR(H12/G12, "") -> -0.14996047
A13: Lone Tree | B13: CO | C13: 1922.5 | D13: 0 | E13: =IF(AND(ISNUMBER(C13),ISNUMBER(D13)), C13-D13, "") -> 1922.5 | F13: =IFERROR(E13/D13, "") | G13: 2891 | H13: =IF(AND(ISNUMBER(C13),ISNUMBER(G13)), C13-G13, "") -> -968.5 | I13: =IFERROR(H13/G13, "") -> -0.33500519
A14: Meridian | B14: CO | C14: 1964.8 | D14: 0 | E14: =IF(AND(ISNUMBER(C14),ISNUMBER(D14)), C14-D14, "") -> 1964.8 | F14: =IFERROR(E14/D14, "") | G14: 1699 | H14: =IF(AND(ISNUMBER(C14),ISNUMBER(G14)), C14-G14, "") -> 265.8 | I14: =IFERROR(H14/G14, "") -> 0.15644497
A15: Southglenn | B15: CO | C15: 1800.9 | D15: 0 | E15: =IF(AND(ISNUMBER(C15),ISNUMBER(D15)), C15-D15, "") -> 1800.9 | F15: =IFERROR(E15/D15, "") | G15: 1778 | H15: =IF(AND(ISNUMBER(C15),ISNUMBER(G15)), C15-G15, "") -> 22.9 | I15: =IFERROR(H15/G15, "") -> 0.01287964
A16: Standley Lake | B16: CO | C16: 2393.1 | D16: 0 | E16: =IF(AND(ISNUMBER(C16),ISNUMBER(D16)), C16-D16, "") -> 2393.1 | F16: =IFERROR(E16/D16, "") | G16: 2371 | H16: =IF(AND(ISNUMBER(C16),ISNUMBER(G16)), C16-G16, "") -> 22.1 | I16: =IFERROR(H16/G16, "") -> 0.0093209616
A17: Havana Gardens | B17: CO | C17: 2062.1 | D17: 0 | E17: =IF(AND(ISNUMBER(C17),ISNUMBER(D17)), C17-D17, "") -> 2062.1 | F17: =IFERROR(E17/D17, "") | G17: 926 | H17: =IF(AND(ISNUMBER(C17),ISNUMBER(G17)), C17-G17, "") -> 1136.1 | I17: =IFERROR(H17/G17, "") -> 1.2268898 | J17: 03/01/2023 Per Kate - Do Not Pursue Weather Station
A18: East Hartford | B18: CT | C18: 277.7 | D18: 420.284 | E18: =IF(AND(ISNUMBER(C18),ISNUMBER(D18)), C18-D18, "") -> -142.584 | F18: =IFERROR(E18/D18, "") -> -0.33925631 | G18: 431.1858 | H18: -153 | I18: =IFERROR(H18/G18, "") -> -0.35483543
A19: Norwalk | B19: CT | C19: 212.00969 | D19: 641.9062 | E19: =IF(AND(ISNUMBER(C19),ISNUMBER(D19)), C19-D19, "") -> -429.89651 | F19: =IFERROR(E19/D19, "") -> -0.66971858 | G19: 490.3875 | H19: -278 | I19: =IFERROR(H19/G19, "") -> -0.56689863
A20: Hialeah Gardens | B20: FL | C20: 1245.3049 | D20: 3165.837 | E20: =IF(AND(ISNUMBER(C20),ISNUMBER(D20)), C20-D20, "") -> -1920.5321 | F20: =IFERROR(E20/D20, "") -> -0.60664275 | G20: 3739 | H20: =IF(AND(ISNUMBER(C20),ISNUMBER(G20)), C20-G20, "") -> -2493.6951 | I20: =IFERROR(H20/G20, "") -> -0.66694171 | J20: 1. Daily drop in production due to inverter fan failure. | K20: 1. SR081410
A21: West Des Moines - HMHQ | B21: IA | C21: 33641.5 | D21: 34557.14 | E21: =IF(AND(ISNUMBER(C21),ISNUMBER(D21)), C21-D21, "") -> -915.64 | F21: =IFERROR(E21/D21, "") -> -0.026496406 | G21: 29114.09 | H21: =IF(AND(ISNUMBER(C21),ISNUMBER(G21)), C21-G21, "") -> 4527.41 | I21: =IFERROR(H21/G21, "") -> 0.1555058
A22: W. Des Moines Campus EAST | B22: IA | C22: 154786 | D22: 162400.1 | E22: =IF(AND(ISNUMBER(C22),ISNUMBER(D22)), C22-D22, "") -> -7614.1 | F22: =IFERROR(E22/D22, "") -> -0.046884823 | G22: 124800 | H22: =IF(AND(ISNUMBER(C22),ISNUMBER(G22)), C22-G22, "") -> 29986 | I22: =IFERROR(H22/G22, "") -> 0.24027244
A23: W. Des Moines Campus SW | B23: IA | C23: 63016.5 | D23: 89106.8 | E23: =IF(AND(ISNUMBER(C23),ISNUMBER(D23)), C23-D23, "") -> -26090.3 | F23: =IFERROR(E23/D23, "") -> -0.29279808 | G23: 63174.59 | H23: =IF(AND(ISNUMBER(C23),ISNUMBER(G23)), C23-G23, "") -> -158.09 | I23: =IFERROR(H23/G23, "") -> -0.0025024302 | J23: 1. Inverter 4 back online on 02/21 after replacement | K23: 1. SR080633
A24: WF - CIC | B24: NC | C24: 0 | D24: 0 | E24: =IF(AND(ISNUMBER(C24),ISNUMBER(D24)), C24-D24, "") -> 0 | F24: =IFERROR(E24/D24, "") | G24: 0 | H24: =IF(AND(ISNUMBER(C24),ISNUMBER(G24)), C24-G24, "") -> 0 | I24: =IFERROR(H24/G24, "")
A25: Charlotte - Wells Fargo - DUC | B25: NC | C25: 0 | D25: 0 | E25: =IF(AND(ISNUMBER(C25),ISNUMBER(D25)), C25-D25, "") -> 0 | F25: =IFERROR(E25/D25, "") | G25: 0 | H25: =IF(AND(ISNUMBER(C25),ISNUMBER(G25)), C25-G25, "") -> 0 | I25: =IFERROR(H25/G25, "")
A26: East Windsor | B26: NJ | C26: 616.9 | D26: 728.9626 | E26: =IF(AND(ISNUMBER(C26),ISNUMBER(D26)), C26-D26, "") -> -112.0626 | F26: =IFERROR(E26/D26, "") -> -0.15372887 | G26: 481.6708 | H26: =IF(AND(ISNUMBER(C26),ISNUMBER(G26)), C26-G26, "") -> 135.2292 | I26: =IFERROR(H26/G26, "") -> 0.28075026
A27: Burlington | B27: NJ | C27: 1843.1 | D27: 1626.606 | E27: =IF(AND(ISNUMBER(C27),ISNUMBER(D27)), C27-D27, "") -> 216.494 | F27: =IFERROR(E27/D27, "") -> 0.13309554 | G27: 1364.992 | H27: =IF(AND(ISNUMBER(C27),ISNUMBER(G27)), C27-G27, "") -> 478.108 | I27: =IFERROR(H27/G27, "") -> 0.35026432
A28: Bayonne | B28: NJ | C28: 1770 | D28: 2142.025 | E28: =IF(AND(ISNUMBER(C28),ISNUMBER(D28)), C28-D28, "") -> -372.025 | F28: =IFERROR(E28/D28, "") -> -0.17367911 | G28: 2322.581 | H28: =IF(AND(ISNUMBER(C28),ISNUMBER(G28)), C28-G28, "") -> -552.581 | I28: =IFERROR(H28/G28, "") -> -0.23791678
A29: Clifton | B29: NJ | C29: 2043.2812 | D29: 2654.534 | E29: =IF(AND(ISNUMBER(C29),ISNUMBER(D29)), C29-D29, "") -> -611.25275 | F29: =IFERROR(E29/D29, "") -> -0.23026744 | G29: 3038.303 | H29: =IF(AND(ISNUMBER(C29),ISNUMBER(G29)), C29-G29, "") -> -995.02175 | I29: =IFERROR(H29/G29, "") -> -0.3274926
A30: North Elizabeth | B30: NJ | C30: 1566.5 | D30: 1603.561 | E30: =IF(AND(ISNUMBER(C30),ISNUMBER(D30)), C30-D30, "") -> -37.061 | F30: =IFERROR(E30/D30, "") -> -0.023111687 | G30: 1917.395 | H30: =IF(AND(ISNUMBER(C30),ISNUMBER(G30)), C30-G30, "") -> -350.895 | I30: =IFERROR(H30/G30, "") -> -0.18300611
A31: Haddon Westmont Plaza | B31: NJ | C31: 1473.6 | D31: 1550.355 | E31: =IF(AND(ISNUMBER(C31),ISNUMBER(D31)), C31-D31, "") -> -76.755 | F31: =IFERROR(E31/D31, "") -> -0.049508016 | G31: 1328.679 | H31: =IF(AND(ISNUMBER(C31),ISNUMBER(G31)), C31-G31, "") -> 144.921 | I31: =IFERROR(H31/G31, "") -> 0.10907149
A32: Parsippany | B32: NJ | C32: 1595.4 | D32: 2384.318 | E32: =IF(AND(ISNUMBER(C32),ISNUMBER(D32)), C32-D32, "") -> -788.918 | F32: =IFERROR(E32/D32, "") -> -0.33087784 | G32: 1729.456 | H32: =IF(AND(ISNUMBER(C32),ISNUMBER(G32)), C32-G32, "") -> -134.056 | I32: =IFERROR(H32/G32, "") -> -0.077513391
A33: Clark | B33: NJ | C33: 1274.5 | D33: 1502.578 | E33: =IF(AND(ISNUMBER(C33),ISNUMBER(D33)), C33-D33, "") -> -228.078 | F33: =IFERROR(E33/D33, "") -> -0.15179112 | G33: 1380.123 | H33: =IF(AND(ISNUMBER(C33),ISNUMBER(G33)), C33-G33, "") -> -105.623 | I33: =IFERROR(H33/G33, "") -> -0.076531585
A34: Closter | B34: NJ | C34: 304.9 | D34: 446.6089 | E34: =IF(AND(ISNUMBER(C34),ISNUMBER(D34)), C34-D34, "") -> -141.7089 | F34: =IFERROR(E34/D34, "") -> -0.31729977 | G34: 770.4244 | H34: =IF(AND(ISNUMBER(C34),ISNUMBER(G34)), C34-G34, "") -> -465.5244 | I34: =IFERROR(H34/G34, "") -> -0.6042441
A35: Holmdel | B35: NJ | C35: 1149.5 | D35: 1236.095 | E35: =IF(AND(ISNUMBER(C35),ISNUMBER(D35)), C35-D35, "") -> -86.595 | F35: =IFERROR(E35/D35, "") -> -0.070055295 | G35: 1001 | H35: =IF(AND(ISNUMBER(C35),ISNUMBER(G35)), C35-G35, "") -> 148.5 | I35: =IFERROR(H35/G35, "") -> 0.14835165
... A56: Hainesport | B56: NJ | C56: 1647.1 | D56: 1596.808 | E56: =IF(AND(ISNUMBER(C56),ISNUMBER(D56)), C56-D56, "") -> 50.292 | F56: =IFERROR(E56/D56, "") -> 0.031495333 | G56: 1161.867 | H56: =IF(AND(ISNUMBER(C56),ISNUMBER(G56)), C56-G56, "") -> 485.233 | I56: =IFERROR(H56/G56, "") -> 0.41763214
A57: San Antonio - Ops Ctr (Bldg 106) | B57: TX | C57: 2887 | D57: 0 | E57: =IF(AND(ISNUMBER(C57),ISNUMBER(D57)), C57-D57, "") -> 2887 | F57: =IFERROR(E57/D57, "") | G57: 38409 | H57: =IF(AND(ISNUMBER(C57),ISNUMBER(G57)), C57-G57, "") -> -35522 | I57: =IFERROR(H57/G57, "") -> -0.92483533 | J57: 1. Site reenergized on 02/27 after TIGO investigation | K57: 1. SR078163
A58: San Antonio - Ops Ctr GM | B58: TX | C58: 285995.75 | D58: 324168.8 | E58: =IF(AND(ISNUMBER(C58),ISNUMBER(D58)), C58-D58, "") -> -38173.05 | F58: =IFERROR(E58/D58, "") -> -0.11775671 | G58: 305642 | H58: =IF(AND(ISNUMBER(C58),ISNUMBER(G58)), C58-G58, "") -> -19646.25 | I58: =IFERROR(H58/G58, "") -> -0.064278633
A59: San Antonio - Ctr (Bldg 201) | B59: TX | C59: 0 | D59: 0 | E59: =IF(AND(ISNUMBER(C59),ISNUMBER(D59)), C59-D59, "") -> 0 | F59: =IFERROR(E59/D59, "") | G59: 38321 | H59: =IF(AND(ISNUMBER(C59),ISNUMBER(G59)), C59-G59, "") -> -38321 | I59: =IFERROR(H59/G59, "") -> -1 | J59: 1. Site's de-energized on 06/02/2023 due to TIGO investigation and renergized on 03/05/2024 | K59: 1. SR078159
A60: San Antonio - Ops Ctr (Bldg 203) | B60: TX | C60: 0 | D60: 0 | E60: =IF(AND(ISNUMBER(C60),ISNUMBER(D60)), C60-D60, "") -> 0 | F60: =IFERROR(E60/D60, "") | G60: 39375.26 | H60: =IF(AND(ISNUMBER(C60),ISNUMBER(G60)), C60-G60, "") -> -39375.26 | I60: =IFERROR(H60/G60, "") -> -1 | J60: 1. Site's de-energized 06/02/2023 due to TIGO investigation | K60: 1. SR078164
...

Sheet Mar
A1: {=portfolio} -> Wells Fargo | D1: March Actual v. Expected | G1: March Actual v. Forecasted
A2: Total | C2: =SUM(C4:C87) -> 936474.4 | D2: =SUM(D4:D87) -> 1151423 | E2: =C2-D2 -> -214948.6 | F2: =IFERROR(E2/D2, 0) -> -0.18668083 | G2: =SUM(G4:G87) -> 1453708.8 | H2: =C2-G2 -> -517234.4 | I2: =IFERROR(H2/G2, 0) -> -0.35580331 | J2: =IF(AND(TODAY()>DATE(2024, 3, 1), COUNTA(Sites[Site])<>(COUNT(C:C)-1)), "Some sites are missing actual data; if new sites were added, make sure they are aligned correctly (including prior months!)", "") -> Some sites are missing actual data; if new sites were added, make sure they are aligned correctly (including prior months!)
A3: Site | B3: State | C3: Actual | D3: Expected | E3: Delta | F3: % | G3: Forecasted | H3: Delta | I3: % | J3: Notes | K3: Service Requests
A4: {=Sites[Site]} -> Adams & Broadway | B4: {=Sites[State]} -> CA | C4: 1138 | D4: 0 | E4: =IF(AND(ISNUMBER(C4),ISNUMBER(D4)), C4-D4, "") -> 1138 | F4: =IFERROR(E4/D4, "") | G4: 1060 | H4: =IF(AND(ISNUMBER(C4),ISNUMBER(G4)), C4-G4, "") -> 78 | I4: =IFERROR(H4/G4, "") -> 0.073584906
A5: Otay Mesa | B5: CA | D5: 0 | E5: =IF(AND(ISNUMBER(C5),ISNUMBER(D5)), C5-D5, "") | F5: =IFERROR(E5/D5, "") | H5: =IF(AND(ISNUMBER(C5),ISNUMBER(G5)), C5-G5, "") | I5: =IFERROR(H5/G5, "")
A6: San Leandro | B6: CA | C6: 43042 | D6: 41936 | E6: =IF(AND(ISNUMBER(C6),ISNUMBER(D6)), C6-D6, "") -> 1106 | F6: =IFERROR(E6/D6, "") -> 0.026373522 | G6: 37309 | H6: =IF(AND(ISNUMBER(C6),ISNUMBER(G6)), C6-G6, "") -> 5733 | I6: =IFERROR(H6/G6, "") -> 0.15366266 | J6: 1. Inverter 4 offline on 03/02, 03/04, 03/05, 03/06, 03/08, 03/10 | K6: 1. SR080945
A7: Van Nuys | B7: CA | C7: 1947 | D7: 0 | E7: =IF(AND(ISNUMBER(C7),ISNUMBER(D7)), C7-D7, "") -> 1947 | F7: =IFERROR(E7/D7, "") | G7: 2127 | H7: =IF(AND(ISNUMBER(C7),ISNUMBER(G7)), C7-G7, "") -> -180 | I7: =IFERROR(H7/G7, "") -> -0.084626234
A8: 98th & Grant | B8: CO | C8: 1216 | D8: 0 | E8: =IF(AND(ISNUMBER(C8),ISNUMBER(D8)), C8-D8, "") -> 1216 | F8: =IFERROR(E8/D8, "") | G8: 1984 | H8: =IF(AND(ISNUMBER(C8),ISNUMBER(G8)), C8-G8, "") -> -768 | I8: =IFERROR(H8/G8, "") -> -0.38709677
A9: Arapahoe Crossings | B9: CO | C9: 3183.3998 | D9: 0 | E9: =IF(AND(ISNUMBER(C9),ISNUMBER(D9)), C9-D9, "") -> 3183.3998 | F9: =IFERROR(E9/D9, "") | G9: 3628.808 | H9: =IF(AND(ISNUMBER(C9),ISNUMBER(G9)), C9-G9, "") -> -445.40822 | I9: =IFERROR(H9/G9, "") -> -0.1227423
A10: Aurora City Center | B10: CO | C10: 1628 | D10: 0 | E10: =IF(AND(ISNUMBER(C10),ISNUMBER(D10)), C10-D10, "") -> 1628 | F10: =IFERROR(E10/D10, "") | G10: 1727 | H10: =IF(AND(ISNUMBER(C10),ISNUMBER(G10)), C10-G10, "") -> -99 | I10: =IFERROR(H10/G10, "") -> -0.057324841
A11: Dry Creek | B11: CO | C11: -2.9959823 | D11: 0 | E11: =IF(AND(ISNUMBER(C11),ISNUMBER(D11)), C11-D11, "") -> -2.9959823 | F11: =IFERROR(E11/D11, "") | G11: 2153 | H11: =IF(AND(ISNUMBER(C11),ISNUMBER(G11)), C11-G11, "") -> -2155.996 | I11: =IFERROR(H11/G11, "") -> -1.0013915 | J11: 1. Site stopped communicating since 03/22 | K11: 1. SR078942
A12: Highlands Ranch S. | B12: CO | C12: 1464 | D12: 0 | E12: =IF(AND(ISNUMBER(C12),ISNUMBER(D12)), C12-D12, "") -> 1464 | F12: =IFERROR(E12/D12, "") | G12: 2006 | H12: =IF(AND(ISNUMBER(C12),ISNUMBER(G12)), C12-G12, "") -> -542 | I12: =IFERROR(H12/G12, "") -> -0.27018943
A13: Lone Tree | B13: CO | C13: 2352 | D13: 0 | E13: =IF(AND(ISNUMBER(C13),ISNUMBER(D13)), C13-D13, "") -> 2352 | F13: =IFERROR(E13/D13, "") | G13: 4580 | H13: =IF(AND(ISNUMBER(C13),ISNUMBER(G13)), C13-G13, "") -> -2228 | I13: =IFERROR(H13/G13, "") -> -0.48646288
A14: Meridian | B14: CO | C14: 2687 | D14: 0 | E14: =IF(AND(ISNUMBER(C14),ISNUMBER(D14)), C14-D14, "") -> 2687 | F14: =IFERROR(E14/D14, "") | G14: 2667 | H14: =IF(AND(ISNUMBER(C14),ISNUMBER(G14)), C14-G14, "") -> 20 | I14: =IFERROR(H14/G14, "") -> 0.0074990626
A15: Southglenn | B15: CO | C15: 2486 | D15: 0 | E15: =IF(AND(ISNUMBER(C15),ISNUMBER(D15)), C15-D15, "") -> 2486 | F15: =IFERROR(E15/D15, "") | G15: 2762 | H15: =IF(AND(ISNUMBER(C15),ISNUMBER(G15)), C15-G15, "") -> -276 | I15: =IFERROR(H15/G15, "") -> -0.099927589
A16: Standley Lake | B16: CO | C16: 1464 | D16: 0 | E16: =IF(AND(ISNUMBER(C16),ISNUMBER(D16)), C16-D16, "") -> 1464 | F16: =IFERROR(E16/D16, "") | G16: 3683 | H16: =IF(AND(ISNUMBER(C16),ISNUMBER(G16)), C16-G16, "") -> -2219 | I16: =IFERROR(H16/G16, "") -> -0.60249796
A17: Havana Gardens | B17: CO | C17: 2966 | D17: 0 | E17: =IF(AND(ISNUMBER(C17),ISNUMBER(D17)), C17-D17, "") -> 2966 | F17: =IFERROR(E17/D17, "") | G17: 1436 | H17: =IF(AND(ISNUMBER(C17),ISNUMBER(G17)), C17-G17, "") -> 1530 | I17: =IFERROR(H17/G17, "") -> 1.0654596
A18: East Hartford | B18: CT | D18: 609 | E18: =IF(AND(ISNUMBER(C18),ISNUMBER(D18)), C18-D18, "") | F18: =IFERROR(E18/D18, "") | G18: 599 | H18: =IF(AND(ISNUMBER(C18),ISNUMBER(G18)), C18-G18, "") | I18: =IFERROR(H18/G18, "")
A19: Norwalk | B19: CT | C19: 710 | D19: 863 | E19: =IF(AND(ISNUMBER(C19),ISNUMBER(D19)), C19-D19, "") -> -153 | F19: =IFERROR(E19/D19, "") -> -0.17728853 | G19: 734 | H19: =IF(AND(ISNUMBER(C19),ISNUMBER(G19)), C19-G19, "") -> -24 | I19: =IFERROR(H19/G19, "") -> -0.032697548
A20: Hialeah Gardens | B20: FL | C20: 754 | D20: 3725 | E20: =IF(AND(ISNUMBER(C20),ISNUMBER(D20)), C20-D20, "") -> -2971 | F20: =IFERROR(E20/D20, "") -> -0.79758389 | G20: 5039 | H20: =IF(AND(ISNUMBER(C20),ISNUMBER(G20)), C20-G20, "") -> -4285 | I20: =IFERROR(H20/G20, "") -> -0.85036714 | J20: 1. Daily drop in production due to inverter fan failure | K20: 1. SR081410
A21: West Des Moines - HMHQ | B21: IA | C21: 0 | D21: 0 | E21: =IF(AND(ISNUMBER(C21),ISNUMBER(D21)), C21-D21, "") -> 0 | F21: =IFERROR(E21/D21, "") | G21: 0 | H21: =IF(AND(ISNUMBER(C21),ISNUMBER(G21)), C21-G21, "") -> 0 | I21: =IFERROR(H21/G21, "")
A22: W. Des Moines Campus EAST | B22: IA | C22: 168562 | D22: 169387 | E22: =IF(AND(ISNUMBER(C22),ISNUMBER(D22)), C22-D22, "") -> -825 | F22: =IFERROR(E22/D22, "") -> -0.0048705036 | G22: 159000 | H22: =IF(AND(ISNUMBER(C22),ISNUMBER(G22)), C22-G22, "") -> 9562 | I22: =IFERROR(H22/G22, "") -> 0.060138365
