Workbook
Name JanActual: #REF!
Name JanActual2: #REF!
Name JanExpected: #REF!
Name JanExpectedDelta: #REF!
Name JanExpectedPercent: #REF!
Name JanExpPercent: #REF!
Name JanForecasted: #REF!
Name JanForecastedDelta: #REF!
Name JanForecastedPercent: #REF!
Name portfolio: Sites!$B$1:$B$1
Name Year: Sites!#REF!

Sheet Year to Date
A1: {=portfolio} -> Silicon Ranch | D1: Year to Date Actual v. Expected | G1: Year to Date Actual v. Forecasted
A2: Total | C2: =SUM(C4:C99) -> 1984478.1 | D2: =SUM(D4:D99) -> 1107350 | E2: =C2-D2 -> 877128.15 | F2: =IFERROR(E2/D2, 0) -> 0.79209658 | G2: =SUM(G4:G99) -> 1915460.7 | H2: =C2-G2 -> 69017.41 | I2: =IFERROR(H2/G2, 0) -> 0.036031754
A3: Site | B3: State | C3: Actual | D3: Expected | E3: Delta | F3: % | G3: Forecasted | H3: Delta | I3: %
A4: {=Sites[Site]} -> Iron Mountain - Windsor | B4: {=Sites[State]} -> CT | C4: =SUM('1st Qtr'!C4, '2nd Qtr'!C4, '3rd Qtr'!C4, '4th Qtr'!C4) -> 6816 | D4: =SUM('1st Qtr'!D4, '2nd Qtr'!D4, '3rd Qtr'!D4, '4th Qtr'!D4) -> 6764 | E4: =IF(AND(ISNUMBER(C4),ISNUMBER(D4)), C4-D4, "") -> 52 | F4: =IFERROR(E4/D4, "") -> 0.0076877587 | G4: =SUM('1st Qtr'!G4, '2nd Qtr'!G4, '3rd Qtr'!G4, '4th Qtr'!G4) -> 12840.66 | H4: =SUM('1st Qtr'!H4, '2nd Qtr'!H4, '3rd Qtr'!H4, '4th Qtr'!H4) -> -6024.66 | I4: =IFERROR(H4/G4, "") -> -0.46918616 | K4: =C4-G4 -> -6024.66
A5: Kohls - Auburn | B5: NY | C5: =SUM('1st Qtr'!C5, '2nd Qtr'!C5, '3rd Qtr'!C5, '4th Qtr'!C5) -> 645 | D5: =SUM('1st Qtr'!D5, '2nd Qtr'!D5, '3rd Qtr'!D5, '4th Qtr'!D5) -> 645 | E5: =IF(AND(ISNUMBER(C5),ISNUMBER(D5)), C5-D5, "") -> 0 | F5: =IFERROR(E5/D5, "") -> 0 | G5: =SUM('1st Qtr'!G5, '2nd Qtr'!G5, '3rd Qtr'!G5, '4th Qtr'!G5) -> 4715.29 | H5: =SUM('1st Qtr'!H5, '2nd Qtr'!H5, '3rd Qtr'!H5, '4th Qtr'!H5) -> -4070.29 | I5: =IFERROR(H5/G5, "") -> -0.86321096 | K5: =C5-G5 -> -4070.29
A6: Kohls - Bensalem | B6: PA | C6: =SUM('1st Qtr'!C6, '2nd Qtr'!C6, '3rd Qtr'!C6, '4th Qtr'!C6) -> 10621 | D6: =SUM('1st Qtr'!D6, '2nd Qtr'!D6, '3rd Qtr'!D6, '4th Qtr'!D6) -> 0 | E6: =IF(AND(ISNUMBER(C6),ISNUMBER(D6)), C6-D6, "") -> 10621 | F6: =IFERROR(E6/D6, "") | G6: =SUM('1st Qtr'!G6, '2nd Qtr'!G6, '3rd Qtr'!G6, '4th Qtr'!G6) -> 15534.61 | H6: =SUM('1st Qtr'!H6, '2nd Qtr'!H6, '3rd Qtr'!H6, '4th Qtr'!H6) -> -4913.61 | I6: =IFERROR(H6/G6, "") -> -0.31630083 | K6: =C6-G6 -> -4913.61
A7: Kohls - Brick | B7: NJ | C7: =SUM('1st Qtr'!C7, '2nd Qtr'!C7, '3rd Qtr'!C7, '4th Qtr'!C7) -> 12552 | D7: =SUM('1st Qtr'!D7, '2nd Qtr'!D7, '3rd Qtr'!D7, '4th Qtr'!D7) -> 12511 | E7: =IF(AND(ISNUMBER(C7),ISNUMBER(D7)), C7-D7, "") -> 41 | F7: =IFERROR(E7/D7, "") -> 0.0032771161 | G7: =SUM('1st Qtr'!G7, '2nd Qtr'!G7, '3rd Qtr'!G7, '4th Qtr'!G7) -> 16463.56 | H7: =SUM('1st Qtr'!H7, '2nd Qtr'!H7, '3rd Qtr'!H7, '4th Qtr'!H7) -> -3911.56 | I7: =IFERROR(H7/G7, "") -> -0.23758895 | K7: =C7-G7 -> -3911.56
A8: Kohls - Buffalo | B8: NY | C8: =SUM('1st Qtr'!C8, '2nd Qtr'!C8, '3rd Qtr'!C8, '4th Qtr'!C8) -> 3229 | D8: =SUM('1st Qtr'!D8, '2nd Qtr'!D8, '3rd Qtr'!D8, '4th Qtr'!D8) -> 0 | E8: =IF(AND(ISNUMBER(C8),ISNUMBER(D8)), C8-D8, "") -> 3229 | F8: =IFERROR(E8/D8, "") | G8: =SUM('1st Qtr'!G8, '2nd Qtr'!G8, '3rd Qtr'!G8, '4th Qtr'!G8) -> 7932.35 | H8: =SUM('1st Qtr'!H8, '2nd Qtr'!H8, '3rd Qtr'!H8, '4th Qtr'!H8) -> -4703.35 | I8: =IFERROR(H8/G8, "") -> -0.59293274 | K8: =C8-G8 -> -4703.35
A9: Kohls - Canton | B9: CT | C9: =SUM('1st Qtr'!C9, '2nd Qtr'!C9, '3rd Qtr'!C9, '4th Qtr'!C9) -> 1564 | D9: =SUM('1st Qtr'!D9, '2nd Qtr'!D9, '3rd Qtr'!D9, '4th Qtr'!D9) -> 1330 | E9: =IF(AND(ISNUMBER(C9),ISNUMBER(D9)), C9-D9, "") -> 234 | F9: =IFERROR(E9/D9, "") -> 0.17593985 | G9: =SUM('1st Qtr'!G9, '2nd Qtr'!G9, '3rd Qtr'!G9, '4th Qtr'!G9) -> 5755.92 | H9: =SUM('1st Qtr'!H9, '2nd Qtr'!H9, '3rd Qtr'!H9, '4th Qtr'!H9) -> -4191.92 | I9: =IFERROR(H9/G9, "") -> -0.72827975 | K9: =C9-G9 -> -4191.92
A10: Kohls - East Amherst | B10: NY | C10: =SUM('1st Qtr'!C10, '2nd Qtr'!C10, '3rd Qtr'!C10, '4th Qtr'!C10) -> 1721 | D10: =SUM('1st Qtr'!D10, '2nd Qtr'!D10, '3rd Qtr'!D10, '4th Qtr'!D10) -> 1585 | E10: =IF(AND(ISNUMBER(C10),ISNUMBER(D10)), C10-D10, "") -> 136 | F10: =IFERROR(E10/D10, "") -> 0.085804416 | G10: =SUM('1st Qtr'!G10, '2nd Qtr'!G10, '3rd Qtr'!G10, '4th Qtr'!G10) -> 8364.35 | H10: =SUM('1st Qtr'!H10, '2nd Qtr'!H10, '3rd Qtr'!H10, '4th Qtr'!H10) -> -6643.35 | I10: =IFERROR(H10/G10, "") -> -0.79424582 | K10: =C10-G10 -> -6643.35
A11: Kohls - East Brunswick | B11: NJ | C11: =SUM('1st Qtr'!C11, '2nd Qtr'!C11, '3rd Qtr'!C11, '4th Qtr'!C11) -> 13312.05 | D11: =SUM('1st Qtr'!D11, '2nd Qtr'!D11, '3rd Qtr'!D11, '4th Qtr'!D11) -> 0 | E11: =IF(AND(ISNUMBER(C11),ISNUMBER(D11)), C11-D11, "") -> 13312.05 | F11: =IFERROR(E11/D11, "") | G11: =SUM('1st Qtr'!G11, '2nd Qtr'!G11, '3rd Qtr'!G11, '4th Qtr'!G11) -> 22969.47 | H11: =SUM('1st Qtr'!H11, '2nd Qtr'!H11, '3rd Qtr'!H11, '4th Qtr'!H11) -> -9657.42 | I11: =IFERROR(H11/G11, "") -> -0.42044592 | K11: =C11-G11 -> -9657.42
A12: Kohls - Edgewood | B12: MD | C12: =SUM('1st Qtr'!C12, '2nd Qtr'!C12, '3rd Qtr'!C12, '4th Qtr'!C12) -> 69205 | D12: =SUM('1st Qtr'!D12, '2nd Qtr'!D12, '3rd Qtr'!D12, '4th Qtr'!D12) -> 68059 | E12: =IF(AND(ISNUMBER(C12),ISNUMBER(D12)), C12-D12, "") -> 1146 | F12: =IFERROR(E12/D12, "") -> 0.016838331 | G12: =SUM('1st Qtr'!G12, '2nd Qtr'!G12, '3rd Qtr'!G12, '4th Qtr'!G12) -> 134337.97 | H12: =SUM('1st Qtr'!H12, '2nd Qtr'!H12, '3rd Qtr'!H12, '4th Qtr'!H12) -> -65132.97 | I12: =IFERROR(H12/G12, "") -> -0.48484408 | K12: =C12-G12 -> -65132.97
A13: Kohls - Granite Run | B13: PA | C13: =SUM('1st Qtr'!C13, '2nd Qtr'!C13, '3rd Qtr'!C13, '4th Qtr'!C13) -> 9634 | D13: =SUM('1st Qtr'!D13, '2nd Qtr'!D13, '3rd Qtr'!D13, '4th Qtr'!D13) -> 9462 | E13: =IF(AND(ISNUMBER(C13),ISNUMBER(D13)), C13-D13, "") -> 172 | F13: =IFERROR(E13/D13, "") -> 0.018177975 | G13: =SUM('1st Qtr'!G13, '2nd Qtr'!G13, '3rd Qtr'!G13, '4th Qtr'!G13) -> 15797.45 | H13: =SUM('1st Qtr'!H13, '2nd Qtr'!H13, '3rd Qtr'!H13, '4th Qtr'!H13) -> -6163.45 | I13: =IFERROR(H13/G13, "") -> -0.39015474 | K13: =C13-G13 -> -6163.45
A14: Kohls - Greece | B14: NY | C14: =SUM('1st Qtr'!C14, '2nd Qtr'!C14, '3rd Qtr'!C14, '4th Qtr'!C14) -> 2440 | D14: =SUM('1st Qtr'!D14, '2nd Qtr'!D14, '3rd Qtr'!D14, '4th Qtr'!D14) -> 2296 | E14: =IF(AND(ISNUMBER(C14),ISNUMBER(D14)), C14-D14, "") -> 144 | F14: =IFERROR(E14/D14, "") -> 0.06271777 | G14: =SUM('1st Qtr'!G14, '2nd Qtr'!G14, '3rd Qtr'!G14, '4th Qtr'!G14) -> 9292.71 | H14: =SUM('1st Qtr'!H14, '2nd Qtr'!H14, '3rd Qtr'!H14, '4th Qtr'!H14) -> -6852.71 | I14: =IFERROR(H14/G14, "") -> -0.73742859 | K14: =C14-G14 -> -6852.71
A15: Kohls - Hanover | B15: PA | C15: =SUM('1st Qtr'!C15, '2nd Qtr'!C15, '3rd Qtr'!C15, '4th Qtr'!C15) -> 13956 | D15: =SUM('1st Qtr'!D15, '2nd Qtr'!D15, '3rd Qtr'!D15, '4th Qtr'!D15) -> 13682 | E15: =IF(AND(ISNUMBER(C15),ISNUMBER(D15)), C15-D15, "") -> 274 | F15: =IFERROR(E15/D15, "") -> 0.020026312 | G15: =SUM('1st Qtr'!G15, '2nd Qtr'!G15, '3rd Qtr'!G15, '4th Qtr'!G15) -> 18615.25 | H15: =SUM('1st Qtr'!H15, '2nd Qtr'!H15, '3rd Qtr'!H15, '4th Qtr'!H15) -> -4659.25 | I15: =IFERROR(H15/G15, "") -> -0.2502921 | K15: =C15-G15 -> -4659.25
A16: Kohls - Horsehead | B16: NY | C16: =SUM('1st Qtr'!C16, '2nd Qtr'!C16, '3rd Qtr'!C16, '4th Qtr'!C16) -> 7602 | D16: =SUM('1st Qtr'!D16, '2nd Qtr'!D16, '3rd Qtr'!D16, '4th Qtr'!D16) -> 7428 | E16: =IF(AND(ISNUMBER(C16),ISNUMBER(D16)), C16-D16, "") -> 174 | F16: =IFERROR(E16/D16, "") -> 0.023424879 | G16: =SUM('1st Qtr'!G16, '2nd Qtr'!G16, '3rd Qtr'!G16, '4th Qtr'!G16) -> 12592.49 | H16: =SUM('1st Qtr'!H16, '2nd Qtr'!H16, '3rd Qtr'!H16, '4th Qtr'!H16) -> -4990.49 | I16: =IFERROR(H16/G16, "") -> -0.39630685 | K16: =C16-G16 -> -4990.49
... A68: North Stonington | B68: CT | C68: =SUM('1st Qtr'!C68, '2nd Qtr'!C68, '3rd Qtr'!C68, '4th Qtr'!C68) -> 482520 | D68: =SUM('1st Qtr'!D68, '2nd Qtr'!D68, '3rd Qtr'!D68, '4th Qtr'!D68) -> 0 | E68: =IF(AND(ISNUMBER(C68),ISNUMBER(D68)), C68-D68, "") -> 482520 | F68: =IFERROR(E68/D68, "") | G68: =SUM('1st Qtr'!G68, '2nd Qtr'!G68, '3rd Qtr'!G68, '4th Qtr'!G68) -> 0 | H68: =SUM('1st Qtr'!H68, '2nd Qtr'!H68, '3rd Qtr'!H68, '4th Qtr'!H68) -> 0 | I68: =IFERROR(H68/G68, "") | K68: =C68-G68 -> 482520
A69: CT: Torrington - 2-298 Rossi Road | B69: CT | C69: =SUM('1st Qtr'!C69, '2nd Qtr'!C69, '3rd Qtr'!C69, '4th Qtr'!C69) -> 555.63 | D69: =SUM('1st Qtr'!D69, '2nd Qtr'!D69, '3rd Qtr'!D69, '4th Qtr'!D69) -> 0 | E69: =IF(AND(ISNUMBER(C69),ISNUMBER(D69)), C69-D69, "") -> 555.63 | F69: =IFERROR(E69/D69, "") | G69: =SUM('1st Qtr'!G69, '2nd Qtr'!G69, '3rd Qtr'!G69, '4th Qtr'!G69) -> 0 | H69: =SUM('1st Qtr'!H69, '2nd Qtr'!H69, '3rd Qtr'!H69, '4th Qtr'!H69) -> 0 | I69: =IFERROR(H69/G69, "")

Sheet 1st Qtr
A1: {=portfolio} -> Silicon Ranch | D1: 1st Quarter Actual v. Expected | G1: 1st Quarter Actual v. Forecasted
A2: Total | C2: =SUM(C4:C100) -> 1984478.1 | D2: =SUM(D4:D100) -> 1107350 | E2: =C2-D2 -> 877128.15 | F2: =IFERROR(E2/D2, 0) -> 0.79209658 | G2: =SUM(G4:G100) -> 1915460.7 | H2: =C2-G2 -> 69017.41 | I2: =IFERROR(H2/G2, 0) -> 0.036031754
A3: Site | B3: State | C3: Actual | D3: Expected | E3: Delta | F3: % | G3: Forecasted | H3: Delta | I3: %
A4: {=Sites[Site]} -> Iron Mountain - Windsor | B4: {=Sites[State]} -> CT | C4: =SUM(Jan!C4, Feb!C4, Mar!C4) -> 6816 | D4: =SUM(Jan!D4, Feb!D4, Mar!D4) -> 6764 | E4: =IF(AND(ISNUMBER(C4),ISNUMBER(D4)), C4-D4, "") -> 52 | F4: =IFERROR(E4/D4, "") -> 0.0076877587 | G4: =SUM(Jan!G4, Feb!G4, Mar!G4) -> 12840.66 | H4: =SUM(Jan!H4, Feb!H4, Mar!H4) -> -6024.66 | I4: =IFERROR(H4/G4, "") -> -0.46918616
A5: Kohls - Auburn | B5: NY | C5: =SUM(Jan!C5, Feb!C5, Mar!C5) -> 645 | D5: =SUM(Jan!D5, Feb!D5, Mar!D5) -> 645 | E5: =IF(AND(ISNUMBER(C5),ISNUMBER(D5)), C5-D5, "") -> 0 | F5: =IFERROR(E5/D5, "") -> 0 | G5: =SUM(Jan!G5, Feb!G5, Mar!G5) -> 4715.29 | H5: =SUM(Jan!H5, Feb!H5, Mar!H5) -> -4070.29 | I5: =IFERROR(H5/G5, "") -> -0.86321096
A6: Kohls - Bensalem | B6: PA | C6: =SUM(Jan!C6, Feb!C6, Mar!C6) -> 10621 | D6: =SUM(Jan!D6, Feb!D6, Mar!D6) -> 0 | E6: =IF(AND(ISNUMBER(C6),ISNUMBER(D6)), C6-D6, "") -> 10621 | F6: =IFERROR(E6/D6, "") | G6: =SUM(Jan!G6, Feb!G6, Mar!G6) -> 15534.61 | H6: =SUM(Jan!H6, Feb!H6, Mar!H6) -> -4913.61 | I6: =IFERROR(H6/G6, "") -> -0.31630083
A7: Kohls - Brick | B7: NJ | C7: =SUM(Jan!C7, Feb!C7, Mar!C7) -> 12552 | D7: =SUM(Jan!D7, Feb!D7, Mar!D7) -> 12511 | E7: =IF(AND(ISNUMBER(C7),ISNUMBER(D7)), C7-D7, "") -> 41 | F7: =IFERROR(E7/D7, "") -> 0.0032771161 | G7: =SUM(Jan!G7, Feb!G7, Mar!G7) -> 16463.56 | H7: =SUM(Jan!H7, Feb!H7, Mar!H7) -> -3911.56 | I7: =IFERROR(H7/G7, "") -> -0.23758895
A8: Kohls - Buffalo | B8: NY | C8: =SUM(Jan!C8, Feb!C8, Mar!C8) -> 3229 | D8: =SUM(Jan!D8, Feb!D8, Mar!D8) -> 0 | E8: =IF(AND(ISNUMBER(C8),ISNUMBER(D8)), C8-D8, "") -> 3229 | F8: =IFERROR(E8/D8, "") | G8: =SUM(Jan!G8, Feb!G8, Mar!G8) -> 7932.35 | H8: =SUM(Jan!H8, Feb!H8, Mar!H8) -> -4703.35 | I8: =IFERROR(H8/G8, "") -> -0.59293274
A9: Kohls - Canton | B9: CT | C9: =SUM(Jan!C9, Feb!C9, Mar!C9) -> 1564 | D9: =SUM(Jan!D9, Feb!D9, Mar!D9) -> 1330 | E9: =IF(AND(ISNUMBER(C9),ISNUMBER(D9)), C9-D9, "") -> 234 | F9: =IFERROR(E9/D9, "") -> 0.17593985 | G9: =SUM(Jan!G9, Feb!G9, Mar!G9) -> 5755.92 | H9: =SUM(Jan!H9, Feb!H9, Mar!H9) -> -4191.92 | I9: =IFERROR(H9/G9, "") -> -0.72827975
A10: Kohls - East Amherst | B10: NY | C10: =SUM(Jan!C10, Feb!C10, Mar!C10) -> 1721 | D10: =SUM(Jan!D10, Feb!D10, Mar!D10) -> 1585 | E10: =IF(AND(ISNUMBER(C10),ISNUMBER(D10)), C10-D10, "") -> 136 | F10: =IFERROR(E10/D10, "") -> 0.085804416 | G10: =SUM(Jan!G10, Feb!G10, Mar!G10) -> 8364.35 | H10: =SUM(Jan!H10, Feb!H10, Mar!H10) -> -6643.35 | I10: =IFERROR(H10/G10, "") -> -0.79424582
A11: Kohls - East Brunswick | B11: NJ | C11: =SUM(Jan!C11, Feb!C11, Mar!C11) -> 13312.05 | D11: =SUM(Jan!D11, Feb!D11, Mar!D11) -> 0 | E11: =IF(AND(ISNUMBER(C11),ISNUMBER(D11)), C11-D11, "") -> 13312.05 | F11: =IFERROR(E11/D11, "") | G11: =SUM(Jan!G11, Feb!G11, Mar!G11) -> 22969.47 | H11: =SUM(Jan!H11, Feb!H11, Mar!H11) -> -9657.42 | I11: =IFERROR(H11/G11, "") -> -0.42044592
A12: Kohls - Edgewood | B12: MD | C12: =SUM(Jan!C12, Feb!C12, Mar!C12) -> 69205 | D12: =SUM(Jan!D12, Feb!D12, Mar!D12) -> 68059 | E12: =IF(AND(ISNUMBER(C12),ISNUMBER(D12)), C12-D12, "") -> 1146 | F12: =IFERROR(E12/D12, "") -> 0.016838331 | G12: =SUM(Jan!G12, Feb!G12, Mar!G12) -> 134337.97 | H12: =SUM(Jan!H12, Feb!H12, Mar!H12) -> -65132.97 | I12: =IFERROR(H12/G12, "") -> -0.48484408
A13: Kohls - Granite Run | B13: PA | C13: =SUM(Jan!C13, Feb!C13, Mar!C13) -> 9634 | D13: =SUM(Jan!D13, Feb!D13, Mar!D13) -> 9462 | E13: =IF(AND(ISNUMBER(C13),ISNUMBER(D13)), C13-D13, "") -> 172 | F13: =IFERROR(E13/D13, "") -> 0.018177975 | G13: =SUM(Jan!G13, Feb!G13, Mar!G13) -> 15797.45 | H13: =SUM(Jan!H13, Feb!H13, Mar!H13) -> -6163.45 | I13: =IFERROR(H13/G13, "") -> -0.39015474
A14: Kohls - Greece | B14: NY | C14: =SUM(Jan!C14, Feb!C14, Mar!C14) -> 2440 | D14: =SUM(Jan!D14, Feb!D14, Mar!D14) -> 2296 | E14: =IF(AND(ISNUMBER(C14),ISNUMBER(D14)), C14-D14, "") -> 144 | F14: =IFERROR(E14/D14, "") -> 0.06271777 | G14: =SUM(Jan!G14, Feb!G14, Mar!G14) -> 9292.71 | H14: =SUM(Jan!H14, Feb!H14, Mar!H14) -> -6852.71 | I14: =IFERROR(H14/G14, "") -> -0.73742859
A15: Kohls - Hanover | B15: PA | C15: =SUM(Jan!C15, Feb!C15, Mar!C15) -> 13956 | D15: =SUM(Jan!D15, Feb!D15, Mar!D15) -> 13682 | E15: =IF(AND(ISNUMBER(C15),ISNUMBER(D15)), C15-D15, "") -> 274 | F15: =IFERROR(E15/D15, "") -> 0.020026312 | G15: =SUM(Jan!G15, Feb!G15, Mar!G15) -> 18615.25 | H15: =SUM(Jan!H15, Feb!H15, Mar!H15) -> -4659.25 | I15: =IFERROR(H15/G15, "") -> -0.2502921
A16: Kohls - Horsehead | B16: NY | C16: =SUM(Jan!C16, Feb!C16, Mar!C16) -> 7602 | D16: =SUM(Jan!D16, Feb!D16, Mar!D16) -> 7428 | E16: =IF(AND(ISNUMBER(C16),ISNUMBER(D16)), C16-D16, "") -> 174 | F16: =IFERROR(E16/D16, "") -> 0.023424879 | G16: =SUM(Jan!G16, Feb!G16, Mar!G16) -> 12592.49 | H16: =SUM(Jan!H16, Feb!H16, Mar!H16) -> -4990.49 | I16: =IFERROR(H16/G16, "") -> -0.39630685
... A22: Kohls - North Amherst | B22: NY | C22: =SUM(Jan!C22, Feb!C22, Mar!C22) -> 2216 | D22: =SUM(Jan!D22, Feb!D22, Mar!D22) -> 2114 | E22: =IF(AND(ISNUMBER(C22),ISNUMBER(D22)), C22-D22, "") -> 102 | F22: =IFERROR(E22/D22, "") -> 0.048249763 | G22: =SUM(Jan!G22, Feb!G22, Mar!G22) -> 6434.12 | H22: =SUM(Jan!H22, Feb!H22, Mar!H22) -> -4218.12 | I22: =IFERROR(H22/G22, "") -> -0.65558616
A23: Kohls - Staten Island | B23: NY | C23: =SUM(Jan!C23, Feb!C23, Mar!C23) -> 7744 | D23: =SUM(Jan!D23, Feb!D23, Mar!D23) -> 0 | E23: =IF(AND(ISNUMBER(C23),ISNUMBER(D23)), C23-D23, "") -> 7744 | F23: =IFERROR(E23/D23, "") | G23: =SUM(Jan!G23, Feb!G23, Mar!G24) -> 15260.77 | H23: =SUM(Jan!H23, Feb!H23, Mar!H23) -> -7516.77 | I23: =IFERROR(H23/G23, "") -> -0.49255509
A24: Kohls - Warminster | B24: PA | C24: =SUM(Jan!C24, Feb!C24, Mar!C24) -> 11746 | D24: =SUM(Jan!D24, Feb!D24, Mar!D24) -> 11528 | E24: =IF(AND(ISNUMBER(C24),ISNUMBER(D24)), C24-D24, "") -> 218 | F24: =IFERROR(E24/D24, "") -> 0.018910479 | G24: =SUM(Jan!G24, Feb!G24, Mar!G25) -> 19268.71 | H24: =SUM(Jan!H24, Feb!H24, Mar!H24) -> -7522.71 | I24: =IFERROR(H24/G24, "") -> -0.39041067
A25: Kohls - Waterbury | B25: CT | C25: =SUM(Jan!C25, Feb!C25, Mar!C25) -> 6175 | D25: =SUM(Jan!D25, Feb!D25, Mar!D25) -> 6085 | E25: =IF(AND(ISNUMBER(C25),ISNUMBER(D25)), C25-D25, "") -> 90 | F25: =IFERROR(E25/D25, "") -> 0.014790468 | G25: =SUM(Jan!G25, Feb!G25,Mar!G25) -> 15189.49 | H25: =SUM(Jan!H25, Feb!H25, Mar!H25) -> -9014.49 | I25: =IFERROR(H25/G25, "") -> -0.59346891
A26: Mojave Water Agency - Headquarters | B26: CA | C26: =SUM(Jan!C26, Feb!C26, Mar!C26) -> 26259 | D26: =SUM(Jan!D26, Feb!D26, Mar!D26) -> 26144 | E26: =IF(AND(ISNUMBER(C26),ISNUMBER(D26)), C26-D26, "") -> 115 | F26: =IFERROR(E26/D26, "") -> 0.0043987148 | G26: =SUM(Jan!G26, Feb!G26, Mar!G27) -> 25672.5 | H26: =SUM(Jan!H26, Feb!H26, Mar!H26) -> 586.5 | I26: =IFERROR(H26/G26, "") -> 0.022845457
A27: CSU - Bakersfield | B27: CA | C27: =SUM(Jan!C27, Feb!C27, Mar!C27) -> 61123 | D27: =SUM(Jan!D27, Feb!D27, Mar!D27) -> 60461 | E27: =IF(AND(ISNUMBER(C27),ISNUMBER(D27)), C27-D27, "") -> 662 | F27: =IFERROR(E27/D27, "") -> 0.010949207 | G27: =SUM(Jan!G27, Feb!G27,Mar!G27) -> 60206.76 | H27: =SUM(Jan!H27, Feb!H27, Mar!H27) -> 916.24 | I27: =IFERROR(H27/G27, "") -> 0.015218225
A28: Greenfield USD - Fairfield ES | B28: CA | C28: =SUM(Jan!C28, Feb!C28, Mar!C28) -> 6362 | D28: =SUM(Jan!D28, Feb!D28, Mar!D28) -> 6298 | E28: =IF(AND(ISNUMBER(C28),ISNUMBER(D28)), C28-D28, "") -> 64 | F28: =IFERROR(E28/D28, "") -> 0.010161956 | G28: =SUM(Jan!G28, Feb!G28, Mar!G29) -> 6700.67 | H28: =SUM(Jan!H28, Feb!H28, Mar!H28) -> -338.67 | I28: =IFERROR(H28/G28, "") -> -0.050542707
A29: Greenfield USD - Granite Point ES | B29: CA | C29: =SUM(Jan!C29, Feb!C29, Mar!C29) -> 20053 | D29: =SUM(Jan!D29, Feb!D29, Mar!D29) -> 19951 | E29: =IF(AND(ISNUMBER(C29),ISNUMBER(D29)), C29-D29, "") -> 102 | F29: =IFERROR(E29/D29, "") -> 0.0051125257 | G29: =SUM(Jan!G29, Feb!G29,Mar!G29) -> 17528.38 | H29: =SUM(Jan!H29, Feb!H29, Mar!H29) -> 2524.62 | I29: =IFERROR(H29/G29, "") -> 0.14403042
A30: Greenfield USD - Greenfield MS | B30: CA | C30: =SUM(Jan!C30, Feb!C30, Mar!C30) -> 8745 | D30: =SUM(Jan!D30, Feb!D30, Mar!D30) -> 8723 | E30: =IF(AND(ISNUMBER(C30),ISNUMBER(D30)), C30-D30, "") -> 22 | F30: =IFERROR(E30/D30, "") -> 0.0025220681 | G30: =SUM(Jan!G30, Feb!G30, Mar!G31) -> 12096.14 | H30: =SUM(Jan!H30, Feb!H30, Mar!H30) -> -3351.14 | I30: =IFERROR(H30/G30, "") -> -0.2770421
A31: Greenfield USD - Horizon ES | B31: CA | C31: =SUM(Jan!C31, Feb!C31, Mar!C31) -> 19976 | D31: =SUM(Jan!D31, Feb!D31, Mar!D31) -> 19760 | E31: =IF(AND(ISNUMBER(C31),ISNUMBER(D31)), C31-D31, "") -> 216 | F31: =IFERROR(E31/D31, "") -> 0.010931174 | G31: =SUM(Jan!G31, Feb!G31,Mar!G31) -> 17758.17 | H31: =SUM(Jan!H31, Feb!H31, Mar!H31) -> 2217.83 | I31: =IFERROR(H31/G31, "") -> 0.12489068
A32: Greenfield USD - McKee MS | B32: CA | C32: =SUM(Jan!C32, Feb!C32, Mar!C32) -> 5085 | D32: =SUM(Jan!D32, Feb!D32, Mar!D32) -> 3700 | E32: =IF(AND(ISNUMBER(C32),ISNUMBER(D32)), C32-D32, "") -> 1385 | F32: =IFERROR(E32/D32, "") -> 0.37432432 | G32: =SUM(Jan!G32, Feb!G32, Mar!G33) -> 10873.66 | H32: =SUM(Jan!H32, Feb!H32, Mar!H32) -> -5788.66 | I32: =IFERROR(H32/G32, "") -> -0.53235617
A33: Greenfield USD - Plantation ES | B33: CA | C33: =SUM(Jan!C33, Feb!C33, Mar!C33) -> 8003 | D33: =SUM(Jan!D33, Feb!D33, Mar!D33) -> 7982 | E33: =IF(AND(ISNUMBER(C33),ISNUMBER(D33)), C33-D33, "") -> 21 | F33: =IFERROR(E33/D33, "") -> 0.0026309196 | G33: =SUM(Jan!G33, Feb!G33,Mar!G33) -> 7785.28 | H33: =SUM(Jan!H33, Feb!H33, Mar!H33) -> 217.72 | I33: =IFERROR(H33/G33, "") -> 0.027965597
A34: Greenfield USD - Planz ES | B34: CA | C34: =SUM(Jan!C34, Feb!C34, Mar!C34) -> 8297 | D34: =SUM(Jan!D34, Feb!D34, Mar!D34) -> 8233 | E34: =IF(AND(ISNUMBER(C34),ISNUMBER(D34)), C34-D34, "") -> 64 | F34: =IFERROR(E34/D34, "") -> 0.0077735941 | G34: =SUM(Jan!G34, Feb!G34, Mar!G35) -> 8649.29 | H34: =SUM(Jan!H34, Feb!H34, Mar!H34) -> -352.29 | I34: =IFERROR(H34/G34, "") -> -0.040730511
A35: Greenfield USD - Raffaello Palla ES | B35: CA | C35: =SUM(Jan!C35, Feb!C35, Mar!C35) -> 17711 | D35: =SUM(Jan!D35, Feb!D35, Mar!D35) -> 17200 | E35: =IF(AND(ISNUMBER(C35),ISNUMBER(D35)), C35-D35, "") -> 511 | F35: =IFERROR(E35/D35, "") -> 0.029709302 | G35: =SUM(Jan!G35, Feb!G35,Mar!G35) -> 19651.64 | H35: =SUM(Jan!H35, Feb!H35, Mar!H35) -> -1940.64 | I35: =IFERROR(H35/G35, "") -> -0.098752063
A36: Greenfield USD - Valle Verde ES | B36: CA | C36: =SUM(Jan!C36, Feb!C36, Mar!C36) -> 11095 | D36: =SUM(Jan!D36, Feb!D36, Mar!D36) -> 11046 | E36: =IF(AND(ISNUMBER(C36),ISNUMBER(D36)), C36-D36, "") -> 49 | F36: =IFERROR(E36/D36, "") -> 0.0044359949 | G36: =SUM(Jan!G36, Feb!G36, Mar!G37) -> 18530.26 | H36: =SUM(Jan!H36, Feb!H36, Mar!H36) -> -7435.26 | I36: =IFERROR(H36/G36, "") -> -0.40124963
A37: Greenfield USD - W.A. Kendrick ES | B37: CA | C37: =SUM(Jan!C37, Feb!C37, Mar!C37) -> 7387 | D37: =SUM(Jan!D37, Feb!D37, Mar!D37) -> 0 | E37: =IF(AND(ISNUMBER(C37),ISNUMBER(D37)), C37-D37, "") -> 7387 | F37: =IFERROR(E37/D37, "") | G37: =SUM(Jan!G37, Feb!G37,Mar!G37) -> 7151.06 | H37: =SUM(Jan!H37, Feb!H37, Mar!H37) -> 235.94 | I37: =IFERROR(H37/G37, "") -> 0.03299371
A38: Muroc Joint USD - Boron HS | B38: CA | C38: =SUM(Jan!C38, Feb!C38, Mar!C38) -> 0 | D38: =SUM(Jan!D38, Feb!D38, Mar!D38) -> 0 | E38: =IF(AND(ISNUMBER(C38),ISNUMBER(D38)), C38-D38, "") -> 0 | F38: =IFERROR(E38/D38, "") | G38: =SUM(Jan!G38, Feb!G38, Mar!G39) -> 23447.83 | H38: =SUM(Jan!H38, Feb!H38, Mar!H38) -> -23447.83 | I38: =IFERROR(H38/G38, "") -> -1
A39: Muroc Joint USD - W. Boron ES | B39: CA | C39: =SUM(Jan!C39, Feb!C39, Mar!C39) -> 7080 | D39: =SUM(Jan!D39, Feb!D39, Mar!D39) -> 7052 | E39: =IF(AND(ISNUMBER(C39),ISNUMBER(D39)), C39-D39, "") -> 28 | F39: =IFERROR(E39/D39, "") -> 0.0039705048 | G39: =SUM(Jan!G39, Feb!G39,Mar!G39) -> 8694.49 | H39: =SUM(Jan!H39, Feb!H39, Mar!H39) -> -1614.49 | I39: =IFERROR(H39/G39, "") -> -0.18569117
A40: Colusa - WTP | B40: CA | C40: =SUM(Jan!C40, Feb!C40, Mar!C40) -> 14057 | D40: =SUM(Jan!D40, Feb!D40, Mar!D40) -> 0 | E40: =IF(AND(ISNUMBER(C40),ISNUMBER(D40)), C40-D40, "") -> 14057 | F40: =IFERROR(E40/D40, "") | G40: =SUM(Jan!G40, Feb!G40, Mar!G41) -> 0 | H40: =SUM(Jan!H40, Feb!H40, Mar!H40) -> 0 | I40: =IFERROR(H40/G40, "")
A41: CDCR-North Kern State Prision | B41: CA | C41: =SUM(Jan!C41, Feb!C41, Mar!C41) -> 62226 | D41: =SUM(Jan!D41, Feb!D41, Mar!D41) -> 61499 | E41: =IF(AND(ISNUMBER(C41),ISNUMBER(D41)), C41-D41, "") -> 727 | F41: =IFERROR(E41/D41, "") -> 0.01182133 | G41: =SUM(Jan!G41, Feb!G41,Mar!G41) -> 79757.61 | H41: =SUM(Jan!H41, Feb!H41, Mar!H41) -> -17531.61 | I41: =IFERROR(H41/G41, "") -> -0.21981113
A42: Muroc Joint USD - District Office | B42: CA | C42: =SUM(Jan!C42, Feb!C42, Mar!C42) -> 7120 | D42: =SUM(Jan!D42, Feb!D42, Mar!D42) -> 7105 | E42: =IF(AND(ISNUMBER(C42),ISNUMBER(D42)), C42-D42, "") -> 15 | F42: =IFERROR(E42/D42, "") -> 0.0021111893 | G42: =SUM(Jan!G42, Feb!G42, Mar!G43) -> 6135.9 | H42: =SUM(Jan!H42, Feb!H42, Mar!H42) -> 984.1 | I42: =IFERROR(H42/G42, "") -> 0.16038397
A43: Whole Foods - Manhattan Beach | B43: CA | C43: =SUM(Jan!C43, Feb!C43, Mar!C43) -> 13065 | D43: =SUM(Jan!D43, Feb!D43, Mar!D43) -> 13027 | E43: =IF(AND(ISNUMBER(C43),ISNUMBER(D43)), C43-D43, "") -> 38 | F43: =IFERROR(E43/D43, "") -> 0.0029170185 | G43: =SUM(Jan!G43, Feb!G43,Mar!G43) -> 13690.88 | H43: =SUM(Jan!H43, Feb!H43, Mar!H43) -> -625.88 | I43: =IFERROR(H43/G43, "") -> -0.045715104
A44: Pioneer USD - Frontier ES | B44: CA | C44: =SUM(Jan!C44, Feb!C44, Mar!C44) -> 2844 | D44: =SUM(Jan!D44, Feb!D44, Mar!D44) -> 0 | E44: =IF(AND(ISNUMBER(C44),ISNUMBER(D44)), C44-D44, "") -> 2844 | F44: =IFERROR(E44/D44, "") | G44: =SUM(Jan!G44, Feb!G44, Mar!G45) -> 11753.84 | H44: =SUM(Jan!H44, Feb!H44, Mar!H44) -> -8909.84 | I44: =IFERROR(H44/G44, "") -> -0.75803652
A45: Pioneer USD - Pioneer ES | B45: CA | C45: =SUM(Jan!C45, Feb!C45, Mar!C45) -> 12485 | D45: =SUM(Jan!D45, Feb!D45, Mar!D45) -> 0 | E45: =IF(AND(ISNUMBER(C45),ISNUMBER(D45)), C45-D45, "") -> 12485 | F45: =IFERROR(E45/D45, "") | G45: =SUM(Jan!G45, Feb!G45,Mar!G45) -> 11589.4 | H45: =SUM(Jan!H45, Feb!H45, Mar!H45) -> 895.6 | I45: =IFERROR(H45/G45, "") -> 0.077277512
...

Sheet 2nd Qtr
A1: {=portfolio} -> Silicon Ranch | D1: 2nd Quarter Actual v. Expected | G1: 2nd Quarter Actual v. Forecasted
A2: Total | C2: =SUM(C4:C100) -> 0 | D2: =SUM(D4:D100) -> 0 | E2: =C2-D2 -> 0 | F2: =IFERROR(E2/D2, 0) -> 0 | G2: =SUM(G4:G100) -> 0 | H2: =C2-G2 -> 0 | I2: =IFERROR(H2/G2, 0) -> 0
A3: Site | B3: State | C3: Actual | D3: Expected | E3: Delta | F3: % | G3: Forecasted | H3: Delta | I3: %
A4: {=Sites[Site]} -> Iron Mountain - Windsor | B4: {=Sites[State]} -> CT | C4: =SUM(Apr!C4, May!C4, Jun!C4) -> 0 | D4: =SUM(Apr!D4, May!D4, Jun!D4) -> 0 | E4: =IF(AND(ISNUMBER(C4),ISNUMBER(D4)), C4-D4, "") -> 0 | F4: =IFERROR(E4/D4, "") | G4: =SUM(Apr!G4, May!G4, Jun!G4) -> 0 | H4: =SUM(Apr!H4, May!H4, Jun!H4) -> 0 | I4: =IFERROR(H4/G4, "")
A5: Kohls - Auburn | B5: NY | C5: =SUM(Apr!C5, May!C5, Jun!C5) -> 0 | D5: =SUM(Apr!D5, May!D5, Jun!D5) -> 0 | E5: =IF(AND(ISNUMBER(C5),ISNUMBER(D5)), C5-D5, "") -> 0 | F5: =IFERROR(E5/D5, "") | G5: =SUM(Apr!G5, May!G5, Jun!G5) -> 0 | H5: =SUM(Apr!H5, May!H5, Jun!H5) -> 0 | I5: =IFERROR(H5/G5, "")
A6: Kohls - Bensalem | B6: PA | C6: =SUM(Apr!C6, May!C6, Jun!C6) -> 0 | D6: =SUM(Apr!D6, May!D6, Jun!D6) -> 0 | E6: =IF(AND(ISNUMBER(C6),ISNUMBER(D6)), C6-D6, "") -> 0 | F6: =IFERROR(E6/D6, "") | G6: =SUM(Apr!G6, May!G6, Jun!G6) -> 0 | H6: =SUM(Apr!H6, May!H6, Jun!H6) -> 0 | I6: =IFERROR(H6/G6, "")
A7: Kohls - Brick | B7: NJ | C7: =SUM(Apr!C7, May!C7, Jun!C7) -> 0 | D7: =SUM(Apr!D7, May!D7, Jun!D7) -> 0 | E7: =IF(AND(ISNUMBER(C7),ISNUMBER(D7)), C7-D7, "") -> 0 | F7: =IFERROR(E7/D7, "") | G7: =SUM(Apr!G7, May!G7, Jun!G7) -> 0 | H7: =SUM(Apr!H7, May!H7, Jun!H7) -> 0 | I7: =IFERROR(H7/G7, "")
A8: Kohls - Buffalo | B8: NY | C8: =SUM(Apr!C8, May!C8, Jun!C8) -> 0 | D8: =SUM(Apr!D8, May!D8, Jun!D8) -> 0 | E8: =IF(AND(ISNUMBER(C8),ISNUMBER(D8)), C8-D8, "") -> 0 | F8: =IFERROR(E8/D8, "") | G8: =SUM(Apr!G8, May!G8, Jun!G8) -> 0 | H8: =SUM(Apr!H8, May!H8, Jun!H8) -> 0 | I8: =IFERROR(H8/G8, "")
A9: Kohls - Canton | B9: CT | C9: =SUM(Apr!C9, May!C9, Jun!C9) -> 0 | D9: =SUM(Apr!D9, May!D9, Jun!D9) -> 0 | E9: =IF(AND(ISNUMBER(C9),ISNUMBER(D9)), C9-D9, "") -> 0 | F9: =IFERROR(E9/D9, "") | G9: =SUM(Apr!G9, May!G9, Jun!G9) -> 0 | H9: =SUM(Apr!H9, May!H9, Jun!H9) -> 0 | I9: =IFERROR(H9/G9, "")
A10: Kohls - East Amherst | B10: NY | C10: =SUM(Apr!C10, May!C10, Jun!C10) -> 0 | D10: =SUM(Apr!D10, May!D10, Jun!D10) -> 0 | E10: =IF(AND(ISNUMBER(C10),ISNUMBER(D10)), C10-D10, "") -> 0 | F10: =IFERROR(E10/D10, "") | G10: =SUM(Apr!G10, May!G10, Jun!G10) -> 0 | H10: =SUM(Apr!H10, May!H10, Jun!H10) -> 0 | I10: =IFERROR(H10/G10, "")
A11: Kohls - East Brunswick | B11: NJ | C11: =SUM(Apr!C11, May!C11, Jun!C11) -> 0 | D11: =SUM(Apr!D11, May!D11, Jun!D11) -> 0 | E11: =IF(AND(ISNUMBER(C11),ISNUMBER(D11)), C11-D11, "") -> 0 | F11: =IFERROR(E11/D11, "") | G11: =SUM(Apr!G11, May!G11, Jun!G11) -> 0 | H11: =SUM(Apr!H11, May!H11, Jun!H11) -> 0 | I11: =IFERROR(H11/G11, "")
A12: Kohls - Edgewood | B12: MD | C12: =SUM(Apr!C12, May!C12, Jun!C12) -> 0 | D12: =SUM(Apr!D12, May!D12, Jun!D12) -> 0 | E12: =IF(AND(ISNUMBER(C12),ISNUMBER(D12)), C12-D12, "") -> 0 | F12: =IFERROR(E12/D12, "") | G12: =SUM(Apr!G12, May!G12, Jun!G12) -> 0 | H12: =SUM(Apr!H12, May!H12, Jun!H12) -> 0 | I12: =IFERROR(H12/G12, "")
A13: Kohls - Granite Run | B13: PA | C13: =SUM(Apr!C13, May!C13, Jun!C13) -> 0 | D13: =SUM(Apr!D13, May!D13, Jun!D13) -> 0 | E13: =IF(AND(ISNUMBER(C13),ISNUMBER(D13)), C13-D13, "") -> 0 | F13: =IFERROR(E13/D13, "") | G13: =SUM(Apr!G13, May!G13, Jun!G13) -> 0 | H13: =SUM(Apr!H13, May!H13, Jun!H13) -> 0 | I13: =IFERROR(H13/G13, "")
A14: Kohls - Greece | B14: NY | C14: =SUM(Apr!C14, May!C14, Jun!C14) -> 0 | D14: =SUM(Apr!D14, May!D14, Jun!D14) -> 0 | E14: =IF(AND(ISNUMBER(C14),ISNUMBER(D14)), C14-D14, "") -> 0 | F14: =IFERROR(E14/D14, "") | G14: =SUM(Apr!G14, May!G14, Jun!G14) -> 0 | H14: =SUM(Apr!H14, May!H14, Jun!H14) -> 0 | I14: =IFERROR(H14/G14, "")
A15: Kohls - Hanover | B15: PA | C15: =SUM(Apr!C15, May!C15, Jun!C15) -> 0 | D15: =SUM(Apr!D15, May!D15, Jun!D15) -> 0 | E15: =IF(AND(ISNUMBER(C15),ISNUMBER(D15)), C15-D15, "") -> 0 | F15: =IFERROR(E15/D15, "") | G15: =SUM(Apr!G15, May!G15, Jun!G15) -> 0 | H15: =SUM(Apr!H15, May!H15, Jun!H15) -> 0 | I15: =IFERROR(H15/G15, "")
A16: Kohls - Horsehead | B16: NY | C16: =SUM(Apr!C16, May!C16, Jun!C16) -> 0 | D16: =SUM(Apr!D16, May!D16, Jun!D16) -> 0 | E16: =IF(AND(ISNUMBER(C16),ISNUMBER(D16)), C16-D16, "") -> 0 | F16: =IFERROR(E16/D16, "") | G16: =SUM(Apr!G16, May!G16, Jun!G16) -> 0 | H16: =SUM(Apr!H16, May!H16, Jun!H16) -> 0 | I16: =IFERROR(H16/G16, "")
... A69: CT: Torrington - 2-298 Rossi Road | B69: CT | C69: =SUM(Apr!C69, May!C69, Jun!C69) -> 0 | D69: =SUM(Apr!D69, May!D69, Jun!D69) -> 0 | E69: =IF(AND(ISNUMBER(C69),ISNUMBER(D69)), C69-D69, "") -> 0 | F69: =IFERROR(E69/D69, "") | G69: =SUM(Apr!G69, May!G69, Jun!G69) -> 0 | H69: =SUM(Apr!H69, May!H69, Jun!H69) -> 0 | I69: =IFERROR(H69/G69, "")

Sheet 3rd Qtr
A1: {=portfolio} -> Silicon Ranch | D1: 3rd Quarter Actual v. Expected | G1: 3rd Quarter Actual v. Forecasted
A2: Total | C2: =SUM(C4:C100) -> 0 | D2: =SUM(D4:D100) -> 0 | E2: =C2-D2 -> 0 | F2: =IFERROR(E2/D2, 0) -> 0 | G2: =SUM(G4:G100) -> 0 | H2: =C2-G2 -> 0 | I2: =IFERROR(H2/G2, 0) -> 0
A3: Site | B3: State | C3: Actual | D3: Expected | E3: Delta | F3: % | G3: Forecasted | H3: Delta | I3: %
A4: {=Sites[Site]} -> Iron Mountain - Windsor | B4: {=Sites[State]} -> CT | C4: =SUM(Jul!C4, Aug!C4, Sep!C4) -> 0 | D4: =SUM(Jul!D4, Aug!D4, Sep!D4) -> 0 | E4: =IF(AND(ISNUMBER(C4),ISNUMBER(D4)), C4-D4, "") -> 0 | F4: =IFERROR(E4/D4, "") | G4: =SUM(Jul!G4, Aug!G4, Sep!G4) -> 0 | H4: =SUM(Jul!H4, Aug!H4, Sep!H4) -> 0 | I4: =IFERROR(H4/G4, "")
A5: Kohls - Auburn | B5: NY | C5: =SUM(Jul!C5, Aug!C5, Sep!C5) -> 0 | D5: =SUM(Jul!D5, Aug!D5, Sep!D5) -> 0 | E5: =IF(AND(ISNUMBER(C5),ISNUMBER(D5)), C5-D5, "") -> 0 | F5: =IFERROR(E5/D5, "") | G5: =SUM(Jul!G5, Aug!G5, Sep!G5) -> 0 | H5: =SUM(Jul!H5, Aug!H5, Sep!H5) -> 0 | I5: =IFERROR(H5/G5, "")
A6: Kohls - Bensalem | B6: PA | C6: =SUM(Jul!C6, Aug!C6, Sep!C6) -> 0 | D6: =SUM(Jul!D6, Aug!D6, Sep!D6) -> 0 | E6: =IF(AND(ISNUMBER(C6),ISNUMBER(D6)), C6-D6, "") -> 0 | F6: =IFERROR(E6/D6, "") | G6: =SUM(Jul!G6, Aug!G6, Sep!G6) -> 0 | H6: =SUM(Jul!H6, Aug!H6, Sep!H6) -> 0 | I6: =IFERROR(H6/G6, "")
A7: Kohls - Brick | B7: NJ | C7: =SUM(Jul!C7, Aug!C7, Sep!C7) -> 0 | D7: =SUM(Jul!D7, Aug!D7, Sep!D7) -> 0 | E7: =IF(AND(ISNUMBER(C7),ISNUMBER(D7)), C7-D7, "") -> 0 | F7: =IFERROR(E7/D7, "") | G7: =SUM(Jul!G7, Aug!G7, Sep!G7) -> 0 | H7: =SUM(Jul!H7, Aug!H7, Sep!H7) -> 0 | I7: =IFERROR(H7/G7, "")
A8: Kohls - Buffalo | B8: NY | C8: =SUM(Jul!C8, Aug!C8, Sep!C8) -> 0 | D8: =SUM(Jul!D8, Aug!D8, Sep!D8) -> 0 | E8: =IF(AND(ISNUMBER(C8),ISNUMBER(D8)), C8-D8, "") -> 0 | F8: =IFERROR(E8/D8, "") | G8: =SUM(Jul!G8, Aug!G8, Sep!G8) -> 0 | H8: =SUM(Jul!H8, Aug!H8, Sep!H8) -> 0 | I8: =IFERROR(H8/G8, "")
A9: Kohls - Canton | B9: CT | C9: =SUM(Jul!C9, Aug!C9, Sep!C9) -> 0 | D9: =SUM(Jul!D9, Aug!D9, Sep!D9) -> 0 | E9: =IF(AND(ISNUMBER(C9),ISNUMBER(D9)), C9-D9, "") -> 0 | F9: =IFERROR(E9/D9, "") | G9: =SUM(Jul!G9, Aug!G9, Sep!G9) -> 0 | H9: =SUM(Jul!H9, Aug!H9, Sep!H9) -> 0 | I9: =IFERROR(H9/G9, "")
A10: Kohls - East Amherst | B10: NY | C10: =SUM(Jul!C10, Aug!C10, Sep!C10) -> 0 | D10: =SUM(Jul!D10, Aug!D10, Sep!D10) -> 0 | E10: =IF(AND(ISNUMBER(C10),ISNUMBER(D10)), C10-D10, "") -> 0 | F10: =IFERROR(E10/D10, "") | G10: =SUM(Jul!G10, Aug!G10, Sep!G10) -> 0 | H10: =SUM(Jul!H10, Aug!H10, Sep!H10) -> 0 | I10: =IFERROR(H10/G10, "")
A11: Kohls - East Brunswick | B11: NJ | C11: =SUM(Jul!C11, Aug!C11, Sep!C11) -> 0 | D11: =SUM(Jul!D11, Aug!D11, Sep!D11) -> 0 | E11: =IF(AND(ISNUMBER(C11),ISNUMBER(D11)), C11-D11, "") -> 0 | F11: =IFERROR(E11/D11, "") | G11: =SUM(Jul!G11, Aug!G11, Sep!G11) -> 0 | H11: =SUM(Jul!H11, Aug!H11, Sep!H11) -> 0 | I11: =IFERROR(H11/G11, "")
A12: Kohls - Edgewood | B12: MD | C12: =SUM(Jul!C12, Aug!C12, Sep!C12) -> 0 | D12: =SUM(Jul!D12, Aug!D12, Sep!D12) -> 0 | E12: =IF(AND(ISNUMBER(C12),ISNUMBER(D12)), C12-D12, "") -> 0 | F12: =IFERROR(E12/D12, "") | G12: =SUM(Jul!G12, Aug!G12, Sep!G12) -> 0 | H12: =SUM(Jul!H12, Aug!H12, Sep!H12) -> 0 | I12: =IFERROR(H12/G12, "")
A13: Kohls - Granite Run | B13: PA | C13: =SUM(Jul!C13, Aug!C13, Sep!C13) -> 0 | D13: =SUM(Jul!D13, Aug!D13, Sep!D13) -> 0 | E13: =IF(AND(ISNUMBER(C13),ISNUMBER(D13)), C13-D13, "") -> 0 | F13: =IFERROR(E13/D13, "") | G13: =SUM(Jul!G13, Aug!G13, Sep!G13) -> 0 | H13: =SUM(Jul!H13, Aug!H13, Sep!H13) -> 0 | I13: =IFERROR(H13/G13, "")
A14: Kohls - Greece | B14: NY | C14: =SUM(Jul!C14, Aug!C14, Sep!C14) -> 0 | D14: =SUM(Jul!D14, Aug!D14, Sep!D14) -> 0 | E14: =IF(AND(ISNUMBER(C14),ISNUMBER(D14)), C14-D14, "") -> 0 | F14: =IFERROR(E14/D14, "") | G14: =SUM(Jul!G14, Aug!G14, Sep!G14) -> 0 | H14: =SUM(Jul!H14, Aug!H14, Sep!H14) -> 0 | I14: =IFERROR(H14/G14, "")
A15: Kohls - Hanover | B15: PA | C15: =SUM(Jul!C15, Aug!C15, Sep!C15) -> 0 | D15: =SUM(Jul!D15, Aug!D15, Sep!D15) -> 0 | E15: =IF(AND(ISNUMBER(C15),ISNUMBER(D15)), C15-D15, "") -> 0 | F15: =IFERROR(E15/D15, "") | G15: =SUM(Jul!G15, Aug!G15, Sep!G15) -> 0 | H15: =SUM(Jul!H15, Aug!H15, Sep!H15) -> 0 | I15: =IFERROR(H15/G15, "")
A16: Kohls - Horsehead | B16: NY | C16: =SUM(Jul!C16, Aug!C16, Sep!C16) -> 0 | D16: =SUM(Jul!D16, Aug!D16, Sep!D16) -> 0 | E16: =IF(AND(ISNUMBER(C16),ISNUMBER(D16)), C16-D16, "") -> 0 | F16: =IFERROR(E16/D16, "") | G16: =SUM(Jul!G16, Aug!G16, Sep!G16) -> 0 | H16: =SUM(Jul!H16, Aug!H16, Sep!H16) -> 0 | I16: =IFERROR(H16/G16, "")
... A37: Greenfield USD - W.A. Kendrick ES | B37: CA | C37: =SUM(Jul!C37, Aug!C37, Sep!C37) -> 0 | D37: =SUM(Jul!D37, Aug!D37, Sep!D37) -> 0 | E37: =IF(AND(ISNUMBER(C37),ISNUMBER(D37)), C37-D37, "") -> 0 | F37: =IFERROR(E37/D37, "") | G37: =SUM(Jul!G37, Aug!G37, Sep!G37) -> 0 | H37: =SUM(Jul!H37, Aug!H37, Sep!H37) -> 0 | I37: =IFERROR(H37/G37, "")
A38: Muroc Joint USD - Boron HS | B38: CA | C38: =SUM(Jul!B38, Aug!C38, Sep!C38) -> 0 | D38: =SUM(Jul!D38, Aug!D38, Sep!D38) -> 0 | E38: =IF(AND(ISNUMBER(C38),ISNUMBER(D38)), C38-D38, "") -> 0 | F38: =IFERROR(E38/D38, "") | G38: =SUM(Jul!G38, Aug!G38, Sep!G38) -> 0 | H38: =SUM(Jul!H38, Aug!H38, Sep!H38) -> 0 | I38: =IFERROR(H38/G38, "")
A39: Muroc Joint USD - W. Boron ES | B39: CA | C39: =SUM(Jul!C39, Aug!C39, Sep!C39) -> 0 | D39: =SUM(Jul!D39, Aug!D39, Sep!D39) -> 0 | E39: =IF(AND(ISNUMBER(C39),ISNUMBER(D39)), C39-D39, "") -> 0 | F39: =IFERROR(E39/D39, "") | G39: =SUM(Jul!G39, Aug!G39, Sep!G39) -> 0 | H39: =SUM(Jul!H39, Aug!H39, Sep!H39) -> 0 | I39: =IFERROR(H39/G39, "")
A40: Colusa - WTP | B40: CA | C40: =SUM(Jul!C40, Aug!C40, Sep!C40) -> 0 | D40: =SUM(Jul!D40, Aug!D40, Sep!D40) -> 0 | E40: =IF(AND(ISNUMBER(C40),ISNUMBER(D40)), C40-D40, "") -> 0 | F40: =IFERROR(E40/D40, "") | G40: =SUM(Jul!G40, Aug!G40, Sep!G40) -> 0 | H40: =SUM(Jul!H40, Aug!H40, Sep!H40) -> 0 | I40: =IFERROR(H40/G40, "")
A41: CDCR-North Kern State Prision | B41: CA | C41: =SUM(Jul!C41, Aug!C41, Sep!C41) -> 0 | D41: =SUM(Jul!D41, Aug!D41, Sep!D41) -> 0 | E41: =IF(AND(ISNUMBER(C41),ISNUMBER(D41)), C41-D41, "") -> 0 | F41: =IFERROR(E41/D41, "") | G41: =SUM(Jul!G41, Aug!G41, Sep!G41) -> 0 | H41: =SUM(Jul!H41, Aug!H41, Sep!H41) -> 0 | I41: =IFERROR(H41/G41, "")
A42: Muroc Joint USD - District Office | B42: CA | C42: =SUM(Jul!C42, Aug!C42, Sep!C42) -> 0 | D42: =SUM(Jul!D42, Aug!D42, Sep!D42) -> 0 | E42: =IF(AND(ISNUMBER(C42),ISNUMBER(D42)), C42-D42, "") -> 0 | F42: =IFERROR(E42/D42, "") | G42: =SUM(Jul!G42, Aug!G42, Sep!G42) -> 0 | H42: =SUM(Jul!H42, Aug!H42, Sep!H42) -> 0 | I42: =IFERROR(H42/G42, "")
A43: Whole Foods - Manhattan Beach | B43: CA | C43: =SUM(Jul!C43, Aug!C43, Sep!C43) -> 0 | D43: =SUM(Jul!D43, Aug!D43, Sep!D43) -> 0 | E43: =IF(AND(ISNUMBER(C43),ISNUMBER(D43)), C43-D43, "") -> 0 | F43: =IFERROR(E43/D43, "") | G43: =SUM(Jul!G43, Aug!G43, Sep!G43) -> 0 | H43: =SUM(Jul!H43, Aug!H43, Sep!H43) -> 0 | I43: =IFERROR(H43/G43, "")
A44: Pioneer USD - Frontier ES | B44: CA | C44: =SUM(Jul!C44, Aug!C44, Sep!C44) -> 0 | D44: =SUM(Jul!D44, Aug!D44, Sep!D44) -> 0 | E44: =IF(AND(ISNUMBER(C44),ISNUMBER(D44)), C44-D44, "") -> 0 | F44: =IFERROR(E44/D44, "") | G44: =SUM(Jul!G44, Aug!G44, Sep!G44) -> 0 | H44: =SUM(Jul!H44, Aug!H44, Sep!H44) -> 0 | I44: =IFERROR(H44/G44, "")
A45: Pioneer USD - Pioneer ES | B45: CA | C45: =SUM(Jul!C45, Aug!C45, Sep!C45) -> 0 | D45: =SUM(Jul!D45, Aug!D45, Sep!D45) -> 0 | E45: =IF(AND(ISNUMBER(C45),ISNUMBER(D45)), C45-D45, "") -> 0 | F45: =IFERROR(E45/D45, "") | G45: =SUM(Jul!G45, Aug!G45, Sep!G45) -> 0 | H45: =SUM(Jul!H45, Aug!H45, Sep!H45) -> 0 | I45: =IFERROR(H45/G45, "")
A46: Pioneer USD - Pioneer MS | B46: CA | C46: =SUM(Jul!C46, Aug!C46, Sep!C46) -> 0 | D46: =SUM(Jul!D46, Aug!D46, Sep!D46) -> 0 | E46: =IF(AND(ISNUMBER(C46),ISNUMBER(D46)), C46-D46, "") -> 0 | F46: =IFERROR(E46/D46, "") | G46: =SUM(Jul!G46, Aug!G46, Sep!G46) -> 0 | H46: =SUM(Jul!H46, Aug!H46, Sep!H46) -> 0 | I46: =IFERROR(H46/G46, "")
A47: Kingsburg Joint UHSD - Kingsburg HS | B47: CA | C47: =SUM(Jul!C47, Aug!C47, Sep!C47) -> 0 | D47: =SUM(Jul!D47, Aug!D47, Sep!D47) -> 0 | E47: =IF(AND(ISNUMBER(C47),ISNUMBER(D47)), C47-D47, "") -> 0 | F47: =IFERROR(E47/D47, "") | G47: =SUM(Jul!G47, Aug!G47, Sep!G47) -> 0 | H47: =SUM(Jul!H47, Aug!H47, Sep!H47) -> 0 | I47: =IFERROR(H47/G47, "")
A48: CADRB | B48: CA | C48: =SUM(Jul!C48, Aug!C48, Sep!C48) -> 0 | D48: =SUM(Jul!D48, Aug!D48, Sep!D48) -> 0 | E48: =IF(AND(ISNUMBER(C48),ISNUMBER(D48)), C48-D48, "") -> 0 | F48: =IFERROR(E48/D48, "") | G48: =SUM(Jul!G48, Aug!G48, Sep!G48) -> 0 | H48: =SUM(Jul!H48, Aug!H48, Sep!H48) -> 0 | I48: =IFERROR(H48/G48, "")
A49: CDCR-CA State Prison LA County | B49: CA | C49: =SUM(Jul!C49, Aug!C49, Sep!C49) -> 0 | D49: =SUM(Jul!D49, Aug!D49, Sep!D49) -> 0 | E49: =IF(AND(ISNUMBER(C49),ISNUMBER(D49)), C49-D49, "") -> 0 | F49: =IFERROR(E49/D49, "") | G49: =SUM(Jul!G49, Aug!G49, Sep!G49) -> 0 | H49: =SUM(Jul!H49, Aug!H49, Sep!H49) -> 0 | I49: =IFERROR(H49/G49, "")
A50: Central USD Akers ES | B50: CA | C50: =SUM(Jul!C50, Aug!C50, Sep!C50) -> 0 | D50: =SUM(Jul!D50, Aug!D50, Sep!D50) -> 0 | E50: =IF(AND(ISNUMBER(C50),ISNUMBER(D50)), C50-D50, "") -> 0 | F50: =IFERROR(E50/D50, "") | G50: =SUM(Jul!G50, Aug!G50, Sep!G50) -> 0 | H50: =SUM(Jul!H50, Aug!H50, Sep!H50) -> 0 | I50: =IFERROR(H50/G50, "")
... A69: CT: Torrington - 2-298 Rossi Road | B69: CT | C69: =SUM(Jul!C69, Aug!C69, Sep!C69) -> 0 | D69: =SUM(Jul!D69, Aug!D69, Sep!D69) -> 0 | E69: =IF(AND(ISNUMBER(C69),ISNUMBER(D69)), C69-D69, "") -> 0 | F69: =IFERROR(E69/D69, "") | G69: =SUM(Jul!G69, Aug!G69, Sep!G69) -> 0 | H69: =SUM(Jul!H69, Aug!H69, Sep!H69) -> 0 | I69: =IFERROR(H69/G69, "")
E70: =IF(AND(ISNUMBER(C70),ISNUMBER(D70)), C70-D70, "") | F70: =IFERROR(E70/D70, "") | G70: =SUM(Jul!G70, Aug!G70, Sep!G70) -> 0 | H70: =SUM(Jul!H70, Aug!H70, Sep!H70) -> 0 | I70: =IFERROR(H70/G70, "")

Sheet 4th Qtr
A1: {=portfolio} -> Silicon Ranch | D1: 4th Quarter Actual v. Expected | G1: 4th Quarter Actual v. Forecasted
A2: Total | C2: =SUM(C4:C100) -> 0 | D2: =SUM(D4:D100) -> 0 | E2: =C2-D2 -> 0 | F2: =IFERROR(E2/D2, 0) -> 0 | G2: =SUM(G4:G100) -> 0 | H2: =C2-G2 -> 0 | I2: =IFERROR(H2/G2, 0) -> 0
A3: Site | B3: State | C3: Actual | D3: Expected | E3: Delta | F3: % | G3: Forecasted | H3: Delta | I3: %
A4: {=Sites[Site]} -> Iron Mountain - Windsor | B4: {=Sites[State]} -> CT | C4: =SUM(Oct!C4, Nov!C4, Dec!C4) -> 0 | D4: =SUM(Oct!D4, Nov!D4, Dec!D4) -> 0 | E4: =IF(AND(ISNUMBER(C4),ISNUMBER(D4)), C4-D4, "") -> 0 | F4: =IFERROR(E4/D4, "") | G4: =SUM(Oct!G4,Nov!G4,Dec!G4) -> 0 | H4: =SUM(Oct!H4, Nov!H4, Dec!H4) -> 0 | I4: =IFERROR(H4/G4, "")
A5: Kohls - Auburn | B5: NY | C5: =SUM(Oct!C5, Nov!C5, Dec!C5) -> 0 | D5: =SUM(Oct!D5, Nov!D5, Dec!D5) -> 0 | E5: =IF(AND(ISNUMBER(C5),ISNUMBER(D5)), C5-D5, "") -> 0 | F5: =IFERROR(E5/D5, "") | G5: =SUM(Oct!G5,Nov!G5,Dec!G5) -> 0 | H5: =SUM(Oct!H5, Nov!H5, Dec!H5) -> 0 | I5: =IFERROR(H5/G5, "")
A6: Kohls - Bensalem | B6: PA | C6: =SUM(Oct!C6, Nov!C6, Dec!C6) -> 0 | D6: =SUM(Oct!D6, Nov!D6, Dec!D6) -> 0 | E6: =IF(AND(ISNUMBER(C6),ISNUMBER(D6)), C6-D6, "") -> 0 | F6: =IFERROR(E6/D6, "") | G6: =SUM(Oct!G6,Nov!G6,Dec!G6) -> 0 | H6: =SUM(Oct!H6, Nov!H6, Dec!H6) -> 0 | I6: =IFERROR(H6/G6, "")
A7: Kohls - Brick | B7: NJ | C7: =SUM(Oct!C7, Nov!C7, Dec!C7) -> 0 | D7: =SUM(Oct!D7, Nov!D7, Dec!D7) -> 0 | E7: =IF(AND(ISNUMBER(C7),ISNUMBER(D7)), C7-D7, "") -> 0 | F7: =IFERROR(E7/D7, "") | G7: =SUM(Oct!G7,Nov!G7,Dec!G7) -> 0 | H7: =SUM(Oct!H7, Nov!H7, Dec!H7) -> 0 | I7: =IFERROR(H7/G7, "")
A8: Kohls - Buffalo | B8: NY | C8: =SUM(Oct!C8, Nov!C8, Dec!C8) -> 0 | D8: =SUM(Oct!D8, Nov!D8, Dec!D8) -> 0 | E8: =IF(AND(ISNUMBER(C8),ISNUMBER(D8)), C8-D8, "") -> 0 | F8: =IFERROR(E8/D8, "") | G8: =SUM(Oct!G8,Nov!G8,Dec!G8) -> 0 | H8: =SUM(Oct!H8, Nov!H8, Dec!H8) -> 0 | I8: =IFERROR(H8/G8, "")
A9: Kohls - Canton | B9: CT | C9: =SUM(Oct!C9, Nov!C9, Dec!C9) -> 0 | D9: =SUM(Oct!D9, Nov!D9, Dec!D9) -> 0 | E9: =IF(AND(ISNUMBER(C9),ISNUMBER(D9)), C9-D9, "") -> 0 | F9: =IFERROR(E9/D9, "") | G9: =SUM(Oct!G9,Nov!G9,Dec!G9) -> 0 | H9: =SUM(Oct!H9, Nov!H9, Dec!H9) -> 0 | I9: =IFERROR(H9/G9, "")
A10: Kohls - East Amherst | B10: NY | C10: =SUM(Oct!C10, Nov!C10, Dec!C10) -> 0 | D10: =SUM(Oct!D10, Nov!D10, Dec!D10) -> 0 | E10: =IF(AND(ISNUMBER(C10),ISNUMBER(D10)), C10-D10, "") -> 0 | F10: =IFERROR(E10/D10, "") | G10: =SUM(Oct!G10,Nov!G10,Dec!G10) -> 0 | H10: =SUM(Oct!H10, Nov!H10, Dec!H10) -> 0 | I10: =IFERROR(H10/G10, "")
A11: Kohls - East Brunswick | B11: NJ | C11: =SUM(Oct!C11, Nov!C11, Dec!C11) -> 0 | D11: =SUM(Oct!D11, Nov!D11, Dec!D11) -> 0 | E11: =IF(AND(ISNUMBER(C11),ISNUMBER(D11)), C11-D11, "") -> 0 | F11: =IFERROR(E11/D11, "") | G11: =SUM(Oct!G11,Nov!G11,Dec!G11) -> 0 | H11: =SUM(Oct!H11, Nov!H11, Dec!H11) -> 0 | I11: =IFERROR(H11/G11, "")
A12: Kohls - Edgewood | B12: MD | C12: =SUM(Oct!C12, Nov!C12, Dec!C12) -> 0 | D12: =SUM(Oct!D12, Nov!D12, Dec!D12) -> 0 | E12: =IF(AND(ISNUMBER(C12),ISNUMBER(D12)), C12-D12, "") -> 0 | F12: =IFERROR(E12/D12, "") | G12: =SUM(Oct!G12,Nov!G12,Dec!G12) -> 0 | H12: =SUM(Oct!H12, Nov!H12, Dec!H12) -> 0 | I12: =IFERROR(H12/G12, "")
A13: Kohls - Granite Run | B13: PA | C13: =SUM(Oct!C13, Nov!C13, Dec!C13) -> 0 | D13: =SUM(Oct!D13, Nov!D13, Dec!D13) -> 0 | E13: =IF(AND(ISNUMBER(C13),ISNUMBER(D13)), C13-D13, "") -> 0 | F13: =IFERROR(E13/D13, "") | G13: =SUM(Oct!G13,Nov!G13,Dec!G13) -> 0 | H13: =SUM(Oct!H13, Nov!H13, Dec!H13) -> 0 | I13: =IFERROR(H13/G13, "")
A14: Kohls - Greece | B14: NY | C14: =SUM(Oct!C14, Nov!C14, Dec!C14) -> 0 | D14: =SUM(Oct!D14, Nov!D14, Dec!D14) -> 0 | E14: =IF(AND(ISNUMBER(C14),ISNUMBER(D14)), C14-D14, "") -> 0 | F14: =IFERROR(E14/D14, "") | G14: =SUM(Oct!G14,Nov!G14,Dec!G14) -> 0 | H14: =SUM(Oct!H14, Nov!H14, Dec!H14) -> 0 | I14: =IFERROR(H14/G14, "")
A15: Kohls - Hanover | B15: PA | C15: =SUM(Oct!C15, Nov!C15, Dec!C15) -> 0 | D15: =SUM(Oct!D15, Nov!D15, Dec!D15) -> 0 | E15: =IF(AND(ISNUMBER(C15),ISNUMBER(D15)), C15-D15, "") -> 0 | F15: =IFERROR(E15/D15, "") | G15: =SUM(Oct!G15,Nov!G15,Dec!G15) -> 0 | H15: =SUM(Oct!H15, Nov!H15, Dec!H15) -> 0 | I15: =IFERROR(H15/G15, "")
A16: Kohls - Horsehead | B16: NY | C16: =SUM(Oct!C16, Nov!C16, Dec!C16) -> 0 | D16: =SUM(Oct!D16, Nov!D16, Dec!D16) -> 0 | E16: =IF(AND(ISNUMBER(C16),ISNUMBER(D16)), C16-D16, "") -> 0 | F16: =IFERROR(E16/D16, "") | G16: =SUM(Oct!G16,Nov!G16,Dec!G16) -> 0 | H16: =SUM(Oct!H16, Nov!H16, Dec!H16) -> 0 | I16: =IFERROR(H16/G16, "")
... A69: CT: Torrington - 2-298 Rossi Road | B69: CT | C69: =SUM(Oct!C69, Nov!C69, Dec!C69) -> 0 | D69: =SUM(Oct!D69, Nov!D69, Dec!D69) -> 0 | E69: =IF(AND(ISNUMBER(C69),ISNUMBER(D69)), C69-D69, "") -> 0 | F69: =IFERROR(E69/D69, "") | G69: =SUM(Oct!G69,Nov!G69,Dec!G69) -> 0 | H69: =SUM(Oct!H69, Nov!H69, Dec!H69) -> 0 | I69: =IFERROR(H69/G69, "")
C70: =SUM(Oct!C70, Nov!C70, Dec!C70) -> 0 | D70: =SUM(Oct!D70, Nov!D70, Dec!D70) -> 0 | E70: =IF(AND(ISNUMBER(C70),ISNUMBER(D70)), C70-D70, "") -> 0 | F70: =IFERROR(E70/D70, "") | G70: =SUM(Oct!G70,Nov!G70,Dec!G70) -> 0 | H70: =SUM(Oct!H70, Nov!H70, Dec!H70) -> 0 | I70: =IFERROR(H70/G70, "")

Sheet Jan
A1: {=portfolio} -> Silicon Ranch | D1: January Actual v. Expected | G1: January Actual v. Forecasted
A2: Total | C2: =SUM(C4:C98) -> 1984478.1 | D2: =SUM(D4:D98) -> 1107350 | E2: =C2-D2 -> 877128.15 | F2: =IFERROR(E2/D2, 0) -> 0.79209658 | G2: =SUM(G4:G98) -> 1915460.7 | H2: =C2-G2 -> 69017.41 | I2: =IFERROR(H2/G2, 0) -> 0.036031754 | J2: =IF(AND(TODAY()>DATE(2024, 1, 1), COUNTA(Sites[Site])<>(COUNT(C:C)-1)), "Some sites are missing actual data; if new sites were added, make sure they are aligned correctly (including prior months!)", "")
A3: Site | B3: State | C3: Actual | D3: Expected | E3: Delta | F3: % | G3: Forecasted | H3: Delta | I3: % | J3: Notes | K3: Service Requests | L3: Status
A4: {=Sites[Site]} -> Iron Mountain - Windsor | B4: {=Sites[State]} -> CT | C4: 6816 | D4: 6764 | E4: =IF(AND(ISNUMBER(C4),ISNUMBER(D4)), C4-D4, "") -> 52 | F4: =IFERROR(E4/D4, "") -> 0.0076877587 | G4: 12840.66 | H4: =IF(AND(ISNUMBER(C4),ISNUMBER(G4)), C4-G4, "") -> -6024.66 | I4: =IFERROR(H4/G4, "") -> -0.46918616 | J4: 1. Site production was low on 01/17 to 01/22, 01/25 to 01/27 due to snow.
A5: Kohls - Auburn | B5: NY | C5: 645 | D5: 645 | E5: =IF(AND(ISNUMBER(C5),ISNUMBER(D5)), C5-D5, "") -> 0 | F5: =IFERROR(E5/D5, "") -> 0 | G5: 4715.29 | H5: =IF(AND(ISNUMBER(C5),ISNUMBER(G5)), C5-G5, "") -> -4070.29 | I5: =IFERROR(H5/G5, "") -> -0.86321096 | J5: 1. Site was barely producing from 01/12 to 01/22 and was offline from 01/25 to 01/27 due to snow.
A6: Kohls - Bensalem | B6: PA | C6: 10621 | D6: 0 | E6: =IF(AND(ISNUMBER(C6),ISNUMBER(D6)), C6-D6, "") -> 10621 | F6: =IFERROR(E6/D6, "") | G6: 15534.61 | H6: =IF(AND(ISNUMBER(C6),ISNUMBER(G6)), C6-G6, "") -> -4913.61 | I6: =IFERROR(H6/G6, "") -> -0.31630083 | J6: 1.Meter was not communicated for whole month but production can be verified at interver 2. Inverter was offline from 11:00 on 01/17 to end of the month due to snow. | K6: 1. SR111409 2. SR114708 | L6: 1.pending 2. Pending | M6: SR114708
A7: Kohls - Brick | B7: NJ | C7: 12552 | D7: 12511 | E7: =IF(AND(ISNUMBER(C7),ISNUMBER(D7)), C7-D7, "") -> 41 | F7: =IFERROR(E7/D7, "") -> 0.0032771161 | G7: 16463.56 | H7: =IF(AND(ISNUMBER(C7),ISNUMBER(G7)), C7-G7, "") -> -3911.56 | I7: =IFERROR(H7/G7, "") -> -0.23758895 | J7: 1. Site production was low from 01/25 to end of the month due to snow. 2. Inverter was offline from 09:40 to 10:40 on 01/02. | K7: 1. SR113990 | L7: 1. Closed
A8: Kohls - Buffalo | B8: NY | C8: 3229 | D8: 0 | E8: =IF(AND(ISNUMBER(C8),ISNUMBER(D8)), C8-D8, "") -> 3229 | F8: =IFERROR(E8/D8, "") | G8: 7932.35 | H8: =IF(AND(ISNUMBER(C8),ISNUMBER(G8)), C8-G8, "") -> -4703.35 | I8: =IFERROR(H8/G8, "") -> -0.59293274 | J8: 1. Site production was low on 01/04, 01/05, 01/07,01/11,01/15,01/22, 01/29,01/30due to snow.
A9: Kohls - Canton | B9: CT | C9: 1564 | D9: 1330 | E9: =IF(AND(ISNUMBER(C9),ISNUMBER(D9)), C9-D9, "") -> 234 | F9: =IFERROR(E9/D9, "") -> 0.17593985 | G9: 5755.92 | H9: =IF(AND(ISNUMBER(C9),ISNUMBER(G9)), C9-G9, "") -> -4191.92 | I9: =IFERROR(H9/G9, "") -> -0.72827975 | J9: 1. Site was not communicated from 01:40 on 01/15 to end of the month. | K9: 1. SR114652 | L9: 1. Work in progress
A10: Kohls - East Amherst | B10: NY | C10: 1721 | D10: 1585 | E10: =IF(AND(ISNUMBER(C10),ISNUMBER(D10)), C10-D10, "") -> 136 | F10: =IFERROR(E10/D10, "") -> 0.085804416 | G10: 8364.35 | H10: =IF(AND(ISNUMBER(C10),ISNUMBER(G10)), C10-G10, "") -> -6643.35 | I10: =IFERROR(H10/G10, "") -> -0.79424582 | J10: 1. Site production was low most of the days in month due to snow
A11: Kohls - East Brunswick | B11: NJ | C11: 13312.05 | D11: 0 | E11: =IF(AND(ISNUMBER(C11),ISNUMBER(D11)), C11-D11, "") -> 13312.05 | F11: =IFERROR(E11/D11, "") | G11: 22969.47 | H11: =IF(AND(ISNUMBER(C11),ISNUMBER(G11)), C11-G11, "") -> -9657.42 | I11: =IFERROR(H11/G11, "") -> -0.42044592 | J11: 1. Meter was not communicated for whole month but production can be verified at interver 2. Inverter was offline from 01/25 to end of the month due to snow. | K11: 1.SR108676 | L11: 1.pending
A12: Kohls - Edgewood | B12: MD | C12: 69205 | D12: 68059 | E12: =IF(AND(ISNUMBER(C12),ISNUMBER(D12)), C12-D12, "") -> 1146 | F12: =IFERROR(E12/D12, "") -> 0.016838331 | G12: 134337.97 | H12: =IF(AND(ISNUMBER(C12),ISNUMBER(G12)), C12-G12, "") -> -65132.97 | I12: =IFERROR(H12/G12, "") -> -0.48484408 | J12: 1. Meter 3 stopped communicating at 16:23 from 06/23 but production can be verified at inverter level. Meter has failed and needs to be replaced. Due to this the overall meter is reporting 200kW down than the produced value. 2. Site production was low on 01/25 to end of the month due to snow. | K12: 1. SR107924 | L12: 1.Deined
A13: Kohls - Granite Run | B13: PA | C13: 9634 | D13: 9462 | E13: =IF(AND(ISNUMBER(C13),ISNUMBER(D13)), C13-D13, "") -> 172 | F13: =IFERROR(E13/D13, "") -> 0.018177975 | G13: 15797.45 | H13: =IF(AND(ISNUMBER(C13),ISNUMBER(G13)), C13-G13, "") -> -6163.45 | I13: =IFERROR(H13/G13, "") -> -0.39015474 | J13: 1. Site production was low on 01/25 to end of the month due to snow.
A14: Kohls - Greece | B14: NY | C14: 2440 | D14: 2296 | E14: =IF(AND(ISNUMBER(C14),ISNUMBER(D14)), C14-D14, "") -> 144 | F14: =IFERROR(E14/D14, "") -> 0.06271777 | G14: 9292.71 | H14: =IF(AND(ISNUMBER(C14),ISNUMBER(G14)), C14-G14, "") -> -6852.71 | I14: =IFERROR(H14/G14, "") -> -0.73742859 | J14: 1. Site production was low on 01/25 to end of the month due to snow.
A15: Kohls - Hanover | B15: PA | C15: 13956 | D15: 13682 | E15: =IF(AND(ISNUMBER(C15),ISNUMBER(D15)), C15-D15, "") -> 274 | F15: =IFERROR(E15/D15, "") -> 0.020026312 | G15: 18615.25 | H15: =IF(AND(ISNUMBER(C15),ISNUMBER(G15)), C15-G15, "") -> -4659.25 | I15: =IFERROR(H15/G15, "") -> -0.2502921 | J15: 1. Site production was low on 01/17 to 01/22, 01/25 to 01/27 due to snow.
A16: Kohls - Horsehead | B16: NY | C16: 7602 | D16: 7428 | E16: =IF(AND(ISNUMBER(C16),ISNUMBER(D16)), C16-D16, "") -> 174 | F16: =IFERROR(E16/D16, "") -> 0.023424879 | G16: 12592.49 | H16: =IF(AND(ISNUMBER(C16),ISNUMBER(G16)), C16-G16, "") -> -4990.49 | I16: =IFERROR(H16/G16, "") -> -0.39630685 | J16: 1. Site production was low on 01/25 to end of the month due to snow. 2. Inverter started late for production on 01/17 at 09:10. | K16: 2. SR095654 | L16: 1. closed
A17: Kohls - Hudson | B17: NY | C17: 5478 | D17: 0 | E17: =IF(AND(ISNUMBER(C17),ISNUMBER(D17)), C17-D17, "") -> 5478 | F17: =IFERROR(E17/D17, "") | G17: 12675.21 | H17: =IF(AND(ISNUMBER(C17),ISNUMBER(G17)), C17-G17, "") -> -7197.21 | I17: =IFERROR(H17/G17, "") -> -0.56781781 | J17: 1. Meter was not communicated for whole month but production can be verified at interver 2. Site production was low on 01/25 to end of the month due to snow. | K17: 1. SR103499 | L17: 1.closed
A18: Kohls - Ithaca | B18: NY | C18: 5406 | D18: 5279 | E18: =IF(AND(ISNUMBER(C18),ISNUMBER(D18)), C18-D18, "") -> 127 | F18: =IFERROR(E18/D18, "") -> 0.024057587 | G18: 11746.86 | H18: =IF(AND(ISNUMBER(C18),ISNUMBER(G18)), C18-G18, "") -> -6340.86 | I18: =IFERROR(H18/G18, "") -> -0.53979191 | J18: 1. Site production was low on 01/17 to 01/22, 01/25 to 01/27 due to snow.
A19: Kohls - Kingston | B19: NY | C19: 5082 | D19: 5015 | E19: =IF(AND(ISNUMBER(C19),ISNUMBER(D19)), C19-D19, "") -> 67 | F19: =IFERROR(E19/D19, "") -> 0.01335992 | G19: 22069.03 | H19: =IF(AND(ISNUMBER(C19),ISNUMBER(G19)), C19-G19, "") -> -16987.03 | I19: =IFERROR(H19/G19, "") -> -0.76972255 | J19: 1. Site production was low on 01/25 to end of the month due to snow. 2. Site was offline from 12/27 to 01/07. | K19: 2. SR114087 | L19: 2. Completed
A20: Kohls - Mechanicsburg | B20: PA | C20: 13803 | D20: 13468 | E20: =IF(AND(ISNUMBER(C20),ISNUMBER(D20)), C20-D20, "") -> 335 | F20: =IFERROR(E20/D20, "") -> 0.024873775 | G20: 21317.04 | H20: =IF(AND(ISNUMBER(C20),ISNUMBER(G20)), C20-G20, "") -> -7514.04 | I20: =IFERROR(H20/G20, "") -> -0.35248984 | J20: 1. Site production was low on 01/25 to end of the month due to snow.
A21: Kohls - Middletown | B21: NJ | C21: 18759 | D21: 18144 | E21: =IF(AND(ISNUMBER(C21),ISNUMBER(D21)), C21-D21, "") -> 615 | F21: =IFERROR(E21/D21, "") -> 0.033895503 | G21: 29222.37 | H21: =IF(AND(ISNUMBER(C21),ISNUMBER(G21)), C21-G21, "") -> -10463.37 | I21: =IFERROR(H21/G21, "") -> -0.35806028 | J21: 1. Site production was low on 01/25 to end of the month due to snow.
A22: Kohls - North Amherst | B22: NY | C22: 2216 | D22: 2114 | E22: =IF(AND(ISNUMBER(C22),ISNUMBER(D22)), C22-D22, "") -> 102 | F22: =IFERROR(E22/D22, "") -> 0.048249763 | G22: 6434.12 | H22: =IF(AND(ISNUMBER(C22),ISNUMBER(G22)), C22-G22, "") -> -4218.12 | I22: =IFERROR(H22/G22, "") -> -0.65558616 | J22: 1. Inverter is barely producing, mostly remained offline and reporting "AC Surge Warning" from 11/27. There was snow accumulation and clearing at the site from past couple of days | K22: 1. SR111831 | L22: 1.pending
A23: Kohls - Staten Island | B23: NY | C23: 7744 | D23: 0 | E23: =IF(AND(ISNUMBER(C23),ISNUMBER(D23)), C23-D23, "") -> 7744 | F23: =IFERROR(E23/D23, "") | G23: 15260.77 | H23: =IF(AND(ISNUMBER(C23),ISNUMBER(G23)), C23-G23, "") -> -7516.77 | I23: =IFERROR(H23/G23, "") -> -0.49255509 | J23: 1. 13 modules nee to bereplaced. 2. Inverter 8, 20, 21 were offline for whole month. 3. Pyronometer was displaying 0w/m2 for whole month. | K23: 1. SR105403 2. SR095623 3. SR108240 | L23: 1. Pending 2. Pending 3. Denied | M23: SR095623 | N23: SR108240
A24: Kohls - Warminster | B24: PA | C24: 11746 | D24: 11528 | E24: =IF(AND(ISNUMBER(C24),ISNUMBER(D24)), C24-D24, "") -> 218 | F24: =IFERROR(E24/D24, "") -> 0.018910479 | G24: 19268.71 | H24: =IF(AND(ISNUMBER(C24),ISNUMBER(G24)), C24-G24, "") -> -7522.71 | I24: =IFERROR(H24/G24, "") -> -0.39041067 | J24: 1. Site was barely producing from 01/17 to 01/22 and also from 01/25 to end of the month due to snow.
A25: Kohls - Waterbury | B25: CT | C25: 6175 | D25: 6085 | E25: =IF(AND(ISNUMBER(C25),ISNUMBER(D25)), C25-D25, "") -> 90 | F25: =IFERROR(E25/D25, "") -> 0.014790468 | G25: 15189.49 | H25: =IF(AND(ISNUMBER(C25),ISNUMBER(G25)), C25-G25, "") -> -9014.49 | I25: =IFERROR(H25/G25, "") -> -0.59346891 | J25: 1. Site was barely producing from 01/17 to 01/22 and also from 01/25 to end of the month due to snow.
A26: Mojave Water Agency - Headquarters | B26: CA | C26: 26259 | D26: 26144 | E26: =IF(AND(ISNUMBER(C26),ISNUMBER(D26)), C26-D26, "") -> 115 | F26: =IFERROR(E26/D26, "") -> 0.0043987148 | G26: 25672.5 | H26: =IF(AND(ISNUMBER(C26),ISNUMBER(G26)), C26-G26, "") -> 586.5 | I26: =IFERROR(H26/G26, "") -> 0.022845457
A27: CSU - Bakersfield | B27: CA | C27: 61123 | D27: 60461 | E27: =IF(AND(ISNUMBER(C27),ISNUMBER(D27)), C27-D27, "") -> 662 | F27: =IFERROR(E27/D27, "") -> 0.010949207 | G27: 60206.76 | H27: =IF(AND(ISNUMBER(C27),ISNUMBER(G27)), C27-G27, "") -> 916.24 | I27: =IFERROR(H27/G27, "") -> 0.015218225
A28: Greenfield USD - Fairfield ES | B28: CA | C28: 6362 | D28: 6298 | E28: =IF(AND(ISNUMBER(C28),ISNUMBER(D28)), C28-D28, "") -> 64 | F28: =IFERROR(E28/D28, "") -> 0.010161956 | G28: 6700.67 | H28: =IF(AND(ISNUMBER(C28),ISNUMBER(G28)), C28-G28, "") -> -338.67 | I28: =IFERROR(H28/G28, "") -> -0.050542707
A29: Greenfield USD - Granite Point ES | B29: CA | C29: 20053 | D29: 19951 | E29: =IF(AND(ISNUMBER(C29),ISNUMBER(D29)), C29-D29, "") -> 102 | F29: =IFERROR(E29/D29, "") -> 0.0051125257 | G29: 17528.38 | H29: =IF(AND(ISNUMBER(C29),ISNUMBER(G29)), C29-G29, "") -> 2524.62 | I29: =IFERROR(H29/G29, "") -> 0.14403042 | J29: 1. Inverter 1 PAD 1 was offline form 10/14and back online at 12:10 on 01/02. | K29: 1. SR109478 | L29: 1. Closed
A30: Greenfield USD - Greenfield MS | B30: CA | C30: 8745 | D30: 8723 | E30: =IF(AND(ISNUMBER(C30),ISNUMBER(D30)), C30-D30, "") -> 22 | F30: =IFERROR(E30/D30, "") -> 0.0025220681 | G30: 12096.14 | H30: =IF(AND(ISNUMBER(C30),ISNUMBER(G30)), C30-G30, "") -> -3351.14 | I30: =IFERROR(H30/G30, "") -> -0.2770421 | J30: 1. As per site weather station data, the plant is performing as expected. The forecasted (theoretical) values appear higher because they are based on long-term average weather data (typically 10–15 years). In contrast, actual vs expected generation reflects real-time weather conditions during the period, providing a more accurate measure of current performance
A31: Greenfield USD - Horizon ES | B31: CA | C31: 19976 | D31: 19760 | E31: =IF(AND(ISNUMBER(C31),ISNUMBER(D31)), C31-D31, "") -> 216 | F31: =IFERROR(E31/D31, "") -> 0.010931174 | G31: 17758.17 | H31: =IF(AND(ISNUMBER(C31),ISNUMBER(G31)), C31-G31, "") -> 2217.83 | I31: =IFERROR(H31/G31, "") -> 0.12489068 | J31: 1. As per site weather station data, the plant is performing as expected. The forecasted (theoretical) values appear higher because they are based on long-term average weather data (typically 10–15 years). In contrast, actual vs expected generation reflects real-time weather conditions during the period, providing a more accurate measure of current performance
A32: Greenfield USD - McKee MS | B32: CA | C32: 5085 | D32: 3700 | E32: =IF(AND(ISNUMBER(C32),ISNUMBER(D32)), C32-D32, "") -> 1385 | F32: =IFERROR(E32/D32, "") -> 0.37432432 | G32: 10873.66 | H32: =IF(AND(ISNUMBER(C32),ISNUMBER(G32)), C32-G32, "") -> -5788.66 | I32: =IFERROR(H32/G32, "") -> -0.53235617 | J32: 1. 12 additional damaged modules. Combiner left offline. 2.Weather station reporting 0W/M^2 from 01/25 | K32: 1. SR109483 | L32: 1.pending
A33: Greenfield USD - Plantation ES | B33: CA | C33: 8003 | D33: 7982 | E33: =IF(AND(ISNUMBER(C33),ISNUMBER(D33)), C33-D33, "") -> 21 | F33: =IFERROR(E33/D33, "") -> 0.0026309196 | G33: 7785.28 | H33: =IF(AND(ISNUMBER(C33),ISNUMBER(G33)), C33-G33, "") -> 217.72 | I33: =IFERROR(H33/G33, "") -> 0.027965597 | J33: 1. 1 module need to be replaced. | K33: 1. SR109260 | L33: 1. Pending
A34: Greenfield USD - Planz ES | B34: CA | C34: 8297 | D34: 8233 | E34: =IF(AND(ISNUMBER(C34),ISNUMBER(D34)), C34-D34, "") -> 64 | F34: =IFERROR(E34/D34, "") -> 0.0077735941 | G34: 8649.29 | H34: =IF(AND(ISNUMBER(C34),ISNUMBER(G34)), C34-G34, "") -> -352.29 | I34: =IFERROR(H34/G34, "") -> -0.040730511
A35: Greenfield USD - Raffaello Palla ES | B35: CA | C35: 17711 | D35: 17200 | E35: =IF(AND(ISNUMBER(C35),ISNUMBER(D35)), C35-D35, "") -> 511 | F35: =IFERROR(E35/D35, "") -> 0.029709302 | G35: 19651.64 | H35: =IF(AND(ISNUMBER(C35),ISNUMBER(G35)), C35-G35, "") -> -1940.64 | I35: =IFERROR(H35/G35, "") -> -0.098752063 | J35: 1. 14 modules need to be replaced. 2. Meter intermettently drops to zero but production can be verified at inverter. 3. CB 460 was offline for whole month. | K35: 1. SR110823 2. SR091550 3. SR110826 | L35: 1. Pending 2. Pending 3. Pending | M35: SR091550 | N35: SR110826
A36: Greenfield USD - Valle Verde ES | B36: CA | C36: 11095 | D36: 11046 | E36: =IF(AND(ISNUMBER(C36),ISNUMBER(D36)), C36-D36, "") -> 49 | F36: =IFERROR(E36/D36, "") -> 0.0044359949 | G36: 18530.26 | H36: =IF(AND(ISNUMBER(C36),ISNUMBER(G36)), C36-G36, "") -> -7435.26 | I36: =IFERROR(H36/G36, "") -> -0.40124963 | J36: 1. 5 Modules need to be replaced. 2.As per site weather station data, the plant is performing as expected. The forecasted (theoretical) values appear higher because they are based on long-term average weather data (typically 10–15 years). In contrast, actual vs expected generation reflects real-time weather conditions during the period, providing a more accurate measure of current performance | K36: 1. SR111114 | L36: 1. Pending
A37: Greenfield USD - W.A. Kendrick ES | B37: CA | C37: 7387 | D37: 0 | E37: =IF(AND(ISNUMBER(C37),ISNUMBER(D37)), C37-D37, "") -> 7387 | F37: =IFERROR(E37/D37, "") | G37: 7151.06 | H37: =IF(AND(ISNUMBER(C37),ISNUMBER(G37)), C37-G37, "") -> 235.94 | I37: =IFERROR(H37/G37, "") -> 0.03299371 | J37: 1.Meter reporting half of inverter production since 6/11/22 waiting for client approval for investigation. | K37: 1.SR106741 | L37: 1.pending
A38: Muroc Joint USD - Boron HS | B38: CA | C38: 0 | D38: 0 | E38: =IF(AND(ISNUMBER(C38),ISNUMBER(D38)), C38-D38, "") -> 0 | F38: =IFERROR(E38/D38, "") | G38: 23447.83 | H38: =IF(AND(ISNUMBER(C38),ISNUMBER(G38)), C38-G38, "") -> -23447.83 | I38: =IFERROR(H38/G38, "") -> -1 | J38: 1. Site was not communicated for whole month GPM recommended NPort failure. | K38: 1.SR111715 | L38: 1.pending
A39: Muroc Joint USD - W. Boron ES | B39: CA | C39: 7080 | D39: 7052 | E39: =IF(AND(ISNUMBER(C39),ISNUMBER(D39)), C39-D39, "") -> 28 | F39: =IFERROR(E39/D39, "") -> 0.0039705048 | G39: 8694.49 | H39: =IF(AND(ISNUMBER(C39),ISNUMBER(G39)), C39-G39, "") -> -1614.49 | I39: =IFERROR(H39/G39, "") -> -0.18569117 | J39: 1. As per site weather station data, the plant is performing as expected. The forecasted (theoretical) values appear higher because they are based on long-term average weather data (typically 10–15 years). In contrast, actual vs expected generation reflects real-time weather conditions during the period, providing a more accurate measure of current performance
