Workbook
Name JanActual: #REF!
Name JanActual2: #REF!
Name JanExpected: #REF!
Name JanExpectedDelta: #REF!
Name JanExpectedPercent: #REF!
Name JanExpPercent: #REF!
Name JanForecasted: #REF!
Name JanForecastedDelta: #REF!
Name JanForecastedPercent: #REF!
Name portfolio: Sites!$B$1:$B$1
Name Year: Sites!#REF!

Sheet Year to Date
A1: {=portfolio} -> Wells Fargo | C1: Year to Date Actual v. Expected | F1: Year to Date Actual v. Forecasted
A2: Total | B2: =SUM(B4:B95) -> 1139669.8 | C2: =SUM(C4:C94) -> 1251030.8 | D2: =B2-C2 -> -111361.01 | E2: =IFERROR(D2/C2, 0) -> -0.089015403 | F2: =SUM(F4:F94) -> 1283420.3 | G2: =B2-F2 -> -143750.48 | H2: =IFERROR(G2/F2, 0) -> -0.11200577
A3: Site | B3: Actual | C3: Expected | D3: Delta | E3: % | F3: Forecasted | G3: Delta | H3: %
A4: {=_xlfn.UNIQUE(Sites[State])} -> CA | B4: =SUM('1st Qtr'!B4, '2nd Qtr'!B4, '3rd Qtr'!B4, '4th Qtr'!B4) -> 68153.671 | C4: =SUM('1st Qtr'!C4, '2nd Qtr'!C4, '3rd Qtr'!C4, '4th Qtr'!C4) -> 61975.617 | D4: =IF(AND(ISNUMBER($B4),ISNUMBER(C4)), $B4-C4, "") -> 6178.0535 | E4: =IFERROR(D4/C4, "") -> 0.099685229 | F4: =SUM('1st Qtr'!F4, '2nd Qtr'!F4, '3rd Qtr'!F4, '4th Qtr'!F4) -> 74698.394 | G4: =IF(AND(ISNUMBER($B4),ISNUMBER(F4)), $B4-F4, "") -> -6544.7235 | H4: =IFERROR(G4/F4, "") -> -0.087615317
A5: CO | B5: =SUM('1st Qtr'!B5, '2nd Qtr'!B5, '3rd Qtr'!B5, '4th Qtr'!B5) -> 12717.192 | C5: =SUM('1st Qtr'!C5, '2nd Qtr'!C5, '3rd Qtr'!C5, '4th Qtr'!C5) -> 14574.416 | D5: =IF(AND(ISNUMBER($B5),ISNUMBER(C5)), $B5-C5, "") -> -1857.2237 | E5: =IFERROR(D5/C5, "") -> -0.1274304 | F5: =SUM('1st Qtr'!F5, '2nd Qtr'!F5, '3rd Qtr'!F5, '4th Qtr'!F5) -> 13249.6 | G5: =IF(AND(ISNUMBER($B5),ISNUMBER(F5)), $B5-F5, "") -> -532.40769 | H5: =IFERROR(G5/F5, "") -> -0.040182926
A6: CT | B6: =SUM('1st Qtr'!B6, '2nd Qtr'!B6, '3rd Qtr'!B6, '4th Qtr'!B6) -> 34.6 | C6: =SUM('1st Qtr'!C6, '2nd Qtr'!C6, '3rd Qtr'!C6, '4th Qtr'!C6) -> 391.1425 | D6: =IF(AND(ISNUMBER($B6),ISNUMBER(C6)), $B6-C6, "") -> -356.5425 | E6: =IFERROR(D6/C6, "") -> -0.91154119 | F6: =SUM('1st Qtr'!F6, '2nd Qtr'!F6, '3rd Qtr'!F6, '4th Qtr'!F6) -> 647.9245 | G6: =IF(AND(ISNUMBER($B6),ISNUMBER(F6)), $B6-F6, "") -> -613.3245 | H6: =IFERROR(G6/F6, "") -> -0.94659872
A7: FL | B7: =SUM('1st Qtr'!B7, '2nd Qtr'!B7, '3rd Qtr'!B7, '4th Qtr'!B7) -> 662.6044 | C7: =SUM('1st Qtr'!C7, '2nd Qtr'!C7, '3rd Qtr'!C7, '4th Qtr'!C7) -> 4236.788 | D7: =IF(AND(ISNUMBER($B7),ISNUMBER(C7)), $B7-C7, "") -> -3574.1836 | E7: =IFERROR(D7/C7, "") -> -0.8436069 | F7: =SUM('1st Qtr'!F7, '2nd Qtr'!F7, '3rd Qtr'!F7, '4th Qtr'!F7) -> 3416 | G7: =IF(AND(ISNUMBER($B7),ISNUMBER(F7)), $B7-F7, "") -> -2753.3956 | H7: =IFERROR(G7/F7, "") -> -0.80602916
A8: IA | B8: =SUM('1st Qtr'!B8, '2nd Qtr'!B8, '3rd Qtr'!B8, '4th Qtr'!B8) -> 158231.5 | C8: =SUM('1st Qtr'!C8, '2nd Qtr'!C8, '3rd Qtr'!C8, '4th Qtr'!C8) -> 182371.45 | D8: =IF(AND(ISNUMBER($B8),ISNUMBER(C8)), $B8-C8, "") -> -24139.95 | E8: =IFERROR(D8/C8, "") -> -0.13236694 | F8: =SUM('1st Qtr'!F8, '2nd Qtr'!F8, '3rd Qtr'!F8, '4th Qtr'!F8) -> 158543.48 | G8: =IF(AND(ISNUMBER($B8),ISNUMBER(F8)), $B8-F8, "") -> -311.98 | H8: =IFERROR(G8/F8, "") -> -0.0019677883
A9: NC | B9: =SUM('1st Qtr'!B9, '2nd Qtr'!B9, '3rd Qtr'!B9, '4th Qtr'!B9) -> 91934.3 | C9: =SUM('1st Qtr'!C9, '2nd Qtr'!C9, '3rd Qtr'!C9, '4th Qtr'!C9) -> 93258.401 | D9: =IF(AND(ISNUMBER($B9),ISNUMBER(C9)), $B9-C9, "") -> -1324.101 | E9: =IFERROR(D9/C9, "") -> -0.014198195 | F9: =SUM('1st Qtr'!F9, '2nd Qtr'!F9, '3rd Qtr'!F9, '4th Qtr'!F9) -> 108350.38 | G9: =IF(AND(ISNUMBER($B9),ISNUMBER(F9)), $B9-F9, "") -> -16416.078 | H9: =IFERROR(G9/F9, "") -> -0.15150919
A10: NJ | B10: =SUM('1st Qtr'!B10, '2nd Qtr'!B10, '3rd Qtr'!B10, '4th Qtr'!B10) -> 25827.002 | C10: =SUM('1st Qtr'!C10, '2nd Qtr'!C10, '3rd Qtr'!C10, '4th Qtr'!C10) -> 38938.495 | D10: =IF(AND(ISNUMBER($B10),ISNUMBER(C10)), $B10-C10, "") -> -13111.494 | E10: =IFERROR(D10/C10, "") -> -0.33672318 | F10: =SUM('1st Qtr'!F10, '2nd Qtr'!F10, '3rd Qtr'!F10, '4th Qtr'!F10) -> 39314.465 | G10: =IF(AND(ISNUMBER($B10),ISNUMBER(F10)), $B10-F10, "") -> -13487.463 | H10: =IFERROR(G10/F10, "") -> -0.34306618
A11: TX | B11: =SUM('1st Qtr'!B11, '2nd Qtr'!B11, '3rd Qtr'!B11, '4th Qtr'!B11) -> 502655.16 | C11: =SUM('1st Qtr'!C11, '2nd Qtr'!C11, '3rd Qtr'!C11, '4th Qtr'!C11) -> 542020.71 | D11: =IF(AND(ISNUMBER($B11),ISNUMBER(C11)), $B11-C11, "") -> -39365.554 | E11: =IFERROR(D11/C11, "") -> -0.072627398 | F11: =SUM('1st Qtr'!F11, '2nd Qtr'!F11, '3rd Qtr'!F11, '4th Qtr'!F11) -> 540479.5 | G11: =IF(AND(ISNUMBER($B11),ISNUMBER(F11)), $B11-F11, "") -> -37824.344 | H11: =IFERROR(G11/F11, "") -> -0.069982939
A12: AZ | B12: =SUM('1st Qtr'!B12, '2nd Qtr'!B12, '3rd Qtr'!B12, '4th Qtr'!B12) -> 279453.78 | C12: =SUM('1st Qtr'!C12, '2nd Qtr'!C12, '3rd Qtr'!C12, '4th Qtr'!C12) -> 313263.8 | D12: =IF(AND(ISNUMBER($B12),ISNUMBER(C12)), $B12-C12, "") -> -33810.017 | E12: =IFERROR(D12/C12, "") -> -0.10792826 | F12: =SUM('1st Qtr'!F12, '2nd Qtr'!F12, '3rd Qtr'!F12, '4th Qtr'!F12) -> 344720.54 | G12: =IF(AND(ISNUMBER($B12),ISNUMBER(F12)), $B12-F12, "") -> -65266.761 | H12: =IFERROR(G12/F12, "") -> -0.18933238

Sheet 1st Qtr
A1: {=portfolio} -> Wells Fargo | C1: 1st Quarter Actual v. Expected | F1: 1st Quarter Actual v. Forecasted
A2: Total | B2: =SUM(B4:B90) -> 1139669.8 | C2: =SUM(C4:C90) -> 1251030.8 | D2: =B2-C2 -> -111361.01 | E2: =IFERROR(D2/C2, 0) -> -0.089015403 | F2: =SUM(F4:F90) -> 1283420.3 | G2: =B2-F2 -> -143750.48 | H2: =IFERROR(G2/F2, 0) -> -0.11200577
A3: State | B3: Actual | C3: Expected | D3: Delta | E3: % | F3: Forecasted | G3: Delta | H3: %
A4: {=_xlfn.UNIQUE(Sites[State])} -> CA | B4: =SUM(SUMIF(_xlfn.ANCHORARRAY(Jan!$B$4), $A4, Jan!C$4:C$65), SUMIF(_xlfn.ANCHORARRAY(Feb!$B$4), $A4, Feb!C$4:C$76), SUMIF(_xlfn.ANCHORARRAY(Mar!$B$4), $A4, Mar!C$4:C$65)) -> 68153.671 | C4: =SUM(SUMIF(_xlfn.ANCHORARRAY(Jan!$B$4), $A4, Jan!D$4:D$65), SUMIF(_xlfn.ANCHORARRAY(Feb!$B$4), $A4, Feb!D$4:D$76), SUMIF(_xlfn.ANCHORARRAY(Mar!$B$4), $A4, Mar!D$4:D$65)) -> 61975.617 | D4: =IF(AND(ISNUMBER(B4),ISNUMBER(C4)), B4-C4, "") -> 6178.0535 | E4: =IFERROR(D4/C4, "") -> 0.099685229 | F4: =SUM(SUMIF(_xlfn.ANCHORARRAY(Jan!$B$4), $A4, Jan!G$4:G$65), SUMIF(_xlfn.ANCHORARRAY(Feb!$B$4), $A4, Feb!G$4:G$76), SUMIF(_xlfn.ANCHORARRAY(Mar!$B$4), $A4, Mar!G$4:G$65)) -> 74698.394 | G4: =IF(AND(ISNUMBER(B4),ISNUMBER(F4)), B4-F4, "") -> -6544.7235 | H4: =IFERROR(G4/F4, "") -> -0.087615317
A5: CO | B5: =SUM(SUMIF(_xlfn.ANCHORARRAY(Jan!$B$4), $A5, Jan!C$4:C$65), SUMIF(_xlfn.ANCHORARRAY(Feb!$B$4), $A5, Feb!C$4:C$76), SUMIF(_xlfn.ANCHORARRAY(Mar!$B$4), $A5, Mar!C$4:C$65)) -> 12717.192 | C5: =SUM(SUMIF(_xlfn.ANCHORARRAY(Jan!$B$4), $A5, Jan!D$4:D$65), SUMIF(_xlfn.ANCHORARRAY(Feb!$B$4), $A5, Feb!D$4:D$76), SUMIF(_xlfn.ANCHORARRAY(Mar!$B$4), $A5, Mar!D$4:D$65)) -> 14574.416 | D5: =IF(AND(ISNUMBER(B5),ISNUMBER(C5)), B5-C5, "") -> -1857.2237 | E5: =IFERROR(D5/C5, "") -> -0.1274304 | F5: =SUM(SUMIF(_xlfn.ANCHORARRAY(Jan!$B$4), $A5, Jan!G$4:G$65), SUMIF(_xlfn.ANCHORARRAY(Feb!$B$4), $A5, Feb!G$4:G$76), SUMIF(_xlfn.ANCHORARRAY(Mar!$B$4), $A5, Mar!G$4:G$65)) -> 13249.6 | G5: =IF(AND(ISNUMBER(B5),ISNUMBER(F5)), B5-F5, "") -> -532.40769 | H5: =IFERROR(G5/F5, "") -> -0.040182926
A6: CT | B6: =SUM(SUMIF(_xlfn.ANCHORARRAY(Jan!$B$4), $A6, Jan!C$4:C$65), SUMIF(_xlfn.ANCHORARRAY(Feb!$B$4), $A6, Feb!C$4:C$76), SUMIF(_xlfn.ANCHORARRAY(Mar!$B$4), $A6, Mar!C$4:C$65)) -> 34.6 | C6: =SUM(SUMIF(_xlfn.ANCHORARRAY(Jan!$B$4), $A6, Jan!D$4:D$65), SUMIF(_xlfn.ANCHORARRAY(Feb!$B$4), $A6, Feb!D$4:D$76), SUMIF(_xlfn.ANCHORARRAY(Mar!$B$4), $A6, Mar!D$4:D$65)) -> 391.1425 | D6: =IF(AND(ISNUMBER(B6),ISNUMBER(C6)), B6-C6, "") -> -356.5425 | E6: =IFERROR(D6/C6, "") -> -0.91154119 | F6: =SUM(SUMIF(_xlfn.ANCHORARRAY(Jan!$B$4), $A6, Jan!G$4:G$65), SUMIF(_xlfn.ANCHORARRAY(Feb!$B$4), $A6, Feb!G$4:G$76), SUMIF(_xlfn.ANCHORARRAY(Mar!$B$4), $A6, Mar!G$4:G$65)) -> 647.9245 | G6: =IF(AND(ISNUMBER(B6),ISNUMBER(F6)), B6-F6, "") -> -613.3245 | H6: =IFERROR(G6/F6, "") -> -0.94659872
A7: FL | B7: =SUM(SUMIF(_xlfn.ANCHORARRAY(Jan!$B$4), $A7, Jan!C$4:C$65), SUMIF(_xlfn.ANCHORARRAY(Feb!$B$4), $A7, Feb!C$4:C$76), SUMIF(_xlfn.ANCHORARRAY(Mar!$B$4), $A7, Mar!C$4:C$65)) -> 662.6044 | C7: =SUM(SUMIF(_xlfn.ANCHORARRAY(Jan!$B$4), $A7, Jan!D$4:D$65), SUMIF(_xlfn.ANCHORARRAY(Feb!$B$4), $A7, Feb!D$4:D$76), SUMIF(_xlfn.ANCHORARRAY(Mar!$B$4), $A7, Mar!D$4:D$65)) -> 4236.788 | D7: =IF(AND(ISNUMBER(B7),ISNUMBER(C7)), B7-C7, "") -> -3574.1836 | E7: =IFERROR(D7/C7, "") -> -0.8436069 | F7: =SUM(SUMIF(_xlfn.ANCHORARRAY(Jan!$B$4), $A7, Jan!G$4:G$65), SUMIF(_xlfn.ANCHORARRAY(Feb!$B$4), $A7, Feb!G$4:G$76), SUMIF(_xlfn.ANCHORARRAY(Mar!$B$4), $A7, Mar!G$4:G$65)) -> 3416 | G7: =IF(AND(ISNUMBER(B7),ISNUMBER(F7)), B7-F7, "") -> -2753.3956 | H7: =IFERROR(G7/F7, "") -> -0.80602916
A8: IA | B8: =SUM(SUMIF(_xlfn.ANCHORARRAY(Jan!$B$4), $A8, Jan!C$4:C$65), SUMIF(_xlfn.ANCHORARRAY(Feb!$B$4), $A8, Feb!C$4:C$76), SUMIF(_xlfn.ANCHORARRAY(Mar!$B$4), $A8, Mar!C$4:C$65)) -> 158231.5 | C8: =SUM(SUMIF(_xlfn.ANCHORARRAY(Jan!$B$4), $A8, Jan!D$4:D$65), SUMIF(_xlfn.ANCHORARRAY(Feb!$B$4), $A8, Feb!D$4:D$76), SUMIF(_xlfn.ANCHORARRAY(Mar!$B$4), $A8, Mar!D$4:D$65)) -> 182371.45 | D8: =IF(AND(ISNUMBER(B8),ISNUMBER(C8)), B8-C8, "") -> -24139.95 | E8: =IFERROR(D8/C8, "") -> -0.13236694 | F8: =SUM(SUMIF(_xlfn.ANCHORARRAY(Jan!$B$4), $A8, Jan!G$4:G$65), SUMIF(_xlfn.ANCHORARRAY(Feb!$B$4), $A8, Feb!G$4:G$76), SUMIF(_xlfn.ANCHORARRAY(Mar!$B$4), $A8, Mar!G$4:G$65)) -> 158543.48 | G8: =IF(AND(ISNUMBER(B8),ISNUMBER(F8)), B8-F8, "") -> -311.98 | H8: =IFERROR(G8/F8, "") -> -0.0019677883
A9: NC | B9: =SUM(SUMIF(_xlfn.ANCHORARRAY(Jan!$B$4), $A9, Jan!C$4:C$65), SUMIF(_xlfn.ANCHORARRAY(Feb!$B$4), $A9, Feb!C$4:C$76), SUMIF(_xlfn.ANCHORARRAY(Mar!$B$4), $A9, Mar!C$4:C$65)) -> 91934.3 | C9: =SUM(SUMIF(_xlfn.ANCHORARRAY(Jan!$B$4), $A9, Jan!D$4:D$65), SUMIF(_xlfn.ANCHORARRAY(Feb!$B$4), $A9, Feb!D$4:D$76), SUMIF(_xlfn.ANCHORARRAY(Mar!$B$4), $A9, Mar!D$4:D$65)) -> 93258.401 | D9: =IF(AND(ISNUMBER(B9),ISNUMBER(C9)), B9-C9, "") -> -1324.101 | E9: =IFERROR(D9/C9, "") -> -0.014198195 | F9: =SUM(SUMIF(_xlfn.ANCHORARRAY(Jan!$B$4), $A9, Jan!G$4:G$65), SUMIF(_xlfn.ANCHORARRAY(Feb!$B$4), $A9, Feb!G$4:G$76), SUMIF(_xlfn.ANCHORARRAY(Mar!$B$4), $A9, Mar!G$4:G$65)) -> 108350.38 | G9: =IF(AND(ISNUMBER(B9),ISNUMBER(F9)), B9-F9, "") -> -16416.078 | H9: =IFERROR(G9/F9, "") -> -0.15150919
A10: NJ | B10: =SUM(SUMIF(_xlfn.ANCHORARRAY(Jan!$B$4), $A10, Jan!C$4:C$65), SUMIF(_xlfn.ANCHORARRAY(Feb!$B$4), $A10, Feb!C$4:C$76), SUMIF(_xlfn.ANCHORARRAY(Mar!$B$4), $A10, Mar!C$4:C$65)) -> 25827.002 | C10: =SUM(SUMIF(_xlfn.ANCHORARRAY(Jan!$B$4), $A10, Jan!D$4:D$65), SUMIF(_xlfn.ANCHORARRAY(Feb!$B$4), $A10, Feb!D$4:D$76), SUMIF(_xlfn.ANCHORARRAY(Mar!$B$4), $A10, Mar!D$4:D$65)) -> 38938.495 | D10: =IF(AND(ISNUMBER(B10),ISNUMBER(C10)), B10-C10, "") -> -13111.494 | E10: =IFERROR(D10/C10, "") -> -0.33672318 | F10: =SUM(SUMIF(_xlfn.ANCHORARRAY(Jan!$B$4), $A10, Jan!G$4:G$65), SUMIF(_xlfn.ANCHORARRAY(Feb!$B$4), $A10, Feb!G$4:G$76), SUMIF(_xlfn.ANCHORARRAY(Mar!$B$4), $A10, Mar!G$4:G$65)) -> 39314.465 | G10: =IF(AND(ISNUMBER(B10),ISNUMBER(F10)), B10-F10, "") -> -13487.463 | H10: =IFERROR(G10/F10, "") -> -0.34306618
A11: TX | B11: =SUM(SUMIF(_xlfn.ANCHORARRAY(Jan!$B$4), $A11, Jan!C$4:C$65), SUMIF(_xlfn.ANCHORARRAY(Feb!$B$4), $A11, Feb!C$4:C$76), SUMIF(_xlfn.ANCHORARRAY(Mar!$B$4), $A11, Mar!C$4:C$65)) -> 502655.16 | C11: =SUM(SUMIF(_xlfn.ANCHORARRAY(Jan!$B$4), $A11, Jan!D$4:D$65), SUMIF(_xlfn.ANCHORARRAY(Feb!$B$4), $A11, Feb!D$4:D$76), SUMIF(_xlfn.ANCHORARRAY(Mar!$B$4), $A11, Mar!D$4:D$65)) -> 542020.71 | D11: =IF(AND(ISNUMBER(B11),ISNUMBER(C11)), B11-C11, "") -> -39365.554 | E11: =IFERROR(D11/C11, "") -> -0.072627398 | F11: =SUM(SUMIF(_xlfn.ANCHORARRAY(Jan!$B$4), $A11, Jan!G$4:G$65), SUMIF(_xlfn.ANCHORARRAY(Feb!$B$4), $A11, Feb!G$4:G$76), SUMIF(_xlfn.ANCHORARRAY(Mar!$B$4), $A11, Mar!G$4:G$65)) -> 540479.5 | G11: =IF(AND(ISNUMBER(B11),ISNUMBER(F11)), B11-F11, "") -> -37824.344 | H11: =IFERROR(G11/F11, "") -> -0.069982939
A12: AZ | B12: =SUM(SUMIF(_xlfn.ANCHORARRAY(Jan!$B$4), $A12, Jan!C$4:C$65), SUMIF(_xlfn.ANCHORARRAY(Feb!$B$4), $A12, Feb!C$4:C$76), SUMIF(_xlfn.ANCHORARRAY(Mar!$B$4), $A12, Mar!C$4:C$65)) -> 279453.78 | C12: =SUM(SUMIF(_xlfn.ANCHORARRAY(Jan!$B$4), $A12, Jan!D$4:D$65), SUMIF(_xlfn.ANCHORARRAY(Feb!$B$4), $A12, Feb!D$4:D$76), SUMIF(_xlfn.ANCHORARRAY(Mar!$B$4), $A12, Mar!D$4:D$65)) -> 313263.8 | D12: =IF(AND(ISNUMBER(B12),ISNUMBER(C12)), B12-C12, "") -> -33810.017 | E12: =IFERROR(D12/C12, "") -> -0.10792826 | F12: =SUM(SUMIF(_xlfn.ANCHORARRAY(Jan!$B$4), $A12, Jan!G$4:G$65), SUMIF(_xlfn.ANCHORARRAY(Feb!$B$4), $A12, Feb!G$4:G$76), SUMIF(_xlfn.ANCHORARRAY(Mar!$B$4), $A12, Mar!G$4:G$65)) -> 344720.54 | G12: =IF(AND(ISNUMBER(B12),ISNUMBER(F12)), B12-F12, "") -> -65266.761 | H12: =IFERROR(G12/F12, "") -> -0.18933238

Sheet 2nd Qtr
A1: {=portfolio} -> Wells Fargo | C1: 2nd Quarter Actual v. Expected | F1: 2nd Quarter Actual v. Forecasted
A2: Total | B2: =SUM(B4:B85) -> 0 | C2: =SUM(C4:C85) -> 0 | D2: =B2-C2 -> 0 | E2: =IFERROR(D2/C2, 0) -> 0 | F2: =SUM(F4:F85) -> 0 | G2: =B2-F2 -> 0 | H2: =IFERROR(G2/F2, 0) -> 0
A3: State | B3: Actual | C3: Expected | D3: Delta | E3: % | F3: Forecasted | G3: Delta | H3: %
A4: {=_xlfn.UNIQUE(Sites[State])} -> CA | B4: =SUM(SUMIF(_xlfn.ANCHORARRAY(Apr!$B$4), $A4, Apr!C$4:C$78), SUMIF(_xlfn.ANCHORARRAY(May!$B$4), $A4, May!C$4:C$65), SUMIF(_xlfn.ANCHORARRAY(Jun!$B$4), $A4, Jun!C$4:C$65)) -> 0 | C4: =SUM(SUMIF(_xlfn.ANCHORARRAY(Apr!$B$4), $A4, Apr!D$4:D$78), SUMIF(_xlfn.ANCHORARRAY(May!$B$4), $A4, May!D$4:D$65), SUMIF(_xlfn.ANCHORARRAY(Jun!$B$4), $A4, Jun!D$4:D$65)) -> 0 | D4: =IF(AND(ISNUMBER(B4),ISNUMBER(C4)), B4-C4, "") -> 0 | E4: =IFERROR(D4/C4, "") | F4: =SUM(SUMIF(_xlfn.ANCHORARRAY(Apr!$B$4), $A4, Apr!G$4:G$78), SUMIF(_xlfn.ANCHORARRAY(May!$B$4), $A4, May!G$4:G$65), SUMIF(_xlfn.ANCHORARRAY(Jun!$B$4), $A4, Jun!G$4:G$65)) -> 0 | G4: =IF(AND(ISNUMBER(B4),ISNUMBER(F4)), B4-F4, "") -> 0 | H4: =IFERROR(G4/F4, "")
A5: CO | B5: =SUM(SUMIF(_xlfn.ANCHORARRAY(Apr!$B$4), $A5, Apr!C$4:C$78), SUMIF(_xlfn.ANCHORARRAY(May!$B$4), $A5, May!C$4:C$65), SUMIF(_xlfn.ANCHORARRAY(Jun!$B$4), $A5, Jun!C$4:C$65)) -> 0 | C5: =SUM(SUMIF(_xlfn.ANCHORARRAY(Apr!$B$4), $A5, Apr!D$4:D$78), SUMIF(_xlfn.ANCHORARRAY(May!$B$4), $A5, May!D$4:D$65), SUMIF(_xlfn.ANCHORARRAY(Jun!$B$4), $A5, Jun!D$4:D$65)) -> 0 | D5: =IF(AND(ISNUMBER(B5),ISNUMBER(C5)), B5-C5, "") -> 0 | E5: =IFERROR(D5/C5, "") | F5: =SUM(SUMIF(_xlfn.ANCHORARRAY(Apr!$B$4), $A5, Apr!G$4:G$78), SUMIF(_xlfn.ANCHORARRAY(May!$B$4), $A5, May!G$4:G$65), SUMIF(_xlfn.ANCHORARRAY(Jun!$B$4), $A5, Jun!G$4:G$65)) -> 0 | G5: =IF(AND(ISNUMBER(B5),ISNUMBER(F5)), B5-F5, "") -> 0 | H5: =IFERROR(G5/F5, "")
A6: CT | B6: =SUM(SUMIF(_xlfn.ANCHORARRAY(Apr!$B$4), $A6, Apr!C$4:C$78), SUMIF(_xlfn.ANCHORARRAY(May!$B$4), $A6, May!C$4:C$65), SUMIF(_xlfn.ANCHORARRAY(Jun!$B$4), $A6, Jun!C$4:C$65)) -> 0 | C6: =SUM(SUMIF(_xlfn.ANCHORARRAY(Apr!$B$4), $A6, Apr!D$4:D$78), SUMIF(_xlfn.ANCHORARRAY(May!$B$4), $A6, May!D$4:D$65), SUMIF(_xlfn.ANCHORARRAY(Jun!$B$4), $A6, Jun!D$4:D$65)) -> 0 | D6: =IF(AND(ISNUMBER(B6),ISNUMBER(C6)), B6-C6, "") -> 0 | E6: =IFERROR(D6/C6, "") | F6: =SUM(SUMIF(_xlfn.ANCHORARRAY(Apr!$B$4), $A6, Apr!G$4:G$78), SUMIF(_xlfn.ANCHORARRAY(May!$B$4), $A6, May!G$4:G$65), SUMIF(_xlfn.ANCHORARRAY(Jun!$B$4), $A6, Jun!G$4:G$65)) -> 0 | G6: =IF(AND(ISNUMBER(B6),ISNUMBER(F6)), B6-F6, "") -> 0 | H6: =IFERROR(G6/F6, "")
A7: FL | B7: =SUM(SUMIF(_xlfn.ANCHORARRAY(Apr!$B$4), $A7, Apr!C$4:C$78), SUMIF(_xlfn.ANCHORARRAY(May!$B$4), $A7, May!C$4:C$65), SUMIF(_xlfn.ANCHORARRAY(Jun!$B$4), $A7, Jun!C$4:C$65)) -> 0 | C7: =SUM(SUMIF(_xlfn.ANCHORARRAY(Apr!$B$4), $A7, Apr!D$4:D$78), SUMIF(_xlfn.ANCHORARRAY(May!$B$4), $A7, May!D$4:D$65), SUMIF(_xlfn.ANCHORARRAY(Jun!$B$4), $A7, Jun!D$4:D$65)) -> 0 | D7: =IF(AND(ISNUMBER(B7),ISNUMBER(C7)), B7-C7, "") -> 0 | E7: =IFERROR(D7/C7, "") | F7: =SUM(SUMIF(_xlfn.ANCHORARRAY(Apr!$B$4), $A7, Apr!G$4:G$78), SUMIF(_xlfn.ANCHORARRAY(May!$B$4), $A7, May!G$4:G$65), SUMIF(_xlfn.ANCHORARRAY(Jun!$B$4), $A7, Jun!G$4:G$65)) -> 0 | G7: =IF(AND(ISNUMBER(B7),ISNUMBER(F7)), B7-F7, "") -> 0 | H7: =IFERROR(G7/F7, "")
A8: IA | B8: =SUM(SUMIF(_xlfn.ANCHORARRAY(Apr!$B$4), $A8, Apr!C$4:C$78), SUMIF(_xlfn.ANCHORARRAY(May!$B$4), $A8, May!C$4:C$65), SUMIF(_xlfn.ANCHORARRAY(Jun!$B$4), $A8, Jun!C$4:C$65)) -> 0 | C8: =SUM(SUMIF(_xlfn.ANCHORARRAY(Apr!$B$4), $A8, Apr!D$4:D$78), SUMIF(_xlfn.ANCHORARRAY(May!$B$4), $A8, May!D$4:D$65), SUMIF(_xlfn.ANCHORARRAY(Jun!$B$4), $A8, Jun!D$4:D$65)) -> 0 | D8: =IF(AND(ISNUMBER(B8),ISNUMBER(C8)), B8-C8, "") -> 0 | E8: =IFERROR(D8/C8, "") | F8: =SUM(SUMIF(_xlfn.ANCHORARRAY(Apr!$B$4), $A8, Apr!G$4:G$78), SUMIF(_xlfn.ANCHORARRAY(May!$B$4), $A8, May!G$4:G$65), SUMIF(_xlfn.ANCHORARRAY(Jun!$B$4), $A8, Jun!G$4:G$65)) -> 0 | G8: =IF(AND(ISNUMBER(B8),ISNUMBER(F8)), B8-F8, "") -> 0 | H8: =IFERROR(G8/F8, "")
A9: NC | B9: =SUM(SUMIF(_xlfn.ANCHORARRAY(Apr!$B$4), $A9, Apr!C$4:C$78), SUMIF(_xlfn.ANCHORARRAY(May!$B$4), $A9, May!C$4:C$65), SUMIF(_xlfn.ANCHORARRAY(Jun!$B$4), $A9, Jun!C$4:C$65)) -> 0 | C9: =SUM(SUMIF(_xlfn.ANCHORARRAY(Apr!$B$4), $A9, Apr!D$4:D$78), SUMIF(_xlfn.ANCHORARRAY(May!$B$4), $A9, May!D$4:D$65), SUMIF(_xlfn.ANCHORARRAY(Jun!$B$4), $A9, Jun!D$4:D$65)) -> 0 | D9: =IF(AND(ISNUMBER(B9),ISNUMBER(C9)), B9-C9, "") -> 0 | E9: =IFERROR(D9/C9, "") | F9: =SUM(SUMIF(_xlfn.ANCHORARRAY(Apr!$B$4), $A9, Apr!G$4:G$78), SUMIF(_xlfn.ANCHORARRAY(May!$B$4), $A9, May!G$4:G$65), SUMIF(_xlfn.ANCHORARRAY(Jun!$B$4), $A9, Jun!G$4:G$65)) -> 0 | G9: =IF(AND(ISNUMBER(B9),ISNUMBER(F9)), B9-F9, "") -> 0 | H9: =IFERROR(G9/F9, "")
A10: NJ | B10: =SUM(SUMIF(_xlfn.ANCHORARRAY(Apr!$B$4), $A10, Apr!C$4:C$78), SUMIF(_xlfn.ANCHORARRAY(May!$B$4), $A10, May!C$4:C$65), SUMIF(_xlfn.ANCHORARRAY(Jun!$B$4), $A10, Jun!C$4:C$65)) -> 0 | C10: =SUM(SUMIF(_xlfn.ANCHORARRAY(Apr!$B$4), $A10, Apr!D$4:D$78), SUMIF(_xlfn.ANCHORARRAY(May!$B$4), $A10, May!D$4:D$65), SUMIF(_xlfn.ANCHORARRAY(Jun!$B$4), $A10, Jun!D$4:D$65)) -> 0 | D10: =IF(AND(ISNUMBER(B10),ISNUMBER(C10)), B10-C10, "") -> 0 | E10: =IFERROR(D10/C10, "") | F10: =SUM(SUMIF(_xlfn.ANCHORARRAY(Apr!$B$4), $A10, Apr!G$4:G$78), SUMIF(_xlfn.ANCHORARRAY(May!$B$4), $A10, May!G$4:G$65), SUMIF(_xlfn.ANCHORARRAY(Jun!$B$4), $A10, Jun!G$4:G$65)) -> 0 | G10: =IF(AND(ISNUMBER(B10),ISNUMBER(F10)), B10-F10, "") -> 0 | H10: =IFERROR(G10/F10, "")
A11: TX | B11: =SUM(SUMIF(_xlfn.ANCHORARRAY(Apr!$B$4), $A11, Apr!C$4:C$78), SUMIF(_xlfn.ANCHORARRAY(May!$B$4), $A11, May!C$4:C$65), SUMIF(_xlfn.ANCHORARRAY(Jun!$B$4), $A11, Jun!C$4:C$65)) -> 0 | C11: =SUM(SUMIF(_xlfn.ANCHORARRAY(Apr!$B$4), $A11, Apr!D$4:D$78), SUMIF(_xlfn.ANCHORARRAY(May!$B$4), $A11, May!D$4:D$65), SUMIF(_xlfn.ANCHORARRAY(Jun!$B$4), $A11, Jun!D$4:D$65)) -> 0 | D11: =IF(AND(ISNUMBER(B11),ISNUMBER(C11)), B11-C11, "") -> 0 | E11: =IFERROR(D11/C11, "") | F11: =SUM(SUMIF(_xlfn.ANCHORARRAY(Apr!$B$4), $A11, Apr!G$4:G$78), SUMIF(_xlfn.ANCHORARRAY(May!$B$4), $A11, May!G$4:G$65), SUMIF(_xlfn.ANCHORARRAY(Jun!$B$4), $A11, Jun!G$4:G$65)) -> 0 | G11: =IF(AND(ISNUMBER(B11),ISNUMBER(F11)), B11-F11, "") -> 0 | H11: =IFERROR(G11/F11, "")
A12: AZ | B12: =SUM(SUMIF(_xlfn.ANCHORARRAY(Apr!$B$4), $A12, Apr!C$4:C$78), SUMIF(_xlfn.ANCHORARRAY(May!$B$4), $A12, May!C$4:C$65), SUMIF(_xlfn.ANCHORARRAY(Jun!$B$4), $A12, Jun!C$4:C$65)) -> 0 | C12: =SUM(SUMIF(_xlfn.ANCHORARRAY(Apr!$B$4), $A12, Apr!D$4:D$78), SUMIF(_xlfn.ANCHORARRAY(May!$B$4), $A12, May!D$4:D$65), SUMIF(_xlfn.ANCHORARRAY(Jun!$B$4), $A12, Jun!D$4:D$65)) -> 0 | D12: =IF(AND(ISNUMBER(B12),ISNUMBER(C12)), B12-C12, "") -> 0 | E12: =IFERROR(D12/C12, "") | F12: =SUM(SUMIF(_xlfn.ANCHORARRAY(Apr!$B$4), $A12, Apr!G$4:G$78), SUMIF(_xlfn.ANCHORARRAY(May!$B$4), $A12, May!G$4:G$65), SUMIF(_xlfn.ANCHORARRAY(Jun!$B$4), $A12, Jun!G$4:G$65)) -> 0 | G12: =IF(AND(ISNUMBER(B12),ISNUMBER(F12)), B12-F12, "") -> 0 | H12: =IFERROR(G12/F12, "")

Sheet 3rd Qtr
A1: {=portfolio} -> Wells Fargo | C1: 3rd Quarter Actual v. Expected | F1: 3rd Quarter Actual v. Forecasted
A2: Total | B2: =SUM(B4:B90) -> 0 | C2: =SUM(C4:C90) -> 0 | D2: =B2-C2 -> 0 | E2: =IFERROR(D2/C2, 0) -> 0 | F2: =SUM(F4:F90) -> 0 | G2: =B2-F2 -> 0 | H2: =IFERROR(G2/F2, 0) -> 0
A3: State | B3: Actual | C3: Expected | D3: Delta | E3: % | F3: Forecasted | G3: Delta | H3: %
A4: {=_xlfn.UNIQUE(Sites[State])} -> CA | D4: =IF(AND(ISNUMBER(B4),ISNUMBER(C4)), B4-C4, "") | E4: =IFERROR(D4/C4, "") | G4: =IF(AND(ISNUMBER(B4),ISNUMBER(F4)), B4-F4, "") | H4: =IFERROR(G4/F4, "")
A5: CO | D5: =IF(AND(ISNUMBER(B5),ISNUMBER(C5)), B5-C5, "") | E5: =IFERROR(D5/C5, "") | G5: =IF(AND(ISNUMBER(B5),ISNUMBER(F5)), B5-F5, "") | H5: =IFERROR(G5/F5, "")
A6: CT | D6: =IF(AND(ISNUMBER(B6),ISNUMBER(C6)), B6-C6, "") | E6: =IFERROR(D6/C6, "") | G6: =IF(AND(ISNUMBER(B6),ISNUMBER(F6)), B6-F6, "") | H6: =IFERROR(G6/F6, "")
A7: FL | D7: =IF(AND(ISNUMBER(B7),ISNUMBER(C7)), B7-C7, "") | E7: =IFERROR(D7/C7, "") | G7: =IF(AND(ISNUMBER(B7),ISNUMBER(F7)), B7-F7, "") | H7: =IFERROR(G7/F7, "")
A8: IA | D8: =IF(AND(ISNUMBER(B8),ISNUMBER(C8)), B8-C8, "") | E8: =IFERROR(D8/C8, "") | G8: =IF(AND(ISNUMBER(B8),ISNUMBER(F8)), B8-F8, "") | H8: =IFERROR(G8/F8, "")
A9: NC | D9: =IF(AND(ISNUMBER(B9),ISNUMBER(C9)), B9-C9, "") | E9: =IFERROR(D9/C9, "") | G9: =IF(AND(ISNUMBER(B9),ISNUMBER(F9)), B9-F9, "") | H9: =IFERROR(G9/F9, "")
A10: NJ | D10: =IF(AND(ISNUMBER(B10),ISNUMBER(C10)), B10-C10, "") | E10: =IFERROR(D10/C10, "") | G10: =IF(AND(ISNUMBER(B10),ISNUMBER(F10)), B10-F10, "") | H10: =IFERROR(G10/F10, "")
A11: TX | D11: =IF(AND(ISNUMBER(B11),ISNUMBER(C11)), B11-C11, "") | E11: =IFERROR(D11/C11, "") | G11: =IF(AND(ISNUMBER(B11),ISNUMBER(F11)), B11-F11, "") | H11: =IFERROR(G11/F11, "")
A12: AZ | D12: =IF(AND(ISNUMBER(B12),ISNUMBER(C12)), B12-C12, "") | E12: =IFERROR(D12/C12, "") | G12: =IF(AND(ISNUMBER(B12),ISNUMBER(F12)), B12-F12, "") | H12: =IFERROR(G12/F12, "")

Sheet 4th Qtr
A1: {=portfolio} -> Wells Fargo | C1: 4th Quarter Actual v. Expected | F1: 4th Quarter Actual v. Forecasted
A2: Total | B2: =SUM(B4:B90) -> 0 | C2: =SUM(C4:C90) -> 0 | D2: =B2-C2 -> 0 | E2: =IFERROR(D2/C2, 0) -> 0 | F2: =SUM(F4:F90) -> 0 | G2: =B2-F2 -> 0 | H2: =IFERROR(G2/F2, 0) -> 0
A3: State | B3: Actual | C3: Expected | D3: Delta | E3: % | F3: Forecasted | G3: Delta | H3: %
A4: {=_xlfn.UNIQUE(Sites[State])} -> CA | B4: =SUM(SUMIF(_xlfn.ANCHORARRAY(Oct!$B$4), $A4, Oct!C$4:C$69), SUMIF(_xlfn.ANCHORARRAY(Nov!$B$4), $A4, Nov!C$4:C$69), SUMIF(_xlfn.ANCHORARRAY(Dec!$B$4), $A4, Dec!C$4:C$69)) -> 0 | C4: =SUM(SUMIF(_xlfn.ANCHORARRAY(Oct!$B$4), $A4, Oct!D$4:D$69), SUMIF(_xlfn.ANCHORARRAY(Nov!$B$4), $A4, Nov!D$4:D$69), SUMIF(_xlfn.ANCHORARRAY(Dec!$B$4), $A4, Dec!D$4:D$69)) -> 0 | D4: =IF(AND(ISNUMBER(B4),ISNUMBER(C4)), B4-C4, "") -> 0 | E4: =IFERROR(D4/C4, "") | F4: =SUM(SUMIF(_xlfn.ANCHORARRAY(Oct!$B$4), $A4, Oct!G$4:G$69), SUMIF(_xlfn.ANCHORARRAY(Nov!$B$4), $A4, Nov!G$4:G$69), SUMIF(_xlfn.ANCHORARRAY(Dec!$B$4), $A4, Dec!G$4:G$69)) -> 0 | G4: =IF(AND(ISNUMBER(B4),ISNUMBER(F4)), B4-F4, "") -> 0 | H4: =IFERROR(G4/F4, "")
A5: CO | B5: =SUM(SUMIF(_xlfn.ANCHORARRAY(Oct!$B$4), $A5, Oct!C$4:C$69), SUMIF(_xlfn.ANCHORARRAY(Nov!$B$4), $A5, Nov!C$4:C$69), SUMIF(_xlfn.ANCHORARRAY(Dec!$B$4), $A5, Dec!C$4:C$69)) -> 0 | C5: =SUM(SUMIF(_xlfn.ANCHORARRAY(Oct!$B$4), $A5, Oct!D$4:D$69), SUMIF(_xlfn.ANCHORARRAY(Nov!$B$4), $A5, Nov!D$4:D$69), SUMIF(_xlfn.ANCHORARRAY(Dec!$B$4), $A5, Dec!D$4:D$69)) -> 0 | D5: =IF(AND(ISNUMBER(B5),ISNUMBER(C5)), B5-C5, "") -> 0 | E5: =IFERROR(D5/C5, "") | F5: =SUM(SUMIF(_xlfn.ANCHORARRAY(Oct!$B$4), $A5, Oct!G$4:G$69), SUMIF(_xlfn.ANCHORARRAY(Nov!$B$4), $A5, Nov!G$4:G$69), SUMIF(_xlfn.ANCHORARRAY(Dec!$B$4), $A5, Dec!G$4:G$69)) -> 0 | G5: =IF(AND(ISNUMBER(B5),ISNUMBER(F5)), B5-F5, "") -> 0 | H5: =IFERROR(G5/F5, "")
A6: CT | B6: =SUM(SUMIF(_xlfn.ANCHORARRAY(Oct!$B$4), $A6, Oct!C$4:C$69), SUMIF(_xlfn.ANCHORARRAY(Nov!$B$4), $A6, Nov!C$4:C$69), SUMIF(_xlfn.ANCHORARRAY(Dec!$B$4), $A6, Dec!C$4:C$69)) -> 0 | C6: =SUM(SUMIF(_xlfn.ANCHORARRAY(Oct!$B$4), $A6, Oct!D$4:D$69), SUMIF(_xlfn.ANCHORARRAY(Nov!$B$4), $A6, Nov!D$4:D$69), SUMIF(_xlfn.ANCHORARRAY(Dec!$B$4), $A6, Dec!D$4:D$69)) -> 0 | D6: =IF(AND(ISNUMBER(B6),ISNUMBER(C6)), B6-C6, "") -> 0 | E6: =IFERROR(D6/C6, "") | F6: =SUM(SUMIF(_xlfn.ANCHORARRAY(Oct!$B$4), $A6, Oct!G$4:G$69), SUMIF(_xlfn.ANCHORARRAY(Nov!$B$4), $A6, Nov!G$4:G$69), SUMIF(_xlfn.ANCHORARRAY(Dec!$B$4), $A6, Dec!G$4:G$69)) -> 0 | G6: =IF(AND(ISNUMBER(B6),ISNUMBER(F6)), B6-F6, "") -> 0 | H6: =IFERROR(G6/F6, "")
A7: FL | B7: =SUM(SUMIF(_xlfn.ANCHORARRAY(Oct!$B$4), $A7, Oct!C$4:C$69), SUMIF(_xlfn.ANCHORARRAY(Nov!$B$4), $A7, Nov!C$4:C$69), SUMIF(_xlfn.ANCHORARRAY(Dec!$B$4), $A7, Dec!C$4:C$69)) -> 0 | C7: =SUM(SUMIF(_xlfn.ANCHORARRAY(Oct!$B$4), $A7, Oct!D$4:D$69), SUMIF(_xlfn.ANCHORARRAY(Nov!$B$4), $A7, Nov!D$4:D$69), SUMIF(_xlfn.ANCHORARRAY(Dec!$B$4), $A7, Dec!D$4:D$69)) -> 0 | D7: =IF(AND(ISNUMBER(B7),ISNUMBER(C7)), B7-C7, "") -> 0 | E7: =IFERROR(D7/C7, "") | F7: =SUM(SUMIF(_xlfn.ANCHORARRAY(Oct!$B$4), $A7, Oct!G$4:G$69), SUMIF(_xlfn.ANCHORARRAY(Nov!$B$4), $A7, Nov!G$4:G$69), SUMIF(_xlfn.ANCHORARRAY(Dec!$B$4), $A7, Dec!G$4:G$69)) -> 0 | G7: =IF(AND(ISNUMBER(B7),ISNUMBER(F7)), B7-F7, "") -> 0 | H7: =IFERROR(G7/F7, "")
A8: IA | B8: =SUM(SUMIF(_xlfn.ANCHORARRAY(Oct!$B$4), $A8, Oct!C$4:C$69), SUMIF(_xlfn.ANCHORARRAY(Nov!$B$4), $A8, Nov!C$4:C$69), SUMIF(_xlfn.ANCHORARRAY(Dec!$B$4), $A8, Dec!C$4:C$69)) -> 0 | C8: =SUM(SUMIF(_xlfn.ANCHORARRAY(Oct!$B$4), $A8, Oct!D$4:D$69), SUMIF(_xlfn.ANCHORARRAY(Nov!$B$4), $A8, Nov!D$4:D$69), SUMIF(_xlfn.ANCHORARRAY(Dec!$B$4), $A8, Dec!D$4:D$69)) -> 0 | D8: =IF(AND(ISNUMBER(B8),ISNUMBER(C8)), B8-C8, "") -> 0 | E8: =IFERROR(D8/C8, "") | F8: =SUM(SUMIF(_xlfn.ANCHORARRAY(Oct!$B$4), $A8, Oct!G$4:G$69), SUMIF(_xlfn.ANCHORARRAY(Nov!$B$4), $A8, Nov!G$4:G$69), SUMIF(_xlfn.ANCHORARRAY(Dec!$B$4), $A8, Dec!G$4:G$69)) -> 0 | G8: =IF(AND(ISNUMBER(B8),ISNUMBER(F8)), B8-F8, "") -> 0 | H8: =IFERROR(G8/F8, "")
A9: NC | B9: =SUM(SUMIF(_xlfn.ANCHORARRAY(Oct!$B$4), $A9, Oct!C$4:C$69), SUMIF(_xlfn.ANCHORARRAY(Nov!$B$4), $A9, Nov!C$4:C$69), SUMIF(_xlfn.ANCHORARRAY(Dec!$B$4), $A9, Dec!C$4:C$69)) -> 0 | C9: =SUM(SUMIF(_xlfn.ANCHORARRAY(Oct!$B$4), $A9, Oct!D$4:D$69), SUMIF(_xlfn.ANCHORARRAY(Nov!$B$4), $A9, Nov!D$4:D$69), SUMIF(_xlfn.ANCHORARRAY(Dec!$B$4), $A9, Dec!D$4:D$69)) -> 0 | D9: =IF(AND(ISNUMBER(B9),ISNUMBER(C9)), B9-C9, "") -> 0 | E9: =IFERROR(D9/C9, "") | F9: =SUM(SUMIF(_xlfn.ANCHORARRAY(Oct!$B$4), $A9, Oct!G$4:G$69), SUMIF(_xlfn.ANCHORARRAY(Nov!$B$4), $A9, Nov!G$4:G$69), SUMIF(_xlfn.ANCHORARRAY(Dec!$B$4), $A9, Dec!G$4:G$69)) -> 0 | G9: =IF(AND(ISNUMBER(B9),ISNUMBER(F9)), B9-F9, "") -> 0 | H9: =IFERROR(G9/F9, "")
A10: NJ | B10: =SUM(SUMIF(_xlfn.ANCHORARRAY(Oct!$B$4), $A10, Oct!C$4:C$69), SUMIF(_xlfn.ANCHORARRAY(Nov!$B$4), $A10, Nov!C$4:C$69), SUMIF(_xlfn.ANCHORARRAY(Dec!$B$4), $A10, Dec!C$4:C$69)) -> 0 | C10: =SUM(SUMIF(_xlfn.ANCHORARRAY(Oct!$B$4), $A10, Oct!D$4:D$69), SUMIF(_xlfn.ANCHORARRAY(Nov!$B$4), $A10, Nov!D$4:D$69), SUMIF(_xlfn.ANCHORARRAY(Dec!$B$4), $A10, Dec!D$4:D$69)) -> 0 | D10: =IF(AND(ISNUMBER(B10),ISNUMBER(C10)), B10-C10, "") -> 0 | E10: =IFERROR(D10/C10, "") | F10: =SUM(SUMIF(_xlfn.ANCHORARRAY(Oct!$B$4), $A10, Oct!G$4:G$69), SUMIF(_xlfn.ANCHORARRAY(Nov!$B$4), $A10, Nov!G$4:G$69), SUMIF(_xlfn.ANCHORARRAY(Dec!$B$4), $A10, Dec!G$4:G$69)) -> 0 | G10: =IF(AND(ISNUMBER(B10),ISNUMBER(F10)), B10-F10, "") -> 0 | H10: =IFERROR(G10/F10, "")
A11: TX | B11: =SUM(SUMIF(_xlfn.ANCHORARRAY(Oct!$B$4), $A11, Oct!C$4:C$69), SUMIF(_xlfn.ANCHORARRAY(Nov!$B$4), $A11, Nov!C$4:C$69), SUMIF(_xlfn.ANCHORARRAY(Dec!$B$4), $A11, Dec!C$4:C$69)) -> 0 | C11: =SUM(SUMIF(_xlfn.ANCHORARRAY(Oct!$B$4), $A11, Oct!D$4:D$69), SUMIF(_xlfn.ANCHORARRAY(Nov!$B$4), $A11, Nov!D$4:D$69), SUMIF(_xlfn.ANCHORARRAY(Dec!$B$4), $A11, Dec!D$4:D$69)) -> 0 | D11: =IF(AND(ISNUMBER(B11),ISNUMBER(C11)), B11-C11, "") -> 0 | E11: =IFERROR(D11/C11, "") | F11: =SUM(SUMIF(_xlfn.ANCHORARRAY(Oct!$B$4), $A11, Oct!G$4:G$69), SUMIF(_xlfn.ANCHORARRAY(Nov!$B$4), $A11, Nov!G$4:G$69), SUMIF(_xlfn.ANCHORARRAY(Dec!$B$4), $A11, Dec!G$4:G$69)) -> 0 | G11: =IF(AND(ISNUMBER(B11),ISNUMBER(F11)), B11-F11, "") -> 0 | H11: =IFERROR(G11/F11, "")
A12: AZ | B12: =SUM(SUMIF(_xlfn.ANCHORARRAY(Oct!$B$4), $A12, Oct!C$4:C$69), SUMIF(_xlfn.ANCHORARRAY(Nov!$B$4), $A12, Nov!C$4:C$69), SUMIF(_xlfn.ANCHORARRAY(Dec!$B$4), $A12, Dec!C$4:C$69)) -> 0 | C12: =SUM(SUMIF(_xlfn.ANCHORARRAY(Oct!$B$4), $A12, Oct!D$4:D$69), SUMIF(_xlfn.ANCHORARRAY(Nov!$B$4), $A12, Nov!D$4:D$69), SUMIF(_xlfn.ANCHORARRAY(Dec!$B$4), $A12, Dec!D$4:D$69)) -> 0 | D12: =IF(AND(ISNUMBER(B12),ISNUMBER(C12)), B12-C12, "") -> 0 | E12: =IFERROR(D12/C12, "") | F12: =SUM(SUMIF(_xlfn.ANCHORARRAY(Oct!$B$4), $A12, Oct!G$4:G$69), SUMIF(_xlfn.ANCHORARRAY(Nov!$B$4), $A12, Nov!G$4:G$69), SUMIF(_xlfn.ANCHORARRAY(Dec!$B$4), $A12, Dec!G$4:G$69)) -> 0 | G12: =IF(AND(ISNUMBER(B12),ISNUMBER(F12)), B12-F12, "") -> 0 | H12: =IFERROR(G12/F12, "")

Sheet Jan
A1: {=portfolio} -> Wells Fargo | D1: January Actual v. Expected | G1: January Actual v. Forecasted
A2: Total | C2: =SUM(C4:C65) -> 344030.5 | D2: =SUM(D4:D65) -> 381964.55 | E2: =C2-D2 -> -37934.05 | F2: =IFERROR(E2/D2, 0) -> -0.099313013 | G2: =SUM(G4:G65) -> 385301.56 | H2: =C2-G2 -> -41271.059 | I2: =IFERROR(H2/G2, 0) -> -0.10711366 | J2: =IF(AND(TODAY()>DATE(2024, 1, 1), COUNTA(Sites[Site])<>(COUNT(C:C)-1)), "Some sites are missing actual data; if new sites were added, make sure they are aligned correctly (including prior months!)", "") -> Some sites are missing actual data; if new sites were added, make sure they are aligned correctly (including prior months!)
A3: Site | B3: State | C3: Actual | D3: Expected | E3: Delta | F3: % | G3: Forecasted | H3: Delta | I3: % | J3: Notes | K3: Service Requests | L3: Status
A4: {=Sites[Site]} -> Adams & Broadway | B4: {=Sites[State]} -> CA | C4: 665.1 | D4: 2313.944 | E4: =IF(AND(ISNUMBER(C4),ISNUMBER(D4)), C4-D4, "") -> -1648.844 | F4: =IFERROR(E4/D4, "") -> -0.71256867 | G4: 661 | H4: =IF(AND(ISNUMBER(C4),ISNUMBER(G4)), C4-G4, "") -> 4.1 | I4: =IFERROR(H4/G4, "") -> 0.0062027231 | J4: 1. Compared to last year’s delta values, we can still see a negative variance for this site, which suggests an issue with the forecasted value.
A5: Otay Mesa | B5: CA | C5: 39.5 | D5: N/A | E5: =IF(AND(ISNUMBER(C5),ISNUMBER(D5)), C5-D5, "") | F5: =IFERROR(E5/D5, "") | G5: N/A | H5: =IF(AND(ISNUMBER(C5),ISNUMBER(G5)), C5-G5, "") | I5: =IFERROR(H5/G5, "") | J5: 1. Production data taken from consumption meter.
A6: San Leandro | B6: CA | C6: 0 | D6: 0 | E6: =IF(AND(ISNUMBER(C6),ISNUMBER(D6)), C6-D6, "") -> 0 | F6: =IFERROR(E6/D6, "") | G6: 0 | H6: =IF(AND(ISNUMBER(C6),ISNUMBER(G6)), C6-G6, "") -> 0 | I6: =IFERROR(H6/G6, "") | J6: 1. Site was not communicated for whole month. | K6: 1. SR099548 | L6: 1. Pending
A7: Van Nuys | B7: CA | C7: 1175.2 | D7: N/A | E7: =IF(AND(ISNUMBER(C7),ISNUMBER(D7)), C7-D7, "") | F7: =IFERROR(E7/D7, "") | G7: 1313.97 | H7: =IF(AND(ISNUMBER(C7),ISNUMBER(G7)), C7-G7, "") -> -138.77 | I7: =IFERROR(H7/G7, "") -> -0.10561124 | J7: 1. Inverter 1 has heavy shading from afternoon to evening.
A8: Lodi - Lodi Vineyard | B8: CA | C8: 17201.812 | D8: 18075.58 | E8: =IF(AND(ISNUMBER(C8),ISNUMBER(D8)), C8-D8, "") -> -873.7675 | F8: =IFERROR(E8/D8, "") -> -0.048339666 | G8: 17814 | H8: =IF(AND(ISNUMBER(C8),ISNUMBER(G8)), C8-G8, "") -> -612.1875 | I8: =IFERROR(H8/G8, "") -> -0.034365527 | J8: 1. Inverter 1 and 7 have morning to afternoon shading.
A9: Arden Fair Mall | B9: CA | C9: 8795.25 | D9: 10365.24 | E9: =IF(AND(ISNUMBER(C9),ISNUMBER(D9)), C9-D9, "") -> -1569.99 | F9: =IFERROR(E9/D9, "") -> -0.15146683 | G9: 10608 | H9: =IF(AND(ISNUMBER(C9),ISNUMBER(G9)), C9-G9, "") -> -1812.75 | I9: =IFERROR(H9/G9, "") -> -0.17088518 | J9: 1. Inverter 2 has heavy shading in the morning.
A10: Modesto - Modesto Main | B10: CA | C10: 6088.9375 | D10: 8165.521 | E10: =IF(AND(ISNUMBER(C10),ISNUMBER(D10)), C10-D10, "") -> -2076.5835 | F10: =IFERROR(E10/D10, "") -> -0.25431121 | G10: 10217.37 | H10: =IF(AND(ISNUMBER(C10),ISNUMBER(G10)), C10-G10, "") -> -4128.4325 | I10: =IFERROR(H10/G10, "") -> -0.40406019 | J10: 1. Inverters 1, 4, and 5 have some afternoon shading. Inverter 5 is underperforming by 3kW; likely soiling. | K10: 1. SR101247 | L10: 1. Closed
A11: Stevens Creek | B11: CA | C11: 2947.9049 | D11: 2514.951 | E11: =IF(AND(ISNUMBER(C11),ISNUMBER(D11)), C11-D11, "") -> 432.95389 | F11: =IFERROR(E11/D11, "") -> 0.17215202 | G11: 2416 | H11: =IF(AND(ISNUMBER(C11),ISNUMBER(G11)), C11-G11, "") -> 531.90489 | I11: =IFERROR(H11/G11, "") -> 0.22015931
A12: Covina Main | B12: CA | C12: 2249.8 | D12: 1759.853 | E12: =IF(AND(ISNUMBER(C12),ISNUMBER(D12)), C12-D12, "") -> 489.947 | F12: =IFERROR(E12/D12, "") -> 0.27840223 | G12: 2134 | H12: =IF(AND(ISNUMBER(C12),ISNUMBER(G12)), C12-G12, "") -> 115.8 | I12: =IFERROR(H12/G12, "") -> 0.054264292
A13: Old Ranch Town Center | B13: CA | C13: 750.18945 | D13: N/A | E13: =IF(AND(ISNUMBER(C13),ISNUMBER(D13)), C13-D13, "") | F13: =IFERROR(E13/D13, "") | G13: 910 | H13: =IF(AND(ISNUMBER(C13),ISNUMBER(G13)), C13-G13, "") -> -159.81055 | I13: =IFERROR(H13/G13, "") -> -0.17561599 | J13: 1. The plant is performing as expected. The forecasted (theoretical) values may appear higher because they are based on long-term average weather data (typically over 10–15 years). In contrast, the actual vs. expected generation reflects real-time weather conditions during the period, offering a more accurate representation of current performance.
A14: Mountain Gate Plaza | B14: CA | C14: 5234.9057 | D14: N/A | E14: =IF(AND(ISNUMBER(C14),ISNUMBER(D14)), C14-D14, "") | F14: =IFERROR(E14/D14, "") | G14: 6591 | H14: =IF(AND(ISNUMBER(C14),ISNUMBER(G14)), C14-G14, "") -> -1356.0943 | I14: =IFERROR(H14/G14, "") -> -0.20574939 | J14: 1. As per site weather station data, the plant is performing as expected. The forecasted (theoretical) values appear higher because they are based on long-term average weather data (typically 10–15 years). In contrast, actual vs expected generation reflects real-time weather conditions during the period, providing a more accurate measure of current performance.
A15: Arcadia Main | B15: CA | C15: 2384.6684 | D15: N/A | E15: =IF(AND(ISNUMBER(C15),ISNUMBER(D15)), C15-D15, "") | F15: =IFERROR(E15/D15, "") | G15: 3550 | H15: =IF(AND(ISNUMBER(C15),ISNUMBER(G15)), C15-G15, "") -> -1165.3316 | I15: =IFERROR(H15/G15, "") -> -0.32826242 | J15: 1. As per site weather station data, the plant is performing as expected. The forecasted (theoretical) values appear higher because they are based on long-term average weather data (typically 10–15 years). In contrast, actual vs expected generation reflects real-time weather conditions during the period, providing a more accurate measure of current performance.
A16: Fairfield | B16: CA | C16: 1818.8125 | D16: 2026.964 | E16: =IF(AND(ISNUMBER(C16),ISNUMBER(D16)), C16-D16, "") -> -208.1515 | F16: =IFERROR(E16/D16, "") -> -0.10269127 | G16: 2037 | H16: =IF(AND(ISNUMBER(C16),ISNUMBER(G16)), C16-G16, "") -> -218.1875 | I16: =IFERROR(H16/G16, "") -> -0.10711217 | J16: 1. As per site weather station data, the plant is performing as expected. The forecasted (theoretical) values appear higher because they are based on long-term average weather data (typically 10–15 years). In contrast, actual vs expected generation reflects real-time weather conditions during the period, providing a more accurate measure of current performance.
A17: Los Gatos | B17: CA | C17: 1103.5741 | D17: 1020.455 | E17: =IF(AND(ISNUMBER(C17),ISNUMBER(D17)), C17-D17, "") -> 83.119093 | F17: =IFERROR(E17/D17, "") -> 0.081452973 | G17: 0 | H17: =IF(AND(ISNUMBER(C17),ISNUMBER(G17)), C17-G17, "") -> 1103.5741 | I17: =IFERROR(H17/G17, "")
A18: San Marino | B18: CA | C18: 2323.3035 | D18: 2283.149 | E18: =IF(AND(ISNUMBER(C18),ISNUMBER(D18)), C18-D18, "") -> 40.154538 | F18: =IFERROR(E18/D18, "") -> 0.017587349 | G18: 2880.538 | H18: =IF(AND(ISNUMBER(C18),ISNUMBER(G18)), C18-G18, "") -> -557.23446 | I18: =IFERROR(H18/G18, "") -> -0.19344805 | J18: 1. Inverter 1 is underperforming by 13kW and inverter 2 by 10kW. Pending quote for return visit. | K18: 1. SR104629 | L18: 1. Closed
A19: Buenaventura | B19: CA | C19: 3254.2737 | D19: 2391.687 | E19: =IF(AND(ISNUMBER(C19),ISNUMBER(D19)), C19-D19, "") -> 862.58671 | F19: =IFERROR(E19/D19, "") -> 0.36066037 | G19: 3912.548 | H19: =IF(AND(ISNUMBER(C19),ISNUMBER(G19)), C19-G19, "") -> -658.27429 | I19: =IFERROR(H19/G19, "") -> -0.16824696 | J19: 1. As per site weather station data, the plant is performing as expected. The forecasted (theoretical) values appear higher because they are based on long-term average weather data (typically 10–15 years). In contrast, actual vs expected generation reflects real-time weather conditions during the period, providing a more accurate measure of current performance.
A20: BE 199502 - Westgate | B20: CA | C20: 1025.1 | D20: N/A | E20: =IF(AND(ISNUMBER(C20),ISNUMBER(D20)), C20-D20, "") | F20: =IFERROR(E20/D20, "") | G20: N/A | H20: =IF(AND(ISNUMBER(C20),ISNUMBER(G20)), C20-G20, "") | I20: =IFERROR(H20/G20, "") | J20: 1. The plant is performing as expected. The forecasted (theoretical) values may appear higher because they are based on long-term average weather data (typically over 10–15 years). In contrast, the actual vs. expected generation reflects real-time weather conditions during the period, offering a more accurate representation of current performance.
A21: 98th & Grant | B21: CO | C21: 1246.8 | D21: N/A | E21: =IF(AND(ISNUMBER(C21),ISNUMBER(D21)), C21-D21, "") | F21: =IFERROR(E21/D21, "") | G21: 1170 | H21: =IF(AND(ISNUMBER(C21),ISNUMBER(G21)), C21-G21, "") -> 76.8 | I21: =IFERROR(H21/G21, "") -> 0.065641026
A22: Arapahoe Crossings | B22: CO | C22: 0 | D22: 0 | E22: =IF(AND(ISNUMBER(C22),ISNUMBER(D22)), C22-D22, "") -> 0 | F22: =IFERROR(E22/D22, "") | G22: 0 | H22: =IF(AND(ISNUMBER(C22),ISNUMBER(G22)), C22-G22, "") -> 0 | I22: =IFERROR(H22/G22, "") | J22: 1. No communication to the inverters, As per technician visit on 08/08 inverter 3 is offline and inverter 1 is underperforming. 2. Site stopped communicating to the DAS at 23:00 on 11/02 because the modem is not powering up. The modem is currently under RMA. | K22: 1. SR105604 2. SR111494 | L22: 1. Closed 2. Pending | M22: SR111494
A23: Aurora City Center | B23: CO | C23: 712.9 | D23: N/A | E23: =IF(AND(ISNUMBER(C23),ISNUMBER(D23)), C23-D23, "") | F23: =IFERROR(E23/D23, "") | G23: 1050 | H23: =IF(AND(ISNUMBER(C23),ISNUMBER(G23)), C23-G23, "") -> -337.1 | I23: =IFERROR(H23/G23, "") -> -0.32104762 | J23: 1. The plant is performing as expected. The forecasted (theoretical) values may appear higher because they are based on long-term average weather data (typically over 10–15 years). In contrast, the actual vs. expected generation reflects real-time weather conditions during the period, offering a more accurate representation of current performance.
A24: Dry Creek | B24: CO | C24: 877.39231 | D24: 0 | E24: =IF(AND(ISNUMBER(C24),ISNUMBER(D24)), C24-D24, "") -> 877.39231 | F24: =IFERROR(E24/D24, "") | G24: 1261 | H24: =IF(AND(ISNUMBER(C24),ISNUMBER(G24)), C24-G24, "") -> -383.60769 | I24: =IFERROR(H24/G24, "") -> -0.30420912 | J24: 1. Meter phase A and B currents dropped to 18 amps on 10/01, and the meter also showed a production drop of 5–6 kW, possibly due to thermal damage to the CTs. Additionally, on 01/15, a technician found that the inverter was offline at the site. | K24: 1. SR110707 | L24: 1. Closed
A25: Highlands Ranch S. | B25: CO | C25: 1027.3 | D25: 4024.53 | E25: =IF(AND(ISNUMBER(C25),ISNUMBER(D25)), C25-D25, "") -> -2997.23 | F25: =IFERROR(E25/D25, "") -> -0.74474038 | G25: 1109 | H25: =IF(AND(ISNUMBER(C25),ISNUMBER(G25)), C25-G25, "") -> -81.7 | I25: =IFERROR(H25/G25, "") -> -0.073669973 | J25: 1. As per site weather station data, the plant is performing as expected. The forecasted (theoretical) values appear higher because they are based on long-term average weather data (typically 10–15 years). In contrast, actual vs expected generation reflects real-time weather conditions during the period, providing a more accurate measure of current performance.
A26: Lone Tree | B26: CO | C26: 1408.4 | D26: 3086.863 | E26: =IF(AND(ISNUMBER(C26),ISNUMBER(D26)), C26-D26, "") -> -1678.463 | F26: =IFERROR(E26/D26, "") -> -0.54374392 | G26: 2554 | H26: =IF(AND(ISNUMBER(C26),ISNUMBER(G26)), C26-G26, "") -> -1145.6 | I26: =IFERROR(H26/G26, "") -> -0.44855129 | J26: 1. Inverter 2 was offline for the entire month. | K26: 1. SR101743 | L26: 1. Closed
A27: Meridian | B27: CO | C27: 1691.7 | D27: N/A | E27: =IF(AND(ISNUMBER(C27),ISNUMBER(D27)), C27-D27, "") | F27: =IFERROR(E27/D27, "") | G27: 1505 | H27: =IF(AND(ISNUMBER(C27),ISNUMBER(G27)), C27-G27, "") -> 186.7 | I27: =IFERROR(H27/G27, "") -> 0.12405316
A28: Southglenn | B28: CO | C28: 1653.4 | D28: N/A | E28: =IF(AND(ISNUMBER(C28),ISNUMBER(D28)), C28-D28, "") | F28: =IFERROR(E28/D28, "") | G28: 1619.6 | H28: =IF(AND(ISNUMBER(C28),ISNUMBER(G28)), C28-G28, "") -> 33.8 | I28: =IFERROR(H28/G28, "") -> 0.02086935
A29: Standley Lake | B29: CO | C29: 2227.7 | D29: 7463.023 | E29: =IF(AND(ISNUMBER(C29),ISNUMBER(D29)), C29-D29, "") -> -5235.323 | F29: =IFERROR(E29/D29, "") -> -0.70150166 | G29: 2142 | H29: =IF(AND(ISNUMBER(C29),ISNUMBER(G29)), C29-G29, "") -> 85.7 | I29: =IFERROR(H29/G29, "") -> 0.040009337 | J29: 1. The plant is performing as expected. The forecasted (theoretical) values may appear higher because they are based on long-term average weather data (typically over 10–15 years). In contrast, the actual vs. expected generation reflects real-time weather conditions during the period, offering a more accurate representation of current performance. 2. Weather station reporting erroneous 1237.82w/m^2 values since commissioning
A30: Havana Gardens | B30: CO | C30: 1871.6 | D30: N/A | E30: =IF(AND(ISNUMBER(C30),ISNUMBER(D30)), C30-D30, "") | F30: =IFERROR(E30/D30, "") | G30: 839 | H30: =IF(AND(ISNUMBER(C30),ISNUMBER(G30)), C30-G30, "") -> 1032.6 | I30: =IFERROR(H30/G30, "") -> 1.2307509
A31: East Hartford | B31: CT | C31: 123.5 | D31: 266.2267 | E31: =IF(AND(ISNUMBER(C31),ISNUMBER(D31)), C31-D31, "") -> -142.7267 | F31: =IFERROR(E31/D31, "") -> -0.53610964 | G31: 269.7242 | H31: =IF(AND(ISNUMBER(C31),ISNUMBER(G31)), C31-G31, "") -> -146.2242 | I31: =IFERROR(H31/G31, "") -> -0.54212488 | J31: 1. The Site was offline for most days during the month due to snow.
A32: Norwalk | B32: CT | C32: -88.9 | D32: 124.9158 | E32: =IF(AND(ISNUMBER(C32),ISNUMBER(D32)), C32-D32, "") -> -213.8158 | F32: =IFERROR(E32/D32, "") -> -1.7116794 | G32: 378.2003 | H32: =IF(AND(ISNUMBER(C32),ISNUMBER(G32)), C32-G32, "") -> -467.1003 | I32: =IFERROR(H32/G32, "") -> -1.2350606 | J32: 1. Weather station reporting erroneous values from 07/04/2024. Will investigate next time onsite 2. An intermittent issue with Meter Phase C/Power Factor is slightly affecting the reported energy production. A case has been created with AlsoEnergy, and they have confirmed a site visit for further investigation | K32: 1. SR107668, SR088667, SR107670 2. SR077700, SR113568 | L32: 1. Pending 2. Denied | M32: SR088667 | N32: SR107670 | O32: SR077700 | P32: SR113568
A33: Hialeah Gardens | B33: FL | C33: 662.6044 | D33: 4236.788 | E33: =IF(AND(ISNUMBER(C33),ISNUMBER(D33)), C33-D33, "") -> -3574.1836 | F33: =IFERROR(E33/D33, "") -> -0.8436069 | G33: 3416 | H33: =IF(AND(ISNUMBER(C33),ISNUMBER(G33)), C33-G33, "") -> -2753.3956 | I33: =IFERROR(H33/G33, "") -> -0.80602916 | J33: 1. Site underperforming by ~15 kW. Production appears capped at 1.6 kW on high irradiance days, with brief spikes. Will be investigating during next site visit. | K33: 1. SR098782 | L33: 1. Closed
A34: W. Des Moines Campus EAST | B34: IA | C34: 104686.5 | D34: 116276.6 | E34: =IF(AND(ISNUMBER(C34),ISNUMBER(D34)), C34-D34, "") -> -11590.1 | F34: =IFERROR(E34/D34, "") -> -0.099676977 | G34: 103900 | H34: =IF(AND(ISNUMBER(C34),ISNUMBER(G34)), C34-G34, "") -> 786.5 | I34: =IFERROR(H34/G34, "") -> 0.0075697786
A35: W. Des Moines Campus SW | B35: IA | C35: 53545 | D35: 66094.85 | E35: =IF(AND(ISNUMBER(C35),ISNUMBER(D35)), C35-D35, "") -> -12549.85 | F35: =IFERROR(E35/D35, "") -> -0.18987637 | G35: 54643.48 | H35: =IF(AND(ISNUMBER(C35),ISNUMBER(G35)), C35-G35, "") -> -1098.48 | I35: =IFERROR(H35/G35, "") -> -0.020102673 | J35: 1. Phase A on the meter is lower than phases B and C, corresponding to the meter not capturing full inverter production since 01/12. | K35: 1. SR114480 | L35: 1. Pending
A36: WF - CIC | B36: NC | C36: 90929 | D36: 91687.46 | E36: =IF(AND(ISNUMBER(C36),ISNUMBER(D36)), C36-D36, "") -> -758.46 | F36: =IFERROR(E36/D36, "") -> -0.0082722326 | G36: 106712 | H36: =IF(AND(ISNUMBER(C36),ISNUMBER(G36)), C36-G36, "") -> -15783 | I36: =IFERROR(H36/G36, "") -> -0.14790277 | J36: 1. The production was low on 01/02,01/03,01/05,01/09,01/10,01/14,01/17,01/18 and 01/22 to 01/25 due to snow.
A37: Charlotte - Wells Fargo - DUC | B37: NC | C37: 1005.3 | D37: 1570.941 | E37: =IF(AND(ISNUMBER(C37),ISNUMBER(D37)), C37-D37, "") -> -565.641 | F37: =IFERROR(E37/D37, "") -> -0.36006508 | G37: 1638.378 | H37: =IF(AND(ISNUMBER(C37),ISNUMBER(G37)), C37-G37, "") -> -633.078 | I37: =IFERROR(H37/G37, "") -> -0.38640534 | J37: 1. All inverters have morning shading.
A38: East Windsor | B38: NJ | C38: 274.5 | D38: 539.5706 | E38: =IF(AND(ISNUMBER(C38),ISNUMBER(D38)), C38-D38, "") -> -265.0706 | F38: =IFERROR(E38/D38, "") -> -0.49126213 | G38: 404.4261 | H38: =IF(AND(ISNUMBER(C38),ISNUMBER(G38)), C38-G38, "") -> -129.9261 | I38: =IFERROR(H38/G38, "") -> -0.32126042 | J38: 1. The Site was offline for most days during the month due to snow.
A39: Burlington | B39: NJ | C39: 830.2 | D39: 1183.541 | E39: =IF(AND(ISNUMBER(C39),ISNUMBER(D39)), C39-D39, "") -> -353.341 | F39: =IFERROR(E39/D39, "") -> -0.29854564 | G39: 1081.357 | H39: =IF(AND(ISNUMBER(C39),ISNUMBER(G39)), C39-G39, "") -> -251.157 | I39: =IFERROR(H39/G39, "") -> -0.23226095 | J39: 1. Site production was low most of the days in a month due to snow.
A40: Bayonne | B40: NJ | C40: 309.2 | D40: 879.3118 | E40: =IF(AND(ISNUMBER(C40),ISNUMBER(D40)), C40-D40, "") -> -570.1118 | F40: =IFERROR(E40/D40, "") -> -0.64836137 | G40: 1991.37 | H40: =IF(AND(ISNUMBER(C40),ISNUMBER(G40)), C40-G40, "") -> -1682.17 | I40: =IFERROR(H40/G40, "") -> -0.84473001 | J40: 1. The site stopped communicating to the DAS at 11:00 on 11/14, possibly due to being offline after installed with new roof and back online at 07:00 on 01/14. 2. The Site was offline for most days during the month due to snow. | K40: 1. SR111319 | L40: 1. Pending
...

Sheet Feb
A1: {=portfolio} -> Wells Fargo | D1: February Actual v. Expected | G1: February Actual v. Forecasted
A2: Total | C2: =SUM(C4:C97) -> 0 | D2: =SUM(D4:D97) -> 0 | E2: =C2-D2 -> 0 | F2: =IFERROR(E2/D2, 0) -> 0 | G2: =SUM(G4:G97) -> 0 | H2: =C2-G2 -> 0 | I2: =IFERROR(H2/G2, 0) -> 0 | J2: Some sites are missing actual data; if new sites were added, make sure they are aligned correctly (including prior months!)
A3: Site | B3: State | C3: Actual | D3: Expected | E3: Delta | F3: % | G3: Forecasted | H3: Delta | I3: % | J3: Notes | K3: Service Requests
A4: {=Sites[Site]} -> Adams & Broadway | B4: {=Sites[State]} -> CA | F4: =IFERROR(E4/D4, "") | I4: =IFERROR(H4/G4, "")
A5: Otay Mesa | B5: CA | F5: =IFERROR(E5/D5, "") | I5: =IFERROR(H5/G5, "")
A6: San Leandro | B6: CA | F6: =IFERROR(E6/D6, "") | I6: =IFERROR(H6/G6, "")
A7: Van Nuys | B7: CA | F7: =IFERROR(E7/D7, "") | I7: =IFERROR(H7/G7, "")
A8: Lodi - Lodi Vineyard | B8: CA
A9: Arden Fair Mall | B9: CA
A10: Modesto - Modesto Main | B10: CA
A11: Stevens Creek | B11: CA
A12: Covina Main | B12: CA
A13: Old Ranch Town Center | B13: CA
A14: Mountain Gate Plaza | B14: CA
A15: Arcadia Main | B15: CA
A16: Fairfield | B16: CA
A17: Los Gatos | B17: CA
A18: San Marino | B18: CA
A19: Buenaventura | B19: CA
... A90: CA: Newport Beach - MARINERS | B90: CA

Sheet Mar
A1: {=portfolio} -> Wells Fargo | D1: March Actual v. Expected | G1: March Actual v. Forecasted
A2: Total | C2: =SUM(C4:C86) -> 0 | D2: =SUM(D4:D86) -> 0 | E2: =C2-D2 -> 0 | F2: =IFERROR(E2/D2, 0) -> 0 | G2: =SUM(G4:G86) -> 0 | H2: =C2-G2 -> 0 | I2: =IFERROR(H2/G2, 0) -> 0 | J2: =IF(AND(TODAY()>DATE(2024, 3, 1), COUNTA(Sites[Site])<>(COUNT(C:C)-1)), "Some sites are missing actual data; if new sites were added, make sure they are aligned correctly (including prior months!)", "") -> Some sites are missing actual data; if new sites were added, make sure they are aligned correctly (including prior months!)
A3: Site | B3: State | C3: Actual | D3: Expected | E3: Delta | F3: % | G3: Forecasted | H3: Delta | I3: % | J3: Notes | K3: Service Requests
A4: {=Sites[Site]} -> Adams & Broadway | B4: {=Sites[State]} -> CA | F4: =IFERROR(E4/D4, "") | I4: =IFERROR(H4/G4, "")
A5: Otay Mesa | B5: CA | F5: =IFERROR(E5/D5, "") | I5: =IFERROR(H5/G5, "")
A6: San Leandro | B6: CA | F6: =IFERROR(E6/D6, "") | I6: =IFERROR(H6/G6, "")
A7: Van Nuys | B7: CA | F7: =IFERROR(E7/D7, "") | I7: =IFERROR(H7/G7, "")
A8: Lodi - Lodi Vineyard | B8: CA
A9: Arden Fair Mall | B9: CA
A10: Modesto - Modesto Main | B10: CA
A11: Stevens Creek | B11: CA
A12: Covina Main | B12: CA
A13: Old Ranch Town Center | B13: CA
A14: Mountain Gate Plaza | B14: CA
A15: Arcadia Main | B15: CA
A16: Fairfield | B16: CA
A17: Los Gatos | B17: CA
A18: San Marino | B18: CA
A19: Buenaventura | B19: CA
... A90: CA: Newport Beach - MARINERS | B90: CA

Sheet Apr
A1: {=portfolio} -> Wells Fargo | D1: April Actual v. Expected | G1: April Actual v. Forecasted
A2: Total | C2: =SUM(C4:C99) -> 0 | D2: =SUM(D4:D99) -> 0 | E2: =C2-D2 -> 0 | F2: =IFERROR(E2/D2, 0) -> 0 | G2: =SUM(G4:G99) -> 0 | H2: =C2-G2 -> 0 | I2: =IFERROR(H2/G2, 0) -> 0 | J2: =IF(AND(TODAY()>DATE(2024, 4, 1), COUNTA(Sites[Site])<>(COUNT(C:C)-1)), "Some sites are missing actual data; if new sites were added, make sure they are aligned correctly (including prior months!)", "") -> Some sites are missing actual data; if new sites were added, make sure they are aligned correctly (including prior months!)
A3: Site | B3: State | C3: Actual | D3: Expected | E3: Delta | F3: % | G3: Forecasted | H3: Delta | I3: % | J3: Notes | K3: Service Requests
A4: {=Sites[Site]} -> Adams & Broadway | B4: {=Sites[State]} -> CA | F4: =IFERROR(E4/D4, "") | I4: =IFERROR(H4/G4, "")
A5: Otay Mesa | B5: CA | F5: =IFERROR(E5/D5, "") | I5: =IFERROR(H5/G5, "")
A6: San Leandro | B6: CA | F6: =IFERROR(E6/D6, "") | I6: =IFERROR(H6/G6, "")
A7: Van Nuys | B7: CA | F7: =IFERROR(E7/D7, "") | I7: =IFERROR(H7/G7, "")
A8: Lodi - Lodi Vineyard | B8: CA
A9: Arden Fair Mall | B9: CA
A10: Modesto - Modesto Main | B10: CA
A11: Stevens Creek | B11: CA
A12: Covina Main | B12: CA
A13: Old Ranch Town Center | B13: CA
A14: Mountain Gate Plaza | B14: CA
A15: Arcadia Main | B15: CA
A16: Fairfield | B16: CA
A17: Los Gatos | B17: CA
A18: San Marino | B18: CA
A19: Buenaventura | B19: CA
... A90: CA: Newport Beach - MARINERS | B90: CA

Sheet May
A1: {=portfolio} -> Wells Fargo | D1: May Actual v. Expected | G1: May Actual v. Forecasted
A2: Total | C2: =SUM(C4:C87) -> 0 | D2: =SUM(D4:D87) -> 0 | E2: =C2-D2 -> 0 | F2: =IFERROR(E2/D2, 0) -> 0 | G2: =SUM(G4:G87) -> 0 | H2: =C2-G2 -> 0 | I2: =IFERROR(H2/G2, 0) -> 0 | J2: =IF(AND(TODAY()>DATE(2024, 5, 1), COUNTA(Sites[Site])<>(COUNT(C:C)-1)), "Some sites are missing actual data; if new sites were added, make sure they are aligned correctly (including prior months!)", "") -> Some sites are missing actual data; if new sites were added, make sure they are aligned correctly (including prior months!)
A3: Site | B3: State | C3: Actual | D3: Expected | E3: Delta | F3: % | G3: Forecasted | H3: Delta | I3: % | J3: Notes | K3: Service Requests
A4: {=Sites[Site]} -> Adams & Broadway | B4: {=Sites[State]} -> CA | F4: =IFERROR(E4/D4, "") | I4: =IFERROR(H4/G4, "")
A5: Otay Mesa | B5: CA | F5: =IFERROR(E5/D5, "") | I5: =IFERROR(H5/G5, "")
A6: San Leandro | B6: CA | F6: =IFERROR(E6/D6, "") | I6: =IFERROR(H6/G6, "")
A7: Van Nuys | B7: CA | F7: =IFERROR(E7/D7, "") | I7: =IFERROR(H7/G7, "")
A8: Lodi - Lodi Vineyard | B8: CA
A9: Arden Fair Mall | B9: CA
A10: Modesto - Modesto Main | B10: CA
A11: Stevens Creek | B11: CA
A12: Covina Main | B12: CA
A13: Old Ranch Town Center | B13: CA
A14: Mountain Gate Plaza | B14: CA
A15: Arcadia Main | B15: CA
A16: Fairfield | B16: CA
A17: Los Gatos | B17: CA
A18: San Marino | B18: CA
A19: Buenaventura | B19: CA
... A90: CA: Newport Beach - MARINERS | B90: CA

Sheet Jun
A1: {=portfolio} -> Wells Fargo | D1: June Actual v. Expected | G1: June Actual v. Forecasted
A2: Total | C2: =SUM(C4:C87) -> 0 | D2: =SUM(D4:D87) -> 0 | E2: =C2-D2 -> 0 | F2: =IFERROR(E2/D2, 0) -> 0 | G2: =SUM(G4:G87) -> 0 | H2: =C2-G2 -> 0 | I2: =IFERROR(H2/G2, 0) -> 0 | J2: =IF(AND(TODAY()>DATE(2024, 6, 1), COUNTA(Sites[Site])<>(COUNT(C:C)-1)), "Some sites are missing actual data; if new sites were added, make sure they are aligned correctly (including prior months!)", "") -> Some sites are missing actual data; if new sites were added, make sure they are aligned correctly (including prior months!)
A3: Site | B3: State | C3: Actual | D3: Expected | E3: Delta | F3: % | G3: Forecasted | H3: Delta | I3: % | J3: Notes | K3: Service Requests
A4: {=Sites[Site]} -> Adams & Broadway | B4: {=Sites[State]} -> CA | F4: =IFERROR(E4/D4, "") | I4: =IFERROR(H4/G4, "")
A5: Otay Mesa | B5: CA | F5: =IFERROR(E5/D5, "") | I5: =IFERROR(H5/G5, "")
A6: San Leandro | B6: CA | F6: =IFERROR(E6/D6, "") | I6: =IFERROR(H6/G6, "")
A7: Van Nuys | B7: CA | F7: =IFERROR(E7/D7, "") | I7: =IFERROR(H7/G7, "")
A8: Lodi - Lodi Vineyard | B8: CA
A9: Arden Fair Mall | B9: CA
A10: Modesto - Modesto Main | B10: CA
A11: Stevens Creek | B11: CA
A12: Covina Main | B12: CA
A13: Old Ranch Town Center | B13: CA
A14: Mountain Gate Plaza | B14: CA
A15: Arcadia Main | B15: CA
A16: Fairfield | B16: CA
A17: Los Gatos | B17: CA
A18: San Marino | B18: CA
A19: Buenaventura | B19: CA
... A90: CA: Newport Beach - MARINERS | B90: CA

Sheet Jul
A1: {=portfolio} -> Wells Fargo | D1: July Actual v. Expected | G1: July Actual v. Forecasted
A2: Total | C2: =SUM(C4:C86) -> 0 | D2: =SUM(D4:D86) -> 0 | E2: =C2-D2 -> 0 | F2: =IFERROR(E2/D2, 0) -> 0 | G2: =SUM(G4:G86) -> 0 | H2: =C2-G2 -> 0 | I2: =IFERROR(H2/G2, 0) -> 0 | J2: =IF(AND(TODAY()>DATE(2024, 7, 1), COUNTA(Sites[Site])<>(COUNT(C:C)-1)), "Some sites are missing actual data; if new sites were added, make sure they are aligned correctly (including prior months!)", "") -> Some sites are missing actual data; if new sites were added, make sure they are aligned correctly (including prior months!) | M2: Performance vs Prior Year | N2: Notes
A3: Site | B3: State | C3: Actual | D3: Expected | E3: Delta | F3: % | G3: Forecasted | H3: Delta | I3: % | J3: Notes | K3: Service Requests | M3: + or -
A4: {=Sites[Site]} -> Adams & Broadway | B4: {=Sites[State]} -> CA | F4: =IFERROR(E4/D4, "") | I4: =IFERROR(H4/G4, "")
A5: Otay Mesa | B5: CA | F5: =IFERROR(E5/D5, "") | I5: =IFERROR(H5/G5, "")
A6: San Leandro | B6: CA | F6: =IFERROR(E6/D6, "") | I6: =IFERROR(H6/G6, "")
A7: Van Nuys | B7: CA | F7: =IFERROR(E7/D7, "") | I7: =IFERROR(H7/G7, "")
A8: Lodi - Lodi Vineyard | B8: CA
A9: Arden Fair Mall | B9: CA
A10: Modesto - Modesto Main | B10: CA
A11: Stevens Creek | B11: CA
A12: Covina Main | B12: CA
A13: Old Ranch Town Center | B13: CA
A14: Mountain Gate Plaza | B14: CA
A15: Arcadia Main | B15: CA
A16: Fairfield | B16: CA
A17: Los Gatos | B17: CA
A18: San Marino | B18: CA
A19: Buenaventura | B19: CA
... A90: CA: Newport Beach - MARINERS | B90: CA

Sheet Aug
B1: {=portfolio} -> Wells Fargo | E1: August Actual v. Expected | H1: August Actual v. Forecasted
B2: Total | D2: =SUM(D4:D91) -> 0 | E2: =SUM(E4:E91) -> 0 | F2: =D2-E2 -> 0 | G2: =IFERROR(F2/E2, 0) -> 0 | H2: =SUM(H4:H91) -> 0 | I2: =D2-H2 -> 0 | J2: =IFERROR(I2/H2, 0) -> 0 | K2: =IF(AND(TODAY()>DATE(2024, 8, 1), COUNTA(Sites[Site])<>(COUNT(D:D)-1)), "Some sites are missing actual data; if new sites were added, make sure they are aligned correctly (including prior months!)", "") -> Some sites are missing actual data; if new sites were added, make sure they are aligned correctly (including prior months!)
B3: Site | C3: State | D3: Actual | E3: Expected | F3: Delta | G3: % | H3: Forecasted | I3: Delta | J3: % | K3: Notes | L3: Service Requests
A4: 1 | B4: {=Sites[Site]} -> Adams & Broadway | F4: =IF(AND(ISNUMBER(D4),ISNUMBER(E4)), D4-E4, "") | I4: =IF(AND(ISNUMBER(D4),ISNUMBER(H4)), D4-H4, "")
A5: =A4+1 -> 2 | B5: Otay Mesa | F5: =IF(AND(ISNUMBER(D5),ISNUMBER(E5)), D5-E5, "") | I5: =IF(AND(ISNUMBER(D5),ISNUMBER(H5)), D5-H5, "")
A6: =A5+1 -> 3 | B6: San Leandro | F6: =IF(AND(ISNUMBER(D6),ISNUMBER(E6)), D6-E6, "") | I6: =IF(AND(ISNUMBER(D6),ISNUMBER(H6)), D6-H6, "")
A7: =A6+1 -> 4 | B7: Van Nuys | F7: =IF(AND(ISNUMBER(D7),ISNUMBER(E7)), D7-E7, "") | I7: =IF(AND(ISNUMBER(D7),ISNUMBER(H7)), D7-H7, "")
A8: =A7+1 -> 5 | B8: Lodi - Lodi Vineyard
A9: =A8+1 -> 6 | B9: Arden Fair Mall
A10: =A9+1 -> 7 | B10: Modesto - Modesto Main
A11: =A10+1 -> 8 | B11: Stevens Creek
A12: =A11+1 -> 9 | B12: Covina Main
A13: =A12+1 -> 10 | B13: Old Ranch Town Center
A14: =A13+1 -> 11 | B14: Mountain Gate Plaza
A15: =A14+1 -> 12 | B15: Arcadia Main
A16: =A15+1 -> 13 | B16: Fairfield
A17: =A16+1 -> 14 | B17: Los Gatos
A18: =A17+1 -> 15 | B18: San Marino
A19: =A18+1 -> 16 | B19: Buenaventura
... A84: =A83+1 -> 81 | B84: Tucson Main Parking Garage
B85: AZ: Chandler - Chandler Campus - Bldg A
B86: AZ: Phoenix - Pinnacle Peak Ops
B87: CA: Alhambra - North Alhambra
B88: CA: La Canada - La Canada
B89: CA: Laguna Beach - LAGUNA BEACH
B90: CA: Newport Beach - MARINERS
B256: Actual vs weather adjusted (August 2025)
B257: Negative | C257: 23 | D257: 0.284
B258: No Change | C258: 18 | D258: 0.2222
B259: Positive | C259: 40 | D259: 0.4938
B262: Actual vs forecasted (August 2025)
B263: Negative | C263: 58 | D263: 0.716
B264: No Change | C264: 8 | D264: 0.0988
B265: Positive | C265: 15 | D265: 0.1852

Sheet Sep
A1: {=portfolio} -> Wells Fargo | D1: September Actual v. Expected | G1: September Actual v. Forecasted
A2: Total | C2: =SUM(C4:C91) -> 0 | D2: =SUM(D4:D91) -> 0 | E2: =C2-D2 -> 0 | F2: =IFERROR(E2/D2, 0) -> 0 | G2: =SUM(G4:G91) -> 0 | H2: =C2-G2 -> 0 | I2: =IFERROR(H2/G2, 0) -> 0 | J2: =IF(AND(TODAY()>DATE(2024, 9, 1), COUNTA(Sites[Site])<>(COUNT(C:C)-1)), "Some sites are missing actual data; if new sites were added, make sure they are aligned correctly (including prior months!)", "") -> Some sites are missing actual data; if new sites were added, make sure they are aligned correctly (including prior months!)
A3: Site | B3: State | C3: Actual | D3: Expected | E3: Delta | F3: % | G3: Forecasted | H3: Delta | I3: % | J3: Notes | K3: Service Requests
A4: {=Sites[Site]} -> Adams & Broadway | B4: {=Sites[State]} -> CA | F4: =IFERROR(E4/D4, "") | I4: =IFERROR(H4/G4, "")
A5: Otay Mesa | B5: CA | F5: =IFERROR(E5/D5, "") | I5: =IFERROR(H5/G5, "")
A6: San Leandro | B6: CA | F6: =IFERROR(E6/D6, "") | I6: =IFERROR(H6/G6, "")
A7: Van Nuys | B7: CA | F7: =IFERROR(E7/D7, "") | I7: =IFERROR(H7/G7, "")
A8: Lodi - Lodi Vineyard | B8: CA
A9: Arden Fair Mall | B9: CA
A10: Modesto - Modesto Main | B10: CA
A11: Stevens Creek | B11: CA
A12: Covina Main | B12: CA
A13: Old Ranch Town Center | B13: CA
A14: Mountain Gate Plaza | B14: CA
A15: Arcadia Main | B15: CA
A16: Fairfield | B16: CA
A17: Los Gatos | B17: CA
A18: San Marino | B18: CA
A19: Buenaventura | B19: CA
... A90: CA: Newport Beach - MARINERS | B90: CA

Sheet Oct
A1: {=portfolio} -> Wells Fargo | D1: October Actual v. Expected | G1: October Actual v. Forecasted
A2: Total | C2: =SUM(C4:C90) -> 0 | D2: =SUM(D4:D90) -> 0 | E2: =C2-D2 -> 0 | F2: =IFERROR(E2/D2, 0) -> 0 | G2: =SUM(G4:G90) -> 0 | H2: =C2-G2 -> 0 | I2: =IFERROR(H2/G2, 0) -> 0 | J2: =IF(AND(TODAY()>DATE(2024, 10, 1), COUNTA(Sites[Site])<>(COUNT(C:C)-1)), "Some sites are missing actual data; if new sites were added, make sure they are aligned correctly (including prior months!)", "") -> Some sites are missing actual data; if new sites were added, make sure they are aligned correctly (including prior months!)
