Workbook
Name JanActual: #REF!
Name JanActual2: #REF!
Name JanExpected: #REF!
Name JanExpectedDelta: #REF!
Name JanExpectedPercent: #REF!
Name JanExpPercent: #REF!
Name JanForecasted: #REF!
Name JanForecastedDelta: #REF!
Name JanForecastedPercent: #REF!
Name portfolio: Sites!$B$1:$B$1
Name Year: Sites!#REF!

Sheet Year to Date
A1: {=portfolio} -> Pardee (ENCAP) | D1: Year to Date Actual v. Expected | G1: Year to Date Actual v. Forecasted
A2: Total | C2: =SUM(C4:C86) -> 1004744.6 | D2: =SUM(D4:D86) -> 1086389.2 | E2: =C2-D2 -> -81644.602 | F2: =IFERROR(E2/D2, 0) -> -0.075152256 | G2: =SUM(G4:G86) -> 1083575.2 | H2: =C2-G2 -> -78830.529 | I2: =IFERROR(H2/G2, 0) -> -0.072750402
A3: Site | B3: State | C3: Actual | D3: Expected | E3: Delta | F3: % | G3: Forecasted | H3: Delta | I3: %
A4: {=Sites[Site]} -> AZ: ASU - Pardee - Discovery Hall | B4: {=Sites[State]} -> AZ | C4: =SUM('1st Qtr'!C4, '2nd Qtr'!C4, '3rd Qtr'!C4, '4th Qtr'!C4) -> 21298.125 | D4: =SUM('1st Qtr'!D4, '2nd Qtr'!D4, '3rd Qtr'!D4, '4th Qtr'!D4) -> 18845.884 | E4: =IF(AND(ISNUMBER(C4),ISNUMBER(D4)), C4-D4, "") -> 2452.241 | F4: =IFERROR(E4/D4, "") -> 0.13012077 | G4: =SUM('1st Qtr'!G4,'2nd Qtr'!G4,'3rd Qtr'!G4,'4th Qtr'!G4) -> 23742.099 | H4: =SUM('1st Qtr'!H4, '2nd Qtr'!H4, '3rd Qtr'!H4, '4th Qtr'!H4) -> -2443.974 | I4: =IFERROR(H4/G4, "") -> -0.10293841
A5: AZ: ASU - Pardee - Farrington | B5: AZ | C5: =SUM('1st Qtr'!C5, '2nd Qtr'!C5, '3rd Qtr'!C5, '4th Qtr'!C5) -> 90404.823 | D5: =SUM('1st Qtr'!D5, '2nd Qtr'!D5, '3rd Qtr'!D5, '4th Qtr'!D5) -> 87040.22 | E5: =IF(AND(ISNUMBER(C5),ISNUMBER(D5)), C5-D5, "") -> 3364.6035 | F5: =IFERROR(E5/D5, "") -> 0.038655732 | G5: =SUM('1st Qtr'!G5,'2nd Qtr'!G5,'3rd Qtr'!G5,'4th Qtr'!G5) -> 88173.74 | H5: =SUM(Jan!H5, Feb!H5, Mar!H5) -> 2231.0835 | I5: =IFERROR(H5/G5, "") -> 0.025303264
A6: AZ: ASU - Pardee - Macro Tech. | B6: AZ | C6: =SUM('1st Qtr'!C6, '2nd Qtr'!C6, '3rd Qtr'!C6, '4th Qtr'!C6) -> 214085.88 | D6: =SUM('1st Qtr'!D6, '2nd Qtr'!D6, '3rd Qtr'!D6, '4th Qtr'!D6) -> 326130.6 | E6: =IF(AND(ISNUMBER(C6),ISNUMBER(D6)), C6-D6, "") -> -112044.72 | F6: =IFERROR(E6/D6, "") -> -0.34355784 | G6: =SUM('1st Qtr'!G6,'2nd Qtr'!G6,'3rd Qtr'!G6,'4th Qtr'!G6) -> 318970.24 | H6: =SUM(Jan!H6, Feb!H6, Mar!H6) -> -104884.36 | I6: =IFERROR(H6/G6, "") -> -0.32882179
A7: AZ: ASU - Pardee - McCord Hall | B7: AZ | C7: =SUM('1st Qtr'!C7, '2nd Qtr'!C7, '3rd Qtr'!C7, '4th Qtr'!C7) -> 29492.25 | D7: =SUM('1st Qtr'!D7, '2nd Qtr'!D7, '3rd Qtr'!D7, '4th Qtr'!D7) -> 23630.756 | E7: =IF(AND(ISNUMBER(C7),ISNUMBER(D7)), C7-D7, "") -> 5861.494 | F7: =IFERROR(E7/D7, "") -> 0.24804513 | G7: =SUM('1st Qtr'!G7,'2nd Qtr'!G7,'3rd Qtr'!G7,'4th Qtr'!G7) -> 32051.733 | H7: =SUM(Jan!H7, Feb!H7, Mar!H7) -> -2559.483 | I7: =IFERROR(H7/G7, "") -> -0.079854746
A8: AZ: NAU - SF Garage | B8: AZ | C8: =SUM('1st Qtr'!C8, '2nd Qtr'!C8, '3rd Qtr'!C8, '4th Qtr'!C8) -> 180392 | D8: =SUM('1st Qtr'!D8, '2nd Qtr'!D8, '3rd Qtr'!D8, '4th Qtr'!D8) -> 194414.14 | E8: =IF(AND(ISNUMBER(C8),ISNUMBER(D8)), C8-D8, "") -> -14022.138 | F8: =IFERROR(E8/D8, "") -> -0.072125094 | G8: =SUM('1st Qtr'!G8,'2nd Qtr'!G8,'3rd Qtr'!G8,'4th Qtr'!G8) -> 170818.65 | H8: =SUM(Jan!H8, Feb!H8, Mar!H8) -> 9573.347 | I8: =IFERROR(H8/G8, "") -> 0.05604392
A9: AZ: ASU - Pardee - Parking Lot 11 | B9: AZ | C9: =SUM('1st Qtr'!C9, '2nd Qtr'!C9, '3rd Qtr'!C9, '4th Qtr'!C9) -> 64410.188 | D9: =SUM('1st Qtr'!D9, '2nd Qtr'!D9, '3rd Qtr'!D9, '4th Qtr'!D9) -> 60049.91 | E9: =IF(AND(ISNUMBER(C9),ISNUMBER(D9)), C9-D9, "") -> 4360.2775 | F9: =IFERROR(E9/D9, "") -> 0.072610892 | G9: =SUM('1st Qtr'!G9,'2nd Qtr'!G9,'3rd Qtr'!G9,'4th Qtr'!G9) -> 43935.49 | H9: =SUM(Jan!H9, Feb!H9, Mar!H9) -> 20474.698 | I9: =IFERROR(H9/G9, "") -> 0.46601728
A10: AZ: ASU - Pardee - Parking Lot 19 | B10: AZ | C10: =SUM('1st Qtr'!C10, '2nd Qtr'!C10, '3rd Qtr'!C10, '4th Qtr'!C10) -> 92152.625 | D10: =SUM('1st Qtr'!D10, '2nd Qtr'!D10, '3rd Qtr'!D10, '4th Qtr'!D10) -> 84699.63 | E10: =IF(AND(ISNUMBER(C10),ISNUMBER(D10)), C10-D10, "") -> 7452.995 | F10: =IFERROR(E10/D10, "") -> 0.087993242 | G10: =SUM('1st Qtr'!G10,'2nd Qtr'!G10,'3rd Qtr'!G10,'4th Qtr'!G10) -> 65057.32 | H10: =SUM(Jan!H10, Feb!H10, Mar!H10) -> 27095.305 | I10: =IFERROR(H10/G10, "") -> 0.41648357
A11: AZ: ASU - Pardee - Parking Lot 41 | B11: AZ | C11: =SUM('1st Qtr'!C11, '2nd Qtr'!C11, '3rd Qtr'!C11, '4th Qtr'!C11) -> 74533.5 | D11: =SUM('1st Qtr'!D11, '2nd Qtr'!D11, '3rd Qtr'!D11, '4th Qtr'!D11) -> 72187.7 | E11: =IF(AND(ISNUMBER(C11),ISNUMBER(D11)), C11-D11, "") -> 2345.8 | F11: =IFERROR(E11/D11, "") -> 0.032495841 | G11: =SUM('1st Qtr'!G11,'2nd Qtr'!G11,'3rd Qtr'!G11,'4th Qtr'!G11) -> 78967.29 | H11: =SUM(Jan!H11, Feb!H11, Mar!H11) -> -4433.79 | I11: =IFERROR(H11/G11, "") -> -0.056147172
A12: AZ: ASU - Pardee - Parking Lot 58 | B12: AZ | C12: =SUM('1st Qtr'!C12, '2nd Qtr'!C12, '3rd Qtr'!C12, '4th Qtr'!C12) -> 91159.5 | D12: =SUM('1st Qtr'!D12, '2nd Qtr'!D12, '3rd Qtr'!D12, '4th Qtr'!D12) -> 73363.57 | E12: =IF(AND(ISNUMBER(C12),ISNUMBER(D12)), C12-D12, "") -> 17795.93 | F12: =IFERROR(E12/D12, "") -> 0.24257176 | G12: =SUM('1st Qtr'!G12,'2nd Qtr'!G12,'3rd Qtr'!G12,'4th Qtr'!G12) -> 82881.3 | H12: =SUM(Jan!H12, Feb!H12, Mar!H12) -> 8278.2 | I12: =IFERROR(H12/G12, "") -> 0.09988019
A13: AZ: ASU - Pardee - Parking Lot 59S | B13: AZ | C13: =SUM('1st Qtr'!C13, '2nd Qtr'!C13, '3rd Qtr'!C13, '4th Qtr'!C13) -> 75749.75 | D13: =SUM('1st Qtr'!D13, '2nd Qtr'!D13, '3rd Qtr'!D13, '4th Qtr'!D13) -> 67144.1 | E13: =IF(AND(ISNUMBER(C13),ISNUMBER(D13)), C13-D13, "") -> 8605.65 | F13: =IFERROR(E13/D13, "") -> 0.12816688 | G13: =SUM('1st Qtr'!G13,'2nd Qtr'!G13,'3rd Qtr'!G13,'4th Qtr'!G13) -> 90651.3 | H13: =SUM(Jan!H13, Feb!H13, Mar!H13) -> -14901.55 | I13: =IFERROR(H13/G13, "") -> -0.16438319
A14: AZ: ASU - Pardee - Sun Devil Complex | B14: AZ | C14: =SUM('1st Qtr'!C14, '2nd Qtr'!C14, '3rd Qtr'!C14, '4th Qtr'!C14) -> 71066 | D14: =SUM('1st Qtr'!D14, '2nd Qtr'!D14, '3rd Qtr'!D14, '4th Qtr'!D14) -> 78882.73 | E14: =IF(AND(ISNUMBER(C14),ISNUMBER(D14)), C14-D14, "") -> -7816.73 | F14: =IFERROR(E14/D14, "") -> -0.099093046 | G14: =SUM('1st Qtr'!G14,'2nd Qtr'!G14,'3rd Qtr'!G14,'4th Qtr'!G14) -> 88326 | H14: =SUM(Jan!H14, Feb!H14, Mar!H14) -> -17260 | I14: =IFERROR(H14/G14, "") -> -0.19541245

Sheet 1st Qtr
A1: {=portfolio} -> Pardee (ENCAP) | D1: 1st Quarter Actual v. Expected | G1: 1st Quarter Actual v. Forecasted
A2: Total | C2: =SUM(C4:C86) -> 1004744.6 | D2: =SUM(D4:D86) -> 1086389.2 | E2: =C2-D2 -> -81644.602 | F2: =IFERROR(E2/D2, 0) -> -0.075152256 | G2: =SUM(G4:G86) -> 1083575.2 | H2: =C2-G2 -> -78830.529 | I2: =IFERROR(H2/G2, 0) -> -0.072750402
A3: Site | B3: State | C3: Actual | D3: Expected | E3: Delta | F3: % | G3: Forecasted | H3: Delta | I3: %
A4: {=Sites[Site]} -> AZ: ASU - Pardee - Discovery Hall | B4: {=Sites[State]} -> AZ | C4: =SUM(Jan!C4, Feb!C4, Mar!C4) -> 21298.125 | D4: =SUM(Jan!D4, Feb!D4, Mar!D4) -> 18845.884 | E4: =IF(AND(ISNUMBER(C4),ISNUMBER(D4)), C4-D4, "") -> 2452.241 | F4: =IFERROR(E4/D4, "") -> 0.13012077 | G4: =SUM(Jan!G4, Feb!G4, Mar!G4) -> 23742.099 | H4: =SUM(Jan!H4, Feb!H4, Mar!H4) -> -2443.974 | I4: =IFERROR(H4/G4, "") -> -0.10293841
A5: AZ: ASU - Pardee - Farrington | B5: AZ | C5: =SUM(Jan!C5, Feb!C5, Mar!C5) -> 90404.823 | D5: =SUM(Jan!D5, Feb!D5, Mar!D5) -> 87040.22 | E5: =IF(AND(ISNUMBER(C5),ISNUMBER(D5)), C5-D5, "") -> 3364.6035 | F5: =IFERROR(E5/D5, "") -> 0.038655732 | G5: =SUM(Jan!G5, Feb!G5, Mar!G5) -> 88173.74 | H5: =SUM(Jan!H5, Feb!H5, Mar!H5) -> 2231.0835 | I5: =IFERROR(H5/G5, "") -> 0.025303264
A6: AZ: ASU - Pardee - Macro Tech. | B6: AZ | C6: =SUM(Jan!C6, Feb!C6, Mar!C6) -> 214085.88 | D6: =SUM(Jan!D6, Feb!D6, Mar!D6) -> 326130.6 | E6: =IF(AND(ISNUMBER(C6),ISNUMBER(D6)), C6-D6, "") -> -112044.72 | F6: =IFERROR(E6/D6, "") -> -0.34355784 | G6: =SUM(Jan!G6, Feb!G6, Mar!G6) -> 318970.24 | H6: =SUM(Jan!H6, Feb!H6, Mar!H6) -> -104884.36 | I6: =IFERROR(H6/G6, "") -> -0.32882179
A7: AZ: ASU - Pardee - McCord Hall | B7: AZ | C7: =SUM(Jan!C7, Feb!C7, Mar!C7) -> 29492.25 | D7: =SUM(Jan!D7, Feb!D7, Mar!D7) -> 23630.756 | E7: =IF(AND(ISNUMBER(C7),ISNUMBER(D7)), C7-D7, "") -> 5861.494 | F7: =IFERROR(E7/D7, "") -> 0.24804513 | G7: =SUM(Jan!G7, Feb!G7, Mar!G7) -> 32051.733 | H7: =SUM(Jan!H7, Feb!H7, Mar!H7) -> -2559.483 | I7: =IFERROR(H7/G7, "") -> -0.079854746
A8: AZ: NAU - SF Garage | B8: AZ | C8: =SUM(Jan!C8, Feb!C8, Mar!C8) -> 180392 | D8: =SUM(Jan!D8, Feb!D8, Mar!D8) -> 194414.14 | E8: =IF(AND(ISNUMBER(C8),ISNUMBER(D8)), C8-D8, "") -> -14022.138 | F8: =IFERROR(E8/D8, "") -> -0.072125094 | G8: =SUM(Jan!G8, Feb!G8, Mar!G8) -> 170818.65 | H8: =SUM(Jan!H8, Feb!H8, Mar!H8) -> 9573.347 | I8: =IFERROR(H8/G8, "") -> 0.05604392
A9: AZ: ASU - Pardee - Parking Lot 11 | B9: AZ | C9: =SUM(Jan!C9, Feb!C9, Mar!C9) -> 64410.188 | D9: =SUM(Jan!D9, Feb!D9, Mar!D9) -> 60049.91 | E9: =IF(AND(ISNUMBER(C9),ISNUMBER(D9)), C9-D9, "") -> 4360.2775 | F9: =IFERROR(E9/D9, "") -> 0.072610892 | G9: =SUM(Jan!G9, Feb!G9, Mar!G9) -> 43935.49 | H9: =SUM(Jan!H9, Feb!H9, Mar!H9) -> 20474.698 | I9: =IFERROR(H9/G9, "") -> 0.46601728
A10: AZ: ASU - Pardee - Parking Lot 19 | B10: AZ | C10: =SUM(Jan!C10, Feb!C10, Mar!C10) -> 92152.625 | D10: =SUM(Jan!D10, Feb!D10, Mar!D10) -> 84699.63 | E10: =IF(AND(ISNUMBER(C10),ISNUMBER(D10)), C10-D10, "") -> 7452.995 | F10: =IFERROR(E10/D10, "") -> 0.087993242 | G10: =SUM(Jan!G10, Feb!G10, Mar!G10) -> 65057.32 | H10: =SUM(Jan!H10, Feb!H10, Mar!H10) -> 27095.305 | I10: =IFERROR(H10/G10, "") -> 0.41648357
A11: AZ: ASU - Pardee - Parking Lot 41 | B11: AZ | C11: =SUM(Jan!C11, Feb!C11, Mar!C11) -> 74533.5 | D11: =SUM(Jan!D11, Feb!D11, Mar!D11) -> 72187.7 | E11: =IF(AND(ISNUMBER(C11),ISNUMBER(D11)), C11-D11, "") -> 2345.8 | F11: =IFERROR(E11/D11, "") -> 0.032495841 | G11: =SUM(Jan!G11, Feb!G11, Mar!G11) -> 78967.29 | H11: =SUM(Jan!H11, Feb!H11, Mar!H11) -> -4433.79 | I11: =IFERROR(H11/G11, "") -> -0.056147172
A12: AZ: ASU - Pardee - Parking Lot 58 | B12: AZ | C12: =SUM(Jan!C12, Feb!C12, Mar!C12) -> 91159.5 | D12: =SUM(Jan!D12, Feb!D12, Mar!D12) -> 73363.57 | E12: =IF(AND(ISNUMBER(C12),ISNUMBER(D12)), C12-D12, "") -> 17795.93 | F12: =IFERROR(E12/D12, "") -> 0.24257176 | G12: =SUM(Jan!G12, Feb!G12, Mar!G12) -> 82881.3 | H12: =SUM(Jan!H12, Feb!H12, Mar!H12) -> 8278.2 | I12: =IFERROR(H12/G12, "") -> 0.09988019
A13: AZ: ASU - Pardee - Parking Lot 59S | B13: AZ | C13: =SUM(Jan!C13, Feb!C13, Mar!C13) -> 75749.75 | D13: =SUM(Jan!D13, Feb!D13, Mar!D13) -> 67144.1 | E13: =IF(AND(ISNUMBER(C13),ISNUMBER(D13)), C13-D13, "") -> 8605.65 | F13: =IFERROR(E13/D13, "") -> 0.12816688 | G13: =SUM(Jan!G13, Feb!G13, Mar!G13) -> 90651.3 | H13: =SUM(Jan!H13, Feb!H13, Mar!H13) -> -14901.55 | I13: =IFERROR(H13/G13, "") -> -0.16438319
A14: AZ: ASU - Pardee - Sun Devil Complex | B14: AZ | C14: =SUM(Jan!C14, Feb!C14, Mar!C14) -> 71066 | D14: =SUM(Jan!D14, Feb!D14, Mar!D14) -> 78882.73 | E14: =IF(AND(ISNUMBER(C14),ISNUMBER(D14)), C14-D14, "") -> -7816.73 | F14: =IFERROR(E14/D14, "") -> -0.099093046 | G14: =SUM(Jan!G14, Feb!G14, Mar!G14) -> 88326 | H14: =SUM(Jan!H14, Feb!H14, Mar!H14) -> -17260 | I14: =IFERROR(H14/G14, "") -> -0.19541245

Sheet 2nd Qtr
A1: {=portfolio} -> Pardee (ENCAP) | D1: 2nd Quarter Actual v. Expected | G1: 2nd Quarter Actual v. Forecasted
A2: Total | C2: =SUM(C4:C86) -> 0 | D2: =SUM(D4:D86) -> 0 | E2: =C2-D2 -> 0 | F2: =IFERROR(E2/D2, 0) -> 0 | G2: =SUM(G4:G86) -> 0 | H2: =C2-G2 -> 0 | I2: =IFERROR(H2/G2, 0) -> 0
A3: Site | B3: State | C3: Actual | D3: Expected | E3: Delta | F3: % | G3: Forecasted | H3: Delta | I3: %
A4: {=Sites[Site]} -> AZ: ASU - Pardee - Discovery Hall | B4: {=Sites[State]} -> AZ | C4: =SUM(Apr!C4, May!C4, Jun!C4) -> 0 | D4: =SUM(Apr!D4, May!D4, Jun!D4) -> 0 | E4: =IF(AND(ISNUMBER(C4),ISNUMBER(D4)), C4-D4, "") -> 0 | F4: =IFERROR(E4/D4, "") | G4: =SUM(Apr!G4,May!G4,Jun!G4) -> 0 | H4: =SUM(Apr!H4, May!H4, Jun!H4) -> 0 | I4: =IFERROR(H4/G4, "")
A5: AZ: ASU - Pardee - Farrington | B5: AZ | C5: =SUM(Apr!C5, May!C5, Jun!C5) -> 0 | D5: =SUM(Apr!D5, May!D5, Jun!D5) -> 0 | E5: =IF(AND(ISNUMBER(C5),ISNUMBER(D5)), C5-D5, "") -> 0 | F5: =IFERROR(E5/D5, "") | G5: =SUM(Apr!G5,May!G5,Jun!G5) -> 0 | H5: =SUM(Apr!H5, May!H5, Jun!H5) -> 0 | I5: =IFERROR(H5/G5, "")
A6: AZ: ASU - Pardee - Macro Tech. | B6: AZ | C6: =SUM(Apr!C6, May!C6, Jun!C6) -> 0 | D6: =SUM(Apr!D6, May!D6, Jun!D6) -> 0 | E6: =IF(AND(ISNUMBER(C6),ISNUMBER(D6)), C6-D6, "") -> 0 | F6: =IFERROR(E6/D6, "") | G6: =SUM(Apr!G6,May!G6,Jun!G6) -> 0 | H6: =SUM(Apr!H6, May!H6, Jun!H6) -> 0 | I6: =IFERROR(H6/G6, "")
A7: AZ: ASU - Pardee - McCord Hall | B7: AZ | C7: =SUM(Apr!C7, May!C7, Jun!C7) -> 0 | D7: =SUM(Apr!D7, May!D7, Jun!D7) -> 0 | E7: =IF(AND(ISNUMBER(C7),ISNUMBER(D7)), C7-D7, "") -> 0 | F7: =IFERROR(E7/D7, "") | G7: =SUM(Apr!G7,May!G7,Jun!G7) -> 0 | H7: =SUM(Apr!H7, May!H7, Jun!H7) -> 0 | I7: =IFERROR(H7/G7, "")
A8: AZ: NAU - SF Garage | B8: AZ | C8: =SUM(Apr!C8, May!C8, Jun!C8) -> 0 | D8: =SUM(Apr!D8, May!D8, Jun!D8) -> 0 | E8: =IF(AND(ISNUMBER(C8),ISNUMBER(D8)), C8-D8, "") -> 0 | F8: =IFERROR(E8/D8, "") | G8: =SUM(Apr!G8,May!G8,Jun!G8) -> 0 | H8: =SUM(Apr!H8, May!H8, Jun!H8) -> 0 | I8: =IFERROR(H8/G8, "")
A9: AZ: ASU - Pardee - Parking Lot 11 | B9: AZ | C9: =SUM(Apr!C9, May!C9, Jun!C9) -> 0 | D9: =SUM(Apr!D9, May!D9, Jun!D9) -> 0 | E9: =IF(AND(ISNUMBER(C9),ISNUMBER(D9)), C9-D9, "") -> 0 | F9: =IFERROR(E9/D9, "") | G9: =SUM(Apr!G9,May!G9,Jun!G9) -> 0 | H9: =SUM(Apr!H9, May!H9, Jun!H9) -> 0 | I9: =IFERROR(H9/G9, "")
A10: AZ: ASU - Pardee - Parking Lot 19 | B10: AZ | C10: =SUM(Apr!C10, May!C10, Jun!C10) -> 0 | D10: =SUM(Apr!D10, May!D10, Jun!D10) -> 0 | E10: =IF(AND(ISNUMBER(C10),ISNUMBER(D10)), C10-D10, "") -> 0 | F10: =IFERROR(E10/D10, "") | G10: =SUM(Apr!G10,May!G10,Jun!G10) -> 0 | H10: =SUM(Apr!H10, May!H10, Jun!H10) -> 0 | I10: =IFERROR(H10/G10, "")
A11: AZ: ASU - Pardee - Parking Lot 41 | B11: AZ | C11: =SUM(Apr!C11, May!C11, Jun!C11) -> 0 | D11: =SUM(Apr!D11, May!D11, Jun!D11) -> 0 | E11: =IF(AND(ISNUMBER(C11),ISNUMBER(D11)), C11-D11, "") -> 0 | F11: =IFERROR(E11/D11, "") | G11: =SUM(Apr!G11,May!G11,Jun!G11) -> 0 | H11: =SUM(Apr!H11, May!H11, Jun!H11) -> 0 | I11: =IFERROR(H11/G11, "")
A12: AZ: ASU - Pardee - Parking Lot 58 | B12: AZ | C12: =SUM(Apr!C12, May!C12, Jun!C12) -> 0 | D12: =SUM(Apr!D12, May!D12, Jun!D12) -> 0 | E12: =IF(AND(ISNUMBER(C12),ISNUMBER(D12)), C12-D12, "") -> 0 | F12: =IFERROR(E12/D12, "") | G12: =SUM(Apr!G12,May!G12,Jun!G12) -> 0 | H12: =SUM(Apr!H12, May!H12, Jun!H12) -> 0 | I12: =IFERROR(H12/G12, "")
A13: AZ: ASU - Pardee - Parking Lot 59S | B13: AZ | C13: =SUM(Apr!C13, May!C13, Jun!C13) -> 0 | D13: =SUM(Apr!D13, May!D13, Jun!D13) -> 0 | E13: =IF(AND(ISNUMBER(C13),ISNUMBER(D13)), C13-D13, "") -> 0 | F13: =IFERROR(E13/D13, "") | G13: =SUM(Apr!G13,May!G13,Jun!G13) -> 0 | H13: =SUM(Apr!H13, May!H13, Jun!H13) -> 0 | I13: =IFERROR(H13/G13, "")
A14: AZ: ASU - Pardee - Sun Devil Complex | B14: AZ | C14: =SUM(Apr!C14, May!C14, Jun!C14) -> 0 | D14: =SUM(Apr!D14, May!D14, Jun!D14) -> 0 | E14: =IF(AND(ISNUMBER(C14),ISNUMBER(D14)), C14-D14, "") -> 0 | F14: =IFERROR(E14/D14, "") | G14: =SUM(Apr!G14,May!G14,Jun!G14) -> 0 | H14: =SUM(Apr!H14, May!H14, Jun!H14) -> 0 | I14: =IFERROR(H14/G14, "")

Sheet 3rd Qtr
A1: {=portfolio} -> Pardee (ENCAP) | D1: 3rd Quarter Actual v. Expected | G1: 3rd Quarter Actual v. Forecasted
A2: Total | C2: =SUM(C4:C86) -> 0 | D2: =SUM(D4:D86) -> 0 | E2: =C2-D2 -> 0 | F2: =IFERROR(E2/D2, 0) -> 0 | G2: =SUM(G4:G86) -> 0 | H2: =C2-G2 -> 0 | I2: =IFERROR(H2/G2, 0) -> 0
A3: Site | B3: State | C3: Actual | D3: Expected | E3: Delta | F3: % | G3: Forecasted | H3: Delta | I3: %
A4: {=Sites[Site]} -> AZ: ASU - Pardee - Discovery Hall | B4: {=Sites[State]} -> AZ | C4: =SUM(Jul!C4, Aug!C4, Sep!C4) -> 0 | D4: =SUM(Jul!D4, Aug!D4, Sep!D4) -> 0 | E4: =IF(AND(ISNUMBER(C4),ISNUMBER(D4)), C4-D4, "") -> 0 | F4: =IFERROR(E4/D4, "") | G4: =SUM(Jul!G4,Aug!G4,Sep!G4) -> 0 | H4: =SUM(Jul!H4, Aug!H4, Sep!H4) -> 0 | I4: =IFERROR(H4/G4, "")
A5: AZ: ASU - Pardee - Farrington | B5: AZ | C5: =SUM(Jul!C5, Aug!C5, Sep!C5) -> 0 | D5: =SUM(Jul!D5, Aug!D5, Sep!D5) -> 0 | E5: =IF(AND(ISNUMBER(C5),ISNUMBER(D5)), C5-D5, "") -> 0 | F5: =IFERROR(E5/D5, "") | G5: =SUM(Jul!G5,Aug!G5,Sep!G5) -> 0 | H5: =SUM(Jul!H5, Aug!H5, Sep!H5) -> 0 | I5: =IFERROR(H5/G5, "")
A6: AZ: ASU - Pardee - Macro Tech. | B6: AZ | C6: =SUM(Jul!C6, Aug!C6, Sep!C6) -> 0 | D6: =SUM(Jul!D6, Aug!D6, Sep!D6) -> 0 | E6: =IF(AND(ISNUMBER(C6),ISNUMBER(D6)), C6-D6, "") -> 0 | F6: =IFERROR(E6/D6, "") | G6: =SUM(Jul!G6,Aug!G6,Sep!G6) -> 0 | H6: =SUM(Jul!H6, Aug!H6, Sep!H6) -> 0 | I6: =IFERROR(H6/G6, "")
A7: AZ: ASU - Pardee - McCord Hall | B7: AZ | C7: =SUM(Jul!C7, Aug!C7, Sep!C7) -> 0 | D7: =SUM(Jul!D7, Aug!D7, Sep!D7) -> 0 | E7: =IF(AND(ISNUMBER(C7),ISNUMBER(D7)), C7-D7, "") -> 0 | F7: =IFERROR(E7/D7, "") | G7: =SUM(Jul!G7,Aug!G7,Sep!G7) -> 0 | H7: =SUM(Jul!H7, Aug!H7, Sep!H7) -> 0 | I7: =IFERROR(H7/G7, "")
A8: AZ: NAU - SF Garage | B8: AZ | C8: =SUM(Jul!C8, Aug!C8, Sep!C8) -> 0 | D8: =SUM(Jul!D8, Aug!D8, Sep!D8) -> 0 | E8: =IF(AND(ISNUMBER(C8),ISNUMBER(D8)), C8-D8, "") -> 0 | F8: =IFERROR(E8/D8, "") | G8: =SUM(Jul!G8,Aug!G8,Sep!G8) -> 0 | H8: =SUM(Jul!H8, Aug!H8, Sep!H8) -> 0 | I8: =IFERROR(H8/G8, "")
A9: AZ: ASU - Pardee - Parking Lot 11 | B9: AZ | C9: =SUM(Jul!C9, Aug!C9, Sep!C9) -> 0 | D9: =SUM(Jul!D9, Aug!D9, Sep!D9) -> 0 | E9: =IF(AND(ISNUMBER(C9),ISNUMBER(D9)), C9-D9, "") -> 0 | F9: =IFERROR(E9/D9, "") | G9: =SUM(Jul!G9,Aug!G9,Sep!G9) -> 0 | H9: =SUM(Jul!H9, Aug!H9, Sep!H9) -> 0 | I9: =IFERROR(H9/G9, "")
A10: AZ: ASU - Pardee - Parking Lot 19 | B10: AZ | C10: =SUM(Jul!C10, Aug!C10, Sep!C10) -> 0 | D10: =SUM(Jul!D10, Aug!D10, Sep!D10) -> 0 | E10: =IF(AND(ISNUMBER(C10),ISNUMBER(D10)), C10-D10, "") -> 0 | F10: =IFERROR(E10/D10, "") | G10: =SUM(Jul!G10,Aug!G10,Sep!G10) -> 0 | H10: =SUM(Jul!H10, Aug!H10, Sep!H10) -> 0 | I10: =IFERROR(H10/G10, "")
A11: AZ: ASU - Pardee - Parking Lot 41 | B11: AZ | C11: =SUM(Jul!C11, Aug!C11, Sep!C11) -> 0 | D11: =SUM(Jul!D11, Aug!D11, Sep!D11) -> 0 | E11: =IF(AND(ISNUMBER(C11),ISNUMBER(D11)), C11-D11, "") -> 0 | F11: =IFERROR(E11/D11, "") | G11: =SUM(Jul!G11,Aug!G11,Sep!G11) -> 0 | H11: =SUM(Jul!H11, Aug!H11, Sep!H11) -> 0 | I11: =IFERROR(H11/G11, "")
A12: AZ: ASU - Pardee - Parking Lot 58 | B12: AZ | C12: =SUM(Jul!C12, Aug!C12, Sep!C12) -> 0 | D12: =SUM(Jul!D12, Aug!D12, Sep!D12) -> 0 | E12: =IF(AND(ISNUMBER(C12),ISNUMBER(D12)), C12-D12, "") -> 0 | F12: =IFERROR(E12/D12, "") | G12: =SUM(Jul!G12,Aug!G12,Sep!G12) -> 0 | H12: =SUM(Jul!H12, Aug!H12, Sep!H12) -> 0 | I12: =IFERROR(H12/G12, "")
A13: AZ: ASU - Pardee - Parking Lot 59S | B13: AZ | C13: =SUM(Jul!C13, Aug!C13, Sep!C13) -> 0 | D13: =SUM(Jul!D13, Aug!D13, Sep!D13) -> 0 | E13: =IF(AND(ISNUMBER(C13),ISNUMBER(D13)), C13-D13, "") -> 0 | F13: =IFERROR(E13/D13, "") | G13: =SUM(Jul!G13,Aug!G13,Sep!G13) -> 0 | H13: =SUM(Jul!H13, Aug!H13, Sep!H13) -> 0 | I13: =IFERROR(H13/G13, "")
A14: AZ: ASU - Pardee - Sun Devil Complex | B14: AZ | C14: =SUM(Jul!C14, Aug!C14, Sep!C14) -> 0 | D14: =SUM(Jul!D14, Aug!D14, Sep!D14) -> 0 | E14: =IF(AND(ISNUMBER(C14),ISNUMBER(D14)), C14-D14, "") -> 0 | F14: =IFERROR(E14/D14, "") | G14: =SUM(Jul!G14,Aug!G14,Sep!G14) -> 0 | H14: =SUM(Jul!H14, Aug!H14, Sep!H14) -> 0 | I14: =IFERROR(H14/G14, "")

Sheet 4th Qtr
A1: {=portfolio} -> Pardee (ENCAP) | D1: 4th Quarter Actual v. Expected | G1: 4th Quarter Actual v. Forecasted
A2: Total | C2: =SUM(C4:C86) -> 0 | D2: =SUM(D4:D86) -> 0 | E2: =C2-D2 -> 0 | F2: =IFERROR(E2/D2, 0) -> 0 | G2: =SUM(G4:G86) -> 0 | H2: =C2-G2 -> 0 | I2: =IFERROR(H2/G2, 0) -> 0
A3: Site | B3: State | C3: Actual | D3: Expected | E3: Delta | F3: % | G3: Forecasted | H3: Delta | I3: %
A4: {=Sites[Site]} -> AZ: ASU - Pardee - Discovery Hall | B4: {=Sites[State]} -> AZ | C4: =SUM(Oct!C4, Nov!C4, Dec!C4) -> 0 | D4: =SUM(Oct!D4, Nov!D4, Dec!D4) -> 0 | E4: =IF(AND(ISNUMBER(C4),ISNUMBER(D4)), C4-D4, "") -> 0 | F4: =IFERROR(E4/D4, "") | G4: =SUM(Oct!G4,Nov!G4,Dec!G4) -> 0 | H4: =SUM(Oct!H4, Nov!H4, Dec!H4) -> 0 | I4: =IFERROR(H4/G4, "")
A5: AZ: ASU - Pardee - Farrington | B5: AZ | C5: =SUM(Oct!C5, Nov!C5, Dec!C5) -> 0 | D5: =SUM(Oct!D5, Nov!D5, Dec!D5) -> 0 | E5: =IF(AND(ISNUMBER(C5),ISNUMBER(D5)), C5-D5, "") -> 0 | F5: =IFERROR(E5/D5, "") | G5: =SUM(Oct!G5,Nov!G5,Dec!G5) -> 0 | H5: =SUM(Oct!H5, Nov!H5, Dec!H5) -> 0 | I5: =IFERROR(H5/G5, "")
A6: AZ: ASU - Pardee - Macro Tech. | B6: AZ | C6: =SUM(Oct!C6, Nov!C6, Dec!C6) -> 0 | D6: =SUM(Oct!D6, Nov!D6, Dec!D6) -> 0 | E6: =IF(AND(ISNUMBER(C6),ISNUMBER(D6)), C6-D6, "") -> 0 | F6: =IFERROR(E6/D6, "") | G6: =SUM(Oct!G6,Nov!G6,Dec!G6) -> 0 | H6: =SUM(Oct!H6, Nov!H6, Dec!H6) -> 0 | I6: =IFERROR(H6/G6, "")
A7: AZ: ASU - Pardee - McCord Hall | B7: AZ | C7: =SUM(Oct!C7, Nov!C7, Dec!C7) -> 0 | D7: =SUM(Oct!D7, Nov!D7, Dec!D7) -> 0 | E7: =IF(AND(ISNUMBER(C7),ISNUMBER(D7)), C7-D7, "") -> 0 | F7: =IFERROR(E7/D7, "") | G7: =SUM(Oct!G7,Nov!G7,Dec!G7) -> 0 | H7: =SUM(Oct!H7, Nov!H7, Dec!H7) -> 0 | I7: =IFERROR(H7/G7, "")
A8: AZ: NAU - SF Garage | B8: AZ | C8: =SUM(Oct!C8, Nov!C8, Dec!C8) -> 0 | D8: =SUM(Oct!D8, Nov!D8, Dec!D8) -> 0 | E8: =IF(AND(ISNUMBER(C8),ISNUMBER(D8)), C8-D8, "") -> 0 | F8: =IFERROR(E8/D8, "") | G8: =SUM(Oct!G8,Nov!G8,Dec!G8) -> 0 | H8: =SUM(Oct!H8, Nov!H8, Dec!H8) -> 0 | I8: =IFERROR(H8/G8, "")
A9: AZ: ASU - Pardee - Parking Lot 11 | B9: AZ | C9: =SUM(Oct!C9, Nov!C9, Dec!C9) -> 0 | D9: =SUM(Oct!D9, Nov!D9, Dec!D9) -> 0 | E9: =IF(AND(ISNUMBER(C9),ISNUMBER(D9)), C9-D9, "") -> 0 | F9: =IFERROR(E9/D9, "") | G9: =SUM(Oct!G9,Nov!G9,Dec!G9) -> 0 | H9: =SUM(Oct!H9, Nov!H9, Dec!H9) -> 0 | I9: =IFERROR(H9/G9, "")
A10: AZ: ASU - Pardee - Parking Lot 19 | B10: AZ | C10: =SUM(Oct!C10, Nov!C10, Dec!C10) -> 0 | D10: =SUM(Oct!D10, Nov!D10, Dec!D10) -> 0 | E10: =IF(AND(ISNUMBER(C10),ISNUMBER(D10)), C10-D10, "") -> 0 | F10: =IFERROR(E10/D10, "") | G10: =SUM(Oct!G10,Nov!G10,Dec!G10) -> 0 | H10: =SUM(Oct!H10, Nov!H10, Dec!H10) -> 0 | I10: =IFERROR(H10/G10, "")
A11: AZ: ASU - Pardee - Parking Lot 41 | B11: AZ | C11: =SUM(Oct!C11, Nov!C11, Dec!C11) -> 0 | D11: =SUM(Oct!D11, Nov!D11, Dec!D11) -> 0 | E11: =IF(AND(ISNUMBER(C11),ISNUMBER(D11)), C11-D11, "") -> 0 | F11: =IFERROR(E11/D11, "") | G11: =SUM(Oct!G11,Nov!G11,Dec!G11) -> 0 | H11: =SUM(Oct!H11, Nov!H11, Dec!H11) -> 0 | I11: =IFERROR(H11/G11, "")
A12: AZ: ASU - Pardee - Parking Lot 58 | B12: AZ | C12: =SUM(Oct!C12, Nov!C12, Dec!C12) -> 0 | D12: =SUM(Oct!D12, Nov!D12, Dec!D12) -> 0 | E12: =IF(AND(ISNUMBER(C12),ISNUMBER(D12)), C12-D12, "") -> 0 | F12: =IFERROR(E12/D12, "") | G12: =SUM(Oct!G12,Nov!G12,Dec!G12) -> 0 | H12: =SUM(Oct!H12, Nov!H12, Dec!H12) -> 0 | I12: =IFERROR(H12/G12, "")
A13: AZ: ASU - Pardee - Parking Lot 59S | B13: AZ | C13: =SUM(Oct!C13, Nov!C13, Dec!C13) -> 0 | D13: =SUM(Oct!D13, Nov!D13, Dec!D13) -> 0 | E13: =IF(AND(ISNUMBER(C13),ISNUMBER(D13)), C13-D13, "") -> 0 | F13: =IFERROR(E13/D13, "") | G13: =SUM(Oct!G13,Nov!G13,Dec!G13) -> 0 | H13: =SUM(Oct!H13, Nov!H13, Dec!H13) -> 0 | I13: =IFERROR(H13/G13, "")
A14: AZ: ASU - Pardee - Sun Devil Complex | B14: AZ | C14: =SUM(Oct!C14, Nov!C14, Dec!C14) -> 0 | D14: =SUM(Oct!D14, Nov!D14, Dec!D14) -> 0 | E14: =IF(AND(ISNUMBER(C14),ISNUMBER(D14)), C14-D14, "") -> 0 | F14: =IFERROR(E14/D14, "") | G14: =SUM(Oct!G14,Nov!G14,Dec!G14) -> 0 | H14: =SUM(Oct!H14, Nov!H14, Dec!H14) -> 0 | I14: =IFERROR(H14/G14, "")

Sheet Jan
A1: {=portfolio} -> Pardee (ENCAP) | D1: January Actual v. Expected | G1: January Actual v. Forecasted
A2: Total | C2: =SUM(C4:C85) -> 288814.38 | D2: =SUM(D4:D85) -> 316487.48 | E2: =C2-D2 -> -27673.109 | F2: =IFERROR(E2/D2, 0) -> -0.08743824 | G2: =SUM(G4:G85) -> 295930.85 | H2: =C2-G2 -> -7116.4695 | I2: =IFERROR(H2/G2, 0) -> -0.024047745 | J2: =IF(AND(TODAY()>DATE(2024, 1, 1), COUNTA(Sites[Site])<>(COUNT(C:C)-1)), "Some sites are missing actual data; if new sites were added, make sure they are aligned correctly (including prior months!)", "")
A3: Site | B3: State | C3: Actual | D3: Expected | E3: Delta | F3: % | G3: Forecasted | H3: Delta | I3: % | J3: Notes | K3: Service Requests
A4: {=Sites[Site]} -> AZ: ASU - Pardee - Discovery Hall | B4: {=Sites[State]} -> AZ | C4: 5916.75 | D4: 5538.374 | E4: =IF(AND(ISNUMBER(C4),ISNUMBER(D4)), C4-D4, "") -> 378.376 | F4: =IFERROR(E4/D4, "") -> 0.068318969 | G4: 6580.477 | H4: =IF(AND(ISNUMBER(C4),ISNUMBER(G4)), C4-G4, "") -> -663.727 | I4: =IFERROR(H4/G4, "") -> -0.10086305 | J4: 1. Inverter is producing at maximum 40 kW throughout the month compared to its capacity 50kW due to seasonal underperformance | K4: 1. SR099649
A5: AZ: ASU - Pardee - Farrington | B5: AZ | C5: 17359 | D5: 25551.77 | E5: =IF(AND(ISNUMBER(C5),ISNUMBER(D5)), C5-D5, "") -> -8192.7695 | F5: =IFERROR(E5/D5, "") -> -0.32063413 | G5: 24198.86 | H5: =IF(AND(ISNUMBER(C5),ISNUMBER(G5)), C5-G5, "") -> -6839.8595 | I5: =IFERROR(H5/G5, "") -> -0.28265214 | J5: 1. Meter CT was replaced on 01/13 and AlsoEnergy was able to regain meter communication from 12:00 PM on 01/13 | K5: 1. SR094972
A6: AZ: ASU - Pardee - Macro Tech. | B6: AZ | C6: 76476.625 | D6: 96023.1 | E6: =IF(AND(ISNUMBER(C6),ISNUMBER(D6)), C6-D6, "") -> -19546.475 | F6: =IFERROR(E6/D6, "") -> -0.20356013 | G6: 89844.16 | H6: =IF(AND(ISNUMBER(C6),ISNUMBER(G6)), C6-G6, "") -> -13367.535 | I6: =IFERROR(H6/G6, "") -> -0.1487858 | J6: 1.Inverter 4 was offline from 01/21 and came back online on 01/24 at 10:30 after the blown fuse was replaced. 2. Inverter 4 offline from 01/25 and came back online on 01/29 at 10:45 after the blown fuse was replaced. | K6: 1. SR095814 2.SR096012 , SR096160
A7: AZ: ASU - Pardee - McCord Hall | B7: AZ | C7: 8385.875 | D7: 6453.786 | E7: =IF(AND(ISNUMBER(C7),ISNUMBER(D7)), C7-D7, "") -> 1932.089 | F7: =IFERROR(E7/D7, "") -> 0.29937296 | G7: 8884.123 | H7: =IF(AND(ISNUMBER(C7),ISNUMBER(G7)), C7-G7, "") -> -498.248 | I7: =IFERROR(H7/G7, "") -> -0.05608297
A8: AZ: NAU - SF Garage | B8: AZ | C8: 52716 | D8: 57354.054 | E8: =IF(AND(ISNUMBER(C8),ISNUMBER(D8)), C8-D8, "") -> -4638.054 | F8: =IFERROR(E8/D8, "") -> -0.080867065 | G8: 45999.135 | H8: =IF(AND(ISNUMBER(C8),ISNUMBER(G8)), C8-G8, "") -> 6716.865 | I8: =IFERROR(H8/G8, "") -> 0.14602155
A9: AZ: ASU - Pardee - Parking Lot 11 | B9: AZ | C9: 18327.75 | D9: 17757.76 | E9: =IF(AND(ISNUMBER(C9),ISNUMBER(D9)), C9-D9, "") -> 569.99 | F9: =IFERROR(E9/D9, "") -> 0.03209808 | G9: 10305.89 | H9: =IF(AND(ISNUMBER(C9),ISNUMBER(G9)), C9-G9, "") -> 8021.86 | I9: =IFERROR(H9/G9, "") -> 0.77837625
A10: AZ: ASU - Pardee - Parking Lot 19 | B10: AZ | C10: 26035.5 | D10: 25220.52 | E10: =IF(AND(ISNUMBER(C10),ISNUMBER(D10)), C10-D10, "") -> 814.98 | F10: =IFERROR(E10/D10, "") -> 0.032314163 | G10: 15260.94 | H10: =IF(AND(ISNUMBER(C10),ISNUMBER(G10)), C10-G10, "") -> 10774.56 | I10: =IFERROR(H10/G10, "") -> 0.70602204
A11: AZ: ASU - Pardee - Parking Lot 41 | B11: AZ | C11: 19602.125 | D11: 21279.74 | E11: =IF(AND(ISNUMBER(C11),ISNUMBER(D11)), C11-D11, "") -> -1677.615 | F11: =IFERROR(E11/D11, "") -> -0.078836255 | G11: 21672.34 | H11: =IF(AND(ISNUMBER(C11),ISNUMBER(G11)), C11-G11, "") -> -2070.215 | I11: =IFERROR(H11/G11, "") -> -0.095523372 | J11: 1. Inverter 2 was underperforming 20kW down compared to inverter 1 due to L1 SP320 cartilage needs replacement and found active ground fault on CB 2-2 string 5. | K11: 1. PM4031, SR086964, SR086966
A12: AZ: ASU - Pardee - Parking Lot 58 | B12: AZ | C12: 25842.75 | D12: 19977.46 | E12: =IF(AND(ISNUMBER(C12),ISNUMBER(D12)), C12-D12, "") -> 5865.29 | F12: =IFERROR(E12/D12, "") -> 0.29359538 | G12: 22973.07 | H12: =IF(AND(ISNUMBER(C12),ISNUMBER(G12)), C12-G12, "") -> 2869.68 | I12: =IFERROR(H12/G12, "") -> 0.12491495
A13: AZ: ASU - Pardee - Parking Lot 59S | B13: AZ | C13: 20102.5 | D13: 18284.13 | E13: =IF(AND(ISNUMBER(C13),ISNUMBER(D13)), C13-D13, "") -> 1818.37 | F13: =IFERROR(E13/D13, "") -> 0.099450726 | G13: 25126.85 | H13: =IF(AND(ISNUMBER(C13),ISNUMBER(G13)), C13-G13, "") -> -5024.35 | I13: =IFERROR(H13/G13, "") -> -0.19995941 | J13: 1.Inverter 1 is underperforming by 12kW down from 08:00 AM to 12:30 PM due to seasonal shading | K13: 1. SR099639
A14: AZ: ASU - Pardee - Sun Devil Complex | B14: AZ | C14: 18049.5 | D14: 23046.79 | E14: =IF(AND(ISNUMBER(C14),ISNUMBER(D14)), C14-D14, "") -> -4997.29 | F14: =IFERROR(E14/D14, "") -> -0.21683237 | G14: 25085 | H14: =IF(AND(ISNUMBER(C14),ISNUMBER(G14)), C14-G14, "") -> -7035.5 | I14: =IFERROR(H14/G14, "") -> -0.28046641 | J14: 1. Inverter 1 was offline from 07:00 on 01/06 to 12:00pm on 01/24 due to failed PWR DIST Card | K14: 1. SR094724

Sheet Feb
A1: {=portfolio} -> Pardee (ENCAP) | D1: February Actual v. Expected | G1: February Actual v. Forecasted
A2: Total | C2: =SUM(C4:C86) -> 332166.08 | D2: =SUM(D4:D86) -> 336249.9 | E2: =C2-D2 -> -4083.8216 | F2: =IFERROR(E2/D2, 0) -> -0.012145198 | G2: =SUM(G4:G86) -> 336219.7 | H2: =C2-G2 -> -4053.6226 | I2: =IFERROR(H2/G2, 0) -> -0.012056469 | J2: =IF(AND(TODAY()>DATE(2024, 2, 1), COUNTA(Sites[Site])<>(COUNT(C:C)-1)), "Some sites are missing actual data; if new sites were added, make sure they are aligned correctly (including prior months!)", "")
A3: Site | B3: State | C3: Actual | D3: Expected | E3: Delta | F3: % | G3: Forecasted | H3: Delta | I3: % | J3: Notes | K3: Service Requests
A4: {=Sites[Site]} -> AZ: ASU - Pardee - Discovery Hall | B4: {=Sites[State]} -> AZ | C4: 6598.875 | D4: 5712.358 | E4: =IF(AND(ISNUMBER(C4),ISNUMBER(D4)), C4-D4, "") -> 886.517 | F4: =IFERROR(E4/D4, "") -> 0.15519283 | G4: 7494.711 | H4: =IF(AND(ISNUMBER(C4),ISNUMBER(G4)), C4-G4, "") -> -895.836 | I4: =IFERROR(H4/G4, "") -> -0.11952909 | J4: 1. Inverter is producing at maximum 40 kW throughout the month compared to its capacity 50kW due to seasonal underperformance | K4: 1. SR099649
A5: AZ: ASU - Pardee - Farrington | B5: AZ | C5: 31007.328 | D5: 26810.49 | E5: =IF(AND(ISNUMBER(C5),ISNUMBER(D5)), C5-D5, "") -> 4196.8384 | F5: =IFERROR(E5/D5, "") -> 0.15653718 | G5: 27770.28 | H5: =IF(AND(ISNUMBER(C5),ISNUMBER(G5)), C5-G5, "") -> 3237.0484 | I5: =IFERROR(H5/G5, "") -> 0.11656521
A6: AZ: ASU - Pardee - Macro Tech. | B6: AZ | C6: 72327.375 | D6: 99628.9 | E6: =IF(AND(ISNUMBER(C6),ISNUMBER(D6)), C6-D6, "") -> -27301.525 | F6: =IFERROR(E6/D6, "") -> -0.27403218 | G6: 97007.78 | H6: =IF(AND(ISNUMBER(C6),ISNUMBER(G6)), C6-G6, "") -> -24680.405 | I6: =IFERROR(H6/G6, "") -> -0.25441676 | J6: 1. Inverter 4 was tripped offline at 18:15 on 02/16 due to control card assembly plus backplane. 2. Inverter 2 and meter 2 stopped communication at 11:50AM on 02/20 tech suggested that replacing the Vlink MESR901 serial server. | K6: 1. SR095814, SR096160, SR096012 2. SR097592 | L6: SR096160 | M6: SR096012 | N6: SR097592
A7: AZ: ASU - Pardee - McCord Hall | B7: AZ | C7: 9147.5 | D7: 7200.132 | E7: =IF(AND(ISNUMBER(C7),ISNUMBER(D7)), C7-D7, "") -> 1947.368 | F7: =IFERROR(E7/D7, "") -> 0.27046282 | G7: 10117.14 | H7: =IF(AND(ISNUMBER(C7),ISNUMBER(G7)), C7-G7, "") -> -969.64 | I7: =IFERROR(H7/G7, "") -> -0.095841315
A8: AZ: NAU - SF Garage | B8: AZ | C8: 60795 | D8: 63728.1 | E8: =IF(AND(ISNUMBER(C8),ISNUMBER(D8)), C8-D8, "") -> -2933.1 | F8: =IFERROR(E8/D8, "") -> -0.046025223 | G8: 53900.3 | H8: =IF(AND(ISNUMBER(C8),ISNUMBER(G8)), C8-G8, "") -> 6894.7 | I8: =IFERROR(H8/G8, "") -> 0.1279158
A9: AZ: ASU - Pardee - Parking Lot 11 | B9: AZ | C9: 20052.5 | D9: 18203.32 | E9: =IF(AND(ISNUMBER(C9),ISNUMBER(D9)), C9-D9, "") -> 1849.18 | F9: =IFERROR(E9/D9, "") -> 0.10158477 | G9: 13387.73 | H9: =IF(AND(ISNUMBER(C9),ISNUMBER(G9)), C9-G9, "") -> 6664.77 | I9: =IFERROR(H9/G9, "") -> 0.49782674
A10: AZ: ASU - Pardee - Parking Lot 19 | B10: AZ | C10: 28758 | D10: 25680.77 | E10: =IF(AND(ISNUMBER(C10),ISNUMBER(D10)), C10-D10, "") -> 3077.23 | F10: =IFERROR(E10/D10, "") -> 0.11982624 | G10: 19823.29 | H10: =IF(AND(ISNUMBER(C10),ISNUMBER(G10)), C10-G10, "") -> 8934.71 | I10: =IFERROR(H10/G10, "") -> 0.45071782
A11: AZ: ASU - Pardee - Parking Lot 41 | B11: AZ | C11: 23110.25 | D11: 22043 | E11: =IF(AND(ISNUMBER(C11),ISNUMBER(D11)), C11-D11, "") -> 1067.25 | F11: =IFERROR(E11/D11, "") -> 0.048416731 | G11: 24870.34 | H11: =IF(AND(ISNUMBER(C11),ISNUMBER(G11)), C11-G11, "") -> -1760.09 | I11: =IFERROR(H11/G11, "") -> -0.070770645 | J11: 1.Inverter 2 is underperforming by 20kW down due to shading related issue. | K11: 1. SR096743
A12: AZ: ASU - Pardee - Parking Lot 58 | B12: AZ | C12: 28384.25 | D12: 22538.77 | E12: =IF(AND(ISNUMBER(C12),ISNUMBER(D12)), C12-D12, "") -> 5845.48 | F12: =IFERROR(E12/D12, "") -> 0.25935222 | G12: 26162.83 | H12: =IF(AND(ISNUMBER(C12),ISNUMBER(G12)), C12-G12, "") -> 2221.42 | I12: =IFERROR(H12/G12, "") -> 0.084907481
A13: AZ: ASU - Pardee - Parking Lot 59S | B13: AZ | C13: 23550 | D13: 20628.14 | E13: =IF(AND(ISNUMBER(C13),ISNUMBER(D13)), C13-D13, "") -> 2921.86 | F13: =IFERROR(E13/D13, "") -> 0.14164438 | G13: 28615.3 | H13: =IF(AND(ISNUMBER(C13),ISNUMBER(G13)), C13-G13, "") -> -5065.3 | I13: =IFERROR(H13/G13, "") -> -0.1770137 | J13: 1.Inverter 1 is underperforming by 12kW down from 08:00 AM to 12:30 PM due to seasonal shading | K13: 1. SR099639
A14: AZ: ASU - Pardee - Sun Devil Complex | B14: AZ | C14: 28435 | D14: 24075.92 | E14: =IF(AND(ISNUMBER(C14),ISNUMBER(D14)), C14-D14, "") -> 4359.08 | F14: =IFERROR(E14/D14, "") -> 0.18105559 | G14: 27070 | H14: =IF(AND(ISNUMBER(C14),ISNUMBER(G14)), C14-G14, "") -> 1365 | I14: =IFERROR(H14/G14, "") -> 0.050424825 | J14: 1. Inverter 2 having multiple tripping events on 02/25 and 02/27. | K14: 1. SR097804

Sheet Mar
A1: {=portfolio} -> Pardee (ENCAP) | D1: March Actual v. Expected | G1: March Actual v. Forecasted
A2: Total | C2: =SUM(C4:C86) -> 383764.18 | D2: =SUM(D4:D86) -> 433651.85 | E2: =C2-D2 -> -49887.672 | F2: =IFERROR(E2/D2, 0) -> -0.11504084 | G2: =SUM(G4:G86) -> 451424.62 | H2: =C2-G2 -> -67660.437 | I2: =IFERROR(H2/G2, 0) -> -0.14988203 | J2: =IF(AND(TODAY()>DATE(2024, 3, 1), COUNTA(Sites[Site])<>(COUNT(C:C)-1)), "Some sites are missing actual data; if new sites were added, make sure they are aligned correctly (including prior months!)", "")
A3: Site | B3: State | C3: Actual | D3: Expected | E3: Delta | F3: % | G3: Forecasted | H3: Delta | I3: % | J3: Notes | K3: Service Requests
A4: {=Sites[Site]} -> AZ: ASU - Pardee - Discovery Hall | B4: {=Sites[State]} -> AZ | C4: 8782.5 | D4: 7595.152 | E4: =IF(AND(ISNUMBER(C4),ISNUMBER(D4)), C4-D4, "") -> 1187.348 | F4: =IFERROR(E4/D4, "") -> 0.15632972 | G4: 9666.911 | H4: =IF(AND(ISNUMBER(C4),ISNUMBER(G4)), C4-G4, "") -> -884.411 | I4: =IFERROR(H4/G4, "") -> -0.091488481
A5: AZ: ASU - Pardee - Farrington | B5: AZ | C5: 42038.495 | D5: 34677.96 | E5: =IF(AND(ISNUMBER(C5),ISNUMBER(D5)), C5-D5, "") -> 7360.5346 | F5: =IFERROR(E5/D5, "") -> 0.21225397 | G5: 36204.6 | H5: =IF(AND(ISNUMBER(C5),ISNUMBER(G5)), C5-G5, "") -> 5833.8946 | I5: =IFERROR(H5/G5, "") -> 0.16113683
A6: AZ: ASU - Pardee - Macro Tech. | B6: AZ | C6: 65281.875 | D6: 130478.6 | E6: =IF(AND(ISNUMBER(C6),ISNUMBER(D6)), C6-D6, "") -> -65196.725 | F6: =IFERROR(E6/D6, "") -> -0.4996737 | G6: 132118.3 | H6: =IF(AND(ISNUMBER(C6),ISNUMBER(G6)), C6-G6, "") -> -66836.425 | I6: =IFERROR(H6/G6, "") -> -0.50588317 | J6: 1.Inverter 4 was offline from 18:20 on 02/16 to 22:20 on 03/25. On 03/25, a Bold technician was onsite to replace the controller card and Upon arrival he found a worn DC shunt harness, which was requested for replacement. The inverter went offline again at 18:45 on 03/26 and requires additional components for full restoration. 2. Inverter 2 and meter 2 stopped communicating at 11:50AM on 02/20 and production can't be confirmed.On 02/24 upon troubleshooting ,technician recommends replacing the Vlink MESR901 serial server | K6: 1.SR096012,SR096160 2.SR097592 | L6: SR096160 | M6: SR097592
A7: AZ: ASU - Pardee - McCord Hall | B7: AZ | C7: 11958.875 | D7: 9976.838 | E7: =IF(AND(ISNUMBER(C7),ISNUMBER(D7)), C7-D7, "") -> 1982.037 | F7: =IFERROR(E7/D7, "") -> 0.19866385 | G7: 13050.47 | H7: =IF(AND(ISNUMBER(C7),ISNUMBER(G7)), C7-G7, "") -> -1091.595 | I7: =IFERROR(H7/G7, "") -> -0.083644114
A8: AZ: NAU - SF Garage | B8: AZ | C8: 66881 | D8: 73331.984 | E8: =IF(AND(ISNUMBER(C8),ISNUMBER(D8)), C8-D8, "") -> -6450.984 | F8: =IFERROR(E8/D8, "") -> -0.087969582 | G8: 70919.218 | H8: =IF(AND(ISNUMBER(C8),ISNUMBER(G8)), C8-G8, "") -> -4038.218 | I8: =IFERROR(H8/G8, "") -> -0.056941096
A9: AZ: ASU - Pardee - Parking Lot 11 | B9: AZ | C9: 26029.938 | D9: 24088.83 | E9: =IF(AND(ISNUMBER(C9),ISNUMBER(D9)), C9-D9, "") -> 1941.1075 | F9: =IFERROR(E9/D9, "") -> 0.080581228 | G9: 20241.87 | H9: =IF(AND(ISNUMBER(C9),ISNUMBER(G9)), C9-G9, "") -> 5788.0675 | I9: =IFERROR(H9/G9, "") -> 0.2859453
A10: AZ: ASU - Pardee - Parking Lot 19 | B10: AZ | C10: 37359.125 | D10: 33798.34 | E10: =IF(AND(ISNUMBER(C10),ISNUMBER(D10)), C10-D10, "") -> 3560.785 | F10: =IFERROR(E10/D10, "") -> 0.10535384 | G10: 29973.09 | H10: =IF(AND(ISNUMBER(C10),ISNUMBER(G10)), C10-G10, "") -> 7386.035 | I10: =IFERROR(H10/G10, "") -> 0.24642221
A11: AZ: ASU - Pardee - Parking Lot 41 | B11: AZ | C11: 31821.125 | D11: 28864.96 | E11: =IF(AND(ISNUMBER(C11),ISNUMBER(D11)), C11-D11, "") -> 2956.165 | F11: =IFERROR(E11/D11, "") -> 0.10241362 | G11: 32424.61 | H11: =IF(AND(ISNUMBER(C11),ISNUMBER(G11)), C11-G11, "") -> -603.485 | I11: =IFERROR(H11/G11, "") -> -0.018611943 | J11: 1.Inverter 2 is underperforming by approximately 20 kW, likely due to shading related issues | K11: 1.SR096743
A12: AZ: ASU - Pardee - Parking Lot 58 | B12: AZ | C12: 36932.5 | D12: 30847.34 | E12: =IF(AND(ISNUMBER(C12),ISNUMBER(D12)), C12-D12, "") -> 6085.16 | F12: =IFERROR(E12/D12, "") -> 0.19726693 | G12: 33745.4 | H12: =IF(AND(ISNUMBER(C12),ISNUMBER(G12)), C12-G12, "") -> 3187.1 | I12: =IFERROR(H12/G12, "") -> 0.094445465 | J12: 1. A canopy strike was reported on 01/17, prompting immediate dispatch to secure the parking lot array and document the damages. Dispatch is scheduled to return on 04/10 to install five modules, reconnect homeruns, and re-energize the string. | K12: 1.SR095815
A13: AZ: ASU - Pardee - Parking Lot 59S | B13: AZ | C13: 32097.25 | D13: 28231.83 | E13: =IF(AND(ISNUMBER(C13),ISNUMBER(D13)), C13-D13, "") -> 3865.42 | F13: =IFERROR(E13/D13, "") -> 0.13691709 | G13: 36909.15 | H13: =IF(AND(ISNUMBER(C13),ISNUMBER(G13)), C13-G13, "") -> -4811.9 | I13: =IFERROR(H13/G13, "") -> -0.13037147 | J13: 1.Inverter 1 is underperforming by 12kW down from 08:00 AM to 12:30 PM due to seasonal shading | K13: 1. SR099639
A14: AZ: ASU - Pardee - Sun Devil Complex | B14: AZ | C14: 24581.5 | D14: 31760.02 | E14: =IF(AND(ISNUMBER(C14),ISNUMBER(D14)), C14-D14, "") -> -7178.52 | F14: =IFERROR(E14/D14, "") -> -0.22602379 | G14: 36171 | H14: =IF(AND(ISNUMBER(C14),ISNUMBER(G14)), C14-G14, "") -> -11589.5 | I14: =IFERROR(H14/G14, "") -> -0.32040861 | J14: 1. Inverter 2 tripped offline at 15:45 on 03/02 and was restored at 16:10 on 03/03 after a technician restart. It went offline again on 03/23 due to a "Watchdog Timer Fault." On 03/24, technicians confirmed the fault is related to internal monitoring and can be triggered by grid voltage fluctuations. The inverter was power cycled and back online at 09:10 AM on 03/24. 2. Inverter 1 tripped offline at 13:00 on 03/15/25 due to a ground fault. On 03/18, the technician observed heat marks on several Trina modules, likely impacted by recent heavy rain. A follow-up visit is required, along with replacement of 5A fuses. | K14: 1.SR097804,SR098900 2.SR098620 | L14: SR098900 | M14: SR098620

Sheet Apr
A1: {=portfolio} -> Pardee (ENCAP) | D1: April Actual v. Expected | G1: April Actual v. Forecasted
A2: Total | C2: =SUM(C4:C86) -> 0 | D2: =SUM(D4:D86) -> 0 | E2: =C2-D2 -> 0 | F2: =IFERROR(E2/D2, 0) -> 0 | G2: =SUM(G4:G86) -> 0 | H2: =C2-G2 -> 0 | I2: =IFERROR(H2/G2, 0) -> 0 | J2: =IF(AND(TODAY()>DATE(2024, 4, 1), COUNTA(Sites[Site])<>(COUNT(C:C)-1)), "Some sites are missing actual data; if new sites were added, make sure they are aligned correctly (including prior months!)", "") -> Some sites are missing actual data; if new sites were added, make sure they are aligned correctly (including prior months!)
A3: Site | B3: State | C3: Actual | D3: Expected | E3: Delta | F3: % | G3: Forecasted | H3: Delta | I3: % | J3: Notes | K3: Service Requests
A4: {=Sites[Site]} -> AZ: ASU - Pardee - Discovery Hall | B4: {=Sites[State]} -> AZ | E4: =IF(AND(ISNUMBER(C4),ISNUMBER(D4)), C4-D4, "") | F4: =IFERROR(E4/D4, "") | H4: =IF(AND(ISNUMBER(C4),ISNUMBER(G4)), C4-G4, "") | I4: =IFERROR(H4/G4, "")
A5: AZ: ASU - Pardee - Farrington | B5: AZ | E5: =IF(AND(ISNUMBER(C5),ISNUMBER(D5)), C5-D5, "") | F5: =IFERROR(E5/D5, "") | H5: =IF(AND(ISNUMBER(C5),ISNUMBER(G5)), C5-G5, "") | I5: =IFERROR(H5/G5, "")
A6: AZ: ASU - Pardee - Macro Tech. | B6: AZ | E6: =IF(AND(ISNUMBER(C6),ISNUMBER(D6)), C6-D6, "") | F6: =IFERROR(E6/D6, "") | H6: =IF(AND(ISNUMBER(C6),ISNUMBER(G6)), C6-G6, "") | I6: =IFERROR(H6/G6, "")
A7: AZ: ASU - Pardee - McCord Hall | B7: AZ | E7: =IF(AND(ISNUMBER(C7),ISNUMBER(D7)), C7-D7, "") | F7: =IFERROR(E7/D7, "") | H7: =IF(AND(ISNUMBER(C7),ISNUMBER(G7)), C7-G7, "") | I7: =IFERROR(H7/G7, "")
A8: AZ: NAU - SF Garage | B8: AZ | E8: =IF(AND(ISNUMBER(C8),ISNUMBER(D8)), C8-D8, "") | F8: =IFERROR(E8/D8, "") | H8: =IF(AND(ISNUMBER(C8),ISNUMBER(G8)), C8-G8, "") | I8: =IFERROR(H8/G8, "")
A9: AZ: ASU - Pardee - Parking Lot 11 | B9: AZ | E9: =IF(AND(ISNUMBER(C9),ISNUMBER(D9)), C9-D9, "") | F9: =IFERROR(E9/D9, "") | H9: =IF(AND(ISNUMBER(C9),ISNUMBER(G9)), C9-G9, "") | I9: =IFERROR(H9/G9, "")
A10: AZ: ASU - Pardee - Parking Lot 19 | B10: AZ | E10: =IF(AND(ISNUMBER(C10),ISNUMBER(D10)), C10-D10, "") | F10: =IFERROR(E10/D10, "") | H10: =IF(AND(ISNUMBER(C10),ISNUMBER(G10)), C10-G10, "") | I10: =IFERROR(H10/G10, "")
A11: AZ: ASU - Pardee - Parking Lot 41 | B11: AZ | E11: =IF(AND(ISNUMBER(C11),ISNUMBER(D11)), C11-D11, "") | F11: =IFERROR(E11/D11, "") | H11: =IF(AND(ISNUMBER(C11),ISNUMBER(G11)), C11-G11, "") | I11: =IFERROR(H11/G11, "")
A12: AZ: ASU - Pardee - Parking Lot 58 | B12: AZ | E12: =IF(AND(ISNUMBER(C12),ISNUMBER(D12)), C12-D12, "") | F12: =IFERROR(E12/D12, "") | H12: =IF(AND(ISNUMBER(C12),ISNUMBER(G12)), C12-G12, "") | I12: =IFERROR(H12/G12, "")
A13: AZ: ASU - Pardee - Parking Lot 59S | B13: AZ | E13: =IF(AND(ISNUMBER(C13),ISNUMBER(D13)), C13-D13, "") | F13: =IFERROR(E13/D13, "") | H13: =IF(AND(ISNUMBER(C13),ISNUMBER(G13)), C13-G13, "") | I13: =IFERROR(H13/G13, "")
A14: AZ: ASU - Pardee - Sun Devil Complex | B14: AZ | E14: =IF(AND(ISNUMBER(C14),ISNUMBER(D14)), C14-D14, "") | F14: =IFERROR(E14/D14, "") | H14: =IF(AND(ISNUMBER(C14),ISNUMBER(G14)), C14-G14, "") | I14: =IFERROR(H14/G14, "")

Sheet May
A1: {=portfolio} -> Pardee (ENCAP) | D1: May Actual v. Expected | G1: May Actual v. Forecasted
A2: Total | C2: =SUM(C4:C86) -> 0 | D2: =SUM(D4:D86) -> 0 | E2: =C2-D2 -> 0 | F2: =IFERROR(E2/D2, 0) -> 0 | G2: =SUM(G4:G86) -> 0 | H2: =C2-G2 -> 0 | I2: =IFERROR(H2/G2, 0) -> 0 | J2: =IF(AND(TODAY()>DATE(2024, 5, 1), COUNTA(Sites[Site])<>(COUNT(C:C)-1)), "Some sites are missing actual data; if new sites were added, make sure they are aligned correctly (including prior months!)", "") -> Some sites are missing actual data; if new sites were added, make sure they are aligned correctly (including prior months!)
A3: Site | B3: State | C3: Actual | D3: Expected | E3: Delta | F3: % | G3: Forecasted | H3: Delta | I3: % | J3: Notes | K3: Service Requests
A4: {=Sites[Site]} -> AZ: ASU - Pardee - Discovery Hall | B4: {=Sites[State]} -> AZ | E4: =IF(AND(ISNUMBER(C4),ISNUMBER(D4)), C4-D4, "") | F4: =IFERROR(E4/D4, "") | H4: =IF(AND(ISNUMBER(C4),ISNUMBER(G4)), C4-G4, "") | I4: =IFERROR(H4/G4, "")
A5: AZ: ASU - Pardee - Farrington | B5: AZ | E5: =IF(AND(ISNUMBER(C5),ISNUMBER(D5)), C5-D5, "") | F5: =IFERROR(E5/D5, "") | H5: =IF(AND(ISNUMBER(C5),ISNUMBER(G5)), C5-G5, "") | I5: =IFERROR(H5/G5, "")
A6: AZ: ASU - Pardee - Macro Tech. | B6: AZ | E6: =IF(AND(ISNUMBER(C6),ISNUMBER(D6)), C6-D6, "") | F6: =IFERROR(E6/D6, "") | H6: =IF(AND(ISNUMBER(C6),ISNUMBER(G6)), C6-G6, "") | I6: =IFERROR(H6/G6, "")
A7: AZ: ASU - Pardee - McCord Hall | B7: AZ | E7: =IF(AND(ISNUMBER(C7),ISNUMBER(D7)), C7-D7, "") | F7: =IFERROR(E7/D7, "") | H7: =IF(AND(ISNUMBER(C7),ISNUMBER(G7)), C7-G7, "") | I7: =IFERROR(H7/G7, "")
A8: AZ: NAU - SF Garage | B8: AZ | E8: =IF(AND(ISNUMBER(C8),ISNUMBER(D8)), C8-D8, "") | F8: =IFERROR(E8/D8, "") | H8: =IF(AND(ISNUMBER(C8),ISNUMBER(G8)), C8-G8, "") | I8: =IFERROR(H8/G8, "")
A9: AZ: ASU - Pardee - Parking Lot 11 | B9: AZ | E9: =IF(AND(ISNUMBER(C9),ISNUMBER(D9)), C9-D9, "") | F9: =IFERROR(E9/D9, "") | H9: =IF(AND(ISNUMBER(C9),ISNUMBER(G9)), C9-G9, "") | I9: =IFERROR(H9/G9, "")
A10: AZ: ASU - Pardee - Parking Lot 19 | B10: AZ | E10: =IF(AND(ISNUMBER(C10),ISNUMBER(D10)), C10-D10, "") | F10: =IFERROR(E10/D10, "") | H10: =IF(AND(ISNUMBER(C10),ISNUMBER(G10)), C10-G10, "") | I10: =IFERROR(H10/G10, "")
A11: AZ: ASU - Pardee - Parking Lot 41 | B11: AZ | E11: =IF(AND(ISNUMBER(C11),ISNUMBER(D11)), C11-D11, "") | F11: =IFERROR(E11/D11, "") | H11: =IF(AND(ISNUMBER(C11),ISNUMBER(G11)), C11-G11, "") | I11: =IFERROR(H11/G11, "")
A12: AZ: ASU - Pardee - Parking Lot 58 | B12: AZ | E12: =IF(AND(ISNUMBER(C12),ISNUMBER(D12)), C12-D12, "") | F12: =IFERROR(E12/D12, "") | H12: =IF(AND(ISNUMBER(C12),ISNUMBER(G12)), C12-G12, "") | I12: =IFERROR(H12/G12, "")
A13: AZ: ASU - Pardee - Parking Lot 59S | B13: AZ | E13: =IF(AND(ISNUMBER(C13),ISNUMBER(D13)), C13-D13, "") | F13: =IFERROR(E13/D13, "") | H13: =IF(AND(ISNUMBER(C13),ISNUMBER(G13)), C13-G13, "") | I13: =IFERROR(H13/G13, "")
A14: AZ: ASU - Pardee - Sun Devil Complex | B14: AZ | E14: =IF(AND(ISNUMBER(C14),ISNUMBER(D14)), C14-D14, "") | F14: =IFERROR(E14/D14, "") | H14: =IF(AND(ISNUMBER(C14),ISNUMBER(G14)), C14-G14, "") | I14: =IFERROR(H14/G14, "")

Sheet Jun
A1: {=portfolio} -> Pardee (ENCAP) | D1: June Actual v. Expected | G1: June Actual v. Forecasted
A2: Total | C2: =SUM(C4:C86) -> 0 | D2: =SUM(D4:D86) -> 0 | E2: =C2-D2 -> 0 | F2: =IFERROR(E2/D2, 0) -> 0 | G2: =SUM(G4:G86) -> 0 | H2: =C2-G2 -> 0 | I2: =IFERROR(H2/G2, 0) -> 0 | J2: =IF(AND(TODAY()>DATE(2024, 6, 1), COUNTA(Sites[Site])<>(COUNT(C:C)-1)), "Some sites are missing actual data; if new sites were added, make sure they are aligned correctly (including prior months!)", "") -> Some sites are missing actual data; if new sites were added, make sure they are aligned correctly (including prior months!)
A3: Site | B3: State | C3: Actual | D3: Expected | E3: Delta | F3: % | G3: Forecasted | H3: Delta | I3: % | J3: Notes | K3: Service Requests
A4: {=Sites[Site]} -> AZ: ASU - Pardee - Discovery Hall | B4: {=Sites[State]} -> AZ | E4: =IF(AND(ISNUMBER(C4),ISNUMBER(D4)), C4-D4, "") | F4: =IFERROR(E4/D4, "") | H4: =IF(AND(ISNUMBER(C4),ISNUMBER(G4)), C4-G4, "") | I4: =IFERROR(H4/G4, "")
A5: AZ: ASU - Pardee - Farrington | B5: AZ | E5: =IF(AND(ISNUMBER(C5),ISNUMBER(D5)), C5-D5, "") | F5: =IFERROR(E5/D5, "") | H5: =IF(AND(ISNUMBER(C5),ISNUMBER(G5)), C5-G5, "") | I5: =IFERROR(H5/G5, "")
A6: AZ: ASU - Pardee - Macro Tech. | B6: AZ | E6: =IF(AND(ISNUMBER(C6),ISNUMBER(D6)), C6-D6, "") | F6: =IFERROR(E6/D6, "") | H6: =IF(AND(ISNUMBER(C6),ISNUMBER(G6)), C6-G6, "") | I6: =IFERROR(H6/G6, "")
A7: AZ: ASU - Pardee - McCord Hall | B7: AZ | E7: =IF(AND(ISNUMBER(C7),ISNUMBER(D7)), C7-D7, "") | F7: =IFERROR(E7/D7, "") | H7: =IF(AND(ISNUMBER(C7),ISNUMBER(G7)), C7-G7, "") | I7: =IFERROR(H7/G7, "")
A8: AZ: NAU - SF Garage | B8: AZ | E8: =IF(AND(ISNUMBER(C8),ISNUMBER(D8)), C8-D8, "") | F8: =IFERROR(E8/D8, "") | H8: =IF(AND(ISNUMBER(C8),ISNUMBER(G8)), C8-G8, "") | I8: =IFERROR(H8/G8, "")
A9: AZ: ASU - Pardee - Parking Lot 11 | B9: AZ | E9: =IF(AND(ISNUMBER(C9),ISNUMBER(D9)), C9-D9, "") | F9: =IFERROR(E9/D9, "") | H9: =IF(AND(ISNUMBER(C9),ISNUMBER(G9)), C9-G9, "") | I9: =IFERROR(H9/G9, "")
A10: AZ: ASU - Pardee - Parking Lot 19 | B10: AZ | E10: =IF(AND(ISNUMBER(C10),ISNUMBER(D10)), C10-D10, "") | F10: =IFERROR(E10/D10, "") | H10: =IF(AND(ISNUMBER(C10),ISNUMBER(G10)), C10-G10, "") | I10: =IFERROR(H10/G10, "")
A11: AZ: ASU - Pardee - Parking Lot 41 | B11: AZ | E11: =IF(AND(ISNUMBER(C11),ISNUMBER(D11)), C11-D11, "") | F11: =IFERROR(E11/D11, "") | H11: =IF(AND(ISNUMBER(C11),ISNUMBER(G11)), C11-G11, "") | I11: =IFERROR(H11/G11, "")
A12: AZ: ASU - Pardee - Parking Lot 58 | B12: AZ | E12: =IF(AND(ISNUMBER(C12),ISNUMBER(D12)), C12-D12, "") | F12: =IFERROR(E12/D12, "") | H12: =IF(AND(ISNUMBER(C12),ISNUMBER(G12)), C12-G12, "") | I12: =IFERROR(H12/G12, "")
A13: AZ: ASU - Pardee - Parking Lot 59S | B13: AZ | E13: =IF(AND(ISNUMBER(C13),ISNUMBER(D13)), C13-D13, "") | F13: =IFERROR(E13/D13, "") | H13: =IF(AND(ISNUMBER(C13),ISNUMBER(G13)), C13-G13, "") | I13: =IFERROR(H13/G13, "")
A14: AZ: ASU - Pardee - Sun Devil Complex | B14: AZ | E14: =IF(AND(ISNUMBER(C14),ISNUMBER(D14)), C14-D14, "") | F14: =IFERROR(E14/D14, "") | H14: =IF(AND(ISNUMBER(C14),ISNUMBER(G14)), C14-G14, "") | I14: =IFERROR(H14/G14, "")

Sheet Jul
A1: {=portfolio} -> Pardee (ENCAP) | D1: July Actual v. Expected | G1: July Actual v. Forecasted
A2: Total | C2: =SUM(C4:C86) -> 0 | D2: =SUM(D4:D86) -> 0 | E2: =C2-D2 -> 0 | F2: =IFERROR(E2/D2, 0) -> 0 | G2: =SUM(G4:G86) -> 0 | H2: =C2-G2 -> 0 | I2: =IFERROR(H2/G2, 0) -> 0 | J2: =IF(AND(TODAY()>DATE(2024, 7, 1), COUNTA(Sites[Site])<>(COUNT(C:C)-1)), "Some sites are missing actual data; if new sites were added, make sure they are aligned correctly (including prior months!)", "") -> Some sites are missing actual data; if new sites were added, make sure they are aligned correctly (including prior months!)
A3: Site | B3: State | C3: Actual | D3: Expected | E3: Delta | F3: % | G3: Forecasted | H3: Delta | I3: % | J3: Notes | K3: Service Requests
A4: {=Sites[Site]} -> AZ: ASU - Pardee - Discovery Hall | B4: {=Sites[State]} -> AZ | E4: =IF(AND(ISNUMBER(C4),ISNUMBER(D4)), C4-D4, "") | F4: =IFERROR(E4/D4, "") | H4: =IF(AND(ISNUMBER(C4),ISNUMBER(G4)), C4-G4, "") | I4: =IFERROR(H4/G4, "")
A5: AZ: ASU - Pardee - Farrington | B5: AZ | E5: =IF(AND(ISNUMBER(C5),ISNUMBER(D5)), C5-D5, "") | F5: =IFERROR(E5/D5, "") | H5: =IF(AND(ISNUMBER(C5),ISNUMBER(G5)), C5-G5, "") | I5: =IFERROR(H5/G5, "")
A6: AZ: ASU - Pardee - Macro Tech. | B6: AZ | E6: =IF(AND(ISNUMBER(C6),ISNUMBER(D6)), C6-D6, "") | F6: =IFERROR(E6/D6, "") | H6: =IF(AND(ISNUMBER(C6),ISNUMBER(G6)), C6-G6, "") | I6: =IFERROR(H6/G6, "")
A7: AZ: ASU - Pardee - McCord Hall | B7: AZ | E7: =IF(AND(ISNUMBER(C7),ISNUMBER(D7)), C7-D7, "") | F7: =IFERROR(E7/D7, "") | H7: =IF(AND(ISNUMBER(C7),ISNUMBER(G7)), C7-G7, "") | I7: =IFERROR(H7/G7, "")
A8: AZ: NAU - SF Garage | B8: AZ | E8: =IF(AND(ISNUMBER(C8),ISNUMBER(D8)), C8-D8, "") | F8: =IFERROR(E8/D8, "") | H8: =IF(AND(ISNUMBER(C8),ISNUMBER(G8)), C8-G8, "") | I8: =IFERROR(H8/G8, "")
A9: AZ: ASU - Pardee - Parking Lot 11 | B9: AZ | E9: =IF(AND(ISNUMBER(C9),ISNUMBER(D9)), C9-D9, "") | F9: =IFERROR(E9/D9, "") | H9: =IF(AND(ISNUMBER(C9),ISNUMBER(G9)), C9-G9, "") | I9: =IFERROR(H9/G9, "")
A10: AZ: ASU - Pardee - Parking Lot 19 | B10: AZ | E10: =IF(AND(ISNUMBER(C10),ISNUMBER(D10)), C10-D10, "") | F10: =IFERROR(E10/D10, "") | H10: =IF(AND(ISNUMBER(C10),ISNUMBER(G10)), C10-G10, "") | I10: =IFERROR(H10/G10, "")
A11: AZ: ASU - Pardee - Parking Lot 41 | B11: AZ | E11: =IF(AND(ISNUMBER(C11),ISNUMBER(D11)), C11-D11, "") | F11: =IFERROR(E11/D11, "") | H11: =IF(AND(ISNUMBER(C11),ISNUMBER(G11)), C11-G11, "") | I11: =IFERROR(H11/G11, "")
A12: AZ: ASU - Pardee - Parking Lot 58 | B12: AZ | E12: =IF(AND(ISNUMBER(C12),ISNUMBER(D12)), C12-D12, "") | F12: =IFERROR(E12/D12, "") | H12: =IF(AND(ISNUMBER(C12),ISNUMBER(G12)), C12-G12, "") | I12: =IFERROR(H12/G12, "")
A13: AZ: ASU - Pardee - Parking Lot 59S | B13: AZ | E13: =IF(AND(ISNUMBER(C13),ISNUMBER(D13)), C13-D13, "") | F13: =IFERROR(E13/D13, "") | H13: =IF(AND(ISNUMBER(C13),ISNUMBER(G13)), C13-G13, "") | I13: =IFERROR(H13/G13, "")
A14: AZ: ASU - Pardee - Sun Devil Complex | B14: AZ | E14: =IF(AND(ISNUMBER(C14),ISNUMBER(D14)), C14-D14, "") | F14: =IFERROR(E14/D14, "") | H14: =IF(AND(ISNUMBER(C14),ISNUMBER(G14)), C14-G14, "") | I14: =IFERROR(H14/G14, "")

Sheet Aug
A1: {=portfolio} -> Pardee (ENCAP) | D1: August Actual v. Expected | G1: August Actual v. Forecasted
A2: Total | C2: =SUM(C4:C86) -> 0 | D2: =SUM(D4:D86) -> 0 | E2: =C2-D2 -> 0 | F2: =IFERROR(E2/D2, 0) -> 0 | G2: =SUM(G4:G86) -> 0 | H2: =C2-G2 -> 0 | I2: =IFERROR(H2/G2, 0) -> 0 | J2: =IF(AND(TODAY()>DATE(2024, 8, 1), COUNTA(Sites[Site])<>(COUNT(C:C)-1)), "Some sites are missing actual data; if new sites were added, make sure they are aligned correctly (including prior months!)", "") -> Some sites are missing actual data; if new sites were added, make sure they are aligned correctly (including prior months!)
A3: Site | B3: State | C3: Actual | D3: Expected | E3: Delta | F3: % | G3: Forecasted | H3: Delta | I3: % | J3: Notes | K3: Service Requests
A4: {=Sites[Site]} -> AZ: ASU - Pardee - Discovery Hall | B4: {=Sites[State]} -> AZ | E4: =IF(AND(ISNUMBER(C4),ISNUMBER(D4)), C4-D4, "") | F4: =IFERROR(E4/D4, "") | H4: =IF(AND(ISNUMBER(C4),ISNUMBER(G4)), C4-G4, "") | I4: =IFERROR(H4/G4, "")
A5: AZ: ASU - Pardee - Farrington | B5: AZ | E5: =IF(AND(ISNUMBER(C5),ISNUMBER(D5)), C5-D5, "") | F5: =IFERROR(E5/D5, "") | H5: =IF(AND(ISNUMBER(C5),ISNUMBER(G5)), C5-G5, "") | I5: =IFERROR(H5/G5, "")
A6: AZ: ASU - Pardee - Macro Tech. | B6: AZ | E6: =IF(AND(ISNUMBER(C6),ISNUMBER(D6)), C6-D6, "") | F6: =IFERROR(E6/D6, "") | H6: =IF(AND(ISNUMBER(C6),ISNUMBER(G6)), C6-G6, "") | I6: =IFERROR(H6/G6, "")
A7: AZ: ASU - Pardee - McCord Hall | B7: AZ | E7: =IF(AND(ISNUMBER(C7),ISNUMBER(D7)), C7-D7, "") | F7: =IFERROR(E7/D7, "") | H7: =IF(AND(ISNUMBER(C7),ISNUMBER(G7)), C7-G7, "") | I7: =IFERROR(H7/G7, "")
A8: AZ: NAU - SF Garage | B8: AZ | E8: =IF(AND(ISNUMBER(C8),ISNUMBER(D8)), C8-D8, "") | F8: =IFERROR(E8/D8, "") | H8: =IF(AND(ISNUMBER(C8),ISNUMBER(G8)), C8-G8, "") | I8: =IFERROR(H8/G8, "")
A9: AZ: ASU - Pardee - Parking Lot 11 | B9: AZ | E9: =IF(AND(ISNUMBER(C9),ISNUMBER(D9)), C9-D9, "") | F9: =IFERROR(E9/D9, "") | H9: =IF(AND(ISNUMBER(C9),ISNUMBER(G9)), C9-G9, "") | I9: =IFERROR(H9/G9, "")
A10: AZ: ASU - Pardee - Parking Lot 19 | B10: AZ | E10: =IF(AND(ISNUMBER(C10),ISNUMBER(D10)), C10-D10, "") | F10: =IFERROR(E10/D10, "") | H10: =IF(AND(ISNUMBER(C10),ISNUMBER(G10)), C10-G10, "") | I10: =IFERROR(H10/G10, "")
A11: AZ: ASU - Pardee - Parking Lot 41 | B11: AZ | E11: =IF(AND(ISNUMBER(C11),ISNUMBER(D11)), C11-D11, "") | F11: =IFERROR(E11/D11, "") | H11: =IF(AND(ISNUMBER(C11),ISNUMBER(G11)), C11-G11, "") | I11: =IFERROR(H11/G11, "")
A12: AZ: ASU - Pardee - Parking Lot 58 | B12: AZ | E12: =IF(AND(ISNUMBER(C12),ISNUMBER(D12)), C12-D12, "") | F12: =IFERROR(E12/D12, "") | H12: =IF(AND(ISNUMBER(C12),ISNUMBER(G12)), C12-G12, "") | I12: =IFERROR(H12/G12, "")
A13: AZ: ASU - Pardee - Parking Lot 59S | B13: AZ | E13: =IF(AND(ISNUMBER(C13),ISNUMBER(D13)), C13-D13, "") | F13: =IFERROR(E13/D13, "") | H13: =IF(AND(ISNUMBER(C13),ISNUMBER(G13)), C13-G13, "") | I13: =IFERROR(H13/G13, "")
A14: AZ: ASU - Pardee - Sun Devil Complex | B14: AZ | E14: =IF(AND(ISNUMBER(C14),ISNUMBER(D14)), C14-D14, "") | F14: =IFERROR(E14/D14, "") | H14: =IF(AND(ISNUMBER(C14),ISNUMBER(G14)), C14-G14, "") | I14: =IFERROR(H14/G14, "")

Sheet Sep
A1: {=portfolio} -> Pardee (ENCAP) | D1: September Actual v. Expected | G1: September Actual v. Forecasted
A2: Total | C2: =SUM(C4:C86) -> 0 | D2: =SUM(D4:D86) -> 0 | E2: =C2-D2 -> 0 | F2: =IFERROR(E2/D2, 0) -> 0 | G2: =SUM(G4:G86) -> 0 | H2: =C2-G2 -> 0 | I2: =IFERROR(H2/G2, 0) -> 0 | J2: =IF(AND(TODAY()>DATE(2024, 9, 1), COUNTA(Sites[Site])<>(COUNT(C:C)-1)), "Some sites are missing actual data; if new sites were added, make sure they are aligned correctly (including prior months!)", "") -> Some sites are missing actual data; if new sites were added, make sure they are aligned correctly (including prior months!)
A3: Site | B3: State | C3: Actual | D3: Expected | E3: Delta | F3: % | G3: Forecasted | H3: Delta | I3: % | J3: Notes | K3: Service Requests
A4: {=Sites[Site]} -> AZ: ASU - Pardee - Discovery Hall | B4: {=Sites[State]} -> AZ | E4: =IF(AND(ISNUMBER(C4),ISNUMBER(D4)), C4-D4, "") | F4: =IFERROR(E4/D4, "") | H4: =IF(AND(ISNUMBER(C4),ISNUMBER(G4)), C4-G4, "") | I4: =IFERROR(H4/G4, "")
A5: AZ: ASU - Pardee - Farrington | B5: AZ | E5: =IF(AND(ISNUMBER(C5),ISNUMBER(D5)), C5-D5, "") | F5: =IFERROR(E5/D5, "") | H5: =IF(AND(ISNUMBER(C5),ISNUMBER(G5)), C5-G5, "") | I5: =IFERROR(H5/G5, "")
A6: AZ: ASU - Pardee - Macro Tech. | B6: AZ | E6: =IF(AND(ISNUMBER(C6),ISNUMBER(D6)), C6-D6, "") | F6: =IFERROR(E6/D6, "") | H6: =IF(AND(ISNUMBER(C6),ISNUMBER(G6)), C6-G6, "") | I6: =IFERROR(H6/G6, "")
A7: AZ: ASU - Pardee - McCord Hall | B7: AZ | E7: =IF(AND(ISNUMBER(C7),ISNUMBER(D7)), C7-D7, "") | F7: =IFERROR(E7/D7, "") | H7: =IF(AND(ISNUMBER(C7),ISNUMBER(G7)), C7-G7, "") | I7: =IFERROR(H7/G7, "")
A8: AZ: NAU - SF Garage | B8: AZ | E8: =IF(AND(ISNUMBER(C8),ISNUMBER(D8)), C8-D8, "") | F8: =IFERROR(E8/D8, "") | H8: =IF(AND(ISNUMBER(C8),ISNUMBER(G8)), C8-G8, "") | I8: =IFERROR(H8/G8, "")
A9: AZ: ASU - Pardee - Parking Lot 11 | B9: AZ | E9: =IF(AND(ISNUMBER(C9),ISNUMBER(D9)), C9-D9, "") | F9: =IFERROR(E9/D9, "") | H9: =IF(AND(ISNUMBER(C9),ISNUMBER(G9)), C9-G9, "") | I9: =IFERROR(H9/G9, "")
A10: AZ: ASU - Pardee - Parking Lot 19 | B10: AZ | E10: =IF(AND(ISNUMBER(C10),ISNUMBER(D10)), C10-D10, "") | F10: =IFERROR(E10/D10, "") | H10: =IF(AND(ISNUMBER(C10),ISNUMBER(G10)), C10-G10, "") | I10: =IFERROR(H10/G10, "")
A11: AZ: ASU - Pardee - Parking Lot 41 | B11: AZ | E11: =IF(AND(ISNUMBER(C11),ISNUMBER(D11)), C11-D11, "") | F11: =IFERROR(E11/D11, "") | H11: =IF(AND(ISNUMBER(C11),ISNUMBER(G11)), C11-G11, "") | I11: =IFERROR(H11/G11, "")
A12: AZ: ASU - Pardee - Parking Lot 58 | B12: AZ | E12: =IF(AND(ISNUMBER(C12),ISNUMBER(D12)), C12-D12, "") | F12: =IFERROR(E12/D12, "") | H12: =IF(AND(ISNUMBER(C12),ISNUMBER(G12)), C12-G12, "") | I12: =IFERROR(H12/G12, "")
A13: AZ: ASU - Pardee - Parking Lot 59S | B13: AZ | E13: =IF(AND(ISNUMBER(C13),ISNUMBER(D13)), C13-D13, "") | F13: =IFERROR(E13/D13, "") | H13: =IF(AND(ISNUMBER(C13),ISNUMBER(G13)), C13-G13, "") | I13: =IFERROR(H13/G13, "")
A14: AZ: ASU - Pardee - Sun Devil Complex | B14: AZ | E14: =IF(AND(ISNUMBER(C14),ISNUMBER(D14)), C14-D14, "") | F14: =IFERROR(E14/D14, "") | H14: =IF(AND(ISNUMBER(C14),ISNUMBER(G14)), C14-G14, "") | I14: =IFERROR(H14/G14, "")

Sheet Oct
A1: {=portfolio} -> Pardee (ENCAP) | D1: October Actual v. Expected | G1: October Actual v. Forecasted
A2: Total | C2: =SUM(C4:C86) -> 0 | D2: =SUM(D4:D86) -> 0 | E2: =C2-D2 -> 0 | F2: =IFERROR(E2/D2, 0) -> 0 | G2: =SUM(G4:G86) -> 0 | H2: =C2-G2 -> 0 | I2: =IFERROR(H2/G2, 0) -> 0 | J2: =IF(AND(TODAY()>DATE(2024, 10, 1), COUNTA(Sites[Site])<>(COUNT(C:C)-1)), "Some sites are missing actual data; if new sites were added, make sure they are aligned correctly (including prior months!)", "") -> Some sites are missing actual data; if new sites were added, make sure they are aligned correctly (including prior months!)
A3: Site | B3: State | C3: Actual | D3: Expected | E3: Delta | F3: % | G3: Forecasted | H3: Delta | I3: % | J3: Notes | K3: Service Requests
A4: {=Sites[Site]} -> AZ: ASU - Pardee - Discovery Hall | B4: {=Sites[State]} -> AZ | E4: =IF(AND(ISNUMBER(C4),ISNUMBER(D4)), C4-D4, "") | F4: =IFERROR(E4/D4, "") | H4: =IF(AND(ISNUMBER(C4),ISNUMBER(G4)), C4-G4, "") | I4: =IFERROR(H4/G4, "")
A5: AZ: ASU - Pardee - Farrington | B5: AZ | E5: =IF(AND(ISNUMBER(C5),ISNUMBER(D5)), C5-D5, "") | F5: =IFERROR(E5/D5, "") | H5: =IF(AND(ISNUMBER(C5),ISNUMBER(G5)), C5-G5, "") | I5: =IFERROR(H5/G5, "")
A6: AZ: ASU - Pardee - Macro Tech. | B6: AZ | E6: =IF(AND(ISNUMBER(C6),ISNUMBER(D6)), C6-D6, "") | F6: =IFERROR(E6/D6, "") | H6: =IF(AND(ISNUMBER(C6),ISNUMBER(G6)), C6-G6, "") | I6: =IFERROR(H6/G6, "")
A7: AZ: ASU - Pardee - McCord Hall | B7: AZ | E7: =IF(AND(ISNUMBER(C7),ISNUMBER(D7)), C7-D7, "") | F7: =IFERROR(E7/D7, "") | H7: =IF(AND(ISNUMBER(C7),ISNUMBER(G7)), C7-G7, "") | I7: =IFERROR(H7/G7, "")
A8: AZ: NAU - SF Garage | B8: AZ | E8: =IF(AND(ISNUMBER(C8),ISNUMBER(D8)), C8-D8, "") | F8: =IFERROR(E8/D8, "") | H8: =IF(AND(ISNUMBER(C8),ISNUMBER(G8)), C8-G8, "") | I8: =IFERROR(H8/G8, "")
A9: AZ: ASU - Pardee - Parking Lot 11 | B9: AZ | E9: =IF(AND(ISNUMBER(C9),ISNUMBER(D9)), C9-D9, "") | F9: =IFERROR(E9/D9, "") | H9: =IF(AND(ISNUMBER(C9),ISNUMBER(G9)), C9-G9, "") | I9: =IFERROR(H9/G9, "")
