Workbook
Name JanActual: #REF!
Name JanActual2: #REF!
Name JanExpected: #REF!
Name JanExpectedDelta: #REF!
Name JanExpectedPercent: #REF!
Name JanExpPercent: #REF!
Name JanForecasted: #REF!
Name JanForecastedDelta: #REF!
Name JanForecastedPercent: #REF!
Name portfolio: Sites!$B$1:$B$1
Name Year: Sites!#REF!

Sheet Year to Date
A1: {=portfolio} -> CITI | D1: Year to Date Actual v. Expected | G1: Year to Date Actual v. Forecasted
A2: Total | C2: =SUM(C4:C100) -> 3998283.1 | D2: =SUM(D4:D100) -> 4194441.3 | E2: =C2-D2 -> -196158.23 | F2: =IFERROR(E2/D2, 0) -> -0.046766235 | G2: =SUM(G4:G100) -> 14740224 | H2: =C2-G2 -> -10741941 | I2: =IFERROR(H2/G2, 0) -> -0.72875017
A3: Site | B3: State | C3: Actual | D3: Expected | E3: Delta | F3: % | G3: Forecasted | H3: Delta | I3: %
A4: {=Sites[Site]} -> CA: Antioch Deer Valley - Citi | B4: {=Sites[State]} -> CA | C4: =SUM('1st Qtr'!C4, '2nd Qtr'!C4, '3rd Qtr'!C4, '4th Qtr'!C4) -> 461871.5 | D4: =SUM('1st Qtr'!D4, '2nd Qtr'!D4, '3rd Qtr'!D4, '4th Qtr'!D4) -> 483886 | E4: =IF(AND(ISNUMBER(C4),ISNUMBER(D4)), C4-D4, "") -> -22014.5 | F4: =IFERROR(E4/D4, "") -> -0.04549522 | G4: =SUM('1st Qtr'!G4,'2nd Qtr'!G4,'3rd Qtr'!G4,'4th Qtr'!G4) -> 408707.08 | H4: =SUM('1st Qtr'!H4, '2nd Qtr'!H4, '3rd Qtr'!H4, '4th Qtr'!H4) -> -19219.764 | I4: =IFERROR(H4/G4, "") -> -0.047025767
A5: CA: Antioch MC CUP - Citi | B5: CA | C5: =SUM(Jan!C5, Feb!C5, Mar!C5) -> 362875.5 | D5: =SUM(Jan!F5, Feb!F5, Mar!G5) -> 380766 | E5: =IF(AND(ISNUMBER(C5),ISNUMBER(D5)), C5-D5, "") -> -17890.5 | F5: =IFERROR(E5/D5, "") -> -0.04698555 | G5: =SUM('1st Qtr'!G5,'2nd Qtr'!G5,'3rd Qtr'!G5,'4th Qtr'!G5) -> 1430803.2 | H5: =SUM(Jan!J5, Feb!J5, Mar!K5) -> -12055.933 | I5: =IFERROR(H5/G5, "") -> -0.0084259896
A6: CA: Clovis - Citi | B6: CA | C6: =SUM(Jan!C6, Feb!C6, Mar!C6) -> 154790 | D6: =SUM(Jan!F6, Feb!F6, Mar!G6) -> 148411 | E6: =IF(AND(ISNUMBER(C6),ISNUMBER(D6)), C6-D6, "") -> 6379 | F6: =IFERROR(E6/D6, "") -> 0.042981989 | G6: =SUM('1st Qtr'!G6,'2nd Qtr'!G6,'3rd Qtr'!G6,'4th Qtr'!G6) -> 612284.44 | H6: =SUM(Jan!J6, Feb!J6, Mar!K6) -> -23438.83 | I6: =IFERROR(H6/G6, "") -> -0.03828095
A7: CA: Elk Grove MOB - Citi | B7: CA | C7: =SUM(Jan!C7, Feb!C7, Mar!C7) -> 226351 | D7: =SUM(Jan!F7, Feb!F7, Mar!G7) -> 244939 | E7: =IF(AND(ISNUMBER(C7),ISNUMBER(D7)), C7-D7, "") -> -18588 | F7: =IFERROR(E7/D7, "") -> -0.075888282 | G7: =SUM('1st Qtr'!G7,'2nd Qtr'!G7,'3rd Qtr'!G7,'4th Qtr'!G7) -> 941082.86 | H7: =SUM(Jan!J7, Feb!J7, Mar!K7) -> -15943.911 | I7: =IFERROR(H7/G7, "") -> -0.01694209
A8: CA: Elk Grove Promenade - Citi | B8: CA | C8: =SUM(Jan!C8, Feb!C8, Mar!C8) -> 108983.5 | D8: =SUM(Jan!F8, Feb!F8, Mar!G8) -> 133398.35 | E8: =IF(AND(ISNUMBER(C8),ISNUMBER(D8)), C8-D8, "") -> -24414.85 | F8: =IFERROR(E8/D8, "") -> -0.18302213 | G8: =SUM('1st Qtr'!G8,'2nd Qtr'!G8,'3rd Qtr'!G8,'4th Qtr'!G8) -> 498092.23 | H8: =SUM(Jan!J8, Feb!J8, Mar!K8) -> -25538.638 | I8: =IFERROR(H8/G8, "") -> -0.05127291
A9: CA: Fresno Sequioa - Citi | B9: CA | C9: =SUM(Jan!C9, Feb!C9, Mar!C9) -> 270913 | D9: =SUM(Jan!F9, Feb!F9, Mar!G9) -> 265872 | E9: =IF(AND(ISNUMBER(C9),ISNUMBER(D9)), C9-D9, "") -> 5041 | F9: =IFERROR(E9/D9, "") -> 0.018960252 | G9: =SUM('1st Qtr'!G9,'2nd Qtr'!G9,'3rd Qtr'!G9,'4th Qtr'!G9) -> 1014642.1 | H9: =SUM(Jan!J9, Feb!J9, Mar!K9) -> -14907.301 | I9: =IFERROR(H9/G9, "") -> -0.014692177
A10: CA: Fresno MOB - Citi | B10: CA | C10: =SUM(Jan!C10, Feb!C10, Mar!C10) -> 107138 | D10: =SUM(Jan!F10, Feb!F10, Mar!G10) -> 107580 | E10: =IF(AND(ISNUMBER(C10),ISNUMBER(D10)), C10-D10, "") -> -442 | F10: =IFERROR(E10/D10, "") -> -0.0041085704 | G10: =SUM('1st Qtr'!G10,'2nd Qtr'!G10,'3rd Qtr'!G10,'4th Qtr'!G10) -> 385062.75 | H10: =SUM(Jan!J10, Feb!J10, Mar!K10) -> -1747.549 | I10: =IFERROR(H10/G10, "") -> -0.0045383486
A11: CA: Modesto Bangs - Citi | B11: CA | C11: =SUM(Jan!C11, Feb!C11, Mar!C11) -> 60911.87 | D11: =SUM(Jan!F11, Feb!F11, Mar!G11) -> 63488 | E11: =IF(AND(ISNUMBER(C11),ISNUMBER(D11)), C11-D11, "") -> -2576.13 | F11: =IFERROR(E11/D11, 0) -> -0.040576644 | G11: =SUM('1st Qtr'!G11,'2nd Qtr'!G11,'3rd Qtr'!G11,'4th Qtr'!G11) -> 242329.25 | H11: =SUM(Jan!J11, Feb!J11, Mar!K11) -> -2931.18 | I11: =IFERROR(H11/G11, 0) -> -0.012095857
A12: CA: Napa Data Center - Citi | B12: CA | C12: =SUM(Jan!C12, Feb!C12, Mar!C12) -> 63472 | D12: =SUM(Jan!F12, Feb!F12, Mar!G12) -> 76672 | E12: =IF(AND(ISNUMBER(C12),ISNUMBER(D12)), C12-D12, "") -> -13200 | F12: =IFERROR(E12/D12, "") -> -0.17216194 | G12: =SUM('1st Qtr'!G12,'2nd Qtr'!G12,'3rd Qtr'!G12,'4th Qtr'!G12) -> 273969.94 | H12: =SUM(Jan!J12, Feb!J12, Mar!K12) -> -13216.069 | I12: =IFERROR(H12/G12, "") -> -0.04823912
A13: CA: Petaluma MOB - Citi | B13: CA | C13: =SUM(Jan!C13, Feb!C13, Mar!C13) -> 154083 | D13: =SUM(Jan!F13, Feb!F13, Mar!G13) -> 174957 | E13: =IF(AND(ISNUMBER(C13),ISNUMBER(D13)), C13-D13, "") -> -20874 | F13: =IFERROR(E13/D13, "") -> -0.11930932 | G13: =SUM('1st Qtr'!G13,'2nd Qtr'!G13,'3rd Qtr'!G13,'4th Qtr'!G13) -> 503406.5 | H13: =SUM(Jan!J13, Feb!J13, Mar!K13) -> -24742.416 | I13: =IFERROR(H13/G13, "") -> -0.049149974
A14: CA: Pleasanton Tec Ctr - Citi | B14: CA | C14: =SUM(Jan!C14, Feb!C14, Mar!C14) -> 201975 | D14: =SUM(Jan!F14, Feb!F14, Mar!G14) -> 250800 | E14: =IF(AND(ISNUMBER(C14),ISNUMBER(D14)), C14-D14, "") -> -48825 | F14: =IFERROR(E14/D14, "") -> -0.19467703 | G14: =SUM('1st Qtr'!G14,'2nd Qtr'!G14,'3rd Qtr'!G14,'4th Qtr'!G14) -> 925839.74 | H14: =SUM(Jan!J14, Feb!J14, Mar!K14) -> -37017.829 | I14: =IFERROR(H14/G14, "") -> -0.039982977
A15: CA: Rancho Cordova - Citi | B15: CA | C15: =SUM(Jan!C15, Feb!C15, Mar!C15) -> 369775 | D15: =SUM(Jan!F15, Feb!F15, Mar!G15) -> 375511 | E15: =IF(AND(ISNUMBER(C15),ISNUMBER(D15)), C15-D15, "") -> -5736 | F15: =IFERROR(E15/D15, "") -> -0.015275185 | G15: =SUM('1st Qtr'!G15,'2nd Qtr'!G15,'3rd Qtr'!G15,'4th Qtr'!G15) -> 1340935.7 | H15: =SUM(Jan!J15, Feb!J15, Mar!K15) -> -11520.02 | I15: =IFERROR(H15/G15, "") -> -0.0085910306
A16: CA: S Sacramento Wyndham - Citi | B16: CA | C16: =SUM(Jan!C16, Feb!C16, Mar!C16) -> 190604.5 | D16: =SUM(Jan!F16, Feb!F16, Mar!G16) -> 210511 | E16: =IF(AND(ISNUMBER(C16),ISNUMBER(D16)), C16-D16, "") -> -19906.5 | F16: =IFERROR(E16/D16, "") -> -0.094562754 | G16: =SUM('1st Qtr'!G16,'2nd Qtr'!G16,'3rd Qtr'!G16,'4th Qtr'!G16) -> 759394.92 | H16: =SUM(Jan!J16, Feb!J16, Mar!K16) -> -3945.181 | I16: =IFERROR(H16/G16, "") -> -0.0051951638
A17: CA: Sacramento Point West - Citi | B17: CA | C17: =SUM(Jan!C17, Feb!C17, Mar!C17) -> 339615.5 | D17: =SUM(Jan!F17, Feb!F17, Mar!G17) -> 404674 | E17: =IF(AND(ISNUMBER(C17),ISNUMBER(D17)), C17-D17, "") -> -65058.5 | F17: =IFERROR(E17/D17, "") -> -0.16076768 | G17: =SUM('1st Qtr'!G17,'2nd Qtr'!G17,'3rd Qtr'!G17,'4th Qtr'!G17) -> 1564941.9 | H17: =SUM(Jan!J17, Feb!J17, Mar!K17) -> -60477.779 | I17: =IFERROR(H17/G17, "") -> -0.038645382
A18: CA: San Jose FHC - Citi | B18: CA | C18: =SUM(Jan!C18, Feb!C18, Mar!C18) -> 72919.87 | D18: =SUM(Jan!F18, Feb!F18, Mar!G18) -> 93317 | E18: =IF(AND(ISNUMBER(C18),ISNUMBER(D18)), C18-D18, "") -> -20397.13 | F18: =IFERROR(E18/D18, "") -> -0.21857893 | G18: =SUM('1st Qtr'!G18,'2nd Qtr'!G18,'3rd Qtr'!G18,'4th Qtr'!G18) -> 251058.2 | H18: =SUM(Jan!J18, Feb!J18, Mar!K18) -> -10260.123 | I18: =IFERROR(H18/G18, "") -> -0.040867508
A19: CA: San Jose MOB - Citi | B19: CA | C19: =SUM(Jan!C19, Feb!C19, Mar!C19) -> 109423 | D19: =SUM(Jan!F19, Feb!F19, Mar!G19) -> 148699 | E19: =IF(AND(ISNUMBER(C19),ISNUMBER(D19)), C19-D19, "") -> -39276 | F19: =IFERROR(E19/D19, "") -> -0.2641309 | G19: =SUM('1st Qtr'!G19,'2nd Qtr'!G19,'3rd Qtr'!G19,'4th Qtr'!G19) -> 510983.88 | H19: =SUM(Jan!J19, Feb!J19, Mar!K19) -> -24509.623 | I19: =IFERROR(H19/G19, "") -> -0.04796555
A20: CA: Selma - Citi | B20: CA | C20: =SUM(Jan!C20, Feb!C20, Mar!C20) -> 78863.13 | D20: =SUM(Jan!F20, Feb!F20, Mar!G20) -> 76746 | E20: =IF(AND(ISNUMBER(C20),ISNUMBER(D20)), C20-D20, "") -> 2117.13 | F20: =IFERROR(E20/D20, "") -> 0.027586193 | G20: =SUM('1st Qtr'!G20,'2nd Qtr'!G20,'3rd Qtr'!G20,'4th Qtr'!G20) -> 311957.5 | H20: =SUM(Jan!J20, Feb!J20, Mar!K20) -> -8645.63 | I20: =IFERROR(H20/G20, "") -> -0.027714128
A21: CA: Vacaville Hospital | B21: CA | C21: =SUM(Jan!C21, Feb!C21, Mar!C21) -> 499858.25 | D21: =SUM(Jan!F21, Feb!F21, Mar!G21) -> 554214 | E21: =IF(AND(ISNUMBER(C21),ISNUMBER(D21)), C21-D21, "") -> -54355.75 | F21: =IFERROR(E21/D21, "") -> -0.098077187 | G21: =SUM('1st Qtr'!G21,'2nd Qtr'!G21,'3rd Qtr'!G21,'4th Qtr'!G21) -> 2204548.2 | H21: =SUM(Jan!J21, Feb!J21, Mar!K21) -> 6850.581 | I21: =IFERROR(H21/G21, "") -> 0.0031074762
A22: CA: Manteca - KP Manteca Hospital | B22: CA | C22: =SUM(Jan!C22, Feb!C22, Mar!C22) -> 163859.5 | D22: =SUM(Jan!F22, Feb!F22, Mar!G22) -> 0 | E22: =IF(AND(ISNUMBER(C22),ISNUMBER(D22)), C22-D22, "") -> 163859.5 | F22: =IFERROR(E22/D22, 0) -> 0 | G22: =SUM('1st Qtr'!G22,'2nd Qtr'!G22,'3rd Qtr'!G22,'4th Qtr'!G22) -> 560183.18 | H22: =SUM(Jan!J22, Feb!J22, Mar!K22) -> 29908.895 | I22: =IFERROR(H22/G22, 0) -> 0.053391276

Sheet 1st Qtr
A1: {=portfolio} -> CITI | D1: 1st Quarter Actual v. Expected | G1: 1st Quarter Actual v. Forecasted
A2: Total | C2: =SUM(C4:C100) -> 3630731.4 | D2: =SUM(D4:D100) -> 3825386.4 | E2: =C2-D2 -> -194654.98 | F2: =IFERROR(E2/D2, 0) -> -0.050885051 | G2: =SUM(G4:G100) -> 3888648.5 | H2: =C2-G2 -> -257917.1 | I2: =IFERROR(H2/G2, 0) -> -0.06632564
A3: Site | B3: State | C3: Actual | D3: Expected | E3: Delta | F3: % | G3: Forecasted | H3: Delta | I3: %
A4: {=Sites[Site]} -> CA: Antioch Deer Valley - Citi | B4: {=Sites[State]} -> CA | C4: =SUM(Jan!C4, Feb!C4, Mar!C4) -> 94319.75 | D4: =SUM(Jan!F4, Feb!F4, Mar!G4) -> 114831 | E4: =IF(AND(ISNUMBER(C4),ISNUMBER(D4)), C4-D4, "") -> -20511.25 | F4: =IFERROR(E4/D4, "") -> -0.17862119 | G4: =SUM(Jan!I4, Feb!I4, Mar!J4) -> 98098.311 | H4: =SUM(Jan!J4, Feb!J4, Mar!K4) -> -3778.561 | I4: =IFERROR(H4/G4, "") -> -0.038518105
A5: CA: Antioch MC CUP - Citi | B5: CA | C5: =SUM(Jan!C5, Feb!C5, Mar!C5) -> 362875.5 | D5: =SUM(Jan!F5, Feb!F5, Mar!G5) -> 380766 | E5: =IF(AND(ISNUMBER(C5),ISNUMBER(D5)), C5-D5, "") -> -17890.5 | F5: =IFERROR(E5/D5, "") -> -0.04698555 | G5: =SUM(Jan!I5, Feb!I5, Mar!J5) -> 374931.43 | H5: =SUM(Jan!J5, Feb!J5, Mar!K5) -> -12055.933 | I5: =IFERROR(H5/G5, "") -> -0.032155034
A6: CA: Clovis - Citi | B6: CA | C6: =SUM(Jan!C6, Feb!C6, Mar!C6) -> 154790 | D6: =SUM(Jan!F6, Feb!F6, Mar!G6) -> 148411 | E6: =IF(AND(ISNUMBER(C6),ISNUMBER(D6)), C6-D6, "") -> 6379 | F6: =IFERROR(E6/D6, "") -> 0.042981989 | G6: =SUM(Jan!I6, Feb!I6, Mar!J6) -> 178228.83 | H6: =SUM(Jan!J6, Feb!J6, Mar!K6) -> -23438.83 | I6: =IFERROR(H6/G6, "") -> -0.13150976
A7: CA: Elk Grove MOB - Citi | B7: CA | C7: =SUM(Jan!C7, Feb!C7, Mar!C7) -> 226351 | D7: =SUM(Jan!F7, Feb!F7, Mar!G7) -> 244939 | E7: =IF(AND(ISNUMBER(C7),ISNUMBER(D7)), C7-D7, "") -> -18588 | F7: =IFERROR(E7/D7, "") -> -0.075888282 | G7: =SUM(Jan!I7, Feb!I7, Mar!J7) -> 242294.91 | H7: =SUM(Jan!J7, Feb!J7, Mar!K7) -> -15943.911 | I7: =IFERROR(H7/G7, "") -> -0.065803739
A8: CA: Elk Grove Promenade - Citi | B8: CA | C8: =SUM(Jan!C8, Feb!C8, Mar!C8) -> 108983.5 | D8: =SUM(Jan!F8, Feb!F8, Mar!G8) -> 133398.35 | E8: =IF(AND(ISNUMBER(C8),ISNUMBER(D8)), C8-D8, "") -> -24414.85 | F8: =IFERROR(E8/D8, "") -> -0.18302213 | G8: =SUM(Jan!I8, Feb!I8, Mar!J8) -> 134522.14 | H8: =SUM(Jan!J8, Feb!J8, Mar!K8) -> -25538.638 | I8: =IFERROR(H8/G8, "") -> -0.1898471
A9: CA: Fresno Sequioa - Citi | B9: CA | C9: =SUM(Jan!C9, Feb!C9, Mar!C9) -> 270913 | D9: =SUM(Jan!F9, Feb!F9, Mar!G9) -> 265872 | E9: =IF(AND(ISNUMBER(C9),ISNUMBER(D9)), C9-D9, "") -> 5041 | F9: =IFERROR(E9/D9, "") -> 0.018960252 | G9: =SUM(Jan!I9, Feb!I9, Mar!J9) -> 285820.3 | H9: =SUM(Jan!J9, Feb!J9, Mar!K9) -> -14907.301 | I9: =IFERROR(H9/G9, "") -> -0.052156201
A10: CA: Fresno MOB - Citi | B10: CA | C10: =SUM(Jan!C10, Feb!C10, Mar!C10) -> 107138 | D10: =SUM(Jan!F10, Feb!F10, Mar!G10) -> 107580 | E10: =IF(AND(ISNUMBER(C10),ISNUMBER(D10)), C10-D10, "") -> -442 | F10: =IFERROR(E10/D10, "") -> -0.0041085704 | G10: =SUM(Jan!I10, Feb!I10, Mar!J10) -> 108885.55 | H10: =SUM(Jan!J10, Feb!J10, Mar!K10) -> -1747.549 | I10: =IFERROR(H10/G10, "") -> -0.016049412
A11: CA: Modesto Bangs - Citi | B11: CA | C11: =SUM(Jan!C11, Feb!C11, Mar!C11) -> 60911.87 | D11: =SUM(Jan!F11, Feb!F11, Mar!G11) -> 63488 | E11: =IF(AND(ISNUMBER(C11),ISNUMBER(D11)), C11-D11, "") -> -2576.13 | F11: =IFERROR(E11/D11, 0) -> -0.040576644 | G11: =SUM(Jan!I11, Feb!I11, Mar!J11) -> 63843.05 | H11: =SUM(Jan!J11, Feb!J11, Mar!K11) -> -2931.18 | I11: =IFERROR(H11/G11, 0) -> -0.04591228
A12: CA: Napa Data Center - Citi | B12: CA | C12: =SUM(Jan!C12, Feb!C12, Mar!C12) -> 63472 | D12: =SUM(Jan!F12, Feb!F12, Mar!G12) -> 76672 | E12: =IF(AND(ISNUMBER(C12),ISNUMBER(D12)), C12-D12, "") -> -13200 | F12: =IFERROR(E12/D12, "") -> -0.17216194 | G12: =SUM(Jan!I12, Feb!I12, Mar!J12) -> 76688.069 | H12: =SUM(Jan!J12, Feb!J12, Mar!K12) -> -13216.069 | I12: =IFERROR(H12/G12, "") -> -0.1723354
A13: CA: Petaluma MOB - Citi | B13: CA | C13: =SUM(Jan!C13, Feb!C13, Mar!C13) -> 154083 | D13: =SUM(Jan!F13, Feb!F13, Mar!G13) -> 174957 | E13: =IF(AND(ISNUMBER(C13),ISNUMBER(D13)), C13-D13, "") -> -20874 | F13: =IFERROR(E13/D13, "") -> -0.11930932 | G13: =SUM(Jan!I13, Feb!I13, Mar!J13) -> 178825.42 | H13: =SUM(Jan!J13, Feb!J13, Mar!K13) -> -24742.416 | I13: =IFERROR(H13/G13, "") -> -0.13836074
A14: CA: Pleasanton Tec Ctr - Citi | B14: CA | C14: =SUM(Jan!C14, Feb!C14, Mar!C14) -> 201975 | D14: =SUM(Jan!F14, Feb!F14, Mar!G14) -> 250800 | E14: =IF(AND(ISNUMBER(C14),ISNUMBER(D14)), C14-D14, "") -> -48825 | F14: =IFERROR(E14/D14, "") -> -0.19467703 | G14: =SUM(Jan!I14, Feb!I14, Mar!J14) -> 238992.83 | H14: =SUM(Jan!J14, Feb!J14, Mar!K14) -> -37017.829 | I14: =IFERROR(H14/G14, "") -> -0.15489096
A15: CA: Rancho Cordova - Citi | B15: CA | C15: =SUM(Jan!C15, Feb!C15, Mar!C15) -> 369775 | D15: =SUM(Jan!F15, Feb!F15, Mar!G15) -> 375511 | E15: =IF(AND(ISNUMBER(C15),ISNUMBER(D15)), C15-D15, "") -> -5736 | F15: =IFERROR(E15/D15, "") -> -0.015275185 | G15: =SUM(Jan!I15, Feb!I15, Mar!J15) -> 381295.02 | H15: =SUM(Jan!J15, Feb!J15, Mar!K15) -> -11520.02 | I15: =IFERROR(H15/G15, "") -> -0.030212878
A16: CA: S Sacramento Wyndham - Citi | B16: CA | C16: =SUM(Jan!C16, Feb!C16, Mar!C16) -> 190604.5 | D16: =SUM(Jan!F16, Feb!F16, Mar!G16) -> 210511 | E16: =IF(AND(ISNUMBER(C16),ISNUMBER(D16)), C16-D16, "") -> -19906.5 | F16: =IFERROR(E16/D16, "") -> -0.094562754 | G16: =SUM(Jan!I16, Feb!I16, Mar!J16) -> 194549.68 | H16: =SUM(Jan!J16, Feb!J16, Mar!K16) -> -3945.181 | I16: =IFERROR(H16/G16, "") -> -0.020278527
A17: CA: Sacramento Point West - Citi | B17: CA | C17: =SUM(Jan!C17, Feb!C17, Mar!C17) -> 339615.5 | D17: =SUM(Jan!F17, Feb!F17, Mar!G17) -> 404674 | E17: =IF(AND(ISNUMBER(C17),ISNUMBER(D17)), C17-D17, "") -> -65058.5 | F17: =IFERROR(E17/D17, "") -> -0.16076768 | G17: =SUM(Jan!I17, Feb!I17, Mar!J17) -> 400093.28 | H17: =SUM(Jan!J17, Feb!J17, Mar!K17) -> -60477.779 | I17: =IFERROR(H17/G17, "") -> -0.1511592
A18: CA: San Jose FHC - Citi | B18: CA | C18: =SUM(Jan!C18, Feb!C18, Mar!C18) -> 72919.87 | D18: =SUM(Jan!F18, Feb!F18, Mar!G18) -> 93317 | E18: =IF(AND(ISNUMBER(C18),ISNUMBER(D18)), C18-D18, "") -> -20397.13 | F18: =IFERROR(E18/D18, "") -> -0.21857893 | G18: =SUM(Jan!I18, Feb!I18, Mar!J18) -> 83179.993 | H18: =SUM(Jan!J18, Feb!J18, Mar!K18) -> -10260.123 | I18: =IFERROR(H18/G18, "") -> -0.12334845
A19: CA: San Jose MOB - Citi | B19: CA | C19: =SUM(Jan!C19, Feb!C19, Mar!C19) -> 109423 | D19: =SUM(Jan!F19, Feb!F19, Mar!G19) -> 148699 | E19: =IF(AND(ISNUMBER(C19),ISNUMBER(D19)), C19-D19, "") -> -39276 | F19: =IFERROR(E19/D19, "") -> -0.2641309 | G19: =SUM(Jan!I19, Feb!I19, Mar!J19) -> 133932.62 | H19: =SUM(Jan!J19, Feb!J19, Mar!K19) -> -24509.623 | I19: =IFERROR(H19/G19, "") -> -0.18299965
A20: CA: Selma - Citi | B20: CA | C20: =SUM(Jan!C20, Feb!C20, Mar!C20) -> 78863.13 | D20: =SUM(Jan!F20, Feb!F20, Mar!G20) -> 76746 | E20: =IF(AND(ISNUMBER(C20),ISNUMBER(D20)), C20-D20, "") -> 2117.13 | F20: =IFERROR(E20/D20, "") -> 0.027586193 | G20: =SUM(Jan!I20, Feb!I20, Mar!J20) -> 87508.76 | H20: =SUM(Jan!J20, Feb!J20, Mar!K20) -> -8645.63 | I20: =IFERROR(H20/G20, "") -> -0.098797309
A21: CA: Vacaville Hospital | B21: CA | C21: =SUM(Jan!C21, Feb!C21, Mar!C21) -> 499858.25 | D21: =SUM(Jan!F21, Feb!F21, Mar!G21) -> 554214 | E21: =IF(AND(ISNUMBER(C21),ISNUMBER(D21)), C21-D21, "") -> -54355.75 | F21: =IFERROR(E21/D21, "") -> -0.098077187 | G21: =SUM(Jan!I21, Feb!I21, Mar!J21) -> 493007.67 | H21: =SUM(Jan!J21, Feb!J21, Mar!K21) -> 6850.581 | I21: =IFERROR(H21/G21, "") -> 0.013895486
A22: CA: Manteca - KP Manteca Hospital | B22: CA | C22: =SUM(Jan!C22, Feb!C22, Mar!C22) -> 163859.5 | D22: =SUM(Jan!F22, Feb!F22, Mar!G22) -> 0 | E22: =IF(AND(ISNUMBER(C22),ISNUMBER(D22)), C22-D22, "") -> 163859.5 | F22: =IFERROR(E22/D22, 0) -> 0 | G22: =SUM(Jan!I22, Feb!I22, Mar!J22) -> 133950.6 | H22: =SUM(Jan!J22, Feb!J22, Mar!K22) -> 29908.895 | I22: =IFERROR(H22/G22, 0) -> 0.22328302

Sheet 2nd Qtr
A1: {=portfolio} -> CITI | D1: 2nd Quarter Actual v. Expected | G1: 2nd Quarter Actual v. Forecasted
A2: Total | C2: =SUM(C4:C100) -> 7381762.8 | D2: =SUM(D4:D100) -> 7509406.7 | E2: =C2-D2 -> -127643.98 | F2: =IFERROR(E2/D2, 0) -> -0.016997879 | G2: =SUM(G4:G100) -> 8131944.1 | H2: =C2-G2 -> -750181.3 | I2: =IFERROR(H2/G2, 0) -> -0.092251164
A3: Site | B3: State | C3: Actual | D3: Expected | E3: Delta | F3: % | G3: Forecasted | H3: Delta | I3: %
A4: {=Sites[Site]} -> CA: Antioch Deer Valley - Citi | B4: {=Sites[State]} -> CA | C4: =SUM(Apr!C4, May!C4, Jun!C4) -> 220659.25 | D4: =SUM(Apr!F4, May!F4, Jun!G4) -> 215282 | E4: =IF(AND(ISNUMBER(C4),ISNUMBER(D4)), C4-D4, "") -> 5377.25 | F4: =IFERROR(E4/D4, "") -> 0.024977704 | G4: =SUM(Apr!I4+May!I4+Jun!J4) -> 231981.46 | H4: =SUM(Apr!J4, May!J4, Jun!K4) -> -11322.21 | I4: =IFERROR(H4/G4, "") -> -0.04880653
A5: CA: Antioch MC CUP - Citi | B5: CA | C5: =SUM(Apr!C5, May!C5, Jun!C5) -> 757441 | D5: =SUM(Apr!F5, May!F5, Jun!G5) -> 734291 | E5: =IF(AND(ISNUMBER(C5),ISNUMBER(D5)), C5-D5, "") -> 23150 | F5: =IFERROR(E5/D5, "") -> 0.03152701 | G5: =SUM(Apr!I5+May!I5+Jun!J5) -> 787180.74 | H5: =SUM(Apr!J5, May!J5, Jun!K5) -> -29739.744 | I5: =IFERROR(H5/G5, "") -> -0.03778007
A6: CA: Clovis - Citi | B6: CA | C6: =SUM(Apr!C6, May!C6, Jun!C6) -> 316814.5 | D6: =SUM(Apr!F6, May!F6, Jun!G6) -> 312002 | E6: =IF(AND(ISNUMBER(C6),ISNUMBER(D6)), C6-D6, "") -> 4812.5 | F6: =IFERROR(E6/D6, "") -> 0.015424581 | G6: =SUM(Apr!I6+May!I6+Jun!J6) -> 323891.83 | H6: =SUM(Apr!J6, May!J6, Jun!K6) -> -7077.33 | I6: =IFERROR(H6/G6, "") -> -0.021850906
A7: CA: Elk Grove MOB - Citi | B7: CA | C7: =SUM(Apr!C7, May!C7, Jun!C7) -> 486584.5 | D7: =SUM(Apr!F7, May!F7, Jun!G7) -> 506248 | E7: =IF(AND(ISNUMBER(C7),ISNUMBER(D7)), C7-D7, "") -> -19663.5 | F7: =IFERROR(E7/D7, "") -> -0.038841635 | G7: =SUM(Apr!I7+May!I7+Jun!J7) -> 522356.97 | H7: =SUM(Apr!J7, May!J7, Jun!K7) -> -35772.472 | I7: =IFERROR(H7/G7, "") -> -0.068482808
A8: CA: Elk Grove Promenade - Citi | B8: CA | C8: =SUM(Apr!C8, May!C8, Jun!C8) -> 256185.75 | D8: =SUM(Apr!F8, May!F8, Jun!G8) -> 267090.73 | E8: =IF(AND(ISNUMBER(C8),ISNUMBER(D8)), C8-D8, "") -> -10904.985 | F8: =IFERROR(E8/D8, "") -> -0.040828766 | G8: =SUM(Apr!I8+May!I8+Jun!J8) -> 273326.74 | H8: =SUM(Apr!J8, May!J8, Jun!K8) -> -17140.991 | I8: =IFERROR(H8/G8, "") -> -0.062712455
A9: CA: Fresno Sequioa - Citi | B9: CA | C9: =SUM(Apr!C9, May!C9, Jun!C9) -> 523930.25 | D9: =SUM(Apr!F9, May!F9, Jun!G9) -> 527508 | E9: =IF(AND(ISNUMBER(C9),ISNUMBER(D9)), C9-D9, "") -> -3577.75 | F9: =IFERROR(E9/D9, "") -> -0.0067823616 | G9: =SUM(Apr!I9+May!I9+Jun!J9) -> 542861.36 | H9: =SUM(Apr!J9, May!J9, Jun!K9) -> -18931.113 | I9: =IFERROR(H9/G9, "") -> -0.034872832
A10: CA: Fresno MOB - Citi | B10: CA | C10: =SUM(Apr!C10, May!C10, Jun!C10) -> 203098.5 | D10: =SUM(Apr!F10, May!F10, Jun!G10) -> 215736 | E10: =IF(AND(ISNUMBER(C10),ISNUMBER(D10)), C10-D10, "") -> -12637.5 | F10: =IFERROR(E10/D10, "") -> -0.05857854 | G10: =SUM(Apr!I10+May!I10+Jun!J10) -> 206652.11 | H10: =SUM(Apr!J10, May!J10, Jun!K10) -> -3553.609 | I10: =IFERROR(H10/G10, "") -> -0.017196094
A11: CA: Modesto Bangs - Citi | B11: CA | C11: =SUM(Apr!C11, May!C11, Jun!C11) -> 130541.38 | D11: =SUM(Apr!F11, May!F11, Jun!G11) -> 153691 | E11: =IF(AND(ISNUMBER(C11),ISNUMBER(D11)), C11-D11, "") -> -23149.62 | F11: =IFERROR(E11/D11, "") -> -0.15062443 | G11: =SUM(Apr!I11+May!I11+Jun!J11) -> 134261.63 | H11: =SUM(Apr!J11, May!J11, Jun!K11) -> -3720.252 | I11: =IFERROR(H11/G11, "") -> -0.027708973
A12: CA: Napa Data Center - Citi | B12: CA | C12: =SUM(Apr!C12, May!C12, Jun!C12) -> 128313.87 | D12: =SUM(Apr!F12, May!F12, Jun!G12) -> 149198 | E12: =IF(AND(ISNUMBER(C12),ISNUMBER(D12)), C12-D12, "") -> -20884.13 | F12: =IFERROR(E12/D12, "") -> -0.13997594 | G12: =SUM(Apr!I12+May!I12+Jun!J12) -> 145949.21 | H12: =SUM(Apr!J12, May!J12, Jun!K12) -> -17635.337 | I12: =IFERROR(H12/G12, "") -> -0.12083202
A13: CA: Petaluma MOB - Citi | B13: CA | C13: =SUM(Apr!C13, May!C13, Jun!C13) -> 325444.5 | D13: =SUM(Apr!F13, May!F13, Jun!G13) -> 341582 | E13: =IF(AND(ISNUMBER(C13),ISNUMBER(D13)), C13-D13, "") -> -16137.5 | F13: =IFERROR(E13/D13, "") -> -0.047243414 | G13: =SUM(Apr!I13+May!I13+Jun!J13) -> 298577.28 | H13: =SUM(Apr!J13, May!J13, Jun!K13) -> 26867.22 | I13: =IFERROR(H13/G13, "") -> 0.089984141
A14: CA: Pleasanton Tec Ctr - Citi | B14: CA | C14: =SUM(Apr!C14, May!C14, Jun!C14) -> 308543 | D14: =SUM(Apr!F14, May!F14, Jun!G14) -> 487317 | E14: =IF(AND(ISNUMBER(C14),ISNUMBER(D14)), C14-D14, "") -> -178774 | F14: =IFERROR(E14/D14, "") -> -0.36685361 | G14: =SUM(Apr!I14+May!I14+Jun!J14) -> 506725.6 | H14: =SUM(Apr!J14, May!J14, Jun!K14) -> -198182.6 | I14: =IFERROR(H14/G14, "") -> -0.39110438
A15: CA: Rancho Cordova - Citi | B15: CA | C15: =SUM(Apr!C15, May!C15, Jun!C15) -> 677515.5 | D15: =SUM(Apr!F15, May!F15, Jun!G15) -> 677829 | E15: =IF(AND(ISNUMBER(C15),ISNUMBER(D15)), C15-D15, "") -> -313.5 | F15: =IFERROR(E15/D15, "") -> -0.00046250603 | G15: =SUM(Apr!I15+May!I15+Jun!J15) -> 720547.42 | H15: =SUM(Apr!J15, May!J15, Jun!K15) -> -43031.915 | I15: =IFERROR(H15/G15, "") -> -0.059721143
A16: CA: S Sacramento Wyndham - Citi | B16: CA | C16: =SUM(Apr!C16, May!C16, Jun!C16) -> 425085.25 | D16: =SUM(Apr!F16, May!F16, Jun!G16) -> 437275 | E16: =IF(AND(ISNUMBER(C16),ISNUMBER(D16)), C16-D16, "") -> -12189.75 | F16: =IFERROR(E16/D16, "") -> -0.027876622 | G16: =SUM(Apr!I16+May!I16+Jun!J16) -> 421749.33 | H16: =SUM(Apr!J16, May!J16, Jun!K16) -> 3335.922 | I16: =IFERROR(H16/G16, "") -> 0.0079097269
... A21: CA: Vacaville Hospital | B21: CA | C21: =SUM(Apr!C21, May!C21, Jun!C21) -> 1030002 | D21: =SUM(Apr!F21, May!F21, Jun!G21) -> 1102366 | E21: =IF(AND(ISNUMBER(C21),ISNUMBER(D21)), C21-D21, "") -> -72364 | F21: =IFERROR(E21/D21, "") -> -0.06564426 | G21: =SUM(Apr!I21+May!I21+Jun!J21) -> 1268327.2 | H21: =SUM(Apr!J21, May!J21, Jun!K21) -> -238325.16 | I21: =IFERROR(H21/G21, "") -> -0.18790511
A22: CA: Manteca - KP Manteca Hospital | B22: CA | C22: =SUM(Apr!C22, May!C22, Jun!C22) -> 332143 | D22: =SUM(Apr!F22, May!F22, Jun!G22) -> 0 | E22: =IF(AND(ISNUMBER(C22),ISNUMBER(D22)), C22-D22, "") -> 332143 | F22: =IFERROR(E22/D22, "") | G22: =SUM(Apr!I22+May!I22+Jun!J22) -> 317610.63 | H22: =SUM(Apr!J22, May!J22, Jun!K22) -> 14532.37

Sheet 3rd Qtr
A1: {=portfolio} -> CITI | D1: 3rd Quarter Actual v. Expected | G1: 3rd Quarter Actual v. Forecasted
A2: Total | C2: =SUM(C4:C100) -> 4691895 | D2: =SUM(D4:D100) -> 5584956 | E2: =C2-D2 -> -893061.05 | F2: =IFERROR(E2/D2, 0) -> -0.15990476 | G2: =SUM(G4:G100) -> 2719631.1 | H2: =C2-G2 -> 1972263.9 | I2: =IFERROR(H2/G2, 0) -> 0.72519537
A3: Site | B3: State | C3: Actual | D3: Expected | E3: Delta | F3: % | G3: Forecasted | H3: Delta | I3: %
A4: {=Sites[Site]} -> CA: Antioch Deer Valley - Citi | B4: {=Sites[State]} -> CA | C4: =SUM(Jul!C4, Aug!C4, Sep!C4) -> 146892.5 | D4: =SUM(Jul!F4, Aug!F4, Sep!D4) -> 153773 | E4: =IF(AND(ISNUMBER(C4),ISNUMBER(D4)), C4-D4, "") -> -6880.5 | F4: =IFERROR(E4/D4, "") -> -0.044744526 | G4: =SUM(Jul!I4, Aug!K4, Sep!I4) -> 78627.311 | H4: =SUM(Jul!J4, Aug!J4, Sep!H4) -> -4118.993 | I4: =IFERROR(H4/G4, "") -> -0.052386289
A5: CA: Antioch MC CUP - Citi | B5: CA | C5: =SUM(Jul!C5, Aug!C5, Sep!C5) -> 487866 | D5: =SUM(Jul!F5, Aug!F5, Sep!D5) -> 524198 | E5: =IF(AND(ISNUMBER(C5),ISNUMBER(D5)), C5-D5, "") -> -36332 | F5: =IFERROR(E5/D5, "") -> -0.069309688 | G5: =SUM(Jul!I5, Aug!K5, Sep!I5) -> 268691.03 | H5: =SUM(Jul!J5, Aug!J5, Sep!H5) -> -21622.496 | I5: =IFERROR(H5/G5, "") -> -0.080473456
A6: CA: Clovis - Citi | B6: CA | C6: =SUM(Jul!C6, Aug!C6, Sep!C6) -> 193244.5 | D6: =SUM(Jul!F6, Aug!F6, Sep!D6) -> 214885 | E6: =IF(AND(ISNUMBER(C6),ISNUMBER(D6)), C6-D6, "") -> -21640.5 | F6: =IFERROR(E6/D6, "") -> -0.10070736 | G6: =SUM(Jul!I6, Aug!K6, Sep!I6) -> 110163.78 | H6: =SUM(Jul!J6, Aug!J6, Sep!H6) -> -19025.68 | I6: =IFERROR(H6/G6, "") -> -0.17270359
A7: CA: Elk Grove MOB - Citi | B7: CA | C7: =SUM(Jul!C7, Aug!C7, Sep!C7) -> 268083 | D7: =SUM(Jul!F7, Aug!F7, Sep!D7) -> 360303 | E7: =IF(AND(ISNUMBER(C7),ISNUMBER(D7)), C7-D7, "") -> -92220 | F7: =IFERROR(E7/D7, "") -> -0.25595124 | G7: =SUM(Jul!I7, Aug!K7, Sep!I7) -> 176430.98 | H7: =SUM(Jul!J7, Aug!J7, Sep!H7) -> -69875.684 | I7: =IFERROR(H7/G7, "") -> -0.3960511
A8: CA: Elk Grove Promenade - Citi | B8: CA | C8: =SUM(Jul!C8, Aug!C8, Sep!C8) -> 152075.75 | D8: =SUM(Jul!F8, Aug!F8, Sep!D8) -> 190345.03 | E8: =IF(AND(ISNUMBER(C8),ISNUMBER(D8)), C8-D8, "") -> -38269.28 | F8: =IFERROR(E8/D8, "") -> -0.20105216 | G8: =SUM(Jul!I8, Aug!K8, Sep!I8) -> 90243.347 | H8: =SUM(Jul!J8, Aug!J8, Sep!H8) -> -22765.66 | I8: =IFERROR(H8/G8, "") -> -0.25226968
A9: CA: Fresno Sequioa - Citi | B9: CA | C9: =SUM(Jul!C9, Aug!C9, Sep!C9) -> 313908 | D9: =SUM(Jul!F9, Aug!F9, Sep!D9) -> 363493 | E9: =IF(AND(ISNUMBER(C9),ISNUMBER(D9)), C9-D9, "") -> -49585 | F9: =IFERROR(E9/D9, "") -> -0.13641253 | G9: =SUM(Jul!I9, Aug!K9, Sep!I9) -> 185960.43 | H9: =SUM(Jul!J9, Aug!J9, Sep!H9) -> -40940.288 | I9: =IFERROR(H9/G9, "") -> -0.22015591
A10: CA: Fresno MOB - Citi | B10: CA | C10: =SUM(Jul!C10, Aug!C10, Sep!C10) -> 122536.5 | D10: =SUM(Jul!F10, Aug!F10, Sep!D10) -> 148121 | E10: =IF(AND(ISNUMBER(C10),ISNUMBER(D10)), C10-D10, "") -> -25584.5 | F10: =IFERROR(E10/D10, "") -> -0.17272703 | G10: =SUM(Jul!I10, Aug!K10, Sep!I10) -> 69525.091 | H10: =SUM(Jul!J10, Aug!J10, Sep!H10) -> -567701.33 | I10: =IFERROR(H10/G10, "") -> -8.1654165
A11: CA: Modesto Bangs - Citi | B11: CA | C11: =SUM(Jul!C11, Aug!C11, Sep!C11) -> 74163.25 | D11: =SUM(Jul!F11, Aug!F11, Sep!D11) -> 102753 | E11: =IF(AND(ISNUMBER(C11),ISNUMBER(D11)), C11-D11, "") -> -28589.75 | F11: =IFERROR(E11/D11, "") -> -0.27823762 | G11: =SUM(Jul!I11, Aug!K11, Sep!I11) -> 44224.571 | H11: =SUM(Jul!J11, Aug!J11, Sep!H11) -> -8552.852 | I11: =IFERROR(H11/G11, "") -> -0.19339593
A12: CA: Napa Data Center - Citi | B12: CA | C12: =SUM(Jul!C12, Aug!C12, Sep!C12) -> 81102 | D12: =SUM(Jul!F12, Aug!F12, Sep!D12) -> 102554 | E12: =IF(AND(ISNUMBER(C12),ISNUMBER(D12)), C12-D12, "") -> -21452 | F12: =IFERROR(E12/D12, "") -> -0.2091776 | G12: =SUM(Jul!I12, Aug!K12, Sep!I12) -> 51332.668 | H12: =SUM(Jul!J12, Aug!J12, Sep!H12) -> -22406.738 | I12: =IFERROR(H12/G12, "") -> -0.43650055
A13: CA: Petaluma MOB - Citi | B13: CA | C13: =SUM(Jul!C13, Aug!C13, Sep!C13) -> 194651.5 | D13: =SUM(Jul!F13, Aug!F13, Sep!D13) -> 240235 | E13: =IF(AND(ISNUMBER(C13),ISNUMBER(D13)), C13-D13, "") -> -45583.5 | F13: =IFERROR(E13/D13, "") -> -0.18974546 | G13: =SUM(Jul!I13, Aug!K13, Sep!I13) -> 26003.8 | H13: =SUM(Jul!J13, Aug!J13, Sep!H13) -> 147766.88 | I13: =IFERROR(H13/G13, "") -> 5.682511
A14: CA: Pleasanton Tec Ctr - Citi | B14: CA | C14: =SUM(Jul!C14, Aug!C14, Sep!C14) -> 286242 | D14: =SUM(Jul!F14, Aug!F14, Sep!D14) -> 349209 | E14: =IF(AND(ISNUMBER(C14),ISNUMBER(D14)), C14-D14, "") -> -62967 | F14: =IFERROR(E14/D14, "") -> -0.18031322 | G14: =SUM(Jul!I14, Aug!K14, Sep!I14) -> 180121.31 | H14: =SUM(Jul!J14, Aug!J14, Sep!H14) -> -56073.072 | I14: =IFERROR(H14/G14, "") -> -0.31130727
A15: CA: Rancho Cordova - Citi | B15: CA | C15: =SUM(Jul!C15, Aug!C15, Sep!C15) -> 432688.5 | D15: =SUM(Jul!F15, Aug!F15, Sep!D15) -> 483278 | E15: =IF(AND(ISNUMBER(C15),ISNUMBER(D15)), C15-D15, "") -> -50589.5 | F15: =IFERROR(E15/D15, "") -> -0.10467992 | G15: =SUM(Jul!I15, Aug!K15, Sep!I15) -> 239093.31 | H15: =SUM(Jul!J15, Aug!J15, Sep!H15) -> -36411.487 | I15: =IFERROR(H15/G15, "") -> -0.15228986
A16: CA: S Sacramento Wyndham - Citi | B16: CA | C16: =SUM(Jul!C16, Aug!C16, Sep!C16) -> 267318.75 | D16: =SUM(Jul!F16, Aug!F16, Sep!D16) -> 312268 | E16: =IF(AND(ISNUMBER(C16),ISNUMBER(D16)), C16-D16, "") -> -44949.25 | F16: =IFERROR(E16/D16, "") -> -0.14394446 | G16: =SUM(Jul!I16, Aug!K16, Sep!I16) -> 143095.91 | H16: =SUM(Jul!J16, Aug!J16, Sep!H16) -> -3233.347 | I16: =IFERROR(H16/G16, "") -> -0.022595663
... A20: CA: Selma - Citi | B20: CA | C20: =SUM(Jul!C20, Aug!C20, Sep!C20) -> 91984 | D20: =SUM(Jul!F20, Aug!F20, Sep!D20) -> 111286 | E20: =IF(AND(ISNUMBER(C20),ISNUMBER(D20)), C20-D20, "") -> -19302 | F20: =IFERROR(E20/D20, "") -> -0.173445 | G20: =SUM(Jul!I20, Aug!K20, Sep!I20) -> 57505.445 | H20: =SUM(Jul!J20, Aug!J20, Sep!H20) -> -17860.802 | I20: =IFERROR(H20/G20, "") -> -0.31059323
A21: CA: Vacaville Hospital | B21: CA | C21: =SUM(Jul!C21, Aug!C21, Sep!C21) -> 664465.75 | D21: =SUM(Jul!F21, Aug!F21, Sep!D21) -> 771284 | E21: =SUM(Jul!G21, Aug!G21, Sep!E21) -> -106818.25 | F21: =IFERROR(E21/D21, "") -> -0.13849406 | G21: =SUM(Jul!I21, Aug!K21, Sep!I21) -> 443213.35 | H21: =SUM(Jul!J21, Aug!J21, Sep!H21) -> -176660 | I21: =IFERROR(H21/G21, "") -> -0.39858908
A22: CA: Manteca - KP Manteca Hospital | B22: CA | C22: =SUM(Jul!C22, Aug!C22, Sep!C22) -> 197468.5 | D22: =SUM(Jul!F22, Aug!F22, Sep!D22) -> 243489.02 | E22: =SUM(Jul!G22, Aug!G22, Sep!E22) -> -46020.516 | F22: =IFERROR(E22/D22, "") -> -0.18900448 | G22: =SUM(Jul!I22, Aug!K22, Sep!I22) -> 108621.95 | H22: =SUM(Jul!J22, Aug!J22, Sep!H22) -> -9253.725 | I22: =IFERROR(H22/G22, "") -> -0.085192037

Sheet 4th Qtr
A1: {=portfolio} -> CITI | D1: 4th Quarter Actual v. Expected | G1: 4th Quarter Actual v. Forecasted
A2: Total | C2: =SUM(C4:C100) -> 0 | D2: =SUM(D4:D100) -> 0 | E2: =C2-D2 -> 0 | F2: =IFERROR(E2/D2, 0) -> 0 | G2: =SUM(G4:G100) -> 0 | H2: =C2-G2 -> 0 | I2: =IFERROR(H2/G2, 0) -> 0
A3: Site | B3: State | C3: Actual | D3: Expected | E3: Delta | F3: % | G3: Forecasted | H3: Delta | I3: %
A4: {=Sites[Site]} -> CA: Antioch Deer Valley - Citi | B4: {=Sites[State]} -> CA | C4: =SUM(Oct!C4, Nov!C4, Dec!C4) -> 0 | D4: =SUM(Oct!D4, Nov!D4, Dec!D4) -> 0 | E4: =IF(AND(ISNUMBER(C4),ISNUMBER(D4)), C4-D4, "") -> 0 | F4: =IFERROR(E4/D4, "") | H4: =SUM(Oct!H4, Nov!H4, Dec!H4) -> 0 | I4: =IFERROR(H4/G4, "")
A5: CA: Antioch MC CUP - Citi | B5: CA | C5: =SUM(Oct!C5, Nov!C5, Dec!C5) -> 0 | D5: =SUM(Oct!D5, Nov!D5, Dec!D5) -> 0 | E5: =IF(AND(ISNUMBER(C5),ISNUMBER(D5)), C5-D5, "") -> 0 | F5: =IFERROR(E5/D5, "") | H5: =SUM(Oct!H5, Nov!H5, Dec!H5) -> 0 | I5: =IFERROR(H5/G5, "")
A6: CA: Clovis - Citi | B6: CA | C6: =SUM(Oct!C6, Nov!C6, Dec!C6) -> 0 | D6: =SUM(Oct!D6, Nov!D6, Dec!D6) -> 0 | E6: =IF(AND(ISNUMBER(C6),ISNUMBER(D6)), C6-D6, "") -> 0 | F6: =IFERROR(E6/D6, "") | H6: =SUM(Oct!H6, Nov!H6, Dec!H6) -> 0 | I6: =IFERROR(H6/G6, "")
A7: CA: Elk Grove MOB - Citi | B7: CA | C7: =SUM(Oct!C7, Nov!C7, Dec!C7) -> 0 | D7: =SUM(Oct!D7, Nov!D7, Dec!D7) -> 0 | E7: =IF(AND(ISNUMBER(C7),ISNUMBER(D7)), C7-D7, "") -> 0 | F7: =IFERROR(E7/D7, "") | H7: =SUM(Oct!H7, Nov!H7, Dec!H7) -> 0 | I7: =IFERROR(H7/G7, "")
A8: CA: Elk Grove Promenade - Citi | B8: CA | C8: =SUM(Oct!C8, Nov!C8, Dec!C8) -> 0 | D8: =SUM(Oct!D8, Nov!D8, Dec!D8) -> 0 | E8: =IF(AND(ISNUMBER(C8),ISNUMBER(D8)), C8-D8, "") -> 0 | F8: =IFERROR(E8/D8, "") | H8: =SUM(Oct!H8, Nov!H8, Dec!H8) -> 0 | I8: =IFERROR(H8/G8, "")
A9: CA: Fresno Sequioa - Citi | B9: CA | C9: =SUM(Oct!C9, Nov!C9, Dec!C9) -> 0 | D9: =SUM(Oct!D9, Nov!D9, Dec!D9) -> 0 | E9: =IF(AND(ISNUMBER(C9),ISNUMBER(D9)), C9-D9, "") -> 0 | F9: =IFERROR(E9/D9, "") | H9: =SUM(Oct!H9, Nov!H9, Dec!H9) -> 0 | I9: =IFERROR(H9/G9, "")
A10: CA: Fresno MOB - Citi | B10: CA | C10: =SUM(Oct!C10, Nov!C10, Dec!C10) -> 0 | D10: =SUM(Oct!D10, Nov!D10, Dec!D10) -> 0 | E10: =IF(AND(ISNUMBER(C10),ISNUMBER(D10)), C10-D10, "") -> 0 | F10: =IFERROR(E10/D10, "") | H10: =SUM(Oct!H10, Nov!H10, Dec!H10) -> 0 | I10: =IFERROR(H10/G10, "")
A11: CA: Modesto Bangs - Citi | B11: CA | C11: =SUM(Oct!C11, Nov!C11, Dec!C11) -> 0 | D11: =SUM(Oct!D11, Nov!D11, Dec!D11) -> 0 | E11: =IF(AND(ISNUMBER(C11),ISNUMBER(D11)), C11-D11, "") -> 0 | F11: =IFERROR(E11/D11, "") | H11: =SUM(Oct!H11, Nov!H11, Dec!H11) -> 0 | I11: =IFERROR(H11/G11, "")
A12: CA: Napa Data Center - Citi | B12: CA | C12: =SUM(Oct!C12, Nov!C12, Dec!C12) -> 0 | D12: =SUM(Oct!D12, Nov!D12, Dec!D12) -> 0 | E12: =IF(AND(ISNUMBER(C12),ISNUMBER(D12)), C12-D12, "") -> 0 | F12: =IFERROR(E12/D12, "") | H12: =SUM(Oct!H12, Nov!H12, Dec!H12) -> 0 | I12: =IFERROR(H12/G12, "")
A13: CA: Petaluma MOB - Citi | B13: CA | C13: =SUM(Oct!C13, Nov!C13, Dec!C13) -> 0 | D13: =SUM(Oct!D13, Nov!D13, Dec!D13) -> 0 | E13: =IF(AND(ISNUMBER(C13),ISNUMBER(D13)), C13-D13, "") -> 0 | F13: =IFERROR(E13/D13, "") | H13: =SUM(Oct!H13, Nov!H13, Dec!H13) -> 0 | I13: =IFERROR(H13/G13, "")
A14: CA: Pleasanton Tec Ctr - Citi | B14: CA | C14: =SUM(Oct!C14, Nov!C14, Dec!C14) -> 0 | D14: =SUM(Oct!D14, Nov!D14, Dec!D14) -> 0 | E14: =IF(AND(ISNUMBER(C14),ISNUMBER(D14)), C14-D14, "") -> 0 | F14: =IFERROR(E14/D14, "") | H14: =SUM(Oct!H14, Nov!H14, Dec!H14) -> 0 | I14: =IFERROR(H14/G14, "")
A15: CA: Rancho Cordova - Citi | B15: CA | C15: =SUM(Oct!C15, Nov!C15, Dec!C15) -> 0 | D15: =SUM(Oct!D15, Nov!D15, Dec!D15) -> 0 | E15: =IF(AND(ISNUMBER(C15),ISNUMBER(D15)), C15-D15, "") -> 0 | F15: =IFERROR(E15/D15, "") | H15: =SUM(Oct!H15, Nov!H15, Dec!H15) -> 0 | I15: =IFERROR(H15/G15, "")
A16: CA: S Sacramento Wyndham - Citi | B16: CA | C16: =SUM(Oct!C16, Nov!C16, Dec!C16) -> 0 | D16: =SUM(Oct!D16, Nov!D16, Dec!D16) -> 0 | E16: =IF(AND(ISNUMBER(C16),ISNUMBER(D16)), C16-D16, "") -> 0 | F16: =IFERROR(E16/D16, "") | H16: =SUM(Oct!H16, Nov!H16, Dec!H16) -> 0 | I16: =IFERROR(H16/G16, "")
... A21: CA: Vacaville Hospital | B21: CA | C21: =SUM(Oct!C21, Nov!C21, Dec!C21) -> 0 | D21: =SUM(Oct!D21, Nov!D21, Dec!D21) -> 0 | E21: =IF(AND(ISNUMBER(C21),ISNUMBER(D21)), C21-D21, "") -> 0 | F21: =IFERROR(E21/D21, "") | H21: =SUM(Oct!H21, Nov!H21, Dec!H21) -> 0 | I21: =IFERROR(H21/G21, "")
A22: CA: Manteca - KP Manteca Hospital | B22: CA

Sheet Jan
A1: {=portfolio} -> CITI | D1: PPA Modeled Output | E1: Production VS Acual | F1: January Actual v. Expected | I1: January Actual v. Forecasted
A2: Total | C2: =SUM(C4:C99) -> 761476.62 | D2: =SUM(D4:D22) -> 909284 | E2: =C2/D2 -> 0.83744641 | F2: =SUM(F4:F99) -> 875402.64 | G2: =C2-F2 -> -113926.02 | H2: =IFERROR(G2/F2, 0) -> -0.13014127 | I2: =SUM(I4:I99) -> 819042.33 | J2: =C2-I2 -> -57565.706 | K2: =IFERROR(J2/I2, 0) -> -0.070284165 | L2: =IF(AND(TODAY()>DATE(2024, 1, 1), COUNTA(Sites[Site])<>(COUNT(C:C)-1)), "Some sites are missing actual data; if new sites were added, make sure they are aligned correctly (including prior months!)", "")
A3: Site | B3: State | C3: Actual | F3: Expected | G3: Delta | H3: % | I3: Forecasted | J3: Delta | K3: % | L3: Notes | M3: Service Requests
A4: {=Sites[Site]} -> CA: Antioch Deer Valley - Citi | B4: {=Sites[State]} -> CA | C4: 23783.25 | D4: 26935 | E4: =C4/D4 -> 0.88298682 | F4: 26802 | G4: =IF(AND(ISNUMBER(C4),ISNUMBER(F4)), C4-F4, "") -> -3018.75 | H4: =IFERROR(G4/F4, "") -> -0.11263152 | I4: 25333.655 | J4: =IF(AND(ISNUMBER(C4),ISNUMBER(I4)), C4-I4, "") -> -1550.405 | K4: =IFERROR(J4/I4, "") -> -0.06119942
A5: CA: Antioch MC CUP - Citi | B5: CA | C5: 77142 | D5: 88103 | E5: =C5/D5 -> 0.8755888 | F5: 87662 | G5: =IF(AND(ISNUMBER(C5),ISNUMBER(F5)), C5-F5, "") -> -10520 | H5: =IFERROR(G5/F5, "") -> -0.12000639 | I5: 82559.584 | J5: =IF(AND(ISNUMBER(C5),ISNUMBER(I5)), C5-I5, "") -> -5417.584 | K5: =IFERROR(J5/I5, "") -> -0.065620292
A6: CA: Clovis - Citi | B6: CA | C6: 32833 | D6: 30338 | E6: =C6/D6 -> 1.0822401 | F6: 29586 | G6: =IF(AND(ISNUMBER(C6),ISNUMBER(F6)), C6-F6, "") -> 3247 | H6: =IFERROR(G6/F6, "") -> 0.10974785 | I6: 39905.663 | J6: =IF(AND(ISNUMBER(C6),ISNUMBER(I6)), C6-I6, "") -> -7072.663 | K6: =IFERROR(J6/I6, "") -> -0.17723457
A7: CA: Elk Grove MOB - Citi | B7: CA | C7: 45130 | D7: 55259 | E7: =C7/D7 -> 0.81669954 | F7: 54986 | G7: =IF(AND(ISNUMBER(C7),ISNUMBER(F7)), C7-F7, "") -> -9856 | H7: =IFERROR(G7/F7, "") -> -0.17924563 | I7: 50117.35 | J7: =IF(AND(ISNUMBER(C7),ISNUMBER(I7)), C7-I7, "") -> -4987.35 | K7: =IFERROR(J7/I7, "") -> -0.099513442
A8: CA: Elk Grove Promenade - Citi | B8: CA | C8: 22326 | D8: 30535 | E8: =C8/D8 -> 0.73116096 | F8: 30384.635 | G8: =IF(AND(ISNUMBER(C8),ISNUMBER(F8)), C8-F8, "") -> -8058.635 | H8: =IFERROR(G8/F8, "") -> -0.26522073 | I8: 28265.13 | J8: =IF(AND(ISNUMBER(C8),ISNUMBER(I8)), C8-I8, "") -> -5939.13 | K8: =IFERROR(J8/I8, "") -> -0.21012215 | L8: 1. Inverter 2.3 was offline for whole month. | M8: 1. SR079094
A9: CA: Fresno Sequioa - Citi | B9: CA | C9: 54028.75 | D9: 54436 | E9: =C9/D9 -> 0.99251874 | F9: 54179 | G9: =IF(AND(ISNUMBER(C9),ISNUMBER(F9)), C9-F9, "") -> -150.25 | H9: =IFERROR(G9/F9, "") -> -0.0027732147 | I9: 60597.623 | J9: =IF(AND(ISNUMBER(C9),ISNUMBER(I9)), C9-I9, "") -> -6568.873 | K9: =IFERROR(J9/I9, "") -> -0.1084015
A10: CA: Fresno MOB - Citi | B10: CA | C10: 23116 | D10: 21918 | E10: =C10/D10 -> 1.0546583 | F10: 21868 | G10: =IF(AND(ISNUMBER(C10),ISNUMBER(F10)), C10-F10, "") -> 1248 | H10: =IFERROR(G10/F10, "") -> 0.057069691 | I10: 24310.019 | J10: =IF(AND(ISNUMBER(C10),ISNUMBER(I10)), C10-I10, "") -> -1194.019 | K10: =IFERROR(J10/I10, "") -> -0.049116333
A11: CA: Modesto Bangs - Citi | B11: CA | C11: 12386.25 | D11: 12108 | E11: =C11/D11 -> 1.0229807 | F11: 12166 | G11: =IF(AND(ISNUMBER(C11),ISNUMBER(F11)), C11-F11, "") -> 220.25 | H11: =IFERROR(G11/F11, "") -> 0.018103732 | I11: 13154.418 | J11: =IF(AND(ISNUMBER(C11),ISNUMBER(I11)), C11-I11, "") -> -768.168 | K11: =IFERROR(J11/I11, "") -> -0.058396198
A12: CA: Napa Data Center - Citi | B12: CA | C12: 13910.87 | D12: 18607 | E12: =C12/D12 -> 0.74761488 | F12: 18187 | G12: =IF(AND(ISNUMBER(C12),ISNUMBER(F12)), C12-F12, "") -> -4276.13 | H12: =IFERROR(G12/F12, "") -> -0.23512014 | I12: 17420.203 | J12: =IF(AND(ISNUMBER(C12),ISNUMBER(I12)), C12-I12, "") -> -3509.333 | K12: =IFERROR(J12/I12, "") -> -0.2014519 | L12: 1. Inverter 3 was late started on 01/20 due to isolation fault. 2. Inverter 2 was late started on 01/23 due to isolation fault. | M12: 1. SR080355 2. SR080409
A13: CA: Petaluma MOB - Citi | B13: CA | C13: 33858.75 | D13: 45402 | E13: =C13/D13 -> 0.74575459 | F13: 43911 | G13: =IF(AND(ISNUMBER(C13),ISNUMBER(F13)), C13-F13, "") -> -10052.25 | H13: =IFERROR(G13/F13, "") -> -0.22892328 | I13: 41451.396 | J13: =IF(AND(ISNUMBER(C13),ISNUMBER(I13)), C13-I13, "") -> -7592.646 | K13: =IFERROR(J13/I13, "") -> -0.18316985 | L13: 1. Inverter 5 tripped offline on 1/27 at 12:00 PM and back online on 1/28. | M13: 1. SR080526
A14: CA: Pleasanton Tec Ctr - Citi | B14: CA | C14: 45268 | D14: 61178 | E14: =C14/D14 -> 0.73993919 | F14: 60582 | G14: =IF(AND(ISNUMBER(C14),ISNUMBER(F14)), C14-F14, "") -> -15314 | H14: =IFERROR(G14/F14, "") -> -0.25278135 | I14: 54214.861 | J14: =IF(AND(ISNUMBER(C14),ISNUMBER(I14)), C14-I14, "") -> -8946.861 | K14: =IFERROR(J14/I14, "") -> -0.16502599
A15: CA: Rancho Cordova - Citi | B15: CA | C15: 81162.5 | D15: 89790 | E15: =C15/D15 -> 0.90391469 | F15: 89248 | G15: =IF(AND(ISNUMBER(C15),ISNUMBER(F15)), C15-F15, "") -> -8085.5 | H15: =IFERROR(G15/F15, "") -> -0.090595868 | I15: 85149.358 | J15: =IF(AND(ISNUMBER(C15),ISNUMBER(I15)), C15-I15, "") -> -3986.858 | K15: =IFERROR(J15/I15, "") -> -0.046821938
A16: CA: S Sacramento Wyndham - Citi | B16: CA | C16: 38853.75 | D16: 47416 | E16: =C16/D16 -> 0.81942277 | F16: 47087 | G16: =IF(AND(ISNUMBER(C16),ISNUMBER(F16)), C16-F16, "") -> -8233.25 | H16: =IFERROR(G16/F16, "") -> -0.17485187 | I16: 39156.317 | J16: =IF(AND(ISNUMBER(C16),ISNUMBER(I16)), C16-I16, "") -> -302.567 | K16: =IFERROR(J16/I16, "") -> -0.0077271568
A17: CA: Sacramento Point West - Citi | B17: CA | C17: 61132.5 | D17: 90699 | E17: =C17/D17 -> 0.67401515 | F17: 90683 | G17: =IF(AND(ISNUMBER(C17),ISNUMBER(F17)), C17-F17, "") -> -29550.5 | H17: =IFERROR(G17/F17, "") -> -0.32586593 | I17: 84913.76 | J17: =IF(AND(ISNUMBER(C17),ISNUMBER(I17)), C17-I17, "") -> -23781.26 | K17: =IFERROR(J17/I17, "") -> -0.28006368 | L17: 1. Meter only captured 2/3rd of inverter production from 01/11 to 1/18 and later technician resolved the issue. 2. Inverter 1.1 offline on 01/17, 1/19. | M17: 1. SR080147
A18: CA: San Jose FHC - Citi | B18: CA | C18: 16855.75 | D18: 22812 | E18: =C18/D18 -> 0.73889839 | F18: 23498 | G18: =IF(AND(ISNUMBER(C18),ISNUMBER(F18)), C18-F18, "") -> -6642.25 | H18: =IFERROR(G18/F18, "") -> -0.28267299 | I18: 19495.033 | J18: =IF(AND(ISNUMBER(C18),ISNUMBER(I18)), C18-I18, "") -> -2639.283 | K18: =IFERROR(J18/I18, "") -> -0.13538233 | L18: 1. Inverter 8 is derating approximately 10kW. | M18: 1. SR080602
A19: CA: San Jose MOB - Citi | B19: CA | C19: 22890.75 | D19: 37720 | E19: =C19/D19 -> 0.60685976 | F19: 38233 | G19: =IF(AND(ISNUMBER(C19),ISNUMBER(F19)), C19-F19, "") -> -15342.25 | H19: =IFERROR(G19/F19, "") -> -0.40128292 | I19: 30904.094 | J19: =IF(AND(ISNUMBER(C19),ISNUMBER(I19)), C19-I19, "") -> -8013.344 | K19: =IFERROR(J19/I19, "") -> -0.25929717 | L19: 1. Inverter 2 is offline for whole month due to breaker over heating issue. | M19: 1. PM4756
A20: CA: Selma - Citi | B20: CA | C20: 16830.5 | D20: 15404 | E20: =C20/D20 -> 1.0926058 | F20: 15271 | G20: =IF(AND(ISNUMBER(C20),ISNUMBER(F20)), C20-F20, "") -> 1559.5 | H20: =IFERROR(G20/F20, "") -> 0.10212167 | I20: 19231.67 | J20: =IF(AND(ISNUMBER(C20),ISNUMBER(I20)), C20-I20, "") -> -2401.17 | K20: =IFERROR(J20/I20, "") -> -0.12485499
A21: CA: Vacaville Hospital | B21: CA | C21: 105587 | D21: 130651 | E21: =C21/D21 -> 0.80816067 | F21: 131069 | G21: =IF(AND(ISNUMBER(C21),ISNUMBER(F21)), C21-F21, "") -> -25482 | H21: =IFERROR(G21/F21, "") -> -0.19441668 | I21: 102862.19 | J21: =IF(AND(ISNUMBER(C21),ISNUMBER(I21)), C21-I21, "") -> 2724.808 | K21: =IFERROR(J21/I21, "") -> 0.026489889
A22: CA: Manteca - KP Manteca Hospital | B22: CA | C22: 34381 | D22: 29973 | E22: =C22/D22 -> 1.1470657 | F22: 0 | G22: =IF(AND(ISNUMBER(C22),ISNUMBER(F22)), C22-F22, "") -> 34381 | H22: =IFERROR(G22/F22, 0) -> 0 | I22: 0 | J22: =IF(AND(ISNUMBER(C22),ISNUMBER(I22)), C22-I22, "") -> 34381 | K22: =IFERROR(J22/I22, 0) -> 0

Sheet Feb
A1: {=portfolio} -> CITI | D1: PPA Modeled Output | E1: Production VS Acual | F1: February Actual v. Expected | I1: February Actual v. Forecasted
A2: Total | C2: =SUM(C4:C100) -> 1148130.9 | D2: =SUM(D4:D22) -> 1192647 | E2: =C2/D2 -> 0.96267454 | F2: =SUM(F4:F100) -> 1139799.2 | G2: =C2-F2 -> 8331.74 | H2: =IFERROR(G2/F2, 0) -> 0.0073098317 | I2: =SUM(I4:I100) -> 1229355.3 | J2: =C2-I2 -> -81224.444 | K2: =IFERROR(J2/I2, 0) -> -0.066070762 | L2: =IF(AND(TODAY()>DATE(2024, 2, 1), COUNTA(Sites[Site])<>(COUNT(C:C)-1)), "Some sites are missing actual data; if new sites were added, make sure they are aligned correctly (including prior months!)", "")
A3: Site | B3: State | C3: Actual | F3: Expected | G3: Delta | H3: % | I3: Forecasted | J3: Delta | K3: % | L3: Notes | M3: Service Requests
A4: {=Sites[Site]} -> CA: Antioch Deer Valley - Citi | B4: {=Sites[State]} -> CA | C4: 33559 | D4: 33838 | E4: =C4/D4 -> 0.99175483 | F4: 33671 | G4: =IF(AND(ISNUMBER(C4),ISNUMBER(F4)), C4-F4, "") -> -112 | H4: =IFERROR(G4/F4, "") -> -0.0033263045 | I4: 34392.865 | J4: =IF(AND(ISNUMBER(C4),ISNUMBER(I4)), C4-I4, "") -> -833.865 | K4: =IFERROR(J4/I4, "") -> -0.02424529
A5: CA: Antioch MC CUP - Citi | B5: CA | C5: 110890 | D5: 111656 | E5: =C5/D5 -> 0.99313964 | F5: 111096 | G5: =IF(AND(ISNUMBER(C5),ISNUMBER(F5)), C5-F5, "") -> -206 | H5: =IFERROR(G5/F5, "") -> -0.0018542522 | I5: 113606.75 | J5: =IF(AND(ISNUMBER(C5),ISNUMBER(I5)), C5-I5, "") -> -2716.749 | K5: =IFERROR(J5/I5, "") -> -0.023913623
A6: CA: Clovis - Citi | B6: CA | C6: 48875.75 | D6: 46788 | E6: =C6/D6 -> 1.0446215 | F6: 45628 | G6: =IF(AND(ISNUMBER(C6),ISNUMBER(F6)), C6-F6, "") -> 3247.75 | H6: =IFERROR(G6/F6, "") -> 0.071178881 | I6: 55784.006 | J6: =IF(AND(ISNUMBER(C6),ISNUMBER(I6)), C6-I6, "") -> -6908.256 | K6: =IFERROR(J6/I6, "") -> -0.12383937
A7: CA: Elk Grove MOB - Citi | B7: CA | C7: 72294.5 | D7: 74269 | E7: =C7/D7 -> 0.97341421 | F7: 73903 | G7: =IF(AND(ISNUMBER(C7),ISNUMBER(F7)), C7-F7, "") -> -1608.5 | H7: =IFERROR(G7/F7, "") -> -0.021765016 | I7: 76074.415 | J7: =IF(AND(ISNUMBER(C7),ISNUMBER(I7)), C7-I7, "") -> -3779.915 | K7: =IFERROR(J7/I7, "") -> -0.049687073
A8: CA: Elk Grove Promenade - Citi | B8: CA | C8: 34178.25 | D8: 40582 | E8: =C8/D8 -> 0.84220221 | F8: 40382.16 | G8: =IF(AND(ISNUMBER(C8),ISNUMBER(F8)), C8-F8, "") -> -6203.91 | H8: =IFERROR(G8/F8, "") -> -0.15362997 | I8: 42366.747 | J8: =IF(AND(ISNUMBER(C8),ISNUMBER(I8)), C8-I8, "") -> -8188.497 | K8: =IFERROR(J8/I8, "") -> -0.19327651
A9: CA: Fresno Sequioa - Citi | B9: CA | C9: 87690.75 | D9: 83832 | E9: =C9/D9 -> 1.0460296 | F9: 83436 | G9: =IF(AND(ISNUMBER(C9),ISNUMBER(F9)), C9-F9, "") -> 4254.75 | H9: =IFERROR(G9/F9, "") -> 0.050994175 | I9: 90443.703 | J9: =IF(AND(ISNUMBER(C9),ISNUMBER(I9)), C9-I9, "") -> -2752.953 | K9: =IFERROR(J9/I9, "") -> -0.030438305
A10: CA: Fresno MOB - Citi | B10: CA | C10: 33643.13 | D10: 33738 | E10: =C10/D10 -> 0.99718804 | F10: 33625 | G10: =IF(AND(ISNUMBER(C10),ISNUMBER(F10)), C10-F10, "") -> 18.13 | H10: =IFERROR(G10/F10, "") -> 0.00053918216 | I10: 33875.379 | J10: =IF(AND(ISNUMBER(C10),ISNUMBER(I10)), C10-I10, "") -> -232.249 | K10: =IFERROR(J10/I10, "") -> -0.0068559823
A11: CA: Modesto Bangs - Citi | B11: CA | C11: 18676.37 | D11: 20448 | E11: =C11/D11 -> 0.91335925 | F11: 20450 | G11: =IF(AND(ISNUMBER(C11),ISNUMBER(F11)), C11-F11, "") -> -1773.63 | H11: =IFERROR(G11/F11, "") -> -0.086730073 | I11: 19457.064 | J11: =IF(AND(ISNUMBER(C11),ISNUMBER(I11)), C11-I11, "") -> -780.694 | K11: =IFERROR(J11/I11, "") -> -0.040123936
A12: CA: Napa Data Center - Citi | B12: CA | C12: 19292 | D12: 22694 | E12: =C12/D12 -> 0.85009254 | F12: 22187 | G12: =IF(AND(ISNUMBER(C12),ISNUMBER(F12)), C12-F12, "") -> -2895 | H12: =IFERROR(G12/F12, "") -> -0.13048181 | I12: 23401.866 | J12: =IF(AND(ISNUMBER(C12),ISNUMBER(I12)), C12-I12, "") -> -4109.866 | K12: =IFERROR(J12/I12, "") -> -0.17562129 | L12: 1. Inverter 3 was late started on 02/20, 02/21, 02/22 due to isolation fault. | M12: 1. SR081199
A13: CA: Petaluma MOB - Citi | B13: CA | C13: 45005 | D13: 52699 | E13: =C13/D13 -> 0.85400102 | F13: 50968 | G13: =IF(AND(ISNUMBER(C13),ISNUMBER(F13)), C13-F13, "") -> -5963 | H13: =IFERROR(G13/F13, "") -> -0.11699498 | I13: 53496.513 | J13: =IF(AND(ISNUMBER(C13),ISNUMBER(I13)), C13-I13, "") -> -8491.513 | K13: =IFERROR(J13/I13, "") -> -0.15873021 | L13: 1. Inverter 4 has tripping event frequently from 02/02/2024 to 02/21/2024. | M13: 1. SR080566
A14: CA: Pleasanton Tec Ctr - Citi | B14: CA | C14: 61506.5 | D14: 71770 | E14: =C14/D14 -> 0.85699457 | F14: 71319 | G14: =IF(AND(ISNUMBER(C14),ISNUMBER(F14)), C14-F14, "") -> -9812.5 | H14: =IFERROR(G14/F14, "") -> -0.13758606 | I14: 73097.041 | J14: =IF(AND(ISNUMBER(C14),ISNUMBER(I14)), C14-I14, "") -> -11590.541 | K14: =IFERROR(J14/I14, "") -> -0.15856375
A15: CA: Rancho Cordova - Citi | B15: CA | C15: 122166.5 | D15: 116945 | E15: =C15/D15 -> 1.0446492 | F15: 116239 | G15: =IF(AND(ISNUMBER(C15),ISNUMBER(F15)), C15-F15, "") -> 5927.5 | H15: =IFERROR(G15/F15, "") -> 0.050994073 | I15: 124611.56 | J15: =IF(AND(ISNUMBER(C15),ISNUMBER(I15)), C15-I15, "") -> -2445.064 | K15: =IFERROR(J15/I15, "") -> -0.019621486
A16: CA: S Sacramento Wyndham - Citi | B16: CA | C16: 59864.25 | D16: 63883 | E16: =C16/D16 -> 0.93709203 | F16: 63439 | G16: =IF(AND(ISNUMBER(C16),ISNUMBER(F16)), C16-F16, "") -> -3574.75 | H16: =IFERROR(G16/F16, "") -> -0.056349407 | I16: 60517.139 | J16: =IF(AND(ISNUMBER(C16),ISNUMBER(I16)), C16-I16, "") -> -652.889 | K16: =IFERROR(J16/I16, "") -> -0.010788497
A17: CA: Sacramento Point West - Citi | B17: CA | C17: 112885.5 | D17: 122199 | E17: =C17/D17 -> 0.92378416 | F17: 122195 | G17: =IF(AND(ISNUMBER(C17),ISNUMBER(F17)), C17-F17, "") -> -9309.5 | H17: =IFERROR(G17/F17, "") -> -0.076185605 | I17: 126300.29 | J17: =IF(AND(ISNUMBER(C17),ISNUMBER(I17)), C17-I17, "") -> -13414.785 | K17: =IFERROR(J17/I17, "") -> -0.10621342
A18: CA: San Jose FHC - Citi | B18: CA | C18: 22462.87 | D18: 25813 | E18: =C18/D18 -> 0.8702154 | F18: 26589 | G18: =IF(AND(ISNUMBER(C18),ISNUMBER(F18)), C18-F18, "") -> -4126.13 | H18: =IFERROR(G18/F18, "") -> -0.15518184 | I18: 26197.634 | J18: =IF(AND(ISNUMBER(C18),ISNUMBER(I18)), C18-I18, "") -> -3734.764 | K18: =IFERROR(J18/I18, "") -> -0.14256112 | L18: 1. Inverter 8 was derating 10kW compared to peers. Inverter 8 was kept offline from 02/08 and replaced on 02/22 | M18: 1. SR080602
A19: CA: San Jose MOB - Citi | B19: CA | C19: 35183 | D19: 41784 | E19: =C19/D19 -> 0.84202087 | F19: 42352 | G19: =IF(AND(ISNUMBER(C19),ISNUMBER(F19)), C19-F19, "") -> -7169 | H19: =IFERROR(G19/F19, "") -> -0.16927182 | I19: 42492.879 | J19: =IF(AND(ISNUMBER(C19),ISNUMBER(I19)), C19-I19, "") -> -7309.879 | K19: =IFERROR(J19/I19, "") -> -0.17202598 | L19: 1. Inverter 2 was back online on 02/09/2024 | M19: 1. SR080860
A20: CA: Selma - Citi | B20: CA | C20: 24445.75 | D20: 23767 | E20: =C20/D20 -> 1.0285585 | F20: 23641 | G20: =IF(AND(ISNUMBER(C20),ISNUMBER(F20)), C20-F20, "") -> 804.75 | H20: =IFERROR(G20/F20, "") -> 0.034040438 | I20: 27180.013 | J20: =IF(AND(ISNUMBER(C20),ISNUMBER(I20)), C20-I20, "") -> -2734.263 | K20: =IFERROR(J20/I20, "") -> -0.1005983
A21: CA: Vacaville Hospital | B21: CA | C21: 153862.75 | D21: 157635 | E21: =C21/D21 -> 0.97606972 | F21: 158679 | G21: =IF(AND(ISNUMBER(C21),ISNUMBER(F21)), C21-F21, "") -> -4816.25 | H21: =IFERROR(G21/F21, "") -> -0.030352158 | I21: 151744.48 | J21: =IF(AND(ISNUMBER(C21),ISNUMBER(I21)), C21-I21, "") -> 2118.271 | K21: =IFERROR(J21/I21, "") -> 0.01395946
A22: CA: Manteca - KP Manteca Hospital | B22: CA | C22: 51649.03 | D22: 48307 | E22: =C22/D22 -> 1.0691831 | F22: 0 | G22: =IF(AND(ISNUMBER(C22),ISNUMBER(F22)), C22-F22, "") -> 51649.03 | H22: =IFERROR(G22/F22, "") | I22: 54315.003 | J22: =IF(AND(ISNUMBER(C22),ISNUMBER(I22)), C22-I22, "") -> -2665.973 | K22: =IFERROR(J22/I22, "") -> -0.049083547
J23: =IF(AND(ISNUMBER(C23),ISNUMBER(I23)), C23-I23, "")

Sheet Mar
A1: {=portfolio} -> CITI | D1: PPA Modeled Output | E1: Production VS Acual | F1: Q1 Production Vs PPA | G1: March Actual v. Expected | J1: March Actual v. Forecasted
A2: Total | C2: =SUM(C4:C100) -> 1721123.8 | D2: =SUM(D4:D22) -> 1908971 | E2: =C2/D2 -> 0.90159769 | F2: =AVERAGE(F4:F22) -> 0.90062069 | G2: =SUM(G4:G100) -> 1810184.6 | H2: =C2-G2 -> -89060.705 | I2: =IFERROR(H2/G2, 0) -> -0.049199793 | J2: =SUM(J4:J100) -> 1840250.8 | K2: =C2-J2 -> -119126.95 | L2: =IFERROR(K2/J2, 0) -> -0.064734083 | M2: =IF(AND(TODAY()>DATE(2024, 3, 1), COUNTA(Sites[Site])<>(COUNT(C:C)-1)), "Some sites are missing actual data; if new sites were added, make sure they are aligned correctly (including prior months!)", "")
A3: Site | B3: State | C3: Actual | G3: Expected | H3: Delta | I3: % | J3: Forecasted | K3: Delta | L3: % | M3: Notes | N3: Service Requests
A4: {=Sites[Site]} -> CA: Antioch Deer Valley - Citi | B4: {=Sites[State]} -> CA | C4: 36977.5 | D4: 54627 | E4: =C4/D4 -> 0.67690885 | F4: =(SUM(C4,Feb!C4,Jan!C4))/(SUM(Jan!D4,Feb!D4,Mar!D4)) -> 0.81732886 | G4: 54358 | H4: =IF(AND(ISNUMBER(C4),ISNUMBER(G4)), C4-G4, "") -> -17380.5 | I4: =IFERROR(H4/G4, "") -> -0.31974134 | J4: 38371.791 | K4: =IF(AND(ISNUMBER(C4),ISNUMBER(J4)), C4-J4, "") -> -1394.291 | L4: =IFERROR(K4/J4, "") -> -0.036336354 | M4: 1. Site tripped offline on 03/15 at 16 :30 & back online on 03/21 at 15:15. | N4: 1.SR081976
A5: CA: Antioch MC CUP - Citi | B5: CA | C5: 174843.5 | D5: 182925 | E5: =C5/D5 -> 0.95582069 | F5: =(SUM(C5,Feb!C5,Jan!C5))/(SUM(Jan!D5,Feb!D5,Mar!D5)) -> 0.94823797 | G5: 182008 | H5: =IF(AND(ISNUMBER(C5),ISNUMBER(G5)), C5-G5, "") -> -7164.5 | I5: =IFERROR(H5/G5, "") -> -0.039363654 | J5: 178765.1 | K5: =IF(AND(ISNUMBER(C5),ISNUMBER(J5)), C5-J5, "") -> -3921.6 | L5: =IFERROR(K5/J5, "") -> -0.021937168
A6: CA: Clovis - Citi | B6: CA | C6: 73081.25 | D6: 75057 | E6: =C6/D6 -> 0.97367667 | F6: =(SUM(C6,Feb!C6,Jan!C6))/(SUM(Jan!D6,Feb!D6,Mar!D6)) -> 1.0171307 | G6: 73197 | H6: =IF(AND(ISNUMBER(C6),ISNUMBER(G6)), C6-G6, "") -> -115.75 | I6: =IFERROR(H6/G6, "") -> -0.001581349 | J6: 82539.161 | K6: =IF(AND(ISNUMBER(C6),ISNUMBER(J6)), C6-J6, "") -> -9457.911 | L6: =IFERROR(K6/J6, "") -> -0.11458695
A7: CA: Elk Grove MOB - Citi | B7: CA | C7: 108926.5 | D7: 116624 | E7: =C7/D7 -> 0.93399729 | F7: =(SUM(C7,Feb!C7,Jan!C7))/(SUM(Jan!D7,Feb!D7,Mar!D7)) -> 0.91955783 | G7: 116050 | H7: =IF(AND(ISNUMBER(C7),ISNUMBER(G7)), C7-G7, "") -> -7123.5 | I7: =IFERROR(H7/G7, "") -> -0.061383025 | J7: 116103.15 | K7: =IF(AND(ISNUMBER(C7),ISNUMBER(J7)), C7-J7, "") -> -7176.646 | L7: =IFERROR(K7/J7, "") -> -0.061812675
A8: CA: Elk Grove Promenade - Citi | B8: CA | C8: 52479.25 | D8: 62941 | E8: =C8/D8 -> 0.83378481 | F8: =(SUM(C8,Feb!C8,Jan!C8))/(SUM(Jan!D8,Feb!D8,Mar!D8)) -> 0.81295782 | G8: 62631.555 | H8: =IF(AND(ISNUMBER(C8),ISNUMBER(G8)), C8-G8, "") -> -10152.305 | I8: =IFERROR(H8/G8, "") -> -0.16209569 | J8: 63890.261 | K8: =IF(AND(ISNUMBER(C8),ISNUMBER(J8)), C8-J8, "") -> -11411.011 | L8: =IFERROR(K8/J8, "") -> -0.17860329
A9: CA: Fresno Sequioa - Citi | B9: CA | C9: 129193.5 | D9: 128865 | E9: =C9/D9 -> 1.0025492 | F9: =(SUM(C9,Feb!C9,Jan!C9))/(SUM(Jan!D9,Feb!D9,Mar!D9)) -> 1.0141503 | G9: 128257 | H9: =IF(AND(ISNUMBER(C9),ISNUMBER(G9)), C9-G9, "") -> 936.5 | I9: =IFERROR(H9/G9, "") -> 0.0073017457 | J9: 134778.98 | K9: =IF(AND(ISNUMBER(C9),ISNUMBER(J9)), C9-J9, "") -> -5585.475 | L9: =IFERROR(K9/J9, "") -> -0.041441738
A10: CA: Fresno MOB - Citi | B10: CA | C10: 50378.87 | D10: 52132 | E10: =C10/D10 -> 0.96637133 | F10: =(SUM(C10,Feb!C10,Jan!C10))/(SUM(Jan!D10,Feb!D10,Mar!D10)) -> 0.99396964 | G10: 52087 | H10: =IF(AND(ISNUMBER(C10),ISNUMBER(G10)), C10-G10, "") -> -1708.13 | I10: =IFERROR(H10/G10, "") -> -0.032793787 | J10: 50700.151 | K10: =IF(AND(ISNUMBER(C10),ISNUMBER(J10)), C10-J10, "") -> -321.281 | L10: =IFERROR(K10/J10, "") -> -0.0063368845
A11: CA: Modesto Bangs - Citi | B11: CA | C11: 29849.25 | D11: 30868 | E11: =C11/D11 -> 0.96699657 | F11: =(SUM(C11,Feb!C11,Jan!C11))/(SUM(Jan!D11,Feb!D11,Mar!D11)) -> 0.96039149 | G11: 30872 | H11: =IF(AND(ISNUMBER(C11),ISNUMBER(G11)), C11-G11, "") -> -1022.75 | I11: =IFERROR(H11/G11, "") -> -0.033128725 | J11: 31231.568 | K11: =IF(AND(ISNUMBER(C11),ISNUMBER(J11)), C11-J11, "") -> -1382.318 | L11: =IFERROR(K11/J11, "") -> -0.044260282
A12: CA: Napa Data Center - Citi | B12: CA | C12: 30269.13 | D12: 37239 | E12: =C12/D12 -> 0.81283413 | F12: =(SUM(C12,Feb!C12,Jan!C12))/(SUM(Jan!D12,Feb!D12,Mar!D12)) -> 0.80814871 | G12: 36298 | H12: =IF(AND(ISNUMBER(C12),ISNUMBER(G12)), C12-G12, "") -> -6028.87 | I12: =IFERROR(H12/G12, "") -> -0.16609372 | J12: 35866 | K12: =IF(AND(ISNUMBER(C12),ISNUMBER(J12)), C12-J12, "") -> -5596.87 | L12: =IFERROR(K12/J12, "") -> -0.15604946
A13: CA: Petaluma MOB - Citi | B13: CA | C13: 75219.25 | D13: 82799 | E13: =C13/D13 -> 0.90845602 | F13: =(SUM(C13,Feb!C13,Jan!C13))/(SUM(Jan!D13,Feb!D13,Mar!D13)) -> 0.85175788 | G13: 80078 | H13: =IF(AND(ISNUMBER(C13),ISNUMBER(G13)), C13-G13, "") -> -4858.75 | I13: =IFERROR(H13/G13, "") -> -0.060675217 | J13: 83877.507 | K13: =IF(AND(ISNUMBER(C13),ISNUMBER(J13)), C13-J13, "") -> -8658.257 | L13: =IFERROR(K13/J13, "") -> -0.10322502
A14: CA: Pleasanton Tec Ctr - Citi | B14: CA | C14: 95200.5 | D14: 119386 | E14: =C14/D14 -> 0.79741762 | F14: =(SUM(C14,Feb!C14,Jan!C14))/(SUM(Jan!D14,Feb!D14,Mar!D14)) -> 0.80042721 | G14: 118899 | H14: =IF(AND(ISNUMBER(C14),ISNUMBER(G14)), C14-G14, "") -> -23698.5 | I14: =IFERROR(H14/G14, "") -> -0.19931623 | J14: 111680.93 | K14: =IF(AND(ISNUMBER(C14),ISNUMBER(J14)), C14-J14, "") -> -16480.427 | L14: =IFERROR(K14/J14, "") -> -0.14756707 | M14: 1. inverter 12 tripped at 2 pm on 03/25 & back online on 03?26 at 16:00. | N14: 1. SR082719
A15: CA: Rancho Cordova - Citi | B15: CA | C15: 166446 | D15: 171056 | E15: =C15/D15 -> 0.97304976 | F15: =(SUM(C15,Feb!C15,Jan!C15))/(SUM(Jan!D15,Feb!D15,Mar!D15)) -> 0.97878192 | G15: 170024 | H15: =IF(AND(ISNUMBER(C15),ISNUMBER(G15)), C15-G15, "") -> -3578 | I15: =IFERROR(H15/G15, "") -> -0.021044088 | J15: 171534.1 | K15: =IF(AND(ISNUMBER(C15),ISNUMBER(J15)), C15-J15, "") -> -5088.098 | L15: =IFERROR(K15/J15, "") -> -0.029662312 | M15: 1. Inverter 1.1 tripped offline on 03/15 and back online on 03/18 | N15: 1. SR081959
A16: CA: S Sacramento Wyndham - Citi | B16: CA | C16: 91886.5 | D16: 100686 | E16: =C16/D16 -> 0.91260453 | F16: =(SUM(C16,Feb!C16,Jan!C16))/(SUM(Jan!D16,Feb!D16,Mar!D16)) -> 0.89914145 | G16: 99985 | H16: =IF(AND(ISNUMBER(C16),ISNUMBER(G16)), C16-G16, "") -> -8098.5 | I16: =IFERROR(H16/G16, "") -> -0.08099715 | J16: 94876.225 | K16: =IF(AND(ISNUMBER(C16),ISNUMBER(J16)), C16-J16, "") -> -2989.725 | L16: =IFERROR(K16/J16, "") -> -0.031511846
A17: CA: Sacramento Point West - Citi | B17: CA | C17: 165597.5 | D17: 191839 | E17: =C17/D17 -> 0.86321082 | F17: =(SUM(C17,Feb!C17,Jan!C17))/(SUM(Jan!D17,Feb!D17,Mar!D17)) -> 0.83910169 | G17: 191796 | H17: =IF(AND(ISNUMBER(C17),ISNUMBER(G17)), C17-G17, "") -> -26198.5 | I17: =IFERROR(H17/G17, "") -> -0.13659565 | J17: 188879.23 | K17: =IF(AND(ISNUMBER(C17),ISNUMBER(J17)), C17-J17, "") -> -23281.734 | L17: =IFERROR(K17/J17, "") -> -0.12326254 | M17: 1. Inverter 5.5 tripped offline on 03/06 | N17: 1. SR081815
A18: CA: San Jose FHC - Citi | B18: CA | C18: 33601.25 | D18: 41968 | E18: =C18/D18 -> 0.80063977 | F18: =(SUM(C18,Feb!C18,Jan!C18))/(SUM(Jan!D18,Feb!D18,Mar!D18)) -> 0.80491727 | G18: 43230 | H18: =IF(AND(ISNUMBER(C18),ISNUMBER(G18)), C18-G18, "") -> -9628.75 | I18: =IFERROR(H18/G18, "") -> -0.22273306 | J18: 37487.326 | K18: =IF(AND(ISNUMBER(C18),ISNUMBER(J18)), C18-J18, "") -> -3886.076 | L18: =IFERROR(K18/J18, "") -> -0.10366373
A19: CA: San Jose MOB - Citi | B19: CA | C19: 51349.25 | D19: 67200 | E19: =C19/D19 -> 0.76412574 | F19: =(SUM(C19,Feb!C19,Jan!C19))/(SUM(Jan!D19,Feb!D19,Mar!D19)) -> 0.74587605 | G19: 68114 | H19: =IF(AND(ISNUMBER(C19),ISNUMBER(G19)), C19-G19, "") -> -16764.75 | I19: =IFERROR(H19/G19, "") -> -0.24612782 | J19: 60535.65 | K19: =IF(AND(ISNUMBER(C19),ISNUMBER(J19)), C19-J19, "") -> -9186.4 | L19: =IFERROR(K19/J19, "") -> -0.1517519
A20: CA: Selma - Citi | B20: CA | C20: 37586.88 | D20: 38029 | E20: =C20/D20 -> 0.98837414 | F20: =(SUM(C20,Feb!C20,Jan!C20))/(SUM(Jan!D20,Feb!D20,Mar!D20)) -> 1.0215431 | G20: 37834 | H20: =IF(AND(ISNUMBER(C20),ISNUMBER(G20)), C20-G20, "") -> -247.12 | I20: =IFERROR(H20/G20, "") -> -0.0065316911 | J20: 41097.077 | K20: =IF(AND(ISNUMBER(C20),ISNUMBER(J20)), C20-J20, "") -> -3510.197 | L20: =IFERROR(K20/J20, "") -> -0.085412327
A21: CA: Vacaville Hospital | B21: CA | C21: 240408.5 | D21: 264914 | E21: =C21/D21 -> 0.9074964 | F21: =(SUM(C21,Feb!C21,Jan!C21))/(SUM(Jan!D21,Feb!D21,Mar!D21)) -> 0.90357601 | G21: 264466 | H21: =IF(AND(ISNUMBER(C21),ISNUMBER(G21)), C21-G21, "") -> -24057.5 | I21: =IFERROR(H21/G21, "") -> -0.090966325 | J21: 238401 | K21: =IF(AND(ISNUMBER(C21),ISNUMBER(J21)), C21-J21, "") -> 2007.502 | L21: =IFERROR(K21/J21, "") -> 0.0084206946
A22: CA: Manteca - KP Manteca Hospital | B22: CA | C22: 77829.47 | D22: 89816 | E22: =C22/D22 -> 0.86654349 | F22: =(SUM(C22,Feb!C22,Jan!C22))/(SUM(Jan!D22,Feb!D22,Mar!D22)) -> 0.97479714 | G22: 0 | H22: =IF(AND(ISNUMBER(C22),ISNUMBER(G22)), C22-G22, "") -> 77829.47 | I22: =IFERROR(H22/G22, "") | J22: 79635.602 | K22: =IF(AND(ISNUMBER(C22),ISNUMBER(J22)), C22-J22, "") -> -1806.132 | L22: =IFERROR(K22/J22, "") -> -0.022679957

Sheet Apr
A1: {=portfolio} -> CITI | D1: PPA Modeled Output | E1: Production VS Acual | F1: April Actual v. Expected | I1: April Actual v. Forecasted
