Workbook
Name JanActual: #REF!
Name JanActual2: #REF!
Name JanExpected: #REF!
Name JanExpectedDelta: #REF!
Name JanExpectedPercent: #REF!
Name JanExpPercent: #REF!
Name JanForecasted: #REF!
Name JanForecastedDelta: #REF!
Name JanForecastedPercent: #REF!
Name portfolio: Sites!$B$1:$B$1
Name Year: Sites!#REF!

Sheet Year to Date
A1: {=portfolio} -> Silicon Ranch | D1: Year to Date Actual v. Expected | G1: Year to Date Actual v. Forecasted
A2: Total | C2: =SUM(C4:C100) -> 9184681.2 | D2: =SUM(D4:D100) -> 0 | E2: =C2-D2 -> 9184681.2 | F2: =IFERROR(E2/D2, 0) -> 0 | G2: =SUM(G4:G100) -> 11727094 | H2: =C2-G2 -> -2542413.2 | I2: =IFERROR(H2/G2, 0) -> -0.21679822
A3: Site | B3: State | C3: Actual | D3: Expected | E3: Delta | F3: % | G3: Forecasted | H3: Delta | I3: %
A4: {=Sites[Site]} -> Iron Mountain - Windsor | B4: {=Sites[State]} -> CT | C4: =SUM('1st Qtr'!C4, '2nd Qtr'!C4, '3rd Qtr'!C4, '4th Qtr'!C4) -> 219110.75 | D4: =SUM('1st Qtr'!D4, '2nd Qtr'!D4, '3rd Qtr'!D4, '4th Qtr'!D4) -> 0 | E4: =IF(AND(ISNUMBER(C4),ISNUMBER(D4)), C4-D4, "") -> 219110.75 | F4: =IFERROR(E4/D4, "") | G4: =SUM('1st Qtr'!G4, '2nd Qtr'!G4, '3rd Qtr'!G4, '4th Qtr'!G4) -> 228257.79 | H4: =SUM('1st Qtr'!H4, '2nd Qtr'!H4, '3rd Qtr'!H4, '4th Qtr'!H4) -> -9147.04 | I4: =IFERROR(H4/G4, "") -> -0.040073287
A5: Kohls - Auburn | B5: NY | C5: =SUM('1st Qtr'!C5, '2nd Qtr'!C5, '3rd Qtr'!C5, '4th Qtr'!C5) -> 232146 | D5: =SUM('1st Qtr'!D5, '2nd Qtr'!D5, '3rd Qtr'!D5, '4th Qtr'!D5) -> 0 | E5: =IF(AND(ISNUMBER(C5),ISNUMBER(D5)), C5-D5, "") -> 232146 | F5: =IFERROR(E5/D5, "") | G5: =SUM('1st Qtr'!G5, '2nd Qtr'!G5, '3rd Qtr'!G5, '4th Qtr'!G5) -> 248085.76 | H5: =SUM(Jan!H5, Feb!H5, Mar!H5) -> 5388.09 | I5: =IFERROR(H5/G5, "") -> 0.021718659
A6: Kohls - Bensalem | B6: PA | C6: =SUM('1st Qtr'!C6, '2nd Qtr'!C6, '3rd Qtr'!C6, '4th Qtr'!C6) -> 271000 | D6: =SUM('1st Qtr'!D6, '2nd Qtr'!D6, '3rd Qtr'!D6, '4th Qtr'!D6) -> 0 | E6: =IF(AND(ISNUMBER(C6),ISNUMBER(D6)), C6-D6, "") -> 271000 | F6: =IFERROR(E6/D6, "") | G6: =SUM('1st Qtr'!G6, '2nd Qtr'!G6, '3rd Qtr'!G6, '4th Qtr'!G6) -> 254946.52 | H6: =SUM(Jan!H6, Feb!H6, Mar!H6) -> 1265.98 | I6: =IFERROR(H6/G6, "") -> 0.0049656689
A7: Kohls - Brick | B7: NJ | C7: =SUM('1st Qtr'!C7, '2nd Qtr'!C7, '3rd Qtr'!C7, '4th Qtr'!C7) -> 309490 | D7: =SUM('1st Qtr'!D7, '2nd Qtr'!D7, '3rd Qtr'!D7, '4th Qtr'!D7) -> 0 | E7: =IF(AND(ISNUMBER(C7),ISNUMBER(D7)), C7-D7, "") -> 309490 | F7: =IFERROR(E7/D7, "") | G7: =SUM('1st Qtr'!G7, '2nd Qtr'!G7, '3rd Qtr'!G7, '4th Qtr'!G7) -> 302075.77 | H7: =SUM(Jan!H7, Feb!H7, Mar!H7) -> -1190.86 | I7: =IFERROR(H7/G7, "") -> -0.0039422559
A8: Kohls - Buffalo | B8: NY | C8: =SUM('1st Qtr'!C8, '2nd Qtr'!C8, '3rd Qtr'!C8, '4th Qtr'!C8) -> 279669 | D8: =SUM('1st Qtr'!D8, '2nd Qtr'!D8, '3rd Qtr'!D8, '4th Qtr'!D8) -> 0 | E8: =IF(AND(ISNUMBER(C8),ISNUMBER(D8)), C8-D8, "") -> 279669 | F8: =IFERROR(E8/D8, "") | G8: =SUM('1st Qtr'!G8, '2nd Qtr'!G8, '3rd Qtr'!G8, '4th Qtr'!G8) -> 303474.75 | H8: =SUM(Jan!H8, Feb!H8, Mar!H8) -> -818.37 | I8: =IFERROR(H8/G8, "") -> -0.0026966659
A9: Kohls - Canton | B9: CT | C9: =SUM('1st Qtr'!C9, '2nd Qtr'!C9, '3rd Qtr'!C9, '4th Qtr'!C9) -> 107517 | D9: =SUM('1st Qtr'!D9, '2nd Qtr'!D9, '3rd Qtr'!D9, '4th Qtr'!D9) -> 0 | E9: =IF(AND(ISNUMBER(C9),ISNUMBER(D9)), C9-D9, "") -> 107517 | F9: =IFERROR(E9/D9, "") | G9: =SUM('1st Qtr'!G9, '2nd Qtr'!G9, '3rd Qtr'!G9, '4th Qtr'!G9) -> 101196.07 | H9: =SUM(Jan!H9, Feb!H9, Mar!H9) -> 509.95 | I9: =IFERROR(H9/G9, "") -> 0.0050392273
A10: Kohls - East Amherst | B10: NY | C10: =SUM('1st Qtr'!C10, '2nd Qtr'!C10, '3rd Qtr'!C10, '4th Qtr'!C10) -> 256284 | D10: =SUM('1st Qtr'!D10, '2nd Qtr'!D10, '3rd Qtr'!D10, '4th Qtr'!D10) -> 0 | E10: =IF(AND(ISNUMBER(C10),ISNUMBER(D10)), C10-D10, "") -> 256284 | F10: =IFERROR(E10/D10, "") | G10: =SUM('1st Qtr'!G10, '2nd Qtr'!G10, '3rd Qtr'!G10, '4th Qtr'!G10) -> 274055.56 | H10: =SUM(Jan!H10, Feb!H10, Mar!H10) -> -2308.69 | I10: =IFERROR(H10/G10, "") -> -0.0084241677
A11: Kohls - East Brunswick | B11: NJ | C11: =SUM('1st Qtr'!C11, '2nd Qtr'!C11, '3rd Qtr'!C11, '4th Qtr'!C11) -> 317816 | D11: =SUM('1st Qtr'!D11, '2nd Qtr'!D11, '3rd Qtr'!D11, '4th Qtr'!D11) -> 0 | E11: =IF(AND(ISNUMBER(C11),ISNUMBER(D11)), C11-D11, "") -> 317816 | F11: =IFERROR(E11/D11, "") | G11: =SUM('1st Qtr'!G11, '2nd Qtr'!G11, '3rd Qtr'!G11, '4th Qtr'!G11) -> 391028.73 | H11: =SUM(Jan!H11, Feb!H11, Mar!H11) -> -20451.72 | I11: =IFERROR(H11/G11, "") -> -0.052302346
A12: Kohls - Edgewood | B12: MD | C12: =SUM('1st Qtr'!C12, '2nd Qtr'!C12, '3rd Qtr'!C12, '4th Qtr'!C12) -> 1794821 | D12: =SUM('1st Qtr'!D12, '2nd Qtr'!D12, '3rd Qtr'!D12, '4th Qtr'!D12) -> 0 | E12: =IF(AND(ISNUMBER(C12),ISNUMBER(D12)), C12-D12, "") -> 1794821 | F12: =IFERROR(E12/D12, "") | G12: =SUM('1st Qtr'!G12, '2nd Qtr'!G12, '3rd Qtr'!G12, '4th Qtr'!G12) -> 2081403 | H12: =SUM(Jan!H12, Feb!H12, Mar!H12) -> -55603.87 | I12: =IFERROR(H12/G12, "") -> -0.026714611
A13: Kohls - Granite Run | B13: PA | C13: =SUM('1st Qtr'!C13, '2nd Qtr'!C13, '3rd Qtr'!C13, '4th Qtr'!C13) -> 255761 | D13: =SUM('1st Qtr'!D13, '2nd Qtr'!D13, '3rd Qtr'!D13, '4th Qtr'!D13) -> 0 | E13: =IF(AND(ISNUMBER(C13),ISNUMBER(D13)), C13-D13, "") -> 255761 | F13: =IFERROR(E13/D13, "") | G13: =SUM('1st Qtr'!G13, '2nd Qtr'!G13, '3rd Qtr'!G13, '4th Qtr'!G13) -> 253623.08 | H13: =SUM(Jan!H13, Feb!H13, Mar!H13) -> -2068.16 | I13: =IFERROR(H13/G13, "") -> -0.0081544629
A14: Kohls - Greece | B14: NY | C14: =SUM('1st Qtr'!C14, '2nd Qtr'!C14, '3rd Qtr'!C14, '4th Qtr'!C14) -> 207305 | D14: =SUM('1st Qtr'!D14, '2nd Qtr'!D14, '3rd Qtr'!D14, '4th Qtr'!D14) -> 0 | E14: =IF(AND(ISNUMBER(C14),ISNUMBER(D14)), C14-D14, "") -> 207305 | F14: =IFERROR(E14/D14, "") | G14: =SUM('1st Qtr'!G14, '2nd Qtr'!G14, '3rd Qtr'!G14, '4th Qtr'!G14) -> 290228.91 | H14: =SUM(Jan!H14, Feb!H14, Mar!H14) -> -11100.83 | I14: =IFERROR(H14/G14, "") -> -0.038248533
A15: Kohls - Hanover | B15: PA | C15: =SUM('1st Qtr'!C15, '2nd Qtr'!C15, '3rd Qtr'!C15, '4th Qtr'!C15) -> 198839 | D15: =SUM('1st Qtr'!D15, '2nd Qtr'!D15, '3rd Qtr'!D15, '4th Qtr'!D15) -> 0 | E15: =IF(AND(ISNUMBER(C15),ISNUMBER(D15)), C15-D15, "") -> 198839 | F15: =IFERROR(E15/D15, "") | G15: =SUM('1st Qtr'!G15, '2nd Qtr'!G15, '3rd Qtr'!G15, '4th Qtr'!G15) -> 283271.35 | H15: =SUM(Jan!H15, Feb!H15, Mar!H15) -> -9545.67 | I15: =IFERROR(H15/G15, "") -> -0.033697972
A16: Kohls - Horsehead | B16: NY | C16: =SUM('1st Qtr'!C16, '2nd Qtr'!C16, '3rd Qtr'!C16, '4th Qtr'!C16) -> 204714 | D16: =SUM('1st Qtr'!D16, '2nd Qtr'!D16, '3rd Qtr'!D16, '4th Qtr'!D16) -> 0 | E16: =IF(AND(ISNUMBER(C16),ISNUMBER(D16)), C16-D16, "") -> 204714 | F16: =IFERROR(E16/D16, "") | G16: =SUM('1st Qtr'!G16, '2nd Qtr'!G16, '3rd Qtr'!G16, '4th Qtr'!G16) -> 225862.5 | H16: =SUM(Jan!H16, Feb!H16, Mar!H16) -> -9727.88 | I16: =IFERROR(H16/G16, "") -> -0.043069921
... A68: Snowline SD - Vista Verde ES | B68: CA | C68: =SUM('1st Qtr'!C68, '2nd Qtr'!C68, '3rd Qtr'!C68, '4th Qtr'!C68) -> 33695 | D68: =SUM('1st Qtr'!D68, '2nd Qtr'!D68, '3rd Qtr'!D68, '4th Qtr'!D68) -> 0 | E68: =IF(AND(ISNUMBER(C68),ISNUMBER(D68)), C68-D68, "") -> 33695 | F68: =IFERROR(E68/D68, "") | G68: =SUM('1st Qtr'!G68, '2nd Qtr'!G68, '3rd Qtr'!G68, '4th Qtr'!G68) -> 33905.04 | H68: =SUM(Jan!H68, Feb!H68, Mar!H68) -> 0 | I68: =IFERROR(H68/G68, "") -> 0

Sheet 1st Qtr
A1: {=portfolio} -> Silicon Ranch | D1: 1st Quarter Actual v. Expected | G1: 1st Quarter Actual v. Forecasted
A2: Total | C2: =SUM(C4:C100) -> 1611034.4 | D2: =SUM(D4:D100) -> 0 | E2: =C2-D2 -> 1611034.4 | F2: =IFERROR(E2/D2, 0) -> 0 | G2: =SUM(G4:G100) -> 1923155.8 | H2: =C2-G2 -> -312121.44 | I2: =IFERROR(H2/G2, 0) -> -0.16229649
A3: Site | B3: State | C3: Actual | D3: Expected | E3: Delta | F3: % | G3: Forecasted | H3: Delta | I3: %
A4: {=Sites[Site]} -> Iron Mountain - Windsor | B4: {=Sites[State]} -> CT | C4: =SUM(Jan!C4, Feb!C4, Mar!C4) -> 49920.75 | D4: =SUM(Jan!D4, Feb!D4, Mar!D4) -> 0 | E4: =IF(AND(ISNUMBER(C4),ISNUMBER(D4)), C4-D4, "") -> 49920.75 | F4: =IFERROR(E4/D4, "") | G4: =SUM(Jan!G4, Feb!G4, Mar!G4) -> 57306.24 | H4: =SUM(Jan!H4, Feb!H4, Mar!H4) -> -7385.49 | I4: =IFERROR(H4/G4, "") -> -0.12887759
A5: Kohls - Auburn | B5: NY | C5: =SUM(Jan!C5, Feb!C5, Mar!C5) -> 44800 | D5: =SUM(Jan!D5, Feb!D5, Mar!D5) -> 0 | E5: =IF(AND(ISNUMBER(C5),ISNUMBER(D5)), C5-D5, "") -> 44800 | F5: =IFERROR(E5/D5, "") | G5: =SUM(Jan!G5, Feb!G5, Mar!G5) -> 39411.91 | H5: =SUM(Jan!H5, Feb!H5, Mar!H5) -> 5388.09 | I5: =IFERROR(H5/G5, "") -> 0.13671223
A6: Kohls - Bensalem | B6: PA | C6: =SUM(Jan!C6, Feb!C6, Mar!C6) -> 66928 | D6: =SUM(Jan!D6, Feb!D6, Mar!D6) -> 0 | E6: =IF(AND(ISNUMBER(C6),ISNUMBER(D6)), C6-D6, "") -> 66928 | F6: =IFERROR(E6/D6, "") | G6: =SUM(Jan!G6, Feb!G6, Mar!G6) -> 65662.02 | H6: =SUM(Jan!H6, Feb!H6, Mar!H6) -> 1265.98 | I6: =IFERROR(H6/G6, "") -> 0.019280248
A7: Kohls - Brick | B7: NJ | C7: =SUM(Jan!C7, Feb!C7, Mar!C7) -> 74090 | D7: =SUM(Jan!D7, Feb!D7, Mar!D7) -> 0 | E7: =IF(AND(ISNUMBER(C7),ISNUMBER(D7)), C7-D7, "") -> 74090 | F7: =IFERROR(E7/D7, "") | G7: =SUM(Jan!G7, Feb!G7, Mar!G7) -> 75280.86 | H7: =SUM(Jan!H7, Feb!H7, Mar!H7) -> -1190.86 | I7: =IFERROR(H7/G7, "") -> -0.015818895
A8: Kohls - Buffalo | B8: NY | C8: =SUM(Jan!C8, Feb!C8, Mar!C8) -> 53909 | D8: =SUM(Jan!D8, Feb!D8, Mar!D8) -> 0 | E8: =IF(AND(ISNUMBER(C8),ISNUMBER(D8)), C8-D8, "") -> 53909 | F8: =IFERROR(E8/D8, "") | G8: =SUM(Jan!G8, Feb!G8, Mar!G8) -> 54727.37 | H8: =SUM(Jan!H8, Feb!H8, Mar!H8) -> -818.37 | I8: =IFERROR(H8/G8, "") -> -0.014953578
A9: Kohls - Canton | B9: CT | C9: =SUM(Jan!C9, Feb!C9, Mar!C9) -> 24565 | D9: =SUM(Jan!D9, Feb!D9, Mar!D9) -> 0 | E9: =IF(AND(ISNUMBER(C9),ISNUMBER(D9)), C9-D9, "") -> 24565 | F9: =IFERROR(E9/D9, "") | G9: =SUM(Jan!G9, Feb!G9, Mar!G9) -> 24055.05 | H9: =SUM(Jan!H9, Feb!H9, Mar!H9) -> 509.95 | I9: =IFERROR(H9/G9, "") -> 0.021199291
A10: Kohls - East Amherst | B10: NY | C10: =SUM(Jan!C10, Feb!C10, Mar!C10) -> 49240 | D10: =SUM(Jan!D10, Feb!D10, Mar!D10) -> 0 | E10: =IF(AND(ISNUMBER(C10),ISNUMBER(D10)), C10-D10, "") -> 49240 | F10: =IFERROR(E10/D10, "") | G10: =SUM(Jan!G10, Feb!G10, Mar!G10) -> 51548.69 | H10: =SUM(Jan!H10, Feb!H10, Mar!H10) -> -2308.69 | I10: =IFERROR(H10/G10, "") -> -0.044786589
A11: Kohls - East Brunswick | B11: NJ | C11: =SUM(Jan!C11, Feb!C11, Mar!C11) -> 79993 | D11: =SUM(Jan!D11, Feb!D11, Mar!D11) -> 0 | E11: =IF(AND(ISNUMBER(C11),ISNUMBER(D11)), C11-D11, "") -> 79993 | F11: =IFERROR(E11/D11, "") | G11: =SUM(Jan!G11, Feb!G11, Mar!G11) -> 100444.72 | H11: =SUM(Jan!H11, Feb!H11, Mar!H11) -> -20451.72 | I11: =IFERROR(H11/G11, "") -> -0.2036117
A12: Kohls - Edgewood | B12: MD | C12: =SUM(Jan!C12, Feb!C12, Mar!C12) -> 489062 | D12: =SUM(Jan!D12, Feb!D12, Mar!D12) -> 0 | E12: =IF(AND(ISNUMBER(C12),ISNUMBER(D12)), C12-D12, "") -> 489062 | F12: =IFERROR(E12/D12, "") | G12: =SUM(Jan!G12, Feb!G12, Mar!G12) -> 544665.87 | H12: =SUM(Jan!H12, Feb!H12, Mar!H12) -> -55603.87 | I12: =IFERROR(H12/G12, "") -> -0.10208804
A13: Kohls - Granite Run | B13: PA | C13: =SUM(Jan!C13, Feb!C13, Mar!C13) -> 63649 | D13: =SUM(Jan!D13, Feb!D13, Mar!D13) -> 0 | E13: =IF(AND(ISNUMBER(C13),ISNUMBER(D13)), C13-D13, "") -> 63649 | F13: =IFERROR(E13/D13, "") | G13: =SUM(Jan!G13, Feb!G13, Mar!G13) -> 65717.16 | H13: =SUM(Jan!H13, Feb!H13, Mar!H13) -> -2068.16 | I13: =IFERROR(H13/G13, "") -> -0.031470624
A14: Kohls - Greece | B14: NY | C14: =SUM(Jan!C14, Feb!C14, Mar!C14) -> 40858 | D14: =SUM(Jan!D14, Feb!D14, Mar!D14) -> 0 | E14: =IF(AND(ISNUMBER(C14),ISNUMBER(D14)), C14-D14, "") -> 40858 | F14: =IFERROR(E14/D14, "") | G14: =SUM(Jan!G14, Feb!G14, Mar!G14) -> 51958.83 | H14: =SUM(Jan!H14, Feb!H14, Mar!H14) -> -11100.83 | I14: =IFERROR(H14/G14, "") -> -0.21364665
A15: Kohls - Hanover | B15: PA | C15: =SUM(Jan!C15, Feb!C15, Mar!C15) -> 64193 | D15: =SUM(Jan!D15, Feb!D15, Mar!D15) -> 0 | E15: =IF(AND(ISNUMBER(C15),ISNUMBER(D15)), C15-D15, "") -> 64193 | F15: =IFERROR(E15/D15, "") | G15: =SUM(Jan!G15, Feb!G15, Mar!G15) -> 73738.67 | H15: =SUM(Jan!H15, Feb!H15, Mar!H15) -> -9545.67 | I15: =IFERROR(H15/G15, "") -> -0.1294527
A16: Kohls - Horsehead | B16: NY | C16: =SUM(Jan!C16, Feb!C16, Mar!C16) -> 44058 | D16: =SUM(Jan!D16, Feb!D16, Mar!D16) -> 0 | E16: =IF(AND(ISNUMBER(C16),ISNUMBER(D16)), C16-D16, "") -> 44058 | F16: =IFERROR(E16/D16, "") | G16: =SUM(Jan!G16, Feb!G16, Mar!G16) -> 53785.88 | H16: =SUM(Jan!H16, Feb!H16, Mar!H16) -> -9727.88 | I16: =IFERROR(H16/G16, "") -> -0.18086308
... A22: Kohls - North Amherst | B22: NY | C22: =SUM(Jan!C22, Feb!C22, Mar!C22) -> 37771 | D22: =SUM(Jan!D22, Feb!D22, Mar!D22) -> 0 | E22: =IF(AND(ISNUMBER(C22),ISNUMBER(D22)), C22-D22, "") -> 37771 | F22: =IFERROR(E22/D22, "") | G22: =SUM(Jan!G22, Feb!G22, Mar!G22) -> 44557.45 | H22: =SUM(Jan!H22, Feb!H22, Mar!H22) -> -6786.45 | I22: =IFERROR(H22/G22, "") -> -0.15230786
A23: Kohls - Staten Island | B23: NY | C23: =SUM(Jan!C23, Feb!C23, Mar!C23) -> 59937.6 | D23: =SUM(Jan!D23, Feb!D23, Mar!D23) -> 0 | E23: =IF(AND(ISNUMBER(C23),ISNUMBER(D23)), C23-D23, "") -> 59937.6 | F23: =IFERROR(E23/D23, "") | G23: =SUM(Jan!G23, Feb!G23, Mar!G24) -> 73401.73 | H23: =SUM(Jan!H23, Feb!H23, Mar!H23) -> -8920.7 | I23: =IFERROR(H23/G23, "") -> -0.12153256
A24: Kohls - Warminster | B24: PA | C24: =SUM(Jan!C24, Feb!C24, Mar!C24) -> 40475 | D24: =SUM(Jan!D24, Feb!D24, Mar!D24) -> 0 | E24: =IF(AND(ISNUMBER(C24),ISNUMBER(D24)), C24-D24, "") -> 40475 | F24: =IFERROR(E24/D24, "") | G24: =SUM(Jan!G24, Feb!G24, Mar!G25) -> 72736.63 | H24: =SUM(Jan!H24, Feb!H24, Mar!H24) -> -40277.78 | I24: =IFERROR(H24/G24, "") -> -0.55374823
A25: Kohls - Waterbury | B25: CT | C25: =SUM(Jan!C25, Feb!C25, Mar!C25) -> 61440 | D25: =SUM(Jan!D25, Feb!D25, Mar!D25) -> 0 | E25: =IF(AND(ISNUMBER(C25),ISNUMBER(D25)), C25-D25, "") -> 61440 | F25: =IFERROR(E25/D25, "") | G25: =SUM(Jan!G25, Feb!G25,Mar!G25) -> 63468.68 | H25: =SUM(Jan!H25, Feb!H25, Mar!H25) -> -2028.68 | I25: =IFERROR(H25/G25, "") -> -0.031963482
A26: Mojave Water Agency - Headquarters | B26: CA | C26: =SUM(Jan!C26, Feb!C26, Mar!C26) -> 0 | D26: =SUM(Jan!D26, Feb!D26, Mar!D26) -> 0 | E26: =IF(AND(ISNUMBER(C26),ISNUMBER(D26)), C26-D26, "") -> 0 | F26: =IFERROR(E26/D26, "") | G26: =SUM(Jan!G26, Feb!G26, Mar!G27) -> 0 | H26: =SUM(Jan!H26, Feb!H26, Mar!H26) -> 0 | I26: =IFERROR(H26/G26, "")
A27: CSU - Bakersfield | B27: CA | C27: =SUM(Jan!C27, Feb!C27, Mar!C27) -> 0 | D27: =SUM(Jan!D27, Feb!D27, Mar!D27) -> 0 | E27: =IF(AND(ISNUMBER(C27),ISNUMBER(D27)), C27-D27, "") -> 0 | F27: =IFERROR(E27/D27, "") | G27: =SUM(Jan!G27, Feb!G27,Mar!G27) -> 0 | H27: =SUM(Jan!H27, Feb!H27, Mar!H27) -> 0 | I27: =IFERROR(H27/G27, "")
A28: Greenfield USD - Fairfield ES | B28: CA | C28: =SUM(Jan!C28, Feb!C28, Mar!C28) -> 0 | D28: =SUM(Jan!D28, Feb!D28, Mar!D28) -> 0 | E28: =IF(AND(ISNUMBER(C28),ISNUMBER(D28)), C28-D28, "") -> 0 | F28: =IFERROR(E28/D28, "") | G28: =SUM(Jan!G28, Feb!G28, Mar!G29) -> 0 | H28: =SUM(Jan!H28, Feb!H28, Mar!H28) -> 0 | I28: =IFERROR(H28/G28, "")
A29: Greenfield USD - Granite Point ES | B29: CA | C29: =SUM(Jan!C29, Feb!C29, Mar!C29) -> 0 | D29: =SUM(Jan!D29, Feb!D29, Mar!D29) -> 0 | E29: =IF(AND(ISNUMBER(C29),ISNUMBER(D29)), C29-D29, "") -> 0 | F29: =IFERROR(E29/D29, "") | G29: =SUM(Jan!G29, Feb!G29,Mar!G29) -> 0 | H29: =SUM(Jan!H29, Feb!H29, Mar!H29) -> 0 | I29: =IFERROR(H29/G29, "")
A30: Greenfield USD - Greenfield MS | B30: CA | C30: =SUM(Jan!C30, Feb!C30, Mar!C30) -> 0 | D30: =SUM(Jan!D30, Feb!D30, Mar!D30) -> 0 | E30: =IF(AND(ISNUMBER(C30),ISNUMBER(D30)), C30-D30, "") -> 0 | F30: =IFERROR(E30/D30, "") | G30: =SUM(Jan!G30, Feb!G30, Mar!G31) -> 0 | H30: =SUM(Jan!H30, Feb!H30, Mar!H30) -> 0 | I30: =IFERROR(H30/G30, "")
A31: Greenfield USD - Horizon ES | B31: CA | C31: =SUM(Jan!C31, Feb!C31, Mar!C31) -> 0 | D31: =SUM(Jan!D31, Feb!D31, Mar!D31) -> 0 | E31: =IF(AND(ISNUMBER(C31),ISNUMBER(D31)), C31-D31, "") -> 0 | F31: =IFERROR(E31/D31, "") | G31: =SUM(Jan!G31, Feb!G31,Mar!G31) -> 0 | H31: =SUM(Jan!H31, Feb!H31, Mar!H31) -> 0 | I31: =IFERROR(H31/G31, "")
A32: Greenfield USD - McKee MS | B32: CA | C32: =SUM(Jan!C32, Feb!C32, Mar!C32) -> 0 | D32: =SUM(Jan!D32, Feb!D32, Mar!D32) -> 0 | E32: =IF(AND(ISNUMBER(C32),ISNUMBER(D32)), C32-D32, "") -> 0 | F32: =IFERROR(E32/D32, "") | G32: =SUM(Jan!G32, Feb!G32, Mar!G33) -> 0 | H32: =SUM(Jan!H32, Feb!H32, Mar!H32) -> 0 | I32: =IFERROR(H32/G32, "")
A33: Greenfield USD - Plantation ES | B33: CA | C33: =SUM(Jan!C33, Feb!C33, Mar!C33) -> 0 | D33: =SUM(Jan!D33, Feb!D33, Mar!D33) -> 0 | E33: =IF(AND(ISNUMBER(C33),ISNUMBER(D33)), C33-D33, "") -> 0 | F33: =IFERROR(E33/D33, "") | G33: =SUM(Jan!G33, Feb!G33,Mar!G33) -> 0 | H33: =SUM(Jan!H33, Feb!H33, Mar!H33) -> 0 | I33: =IFERROR(H33/G33, "")
A34: Greenfield USD - Planz ES | B34: CA | C34: =SUM(Jan!C34, Feb!C34, Mar!C34) -> 0 | D34: =SUM(Jan!D34, Feb!D34, Mar!D34) -> 0 | E34: =IF(AND(ISNUMBER(C34),ISNUMBER(D34)), C34-D34, "") -> 0 | F34: =IFERROR(E34/D34, "") | G34: =SUM(Jan!G34, Feb!G34, Mar!G35) -> 0 | H34: =SUM(Jan!H34, Feb!H34, Mar!H34) -> 0 | I34: =IFERROR(H34/G34, "")
A35: Greenfield USD - Raffaello Palla ES | B35: CA | C35: =SUM(Jan!C35, Feb!C35, Mar!C35) -> 0 | D35: =SUM(Jan!D35, Feb!D35, Mar!D35) -> 0 | E35: =IF(AND(ISNUMBER(C35),ISNUMBER(D35)), C35-D35, "") -> 0 | F35: =IFERROR(E35/D35, "") | G35: =SUM(Jan!G35, Feb!G35,Mar!G35) -> 0 | H35: =SUM(Jan!H35, Feb!H35, Mar!H35) -> 0 | I35: =IFERROR(H35/G35, "")
A36: Greenfield USD - Valle Verde ES | B36: CA | C36: =SUM(Jan!C36, Feb!C36, Mar!C36) -> 0 | D36: =SUM(Jan!D36, Feb!D36, Mar!D36) -> 0 | E36: =IF(AND(ISNUMBER(C36),ISNUMBER(D36)), C36-D36, "") -> 0 | F36: =IFERROR(E36/D36, "") | G36: =SUM(Jan!G36, Feb!G36, Mar!G37) -> 0 | H36: =SUM(Jan!H36, Feb!H36, Mar!H36) -> 0 | I36: =IFERROR(H36/G36, "")
A37: Greenfield USD - W.A. Kendrick ES | B37: CA | C37: =SUM(Jan!C37, Feb!C37, Mar!C37) -> 0 | D37: =SUM(Jan!D37, Feb!D37, Mar!D37) -> 0 | E37: =IF(AND(ISNUMBER(C37),ISNUMBER(D37)), C37-D37, "") -> 0 | F37: =IFERROR(E37/D37, "") | G37: =SUM(Jan!G37, Feb!G37,Mar!G37) -> 0 | H37: =SUM(Jan!H37, Feb!H37, Mar!H37) -> 0 | I37: =IFERROR(H37/G37, "")
A38: Muroc Joint USD - Boron HS | B38: CA | C38: =SUM(Jan!C38, Feb!C38, Mar!C38) -> 0 | D38: =SUM(Jan!D38, Feb!D38, Mar!D38) -> 0 | E38: =IF(AND(ISNUMBER(C38),ISNUMBER(D38)), C38-D38, "") -> 0 | F38: =IFERROR(E38/D38, "") | G38: =SUM(Jan!G38, Feb!G38, Mar!G39) -> 0 | H38: =SUM(Jan!H38, Feb!H38, Mar!H38) -> 0 | I38: =IFERROR(H38/G38, "")
A39: Muroc Joint USD - W. Boron ES | B39: CA | C39: =SUM(Jan!C39, Feb!C39, Mar!C39) -> 0 | D39: =SUM(Jan!D39, Feb!D39, Mar!D39) -> 0 | E39: =IF(AND(ISNUMBER(C39),ISNUMBER(D39)), C39-D39, "") -> 0 | F39: =IFERROR(E39/D39, "") | G39: =SUM(Jan!G39, Feb!G39,Mar!G39) -> 0 | H39: =SUM(Jan!H39, Feb!H39, Mar!H39) -> 0 | I39: =IFERROR(H39/G39, "")
A40: Colusa - WTP | B40: CA | C40: =SUM(Jan!C40, Feb!C40, Mar!C40) -> 0 | D40: =SUM(Jan!D40, Feb!D40, Mar!D40) -> 0 | E40: =IF(AND(ISNUMBER(C40),ISNUMBER(D40)), C40-D40, "") -> 0 | F40: =IFERROR(E40/D40, "") | G40: =SUM(Jan!G40, Feb!G40, Mar!G41) -> 0 | H40: =SUM(Jan!H40, Feb!H40, Mar!H40) -> 0 | I40: =IFERROR(H40/G40, "")
A41: CDCR-North Kern State Prision | B41: CA | C41: =SUM(Jan!C41, Feb!C41, Mar!C41) -> 0 | D41: =SUM(Jan!D41, Feb!D41, Mar!D41) -> 0 | E41: =IF(AND(ISNUMBER(C41),ISNUMBER(D41)), C41-D41, "") -> 0 | F41: =IFERROR(E41/D41, "") | G41: =SUM(Jan!G41, Feb!G41,Mar!G41) -> 0 | H41: =SUM(Jan!H41, Feb!H41, Mar!H41) -> 0 | I41: =IFERROR(H41/G41, "")
A42: Muroc Joint USD - District Office | B42: CA | C42: =SUM(Jan!C42, Feb!C42, Mar!C42) -> 0 | D42: =SUM(Jan!D42, Feb!D42, Mar!D42) -> 0 | E42: =IF(AND(ISNUMBER(C42),ISNUMBER(D42)), C42-D42, "") -> 0 | F42: =IFERROR(E42/D42, "") | G42: =SUM(Jan!G42, Feb!G42, Mar!G43) -> 0 | H42: =SUM(Jan!H42, Feb!H42, Mar!H42) -> 0 | I42: =IFERROR(H42/G42, "")
A43: Whole Foods - Manhattan Beach | B43: CA | C43: =SUM(Jan!C43, Feb!C43, Mar!C43) -> 0 | D43: =SUM(Jan!D43, Feb!D43, Mar!D43) -> 0 | E43: =IF(AND(ISNUMBER(C43),ISNUMBER(D43)), C43-D43, "") -> 0 | F43: =IFERROR(E43/D43, "") | G43: =SUM(Jan!G43, Feb!G43,Mar!G43) -> 0 | H43: =SUM(Jan!H43, Feb!H43, Mar!H43) -> 0 | I43: =IFERROR(H43/G43, "")
A44: Pioneer USD - Frontier ES | B44: CA | C44: =SUM(Jan!C44, Feb!C44, Mar!C44) -> 0 | D44: =SUM(Jan!D44, Feb!D44, Mar!D44) -> 0 | E44: =IF(AND(ISNUMBER(C44),ISNUMBER(D44)), C44-D44, "") -> 0 | F44: =IFERROR(E44/D44, "") | G44: =SUM(Jan!G44, Feb!G44, Mar!G45) -> 0 | H44: =SUM(Jan!H44, Feb!H44, Mar!H44) -> 0 | I44: =IFERROR(H44/G44, "")
A45: Pioneer USD - Pioneer ES | B45: CA | C45: =SUM(Jan!C45, Feb!C45, Mar!C45) -> 0 | D45: =SUM(Jan!D45, Feb!D45, Mar!D45) -> 0 | E45: =IF(AND(ISNUMBER(C45),ISNUMBER(D45)), C45-D45, "") -> 0 | F45: =IFERROR(E45/D45, "") | G45: =SUM(Jan!G45, Feb!G45,Mar!G45) -> 0 | H45: =SUM(Jan!H45, Feb!H45, Mar!H45) -> 0 | I45: =IFERROR(H45/G45, "")
...

Sheet 2nd Qtr
A1: {=portfolio} -> Silicon Ranch | D1: 2nd Quarter Actual v. Expected | G1: 2nd Quarter Actual v. Forecasted
A2: Total | C2: =SUM(C4:C100) -> 3213988.8 | D2: =SUM(D4:D100) -> 0 | E2: =C2-D2 -> 3213988.8 | F2: =IFERROR(E2/D2, 0) -> 0 | G2: =SUM(G4:G100) -> 3634080.2 | H2: =C2-G2 -> -420091.44 | I2: =IFERROR(H2/G2, 0) -> -0.11559773
A3: Site | B3: State | C3: Actual | D3: Expected | E3: Delta | F3: % | G3: Forecasted | H3: Delta | I3: %
A4: {=Sites[Site]} -> Iron Mountain - Windsor | B4: {=Sites[State]} -> CT | C4: =SUM(Apr!C4, May!C4, Jun!C4) -> 102274 | D4: =SUM(Apr!D4, May!D4, Jun!D4) -> 0 | E4: =IF(AND(ISNUMBER(C4),ISNUMBER(D4)), C4-D4, "") -> 102274 | F4: =IFERROR(E4/D4, "") | G4: =SUM(Apr!G4, May!G4, Jun!G4) -> 102351.26 | H4: =SUM(Apr!H4, May!H4, Jun!H4) -> -77.26 | I4: =IFERROR(H4/G4, "") -> -0.00075485148
A5: Kohls - Auburn | B5: NY | C5: =SUM(Apr!C5, May!C5, Jun!C5) -> 108468 | D5: =SUM(Apr!D5, May!D5, Jun!D5) -> 0 | E5: =IF(AND(ISNUMBER(C5),ISNUMBER(D5)), C5-D5, "") -> 108468 | F5: =IFERROR(E5/D5, "") | G5: =SUM(Apr!G5, May!G5, Jun!G5) -> 123949.89 | H5: =SUM(Apr!H5, May!H5, Jun!H5) -> -15481.89 | I5: =IFERROR(H5/G5, "") -> -0.12490443
A6: Kohls - Bensalem | B6: PA | C6: =SUM(Apr!C6, May!C6, Jun!C6) -> 121398 | D6: =SUM(Apr!D6, May!D6, Jun!D6) -> 0 | E6: =IF(AND(ISNUMBER(C6),ISNUMBER(D6)), C6-D6, "") -> 121398 | F6: =IFERROR(E6/D6, "") | G6: =SUM(Apr!G6, May!G6, Jun!G6) -> 111075.05 | H6: =SUM(Apr!H6, May!H6, Jun!H6) -> 10322.95 | I6: =IFERROR(H6/G6, "") -> 0.092936713
A7: Kohls - Brick | B7: NJ | C7: =SUM(Apr!C7, May!C7, Jun!C7) -> 136988 | D7: =SUM(Apr!D7, May!D7, Jun!D7) -> 0 | E7: =IF(AND(ISNUMBER(C7),ISNUMBER(D7)), C7-D7, "") -> 136988 | F7: =IFERROR(E7/D7, "") | G7: =SUM(Apr!G7, May!G7, Jun!G7) -> 135010.68 | H7: =SUM(Apr!H7, May!H7, Jun!H7) -> 1977.32 | I7: =IFERROR(H7/G7, "") -> 0.014645656
A8: Kohls - Buffalo | B8: NY | C8: =SUM(Apr!C8, May!C8, Jun!C8) -> 118377 | D8: =SUM(Apr!D8, May!D8, Jun!D8) -> 0 | E8: =IF(AND(ISNUMBER(C8),ISNUMBER(D8)), C8-D8, "") -> 118377 | F8: =IFERROR(E8/D8, "") | G8: =SUM(Apr!G8, May!G8, Jun!G8) -> 147114.18 | H8: =SUM(Apr!H8, May!H8, Jun!H8) -> -28737.18 | I8: =IFERROR(H8/G8, "") -> -0.19533929
A9: Kohls - Canton | B9: CT | C9: =SUM(Apr!C9, May!C9, Jun!C9) -> 50060 | D9: =SUM(Apr!D9, May!D9, Jun!D9) -> 0 | E9: =IF(AND(ISNUMBER(C9),ISNUMBER(D9)), C9-D9, "") -> 50060 | F9: =IFERROR(E9/D9, "") | G9: =SUM(Apr!G9, May!G9, Jun!G9) -> 45736.67 | H9: =SUM(Apr!H9, May!H9, Jun!H9) -> 4323.33 | I9: =IFERROR(H9/G9, "") -> 0.094526558
A10: Kohls - East Amherst | B10: NY | C10: =SUM(Apr!C10, May!C10, Jun!C10) -> 121268 | D10: =SUM(Apr!D10, May!D10, Jun!D10) -> 0 | E10: =IF(AND(ISNUMBER(C10),ISNUMBER(D10)), C10-D10, "") -> 121268 | F10: =IFERROR(E10/D10, "") | G10: =SUM(Apr!G10, May!G10, Jun!G10) -> 131248.74 | H10: =SUM(Apr!H10, May!H10, Jun!H10) -> -9980.74 | I10: =IFERROR(H10/G10, "") -> -0.076044463
A11: Kohls - East Brunswick | B11: NJ | C11: =SUM(Apr!C11, May!C11, Jun!C11) -> 125982 | D11: =SUM(Apr!D11, May!D11, Jun!D11) -> 0 | E11: =IF(AND(ISNUMBER(C11),ISNUMBER(D11)), C11-D11, "") -> 125982 | F11: =IFERROR(E11/D11, "") | G11: =SUM(Apr!G11, May!G11, Jun!G11) -> 174470.12 | H11: =SUM(Apr!H11, May!H11, Jun!H11) -> -48488.12 | I11: =IFERROR(H11/G11, "") -> -0.27791647
A12: Kohls - Edgewood | B12: MD | C12: =SUM(Apr!C12, May!C12, Jun!C12) -> 747904 | D12: =SUM(Apr!D12, May!D12, Jun!D12) -> 0 | E12: =IF(AND(ISNUMBER(C12),ISNUMBER(D12)), C12-D12, "") -> 747904 | F12: =IFERROR(E12/D12, "") | G12: =SUM(Apr!G12, May!G12, Jun!G12) -> 923709.28 | H12: =SUM(Apr!H12, May!H12, Jun!H12) -> -175805.28 | I12: =IFERROR(H12/G12, "") -> -0.19032534
A13: Kohls - Granite Run | B13: PA | C13: =SUM(Apr!C13, May!C13, Jun!C13) -> 113938 | D13: =SUM(Apr!D13, May!D13, Jun!D13) -> 0 | E13: =IF(AND(ISNUMBER(C13),ISNUMBER(D13)), C13-D13, "") -> 113938 | F13: =IFERROR(E13/D13, "") | G13: =SUM(Apr!G13, May!G13, Jun!G13) -> 110743.92 | H13: =SUM(Apr!H13, May!H13, Jun!H13) -> 3194.08 | I13: =IFERROR(H13/G13, "") -> 0.028842035
A14: Kohls - Greece | B14: NY | C14: =SUM(Apr!C14, May!C14, Jun!C14) -> 106708 | D14: =SUM(Apr!D14, May!D14, Jun!D14) -> 0 | E14: =IF(AND(ISNUMBER(C14),ISNUMBER(D14)), C14-D14, "") -> 106708 | F14: =IFERROR(E14/D14, "") | G14: =SUM(Apr!G14, May!G14, Jun!G14) -> 142210.99 | H14: =SUM(Apr!H14, May!H14, Jun!H14) -> -35502.99 | I14: =IFERROR(H14/G14, "") -> -0.24965011
A15: Kohls - Hanover | B15: PA | C15: =SUM(Apr!C15, May!C15, Jun!C15) -> 88097 | D15: =SUM(Apr!D15, May!D15, Jun!D15) -> 0 | E15: =IF(AND(ISNUMBER(C15),ISNUMBER(D15)), C15-D15, "") -> 88097 | F15: =IFERROR(E15/D15, "") | G15: =SUM(Apr!G15, May!G15, Jun!G15) -> 125782.71 | H15: =SUM(Apr!H15, May!H15, Jun!H15) -> -37685.71 | I15: =IFERROR(H15/G15, "") -> -0.29960962
A16: Kohls - Horsehead | B16: NY | C16: =SUM(Apr!C16, May!C16, Jun!C16) -> 94689 | D16: =SUM(Apr!D16, May!D16, Jun!D16) -> 0 | E16: =IF(AND(ISNUMBER(C16),ISNUMBER(D16)), C16-D16, "") -> 94689 | F16: =IFERROR(E16/D16, "") | G16: =SUM(Apr!G16, May!G16, Jun!G16) -> 101605.92 | H16: =SUM(Apr!H16, May!H16, Jun!H16) -> -6916.92 | I16: =IFERROR(H16/G16, "") -> -0.068075955
... A68: Snowline SD - Vista Verde ES | B68: CA | C68: =SUM(Apr!C68, May!C68, Jun!C68) -> 0 | D68: =SUM(Apr!D68, May!D68, Jun!D68) -> 0 | E68: =IF(AND(ISNUMBER(C68),ISNUMBER(D68)), C68-D68, "") -> 0 | F68: =IFERROR(E68/D68, "") | G68: =SUM(Apr!G68, May!G68, Jun!G68) -> 0 | H68: =SUM(Apr!H68, May!H68, Jun!H68) -> 0 | I68: =IFERROR(H68/G68, "")

Sheet 3rd Qtr
A1: {=portfolio} -> Silicon Ranch | D1: 3rd Quarter Actual v. Expected | G1: 3rd Quarter Actual v. Forecasted
A2: Total | C2: =SUM(C4:C100) -> 4359658 | D2: =SUM(D4:D100) -> 0 | E2: =C2-D2 -> 4359658 | F2: =IFERROR(E2/D2, 0) -> 0 | G2: =SUM(G4:G100) -> 6169858.3 | H2: =C2-G2 -> -1810200.3 | I2: =IFERROR(H2/G2, 0) -> -0.29339415
A3: Site | B3: State | C3: Actual | D3: Expected | E3: Delta | F3: % | G3: Forecasted | H3: Delta | I3: %
A4: {=Sites[Site]} -> Iron Mountain - Windsor | B4: {=Sites[State]} -> CT | C4: =SUM(Jul!C4, Aug!C4, Sep!C4) -> 66916 | D4: =SUM(Jul!D4, Aug!D4, Sep!D4) -> 0 | E4: =IF(AND(ISNUMBER(C4),ISNUMBER(D4)), C4-D4, "") -> 66916 | F4: =IFERROR(E4/D4, "") | G4: =SUM(Jul!G4, Aug!G4, Sep!G4) -> 68600.29 | H4: =SUM(Jul!H4, Aug!H4, Sep!H4) -> -1684.29 | I4: =IFERROR(H4/G4, "") -> -0.024552229
A5: Kohls - Auburn | B5: NY | C5: =SUM(Jul!C5, Aug!C5, Sep!C5) -> 78878 | D5: =SUM(Jul!D5, Aug!D5, Sep!D5) -> 0 | E5: =IF(AND(ISNUMBER(C5),ISNUMBER(D5)), C5-D5, "") -> 78878 | F5: =IFERROR(E5/D5, "") | G5: =SUM(Jul!G5, Aug!G5, Sep!G5) -> 84723.96 | H5: =SUM(Jul!H5, Aug!H5, Sep!H5) -> -5845.96 | I5: =IFERROR(H5/G5, "") -> -0.06900008
A6: Kohls - Bensalem | B6: PA | C6: =SUM(Jul!C6, Aug!C6, Sep!C6) -> 82674 | D6: =SUM(Jul!D6, Aug!D6, Sep!D6) -> 0 | E6: =IF(AND(ISNUMBER(C6),ISNUMBER(D6)), C6-D6, "") -> 82674 | F6: =IFERROR(E6/D6, "") | G6: =SUM(Jul!G6, Aug!G6, Sep!G6) -> 78209.45 | H6: =SUM(Jul!H6, Aug!H6, Sep!H6) -> 4464.55 | I6: =IFERROR(H6/G6, "") -> 0.057084534
A7: Kohls - Brick | B7: NJ | C7: =SUM(Jul!C7, Aug!C7, Sep!C7) -> 98412 | D7: =SUM(Jul!D7, Aug!D7, Sep!D7) -> 0 | E7: =IF(AND(ISNUMBER(C7),ISNUMBER(D7)), C7-D7, "") -> 98412 | F7: =IFERROR(E7/D7, "") | G7: =SUM(Jul!G7, Aug!G7, Sep!G7) -> 91784.23 | H7: =SUM(Jul!H7, Aug!H7, Sep!H7) -> 6627.77 | I7: =IFERROR(H7/G7, "") -> 0.072210335
A8: Kohls - Buffalo | B8: NY | C8: =SUM(Jul!C8, Aug!C8, Sep!C8) -> 107383 | D8: =SUM(Jul!D8, Aug!D8, Sep!D8) -> 0 | E8: =IF(AND(ISNUMBER(C8),ISNUMBER(D8)), C8-D8, "") -> 107383 | F8: =IFERROR(E8/D8, "") | G8: =SUM(Jul!G8, Aug!G8, Sep!G8) -> 101633.2 | H8: =SUM(Jul!H8, Aug!H8, Sep!H8) -> 5749.8 | I8: =IFERROR(H8/G8, "") -> 0.056574033
A9: Kohls - Canton | B9: CT | C9: =SUM(Jul!C9, Aug!C9, Sep!C9) -> 32892 | D9: =SUM(Jul!D9, Aug!D9, Sep!D9) -> 0 | E9: =IF(AND(ISNUMBER(C9),ISNUMBER(D9)), C9-D9, "") -> 32892 | F9: =IFERROR(E9/D9, "") | G9: =SUM(Jul!G9, Aug!G9, Sep!G9) -> 31404.35 | H9: =SUM(Jul!H9, Aug!H9, Sep!H9) -> 1487.65 | I9: =IFERROR(H9/G9, "") -> 0.047370826
A10: Kohls - East Amherst | B10: NY | C10: =SUM(Jul!C10, Aug!C10, Sep!C10) -> 85776 | D10: =SUM(Jul!D10, Aug!D10, Sep!D10) -> 0 | E10: =IF(AND(ISNUMBER(C10),ISNUMBER(D10)), C10-D10, "") -> 85776 | F10: =IFERROR(E10/D10, "") | G10: =SUM(Jul!G10, Aug!G10, Sep!G10) -> 91258.13 | H10: =SUM(Jul!H10, Aug!H10, Sep!H10) -> -5482.13 | I10: =IFERROR(H10/G10, "") -> -0.060072785
A11: Kohls - East Brunswick | B11: NJ | C11: =SUM(Jul!C11, Aug!C11, Sep!C11) -> 111841 | D11: =SUM(Jul!D11, Aug!D11, Sep!D11) -> 0 | E11: =IF(AND(ISNUMBER(C11),ISNUMBER(D11)), C11-D11, "") -> 111841 | F11: =IFERROR(E11/D11, "") | G11: =SUM(Jul!G11, Aug!G11, Sep!G11) -> 116113.89 | H11: =SUM(Jul!H11, Aug!H11, Sep!H11) -> -4272.89 | I11: =IFERROR(H11/G11, "") -> -0.036799129
A12: Kohls - Edgewood | B12: MD | C12: =SUM(Jul!C12, Aug!C12, Sep!C12) -> 557855 | D12: =SUM(Jul!D12, Aug!D12, Sep!D12) -> 0 | E12: =IF(AND(ISNUMBER(C12),ISNUMBER(D12)), C12-D12, "") -> 557855 | F12: =IFERROR(E12/D12, "") | G12: =SUM(Jul!G12, Aug!G12, Sep!G12) -> 613027.82 | H12: =SUM(Jul!H12, Aug!H12, Sep!H12) -> -55172.82 | I12: =IFERROR(H12/G12, "") -> -0.090000516
A13: Kohls - Granite Run | B13: PA | C13: =SUM(Jul!C13, Aug!C13, Sep!C13) -> 78174 | D13: =SUM(Jul!D13, Aug!D13, Sep!D13) -> 0 | E13: =IF(AND(ISNUMBER(C13),ISNUMBER(D13)), C13-D13, "") -> 78174 | F13: =IFERROR(E13/D13, "") | G13: =SUM(Jul!G13, Aug!G13, Sep!G13) -> 77162 | H13: =SUM(Jul!H13, Aug!H13, Sep!H13) -> 1012 | I13: =IFERROR(H13/G13, "") -> 0.013115264
A14: Kohls - Greece | B14: NY | C14: =SUM(Jul!C14, Aug!C14, Sep!C14) -> 59739 | D14: =SUM(Jul!D14, Aug!D14, Sep!D14) -> 0 | E14: =IF(AND(ISNUMBER(C14),ISNUMBER(D14)), C14-D14, "") -> 59739 | F14: =IFERROR(E14/D14, "") | G14: =SUM(Jul!G14, Aug!G14, Sep!G14) -> 96059.09 | H14: =SUM(Jul!H14, Aug!H14, Sep!H14) -> -36320.09 | I14: =IFERROR(H14/G14, "") -> -0.37810154
A15: Kohls - Hanover | B15: PA | C15: =SUM(Jul!C15, Aug!C15, Sep!C15) -> 46549 | D15: =SUM(Jul!D15, Aug!D15, Sep!D15) -> 0 | E15: =IF(AND(ISNUMBER(C15),ISNUMBER(D15)), C15-D15, "") -> 46549 | F15: =IFERROR(E15/D15, "") | G15: =SUM(Jul!G15, Aug!G15, Sep!G15) -> 83749.97 | H15: =SUM(Jul!H15, Aug!H15, Sep!H15) -> -37200.97 | I15: =IFERROR(H15/G15, "") -> -0.44419085
A16: Kohls - Horsehead | B16: NY | C16: =SUM(Jul!C16, Aug!C16, Sep!C16) -> 65967 | D16: =SUM(Jul!D16, Aug!D16, Sep!D16) -> 0 | E16: =IF(AND(ISNUMBER(C16),ISNUMBER(D16)), C16-D16, "") -> 65967 | F16: =IFERROR(E16/D16, "") | G16: =SUM(Jul!G16, Aug!G16, Sep!G16) -> 70470.7 | H16: =SUM(Jul!H16, Aug!H16, Sep!H16) -> -4503.7 | I16: =IFERROR(H16/G16, "") -> -0.06390883
... A68: Snowline SD - Vista Verde ES | B68: CA | C68: =SUM(Jul!C68, Aug!C68, Sep!C68) -> 33695 | D68: =SUM(Jul!D68, Aug!D68, Sep!D68) -> 0 | E68: =IF(AND(ISNUMBER(C68),ISNUMBER(D68)), C68-D68, "") -> 33695 | F68: =IFERROR(E68/D68, "") | G68: =SUM(Jul!G68, Aug!G68, Sep!G68) -> 33905.04 | H68: =SUM(Jul!H68, Aug!H68, Sep!H68) -> -210.04 | I68: =IFERROR(H68/G68, "") -> -0.0061949492

Sheet 4th Qtr
A1: {=portfolio} -> Silicon Ranch | D1: 4th Quarter Actual v. Expected | G1: 4th Quarter Actual v. Forecasted
A2: Total | C2: =SUM(C4:C100) -> 0 | D2: =SUM(D4:D100) -> 0 | E2: =C2-D2 -> 0 | F2: =IFERROR(E2/D2, 0) -> 0 | G2: =SUM(G4:G100) -> 0 | H2: =C2-G2 -> 0 | I2: =IFERROR(H2/G2, 0) -> 0
A3: Site | B3: State | C3: Actual | D3: Expected | E3: Delta | F3: % | G3: Forecasted | H3: Delta | I3: %
A4: {=Sites[Site]} -> Iron Mountain - Windsor | B4: {=Sites[State]} -> CT | C4: =SUM(Oct!C4, Nov!C4, Dec!C4) -> 0 | D4: =SUM(Oct!D4, Nov!D4, Dec!D4) -> 0 | E4: =IF(AND(ISNUMBER(C4),ISNUMBER(D4)), C4-D4, "") -> 0 | F4: =IFERROR(E4/D4, "") | H4: =SUM(Oct!H4, Nov!H4, Dec!H4) -> 0 | I4: =IFERROR(H4/G4, "")
A5: Kohls - Auburn | B5: NY | C5: =SUM(Oct!C5, Nov!C5, Dec!C5) -> 0 | D5: =SUM(Oct!D5, Nov!D5, Dec!D5) -> 0 | E5: =IF(AND(ISNUMBER(C5),ISNUMBER(D5)), C5-D5, "") -> 0 | F5: =IFERROR(E5/D5, "") | H5: =SUM(Oct!H5, Nov!H5, Dec!H5) -> 0 | I5: =IFERROR(H5/G5, "")
A6: Kohls - Bensalem | B6: PA | C6: =SUM(Oct!C6, Nov!C6, Dec!C6) -> 0 | D6: =SUM(Oct!D6, Nov!D6, Dec!D6) -> 0 | E6: =IF(AND(ISNUMBER(C6),ISNUMBER(D6)), C6-D6, "") -> 0 | F6: =IFERROR(E6/D6, "") | H6: =SUM(Oct!H6, Nov!H6, Dec!H6) -> 0 | I6: =IFERROR(H6/G6, "")
A7: Kohls - Brick | B7: NJ | C7: =SUM(Oct!C7, Nov!C7, Dec!C7) -> 0 | D7: =SUM(Oct!D7, Nov!D7, Dec!D7) -> 0 | E7: =IF(AND(ISNUMBER(C7),ISNUMBER(D7)), C7-D7, "") -> 0 | F7: =IFERROR(E7/D7, "") | H7: =SUM(Oct!H7, Nov!H7, Dec!H7) -> 0 | I7: =IFERROR(H7/G7, "")
A8: Kohls - Buffalo | B8: NY | C8: =SUM(Oct!C8, Nov!C8, Dec!C8) -> 0 | D8: =SUM(Oct!D8, Nov!D8, Dec!D8) -> 0 | E8: =IF(AND(ISNUMBER(C8),ISNUMBER(D8)), C8-D8, "") -> 0 | F8: =IFERROR(E8/D8, "") | H8: =SUM(Oct!H8, Nov!H8, Dec!H8) -> 0 | I8: =IFERROR(H8/G8, "")
A9: Kohls - Canton | B9: CT | C9: =SUM(Oct!C9, Nov!C9, Dec!C9) -> 0 | D9: =SUM(Oct!D9, Nov!D9, Dec!D9) -> 0 | E9: =IF(AND(ISNUMBER(C9),ISNUMBER(D9)), C9-D9, "") -> 0 | F9: =IFERROR(E9/D9, "") | H9: =SUM(Oct!H9, Nov!H9, Dec!H9) -> 0 | I9: =IFERROR(H9/G9, "")
A10: Kohls - East Amherst | B10: NY | C10: =SUM(Oct!C10, Nov!C10, Dec!C10) -> 0 | D10: =SUM(Oct!D10, Nov!D10, Dec!D10) -> 0 | E10: =IF(AND(ISNUMBER(C10),ISNUMBER(D10)), C10-D10, "") -> 0 | F10: =IFERROR(E10/D10, "") | H10: =SUM(Oct!H10, Nov!H10, Dec!H10) -> 0 | I10: =IFERROR(H10/G10, "")
A11: Kohls - East Brunswick | B11: NJ | C11: =SUM(Oct!C11, Nov!C11, Dec!C11) -> 0 | D11: =SUM(Oct!D11, Nov!D11, Dec!D11) -> 0 | E11: =IF(AND(ISNUMBER(C11),ISNUMBER(D11)), C11-D11, "") -> 0 | F11: =IFERROR(E11/D11, "") | H11: =SUM(Oct!H11, Nov!H11, Dec!H11) -> 0 | I11: =IFERROR(H11/G11, "")
A12: Kohls - Edgewood | B12: MD | C12: =SUM(Oct!C12, Nov!C12, Dec!C12) -> 0 | D12: =SUM(Oct!D12, Nov!D12, Dec!D12) -> 0 | E12: =IF(AND(ISNUMBER(C12),ISNUMBER(D12)), C12-D12, "") -> 0 | F12: =IFERROR(E12/D12, "") | H12: =SUM(Oct!H12, Nov!H12, Dec!H12) -> 0 | I12: =IFERROR(H12/G12, "")
A13: Kohls - Granite Run | B13: PA | C13: =SUM(Oct!C13, Nov!C13, Dec!C13) -> 0 | D13: =SUM(Oct!D13, Nov!D13, Dec!D13) -> 0 | E13: =IF(AND(ISNUMBER(C13),ISNUMBER(D13)), C13-D13, "") -> 0 | F13: =IFERROR(E13/D13, "") | H13: =SUM(Oct!H13, Nov!H13, Dec!H13) -> 0 | I13: =IFERROR(H13/G13, "")
A14: Kohls - Greece | B14: NY | C14: =SUM(Oct!C14, Nov!C14, Dec!C14) -> 0 | D14: =SUM(Oct!D14, Nov!D14, Dec!D14) -> 0 | E14: =IF(AND(ISNUMBER(C14),ISNUMBER(D14)), C14-D14, "") -> 0 | F14: =IFERROR(E14/D14, "") | H14: =SUM(Oct!H14, Nov!H14, Dec!H14) -> 0 | I14: =IFERROR(H14/G14, "")
A15: Kohls - Hanover | B15: PA | C15: =SUM(Oct!C15, Nov!C15, Dec!C15) -> 0 | D15: =SUM(Oct!D15, Nov!D15, Dec!D15) -> 0 | E15: =IF(AND(ISNUMBER(C15),ISNUMBER(D15)), C15-D15, "") -> 0 | F15: =IFERROR(E15/D15, "") | H15: =SUM(Oct!H15, Nov!H15, Dec!H15) -> 0 | I15: =IFERROR(H15/G15, "")
A16: Kohls - Horsehead | B16: NY | C16: =SUM(Oct!C16, Nov!C16, Dec!C16) -> 0 | D16: =SUM(Oct!D16, Nov!D16, Dec!D16) -> 0 | E16: =IF(AND(ISNUMBER(C16),ISNUMBER(D16)), C16-D16, "") -> 0 | F16: =IFERROR(E16/D16, "") | H16: =SUM(Oct!H16, Nov!H16, Dec!H16) -> 0 | I16: =IFERROR(H16/G16, "")
... A68: Snowline SD - Vista Verde ES | B68: CA | C68: =SUM(Oct!C68, Nov!C68, Dec!C68) -> 0 | D68: =SUM(Oct!D68, Nov!D68, Dec!D68) -> 0 | E68: =IF(AND(ISNUMBER(C68),ISNUMBER(D68)), C68-D68, "") -> 0 | F68: =IFERROR(E68/D68, "") | H68: =SUM(Oct!H68, Nov!H68, Dec!H68) -> 0 | I68: =IFERROR(H68/G68, "")

Sheet Jan
A1: {=portfolio} -> Silicon Ranch | D1: January Actual v. Expected | G1: January Actual v. Forecasted
A2: Total | C2: =SUM(C4:C99) -> 205652.6 | D2: =SUM(D4:D99) -> 0 | E2: =C2-D2 -> 205652.6 | F2: =IFERROR(E2/D2, 0) -> 0 | G2: =SUM(G4:G99) -> 444598.28 | H2: =C2-G2 -> -238945.68 | I2: =IFERROR(H2/G2, 0) -> -0.53744176 | J2: =IF(AND(TODAY()>DATE(2024, 1, 1), COUNTA(Sites[Site])<>(COUNT(C:C)-1)), "Some sites are missing actual data; if new sites were added, make sure they are aligned correctly (including prior months!)", "") -> Some sites are missing actual data; if new sites were added, make sure they are aligned correctly (including prior months!)
A3: Site | B3: State | C3: Actual | D3: Expected | E3: Delta | F3: % | G3: Forecasted | H3: Delta | I3: % | J3: Notes | K3: Service Requests
A4: {=Sites[Site]} -> Iron Mountain - Windsor | B4: {=Sites[State]} -> CT | C4: 6324 | D4: 0 | E4: =IF(AND(ISNUMBER(C4),ISNUMBER(D4)), C4-D4, "") -> 6324 | F4: =IFERROR(E4/D4, "") | G4: 13022.34 | H4: =IF(AND(ISNUMBER(C4),ISNUMBER(G4)), C4-G4, "") -> -6698.34 | I4: =IFERROR(H4/G4, "") -> -0.51437299
A5: Kohls - Auburn | B5: NY | C5: 4362 | D5: 0 | E5: =IF(AND(ISNUMBER(C5),ISNUMBER(D5)), C5-D5, "") -> 4362 | F5: =IFERROR(E5/D5, "") | G5: 4782 | H5: =IF(AND(ISNUMBER(C5),ISNUMBER(G5)), C5-G5, "") -> -420 | I5: =IFERROR(H5/G5, "") -> -0.08782936 | J5: 1. Site tripped offline due to a utility outage at 10pm on 01/09 and came back online at 3pm on 01/10. | K5: 1. SR080112
A6: Kohls - Bensalem | B6: PA | C6: 9630 | D6: 0 | E6: =IF(AND(ISNUMBER(C6),ISNUMBER(D6)), C6-D6, "") -> 9630 | F6: =IFERROR(E6/D6, "") | G6: 15754.4 | H6: =IF(AND(ISNUMBER(C6),ISNUMBER(G6)), C6-G6, "") -> -6124.4 | I6: =IFERROR(H6/G6, "") -> -0.38874219
A7: Kohls - Brick | B7: NJ | C7: 11393 | D7: 0 | E7: =IF(AND(ISNUMBER(C7),ISNUMBER(D7)), C7-D7, "") -> 11393 | F7: =IFERROR(E7/D7, "") | G7: 16696.5 | H7: =IF(AND(ISNUMBER(C7),ISNUMBER(G7)), C7-G7, "") -> -5303.5 | I7: =IFERROR(H7/G7, "") -> -0.31764142
A8: Kohls - Buffalo | B8: NY | C8: 3961 | D8: 0 | E8: =IF(AND(ISNUMBER(C8),ISNUMBER(D8)), C8-D8, "") -> 3961 | F8: =IFERROR(E8/D8, "") | G8: 8044.58 | H8: =IF(AND(ISNUMBER(C8),ISNUMBER(G8)), C8-G8, "") -> -4083.58 | I8: =IFERROR(H8/G8, "") -> -0.50761879
A9: Kohls - Canton | B9: CT | C9: 2979 | D9: 0 | E9: =IF(AND(ISNUMBER(C9),ISNUMBER(D9)), C9-D9, "") -> 2979 | F9: =IFERROR(E9/D9, "") | G9: 5837.36 | H9: =IF(AND(ISNUMBER(C9),ISNUMBER(G9)), C9-G9, "") -> -2858.36 | I9: =IFERROR(H9/G9, "") -> -0.48966656
A10: Kohls - East Amherst | B10: NY | C10: 2767 | D10: 0 | E10: =IF(AND(ISNUMBER(C10),ISNUMBER(D10)), C10-D10, "") -> 2767 | F10: =IFERROR(E10/D10, "") | G10: 8482.7 | H10: =IF(AND(ISNUMBER(C10),ISNUMBER(G10)), C10-G10, "") -> -5715.7 | I10: =IFERROR(H10/G10, "") -> -0.67380669
A11: Kohls - East Brunswick | B11: NJ | C11: 973 | D11: 0 | E11: =IF(AND(ISNUMBER(C11),ISNUMBER(D11)), C11-D11, "") -> 973 | F11: =IFERROR(E11/D11, "") | G11: 23294.45 | H11: =IF(AND(ISNUMBER(C11),ISNUMBER(G11)), C11-G11, "") -> -22321.45 | I11: =IFERROR(H11/G11, "") -> -0.95823039
A12: Kohls - Edgewood | B12: MD | C12: 71866 | D12: 0 | E12: =IF(AND(ISNUMBER(C12),ISNUMBER(D12)), C12-D12, "") -> 71866 | F12: =IFERROR(E12/D12, "") | G12: 136238.63 | H12: =IF(AND(ISNUMBER(C12),ISNUMBER(G12)), C12-G12, "") -> -64372.63 | I12: =IFERROR(H12/G12, "") -> -0.4724991 | J12: 1. Inverter 3 is offline from 01/01 to 01/03 | K12: 1. SR079771
A13: Kohls - Granite Run | B13: PA | C13: 9421 | D13: 0 | E13: =IF(AND(ISNUMBER(C13),ISNUMBER(D13)), C13-D13, "") -> 9421 | F13: =IFERROR(E13/D13, "") | G13: 16020.95 | H13: =IF(AND(ISNUMBER(C13),ISNUMBER(G13)), C13-G13, "") -> -6599.95 | I13: =IFERROR(H13/G13, "") -> -0.41195747
A14: Kohls - Greece | B14: NY | C14: 0 | D14: 0 | E14: =IF(AND(ISNUMBER(C14),ISNUMBER(D14)), C14-D14, "") -> 0 | F14: =IFERROR(E14/D14, "") | G14: 9424.18 | H14: =IF(AND(ISNUMBER(C14),ISNUMBER(G14)), C14-G14, "") -> -9424.18 | I14: =IFERROR(H14/G14, "") -> -1 | J14: 1. Site offline for module replacement work | K14: 1. SR078556
A15: Kohls - Hanover | B15: PA | C15: 11065 | D15: 0 | E15: =IF(AND(ISNUMBER(C15),ISNUMBER(D15)), C15-D15, "") -> 11065 | F15: =IFERROR(E15/D15, "") | G15: 18878.62 | H15: =IF(AND(ISNUMBER(C15),ISNUMBER(G15)), C15-G15, "") -> -7813.62 | I15: =IFERROR(H15/G15, "") -> -0.41388724
A16: Kohls - Horsehead | B16: NY | C16: 2351 | D16: 0 | E16: =IF(AND(ISNUMBER(C16),ISNUMBER(D16)), C16-D16, "") -> 2351 | F16: =IFERROR(E16/D16, "") | G16: 12770.65 | H16: =IF(AND(ISNUMBER(C16),ISNUMBER(G16)), C16-G16, "") -> -10419.65 | I16: =IFERROR(H16/G16, "") -> -0.815906 | J16: 1. Inverter is offline from 01/07 to 01/26 | K16: 1. SR080006
A17: Kohls - Hudson | B17: NY | C17: 197 | D17: 0 | E17: =IF(AND(ISNUMBER(C17),ISNUMBER(D17)), C17-D17, "") -> 197 | F17: =IFERROR(E17/D17, "") | G17: 12854.55 | H17: =IF(AND(ISNUMBER(C17),ISNUMBER(G17)), C17-G17, "") -> -12657.55 | I17: =IFERROR(H17/G17, "") -> -0.98467469 | J17: 1. Inverter is offline from 12/17 to 01/19. | K17: 1. SR079528
A18: Kohls - Ithaca | B18: NY | C18: 4385 | D18: 0 | E18: =IF(AND(ISNUMBER(C18),ISNUMBER(D18)), C18-D18, "") -> 4385 | F18: =IFERROR(E18/D18, "") | G18: 11913.06 | H18: =IF(AND(ISNUMBER(C18),ISNUMBER(G18)), C18-G18, "") -> -7528.06 | I18: =IFERROR(H18/G18, "") -> -0.63191657
A19: Kohls - Kingston | B19: NY | C19: 9244 | D19: 0 | E19: =IF(AND(ISNUMBER(C19),ISNUMBER(D19)), C19-D19, "") -> 9244 | F19: =IFERROR(E19/D19, "") | G19: 22381.27 | H19: =IF(AND(ISNUMBER(C19),ISNUMBER(G19)), C19-G19, "") -> -13137.27 | I19: =IFERROR(H19/G19, "") -> -0.58697607
A20: Kohls - Mechanicsburg | B20: PA | C20: 11788 | D20: 0 | E20: =IF(AND(ISNUMBER(C20),ISNUMBER(D20)), C20-D20, "") -> 11788 | F20: =IFERROR(E20/D20, "") | G20: 21618.64 | H20: =IF(AND(ISNUMBER(C20),ISNUMBER(G20)), C20-G20, "") -> -9830.64 | I20: =IFERROR(H20/G20, "") -> -0.45472981
A21: Kohls - Middletown | B21: NJ | C21: 15292 | D21: 0 | E21: =IF(AND(ISNUMBER(C21),ISNUMBER(D21)), C21-D21, "") -> 15292 | F21: =IFERROR(E21/D21, "") | G21: 29635.82 | H21: =IF(AND(ISNUMBER(C21),ISNUMBER(G21)), C21-G21, "") -> -14343.82 | I21: =IFERROR(H21/G21, "") -> -0.4840028 | J21: 1. Inverter 1 multiple times tripped offline | K21: 1. SR079062
A22: Kohls - North Amherst | B22: NY | C22: 2846 | D22: 0 | E22: =IF(AND(ISNUMBER(C22),ISNUMBER(D22)), C22-D22, "") -> 2846 | F22: =IFERROR(E22/D22, "") | G22: 6525.15 | H22: =IF(AND(ISNUMBER(C22),ISNUMBER(G22)), C22-G22, "") -> -3679.15 | I22: =IFERROR(H22/G22, "") -> -0.56384144
A23: Kohls - Staten Island | B23: NY | C23: 8661.6 | D23: 0 | E23: =IF(AND(ISNUMBER(C23),ISNUMBER(D23)), C23-D23, "") -> 8661.6 | F23: =IFERROR(E23/D23, "") | G23: 15476.69 | H23: =IF(AND(ISNUMBER(C23),ISNUMBER(G23)), C23-G23, "") -> -6815.09 | I23: =IFERROR(H23/G23, "") -> -0.44034545
A24: Kohls - Warminster | B24: PA | C24: 7770 | D24: 0 | E24: =IF(AND(ISNUMBER(C24),ISNUMBER(D24)), C24-D24, "") -> 7770 | F24: =IFERROR(E24/D24, "") | G24: 19541.34 | H24: =IF(AND(ISNUMBER(C24),ISNUMBER(G24)), C24-G24, "") -> -11771.34 | I24: =IFERROR(H24/G24, "") -> -0.60238141 | J24: 1. Inverter is frequentley offline & reporting "AC current Imbalance". | K24: 1. SR078291
A25: Kohls - Waterbury | B25: CT | C25: 8377 | D25: 0 | E25: =IF(AND(ISNUMBER(C25),ISNUMBER(D25)), C25-D25, "") -> 8377 | F25: =IFERROR(E25/D25, "") | G25: 15404.4 | H25: =IF(AND(ISNUMBER(C25),ISNUMBER(G25)), C25-G25, "") -> -7027.4 | I25: =IFERROR(H25/G25, "") -> -0.45619433
A26: Mojave Water Agency - Headquarters | B26: CA | E26: =IF(AND(ISNUMBER(C26),ISNUMBER(D26)), C26-D26, "") | F26: =IFERROR(E26/D26, "") | H26: =IF(AND(ISNUMBER(C26),ISNUMBER(G26)), C26-G26, "") | I26: =IFERROR(H26/G26, "")
A27: CSU - Bakersfield | B27: CA | E27: =IF(AND(ISNUMBER(C27),ISNUMBER(D27)), C27-D27, "") | F27: =IFERROR(E27/D27, "") | H27: =IF(AND(ISNUMBER(C27),ISNUMBER(G27)), C27-G27, "") | I27: =IFERROR(H27/G27, "")
A28: Greenfield USD - Fairfield ES | B28: CA | E28: =IF(AND(ISNUMBER(C28),ISNUMBER(D28)), C28-D28, "") | F28: =IFERROR(E28/D28, "") | H28: =IF(AND(ISNUMBER(C28),ISNUMBER(G28)), C28-G28, "") | I28: =IFERROR(H28/G28, "")
A29: Greenfield USD - Granite Point ES | B29: CA | E29: =IF(AND(ISNUMBER(C29),ISNUMBER(D29)), C29-D29, "") | F29: =IFERROR(E29/D29, "") | H29: =IF(AND(ISNUMBER(C29),ISNUMBER(G29)), C29-G29, "") | I29: =IFERROR(H29/G29, "")
A30: Greenfield USD - Greenfield MS | B30: CA | E30: =IF(AND(ISNUMBER(C30),ISNUMBER(D30)), C30-D30, "") | F30: =IFERROR(E30/D30, "") | H30: =IF(AND(ISNUMBER(C30),ISNUMBER(G30)), C30-G30, "") | I30: =IFERROR(H30/G30, "")
A31: Greenfield USD - Horizon ES | B31: CA | E31: =IF(AND(ISNUMBER(C31),ISNUMBER(D31)), C31-D31, "") | F31: =IFERROR(E31/D31, "") | H31: =IF(AND(ISNUMBER(C31),ISNUMBER(G31)), C31-G31, "") | I31: =IFERROR(H31/G31, "")
A32: Greenfield USD - McKee MS | B32: CA | E32: =IF(AND(ISNUMBER(C32),ISNUMBER(D32)), C32-D32, "") | F32: =IFERROR(E32/D32, "") | H32: =IF(AND(ISNUMBER(C32),ISNUMBER(G32)), C32-G32, "") | I32: =IFERROR(H32/G32, "")
A33: Greenfield USD - Plantation ES | B33: CA | E33: =IF(AND(ISNUMBER(C33),ISNUMBER(D33)), C33-D33, "") | F33: =IFERROR(E33/D33, "") | H33: =IF(AND(ISNUMBER(C33),ISNUMBER(G33)), C33-G33, "") | I33: =IFERROR(H33/G33, "")
A34: Greenfield USD - Planz ES | B34: CA | E34: =IF(AND(ISNUMBER(C34),ISNUMBER(D34)), C34-D34, "") | F34: =IFERROR(E34/D34, "") | H34: =IF(AND(ISNUMBER(C34),ISNUMBER(G34)), C34-G34, "") | I34: =IFERROR(H34/G34, "")
A35: Greenfield USD - Raffaello Palla ES | B35: CA | E35: =IF(AND(ISNUMBER(C35),ISNUMBER(D35)), C35-D35, "") | F35: =IFERROR(E35/D35, "") | H35: =IF(AND(ISNUMBER(C35),ISNUMBER(G35)), C35-G35, "") | I35: =IFERROR(H35/G35, "")
A36: Greenfield USD - Valle Verde ES | B36: CA | E36: =IF(AND(ISNUMBER(C36),ISNUMBER(D36)), C36-D36, "") | F36: =IFERROR(E36/D36, "") | H36: =IF(AND(ISNUMBER(C36),ISNUMBER(G36)), C36-G36, "") | I36: =IFERROR(H36/G36, "")
A37: Greenfield USD - W.A. Kendrick ES | B37: CA | E37: =IF(AND(ISNUMBER(C37),ISNUMBER(D37)), C37-D37, "") | F37: =IFERROR(E37/D37, "") | H37: =IF(AND(ISNUMBER(C37),ISNUMBER(G37)), C37-G37, "") | I37: =IFERROR(H37/G37, "")
... A68: Snowline SD - Vista Verde ES | B68: CA | E68: =IF(AND(ISNUMBER(C68),ISNUMBER(D68)), C68-D68, "") | F68: =IFERROR(E68/D68, "") | H68: =IF(AND(ISNUMBER(C68),ISNUMBER(G68)), C68-G68, "") | I68: =IFERROR(H68/G68, "")

Sheet Feb
A1: {=portfolio} -> Silicon Ranch | D1: February Actual v. Expected | G1: February Actual v. Forecasted
A2: Total | C2: =SUM(C4:C100) -> 603167.75 | D2: =SUM(D4:D100) -> 0 | E2: =C2-D2 -> 603167.75 | F2: =IFERROR(E2/D2, 0) -> 0 | G2: =SUM(G4:G100) -> 584890.32 | H2: =C2-G2 -> 18277.43 | I2: =IFERROR(H2/G2, 0) -> 0.031249329 | J2: =IF(AND(TODAY()>DATE(2024, 2, 1), COUNTA(Sites[Site])<>(COUNT(C:C)-1)), "Some sites are missing actual data; if new sites were added, make sure they are aligned correctly (including prior months!)", "") -> Some sites are missing actual data; if new sites were added, make sure they are aligned correctly (including prior months!)
A3: Site | B3: State | C3: Actual | D3: Expected | E3: Delta | F3: % | G3: Forecasted | H3: Delta | I3: % | J3: Notes | K3: Service Requests
A4: {=Sites[Site]} -> Iron Mountain - Windsor | B4: {=Sites[State]} -> CT | C4: 16946.75 | D4: 0 | E4: =IF(AND(ISNUMBER(C4),ISNUMBER(D4)), C4-D4, "") -> 16946.75 | F4: =IFERROR(E4/D4, "") | G4: 19218 | H4: =IF(AND(ISNUMBER(C4),ISNUMBER(G4)), C4-G4, "") -> -2271.25 | I4: =IFERROR(H4/G4, "") -> -0.11818347
A5: Kohls - Auburn | B5: NY | C5: 17104 | D5: 0 | E5: =IF(AND(ISNUMBER(C5),ISNUMBER(D5)), C5-D5, "") -> 17104 | F5: =IFERROR(E5/D5, "") | G5: 10813.11 | H5: =IF(AND(ISNUMBER(C5),ISNUMBER(G5)), C5-G5, "") -> 6290.89 | I5: =IFERROR(H5/G5, "") -> 0.58178359
A6: Kohls - Bensalem | B6: PA | C6: 24318 | D6: 0 | E6: =IF(AND(ISNUMBER(C6),ISNUMBER(D6)), C6-D6, "") -> 24318 | F6: =IFERROR(E6/D6, "") | G6: 20009.19 | H6: =IF(AND(ISNUMBER(C6),ISNUMBER(G6)), C6-G6, "") -> 4308.81 | I6: =IFERROR(H6/G6, "") -> 0.21534155
A7: Kohls - Brick | B7: NJ | C7: 26352 | D7: 0 | E7: =IF(AND(ISNUMBER(C7),ISNUMBER(D7)), C7-D7, "") -> 26352 | F7: =IFERROR(E7/D7, "") | G7: 22735.46 | H7: =IF(AND(ISNUMBER(C7),ISNUMBER(G7)), C7-G7, "") -> 3616.54 | I7: =IFERROR(H7/G7, "") -> 0.15907046
A8: Kohls - Buffalo | B8: NY | C8: 21121 | D8: 0 | E8: =IF(AND(ISNUMBER(C8),ISNUMBER(D8)), C8-D8, "") -> 21121 | F8: =IFERROR(E8/D8, "") | G8: 15492.57 | H8: =IF(AND(ISNUMBER(C8),ISNUMBER(G8)), C8-G8, "") -> 5628.43 | I8: =IFERROR(H8/G8, "") -> 0.36329867 | J8: 1. Inverter 7 offline due to "Grid Contactor Open from 02/19 to 02/29 | K8: 1. SR081105
A9: Kohls - Canton | B9: CT | C9: 8146 | D9: 0 | E9: =IF(AND(ISNUMBER(C9),ISNUMBER(D9)), C9-D9, "") -> 8146 | F9: =IFERROR(E9/D9, "") | G9: 7037.82 | H9: =IF(AND(ISNUMBER(C9),ISNUMBER(G9)), C9-G9, "") -> 1108.18 | I9: =IFERROR(H9/G9, "") -> 0.15746069
A10: Kohls - East Amherst | B10: NY | C10: 20665 | D10: 0 | E10: =IF(AND(ISNUMBER(C10),ISNUMBER(D10)), C10-D10, "") -> 20665 | F10: =IFERROR(E10/D10, "") | G10: 14355.33 | H10: =IF(AND(ISNUMBER(C10),ISNUMBER(G10)), C10-G10, "") -> 6309.67 | I10: =IFERROR(H10/G10, "") -> 0.439535
A11: Kohls - East Brunswick | B11: NJ | C11: 31269 | D11: 0 | E11: =IF(AND(ISNUMBER(C11),ISNUMBER(D11)), C11-D11, "") -> 31269 | F11: =IFERROR(E11/D11, "") | G11: 30992.07 | H11: =IF(AND(ISNUMBER(C11),ISNUMBER(G11)), C11-G11, "") -> 276.93 | I11: =IFERROR(H11/G11, "") -> 0.0089355116
A12: Kohls - Edgewood | B12: MD | C12: 184974 | D12: 0 | E12: =IF(AND(ISNUMBER(C12),ISNUMBER(D12)), C12-D12, "") -> 184974 | F12: =IFERROR(E12/D12, "") | G12: 169384.2 | H12: =IF(AND(ISNUMBER(C12),ISNUMBER(G12)), C12-G12, "") -> 15589.8 | I12: =IFERROR(H12/G12, "") -> 0.0920381
A13: Kohls - Granite Run | B13: PA | C13: 22487 | D13: 0 | E13: =IF(AND(ISNUMBER(C13),ISNUMBER(D13)), C13-D13, "") -> 22487 | F13: =IFERROR(E13/D13, "") | G13: 20204.97 | H13: =IF(AND(ISNUMBER(C13),ISNUMBER(G13)), C13-G13, "") -> 2282.03 | I13: =IFERROR(H13/G13, "") -> 0.11294399
A14: Kohls - Greece | B14: NY | C14: 16874 | D14: 0 | E14: =IF(AND(ISNUMBER(C14),ISNUMBER(D14)), C14-D14, "") -> 16874 | F14: =IFERROR(E14/D14, "") | G14: 14942.59 | H14: =IF(AND(ISNUMBER(C14),ISNUMBER(G14)), C14-G14, "") -> 1931.41 | I14: =IFERROR(H14/G14, "") -> 0.12925537
A15: Kohls - Hanover | B15: PA | C15: 26512 | D15: 0 | E15: =IF(AND(ISNUMBER(C15),ISNUMBER(D15)), C15-D15, "") -> 26512 | F15: =IFERROR(E15/D15, "") | G15: 22444.04 | H15: =IF(AND(ISNUMBER(C15),ISNUMBER(G15)), C15-G15, "") -> 4067.96 | I15: =IFERROR(H15/G15, "") -> 0.18124901
A16: Kohls - Horsehead | B16: NY | C16: 18647 | D16: 0 | E16: =IF(AND(ISNUMBER(C16),ISNUMBER(D16)), C16-D16, "") -> 18647 | F16: =IFERROR(E16/D16, "") | G16: 16126.44 | H16: =IF(AND(ISNUMBER(C16),ISNUMBER(G16)), C16-G16, "") -> 2520.56 | I16: =IFERROR(H16/G16, "") -> 0.15629984
A17: Kohls - Hudson | B17: NY | C17: 6932 | D17: 0 | E17: =IF(AND(ISNUMBER(C17),ISNUMBER(D17)), C17-D17, "") -> 6932 | F17: =IFERROR(E17/D17, "") | G17: 18708.54 | H17: =IF(AND(ISNUMBER(C17),ISNUMBER(G17)), C17-G17, "") -> -11776.54 | I17: =IFERROR(H17/G17, "") -> -0.62947403
A18: Kohls - Ithaca | B18: NY | C18: 16819 | D18: 0 | E18: =IF(AND(ISNUMBER(C18),ISNUMBER(D18)), C18-D18, "") -> 16819 | F18: =IFERROR(E18/D18, "") | G18: 17888.23 | H18: =IF(AND(ISNUMBER(C18),ISNUMBER(G18)), C18-G18, "") -> -1069.23 | I18: =IFERROR(H18/G18, "") -> -0.059772823
A19: Kohls - Kingston | B19: NY | C19: 35496 | D19: 0 | E19: =IF(AND(ISNUMBER(C19),ISNUMBER(D19)), C19-D19, "") -> 35496 | F19: =IFERROR(E19/D19, "") | G19: 24776.93 | H19: =IF(AND(ISNUMBER(C19),ISNUMBER(G19)), C19-G19, "") -> 10719.07 | I19: =IFERROR(H19/G19, "") -> 0.43262301
A20: Kohls - Mechanicsburg | B20: PA | C20: 30051 | D20: 0 | E20: =IF(AND(ISNUMBER(C20),ISNUMBER(D20)), C20-D20, "") -> 30051 | F20: =IFERROR(E20/D20, "") | G20: 25384.43 | H20: =IF(AND(ISNUMBER(C20),ISNUMBER(G20)), C20-G20, "") -> 4666.57 | I20: =IFERROR(H20/G20, "") -> 0.18383592
A21: Kohls - Middletown | B21: NJ | C21: 15419 | D21: 0 | E21: =IF(AND(ISNUMBER(C21),ISNUMBER(D21)), C21-D21, "") -> 15419 | F21: =IFERROR(E21/D21, "") | G21: 36407.89 | H21: =IF(AND(ISNUMBER(C21),ISNUMBER(G21)), C21-G21, "") -> -20988.89 | I21: =IFERROR(H21/G21, "") -> -0.5764929 | J21: 1. Inverter tripping offline and reporting "Coolant temperature" for multiple days | K21: 1. SR080696
A22: Kohls - North Amherst | B22: NY | C22: 15228 | D22: 0 | E22: =IF(AND(ISNUMBER(C22),ISNUMBER(D22)), C22-D22, "") -> 15228 | F22: =IFERROR(E22/D22, "") | G22: 12491 | H22: =IF(AND(ISNUMBER(C22),ISNUMBER(G22)), C22-G22, "") -> 2737 | I22: =IFERROR(H22/G22, "") -> 0.21911776
A23: Kohls - Staten Island | B23: NY | C23: 19596 | D23: 0 | E23: =IF(AND(ISNUMBER(C23),ISNUMBER(D23)), C23-D23, "") -> 19596 | F23: =IFERROR(E23/D23, "") | G23: 21345.24 | H23: =IF(AND(ISNUMBER(C23),ISNUMBER(G23)), C23-G23, "") -> -1749.24 | I23: =IFERROR(H23/G23, "") -> -0.081949887
A24: Kohls - Warminster | B24: PA | C24: 8422 | D24: 0 | E24: =IF(AND(ISNUMBER(C24),ISNUMBER(D24)), C24-D24, "") -> 8422 | F24: =IFERROR(E24/D24, "") | G24: 24631.64 | H24: =IF(AND(ISNUMBER(C24),ISNUMBER(G24)), C24-G24, "") -> -16209.64 | I24: =IFERROR(H24/G24, "") -> -0.65808204
A25: Kohls - Waterbury | B25: CT | C25: 19789 | D25: 0 | E25: =IF(AND(ISNUMBER(C25),ISNUMBER(D25)), C25-D25, "") -> 19789 | F25: =IFERROR(E25/D25, "") | G25: 19500.63 | H25: =IF(AND(ISNUMBER(C25),ISNUMBER(G25)), C25-G25, "") -> 288.37 | I25: =IFERROR(H25/G25, "") -> 0.014787727
A26: Mojave Water Agency - Headquarters | B26: CA | E26: =IF(AND(ISNUMBER(C26),ISNUMBER(D26)), C26-D26, "") | F26: =IFERROR(E26/D26, "") | H26: =IF(AND(ISNUMBER(C26),ISNUMBER(G26)), C26-G26, "") | I26: =IFERROR(H26/G26, "")
A27: CSU - Bakersfield | B27: CA | E27: =IF(AND(ISNUMBER(C27),ISNUMBER(D27)), C27-D27, "") | F27: =IFERROR(E27/D27, "") | H27: =IF(AND(ISNUMBER(C27),ISNUMBER(G27)), C27-G27, "") | I27: =IFERROR(H27/G27, "")
A28: Greenfield USD - Fairfield ES | B28: CA | E28: =IF(AND(ISNUMBER(C28),ISNUMBER(D28)), C28-D28, "") | F28: =IFERROR(E28/D28, "") | H28: =IF(AND(ISNUMBER(C28),ISNUMBER(G28)), C28-G28, "") | I28: =IFERROR(H28/G28, "")
A29: Greenfield USD - Granite Point ES | B29: CA | E29: =IF(AND(ISNUMBER(C29),ISNUMBER(D29)), C29-D29, "") | F29: =IFERROR(E29/D29, "") | H29: =IF(AND(ISNUMBER(C29),ISNUMBER(G29)), C29-G29, "") | I29: =IFERROR(H29/G29, "")
A30: Greenfield USD - Greenfield MS | B30: CA | E30: =IF(AND(ISNUMBER(C30),ISNUMBER(D30)), C30-D30, "") | F30: =IFERROR(E30/D30, "") | H30: =IF(AND(ISNUMBER(C30),ISNUMBER(G30)), C30-G30, "") | I30: =IFERROR(H30/G30, "")
A31: Greenfield USD - Horizon ES | B31: CA | E31: =IF(AND(ISNUMBER(C31),ISNUMBER(D31)), C31-D31, "") | F31: =IFERROR(E31/D31, "") | H31: =IF(AND(ISNUMBER(C31),ISNUMBER(G31)), C31-G31, "") | I31: =IFERROR(H31/G31, "")
A32: Greenfield USD - McKee MS | B32: CA | E32: =IF(AND(ISNUMBER(C32),ISNUMBER(D32)), C32-D32, "") | F32: =IFERROR(E32/D32, "") | H32: =IF(AND(ISNUMBER(C32),ISNUMBER(G32)), C32-G32, "") | I32: =IFERROR(H32/G32, "")
A33: Greenfield USD - Plantation ES | B33: CA | E33: =IF(AND(ISNUMBER(C33),ISNUMBER(D33)), C33-D33, "") | F33: =IFERROR(E33/D33, "") | H33: =IF(AND(ISNUMBER(C33),ISNUMBER(G33)), C33-G33, "") | I33: =IFERROR(H33/G33, "")
A34: Greenfield USD - Planz ES | B34: CA | E34: =IF(AND(ISNUMBER(C34),ISNUMBER(D34)), C34-D34, "") | F34: =IFERROR(E34/D34, "") | H34: =IF(AND(ISNUMBER(C34),ISNUMBER(G34)), C34-G34, "") | I34: =IFERROR(H34/G34, "")
A35: Greenfield USD - Raffaello Palla ES | B35: CA | E35: =IF(AND(ISNUMBER(C35),ISNUMBER(D35)), C35-D35, "") | F35: =IFERROR(E35/D35, "") | H35: =IF(AND(ISNUMBER(C35),ISNUMBER(G35)), C35-G35, "") | I35: =IFERROR(H35/G35, "")
A36: Greenfield USD - Valle Verde ES | B36: CA | E36: =IF(AND(ISNUMBER(C36),ISNUMBER(D36)), C36-D36, "") | F36: =IFERROR(E36/D36, "") | H36: =IF(AND(ISNUMBER(C36),ISNUMBER(G36)), C36-G36, "") | I36: =IFERROR(H36/G36, "")
A37: Greenfield USD - W.A. Kendrick ES | B37: CA | E37: =IF(AND(ISNUMBER(C37),ISNUMBER(D37)), C37-D37, "") | F37: =IFERROR(E37/D37, "") | H37: =IF(AND(ISNUMBER(C37),ISNUMBER(G37)), C37-G37, "") | I37: =IFERROR(H37/G37, "")
... A68: Snowline SD - Vista Verde ES | B68: CA | E68: =IF(AND(ISNUMBER(C68),ISNUMBER(D68)), C68-D68, "") | F68: =IFERROR(E68/D68, "") | H68: =IF(AND(ISNUMBER(C68),ISNUMBER(G68)), C68-G68, "") | I68: =IFERROR(H68/G68, "")

Sheet Mar
A1: {=portfolio} -> Silicon Ranch | D1: March Actual v. Expected | G1: March Actual v. Forecasted
A2: Total | C2: =SUM(C4:C100) -> 802214 | D2: =SUM(D4:D100) -> 0 | E2: =C2-D2 -> 802214 | F2: =IFERROR(E2/D2, 0) -> 0 | G2: =SUM(G4:G100) -> 897139.91 | H2: =C2-G2 -> -94925.909 | I2: =IFERROR(H2/G2, 0) -> -0.10580948 | J2: =IF(AND(TODAY()>DATE(2024, 3, 1), COUNTA(Sites[Site])<>(COUNT(C:C)-1)), "Some sites are missing actual data; if new sites were added, make sure they are aligned correctly (including prior months!)", "") -> Some sites are missing actual data; if new sites were added, make sure they are aligned correctly (including prior months!)
A3: Site | B3: State | C3: Actual | D3: Expected | E3: Delta | F3: % | G3: Forecasted | H3: Delta | I3: % | J3: Notes | K3: Service Requests
A4: {=Sites[Site]} -> Iron Mountain - Windsor | B4: {=Sites[State]} -> CT | C4: 26650 | D4: 0 | E4: =IF(AND(ISNUMBER(C4),ISNUMBER(D4)), C4-D4, "") -> 26650 | F4: =IFERROR(E4/D4, "") | G4: 25065.9 | H4: =IF(AND(ISNUMBER(C4),ISNUMBER(G4)), C4-G4, "") -> 1584.1 | I4: =IFERROR(H4/G4, "") -> 0.063197412
A5: Kohls - Auburn | B5: NY | C5: 23334 | D5: 0 | E5: =IF(AND(ISNUMBER(C5),ISNUMBER(D5)), C5-D5, "") -> 23334 | F5: =IFERROR(E5/D5, "") | G5: 23816.8 | H5: =IF(AND(ISNUMBER(C5),ISNUMBER(G5)), C5-G5, "") -> -482.8 | I5: =IFERROR(H5/G5, "") -> -0.020271405
A6: Kohls - Bensalem | B6: PA | C6: 32980 | D6: 0 | E6: =IF(AND(ISNUMBER(C6),ISNUMBER(D6)), C6-D6, "") -> 32980 | F6: =IFERROR(E6/D6, "") | G6: 29898.43 | H6: =IF(AND(ISNUMBER(C6),ISNUMBER(G6)), C6-G6, "") -> 3081.57 | I6: =IFERROR(H6/G6, "") -> 0.10306795
A7: Kohls - Brick | B7: NJ | C7: 36345 | D7: 0 | E7: =IF(AND(ISNUMBER(C7),ISNUMBER(D7)), C7-D7, "") -> 36345 | F7: =IFERROR(E7/D7, "") | G7: 35848.9 | H7: =IF(AND(ISNUMBER(C7),ISNUMBER(G7)), C7-G7, "") -> 496.1 | I7: =IFERROR(H7/G7, "") -> 0.013838639
A8: Kohls - Buffalo | B8: NY | C8: 28827 | D8: 0 | E8: =IF(AND(ISNUMBER(C8),ISNUMBER(D8)), C8-D8, "") -> 28827 | F8: =IFERROR(E8/D8, "") | G8: 31190.22 | H8: =IF(AND(ISNUMBER(C8),ISNUMBER(G8)), C8-G8, "") -> -2363.22 | I8: =IFERROR(H8/G8, "") -> -0.075767981
A9: Kohls - Canton | B9: CT | C9: 13440 | D9: 0 | E9: =IF(AND(ISNUMBER(C9),ISNUMBER(D9)), C9-D9, "") -> 13440 | F9: =IFERROR(E9/D9, "") | G9: 11179.87 | H9: =IF(AND(ISNUMBER(C9),ISNUMBER(G9)), C9-G9, "") -> 2260.13 | I9: =IFERROR(H9/G9, "") -> 0.20216067
A10: Kohls - East Amherst | B10: NY | C10: 25808 | D10: 0 | E10: =IF(AND(ISNUMBER(C10),ISNUMBER(D10)), C10-D10, "") -> 25808 | F10: =IFERROR(E10/D10, "") | G10: 28710.66 | H10: =IF(AND(ISNUMBER(C10),ISNUMBER(G10)), C10-G10, "") -> -2902.66 | I10: =IFERROR(H10/G10, "") -> -0.10110043
A11: Kohls - East Brunswick | B11: NJ | C11: 47751 | D11: 0 | E11: =IF(AND(ISNUMBER(C11),ISNUMBER(D11)), C11-D11, "") -> 47751 | F11: =IFERROR(E11/D11, "") | G11: 46158.2 | H11: =IF(AND(ISNUMBER(C11),ISNUMBER(G11)), C11-G11, "") -> 1592.8 | I11: =IFERROR(H11/G11, "") -> 0.034507411
A12: Kohls - Edgewood | B12: MD | C12: 232222 | D12: 0 | E12: =IF(AND(ISNUMBER(C12),ISNUMBER(D12)), C12-D12, "") -> 232222 | F12: =IFERROR(E12/D12, "") | G12: 239043.04 | H12: =IF(AND(ISNUMBER(C12),ISNUMBER(G12)), C12-G12, "") -> -6821.04 | I12: =IFERROR(H12/G12, "") -> -0.028534778
A13: Kohls - Granite Run | B13: PA | C13: 31741 | D13: 0 | E13: =IF(AND(ISNUMBER(C13),ISNUMBER(D13)), C13-D13, "") -> 31741 | F13: =IFERROR(E13/D13, "") | G13: 29491.24 | H13: =IF(AND(ISNUMBER(C13),ISNUMBER(G13)), C13-G13, "") -> 2249.76 | I13: =IFERROR(H13/G13, "") -> 0.076285704
A14: Kohls - Greece | B14: NY | C14: 23984 | D14: 0 | E14: =IF(AND(ISNUMBER(C14),ISNUMBER(D14)), C14-D14, "") -> 23984 | F14: =IFERROR(E14/D14, "") | G14: 27592.06 | H14: =IF(AND(ISNUMBER(C14),ISNUMBER(G14)), C14-G14, "") -> -3608.06 | I14: =IFERROR(H14/G14, "") -> -0.13076443
