Workbook
Name JanActual: #REF!
Name JanActual2: #REF!
Name JanExpected: #REF!
Name JanExpectedDelta: #REF!
Name JanExpectedPercent: #REF!
Name JanExpPercent: #REF!
Name JanForecasted: #REF!
Name JanForecastedDelta: #REF!
Name JanForecastedPercent: #REF!
Name portfolio: Sites!$B$1:$B$1
Name Year: Sites!#REF!

Sheet Year to Date
A1: {=portfolio} -> Generate Capital | E1: Year to Date Actual v. Expected | H1: Year to Date Actual v. Forecasted
A2: Total | D2: =SUM(D4:D260) -> 4.5427985e+08 | E2: =SUM(E4:E260) -> 2.7963552e+08 | F2: =D2-E2 -> 1.7464433e+08 | G2: =IFERROR(F2/E2, 0) -> 0.62454271 | H2: =SUM(H4:H260) -> 4.3473008e+08 | I2: =D2-H2 -> 19549763 | J2: =IFERROR(I2/H2, 0) -> 0.044969889
A3: Site | B3: State | C3: SOL# | D3: Actual | E3: Expected | F3: Delta | G3: % | H3: Forecasted | I3: Delta | J3: %
A4: {=Sites[Site]} -> K026 | B4: {=Sites[State]} -> NY | C4: =Sites[[#This Row],[SOL'#]] -> SOL-10356 | D4: =SUM('1st Qtr'!D4,'2nd Qtr'!D4,'3rd Qtr'!D4,'4th Qtr'!D4) -> 225804.75 | E4: =SUM('1st Qtr'!E4, '2nd Qtr'!E4, '3rd Qtr'!E4, '4th Qtr'!E4) -> 350601.78 | F4: =IF(AND(ISNUMBER(D4),ISNUMBER(E4)), D4-E4, "") -> -124797.03 | G4: =IFERROR(F4/E4, "") -> -0.35595094 | H4: =SUM('1st Qtr'!H4,'2nd Qtr'!H4,'3rd Qtr'!H4,'4th Qtr'!H4) -> 314456.89 | I4: =SUM('1st Qtr'!I4, '2nd Qtr'!I4, '3rd Qtr'!I4, '4th Qtr'!I4) -> -88652.141 | J4: =IFERROR(I4/H4, "") -> -0.28192144
A5: K041 | B5: NY | C5: =Sites[[#This Row],[SOL'#]] -> SOL-10357 | D5: =SUM('1st Qtr'!D5,'2nd Qtr'!D5,'3rd Qtr'!D5,'4th Qtr'!D5) -> 239804.34 | E5: =SUM('1st Qtr'!E5, '2nd Qtr'!E5, '3rd Qtr'!E5, '4th Qtr'!E5) -> 280822.54 | F5: =IF(AND(ISNUMBER(D5),ISNUMBER(E5)), D5-E5, "") -> -41018.193 | G5: =IFERROR(F5/E5, "") -> -0.14606446 | H5: =SUM('1st Qtr'!H5,'2nd Qtr'!H5,'3rd Qtr'!H5,'4th Qtr'!H5) -> 257372 | I5: =SUM('1st Qtr'!I5, '2nd Qtr'!I5, '3rd Qtr'!I5, '4th Qtr'!I5) -> -17567.656 | J5: =IFERROR(I5/H5, "") -> -0.068257838
A6: K043 | B6: NY | C6: =Sites[[#This Row],[SOL'#]] -> SOL-10358 | D6: =SUM('1st Qtr'!D6,'2nd Qtr'!D6,'3rd Qtr'!D6,'4th Qtr'!D6) -> 288563.34 | E6: =SUM('1st Qtr'!E6, '2nd Qtr'!E6, '3rd Qtr'!E6, '4th Qtr'!E6) -> 311654.07 | F6: =IF(AND(ISNUMBER(D6),ISNUMBER(E6)), D6-E6, "") -> -23090.724 | G6: =IFERROR(F6/E6, "") -> -0.074090879 | H6: =SUM('1st Qtr'!H6,'2nd Qtr'!H6,'3rd Qtr'!H6,'4th Qtr'!H6) -> 56772.278 | I6: =SUM('1st Qtr'!I6, '2nd Qtr'!I6, '3rd Qtr'!I6, '4th Qtr'!I6) -> 231791.07 | J6: =IFERROR(I6/H6, "") -> 4.0828213
A7: K058 | B7: NY | C7: =Sites[[#This Row],[SOL'#]] -> SOL-10360 | D7: =SUM('1st Qtr'!D7,'2nd Qtr'!D7,'3rd Qtr'!D7,'4th Qtr'!D7) -> 94898.875 | E7: =SUM('1st Qtr'!E7, '2nd Qtr'!E7, '3rd Qtr'!E7, '4th Qtr'!E7) -> 110097.18 | F7: =IF(AND(ISNUMBER(D7),ISNUMBER(E7)), D7-E7, "") -> -15198.306 | G7: =IFERROR(F7/E7, "") -> -0.13804446 | H7: =SUM('1st Qtr'!H7,'2nd Qtr'!H7,'3rd Qtr'!H7,'4th Qtr'!H7) -> 215922.72 | I7: =SUM('1st Qtr'!I7, '2nd Qtr'!I7, '3rd Qtr'!I7, '4th Qtr'!I7) -> -121023.84 | J7: =IFERROR(I7/H7, "") -> -0.56049611
A8: K115 | B8: NY | C8: =Sites[[#This Row],[SOL'#]] -> SOL-10361 | D8: =SUM('1st Qtr'!D8,'2nd Qtr'!D8,'3rd Qtr'!D8,'4th Qtr'!D8) -> 73114.289 | E8: =SUM('1st Qtr'!E8, '2nd Qtr'!E8, '3rd Qtr'!E8, '4th Qtr'!E8) -> 130258.31 | F8: =IF(AND(ISNUMBER(D8),ISNUMBER(E8)), D8-E8, "") -> -57144.02 | G8: =IFERROR(F8/E8, "") -> -0.4386977 | H8: =SUM('1st Qtr'!H8,'2nd Qtr'!H8,'3rd Qtr'!H8,'4th Qtr'!H8) -> 145405.69 | I8: =SUM('1st Qtr'!I8, '2nd Qtr'!I8, '3rd Qtr'!I8, '4th Qtr'!I8) -> -72291.404 | J8: =IFERROR(I8/H8, "") -> -0.49717038
A9: K152 | B9: NY | C9: =Sites[[#This Row],[SOL'#]] -> SOL-10362 | D9: =SUM('1st Qtr'!D9,'2nd Qtr'!D9,'3rd Qtr'!D9,'4th Qtr'!D9) -> 87875.438 | E9: =SUM('1st Qtr'!E9, '2nd Qtr'!E9, '3rd Qtr'!E9, '4th Qtr'!E9) -> 94402.486 | F9: =IF(AND(ISNUMBER(D9),ISNUMBER(E9)), D9-E9, "") -> -6527.048 | G9: =IFERROR(F9/E9, "") -> -0.069140637 | H9: =SUM('1st Qtr'!H9,'2nd Qtr'!H9,'3rd Qtr'!H9,'4th Qtr'!H9) -> 92383 | I9: =SUM('1st Qtr'!I9, '2nd Qtr'!I9, '3rd Qtr'!I9, '4th Qtr'!I9) -> -4507.562 | J9: =IFERROR(I9/H9, "") -> -0.048792115
A10: K166 | B10: NY | C10: =Sites[[#This Row],[SOL'#]] -> SOL-10363 | D10: =SUM('1st Qtr'!D10,'2nd Qtr'!D10,'3rd Qtr'!D10,'4th Qtr'!D10) -> 310025.12 | E10: =SUM('1st Qtr'!E10, '2nd Qtr'!E10, '3rd Qtr'!E10, '4th Qtr'!E10) -> 357544.06 | F10: =IF(AND(ISNUMBER(D10),ISNUMBER(E10)), D10-E10, "") -> -47518.936 | G10: =IFERROR(F10/E10, "") -> -0.13290372 | H10: =SUM('1st Qtr'!H10,'2nd Qtr'!H10,'3rd Qtr'!H10,'4th Qtr'!H10) -> 334066.95 | I10: =SUM('1st Qtr'!I10, '2nd Qtr'!I10, '3rd Qtr'!I10, '4th Qtr'!I10) -> -24041.822 | J10: =IFERROR(I10/H10, "") -> -0.071967078
A11: K206 | B11: NY | C11: =Sites[[#This Row],[SOL'#]] -> SOL-10927 | D11: =SUM('1st Qtr'!D11,'2nd Qtr'!D11,'3rd Qtr'!D11,'4th Qtr'!D11) -> 191433.34 | E11: =SUM('1st Qtr'!E11, '2nd Qtr'!E11, '3rd Qtr'!E11, '4th Qtr'!E11) -> 190220.26 | F11: =IF(AND(ISNUMBER(D11),ISNUMBER(E11)), D11-E11, "") -> 1213.0826 | G11: =IFERROR(F11/E11, "") -> 0.0063772525 | H11: =SUM('1st Qtr'!H11,'2nd Qtr'!H11,'3rd Qtr'!H11,'4th Qtr'!H11) -> 187779 | I11: =SUM('1st Qtr'!I11, '2nd Qtr'!I11, '3rd Qtr'!I11, '4th Qtr'!I11) -> 3654.3396 | J11: =IFERROR(I11/H11, "") -> 0.019460853
A12: K251 | B12: NY | C12: =Sites[[#This Row],[SOL'#]] -> SOL-10365 | D12: =SUM('1st Qtr'!D12,'2nd Qtr'!D12,'3rd Qtr'!D12,'4th Qtr'!D12) -> 191459.37 | E12: =SUM('1st Qtr'!E12, '2nd Qtr'!E12, '3rd Qtr'!E12, '4th Qtr'!E12) -> 0 | F12: =IF(AND(ISNUMBER(D12),ISNUMBER(E12)), D12-E12, "") -> 191459.37 | G12: =IFERROR(F12/E12, "") | H12: =SUM('1st Qtr'!H12,'2nd Qtr'!H12,'3rd Qtr'!H12,'4th Qtr'!H12) -> 215815.01 | I12: =SUM('1st Qtr'!I12, '2nd Qtr'!I12, '3rd Qtr'!I12, '4th Qtr'!I12) -> -24355.631 | J12: =IFERROR(I12/H12, "") -> -0.11285421
A13: K269 | B13: NY | C13: =Sites[[#This Row],[SOL'#]] -> SOL-10366 | D13: =SUM('1st Qtr'!D13,'2nd Qtr'!D13,'3rd Qtr'!D13,'4th Qtr'!D13) -> 191448.44 | E13: =SUM('1st Qtr'!E13, '2nd Qtr'!E13, '3rd Qtr'!E13, '4th Qtr'!E13) -> 233166.75 | F13: =IF(AND(ISNUMBER(D13),ISNUMBER(E13)), D13-E13, "") -> -41718.316 | G13: =IFERROR(F13/E13, "") -> -0.17892052 | H13: =SUM('1st Qtr'!H13,'2nd Qtr'!H13,'3rd Qtr'!H13,'4th Qtr'!H13) -> 202482.72 | I13: =SUM('1st Qtr'!I13, '2nd Qtr'!I13, '3rd Qtr'!I13, '4th Qtr'!I13) -> -11034.286 | J13: =IFERROR(I13/H13, "") -> -0.05449495
A14: K273 | B14: NY | C14: =Sites[[#This Row],[SOL'#]] -> SOL-10367 | D14: =SUM('1st Qtr'!D14,'2nd Qtr'!D14,'3rd Qtr'!D14,'4th Qtr'!D14) -> 173177.06 | E14: =SUM('1st Qtr'!E14, '2nd Qtr'!E14, '3rd Qtr'!E14, '4th Qtr'!E14) -> 0 | F14: =IF(AND(ISNUMBER(D14),ISNUMBER(E14)), D14-E14, "") -> 173177.06 | G14: =IFERROR(F14/E14, "") | H14: =SUM('1st Qtr'!H14,'2nd Qtr'!H14,'3rd Qtr'!H14,'4th Qtr'!H14) -> 233475 | I14: =SUM('1st Qtr'!I14, '2nd Qtr'!I14, '3rd Qtr'!I14, '4th Qtr'!I14) -> -72388.938 | J14: =IFERROR(I14/H14, "") -> -0.31005006
A15: K287 | B15: NY | C15: =Sites[[#This Row],[SOL'#]] -> SOL-10919 | D15: =SUM('1st Qtr'!D15,'2nd Qtr'!D15,'3rd Qtr'!D15,'4th Qtr'!D15) -> 167902.94 | E15: =SUM('1st Qtr'!E15, '2nd Qtr'!E15, '3rd Qtr'!E15, '4th Qtr'!E15) -> 152493.26 | F15: =IF(AND(ISNUMBER(D15),ISNUMBER(E15)), D15-E15, "") -> 15409.681 | G15: =IFERROR(F15/E15, "") -> 0.10105156 | H15: =SUM('1st Qtr'!H15,'2nd Qtr'!H15,'3rd Qtr'!H15,'4th Qtr'!H15) -> 177628 | I15: =SUM('1st Qtr'!I15, '2nd Qtr'!I15, '3rd Qtr'!I15, '4th Qtr'!I15) -> -9725.062 | J15: =IFERROR(I15/H15, "") -> -0.0547496
A16: K298 | B16: NY | C16: =Sites[[#This Row],[SOL'#]] -> SOL-10368 | D16: =SUM('1st Qtr'!D16,'2nd Qtr'!D16,'3rd Qtr'!D16,'4th Qtr'!D16) -> 176177.72 | E16: =SUM('1st Qtr'!E16, '2nd Qtr'!E16, '3rd Qtr'!E16, '4th Qtr'!E16) -> 200968.63 | F16: =IF(AND(ISNUMBER(D16),ISNUMBER(E16)), D16-E16, "") -> -24790.907 | G16: =IFERROR(F16/E16, "") -> -0.1233571 | H16: =SUM('1st Qtr'!H16,'2nd Qtr'!H16,'3rd Qtr'!H16,'4th Qtr'!H16) -> 193842 | I16: =SUM('1st Qtr'!I16, '2nd Qtr'!I16, '3rd Qtr'!I16, '4th Qtr'!I16) -> -17664.281 | J16: =IFERROR(I16/H16, "") -> -0.091127211
... A173: IL: Manhattan - Gougar (PW) | B173: IL | C173: =Sites[[#This Row],[SOL'#]] -> SOL-11148 | D173: =SUM('1st Qtr'!D173,'2nd Qtr'!D173,'3rd Qtr'!D173,'4th Qtr'!D173) -> 94776.515 | E173: =SUM('1st Qtr'!E173, '2nd Qtr'!E173, '3rd Qtr'!E173, '4th Qtr'!E173) -> 121981.2 | F173: =IF(AND(ISNUMBER(D173),ISNUMBER(E173)), D173-E173, "") -> -27204.685 | G173: =IFERROR(F173/E173, "") -> -0.22302359 | H173: =SUM('1st Qtr'!H173,'2nd Qtr'!H173,'3rd Qtr'!H173,'4th Qtr'!H173) -> 178632.9 | I173: =SUM('1st Qtr'!I173, '2nd Qtr'!I173, '3rd Qtr'!I173, '4th Qtr'!I173) -> -83856.385 | J173: =IFERROR(I173/H173, "") -> -0.46943416

Sheet 1st Qtr
A1: {=portfolio} -> Generate Capital | E1: 1st Quarter Actual v. Expected | H1: 1st Quarter Actual v. Forecasted
A2: Total | D2: =SUM(D4:D260) -> 73187517 | E2: =SUM(E4:E260) -> 31614296 | F2: =D2-E2 -> 41573221 | G2: =IFERROR(F2/E2, 0) -> 1.3150133 | H2: =SUM(H4:H296) -> 79163514 | I2: =D2-H2 -> -5975997.1 | J2: =IFERROR(I2/H2, 0) -> -0.075489285
A3: Site | B3: State | C3: SOL# | D3: Actual | E3: Expected | F3: Delta | G3: % | H3: Forecasted | I3: Delta | J3: %
A4: {=Sites[Site]} -> K026 | B4: {=Sites[State]} -> NY | C4: =Sites[[#This Row],[SOL'#]] -> SOL-10356 | D4: =SUM(Jan!D4,Feb!D4,Mar!D4) -> 59541.5 | E4: =SUM(Jan!E4,Feb!E4,Mar!E4) -> 72002.03 | F4: =IF(AND(ISNUMBER(D4),ISNUMBER(E4)), D4-E4, "") -> -12460.53 | G4: =IFERROR(F4/E4, "") -> -0.17305804 | H4: =SUM(Jan!H4,Feb!H4,Mar!H4) -> 50886.23 | I4: =SUM(Jan!I4,Feb!I4,Mar!I4) -> 8655.27 | J4: =IFERROR(I4/H4, "") -> 0.17009061
A5: K041 | B5: NY | C5: =Sites[[#This Row],[SOL'#]] -> SOL-10357 | D5: =SUM(Jan!D5,Feb!D5,Mar!D5) -> 45035.969 | E5: =SUM(Jan!E5,Feb!E5,Mar!E5) -> 56199.33 | F5: =IF(AND(ISNUMBER(D5),ISNUMBER(E5)), D5-E5, "") -> -11163.361 | G5: =IFERROR(F5/E5, "") -> -0.19863869 | H5: =SUM(Jan!H5,Feb!H5,Mar!H5) -> 46068 | I5: =SUM(Jan!I5,Feb!I5,Mar!I5) -> -1032.0312 | J5: =IFERROR(I5/H5, "") -> -0.022402345
A6: K043 | B6: NY | C6: =Sites[[#This Row],[SOL'#]] -> SOL-10358 | D6: =SUM(Jan!D6,Feb!D6,Mar!D6) -> 53077.094 | E6: =SUM(Jan!E6,Feb!E6,Mar!E6) -> 62413.61 | F6: =IF(AND(ISNUMBER(D6),ISNUMBER(E6)), D6-E6, "") -> -9336.5163 | G6: =IFERROR(F6/E6, "") -> -0.14959103 | H6: =SUM(Jan!H6,Feb!H6,Mar!H6) -> 10325 | I6: =SUM(Jan!I6,Feb!I6,Mar!I6) -> 42752.094 | J6: =IFERROR(I6/H6, "") -> 4.1406386
A7: K058 | B7: NY | C7: =Sites[[#This Row],[SOL'#]] -> SOL-10360 | D7: =SUM(Jan!D7,Feb!D7,Mar!D7) -> 12634.75 | E7: =SUM(Jan!E7,Feb!E7,Mar!E7) -> 22177.693 | F7: =IF(AND(ISNUMBER(D7),ISNUMBER(E7)), D7-E7, "") -> -9542.943 | G7: =IFERROR(F7/E7, "") -> -0.43029467 | H7: =SUM(Jan!H7,Feb!H7,Mar!H7) -> 39956.249 | I7: =SUM(Jan!I7,Feb!I7,Mar!I7) -> -27321.499 | J7: =IFERROR(I7/H7, "") -> -0.68378538
A8: K115 | B8: NY | C8: =Sites[[#This Row],[SOL'#]] -> SOL-10361 | D8: =SUM(Jan!D8,Feb!D8,Mar!D8) -> 11799.117 | E8: =SUM(Jan!E8,Feb!E8,Mar!E8) -> 26169.976 | F8: =IF(AND(ISNUMBER(D8),ISNUMBER(E8)), D8-E8, "") -> -14370.859 | G8: =IFERROR(F8/E8, "") -> -0.54913535 | H8: =SUM(Jan!H8,Feb!H8,Mar!H8) -> 25362.094 | I8: =SUM(Jan!I8,Feb!I8,Mar!I8) -> -13562.977 | J8: =IFERROR(I8/H8, "") -> -0.53477354
A9: K152 | B9: NY | C9: =Sites[[#This Row],[SOL'#]] -> SOL-10362 | D9: =SUM(Jan!D9,Feb!D9,Mar!D9) -> 16402.188 | E9: =SUM(Jan!E9,Feb!E9,Mar!E9) -> 18944.047 | F9: =IF(AND(ISNUMBER(D9),ISNUMBER(E9)), D9-E9, "") -> -2541.8595 | G9: =IFERROR(F9/E9, "") -> -0.13417722 | H9: =SUM(Jan!H9,Feb!H9,Mar!H9) -> 15415 | I9: =SUM(Jan!I9,Feb!I9,Mar!I9) -> 987.1875 | J9: =IFERROR(I9/H9, "") -> 0.064040707
A10: K166 | B10: NY | C10: =Sites[[#This Row],[SOL'#]] -> SOL-10363 | D10: =SUM(Jan!D10,Feb!D10,Mar!D10) -> 58816.625 | E10: =SUM(Jan!E10,Feb!E10,Mar!E10) -> 71150.65 | F10: =IF(AND(ISNUMBER(D10),ISNUMBER(E10)), D10-E10, "") -> -12334.025 | G10: =IFERROR(F10/E10, "") -> -0.17335084 | H10: =SUM(Jan!H10,Feb!H10,Mar!H10) -> 54476.13 | I10: =SUM(Jan!I10,Feb!I10,Mar!I10) -> 4340.495 | J10: =IFERROR(I10/H10, "") -> 0.079677007
A11: K206 | B11: NY | C11: =Sites[[#This Row],[SOL'#]] -> SOL-10927 | D11: =SUM(Jan!D11,Feb!D11,Mar!D11) -> 35230.824 | E11: =SUM(Jan!E11,Feb!E11,Mar!E11) -> 42404.21 | F11: =IF(AND(ISNUMBER(D11),ISNUMBER(E11)), D11-E11, "") -> -7173.386 | G11: =IFERROR(F11/E11, "") -> -0.16916684 | H11: =SUM(Jan!H11,Feb!H11,Mar!H11) -> 32033 | I11: =SUM(Jan!I11,Feb!I11,Mar!I11) -> 3197.824 | J11: =IFERROR(I11/H11, "") -> 0.099829051
A12: K251 | B12: NY | C12: =Sites[[#This Row],[SOL'#]] -> SOL-10365 | D12: =SUM(Jan!D12,Feb!D12,Mar!D12) -> 39545.375 | E12: =SUM(Jan!E12,Feb!E12,Mar!E12) -> 0 | F12: =IF(AND(ISNUMBER(D12),ISNUMBER(E12)), D12-E12, "") -> 39545.375 | G12: =IFERROR(F12/E12, "") | H12: =SUM(Jan!H12,Feb!H12,Mar!H12) -> 36320.712 | I12: =SUM(Jan!I12,Feb!I12,Mar!I12) -> 3224.663 | J12: =IFERROR(I12/H12, "") -> 0.088783034
A13: K269 | B13: NY | C13: =Sites[[#This Row],[SOL'#]] -> SOL-10366 | D13: =SUM(Jan!D13,Feb!D13,Mar!D13) -> 35207.875 | E13: =SUM(Jan!E13,Feb!E13,Mar!E13) -> 46926.1 | F13: =IF(AND(ISNUMBER(D13),ISNUMBER(E13)), D13-E13, "") -> -11718.225 | G13: =IFERROR(F13/E13, "") -> -0.24971658 | H13: =SUM(Jan!H13,Feb!H13,Mar!H13) -> 35757.562 | I13: =SUM(Jan!I13,Feb!I13,Mar!I13) -> -549.687 | J13: =IFERROR(I13/H13, "") -> -0.015372608
A14: K273 | B14: NY | C14: =Sites[[#This Row],[SOL'#]] -> SOL-10367 | D14: =SUM(Jan!D14,Feb!D14,Mar!D14) -> 37234.688 | E14: =SUM(Jan!E14,Feb!E14,Mar!E14) -> 0 | F14: =IF(AND(ISNUMBER(D14),ISNUMBER(E14)), D14-E14, "") -> 37234.688 | G14: =IFERROR(F14/E14, "") | H14: =SUM(Jan!H14,Feb!H14,Mar!H14) -> 42215 | I14: =SUM(Jan!I14,Feb!I14,Mar!I14) -> -4980.3125 | J14: =IFERROR(I14/H14, "") -> -0.11797495
A15: K287 | B15: NY | C15: =Sites[[#This Row],[SOL'#]] -> SOL-10919 | D15: =SUM(Jan!D15,Feb!D15,Mar!D15) -> 31794.094 | E15: =SUM(Jan!E15,Feb!E15,Mar!E15) -> 31809.195 | F15: =IF(AND(ISNUMBER(D15),ISNUMBER(E15)), D15-E15, "") -> -15.10125 | G15: =IFERROR(F15/E15, "") -> -0.0004747448 | H15: =SUM(Jan!H15,Feb!H15,Mar!H15) -> 31948 | I15: =SUM(Jan!I15,Feb!I15,Mar!I15) -> -153.90625 | J15: =IFERROR(I15/H15, "") -> -0.0048173986
A16: K298 | B16: NY | C16: =Sites[[#This Row],[SOL'#]] -> SOL-10368 | D16: =SUM(Jan!D16,Feb!D16,Mar!D16) -> 30988.312 | E16: =SUM(Jan!E16,Feb!E16,Mar!E16) -> 41019.48 | F16: =IF(AND(ISNUMBER(D16),ISNUMBER(E16)), D16-E16, "") -> -10031.168 | G16: =IFERROR(F16/E16, "") -> -0.24454643 | H16: =SUM(Jan!H16,Feb!H16,Mar!H16) -> 32201 | I16: =SUM(Jan!I16,Feb!I16,Mar!I16) -> -1212.6875 | J16: =IFERROR(I16/H16, "") -> -0.037659933
... A155: Ransom | B155: NY | C155: =Sites[[#This Row],[SOL'#]] -> SOL-11157 | D155: =SUM(Jan!D155,Feb!D155,Mar!D155) -> 573181.7 | E155: =SUM(Jan!E155,Feb!E155,Mar!E155) -> 0 | F155: =IF(AND(ISNUMBER(D155),ISNUMBER(E155)), D155-E155, "") -> 573181.7 | G155: =IFERROR(F155/E155, "") | H155: =SUM(Jan!H155,Feb!H155,Mar!H155) -> 0 | I155: =SUM(Jan!I155,Feb!I155,Mar!I155) -> 573181.7 | J155: =IFERROR(I155/H155, "")
A156: Horseheads - Wedge | B156: NY | C156: =Sites[[#This Row],[SOL'#]] -> SOL-11160 | D156: =SUM(Jan!D156,Feb!D155,Mar!D156) -> 351172 | E156: =SUM(Jan!E156,Feb!E156,Mar!E156) -> 0 | F156: =IF(AND(ISNUMBER(D156),ISNUMBER(E156)), D156-E156, "") -> 351172 | G156: =IFERROR(F156/E156, "") | H156: =SUM(Jan!H156,Feb!H156,Mar!H156) -> 0 | I156: =SUM(Jan!I156,Feb!I156,Mar!I156) -> 351172 | J156: =IFERROR(I156/H156, "")
A157: Otisville - Shoddy Hollow | B157: NY | C157: =Sites[[#This Row],[SOL'#]] -> SOL-11185 | D157: =SUM(Jan!D157,Feb!D157,Mar!D157) -> 770722.7 | E157: =SUM(Jan!E157,Feb!E157,Mar!E157) -> 0 | F157: =IF(AND(ISNUMBER(D157),ISNUMBER(E157)), D157-E157, "") -> 770722.7 | G157: =IFERROR(F157/E157, "") | H157: =SUM(Jan!H157,Feb!H157,Mar!H157) -> 0 | I157: =SUM(Jan!I157,Feb!I157,Mar!I157) -> 770722.7 | J157: =IFERROR(I157/H157, "")
A158: Wellsville - Chenunda Creek | B158: NY | C158: =Sites[[#This Row],[SOL'#]] -> SOL-11187 | D158: =SUM(Jan!D158,Feb!D158,Mar!D158) -> 367949.8 | E158: =SUM(Jan!E158,Feb!E158,Mar!E158) -> 0 | F158: =IF(AND(ISNUMBER(D158),ISNUMBER(E158)), D158-E158, "") -> 367949.8 | G158: =IFERROR(F158/E158, "") | H158: =SUM(Jan!H158,Feb!H158,Mar!H158) -> 0 | I158: =SUM(Jan!I158,Feb!I158,Mar!I158) -> 367949.8 | J158: =IFERROR(I158/H158, "")
A159: DC: Washington - Essex Condominium | B159: DC | C159: =Sites[[#This Row],[SOL'#]] -> SOL-10036 | D159: =SUM(Jan!D159,Feb!E159,Mar!D159) -> 6661.958 | E159: =SUM(Jan!E159,Feb!E159,Mar!E159) -> 7882.524 | F159: =IF(AND(ISNUMBER(D159),ISNUMBER(E159)), D159-E159, "") -> -1220.566 | G159: =IFERROR(F159/E159, "") -> -0.15484457 | H159: =SUM(Jan!H159,Feb!H159,Mar!H159) -> 8796.319 | I159: =SUM(Jan!I159,Feb!I159,Mar!I159) -> -2543.319 | J159: =IFERROR(I159/H159, "") -> -0.28913447
A160: HI: Waipahu - 94-246 Leoku St - E.F.G. | B160: HI | C160: =Sites[[#This Row],[SOL'#]] -> SOL-10071 | D160: =SUM(Jan!D160,Feb!D160,Mar!D160) -> 28914 | E160: =SUM(Jan!E160,Feb!E160,Mar!E160) -> 29374.276 | F160: =IF(AND(ISNUMBER(D160),ISNUMBER(E160)), D160-E160, "") -> -460.276 | G160: =IFERROR(F160/E160, "") -> -0.015669356 | H160: =SUM(Jan!H160,Feb!H160,Mar!H160) -> 32426.188 | I160: =SUM(Jan!I160,Feb!I160,Mar!I160) -> -3512.188 | J160: =IFERROR(I160/H160, "") -> -0.10831332
A161: HI: Waipahu - 94-099 Waipahu St - PV | B161: HI | C161: =Sites[[#This Row],[SOL'#]] -> SOL-10068 | D161: =SUM(Jan!D161,Feb!D161,Mar!D161) -> 34818 | E161: =SUM(Jan!E161,Feb!E161,Mar!E161) -> 28134.248 | F161: =IF(AND(ISNUMBER(D161),ISNUMBER(E161)), D161-E161, "") -> 6683.752 | G161: =IFERROR(F161/E161, "") -> 0.2375664 | H161: =SUM(Jan!H161,Feb!H161,Mar!H161) -> 32408.821 | I161: =SUM(Jan!I161,Feb!I161,Mar!I161) -> 2409.179 | J161: =IFERROR(I161/H161, "") -> 0.074337138
A162: IL: Prophetstown - 5170 Yager Road (PW) | B162: IL | C162: =Sites[[#This Row],[SOL'#]] -> SOL-11149 | D162: =SUM(Jan!D162,Feb!D162,Mar!D162) -> 0 | E162: =SUM(Jan!E162,Feb!E162,Mar!E162) -> 0 | F162: =IF(AND(ISNUMBER(D162),ISNUMBER(E162)), D162-E162, "") -> 0 | G162: =IFERROR(F162/E162, "") | H162: =SUM(Jan!H162,Feb!H162,Mar!H162) -> 0 | I162: =SUM(Jan!I162,Feb!I162,Mar!I162) -> 0 | J162: =IFERROR(I162/H162, "")
A163: IL: Viola - Goldenrod - (PW) | B163: IL | C163: =Sites[[#This Row],[SOL'#]] -> SOL-11132 | D163: =SUM(Jan!D163,Feb!D163,Mar!D163) -> 0 | E163: =SUM(Jan!E163,Feb!E163,Mar!E163) -> 0 | F163: =IF(AND(ISNUMBER(D163),ISNUMBER(E163)), D163-E163, "") -> 0 | G163: =IFERROR(F163/E163, "") | H163: =SUM(Jan!H163,Feb!H163,Mar!H163) -> 0 | I163: =SUM(Jan!I163,Feb!I163,Mar!I163) -> 0 | J163: =IFERROR(I163/H163, "")
A164: IL: Marengo - Grant - (PW) | B164: IL | C164: =Sites[[#This Row],[SOL'#]] -> SOL-11147 | D164: =SUM(Jan!D164,Feb!D164,Mar!D164) -> 0 | E164: =SUM(Jan!E164,Feb!E164,Mar!E164) -> 0 | F164: =IF(AND(ISNUMBER(D164),ISNUMBER(E164)), D164-E164, "") -> 0 | G164: =IFERROR(F164/E164, "") | H164: =SUM(Jan!H164,Feb!H164,Mar!H164) -> 0 | I164: =SUM(Jan!I164,Feb!I164,Mar!I164) -> 0 | J164: =IFERROR(I164/H164, "")
A165: NY: Cambridge - Cambridge (PW) | B165: NY | C165: =Sites[[#This Row],[SOL'#]] -> SOL-11126 | D165: =SUM(Jan!D165,Feb!D165,Mar!D165) -> 0 | E165: =SUM(Jan!E165,Feb!E165,Mar!E165) -> 0 | F165: =IF(AND(ISNUMBER(D165),ISNUMBER(E165)), D165-E165, "") -> 0 | G165: =IFERROR(F165/E165, "") | H165: =SUM(Jan!H165,Feb!H165,Mar!H165) -> 0 | I165: =SUM(Jan!I165,Feb!I165,Mar!I165) -> 0 | J165: =IFERROR(I165/H165, "")
A166: NY: Whitesville - Independence North | B166: NY | C166: =Sites[[#This Row],[SOL'#]] -> SOL-11186 | D166: =SUM(Jan!D166,Feb!D166,Mar!D166) -> 0 | E166: =SUM(Jan!E166,Feb!E166,Mar!E166) -> 0 | F166: =IF(AND(ISNUMBER(D166),ISNUMBER(E166)), D166-E166, "") -> 0 | G166: =IFERROR(F166/E166, "") | H166: =SUM(Jan!H166,Feb!H166,Mar!H166) -> 0 | I166: =SUM(Jan!I166,Feb!I166,Mar!I166) -> 0 | J166: =IFERROR(I166/H166, "")
A167: IL: Beecher - Cottage Grove North (PW) | B167: IL | C167: =Sites[[#This Row],[SOL'#]] -> SOL-11114 | D167: =SUM(Jan!D167,Feb!D167,Mar!D167) -> 0 | E167: =SUM(Jan!E167,Feb!E167,Mar!E167) -> 0 | F167: =IF(AND(ISNUMBER(D167),ISNUMBER(E167)), D167-E167, "") -> 0 | G167: =IFERROR(F167/E167, "") | H167: =SUM(Jan!H167,Feb!H167,Mar!H167) -> 0 | I167: =SUM(Jan!I167,Feb!I167,Mar!I167) -> 0 | J167: =IFERROR(I167/H167, "")
A168: IL: Beecher - Cottage Grove South (PW) | B168: IL | C168: =Sites[[#This Row],[SOL'#]] -> SOL-11115 | D168: =SUM(Jan!D168,Feb!D168,Mar!D168) -> 0 | E168: =SUM(Jan!E168,Feb!E168,Mar!E168) -> 0 | F168: =IF(AND(ISNUMBER(D168),ISNUMBER(E168)), D168-E168, "") -> 0 | G168: =IFERROR(F168/E168, "") | H168: =SUM(Jan!H168,Feb!H168,Mar!H168) -> 0 | I168: =SUM(Jan!I168,Feb!I168,Mar!I168) -> 0 | J168: =IFERROR(I168/H168, "")
A169: IL: Harvard - 9618 US HWY 14 (PW) | B169: IL | C169: =Sites[[#This Row],[SOL'#]] -> SOL-11110 | D169: =SUM(Jan!D169,Feb!D169,Mar!D169) -> 0 | E169: =SUM(Jan!E169,Feb!E169,Mar!E169) -> 0 | F169: =IF(AND(ISNUMBER(D169),ISNUMBER(E169)), D169-E169, "") -> 0 | G169: =IFERROR(F169/E169, "") | H169: =SUM(Jan!H169,Feb!H169,Mar!H169) -> 0 | I169: =SUM(Jan!I169,Feb!I169,Mar!I169) -> 0 | J169: =IFERROR(I169/H169, "")
A170: IL: Beecher - 701 E Goodenow Rd (PW) | B170: IL | C170: =Sites[[#This Row],[SOL'#]] -> SOL-11112 | D170: =SUM(Jan!D170,Feb!D170,Mar!D170) -> 0 | E170: =SUM(Jan!E170,Feb!E170,Mar!E170) -> 0 | F170: =IF(AND(ISNUMBER(D170),ISNUMBER(E170)), D170-E170, "") -> 0 | G170: =IFERROR(F170/E170, "") | H170: =SUM(Jan!H170,Feb!H170,Mar!H170) -> 0 | I170: =SUM(Jan!I170,Feb!I170,Mar!I170) -> 0 | J170: =IFERROR(I170/H170, "")
A171: NY: Stormville - Green Haven - (IRA) | B171: NY | C171: =Sites[[#This Row],[SOL'#]] -> SOL-11151 | D171: =SUM(Jan!D171,Feb!D171,Mar!D171) -> 0 | E171: =SUM(Jan!E171,Feb!E171,Mar!E171) -> 0 | F171: =IF(AND(ISNUMBER(D171),ISNUMBER(E171)), D171-E171, "") -> 0 | G171: =IFERROR(F171/E171, "") | H171: =SUM(Jan!H171,Feb!H171,Mar!H171) -> 0 | I171: =SUM(Jan!I171,Feb!I171,Mar!I171) -> 0 | J171: =IFERROR(I171/H171, "")
A172: IL: Hillsboro - Anacott (PW) | B172: IL | C172: =Sites[[#This Row],[SOL'#]] -> SOL-11134 | D172: =SUM(Jan!D172,Feb!D172,Mar!D172) -> 0 | E172: =SUM(Jan!E172,Feb!E172,Mar!E172) -> 0 | F172: =IF(AND(ISNUMBER(D172),ISNUMBER(E172)), D172-E172, "") -> 0 | H172: =SUM(Jan!H172,Feb!H172,Mar!H172) -> 0 | I172: =SUM(Jan!I172,Feb!I172,Mar!I172) -> 0
A173: IL: Manhattan - Gougar (PW) | B173: IL | C173: =Sites[[#This Row],[SOL'#]] -> SOL-11148 | D173: =SUM(Jan!D173,Feb!D173,Mar!D173) -> 0 | E173: =SUM(Jan!E173,Feb!E173,Mar!E173) -> 0 | F173: =IF(AND(ISNUMBER(D173),ISNUMBER(E173)), D173-E173, "") -> 0 | H173: =SUM(Jan!H173,Feb!H173,Mar!H173) -> 0 | I173: =SUM(Jan!I173,Feb!I173,Mar!I173) -> 0

Sheet 2nd Qtr
A1: {=portfolio} -> Generate Capital | E1: 2nd Quarter Actual v. Expected | H1: 2nd Quarter Actual v. Forecasted
A2: Total | D2: =SUM(D4:D258) -> 1.2100596e+08 | E2: =SUM(E4:E260) -> 46675282 | F2: =D2-E2 -> 74330683 | G2: =IFERROR(F2/E2, 0) -> 1.5925064 | H2: =SUM(H4:H258) -> 1.4163328e+08 | I2: =D2-H2 -> -20627314 | J2: =IFERROR(I2/H2, 0) -> -0.14563889
A3: Site | B3: State | C3: SOL# | D3: Actual | E3: Expected | F3: Delta | G3: % | H3: Forecasted | I3: Delta | J3: %
A4: {=Sites[Site]} -> K026 | B4: {=Sites[State]} -> NY | C4: =Sites[[#This Row],[SOL'#]] -> SOL-10356 | D4: =SUM(Apr!D4,May!D4,Jun!D4) -> 68306.5 | E4: =SUM(Apr!E4,May!E4,Jun!E4) -> 106688.99 | F4: =IF(AND(ISNUMBER(D4),ISNUMBER(E4)), D4-E4, "") -> -38382.49 | G4: =IFERROR(F4/E4, "") -> -0.35976055 | H4: =SUM(Apr!H4,May!H4,Jun!H4) -> 111665.88 | I4: =SUM(Apr!I4,May!I4,Jun!I4) -> -43359.38 | J4: =IFERROR(I4/H4, "") -> -0.38829569
A5: K041 | B5: NY | C5: =Sites[[#This Row],[SOL'#]] -> SOL-10357 | D5: =SUM(Apr!D5,May!D5,Jun!D5) -> 75953.406 | E5: =SUM(Apr!E5,May!E5,Jun!E5) -> 86786.34 | F5: =IF(AND(ISNUMBER(D5),ISNUMBER(E5)), D5-E5, "") -> -10832.934 | G5: =IFERROR(F5/E5, "") -> -0.12482303 | H5: =SUM(Apr!H5,May!H5,Jun!H5) -> 88785 | I5: =SUM(Apr!I5,May!I5,Jun!I5) -> -12831.594 | J5: =IFERROR(I5/H5, "") -> -0.14452434
A6: K043 | B6: NY | C6: =Sites[[#This Row],[SOL'#]] -> SOL-10358 | D6: =SUM(Apr!D6,May!D6,Jun!D6) -> 92752.25 | E6: =SUM(Apr!E6,May!E6,Jun!E6) -> 95284.617 | F6: =IF(AND(ISNUMBER(D6),ISNUMBER(E6)), D6-E6, "") -> -2532.3665 | G6: =IFERROR(F6/E6, "") -> -0.026576866 | H6: =SUM(Apr!H6,May!H6,Jun!H6) -> 19497.39 | I6: =SUM(Apr!I6,May!I6,Jun!I6) -> 73254.86 | J6: =IFERROR(I6/H6, "") -> 3.7571624
A7: K058 | B7: NY | C7: =Sites[[#This Row],[SOL'#]] -> SOL-10360 | D7: =SUM(Apr!D7,May!D7,Jun!D7) -> 0 | E7: =SUM(Apr!E7,May!E7,Jun!E7) -> 0 | F7: =IF(AND(ISNUMBER(D7),ISNUMBER(E7)), D7-E7, "") -> 0 | G7: =IFERROR(F7/E7, "") | H7: =SUM(Apr!H7,May!H7,Jun!H7) -> 59563 | I7: =SUM(Apr!I7,May!I7,Jun!I7) -> -59563 | J7: =IFERROR(I7/H7, "") -> -1
A8: K115 | B8: NY | C8: =Sites[[#This Row],[SOL'#]] -> SOL-10361 | D8: =SUM(Apr!D8,May!D8,Jun!D8) -> 17549.203 | E8: =SUM(Apr!E8,May!E8,Jun!E8) -> 33770.05 | F8: =IF(AND(ISNUMBER(D8),ISNUMBER(E8)), D8-E8, "") -> -16220.847 | G8: =IFERROR(F8/E8, "") -> -0.48033233 | H8: =SUM(Apr!H8,May!H8,Jun!H8) -> 50850.15 | I8: =SUM(Apr!I8,May!I8,Jun!I8) -> -33300.947 | J8: =IFERROR(I8/H8, "") -> -0.65488395
A9: K152 | B9: NY | C9: =Sites[[#This Row],[SOL'#]] -> SOL-10362 | D9: =SUM(Apr!D9,May!D9,Jun!D9) -> 27928.25 | E9: =SUM(Apr!E9,May!E9,Jun!E9) -> 29089.714 | F9: =IF(AND(ISNUMBER(D9),ISNUMBER(E9)), D9-E9, "") -> -1161.464 | G9: =IFERROR(F9/E9, "") -> -0.039926965 | H9: =SUM(Apr!H9,May!H9,Jun!H9) -> 32067 | I9: =SUM(Apr!I9,May!I9,Jun!I9) -> -4138.75 | J9: =IFERROR(I9/H9, "") -> -0.12906571
A10: K166 | B10: NY | C10: =Sites[[#This Row],[SOL'#]] -> SOL-10363 | D10: =SUM(Apr!D10,May!D10,Jun!D10) -> 102875.5 | E10: =SUM(Apr!E10,May!E10,Jun!E10) -> 110758.07 | F10: =IF(AND(ISNUMBER(D10),ISNUMBER(E10)), D10-E10, "") -> -7882.57 | G10: =IFERROR(F10/E10, "") -> -0.071169261 | H10: =SUM(Apr!H10,May!H10,Jun!H10) -> 117571.05 | I10: =SUM(Apr!I10,May!I10,Jun!I10) -> -14695.55 | J10: =IFERROR(I10/H10, "") -> -0.12499293
A11: K206 | B11: NY | C11: =Sites[[#This Row],[SOL'#]] -> SOL-10927 | D11: =SUM(Apr!D11,May!D11,Jun!D11) -> 60686.781 | E11: =SUM(Apr!E11,May!E11,Jun!E11) -> 58984.7 | F11: =IF(AND(ISNUMBER(D11),ISNUMBER(E11)), D11-E11, "") -> 1702.0813 | G11: =IFERROR(F11/E11, "") -> 0.028856318 | H11: =SUM(Apr!H11,May!H11,Jun!H11) -> 65939 | I11: =SUM(Apr!I11,May!I11,Jun!I11) -> -5252.2188 | J11: =IFERROR(I11/H11, "") -> -0.07965269
A12: K251 | B12: NY | C12: =Sites[[#This Row],[SOL'#]] -> SOL-10365 | D12: =SUM(Apr!D12,May!D12,Jun!D12) -> 55076 | E12: =SUM(Apr!E12,May!E12,Jun!E12) -> 0 | F12: =IF(AND(ISNUMBER(D12),ISNUMBER(E12)), D12-E12, "") -> 55076 | G12: =IFERROR(F12/E12, "") | H12: =SUM(Apr!H12,May!H12,Jun!H12) -> 74161.86 | I12: =SUM(Apr!I12,May!I12,Jun!I12) -> -19085.86 | J12: =IFERROR(I12/H12, "") -> -0.25735412
A13: K269 | B13: NY | C13: =Sites[[#This Row],[SOL'#]] -> SOL-10366 | D13: =SUM(Apr!D13,May!D13,Jun!D13) -> 60935.25 | E13: =SUM(Apr!E13,May!E13,Jun!E13) -> 70904.83 | F13: =IF(AND(ISNUMBER(D13),ISNUMBER(E13)), D13-E13, "") -> -9969.58 | G13: =IFERROR(F13/E13, "") -> -0.14060509 | H13: =SUM(Apr!H13,May!H13,Jun!H13) -> 69988.55 | I13: =SUM(Apr!I13,May!I13,Jun!I13) -> -9053.3 | J13: =IFERROR(I13/H13, "") -> -0.12935402
A14: K273 | B14: NY | C14: =Sites[[#This Row],[SOL'#]] -> SOL-10367 | D14: =SUM(Apr!D14,May!D14,Jun!D14) -> 62937.188 | E14: =SUM(Apr!E14,May!E14,Jun!E14) -> 0 | F14: =IF(AND(ISNUMBER(D14),ISNUMBER(E14)), D14-E14, "") -> 62937.188 | G14: =IFERROR(F14/E14, "") | H14: =SUM(Apr!H14,May!H14,Jun!H14) -> 89807 | I14: =SUM(Apr!I14,May!I14,Jun!I14) -> -26869.812 | J14: =IFERROR(I14/H14, "") -> -0.29919508
A15: K287 | B15: NY | C15: =Sites[[#This Row],[SOL'#]] -> SOL-10919 | D15: =SUM(Apr!D15,May!D15,Jun!D15) -> 52962.812 | E15: =SUM(Apr!E15,May!E15,Jun!E15) -> 46110.94 | F15: =IF(AND(ISNUMBER(D15),ISNUMBER(E15)), D15-E15, "") -> 6851.8725 | G15: =IFERROR(F15/E15, "") -> 0.14859538 | H15: =SUM(Apr!H15,May!H15,Jun!H15) -> 61335 | I15: =SUM(Apr!I15,May!I15,Jun!I15) -> -8372.1875 | J15: =IFERROR(I15/H15, "") -> -0.13649935
A16: K298 | B16: NY | C16: =Sites[[#This Row],[SOL'#]] -> SOL-10368 | D16: =SUM(Apr!D16,May!D16,Jun!D16) -> 57863.906 | E16: =SUM(Apr!E16,May!E16,Jun!E16) -> 60971.71 | F16: =IF(AND(ISNUMBER(D16),ISNUMBER(E16)), D16-E16, "") -> -3107.8038 | G16: =IFERROR(F16/E16, "") -> -0.050971241 | H16: =SUM(Apr!H16,May!H16,Jun!H16) -> 70465 | I16: =SUM(Apr!I16,May!I16,Jun!I16) -> -12601.094 | J16: =IFERROR(I16/H16, "") -> -0.1788277
... A173: IL: Manhattan - Gougar (PW) | B173: IL | C173: =Sites[[#This Row],[SOL'#]] -> SOL-11148 | D173: =SUM(Apr!D173,May!D173,Jun!D173) -> 0 | E173: =SUM(Apr!E173,May!E173,Jun!E173) -> 0 | F173: =IF(AND(ISNUMBER(D173),ISNUMBER(E173)), D173-E173, "") -> 0 | G173: =IFERROR(F173/E173, "") | H173: =SUM(Apr!H173,May!H173,Jun!H173) -> 0 | I173: =SUM(Apr!I173,May!I173,Jun!I173) -> 0 | J173: =IFERROR(I173/H173, "")
J201: =IFERROR(I201/H201, "")

Sheet 3rd Qtr
A1: {=portfolio} -> Generate Capital | E1: 3rd Quarter Actual v. Expected | H1: 3rd Quarter Actual v. Forecasted
A2: Total | D2: =SUM(D4:D200) -> 1.5444095e+08 | E2: =SUM(E4:E200) -> 1.4226399e+08 | F2: =D2-E2 -> 12176955 | G2: =IFERROR(F2/E2, 0) -> 0.085594079 | H2: =SUM(H4:H200) -> 1.4191984e+08 | I2: =D2-H2 -> 12521105 | J2: =IFERROR(I2/H2, 0) -> 0.088226597
A3: Site | B3: State | C3: SOL# | D3: Actual | E3: Expected | F3: Delta | G3: % | H3: Forecasted | I3: Delta | J3: %
A4: {=Sites[Site]} -> K026 | B4: {=Sites[State]} -> NY | C4: =Sites[[#This Row],[SOL'#]] -> SOL-10356 | D4: =SUM(Jul!D4, Aug!D4, Sep!D4) -> 67502.625 | E4: =SUM(Jul!E4, Aug!E4, Sep!E4) -> 116340.78 | F4: =IF(AND(ISNUMBER(D4),ISNUMBER(E4)), D4-E4, "") -> -48838.159 | G4: =IFERROR(F4/E4, "") -> -0.41978537 | H4: =SUM(Jul!H4,Aug!H4,Sep!H4) -> 105071.8 | I4: =SUM(Jul!I4, Aug!I4, Sep!I4) -> -37569.18 | J4: =IFERROR(I4/H4, "") -> -0.3575572
A5: K041 | B5: NY | C5: =Sites[[#This Row],[SOL'#]] -> SOL-10357 | D5: =SUM(Jul!D5, Aug!D5, Sep!D5) -> 83369.312 | E5: =SUM(Jul!E5, Aug!E5, Sep!E5) -> 94700.345 | F5: =IF(AND(ISNUMBER(D5),ISNUMBER(E5)), D5-E5, "") -> -11331.033 | G5: =IFERROR(F5/E5, "") -> -0.11965144 | H5: =SUM(Jul!H5,Aug!H5,Sep!H5) -> 84647 | I5: =SUM(Jul!I5, Aug!I5, Sep!I5) -> -1277.6875 | J5: =IFERROR(I5/H5, "") -> -0.015094303
A6: K043 | B6: NY | C6: =Sites[[#This Row],[SOL'#]] -> SOL-10358 | D6: =SUM(Jul!D6, Aug!D6, Sep!D6) -> 100275.62 | E6: =SUM(Jul!E6, Aug!E6, Sep!E6) -> 105766.01 | F6: =IF(AND(ISNUMBER(D6),ISNUMBER(E6)), D6-E6, "") -> -5490.386 | G6: =IFERROR(F6/E6, "") -> -0.051910684 | H6: =SUM(Jul!H6,Aug!H6,Sep!H6) -> 18422.888 | I6: =SUM(Jul!I6, Aug!I6, Sep!I6) -> 81852.737 | J6: =IFERROR(I6/H6, "") -> 4.4429916
A7: K058 | B7: NY | C7: =Sites[[#This Row],[SOL'#]] -> SOL-10360 | D7: =SUM(Jul!D7, Aug!D7, Sep!D7) -> 47810.75 | E7: =SUM(Jul!E7, Aug!E7, Sep!E7) -> 49255.904 | F7: =IF(AND(ISNUMBER(D7),ISNUMBER(E7)), D7-E7, "") -> -1445.1535 | G7: =IFERROR(F7/E7, "") -> -0.029339701 | H7: =SUM(Jul!H7,Aug!H7,Sep!H7) -> 79064.713 | I7: =SUM(Jul!I7, Aug!I7, Sep!I7) -> -31253.963 | J7: =IFERROR(I7/H7, "") -> -0.39529597
A8: K115 | B8: NY | C8: =Sites[[#This Row],[SOL'#]] -> SOL-10361 | D8: =SUM(Jul!D8, Aug!D8, Sep!D8) -> 23853.328 | E8: =SUM(Jul!E8, Aug!E8, Sep!E8) -> 45857.462 | F8: =IF(AND(ISNUMBER(D8),ISNUMBER(E8)), D8-E8, "") -> -22004.134 | G8: =IFERROR(F8/E8, "") -> -0.47983759 | H8: =SUM(Jul!H8,Aug!H8,Sep!H8) -> 48263.555 | I8: =SUM(Jul!I8, Aug!I8, Sep!I8) -> -24410.227 | J8: =IFERROR(I8/H8, "") -> -0.50576935
A9: K152 | B9: NY | C9: =Sites[[#This Row],[SOL'#]] -> SOL-10362 | D9: =SUM(Jul!D9, Aug!D9, Sep!D9) -> 30753.563 | E9: =SUM(Jul!E9, Aug!E9, Sep!E9) -> 31815.94 | F9: =IF(AND(ISNUMBER(D9),ISNUMBER(E9)), D9-E9, "") -> -1062.377 | G9: =IFERROR(F9/E9, "") -> -0.033391344 | H9: =SUM(Jul!H9,Aug!H9,Sep!H9) -> 30294 | I9: =SUM(Jul!I9, Aug!I9, Sep!I9) -> 459.563 | J9: =IFERROR(I9/H9, "") -> 0.0151701
A10: K166 | B10: NY | C10: =Sites[[#This Row],[SOL'#]] -> SOL-10363 | D10: =SUM(Jul!D10, Aug!D10, Sep!D10) -> 108447.88 | E10: =SUM(Jul!E10, Aug!E10, Sep!E10) -> 121781.59 | F10: =IF(AND(ISNUMBER(D10),ISNUMBER(E10)), D10-E10, "") -> -13333.716 | G10: =IFERROR(F10/E10, "") -> -0.10948877 | H10: =SUM(Jul!H10,Aug!H10,Sep!H10) -> 111255.99 | I10: =SUM(Jul!I10, Aug!I10, Sep!I10) -> -2808.112 | J10: =IFERROR(I10/H10, "") -> -0.025240098
A11: K206 | B11: NY | C11: =Sites[[#This Row],[SOL'#]] -> SOL-10927 | D11: =SUM(Jul!D11, Aug!D11, Sep!D11) -> 68533.984 | E11: =SUM(Jul!E11, Aug!E11, Sep!E11) -> 63397.64 | F11: =IF(AND(ISNUMBER(D11),ISNUMBER(E11)), D11-E11, "") -> 5136.3444 | G11: =IFERROR(F11/E11, "") -> 0.081017911 | H11: =SUM(Jul!H11,Aug!H11,Sep!H11) -> 63283 | I11: =SUM(Jul!I11, Aug!I11, Sep!I11) -> 5250.9844 | J11: =IFERROR(I11/H11, "") -> 0.082976224
A12: K251 | B12: NY | C12: =Sites[[#This Row],[SOL'#]] -> SOL-10365 | D12: =SUM(Jul!D12, Aug!D12, Sep!D12) -> 65859.812 | E12: =SUM(Jul!E12, Aug!E12, Sep!E12) -> 0 | F12: =IF(AND(ISNUMBER(D12),ISNUMBER(E12)), D12-E12, "") -> 65859.812 | G12: =IFERROR(F12/E12, "") | H12: =SUM(Jul!H12,Aug!H12,Sep!H12) -> 70866.957 | I12: =SUM(Jul!I12, Aug!I12, Sep!I12) -> -5007.1445 | J12: =IFERROR(I12/H12, "") -> -0.07065556
A13: K269 | B13: NY | C13: =Sites[[#This Row],[SOL'#]] -> SOL-10366 | D13: =SUM(Jul!D13, Aug!D13, Sep!D13) -> 67163 | E13: =SUM(Jul!E13, Aug!E13, Sep!E13) -> 78829.963 | F13: =IF(AND(ISNUMBER(D13),ISNUMBER(E13)), D13-E13, "") -> -11666.963 | G13: =IFERROR(F13/E13, "") -> -0.14800162 | H13: =SUM(Jul!H13,Aug!H13,Sep!H13) -> 67148.255 | I13: =SUM(Jul!I13, Aug!I13, Sep!I13) -> 14.7455 | J13: =IFERROR(I13/H13, "") -> 0.00021959618
A14: K273 | B14: NY | C14: =Sites[[#This Row],[SOL'#]] -> SOL-10367 | D14: =SUM(Jul!D14, Aug!D14, Sep!D14) -> 47901.562 | E14: =SUM(Jul!E14, Aug!E14, Sep!E14) -> 0 | F14: =IF(AND(ISNUMBER(D14),ISNUMBER(E14)), D14-E14, "") -> 47901.562 | G14: =IFERROR(F14/E14, "") | H14: =SUM(Jul!H14,Aug!H14,Sep!H14) -> 61742 | I14: =SUM(Jul!I14, Aug!I14, Sep!I14) -> -25931.438 | J14: =IFERROR(I14/H14, "") -> -0.41999672
A15: K287 | B15: NY | C15: =Sites[[#This Row],[SOL'#]] -> SOL-10919 | D15: =SUM(Jul!D15, Aug!D15, Sep!D15) -> 57940.532 | E15: =SUM(Jul!E15, Aug!E15, Sep!E15) -> 50076.436 | F15: =IF(AND(ISNUMBER(D15),ISNUMBER(E15)), D15-E15, "") -> 7864.0958 | G15: =IFERROR(F15/E15, "") -> 0.15704184 | H15: =SUM(Jul!H15,Aug!H15,Sep!H15) -> 57858 | I15: =SUM(Jul!I15, Aug!I15, Sep!I15) -> 82.53175 | J15: =IFERROR(I15/H15, "") -> 0.0014264536
A16: K298 | B16: NY | C16: =Sites[[#This Row],[SOL'#]] -> SOL-10368 | D16: =SUM(Jul!D16, Aug!D16, Sep!D16) -> 63226.188 | E16: =SUM(Jul!E16, Aug!E16, Sep!E16) -> 67072.088 | F16: =IF(AND(ISNUMBER(D16),ISNUMBER(E16)), D16-E16, "") -> -3845.9 | G16: =IFERROR(F16/E16, "") -> -0.057339798 | H16: =SUM(Jul!H16,Aug!H16,Sep!H16) -> 66523 | I16: =SUM(Jul!I16, Aug!I16, Sep!I16) -> -3296.812 | J16: =IFERROR(I16/H16, "") -> -0.04955898
... A173: IL: Manhattan - Gougar (PW) | B173: IL | C173: =Sites[[#This Row],[SOL'#]] -> SOL-11148 | D173: =SUM(Jul!D173, Aug!D173, Sep!D173) -> 0 | E173: =SUM(Jul!E173, Aug!E173, Sep!E173) -> 0 | F173: =IF(AND(ISNUMBER(D173),ISNUMBER(E173)), D173-E173, "") -> 0 | G173: =IFERROR(F173/E173, "") | H173: =SUM(Jul!H173,Aug!H173,Sep!H173) -> 0 | I173: =SUM(Jul!I173, Aug!I173, Sep!I173) -> 0 | J173: =IFERROR(I173/H173, "")

Sheet 4th Qtr
A1: {=portfolio} -> Generate Capital | E1: 4th Quarter Actual v. Expected | H1: 4th Quarter Actual v. Forecasted
A2: Total | D2: =SUM(D4:D258) -> 1.0564542e+08 | E2: =SUM(E4:E283) -> 59081950 | F2: =D2-E2 -> 46563467 | G2: =IFERROR(F2/E2, 0) -> 0.78811663 | H2: =SUM(H4:H258) -> 72013447 | I2: =D2-H2 -> 33631970 | J2: =IFERROR(I2/H2, 0) -> 0.46702347
A3: Site | B3: State | C3: SOL# | D3: Actual | E3: Expected | F3: Delta | G3: % | H3: Forecasted | I3: Delta | J3: %
A4: {=Sites[Site]} -> K026 | B4: {=Sites[State]} -> NY | C4: =Sites[[#This Row],[SOL'#]] -> SOL-10356 | D4: =SUM(Oct!D4, Nov!D4, Dec!D4) -> 30454.125 | E4: =SUM(Oct!E4, Nov!E4, Dec!E4) -> 55569.98 | F4: =IF(AND(ISNUMBER(D4),ISNUMBER(E4)), D4-E4, "") -> -25115.855 | G4: =IFERROR(F4/E4, "") -> -0.45196804 | H4: =SUM(Oct!H4,Nov!H4,Dec!H4) -> 46832.976 | I4: =SUM(Oct!I4, Nov!I4, Dec!I4) -> -16378.851 | J4: =IFERROR(I4/H4, "") -> -0.34972902
A5: K041 | B5: NY | C5: =Sites[[#This Row],[SOL'#]] -> SOL-10357 | D5: =SUM(Oct!D5, Nov!D5, Dec!D5) -> 35445.656 | E5: =SUM(Oct!E5, Nov!E5, Dec!E5) -> 43136.522 | F5: =IF(AND(ISNUMBER(D5),ISNUMBER(E5)), D5-E5, "") -> -7690.8657 | G5: =IFERROR(F5/E5, "") -> -0.17829128 | H5: =SUM(Oct!H5,Nov!H5,Dec!H5) -> 37872 | I5: =SUM(Oct!I5, Nov!I5, Dec!I5) -> -2426.3438 | J5: =IFERROR(I5/H5, "") -> -0.064066956
A6: K043 | B6: NY | C6: =Sites[[#This Row],[SOL'#]] -> SOL-10358 | D6: =SUM(Oct!D6, Nov!D6, Dec!D6) -> 42458.375 | E6: =SUM(Oct!E6, Nov!E6, Dec!E6) -> 48189.83 | F6: =IF(AND(ISNUMBER(D6),ISNUMBER(E6)), D6-E6, "") -> -5731.455 | G6: =IFERROR(F6/E6, "") -> -0.11893495 | H6: =SUM(Oct!H6,Nov!H6,Dec!H6) -> 8527 | I6: =SUM(Oct!I6, Nov!I6, Dec!I6) -> 33931.375 | J6: =IFERROR(I6/H6, "") -> 3.9792864
A7: K058 | B7: NY | C7: =Sites[[#This Row],[SOL'#]] -> SOL-10360 | D7: =SUM(Oct!D7, Nov!D7, Dec!D7) -> 34453.375 | E7: =SUM(Oct!E7, Nov!E7, Dec!E7) -> 38663.584 | F7: =IF(AND(ISNUMBER(D7),ISNUMBER(E7)), D7-E7, "") -> -4210.209 | G7: =IFERROR(F7/E7, "") -> -0.1088934 | H7: =SUM(Oct!H7,Nov!H7,Dec!H7) -> 37338.756 | I7: =SUM(Oct!I7, Nov!I7, Dec!I7) -> -2885.381 | J7: =IFERROR(I7/H7, "") -> -0.077275767
A8: K115 | B8: NY | C8: =Sites[[#This Row],[SOL'#]] -> SOL-10361 | D8: =SUM(Oct!D8, Nov!D8, Dec!D8) -> 19912.641 | E8: =SUM(Oct!E8, Nov!E8, Dec!E8) -> 24460.821 | F8: =IF(AND(ISNUMBER(D8),ISNUMBER(E8)), D8-E8, "") -> -4548.1804 | G8: =IFERROR(F8/E8, "") -> -0.18593736 | H8: =SUM(Oct!H8,Nov!H8,Dec!H8) -> 20929.894 | I8: =SUM(Oct!I8, Nov!I8, Dec!I8) -> -1017.2534 | J8: =IFERROR(I8/H8, "") -> -0.048602892
A9: K152 | B9: NY | C9: =Sites[[#This Row],[SOL'#]] -> SOL-10362 | D9: =SUM(Oct!D9, Nov!D9, Dec!D9) -> 12791.438 | E9: =SUM(Oct!E9, Nov!E9, Dec!E9) -> 14552.785 | F9: =IF(AND(ISNUMBER(D9),ISNUMBER(E9)), D9-E9, "") -> -1761.3475 | G9: =IFERROR(F9/E9, "") -> -0.12103164 | H9: =SUM(Oct!H9,Nov!H9,Dec!H9) -> 14607 | I9: =SUM(Oct!I9, Nov!I9, Dec!I9) -> -1815.5625 | J9: =IFERROR(I9/H9, "") -> -0.124294
A10: K166 | B10: NY | C10: =Sites[[#This Row],[SOL'#]] -> SOL-10363 | D10: =SUM(Oct!D10, Nov!D10, Dec!D10) -> 39885.125 | E10: =SUM(Oct!E10, Nov!E10, Dec!E10) -> 53853.75 | F10: =IF(AND(ISNUMBER(D10),ISNUMBER(E10)), D10-E10, "") -> -13968.625 | G10: =IFERROR(F10/E10, "") -> -0.25938073 | H10: =SUM(Oct!H10,Nov!H10,Dec!H10) -> 50763.78 | I10: =SUM(Oct!I10, Nov!I10, Dec!I10) -> -10878.655 | J10: =IFERROR(I10/H10, "") -> -0.21429955
A11: K206 | B11: NY | C11: =Sites[[#This Row],[SOL'#]] -> SOL-10927 | D11: =SUM(Oct!D11, Nov!D11, Dec!D11) -> 26981.75 | E11: =SUM(Oct!E11, Nov!E11, Dec!E11) -> 25433.707 | F11: =IF(AND(ISNUMBER(D11),ISNUMBER(E11)), D11-E11, "") -> 1548.043 | G11: =IFERROR(F11/E11, "") -> 0.060865803 | H11: =SUM(Oct!H11,Nov!H11,Dec!H11) -> 26524 | I11: =SUM(Oct!I11, Nov!I11, Dec!I11) -> 457.75 | J11: =IFERROR(I11/H11, "") -> 0.017257955
A12: K251 | B12: NY | C12: =Sites[[#This Row],[SOL'#]] -> SOL-10365 | D12: =SUM(Oct!D12, Nov!D12, Dec!D12) -> 30978.188 | E12: =SUM(Oct!E12, Nov!E12, Dec!E12) -> 0 | F12: =IF(AND(ISNUMBER(D12),ISNUMBER(E12)), D12-E12, "") -> 30978.188 | G12: =IFERROR(F12/E12, "") | H12: =SUM(Oct!H12,Nov!H12,Dec!H12) -> 34465.477 | I12: =SUM(Oct!I12, Nov!I12, Dec!I12) -> -3487.2895 | J12: =IFERROR(I12/H12, "") -> -0.1011821
A13: K269 | B13: NY | C13: =Sites[[#This Row],[SOL'#]] -> SOL-10366 | D13: =SUM(Oct!D13, Nov!D13, Dec!D13) -> 28142.313 | E13: =SUM(Oct!E13, Nov!E13, Dec!E13) -> 36505.861 | F13: =IF(AND(ISNUMBER(D13),ISNUMBER(E13)), D13-E13, "") -> -8363.5485 | G13: =IFERROR(F13/E13, "") -> -0.22910153 | H13: =SUM(Oct!H13,Nov!H13,Dec!H13) -> 29588.357 | I13: =SUM(Oct!I13, Nov!I13, Dec!I13) -> -1446.0445 | J13: =IFERROR(I13/H13, "") -> -0.048872078
A14: K273 | B14: NY | C14: =Sites[[#This Row],[SOL'#]] -> SOL-10367 | D14: =SUM(Oct!D14, Nov!D14, Dec!D14) -> 25103.625 | E14: =SUM(Oct!E14, Nov!E14, Dec!E14) -> 0 | F14: =IF(AND(ISNUMBER(D14),ISNUMBER(E14)), D14-E14, "") -> 25103.625 | G14: =IFERROR(F14/E14, "") | H14: =SUM(Oct!H14,Nov!H14,Dec!H14) -> 39711 | I14: =SUM(Oct!I14, Nov!I14, Dec!I14) -> -14607.375 | J14: =IFERROR(I14/H14, "") -> -0.36784203
A15: K287 | B15: NY | C15: =Sites[[#This Row],[SOL'#]] -> SOL-10919 | D15: =SUM(Oct!D15, Nov!D15, Dec!D15) -> 25205.5 | E15: =SUM(Oct!E15, Nov!E15, Dec!E15) -> 24496.686 | F15: =IF(AND(ISNUMBER(D15),ISNUMBER(E15)), D15-E15, "") -> 708.814 | G15: =IFERROR(F15/E15, "") -> 0.028935098 | H15: =SUM(Oct!H15,Nov!H15,Dec!H15) -> 26487 | I15: =SUM(Oct!I15, Nov!I15, Dec!I15) -> -1281.5 | J15: =IFERROR(I15/H15, "") -> -0.048382225
A16: K298 | B16: NY | C16: =Sites[[#This Row],[SOL'#]] -> SOL-10368 | D16: =SUM(Oct!D16, Nov!D16, Dec!D16) -> 24099.312 | E16: =SUM(Oct!E16, Nov!E16, Dec!E16) -> 31905.348 | F16: =IF(AND(ISNUMBER(D16),ISNUMBER(E16)), D16-E16, "") -> -7806.0355 | G16: =IFERROR(F16/E16, "") -> -0.24466229 | H16: =SUM(Oct!H16,Nov!H16,Dec!H16) -> 24653 | I16: =SUM(Oct!I16, Nov!I16, Dec!I16) -> -553.6875 | J16: =IFERROR(I16/H16, "") -> -0.022459234
... A173: IL: Manhattan - Gougar (PW) | B173: IL | C173: =Sites[[#This Row],[SOL'#]] -> SOL-11148 | D173: =SUM(Oct!D173, Nov!D173, Dec!D173) -> 94776.515 | E173: =SUM(Oct!E173, Nov!E173, Dec!E173) -> 121981.2 | F173: =IF(AND(ISNUMBER(D173),ISNUMBER(E173)), D173-E173, "") -> -27204.685 | G173: =IFERROR(F173/E173, "") -> -0.22302359 | H173: =SUM(Oct!H173,Nov!H173,Dec!H173) -> 178632.9 | I173: =SUM(Oct!I173, Nov!I173, Dec!I173) -> -83856.385 | J173: =IFERROR(I173/H173, "") -> -0.46943416

Sheet Jan
A1: {=portfolio} -> Generate Capital | E1: January Actual v. Expected | H1: January Actual v. Forecasted
A2: Total | D2: =SUM(D4:D95) -> 8302287.9 | E2: =SUM(E4:E95) -> 4150358 | F2: =D2-E2 -> 4151929.9 | G2: =IFERROR(F2/E2, 0) -> 1.0003787 | H2: =SUM(H4:H95) -> 10397498 | I2: =D2-H2 -> -2095209.9 | J2: =IFERROR(I2/H2, 0) -> -0.20151097 | K2: =IF(AND(TODAY()>DATE(2024, 1, 1), COUNTA(Sites[Site])<>(COUNT(D:D)-1)), "Some sites are missing actual data; if new sites were added, make sure they are aligned correctly (including prior months!)", "") -> Some sites are missing actual data; if new sites were added, make sure they are aligned correctly (including prior months!)
A3: Site | B3: State | C3: SOL# | D3: Actual | E3: Expected | F3: Delta | G3: % | H3: Forecasted | I3: Delta | J3: % | K3: Notes | L3: Service Requests
A4: {=Sites[Site]} -> K026 | B4: {=Sites[State]} -> NY | C4: =Sites[[#This Row],[SOL'#]] -> SOL-10356 | D4: 11980.125 | E4: 18586.79 | F4: =IF(AND(ISNUMBER(D4),ISNUMBER(E4)), D4-E4, "") -> -6606.665 | G4: =IFERROR(F4/E4, "") -> -0.35544949 | H4: 11111.47 | I4: =IF(AND(ISNUMBER(D4),ISNUMBER(H4)), D4-H4, "") -> 868.655 | J4: =IFERROR(I4/H4, "") -> 0.078176425
A5: K041 | B5: NY | C5: =Sites[[#This Row],[SOL'#]] -> SOL-10357 | D5: 8842.5469 | E5: 13490.72 | F5: =IF(AND(ISNUMBER(D5),ISNUMBER(E5)), D5-E5, "") -> -4648.1731 | G5: =IFERROR(F5/E5, "") -> -0.34454596 | H5: 9924 | I5: =IF(AND(ISNUMBER(D5),ISNUMBER(H5)), D5-H5, "") -> -1081.4531 | J5: =IFERROR(I5/H5, "") -> -0.10897351
A6: K043 | B6: NY | C6: =Sites[[#This Row],[SOL'#]] -> SOL-10358 | D6: 10563.688 | E6: 15508.68 | F6: =IF(AND(ISNUMBER(D6),ISNUMBER(E6)), D6-E6, "") -> -4944.9925 | G6: =IFERROR(F6/E6, "") -> -0.31885322 | H6: 2303 | I6: =IF(AND(ISNUMBER(D6),ISNUMBER(H6)), D6-H6, "") -> 8260.6875 | J6: =IFERROR(I6/H6, "") -> 3.5869247 | K6: 1.Estimated values are low in AE we have also verified the file which was given GC
A7: K058 | B7: NY | C7: =Sites[[#This Row],[SOL'#]] -> SOL-10360 | D7: 8472.1875 | E7: 12896.51 | F7: =IF(AND(ISNUMBER(D7),ISNUMBER(E7)), D7-E7, "") -> -4424.3225 | G7: =IFERROR(F7/E7, "") -> -0.34306355 | H7: 9147.029 | I7: =IF(AND(ISNUMBER(D7),ISNUMBER(H7)), D7-H7, "") -> -674.8415 | J7: =IFERROR(I7/H7, "") -> -0.073777125
A8: K115 | B8: NY | C8: =Sites[[#This Row],[SOL'#]] -> SOL-10361 | D8: 2497.5194 | E8: 7565.845 | F8: =IF(AND(ISNUMBER(D8),ISNUMBER(E8)), D8-E8, "") -> -5068.3256 | G8: =IFERROR(F8/E8, "") -> -0.66989551 | H8: 5593.833 | I8: =IF(AND(ISNUMBER(D8),ISNUMBER(H8)), D8-H8, "") -> -3096.3136 | J8: =IFERROR(I8/H8, "") -> -0.55352271 | K8: 1. 96 optimizers are down for site construction. | L8: 1.SR093291
A9: K152 | B9: NY | C9: =Sites[[#This Row],[SOL'#]] -> SOL-10362 | D9: 3001 | E9: 4499.147 | F9: =IF(AND(ISNUMBER(D9),ISNUMBER(E9)), D9-E9, "") -> -1498.147 | G9: =IFERROR(F9/E9, "") -> -0.33298467 | H9: 3567 | I9: =IF(AND(ISNUMBER(D9),ISNUMBER(H9)), D9-H9, "") -> -566 | J9: =IFERROR(I9/H9, "") -> -0.15867676 | K9: 1. Low generation due to weather/snow.
A10: K166 | B10: NY | C10: =Sites[[#This Row],[SOL'#]] -> SOL-10363 | D10: 10743.5 | E10: 17382.57 | F10: =IF(AND(ISNUMBER(D10),ISNUMBER(E10)), D10-E10, "") -> -6639.07 | G10: =IFERROR(F10/E10, "") -> -0.38193834 | H10: 12125.14 | I10: =IF(AND(ISNUMBER(D10),ISNUMBER(H10)), D10-H10, "") -> -1381.64 | J10: =IFERROR(I10/H10, "") -> -0.11394838 | K10: 1. Low generation due to weather/snow.
A11: K206 | B11: NY | C11: =Sites[[#This Row],[SOL'#]] -> SOL-10927 | D11: 7155.1976 | E11: 11256.59 | F11: =IF(AND(ISNUMBER(D11),ISNUMBER(E11)), D11-E11, "") -> -4101.3924 | G11: =IFERROR(F11/E11, "") -> -0.36435478 | H11: 6894 | I11: =IF(AND(ISNUMBER(D11),ISNUMBER(H11)), D11-H11, "") -> 261.19765 | J11: =IFERROR(I11/H11, "") -> 0.037887678
A12: K251 | B12: NY | C12: =Sites[[#This Row],[SOL'#]] -> SOL-10365 | D12: 7964.375 | E12: 0 | F12: =IF(AND(ISNUMBER(D12),ISNUMBER(E12)), D12-E12, "") -> 7964.375 | G12: =IFERROR(F12/E12, "") | H12: 8525.692 | I12: =IF(AND(ISNUMBER(D12),ISNUMBER(H12)), D12-H12, "") -> -561.317 | J12: =IFERROR(I12/H12, "") -> -0.065838292 | K12: 1.Weather station is not communicating since 11/22/2024. | L12: 1.SR093633
A13: K269 | B13: NY | C13: =Sites[[#This Row],[SOL'#]] -> SOL-10366 | D13: 6631 | E13: 11493.23 | F13: =IF(AND(ISNUMBER(D13),ISNUMBER(E13)), D13-E13, "") -> -4862.23 | G13: =IFERROR(F13/E13, "") -> -0.42305166 | H13: 7761.932 | I13: =IF(AND(ISNUMBER(D13),ISNUMBER(H13)), D13-H13, "") -> -1130.932 | J13: =IFERROR(I13/H13, "") -> -0.14570238
A14: K273 | B14: NY | C14: =Sites[[#This Row],[SOL'#]] -> SOL-10367 | D14: 6884.75 | E14: 0 | F14: =IF(AND(ISNUMBER(D14),ISNUMBER(E14)), D14-E14, "") -> 6884.75 | G14: =IFERROR(F14/E14, "") | H14: 9546 | I14: =IF(AND(ISNUMBER(D14),ISNUMBER(H14)), D14-H14, "") -> -2661.25 | J14: =IFERROR(I14/H14, "") -> -0.27878169 | K14: 1. Weather station is not communicating since 06/30/2024. 2. 26 optimizers are down for roof repair. | L14: 1.SR086842 2.SR093294 | M14: SR093294
A15: K287 | B15: NY | C15: =Sites[[#This Row],[SOL'#]] -> SOL-10919 | D15: 6469.9062 | E15: 8103.888 | F15: =IF(AND(ISNUMBER(D15),ISNUMBER(E15)), D15-E15, "") -> -1633.9817 | G15: =IFERROR(F15/E15, "") -> -0.20162936 | H15: 7303 | I15: =IF(AND(ISNUMBER(D15),ISNUMBER(H15)), D15-H15, "") -> -833.09375 | J15: =IFERROR(I15/H15, "") -> -0.11407555
A16: K298 | B16: NY | C16: =Sites[[#This Row],[SOL'#]] -> SOL-10368 | D16: 4878.3438 | E16: 10470.4 | F16: =IF(AND(ISNUMBER(D16),ISNUMBER(E16)), D16-E16, "") -> -5592.0562 | G16: =IFERROR(F16/E16, "") -> -0.53408239 | H16: 6119 | I16: =IF(AND(ISNUMBER(D16),ISNUMBER(H16)), D16-H16, "") -> -1240.6562 | J16: =IFERROR(I16/H16, "") -> -0.20275474 | K16: 1. Low generation due to weather/snow.
A17: K335 | B17: NY | C17: =Sites[[#This Row],[SOL'#]] -> SOL-10370 | D17: 6585.9375 | E17: 11111.72 | F17: =IF(AND(ISNUMBER(D17),ISNUMBER(E17)), D17-E17, "") -> -4525.7825 | G17: =IFERROR(F17/E17, "") -> -0.40729811 | H17: 8179 | I17: =IF(AND(ISNUMBER(D17),ISNUMBER(H17)), D17-H17, "") -> -1593.0625 | J17: =IFERROR(I17/H17, "") -> -0.19477473
A18: K345 | B18: NY | C18: =Sites[[#This Row],[SOL'#]] -> SOL-10920 | D18: 7617.6813 | E18: 8115.26 | F18: =IF(AND(ISNUMBER(D18),ISNUMBER(E18)), D18-E18, "") -> -497.57867 | G18: =IFERROR(F18/E18, "") -> -0.061313953 | H18: 6910 | I18: =IF(AND(ISNUMBER(D18),ISNUMBER(H18)), D18-H18, "") -> 707.68133 | J18: =IFERROR(I18/H18, "") -> 0.10241409
A19: K445 | B19: NY | C19: =Sites[[#This Row],[SOL'#]] -> SOL-10373 | D19: 7247.9688 | E19: 11595.77 | F19: =IF(AND(ISNUMBER(D19),ISNUMBER(E19)), D19-E19, "") -> -4347.8013 | G19: =IFERROR(F19/E19, "") -> -0.37494718 | H19: 6816.675 | I19: =IF(AND(ISNUMBER(D19),ISNUMBER(H19)), D19-H19, "") -> 431.29375 | J19: =IFERROR(I19/H19, "") -> 0.063270399
A20: K495 | B20: NY | C20: =Sites[[#This Row],[SOL'#]] -> SOL-10374 | D20: 0 | E20: 32841.14 | F20: =IF(AND(ISNUMBER(D20),ISNUMBER(E20)), D20-E20, "") -> -32841.14 | G20: =IFERROR(F20/E20, "") -> -1 | H20: 33557 | I20: =IF(AND(ISNUMBER(D20),ISNUMBER(H20)), D20-H20, "") -> -33557 | J20: =IFERROR(I20/H20, "") -> -1 | K20: 1.Due to shunt trips of the switchgear and overcurrent faults site is offline since 11/20/2024. | L20: 1.SR093196
A21: M020 | B21: NY | C21: =Sites[[#This Row],[SOL'#]] -> SOL-10380 | D21: 7114.6562 | E21: 10428.83 | F21: =IF(AND(ISNUMBER(D21),ISNUMBER(E21)), D21-E21, "") -> -3314.1737 | G21: =IFERROR(F21/E21, "") -> -0.3177896 | H21: 9125 | I21: =IF(AND(ISNUMBER(D21),ISNUMBER(H21)), D21-H21, "") -> -2010.3438 | J21: =IFERROR(I21/H21, "") -> -0.22031164 | K21: 1. Low generation due to weather/snow.
A22: M092 | B22: NY | C22: =Sites[[#This Row],[SOL'#]] -> SOL-10383 | D22: 7110.6875 | E22: 11229.76 | F22: =IF(AND(ISNUMBER(D22),ISNUMBER(E22)), D22-E22, "") -> -4119.0725 | G22: =IFERROR(F22/E22, "") -> -0.36679969 | H22: 8178.46 | I22: =IF(AND(ISNUMBER(D22),ISNUMBER(H22)), D22-H22, "") -> -1067.7725 | J22: =IFERROR(I22/H22, "") -> -0.13055912 | K22: 1. Low generation due to weather/snow.
A23: M143 | B23: NY | C23: =Sites[[#This Row],[SOL'#]] -> SOL-10384 | D23: 7303.2812 | E23: 10937.18 | F23: =IF(AND(ISNUMBER(D23),ISNUMBER(E23)), D23-E23, "") -> -3633.8988 | G23: =IFERROR(F23/E23, "") -> -0.33225189 | H23: 8702.744 | I23: =IF(AND(ISNUMBER(D23),ISNUMBER(H23)), D23-H23, "") -> -1399.4628 | J23: =IFERROR(I23/H23, "") -> -0.16080707 | K23: 1. Low generation due to weather/snow.
A24: M144 | B24: NY | C24: =Sites[[#This Row],[SOL'#]] -> SOL-10385 | D24: 12171.125 | E24: 0 | F24: =IF(AND(ISNUMBER(D24),ISNUMBER(E24)), D24-E24, "") -> 12171.125 | G24: =IFERROR(F24/E24, "") | H24: 13644 | I24: =IF(AND(ISNUMBER(D24),ISNUMBER(H24)), D24-H24, "") -> -1472.875 | J24: =IFERROR(I24/H24, "") -> -0.10795038 | K24: 1. Low generation due to weather/snow.
A25: M167 | B25: NY | C25: =Sites[[#This Row],[SOL'#]] -> SOL-10386 | D25: 6736.5 | E25: 8426.056 | F25: =IF(AND(ISNUMBER(D25),ISNUMBER(E25)), D25-E25, "") -> -1689.556 | G25: =IFERROR(F25/E25, "") -> -0.20051564 | H25: 8106.211 | I25: =IF(AND(ISNUMBER(D25),ISNUMBER(H25)), D25-H25, "") -> -1369.711 | J25: =IFERROR(I25/H25, "") -> -0.16897056 | K25: 1. Low generation due to weather/snow.
A26: M188 | B26: NY | C26: =Sites[[#This Row],[SOL'#]] -> SOL-10387 | D26: 6676.8125 | E26: 0 | F26: =IF(AND(ISNUMBER(D26),ISNUMBER(E26)), D26-E26, "") -> 6676.8125 | G26: =IFERROR(F26/E26, "") | H26: 6981 | I26: =IF(AND(ISNUMBER(D26),ISNUMBER(H26)), D26-H26, "") -> -304.1875 | J26: =IFERROR(I26/H26, "") -> -0.043573628
A27: EMHC | B27: NY | C27: =Sites[[#This Row],[SOL'#]] -> SOL-10351 | D27: 1958.0469 | E27: 2171.019 | F27: =IF(AND(ISNUMBER(D27),ISNUMBER(E27)), D27-E27, "") -> -212.97212 | G27: =IFERROR(F27/E27, "") -> -0.098097771 | H27: 2319.395 | I27: =IF(AND(ISNUMBER(D27),ISNUMBER(H27)), D27-H27, "") -> -361.34812 | J27: =IFERROR(I27/H27, "") -> -0.15579413
A28: Q008 | B28: NY | C28: =Sites[[#This Row],[SOL'#]] -> SOL-10397 | D28: 11304.469 | E28: 16377.23 | F28: =IF(AND(ISNUMBER(D28),ISNUMBER(E28)), D28-E28, "") -> -5072.7612 | G28: =IFERROR(F28/E28, "") -> -0.30974476 | H28: 10992 | I28: =IF(AND(ISNUMBER(D28),ISNUMBER(H28)), D28-H28, "") -> 312.46875 | J28: =IFERROR(I28/H28, "") -> 0.028426924 | K28: 1. Low generation due to weather/snow.
A29: Q018 | B29: NY | C29: =Sites[[#This Row],[SOL'#]] -> SOL-10398 | D29: 6700.6875 | E29: 8361.302 | F29: =IF(AND(ISNUMBER(D29),ISNUMBER(E29)), D29-E29, "") -> -1660.6145 | G29: =IFERROR(F29/E29, "") -> -0.19860717 | H29: 6682.311 | I29: =IF(AND(ISNUMBER(D29),ISNUMBER(H29)), D29-H29, "") -> 18.3765 | J29: =IFERROR(I29/H29, "") -> 0.0027500217 | K29: 1. Low generation due to weather/snow.
A30: Q021 | B30: NY | C30: =Sites[[#This Row],[SOL'#]] -> SOL-10399 | D30: 5780.4062 | E30: 9454.255 | F30: =IF(AND(ISNUMBER(D30),ISNUMBER(E30)), D30-E30, "") -> -3673.8487 | G30: =IFERROR(F30/E30, "") -> -0.38859209 | H30: 5223.647 | I30: =IF(AND(ISNUMBER(D30),ISNUMBER(H30)), D30-H30, "") -> 556.75925 | J30: =IFERROR(I30/H30, "") -> 0.10658439 | K30: 1. Low generation due to weather/snow.
A31: Q025 | B31: NY | C31: =Sites[[#This Row],[SOL'#]] -> SOL-10400 | D31: 9494.875 | E31: 13415.23 | F31: =IF(AND(ISNUMBER(D31),ISNUMBER(E31)), D31-E31, "") -> -3920.355 | G31: =IFERROR(F31/E31, "") -> -0.29223167 | H31: 7767 | I31: =IF(AND(ISNUMBER(D31),ISNUMBER(H31)), D31-H31, "") -> 1727.875 | J31: =IFERROR(I31/H31, "") -> 0.22246363 | K31: 1. Low generation due to weather/snow.
A32: Q074 | B32: NY | C32: =Sites[[#This Row],[SOL'#]] -> SOL-10402 | D32: 5694.625 | E32: 7433.287 | F32: =IF(AND(ISNUMBER(D32),ISNUMBER(E32)), D32-E32, "") -> -1738.662 | G32: =IFERROR(F32/E32, "") -> -0.23390218 | H32: 6035.102 | I32: =IF(AND(ISNUMBER(D32),ISNUMBER(H32)), D32-H32, "") -> -340.477 | J32: =IFERROR(I32/H32, "") -> -0.056416114 | K32: 1. Site was taken offline from 12/31/24 due to ConEd shut site off for tranformer work and later back online on 01/02 at 09:30 | L32: 1. SR095201
A33: Q115 | B33: NY | C33: =Sites[[#This Row],[SOL'#]] -> SOL-10872 | D33: 7869.5625 | E33: 12376.31 | F33: =IF(AND(ISNUMBER(D33),ISNUMBER(E33)), D33-E33, "") -> -4506.7475 | G33: =IFERROR(F33/E33, "") -> -0.36414307 | H33: 8154.507 | I33: =IF(AND(ISNUMBER(D33),ISNUMBER(H33)), D33-H33, "") -> -284.9445 | J33: =IFERROR(I33/H33, "") -> -0.034943192
A34: Q139 | B34: NY | C34: =Sites[[#This Row],[SOL'#]] -> SOL-10403 | D34: 5074.7187 | E34: 6806.319 | F34: =IF(AND(ISNUMBER(D34),ISNUMBER(E34)), D34-E34, "") -> -1731.6003 | G34: =IFERROR(F34/E34, "") -> -0.25441068 | H34: 5168 | I34: =IF(AND(ISNUMBER(D34),ISNUMBER(H34)), D34-H34, "") -> -93.28125 | J34: =IFERROR(I34/H34, "") -> -0.018049777
A35: Q157 | B35: NY | C35: =Sites[[#This Row],[SOL'#]] -> SOL-10404 | D35: 7985.125 | E35: 13511.83 | F35: =IF(AND(ISNUMBER(D35),ISNUMBER(E35)), D35-E35, "") -> -5526.705 | G35: =IFERROR(F35/E35, "") -> -0.40902713 | H35: 9200.271 | I35: =IF(AND(ISNUMBER(D35),ISNUMBER(H35)), D35-H35, "") -> -1215.146 | J35: =IFERROR(I35/H35, "") -> -0.1320772 | K35: 1.Inverter 3 offline mulptiple days due to parts RMAD 2.Inverter 4 is offline due to "Isolation Fault" from 01/3 | L35: 1. SR094206 2. SR096202 | M35: SR096202
A36: Q192 | B36: NY | C36: =Sites[[#This Row],[SOL'#]] -> SOL-10406 | D36: 13490.125 | E36: 19580.54 | F36: =IF(AND(ISNUMBER(D36),ISNUMBER(E36)), D36-E36, "") -> -6090.415 | G36: =IFERROR(F36/E36, "") -> -0.31104428 | H36: 13910.41 | I36: =IF(AND(ISNUMBER(D36),ISNUMBER(H36)), D36-H36, "") -> -420.285 | J36: =IFERROR(I36/H36, "") -> -0.030213703
A37: Q210 | B37: NY | C37: =Sites[[#This Row],[SOL'#]] -> SOL-10407 | D37: 11766.375 | E37: 14293.21 | F37: =IF(AND(ISNUMBER(D37),ISNUMBER(E37)), D37-E37, "") -> -2526.835 | G37: =IFERROR(F37/E37, "") -> -0.17678569 | H37: 11622 | I37: =IF(AND(ISNUMBER(D37),ISNUMBER(H37)), D37-H37, "") -> 144.375 | J37: =IFERROR(I37/H37, "") -> 0.012422561
A38: Q229 | B38: NY | C38: =Sites[[#This Row],[SOL'#]] -> SOL-10408 | D38: 4152.5312 | E38: 7352.509 | F38: =IF(AND(ISNUMBER(D38),ISNUMBER(E38)), D38-E38, "") -> -3199.9778 | G38: =IFERROR(F38/E38, "") -> -0.43522255 | H38: 3687.114 | I38: =IF(AND(ISNUMBER(D38),ISNUMBER(H38)), D38-H38, "") -> 465.41725 | J38: =IFERROR(I38/H38, "") -> 0.12622806
A39: Q231 | B39: NY | C39: =Sites[[#This Row],[SOL'#]] -> SOL-10870 | D39: 17624.25 | E39: 30638.85 | F39: =IF(AND(ISNUMBER(D39),ISNUMBER(E39)), D39-E39, "") -> -13014.6 | G39: =IFERROR(F39/E39, "") -> -0.42477443 | H39: 16899 | I39: =IF(AND(ISNUMBER(D39),ISNUMBER(H39)), D39-H39, "") -> 725.25 | J39: =IFERROR(I39/H39, "") -> 0.042916741
A40: Q405 | B40: NY | C40: =Sites[[#This Row],[SOL'#]] -> SOL-10409 | D40: 21223.625 | E40: 28842.48 | F40: =IF(AND(ISNUMBER(D40),ISNUMBER(E40)), D40-E40, "") -> -7618.855 | G40: =IFERROR(F40/E40, "") -> -0.26415395 | H40: 20777.84 | I40: =IF(AND(ISNUMBER(D40),ISNUMBER(H40)), D40-H40, "") -> 445.785 | J40: =IFERROR(I40/H40, "") -> 0.021454829
...

Sheet Feb
A1: {=portfolio} -> Generate Capital | E1: February Actual v. Expected | H1: February Actual v. Forecasted
A2: Total | D2: =SUM(D4:D95) -> 9904560.4 | E2: =SUM(E4:E95) -> 4894424.5 | F2: =D2-E2 -> 5010135.8 | G2: =IFERROR(F2/E2, 0) -> 1.0236415 | H2: =SUM(H4:H95) -> 15070075 | I2: =D2-H2 -> -5165514.5 | J2: =IFERROR(I2/H2, 0) -> -0.34276635 | K2: =IF(AND(TODAY()>DATE(2024, 2, 1), COUNTA(Sites[Site])<>(COUNT(D:D)-1)), "Some sites are missing actual data; if new sites were added, make sure they are aligned correctly (including prior months!)", "") -> Some sites are missing actual data; if new sites were added, make sure they are aligned correctly (including prior months!)
A3: Site | B3: State | C3: SOL# | D3: Actual | E3: Expected | F3: Delta | G3: % | H3: Forecasted | I3: Delta | J3: % | K3: Notes | L3: Service Requests
A4: {=Sites[Site]} -> K026 | B4: {=Sites[State]} -> NY | C4: =Sites[[#This Row],[SOL'#]] -> SOL-10356 | D4: 17315.75 | E4: 21363.42 | F4: =IF(AND(ISNUMBER(D4),ISNUMBER(E4)), D4-E4, "") -> -4047.67 | G4: =IFERROR(F4/E4, "") -> -0.18946732 | H4: 15170.88 | I4: =IF(AND(ISNUMBER(D4),ISNUMBER(H4)), D4-H4, "") -> 2144.87 | J4: =IFERROR(I4/H4, "") -> 0.14138072 | K4: 1.Low generation due to weather/snow.
A5: K041 | B5: NY | C5: =Sites[[#This Row],[SOL'#]] -> SOL-10357 | D5: 13320.781 | E5: 17186.99 | F5: =IF(AND(ISNUMBER(D5),ISNUMBER(E5)), D5-E5, "") -> -3866.2088 | G5: =IFERROR(F5/E5, "") -> -0.22494973 | H5: 13859 | I5: =IF(AND(ISNUMBER(D5),ISNUMBER(H5)), D5-H5, "") -> -538.21875 | J5: =IFERROR(I5/H5, "") -> -0.038835324 | K5: 1.Low generation due to weather/snow.
A6: K043 | B6: NY | C6: =Sites[[#This Row],[SOL'#]] -> SOL-10358 | D6: 15518.344 | E6: 18500.95 | F6: =IF(AND(ISNUMBER(D6),ISNUMBER(E6)), D6-E6, "") -> -2982.6063 | G6: =IFERROR(F6/E6, "") -> -0.16121368 | H6: 3061 | I6: =IF(AND(ISNUMBER(D6),ISNUMBER(H6)), D6-H6, "") -> 12457.344 | J6: =IFERROR(I6/H6, "") -> 4.0696974 | K6: 1.Estimated values are low in AE we have also verified the file which was given GC
A7: K058 | B7: NY | C7: =Sites[[#This Row],[SOL'#]] -> SOL-10360 | D7: 4162.5625 | E7: 9281.183 | F7: =IF(AND(ISNUMBER(D7),ISNUMBER(E7)), D7-E7, "") -> -5118.6205 | G7: =IFERROR(F7/E7, "") -> -0.55150518 | H7: 12005.22 | I7: =IF(AND(ISNUMBER(D7),ISNUMBER(H7)), D7-H7, "") -> -7842.6575 | J7: =IFERROR(I7/H7, "") -> -0.65327062 | K7: 1.The inverters experienced multiple tripping events on 02/14,17,18,19,20 due to intermittent voltage on phase B. The site tripped offline at 08:52 AM on 02/21. The technician arrived and stated that the cause was a blown phase C fuse and thermal damage to the AC disconnect. The site will remain offline until the parts are replaced. | L7: 1.SR097569
A8: K115 | B8: NY | C8: =Sites[[#This Row],[SOL'#]] -> SOL-10361 | D8: 3372.4181 | E8: 7965.901 | F8: =IF(AND(ISNUMBER(D8),ISNUMBER(E8)), D8-E8, "") -> -4593.4829 | G8: =IFERROR(F8/E8, "") -> -0.57664323 | H8: 7488.091 | I8: =IF(AND(ISNUMBER(D8),ISNUMBER(H8)), D8-H8, "") -> -4115.6729 | J8: =IFERROR(I8/H8, "") -> -0.54962913 | K8: 1. 96 optimizers are down for site construction. 2. Low generation due to weather/snow. | L8: 1.SR093291
A9: K152 | B9: NY | C9: =Sites[[#This Row],[SOL'#]] -> SOL-10362 | D9: 4885.5938 | E9: 5681.248 | F9: =IF(AND(ISNUMBER(D9),ISNUMBER(E9)), D9-E9, "") -> -795.65425 | G9: =IFERROR(F9/E9, "") -> -0.1400492 | H9: 4676 | I9: =IF(AND(ISNUMBER(D9),ISNUMBER(H9)), D9-H9, "") -> 209.59375 | J9: =IFERROR(I9/H9, "") -> 0.0448233 | K9: 1. Low generation due to weather/snow.
A10: K166 | B10: NY | C10: =Sites[[#This Row],[SOL'#]] -> SOL-10363 | D10: 17203.5 | E10: 21280.06 | F10: =IF(AND(ISNUMBER(D10),ISNUMBER(E10)), D10-E10, "") -> -4076.56 | G10: =IFERROR(F10/E10, "") -> -0.19156713 | H10: 16417.23 | I10: =IF(AND(ISNUMBER(D10),ISNUMBER(H10)), D10-H10, "") -> 786.27 | J10: =IFERROR(I10/H10, "") -> 0.047892976 | K10: 1. Low generation due to weather/snow.
