Workbook
Name JanActual: #REF!
Name JanActual2: #REF!
Name JanExpected: #REF!
Name JanExpectedDelta: #REF!
Name JanExpectedPercent: #REF!
Name JanExpPercent: #REF!
Name JanForecasted: #REF!
Name JanForecastedDelta: #REF!
Name JanForecastedPercent: #REF!
Name portfolio: Sites!$B$1:$B$1
Name Year: Sites!#REF!

Sheet Year to Date
A1: {=portfolio} -> Renewable Properties | D1: Year to Date Actual v. Expected | G1: Year to Date Actual v. Forecasted
A2: Total | C2: =SUM(C4:C80) -> 56380558 | D2: =SUM(D4:D80) -> 64726963 | E2: =C2-D2 -> -8346404.8 | F2: =IFERROR(E2/D2, 0) -> -0.12894788 | G2: =SUM(G4:G80) -> 67591874 | H2: =C2-G2 -> -11211316 | I2: =IFERROR(H2/G2, 0) -> -0.16586781
A3: Site | B3: State | C3: Actual | D3: Expected | E3: Delta | F3: % | G3: Forecasted | H3: Delta | I3: %
A4: {=Sites[Site]} -> Cedar Swamp Rd | B4: {=Sites[State]} -> MA | C4: =SUM('1st Qtr'!C4, '2nd Qtr'!C4, '3rd Qtr'!C4, '4th Qtr'!C4) -> 1242699 | D4: =SUM('1st Qtr'!D4, '2nd Qtr'!D4, '3rd Qtr'!D4, '4th Qtr'!D4) -> 1037011.6 | E4: =IF(AND(ISNUMBER(C4),ISNUMBER(D4)), C4-D4, "") -> 205687.42 | F4: =IFERROR(E4/D4, "") -> 0.19834631 | G4: =SUM('1st Qtr'!G4, '2nd Qtr'!G4, '3rd Qtr'!G4, '4th Qtr'!G4) -> 1111472.9 | H4: =SUM('1st Qtr'!H4, '2nd Qtr'!H4, '3rd Qtr'!H4, '4th Qtr'!H4) -> -50778.867 | I4: =IFERROR(H4/G4, "") -> -0.045686106
A5: Bullis | B5: NY | C5: =SUM('1st Qtr'!C5, '2nd Qtr'!C5, '3rd Qtr'!C5, '4th Qtr'!C5) -> 6531376.5 | D5: =SUM('1st Qtr'!D5, '2nd Qtr'!D5, '3rd Qtr'!D5, '4th Qtr'!D5) -> 6639864.7 | E5: =IF(AND(ISNUMBER(C5),ISNUMBER(D5)), C5-D5, "") -> -108488.2 | F5: =IFERROR(E5/D5, "") -> -0.016338917 | G5: =SUM('1st Qtr'!G5, '2nd Qtr'!G5, '3rd Qtr'!G5, '4th Qtr'!G5) -> 8046414.8 | H5: =SUM('1st Qtr'!H5, '2nd Qtr'!H5, '3rd Qtr'!H5, '4th Qtr'!H5) -> -1515038.3 | I5: =IFERROR(H5/G5, "") -> -0.18828737
A6: Rock Island | B6: NY | C6: =SUM('1st Qtr'!C6, '2nd Qtr'!C6, '3rd Qtr'!C6, '4th Qtr'!C6) -> 5954273.5 | D6: =SUM('1st Qtr'!D6, '2nd Qtr'!D6, '3rd Qtr'!D6, '4th Qtr'!D6) -> 6857128.6 | E6: =IF(AND(ISNUMBER(C6),ISNUMBER(D6)), C6-D6, "") -> -902855.1 | F6: =IFERROR(E6/D6, "") -> -0.13166664 | G6: =SUM('1st Qtr'!G6, '2nd Qtr'!G6, '3rd Qtr'!G6, '4th Qtr'!G6) -> 9471594.8 | H6: =SUM('1st Qtr'!H6, '2nd Qtr'!H6, '3rd Qtr'!H6, '4th Qtr'!H6) -> -3517321.3 | I6: =IFERROR(H6/G6, "") -> -0.3713547
A7: Winslow - Roderick | B7: ME | C7: =SUM('1st Qtr'!C7, '2nd Qtr'!C7, '3rd Qtr'!C7, '4th Qtr'!C7) -> 6059353 | D7: =SUM('1st Qtr'!D7, '2nd Qtr'!D7, '3rd Qtr'!D7, '4th Qtr'!D7) -> 7104210.7 | E7: =IF(AND(ISNUMBER(C7),ISNUMBER(D7)), C7-D7, "") -> -1044857.7 | F7: =IFERROR(E7/D7, "") -> -0.14707583 | G7: =SUM('1st Qtr'!G7, '2nd Qtr'!G7, '3rd Qtr'!G7, '4th Qtr'!G7) -> 6614310.6 | H7: =SUM('1st Qtr'!H7, '2nd Qtr'!H7, '3rd Qtr'!H7, '4th Qtr'!H7) -> -554957.58 | I7: =IFERROR(H7/G7, "") -> -0.083902558
A8: Minoa - Clemons Rd | B8: NY | C8: =SUM('1st Qtr'!C8, '2nd Qtr'!C8, '3rd Qtr'!C8, '4th Qtr'!C8) -> 4110122.6 | D8: =SUM('1st Qtr'!D8, '2nd Qtr'!D8, '3rd Qtr'!D8, '4th Qtr'!D8) -> 4974364.4 | E8: =IF(AND(ISNUMBER(C8),ISNUMBER(D8)), C8-D8, "") -> -864241.8 | F8: =IFERROR(E8/D8, "") -> -0.17373914 | G8: =SUM('1st Qtr'!G8, '2nd Qtr'!G8, '3rd Qtr'!G8, '4th Qtr'!G8) -> 4641239.3 | H8: =SUM('1st Qtr'!H8, '2nd Qtr'!H8, '3rd Qtr'!H8, '4th Qtr'!H8) -> -531116.7 | I8: =IFERROR(H8/G8, "") -> -0.11443424
A9: Manchester - Western | B9: ME | C9: =SUM('1st Qtr'!C9, '2nd Qtr'!C9, '3rd Qtr'!C9, '4th Qtr'!C9) -> 998907.81 | D9: =SUM('1st Qtr'!D9, '2nd Qtr'!D9, '3rd Qtr'!D9, '4th Qtr'!D9) -> 713095.02 | E9: =IF(AND(ISNUMBER(C9),ISNUMBER(D9)), C9-D9, "") -> 285812.79 | F9: =IFERROR(E9/D9, "") -> 0.40080604 | G9: =SUM('1st Qtr'!G9, '2nd Qtr'!G9, '3rd Qtr'!G9, '4th Qtr'!G9) -> 828053.98 | H9: =SUM('1st Qtr'!H9, '2nd Qtr'!H9, '3rd Qtr'!H9, '4th Qtr'!H9) -> 170853.83 | I9: =IFERROR(H9/G9, "") -> 0.20633176
A10: Batavia - Pike Rd | B10: NY | C10: =SUM('1st Qtr'!C10, '2nd Qtr'!C10, '3rd Qtr'!C10, '4th Qtr'!C10) -> 4751219.9 | D10: =SUM('1st Qtr'!D10, '2nd Qtr'!D10, '3rd Qtr'!D10, '4th Qtr'!D10) -> 5073991.7 | E10: =IF(AND(ISNUMBER(C10),ISNUMBER(D10)), C10-D10, "") -> -322771.87 | F10: =IFERROR(E10/D10, "") -> -0.063613007 | G10: =SUM('1st Qtr'!G10, '2nd Qtr'!G10, '3rd Qtr'!G10, '4th Qtr'!G10) -> 5409432.2 | H10: =SUM('1st Qtr'!H10, '2nd Qtr'!H10, '3rd Qtr'!H10, '4th Qtr'!H10) -> -658212.37 | I10: =IFERROR(H10/G10, "") -> -0.12167864
A11: Slayton A & B | B11: NY | C11: =SUM('1st Qtr'!C11, '2nd Qtr'!C11, '3rd Qtr'!C11, '4th Qtr'!C11) -> 11314826 | D11: =SUM('1st Qtr'!D11, '2nd Qtr'!D11, '3rd Qtr'!D11, '4th Qtr'!D11) -> 13353301 | E11: =IF(AND(ISNUMBER(C11),ISNUMBER(D11)), C11-D11, "") -> -2038474.9 | F11: =IFERROR(E11/D11, "") -> -0.152657 | G11: =SUM('1st Qtr'!G11, '2nd Qtr'!G11, '3rd Qtr'!G11, '4th Qtr'!G11) -> 12053440 | H11: =SUM('1st Qtr'!H11, '2nd Qtr'!H11, '3rd Qtr'!H11, '4th Qtr'!H11) -> -738614.24 | I11: =IFERROR(H11/G11, "") -> -0.061278293
A12: Batavia - Alexander Rd | B12: NY | C12: =SUM('1st Qtr'!C12, '2nd Qtr'!C12, '3rd Qtr'!C12, '4th Qtr'!C12) -> 2655255.7 | D12: =SUM('1st Qtr'!D12, '2nd Qtr'!D12, '3rd Qtr'!D12, '4th Qtr'!D12) -> 3249556.5 | E12: =IF(AND(ISNUMBER(C12),ISNUMBER(D12)), C12-D12, "") -> -594300.83 | F12: =IFERROR(E12/D12, "") -> -0.18288675 | G12: =SUM('1st Qtr'!G12, '2nd Qtr'!G12, '3rd Qtr'!G12, '4th Qtr'!G12) -> 2968964.7 | H12: =SUM('1st Qtr'!H12, '2nd Qtr'!H12, '3rd Qtr'!H12, '4th Qtr'!H12) -> -313708.98 | I12: =IFERROR(H12/G12, "") -> -0.10566275
A13: NC: Gibson – Henry Gibson Solar | B13: NC | C13: =SUM('1st Qtr'!C13, '2nd Qtr'!C13, '3rd Qtr'!C13, '4th Qtr'!C13) -> 7986476 | D13: =SUM('1st Qtr'!D13, '2nd Qtr'!D13, '3rd Qtr'!D13, '4th Qtr'!D13) -> 9731775.4 | E13: =IF(AND(ISNUMBER(C13),ISNUMBER(D13)), C13-D13, "") -> -1745299.4 | F13: =IFERROR(E13/D13, "") -> -0.17934029 | G13: =SUM('1st Qtr'!G13, '2nd Qtr'!G13, '3rd Qtr'!G13, '4th Qtr'!G13) -> 9961237.2 | H13: =SUM('1st Qtr'!H13, '2nd Qtr'!H13, '3rd Qtr'!H13, '4th Qtr'!H13) -> -1974761.2 | I13: =IFERROR(H13/G13, "") -> -0.19824457
A14: Bangor - Pushaw | B14: ME | C14: =SUM('1st Qtr'!C14, '2nd Qtr'!C14, '3rd Qtr'!C14, '4th Qtr'!C14) -> 4776048 | D14: =SUM('1st Qtr'!D14, '2nd Qtr'!D14, '3rd Qtr'!D14, '4th Qtr'!D14) -> 5992663.2 | E14: =IF(AND(ISNUMBER(C14),ISNUMBER(D14)), C14-D14, "") -> -1216615.2 | F14: =IFERROR(E14/D14, "") -> -0.20301744 | G14: =SUM('1st Qtr'!G14, '2nd Qtr'!G14, '3rd Qtr'!G14, '4th Qtr'!G14) -> 6485713.2 | H14: =SUM('1st Qtr'!H14, '2nd Qtr'!H14, '3rd Qtr'!H14, '4th Qtr'!H14) -> -1709665.2 | I14: =IFERROR(H14/G14, "") -> -0.26360481

Sheet 1st Qtr
A1: {=portfolio} -> Renewable Properties | D1: 1st Quarter Actual v. Expected | G1: 1st Quarter Actual v. Forecasted
A2: Total | C2: =SUM(C4:C80) -> 10039467 | D2: =SUM(D4:D80) -> 12321100 | E2: =C2-D2 -> -2281632.5 | F2: =IFERROR(E2/D2, 0) -> -0.18518091 | G2: =SUM(G4:G80) -> 12129549 | H2: =C2-G2 -> -2090081.8 | I2: =IFERROR(H2/G2, 0) -> -0.17231323
A3: Site | B3: State | C3: Actual | D3: Expected | E3: Delta | F3: % | G3: Forecasted | H3: Delta | I3: %
A4: {=Sites[Site]} -> Cedar Swamp Rd | B4: {=Sites[State]} -> MA | C4: =SUM(Jan!C4, Feb!C5, Mar!C4) -> 437777 | D4: =SUM(Jan!D4, Feb!D4, Mar!D4) -> 267935.23 | E4: =IF(AND(ISNUMBER(C4),ISNUMBER(D4)), C4-D4, "") -> 169841.77 | F4: =IFERROR(E4/D4, "") -> 0.63389115 | G4: =SUM(Jan!G4, Feb!G4, Mar!G4) -> 205644.36 | H4: =SUM(Jan!H4, Feb!H4, Mar!H4) -> 50127.64 | I4: =IFERROR(H4/G4, "") -> 0.24375889
A5: Bullis | B5: NY | C5: =SUM(Jan!C5, Feb!C5, Mar!C5) -> 1022641.5 | D5: =SUM(Jan!D5, Feb!D5, Mar!D5) -> 1180915.6 | E5: =IF(AND(ISNUMBER(C5),ISNUMBER(D5)), C5-D5, "") -> -158274.1 | F5: =IFERROR(E5/D5, "") -> -0.1340266 | G5: =SUM(Jan!G5, Feb!G5, Mar!G5) -> 1367428.4 | H5: =SUM(Jan!H5, Feb!H5, Mar!H5) -> -344786.9 | I5: =IFERROR(H5/G5, "") -> -0.25214256
A6: Rock Island | B6: NY | C6: =SUM(Jan!C6, Feb!C6, Mar!C6) -> 1051915 | D6: =SUM(Jan!D6, Feb!D6, Mar!D6) -> 1305164.6 | E6: =IF(AND(ISNUMBER(C6),ISNUMBER(D6)), C6-D6, "") -> -253249.6 | F6: =IFERROR(E6/D6, "") -> -0.19403652 | G6: =SUM(Jan!G6, Feb!G6, Mar!G6) -> 1250649.1 | H6: =SUM(Jan!H6, Feb!H6, Mar!H6) -> -198734.1 | I6: =IFERROR(H6/G6, "") -> -0.15890476
A7: Winslow - Roderick | B7: ME | C7: =SUM(Jan!C7, Feb!C7, Mar!C7) -> 1295575 | D7: =SUM(Jan!D7, Feb!D7, Mar!D7) -> 1649057.2 | E7: =IF(AND(ISNUMBER(C7),ISNUMBER(D7)), C7-D7, "") -> -353482.2 | F7: =IFERROR(E7/D7, "") -> -0.21435412 | G7: =SUM(Jan!G7, Feb!G7, Mar!G7) -> 1587877 | H7: =SUM(Jan!H7, Feb!H7, Mar!H7) -> -292302 | I7: =IFERROR(H7/G7, "") -> -0.18408353
A8: Minoa - Clemons Rd | B8: NY | C8: =SUM(Jan!C8, Feb!C8, Mar!C8) -> 629215.62 | D8: =SUM(Jan!D8, Feb!D8, Mar!D8) -> 845731.6 | E8: =IF(AND(ISNUMBER(C8),ISNUMBER(D8)), C8-D8, "") -> -216515.97 | F8: =IFERROR(E8/D8, "") -> -0.25601027 | G8: =SUM(Jan!G8, Feb!G8, Mar!G8) -> 914112.3 | H8: =SUM(Jan!H8, Feb!H8, Mar!H8) -> -284896.68 | I8: =IFERROR(H8/G8, "") -> -0.31166485
A9: Manchester - Western | B9: ME | C9: =SUM(Jan!C9, Feb!C9, Mar!C9) -> 174947.81 | D9: =SUM(Jan!D9, Feb!D9, Mar!D9) -> 0 | E9: =IF(AND(ISNUMBER(C9),ISNUMBER(D9)), C9-D9, "") -> 174947.81 | F9: =IFERROR(E9/D9, "") | G9: =SUM(Jan!G9, Feb!G9, Mar!G9) -> 0 | H9: =SUM(Jan!H9, Feb!H9, Mar!H9) -> 174947.81 | I9: =IFERROR(H9/G9, "")
A10: Batavia - Pike Rd | B10: NY | C10: =SUM(Jan!C10, Feb!C10, Mar!C10) -> 768410.88 | D10: =SUM(Jan!D10, Feb!D10, Mar!D10) -> 975809.7 | E10: =IF(AND(ISNUMBER(C10),ISNUMBER(D10)), C10-D10, "") -> -207398.82 | F10: =IFERROR(E10/D10, "") -> -0.21254024 | G10: =SUM(Jan!G10, Feb!G10, Mar!G10) -> 999612 | H10: =SUM(Jan!H10, Feb!H10, Mar!H10) -> -231201.12 | I10: =IFERROR(H10/G10, "") -> -0.23129087
A11: Slayton A & B | B11: NY | C11: =SUM(Jan!C11, Feb!C11, Mar!C11) -> 1787409 | D11: =SUM(Jan!D11, Feb!D11, Mar!D11) -> 2241667.2 | E11: =IF(AND(ISNUMBER(C11),ISNUMBER(D11)), C11-D11, "") -> -454258.2 | F11: =IFERROR(E11/D11, "") -> -0.20264301 | G11: =SUM(Jan!G11, Feb!G11, Mar!G11) -> 2066288.6 | H11: =SUM(Jan!H11, Feb!H11, Mar!H11) -> -278879.6 | I11: =IFERROR(H11/G11, "") -> -0.13496643
A12: Batavia - Alexander Rd | B12: NY | C12: =SUM(Jan!C12, Feb!C12, Mar!C12) -> 412623.6 | D12: =SUM(Jan!D12, Feb!D12, Mar!D12) -> 584711.9 | E12: =IF(AND(ISNUMBER(C12),ISNUMBER(D12)), C12-D12, "") -> -172088.3 | F12: =IFERROR(E12/D12, "") -> -0.29431298 | G12: =SUM(Jan!G12, Feb!G12, Mar!G12) -> 539206.5 | H12: =SUM(Jan!H12, Feb!H12, Mar!H12) -> -126582.9 | I12: =IFERROR(H12/G12, "") -> -0.23475774
A13: NC: Gibson – Henry Gibson Solar | B13: NC | C13: =SUM(Jan!C13, Feb!C13, Mar!C13) -> 1601858 | D13: =SUM(Jan!D13, Feb!D13, Mar!D13) -> 1870367.4 | E13: =IF(AND(ISNUMBER(C13),ISNUMBER(D13)), C13-D13, "") -> -268509.4 | F13: =IFERROR(E13/D13, "") -> -0.14355971 | G13: =SUM(Jan!G13, Feb!G13, Mar!G13) -> 1679126 | H13: =SUM(Jan!H13, Feb!H13, Mar!H13) -> -77268 | I13: =IFERROR(H13/G13, "") -> -0.046016797
A14: Bangor - Pushaw | B14: ME | C14: =SUM(Jan!C14, Feb!C14, Mar!C14) -> 857094 | D14: =SUM(Jan!D14, Feb!D14, Mar!D14) -> 1399739.5 | E14: =IF(AND(ISNUMBER(C14),ISNUMBER(D14)), C14-D14, "") -> -542645.46 | F14: =IFERROR(E14/D14, "") -> -0.38767605 | G14: =SUM(Jan!G14, Feb!G14, Mar!G14) -> 1519605 | H14: =SUM(Jan!H14, Feb!H14, Mar!H14) -> -662510.97 | I14: =IFERROR(H14/G14, "") -> -0.43597579

Sheet 2nd Qtr
A1: {=portfolio} -> Renewable Properties | D1: 2nd Quarter Actual v. Expected | G1: 2nd Quarter Actual v. Forecasted
A2: Total | C2: =SUM(C4:C80) -> 17335160 | D2: =SUM(D4:D80) -> 18317294 | E2: =C2-D2 -> -982133.38 | F2: =IFERROR(E2/D2, 0) -> -0.053617822 | G2: =SUM(G4:G80) -> 21126873 | H2: =C2-G2 -> -3791713.1 | I2: =IFERROR(H2/G2, 0) -> -0.17947346
A3: Site | B3: State | C3: Actual | D3: Expected | E3: Delta | F3: % | G3: Forecasted | H3: Delta | I3: %
A4: {=Sites[Site]} -> Cedar Swamp Rd | B4: {=Sites[State]} -> MA | C4: =SUM(Apr!C4, May!C4, Jun!C4) -> 230670 | D4: =SUM(Apr!D4, May!D4, Jun!D4) -> 218073.51 | E4: =IF(AND(ISNUMBER(C4),ISNUMBER(D4)), C4-D4, "") -> 12596.49 | F4: =IFERROR(E4/D4, "") -> 0.057762587 | G4: =SUM(Apr!G4, May!G4, Jun!G4) -> 292400.5 | H4: =SUM(Apr!H4, May!H4, Jun!H4) -> -61730.5 | I4: =IFERROR(H4/G4, "") -> -0.21111626
A5: Bullis | B5: NY | C5: =SUM(Apr!C5, May!C5, Jun!C5) -> 2200368 | D5: =SUM(Apr!D5, May!D5, Jun!D5) -> 2131826.4 | E5: =IF(AND(ISNUMBER(C5),ISNUMBER(D5)), C5-D5, "") -> 68541.6 | F5: =IFERROR(E5/D5, "") -> 0.032151586 | G5: =SUM(Apr!G5, May!G5, Jun!G5) -> 2867711.1 | H5: =SUM(Apr!H5, May!H5, Jun!H5) -> -667343.1 | I5: =IFERROR(H5/G5, "") -> -0.23270932
A6: Rock Island | B6: NY | C6: =SUM(Apr!C6, May!C6, Jun!C6) -> 2082820.5 | D6: =SUM(Apr!D6, May!D6, Jun!D6) -> 2174807.4 | E6: =IF(AND(ISNUMBER(C6),ISNUMBER(D6)), C6-D6, "") -> -91986.9 | F6: =IFERROR(E6/D6, "") -> -0.042296573 | G6: =SUM(Apr!G6, May!G6, Jun!G6) -> 2382636.1 | H6: =SUM(Apr!H6, May!H6, Jun!H6) -> -299815.6 | I6: =IFERROR(H6/G6, "") -> -0.12583357
A7: Winslow - Roderick | B7: ME | C7: =SUM(Apr!C7, May!C7, Jun!C7) -> 1342729 | D7: =SUM(Apr!D7, May!D7, Jun!D7) -> 1374298.2 | E7: =IF(AND(ISNUMBER(C7),ISNUMBER(D7)), C7-D7, "") -> -31569.16 | F7: =IFERROR(E7/D7, "") -> -0.022971114 | G7: =SUM(Apr!G7, May!G7, Jun!G7) -> 1573938 | H7: =SUM(Apr!H7, May!H7, Jun!H7) -> -231209 | I7: =IFERROR(H7/G7, "") -> -0.14689842
A8: Minoa - Clemons Rd | B8: NY | C8: =SUM(Apr!C8, May!C8, Jun!C8) -> 1308172.8 | D8: =SUM(Apr!D8, May!D8, Jun!D8) -> 1504589.8 | E8: =IF(AND(ISNUMBER(C8),ISNUMBER(D8)), C8-D8, "") -> -196417.05 | F8: =IFERROR(E8/D8, "") -> -0.13054525 | G8: =SUM(Apr!G8, May!G8, Jun!G8) -> 1760486.8 | H8: =SUM(Apr!H8, May!H8, Jun!H8) -> -452314.05 | I8: =IFERROR(H8/G8, "") -> -0.25692556
A9: Manchester - Western | B9: ME | C9: =SUM(Apr!C9, May!C9, Jun!C9) -> 306860.19 | D9: =SUM(Apr!D9, May!D9, Jun!D9) -> 119325.8 | E9: =IF(AND(ISNUMBER(C9),ISNUMBER(D9)), C9-D9, "") -> 187534.39 | F9: =IFERROR(E9/D9, "") -> 1.5716164 | G9: =SUM(Apr!G9, May!G9, Jun!G9) -> 332824.7 | H9: =SUM(Apr!H9, May!H9, Jun!H9) -> -25964.512 | I9: =IFERROR(H9/G9, "") -> -0.078012577
A10: Batavia - Pike Rd | B10: NY | C10: =SUM(Apr!C10, May!C10, Jun!C10) -> 1601331 | D10: =SUM(Apr!D10, May!D10, Jun!D10) -> 1637420.8 | E10: =IF(AND(ISNUMBER(C10),ISNUMBER(D10)), C10-D10, "") -> -36089.8 | F10: =IFERROR(E10/D10, "") -> -0.022040639 | G10: =SUM(Apr!G10, May!G10, Jun!G10) -> 1898336.7 | H10: =SUM(Apr!H10, May!H10, Jun!H10) -> -297005.7 | I10: =IFERROR(H10/G10, "") -> -0.15645575
A11: Slayton A & B | B11: NY | C11: =SUM(Apr!C11, May!C11, Jun!C11) -> 4066592 | D11: =SUM(Apr!D11, May!D11, Jun!D11) -> 4333834 | E11: =IF(AND(ISNUMBER(C11),ISNUMBER(D11)), C11-D11, "") -> -267242 | F11: =IFERROR(E11/D11, "") -> -0.061664106 | G11: =SUM(Apr!G11, May!G11, Jun!G11) -> 4407054 | H11: =SUM(Apr!H11, May!H11, Jun!H11) -> -340462 | I11: =IFERROR(H11/G11, "") -> -0.077253875
A12: Batavia - Alexander Rd | B12: NY | C12: =SUM(Apr!C12, May!C12, Jun!C12) -> 905518.85 | D12: =SUM(Apr!D12, May!D12, Jun!D12) -> 1020100.9 | E12: =IF(AND(ISNUMBER(C12),ISNUMBER(D12)), C12-D12, "") -> -114582.05 | F12: =IFERROR(E12/D12, "") -> -0.11232423 | G12: =SUM(Apr!G12, May!G12, Jun!G12) -> 1039419.3 | H12: =SUM(Apr!H12, May!H12, Jun!H12) -> -133900.45 | I12: =IFERROR(H12/G12, "") -> -0.12882236
A13: NC: Gibson – Henry Gibson Solar | B13: NC | C13: =SUM(Apr!C13, May!C13, Jun!C13) -> 2078191 | D13: =SUM(Apr!D13, May!D13, Jun!D13) -> 2539787.8 | E13: =IF(AND(ISNUMBER(C13),ISNUMBER(D13)), C13-D13, "") -> -461596.8 | F13: =IFERROR(E13/D13, "") -> -0.18174621 | G13: =SUM(Apr!G13, May!G13, Jun!G13) -> 2632997.2 | H13: =SUM(Apr!H13, May!H13, Jun!H13) -> -554806.2 | I13: =IFERROR(H13/G13, "") -> -0.2107128
A14: Bangor - Pushaw | B14: ME | C14: =SUM(Apr!C14, May!C14, Jun!C14) -> 1211907 | D14: =SUM(Apr!D14, May!D14, Jun!D14) -> 1263229.1 | E14: =IF(AND(ISNUMBER(C14),ISNUMBER(D14)), C14-D14, "") -> -51322.1 | F14: =IFERROR(E14/D14, "") -> -0.040627706 | G14: =SUM(Apr!G14, May!G14, Jun!G14) -> 1939069 | H14: =SUM(Apr!H14, May!H14, Jun!H14) -> -727162 | I14: =IFERROR(H14/G14, "") -> -0.37500574

Sheet 3rd Qtr
A1: {=portfolio} -> Renewable Properties | D1: 3rd Quarter Actual v. Expected | G1: 3rd Quarter Actual v. Forecasted
A2: Total | C2: =SUM(C4:C80) -> 20663235 | D2: =SUM(D4:D80) -> 23704263 | E2: =C2-D2 -> -3041028.7 | F2: =IFERROR(E2/D2, 0) -> -0.12829037 | G2: =SUM(G4:G80) -> 24809936 | H2: =C2-G2 -> -4146701.1 | I2: =IFERROR(H2/G2, 0) -> -0.16713873
A3: Site | B3: State | C3: Actual | D3: Expected | E3: Delta | F3: % | G3: Forecasted | H3: Delta | I3: %
A4: {=Sites[Site]} -> Cedar Swamp Rd | B4: {=Sites[State]} -> MA | C4: =SUM(Jul!C4, Aug!C4, Sep!C4) -> 377110 | D4: =SUM(Jul!D4, Aug!D4, Sep!D4) -> 348432.38 | E4: =IF(AND(ISNUMBER(C4),ISNUMBER(D4)), C4-D4, "") -> 28677.619 | F4: =IFERROR(E4/D4, "") -> 0.08230469 | G4: =SUM(Jul!G4, Aug!G4, Sep!G4) -> 442643.89 | H4: =SUM(Jul!H4, Aug!H4, Sep!H4) -> -65533.887 | I4: =IFERROR(H4/G4, "") -> -0.14805104
A5: Bullis | B5: NY | C5: =SUM(Jul!C5, Aug!C5, Sep!C5) -> 2507081 | D5: =SUM(Jul!D5, Aug!D5, Sep!D5) -> 2447788.2 | E5: =IF(AND(ISNUMBER(C5),ISNUMBER(D5)), C5-D5, "") -> 59292.8 | F5: =IFERROR(E5/D5, "") -> 0.024223011 | G5: =SUM(Jul!G5, Aug!G5, Sep!G5) -> 2870410.9 | H5: =SUM(Jul!H5, Aug!H5, Sep!H5) -> -363329.9 | I5: =IFERROR(H5/G5, "") -> -0.12657766
A6: Rock Island | B6: NY | C6: =SUM(Jul!C6, Aug!C6, Sep!C6) -> 2041963 | D6: =SUM(Jul!D6, Aug!D6, Sep!D6) -> 2449960.4 | E6: =IF(AND(ISNUMBER(C6),ISNUMBER(D6)), C6-D6, "") -> -407997.4 | F6: =IFERROR(E6/D6, "") -> -0.16653224 | G6: =SUM(Jul!G6, Aug!G6, Sep!G6) -> 4991919.2 | H6: =SUM(Jul!H6, Aug!H6, Sep!H6) -> -2949956.2 | I6: =IFERROR(H6/G6, "") -> -0.5909463
A7: Winslow - Roderick | B7: ME | C7: =SUM(Jul!C7, Aug!C7, Sep!C7) -> 2388720 | D7: =SUM(Jul!D7, Aug!D7, Sep!D7) -> 2620290.4 | E7: =IF(AND(ISNUMBER(C7),ISNUMBER(D7)), C7-D7, "") -> -231570.43 | F7: =IFERROR(E7/D7, "") -> -0.088375865 | G7: =SUM(Jul!G7, Aug!G7, Sep!G7) -> 2353795.6 | H7: =SUM(Jul!H7, Aug!H7, Sep!H7) -> 34924.42 | I7: =IFERROR(H7/G7, "") -> 0.014837491
A8: Minoa - Clemons Rd | B8: NY | C8: =SUM(Jul!C8, Aug!C8, Sep!C8) -> 1658917.8 | D8: =SUM(Jul!D8, Aug!D8, Sep!D8) -> 1940181.1 | E8: =IF(AND(ISNUMBER(C8),ISNUMBER(D8)), C8-D8, "") -> -281263.37 | F8: =IFERROR(E8/D8, "") -> -0.14496759 | G8: =SUM(Jul!G8, Aug!G8, Sep!G8) -> 1385535.1 | H8: =SUM(Jul!H8, Aug!H8, Sep!H8) -> 273382.63 | I8: =IFERROR(H8/G8, "") -> 0.19731194
A9: Manchester - Western | B9: ME | C9: =SUM(Jul!C9, Aug!C9, Sep!C9) -> 358185.81 | D9: =SUM(Jul!D9, Aug!D9, Sep!D9) -> 380858.28 | E9: =IF(AND(ISNUMBER(C9),ISNUMBER(D9)), C9-D9, "") -> -22672.467 | F9: =IFERROR(E9/D9, "") -> -0.059529931 | G9: =SUM(Jul!G9, Aug!G9, Sep!G9) -> 338067.22 | H9: =SUM(Jul!H9, Aug!H9, Sep!H9) -> 20118.592 | I9: =IFERROR(H9/G9, "") -> 0.059510626
A10: Batavia - Pike Rd | B10: NY | C10: =SUM(Jul!C10, Aug!C10, Sep!C10) -> 1720325.4 | D10: =SUM(Jul!D10, Aug!D10, Sep!D10) -> 1734045.4 | E10: =IF(AND(ISNUMBER(C10),ISNUMBER(D10)), C10-D10, "") -> -13720.093 | F10: =IFERROR(E10/D10, "") -> -0.0079121877 | G10: =SUM(Jul!G10, Aug!G10, Sep!G10) -> 1828409.1 | H10: =SUM(Jul!H10, Aug!H10, Sep!H10) -> -108083.7 | I10: =IFERROR(H10/G10, "") -> -0.05911352
A11: Slayton A & B | B11: NY | C11: =SUM(Jul!C11, Aug!C11, Sep!C11) -> 3890108 | D11: =SUM(Jul!D11, Aug!D11, Sep!D11) -> 4991361.3 | E11: =IF(AND(ISNUMBER(C11),ISNUMBER(D11)), C11-D11, "") -> -1101253.3 | F11: =IFERROR(E11/D11, "") -> -0.22063186 | G11: =SUM(Jul!G11, Aug!G11, Sep!G11) -> 4190656.4 | H11: =SUM(Jul!H11, Aug!H11, Sep!H11) -> -300548.44 | I11: =IFERROR(H11/G11, "") -> -0.071718702
A12: Batavia - Alexander Rd | B12: NY | C12: =SUM(Jul!C12, Aug!C12, Sep!C12) -> 1002641.8 | D12: =SUM(Jul!D12, Aug!D12, Sep!D12) -> 1183189.3 | E12: =IF(AND(ISNUMBER(C12),ISNUMBER(D12)), C12-D12, "") -> -180547.53 | F12: =IFERROR(E12/D12, "") -> -0.15259395 | G12: =SUM(Jul!G12, Aug!G12, Sep!G12) -> 1035998.2 | H12: =SUM(Jul!H12, Aug!H12, Sep!H12) -> -33356.46 | I12: =IFERROR(H12/G12, "") -> -0.032197411
A13: NC: Gibson – Henry Gibson Solar | B13: NC | C13: =SUM(Jul!C13, Aug!C13, Sep!C13) -> 2820248 | D13: =SUM(Jul!D13, Aug!D13, Sep!D13) -> 3352789 | E13: =IF(AND(ISNUMBER(C13),ISNUMBER(D13)), C13-D13, "") -> -532541 | F13: =IFERROR(E13/D13, "") -> -0.15883523 | G13: =SUM(Jul!G13, Aug!G13, Sep!G13) -> 3426970 | H13: =SUM(Jul!H13, Aug!H13, Sep!H13) -> -606722 | I13: =IFERROR(H13/G13, "") -> -0.17704328
A14: Bangor - Pushaw | B14: ME | C14: =SUM(Jul!C14, Aug!C14, Sep!C14) -> 1897934 | D14: =SUM(Jul!D14, Aug!D14, Sep!D14) -> 2255367.5 | E14: =IF(AND(ISNUMBER(C14),ISNUMBER(D14)), C14-D14, "") -> -357433.5 | F14: =IFERROR(E14/D14, "") -> -0.15848127 | G14: =SUM(Jul!G14, Aug!G14, Sep!G14) -> 1945530.2 | H14: =SUM(Jul!H14, Aug!H14, Sep!H14) -> -47596.2 | I14: =IFERROR(H14/G14, "") -> -0.024464385

Sheet 4th Qtr
A1: {=portfolio} -> Renewable Properties | D1: 4th Quarter Actual v. Expected | G1: 4th Quarter Actual v. Forecasted
A2: Total | C2: =SUM(C4:C80) -> 8342695.6 | D2: =SUM(D4:D80) -> 10384306 | E2: =C2-D2 -> -2041610.2 | F2: =IFERROR(E2/D2, 0) -> -0.19660536 | G2: =SUM(G4:G80) -> 9525515.4 | H2: =C2-G2 -> -1182819.8 | I2: =IFERROR(H2/G2, 0) -> -0.12417384
A3: Site | B3: State | C3: Actual | D3: Expected | E3: Delta | F3: % | G3: Forecasted | H3: Delta | I3: %
A4: {=Sites[Site]} -> Cedar Swamp Rd | B4: {=Sites[State]} -> MA | C4: =SUM(Oct!C4, Nov!C4, Dec!C4) -> 197142 | D4: =SUM(Oct!D4, Nov!D4, Dec!D4) -> 202570.46 | E4: =IF(AND(ISNUMBER(C4),ISNUMBER(D4)), C4-D4, "") -> -5428.46 | F4: =IFERROR(E4/D4, "") -> -0.026797886 | G4: =SUM(Oct!G4, Nov!G4, Dec!G4) -> 170784.12 | H4: =SUM(Oct!H4, Nov!H4, Dec!H4) -> 26357.88 | I4: =IFERROR(H4/G4, "") -> 0.15433449
A5: Bullis | B5: NY | C5: =SUM(Oct!C5, Nov!C5, Dec!C5) -> 801286 | D5: =SUM(Oct!D5, Nov!D5, Dec!D5) -> 879334.5 | E5: =IF(AND(ISNUMBER(C5),ISNUMBER(D5)), C5-D5, "") -> -78048.5 | F5: =IFERROR(E5/D5, "") -> -0.088758601 | G5: =SUM(Oct!G5, Nov!G5, Dec!G5) -> 940864.4 | H5: =SUM(Oct!H5, Nov!H5, Dec!H5) -> -139578.4 | I5: =IFERROR(H5/G5, "") -> -0.14835124
A6: Rock Island | B6: NY | C6: =SUM(Oct!C6, Nov!C6, Dec!C6) -> 777575 | D6: =SUM(Oct!D6, Nov!D6, Dec!D6) -> 927196.2 | E6: =IF(AND(ISNUMBER(C6),ISNUMBER(D6)), C6-D6, "") -> -149621.2 | F6: =IFERROR(E6/D6, "") -> -0.16136951 | G6: =SUM(Oct!G6, Nov!G6, Dec!G6) -> 846390.4 | H6: =SUM(Oct!H6, Nov!H6, Dec!H6) -> -68815.4 | I6: =IFERROR(H6/G6, "") -> -0.081304561
A7: Winslow - Roderick | B7: ME | C7: =SUM(Oct!C7, Nov!C7, Dec!C7) -> 1032329 | D7: =SUM(Oct!D7, Nov!D7, Dec!D7) -> 1460564.9 | E7: =IF(AND(ISNUMBER(C7),ISNUMBER(D7)), C7-D7, "") -> -428235.9 | F7: =IFERROR(E7/D7, "") -> -0.29319882 | G7: =SUM(Oct!G7, Nov!G7, Dec!G7) -> 1098700 | H7: =SUM(Oct!H7, Nov!H7, Dec!H7) -> -66371 | I7: =IFERROR(H7/G7, "") -> -0.060408665
A8: Minoa - Clemons Rd | B8: NY | C8: =SUM(Oct!C8, Nov!C8, Dec!C8) -> 513816.5 | D8: =SUM(Oct!D8, Nov!D8, Dec!D8) -> 683861.9 | E8: =IF(AND(ISNUMBER(C8),ISNUMBER(D8)), C8-D8, "") -> -170045.4 | F8: =IFERROR(E8/D8, "") -> -0.24865459 | G8: =SUM(Oct!G8, Nov!G8, Dec!G8) -> 581105.1 | H8: =SUM(Oct!H8, Nov!H8, Dec!H8) -> -67288.6 | I8: =IFERROR(H8/G8, "") -> -0.1157942
A9: Manchester - Western | B9: ME | C9: =SUM(Oct!C9, Nov!C9, Dec!C9) -> 158914 | D9: =SUM(Oct!D9, Nov!D9, Dec!D9) -> 212910.94 | E9: =IF(AND(ISNUMBER(C9),ISNUMBER(D9)), C9-D9, "") -> -53996.94 | F9: =IFERROR(E9/D9, "") -> -0.2536128 | G9: =SUM(Oct!G9, Nov!G9, Dec!G9) -> 157162.06 | H9: =SUM(Oct!H9, Nov!H9, Dec!H9) -> 1751.94 | I9: =IFERROR(H9/G9, "") -> 0.011147347
A10: Batavia - Pike Rd | B10: NY | C10: =SUM(Oct!C10, Nov!C10, Dec!C10) -> 661152.65 | D10: =SUM(Oct!D10, Nov!D10, Dec!D10) -> 726715.8 | E10: =IF(AND(ISNUMBER(C10),ISNUMBER(D10)), C10-D10, "") -> -65563.155 | F10: =IFERROR(E10/D10, "") -> -0.090218425 | G10: =SUM(Oct!G10, Nov!G10, Dec!G10) -> 683074.5 | H10: =SUM(Oct!H10, Nov!H10, Dec!H10) -> -21921.855 | I10: =IFERROR(H10/G10, "") -> -0.03209292
A11: Slayton A & B | B11: NY | C11: =SUM(Oct!C11, Nov!C11, Dec!C11) -> 1570717 | D11: =SUM(Oct!D11, Nov!D11, Dec!D11) -> 1786438.4 | E11: =IF(AND(ISNUMBER(C11),ISNUMBER(D11)), C11-D11, "") -> -215721.4 | F11: =IFERROR(E11/D11, "") -> -0.12075502 | G11: =SUM(Oct!G11, Nov!G11, Dec!G11) -> 1389441.2 | H11: =SUM(Oct!H11, Nov!H11, Dec!H11) -> 181275.8 | I11: =IFERROR(H11/G11, "") -> 0.13046669
A12: Batavia - Alexander Rd | B12: NY | C12: =SUM(Oct!C12, Nov!C12, Dec!C12) -> 334471.5 | D12: =SUM(Oct!D12, Nov!D12, Dec!D12) -> 461554.45 | E12: =IF(AND(ISNUMBER(C12),ISNUMBER(D12)), C12-D12, "") -> -127082.95 | F12: =IFERROR(E12/D12, "") -> -0.27533685 | G12: =SUM(Oct!G12, Nov!G12, Dec!G12) -> 354340.67 | H12: =SUM(Oct!H12, Nov!H12, Dec!H12) -> -19869.17 | I12: =IFERROR(H12/G12, "") -> -0.056073637
A13: NC: Gibson – Henry Gibson Solar | B13: NC | C13: =SUM(Oct!C13, Nov!C13, Dec!C13) -> 1486179 | D13: =SUM(Oct!D13, Nov!D13, Dec!D13) -> 1968831.2 | E13: =IF(AND(ISNUMBER(C13),ISNUMBER(D13)), C13-D13, "") -> -482652.2 | F13: =IFERROR(E13/D13, "") -> -0.24514656 | G13: =SUM(Oct!G13, Nov!G13, Dec!G13) -> 2222144 | H13: =SUM(Oct!H13, Nov!H13, Dec!H13) -> -735965 | I13: =IFERROR(H13/G13, "") -> -0.33119591
A14: Bangor - Pushaw | B14: ME | C14: =SUM(Oct!C14, Nov!C14, Dec!C14) -> 809113 | D14: =SUM(Oct!D14, Nov!D14, Dec!D14) -> 1074327.1 | E14: =IF(AND(ISNUMBER(C14),ISNUMBER(D14)), C14-D14, "") -> -265214.1 | F14: =IFERROR(E14/D14, "") -> -0.24686532 | G14: =SUM(Oct!G14, Nov!G14, Dec!G14) -> 1081509 | H14: =SUM(Oct!H14, Nov!H14, Dec!H14) -> -272396 | I14: =IFERROR(H14/G14, "") -> -0.2518666

Sheet Jan
A1: {=portfolio} -> Renewable Properties | D1: January Actual v. Expected | G1: January Actual v. Forecasted
A2: Total | C2: =SUM(C4:C79) -> 1767768.5 | D2: =SUM(D4:D79) -> 2623230.7 | E2: =C2-D2 -> -855462.23 | F2: =IFERROR(E2/D2, 0) -> -0.32611018 | G2: =SUM(G4:G79) -> 2261375.5 | H2: =C2-G2 -> -493607.01 | I2: =IFERROR(H2/G2, 0) -> -0.21827733 | J2: =IF(AND(TODAY()>DATE(2024, 1, 1), COUNTA(Sites[Site])<>(COUNT(C:C)-1)), "Some sites are missing actual data; if new sites were added, make sure they are aligned correctly (including prior months!)", "") -> Some sites are missing actual data; if new sites were added, make sure they are aligned correctly (including prior months!)
A3: Site | B3: State | C3: Actual | D3: Expected | E3: Delta | F3: % | G3: Forecasted | H3: Delta | I3: % | J3: Notes | K3: Service Requests
A4: {=Sites[Site]} -> Cedar Swamp Rd | B4: {=Sites[State]} -> MA | C4: 61046 | D4: 72282.67 | E4: =IF(AND(ISNUMBER(C4),ISNUMBER(D4)), C4-D4, "") -> -11236.67 | F4: =IFERROR(E4/D4, "") -> -0.15545455 | G4: 41663.38 | H4: =IF(AND(ISNUMBER(C4),ISNUMBER(G4)), C4-G4, "") -> 19382.62 | I4: =IFERROR(H4/G4, "") -> 0.46521958
A5: Bullis | B5: NY | C5: 179917 | D5: 269796.6 | E5: =IF(AND(ISNUMBER(C5),ISNUMBER(D5)), C5-D5, "") -> -89879.6 | F5: =IFERROR(E5/D5, "") -> -0.33313837 | G5: 264056.9 | H5: =IF(AND(ISNUMBER(C5),ISNUMBER(G5)), C5-G5, "") -> -84139.9 | I5: =IFERROR(H5/G5, "") -> -0.31864307 | J5: 1.Site tripped offline at 19:46 on 01/25 due to recloser trip and again back online on 10:45am on 01/26 | K5: 1.SR095981
A6: Rock Island | B6: NY | C6: 230466.5 | D6: 342985.3 | E6: =IF(AND(ISNUMBER(C6),ISNUMBER(D6)), C6-D6, "") -> -112518.8 | F6: =IFERROR(E6/D6, "") -> -0.32805721 | G6: 246331.8 | H6: =IF(AND(ISNUMBER(C6),ISNUMBER(G6)), C6-G6, "") -> -15865.3 | I6: =IFERROR(H6/G6, "") -> -0.06440622 | J6: 1.Low generation due to weather/snow.
A7: Winslow - Roderick | B7: ME | C7: 361423 | D7: 473366.7 | E7: =IF(AND(ISNUMBER(C7),ISNUMBER(D7)), C7-D7, "") -> -111943.7 | F7: =IFERROR(E7/D7, "") -> -0.2364841 | G7: 385109 | H7: =IF(AND(ISNUMBER(C7),ISNUMBER(G7)), C7-G7, "") -> -23686 | I7: =IFERROR(H7/G7, "") -> -0.061504665
A8: Minoa - Clemons Rd | B8: NY | C8: 128703.75 | D8: 206281.4 | E8: =IF(AND(ISNUMBER(C8),ISNUMBER(D8)), C8-D8, "") -> -77577.65 | F8: =IFERROR(E8/D8, "") -> -0.37607681 | G8: 191393.5 | H8: =IF(AND(ISNUMBER(C8),ISNUMBER(G8)), C8-G8, "") -> -62689.75 | I8: =IFERROR(H8/G8, "") -> -0.32754378 | J8: 1.Site tripped offline at 04:45 on 01/05 due to SEL tripped offline later technician was able to re-energize the site on 12:45pm on 01/06 2. Tracker TCU 39 is not configured after being replaced on 12/16 and requires further troubleshooting with Suntrack. | K8: 1.SR095317 2.SR095762
A9: Manchester - Western | B9: ME | C9: 47584.812 | D9: 0 | E9: =IF(AND(ISNUMBER(C9),ISNUMBER(D9)), C9-D9, "") -> 47584.812 | F9: =IFERROR(E9/D9, "") | G9: 0 | H9: =IF(AND(ISNUMBER(C9),ISNUMBER(G9)), C9-G9, "") -> 47584.812 | I9: =IFERROR(H9/G9, "")
A10: Batavia - Pike Rd | B10: NY | C10: 159955.82 | D10: 246837.6 | E10: =IF(AND(ISNUMBER(C10),ISNUMBER(D10)), C10-D10, "") -> -86881.776 | F10: =IFERROR(E10/D10, "") -> -0.3519795 | G10: 219320.6 | H10: =IF(AND(ISNUMBER(C10),ISNUMBER(G10)), C10-G10, "") -> -59364.776 | I10: =IFERROR(H10/G10, "") -> -0.27067579 | J10: 1.Site was taken offline for replacing the transformer fuses by United power on 01/22 from 14:54 to 15:41. 2.Tracker 11 has been stuck and reporting "Motor overcurrent detected" on 01/09 technician was able to blocking & alarm and trackers are back online at 10:30 on 01/28 | K10: 1.SR094826 2.SR095434
A11: Slayton A & B | B11: NY | C11: 353338 | D11: 494949.8 | E11: =IF(AND(ISNUMBER(C11),ISNUMBER(D11)), C11-D11, "") -> -141611.8 | F11: =IFERROR(E11/D11, "") -> -0.28611346 | G11: 398835.4 | H11: =IF(AND(ISNUMBER(C11),ISNUMBER(G11)), C11-G11, "") -> -45497.4 | I11: =IFERROR(H11/G11, "") -> -0.11407563 | J11: 1.Low generation due to weather/snow.
A12: Batavia - Alexander Rd | B12: NY | C12: 75534.582 | D12: 136027.1 | E12: =IF(AND(ISNUMBER(C12),ISNUMBER(D12)), C12-D12, "") -> -60492.518 | F12: =IFERROR(E12/D12, "") -> -0.44470931 | G12: 110310.9 | H12: =IF(AND(ISNUMBER(C12),ISNUMBER(G12)), C12-G12, "") -> -34776.318 | I12: =IFERROR(H12/G12, "") -> -0.31525731 | J12: 1.Inverter 10 has tripped at 11:45am on 01/10 while United renewables was onsite later technician has brought inverter back online on 01/14 at 11:15 2.Site was taken offline from 08:15am to 15:00 on 01/23 by Asplundh Electrical for transformer testing. 3.All trackers are no tracking due to Overcurrent and snow alarm on 01/24. | K12: 1.SR095486 2.SR095884 3.SR095924
A13: NC: Gibson – Henry Gibson Solar | B13: NC | E13: =IF(AND(ISNUMBER(C13),ISNUMBER(D13)), C13-D13, "") | F13: =IFERROR(E13/D13, "") | H13: =IF(AND(ISNUMBER(C13),ISNUMBER(G13)), C13-G13, "") | I13: =IFERROR(H13/G13, "")
A14: Bangor - Pushaw | B14: ME | C14: 169799 | D14: 380703.53 | E14: =IF(AND(ISNUMBER(C14),ISNUMBER(D14)), C14-D14, "") -> -210904.53 | F14: =IFERROR(E14/D14, "") -> -0.55398627 | G14: 404354 | H14: =IF(AND(ISNUMBER(C14),ISNUMBER(G14)), C14-G14, "") -> -234555 | I14: =IFERROR(H14/G14, "") -> -0.5800734 | J14: 1. Low production due to snow/rain.

Sheet Feb
A1: {=portfolio} -> Renewable Properties | D1: February Actual v. Expected | G1: February Actual v. Forecasted
A2: Total | C2: =SUM(C5:C80) -> 2742058 | D2: =SUM(D4:D80) -> 4023644.7 | E2: =C2-D2 -> -1281586.6 | F2: =IFERROR(E2/D2, 0) -> -0.31851387 | G2: =SUM(G4:G80) -> 3948929.3 | H2: =C2-G2 -> -1206871.3 | I2: =IFERROR(H2/G2, 0) -> -0.30561988 | J2: =IF(AND(TODAY()>DATE(2024, 2, 1), COUNTA(Sites[Site])<>(COUNT(C:C)-1)), "Some sites are missing actual data; if new sites were added, make sure they are aligned correctly (including prior months!)", "")
A3: Site | B3: State | C3: Actual | D3: Expected | E3: Delta | F3: % | G3: Forecasted | H3: Delta | I3: % | J3: Notes | K3: Service Requests
A4: {=Sites[Site]} -> Cedar Swamp Rd | B4: {=Sites[State]} -> MA | C4: 75305 | D4: 82808.46 | E4: =IF(AND(ISNUMBER(C4),ISNUMBER(D4)), C4-D4, "") -> -7503.46 | F4: =IFERROR(E4/D4, "") -> -0.090612239 | G4: 55035.28 | H4: =IF(AND(ISNUMBER(C4),ISNUMBER(G4)), C4-G4, "") -> 20269.72 | I4: =IFERROR(H4/G4, "") -> 0.36830411 | J4: 1. Low generation due to weather/snow.
A5: Bullis | B5: NY | C5: 257310 | D5: 328876.1 | E5: =IF(AND(ISNUMBER(C5),ISNUMBER(D5)), C5-D5, "") -> -71566.1 | F5: =IFERROR(E5/D5, "") -> -0.21760809 | G5: 421521.9 | H5: =IF(AND(ISNUMBER(C5),ISNUMBER(G5)), C5-G5, "") -> -164211.9 | I5: =IFERROR(H5/G5, "") -> -0.38956908 | J5: 1.Site tripped offline at 15:45 on 02/08/25 due to recloser trip and later auto reclosed back online at 19:00 the same day. | K5: 1. SR096532
A6: Rock Island | B6: NY | C6: 290891.5 | D6: 392222 | E6: =IF(AND(ISNUMBER(C6),ISNUMBER(D6)), C6-D6, "") -> -101330.5 | F6: =IFERROR(E6/D6, "") -> -0.25834986 | G6: 387802 | H6: =IF(AND(ISNUMBER(C6),ISNUMBER(G6)), C6-G6, "") -> -96910.5 | I6: =IFERROR(H6/G6, "") -> -0.24989685 | J6: 1.Site tripped offline at 07:45AM on 02/19/25 due to recloser trip and was back online at 9:30AM on 02/21 after technician re-enerzied. | K6: 1. SR097445
A7: Winslow - Roderick | B7: ME | C7: 361591 | D7: 581795.4 | E7: =IF(AND(ISNUMBER(C7),ISNUMBER(D7)), C7-D7, "") -> -220204.4 | F7: =IFERROR(E7/D7, "") -> -0.37849113 | G7: 500603 | H7: =IF(AND(ISNUMBER(C7),ISNUMBER(G7)), C7-G7, "") -> -139012 | I7: =IFERROR(H7/G7, "") -> -0.27768911 | J7: 1. Low generation due to weather/snow.
A8: Minoa - Clemons Rd | B8: NY | C8: 147261.25 | D8: 204792.3 | E8: =IF(AND(ISNUMBER(C8),ISNUMBER(D8)), C8-D8, "") -> -57531.05 | F8: =IFERROR(E8/D8, "") -> -0.28092389 | G8: 282687.4 | H8: =IF(AND(ISNUMBER(C8),ISNUMBER(G8)), C8-G8, "") -> -135426.15 | I8: =IFERROR(H8/G8, "") -> -0.47906681 | J8: 1. Site was taken offline from 09:00 AM on 02/03/25 to 09:45 AM on 02/04/25 by United Renewable Energy to paint the transformer on-site. Site again tripped offline at 14:30 on the same day and came back online at 12:30 on 02/08/25, after the technician swapped the blown transformer fuses for a new type. 2. Tracker TCU 39 was reconfigured and set back to Auto by the technician, and it was operating as expected on 02/27/25. However the tracker was stuck again on 02/28/25. | K8: 1. SR094897 2. SR095762 | L8: SR095762
A9: Manchester - Western | B9: ME | C9: 43938.812 | D9: 0 | E9: =IF(AND(ISNUMBER(C9),ISNUMBER(D9)), C9-D9, "") -> 43938.812 | F9: =IFERROR(E9/D9, "") | G9: 0 | H9: =IF(AND(ISNUMBER(C9),ISNUMBER(G9)), C9-G9, "") -> 43938.812 | I9: =IFERROR(H9/G9, "")
A10: Batavia - Pike Rd | B10: NY | C10: 192004.55 | D10: 293733.3 | E10: =IF(AND(ISNUMBER(C10),ISNUMBER(D10)), C10-D10, "") -> -101728.75 | F10: =IFERROR(E10/D10, "") -> -0.34633032 | G10: 307523.4 | H10: =IF(AND(ISNUMBER(C10),ISNUMBER(G10)), C10-G10, "") -> -115518.85 | I10: =IFERROR(H10/G10, "") -> -0.37564247 | J10: 1. Tracker 11 has been stuck and reporting "Motor overcurrent detected" on 02/06/25 technician was able to blocking & alarm and trackers are back online at 18:15 on 02/10/25. 2. Tracker 11 has been stuck and reporting "Motor overcurrent detected" on 02/11/25 technician was able to blocking & alarm and trackers are back online at 13:00 on 02/12/25. | K10: 1. SR096403 2. SR096696 | L10: SR096696
A11: Slayton A & B | B11: NY | C11: 451738 | D11: 695245.4 | E11: =IF(AND(ISNUMBER(C11),ISNUMBER(D11)), C11-D11, "") -> -243507.4 | F11: =IFERROR(E11/D11, "") -> -0.35024669 | G11: 637509.2 | H11: =IF(AND(ISNUMBER(C11),ISNUMBER(G11)), C11-G11, "") -> -185771.2 | I11: =IFERROR(H11/G11, "") -> -0.2914016 | J11: 1. Site was taken offline from 08:15 AM to 09:15 AM on 02/05/25 by United Renewable Energy to swap out parts of the transformer, and they left the GOAB open at Site A for further work. On 02/06/25, they re-energized the site and brought it back online at 11:30 AM. Additionally, they reset the AC combiner to restore voltage, bringing Inverters A 13-16 back online at 14:30 the same day. 2. Six trackers were stuck on 02/06/25. On 02/07/25, the technician secured the loose connection and found alarms for motor overcurrent. All trackers were inspected and cleared, and they returned to normal operation the same day. 3. Seven trackers were stuck on 02/10/25. On 02/11/25, the technician cleared the fault, and the trackers were operating normally the same day. 4. Multiple trackers were stuck on 02/19/25. On 02/24/25, the technician tightened the fuse holders and cleared the alarms, but further troubleshooting with Suntrack is required. On 02/26/25, the technician cleared all remaining fault alarms except for tracker 132, which requires additional troubleshooting. | K11: 1. SR096326 2. SR096398 3. SR096626 4. SR096935 | L11: SR096398 | M11: SR096626 | N11: SR096935
A12: Batavia - Alexander Rd | B12: NY | C12: 106100.91 | D12: 176053.3 | E12: =IF(AND(ISNUMBER(C12),ISNUMBER(D12)), C12-D12, "") -> -69952.386 | F12: =IFERROR(E12/D12, "") -> -0.39733641 | G12: 167939.4 | H12: =IF(AND(ISNUMBER(C12),ISNUMBER(G12)), C12-G12, "") -> -61838.486 | I12: =IFERROR(H12/G12, "") -> -0.36821905 | J12: 1. Low generation due to weather/snow.
A13: NC: Gibson – Henry Gibson Solar | B13: NC | C13: 689224 | D13: 766019.4 | E13: =IF(AND(ISNUMBER(C13),ISNUMBER(D13)), C13-D13, "") -> -76795.4 | F13: =IFERROR(E13/D13, "") -> -0.10025255 | G13: 707894 | H13: =IF(AND(ISNUMBER(C13),ISNUMBER(G13)), C13-G13, "") -> -18670 | I13: =IFERROR(H13/G13, "") -> -0.026374005 | J13: 1. Inverter 1.21 has been offline throughout the month. To bring it back online, the EPC needs to replace the inverter. 2.Inverter 2.11 tripped offline at 13:45 on 02/22/25 due to a grid phase voltage out of range and remained offline throughout the month. | K13: 1. SR097527 2. SR097650 | L13: SR097650
A14: Bangor - Pushaw | B14: ME | C14: 201998 | D14: 502099 | E14: =IF(AND(ISNUMBER(C14),ISNUMBER(D14)), C14-D14, "") -> -300101 | F14: =IFERROR(E14/D14, "") -> -0.59769289 | G14: 480413.75 | H14: =IF(AND(ISNUMBER(C14),ISNUMBER(G14)), C14-G14, "") -> -278415.75 | I14: =IFERROR(H14/G14, "") -> -0.57953327 | J14: 1. Low production due to snow/rain.

Sheet Mar
A1: {=portfolio} -> Renewable Properties | D1: March Actual v. Expected | G1: March Actual v. Forecasted
A2: Total | C2: =SUM(C4:C80) -> 5272330.9 | D2: =SUM(D4:D80) -> 5674224.5 | E2: =C2-D2 -> -401893.62 | F2: =IFERROR(E2/D2, 0) -> -0.070827937 | G2: =SUM(G4:G80) -> 5919244.4 | H2: =C2-G2 -> -646913.5 | I2: =IFERROR(H2/G2, 0) -> -0.10928988 | J2: =IF(AND(TODAY()>DATE(2024, 3, 1), COUNTA(Sites[Site])<>(COUNT(C:C)-1)), "Some sites are missing actual data; if new sites were added, make sure they are aligned correctly (including prior months!)", "")
A3: Site | B3: State | C3: Actual | D3: Expected | E3: Delta | F3: % | G3: Forecasted | H3: Delta | I3: % | J3: Notes | K3: Service Requests
A4: {=Sites[Site]} -> Cedar Swamp Rd | B4: {=Sites[State]} -> MA | C4: 119421 | D4: 112844.1 | E4: =IF(AND(ISNUMBER(C4),ISNUMBER(D4)), C4-D4, "") -> 6576.9 | F4: =IFERROR(E4/D4, "") -> 0.058283065 | G4: 108945.7 | H4: =IF(AND(ISNUMBER(C4),ISNUMBER(G4)), C4-G4, "") -> 10475.3 | I4: =IFERROR(H4/G4, "") -> 0.096151569 | J4: 1. Site was taken offline from 09:05am to 11:10am on 03/14 as to replace the voltage sensing cable. | K4: 1.SR096338
A5: Bullis | B5: NY | C5: 585414.5 | D5: 582242.9 | E5: =IF(AND(ISNUMBER(C5),ISNUMBER(D5)), C5-D5, "") -> 3171.6 | F5: =IFERROR(E5/D5, "") -> 0.0054472111 | G5: 681849.6 | H5: =IF(AND(ISNUMBER(C5),ISNUMBER(G5)), C5-G5, "") -> -96435.1 | I5: =IFERROR(H5/G5, "") -> -0.14143163 | J5: 1. The site tripped offline at 23:00 EDT on 03/16. On 03/17. The technician performed a reset and closed the recloser. The site was back online from 08:45 AM on 03/17 | K5: 1.SR098647
A6: Rock Island | B6: NY | C6: 530557 | D6: 569957.3 | E6: =IF(AND(ISNUMBER(C6),ISNUMBER(D6)), C6-D6, "") -> -39400.3 | F6: =IFERROR(E6/D6, "") -> -0.069128512 | G6: 616515.3 | H6: =IF(AND(ISNUMBER(C6),ISNUMBER(G6)), C6-G6, "") -> -85958.3 | I6: =IFERROR(H6/G6, "") -> -0.13942606 | J6: 1. The site tripped offline at 10:15 EDT on 03/03. On 03/05, a technician found the SEL and both pad breakers open, closed them, and restored production. The site has been online and producing normally since 13:15 EDT on 03/05 | K6: 1.SR097988
A7: Winslow - Roderick | B7: ME | C7: 572561 | D7: 593895.1 | E7: =IF(AND(ISNUMBER(C7),ISNUMBER(D7)), C7-D7, "") -> -21334.1 | F7: =IFERROR(E7/D7, "") -> -0.035922337 | G7: 702165 | H7: =IF(AND(ISNUMBER(C7),ISNUMBER(G7)), C7-G7, "") -> -129604 | I7: =IFERROR(H7/G7, "") -> -0.1845777 | J7: 1. Site production was low on 03/05, 03/16, 03/17, 03/24 and 03/30 due to bad weather.
A8: Minoa - Clemons Rd | B8: NY | C8: 353250.62 | D8: 434657.9 | E8: =IF(AND(ISNUMBER(C8),ISNUMBER(D8)), C8-D8, "") -> -81407.275 | F8: =IFERROR(E8/D8, "") -> -0.18729045 | G8: 440031.4 | H8: =IF(AND(ISNUMBER(C8),ISNUMBER(G8)), C8-G8, "") -> -86780.775 | I8: =IFERROR(H8/G8, "") -> -0.19721496 | J8: 1. Site tripped offline at 14:25 EDT on 03/05. On 03/06, a technician closed the recloser at 10:15 EDT. Tracker TSU 8 (address 39) was misaligned, deviating. After renergization,the technician adjusted it to match TSU 7, cleared the blocking, and restored proper tracking. 2. USNE technician took the site offline from 11:55am to 15:05 on 03/18 for transformer testing. 3. On 03/20, a technician visited the site to troubleshoot inverter 15's frequent trip events (since 03/17) and trackers 39, 28, and 35. Inverter 15 and two fuses are being RMA'd, with further tracker troubleshooting needed. 4. The Site is experiencing the following tracker issues: NCU-01: Tracker 39 is stuck at -56°. Tracker 28 deviates during morning hours and experiences intermittent failure. NCU-02: Tracker 35 deviates during morning hours and experiences intermittent failure. | K8: 1.SR098176 2.SR098356 3.SR098701 4.SR098775 | L8: SR098356 | M8: SR098701 | N8: SR098775
A9: Manchester - Western | B9: ME | C9: 83424.188 | D9: 0 | E9: =IF(AND(ISNUMBER(C9),ISNUMBER(D9)), C9-D9, "") -> 83424.188 | F9: =IFERROR(E9/D9, "") | G9: 0 | H9: =IF(AND(ISNUMBER(C9),ISNUMBER(G9)), C9-G9, "") -> 83424.188 | I9: =IFERROR(H9/G9, "")
A10: Batavia - Pike Rd | B10: NY | C10: 416450.5 | D10: 435238.8 | E10: =IF(AND(ISNUMBER(C10),ISNUMBER(D10)), C10-D10, "") -> -18788.3 | F10: =IFERROR(E10/D10, "") -> -0.043167797 | G10: 472768 | H10: =IF(AND(ISNUMBER(C10),ISNUMBER(G10)), C10-G10, "") -> -56317.5 | I10: =IFERROR(H10/G10, "") -> -0.11912291 | J10: 1. NCU-01 (120): Tracker Position TCU 11 stuck at -54 degrees from 10:15 EDT on 03/27 | K10: 1.SR098907
A11: Slayton A & B | B11: NY | C11: 982333 | D11: 1051472 | E11: =IF(AND(ISNUMBER(C11),ISNUMBER(D11)), C11-D11, "") -> -69139 | F11: =IFERROR(E11/D11, "") -> -0.065754485 | G11: 1029944 | H11: =IF(AND(ISNUMBER(C11),ISNUMBER(G11)), C11-G11, "") -> -47611 | I11: =IFERROR(H11/G11, "") -> -0.046226785 | J11: 1. NCU-A.01-tracker 132 was stuck on 02/19/25. On 03/10, a technician power-cycled all NCUs, restoring communication except for tracker 132, which had wind damage. Further troubleshooting was needed. On 03/28, a technician cleared faults and aligned all trackers except tracker 132. Inverter A.22 has one string (11) disconnected until tracker repairs are complete 2. Site was de-energized by the USNE technician at 08:45 AM on 03/13 to work on the transformers.Site was Re-energized at 12:00 EDT on 03/13 3. Inverter A.34 is derating 50% during morning hours becuase of the trackers stuck | K11: 1.SR096935,SR098375,SR098777 2.SR097819 | L11: SR098375 | M11: SR098777 | N11: SR097819
A12: Batavia - Alexander Rd | B12: NY | C12: 230988.1 | D12: 272631.5 | E12: =IF(AND(ISNUMBER(C12),ISNUMBER(D12)), C12-D12, "") -> -41643.396 | F12: =IFERROR(E12/D12, "") -> -0.15274609 | G12: 260956.2 | H12: =IF(AND(ISNUMBER(C12),ISNUMBER(G12)), C12-G12, "") -> -29968.096 | I12: =IFERROR(H12/G12, "") -> -0.11483956 | J12: 1.NSU 02 - Tracker 49 motor is stuck at -16.9 degrees on 02/08/25 from 08:45AM from then it started reporting in different values which is impacting Inverter 05 production after mid-day. | K12: 1.SR098763
A13: NC: Gibson – Henry Gibson Solar | B13: NC | C13: 912634 | D13: 1104348 | E13: =IF(AND(ISNUMBER(C13),ISNUMBER(D13)), C13-D13, "") -> -191714 | F13: =IFERROR(E13/D13, "") -> -0.17359926 | G13: 971232 | H13: =IF(AND(ISNUMBER(C13),ISNUMBER(G13)), C13-G13, "") -> -58598 | I13: =IFERROR(H13/G13, "") -> -0.060333679 | J13: 1. Inverter 1.21 was offline from 03/01. On 03/18, a USNE technician replaced it but noted further troubleshooting was needed. The site remained offline until the punch list was completed on 03/19, when it was re-energized at 18:15 EDT. Inverters 1.04, 2.10, and 2.11 are offline due to removed faulty AC combiner fuses. Inverter 1.22 is producing power but not communicating, likely due to a daisy chain issue with the unprogrammed inverter 1.21. 2. Inverter 2.11 was offline from 03/01. On 03/04, a technician found the fault "Out of phase-Occur" and identified a blown fuse. Technician mentioned a fuse replacement is needed, and the inverter will remain offline.On 03/27, a technician replaced the blown fuse and re-powdered AC combiner and inverter2.11 .Inverter 2.11 is back online and producing as expected from 10:25 EDT. 3. Inverter 2.09 tripped offline at 14:30 on 03/24. On 03/27, a technician replaced the blown Phase B fuse and re-powered the inverter. It was back online at 12:00 EDT. 4. Inverters 1.04 and 2.10 went offline after USNE technician's checkout on 03/19 due to faulty AC combiner fuses. On 03/27, a technician found Inverter 2.10 had a damaged insulated fuse stud preventing fuse installation, while Inverter 1.04 was unresponsive and mentioned Both the inverters will remain offline until repaired. 5. Inverter 2.05 tripped offline at 14:15 after a USNE technician check out and remained offline for rest of the month. | K13: 1.SR097527 2.SR097650,SR098979 3.SR098946, SR098979 4.SR098979,SR099163 5.SR099057 | L13: SR097650 | M13: SR098979 | N13: SR098946 | O13: SR098979 | P13: SR098979 | Q13: SR099163 | R13: SR099057
A14: Bangor - Pushaw | B14: ME | C14: 485297 | D14: 516936.93 | E14: =IF(AND(ISNUMBER(C14),ISNUMBER(D14)), C14-D14, "") -> -31639.932 | F14: =IFERROR(E14/D14, "") -> -0.061206561 | G14: 634837.22 | H14: =IF(AND(ISNUMBER(C14),ISNUMBER(G14)), C14-G14, "") -> -149540.22 | I14: =IFERROR(H14/G14, "") -> -0.23555679 | J14: 1. Site production was low on 03/05 to 03/07, 03/16 to 03/17, 03/20 to 03/21, 03/24 to 03/25 and 03/30 to 03/31.

Sheet Apr
A1: {=portfolio} -> Renewable Properties | D1: April Actual v. Expected | G1: April Actual v. Forecasted
A2: Total | C2: =SUM(C4:C80) -> 6111269.2 | D2: =SUM(D4:D80) -> 6474775.4 | E2: =C2-D2 -> -363506.24 | F2: =IFERROR(E2/D2, 0) -> -0.056141907 | G2: =SUM(G4:G80) -> 6741811.7 | H2: =C2-G2 -> -630542.54 | I2: =IFERROR(H2/G2, 0) -> -0.093527165 | J2: =IF(AND(TODAY()>DATE(2024, 4, 1), COUNTA(Sites[Site])<>(COUNT(C:C)-1)), "Some sites are missing actual data; if new sites were added, make sure they are aligned correctly (including prior months!)", "")
A3: Site | B3: State | C3: Actual | D3: Expected | E3: Delta | F3: % | G3: Forecasted | H3: Delta | I3: % | J3: Notes | K3: Service Requests
A4: {=Sites[Site]} -> Cedar Swamp Rd | B4: {=Sites[State]} -> MA | C4: 132729 | D4: 124295.4 | E4: =IF(AND(ISNUMBER(C4),ISNUMBER(D4)), C4-D4, "") -> 8433.6 | F4: =IFERROR(E4/D4, "") -> 0.067851264 | G4: 137919.5 | H4: =IF(AND(ISNUMBER(C4),ISNUMBER(G4)), C4-G4, "") -> -5190.5 | I4: =IFERROR(H4/G4, "") -> -0.037634272 | J4: 1.Inverter 2 started late for production at 13:30 on 04/23 and found inverter DC voltages are high. Inverter 2 tripped offline at 12:30pm on 04/26. Inverter 2 has started for production on 04/27 ,voltages are normalized ,issue got self resolved. | K4: 1.SR100208
A5: Bullis | B5: NY | C5: 716355 | D5: 704002.3 | E5: =IF(AND(ISNUMBER(C5),ISNUMBER(D5)), C5-D5, "") -> 12352.7 | F5: =IFERROR(E5/D5, "") -> 0.017546392 | G5: 820770.1 | H5: =IF(AND(ISNUMBER(C5),ISNUMBER(G5)), C5-G5, "") -> -104415.1 | I5: =IFERROR(H5/G5, "") -> -0.12721601 | J5: 1.Since 03/18/25, Inverter 8 has been derating by ~25–30 kW during high irradiance due to increase in internal temperatures, possibly from a fan fault. On 04/19, a technician found string 6 on CB 8 reading low voltage (1135V vs. 1165V), suggesting a possible bad panel. CB 8 location differs from plans; further troubleshooting is needed. 2.Site tripped offline at 11:33 AM on 04/19 and was back online at 16:30 after the technician closed the relay. | K5: 1.SR099753 2.SR100017 | L5: SR100017
A6: Rock Island | B6: NY | C6: 577733 | D6: 639667.7 | E6: =IF(AND(ISNUMBER(C6),ISNUMBER(D6)), C6-D6, "") -> -61934.7 | F6: =IFERROR(E6/D6, "") -> -0.096823241 | G6: 633812.4 | H6: =IF(AND(ISNUMBER(C6),ISNUMBER(G6)), C6-G6, "") -> -56079.4 | I6: =IFERROR(H6/G6, "") -> -0.088479493 | J6: 1. Site tripped offline at 14:18 on 04/03 and was back online at 10:15 after the technician closed the relay on 04/05 2.Inverter 17 was offline on 04/26 and then started for production next day issue self resolved. | K6: 1.SR099376 2.SR100451 | L6: SR100451
A7: Winslow - Roderick | B7: ME | C7: 658339 | D7: 684937.9 | E7: =IF(AND(ISNUMBER(C7),ISNUMBER(D7)), C7-D7, "") -> -26598.9 | F7: =IFERROR(E7/D7, "") -> -0.038834032 | G7: 697456 | H7: =IF(AND(ISNUMBER(C7),ISNUMBER(G7)), C7-G7, "") -> -39117 | I7: =IFERROR(H7/G7, "") -> -0.056085258
A8: Minoa - Clemons Rd | B8: NY | C8: 392341 | D8: 467637.9 | E8: =IF(AND(ISNUMBER(C8),ISNUMBER(D8)), C8-D8, "") -> -75296.9 | F8: =IFERROR(E8/D8, "") -> -0.16101539 | G8: 499299.5 | H8: =IF(AND(ISNUMBER(C8),ISNUMBER(G8)), C8-G8, "") -> -106958.5 | I8: =IFERROR(H8/G8, "") -> -0.21421712 | J8: 1.Inverter 15 is being RMAD from 04/10 due to its multiple trip events.On 04/30 ,technician troubleshoot the inverter came back online at 14:45 on 04/30 2.The site was offline from 17:15 on 04/29 to 06:45 EDT on 04/30 due to transformer testing conducted by USNE. 3.The site tripped offline at 12:30 EDT on 04/30 and back online at 13:30 the same day. The issue got self-resolved. 4.Multiple trackers were observed stuck on various days with no consistent pattern. | K8: 1.SR098701 2.SR100667 3.SR100717 4.SR098775 | L8: SR100667 | M8: SR100717 | N8: SR098775
A9: Manchester - Western | B9: ME | C9: 96372.375 | D9: 0 | E9: =IF(AND(ISNUMBER(C9),ISNUMBER(D9)), C9-D9, "") -> 96372.375 | F9: =IFERROR(E9/D9, "") | G9: 104717.2 | H9: =IF(AND(ISNUMBER(C9),ISNUMBER(G9)), C9-G9, "") -> -8344.825 | I9: =IFERROR(H9/G9, "") -> -0.079689153 | J9: 1.Inverter 2 tripped offline at 11:15 AM on 04/01 and was back online at 14:48 the same day. The issue self-resolved 2. Inverter 2 tripped offline from 11:30 to 12:30 EDT. Inverter 3 tripped offline from 12:30 to 14:00 and again from 14:45 to 17:30 on 04/23.Issue got resolved after tech visit and they are operating on 04/24. | K9: 1.SR099279 2.SR100248,SR100392 | L9: SR100248 | M9: SR100392
A10: Batavia - Pike Rd | B10: NY | C10: 496293.06 | D10: 499624.7 | E10: =IF(AND(ISNUMBER(C10),ISNUMBER(D10)), C10-D10, "") -> -3331.636 | F10: =IFERROR(E10/D10, "") -> -0.0066682771 | G10: 530455.1 | H10: =IF(AND(ISNUMBER(C10),ISNUMBER(G10)), C10-G10, "") -> -34162.036 | I10: =IFERROR(H10/G10, "") -> -0.064401372 | J10: 1.NCU-01 (120): Tracker Position TCU 11 stuck at -54 degrees from 03/21.Issue existed for rest of the month | K10: 1.SR098907
A11: Slayton A & B | B11: NY | C11: 1190178 | D11: 1248265 | E11: =IF(AND(ISNUMBER(C11),ISNUMBER(D11)), C11-D11, "") -> -58087 | F11: =IFERROR(E11/D11, "") -> -0.046534189 | G11: 1237720 | H11: =IF(AND(ISNUMBER(C11),ISNUMBER(G11)), C11-G11, "") -> -47542 | I11: =IFERROR(H11/G11, "") -> -0.038410949 | J11: 1.NCU-A.01-tracker 132 was stuck on 02/19/25 .On 04/21 ,technician received the materials from FlexRack and further accessed the wind damage to the row and then also replaced the GHI sensor wiring for site A. From then POA sensor is communicating.Additional troubleshooting is required 2.All Pad A inverters and the meter tripped offline at 13:30 on 04/10 and back online at 17:30 the same day after technician closed relay on Pad A. 3.Site was offline from 12:30 to 13:45 on 04/28 due to RESA technician check into the site for repairing the breaker on a transformer 4.All trackers are stuck from 10:45AM on 04/29 All trackers has resumed tracking on 04/30 except - NCU A.01 - Tracker S132 still struck , NCU A.02 - Trackers S71 & S72 still struck , NCU B.01 - Tracker S2 still struck. | K11: 1.SR098375 2.SR099651 3.SR100352 4.SR100666 | L11: SR099651 | M11: SR100352 | N11: SR100666
A12: Batavia - Alexander Rd | B12: NY | C12: 272601.72 | D12: 301844.3 | E12: =IF(AND(ISNUMBER(C12),ISNUMBER(D12)), C12-D12, "") -> -29242.576 | F12: =IFERROR(E12/D12, "") -> -0.096879669 | G12: 292096.9 | H12: =IF(AND(ISNUMBER(C12),ISNUMBER(G12)), C12-G12, "") -> -19495.176 | I12: =IFERROR(H12/G12, "") -> -0.066742153 | J12: 1.Tracker 76 motor has been observed stuck at 30.76° across multiple days, with no consistent time pattern,NSU 02 - Tracker 49 motor is stuck at -16.9 degrees on 02/08/25 from 08:45AM,NSU 02 - Tracker 27 motor is struck at -1.01 DEG .Inverter 05 is impacting production after mid-day. | K12: 1.SR098763
A13: NC: Gibson – Henry Gibson Solar | B13: NC | C13: 1024404 | D13: 1232185 | E13: =IF(AND(ISNUMBER(C13),ISNUMBER(D13)), C13-D13, "") -> -207781 | F13: =IFERROR(E13/D13, "") -> -0.16862809 | G13: 1177694 | H13: =IF(AND(ISNUMBER(C13),ISNUMBER(G13)), C13-G13, "") -> -153290 | I13: =IFERROR(H13/G13, "") -> -0.13016115 | J13: 1.Inverter 1.04 &2.10 are offline throughout the month.Inverter 2.10 has damaged insulated fuse stud which is preventing fuse from being installed. Inverter 1.04 is unresponsive and pending RMA for the wire box 2.The site remained offline from 15:45 on 04/07 to 07:45 on 04/10 due to weather-related outages in the area. Power was restored on 04/08, after a technician closed the recloser. 3.Trackers stuck at 0 degrees and set points are also reporting 0 degrees from 04/23 All trackers started tracking from 04/25 10:00AM. Issue got self resolved | K13: 1.SR098979 2.SR099483 3.SR100204 | L13: SR099483 | M13: SR100204
A14: Bangor - Pushaw | B14: ME | C14: 553923 | D14: 572315.2 | E14: =IF(AND(ISNUMBER(C14),ISNUMBER(D14)), C14-D14, "") -> -18392.2 | F14: =IFERROR(E14/D14, "") -> -0.032136487 | G14: 609871 | H14: =IF(AND(ISNUMBER(C14),ISNUMBER(G14)), C14-G14, "") -> -55948 | I14: =IFERROR(H14/G14, "") -> -0.091737433 | J14: 1.The site tripped offline at 12:15 on 04/15 and was back online at 13:30 after the recloser auto-reclosed. | K14: 1.SR099819

Sheet May
A1: {=portfolio} -> Renewable Properties | D1: May Actual v. Expected | G1: May Actual v. Forecasted
A2: Total | C2: =SUM(C4:C80) -> 5909424.9 | D2: =SUM(D4:D80) -> 6255273.8 | E2: =C2-D2 -> -345848.87 | F2: =IFERROR(E2/D2, 0) -> -0.055289165 | G2: =SUM(G4:G80) -> 8160249.2 | H2: =C2-G2 -> -2250824.3 | I2: =IFERROR(H2/G2, 0) -> -0.27582788 | J2: =IF(AND(TODAY()>DATE(2024, 5, 1), COUNTA(Sites[Site])<>(COUNT(C:C)-1)), "Some sites are missing actual data; if new sites were added, make sure they are aligned correctly (including prior months!)", "")
A3: Site | B3: State | C3: Actual | D3: Expected | E3: Delta | F3: % | G3: Forecasted | H3: Delta | I3: % | J3: Notes | K3: Service Requests
A4: {=Sites[Site]} -> Cedar Swamp Rd | B4: {=Sites[State]} -> MA | C4: 97941 | D4: 93778.11 | E4: =IF(AND(ISNUMBER(C4),ISNUMBER(D4)), C4-D4, "") -> 4162.89 | F4: =IFERROR(E4/D4, "") -> 0.04439085 | G4: 154481 | H4: =IF(AND(ISNUMBER(C4),ISNUMBER(G4)), C4-G4, "") -> -56540 | I4: =IFERROR(H4/G4, "") -> -0.3659997 | J4: 1. Site was tripped offline from 05/20 at 11:00 and offline for End of the month due to utility was working on substation. | K4: 1. SR101723
A5: Bullis | B5: NY | C5: 676501 | D5: 657346 | E5: =IF(AND(ISNUMBER(C5),ISNUMBER(D5)), C5-D5, "") -> 19155 | F5: =IFERROR(E5/D5, "") -> 0.029139905 | G5: 1003046 | H5: =IF(AND(ISNUMBER(C5),ISNUMBER(G5)), C5-G5, "") -> -326545 | I5: =IFERROR(H5/G5, "") -> -0.32555336 | J5: 1. Inverter 8 was derating by 40kW down for whole month compared to its peers due to the fan being RMA'd. 2. Site was offline from 09:45 to 13:00 on 05/16 due to utility outage. 3. The site went offline on 05/25 at 14:30. On 05/27, a technician inspected the MV lines and switchgear and found that the recloser and the main breaker had tripped. He reclosed the site, and it was back online at 09:00 on 05/27. 4.The site tripped offline on 05/28 at 16:40. It was later remotely reset, and Pad 2 came back online at 21:00; however, Pad 1 remained offline. A technician later re-energized the site at 08:15 on 05/29. The site tripped offline again on 05/29 at 13:45 and was re-energized by a technician at 15:45 the same day. 5. The site tripped offline at 17:56 on 05/30 and came back online at 18:20 on the same day. Pad 2 was restored, but Pad 1 remained offline. | K5: 1. SR099753 2. SR101577 3. SR101927 4. SR102059 5. SR102206 | L5: SR101577 | M5: SR101927 | N5: SR102059 | O5: SR102206
A6: Rock Island | B6: NY | C6: 636980 | D6: 635371.2 | E6: =IF(AND(ISNUMBER(C6),ISNUMBER(D6)), C6-D6, "") -> 1608.8 | F6: =IFERROR(E6/D6, "") -> 0.0025320631 | G6: 879182.1 | H6: =IF(AND(ISNUMBER(C6),ISNUMBER(G6)), C6-G6, "") -> -242202.1 | I6: =IFERROR(H6/G6, "") -> -0.2754857 | J6: 1. Inverter 17 had late starting issue. | K6: 1.SR100451
A7: Winslow - Roderick | B7: ME | C7: 626213 | D7: 636729 | E7: =IF(AND(ISNUMBER(C7),ISNUMBER(D7)), C7-D7, "") -> -10516 | F7: =IFERROR(E7/D7, "") -> -0.016515661 | G7: 797959 | H7: =IF(AND(ISNUMBER(C7),ISNUMBER(G7)), C7-G7, "") -> -171746 | I7: =IFERROR(H7/G7, "") -> -0.21523161 | J7: Based on actual weather station data, the site is performing close to expected levels, with no major events or anomalies observed during the reporting period
A8: Minoa - Clemons Rd | B8: NY | C8: 379990.25 | D8: 419545.1 | E8: =IF(AND(ISNUMBER(C8),ISNUMBER(D8)), C8-D8, "") -> -39554.85 | F8: =IFERROR(E8/D8, "") -> -0.094280329 | G8: 620710.4 | H8: =IF(AND(ISNUMBER(C8),ISNUMBER(G8)), C8-G8, "") -> -240720.15 | I8: =IFERROR(H8/G8, "") -> -0.38781395 | J8: 1. Site tripped offline on 05/04 at 18:15 due to storm activity. On 05/05 technician reclosed the recloser site came back online at 13:45 2. NCU 01 tracker 39, NCU 02 trackers 44 & 47 (tracker and setpoint 0 DEG) were stuck technician was on site on 05/15 to troubleshoot the trackers NCU 1 TCU 39 was set to auto and resumed tracking. The NCU 2 TCU 44 & 47 have blown fuses and will remain stuck until replacements can be installed. On 05/18 NCU 01 tracker 39 got stuck again. | K8: 1. SR100717 2. SR098775 | L8: SR098775
A9: Manchester - Western | B9: ME | C9: 94785.438 | D9: N/A | E9: =IF(AND(ISNUMBER(C9),ISNUMBER(D9)), C9-D9, "") | F9: =IFERROR(E9/D9, "") | G9: 114913.1 | H9: =IF(AND(ISNUMBER(C9),ISNUMBER(G9)), C9-G9, "") -> -20127.663 | I9: =IFERROR(H9/G9, "") -> -0.17515551 | J9: While expected energy data is not available, weather station data indicates normal irradiance levels, and no major issues were observed on site. Based on available information, system performance appears consistent with typical operating conditions.
A10: Batavia - Pike Rd | B10: NY | C10: 456032.91 | D10: 509437.7 | E10: =IF(AND(ISNUMBER(C10),ISNUMBER(D10)), C10-D10, "") -> -53404.79 | F10: =IFERROR(E10/D10, "") -> -0.10483086 | G10: 673777.4 | H10: =IF(AND(ISNUMBER(C10),ISNUMBER(G10)), C10-G10, "") -> -217744.49 | I10: =IFERROR(H10/G10, "") -> -0.32316977 | J10: 1. Site tripped offline on 05/11 at 13:30 due to utility had a line outage for emergency work. On 05/12 at 10:00 technician re-energized the site. 2. Site tripped offline on 05/02 at 16:00 due to fiuse blown on transformer and later technician re-energised the site on 05/06 at 09:00 but inverters 1, 2, 3, 4 and 5 remained offline and back online on 05/12 at 10:00 after technician reclose the breaker. | K10: 1. SR101280 2. SR101153, SR100944 | L10: SR101153 | M10: SR100944
A11: Slayton A & B | B11: NY | C11: 1382406 | D11: 1432195 | E11: =IF(AND(ISNUMBER(C11),ISNUMBER(D11)), C11-D11, "") -> -49789 | F11: =IFERROR(E11/D11, "") -> -0.034764121 | G11: 1549451 | H11: =IF(AND(ISNUMBER(C11),ISNUMBER(G11)), C11-G11, "") -> -167045 | I11: =IFERROR(H11/G11, "") -> -0.10780915 | J11: 1. NCU A.01 - Tracker S132 struck, NCU A.02 - Trackers S71 & S72 struck, NCU B.01 - Tracker S2 struck for whole month. | K11: 1. SR100666
