Workbook
Name JanActual: #REF!
Name JanActual2: #REF!
Name JanExpected: #REF!
Name JanExpectedDelta: #REF!
Name JanExpectedPercent: #REF!
Name JanExpPercent: #REF!
Name JanForecasted: #REF!
Name JanForecastedDelta: #REF!
Name JanForecastedPercent: #REF!
Name portfolio: Sites!$B$1:$B$1
Name Year: Sites!#REF!

Sheet Year to Date
A1: {=portfolio} -> Cushman & Wakefield | D1: Year to Date Actual v. Expected | G1: Year to Date Actual v. Forecasted
A2: Total | C2: =SUM(C4:C38) -> 0 | D2: =SUM(D4:D38) -> 0 | E2: =C2-D2 -> 0 | F2: =IFERROR(E2/D2, 0) -> 0 | G2: =SUM(G4:G38) -> 0 | H2: =C2-G2 -> 0 | I2: =IFERROR(H2/G2, 0) -> 0
A3: Site | B3: State | C3: Actual | D3: Expected | E3: Delta | F3: % | G3: Forecasted | H3: Delta | I3: %
A4: {=Sites[Site]} -> Adelanto - Bank of America | B4: {=Sites[State]} -> CA | C4: =SUM('1st Qtr'!C4, '2nd Qtr'!C4, '3rd Qtr'!C4, '4th Qtr'!C4) -> 0 | D4: =SUM('1st Qtr'!D4, '2nd Qtr'!D4, '3rd Qtr'!D4, '4th Qtr'!D4) -> 0 | E4: =IF(AND(ISNUMBER(C4),ISNUMBER(D4)), C4-D4, "") -> 0 | F4: =IFERROR(E4/D4, "") | G4: =SUM('1st Qtr'!G4+'2nd Qtr'!G4+'3rd Qtr'!G4+'4th Qtr'!G4) -> 0 | H4: =IF(AND(ISNUMBER(C4),ISNUMBER(G4)), C4-G4, "") -> 0 | I4: =IFERROR(H4/G4, "")
A5: Apple Valley - Bank of America | B5: CA | C5: =SUM(Jan!C5, Feb!C5, Mar!C5) -> 0 | D5: =SUM(Jan!D5, Feb!D5, Mar!D5) -> 0 | E5: =IF(AND(ISNUMBER(C5),ISNUMBER(D5)), C5-D5, "") -> 0 | F5: =IFERROR(E5/D5, "") | G5: =SUM('1st Qtr'!G5+'2nd Qtr'!G5+'3rd Qtr'!G5+'4th Qtr'!G5) -> 0 | H5: =IF(AND(ISNUMBER(C5),ISNUMBER(G5)), C5-G5, "") -> 0 | I5: =IFERROR(H5/G5, "")
A6: Arvin - Bank of America | B6: CA | C6: =SUM(Jan!C6, Feb!C6, Mar!C6) -> 0 | D6: =SUM(Jan!D6, Feb!D6, Mar!D6) -> 0 | E6: =IF(AND(ISNUMBER(C6),ISNUMBER(D6)), C6-D6, "") -> 0 | F6: =IFERROR(E6/D6, "") | G6: =SUM('1st Qtr'!G6+'2nd Qtr'!G6+'3rd Qtr'!G6+'4th Qtr'!G6) -> 0 | H6: =IF(AND(ISNUMBER(C6),ISNUMBER(G6)), C6-G6, "") -> 0 | I6: =IFERROR(H6/G6, "")
A7: Bell - Bank of America | B7: CA | C7: =SUM(Jan!C7, Feb!C7, Mar!C7) -> 0 | D7: =SUM(Jan!D7, Feb!D7, Mar!D7) -> 0 | E7: =IF(AND(ISNUMBER(C7),ISNUMBER(D7)), C7-D7, "") -> 0 | F7: =IFERROR(E7/D7, "") | G7: =SUM('1st Qtr'!G7+'2nd Qtr'!G7+'3rd Qtr'!G7+'4th Qtr'!G7) -> 0 | H7: =IF(AND(ISNUMBER(C7),ISNUMBER(G7)), C7-G7, "") -> 0 | I7: =IFERROR(H7/G7, "")
A8: Chula Vista - Bank of America | B8: CA | C8: =SUM(Jan!C8, Feb!C8, Mar!C8) -> 0 | D8: =SUM(Jan!D8, Feb!D8, Mar!D8) -> 0 | E8: =IF(AND(ISNUMBER(C8),ISNUMBER(D8)), C8-D8, "") -> 0 | F8: =IFERROR(E8/D8, "") | G8: =SUM('1st Qtr'!G8+'2nd Qtr'!G8+'3rd Qtr'!G8+'4th Qtr'!G8) -> 0 | H8: =IF(AND(ISNUMBER(C8),ISNUMBER(G8)), C8-G8, "") -> 0 | I8: =IFERROR(H8/G8, "")
A9: Cupertino - Bank of America | B9: CA | C9: =SUM(Jan!C9, Feb!C9, Mar!C9) -> 0 | D9: =SUM(Jan!D9, Feb!D9, Mar!D9) -> 0 | E9: =IF(AND(ISNUMBER(C9),ISNUMBER(D9)), C9-D9, "") -> 0 | F9: =IFERROR(E9/D9, "") | G9: =SUM('1st Qtr'!G9+'2nd Qtr'!G9+'3rd Qtr'!G9+'4th Qtr'!G9) -> 0 | H9: =IF(AND(ISNUMBER(C9),ISNUMBER(G9)), C9-G9, "") -> 0 | I9: =IFERROR(H9/G9, "")
A10: Diamond Bar - Bank of America | B10: CA | C10: =SUM(Jan!C10, Feb!C10, Mar!C10) -> 0 | D10: =SUM(Jan!D10, Feb!D10, Mar!D10) -> 0 | E10: =IF(AND(ISNUMBER(C10),ISNUMBER(D10)), C10-D10, "") -> 0 | F10: =IFERROR(E10/D10, "") | G10: =SUM('1st Qtr'!G10+'2nd Qtr'!G10+'3rd Qtr'!G10+'4th Qtr'!G10) -> 0 | H10: =IF(AND(ISNUMBER(C10),ISNUMBER(G10)), C10-G10, "") -> 0 | I10: =IFERROR(H10/G10, "")
A11: El Centro - Bank of America | B11: CA | C11: =SUM(Jan!C11, Feb!C11, Mar!C11) -> 0 | D11: =SUM(Jan!D11, Feb!D11, Mar!D11) -> 0 | E11: =IF(AND(ISNUMBER(C11),ISNUMBER(D11)), C11-D11, "") -> 0 | F11: =IFERROR(E11/D11, "") | G11: =SUM('1st Qtr'!G11+'2nd Qtr'!G11+'3rd Qtr'!G11+'4th Qtr'!G11) -> 0 | H11: =IF(AND(ISNUMBER(C11),ISNUMBER(G11)), C11-G11, "") -> 0 | I11: =IFERROR(H11/G11, "")
A12: Moreno Valley - Bank of America | B12: CA | C12: =SUM(Jan!C12, Feb!C12, Mar!C12) -> 0 | D12: =SUM(Jan!D12, Feb!D12, Mar!D12) -> 0 | E12: =IF(AND(ISNUMBER(C12),ISNUMBER(D12)), C12-D12, "") -> 0 | F12: =IFERROR(E12/D12, "") | G12: =SUM('1st Qtr'!G12+'2nd Qtr'!G12+'3rd Qtr'!G12+'4th Qtr'!G12) -> 0 | H12: =IF(AND(ISNUMBER(C12),ISNUMBER(G12)), C12-G12, "") -> 0 | I12: =IFERROR(H12/G12, "")
A13: Redlands - Bank of America | B13: CA | C13: =SUM(Jan!C13, Feb!C13, Mar!C13) -> 0 | D13: =SUM(Jan!D13, Feb!D13, Mar!D13) -> 0 | E13: =IF(AND(ISNUMBER(C13),ISNUMBER(D13)), C13-D13, "") -> 0 | F13: =IFERROR(E13/D13, "") | G13: =SUM('1st Qtr'!G13+'2nd Qtr'!G13+'3rd Qtr'!G13+'4th Qtr'!G13) -> 0 | H13: =IF(AND(ISNUMBER(C13),ISNUMBER(G13)), C13-G13, "") -> 0 | I13: =IFERROR(H13/G13, "")
A14: Roseville - Bank of America | B14: CA | C14: =SUM(Jan!C14, Feb!C14, Mar!C14) -> 0 | D14: =SUM(Jan!D14, Feb!D14, Mar!D14) -> 0 | E14: =IF(AND(ISNUMBER(C14),ISNUMBER(D14)), C14-D14, "") -> 0 | F14: =IFERROR(E14/D14, "") | G14: =SUM('1st Qtr'!G14+'2nd Qtr'!G14+'3rd Qtr'!G14+'4th Qtr'!G14) -> 0 | H14: =IF(AND(ISNUMBER(C14),ISNUMBER(G14)), C14-G14, "") -> 0 | I14: =IFERROR(H14/G14, "")
A15: San Bernardino - Bank of America | B15: CA | C15: =SUM(Jan!C15, Feb!C15, Mar!C15) -> 0 | D15: =SUM(Jan!D15, Feb!D15, Mar!D15) -> 0 | E15: =IF(AND(ISNUMBER(C15),ISNUMBER(D15)), C15-D15, "") -> 0 | F15: =IFERROR(E15/D15, "") | G15: =SUM('1st Qtr'!G15+'2nd Qtr'!G15+'3rd Qtr'!G15+'4th Qtr'!G15) -> 0 | H15: =IF(AND(ISNUMBER(C15),ISNUMBER(G15)), C15-G15, "") -> 0 | I15: =IFERROR(H15/G15, "")
A16: San Diego - Bank of America | B16: CA | C16: =SUM(Jan!C16, Feb!C16, Mar!C16) -> 0 | D16: =SUM(Jan!D16, Feb!D16, Mar!D16) -> 0 | E16: =IF(AND(ISNUMBER(C16),ISNUMBER(D16)), C16-D16, "") -> 0 | F16: =IFERROR(E16/D16, "") | G16: =SUM('1st Qtr'!G16+'2nd Qtr'!G16+'3rd Qtr'!G16+'4th Qtr'!G16) -> 0 | H16: =IF(AND(ISNUMBER(C16),ISNUMBER(G16)), C16-G16, "") -> 0 | I16: =IFERROR(H16/G16, "")
... A38: Salt Lake City - Bank of America | B38: UT | C38: =SUM(Jan!C38, Feb!C38, Mar!C38) -> 0 | D38: =SUM(Jan!D38, Feb!D38, Mar!D38) -> 0 | E38: =IF(AND(ISNUMBER(C38),ISNUMBER(D38)), C38-D38, "") -> 0 | F38: =IFERROR(E38/D38, "") | G38: =SUM('1st Qtr'!G38+'2nd Qtr'!G38+'3rd Qtr'!G38+'4th Qtr'!G38) -> 0 | H38: =IF(AND(ISNUMBER(C38),ISNUMBER(G38)), C38-G38, "") -> 0 | I38: =IFERROR(H38/G38, "")

Sheet 1st Qtr
A1: {=portfolio} -> Cushman & Wakefield | D1: 1st Quarter Actual v. Expected | G1: 1st Quarter Actual v. Forecasted
A2: Total | C2: =SUM(C4:C38) -> 0 | D2: =SUM(D4:D38) -> 0 | E2: =C2-D2 -> 0 | F2: =IFERROR(E2/D2, 0) -> 0 | G2: =SUM(G4:G38) -> 0 | H2: =C2-G2 -> 0 | I2: =IFERROR(H2/G2, 0) -> 0
A3: Site | B3: State | C3: Actual | D3: Expected | E3: Delta | F3: % | G3: Forecasted | H3: Delta | I3: %
A4: {=Sites[Site]} -> Adelanto - Bank of America | B4: {=Sites[State]} -> CA | C4: =SUM(Jan!C4, Feb!C4, Mar!C4) -> 0 | D4: =SUM(Jan!D4, Feb!D4, Mar!D4) -> 0 | E4: =IF(AND(ISNUMBER(C4),ISNUMBER(D4)), C4-D4, "") -> 0 | F4: =IFERROR(E4/D4, "") | G4: =SUM(Jan!G4, Feb!G4, Mar!G4) -> 0 | H4: =IF(AND(ISNUMBER(C4),ISNUMBER(G4)), C4-G4, "") -> 0 | I4: =IFERROR(H4/G4, "")
A5: Apple Valley - Bank of America | B5: CA | C5: =SUM(Jan!C5, Feb!C5, Mar!C5) -> 0 | D5: =SUM(Jan!D5, Feb!D5, Mar!D5) -> 0 | E5: =IF(AND(ISNUMBER(C5),ISNUMBER(D5)), C5-D5, "") -> 0 | F5: =IFERROR(E5/D5, "") | G5: =SUM(Jan!G5, Feb!G5, Mar!G5) -> 0 | H5: =IF(AND(ISNUMBER(C5),ISNUMBER(G5)), C5-G5, "") -> 0 | I5: =IFERROR(H5/G5, "")
A6: Arvin - Bank of America | B6: CA | C6: =SUM(Jan!C6, Feb!C6, Mar!C6) -> 0 | D6: =SUM(Jan!D6, Feb!D6, Mar!D6) -> 0 | E6: =IF(AND(ISNUMBER(C6),ISNUMBER(D6)), C6-D6, "") -> 0 | F6: =IFERROR(E6/D6, "") | G6: =SUM(Jan!G6, Feb!G6, Mar!G6) -> 0 | H6: =IF(AND(ISNUMBER(C6),ISNUMBER(G6)), C6-G6, "") -> 0 | I6: =IFERROR(H6/G6, "")
A7: Bell - Bank of America | B7: CA | C7: =SUM(Jan!C7, Feb!C7, Mar!C7) -> 0 | D7: =SUM(Jan!D7, Feb!D7, Mar!D7) -> 0 | E7: =IF(AND(ISNUMBER(C7),ISNUMBER(D7)), C7-D7, "") -> 0 | F7: =IFERROR(E7/D7, "") | G7: =SUM(Jan!G7, Feb!G7, Mar!G7) -> 0 | H7: =IF(AND(ISNUMBER(C7),ISNUMBER(G7)), C7-G7, "") -> 0 | I7: =IFERROR(H7/G7, "")
A8: Chula Vista - Bank of America | B8: CA | C8: =SUM(Jan!C8, Feb!C8, Mar!C8) -> 0 | D8: =SUM(Jan!D8, Feb!D8, Mar!D8) -> 0 | E8: =IF(AND(ISNUMBER(C8),ISNUMBER(D8)), C8-D8, "") -> 0 | F8: =IFERROR(E8/D8, "") | G8: =SUM(Jan!G8, Feb!G8, Mar!G8) -> 0 | H8: =IF(AND(ISNUMBER(C8),ISNUMBER(G8)), C8-G8, "") -> 0 | I8: =IFERROR(H8/G8, "")
A9: Cupertino - Bank of America | B9: CA | C9: =SUM(Jan!C9, Feb!C9, Mar!C9) -> 0 | D9: =SUM(Jan!D9, Feb!D9, Mar!D9) -> 0 | E9: =IF(AND(ISNUMBER(C9),ISNUMBER(D9)), C9-D9, "") -> 0 | F9: =IFERROR(E9/D9, "") | G9: =SUM(Jan!G9, Feb!G9, Mar!G9) -> 0 | H9: =IF(AND(ISNUMBER(C9),ISNUMBER(G9)), C9-G9, "") -> 0 | I9: =IFERROR(H9/G9, "")
A10: Diamond Bar - Bank of America | B10: CA | C10: =SUM(Jan!C10, Feb!C10, Mar!C10) -> 0 | D10: =SUM(Jan!D10, Feb!D10, Mar!D10) -> 0 | E10: =IF(AND(ISNUMBER(C10),ISNUMBER(D10)), C10-D10, "") -> 0 | F10: =IFERROR(E10/D10, "") | G10: =SUM(Jan!G10, Feb!G10, Mar!G10) -> 0 | H10: =IF(AND(ISNUMBER(C10),ISNUMBER(G10)), C10-G10, "") -> 0 | I10: =IFERROR(H10/G10, "")
A11: El Centro - Bank of America | B11: CA | C11: =SUM(Jan!C11, Feb!C11, Mar!C11) -> 0 | D11: =SUM(Jan!D11, Feb!D11, Mar!D11) -> 0 | E11: =IF(AND(ISNUMBER(C11),ISNUMBER(D11)), C11-D11, "") -> 0 | F11: =IFERROR(E11/D11, "") | G11: =SUM(Jan!G11, Feb!G11, Mar!G11) -> 0 | H11: =IF(AND(ISNUMBER(C11),ISNUMBER(G11)), C11-G11, "") -> 0 | I11: =IFERROR(H11/G11, "")
A12: Moreno Valley - Bank of America | B12: CA | C12: =SUM(Jan!C12, Feb!C12, Mar!C12) -> 0 | D12: =SUM(Jan!D12, Feb!D12, Mar!D12) -> 0 | E12: =IF(AND(ISNUMBER(C12),ISNUMBER(D12)), C12-D12, "") -> 0 | F12: =IFERROR(E12/D12, "") | G12: =SUM(Jan!G12, Feb!G12, Mar!G12) -> 0 | H12: =IF(AND(ISNUMBER(C12),ISNUMBER(G12)), C12-G12, "") -> 0 | I12: =IFERROR(H12/G12, "")
A13: Redlands - Bank of America | B13: CA | C13: =SUM(Jan!C13, Feb!C13, Mar!C13) -> 0 | D13: =SUM(Jan!D13, Feb!D13, Mar!D13) -> 0 | E13: =IF(AND(ISNUMBER(C13),ISNUMBER(D13)), C13-D13, "") -> 0 | F13: =IFERROR(E13/D13, "") | G13: =SUM(Jan!G13, Feb!G13, Mar!G13) -> 0 | H13: =IF(AND(ISNUMBER(C13),ISNUMBER(G13)), C13-G13, "") -> 0 | I13: =IFERROR(H13/G13, "")
A14: Roseville - Bank of America | B14: CA | C14: =SUM(Jan!C14, Feb!C14, Mar!C14) -> 0 | D14: =SUM(Jan!D14, Feb!D14, Mar!D14) -> 0 | E14: =IF(AND(ISNUMBER(C14),ISNUMBER(D14)), C14-D14, "") -> 0 | F14: =IFERROR(E14/D14, "") | G14: =SUM(Jan!G14, Feb!G14, Mar!G14) -> 0 | H14: =IF(AND(ISNUMBER(C14),ISNUMBER(G14)), C14-G14, "") -> 0 | I14: =IFERROR(H14/G14, "")
A15: San Bernardino - Bank of America | B15: CA | C15: =SUM(Jan!C15, Feb!C15, Mar!C15) -> 0 | D15: =SUM(Jan!D15, Feb!D15, Mar!D15) -> 0 | E15: =IF(AND(ISNUMBER(C15),ISNUMBER(D15)), C15-D15, "") -> 0 | F15: =IFERROR(E15/D15, "") | G15: =SUM(Jan!G15, Feb!G15, Mar!G15) -> 0 | H15: =IF(AND(ISNUMBER(C15),ISNUMBER(G15)), C15-G15, "") -> 0 | I15: =IFERROR(H15/G15, "")
A16: San Diego - Bank of America | B16: CA | C16: =SUM(Jan!C16, Feb!C16, Mar!C16) -> 0 | D16: =SUM(Jan!D16, Feb!D16, Mar!D16) -> 0 | E16: =IF(AND(ISNUMBER(C16),ISNUMBER(D16)), C16-D16, "") -> 0 | F16: =IFERROR(E16/D16, "") | G16: =SUM(Jan!G16, Feb!G16, Mar!G16) -> 0 | H16: =IF(AND(ISNUMBER(C16),ISNUMBER(G16)), C16-G16, "") -> 0 | I16: =IFERROR(H16/G16, "")
... A38: Salt Lake City - Bank of America | B38: UT | C38: =SUM(Jan!C38, Feb!C38, Mar!C38) -> 0 | D38: =SUM(Jan!D38, Feb!D38, Mar!D38) -> 0 | E38: =IF(AND(ISNUMBER(C38),ISNUMBER(D38)), C38-D38, "") -> 0 | F38: =IFERROR(E38/D38, "") | G38: =SUM(Jan!G38, Feb!G38, Mar!G38) -> 0 | H38: =IF(AND(ISNUMBER(C38),ISNUMBER(G38)), C38-G38, "") -> 0 | I38: =IFERROR(H38/G38, "")

Sheet 2nd Qtr
A1: {=portfolio} -> Cushman & Wakefield | D1: 2nd Quarter Actual v. Expected | G1: 2nd Quarter Actual v. Forecasted
A2: Total | C2: =SUM(C4:C38) -> 0 | D2: =SUM(D4:D38) -> 0 | E2: =C2-D2 -> 0 | F2: =IFERROR(E2/D2, 0) -> 0 | G2: =SUM(G4:G38) -> 0 | H2: =C2-G2 -> 0 | I2: =IFERROR(H2/G2, 0) -> 0
A3: Site | B3: State | C3: Actual | D3: Expected | E3: Delta | F3: % | G3: Forecasted | H3: Delta | I3: %
A4: {=Sites[Site]} -> Adelanto - Bank of America | B4: {=Sites[State]} -> CA | C4: =SUM(Apr!C4, May!C4, Jun!C4) -> 0 | D4: =SUM(Apr!D4, May!D4, Jun!D4) -> 0 | E4: =IF(AND(ISNUMBER(C4),ISNUMBER(D4)), C4-D4, "") -> 0 | F4: =IFERROR(E4/D4, "") | H4: =IF(AND(ISNUMBER(C4),ISNUMBER(G4)), C4-G4, "") | I4: =IFERROR(H4/G4, "")
A5: Apple Valley - Bank of America | B5: CA | C5: =SUM(Apr!C5, May!C5, Jun!C5) -> 0 | D5: =SUM(Apr!D5, May!D5, Jun!D5) -> 0 | E5: =IF(AND(ISNUMBER(C5),ISNUMBER(D5)), C5-D5, "") -> 0 | F5: =IFERROR(E5/D5, "") | H5: =IF(AND(ISNUMBER(C5),ISNUMBER(G5)), C5-G5, "") | I5: =IFERROR(H5/G5, "")
A6: Arvin - Bank of America | B6: CA | C6: =SUM(Apr!C6, May!C6, Jun!C6) -> 0 | D6: =SUM(Apr!D6, May!D6, Jun!D6) -> 0 | E6: =IF(AND(ISNUMBER(C6),ISNUMBER(D6)), C6-D6, "") -> 0 | F6: =IFERROR(E6/D6, "") | H6: =IF(AND(ISNUMBER(C6),ISNUMBER(G6)), C6-G6, "") | I6: =IFERROR(H6/G6, "")
A7: Bell - Bank of America | B7: CA | C7: =SUM(Apr!C7, May!C7, Jun!C7) -> 0 | D7: =SUM(Apr!D7, May!D7, Jun!D7) -> 0 | E7: =IF(AND(ISNUMBER(C7),ISNUMBER(D7)), C7-D7, "") -> 0 | F7: =IFERROR(E7/D7, "") | H7: =IF(AND(ISNUMBER(C7),ISNUMBER(G7)), C7-G7, "") | I7: =IFERROR(H7/G7, "")
A8: Chula Vista - Bank of America | B8: CA | C8: =SUM(Apr!C8, May!C8, Jun!C8) -> 0 | D8: =SUM(Apr!D8, May!D8, Jun!D8) -> 0 | E8: =IF(AND(ISNUMBER(C8),ISNUMBER(D8)), C8-D8, "") -> 0 | F8: =IFERROR(E8/D8, "") | H8: =IF(AND(ISNUMBER(C8),ISNUMBER(G8)), C8-G8, "") | I8: =IFERROR(H8/G8, "")
A9: Cupertino - Bank of America | B9: CA | C9: =SUM(Apr!C9, May!C9, Jun!C9) -> 0 | D9: =SUM(Apr!D9, May!D9, Jun!D9) -> 0 | E9: =IF(AND(ISNUMBER(C9),ISNUMBER(D9)), C9-D9, "") -> 0 | F9: =IFERROR(E9/D9, "") | H9: =IF(AND(ISNUMBER(C9),ISNUMBER(G9)), C9-G9, "") | I9: =IFERROR(H9/G9, "")
A10: Diamond Bar - Bank of America | B10: CA | C10: =SUM(Apr!C10, May!C10, Jun!C10) -> 0 | D10: =SUM(Apr!D10, May!D10, Jun!D10) -> 0 | E10: =IF(AND(ISNUMBER(C10),ISNUMBER(D10)), C10-D10, "") -> 0 | F10: =IFERROR(E10/D10, "") | H10: =IF(AND(ISNUMBER(C10),ISNUMBER(G10)), C10-G10, "") | I10: =IFERROR(H10/G10, "")
A11: El Centro - Bank of America | B11: CA | C11: =SUM(Apr!C11, May!C11, Jun!C11) -> 0 | D11: =SUM(Apr!D11, May!D11, Jun!D11) -> 0 | E11: =IF(AND(ISNUMBER(C11),ISNUMBER(D11)), C11-D11, "") -> 0 | F11: =IFERROR(E11/D11, "") | H11: =IF(AND(ISNUMBER(C11),ISNUMBER(G11)), C11-G11, "") | I11: =IFERROR(H11/G11, "")
A12: Moreno Valley - Bank of America | B12: CA | C12: =SUM(Apr!C12, May!C12, Jun!C12) -> 0 | D12: =SUM(Apr!D12, May!D12, Jun!D12) -> 0 | E12: =IF(AND(ISNUMBER(C12),ISNUMBER(D12)), C12-D12, "") -> 0 | F12: =IFERROR(E12/D12, "") | H12: =IF(AND(ISNUMBER(C12),ISNUMBER(G12)), C12-G12, "") | I12: =IFERROR(H12/G12, "")
A13: Redlands - Bank of America | B13: CA | C13: =SUM(Apr!C13, May!C13, Jun!C13) -> 0 | D13: =SUM(Apr!D13, May!D13, Jun!D13) -> 0 | E13: =IF(AND(ISNUMBER(C13),ISNUMBER(D13)), C13-D13, "") -> 0 | F13: =IFERROR(E13/D13, "") | H13: =IF(AND(ISNUMBER(C13),ISNUMBER(G13)), C13-G13, "") | I13: =IFERROR(H13/G13, "")
A14: Roseville - Bank of America | B14: CA | C14: =SUM(Apr!C14, May!C14, Jun!C14) -> 0 | D14: =SUM(Apr!D14, May!D14, Jun!D14) -> 0 | E14: =IF(AND(ISNUMBER(C14),ISNUMBER(D14)), C14-D14, "") -> 0 | F14: =IFERROR(E14/D14, "") | H14: =IF(AND(ISNUMBER(C14),ISNUMBER(G14)), C14-G14, "") | I14: =IFERROR(H14/G14, "")
A15: San Bernardino - Bank of America | B15: CA | C15: =SUM(Apr!C15, May!C15, Jun!C15) -> 0 | D15: =SUM(Apr!D15, May!D15, Jun!D15) -> 0 | E15: =IF(AND(ISNUMBER(C15),ISNUMBER(D15)), C15-D15, "") -> 0 | F15: =IFERROR(E15/D15, "") | H15: =IF(AND(ISNUMBER(C15),ISNUMBER(G15)), C15-G15, "") | I15: =IFERROR(H15/G15, "")
A16: San Diego - Bank of America | B16: CA | C16: =SUM(Apr!C16, May!C16, Jun!C16) -> 0 | D16: =SUM(Apr!D16, May!D16, Jun!D16) -> 0 | E16: =IF(AND(ISNUMBER(C16),ISNUMBER(D16)), C16-D16, "") -> 0 | F16: =IFERROR(E16/D16, "") | H16: =IF(AND(ISNUMBER(C16),ISNUMBER(G16)), C16-G16, "") | I16: =IFERROR(H16/G16, "")
A17: Stockton - Bank of America | B17: CA | C17: =SUM(Apr!C17, May!C17, Jun!C17) -> 0 | D17: =SUM(Apr!D17, May!D17, Jun!D17) -> 0 | E17: =IF(AND(ISNUMBER(C17),ISNUMBER(D17)), C17-D17, "") -> 0 | F17: =IFERROR(E17/D17, "") | H17: =IF(AND(ISNUMBER(C17),ISNUMBER(G17)), C17-G17, "") | I17: =IFERROR(H17/G17, "")
A18: Victorville - Bank of America | B18: CA | C18: =SUM(Apr!C18, May!C18, Jun!C18) -> 0 | D18: =SUM(Apr!D18, May!D18, Jun!D18) -> 0 | E18: =IF(AND(ISNUMBER(C18),ISNUMBER(D18)), C18-D18, "") -> 0 | F18: =IFERROR(E18/D18, "") | H18: =IF(AND(ISNUMBER(C18),ISNUMBER(G18)), C18-G18, "")
A19: Aurora - BA - Colfax Ave | B19: CO | C19: =SUM(Apr!C19, May!C19, Jun!C19) -> 0 | D19: =SUM(Apr!D19, May!D19, Jun!D19) -> 0 | E19: =IF(AND(ISNUMBER(C19),ISNUMBER(D19)), C19-D19, "") -> 0 | F19: =IFERROR(E19/D19, "") | H19: =IF(AND(ISNUMBER(C19),ISNUMBER(G19)), C19-G19, "")
A20: Aurora - BA - Parker Rd | B20: CO | C20: =SUM(Apr!C20, May!C20, Jun!C20) -> 0 | D20: =SUM(Apr!D20, May!D20, Jun!D20) -> 0 | E20: =IF(AND(ISNUMBER(C20),ISNUMBER(D20)), C20-D20, "") -> 0 | F20: =IFERROR(E20/D20, "") | H20: =IF(AND(ISNUMBER(C20),ISNUMBER(G20)), C20-G20, "")
A21: Broomfield - Bank of America | B21: CO | C21: =SUM(Apr!C21, May!C21, Jun!C21) -> 0 | D21: =SUM(Apr!D21, May!D21, Jun!D21) -> 0 | E21: =IF(AND(ISNUMBER(C21),ISNUMBER(D21)), C21-D21, "") -> 0 | F21: =IFERROR(E21/D21, "") | H21: =IF(AND(ISNUMBER(C21),ISNUMBER(G21)), C21-G21, "")
A22: Colorado Springs - Bank of America | B22: CO | C22: =SUM(Apr!C22, May!C22, Jun!C22) -> 0 | D22: =SUM(Apr!D22, May!D22, Jun!D22) -> 0 | E22: =IF(AND(ISNUMBER(C22),ISNUMBER(D22)), C22-D22, "") -> 0 | F22: =IFERROR(E22/D22, "") | H22: =IF(AND(ISNUMBER(C22),ISNUMBER(G22)), C22-G22, "")
A23: Denver - BA - 49th Ave | B23: CO | C23: =SUM(Apr!C23, May!C23, Jun!C23) -> 0 | D23: =SUM(Apr!D23, May!D23, Jun!D23) -> 0 | E23: =IF(AND(ISNUMBER(C23),ISNUMBER(D23)), C23-D23, "") -> 0 | F23: =IFERROR(E23/D23, "") | H23: =IF(AND(ISNUMBER(C23),ISNUMBER(G23)), C23-G23, "")
A24: Denver - BA Wadsworth Blvd | B24: CO | C24: =SUM(Apr!C24, May!C24, Jun!C24) -> 0 | D24: =SUM(Apr!D24, May!D24, Jun!D24) -> 0 | E24: =IF(AND(ISNUMBER(C24),ISNUMBER(D24)), C24-D24, "") -> 0 | F24: =IFERROR(E24/D24, "") | H24: =IF(AND(ISNUMBER(C24),ISNUMBER(G24)), C24-G24, "")
A25: Fort Collins - Bank of America | B25: CO | C25: =SUM(Apr!C25, May!C25, Jun!C25) -> 0 | D25: =SUM(Apr!D25, May!D25, Jun!D25) -> 0 | E25: =IF(AND(ISNUMBER(C25),ISNUMBER(D25)), C25-D25, "") -> 0 | F25: =IFERROR(E25/D25, "") | H25: =IF(AND(ISNUMBER(C25),ISNUMBER(G25)), C25-G25, "")
A26: Lafayette - Bank of America | B26: CO | C26: =SUM(Apr!C26, May!C26, Jun!C26) -> 0 | D26: =SUM(Apr!D26, May!D26, Jun!D26) -> 0 | E26: =IF(AND(ISNUMBER(C26),ISNUMBER(D26)), C26-D26, "") -> 0 | F26: =IFERROR(E26/D26, "") | H26: =IF(AND(ISNUMBER(C26),ISNUMBER(G26)), C26-G26, "")
A27: Lakewood - Bank of America | B27: CO | C27: =SUM(Apr!C27, May!C27, Jun!C27) -> 0 | D27: =SUM(Apr!D27, May!D27, Jun!D27) -> 0 | E27: =IF(AND(ISNUMBER(C27),ISNUMBER(D27)), C27-D27, "") -> 0 | F27: =IFERROR(E27/D27, "") | H27: =IF(AND(ISNUMBER(C27),ISNUMBER(G27)), C27-G27, "")
A28: Longmont - Bank of America | B28: CO | C28: =SUM(Apr!C28, May!C28, Jun!C28) -> 0 | D28: =SUM(Apr!D28, May!D28, Jun!D28) -> 0 | E28: =IF(AND(ISNUMBER(C28),ISNUMBER(D28)), C28-D28, "") -> 0 | F28: =IFERROR(E28/D28, "") | H28: =IF(AND(ISNUMBER(C28),ISNUMBER(G28)), C28-G28, "")
A29: Thornton - Bank of America | B29: CO | C29: =SUM(Apr!C29, May!C29, Jun!C29) -> 0 | D29: =SUM(Apr!D29, May!D29, Jun!D29) -> 0 | E29: =IF(AND(ISNUMBER(C29),ISNUMBER(D29)), C29-D29, "") -> 0 | F29: =IFERROR(E29/D29, "") | H29: =IF(AND(ISNUMBER(C29),ISNUMBER(G29)), C29-G29, "")
... A38: Salt Lake City - Bank of America | B38: UT | C38: =SUM(Apr!C38, May!C38, Jun!C38) -> 0 | D38: =SUM(Apr!D38, May!D38, Jun!D38) -> 0 | E38: =IF(AND(ISNUMBER(C38),ISNUMBER(D38)), C38-D38, "") -> 0 | F38: =IFERROR(E38/D38, "") | H38: =IF(AND(ISNUMBER(C38),ISNUMBER(G38)), C38-G38, "")

Sheet 3rd Qtr
A1: {=portfolio} -> Cushman & Wakefield | D1: 3rd Quarter Actual v. Expected | G1: 3rd Quarter Actual v. Forecasted
A2: Total | C2: =SUM(C4:C38) -> 0 | D2: =SUM(D4:D38) -> 0 | E2: =C2-D2 -> 0 | F2: =IFERROR(E2/D2, 0) -> 0 | G2: =SUM(G4:G38) -> 0 | H2: =C2-G2 -> 0 | I2: =IFERROR(H2/G2, 0) -> 0
A3: Site | B3: State | C3: Actual | D3: Expected | E3: Delta | F3: % | G3: Forecasted | H3: Delta | I3: %
A4: {=Sites[Site]} -> Adelanto - Bank of America | B4: {=Sites[State]} -> CA | C4: =SUM(Jul!C4, Aug!C4, Sep!C4) -> 0 | D4: =SUM(Jul!D4, Aug!D4, Sep!D4) -> 0 | E4: =IF(AND(ISNUMBER(C4),ISNUMBER(D4)), C4-D4, "") -> 0 | F4: =IFERROR(E4/D4, "") | H4: =IF(AND(ISNUMBER(C4),ISNUMBER(G4)), C4-G4, "") | I4: =IFERROR(H4/G4, "")
A5: Apple Valley - Bank of America | B5: CA | C5: =SUM(Jul!C5, Aug!C5, Sep!C5) -> 0 | D5: =SUM(Jul!D5, Aug!D5, Sep!D5) -> 0 | E5: =IF(AND(ISNUMBER(C5),ISNUMBER(D5)), C5-D5, "") -> 0 | F5: =IFERROR(E5/D5, "") | H5: =IF(AND(ISNUMBER(C5),ISNUMBER(G5)), C5-G5, "") | I5: =IFERROR(H5/G5, "")
A6: Arvin - Bank of America | B6: CA | C6: =SUM(Jul!C6, Aug!C6, Sep!C6) -> 0 | D6: =SUM(Jul!D6, Aug!D6, Sep!D6) -> 0 | E6: =IF(AND(ISNUMBER(C6),ISNUMBER(D6)), C6-D6, "") -> 0 | F6: =IFERROR(E6/D6, "") | H6: =IF(AND(ISNUMBER(C6),ISNUMBER(G6)), C6-G6, "") | I6: =IFERROR(H6/G6, "")
A7: Bell - Bank of America | B7: CA | C7: =SUM(Jul!C7, Aug!C7, Sep!C7) -> 0 | D7: =SUM(Jul!D7, Aug!D7, Sep!D7) -> 0 | E7: =IF(AND(ISNUMBER(C7),ISNUMBER(D7)), C7-D7, "") -> 0 | F7: =IFERROR(E7/D7, "") | H7: =IF(AND(ISNUMBER(C7),ISNUMBER(G7)), C7-G7, "") | I7: =IFERROR(H7/G7, "")
A8: Chula Vista - Bank of America | B8: CA | C8: =SUM(Jul!C8, Aug!C8, Sep!C8) -> 0 | D8: =SUM(Jul!D8, Aug!D8, Sep!D8) -> 0 | E8: =IF(AND(ISNUMBER(C8),ISNUMBER(D8)), C8-D8, "") -> 0 | F8: =IFERROR(E8/D8, "") | H8: =IF(AND(ISNUMBER(C8),ISNUMBER(G8)), C8-G8, "") | I8: =IFERROR(H8/G8, "")
A9: Cupertino - Bank of America | B9: CA | C9: =SUM(Jul!C9, Aug!C9, Sep!C9) -> 0 | D9: =SUM(Jul!D9, Aug!D9, Sep!D9) -> 0 | E9: =IF(AND(ISNUMBER(C9),ISNUMBER(D9)), C9-D9, "") -> 0 | F9: =IFERROR(E9/D9, "") | H9: =IF(AND(ISNUMBER(C9),ISNUMBER(G9)), C9-G9, "") | I9: =IFERROR(H9/G9, "")
A10: Diamond Bar - Bank of America | B10: CA | C10: =SUM(Jul!C10, Aug!C10, Sep!C10) -> 0 | D10: =SUM(Jul!D10, Aug!D10, Sep!D10) -> 0 | E10: =IF(AND(ISNUMBER(C10),ISNUMBER(D10)), C10-D10, "") -> 0 | F10: =IFERROR(E10/D10, "") | H10: =IF(AND(ISNUMBER(C10),ISNUMBER(G10)), C10-G10, "") | I10: =IFERROR(H10/G10, "")
A11: El Centro - Bank of America | B11: CA | C11: =SUM(Jul!C11, Aug!C11, Sep!C11) -> 0 | D11: =SUM(Jul!D11, Aug!D11, Sep!D11) -> 0 | E11: =IF(AND(ISNUMBER(C11),ISNUMBER(D11)), C11-D11, "") -> 0 | F11: =IFERROR(E11/D11, "") | H11: =IF(AND(ISNUMBER(C11),ISNUMBER(G11)), C11-G11, "") | I11: =IFERROR(H11/G11, "")
A12: Moreno Valley - Bank of America | B12: CA | C12: =SUM(Jul!C12, Aug!C12, Sep!C12) -> 0 | D12: =SUM(Jul!D12, Aug!D12, Sep!D12) -> 0 | E12: =IF(AND(ISNUMBER(C12),ISNUMBER(D12)), C12-D12, "") -> 0 | F12: =IFERROR(E12/D12, "") | H12: =IF(AND(ISNUMBER(C12),ISNUMBER(G12)), C12-G12, "") | I12: =IFERROR(H12/G12, "")
A13: Redlands - Bank of America | B13: CA | C13: =SUM(Jul!C13, Aug!C13, Sep!C13) -> 0 | D13: =SUM(Jul!D13, Aug!D13, Sep!D13) -> 0 | E13: =IF(AND(ISNUMBER(C13),ISNUMBER(D13)), C13-D13, "") -> 0 | F13: =IFERROR(E13/D13, "") | H13: =IF(AND(ISNUMBER(C13),ISNUMBER(G13)), C13-G13, "") | I13: =IFERROR(H13/G13, "")
A14: Roseville - Bank of America | B14: CA | C14: =SUM(Jul!C14, Aug!C14, Sep!C14) -> 0 | D14: =SUM(Jul!D14, Aug!D14, Sep!D14) -> 0 | E14: =IF(AND(ISNUMBER(C14),ISNUMBER(D14)), C14-D14, "") -> 0 | F14: =IFERROR(E14/D14, "") | H14: =IF(AND(ISNUMBER(C14),ISNUMBER(G14)), C14-G14, "") | I14: =IFERROR(H14/G14, "")
A15: San Bernardino - Bank of America | B15: CA | C15: =SUM(Jul!C15, Aug!C15, Sep!C15) -> 0 | D15: =SUM(Jul!D15, Aug!D15, Sep!D15) -> 0 | E15: =IF(AND(ISNUMBER(C15),ISNUMBER(D15)), C15-D15, "") -> 0 | F15: =IFERROR(E15/D15, "") | H15: =IF(AND(ISNUMBER(C15),ISNUMBER(G15)), C15-G15, "") | I15: =IFERROR(H15/G15, "")
A16: San Diego - Bank of America | B16: CA | C16: =SUM(Jul!C16, Aug!C16, Sep!C16) -> 0 | D16: =SUM(Jul!D16, Aug!D16, Sep!D16) -> 0 | E16: =IF(AND(ISNUMBER(C16),ISNUMBER(D16)), C16-D16, "") -> 0 | F16: =IFERROR(E16/D16, "") | H16: =IF(AND(ISNUMBER(C16),ISNUMBER(G16)), C16-G16, "") | I16: =IFERROR(H16/G16, "")
A17: Stockton - Bank of America | B17: CA | C17: =SUM(Jul!C17, Aug!C17, Sep!C17) -> 0 | D17: =SUM(Jul!D17, Aug!D17, Sep!D17) -> 0 | E17: =IF(AND(ISNUMBER(C17),ISNUMBER(D17)), C17-D17, "") -> 0 | F17: =IFERROR(E17/D17, "") | H17: =IF(AND(ISNUMBER(C17),ISNUMBER(G17)), C17-G17, "") | I17: =IFERROR(H17/G17, "")
A18: Victorville - Bank of America | B18: CA | E18: =IF(AND(ISNUMBER(C18),ISNUMBER(D18)), C18-D18, "") | H18: =IF(AND(ISNUMBER(C18),ISNUMBER(G18)), C18-G18, "")
A19: Aurora - BA - Colfax Ave | B19: CO | E19: =IF(AND(ISNUMBER(C19),ISNUMBER(D19)), C19-D19, "") | H19: =IF(AND(ISNUMBER(C19),ISNUMBER(G19)), C19-G19, "")
A20: Aurora - BA - Parker Rd | B20: CO | E20: =IF(AND(ISNUMBER(C20),ISNUMBER(D20)), C20-D20, "") | H20: =IF(AND(ISNUMBER(C20),ISNUMBER(G20)), C20-G20, "")
A21: Broomfield - Bank of America | B21: CO | E21: =IF(AND(ISNUMBER(C21),ISNUMBER(D21)), C21-D21, "") | H21: =IF(AND(ISNUMBER(C21),ISNUMBER(G21)), C21-G21, "")
A22: Colorado Springs - Bank of America | B22: CO | E22: =IF(AND(ISNUMBER(C22),ISNUMBER(D22)), C22-D22, "") | H22: =IF(AND(ISNUMBER(C22),ISNUMBER(G22)), C22-G22, "")
A23: Denver - BA - 49th Ave | B23: CO | E23: =IF(AND(ISNUMBER(C23),ISNUMBER(D23)), C23-D23, "") | H23: =IF(AND(ISNUMBER(C23),ISNUMBER(G23)), C23-G23, "")
A24: Denver - BA Wadsworth Blvd | B24: CO | E24: =IF(AND(ISNUMBER(C24),ISNUMBER(D24)), C24-D24, "") | H24: =IF(AND(ISNUMBER(C24),ISNUMBER(G24)), C24-G24, "")
A25: Fort Collins - Bank of America | B25: CO | E25: =IF(AND(ISNUMBER(C25),ISNUMBER(D25)), C25-D25, "") | H25: =IF(AND(ISNUMBER(C25),ISNUMBER(G25)), C25-G25, "")
A26: Lafayette - Bank of America | B26: CO | E26: =IF(AND(ISNUMBER(C26),ISNUMBER(D26)), C26-D26, "") | H26: =IF(AND(ISNUMBER(C26),ISNUMBER(G26)), C26-G26, "")
A27: Lakewood - Bank of America | B27: CO | E27: =IF(AND(ISNUMBER(C27),ISNUMBER(D27)), C27-D27, "") | H27: =IF(AND(ISNUMBER(C27),ISNUMBER(G27)), C27-G27, "")
A28: Longmont - Bank of America | B28: CO | E28: =IF(AND(ISNUMBER(C28),ISNUMBER(D28)), C28-D28, "") | H28: =IF(AND(ISNUMBER(C28),ISNUMBER(G28)), C28-G28, "")
A29: Thornton - Bank of America | B29: CO | E29: =IF(AND(ISNUMBER(C29),ISNUMBER(D29)), C29-D29, "") | H29: =IF(AND(ISNUMBER(C29),ISNUMBER(G29)), C29-G29, "")
... A38: Salt Lake City - Bank of America | B38: UT | E38: =IF(AND(ISNUMBER(C38),ISNUMBER(D38)), C38-D38, "") | H38: =IF(AND(ISNUMBER(C38),ISNUMBER(G38)), C38-G38, "")

Sheet 4th Qtr
A1: {=portfolio} -> Cushman & Wakefield | D1: 4th Quarter Actual v. Expected | G1: 4th Quarter Actual v. Forecasted
A2: Total | C2: =SUM(C4:C38) -> 0 | D2: =SUM(D4:D38) -> 0 | E2: =C2-D2 -> 0 | F2: =IFERROR(E2/D2, 0) -> 0 | G2: =SUM(G4:G38) -> 0 | H2: =C2-G2 -> 0 | I2: =IFERROR(H2/G2, 0) -> 0
A3: Site | B3: State | C3: Actual | D3: Expected | E3: Delta | F3: % | G3: Forecasted | H3: Delta | I3: %
A4: {=Sites[Site]} -> Adelanto - Bank of America | B4: {=Sites[State]} -> CA | C4: =SUM(Oct!C4, Nov!C4, Dec!C4) -> 0 | D4: =SUM(Oct!D4, Nov!D4, Dec!D4) -> 0 | E4: =IF(AND(ISNUMBER(C4),ISNUMBER(D4)), C4-D4, "") -> 0 | F4: =IFERROR(E4/D4, "") | H4: =IF(AND(ISNUMBER(C4),ISNUMBER(G4)), C4-G4, "") | I4: =IFERROR(H4/G4, "")
A5: Apple Valley - Bank of America | B5: CA | C5: =SUM(Oct!C5, Nov!C5, Dec!C5) -> 0 | D5: =SUM(Oct!D5, Nov!D5, Dec!D5) -> 0 | E5: =IF(AND(ISNUMBER(C5),ISNUMBER(D5)), C5-D5, "") -> 0 | F5: =IFERROR(E5/D5, "") | H5: =IF(AND(ISNUMBER(C5),ISNUMBER(G5)), C5-G5, "") | I5: =IFERROR(H5/G5, "")
A6: Arvin - Bank of America | B6: CA | C6: =SUM(Oct!C6, Nov!C6, Dec!C6) -> 0 | D6: =SUM(Oct!D6, Nov!D6, Dec!D6) -> 0 | E6: =IF(AND(ISNUMBER(C6),ISNUMBER(D6)), C6-D6, "") -> 0 | F6: =IFERROR(E6/D6, "") | H6: =IF(AND(ISNUMBER(C6),ISNUMBER(G6)), C6-G6, "") | I6: =IFERROR(H6/G6, "")
A7: Bell - Bank of America | B7: CA | C7: =SUM(Oct!C7, Nov!C7, Dec!C7) -> 0 | D7: =SUM(Oct!D7, Nov!D7, Dec!D7) -> 0 | E7: =IF(AND(ISNUMBER(C7),ISNUMBER(D7)), C7-D7, "") -> 0 | F7: =IFERROR(E7/D7, "") | H7: =IF(AND(ISNUMBER(C7),ISNUMBER(G7)), C7-G7, "") | I7: =IFERROR(H7/G7, "")
A8: Chula Vista - Bank of America | B8: CA | C8: =SUM(Oct!C8, Nov!C8, Dec!C8) -> 0 | D8: =SUM(Oct!D8, Nov!D8, Dec!D8) -> 0 | E8: =IF(AND(ISNUMBER(C8),ISNUMBER(D8)), C8-D8, "") -> 0 | F8: =IFERROR(E8/D8, "") | H8: =IF(AND(ISNUMBER(C8),ISNUMBER(G8)), C8-G8, "") | I8: =IFERROR(H8/G8, "")
A9: Cupertino - Bank of America | B9: CA | C9: =SUM(Oct!C9, Nov!C9, Dec!C9) -> 0 | D9: =SUM(Oct!D9, Nov!D9, Dec!D9) -> 0 | E9: =IF(AND(ISNUMBER(C9),ISNUMBER(D9)), C9-D9, "") -> 0 | F9: =IFERROR(E9/D9, "") | H9: =IF(AND(ISNUMBER(C9),ISNUMBER(G9)), C9-G9, "") | I9: =IFERROR(H9/G9, "")
A10: Diamond Bar - Bank of America | B10: CA | C10: =SUM(Oct!C10, Nov!C10, Dec!C10) -> 0 | D10: =SUM(Oct!D10, Nov!D10, Dec!D10) -> 0 | E10: =IF(AND(ISNUMBER(C10),ISNUMBER(D10)), C10-D10, "") -> 0 | F10: =IFERROR(E10/D10, "") | H10: =IF(AND(ISNUMBER(C10),ISNUMBER(G10)), C10-G10, "") | I10: =IFERROR(H10/G10, "")
A11: El Centro - Bank of America | B11: CA | C11: =SUM(Oct!C11, Nov!C11, Dec!C11) -> 0 | D11: =SUM(Oct!D11, Nov!D11, Dec!D11) -> 0 | E11: =IF(AND(ISNUMBER(C11),ISNUMBER(D11)), C11-D11, "") -> 0 | F11: =IFERROR(E11/D11, "") | H11: =IF(AND(ISNUMBER(C11),ISNUMBER(G11)), C11-G11, "") | I11: =IFERROR(H11/G11, "")
A12: Moreno Valley - Bank of America | B12: CA | C12: =SUM(Oct!C12, Nov!C12, Dec!C12) -> 0 | D12: =SUM(Oct!D12, Nov!D12, Dec!D12) -> 0 | E12: =IF(AND(ISNUMBER(C12),ISNUMBER(D12)), C12-D12, "") -> 0 | F12: =IFERROR(E12/D12, "") | H12: =IF(AND(ISNUMBER(C12),ISNUMBER(G12)), C12-G12, "") | I12: =IFERROR(H12/G12, "")
A13: Redlands - Bank of America | B13: CA | C13: =SUM(Oct!C13, Nov!C13, Dec!C13) -> 0 | D13: =SUM(Oct!D13, Nov!D13, Dec!D13) -> 0 | E13: =IF(AND(ISNUMBER(C13),ISNUMBER(D13)), C13-D13, "") -> 0 | F13: =IFERROR(E13/D13, "") | H13: =IF(AND(ISNUMBER(C13),ISNUMBER(G13)), C13-G13, "") | I13: =IFERROR(H13/G13, "")
A14: Roseville - Bank of America | B14: CA | C14: =SUM(Oct!C14, Nov!C14, Dec!C14) -> 0 | D14: =SUM(Oct!D14, Nov!D14, Dec!D14) -> 0 | E14: =IF(AND(ISNUMBER(C14),ISNUMBER(D14)), C14-D14, "") -> 0 | F14: =IFERROR(E14/D14, "") | H14: =IF(AND(ISNUMBER(C14),ISNUMBER(G14)), C14-G14, "") | I14: =IFERROR(H14/G14, "")
A15: San Bernardino - Bank of America | B15: CA | C15: =SUM(Oct!C15, Nov!C15, Dec!C15) -> 0 | D15: =SUM(Oct!D15, Nov!D15, Dec!D15) -> 0 | E15: =IF(AND(ISNUMBER(C15),ISNUMBER(D15)), C15-D15, "") -> 0 | F15: =IFERROR(E15/D15, "") | H15: =IF(AND(ISNUMBER(C15),ISNUMBER(G15)), C15-G15, "") | I15: =IFERROR(H15/G15, "")
A16: San Diego - Bank of America | B16: CA | C16: =SUM(Oct!C16, Nov!C16, Dec!C16) -> 0 | D16: =SUM(Oct!D16, Nov!D16, Dec!D16) -> 0 | E16: =IF(AND(ISNUMBER(C16),ISNUMBER(D16)), C16-D16, "") -> 0 | F16: =IFERROR(E16/D16, "") | H16: =IF(AND(ISNUMBER(C16),ISNUMBER(G16)), C16-G16, "") | I16: =IFERROR(H16/G16, "")
A17: Stockton - Bank of America | B17: CA | C17: =SUM(Oct!C17, Nov!C17, Dec!C17) -> 0 | D17: =SUM(Oct!D17, Nov!D17, Dec!D17) -> 0 | E17: =IF(AND(ISNUMBER(C17),ISNUMBER(D17)), C17-D17, "") -> 0 | F17: =IFERROR(E17/D17, "") | H17: =IF(AND(ISNUMBER(C17),ISNUMBER(G17)), C17-G17, "") | I17: =IFERROR(H17/G17, "")
A18: Victorville - Bank of America | B18: CA | E18: =IF(AND(ISNUMBER(C18),ISNUMBER(D18)), C18-D18, "") | H18: =IF(AND(ISNUMBER(C18),ISNUMBER(G18)), C18-G18, "")
A19: Aurora - BA - Colfax Ave | B19: CO | E19: =IF(AND(ISNUMBER(C19),ISNUMBER(D19)), C19-D19, "") | H19: =IF(AND(ISNUMBER(C19),ISNUMBER(G19)), C19-G19, "")
A20: Aurora - BA - Parker Rd | B20: CO | E20: =IF(AND(ISNUMBER(C20),ISNUMBER(D20)), C20-D20, "") | H20: =IF(AND(ISNUMBER(C20),ISNUMBER(G20)), C20-G20, "")
A21: Broomfield - Bank of America | B21: CO | E21: =IF(AND(ISNUMBER(C21),ISNUMBER(D21)), C21-D21, "") | H21: =IF(AND(ISNUMBER(C21),ISNUMBER(G21)), C21-G21, "")
A22: Colorado Springs - Bank of America | B22: CO | E22: =IF(AND(ISNUMBER(C22),ISNUMBER(D22)), C22-D22, "") | H22: =IF(AND(ISNUMBER(C22),ISNUMBER(G22)), C22-G22, "")
A23: Denver - BA - 49th Ave | B23: CO | E23: =IF(AND(ISNUMBER(C23),ISNUMBER(D23)), C23-D23, "") | H23: =IF(AND(ISNUMBER(C23),ISNUMBER(G23)), C23-G23, "")
A24: Denver - BA Wadsworth Blvd | B24: CO | E24: =IF(AND(ISNUMBER(C24),ISNUMBER(D24)), C24-D24, "") | H24: =IF(AND(ISNUMBER(C24),ISNUMBER(G24)), C24-G24, "")
A25: Fort Collins - Bank of America | B25: CO | E25: =IF(AND(ISNUMBER(C25),ISNUMBER(D25)), C25-D25, "") | H25: =IF(AND(ISNUMBER(C25),ISNUMBER(G25)), C25-G25, "")
A26: Lafayette - Bank of America | B26: CO | E26: =IF(AND(ISNUMBER(C26),ISNUMBER(D26)), C26-D26, "") | H26: =IF(AND(ISNUMBER(C26),ISNUMBER(G26)), C26-G26, "")
A27: Lakewood - Bank of America | B27: CO | E27: =IF(AND(ISNUMBER(C27),ISNUMBER(D27)), C27-D27, "") | H27: =IF(AND(ISNUMBER(C27),ISNUMBER(G27)), C27-G27, "")
A28: Longmont - Bank of America | B28: CO | E28: =IF(AND(ISNUMBER(C28),ISNUMBER(D28)), C28-D28, "") | H28: =IF(AND(ISNUMBER(C28),ISNUMBER(G28)), C28-G28, "")
A29: Thornton - Bank of America | B29: CO | E29: =IF(AND(ISNUMBER(C29),ISNUMBER(D29)), C29-D29, "") | H29: =IF(AND(ISNUMBER(C29),ISNUMBER(G29)), C29-G29, "")
... A38: Salt Lake City - Bank of America | B38: UT | E38: =IF(AND(ISNUMBER(C38),ISNUMBER(D38)), C38-D38, "") | H38: =IF(AND(ISNUMBER(C38),ISNUMBER(G38)), C38-G38, "")

Sheet Jan
A1: {=portfolio} -> Cushman & Wakefield | D1: January Actual v. Expected | G1: January Actual v. Forecasted
A2: Total | C2: =SUM(C4:C38) -> 0 | D2: =SUM(D4:D38) -> 0 | E2: =C2-D2 -> 0 | F2: =IFERROR(E2/D2, 0) -> 0 | G2: =SUM(G4:G38) -> 0 | H2: =C2-G2 -> 0 | I2: =IFERROR(H2/G2, 0) -> 0 | J2: =IF(AND(TODAY()>DATE(2024, 1, 1), COUNTA(Sites[Site])<>(COUNT(C:C)-1)), "Some sites are missing actual data; if new sites were added, make sure they are aligned correctly (including prior months!)", "") -> Some sites are missing actual data; if new sites were added, make sure they are aligned correctly (including prior months!)
A3: Site | B3: State | C3: Actual | D3: Expected | E3: Delta | F3: % | G3: Forecasted | H3: Delta | I3: % | J3: Notes | K3: Service Requests
A4: {=Sites[Site]} -> Adelanto - Bank of America | B4: {=Sites[State]} -> CA | E4: =IF(AND(ISNUMBER(C4),ISNUMBER(D4)), C4-D4, "") | F4: =IFERROR(E4/D4, "") | H4: =IF(AND(ISNUMBER(C4),ISNUMBER(G4)), C4-G4, "") | I4: =IFERROR(H4/G4, "")
A5: Apple Valley - Bank of America | B5: CA | E5: =IF(AND(ISNUMBER(C5),ISNUMBER(D5)), C5-D5, "") | F5: =IFERROR(E5/D5, "") | H5: =IF(AND(ISNUMBER(C5),ISNUMBER(G5)), C5-G5, "") | I5: =IFERROR(H5/G5, "")
A6: Arvin - Bank of America | B6: CA | E6: =IF(AND(ISNUMBER(C6),ISNUMBER(D6)), C6-D6, "") | F6: =IFERROR(E6/D6, "") | H6: =IF(AND(ISNUMBER(C6),ISNUMBER(G6)), C6-G6, "") | I6: =IFERROR(H6/G6, "")
A7: Bell - Bank of America | B7: CA | E7: =IF(AND(ISNUMBER(C7),ISNUMBER(D7)), C7-D7, "") | F7: =IFERROR(E7/D7, "") | H7: =IF(AND(ISNUMBER(C7),ISNUMBER(G7)), C7-G7, "") | I7: =IFERROR(H7/G7, "")
A8: Chula Vista - Bank of America | B8: CA | E8: =IF(AND(ISNUMBER(C8),ISNUMBER(D8)), C8-D8, "") | F8: =IFERROR(E8/D8, "") | H8: =IF(AND(ISNUMBER(C8),ISNUMBER(G8)), C8-G8, "") | I8: =IFERROR(H8/G8, "")
A9: Cupertino - Bank of America | B9: CA | E9: =IF(AND(ISNUMBER(C9),ISNUMBER(D9)), C9-D9, "") | F9: =IFERROR(E9/D9, "") | H9: =IF(AND(ISNUMBER(C9),ISNUMBER(G9)), C9-G9, "") | I9: =IFERROR(H9/G9, "")
A10: Diamond Bar - Bank of America | B10: CA | E10: =IF(AND(ISNUMBER(C10),ISNUMBER(D10)), C10-D10, "") | F10: =IFERROR(E10/D10, "") | H10: =IF(AND(ISNUMBER(C10),ISNUMBER(G10)), C10-G10, "") | I10: =IFERROR(H10/G10, "")
A11: El Centro - Bank of America | B11: CA | E11: =IF(AND(ISNUMBER(C11),ISNUMBER(D11)), C11-D11, "") | F11: =IFERROR(E11/D11, "") | H11: =IF(AND(ISNUMBER(C11),ISNUMBER(G11)), C11-G11, "") | I11: =IFERROR(H11/G11, "")
A12: Moreno Valley - Bank of America | B12: CA | E12: =IF(AND(ISNUMBER(C12),ISNUMBER(D12)), C12-D12, "") | F12: =IFERROR(E12/D12, "") | H12: =IF(AND(ISNUMBER(C12),ISNUMBER(G12)), C12-G12, "") | I12: =IFERROR(H12/G12, "")
A13: Redlands - Bank of America | B13: CA | E13: =IF(AND(ISNUMBER(C13),ISNUMBER(D13)), C13-D13, "") | F13: =IFERROR(E13/D13, "") | H13: =IF(AND(ISNUMBER(C13),ISNUMBER(G13)), C13-G13, "") | I13: =IFERROR(H13/G13, "")
A14: Roseville - Bank of America | B14: CA | E14: =IF(AND(ISNUMBER(C14),ISNUMBER(D14)), C14-D14, "") | F14: =IFERROR(E14/D14, "") | H14: =IF(AND(ISNUMBER(C14),ISNUMBER(G14)), C14-G14, "") | I14: =IFERROR(H14/G14, "")
A15: San Bernardino - Bank of America | B15: CA | E15: =IF(AND(ISNUMBER(C15),ISNUMBER(D15)), C15-D15, "") | F15: =IFERROR(E15/D15, "") | H15: =IF(AND(ISNUMBER(C15),ISNUMBER(G15)), C15-G15, "") | I15: =IFERROR(H15/G15, "")
A16: San Diego - Bank of America | B16: CA | E16: =IF(AND(ISNUMBER(C16),ISNUMBER(D16)), C16-D16, "") | F16: =IFERROR(E16/D16, "") | H16: =IF(AND(ISNUMBER(C16),ISNUMBER(G16)), C16-G16, "") | I16: =IFERROR(H16/G16, "")
... A38: Salt Lake City - Bank of America | B38: UT | E38: =IF(AND(ISNUMBER(C38),ISNUMBER(D38)), C38-D38, "") | F38: =IFERROR(E38/D38, "") | H38: =IF(AND(ISNUMBER(C38),ISNUMBER(G38)), C38-G38, "") | I38: =IFERROR(H38/G38, "")

Sheet Feb
A1: {=portfolio} -> Cushman & Wakefield | D1: February Actual v. Expected | G1: February Actual v. Forecasted
A2: Total | C2: =SUM(C4:C38) -> 0 | D2: =SUM(D4:D38) -> 0 | E2: =C2-D2 -> 0 | F2: =IFERROR(E2/D2, 0) -> 0 | G2: =SUM(G4:G38) -> 0 | H2: =C2-G2 -> 0 | I2: =IFERROR(H2/G2, 0) -> 0 | J2: =IF(AND(TODAY()>DATE(2024, 2, 1), COUNTA(Sites[Site])<>(COUNT(C:C)-1)), "Some sites are missing actual data; if new sites were added, make sure they are aligned correctly (including prior months!)", "") -> Some sites are missing actual data; if new sites were added, make sure they are aligned correctly (including prior months!)
A3: Site | B3: State | C3: Actual | D3: Expected | E3: Delta | F3: % | G3: Forecasted | H3: Delta | I3: % | J3: Notes | K3: Service Requests
A4: {=Sites[Site]} -> Adelanto - Bank of America | B4: {=Sites[State]} -> CA | E4: =IF(AND(ISNUMBER(C4),ISNUMBER(D4)), C4-D4, "") | F4: =IFERROR(E4/D4, "") | H4: =IF(AND(ISNUMBER(C4),ISNUMBER(G4)), C4-G4, "") | I4: =IFERROR(H4/G4, "")
A5: Apple Valley - Bank of America | B5: CA | E5: =IF(AND(ISNUMBER(C5),ISNUMBER(D5)), C5-D5, "") | F5: =IFERROR(E5/D5, "") | H5: =IF(AND(ISNUMBER(C5),ISNUMBER(G5)), C5-G5, "") | I5: =IFERROR(H5/G5, "")
A6: Arvin - Bank of America | B6: CA | E6: =IF(AND(ISNUMBER(C6),ISNUMBER(D6)), C6-D6, "") | F6: =IFERROR(E6/D6, "") | H6: =IF(AND(ISNUMBER(C6),ISNUMBER(G6)), C6-G6, "") | I6: =IFERROR(H6/G6, "")
A7: Bell - Bank of America | B7: CA | E7: =IF(AND(ISNUMBER(C7),ISNUMBER(D7)), C7-D7, "") | F7: =IFERROR(E7/D7, "") | H7: =IF(AND(ISNUMBER(C7),ISNUMBER(G7)), C7-G7, "") | I7: =IFERROR(H7/G7, "")
A8: Chula Vista - Bank of America | B8: CA | E8: =IF(AND(ISNUMBER(C8),ISNUMBER(D8)), C8-D8, "") | F8: =IFERROR(E8/D8, "") | H8: =IF(AND(ISNUMBER(C8),ISNUMBER(G8)), C8-G8, "") | I8: =IFERROR(H8/G8, "")
A9: Cupertino - Bank of America | B9: CA | E9: =IF(AND(ISNUMBER(C9),ISNUMBER(D9)), C9-D9, "") | F9: =IFERROR(E9/D9, "") | H9: =IF(AND(ISNUMBER(C9),ISNUMBER(G9)), C9-G9, "") | I9: =IFERROR(H9/G9, "")
A10: Diamond Bar - Bank of America | B10: CA | E10: =IF(AND(ISNUMBER(C10),ISNUMBER(D10)), C10-D10, "") | F10: =IFERROR(E10/D10, "") | H10: =IF(AND(ISNUMBER(C10),ISNUMBER(G10)), C10-G10, "") | I10: =IFERROR(H10/G10, "")
A11: El Centro - Bank of America | B11: CA | E11: =IF(AND(ISNUMBER(C11),ISNUMBER(D11)), C11-D11, "") | F11: =IFERROR(E11/D11, "") | H11: =IF(AND(ISNUMBER(C11),ISNUMBER(G11)), C11-G11, "") | I11: =IFERROR(H11/G11, "")
A12: Moreno Valley - Bank of America | B12: CA | E12: =IF(AND(ISNUMBER(C12),ISNUMBER(D12)), C12-D12, "") | F12: =IFERROR(E12/D12, "") | H12: =IF(AND(ISNUMBER(C12),ISNUMBER(G12)), C12-G12, "") | I12: =IFERROR(H12/G12, "")
A13: Redlands - Bank of America | B13: CA | E13: =IF(AND(ISNUMBER(C13),ISNUMBER(D13)), C13-D13, "") | F13: =IFERROR(E13/D13, "") | H13: =IF(AND(ISNUMBER(C13),ISNUMBER(G13)), C13-G13, "") | I13: =IFERROR(H13/G13, "")
A14: Roseville - Bank of America | B14: CA | E14: =IF(AND(ISNUMBER(C14),ISNUMBER(D14)), C14-D14, "") | F14: =IFERROR(E14/D14, "") | H14: =IF(AND(ISNUMBER(C14),ISNUMBER(G14)), C14-G14, "") | I14: =IFERROR(H14/G14, "")
A15: San Bernardino - Bank of America | B15: CA | E15: =IF(AND(ISNUMBER(C15),ISNUMBER(D15)), C15-D15, "") | F15: =IFERROR(E15/D15, "") | H15: =IF(AND(ISNUMBER(C15),ISNUMBER(G15)), C15-G15, "") | I15: =IFERROR(H15/G15, "")
A16: San Diego - Bank of America | B16: CA | E16: =IF(AND(ISNUMBER(C16),ISNUMBER(D16)), C16-D16, "") | F16: =IFERROR(E16/D16, "") | H16: =IF(AND(ISNUMBER(C16),ISNUMBER(G16)), C16-G16, "") | I16: =IFERROR(H16/G16, "")
... A38: Salt Lake City - Bank of America | B38: UT | E38: =IF(AND(ISNUMBER(C38),ISNUMBER(D38)), C38-D38, "") | F38: =IFERROR(E38/D38, "") | H38: =IF(AND(ISNUMBER(C38),ISNUMBER(G38)), C38-G38, "") | I38: =IFERROR(H38/G38, "")

Sheet Mar
A1: {=portfolio} -> Cushman & Wakefield | D1: March Actual v. Expected | G1: March Actual v. Forecasted
A2: Total | C2: =SUM(C4:C39) -> 0 | D2: =SUM(D4:D39) -> 0 | E2: =C2-D2 -> 0 | F2: =IFERROR(E2/D2, 0) -> 0 | G2: =SUM(G4:G39) -> 0 | H2: =C2-G2 -> 0 | I2: =IFERROR(H2/G2, 0) -> 0 | J2: =IF(AND(TODAY()>DATE(2024, 3, 1), COUNTA(Sites[Site])<>(COUNT(C:C)-1)), "Some sites are missing actual data; if new sites were added, make sure they are aligned correctly (including prior months!)", "") -> Some sites are missing actual data; if new sites were added, make sure they are aligned correctly (including prior months!)
A3: Site | B3: State | C3: Actual | D3: Expected | E3: Delta | F3: % | G3: Forecasted | H3: Delta | I3: % | J3: Notes | K3: Service Requests
A4: {=Sites[Site]} -> Adelanto - Bank of America | B4: {=Sites[State]} -> CA | E4: =IF(AND(ISNUMBER(C4),ISNUMBER(D4)), C4-D4, "") | F4: =IFERROR(E4/D4, "") | H4: =IF(AND(ISNUMBER(C4),ISNUMBER(G4)), C4-G4, "") | I4: =IFERROR(H4/G4, "")
A5: Apple Valley - Bank of America | B5: CA | E5: =IF(AND(ISNUMBER(C5),ISNUMBER(D5)), C5-D5, "") | F5: =IFERROR(E5/D5, "") | H5: =IF(AND(ISNUMBER(C5),ISNUMBER(G5)), C5-G5, "") | I5: =IFERROR(H5/G5, "")
A6: Arvin - Bank of America | B6: CA | E6: =IF(AND(ISNUMBER(C6),ISNUMBER(D6)), C6-D6, "") | F6: =IFERROR(E6/D6, "") | H6: =IF(AND(ISNUMBER(C6),ISNUMBER(G6)), C6-G6, "") | I6: =IFERROR(H6/G6, "")
A7: Bell - Bank of America | B7: CA | E7: =IF(AND(ISNUMBER(C7),ISNUMBER(D7)), C7-D7, "") | F7: =IFERROR(E7/D7, "") | H7: =IF(AND(ISNUMBER(C7),ISNUMBER(G7)), C7-G7, "") | I7: =IFERROR(H7/G7, "")
A8: Chula Vista - Bank of America | B8: CA | E8: =IF(AND(ISNUMBER(C8),ISNUMBER(D8)), C8-D8, "") | F8: =IFERROR(E8/D8, "") | H8: =IF(AND(ISNUMBER(C8),ISNUMBER(G8)), C8-G8, "") | I8: =IFERROR(H8/G8, "")
A9: Cupertino - Bank of America | B9: CA | E9: =IF(AND(ISNUMBER(C9),ISNUMBER(D9)), C9-D9, "") | F9: =IFERROR(E9/D9, "") | H9: =IF(AND(ISNUMBER(C9),ISNUMBER(G9)), C9-G9, "") | I9: =IFERROR(H9/G9, "")
A10: Diamond Bar - Bank of America | B10: CA | E10: =IF(AND(ISNUMBER(C10),ISNUMBER(D10)), C10-D10, "") | F10: =IFERROR(E10/D10, "") | H10: =IF(AND(ISNUMBER(C10),ISNUMBER(G10)), C10-G10, "") | I10: =IFERROR(H10/G10, "")
A11: El Centro - Bank of America | B11: CA | E11: =IF(AND(ISNUMBER(C11),ISNUMBER(D11)), C11-D11, "") | F11: =IFERROR(E11/D11, "") | H11: =IF(AND(ISNUMBER(C11),ISNUMBER(G11)), C11-G11, "") | I11: =IFERROR(H11/G11, "")
A12: Moreno Valley - Bank of America | B12: CA | E12: =IF(AND(ISNUMBER(C12),ISNUMBER(D12)), C12-D12, "") | F12: =IFERROR(E12/D12, "") | H12: =IF(AND(ISNUMBER(C12),ISNUMBER(G12)), C12-G12, "") | I12: =IFERROR(H12/G12, "")
A13: Redlands - Bank of America | B13: CA | E13: =IF(AND(ISNUMBER(C13),ISNUMBER(D13)), C13-D13, "") | F13: =IFERROR(E13/D13, "") | H13: =IF(AND(ISNUMBER(C13),ISNUMBER(G13)), C13-G13, "") | I13: =IFERROR(H13/G13, "")
A14: Roseville - Bank of America | B14: CA | E14: =IF(AND(ISNUMBER(C14),ISNUMBER(D14)), C14-D14, "") | F14: =IFERROR(E14/D14, "") | H14: =IF(AND(ISNUMBER(C14),ISNUMBER(G14)), C14-G14, "") | I14: =IFERROR(H14/G14, "")
A15: San Bernardino - Bank of America | B15: CA | E15: =IF(AND(ISNUMBER(C15),ISNUMBER(D15)), C15-D15, "") | F15: =IFERROR(E15/D15, "") | H15: =IF(AND(ISNUMBER(C15),ISNUMBER(G15)), C15-G15, "") | I15: =IFERROR(H15/G15, "")
A16: San Diego - Bank of America | B16: CA | E16: =IF(AND(ISNUMBER(C16),ISNUMBER(D16)), C16-D16, "") | F16: =IFERROR(E16/D16, "") | H16: =IF(AND(ISNUMBER(C16),ISNUMBER(G16)), C16-G16, "") | I16: =IFERROR(H16/G16, "")
... A38: Salt Lake City - Bank of America | B38: UT | E38: =IF(AND(ISNUMBER(C38),ISNUMBER(D38)), C38-D38, "") | F38: =IFERROR(E38/D38, "") | H38: =IF(AND(ISNUMBER(C38),ISNUMBER(G38)), C38-G38, "") | I38: =IFERROR(H38/G38, "")
E39: =IF(AND(ISNUMBER(C39),ISNUMBER(D39)), C39-D39, "") | F39: =IFERROR(E39/D39, "") | H39: =IF(AND(ISNUMBER(C39),ISNUMBER(G39)), C39-G39, "") | I39: =IFERROR(H39/G39, "")
E40: =IF(AND(ISNUMBER(C40),ISNUMBER(D40)), C40-D40, "")

Sheet Apr
A1: {=portfolio} -> Cushman & Wakefield | D1: April Actual v. Expected | G1: April Actual v. Forecasted
A2: Total | C2: =SUM(C4:C38) -> 0 | D2: =SUM(D4:D38) -> 0 | E2: =C2-D2 -> 0 | F2: =IFERROR(E2/D2, 0) -> 0 | G2: =SUM(G4:G38) -> 0 | H2: =C2-G2 -> 0 | I2: =IFERROR(H2/G2, 0) -> 0 | J2: =IF(AND(TODAY()>DATE(2024, 4, 1), COUNTA(Sites[Site])<>(COUNT(C:C)-1)), "Some sites are missing actual data; if new sites were added, make sure they are aligned correctly (including prior months!)", "") -> Some sites are missing actual data; if new sites were added, make sure they are aligned correctly (including prior months!)
A3: Site | B3: State | C3: Actual | D3: Expected | E3: Delta | F3: % | G3: Forecasted | H3: Delta | I3: % | J3: Notes | K3: Service Requests
A4: {=Sites[Site]} -> Adelanto - Bank of America | B4: {=Sites[State]} -> CA | E4: =IF(AND(ISNUMBER(C4),ISNUMBER(D4)), C4-D4, "") | F4: =IFERROR(E4/D4, "") | H4: =IF(AND(ISNUMBER(C4),ISNUMBER(G4)), C4-G4, "") | I4: =IFERROR(H4/G4, "")
A5: Apple Valley - Bank of America | B5: CA | E5: =IF(AND(ISNUMBER(C5),ISNUMBER(D5)), C5-D5, "") | F5: =IFERROR(E5/D5, "") | H5: =IF(AND(ISNUMBER(C5),ISNUMBER(G5)), C5-G5, "") | I5: =IFERROR(H5/G5, "")
A6: Arvin - Bank of America | B6: CA | E6: =IF(AND(ISNUMBER(C6),ISNUMBER(D6)), C6-D6, "") | F6: =IFERROR(E6/D6, "") | H6: =IF(AND(ISNUMBER(C6),ISNUMBER(G6)), C6-G6, "") | I6: =IFERROR(H6/G6, "")
A7: Bell - Bank of America | B7: CA | E7: =IF(AND(ISNUMBER(C7),ISNUMBER(D7)), C7-D7, "") | F7: =IFERROR(E7/D7, "") | H7: =IF(AND(ISNUMBER(C7),ISNUMBER(G7)), C7-G7, "") | I7: =IFERROR(H7/G7, "")
A8: Chula Vista - Bank of America | B8: CA | E8: =IF(AND(ISNUMBER(C8),ISNUMBER(D8)), C8-D8, "") | F8: =IFERROR(E8/D8, "") | H8: =IF(AND(ISNUMBER(C8),ISNUMBER(G8)), C8-G8, "") | I8: =IFERROR(H8/G8, "")
A9: Cupertino - Bank of America | B9: CA | E9: =IF(AND(ISNUMBER(C9),ISNUMBER(D9)), C9-D9, "") | F9: =IFERROR(E9/D9, "") | H9: =IF(AND(ISNUMBER(C9),ISNUMBER(G9)), C9-G9, "") | I9: =IFERROR(H9/G9, "")
A10: Diamond Bar - Bank of America | B10: CA | E10: =IF(AND(ISNUMBER(C10),ISNUMBER(D10)), C10-D10, "") | F10: =IFERROR(E10/D10, "") | H10: =IF(AND(ISNUMBER(C10),ISNUMBER(G10)), C10-G10, "") | I10: =IFERROR(H10/G10, "")
A11: El Centro - Bank of America | B11: CA | E11: =IF(AND(ISNUMBER(C11),ISNUMBER(D11)), C11-D11, "") | F11: =IFERROR(E11/D11, "") | H11: =IF(AND(ISNUMBER(C11),ISNUMBER(G11)), C11-G11, "") | I11: =IFERROR(H11/G11, "")
A12: Moreno Valley - Bank of America | B12: CA | E12: =IF(AND(ISNUMBER(C12),ISNUMBER(D12)), C12-D12, "") | F12: =IFERROR(E12/D12, "") | H12: =IF(AND(ISNUMBER(C12),ISNUMBER(G12)), C12-G12, "") | I12: =IFERROR(H12/G12, "")
A13: Redlands - Bank of America | B13: CA | E13: =IF(AND(ISNUMBER(C13),ISNUMBER(D13)), C13-D13, "") | F13: =IFERROR(E13/D13, "") | H13: =IF(AND(ISNUMBER(C13),ISNUMBER(G13)), C13-G13, "") | I13: =IFERROR(H13/G13, "")
A14: Roseville - Bank of America | B14: CA | E14: =IF(AND(ISNUMBER(C14),ISNUMBER(D14)), C14-D14, "") | F14: =IFERROR(E14/D14, "") | H14: =IF(AND(ISNUMBER(C14),ISNUMBER(G14)), C14-G14, "") | I14: =IFERROR(H14/G14, "")
A15: San Bernardino - Bank of America | B15: CA | E15: =IF(AND(ISNUMBER(C15),ISNUMBER(D15)), C15-D15, "") | F15: =IFERROR(E15/D15, "") | H15: =IF(AND(ISNUMBER(C15),ISNUMBER(G15)), C15-G15, "") | I15: =IFERROR(H15/G15, "")
A16: San Diego - Bank of America | B16: CA | E16: =IF(AND(ISNUMBER(C16),ISNUMBER(D16)), C16-D16, "") | F16: =IFERROR(E16/D16, "") | H16: =IF(AND(ISNUMBER(C16),ISNUMBER(G16)), C16-G16, "") | I16: =IFERROR(H16/G16, "")
A17: Stockton - Bank of America | B17: CA | E17: =IF(AND(ISNUMBER(C17),ISNUMBER(D17)), C17-D17, "") | F17: =IFERROR(E17/D17, "") | H17: =IF(AND(ISNUMBER(C17),ISNUMBER(G17)), C17-G17, "") | I17: =IFERROR(H17/G17, "")
A18: Victorville - Bank of America | B18: CA
A19: Aurora - BA - Colfax Ave | B19: CO
A20: Aurora - BA - Parker Rd | B20: CO
A21: Broomfield - Bank of America | B21: CO
A22: Colorado Springs - Bank of America | B22: CO
A23: Denver - BA - 49th Ave | B23: CO
A24: Denver - BA Wadsworth Blvd | B24: CO
A25: Fort Collins - Bank of America | B25: CO
A26: Lafayette - Bank of America | B26: CO
A27: Lakewood - Bank of America | B27: CO
A28: Longmont - Bank of America | B28: CO
A29: Thornton - Bank of America | B29: CO
... A38: Salt Lake City - Bank of America | B38: UT

Sheet May
A1: {=portfolio} -> Cushman & Wakefield | D1: May Actual v. Expected | G1: May Actual v. Forecasted
A2: Total | C2: =SUM(C4:C38) -> 0 | D2: =SUM(D4:D38) -> 0 | E2: =C2-D2 -> 0 | F2: =IFERROR(E2/D2, 0) -> 0 | G2: =SUM(G4:G38) -> 0 | H2: =C2-G2 -> 0 | I2: =IFERROR(H2/G2, 0) -> 0 | J2: =IF(AND(TODAY()>DATE(2024, 5, 1), COUNTA(Sites[Site])<>(COUNT(C:C)-1)), "Some sites are missing actual data; if new sites were added, make sure they are aligned correctly (including prior months!)", "") -> Some sites are missing actual data; if new sites were added, make sure they are aligned correctly (including prior months!)
A3: Site | B3: State | C3: Actual | D3: Expected | E3: Delta | F3: % | G3: Forecasted | H3: Delta | I3: % | J3: Notes | K3: Service Requests
A4: {=Sites[Site]} -> Adelanto - Bank of America | B4: {=Sites[State]} -> CA | E4: =IF(AND(ISNUMBER(C4),ISNUMBER(D4)), C4-D4, "") | F4: =IFERROR(E4/D4, "") | H4: =IF(AND(ISNUMBER(C4),ISNUMBER(G4)), C4-G4, "") | I4: =IFERROR(H4/G4, "")
A5: Apple Valley - Bank of America | B5: CA | E5: =IF(AND(ISNUMBER(C5),ISNUMBER(D5)), C5-D5, "") | F5: =IFERROR(E5/D5, "") | H5: =IF(AND(ISNUMBER(C5),ISNUMBER(G5)), C5-G5, "") | I5: =IFERROR(H5/G5, "")
A6: Arvin - Bank of America | B6: CA | E6: =IF(AND(ISNUMBER(C6),ISNUMBER(D6)), C6-D6, "") | F6: =IFERROR(E6/D6, "") | H6: =IF(AND(ISNUMBER(C6),ISNUMBER(G6)), C6-G6, "") | I6: =IFERROR(H6/G6, "")
A7: Bell - Bank of America | B7: CA | E7: =IF(AND(ISNUMBER(C7),ISNUMBER(D7)), C7-D7, "") | F7: =IFERROR(E7/D7, "") | H7: =IF(AND(ISNUMBER(C7),ISNUMBER(G7)), C7-G7, "") | I7: =IFERROR(H7/G7, "")
A8: Chula Vista - Bank of America | B8: CA | E8: =IF(AND(ISNUMBER(C8),ISNUMBER(D8)), C8-D8, "") | F8: =IFERROR(E8/D8, "") | H8: =IF(AND(ISNUMBER(C8),ISNUMBER(G8)), C8-G8, "") | I8: =IFERROR(H8/G8, "")
A9: Cupertino - Bank of America | B9: CA | E9: =IF(AND(ISNUMBER(C9),ISNUMBER(D9)), C9-D9, "") | F9: =IFERROR(E9/D9, "") | H9: =IF(AND(ISNUMBER(C9),ISNUMBER(G9)), C9-G9, "") | I9: =IFERROR(H9/G9, "")
A10: Diamond Bar - Bank of America | B10: CA | E10: =IF(AND(ISNUMBER(C10),ISNUMBER(D10)), C10-D10, "") | F10: =IFERROR(E10/D10, "") | H10: =IF(AND(ISNUMBER(C10),ISNUMBER(G10)), C10-G10, "") | I10: =IFERROR(H10/G10, "")
A11: El Centro - Bank of America | B11: CA | E11: =IF(AND(ISNUMBER(C11),ISNUMBER(D11)), C11-D11, "") | F11: =IFERROR(E11/D11, "") | H11: =IF(AND(ISNUMBER(C11),ISNUMBER(G11)), C11-G11, "") | I11: =IFERROR(H11/G11, "")
A12: Moreno Valley - Bank of America | B12: CA | E12: =IF(AND(ISNUMBER(C12),ISNUMBER(D12)), C12-D12, "") | F12: =IFERROR(E12/D12, "") | H12: =IF(AND(ISNUMBER(C12),ISNUMBER(G12)), C12-G12, "") | I12: =IFERROR(H12/G12, "")
A13: Redlands - Bank of America | B13: CA | E13: =IF(AND(ISNUMBER(C13),ISNUMBER(D13)), C13-D13, "") | F13: =IFERROR(E13/D13, "") | H13: =IF(AND(ISNUMBER(C13),ISNUMBER(G13)), C13-G13, "") | I13: =IFERROR(H13/G13, "")
A14: Roseville - Bank of America | B14: CA | E14: =IF(AND(ISNUMBER(C14),ISNUMBER(D14)), C14-D14, "") | F14: =IFERROR(E14/D14, "") | H14: =IF(AND(ISNUMBER(C14),ISNUMBER(G14)), C14-G14, "") | I14: =IFERROR(H14/G14, "")
A15: San Bernardino - Bank of America | B15: CA | E15: =IF(AND(ISNUMBER(C15),ISNUMBER(D15)), C15-D15, "") | F15: =IFERROR(E15/D15, "") | H15: =IF(AND(ISNUMBER(C15),ISNUMBER(G15)), C15-G15, "") | I15: =IFERROR(H15/G15, "")
A16: San Diego - Bank of America | B16: CA | E16: =IF(AND(ISNUMBER(C16),ISNUMBER(D16)), C16-D16, "") | F16: =IFERROR(E16/D16, "") | H16: =IF(AND(ISNUMBER(C16),ISNUMBER(G16)), C16-G16, "") | I16: =IFERROR(H16/G16, "")
A17: Stockton - Bank of America | B17: CA | E17: =IF(AND(ISNUMBER(C17),ISNUMBER(D17)), C17-D17, "") | F17: =IFERROR(E17/D17, "") | H17: =IF(AND(ISNUMBER(C17),ISNUMBER(G17)), C17-G17, "") | I17: =IFERROR(H17/G17, "")
A18: Victorville - Bank of America | B18: CA
A19: Aurora - BA - Colfax Ave | B19: CO
A20: Aurora - BA - Parker Rd | B20: CO
A21: Broomfield - Bank of America | B21: CO
A22: Colorado Springs - Bank of America | B22: CO
A23: Denver - BA - 49th Ave | B23: CO
A24: Denver - BA Wadsworth Blvd | B24: CO
A25: Fort Collins - Bank of America | B25: CO
A26: Lafayette - Bank of America | B26: CO
A27: Lakewood - Bank of America | B27: CO
A28: Longmont - Bank of America | B28: CO
A29: Thornton - Bank of America | B29: CO
... A38: Salt Lake City - Bank of America | B38: UT

Sheet Jun
A1: {=portfolio} -> Cushman & Wakefield | D1: June Actual v. Expected | G1: June Actual v. Forecasted
A2: Total | C2: =SUM(C4:C38) -> 0 | D2: =SUM(D4:D38) -> 0 | E2: =C2-D2 -> 0 | F2: =IFERROR(E2/D2, 0) -> 0 | G2: =SUM(G4:G38) -> 0 | H2: =C2-G2 -> 0 | I2: =IFERROR(H2/G2, 0) -> 0 | J2: =IF(AND(TODAY()>DATE(2024, 6, 1), COUNTA(Sites[Site])<>(COUNT(C:C)-1)), "Some sites are missing actual data; if new sites were added, make sure they are aligned correctly (including prior months!)", "")
A3: Site | B3: State | C3: Actual | D3: Expected | E3: Delta | F3: % | G3: Forecasted | H3: Delta | I3: % | J3: Notes | K3: Service Requests
A4: {=Sites[Site]} -> Adelanto - Bank of America | B4: {=Sites[State]} -> CA | E4: =IF(AND(ISNUMBER(C4),ISNUMBER(D4)), C4-D4, "") | F4: =IFERROR(E4/D4, "") | H4: =IF(AND(ISNUMBER(C4),ISNUMBER(G4)), C4-G4, "") | I4: =IFERROR(H4/G4, "")
A5: Apple Valley - Bank of America | B5: CA | E5: =IF(AND(ISNUMBER(C5),ISNUMBER(D5)), C5-D5, "") | F5: =IFERROR(E5/D5, "") | H5: =IF(AND(ISNUMBER(C5),ISNUMBER(G5)), C5-G5, "") | I5: =IFERROR(H5/G5, "")
A6: Arvin - Bank of America | B6: CA | E6: =IF(AND(ISNUMBER(C6),ISNUMBER(D6)), C6-D6, "") | F6: =IFERROR(E6/D6, "") | H6: =IF(AND(ISNUMBER(C6),ISNUMBER(G6)), C6-G6, "") | I6: =IFERROR(H6/G6, "")
A7: Bell - Bank of America | B7: CA | E7: =IF(AND(ISNUMBER(C7),ISNUMBER(D7)), C7-D7, "") | F7: =IFERROR(E7/D7, "") | H7: =IF(AND(ISNUMBER(C7),ISNUMBER(G7)), C7-G7, "") | I7: =IFERROR(H7/G7, "")
A8: Chula Vista - Bank of America | B8: CA | E8: =IF(AND(ISNUMBER(C8),ISNUMBER(D8)), C8-D8, "") | F8: =IFERROR(E8/D8, "") | H8: =IF(AND(ISNUMBER(C8),ISNUMBER(G8)), C8-G8, "") | I8: =IFERROR(H8/G8, "")
A9: Cupertino - Bank of America | B9: CA | E9: =IF(AND(ISNUMBER(C9),ISNUMBER(D9)), C9-D9, "") | F9: =IFERROR(E9/D9, "") | H9: =IF(AND(ISNUMBER(C9),ISNUMBER(G9)), C9-G9, "") | I9: =IFERROR(H9/G9, "")
A10: Diamond Bar - Bank of America | B10: CA | E10: =IF(AND(ISNUMBER(C10),ISNUMBER(D10)), C10-D10, "") | F10: =IFERROR(E10/D10, "") | H10: =IF(AND(ISNUMBER(C10),ISNUMBER(G10)), C10-G10, "") | I10: =IFERROR(H10/G10, "")
A11: El Centro - Bank of America | B11: CA | E11: =IF(AND(ISNUMBER(C11),ISNUMBER(D11)), C11-D11, "") | F11: =IFERROR(E11/D11, "") | H11: =IF(AND(ISNUMBER(C11),ISNUMBER(G11)), C11-G11, "") | I11: =IFERROR(H11/G11, "")
A12: Moreno Valley - Bank of America | B12: CA | E12: =IF(AND(ISNUMBER(C12),ISNUMBER(D12)), C12-D12, "") | F12: =IFERROR(E12/D12, "") | H12: =IF(AND(ISNUMBER(C12),ISNUMBER(G12)), C12-G12, "") | I12: =IFERROR(H12/G12, "")
A13: Redlands - Bank of America | B13: CA | E13: =IF(AND(ISNUMBER(C13),ISNUMBER(D13)), C13-D13, "") | F13: =IFERROR(E13/D13, "") | H13: =IF(AND(ISNUMBER(C13),ISNUMBER(G13)), C13-G13, "") | I13: =IFERROR(H13/G13, "")
A14: Roseville - Bank of America | B14: CA | E14: =IF(AND(ISNUMBER(C14),ISNUMBER(D14)), C14-D14, "") | F14: =IFERROR(E14/D14, "") | H14: =IF(AND(ISNUMBER(C14),ISNUMBER(G14)), C14-G14, "") | I14: =IFERROR(H14/G14, "")
A15: San Bernardino - Bank of America | B15: CA | E15: =IF(AND(ISNUMBER(C15),ISNUMBER(D15)), C15-D15, "") | F15: =IFERROR(E15/D15, "") | H15: =IF(AND(ISNUMBER(C15),ISNUMBER(G15)), C15-G15, "") | I15: =IFERROR(H15/G15, "")
A16: San Diego - Bank of America | B16: CA | E16: =IF(AND(ISNUMBER(C16),ISNUMBER(D16)), C16-D16, "") | F16: =IFERROR(E16/D16, "") | H16: =IF(AND(ISNUMBER(C16),ISNUMBER(G16)), C16-G16, "") | I16: =IFERROR(H16/G16, "")
A17: Stockton - Bank of America | B17: CA | E17: =IF(AND(ISNUMBER(C17),ISNUMBER(D17)), C17-D17, "") | F17: =IFERROR(E17/D17, "") | H17: =IF(AND(ISNUMBER(C17),ISNUMBER(G17)), C17-G17, "") | I17: =IFERROR(H17/G17, "")
A18: Victorville - Bank of America | B18: CA
A19: Aurora - BA - Colfax Ave | B19: CO
A20: Aurora - BA - Parker Rd | B20: CO
A21: Broomfield - Bank of America | B21: CO
A22: Colorado Springs - Bank of America | B22: CO
A23: Denver - BA - 49th Ave | B23: CO
A24: Denver - BA Wadsworth Blvd | B24: CO
A25: Fort Collins - Bank of America | B25: CO
A26: Lafayette - Bank of America | B26: CO
A27: Lakewood - Bank of America | B27: CO
A28: Longmont - Bank of America | B28: CO
A29: Thornton - Bank of America | B29: CO
... A38: Salt Lake City - Bank of America | B38: UT

Sheet Jul
A1: {=portfolio} -> Cushman & Wakefield | D1: July Actual v. Expected | G1: July Actual v. Forecasted
A2: Total | C2: =SUM(C4:C38) -> 0 | D2: =SUM(D4:D38) -> 0 | E2: =C2-D2 -> 0 | F2: =IFERROR(E2/D2, 0) -> 0 | G2: =SUM(G4:G38) -> 0 | H2: =C2-G2 -> 0 | I2: =IFERROR(H2/G2, 0) -> 0 | J2: =IF(AND(TODAY()>DATE(2024, 7, 1), COUNTA(Sites[Site])<>(COUNT(C:C)-1)), "Some sites are missing actual data; if new sites were added, make sure they are aligned correctly (including prior months!)", "")
A3: Site | B3: State | C3: Actual | D3: Expected | E3: Delta | F3: % | G3: Forecasted | H3: Delta | I3: % | J3: Notes | K3: Service Requests
A4: {=Sites[Site]} -> Adelanto - Bank of America | B4: {=Sites[State]} -> CA | E4: =IF(AND(ISNUMBER(C4),ISNUMBER(D4)), C4-D4, "") | F4: =IFERROR(E4/D4, "") | H4: =IF(AND(ISNUMBER(C4),ISNUMBER(G4)), C4-G4, "") | I4: =IFERROR(H4/G4, "")
A5: Apple Valley - Bank of America | B5: CA | E5: =IF(AND(ISNUMBER(C5),ISNUMBER(D5)), C5-D5, "") | F5: =IFERROR(E5/D5, "") | H5: =IF(AND(ISNUMBER(C5),ISNUMBER(G5)), C5-G5, "") | I5: =IFERROR(H5/G5, "")
A6: Arvin - Bank of America | B6: CA | E6: =IF(AND(ISNUMBER(C6),ISNUMBER(D6)), C6-D6, "") | F6: =IFERROR(E6/D6, "") | H6: =IF(AND(ISNUMBER(C6),ISNUMBER(G6)), C6-G6, "") | I6: =IFERROR(H6/G6, "")
A7: Bell - Bank of America | B7: CA | E7: =IF(AND(ISNUMBER(C7),ISNUMBER(D7)), C7-D7, "") | F7: =IFERROR(E7/D7, "") | H7: =IF(AND(ISNUMBER(C7),ISNUMBER(G7)), C7-G7, "") | I7: =IFERROR(H7/G7, "")
A8: Chula Vista - Bank of America | B8: CA | E8: =IF(AND(ISNUMBER(C8),ISNUMBER(D8)), C8-D8, "") | F8: =IFERROR(E8/D8, "") | H8: =IF(AND(ISNUMBER(C8),ISNUMBER(G8)), C8-G8, "") | I8: =IFERROR(H8/G8, "")
A9: Cupertino - Bank of America | B9: CA | E9: =IF(AND(ISNUMBER(C9),ISNUMBER(D9)), C9-D9, "") | F9: =IFERROR(E9/D9, "") | H9: =IF(AND(ISNUMBER(C9),ISNUMBER(G9)), C9-G9, "") | I9: =IFERROR(H9/G9, "")
A10: Diamond Bar - Bank of America | B10: CA | E10: =IF(AND(ISNUMBER(C10),ISNUMBER(D10)), C10-D10, "") | F10: =IFERROR(E10/D10, "") | H10: =IF(AND(ISNUMBER(C10),ISNUMBER(G10)), C10-G10, "") | I10: =IFERROR(H10/G10, "")
A11: El Centro - Bank of America | B11: CA | E11: =IF(AND(ISNUMBER(C11),ISNUMBER(D11)), C11-D11, "") | F11: =IFERROR(E11/D11, "") | H11: =IF(AND(ISNUMBER(C11),ISNUMBER(G11)), C11-G11, "") | I11: =IFERROR(H11/G11, "")
A12: Moreno Valley - Bank of America | B12: CA | E12: =IF(AND(ISNUMBER(C12),ISNUMBER(D12)), C12-D12, "") | F12: =IFERROR(E12/D12, "") | H12: =IF(AND(ISNUMBER(C12),ISNUMBER(G12)), C12-G12, "") | I12: =IFERROR(H12/G12, "")
