Workbook
Name JanActual: #REF!
Name JanActual2: #REF!
Name JanExpected: #REF!
Name JanExpectedDelta: #REF!
Name JanExpectedPercent: #REF!
Name JanExpPercent: #REF!
Name JanForecasted: #REF!
Name JanForecastedDelta: #REF!
Name JanForecastedPercent: #REF!
Name portfolio: Sites!$B$1:$B$1
Name Year: Sites!#REF!

Sheet Year to Date
A1: {=portfolio} -> Catalyze | D1: Year to Date Actual v. Expected | G1: Year to Date Actual v. Forecasted
A2: Total | C2: =SUM(C4:C92) -> 13433338 | D2: =SUM(D4:D92) -> 15240883 | E2: =C2-D2 -> -1807545.2 | F2: =IFERROR(E2/D2, 0) -> -0.11859845 | G2: =SUM(G4:G92) -> 15816760 | H2: =C2-G2 -> -2383421.8 | I2: =IFERROR(H2/G2, 0) -> -0.15068964
A3: Site | B3: State | C3: Actual | D3: Expected | E3: Delta | F3: % | G3: Forecasted | H3: Delta | I3: %
A4: {=Sites[Site]} -> Fresno - 3150 Shaw Ave | B4: {=Sites[State]} -> CA | C4: =SUM('1st Qtr'!C4, '2nd Qtr'!C4, '3rd Qtr'!C4, '4th Qtr'!C4) -> 291930.25 | D4: =SUM('1st Qtr'!D4, '2nd Qtr'!D4, '3rd Qtr'!D4, '4th Qtr'!D4) -> 281534.08 | E4: =IF(AND(ISNUMBER(C4),ISNUMBER(D4)), C4-D4, "") -> 10396.17 | F4: =IFERROR(E4/D4, "") -> 0.036926862 | G4: =SUM('1st Qtr'!G4, '2nd Qtr'!G4, '3rd Qtr'!G4, '4th Qtr'!G4) -> 319369.66 | H4: =SUM('1st Qtr'!H4, '2nd Qtr'!H4, '3rd Qtr'!H4, '4th Qtr'!H4) -> -27439.41 | I4: =IFERROR(H4/G4, "") -> -0.085917397
A5: Adelanto - 1 Sheep Creek Road | B5: CA | C5: =SUM('1st Qtr'!C5, '2nd Qtr'!C5, '3rd Qtr'!C5, '4th Qtr'!C5) -> 2373649 | D5: =SUM('1st Qtr'!D5, '2nd Qtr'!D5, '3rd Qtr'!D5, '4th Qtr'!D5) -> 1228232.7 | E5: =IF(AND(ISNUMBER(C5),ISNUMBER(D5)), C5-D5, "") -> 1145416.3 | F5: =IFERROR(E5/D5, "") -> 0.93257273 | G5: =SUM('1st Qtr'!G5, '2nd Qtr'!G5, '3rd Qtr'!G5, '4th Qtr'!G5) -> 1729663.7 | H5: =SUM('1st Qtr'!H5, '2nd Qtr'!H5, '3rd Qtr'!H5, '4th Qtr'!H5) -> -142320.74 | I5: =IFERROR(H5/G5, "") -> -0.082282317
A6: Blackstone - 83 Federal Street | B6: MA | C6: =SUM('1st Qtr'!C6, '2nd Qtr'!C6, '3rd Qtr'!C6, '4th Qtr'!C6) -> 1677975.3 | D6: =SUM('1st Qtr'!D6, '2nd Qtr'!D6, '3rd Qtr'!D6, '4th Qtr'!D6) -> 2388153.2 | E6: =IF(AND(ISNUMBER(C6),ISNUMBER(D6)), C6-D6, "") -> -710177.9 | F6: =IFERROR(E6/D6, "") -> -0.29737535 | G6: =SUM('1st Qtr'!G6, '2nd Qtr'!G6, '3rd Qtr'!G6, '4th Qtr'!G6) -> 2337925.9 | H6: =SUM('1st Qtr'!H6, '2nd Qtr'!H6, '3rd Qtr'!H6, '4th Qtr'!H6) -> -659950.6 | I6: =IFERROR(H6/G6, "") -> -0.28228038
A7: Charlton - 299 Worcester Road | B7: MA | C7: =SUM('1st Qtr'!C7, '2nd Qtr'!C7, '3rd Qtr'!C7, '4th Qtr'!C7) -> 166674.25 | D7: =SUM('1st Qtr'!D7, '2nd Qtr'!D7, '3rd Qtr'!D7, '4th Qtr'!D7) -> 192839.41 | E7: =IF(AND(ISNUMBER(C7),ISNUMBER(D7)), C7-D7, "") -> -26165.16 | F7: =IFERROR(E7/D7, "") -> -0.13568368 | G7: =SUM('1st Qtr'!G7, '2nd Qtr'!G7, '3rd Qtr'!G7, '4th Qtr'!G7) -> 191791.81 | H7: =SUM('1st Qtr'!H7, '2nd Qtr'!H7, '3rd Qtr'!H7, '4th Qtr'!H7) -> -25117.56 | I7: =IFERROR(H7/G7, "") -> -0.13096263
A8: Wareham - 8 Thatcher Drive | B8: MA | C8: =SUM('1st Qtr'!C8, '2nd Qtr'!C8, '3rd Qtr'!C8, '4th Qtr'!C8) -> 48696.25 | D8: =SUM('1st Qtr'!D8, '2nd Qtr'!D8, '3rd Qtr'!D8, '4th Qtr'!D8) -> 52204.658 | E8: =IF(AND(ISNUMBER(C8),ISNUMBER(D8)), C8-D8, "") -> -3508.408 | F8: =IFERROR(E8/D8, "") -> -0.067204884 | G8: =SUM('1st Qtr'!G8, '2nd Qtr'!G8, '3rd Qtr'!G8, '4th Qtr'!G8) -> 57449.88 | H8: =SUM('1st Qtr'!H8, '2nd Qtr'!H8, '3rd Qtr'!H8, '4th Qtr'!H8) -> -8753.63 | I8: =IFERROR(H8/G8, "") -> -0.15236986
A9: West Yarmouth - 42 Mid Tech | B9: MA | C9: =SUM('1st Qtr'!C9, '2nd Qtr'!C9, '3rd Qtr'!C9, '4th Qtr'!C9) -> 40081.319 | D9: =SUM('1st Qtr'!D9, '2nd Qtr'!D9, '3rd Qtr'!D9, '4th Qtr'!D9) -> 46126.38 | E9: =IF(AND(ISNUMBER(C9),ISNUMBER(D9)), C9-D9, "") -> -6045.0607 | F9: =IFERROR(E9/D9, "") -> -0.1310543 | G9: =SUM('1st Qtr'!G9, '2nd Qtr'!G9, '3rd Qtr'!G9, '4th Qtr'!G9) -> 49859.347 | H9: =SUM('1st Qtr'!H9, '2nd Qtr'!H9, '3rd Qtr'!H9, '4th Qtr'!H9) -> -9778.0277 | I9: =IFERROR(H9/G9, "") -> -0.19611223
A10: Harrison - 130 Union Street | B10: NY | C10: =SUM('1st Qtr'!C10, '2nd Qtr'!C10, '3rd Qtr'!C10, '4th Qtr'!C10) -> 70893.688 | D10: =SUM('1st Qtr'!D10, '2nd Qtr'!D10, '3rd Qtr'!D10, '4th Qtr'!D10) -> 80619.77 | E10: =IF(AND(ISNUMBER(C10),ISNUMBER(D10)), C10-D10, "") -> -9726.0825 | F10: =IFERROR(E10/D10, "") -> -0.12064141 | G10: =SUM('1st Qtr'!G10, '2nd Qtr'!G10, '3rd Qtr'!G10, '4th Qtr'!G10) -> 72430.53 | H10: =SUM('1st Qtr'!H10, '2nd Qtr'!H10, '3rd Qtr'!H10, '4th Qtr'!H10) -> -1536.8425 | I10: =IFERROR(H10/G10, "") -> -0.021218159
A11: Staten Island - Ellis Storage | B11: NY | C11: =SUM('1st Qtr'!C11, '2nd Qtr'!C11, '3rd Qtr'!C11, '4th Qtr'!C11) -> 162641.38 | D11: =SUM('1st Qtr'!D11, '2nd Qtr'!D11, '3rd Qtr'!D11, '4th Qtr'!D11) -> 160827.81 | E11: =IF(AND(ISNUMBER(C11),ISNUMBER(D11)), C11-D11, "") -> 1813.565 | F11: =IFERROR(E11/D11, "") -> 0.011276439 | G11: =SUM('1st Qtr'!G11, '2nd Qtr'!G11, '3rd Qtr'!G11, '4th Qtr'!G11) -> 162275.08 | H11: =SUM('1st Qtr'!H11, '2nd Qtr'!H11, '3rd Qtr'!H11, '4th Qtr'!H11) -> 366.295 | I11: =IFERROR(H11/G11, "") -> 0.0022572474
A12: Amherst - 595 Scholles Road | B12: NY | C12: =SUM('1st Qtr'!C12, '2nd Qtr'!C12, '3rd Qtr'!C12, '4th Qtr'!C12) -> 1792663.5 | D12: =SUM('1st Qtr'!D12, '2nd Qtr'!D12, '3rd Qtr'!D12, '4th Qtr'!D12) -> 2310767 | E12: =IF(AND(ISNUMBER(C12),ISNUMBER(D12)), C12-D12, "") -> -518103.5 | F12: =IFERROR(E12/D12, "") -> -0.22421278 | G12: =SUM('1st Qtr'!G12, '2nd Qtr'!G12, '3rd Qtr'!G12, '4th Qtr'!G12) -> 2325289.1 | H12: =SUM('1st Qtr'!H12, '2nd Qtr'!H12, '3rd Qtr'!H12, '4th Qtr'!H12) -> -532625.6 | I12: =IFERROR(H12/G12, "") -> -0.2290578
A13: Lancaster 1 - Gunnville Road | B13: NY | C13: =SUM('1st Qtr'!C13, '2nd Qtr'!C13, '3rd Qtr'!C13, '4th Qtr'!C13) -> 1661925 | D13: =SUM('1st Qtr'!D13, '2nd Qtr'!D13, '3rd Qtr'!D13, '4th Qtr'!D13) -> 1939679.8 | E13: =IF(AND(ISNUMBER(C13),ISNUMBER(D13)), C13-D13, "") -> -277754.8 | F13: =IFERROR(E13/D13, "") -> -0.14319621 | G13: =SUM('1st Qtr'!G13, '2nd Qtr'!G13, '3rd Qtr'!G13, '4th Qtr'!G13) -> 1956948.5 | H13: =SUM('1st Qtr'!H13, '2nd Qtr'!H13, '3rd Qtr'!H13, '4th Qtr'!H13) -> -295023.5 | I13: =IFERROR(H13/G13, "") -> -0.15075691
A14: Lancaster 2 - Shisler Road | B14: NY | C14: =SUM('1st Qtr'!C14, '2nd Qtr'!C14, '3rd Qtr'!C14, '4th Qtr'!C14) -> 1720749 | D14: =SUM('1st Qtr'!D14, '2nd Qtr'!D14, '3rd Qtr'!D14, '4th Qtr'!D14) -> 2170565.5 | E14: =IF(AND(ISNUMBER(C14),ISNUMBER(D14)), C14-D14, "") -> -449816.5 | F14: =IFERROR(E14/D14, "") -> -0.2072347 | G14: =SUM('1st Qtr'!G14, '2nd Qtr'!G14, '3rd Qtr'!G14, '4th Qtr'!G14) -> 2137363.5 | H14: =SUM('1st Qtr'!H14, '2nd Qtr'!H14, '3rd Qtr'!H14, '4th Qtr'!H14) -> -416614.5 | I14: =IFERROR(H14/G14, "") -> -0.19491982
A15: Fullerton - 200 W Orangethorpe | B15: CA | C15: =SUM('1st Qtr'!C15, '2nd Qtr'!C15, '3rd Qtr'!C15, '4th Qtr'!C15) -> 345313.62 | D15: =SUM('1st Qtr'!D15, '2nd Qtr'!D15, '3rd Qtr'!D15, '4th Qtr'!D15) -> 360349.78 | E15: =IF(AND(ISNUMBER(C15),ISNUMBER(D15)), C15-D15, "") -> -15036.155 | F15: =IFERROR(E15/D15, "") -> -0.041726555 | G15: =SUM('1st Qtr'!G15, '2nd Qtr'!G15, '3rd Qtr'!G15, '4th Qtr'!G15) -> 389069.04 | H15: =SUM('1st Qtr'!H15, '2nd Qtr'!H15, '3rd Qtr'!H15, '4th Qtr'!H15) -> -43755.415 | I15: =IFERROR(H15/G15, "") -> -0.11246183
A16: El Paso - 10500 Railroad Drive | B16: TX | C16: =SUM('1st Qtr'!C16, '2nd Qtr'!C16, '3rd Qtr'!C16, '4th Qtr'!C16) -> 490322.25 | D16: =SUM('1st Qtr'!D16, '2nd Qtr'!D16, '3rd Qtr'!D16, '4th Qtr'!D16) -> 452564.9 | E16: =IF(AND(ISNUMBER(C16),ISNUMBER(D16)), C16-D16, "") -> 37757.35 | F16: =IFERROR(E16/D16, "") -> 0.083429692 | G16: =SUM('1st Qtr'!G16, '2nd Qtr'!G16, '3rd Qtr'!G16, '4th Qtr'!G16) -> 476941.4 | H16: =SUM('1st Qtr'!H16, '2nd Qtr'!H16, '3rd Qtr'!H16, '4th Qtr'!H16) -> 13380.85 | I16: =IFERROR(H16/G16, "") -> 0.028055543
... A21: TX: Fort Worth - 5200 Gold Spike Dr | B21: TX | C21: =SUM('1st Qtr'!C21, '2nd Qtr'!C21, '3rd Qtr'!C21, '4th Qtr'!C21) -> 905113 | D21: =SUM('1st Qtr'!D21, '2nd Qtr'!D21, '3rd Qtr'!D21, '4th Qtr'!D21) -> 1676954.3 | E21: =IF(AND(ISNUMBER(C21),ISNUMBER(D21)), C21-D21, "") -> -771841.3 | F21: =IFERROR(E21/D21, "") -> -0.46026377 | G21: =SUM('1st Qtr'!G21, '2nd Qtr'!G21, '3rd Qtr'!G21, '4th Qtr'!G21) -> 1689619.7 | H21: =SUM('1st Qtr'!H21, '2nd Qtr'!H21, '3rd Qtr'!H21, '4th Qtr'!H21) -> -784506.7 | I21: =IFERROR(H21/G21, "") -> -0.46430963

Sheet 1st Qtr
A1: {=portfolio} -> Catalyze | D1: 1st Quarter Actual v. Expected | G1: 1st Quarter Actual v. Forecasted
A2: Total | C2: =SUM(C4:C92) -> 8269951.4 | D2: =SUM(D4:D92) -> 10417124 | E2: =C2-D2 -> -2147173 | F2: =IFERROR(E2/D2, 0) -> -0.20611955 | G2: =SUM(G4:G92) -> 10616413 | H2: =C2-G2 -> -2346461.3 | I2: =IFERROR(H2/G2, 0) -> -0.22102205
A3: Site | B3: State | C3: Actual | D3: Expected | E3: Delta | F3: % | G3: Forecasted | H3: Delta | I3: %
A4: {=Sites[Site]} -> Fresno - 3150 Shaw Ave | B4: {=Sites[State]} -> CA | C4: =SUM(Jan!C4, Feb!C4, Mar!C4) -> 191319.25 | D4: =SUM(Jan!D4, Feb!D4, Mar!D4) -> 182900.39 | E4: =IF(AND(ISNUMBER(C4),ISNUMBER(D4)), C4-D4, "") -> 8418.86 | F4: =IFERROR(E4/D4, "") -> 0.046029754 | G4: =SUM(Jan!G4, Feb!G4, Mar!G4) -> 210362.36 | H4: =SUM(Jan!H4, Feb!H4, Mar!H4) -> -19043.11 | I4: =IFERROR(H4/G4, "") -> -0.090525273
A5: Adelanto - 1 Sheep Creek Road | B5: CA | C5: =SUM(Jan!C5, Feb!C5, Mar!C5) -> 1587343 | D5: =SUM(Jan!D5, Feb!D5, Mar!D5) -> 1054002 | E5: =IF(AND(ISNUMBER(C5),ISNUMBER(D5)), C5-D5, "") -> 533340.96 | F5: =IFERROR(E5/D5, "") -> 0.50601511 | G5: =SUM(Jan!G5, Feb!G5, Mar!G5) -> 1729663.7 | H5: =SUM(Jan!H5, Feb!H5, Mar!H5) -> -142320.74 | I5: =IFERROR(H5/G5, "") -> -0.082282317
A6: Blackstone - 83 Federal Street | B6: MA | C6: =SUM(Jan!C6, Feb!C6, Mar!C6) -> 1187392.8 | D6: =SUM(Jan!D6, Feb!D6, Mar!D6) -> 1690571.4 | E6: =IF(AND(ISNUMBER(C6),ISNUMBER(D6)), C6-D6, "") -> -503178.6 | F6: =IFERROR(E6/D6, "") -> -0.29763818 | G6: =SUM(Jan!G6, Feb!G6, Mar!G6) -> 1569257.1 | H6: =SUM(Jan!H6, Feb!H6, Mar!H6) -> -381864.3 | I6: =IFERROR(H6/G6, "") -> -0.24334081
A7: Charlton - 299 Worcester Road | B7: MA | C7: =SUM(Jan!C7, Feb!C7, Mar!C7) -> 106801.75 | D7: =SUM(Jan!D7, Feb!D7, Mar!D7) -> 132014.25 | E7: =IF(AND(ISNUMBER(C7),ISNUMBER(D7)), C7-D7, "") -> -25212.5 | F7: =IFERROR(E7/D7, "") -> -0.19098317 | G7: =SUM(Jan!G7, Feb!G7, Mar!G7) -> 122312.49 | H7: =SUM(Jan!H7, Feb!H7, Mar!H7) -> -15510.74 | I7: =IFERROR(H7/G7, "") -> -0.1268124
A8: Wareham - 8 Thatcher Drive | B8: MA | C8: =SUM(Jan!C8, Feb!C8, Mar!C8) -> 31580.938 | D8: =SUM(Jan!D8, Feb!D8, Mar!D8) -> 35070.628 | E8: =IF(AND(ISNUMBER(C8),ISNUMBER(D8)), C8-D8, "") -> -3489.6905 | F8: =IFERROR(E8/D8, "") -> -0.099504648 | G8: =SUM(Jan!G8, Feb!G8, Mar!G8) -> 36936.37 | H8: =SUM(Jan!H8, Feb!H8, Mar!H8) -> -5355.4325 | I8: =IFERROR(H8/G8, "") -> -0.14499076
A9: West Yarmouth - 42 Mid Tech | B9: MA | C9: =SUM(Jan!C9, Feb!C9, Mar!C9) -> 24674.209 | D9: =SUM(Jan!D9, Feb!D9, Mar!D9) -> 29517.25 | E9: =IF(AND(ISNUMBER(C9),ISNUMBER(D9)), C9-D9, "") -> -4843.0413 | F9: =IFERROR(E9/D9, "") -> -0.16407495 | G9: =SUM(Jan!G9, Feb!G9, Mar!G9) -> 30853.657 | H9: =SUM(Jan!H9, Feb!H9, Mar!H9) -> -6179.4483 | I9: =IFERROR(H9/G9, "") -> -0.20028252
A10: Harrison - 130 Union Street | B10: NY | C10: =SUM(Jan!C10, Feb!C10, Mar!C10) -> 45554.375 | D10: =SUM(Jan!D10, Feb!D10, Mar!D10) -> 54840.16 | E10: =IF(AND(ISNUMBER(C10),ISNUMBER(D10)), C10-D10, "") -> -9285.785 | F10: =IFERROR(E10/D10, "") -> -0.16932454 | G10: =SUM(Jan!G10, Feb!G10, Mar!G10) -> 46386.63 | H10: =SUM(Jan!H10, Feb!H10, Mar!H10) -> -832.255 | I10: =IFERROR(H10/G10, "") -> -0.0179417
A11: Staten Island - Ellis Storage | B11: NY | C11: =SUM(Jan!C11, Feb!C11, Mar!C11) -> 107385.75 | D11: =SUM(Jan!D11, Feb!D11, Mar!D11) -> 111143.44 | E11: =IF(AND(ISNUMBER(C11),ISNUMBER(D11)), C11-D11, "") -> -3757.69 | F11: =IFERROR(E11/D11, "") -> -0.033809373 | G11: =SUM(Jan!G11, Feb!G11, Mar!G11) -> 101748.88 | H11: =SUM(Jan!H11, Feb!H11, Mar!H11) -> 5636.87 | I11: =IFERROR(H11/G11, "") -> 0.055399824
A12: Amherst - 595 Scholles Road | B12: NY | C12: =SUM(Jan!C12, Feb!C12, Mar!C12) -> 980445 | D12: =SUM(Jan!D12, Feb!D12, Mar!D12) -> 1472428.2 | E12: =IF(AND(ISNUMBER(C12),ISNUMBER(D12)), C12-D12, "") -> -491983.2 | F12: =IFERROR(E12/D12, "") -> -0.33413052 | G12: =SUM(Jan!G12, Feb!G12, Mar!G12) -> 1409205.8 | H12: =SUM(Jan!H12, Feb!H12, Mar!H12) -> -428760.8 | I12: =IFERROR(H12/G12, "") -> -0.30425705
A13: Lancaster 1 - Gunnville Road | B13: NY | C13: =SUM(Jan!C13, Feb!C13, Mar!C13) -> 994031 | D13: =SUM(Jan!D13, Feb!D13, Mar!D13) -> 1280756.5 | E13: =IF(AND(ISNUMBER(C13),ISNUMBER(D13)), C13-D13, "") -> -286725.5 | F13: =IFERROR(E13/D13, "") -> -0.22387199 | G13: =SUM(Jan!G13, Feb!G13, Mar!G13) -> 1213137.7 | H13: =SUM(Jan!H13, Feb!H13, Mar!H13) -> -219106.7 | I13: =IFERROR(H13/G13, "") -> -0.18061157
A14: Lancaster 2 - Shisler Road | B14: NY | C14: =SUM(Jan!C14, Feb!C14, Mar!C14) -> 1018864 | D14: =SUM(Jan!D14, Feb!D14, Mar!D14) -> 1447535.4 | E14: =IF(AND(ISNUMBER(C14),ISNUMBER(D14)), C14-D14, "") -> -428671.4 | F14: =IFERROR(E14/D14, "") -> -0.2961388 | G14: =SUM(Jan!G14, Feb!G14, Mar!G14) -> 1320331.3 | H14: =SUM(Jan!H14, Feb!H14, Mar!H14) -> -301467.3 | I14: =IFERROR(H14/G14, "") -> -0.22832701
A15: Fullerton - 200 W Orangethorpe | B15: CA | C15: =SUM(Jan!C15, Feb!C15, Mar!C15) -> 233829 | D15: =SUM(Jan!D15, Feb!D15, Mar!D15) -> 248271.58 | E15: =IF(AND(ISNUMBER(C15),ISNUMBER(D15)), C15-D15, "") -> -14442.58 | F15: =IFERROR(E15/D15, "") -> -0.058172506 | G15: =SUM(Jan!G15, Feb!G15, Mar!G15) -> 267643.14 | H15: =SUM(Jan!H15, Feb!H15, Mar!H15) -> -33814.14 | I15: =IFERROR(H15/G15, "") -> -0.12634039
A16: El Paso - 10500 Railroad Drive | B16: TX | C16: =SUM(Jan!C16, Feb!C16, Mar!C16) -> 336379.75 | D16: =SUM(Jan!D16, Feb!D16, Mar!D16) -> 316832.5 | E16: =IF(AND(ISNUMBER(C16),ISNUMBER(D16)), C16-D16, "") -> 19547.25 | F16: =IFERROR(E16/D16, "") -> 0.061695849 | G16: =SUM(Jan!G16, Feb!G16, Mar!G16) -> 329629.5 | H16: =SUM(Jan!H16, Feb!H16, Mar!H16) -> 6750.25 | I16: =IFERROR(H16/G16, "") -> 0.020478295
... A18: Augusta - 13 York Farm Road | B18: ME | C18: =SUM(Jan!C18, Feb!C18, Mar!C18) -> 249165.88 | D18: =SUM(Jan!D18, Feb!D18, Mar!D18) -> 430137 | E18: =IF(AND(ISNUMBER(C18),ISNUMBER(D18)), C18-D18, "") -> -180971.12 | F18: =IFERROR(E18/D18, "") -> -0.42072904 | G18: =SUM(Jan!G18, Feb!G18, Mar!G18) -> 370860.9 | H18: =SUM(Jan!H18, Feb!H18, Mar!H18) -> -121695.02 | I18: =IFERROR(H18/G18, "") -> -0.32814197
A19: Santa Ana - 1441 West | B19: CA | C19: =SUM(Jan!C19, Feb!C19, Mar!C19) -> 149317.34 | D19: =SUM(Jan!D19, Feb!D19, Mar!D19) -> 147455.37 | E19: =SUM(Jan!E19, Feb!E19, Mar!E19) -> 1861.9712 | F19: =IFERROR(E19/D19, "") -> 0.012627355 | G19: =SUM(Jan!G19, Feb!G19, Mar!G19) -> 171259.21 | H19: =SUM(Jan!H19, Feb!H19, Mar!H19) -> -21941.869 | I19: =IFERROR(H19/G19, "") -> -0.12812081
A20: Jessup -7950 Oceano Ave | B20: MD | C20: =SUM(Jan!C20, Feb!C20, Mar!C20) -> 468523.25 | D20: =SUM(Jan!D20, Feb!D20, Mar!D20) -> 510687.1 | E20: =SUM(Jan!E20, Feb!E20, Mar!E20) -> -42163.85 | F20: =IFERROR(E20/D20, "") -> -0.082562982 | G20: =SUM(Jan!G20, Feb!G20, Mar!G20) -> 480450.7 | H20: =SUM(Jan!H20, Feb!H20, Mar!H20) -> -11927.45 | I20: =IFERROR(H20/G20, "") -> -0.024825544
A21: TX: Fort Worth - 5200 Gold Spike Dr | B21: TX | C21: =SUM(Jan!C21, Feb!C21, Mar!C21) -> 295518 | D21: =SUM(Jan!D21, Feb!D21, Mar!D21) -> 1021534.4 | E21: =SUM(Jan!E21, Feb!E21, Mar!E21) -> -726016.4 | F21: =IFERROR(E21/D21, "") -> -0.71071165 | G21: =SUM(Jan!G21, Feb!G21, Mar!G21) -> 948956.4 | H21: =SUM(Jan!H21, Feb!H21, Mar!H21) -> -653438.4 | I21: =IFERROR(H21/G21, "") -> -0.68858632

Sheet 2nd Qtr
A1: {=portfolio} -> Catalyze | D1: 2nd Quarter Actual v. Expected | G1: 2nd Quarter Actual v. Forecasted
A2: Total | C2: =SUM(C4:C92) -> 5163386.5 | D2: =SUM(D4:D92) -> 4823758.6 | E2: =C2-D2 -> 339627.84 | F2: =IFERROR(E2/D2, 0) -> 0.070407304 | G2: =SUM(G4:G92) -> 5200347 | H2: =C2-G2 -> -36960.542 | I2: =IFERROR(H2/G2, 0) -> -0.0071073222
A3: Site | B3: State | C3: Actual | D3: Expected | E3: Delta | F3: % | G3: Forecasted | H3: Delta | I3: %
A4: {=Sites[Site]} -> Fresno - 3150 Shaw Ave | B4: {=Sites[State]} -> CA | C4: =SUM(Apr!C4, May!C4, Jun!C4) -> 100611 | D4: =SUM(Apr!D4, May!D4, Jun!D4) -> 98633.69 | E4: =IF(AND(ISNUMBER(C4),ISNUMBER(D4)), C4-D4, "") -> 1977.31 | F4: =IFERROR(E4/D4, "") -> 0.020047004 | G4: =SUM(Apr!G4+May!G4+Jun!G4) -> 109007.3 | H4: =SUM(Apr!H4, May!H4, Jun!H4) -> -8396.3 | I4: =IFERROR(H4/G4, "") -> -0.077025117
A5: Adelanto - 1 Sheep Creek Road | B5: CA | C5: =SUM(Apr!C5, May!C5, Jun!C5) -> 786306 | D5: =SUM(Apr!D5, May!D5, Jun!D5) -> 174230.65 | E5: =IF(AND(ISNUMBER(C5),ISNUMBER(D5)), C5-D5, "") -> 612075.35 | F5: =IFERROR(E5/D5, "") -> 3.5130177 | G5: =SUM(Apr!G5+May!G5+Jun!G5) -> 0 | H5: =SUM(Apr!H5, May!H5, Jun!H5) -> 0 | I5: =IFERROR(H5/G5, "")
A6: Blackstone - 83 Federal Street | B6: MA | C6: =SUM(Apr!C6, May!C6, Jun!C6) -> 490582.5 | D6: =SUM(Apr!D6, May!D6, Jun!D6) -> 697581.8 | E6: =IF(AND(ISNUMBER(C6),ISNUMBER(D6)), C6-D6, "") -> -206999.3 | F6: =IFERROR(E6/D6, "") -> -0.29673839 | G6: =SUM(Apr!G6+May!G6+Jun!G6) -> 768668.8 | H6: =SUM(Apr!H6, May!H6, Jun!H6) -> -278086.3 | I6: =IFERROR(H6/G6, "") -> -0.36177649
A7: Charlton - 299 Worcester Road | B7: MA | C7: =SUM(Apr!C7, May!C7, Jun!C7) -> 59872.5 | D7: =SUM(Apr!D7, May!D7, Jun!D7) -> 60825.16 | E7: =IF(AND(ISNUMBER(C7),ISNUMBER(D7)), C7-D7, "") -> -952.66 | F7: =IFERROR(E7/D7, "") -> -0.015662269 | G7: =SUM(Apr!G7+May!G7+Jun!G7) -> 69479.32 | H7: =SUM(Apr!H7, May!H7, Jun!H7) -> -9606.82 | I7: =IFERROR(H7/G7, "") -> -0.13826877
A8: Wareham - 8 Thatcher Drive | B8: MA | C8: =SUM(Apr!C8, May!C8, Jun!C8) -> 17115.312 | D8: =SUM(Apr!D8, May!D8, Jun!D8) -> 17134.03 | E8: =IF(AND(ISNUMBER(C8),ISNUMBER(D8)), C8-D8, "") -> -18.7175 | F8: =IFERROR(E8/D8, "") -> -0.0010924167 | G8: =SUM(Apr!G8+May!G8+Jun!G8) -> 20513.51 | H8: =SUM(Apr!H8, May!H8, Jun!H8) -> -3398.1975 | I8: =IFERROR(H8/G8, "") -> -0.16565656
A9: West Yarmouth - 42 Mid Tech | B9: MA | C9: =SUM(Apr!C9, May!C9, Jun!C9) -> 15407.111 | D9: =SUM(Apr!D9, May!D9, Jun!D9) -> 16609.13 | E9: =IF(AND(ISNUMBER(C9),ISNUMBER(D9)), C9-D9, "") -> -1202.0194 | F9: =IFERROR(E9/D9, "") -> -0.072371002 | G9: =SUM(Apr!G9+May!G9+Jun!G9) -> 19005.69 | H9: =SUM(Apr!H9, May!H9, Jun!H9) -> -3598.5794 | I9: =IFERROR(H9/G9, "") -> -0.18934221
A10: Harrison - 130 Union Street | B10: NY | C10: =SUM(Apr!C10, May!C10, Jun!C10) -> 25339.312 | D10: =SUM(Apr!D10, May!D10, Jun!D10) -> 25779.61 | E10: =IF(AND(ISNUMBER(C10),ISNUMBER(D10)), C10-D10, "") -> -440.2975 | F10: =IFERROR(E10/D10, "") -> -0.017079293 | G10: =SUM(Apr!G10+May!G10+Jun!G10) -> 26043.9 | H10: =SUM(Apr!H10, May!H10, Jun!H10) -> -704.5875 | I10: =IFERROR(H10/G10, "") -> -0.02705384
A11: Staten Island - Ellis Storage | B11: NY | C11: =SUM(Apr!C11, May!C11, Jun!C11) -> 55255.625 | D11: =SUM(Apr!D11, May!D11, Jun!D11) -> 49684.37 | E11: =IF(AND(ISNUMBER(C11),ISNUMBER(D11)), C11-D11, "") -> 5571.255 | F11: =IFERROR(E11/D11, "") -> 0.11213295 | G11: =SUM(Apr!G11+May!G11+Jun!G11) -> 60526.2 | H11: =SUM(Apr!H11, May!H11, Jun!H11) -> -5270.575 | I11: =IFERROR(H11/G11, "") -> -0.087079232
A12: Amherst - 595 Scholles Road | B12: NY | C12: =SUM(Apr!C12, May!C12, Jun!C12) -> 812218.5 | D12: =SUM(Apr!D12, May!D12, Jun!D12) -> 838338.8 | E12: =IF(AND(ISNUMBER(C12),ISNUMBER(D12)), C12-D12, "") -> -26120.3 | F12: =IFERROR(E12/D12, "") -> -0.031157212 | G12: =SUM(Apr!G12+May!G12+Jun!G12) -> 916083.3 | H12: =SUM(Apr!H12, May!H12, Jun!H12) -> -103864.8 | I12: =IFERROR(H12/G12, "") -> -0.11337921
A13: Lancaster 1 - Gunnville Road | B13: NY | C13: =SUM(Apr!C13, May!C13, Jun!C13) -> 667894 | D13: =SUM(Apr!D13, May!D13, Jun!D13) -> 658923.3 | E13: =IF(AND(ISNUMBER(C13),ISNUMBER(D13)), C13-D13, "") -> 8970.7 | F13: =IFERROR(E13/D13, "") -> 0.013614179 | G13: =SUM(Apr!G13+May!G13+Jun!G13) -> 743810.8 | H13: =SUM(Apr!H13, May!H13, Jun!H13) -> -75916.8 | I13: =IFERROR(H13/G13, "") -> -0.10206466
A14: Lancaster 2 - Shisler Road | B14: NY | C14: =SUM(Apr!C14, May!C14, Jun!C14) -> 701885 | D14: =SUM(Apr!D14, May!D14, Jun!D14) -> 723030.1 | E14: =IF(AND(ISNUMBER(C14),ISNUMBER(D14)), C14-D14, "") -> -21145.1 | F14: =IFERROR(E14/D14, "") -> -0.029245117 | G14: =SUM(Apr!G14+May!G14+Jun!G14) -> 817032.2 | H14: =SUM(Apr!H14, May!H14, Jun!H14) -> -115147.2 | I14: =IFERROR(H14/G14, "") -> -0.14093349
A15: Fullerton - 200 W Orangethorpe | B15: CA | C15: =SUM(Apr!C15, May!C15, Jun!C15) -> 111484.62 | D15: =SUM(Apr!D15, May!D15, Jun!D15) -> 112078.2 | E15: =IF(AND(ISNUMBER(C15),ISNUMBER(D15)), C15-D15, "") -> -593.575 | F15: =IFERROR(E15/D15, "") -> -0.005296079 | G15: =SUM(Apr!G15+May!G15+Jun!G15) -> 121425.9 | H15: =SUM(Apr!H15, May!H15, Jun!H15) -> -9941.275 | I15: =IFERROR(H15/G15, "") -> -0.081871125
A16: El Paso - 10500 Railroad Drive | B16: TX | C16: =SUM(Apr!C16, May!C16, Jun!C16) -> 153942.5 | D16: =SUM(Apr!D16, May!D16, Jun!D16) -> 135732.4 | E16: =IF(AND(ISNUMBER(C16),ISNUMBER(D16)), C16-D16, "") -> 18210.1 | F16: =IFERROR(E16/D16, "") -> 0.13416178 | G16: =SUM(Apr!G16+May!G16+Jun!G16) -> 147311.9 | H16: =SUM(Apr!H16, May!H16, Jun!H16) -> 6630.6 | I16: =IFERROR(H16/G16, "") -> 0.04501062
... A21: TX: Fort Worth - 5200 Gold Spike Dr | B21: TX | C21: =SUM(Apr!C21, May!C21, Jun!C21) -> 609595 | D21: =SUM(Apr!D21, May!D21, Jun!D21) -> 655419.9 | E21: =IF(AND(ISNUMBER(C21),ISNUMBER(D21)), C21-D21, "") -> -45824.9 | F21: =IFERROR(E21/D21, "") -> -0.069916858 | G21: =SUM(Apr!G21+May!G21+Jun!G21) -> 740663.3 | H21: =SUM(Apr!H21, May!H21, Jun!H21) -> -131068.3 | I21: =IFERROR(H21/G21, "") -> -0.17696071

Sheet 3rd Qtr
A1: {=portfolio} -> Catalyze | D1: 3rd Quarter Actual v. Expected | G1: 3rd Quarter Actual v. Forecasted
A2: Total | C2: =SUM(C4:C92) -> 0 | D2: =SUM(D4:D92) -> 0 | E2: =C2-D2 -> 0 | F2: =IFERROR(E2/D2, 0) -> 0 | G2: =SUM(G4:G92) -> 0 | H2: =C2-G2 -> 0 | I2: =IFERROR(H2/G2, 0) -> 0
A3: Site | B3: State | C3: Actual | D3: Expected | E3: Delta | F3: % | G3: Forecasted | H3: Delta | I3: %
A4: {=Sites[Site]} -> Fresno - 3150 Shaw Ave | B4: {=Sites[State]} -> CA | C4: =SUM(Jul!C4, Aug!C4, Sep!C4) -> 0 | D4: =SUM(Jul!D4, Aug!D4, Sep!D4) -> 0 | E4: =IF(AND(ISNUMBER(C4),ISNUMBER(D4)), C4-D4, "") -> 0 | F4: =IFERROR(E4/D4, "") | G4: =SUM(Jul!G4,Aug!G4,Sep!G4) -> 0 | H4: =SUM(Jul!H4, Aug!H4, Sep!H4) -> 0 | I4: =IFERROR(H4/G4, "")
A5: Adelanto - 1 Sheep Creek Road | B5: CA | C5: =SUM(Jul!C5, Aug!C5, Sep!C5) -> 0 | D5: =SUM(Jul!D5, Aug!D5, Sep!D5) -> 0 | E5: =IF(AND(ISNUMBER(C5),ISNUMBER(D5)), C5-D5, "") -> 0 | F5: =IFERROR(E5/D5, "") | G5: =SUM(Jul!G5,Aug!G5,Sep!G5) -> 0 | H5: =SUM(Jul!H5, Aug!H5, Sep!H5) -> 0 | I5: =IFERROR(H5/G5, "")
A6: Blackstone - 83 Federal Street | B6: MA | C6: =SUM(Jul!C6, Aug!C6, Sep!C6) -> 0 | D6: =SUM(Jul!D6, Aug!D6, Sep!D6) -> 0 | E6: =IF(AND(ISNUMBER(C6),ISNUMBER(D6)), C6-D6, "") -> 0 | F6: =IFERROR(E6/D6, "") | G6: =SUM(Jul!G6,Aug!G6,Sep!G6) -> 0 | H6: =SUM(Jul!H6, Aug!H6, Sep!H6) -> 0 | I6: =IFERROR(H6/G6, "")
A7: Charlton - 299 Worcester Road | B7: MA | C7: =SUM(Jul!C7, Aug!C7, Sep!C7) -> 0 | D7: =SUM(Jul!D7, Aug!D7, Sep!D7) -> 0 | E7: =IF(AND(ISNUMBER(C7),ISNUMBER(D7)), C7-D7, "") -> 0 | F7: =IFERROR(E7/D7, "") | G7: =SUM(Jul!G7,Aug!G7,Sep!G7) -> 0 | H7: =SUM(Jul!H7, Aug!H7, Sep!H7) -> 0 | I7: =IFERROR(H7/G7, "")
A8: Wareham - 8 Thatcher Drive | B8: MA | C8: =SUM(Jul!C8, Aug!C8, Sep!C8) -> 0 | D8: =SUM(Jul!D8, Aug!D8, Sep!D8) -> 0 | E8: =IF(AND(ISNUMBER(C8),ISNUMBER(D8)), C8-D8, "") -> 0 | F8: =IFERROR(E8/D8, "") | G8: =SUM(Jul!G8,Aug!G8,Sep!G8) -> 0 | H8: =SUM(Jul!H8, Aug!H8, Sep!H8) -> 0 | I8: =IFERROR(H8/G8, "")
A9: West Yarmouth - 42 Mid Tech | B9: MA | C9: =SUM(Jul!C9, Aug!C9, Sep!C9) -> 0 | D9: =SUM(Jul!D9, Aug!D9, Sep!D9) -> 0 | E9: =IF(AND(ISNUMBER(C9),ISNUMBER(D9)), C9-D9, "") -> 0 | F9: =IFERROR(E9/D9, "") | G9: =SUM(Jul!G9,Aug!G9,Sep!G9) -> 0 | H9: =SUM(Jul!H9, Aug!H9, Sep!H9) -> 0 | I9: =IFERROR(H9/G9, "")
A10: Harrison - 130 Union Street | B10: NY | C10: =SUM(Jul!C10, Aug!C10, Sep!C10) -> 0 | D10: =SUM(Jul!D10, Aug!D10, Sep!D10) -> 0 | E10: =IF(AND(ISNUMBER(C10),ISNUMBER(D10)), C10-D10, "") -> 0 | F10: =IFERROR(E10/D10, "") | G10: =SUM(Jul!G10,Aug!G10,Sep!G10) -> 0 | H10: =SUM(Jul!H10, Aug!H10, Sep!H10) -> 0 | I10: =IFERROR(H10/G10, "")
A11: Staten Island - Ellis Storage | B11: NY | C11: =SUM(Jul!C11, Aug!C11, Sep!C11) -> 0 | D11: =SUM(Jul!D11, Aug!D11, Sep!D11) -> 0 | E11: =IF(AND(ISNUMBER(C11),ISNUMBER(D11)), C11-D11, "") -> 0 | F11: =IFERROR(E11/D11, "") | G11: =SUM(Jul!G11,Aug!G11,Sep!G11) -> 0 | H11: =SUM(Jul!H11, Aug!H11, Sep!H11) -> 0 | I11: =IFERROR(H11/G11, "")
A12: Amherst - 595 Scholles Road | B12: NY | C12: =SUM(Jul!C12, Aug!C12, Sep!C12) -> 0 | D12: =SUM(Jul!D12, Aug!D12, Sep!D12) -> 0 | E12: =IF(AND(ISNUMBER(C12),ISNUMBER(D12)), C12-D12, "") -> 0 | F12: =IFERROR(E12/D12, "") | G12: =SUM(Jul!G12,Aug!G12,Sep!G12) -> 0 | H12: =SUM(Jul!H12, Aug!H12, Sep!H12) -> 0 | I12: =IFERROR(H12/G12, "")
A13: Lancaster 1 - Gunnville Road | B13: NY | C13: =SUM(Jul!C13, Aug!C13, Sep!C13) -> 0 | D13: =SUM(Jul!D13, Aug!D13, Sep!D13) -> 0 | E13: =IF(AND(ISNUMBER(C13),ISNUMBER(D13)), C13-D13, "") -> 0 | F13: =IFERROR(E13/D13, "") | G13: =SUM(Jul!G13,Aug!G13,Sep!G13) -> 0 | H13: =SUM(Jul!H13, Aug!H13, Sep!H13) -> 0 | I13: =IFERROR(H13/G13, "")
A14: Lancaster 2 - Shisler Road | B14: NY | C14: =SUM(Jul!C14, Aug!C14, Sep!C14) -> 0 | D14: =SUM(Jul!D14, Aug!D14, Sep!D14) -> 0 | E14: =IF(AND(ISNUMBER(C14),ISNUMBER(D14)), C14-D14, "") -> 0 | F14: =IFERROR(E14/D14, "") | G14: =SUM(Jul!G14,Aug!G14,Sep!G14) -> 0 | H14: =SUM(Jul!H14, Aug!H14, Sep!H14) -> 0 | I14: =IFERROR(H14/G14, "")
A15: Fullerton - 200 W Orangethorpe | B15: CA | C15: =SUM(Jul!C15, Aug!C15, Sep!C15) -> 0 | D15: =SUM(Jul!D15, Aug!D15, Sep!D15) -> 0 | E15: =IF(AND(ISNUMBER(C15),ISNUMBER(D15)), C15-D15, "") -> 0 | F15: =IFERROR(E15/D15, "") | G15: =SUM(Jul!G15,Aug!G15,Sep!G15) -> 0 | H15: =SUM(Jul!H15, Aug!H15, Sep!H15) -> 0 | I15: =IFERROR(H15/G15, "")
A16: El Paso - 10500 Railroad Drive | B16: TX | C16: =SUM(Jul!C16, Aug!C16, Sep!C16) -> 0 | D16: =SUM(Jul!D16, Aug!D16, Sep!D16) -> 0 | E16: =IF(AND(ISNUMBER(C16),ISNUMBER(D16)), C16-D16, "") -> 0 | F16: =IFERROR(E16/D16, "") | G16: =SUM(Jul!G16,Aug!G16,Sep!G16) -> 0 | H16: =SUM(Jul!H16, Aug!H16, Sep!H16) -> 0 | I16: =IFERROR(H16/G16, "")
... A20: Jessup -7950 Oceano Ave | B20: MD | C20: =SUM(Jul!C20, Aug!C20, Sep!C20) -> 0 | D20: =SUM(Jul!D20, Aug!D20, Sep!D20) -> 0 | E20: =IF(AND(ISNUMBER(C20),ISNUMBER(D20)), C20-D20, "") -> 0 | F20: =IFERROR(E20/D20, "") | G20: =SUM(Jul!G20,Aug!G20,Sep!G20) -> 0 | H20: =SUM(Jul!H20, Aug!H20, Sep!H20) -> 0 | I20: =IFERROR(H20/G20, "")
A21: TX: Fort Worth - 5200 Gold Spike Dr | B21: TX | C21: =SUM(Jul!C21, Aug!C21, Sep!C21) -> 0 | D21: =SUM(Jul!D21, Aug!D21, Sep!D21) -> 0 | E21: =IF(AND(ISNUMBER(C21),ISNUMBER(D21)), C21-D21, "") -> 0 | G21: =SUM(Jul!G21,Aug!G21,Sep!G21) -> 0 | H21: =SUM(Jul!H21, Aug!H21, Sep!H21) -> 0

Sheet 4th Qtr
A1: {=portfolio} -> Catalyze | D1: 4th Quarter Actual v. Expected | G1: 4th Quarter Actual v. Forecasted
A2: Total | C2: =SUM(C4:C92) -> 0 | D2: =SUM(D4:D92) -> 0 | E2: =C2-D2 -> 0 | F2: =IFERROR(E2/D2, 0) -> 0 | G2: =SUM(G4:G92) -> 0 | H2: =C2-G2 -> 0 | I2: =IFERROR(H2/G2, 0) -> 0
A3: Site | B3: State | C3: Actual | D3: Expected | E3: Delta | F3: % | G3: Forecasted | H3: Delta | I3: %
A4: {=Sites[Site]} -> Fresno - 3150 Shaw Ave | B4: {=Sites[State]} -> CA | C4: =SUM(Oct!C4, Nov!C4, Dec!C4) -> 0 | D4: =SUM(Oct!D4, Nov!D4, Dec!D4) -> 0 | E4: =IF(AND(ISNUMBER(C4),ISNUMBER(D4)), C4-D4, "") -> 0 | F4: =IFERROR(E4/D4, "") | G4: =SUM(Oct!G4,Nov!G4,Dec!G4) -> 0 | H4: =SUM(Oct!H4, Nov!H4, Dec!H4) -> 0 | I4: =IFERROR(H4/G4, "")
A5: Adelanto - 1 Sheep Creek Road | B5: CA | C5: =SUM(Oct!C5, Nov!C5, Dec!C5) -> 0 | D5: =SUM(Oct!D5, Nov!D5, Dec!D5) -> 0 | E5: =IF(AND(ISNUMBER(C5),ISNUMBER(D5)), C5-D5, "") -> 0 | F5: =IFERROR(E5/D5, "") | G5: =SUM(Oct!G5,Nov!G5,Dec!G5) -> 0 | H5: =SUM(Oct!H5, Nov!H5, Dec!H5) -> 0 | I5: =IFERROR(H5/G5, "")
A6: Blackstone - 83 Federal Street | B6: MA | C6: =SUM(Oct!C6, Nov!C6, Dec!C6) -> 0 | D6: =SUM(Oct!D6, Nov!D6, Dec!D6) -> 0 | E6: =IF(AND(ISNUMBER(C6),ISNUMBER(D6)), C6-D6, "") -> 0 | F6: =IFERROR(E6/D6, "") | G6: =SUM(Oct!G6,Nov!G6,Dec!G6) -> 0 | H6: =SUM(Oct!H6, Nov!H6, Dec!H6) -> 0 | I6: =IFERROR(H6/G6, "")
A7: Charlton - 299 Worcester Road | B7: MA | C7: =SUM(Oct!C7, Nov!C7, Dec!C7) -> 0 | D7: =SUM(Oct!D7, Nov!D7, Dec!D7) -> 0 | E7: =IF(AND(ISNUMBER(C7),ISNUMBER(D7)), C7-D7, "") -> 0 | F7: =IFERROR(E7/D7, "") | G7: =SUM(Oct!G7,Nov!G7,Dec!G7) -> 0 | H7: =SUM(Oct!H7, Nov!H7, Dec!H7) -> 0 | I7: =IFERROR(H7/G7, "")
A8: Wareham - 8 Thatcher Drive | B8: MA | C8: =SUM(Oct!C8, Nov!C8, Dec!C8) -> 0 | D8: =SUM(Oct!D8, Nov!D8, Dec!D8) -> 0 | E8: =IF(AND(ISNUMBER(C8),ISNUMBER(D8)), C8-D8, "") -> 0 | F8: =IFERROR(E8/D8, "") | G8: =SUM(Oct!G8,Nov!G8,Dec!G8) -> 0 | H8: =SUM(Oct!H8, Nov!H8, Dec!H8) -> 0 | I8: =IFERROR(H8/G8, "")
A9: West Yarmouth - 42 Mid Tech | B9: MA | C9: =SUM(Oct!C9, Nov!C9, Dec!C9) -> 0 | D9: =SUM(Oct!D9, Nov!D9, Dec!D9) -> 0 | E9: =IF(AND(ISNUMBER(C9),ISNUMBER(D9)), C9-D9, "") -> 0 | F9: =IFERROR(E9/D9, "") | G9: =SUM(Oct!G9,Nov!G9,Dec!G9) -> 0 | H9: =SUM(Oct!H9, Nov!H9, Dec!H9) -> 0 | I9: =IFERROR(H9/G9, "")
A10: Harrison - 130 Union Street | B10: NY | C10: =SUM(Oct!C10, Nov!C10, Dec!C10) -> 0 | D10: =SUM(Oct!D10, Nov!D10, Dec!D10) -> 0 | E10: =IF(AND(ISNUMBER(C10),ISNUMBER(D10)), C10-D10, "") -> 0 | F10: =IFERROR(E10/D10, "") | G10: =SUM(Oct!G10,Nov!G10,Dec!G10) -> 0 | H10: =SUM(Oct!H10, Nov!H10, Dec!H10) -> 0 | I10: =IFERROR(H10/G10, "")
A11: Staten Island - Ellis Storage | B11: NY | C11: =SUM(Oct!C11, Nov!C11, Dec!C11) -> 0 | D11: =SUM(Oct!D11, Nov!D11, Dec!D11) -> 0 | E11: =IF(AND(ISNUMBER(C11),ISNUMBER(D11)), C11-D11, "") -> 0 | F11: =IFERROR(E11/D11, "") | G11: =SUM(Oct!G11,Nov!G11,Dec!G11) -> 0 | H11: =SUM(Oct!H11, Nov!H11, Dec!H11) -> 0 | I11: =IFERROR(H11/G11, "")
A12: Amherst - 595 Scholles Road | B12: NY | C12: =SUM(Oct!C12, Nov!C12, Dec!C12) -> 0 | D12: =SUM(Oct!D12, Nov!D12, Dec!D12) -> 0 | E12: =IF(AND(ISNUMBER(C12),ISNUMBER(D12)), C12-D12, "") -> 0 | F12: =IFERROR(E12/D12, "") | G12: =SUM(Oct!G12,Nov!G12,Dec!G12) -> 0 | H12: =SUM(Oct!H12, Nov!H12, Dec!H12) -> 0 | I12: =IFERROR(H12/G12, "")
A13: Lancaster 1 - Gunnville Road | B13: NY | C13: =SUM(Oct!C13, Nov!C13, Dec!C13) -> 0 | D13: =SUM(Oct!D13, Nov!D13, Dec!D13) -> 0 | E13: =IF(AND(ISNUMBER(C13),ISNUMBER(D13)), C13-D13, "") -> 0 | F13: =IFERROR(E13/D13, "") | G13: =SUM(Oct!G13,Nov!G13,Dec!G13) -> 0 | H13: =SUM(Oct!H13, Nov!H13, Dec!H13) -> 0 | I13: =IFERROR(H13/G13, "")
A14: Lancaster 2 - Shisler Road | B14: NY | C14: =SUM(Oct!C14, Nov!C14, Dec!C14) -> 0 | D14: =SUM(Oct!D14, Nov!D14, Dec!D14) -> 0 | E14: =IF(AND(ISNUMBER(C14),ISNUMBER(D14)), C14-D14, "") -> 0 | F14: =IFERROR(E14/D14, "") | G14: =SUM(Oct!G14,Nov!G14,Dec!G14) -> 0 | H14: =SUM(Oct!H14, Nov!H14, Dec!H14) -> 0 | I14: =IFERROR(H14/G14, "")
A15: Fullerton - 200 W Orangethorpe | B15: CA | C15: =SUM(Oct!C15, Nov!C15, Dec!C15) -> 0 | D15: =SUM(Oct!D15, Nov!D15, Dec!D15) -> 0 | E15: =IF(AND(ISNUMBER(C15),ISNUMBER(D15)), C15-D15, "") -> 0 | F15: =IFERROR(E15/D15, "") | G15: =SUM(Oct!G15,Nov!G15,Dec!G15) -> 0 | H15: =SUM(Oct!H15, Nov!H15, Dec!H15) -> 0 | I15: =IFERROR(H15/G15, "")
A16: El Paso - 10500 Railroad Drive | B16: TX | C16: =SUM(Oct!C16, Nov!C16, Dec!C16) -> 0 | D16: =SUM(Oct!D16, Nov!D16, Dec!D16) -> 0 | E16: =IF(AND(ISNUMBER(C16),ISNUMBER(D16)), C16-D16, "") -> 0 | F16: =IFERROR(E16/D16, "") | G16: =SUM(Oct!G16,Nov!G16,Dec!G16) -> 0 | H16: =SUM(Oct!H16, Nov!H16, Dec!H16) -> 0 | I16: =IFERROR(H16/G16, "")
... A20: Jessup -7950 Oceano Ave | B20: MD | C20: =SUM(Oct!C20, Nov!C20, Dec!C20) -> 0 | D20: =SUM(Oct!D20, Nov!D20, Dec!D20) -> 0 | E20: =IF(AND(ISNUMBER(C20),ISNUMBER(D20)), C20-D20, "") -> 0 | F20: =IFERROR(E20/D20, "") | G20: =SUM(Oct!G20,Nov!G20,Dec!G20) -> 0 | H20: =SUM(Oct!H20, Nov!H20, Dec!H20) -> 0 | I20: =IFERROR(H20/G20, "")
A21: TX: Fort Worth - 5200 Gold Spike Dr | B21: TX | C21: =SUM(Oct!C21, Nov!C21, Dec!C21) -> 0 | D21: =SUM(Oct!D21, Nov!D21, Dec!D21) -> 0 | E21: =IF(AND(ISNUMBER(C21),ISNUMBER(D21)), C21-D21, "") -> 0 | G21: =SUM(Oct!G21,Nov!G21,Dec!G21) -> 0 | H21: =SUM(Oct!H21, Nov!H21, Dec!H21) -> 0

Sheet Jan
A1: {=portfolio} -> Catalyze | D1: January Actual v. Expected | G1: January Actual v. Forecasted
A2: Total | C2: =SUM(C4:C91) -> 1684623.5 | D2: =SUM(D4:D91) -> 2378878.9 | E2: =C2-D2 -> -694255.44 | F2: =IFERROR(E2/D2, 0) -> -0.29184144 | G2: =SUM(G4:G91) -> 2175549.7 | H2: =C2-G2 -> -490926.17 | I2: =IFERROR(H2/G2, 0) -> -0.22565615 | J2: =IF(AND(TODAY()>DATE(2024, 1, 1), COUNTA(Sites[Site])<>(COUNT(C:C)-1)), "Some sites are missing actual data; if new sites were added, make sure they are aligned correctly (including prior months!)", "") -> Some sites are missing actual data; if new sites were added, make sure they are aligned correctly (including prior months!)
A3: Site | B3: State | C3: Actual | D3: Expected | E3: Delta | F3: % | G3: Forecasted | H3: Delta | I3: % | J3: Notes | K3: Service Requests
A4: {=Sites[Site]} -> Fresno - 3150 Shaw Ave | B4: {=Sites[State]} -> CA | C4: 53422.875 | D4: 50400.42 | E4: =IF(AND(ISNUMBER(C4),ISNUMBER(D4)), C4-D4, "") -> 3022.455 | F4: =IFERROR(E4/D4, "") -> 0.059968845 | G4: 49997 | H4: =IF(AND(ISNUMBER(C4),ISNUMBER(G4)), C4-G4, "") -> 3425.875 | I4: =IFERROR(H4/G4, "") -> 0.068521611 | J4: 1.Inverter 5 has experienced tripping events on alternate days throughout the month due to water intrusion in the connectors. According to the technician's notes, further troubleshooting is required | K4: 1. SR094993
A5: Adelanto - 1 Sheep Creek Road | B5: CA | C5: 434343 | D5: 163616.27 | E5: =IF(AND(ISNUMBER(C5),ISNUMBER(D5)), C5-D5, "") -> 270726.73 | F5: =IFERROR(E5/D5, "") -> 1.6546443 | G5: 479912.62 | H5: =IF(AND(ISNUMBER(C5),ISNUMBER(G5)), C5-G5, "") -> -45569.62 | I5: =IFERROR(H5/G5, "") -> -0.094953994 | J5: 1. The weather station stopped communicating on 01/08. A technician onsite for inverter and weather station issues contacted SMA and updated five inverters. Communication was restored on 01/21 but again lost on 01/27. On 01/28, the technician contacted Aderis and re-established communication, but it dropped again at 15:00. It was restored at 10:00 on 01/29 while the technician was updating inverter firmware. 2. Inverter 7 was offline from 01/23. The technician investigated the issue and replaced the L2 fuse, bringing the inverter back online on 01/28. 3. The site was offline on 01/28 at 08:00am and later remotely closed by catalyze at 09:00am. | K5: 1. SR092431, SR095414 2. SR096016 3. SR096049 | L5: SR095414 | M5: SR096016 | N5: SR096049
A6: Blackstone - 83 Federal Street | B6: MA | C6: 221322 | D6: 519101.6 | E6: =IF(AND(ISNUMBER(C6),ISNUMBER(D6)), C6-D6, "") -> -297779.6 | F6: =IFERROR(E6/D6, "") -> -0.57364416 | G6: 384369.8 | H6: =IF(AND(ISNUMBER(C6),ISNUMBER(G6)), C6-G6, "") -> -163047.8 | I6: =IFERROR(H6/G6, "") -> -0.42419514 | J6: 1.Inverter 1 tripped offline at 12:45 PM on 01/15. According to the received information, SMA was on-site working on the inverter on the same day, and Inverter 1 was back online at 02:30 PM on 01/15. 2.Inverter 1 is constantly producing 193kW even during non-production hours on 01/16. Issue got self resolved at 10:00 PM on 01/16. 3.Inverter 1 failed to start on 01/21. SMA technicians suspected a communication board issue. After further troubleshooting on 01/22, the inverter 1 was back online at 10:30 AM on 01/22. 4.The site experienced reduced production from 01/20 to 01/24 due to snow cover. On 01/25/25, production dropped to 62kW at 08:30 due to snow buildup. The technician reset the Indie control box, restoring PV production on 01/25. 5. The site tripped offline due to a utility outage at 12:45 PM on 01/28. After the technician reset the recloser, the site was back online at 1:45 PM on 01/29. | K6: 1.SR095598 2.SR095641 3.SR095796 4.SR095973 5.SR096060, SR096061 | L6: SR095641 | M6: SR095796 | N6: SR095973 | O6: SR096060 | P6: SR096061
A7: Charlton - 299 Worcester Road | B7: MA | C7: 23675 | D7: 33780.06 | E7: =IF(AND(ISNUMBER(C7),ISNUMBER(D7)), C7-D7, "") -> -10105.06 | F7: =IFERROR(E7/D7, "") -> -0.29914275 | G7: 31670.95 | H7: =IF(AND(ISNUMBER(C7),ISNUMBER(G7)), C7-G7, "") -> -7995.95 | I7: =IFERROR(H7/G7, "") -> -0.25246953 | J7: 1.Low generation due to weather/snow.
A8: Wareham - 8 Thatcher Drive | B8: MA | C8: 7554.0625 | D8: 9317.288 | E8: =IF(AND(ISNUMBER(C8),ISNUMBER(D8)), C8-D8, "") -> -1763.2255 | F8: =IFERROR(E8/D8, "") -> -0.18924235 | G8: 8974.43 | H8: =IF(AND(ISNUMBER(C8),ISNUMBER(G8)), C8-G8, "") -> -1420.3675 | I8: =IFERROR(H8/G8, "") -> -0.15826827 | J8: 1.Low generation due to weather/snow.
A9: West Yarmouth - 42 Mid Tech | B9: MA | C9: 5192.6952 | D9: 6591.808 | E9: =IF(AND(ISNUMBER(C9),ISNUMBER(D9)), C9-D9, "") -> -1399.1128 | F9: =IFERROR(E9/D9, "") -> -0.21225024 | G9: 6769.91 | H9: =IF(AND(ISNUMBER(C9),ISNUMBER(G9)), C9-G9, "") -> -1577.2148 | I9: =IFERROR(H9/G9, "") -> -0.23297427 | J9: 1. Irradiance sensor has been replaced on 01/22. | K9: 1. SR086960, SR095896 | L9: SR095896
A10: Harrison - 130 Union Street | B10: NY | C10: 9045.625 | D10: 14196.66 | E10: =IF(AND(ISNUMBER(C10),ISNUMBER(D10)), C10-D10, "") -> -5151.035 | F10: =IFERROR(E10/D10, "") -> -0.36283429 | G10: 10694.18 | H10: =IF(AND(ISNUMBER(C10),ISNUMBER(G10)), C10-G10, "") -> -1648.555 | I10: =IFERROR(H10/G10, "") -> -0.15415441 | J10: 1.Low generation due to weather/snow.
A11: Staten Island - Ellis Storage | B11: NY | C11: 22396.625 | D11: 27928.2 | E11: =IF(AND(ISNUMBER(C11),ISNUMBER(D11)), C11-D11, "") -> -5531.575 | F11: =IFERROR(E11/D11, "") -> -0.19806414 | G11: 22865 | H11: =IF(AND(ISNUMBER(C11),ISNUMBER(G11)), C11-G11, "") -> -468.375 | I11: =IFERROR(H11/G11, "") -> -0.020484365 | J11: 1.Low generation due to weather/snow.
A12: Amherst - 595 Scholles Road | B12: NY | C12: 176317 | D12: 351737 | E12: =IF(AND(ISNUMBER(C12),ISNUMBER(D12)), C12-D12, "") -> -175420 | F12: =IFERROR(E12/D12, "") -> -0.4987249 | G12: 279121.6 | H12: =IF(AND(ISNUMBER(C12),ISNUMBER(G12)), C12-G12, "") -> -102804.6 | I12: =IFERROR(H12/G12, "") -> -0.36831474 | J12: 1.The site tripped offline at 01:15 AM on 01/22. On 01/23, after the utility closed their recloser, the technician reset the recloser, bringing the site back online and into production at 5:00 PM on 01/23. | K12: 1.SR095842
A13: Lancaster 1 - Gunnville Road | B13: NY | C13: 167972 | D13: 298839.7 | E13: =IF(AND(ISNUMBER(C13),ISNUMBER(D13)), C13-D13, "") -> -130867.7 | F13: =IFERROR(E13/D13, "") -> -0.43791939 | G13: 191771 | H13: =IF(AND(ISNUMBER(C13),ISNUMBER(G13)), C13-G13, "") -> -23799 | I13: =IFERROR(H13/G13, "") -> -0.12410114 | J13: 1.Low generation due to weather/snow.
A14: Lancaster 2 - Shisler Road | B14: NY | C14: 146912 | D14: 352791.9 | E14: =IF(AND(ISNUMBER(C14),ISNUMBER(D14)), C14-D14, "") -> -205879.9 | F14: =IFERROR(E14/D14, "") -> -0.58357321 | G14: 204880 | H14: =IF(AND(ISNUMBER(C14),ISNUMBER(G14)), C14-G14, "") -> -57968 | I14: =IFERROR(H14/G14, "") -> -0.28293635 | J14: 1. Inverters 3.5 to 3.7 and 3.9 tripped offline at 15:45 and self-resolved at 16:15 on 01/09. A technician was dispatched and found inverter voltages out of range. Terminations were re-tightened. 2. Inverters 3.1 to 3.10 experienced multiple tripping events throughout the month, self-resolving on alternate days. | K14: 1. SR095454 2. SR095996, SR096058, SR096170 | L14: SR095996 | M14: SR096058 | N14: SR096170
A15: Fullerton - 200 W Orangethorpe | B15: CA | C15: 63628.546 | D15: 73372.12 | E15: =IF(AND(ISNUMBER(C15),ISNUMBER(D15)), C15-D15, "") -> -9743.5737 | F15: =IFERROR(E15/D15, "") -> -0.13279668 | G15: 74894 | H15: =IF(AND(ISNUMBER(C15),ISNUMBER(G15)), C15-G15, "") -> -11265.454 | I15: =IFERROR(H15/G15, "") -> -0.15041864 | J15: 1.Low generation due to weather/snow.
A16: El Paso - 10500 Railroad Drive | B16: TX | C16: 93351.5 | D16: 90713.1 | E16: =IF(AND(ISNUMBER(C16),ISNUMBER(D16)), C16-D16, "") -> 2638.4 | F16: =IFERROR(E16/D16, "") -> 0.029085105 | G16: 95865 | H16: =IF(AND(ISNUMBER(C16),ISNUMBER(G16)), C16-G16, "") -> -2513.5 | I16: =IFERROR(H16/G16, "") -> -0.026219162
A17: Friona - 900 Millard Ave | B17: TX | C17: 69688.25 | D17: 68867.83 | E17: =IF(AND(ISNUMBER(C17),ISNUMBER(D17)), C17-D17, "") -> 820.42 | F17: =IFERROR(E17/D17, "") -> 0.011912964 | G17: 72736 | H17: =IF(AND(ISNUMBER(C17),ISNUMBER(G17)), C17-G17, "") -> -3047.75 | I17: =IFERROR(H17/G17, "") -> -0.041901534 | J17: 1. Inverter 6 has been experiencing multiple tripping events throughout the month. The issue, caused by VARS (Volt-Ampere Reactive power) from the utility, scheduled to be addressed in Q3 2025. | K17: 1.SR093503
A18: Augusta - 13 York Farm Road | B18: ME | C18: 69027.875 | D18: 131266.3 | E18: =IF(AND(ISNUMBER(C18),ISNUMBER(D18)), C18-D18, "") -> -62238.425 | F18: =IFERROR(E18/D18, "") -> -0.47413864 | G18: 92474 | H18: =IF(AND(ISNUMBER(C18),ISNUMBER(G18)), C18-G18, "") -> -23446.125 | I18: =IFERROR(H18/G18, "") -> -0.25354289 | J18: 1.Low generation due to weather/snow.
A19: Santa Ana - 1441 West | B19: CA | C19: 36286.812 | D19: 40826.68 | E19: =IF(AND(ISNUMBER(C19),ISNUMBER(D19)), C19-D19, "") -> -4539.8675 | F19: =IFERROR(E19/D19, "") -> -0.11119855 | G19: 47186.47 | H19: =IF(AND(ISNUMBER(C19),ISNUMBER(G19)), C19-G19, "") -> -10899.658 | I19: =IFERROR(H19/G19, "") -> -0.23099116 | J19: 1.Low generation due to weather/snow.
A20: Jessup -7950 Oceano Ave | B20: MD | C20: 84487.625 | D20: 145532 | E20: =IF(AND(ISNUMBER(C20),ISNUMBER(D20)), C20-D20, "") -> -61044.375 | F20: =IFERROR(E20/D20, "") -> -0.41945672 | G20: 121367.7 | H20: =IF(AND(ISNUMBER(C20),ISNUMBER(G20)), C20-G20, "") -> -36880.075 | I20: =IFERROR(H20/G20, "") -> -0.30387059 | J20: 1. Inverter 9 is underproducing compared to its peers due to four faulty optimizers affecting two strings | K20: 1.SR096047
A21: TX: Fort Worth - 5200 Gold Spike Dr | B21: TX | E21: =IF(AND(ISNUMBER(C21),ISNUMBER(D21)), C21-D21, "") | F21: =IFERROR(E21/D21, "") | H21: =IF(AND(ISNUMBER(C21),ISNUMBER(G21)), C21-G21, "") | I21: =IFERROR(H21/G21, "")

Sheet Feb
A1: {=portfolio} -> Catalyze | D1: February Actual v. Expected | G1: February Actual v. Forecasted
A2: Total | C2: =SUM(C4:C91) -> 2290649.9 | D2: =SUM(D4:D91) -> 3115852.4 | E2: =C2-D2 -> -825202.44 | F2: =IFERROR(E2/D2, 0) -> -0.26484003 | G2: =SUM(G4:G91) -> 3274320.2 | H2: =C2-G2 -> -983670.28 | I2: =IFERROR(H2/G2, 0) -> -0.3004197 | J2: =IF(AND(TODAY()>DATE(2024, 2, 1), COUNTA(Sites[Site])<>(COUNT(C:C)-1)), "Some sites are missing actual data; if new sites were added, make sure they are aligned correctly (including prior months!)", "")
A3: Site | B3: State | C3: Actual | D3: Expected | E3: Delta | F3: % | G3: Forecasted | H3: Delta | I3: % | J3: Notes | K3: Service Requests
A4: {=Sites[Site]} -> Fresno - 3150 Shaw Ave | B4: {=Sites[State]} -> CA | C4: 55837 | D4: 53033.79 | E4: =IF(AND(ISNUMBER(C4),ISNUMBER(D4)), C4-D4, "") -> 2803.21 | F4: =IFERROR(E4/D4, "") -> 0.052857056 | G4: 57896.36 | H4: =IF(AND(ISNUMBER(C4),ISNUMBER(G4)), C4-G4, "") -> -2059.36 | I4: =IFERROR(H4/G4, "") -> -0.035569766 | J4: 1. Inverter 5 has experienced tripping events on alternate days since 12/30 due to Fault to stop DC wrong polarity. Further troubleshooting is required. 2. Inverter 2 tripped offline at 10:45AM on 02/16 and later self resolved inverter back online at 15:30 on 02/16. | K4: 1. SR096333, SR094993 2. SR097172 | L4: SR094993 | M4: SR097172
A5: Adelanto - 1 Sheep Creek Road | B5: CA | C5: 539830 | D5: 415542.92 | E5: =IF(AND(ISNUMBER(C5),ISNUMBER(D5)), C5-D5, "") -> 124287.08 | F5: =IFERROR(E5/D5, "") -> 0.29909565 | G5: 569668.74 | H5: =IF(AND(ISNUMBER(C5),ISNUMBER(G5)), C5-G5, "") -> -29838.74 | I5: =IFERROR(H5/G5, "") -> -0.052379107 | J5: 1. Inverter 8 was offline since 01/31 and inverter 7 was offline throughtout the month. 2. Inverter 21 was offline intermittently throughout the month. On 02/28 technician was onsite replaced fuses bringing inverter back but it is in night mode. | K5: 1. SR096178, SR096016 2. SR097916 | L5: SR096016 | M5: SR097916
A6: Blackstone - 83 Federal Street | B6: MA | C6: 344694.9 | D6: 508146.2 | E6: =IF(AND(ISNUMBER(C6),ISNUMBER(D6)), C6-D6, "") -> -163451.3 | F6: =IFERROR(E6/D6, "") -> -0.32166195 | G6: 491267.1 | H6: =IF(AND(ISNUMBER(C6),ISNUMBER(G6)), C6-G6, "") -> -146572.2 | I6: =IFERROR(H6/G6, "") -> -0.29835542 | J6: 1. Inverter was offline intermittently from 02/09 to 02/13 due to snow. | K6: 1. SR096554
A7: Charlton - 299 Worcester Road | B7: MA | C7: 27164.5 | D7: 42025.38 | E7: =IF(AND(ISNUMBER(C7),ISNUMBER(D7)), C7-D7, "") -> -14860.88 | F7: =IFERROR(E7/D7, "") -> -0.35361679 | G7: 31343.27 | H7: =IF(AND(ISNUMBER(C7),ISNUMBER(G7)), C7-G7, "") -> -4178.77 | I7: =IFERROR(H7/G7, "") -> -0.13332272 | J7: 1. Inverter 13 experienced tripping events on high irradiance days reporting PV Abnormal Input - Protect0260. On 02/26 technician was onsite replaced inverter 1. As per solectria advice the bus board on inverter 13 has been removed. If the inverter faults again, will know that the issue lies with the inverter. | K7: 1. SR081303
A8: Wareham - 8 Thatcher Drive | B8: MA | C8: 9151.0625 | D8: 10698.21 | E8: =IF(AND(ISNUMBER(C8),ISNUMBER(D8)), C8-D8, "") -> -1547.1475 | F8: =IFERROR(E8/D8, "") -> -0.14461742 | G8: 11033.87 | H8: =IF(AND(ISNUMBER(C8),ISNUMBER(G8)), C8-G8, "") -> -1882.8075 | I8: =IFERROR(H8/G8, "") -> -0.17063891 | J8: 1. Low generation due to weather/snow.
A9: West Yarmouth - 42 Mid Tech | B9: MA | C9: 7255.8318 | D9: 9324.202 | E9: =IF(AND(ISNUMBER(C9),ISNUMBER(D9)), C9-D9, "") -> -2068.3702 | F9: =IFERROR(E9/D9, "") -> -0.22182811 | G9: 9379.757 | H9: =IF(AND(ISNUMBER(C9),ISNUMBER(G9)), C9-G9, "") -> -2123.9252 | I9: =IFERROR(H9/G9, "") -> -0.22643712 | J9: 1. Low generation due to weather/snow.
A10: Harrison - 130 Union Street | B10: NY | C10: 13226.875 | D10: 16424.34 | E10: =IF(AND(ISNUMBER(C10),ISNUMBER(D10)), C10-D10, "") -> -3197.465 | F10: =IFERROR(E10/D10, "") -> -0.19467845 | G10: 14212.59 | H10: =IF(AND(ISNUMBER(C10),ISNUMBER(G10)), C10-G10, "") -> -985.715 | I10: =IFERROR(H10/G10, "") -> -0.069355058 | J10: 1.Low generation due to weather/snow.
A11: Staten Island - Ellis Storage | B11: NY | C11: 31295.875 | D11: 32267.16 | E11: =IF(AND(ISNUMBER(C11),ISNUMBER(D11)), C11-D11, "") -> -971.285 | F11: =IFERROR(E11/D11, "") -> -0.030101348 | G11: 30624.97 | H11: =IF(AND(ISNUMBER(C11),ISNUMBER(G11)), C11-G11, "") -> 670.905 | I11: =IFERROR(H11/G11, "") -> 0.021907124
A12: Amherst - 595 Scholles Road | B12: NY | C12: 232611 | D12: 417742.3 | E12: =IF(AND(ISNUMBER(C12),ISNUMBER(D12)), C12-D12, "") -> -185131.3 | F12: =IFERROR(E12/D12, "") -> -0.44317107 | G12: 401280.1 | H12: =IF(AND(ISNUMBER(C12),ISNUMBER(G12)), C12-G12, "") -> -168669.1 | I12: =IFERROR(H12/G12, "") -> -0.4203276 | J12: 1. Site tripped offline at 08:30AM on 02/01 and later back online at 11:30AM on 02/02 after technician re-energized. 2. Site tripped offline at 3:30AM, technician closed the recloser. Site back online at 11:10AM on 02/18. 3. Site tripped offline at 14:00 on 02/26 back online at 16:30 on 02/27 after technician re-energized. | K12: 1. SR096212 2. SR097208 3. SR097837 | L12: SR097208 | M12: SR097837
A13: Lancaster 1 - Gunnville Road | B13: NY | C13: 227486 | D13: 352750.8 | E13: =IF(AND(ISNUMBER(C13),ISNUMBER(D13)), C13-D13, "") -> -125264.8 | F13: =IFERROR(E13/D13, "") -> -0.35510848 | G13: 379774.4 | H13: =IF(AND(ISNUMBER(C13),ISNUMBER(G13)), C13-G13, "") -> -152288.4 | I13: =IFERROR(H13/G13, "") -> -0.40099701 | J13: 1. Low generation due to weather/snow.
A14: Lancaster 2 - Shisler Road | B14: NY | C14: 223663 | D14: 402516.6 | E14: =IF(AND(ISNUMBER(C14),ISNUMBER(D14)), C14-D14, "") -> -178853.6 | F14: =IFERROR(E14/D14, "") -> -0.44433844 | G14: 410691.2 | H14: =IF(AND(ISNUMBER(C14),ISNUMBER(G14)), C14-G14, "") -> -187028.2 | I14: =IFERROR(H14/G14, "") -> -0.45539861 | J14: 1.Inverters 3.1 to 3.10 experienced tripping events on 02/04, 02/05, 02/07 and 02/10. On 02/11 USNE was onsite and replaced Bay-O-net fuses. | K14: 1. SR096170
A15: Fullerton - 200 W Orangethorpe | B15: CA | C15: 73626.954 | D15: 75409.94 | E15: =IF(AND(ISNUMBER(C15),ISNUMBER(D15)), C15-D15, "") -> -1782.9863 | F15: =IFERROR(E15/D15, "") -> -0.023643916 | G15: 81220.44 | H15: =IF(AND(ISNUMBER(C15),ISNUMBER(G15)), C15-G15, "") -> -7593.4863 | I15: =IFERROR(H15/G15, "") -> -0.093492306
A16: El Paso - 10500 Railroad Drive | B16: TX | C16: 105996.5 | D16: 100797.2 | E16: =IF(AND(ISNUMBER(C16),ISNUMBER(D16)), C16-D16, "") -> 5199.3 | F16: =IFERROR(E16/D16, "") -> 0.05158179 | G16: 101055 | H16: =IF(AND(ISNUMBER(C16),ISNUMBER(G16)), C16-G16, "") -> 4941.5 | I16: =IFERROR(H16/G16, "") -> 0.048899114
A17: Friona - 900 Millard Ave | B17: TX | C17: 81985 | D17: 72229.98 | E17: =IF(AND(ISNUMBER(C17),ISNUMBER(D17)), C17-D17, "") -> 9755.02 | F17: =IFERROR(E17/D17, "") -> 0.135055 | G17: 78972.4 | H17: =IF(AND(ISNUMBER(C17),ISNUMBER(G17)), C17-G17, "") -> 3012.6 | I17: =IFERROR(H17/G17, "") -> 0.038147505 | J17: 1. Inverter 6 has been experienced tripping event on 02/08 and 02/09. The issue, caused by VARS (Volt-Ampere Reactive power) from the utility, scheduled to be addressed in Q3 2025. | K17: 1. SR093503
A18: Augusta - 13 York Farm Road | B18: ME | C18: 43748.5 | D18: 150180.8 | E18: =IF(AND(ISNUMBER(C18),ISNUMBER(D18)), C18-D18, "") -> -106432.3 | F18: =IFERROR(E18/D18, "") -> -0.70869445 | G18: 115391.9 | H18: =IF(AND(ISNUMBER(C18),ISNUMBER(G18)), C18-G18, "") -> -71643.4 | I18: =IFERROR(H18/G18, "") -> -0.62087027 | J18: 1. Low generation due to weather/snow.
A19: Santa Ana - 1441 West | B19: CA | C19: 47461.375 | D19: 45475.04 | E19: =IF(AND(ISNUMBER(C19),ISNUMBER(D19)), C19-D19, "") -> 1986.335 | F19: =IFERROR(E19/D19, "") -> 0.043679676 | G19: 53286.01 | H19: =IF(AND(ISNUMBER(C19),ISNUMBER(G19)), C19-G19, "") -> -5824.635 | I19: =IFERROR(H19/G19, "") -> -0.1093089
A20: Jessup -7950 Oceano Ave | B20: MD | C20: 143523.25 | D20: 137903.3 | E20: =IF(AND(ISNUMBER(C20),ISNUMBER(D20)), C20-D20, "") -> 5619.95 | F20: =IFERROR(E20/D20, "") -> 0.040752832 | G20: 143903.7 | H20: =IF(AND(ISNUMBER(C20),ISNUMBER(G20)), C20-G20, "") -> -380.45 | I20: =IFERROR(H20/G20, "") -> -0.0026437819 | J20: 1. Inverter 9 underperformance has self-resolved since 02/01 and producing in line with peers. | K20: 1. SR096047
A21: TX: Fort Worth - 5200 Gold Spike Dr | B21: TX | C21: 82092.3 | D21: 273384.2 | E21: =IF(AND(ISNUMBER(C21),ISNUMBER(D21)), C21-D21, "") -> -191291.9 | F21: =IFERROR(E21/D21, "") -> -0.6997182 | G21: 293318.4 | H21: =IF(AND(ISNUMBER(C21),ISNUMBER(G21)), C21-G21, "") -> -211226.1 | I21: =IFERROR(H21/G21, "") -> -0.72012564 | J21: 1. Inverters 1.1, 1.2 are not communicating since 02/13 and inverter 3.4 stopped communicating on 02/24 and possibly offline. Client mentioned these inverters are still under EPC warranty so they are currently handling the RMA process. 2. The meters L1, L2, and L3 stopped communicating at 12:45 AM on 02/28. After communication was regained, only the L3 voltage started updating, while the L1 and L2 voltages dropped to zero. Possibly that the breakers have tripped. | K21: 1. SR097878, SR097940 2. SR097900 | L21: SR097940 | M21: SR097900

Sheet Mar
A1: {=portfolio} -> Catalyze | D1: March Actual v. Expected | G1: March Actual v. Forecasted
A2: Total | C2: =SUM(C4:C92) -> 4294678 | D2: =SUM(D4:D92) -> 4922393.1 | E2: =C2-D2 -> -627715.12 | F2: =IFERROR(E2/D2, 0) -> -0.12752235 | G2: =SUM(G4:G92) -> 5166542.8 | H2: =C2-G2 -> -871864.81 | I2: =IFERROR(H2/G2, 0) -> -0.16875207 | J2: =IF(AND(TODAY()>DATE(2024, 3, 1), COUNTA(Sites[Site])<>(COUNT(C:C)-1)), "Some sites are missing actual data; if new sites were added, make sure they are aligned correctly (including prior months!)", "")
A3: Site | B3: State | C3: Actual | D3: Expected | E3: Delta | F3: % | G3: Forecasted | H3: Delta | I3: % | J3: Notes | K3: Service Requests
A4: {=Sites[Site]} -> Fresno - 3150 Shaw Ave | B4: {=Sites[State]} -> CA | C4: 82059.375 | D4: 79466.18 | E4: =IF(AND(ISNUMBER(C4),ISNUMBER(D4)), C4-D4, "") -> 2593.195 | F4: =IFERROR(E4/D4, "") -> 0.032632687 | G4: 102469 | H4: =IF(AND(ISNUMBER(C4),ISNUMBER(G4)), C4-G4, "") -> -20409.625 | I4: =IFERROR(H4/G4, "") -> -0.19917853 | J4: 1.Inverter 5 has experienced multiple tripping events since 12/30 due to a "Fault to Stop DC Wrong Polarity"; on 03/11, a technician replaced two blown optimizers, and on 03/12, six hotspot modules were identified for replacement. 2.Site was taken offline from 7AM to 9AM on 03/07 due to technician checked in to drain the roof. | K4: 1.SR096333,SR098835. 2.SR097877 | L4: SR098835 | M4: SR097877
A5: Adelanto - 1 Sheep Creek Road | B5: CA | C5: 613170 | D5: 474842.85 | E5: =IF(AND(ISNUMBER(C5),ISNUMBER(D5)), C5-D5, "") -> 138327.15 | F5: =IFERROR(E5/D5, "") -> 0.29131143 | G5: 680082.38 | H5: =IF(AND(ISNUMBER(C5),ISNUMBER(G5)), C5-G5, "") -> -66912.38 | I5: =IFERROR(H5/G5, "") -> -0.098388639 | J5: 1.Inverter 7 was offline on 03/03 in SMA portal, after techician checked in and replaced faulty fuse at L3 inverter back online on same day. 2. CB 14 was offline for whole month and being replaced but technician recieved wrong parts on 03/18. 3.Inverter 2 went offline on 03/13 in the SMA portal and back online on 03/14. 4.On 03/18 technician found inverter 5 was offline and after replacing AC line two blown fuse on 03/18, the Inverter back online on 03/18 at 12:15pm. 5.Adheris was doing backend work. No inverter data on Aderis from 03/27. | K5: 1.SR097992 2. PM5513, SR089076, SR098032 3.SR098553 4.SR098032, SR098706 5.SR098752 | L5: SR089076 | M5: SR098032 | N5: SR098553 | O5: SR098032 | P5: SR098706 | Q5: SR098752
A6: Blackstone - 83 Federal Street | B6: MA | C6: 621375.9 | D6: 663323.6 | E6: =IF(AND(ISNUMBER(C6),ISNUMBER(D6)), C6-D6, "") -> -41947.7 | F6: =IFERROR(E6/D6, "") -> -0.063238667 | G6: 693620.2 | H6: =IF(AND(ISNUMBER(C6),ISNUMBER(G6)), C6-G6, "") -> -72244.3 | I6: =IFERROR(H6/G6, "") -> -0.10415542 | J6: 1.Meter was capturing 50 -250Kw less than Inverter active power during peak hours since 02/18/23. | K6: 1.SR084901, SR099181, SR098032 | L6: SR099181 | M6: SR098032
A7: Charlton - 299 Worcester Road | B7: MA | C7: 55962.25 | D7: 56208.81 | E7: =IF(AND(ISNUMBER(C7),ISNUMBER(D7)), C7-D7, "") -> -246.56 | F7: =IFERROR(E7/D7, "") -> -0.004386501 | G7: 59298.27 | H7: =IF(AND(ISNUMBER(C7),ISNUMBER(G7)), C7-G7, "") -> -3336.02 | I7: =IFERROR(H7/G7, "") -> -0.056258302 | J7: 1. Inverters 6, 7, and 8 were power cycling midday during peak hours on high irradiance days due to "PV Abnormal Input - Protect0260". On 03/10, the technician followed Solectria’s advice, removed the parallel bar, and set dipswitches to independent. Inverters have been producing normally since 03/11. 2.Inverter 7 has experienced multiple trippings on 03/24 due to PV Abnormal Input fault. | K7: 1.SR097972,SR098257 2.SR098919 | L7: SR098257 | M7: SR098919
A8: Wareham - 8 Thatcher Drive | B8: MA | C8: 14875.812 | D8: 15055.13 | E8: =IF(AND(ISNUMBER(C8),ISNUMBER(D8)), C8-D8, "") -> -179.3175 | F8: =IFERROR(E8/D8, "") -> -0.011910724 | G8: 16928.07 | H8: =IF(AND(ISNUMBER(C8),ISNUMBER(G8)), C8-G8, "") -> -2052.2575 | I8: =IFERROR(H8/G8, "") -> -0.12123399 | J8: 1. Site production was low on 03/05, 03/06, 03/17, 03/24 and 03/29 to 03/31 due to weather event.
A9: West Yarmouth - 42 Mid Tech | B9: MA | C9: 12225.682 | D9: 13601.24 | E9: =IF(AND(ISNUMBER(C9),ISNUMBER(D9)), C9-D9, "") -> -1375.5583 | F9: =IFERROR(E9/D9, "") -> -0.10113477 | G9: 14703.99 | H9: =IF(AND(ISNUMBER(C9),ISNUMBER(G9)), C9-G9, "") -> -2478.3083 | I9: =IFERROR(H9/G9, "") -> -0.16854665 | J9: 1. Site production was low on 03/05, 03/06, 03/17, 03/24 and 03/29 to 03/31 due to weather event.
A10: Harrison - 130 Union Street | B10: NY | C10: 23281.875 | D10: 24219.16 | E10: =IF(AND(ISNUMBER(C10),ISNUMBER(D10)), C10-D10, "") -> -937.285 | F10: =IFERROR(E10/D10, "") -> -0.038700145 | G10: 21479.86 | H10: =IF(AND(ISNUMBER(C10),ISNUMBER(G10)), C10-G10, "") -> 1802.015 | I10: =IFERROR(H10/G10, "") -> 0.083893238
A11: Staten Island - Ellis Storage | B11: NY | C11: 53693.25 | D11: 50948.08 | E11: =IF(AND(ISNUMBER(C11),ISNUMBER(D11)), C11-D11, "") -> 2745.17 | F11: =IFERROR(E11/D11, "") -> 0.053881716 | G11: 48258.91 | H11: =IF(AND(ISNUMBER(C11),ISNUMBER(G11)), C11-G11, "") -> 5434.34 | I11: =IFERROR(H11/G11, "") -> 0.11260801
A12: Amherst - 595 Scholles Road | B12: NY | C12: 571517 | D12: 702948.9 | E12: =IF(AND(ISNUMBER(C12),ISNUMBER(D12)), C12-D12, "") -> -131431.9 | F12: =IFERROR(E12/D12, "") -> -0.1869722 | G12: 728804.1 | H12: =IF(AND(ISNUMBER(C12),ISNUMBER(G12)), C12-G12, "") -> -157287.1 | I12: =IFERROR(H12/G12, "") -> -0.21581533 | J12: 1.Site tripped offline at 14:07 on 03/14 and back online at 10AM on 03/15 after technician closed relay and re-energized the site. Again tripped offline at 18:45 on 03/15 back online at 8AM on 03/17. Site again tripped offline at 10:45 on 03/22 and back online at 8:45 on 03/24. Again tripped offline at 17:00 on 03/25 due to utility outage and back online at 11:30 on 03/27. Again tripped offline at 14:45 on 03/28 and back online at 8:15AM on 03/31. | K12: 1.SR098595, SR098886, SR098982 & SR099115. | L12: SR098886 | M12: SR098982 | N12: SR099115
A13: Lancaster 1 - Gunnville Road | B13: NY | C13: 598573 | D13: 629166 | E13: =IF(AND(ISNUMBER(C13),ISNUMBER(D13)), C13-D13, "") -> -30593 | F13: =IFERROR(E13/D13, "") -> -0.048624687 | G13: 641592.3 | H13: =IF(AND(ISNUMBER(C13),ISNUMBER(G13)), C13-G13, "") -> -43019.3 | I13: =IFERROR(H13/G13, "") -> -0.067050836 | J13: 1.Inverter 1.1 was derated at 165KW between 12PM to 16:30 on 03/10, 03/13, 03/14, 03/18 and 03/19. | K13: 1.SR098345
A14: Lancaster 2 - Shisler Road | B14: NY | C14: 648289 | D14: 692226.9 | E14: =IF(AND(ISNUMBER(C14),ISNUMBER(D14)), C14-D14, "") -> -43937.9 | F14: =IFERROR(E14/D14, "") -> -0.063473263 | G14: 704760.1 | H14: =IF(AND(ISNUMBER(C14),ISNUMBER(G14)), C14-G14, "") -> -56471.1 | I14: =IFERROR(H14/G14, "") -> -0.080128117 | J14: 1. Inverter 3.4 with 12 strings, Inverter 3.5 with 12 strings, Inverter 3.6 with 12 strings, Inverter 3.7 with 7 strings, Inverter 3.8 with 4 and 10 strings, Inverter 3.9 with 7 strings, and Inverter 3.10 with 9 strings are overall underperforming by 250KW. | K14: 1. SR098941
A15: Fullerton - 200 W Orangethorpe | B15: CA | C15: 96573.5 | D15: 99489.52 | E15: =IF(AND(ISNUMBER(C15),ISNUMBER(D15)), C15-D15, "") -> -2916.02 | F15: =IFERROR(E15/D15, "") -> -0.029309821 | G15: 111528.7 | H15: =IF(AND(ISNUMBER(C15),ISNUMBER(G15)), C15-G15, "") -> -14955.2 | I15: =IFERROR(H15/G15, "") -> -0.13409284 | J15: 1Inverter 5 was offline for multiple days on 03/03, 03/05, 03/07, 03/08, 03/12, and started late on 03/19 due to a Fault to Stop AFCI Fault. After a technician performed a power cycle on both the AC and DC sides, the inverter performance improved. | K15: 1. SR098011
A16: El Paso - 10500 Railroad Drive | B16: TX | C16: 137031.75 | D16: 125322.2 | E16: =IF(AND(ISNUMBER(C16),ISNUMBER(D16)), C16-D16, "") -> 11709.55 | F16: =IFERROR(E16/D16, "") -> 0.09343556 | G16: 132709.5 | H16: =IF(AND(ISNUMBER(C16),ISNUMBER(G16)), C16-G16, "") -> 4322.25 | I16: =IFERROR(H16/G16, "") -> 0.032569258 | J16: 1.Inverter 6 experienced tripping events on 03/01, 03/05, 03/07 to 03/13, and 03/16. The issue, caused by VARS (Volt-Ampere Reactive power) from the utility, persisted and worsened in February. After the technician performed wire management, the inverter performance improved, and an RMA was initiated for the inverter. | K16: 1.SR098406
