Workbook
Name JanActual: #REF!
Name JanActual2: #REF!
Name JanExpected: #REF!
Name JanExpectedDelta: #REF!
Name JanExpectedPercent: #REF!
Name JanExpPercent: #REF!
Name JanForecasted: #REF!
Name JanForecastedDelta: #REF!
Name JanForecastedPercent: #REF!
Name portfolio: Sites!$B$1:$B$1
Name Year: Sites!#REF!

Sheet Year to Date
A1: {=portfolio} -> Lodestar | D1: Year to Date Actual v. Expected | G1: Year to Date Actual v. Forecasted
A2: Total | C2: =SUM(C4:C103) -> 25286620 | D2: =SUM(D4:D103) -> 25764645 | E2: =C2-D2 -> -478024.99 | F2: =IFERROR(E2/D2, 0) -> -0.018553525 | G2: =SUM(G4:G103) -> 25585452 | H2: =C2-G2 -> -298832.17 | I2: =IFERROR(H2/G2, 0) -> -0.011679769
A3: Site | B3: State | C3: Actual | D3: Expected | E3: Delta | F3: % | G3: Forecasted | H3: Delta | I3: %
A4: {=Sites[Site]} -> Barkhamsted | B4: {=Sites[State]} -> CT | C4: =SUM('1st Qtr'!C4, '2nd Qtr'!C4, '3rd Qtr'!C4, '4th Qtr'!C4) -> 437518 | D4: =SUM('1st Qtr'!D4, '2nd Qtr'!D4, '3rd Qtr'!D4, '4th Qtr'!D4) -> 589021.4 | E4: =IF(AND(ISNUMBER(C4),ISNUMBER(D4)), C4-D4, "") -> -151503.4 | F4: =IFERROR(E4/D4, "") -> -0.25721205 | G4: =SUM('1st Qtr'!G4, '2nd Qtr'!G4, '3rd Qtr'!G4, '4th Qtr'!G4) -> 549865.04 | H4: =SUM('1st Qtr'!H4, '2nd Qtr'!H4, '3rd Qtr'!H4, '4th Qtr'!H4) -> -112347.04 | I4: =IFERROR(H4/G4, "") -> -0.20431748
A5: Bunce | B5: CT | C5: =SUM('1st Qtr'!C5, '2nd Qtr'!C5, '3rd Qtr'!C5, '4th Qtr'!C5) -> 898240 | D5: =SUM('1st Qtr'!D5, '2nd Qtr'!D5, '3rd Qtr'!D5, '4th Qtr'!D5) -> 932394.1 | E5: =IF(AND(ISNUMBER(C5),ISNUMBER(D5)), C5-D5, "") -> -34154.1 | F5: =IFERROR(E5/D5, "") -> -0.036630541 | G5: =SUM('1st Qtr'!G5, '2nd Qtr'!G5, '3rd Qtr'!G5, '4th Qtr'!G5) -> 0 | H5: =SUM('1st Qtr'!H5, '2nd Qtr'!H5, '3rd Qtr'!H5, '4th Qtr'!H5) -> 0 | I5: =IFERROR(H5/G5, "")
A6: Norcap North | B6: CT | C6: =SUM('1st Qtr'!C6, '2nd Qtr'!C6, '3rd Qtr'!C6, '4th Qtr'!C6) -> 979204 | D6: =SUM('1st Qtr'!D6, '2nd Qtr'!D6, '3rd Qtr'!D6, '4th Qtr'!D6) -> 1213884.7 | E6: =IF(AND(ISNUMBER(C6),ISNUMBER(D6)), C6-D6, "") -> -234680.7 | F6: =IFERROR(E6/D6, "") -> -0.19333031 | G6: =SUM('1st Qtr'!G6, '2nd Qtr'!G6, '3rd Qtr'!G6, '4th Qtr'!G6) -> 1020911 | H6: =SUM('1st Qtr'!H6, '2nd Qtr'!H6, '3rd Qtr'!H6, '4th Qtr'!H6) -> -41707 | I6: =IFERROR(H6/G6, "") -> -0.040852729
A7: Norcap South | B7: CT | C7: =SUM('1st Qtr'!C7, '2nd Qtr'!C7, '3rd Qtr'!C7, '4th Qtr'!C7) -> 1052632.5 | D7: =SUM('1st Qtr'!D7, '2nd Qtr'!D7, '3rd Qtr'!D7, '4th Qtr'!D7) -> 1300698.8 | E7: =IF(AND(ISNUMBER(C7),ISNUMBER(D7)), C7-D7, "") -> -248066.3 | F7: =IFERROR(E7/D7, "") -> -0.19071771 | G7: =SUM('1st Qtr'!G7, '2nd Qtr'!G7, '3rd Qtr'!G7, '4th Qtr'!G7) -> 974406.8 | H7: =SUM('1st Qtr'!H7, '2nd Qtr'!H7, '3rd Qtr'!H7, '4th Qtr'!H7) -> 78225.7 | I7: =IFERROR(H7/G7, "") -> 0.080280331
A8: Platt Hill | B8: CT | C8: =SUM('1st Qtr'!C8, '2nd Qtr'!C8, '3rd Qtr'!C8, '4th Qtr'!C8) -> 912441 | D8: =SUM('1st Qtr'!D8, '2nd Qtr'!D8, '3rd Qtr'!D8, '4th Qtr'!D8) -> 1179269.6 | E8: =IF(AND(ISNUMBER(C8),ISNUMBER(D8)), C8-D8, "") -> -266828.6 | F8: =IFERROR(E8/D8, "") -> -0.22626599 | G8: =SUM('1st Qtr'!G8, '2nd Qtr'!G8, '3rd Qtr'!G8, '4th Qtr'!G8) -> 1239875.9 | H8: =SUM('1st Qtr'!H8, '2nd Qtr'!H8, '3rd Qtr'!H8, '4th Qtr'!H8) -> -327434.9 | I8: =IFERROR(H8/G8, "") -> -0.26408683
A9: Powder Hill | B9: CT | C9: =SUM('1st Qtr'!C9, '2nd Qtr'!C9, '3rd Qtr'!C9, '4th Qtr'!C9) -> 965367 | D9: =SUM('1st Qtr'!D9, '2nd Qtr'!D9, '3rd Qtr'!D9, '4th Qtr'!D9) -> 1083867.3 | E9: =IF(AND(ISNUMBER(C9),ISNUMBER(D9)), C9-D9, "") -> -118500.3 | F9: =IFERROR(E9/D9, "") -> -0.109331 | G9: =SUM('1st Qtr'!G9, '2nd Qtr'!G9, '3rd Qtr'!G9, '4th Qtr'!G9) -> 832308 | H9: =SUM('1st Qtr'!H9, '2nd Qtr'!H9, '3rd Qtr'!H9, '4th Qtr'!H9) -> 133059 | I9: =IFERROR(H9/G9, "") -> 0.1598675
A10: Sand Road | B10: CT | C10: =SUM('1st Qtr'!C10, '2nd Qtr'!C10, '3rd Qtr'!C10, '4th Qtr'!C10) -> 953592 | D10: =SUM('1st Qtr'!D10, '2nd Qtr'!D10, '3rd Qtr'!D10, '4th Qtr'!D10) -> 985996.2 | E10: =IF(AND(ISNUMBER(C10),ISNUMBER(D10)), C10-D10, "") -> -32404.2 | F10: =IFERROR(E10/D10, "") -> -0.032864427 | G10: =SUM('1st Qtr'!G10, '2nd Qtr'!G10, '3rd Qtr'!G10, '4th Qtr'!G10) -> 911572 | H10: =SUM('1st Qtr'!H10, '2nd Qtr'!H10, '3rd Qtr'!H10, '4th Qtr'!H10) -> 42020 | I10: =IFERROR(H10/G10, "") -> 0.046096194
A11: Suffield | B11: CT | C11: =SUM('1st Qtr'!C11, '2nd Qtr'!C11, '3rd Qtr'!C11, '4th Qtr'!C11) -> 982535 | D11: =SUM('1st Qtr'!D11, '2nd Qtr'!D11, '3rd Qtr'!D11, '4th Qtr'!D11) -> 1067300.7 | E11: =IF(AND(ISNUMBER(C11),ISNUMBER(D11)), C11-D11, "") -> -84765.7 | F11: =IFERROR(E11/D11, "") -> -0.079420636 | G11: =SUM('1st Qtr'!G11, '2nd Qtr'!G11, '3rd Qtr'!G11, '4th Qtr'!G11) -> 1063535.6 | H11: =SUM('1st Qtr'!H11, '2nd Qtr'!H11, '3rd Qtr'!H11, '4th Qtr'!H11) -> -81000.6 | I11: =IFERROR(H11/G11, "") -> -0.076161625
A12: Ashby-Duffy | B12: MA | C12: =SUM('1st Qtr'!C12, '2nd Qtr'!C12, '3rd Qtr'!C12, '4th Qtr'!C12) -> 844055 | D12: =SUM('1st Qtr'!D12, '2nd Qtr'!D12, '3rd Qtr'!D12, '4th Qtr'!D12) -> 1378683.6 | E12: =IF(AND(ISNUMBER(C12),ISNUMBER(D12)), C12-D12, "") -> -534628.6 | F12: =IFERROR(E12/D12, "") -> -0.38778194 | G12: =SUM('1st Qtr'!G12, '2nd Qtr'!G12, '3rd Qtr'!G12, '4th Qtr'!G12) -> 943502.1 | H12: =SUM('1st Qtr'!H12, '2nd Qtr'!H12, '3rd Qtr'!H12, '4th Qtr'!H12) -> -99447.1 | I12: =IFERROR(H12/G12, "") -> -0.1054021
A13: Ashland | B13: MA | C13: =SUM('1st Qtr'!C13, '2nd Qtr'!C13, '3rd Qtr'!C13, '4th Qtr'!C13) -> 862763.5 | D13: =SUM('1st Qtr'!D13, '2nd Qtr'!D13, '3rd Qtr'!D13, '4th Qtr'!D13) -> 1128879.9 | E13: =IF(AND(ISNUMBER(C13),ISNUMBER(D13)), C13-D13, "") -> -266116.4 | F13: =IFERROR(E13/D13, "") -> -0.23573491 | G13: =SUM('1st Qtr'!G13, '2nd Qtr'!G13, '3rd Qtr'!G13, '4th Qtr'!G13) -> 1030160.8 | H13: =SUM('1st Qtr'!H13, '2nd Qtr'!H13, '3rd Qtr'!H13, '4th Qtr'!H13) -> -167397.3 | I13: =IFERROR(H13/G13, "") -> -0.16249628
A14: Barrington | B14: MA | C14: =SUM('1st Qtr'!C14, '2nd Qtr'!C14, '3rd Qtr'!C14, '4th Qtr'!C14) -> 181283 | D14: =SUM('1st Qtr'!D14, '2nd Qtr'!D14, '3rd Qtr'!D14, '4th Qtr'!D14) -> 88954.92 | E14: =IF(AND(ISNUMBER(C14),ISNUMBER(D14)), C14-D14, "") -> 92328.08 | F14: =IFERROR(E14/D14, "") -> 1.0379199 | G14: =SUM('1st Qtr'!G14, '2nd Qtr'!G14, '3rd Qtr'!G14, '4th Qtr'!G14) -> 233670 | H14: =SUM('1st Qtr'!H14, '2nd Qtr'!H14, '3rd Qtr'!H14, '4th Qtr'!H14) -> -52387 | I14: =IFERROR(H14/G14, "") -> -0.22419224
A15: Bedford - 205 Burlington Rd | B15: MA | C15: =SUM('1st Qtr'!C15, '2nd Qtr'!C15, '3rd Qtr'!C15, '4th Qtr'!C15) -> 95466 | D15: =SUM('1st Qtr'!D15, '2nd Qtr'!D15, '3rd Qtr'!D15, '4th Qtr'!D15) -> 0 | E15: =IF(AND(ISNUMBER(C15),ISNUMBER(D15)), C15-D15, "") -> 95466 | F15: =IFERROR(E15/D15, "") | G15: =SUM('1st Qtr'!G15, '2nd Qtr'!G15, '3rd Qtr'!G15, '4th Qtr'!G15) -> 0 | H15: =SUM('1st Qtr'!H15, '2nd Qtr'!H15, '3rd Qtr'!H15, '4th Qtr'!H15) -> 0 | I15: =IFERROR(H15/G15, "")
A16: Billerica - 6 Cook Street | B16: MA | C16: =SUM('1st Qtr'!C16, '2nd Qtr'!C16, '3rd Qtr'!C16, '4th Qtr'!C16) -> 84751 | D16: =SUM('1st Qtr'!D16, '2nd Qtr'!D16, '3rd Qtr'!D16, '4th Qtr'!D16) -> 0 | E16: =IF(AND(ISNUMBER(C16),ISNUMBER(D16)), C16-D16, "") -> 84751 | F16: =IFERROR(E16/D16, "") | G16: =SUM('1st Qtr'!G16, '2nd Qtr'!G16, '3rd Qtr'!G16, '4th Qtr'!G16) -> 0 | H16: =SUM('1st Qtr'!H16, '2nd Qtr'!H16, '3rd Qtr'!H16, '4th Qtr'!H16) -> 0 | I16: =IFERROR(H16/G16, "")
... A34: Stockbridge – 92 State Line Road Truck Stop | B34: MA | C34: =SUM('1st Qtr'!C34, '2nd Qtr'!C34, '3rd Qtr'!C34, '4th Qtr'!C34) -> 667414.87 | D34: =SUM('1st Qtr'!D34, '2nd Qtr'!D34, '3rd Qtr'!D34, '4th Qtr'!D34) -> 680989.02 | E34: =IF(AND(ISNUMBER(C34),ISNUMBER(D34)), C34-D34, "") -> -13574.152 | F34: =IFERROR(E34/D34, "") -> -0.019932997 | G34: =SUM('1st Qtr'!G34, '2nd Qtr'!G34, '3rd Qtr'!G34, '4th Qtr'!G34) -> 775023.42 | H34: =SUM('1st Qtr'!H34, '2nd Qtr'!H34, '3rd Qtr'!H34, '4th Qtr'!H34) -> -313585.42 | I34: =IFERROR(H34/G34, "") -> -0.40461412

Sheet 1st Qtr
A1: {=portfolio} -> Lodestar | D1: 1st Quarter Actual v. Expected | G1: 1st Quarter Actual v. Forecasted
A2: Total | C2: =SUM(C4:C103) -> 16452264 | D2: =SUM(D4:D103) -> 19010660 | E2: =C2-D2 -> -2558396 | F2: =IFERROR(E2/D2, 0) -> -0.13457692 | G2: =SUM(G4:G103) -> 18375452 | H2: =C2-G2 -> -1923187.8 | I2: =IFERROR(H2/G2, 0) -> -0.10466071
A3: Site | B3: State | C3: Actual | D3: Expected | E3: Delta | F3: % | G3: Forecasted | H3: Delta | I3: %
A4: {=Sites[Site]} -> Barkhamsted | B4: {=Sites[State]} -> CT | C4: =SUM(Jan!C4, Feb!C4, Mar!C4) -> 268344 | D4: =SUM(Jan!D4, Feb!D4, Mar!D4) -> 421750.9 | E4: =IF(AND(ISNUMBER(C4),ISNUMBER(D4)), C4-D4, "") -> -153406.9 | F4: =IFERROR(E4/D4, "") -> -0.36373817 | G4: =SUM(Jan!G4, Feb!G4, Mar!G4) -> 378669.74 | H4: =SUM(Jan!H4, Feb!H4, Mar!H4) -> -110325.74 | I4: =IFERROR(H4/G4, "") -> -0.29135082
A5: Bunce | B5: CT | C5: =SUM(Jan!C5, Feb!C5, Mar!C5) -> 601753.5 | D5: =SUM(Jan!D5, Feb!D5, Mar!D5) -> 684621.1 | E5: =IF(AND(ISNUMBER(C5),ISNUMBER(D5)), C5-D5, "") -> -82867.6 | F5: =IFERROR(E5/D5, "") -> -0.12104155 | G5: =SUM(Jan!G5, Feb!G5, Mar!G5) -> 0 | H5: =SUM(Jan!H5, Feb!H5, Mar!H5) -> 0 | I5: =IFERROR(H5/G5, "")
A6: Norcap North | B6: CT | C6: =SUM(Jan!C6, Feb!C6, Mar!C6) -> 665544 | D6: =SUM(Jan!D6, Feb!D6, Mar!D6) -> 901318.4 | E6: =IF(AND(ISNUMBER(C6),ISNUMBER(D6)), C6-D6, "") -> -235774.4 | F6: =IFERROR(E6/D6, "") -> -0.26158836 | G6: =SUM(Jan!G6, Feb!G6, Mar!G6) -> 696719.6 | H6: =SUM(Jan!H6, Feb!H6, Mar!H6) -> -31175.6 | I6: =IFERROR(H6/G6, "") -> -0.044746265
A7: Norcap South | B7: CT | C7: =SUM(Jan!C7, Feb!C7, Mar!C7) -> 722340.5 | D7: =SUM(Jan!D7, Feb!D7, Mar!D7) -> 975622.9 | E7: =IF(AND(ISNUMBER(C7),ISNUMBER(D7)), C7-D7, "") -> -253282.4 | F7: =IFERROR(E7/D7, "") -> -0.25961096 | G7: =SUM(Jan!G7, Feb!G7, Mar!G7) -> 656577.7 | H7: =SUM(Jan!H7, Feb!H7, Mar!H7) -> 65762.8 | I7: =IFERROR(H7/G7, "") -> 0.10015997
A8: Platt Hill | B8: CT | C8: =SUM(Jan!C8, Feb!C8, Mar!C8) -> 558121 | D8: =SUM(Jan!D8, Feb!D8, Mar!D8) -> 824707.8 | E8: =IF(AND(ISNUMBER(C8),ISNUMBER(D8)), C8-D8, "") -> -266586.8 | F8: =IFERROR(E8/D8, "") -> -0.32325 | G8: =SUM(Jan!G8, Feb!G8, Mar!G8) -> 857153.4 | H8: =SUM(Jan!H8, Feb!H8, Mar!H8) -> -299032.4 | I8: =IFERROR(H8/G8, "") -> -0.34886684
A9: Powder Hill | B9: CT | C9: =SUM(Jan!C9, Feb!C9, Mar!C9) -> 636559 | D9: =SUM(Jan!D9, Feb!D9, Mar!D9) -> 764818.1 | E9: =IF(AND(ISNUMBER(C9),ISNUMBER(D9)), C9-D9, "") -> -128259.1 | F9: =IFERROR(E9/D9, "") -> -0.16769883 | G9: =SUM(Jan!G9, Feb!G9, Mar!G9) -> 566964 | H9: =SUM(Jan!H9, Feb!H9, Mar!H9) -> 69595 | I9: =IFERROR(H9/G9, "") -> 0.1227503
A10: Sand Road | B10: CT | C10: =SUM(Jan!C10, Feb!C10, Mar!C10) -> 629363 | D10: =SUM(Jan!D10, Feb!D10, Mar!D10) -> 693953.2 | E10: =IF(AND(ISNUMBER(C10),ISNUMBER(D10)), C10-D10, "") -> -64590.2 | F10: =IFERROR(E10/D10, "") -> -0.093075729 | G10: =SUM(Jan!G10, Feb!G10, Mar!G10) -> 602989 | H10: =SUM(Jan!H10, Feb!H10, Mar!H10) -> 26374 | I10: =IFERROR(H10/G10, "") -> 0.043738775
A11: Suffield | B11: CT | C11: =SUM(Jan!C11, Feb!C11, Mar!C11) -> 646808 | D11: =SUM(Jan!D11, Feb!D11, Mar!D11) -> 747386.4 | E11: =IF(AND(ISNUMBER(C11),ISNUMBER(D11)), C11-D11, "") -> -100578.4 | F11: =IFERROR(E11/D11, "") -> -0.1345735 | G11: =SUM(Jan!G11, Feb!G11, Mar!G11) -> 728845.7 | H11: =SUM(Jan!H11, Feb!H11, Mar!H11) -> -82037.7 | I11: =IFERROR(H11/G11, "") -> -0.11255839
A12: Ashby-Duffy | B12: MA | C12: =SUM(Jan!C12, Feb!C12, Mar!C12) -> 531938 | D12: =SUM(Jan!D12, Feb!D12, Mar!D12) -> 986411 | E12: =IF(AND(ISNUMBER(C12),ISNUMBER(D12)), C12-D12, "") -> -454473 | F12: =IFERROR(E12/D12, "") -> -0.46073391 | G12: =SUM(Jan!G12, Feb!G12, Mar!G12) -> 648393.4 | H12: =SUM(Jan!H12, Feb!H12, Mar!H12) -> -116455.4 | I12: =IFERROR(H12/G12, "") -> -0.17960608
A13: Ashland | B13: MA | C13: =SUM(Jan!C13, Feb!C13, Mar!C13) -> 531484 | D13: =SUM(Jan!D13, Feb!D13, Mar!D13) -> 790545.5 | E13: =IF(AND(ISNUMBER(C13),ISNUMBER(D13)), C13-D13, "") -> -259061.5 | F13: =IFERROR(E13/D13, "") -> -0.32769967 | G13: =SUM(Jan!G13, Feb!G13, Mar!G13) -> 680224.1 | H13: =SUM(Jan!H13, Feb!H13, Mar!H13) -> -148740.1 | I13: =IFERROR(H13/G13, "") -> -0.21866338
A14: Barrington | B14: MA | C14: =SUM(Jan!C14, Feb!C14, Mar!C14) -> 112260.5 | D14: =SUM(Jan!D14, Feb!D14, Mar!D14) -> 75219.05 | E14: =IF(AND(ISNUMBER(C14),ISNUMBER(D14)), C14-D14, "") -> 37041.45 | F14: =IFERROR(E14/D14, "") -> 0.49244772 | G14: =SUM(Jan!G14, Feb!G14, Mar!G14) -> 159190 | H14: =SUM(Jan!H14, Feb!H14, Mar!H14) -> -46929.5 | I14: =IFERROR(H14/G14, "") -> -0.29480181
A15: Bedford - 205 Burlington Rd | B15: MA | C15: =SUM(Jan!C15, Feb!C15, Mar!C15) -> 54600 | D15: =SUM(Jan!D15, Feb!D15, Mar!D15) -> 0 | E15: =IF(AND(ISNUMBER(C15),ISNUMBER(D15)), C15-D15, "") -> 54600 | F15: =IFERROR(E15/D15, "") | G15: =SUM(Jan!G15, Feb!G15, Mar!G15) -> 0 | H15: =SUM(Jan!H15, Feb!H15, Mar!H15) -> 0 | I15: =IFERROR(H15/G15, "")
A16: Billerica - 6 Cook Street | B16: MA | C16: =SUM(Jan!C16, Feb!C16, Mar!C16) -> 47090 | D16: =SUM(Jan!D16, Feb!D16, Mar!D16) -> 0 | E16: =IF(AND(ISNUMBER(C16),ISNUMBER(D16)), C16-D16, "") -> 47090 | F16: =IFERROR(E16/D16, "") | G16: =SUM(Jan!G16, Feb!G16, Mar!G16) -> 0 | H16: =SUM(Jan!H16, Feb!H16, Mar!H16) -> 0 | I16: =IFERROR(H16/G16, "")
... A34: Stockbridge – 92 State Line Road Truck Stop | B34: MA | C34: =SUM(Jan!C34, Feb!C34, Mar!C34) -> 461438 | D34: =SUM(Jan!D34, Feb!D34, Mar!D34) -> 680989.02 | E34: =IF(AND(ISNUMBER(C34),ISNUMBER(D34)), C34-D34, "") -> -219551.02 | F34: =IFERROR(E34/D34, "") -> -0.32240023 | G34: =SUM(Jan!G34, Feb!G34, Mar!G34) -> 775023.42 | H34: =SUM(Jan!H34, Feb!H34, Mar!H34) -> -313585.42 | I34: =IFERROR(H34/G34, "") -> -0.40461412

Sheet 2nd Qtr
A1: {=portfolio} -> Lodestar | D1: 2nd Quarter Actual v. Expected | G1: 2nd Quarter Actual v. Forecasted
A2: Total | C2: =SUM(C4:C103) -> 8834355.6 | D2: =SUM(D4:D103) -> 6753984.6 | E2: =C2-D2 -> 2080371 | F2: =IFERROR(E2/D2, 0) -> 0.30802129 | G2: =SUM(G4:G103) -> 7209999.9 | H2: =C2-G2 -> 1624355.6 | I2: =IFERROR(H2/G2, 0) -> 0.22529205
A3: Site | B3: State | C3: Actual | D3: Expected | E3: Delta | F3: % | G3: Forecasted | H3: Delta | I3: %
A4: {=Sites[Site]} -> Barkhamsted | B4: {=Sites[State]} -> CT | C4: =SUM(Apr!C4, May!C4, Jun!C4) -> 169174 | D4: =SUM(Apr!D4, May!D4, Jun!D4) -> 167270.5 | E4: =IF(AND(ISNUMBER(C4),ISNUMBER(D4)), C4-D4, "") -> 1903.5 | F4: =IFERROR(E4/D4, "") -> 0.011379771 | G4: =SUM(Apr!G4,May!G4,Jun!G4) -> 171195.3 | H4: =SUM(Apr!H4, May!H4, Jun!H4) -> -2021.3 | I4: =IFERROR(H4/G4, "") -> -0.011806983
A5: Bunce | B5: CT | C5: =SUM(Apr!C5, May!C5, Jun!C5) -> 296486.5 | D5: =SUM(Apr!D5, May!D5, Jun!D5) -> 247773 | E5: =IF(AND(ISNUMBER(C5),ISNUMBER(D5)), C5-D5, "") -> 48713.5 | F5: =IFERROR(E5/D5, "") -> 0.19660536 | G5: =SUM(Apr!G5,May!G5,Jun!G5) -> 0 | H5: =SUM(Apr!H5, May!H5, Jun!H5) -> 0 | I5: =IFERROR(H5/G5, "")
A6: Norcap North | B6: CT | C6: =SUM(Apr!C6, May!C6, Jun!C6) -> 313660 | D6: =SUM(Apr!D6, May!D6, Jun!D6) -> 312566.3 | E6: =IF(AND(ISNUMBER(C6),ISNUMBER(D6)), C6-D6, "") -> 1093.7 | F6: =IFERROR(E6/D6, "") -> 0.0034990976 | G6: =SUM(Apr!G6,May!G6,Jun!G6) -> 324191.4 | H6: =SUM(Apr!H6, May!H6, Jun!H6) -> -10531.4 | I6: =IFERROR(H6/G6, "") -> -0.032485131
A7: Norcap South | B7: CT | C7: =SUM(Apr!C7, May!C7, Jun!C7) -> 330292 | D7: =SUM(Apr!D7, May!D7, Jun!D7) -> 325075.9 | E7: =IF(AND(ISNUMBER(C7),ISNUMBER(D7)), C7-D7, "") -> 5216.1 | F7: =IFERROR(E7/D7, "") -> 0.016045791 | G7: =SUM(Apr!G7,May!G7,Jun!G7) -> 317829.1 | H7: =SUM(Apr!H7, May!H7, Jun!H7) -> 12462.9 | I7: =IFERROR(H7/G7, "") -> 0.039212583
A8: Platt Hill | B8: CT | C8: =SUM(Apr!C8, May!C8, Jun!C8) -> 354320 | D8: =SUM(Apr!D8, May!D8, Jun!D8) -> 354561.8 | E8: =IF(AND(ISNUMBER(C8),ISNUMBER(D8)), C8-D8, "") -> -241.8 | F8: =IFERROR(E8/D8, "") -> -0.00068196856 | G8: =SUM(Apr!G8,May!G8,Jun!G8) -> 382722.5 | H8: =SUM(Apr!H8, May!H8, Jun!H8) -> -28402.5 | I8: =IFERROR(H8/G8, "") -> -0.074211733
A9: Powder Hill | B9: CT | C9: =SUM(Apr!C9, May!C9, Jun!C9) -> 328808 | D9: =SUM(Apr!D9, May!D9, Jun!D9) -> 319049.2 | E9: =IF(AND(ISNUMBER(C9),ISNUMBER(D9)), C9-D9, "") -> 9758.8 | F9: =IFERROR(E9/D9, "") -> 0.030587132 | G9: =SUM(Apr!G9,May!G9,Jun!G9) -> 265344 | H9: =SUM(Apr!H9, May!H9, Jun!H9) -> 63464 | I9: =IFERROR(H9/G9, "") -> 0.23917631
A10: Sand Road | B10: CT | C10: =SUM(Apr!C10, May!C10, Jun!C10) -> 324229 | D10: =SUM(Apr!D10, May!D10, Jun!D10) -> 292043 | E10: =IF(AND(ISNUMBER(C10),ISNUMBER(D10)), C10-D10, "") -> 32186 | F10: =IFERROR(E10/D10, "") -> 0.1102098 | G10: =SUM(Apr!G10,May!G10,Jun!G10) -> 308583 | H10: =SUM(Apr!H10, May!H10, Jun!H10) -> 15646 | I10: =IFERROR(H10/G10, "") -> 0.050702728
A11: Suffield | B11: CT | C11: =SUM(Apr!C11, May!C11, Jun!C11) -> 335727 | D11: =SUM(Apr!D11, May!D11, Jun!D11) -> 319914.3 | E11: =IF(AND(ISNUMBER(C11),ISNUMBER(D11)), C11-D11, "") -> 15812.7 | F11: =IFERROR(E11/D11, "") -> 0.049427925 | G11: =SUM(Apr!G11,May!G11,Jun!G11) -> 334689.9 | H11: =SUM(Apr!H11, May!H11, Jun!H11) -> 1037.1 | I11: =IFERROR(H11/G11, "") -> 0.0030986893
A12: Ashby-Duffy | B12: MA | C12: =SUM(Apr!C12, May!C12, Jun!C12) -> 312117 | D12: =SUM(Apr!D12, May!D12, Jun!D12) -> 392272.6 | E12: =IF(AND(ISNUMBER(C12),ISNUMBER(D12)), C12-D12, "") -> -80155.6 | F12: =IFERROR(E12/D12, "") -> -0.20433647 | G12: =SUM(Apr!G12,May!G12,Jun!G12) -> 295108.7 | H12: =SUM(Apr!H12, May!H12, Jun!H12) -> 17008.3 | I12: =IFERROR(H12/G12, "") -> 0.057634018
A13: Ashland | B13: MA | C13: =SUM(Apr!C13, May!C13, Jun!C13) -> 331279.5 | D13: =SUM(Apr!D13, May!D13, Jun!D13) -> 338334.4 | E13: =IF(AND(ISNUMBER(C13),ISNUMBER(D13)), C13-D13, "") -> -7054.9 | F13: =IFERROR(E13/D13, "") -> -0.020851855 | G13: =SUM(Apr!G13,May!G13,Jun!G13) -> 349936.7 | H13: =SUM(Apr!H13, May!H13, Jun!H13) -> -18657.2 | I13: =IFERROR(H13/G13, "") -> -0.053315928
A14: Barrington | B14: MA | C14: =SUM(Apr!C14, May!C14, Jun!C14) -> 69022.5 | D14: =SUM(Apr!D14, May!D14, Jun!D14) -> 13735.87 | E14: =IF(AND(ISNUMBER(C14),ISNUMBER(D14)), C14-D14, "") -> 55286.63 | F14: =IFERROR(E14/D14, "") -> 4.024982 | G14: =SUM(Apr!G14,May!G14,Jun!G14) -> 74480 | H14: =SUM(Apr!H14, May!H14, Jun!H14) -> -5457.5 | I14: =IFERROR(H14/G14, "") -> -0.073274705
A15: Bedford - 205 Burlington Rd | B15: MA | C15: =SUM(Apr!C15, May!C15, Jun!C15) -> 40866 | D15: =SUM(Apr!D15, May!D15, Jun!D15) -> 0 | E15: =IF(AND(ISNUMBER(C15),ISNUMBER(D15)), C15-D15, "") -> 40866 | F15: =IFERROR(E15/D15, "") | G15: =SUM(Apr!G15,May!G15,Jun!G15) -> 0 | H15: =SUM(Apr!H15, May!H15, Jun!H15) -> 0 | I15: =IFERROR(H15/G15, "")
A16: Billerica - 6 Cook Street | B16: MA | C16: =SUM(Apr!C16, May!C16, Jun!C16) -> 37661 | D16: =SUM(Apr!D16, May!D16, Jun!D16) -> 0 | E16: =IF(AND(ISNUMBER(C16),ISNUMBER(D16)), C16-D16, "") -> 37661 | F16: =IFERROR(E16/D16, "") | G16: =SUM(Apr!G16,May!G16,Jun!G16) -> 0 | H16: =SUM(Apr!H16, May!H16, Jun!H16) -> 0 | I16: =IFERROR(H16/G16, "")
... A34: Stockbridge – 92 State Line Road Truck Stop | B34: MA | C34: =SUM(Apr!C34, May!C34, Jun!C34) -> 205976.87 | D34: =SUM(Apr!D34, May!D34, Jun!D34) -> 0 | E34: =IF(AND(ISNUMBER(C34),ISNUMBER(D34)), C34-D34, "") -> 205976.87 | F34: =IFERROR(E34/D34, "") | G34: =SUM(Apr!G34,May!G34,Jun!G34) -> 0 | H34: =SUM(Apr!H34, May!H34, Jun!H34) -> 0 | I34: =IFERROR(H34/G34, "")

Sheet 3rd Qtr
A1: {=portfolio} -> Lodestar | D1: 3rd Quarter Actual v. Expected | G1: 3rd Quarter Actual v. Forecasted
A2: Total | C2: =SUM(C4:C103) -> 0 | D2: =SUM(D4:D103) -> 0 | E2: =C2-D2 -> 0 | F2: =IFERROR(E2/D2, 0) -> 0 | G2: =SUM(G4:G103) -> 0 | H2: =C2-G2 -> 0 | I2: =IFERROR(H2/G2, 0) -> 0
A3: Site | B3: State | C3: Actual | D3: Expected | E3: Delta | F3: % | G3: Forecasted | H3: Delta | I3: %
A4: {=Sites[Site]} -> Barkhamsted | B4: {=Sites[State]} -> CT | C4: =SUM(Jul!C4, Aug!C4, Sep!C4) -> 0 | D4: =SUM(Jul!D4, Aug!D4, Sep!D4) -> 0 | E4: =IF(AND(ISNUMBER(C4),ISNUMBER(D4)), C4-D4, "") -> 0 | F4: =IFERROR(E4/D4, "") | G4: =SUM(Jul!G4,Aug!G4,Sep!G4) -> 0 | H4: =SUM(Jul!H4, Aug!H4, Sep!H4) -> 0 | I4: =IFERROR(H4/G4, "")
A5: Bunce | B5: CT | C5: =SUM(Jul!C5, Aug!C5, Sep!C5) -> 0 | D5: =SUM(Jul!D5, Aug!D5, Sep!D5) -> 0 | E5: =IF(AND(ISNUMBER(C5),ISNUMBER(D5)), C5-D5, "") -> 0 | F5: =IFERROR(E5/D5, "") | G5: =SUM(Jul!G5,Aug!G5,Sep!G5) -> 0 | H5: =SUM(Jul!H5, Aug!H5, Sep!H5) -> 0 | I5: =IFERROR(H5/G5, "")
A6: Norcap North | B6: CT | C6: =SUM(Jul!C6, Aug!C6, Sep!C6) -> 0 | D6: =SUM(Jul!D6, Aug!D6, Sep!D6) -> 0 | E6: =IF(AND(ISNUMBER(C6),ISNUMBER(D6)), C6-D6, "") -> 0 | F6: =IFERROR(E6/D6, "") | G6: =SUM(Jul!G6,Aug!G6,Sep!G6) -> 0 | H6: =SUM(Jul!H6, Aug!H6, Sep!H6) -> 0 | I6: =IFERROR(H6/G6, "")
A7: Norcap South | B7: CT | C7: =SUM(Jul!C7, Aug!C7, Sep!C7) -> 0 | D7: =SUM(Jul!D7, Aug!D7, Sep!D7) -> 0 | E7: =IF(AND(ISNUMBER(C7),ISNUMBER(D7)), C7-D7, "") -> 0 | F7: =IFERROR(E7/D7, "") | G7: =SUM(Jul!G7,Aug!G7,Sep!G7) -> 0 | H7: =SUM(Jul!H7, Aug!H7, Sep!H7) -> 0 | I7: =IFERROR(H7/G7, "")
A8: Platt Hill | B8: CT | C8: =SUM(Jul!C8, Aug!C8, Sep!C8) -> 0 | D8: =SUM(Jul!D8, Aug!D8, Sep!D8) -> 0 | E8: =IF(AND(ISNUMBER(C8),ISNUMBER(D8)), C8-D8, "") -> 0 | F8: =IFERROR(E8/D8, "") | G8: =SUM(Jul!G8,Aug!G8,Sep!G8) -> 0 | H8: =SUM(Jul!H8, Aug!H8, Sep!H8) -> 0 | I8: =IFERROR(H8/G8, "")
A9: Powder Hill | B9: CT | C9: =SUM(Jul!C9, Aug!C9, Sep!C9) -> 0 | D9: =SUM(Jul!D9, Aug!D9, Sep!D9) -> 0 | E9: =IF(AND(ISNUMBER(C9),ISNUMBER(D9)), C9-D9, "") -> 0 | F9: =IFERROR(E9/D9, "") | G9: =SUM(Jul!G9,Aug!G9,Sep!G9) -> 0 | H9: =SUM(Jul!H9, Aug!H9, Sep!H9) -> 0 | I9: =IFERROR(H9/G9, "")
A10: Sand Road | B10: CT | C10: =SUM(Jul!C10, Aug!C10, Sep!C10) -> 0 | D10: =SUM(Jul!D10, Aug!D10, Sep!D10) -> 0 | E10: =IF(AND(ISNUMBER(C10),ISNUMBER(D10)), C10-D10, "") -> 0 | F10: =IFERROR(E10/D10, "") | G10: =SUM(Jul!G10,Aug!G10,Sep!G10) -> 0 | H10: =SUM(Jul!H10, Aug!H10, Sep!H10) -> 0 | I10: =IFERROR(H10/G10, "")
A11: Suffield | B11: CT | C11: =SUM(Jul!C11, Aug!C11, Sep!C11) -> 0 | D11: =SUM(Jul!D11, Aug!D11, Sep!D11) -> 0 | E11: =IF(AND(ISNUMBER(C11),ISNUMBER(D11)), C11-D11, "") -> 0 | F11: =IFERROR(E11/D11, "") | G11: =SUM(Jul!G11,Aug!G11,Sep!G11) -> 0 | H11: =SUM(Jul!H11, Aug!H11, Sep!H11) -> 0 | I11: =IFERROR(H11/G11, "")
A12: Ashby-Duffy | B12: MA | C12: =SUM(Jul!C12, Aug!C12, Sep!C12) -> 0 | D12: =SUM(Jul!D12, Aug!D12, Sep!D12) -> 0 | E12: =IF(AND(ISNUMBER(C12),ISNUMBER(D12)), C12-D12, "") -> 0 | F12: =IFERROR(E12/D12, "") | G12: =SUM(Jul!G12,Aug!G12,Sep!G12) -> 0 | H12: =SUM(Jul!H12, Aug!H12, Sep!H12) -> 0 | I12: =IFERROR(H12/G12, "")
A13: Ashland | B13: MA | C13: =SUM(Jul!C13, Aug!C13, Sep!C13) -> 0 | D13: =SUM(Jul!D13, Aug!D13, Sep!D13) -> 0 | E13: =IF(AND(ISNUMBER(C13),ISNUMBER(D13)), C13-D13, "") -> 0 | F13: =IFERROR(E13/D13, "") | G13: =SUM(Jul!G13,Aug!G13,Sep!G13) -> 0 | H13: =SUM(Jul!H13, Aug!H13, Sep!H13) -> 0 | I13: =IFERROR(H13/G13, "")
A14: Barrington | B14: MA | C14: =SUM(Jul!C14, Aug!C14, Sep!C14) -> 0 | D14: =SUM(Jul!D14, Aug!D14, Sep!D14) -> 0 | E14: =IF(AND(ISNUMBER(C14),ISNUMBER(D14)), C14-D14, "") -> 0 | F14: =IFERROR(E14/D14, "") | G14: =SUM(Jul!G14,Aug!G14,Sep!G14) -> 0 | H14: =SUM(Jul!H14, Aug!H14, Sep!H14) -> 0 | I14: =IFERROR(H14/G14, "")
A15: Bedford - 205 Burlington Rd | B15: MA | C15: =SUM(Jul!C15, Aug!C15, Sep!C15) -> 0 | D15: =SUM(Jul!D15, Aug!D15, Sep!D15) -> 0 | E15: =IF(AND(ISNUMBER(C15),ISNUMBER(D15)), C15-D15, "") -> 0 | F15: =IFERROR(E15/D15, "") | G15: =SUM(Jul!G15,Aug!G15,Sep!G15) -> 0 | H15: =SUM(Jul!H15, Aug!H15, Sep!H15) -> 0 | I15: =IFERROR(H15/G15, "")
A16: Billerica - 6 Cook Street | B16: MA | C16: =SUM(Jul!C16, Aug!C16, Sep!C16) -> 0 | D16: =SUM(Jul!D16, Aug!D16, Sep!D16) -> 0 | E16: =IF(AND(ISNUMBER(C16),ISNUMBER(D16)), C16-D16, "") -> 0 | F16: =IFERROR(E16/D16, "") | G16: =SUM(Jul!G16,Aug!G16,Sep!G16) -> 0 | H16: =SUM(Jul!H16, Aug!H16, Sep!H16) -> 0 | I16: =IFERROR(H16/G16, "")
... A28: Smith Creek | B28: NY | C28: =SUM(Jul!C28, Aug!C28, Sep!C28) -> 0 | D28: =SUM(Jul!D28, Aug!D28, Sep!D28) -> 0 | E28: =IF(AND(ISNUMBER(C28),ISNUMBER(D28)), C28-D28, "") -> 0 | F28: =IFERROR(E28/D28, "") | G28: =SUM(Jul!G28,Aug!G28,Sep!G28) -> 0 | H28: =SUM(Jul!H28, Aug!H28, Sep!H28) -> 0 | I28: =IFERROR(H28/G28, "")
A29: Bradford - 256 Presidential Dr | B29: MA
A30: Charlton – 111 Brookfield Road - Bus Lot | B30: MA
A31: Charlton – 154 Center Depot Road KMARD | B31: MA
A32: Charlton – 142A Brookfield Rd (Mitchell) | B32: MA
A33: Great Barrington – 3 Nolan Drive | B33: MA
A34: Stockbridge – 92 State Line Road Truck Stop | B34: MA

Sheet 4th Qtr
A1: {=portfolio} -> Lodestar | D1: 4th Quarter Actual v. Expected | G1: 4th Quarter Actual v. Forecasted
A2: Total | C2: =SUM(C4:C103) -> 0 | D2: =SUM(D4:D103) -> 0 | E2: =C2-D2 -> 0 | F2: =IFERROR(E2/D2, 0) -> 0 | G2: =SUM(G4:G103) -> 0 | H2: =C2-G2 -> 0 | I2: =IFERROR(H2/G2, 0) -> 0
A3: Site | B3: State | C3: Actual | D3: Expected | E3: Delta | F3: % | G3: Forecasted | H3: Delta | I3: %
A4: {=Sites[Site]} -> Barkhamsted | B4: {=Sites[State]} -> CT | C4: =SUM(Oct!C4, Nov!C4, Dec!C4) -> 0 | D4: =SUM(Oct!D4, Nov!D4, Dec!D4) -> 0 | E4: =IF(AND(ISNUMBER(C4),ISNUMBER(D4)), C4-D4, "") -> 0 | F4: =IFERROR(E4/D4, "") | G4: =SUM(Oct!G4,Nov!G4,Dec!G4) -> 0 | H4: =SUM(Oct!H4, Nov!H4, Dec!H4) -> 0 | I4: =IFERROR(H4/G4, "")
A5: Bunce | B5: CT | C5: =SUM(Oct!C5, Nov!C5, Dec!C5) -> 0 | D5: =SUM(Oct!D5, Nov!D5, Dec!D5) -> 0 | E5: =IF(AND(ISNUMBER(C5),ISNUMBER(D5)), C5-D5, "") -> 0 | F5: =IFERROR(E5/D5, "") | G5: =SUM(Oct!G5,Nov!G5,Dec!G5) -> 0 | H5: =SUM(Oct!H5, Nov!H5, Dec!H5) -> 0 | I5: =IFERROR(H5/G5, "")
A6: Norcap North | B6: CT | C6: =SUM(Oct!C6, Nov!C6, Dec!C6) -> 0 | D6: =SUM(Oct!D6, Nov!D6, Dec!D6) -> 0 | E6: =IF(AND(ISNUMBER(C6),ISNUMBER(D6)), C6-D6, "") -> 0 | F6: =IFERROR(E6/D6, "") | G6: =SUM(Oct!G6,Nov!G6,Dec!G6) -> 0 | H6: =SUM(Oct!H6, Nov!H6, Dec!H6) -> 0 | I6: =IFERROR(H6/G6, "")
A7: Norcap South | B7: CT | C7: =SUM(Oct!C7, Nov!C7, Dec!C7) -> 0 | D7: =SUM(Oct!D7, Nov!D7, Dec!D7) -> 0 | E7: =IF(AND(ISNUMBER(C7),ISNUMBER(D7)), C7-D7, "") -> 0 | F7: =IFERROR(E7/D7, "") | G7: =SUM(Oct!G7,Nov!G7,Dec!G7) -> 0 | H7: =SUM(Oct!H7, Nov!H7, Dec!H7) -> 0 | I7: =IFERROR(H7/G7, "")
A8: Platt Hill | B8: CT | C8: =SUM(Oct!C8, Nov!C8, Dec!C8) -> 0 | D8: =SUM(Oct!D8, Nov!D8, Dec!D8) -> 0 | E8: =IF(AND(ISNUMBER(C8),ISNUMBER(D8)), C8-D8, "") -> 0 | F8: =IFERROR(E8/D8, "") | G8: =SUM(Oct!G8,Nov!G8,Dec!G8) -> 0 | H8: =SUM(Oct!H8, Nov!H8, Dec!H8) -> 0 | I8: =IFERROR(H8/G8, "")
A9: Powder Hill | B9: CT | C9: =SUM(Oct!C9, Nov!C9, Dec!C9) -> 0 | D9: =SUM(Oct!D9, Nov!D9, Dec!D9) -> 0 | E9: =IF(AND(ISNUMBER(C9),ISNUMBER(D9)), C9-D9, "") -> 0 | F9: =IFERROR(E9/D9, "") | G9: =SUM(Oct!G9,Nov!G9,Dec!G9) -> 0 | H9: =SUM(Oct!H9, Nov!H9, Dec!H9) -> 0 | I9: =IFERROR(H9/G9, "")
A10: Sand Road | B10: CT | C10: =SUM(Oct!C10, Nov!C10, Dec!C10) -> 0 | D10: =SUM(Oct!D10, Nov!D10, Dec!D10) -> 0 | E10: =IF(AND(ISNUMBER(C10),ISNUMBER(D10)), C10-D10, "") -> 0 | F10: =IFERROR(E10/D10, "") | G10: =SUM(Oct!G10,Nov!G10,Dec!G10) -> 0 | H10: =SUM(Oct!H10, Nov!H10, Dec!H10) -> 0 | I10: =IFERROR(H10/G10, "")
A11: Suffield | B11: CT | C11: =SUM(Oct!C11, Nov!C11, Dec!C11) -> 0 | D11: =SUM(Oct!D11, Nov!D11, Dec!D11) -> 0 | E11: =IF(AND(ISNUMBER(C11),ISNUMBER(D11)), C11-D11, "") -> 0 | F11: =IFERROR(E11/D11, "") | G11: =SUM(Oct!G11,Nov!G11,Dec!G11) -> 0 | H11: =SUM(Oct!H11, Nov!H11, Dec!H11) -> 0 | I11: =IFERROR(H11/G11, "")
A12: Ashby-Duffy | B12: MA | C12: =SUM(Oct!C12, Nov!C12, Dec!C12) -> 0 | D12: =SUM(Oct!D12, Nov!D12, Dec!D12) -> 0 | E12: =IF(AND(ISNUMBER(C12),ISNUMBER(D12)), C12-D12, "") -> 0 | F12: =IFERROR(E12/D12, "") | G12: =SUM(Oct!G12,Nov!G12,Dec!G12) -> 0 | H12: =SUM(Oct!H12, Nov!H12, Dec!H12) -> 0 | I12: =IFERROR(H12/G12, "")
A13: Ashland | B13: MA | C13: =SUM(Oct!C13, Nov!C13, Dec!C13) -> 0 | D13: =SUM(Oct!D13, Nov!D13, Dec!D13) -> 0 | E13: =IF(AND(ISNUMBER(C13),ISNUMBER(D13)), C13-D13, "") -> 0 | F13: =IFERROR(E13/D13, "") | G13: =SUM(Oct!G13,Nov!G13,Dec!G13) -> 0 | H13: =SUM(Oct!H13, Nov!H13, Dec!H13) -> 0 | I13: =IFERROR(H13/G13, "")
A14: Barrington | B14: MA | C14: =SUM(Oct!C14, Nov!C14, Dec!C14) -> 0 | D14: =SUM(Oct!D14, Nov!D14, Dec!D14) -> 0 | E14: =IF(AND(ISNUMBER(C14),ISNUMBER(D14)), C14-D14, "") -> 0 | F14: =IFERROR(E14/D14, "") | G14: =SUM(Oct!G14,Nov!G14,Dec!G14) -> 0 | H14: =SUM(Oct!H14, Nov!H14, Dec!H14) -> 0 | I14: =IFERROR(H14/G14, "")
A15: Bedford - 205 Burlington Rd | B15: MA | C15: =SUM(Oct!C15, Nov!C15, Dec!C15) -> 0 | D15: =SUM(Oct!D15, Nov!D15, Dec!D15) -> 0 | E15: =IF(AND(ISNUMBER(C15),ISNUMBER(D15)), C15-D15, "") -> 0 | F15: =IFERROR(E15/D15, "") | G15: =SUM(Oct!G15,Nov!G15,Dec!G15) -> 0 | H15: =SUM(Oct!H15, Nov!H15, Dec!H15) -> 0 | I15: =IFERROR(H15/G15, "")
A16: Billerica - 6 Cook Street | B16: MA | C16: =SUM(Oct!C16, Nov!C16, Dec!C16) -> 0 | D16: =SUM(Oct!D16, Nov!D16, Dec!D16) -> 0 | E16: =IF(AND(ISNUMBER(C16),ISNUMBER(D16)), C16-D16, "") -> 0 | F16: =IFERROR(E16/D16, "") | G16: =SUM(Oct!G16,Nov!G16,Dec!G16) -> 0 | H16: =SUM(Oct!H16, Nov!H16, Dec!H16) -> 0 | I16: =IFERROR(H16/G16, "")
... A28: Smith Creek | B28: NY | C28: =SUM(Oct!C28, Nov!C28, Dec!C28) -> 0 | D28: =SUM(Oct!D28, Nov!D28, Dec!D28) -> 0 | E28: =IF(AND(ISNUMBER(C28),ISNUMBER(D28)), C28-D28, "") -> 0 | F28: =IFERROR(E28/D28, "") | G28: =SUM(Oct!G28,Nov!G28,Dec!G28) -> 0 | H28: =SUM(Oct!H28, Nov!H28, Dec!H28) -> 0 | I28: =IFERROR(H28/G28, "")
A29: Bradford - 256 Presidential Dr | B29: MA
A30: Charlton – 111 Brookfield Road - Bus Lot | B30: MA
A31: Charlton – 154 Center Depot Road KMARD | B31: MA
A32: Charlton – 142A Brookfield Rd (Mitchell) | B32: MA
A33: Great Barrington – 3 Nolan Drive | B33: MA
A34: Stockbridge – 92 State Line Road Truck Stop | B34: MA

Sheet Jan
A1: {=portfolio} -> Lodestar | D1: March Actual v. Expected | G1: March Actual v. Forecasted
A2: Total | C2: =SUM(C4:C102) -> 3838099.4 | D2: =SUM(D4:D102) -> 5382433.9 | E2: =C2-D2 -> -1544334.5 | F2: =IFERROR(E2/D2, 0) -> -0.28692122 | G2: =SUM(G4:G102) -> 4641331.9 | H2: =C2-G2 -> -803232.52 | I2: =IFERROR(H2/G2, 0) -> -0.17306078 | J2: =IF(AND(TODAY()>DATE(2024, 1, 1), COUNTA(Sites[Site])<>(COUNT(C:C)-1)), "Some sites are missing actual data; if new sites were added, make sure they are aligned correctly (including prior months!)", "")
A3: Site | B3: State | C3: Actual | D3: Expected | E3: Delta | F3: % | G3: Forecasted | H3: Delta | I3: % | J3: Notes | K3: Service Requests
A4: {=Sites[Site]} -> Barkhamsted | B4: {=Sites[State]} -> CT | C4: 42488 | D4: 130906.1 | E4: =IF(AND(ISNUMBER(C4),ISNUMBER(D4)), C4-D4, "") -> -88418.1 | F4: =IFERROR(E4/D4, "") -> -0.67543147 | G4: 95618.24 | H4: =IF(AND(ISNUMBER(C4),ISNUMBER(G4)), C4-G4, "") -> -53130.24 | I4: =IFERROR(H4/G4, "") -> -0.55564963 | J4: 1. Combiner Boxes 1.2 (DCP 1), 1.3 (DCP 7), 1.5 (DCP 14), 1.7 (DCP 10), 1.10 (DCP 4), 1.11 (DCP 11), and 1.15 (DCP 12) have been offline since 12/22/24. On 01/02/25, the technician discovered blown glass fuses. As per Shoals' instructions, parts are needed to bring them back online, and they have remained offline throughout the month. 2. Combiner 1.14 (DCP-3) is showing constant value of 312Amps from 08/30 due to a faulty CT. 3. All inverters tripped on and off on 01/09 and 01/10, with Inverter 1.5 tripped offline at 10:30 AM on 01/09. On 01/11, the PE technician restored only Inverter 1.1, while the others remained offline. On 01/13, the PE technician worked on all inverters, brought Inverter 1.5 back online at 16:30. The remaining inverters were restored on 01/14/25. | K4: 1.SR095215 2.SR089788 3.SR095444
A5: Bunce | B5: CT | C5: 147884 | D5: 196766.8 | E5: =IF(AND(ISNUMBER(C5),ISNUMBER(D5)), C5-D5, "") -> -48882.8 | F5: =IFERROR(E5/D5, "") -> -0.24843012 | G5: N/A | H5: =IF(AND(ISNUMBER(C5),ISNUMBER(G5)), C5-G5, "") | I5: =IFERROR(H5/G5, "") | J5: 1. Inverters 10,11 and 13 are started late for production at 11:45AM on 01/17 due to insulation fault. 2. Low generation due to rain/snow. | K5: 1. SR095646
A6: Norcap North | B6: CT | C6: 162639 | D6: 288186.5 | E6: =IF(AND(ISNUMBER(C6),ISNUMBER(D6)), C6-D6, "") -> -125547.5 | F6: =IFERROR(E6/D6, "") -> -0.43564671 | G6: 178945.5 | H6: =IF(AND(ISNUMBER(C6),ISNUMBER(G6)), C6-G6, "") -> -16306.5 | I6: =IFERROR(H6/G6, "") -> -0.09112551 | J6: 1. Inverter 12 came back online at 13:30 on 01/02. The technician investigated the issue and cleared the fault. 2. Inverters 14 to 17 tripped offline at 11:45AM on 01/26. The technician replaced the shunt trip for HP1 with HP4. The inverters came back online at 11:15AM on 01/27. 3. Inverter 25 has been intermittently offline for the whole month due to a bus differential fault. Solectria has issued an RMA for the inverter. 4. Inverter 30 started production late at 13:15 on 01/27. The technician resolved the issue with Solectria. Solectria will issue an RMA if the inverter trips again. | K6: 1. SR095170 2. SR095990 3. SR096190, SR094843 4. SR096007
A7: Norcap South | B7: CT | C7: 184293.5 | D7: 319084.7 | E7: =IF(AND(ISNUMBER(C7),ISNUMBER(D7)), C7-D7, "") -> -134791.2 | F7: =IFERROR(E7/D7, "") -> -0.42243078 | G7: 155781 | H7: =IF(AND(ISNUMBER(C7),ISNUMBER(G7)), C7-G7, "") -> 28512.5 | I7: =IFERROR(H7/G7, "") -> 0.18302938 | J7: 1.Inverter 36 offline on 01/01 due to insulation resistance fault and self resolve on 01/02 2. Low generation due to rain/snow. | K7: 1.SR095132
A8: Platt Hill | B8: CT | C8: 115129.75 | D8: 228108.9 | E8: =IF(AND(ISNUMBER(C8),ISNUMBER(D8)), C8-D8, "") -> -112979.15 | F8: =IFERROR(E8/D8, "") -> -0.49528605 | G8: 231339.2 | H8: =IF(AND(ISNUMBER(C8),ISNUMBER(G8)), C8-G8, "") -> -116209.45 | I8: =IFERROR(H8/G8, "") -> -0.50233361 | J8: 1. The site tripped offline at 10:45AM on 01/03 and came back online at 07:00 AM on 01/06. The technician found that the surge protector breaker had tripped and reset it. 2. The site tripped offline at 05:45AM on 01/16 while the technician was onsite to remove the failed breaker. The site came back online at 08:30AM on 01/17 after the breaker was replaced. 3.Inverter 1 has started late for the production at 12:00 on 01/17 but two strings are kept offline for safety due to tree has felt on array | K8: 1. SR095275 2. SR095529 3.SR095652
A9: Powder Hill | B9: CT | C9: 157653 | D9: 225761.3 | E9: =IF(AND(ISNUMBER(C9),ISNUMBER(D9)), C9-D9, "") -> -68108.3 | F9: =IFERROR(E9/D9, "") -> -0.3016828 | G9: 155676 | H9: =IF(AND(ISNUMBER(C9),ISNUMBER(G9)), C9-G9, "") -> 1977 | I9: =IFERROR(H9/G9, "") -> 0.012699453 | J9: 1. Inverter 7 started production late and later self-resolved at 09:15 AM on 01/13 due to a self-check startup failure. It failed to start again on 01/17 but was brought back online via a remote reset at 10:45 AM the same day. However, it tripped offline again at 11:15 AM on 01/27. The technician investigated the issue, and Inverter 7 was back online at 07:00 AM and 3 CT's were RMA'd on 01/28. 2. Inverter 8 dropped offline at 11:45 AM and was producing only 5 kW consistently. After a remote reset, the inverter came back online at 13:45 on 01/28. 3. Low generation due to rain/snow. | K9: 1. SR095513 2. SR095081
A10: Sand Road | B10: CT | C10: 151595 | D10: 198096.8 | E10: =IF(AND(ISNUMBER(C10),ISNUMBER(D10)), C10-D10, "") -> -46501.8 | F10: =IFERROR(E10/D10, "") -> -0.23474281 | G10: 145302 | H10: =IF(AND(ISNUMBER(C10),ISNUMBER(G10)), C10-G10, "") -> 6293 | I10: =IFERROR(H10/G10, "") -> 0.043309796 | J10: 1. Site offline at 15:30 on 01/18. Technician found the Main AC Breaker tripped and the SEL-751 in the trip position with an "AC Loss" fault. Reset both the SEL and Main AC Breaker. The site is back online at 12:45 on 01/19. 2. Low generation due to rain/snow. | K10: 1. SR095701
A11: Suffield | B11: CT | C11: 177443 | D11: 223979.4 | E11: =IF(AND(ISNUMBER(C11),ISNUMBER(D11)), C11-D11, "") -> -46536.4 | F11: =IFERROR(E11/D11, "") -> -0.20777089 | G11: 190993.6 | H11: =IF(AND(ISNUMBER(C11),ISNUMBER(G11)), C11-G11, "") -> -13550.6 | I11: =IFERROR(H11/G11, "") -> -0.070947927 | J11: 1. Low generation due to rain/snow.
A12: Ashby-Duffy | B12: MA | C12: 153090 | D12: 301950.1 | E12: =IF(AND(ISNUMBER(C12),ISNUMBER(D12)), C12-D12, "") -> -148860.1 | F12: =IFERROR(E12/D12, "") -> -0.4929957 | G12: 157476.5 | H12: =IF(AND(ISNUMBER(C12),ISNUMBER(G12)), C12-G12, "") -> -4386.5 | I12: =IFERROR(H12/G12, "") -> -0.02785495 | J12: 1. Inverter 2 remains offline for the whole month and will need to wait until the ground is unfrozen. 2. Inverter 55 tripped offline at 11:15 AM on 01/03 due to an electrical arc fault. After a reset, the inverter came back online at 10:30 AM on 01/06. 3. Inverter 54 tripped offline at 12:45 on 01/03 due to a high residual current. The technician found a field-made jumper connection with thermal damage. The MC M/F connectors were repaired and replaced. The inverter came back online at 10:30 on 01/06. 4.Inverter 39 string 5 blown a fuse and later technician replaced fuses on 01/15 5. Low generation due to rain/snow. | K12: 1. SR093777 2. SR095277 3. SR095288 4.SR094302
A13: Ashland | B13: MA | C13: 125168.5 | D13: 243462.5 | E13: =IF(AND(ISNUMBER(C13),ISNUMBER(D13)), C13-D13, "") -> -118294 | F13: =IFERROR(E13/D13, "") -> -0.48588181 | G13: 133620.2 | H13: =IF(AND(ISNUMBER(C13),ISNUMBER(G13)), C13-G13, "") -> -8451.7 | I13: =IFERROR(H13/G13, "") -> -0.063251664 | J13: 1. Inverter 16 was offline since 11/13 due to Arc Protection and being RMA'd. 2. Inverter 30 tripped offline at 13:45 on 01/12 due to an insulation fault and later self-resolved, inverter back online at 14:15. 3.Inverter 66 tripped offline at 11:00 AM on 01/06 and self-resolved, inverter back online at 07:00 AM on 01/08. 4. Inverter 12 was offline intermittently whole month and being RMA'd. 5. Inverter 67 was being in RMA'd. 6. Inverter 57 was being in RMA'd. 7.Inverter 66 is bearly producing from 01/30 8. Low generation due to rain/snow. | K13: 1. SR095816 2. SR095504 3. SR094685 4. SR093117 5. SR088450 6. SR091962 7.SR096271
A14: Barrington | B14: MA | C14: 21905.5 | D14: 31381.54 | E14: =IF(AND(ISNUMBER(C14),ISNUMBER(D14)), C14-D14, "") -> -9476.04 | F14: =IFERROR(E14/D14, "") -> -0.30196224 | G14: 35820 | H14: =IF(AND(ISNUMBER(C14),ISNUMBER(G14)), C14-G14, "") -> -13914.5 | I14: =IFERROR(H14/G14, "") -> -0.38845617 | J14: 1. Low generation due to weather/snow.
A15: Bedford - 205 Burlington Rd | B15: MA | C15: 12393 | D15: N/A | E15: =IF(AND(ISNUMBER(C15),ISNUMBER(D15)), C15-D15, "") | F15: =IFERROR(E15/D15, "") | G15: N/A | H15: =IF(AND(ISNUMBER(C15),ISNUMBER(G15)), C15-G15, "") | I15: =IFERROR(H15/G15, "")
A16: Billerica - 6 Cook Street | B16: MA | C16: 9769 | D16: N/A | E16: =IF(AND(ISNUMBER(C16),ISNUMBER(D16)), C16-D16, "") | F16: =IFERROR(E16/D16, "") | G16: N/A | H16: =IF(AND(ISNUMBER(C16),ISNUMBER(G16)), C16-G16, "") | I16: =IFERROR(H16/G16, "")
A17: Billerica - 780 Boston Road | B17: MA | C17: 10676 | D17: N/A | E17: =IF(AND(ISNUMBER(C17),ISNUMBER(D17)), C17-D17, "") | F17: =IFERROR(E17/D17, "") | G17: N/A | H17: =IF(AND(ISNUMBER(C17),ISNUMBER(G17)), C17-G17, "") | I17: =IFERROR(H17/G17, "")
A18: Cheshire | B18: MA | C18: 20350.206 | D18: 43079.92 | E18: =IF(AND(ISNUMBER(C18),ISNUMBER(D18)), C18-D18, "") -> -22729.714 | F18: =IFERROR(E18/D18, "") -> -0.52761736 | G18: 24192.56 | H18: =IF(AND(ISNUMBER(C18),ISNUMBER(G18)), C18-G18, "") -> -3842.3536 | I18: =IFERROR(H18/G18, "") -> -0.15882377 | J18: 1. Low generation due to rain/snow.
A19: Lilly Lane | B19: MA | C19: 66477 | D19: 93441.89 | E19: =IF(AND(ISNUMBER(C19),ISNUMBER(D19)), C19-D19, "") -> -26964.89 | F19: =IFERROR(E19/D19, "") -> -0.28857389 | G19: 112568.7 | H19: =IF(AND(ISNUMBER(C19),ISNUMBER(G19)), C19-G19, "") -> -46091.7 | I19: =IFERROR(H19/G19, "") -> -0.40945396 | J19: 1. Inverter 61 has been intermittently offline throughout the month and has been RMA'd. 2. The site tripped offline at 18:00 on 01/02. The technician found that the switchgear was open and the SEL-351A had tripped. He reset the SEL and closed the switchgear. The site came back online at 09:00 AM on 01/03. | K19: 1. SR095846, SR095210 2. SR095259
A20: Monument Valley | B20: MA | C20: 92298 | D20: 36912.89 | E20: =IF(AND(ISNUMBER(C20),ISNUMBER(D20)), C20-D20, "") -> 55385.11 | F20: =IFERROR(E20/D20, "") -> 1.5004274 | G20: N/A | H20: =IF(AND(ISNUMBER(C20),ISNUMBER(G20)), C20-G20, "") | I20: =IFERROR(H20/G20, "") | J20: 1. Site production dropped at 15:15 on 01/28 as Sungrow technicians were onsite working on BESS. They continued work on 01/29, and production returned to normal at 15:30 on 01/29. 2. Expected generation values are lower than actual values. AlsoEnergy stated that expected values are calculated based on inverter data and weather conditions and recommended an onsite visit. However, due to communication issues with the inverters, the expected values remain low. | K20: 1. SR092970 2. SR087370
A21: Nationwide | B21: MA | C21: 149646 | D21: 334678.8 | E21: =IF(AND(ISNUMBER(C21),ISNUMBER(D21)), C21-D21, "") -> -185032.8 | F21: =IFERROR(E21/D21, "") -> -0.55286681 | G21: 297479.6 | H21: =IF(AND(ISNUMBER(C21),ISNUMBER(G21)), C21-G21, "") -> -147833.6 | I21: =IFERROR(H21/G21, "") -> -0.49695374 | J21: 1. Inverter 16 tripped offline at 08:45AM on 01/19, inverter was self-resolved at 10:15AM on 01/21. 2. Low generation due to rain/snow. | K21: 1. SR095712
A22: Pulpit Hill | B22: MA | C22: 316117.75 | D22: 470954.2 | E22: =IF(AND(ISNUMBER(C22),ISNUMBER(D22)), C22-D22, "") -> -154836.45 | F22: =IFERROR(E22/D22, "") -> -0.32877178 | G22: 355177.1 | H22: =IF(AND(ISNUMBER(C22),ISNUMBER(G22)), C22-G22, "") -> -39059.35 | I22: =IFERROR(H22/G22, "") -> -0.10997148 | J22: 1. Inverter 83 had a string 8 down since 11/27. It will be investigated during the next onsite visit. 2. Inverter 49 did not start production on 01/26. The technician investigated and found that the inverter was online but not communicating due to a Fault Protect 0130/090. Solectria will issue an RMA for the power head. The inverter has been tagged out and de-energized. 3. Inverter 42 did not start production on 01/29 reporting Bus Differential Fault. Technician investigated and found that the inverter was online but not communicating. Solectria processed an RMA. 4. Low generation due to rain/snow. | K22: 1. SR093591 2. SR095984 3. SR096108
A23: Sandwich | B23: MA | C23: 284645 | D23: N/A | E23: =IF(AND(ISNUMBER(C23),ISNUMBER(D23)), C23-D23, "") | F23: =IFERROR(E23/D23, "") | G23: 295751 | H23: =IF(AND(ISNUMBER(C23),ISNUMBER(G23)), C23-G23, "") -> -11106 | I23: =IFERROR(H23/G23, "") -> -0.03755186 | J23: 1. PAD 4 is discharging at 15kW and CES performed calibration on 01/02. 2. The site was taken offline from 8:45 to 15:15 on 01/17 for SIM replacement. Afterward, the technician requested tech support to check production reporting issues on meters 3 and 4. AlsoEnergy confirmed PowerTrack settings were consistent across HEILA BESS Controllers 2, 3, and 4, indicating the issue is likely with the controllers. HEILA will now inspect remotely using the new SIM. | K23: 1.SR095262 2.SR095545
A24: Sturbridge Barn | B24: MA | C24: 75410.5 | D24: 125791.1 | E24: =IF(AND(ISNUMBER(C24),ISNUMBER(D24)), C24-D24, "") -> -50380.6 | F24: =IFERROR(E24/D24, "") -> -0.40051005 | G24: 110058.4 | H24: =IF(AND(ISNUMBER(C24),ISNUMBER(G24)), C24-G24, "") -> -34647.9 | I24: =IFERROR(H24/G24, "") -> -0.31481377 | J24: 1. Site tripped offline and SEL Relay was opened on 01/02 at 18:00 later technician re-energized the relay at 08:15am on 01/03 2.Inverter 32 tripped offline at 13:30 on 01/25 due to "ARC Protection", later technician found and replaced rusty homerun MC connectors, and the inverter came back online at 10:30 on 01/27. 3. Low generation due to rain/snow. | K24: 1.SR095261 2.SR095978
A25: Sturbridge Garage | B25: MA | C25: 36683.75 | D25: 59181.43 | E25: =IF(AND(ISNUMBER(C25),ISNUMBER(D25)), C25-D25, "") -> -22497.68 | F25: =IFERROR(E25/D25, "") -> -0.38014762 | G25: 55606.07 | H25: =IF(AND(ISNUMBER(C25),ISNUMBER(G25)), C25-G25, "") -> -18922.32 | I25: =IFERROR(H25/G25, "") -> -0.34029235 | J25: 1.Inverter 3 tripped offline at 12PM on 01/02 due to Bus(sum) over voltage fault and back online on 01/04. On 01/23 Technicians checked in and replaced RMA'd Inverter with new Inverter. Inverter was again offline from 01/24 due to stuck in standby mode and back online at 12PM on 01/27. 2.Site tripped offline at 17:48 and on battery mode, later auto-reclosed at 18:10 on 01/02. 3.Inverter 8 tripped offline at 10:30AM on 01/12 due to insulation resistance low fault and back online at 11:30AM on 01/13. 4. Low generation due to rain/snow. | K25: 1.SR093378, SR096015 2.SR095260 3.SR095505
A26: Halsey Valley | B26: NY | C26: 352603 | D26: 438815.8 | E26: =IF(AND(ISNUMBER(C26),ISNUMBER(D26)), C26-D26, "") -> -86212.8 | F26: =IFERROR(E26/D26, "") -> -0.19646695 | G26: 384000 | H26: =IF(AND(ISNUMBER(C26),ISNUMBER(G26)), C26-G26, "") -> -31397 | I26: =IFERROR(H26/G26, "") -> -0.081763021 | J26: 1.Inverter 13 was offline from 12/20/24 due to insulation resistance low fault and after technician powered on, inverter back online at 9:30AM on 01/16/25. 2.Inverter 18, string 4 in CB18, was isolated due to poor voltage and a disconnected module caused by severe dirt and ice buildup in the MC4 connections. After inspection on 01/16, the technician replaced both MC4 connectors, reconnected the circuit, and powered on the inverter. It is now performing in line with its peers. 3. Low generation due to rain/snow. | K26: 1.SR094997 2.SR094509
A27: Hunt Creek | B27: NY | C27: 155889 | D27: 294214.5 | E27: =IF(AND(ISNUMBER(C27),ISNUMBER(D27)), C27-D27, "") -> -138325.5 | F27: =IFERROR(E27/D27, "") -> -0.47015188 | G27: 228700 | H27: =IF(AND(ISNUMBER(C27),ISNUMBER(G27)), C27-G27, "") -> -72811 | I27: =IFERROR(H27/G27, "") -> -0.31836904 | J27: 1. Inverter 18 has multiple tripping events from 12/06/24 due to Floating capacitor voltage is high. 2.Site tripped offline at 07:00AM and after technician checked-in, site back online at 11:45 on 01/06. 3.Site tripped offline at 06:30AM and after technician closed the SEL Relay, site back online at 11:15 on 01/22. Inverters 2,3,4,5,6,8,10,14,15,16,17,19,22,25,27,28 and 29 are tripped offline at 09:15AM on 01/21 due to Grid Voltage unbalance and back online at 11:15AM on 01/22. 4.Inverters 5,23 and 27 tripped offline at 13:30 on 01/24 due to Grid voltage unbalance and back online on 01/25. 5. Low generation due to rain/snow. | K27: 1.SR094254 2.SR093451 3.SR095801 4.SR095965
A28: Smith Creek | B28: NY | C28: 264193 | D28: 337115.3 | E28: =IF(AND(ISNUMBER(C28),ISNUMBER(D28)), C28-D28, "") -> -72922.3 | F28: =IFERROR(E28/D28, "") -> -0.21631264 | G28: 398598.4 | H28: =IF(AND(ISNUMBER(C28),ISNUMBER(G28)), C28-G28, "") -> -134405.4 | I28: =IFERROR(H28/G28, "") -> -0.33719503 | J28: 1.Site was taken offline from 10:45 to 16:45 on 01/06 due to technincian checked-in for hot spot remediation. 2. Inverters 1,3,6,12 and 27 tripped offline at 9:15AM on 01/21 due to Grid voltage unbalance and back online at 14:00 on 01/22. Site tripped offline at 06:30AM and after technician closed the SEL Relay, site back online at 14:00 on 01/22. | K28: 1.SR095332 2.SR095805
A29: Bradford - 256 Presidential Dr | B29: MA | C29: 306816.5 | D29: 339000 | E29: =IF(AND(ISNUMBER(C29),ISNUMBER(D29)), C29-D29, "") -> -32183.5 | F29: =IFERROR(E29/D29, "") -> -0.094936578 | G29: 401656.5 | H29: =IF(AND(ISNUMBER(C29),ISNUMBER(G29)), C29-G29, "") -> -94840 | I29: =IFERROR(H29/G29, "") -> -0.23612216 | J29: 1.Inverter 128 was not communicating since 12/07/24. Communications card has been RMA'd and will be replaced during a combined dispatch. 2. Low generation due to rain/snow. | K29: 1.SR096051
A30: Charlton – 111 Brookfield Road - Bus Lot | B30: MA | C30: 36616 | D30: 27710.1 | E30: =IF(AND(ISNUMBER(C30),ISNUMBER(D30)), C30-D30, "") -> 8905.9004 | F30: =IFERROR(E30/D30, "") -> 0.32139547 | G30: 56965.72 | H30: =IF(AND(ISNUMBER(C30),ISNUMBER(G30)), C30-G30, "") -> -20349.72 | I30: =IFERROR(H30/G30, "") -> -0.35722747 | J30: 1. Site stopped communicating at 1:25AM on 01/29 and on 03/31 technician powercycled the DAS comms were restored. 2. Low generation due to rain/snow. | K30: 1. SR096103
A31: Charlton – 154 Center Depot Road KMARD | B31: MA | C31: 31310 | D31: 53271.495 | E31: =IF(AND(ISNUMBER(C31),ISNUMBER(D31)), C31-D31, "") -> -21961.495 | F31: =IFERROR(E31/D31, "") -> -0.41225603 | G31: 54358.81 | H31: =IF(AND(ISNUMBER(C31),ISNUMBER(G31)), C31-G31, "") -> -23048.81 | I31: =IFERROR(H31/G31, "") -> -0.42401241 | J31: 1. Low generation due to weather/snow.
A32: Charlton – 142A Brookfield Rd (Mitchell) | B32: MA | C32: 35707.436 | D32: 52376.025 | E32: =IF(AND(ISNUMBER(C32),ISNUMBER(D32)), C32-D32, "") -> -16668.589 | F32: =IFERROR(E32/D32, "") -> -0.31824846 | G32: 57257.31 | H32: =IF(AND(ISNUMBER(C32),ISNUMBER(G32)), C32-G32, "") -> -21549.874 | I32: =IFERROR(H32/G32, "") -> -0.37636896 | J32: 1. Site lost communication on 01/10 and comms were back on 01/16 after technician powercycled DAS. 2. Low generation due to rain/snow. | K32: 1. SR095421
A33: Great Barrington – 3 Nolan Drive | B33: MA | C33: 55040 | D33: 97230.931 | E33: =IF(AND(ISNUMBER(C33),ISNUMBER(D33)), C33-D33, "") -> -42190.931 | F33: =IFERROR(E33/D33, "") -> -0.43392499 | G33: 112112.88 | H33: =IF(AND(ISNUMBER(C33),ISNUMBER(G33)), C33-G33, "") -> -57072.88 | I33: =IFERROR(H33/G33, "") -> -0.50906622 | J33: 1. Low generation due to weather/snow.
A34: Stockbridge – 92 State Line Road Truck Stop | B34: MA | C34: 86169 | D34: 190974.85 | E34: =IF(AND(ISNUMBER(C34),ISNUMBER(D34)), C34-D34, "") -> -104805.85 | F34: =IFERROR(E34/D34, "") -> -0.54879398 | G34: 216276.62 | H34: =IF(AND(ISNUMBER(C34),ISNUMBER(G34)), C34-G34, "") -> -130107.62 | I34: =IFERROR(H34/G34, "") -> -0.60157968 | J34: 1. Low generation due to weather/snow.
E35: =IF(AND(ISNUMBER(C35),ISNUMBER(D35)), C35-D35, "")

Sheet Feb
A1: {=portfolio} -> Lodestar | D1: February Actual v. Expected | G1: February Actual v. Forecasted
A2: Total | C2: =SUM(C4:C103) -> 4097242.2 | D2: =SUM(D4:D103) -> 5706989.2 | E2: =C2-D2 -> -1609746.9 | F2: =IFERROR(E2/D2, 0) -> -0.28206588 | G2: =SUM(G4:G103) -> 5844278 | H2: =C2-G2 -> -1747035.8 | I2: =IFERROR(H2/G2, 0) -> -0.29893099 | J2: =IF(AND(TODAY()>DATE(2024, 2, 1), COUNTA(Sites[Site])<>(COUNT(C:C)-1)), "Some sites are missing actual data; if new sites were added, make sure they are aligned correctly (including prior months!)", "")
A3: Site | B3: State | C3: Actual | D3: Expected | E3: Delta | F3: % | G3: Forecasted | H3: Delta | I3: % | J3: Notes | K3: Service Requests
A4: {=Sites[Site]} -> Barkhamsted | B4: {=Sites[State]} -> CT | C4: 65600 | D4: 127981.8 | E4: =IF(AND(ISNUMBER(C4),ISNUMBER(D4)), C4-D4, "") -> -62381.8 | F4: =IFERROR(E4/D4, "") -> -0.48742712 | G4: 118820.5 | H4: =IF(AND(ISNUMBER(C4),ISNUMBER(G4)), C4-G4, "") -> -53220.5 | I4: =IFERROR(H4/G4, "") -> -0.44790672 | J4: 1. Combiner Boxes 1.2 (DCP 1), 1.3 (DCP 7), 1.5 (DCP 14), 1.7 (DCP 10), 1.10 (DCP 4), 1.11 (DCP 11), and 1.15 (DCP 12) have been offline since 12/22. On 02/10, technician refitted them with a new contactor. Except for 1.2 (DCP 1), all combiner boxes came back online at 12:15 PM. 2. Low generation due to weather/snow. | K4: 1.SR095215
A5: Bunce | B5: CT | C5: 152247 | D5: 205046.7 | E5: =IF(AND(ISNUMBER(C5),ISNUMBER(D5)), C5-D5, "") -> -52799.7 | F5: =IFERROR(E5/D5, "") -> -0.25750085 | G5: N/A | H5: =IF(AND(ISNUMBER(C5),ISNUMBER(G5)), C5-G5, "") | I5: =IFERROR(H5/G5, "") | J5: 1.Site was taken offline from 13:00 to 14:45 on 02/22 due to planned outage. 2. The site is experiencing multiple trips due to voltage fluctuations. Whenever the meter voltage drops below 610V, the site trips, and when the voltage returns to the nominal value, the site comes back online. This phenomenon has been occurring since Eversource performed maintenance on 02/22. Site production returned to normal on 02/27 after Eversource was dispatched on 02/26. | K5: 1.SR097327 2.SR097832 | L5: SR097832
A6: Norcap North | B6: CT | C6: 196301.5 | D6: 283245.5 | E6: =IF(AND(ISNUMBER(C6),ISNUMBER(D6)), C6-D6, "") -> -86944 | F6: =IFERROR(E6/D6, "") -> -0.30695633 | G6: 212347.1 | H6: =IF(AND(ISNUMBER(C6),ISNUMBER(G6)), C6-G6, "") -> -16045.6 | I6: =IFERROR(H6/G6, "") -> -0.075563076 | J6: 1.Inverter 25 experienced multiple offline incidents throughout the month due to a bus differential high fault and was subsequently RMA'd by Solectria. On 02/26, technicians replaced the RMA'd inverter with a new unit and inverter started producing in line with its peers. 2. Inverter 1 was offline on 02/16 and 02/17 due to a bus differential high fault and came back online on 02/18. It went offline again from 02/20 to 02/23 and on 02/27 and 02/28 due to the same fault. Solectria initiated the RMA process for the inverter on 02/21. 3. Low generation due to rain/snow. | K6: 1.SR096190 2.SR097171, SR097549 & SR097792 | L6: SR097171 | M6: SR097549 | N6: SR097792
A7: Norcap South | B7: CT | C7: 217072.5 | D7: 306757.9 | E7: =IF(AND(ISNUMBER(C7),ISNUMBER(D7)), C7-D7, "") -> -89685.4 | F7: =IFERROR(E7/D7, "") -> -0.29236541 | G7: 202120.5 | H7: =IF(AND(ISNUMBER(C7),ISNUMBER(G7)), C7-G7, "") -> 14952 | I7: =IFERROR(H7/G7, "") -> 0.073975673 | J7: 1. Inverter 36 started late for production on 02/01, 02/04, 02/07 and was offline on 02/13 & 02/27 due to Insulation Resistance Low fault. Self-resolved on 02/28. 2. Low generation due to rain/snow. | K7: 1.SR096465
A8: Platt Hill | B8: CT | C8: 142609.25 | D8: 252288 | E8: =IF(AND(ISNUMBER(C8),ISNUMBER(D8)), C8-D8, "") -> -109678.75 | F8: =IFERROR(E8/D8, "") -> -0.43473627 | G8: 273596.9 | H8: =IF(AND(ISNUMBER(C8),ISNUMBER(G8)), C8-G8, "") -> -130987.65 | I8: =IFERROR(H8/G8, "") -> -0.47876144 | J8: 1.Site was tripped offline at 13:30 on 02/04 due to main breaker trip and back online at 10:30 on 02/05 after tehnician closed the breaker. Again site tripped offline at 20:00 on 02/16 and after technician reset main breaker site back online at 11:30 on 02/18. 2. Low generation due to rain/snow. | K8: 1.SR096295
A9: Powder Hill | B9: CT | C9: 173406 | D9: 236232.6 | E9: =IF(AND(ISNUMBER(C9),ISNUMBER(D9)), C9-D9, "") -> -62826.6 | F9: =IFERROR(E9/D9, "") -> -0.26595229 | G9: 178140 | H9: =IF(AND(ISNUMBER(C9),ISNUMBER(G9)), C9-G9, "") -> -4734 | I9: =IFERROR(H9/G9, "") -> -0.026574604 | J9: 1.Site was tripped offline on battery mode from 12:45 to 13:30 on 02/07. 2.Three CT's of inverter 7 were RMA'd from 01/28. Received parts and need to dispatch. | K9: 1.SR096471 2.SR095513 | L9: SR095513
A10: Sand Road | B10: CT | C10: 157864 | D10: 194906.2 | E10: =IF(AND(ISNUMBER(C10),ISNUMBER(D10)), C10-D10, "") -> -37042.2 | F10: =IFERROR(E10/D10, "") -> -0.19005142 | G10: 179737 | H10: =IF(AND(ISNUMBER(C10),ISNUMBER(G10)), C10-G10, "") -> -21873 | I10: =IFERROR(H10/G10, "") -> -0.12169448 | J10: 1.Site was taken offline from 10:45 to 11:45 on 02/21 due to technicians checked in to collect DGA samples. 2.Site stopped communicating at 12PM on 02/22 and back online at 08:15 on 02/23 after technician reset main breaker and SEL relay. 3.Inverter 9 started late for production at 13:00 on 02/27 due to insulation Fault. | K10: 1.SR097562 2.SR097648 3.SR097870 | L10: SR097648 | M10: SR097870
A11: Suffield | B11: CT | C11: 160474 | D11: 229753.5 | E11: =IF(AND(ISNUMBER(C11),ISNUMBER(D11)), C11-D11, "") -> -69279.5 | F11: =IFERROR(E11/D11, "") -> -0.30153839 | G11: 221930.9 | H11: =IF(AND(ISNUMBER(C11),ISNUMBER(G11)), C11-G11, "") -> -61456.9 | I11: =IFERROR(H11/G11, "") -> -0.27691908 | J11: 1.On 02/26, the technician replaced CB 14's String 9 (faulty) and String 13 (open circuit). 2. Low generation due to rain/snow | K11: 1.SR089923, SR090122 | L11: SR090122
A12: Ashby-Duffy | B12: MA | C12: 85456 | D12: 296805.6 | E12: =IF(AND(ISNUMBER(C12),ISNUMBER(D12)), C12-D12, "") -> -211349.6 | F12: =IFERROR(E12/D12, "") -> -0.7120809 | G12: 209076.1 | H12: =IF(AND(ISNUMBER(C12),ISNUMBER(G12)), C12-G12, "") -> -123620.1 | I12: =IFERROR(H12/G12, "") -> -0.59126844 | J12: 1.Inverter 2 was offline since 12/19 and will remains offline until the ground is unfrozen. 2.Inverter 39 string 5 blew a fuse and requires underground wiring replacement. Work will be scheduled once the ground thaws. 3. Low generation due to rain/snow. | K12: 1. SR093777,SR097797 2.SR094302, SR097796 | L12: SR097797 | M12: SR094302 | N12: SR097796
A13: Ashland | B13: MA | C13: 115560 | D13: 235192.7 | E13: =IF(AND(ISNUMBER(C13),ISNUMBER(D13)), C13-D13, "") -> -119632.7 | F13: =IFERROR(E13/D13, "") -> -0.50865822 | G13: 225868 | H13: =IF(AND(ISNUMBER(C13),ISNUMBER(G13)), C13-G13, "") -> -110308 | I13: =IFERROR(H13/G13, "") -> -0.48837374 | J13: 1.Inverter 49 was being RMA'D since 10/16/23. 2.Inverter 67 was being RMA'd. 3.Inverter 57 was being RMA'd. 4.Inverter 12 was offline intermittently whole month and being RMA'd. 5.Inverter 16 was offline since 11/13 due to Arc Protection and being RMA'd. 6.Inverter 66 is bearly producing due to protect 0260 fault from 01/30 and back to normal after technician replaced MC4 connectors that were causing arc fault on 02/04. 7.Inverter 21 was offline on 02/06 due to ARC Protection fault and back online at 11:45 on 02/07 after technician replaced blown DC fuse and fuse holders. 8.Inverter 24 has multiple trip events through out the month due to Insulation Resistance Low fault. 9. Low generation due to rain/snow. | K13: 1.SR088449 2.SR088450 3.SR091962 4.SR093117, SR097799 5.SR095816 6.SR096271 7.SR096370 8.SR097060 | L13: SR088450 | M13: SR091962 | N13: SR093117 | O13: SR097799 | P13: SR095816 | Q13: SR096271 | R13: SR096370 | S13: SR097060
A14: Barrington | B14: MA | C14: 22100 | D14: 27320.93 | E14: =IF(AND(ISNUMBER(C14),ISNUMBER(D14)), C14-D14, "") -> -5220.93 | F14: =IFERROR(E14/D14, "") -> -0.19109635 | G14: 54460 | H14: =IF(AND(ISNUMBER(C14),ISNUMBER(G14)), C14-G14, "") -> -32360 | I14: =IFERROR(H14/G14, "") -> -0.59419758 | J14: 1. Low generation due to rain/snow.
A15: Bedford - 205 Burlington Rd | B15: MA | C15: 6760 | D15: N/A | E15: =IF(AND(ISNUMBER(C15),ISNUMBER(D15)), C15-D15, "") | F15: =IFERROR(E15/D15, "") | G15: N/A | H15: =IF(AND(ISNUMBER(C15),ISNUMBER(G15)), C15-G15, "") | I15: =IFERROR(H15/G15, "")
A16: Billerica - 6 Cook Street | B16: MA | C16: 5612 | D16: N/A | E16: =IF(AND(ISNUMBER(C16),ISNUMBER(D16)), C16-D16, "") | F16: =IFERROR(E16/D16, "") | G16: N/A | H16: =IF(AND(ISNUMBER(C16),ISNUMBER(G16)), C16-G16, "") | I16: =IFERROR(H16/G16, "")
A17: Billerica - 780 Boston Road | B17: MA | C17: 6214 | D17: N/A | E17: =IF(AND(ISNUMBER(C17),ISNUMBER(D17)), C17-D17, "") | F17: =IFERROR(E17/D17, "") | G17: N/A | H17: =IF(AND(ISNUMBER(C17),ISNUMBER(G17)), C17-G17, "") | I17: =IFERROR(H17/G17, "") | J17: 1.Inverter 4 was offline on 02/27 due to Insulation resistance too low fault and resumed production at 13:40 on 02/28. | K17: 1.SR097899
A18: Cheshire | B18: MA | C18: 16209.044 | D18: 46433.28 | E18: =IF(AND(ISNUMBER(C18),ISNUMBER(D18)), C18-D18, "") -> -30224.236 | F18: =IFERROR(E18/D18, "") -> -0.65091754 | G18: 34106.99 | H18: =IF(AND(ISNUMBER(C18),ISNUMBER(G18)), C18-G18, "") -> -17897.946 | I18: =IFERROR(H18/G18, "") -> -0.5247589 | J18: 1. Low generation due to rain/snow.
A19: Lilly Lane | B19: MA | C19: 70582.5 | D19: 102338.9 | E19: =IF(AND(ISNUMBER(C19),ISNUMBER(D19)), C19-D19, "") -> -31756.4 | F19: =IFERROR(E19/D19, "") -> -0.31030625 | G19: 133421.2 | H19: =IF(AND(ISNUMBER(C19),ISNUMBER(G19)), C19-G19, "") -> -62838.7 | I19: =IFERROR(H19/G19, "") -> -0.47097987 | J19: 1.Inverter 61 was being RMA'd from 01/22. 2.Inverter 67 was offline from 11:15 to 15:30 on 02/17 due to a grid over-frequency fault. On 02/26, it went offline again due to an insulation resistance low fault. The technician repaired broken MC4 connectors and cleared an arc fault, restoring the inverter online at 13:45 on 02/27. 3.On 02/24, Inverter 69 was offline due to an insulation resistance low fault. The technician repaired the jumper cable and ensured sufficient slack, restoring the inverter online at 14:30 on 02/24. 4.Inverter 50 was offline on 02/25 due to Insulation resistance low fault and back online at 13:15 on 02/26 after technician cleared the arc fault and repaired the bad MC4 connections. 5. Low generation due to rain/snow. | K19: 1.SR095846, SR097795 2.SR097191 3.SR097690 4.SR097747 | L19: SR097795 | M19: SR097191 | N19: SR097690 | O19: SR097747
