Workbook
Name JanActual: #REF!
Name JanActual2: #REF!
Name JanExpected: #REF!
Name JanExpectedDelta: #REF!
Name JanExpectedPercent: #REF!
Name JanExpPercent: #REF!
Name JanForecasted: #REF!
Name JanForecastedDelta: #REF!
Name JanForecastedPercent: #REF!
Name portfolio: Sites!$B$1:$B$1
Name Year: Sites!#REF!

Sheet Year to Date
A1: {=portfolio} -> Silicon Ranch | D1: Year to Date Actual v. Expected | G1: Year to Date Actual v. Forecasted
A2: Total | C2: =SUM(C4:C100) -> 12948655 | D2: =SUM(D4:D100) -> 0 | E2: =C2-D2 -> 12948655 | F2: =IFERROR(E2/D2, 0) -> 0 | G2: =SUM(G4:G100) -> 13060951 | H2: =C2-G2 -> -112295.99 | I2: =IFERROR(H2/G2, 0) -> -0.0085978417
A3: Site | B3: State | C3: Actual | D3: Expected | E3: Delta | F3: % | G3: Forecasted | H3: Delta | I3: %
A4: {=Sites[Site]} -> Iron Mountain - Windsor | B4: {=Sites[State]} -> CT | C4: =SUM('1st Qtr'!C4, '2nd Qtr'!C4, '3rd Qtr'!C4, '4th Qtr'!C4) -> 80549 | D4: =SUM('1st Qtr'!D4, '2nd Qtr'!D4, '3rd Qtr'!D4, '4th Qtr'!D4) -> 0 | E4: =IF(AND(ISNUMBER(C4),ISNUMBER(D4)), C4-D4, "") -> 80549 | F4: =IFERROR(E4/D4, "") | G4: =SUM('1st Qtr'!G4, '2nd Qtr'!G4, '3rd Qtr'!G4, '4th Qtr'!G4) -> 85584.6 | H4: =SUM('1st Qtr'!H4, '2nd Qtr'!H4, '3rd Qtr'!H4, '4th Qtr'!H4) -> -5035.6 | I4: =IFERROR(H4/G4, "") -> -0.058837688
A5: Kohls - Auburn | B5: NY | C5: =SUM('1st Qtr'!C5, '2nd Qtr'!C5, '3rd Qtr'!C5, '4th Qtr'!C5) -> 70849 | D5: =SUM('1st Qtr'!D5, '2nd Qtr'!D5, '3rd Qtr'!D5, '4th Qtr'!D5) -> 0 | E5: =IF(AND(ISNUMBER(C5),ISNUMBER(D5)), C5-D5, "") -> 70849 | F5: =IFERROR(E5/D5, "") | G5: =SUM('1st Qtr'!G5, '2nd Qtr'!G5, '3rd Qtr'!G5, '4th Qtr'!G5) -> 72995.91 | H5: =SUM('1st Qtr'!H5, '2nd Qtr'!H5, '3rd Qtr'!H5, '4th Qtr'!H5) -> -2146.91 | I5: =IFERROR(H5/G5, "") -> -0.029411374
A6: Kohls - Bensalem | B6: PA | C6: =SUM('1st Qtr'!C6, '2nd Qtr'!C6, '3rd Qtr'!C6, '4th Qtr'!C6) -> 97605 | D6: =SUM('1st Qtr'!D6, '2nd Qtr'!D6, '3rd Qtr'!D6, '4th Qtr'!D6) -> 0 | E6: =IF(AND(ISNUMBER(C6),ISNUMBER(D6)), C6-D6, "") -> 97605 | F6: =IFERROR(E6/D6, "") | G6: =SUM('1st Qtr'!G6, '2nd Qtr'!G6, '3rd Qtr'!G6, '4th Qtr'!G6) -> 98831.09 | H6: =SUM('1st Qtr'!H6, '2nd Qtr'!H6, '3rd Qtr'!H6, '4th Qtr'!H6) -> -1226.09 | I6: =IFERROR(H6/G6, "") -> -0.012405914
A7: Kohls - Brick | B7: NJ | C7: =SUM('1st Qtr'!C7, '2nd Qtr'!C7, '3rd Qtr'!C7, '4th Qtr'!C7) -> 135696 | D7: =SUM('1st Qtr'!D7, '2nd Qtr'!D7, '3rd Qtr'!D7, '4th Qtr'!D7) -> 0 | E7: =IF(AND(ISNUMBER(C7),ISNUMBER(D7)), C7-D7, "") -> 135696 | F7: =IFERROR(E7/D7, "") | G7: =SUM('1st Qtr'!G7, '2nd Qtr'!G7, '3rd Qtr'!G7, '4th Qtr'!G7) -> 115611.45 | H7: =SUM('1st Qtr'!H7, '2nd Qtr'!H7, '3rd Qtr'!H7, '4th Qtr'!H7) -> 20084.55 | I7: =IFERROR(H7/G7, "") -> 0.17372457
A8: Kohls - Buffalo | B8: NY | C8: =SUM('1st Qtr'!C8, '2nd Qtr'!C8, '3rd Qtr'!C8, '4th Qtr'!C8) -> 64905 | D8: =SUM('1st Qtr'!D8, '2nd Qtr'!D8, '3rd Qtr'!D8, '4th Qtr'!D8) -> 0 | E8: =IF(AND(ISNUMBER(C8),ISNUMBER(D8)), C8-D8, "") -> 64905 | F8: =IFERROR(E8/D8, "") | G8: =SUM('1st Qtr'!G8, '2nd Qtr'!G8, '3rd Qtr'!G8, '4th Qtr'!G8) -> 98321.4 | H8: =SUM('1st Qtr'!H8, '2nd Qtr'!H8, '3rd Qtr'!H8, '4th Qtr'!H8) -> -33416.4 | I8: =IFERROR(H8/G8, "") -> -0.33986904
A9: Kohls - Canton | B9: CT | C9: =SUM('1st Qtr'!C9, '2nd Qtr'!C9, '3rd Qtr'!C9, '4th Qtr'!C9) -> 38395 | D9: =SUM('1st Qtr'!D9, '2nd Qtr'!D9, '3rd Qtr'!D9, '4th Qtr'!D9) -> 0 | E9: =IF(AND(ISNUMBER(C9),ISNUMBER(D9)), C9-D9, "") -> 38395 | F9: =IFERROR(E9/D9, "") | G9: =SUM('1st Qtr'!G9, '2nd Qtr'!G9, '3rd Qtr'!G9, '4th Qtr'!G9) -> 37508.89 | H9: =SUM('1st Qtr'!H9, '2nd Qtr'!H9, '3rd Qtr'!H9, '4th Qtr'!H9) -> 886.11 | I9: =IFERROR(H9/G9, "") -> 0.023624
A10: Kohls - East Amherst | B10: NY | C10: =SUM('1st Qtr'!C10, '2nd Qtr'!C10, '3rd Qtr'!C10, '4th Qtr'!C10) -> 72920 | D10: =SUM('1st Qtr'!D10, '2nd Qtr'!D10, '3rd Qtr'!D10, '4th Qtr'!D10) -> 0 | E10: =IF(AND(ISNUMBER(C10),ISNUMBER(D10)), C10-D10, "") -> 72920 | F10: =IFERROR(E10/D10, "") | G10: =SUM('1st Qtr'!G10, '2nd Qtr'!G10, '3rd Qtr'!G10, '4th Qtr'!G10) -> 89879.57 | H10: =SUM('1st Qtr'!H10, '2nd Qtr'!H10, '3rd Qtr'!H10, '4th Qtr'!H10) -> -16959.57 | I10: =IFERROR(H10/G10, "") -> -0.18869216
A11: Kohls - East Brunswick | B11: NJ | C11: =SUM('1st Qtr'!C11, '2nd Qtr'!C11, '3rd Qtr'!C11, '4th Qtr'!C11) -> 153153 | D11: =SUM('1st Qtr'!D11, '2nd Qtr'!D11, '3rd Qtr'!D11, '4th Qtr'!D11) -> 0 | E11: =IF(AND(ISNUMBER(C11),ISNUMBER(D11)), C11-D11, "") -> 153153 | F11: =IFERROR(E11/D11, "") | G11: =SUM('1st Qtr'!G11, '2nd Qtr'!G11, '3rd Qtr'!G11, '4th Qtr'!G11) -> 152228.56 | H11: =SUM('1st Qtr'!H11, '2nd Qtr'!H11, '3rd Qtr'!H11, '4th Qtr'!H11) -> 924.44 | I11: =IFERROR(H11/G11, "") -> 0.0060727107
A12: Kohls - Edgewood | B12: MD | C12: =SUM('1st Qtr'!C12, '2nd Qtr'!C12, '3rd Qtr'!C12, '4th Qtr'!C12) -> 754081 | D12: =SUM('1st Qtr'!D12, '2nd Qtr'!D12, '3rd Qtr'!D12, '4th Qtr'!D12) -> 0 | E12: =IF(AND(ISNUMBER(C12),ISNUMBER(D12)), C12-D12, "") -> 754081 | F12: =IFERROR(E12/D12, "") | G12: =SUM('1st Qtr'!G12, '2nd Qtr'!G12, '3rd Qtr'!G12, '4th Qtr'!G12) -> 822183.49 | H12: =SUM('1st Qtr'!H12, '2nd Qtr'!H12, '3rd Qtr'!H12, '4th Qtr'!H12) -> -68102.49 | I12: =IFERROR(H12/G12, "") -> -0.082831255
A13: Kohls - Granite Run | B13: PA | C13: =SUM('1st Qtr'!C13, '2nd Qtr'!C13, '3rd Qtr'!C13, '4th Qtr'!C13) -> 98808 | D13: =SUM('1st Qtr'!D13, '2nd Qtr'!D13, '3rd Qtr'!D13, '4th Qtr'!D13) -> 0 | E13: =IF(AND(ISNUMBER(C13),ISNUMBER(D13)), C13-D13, "") -> 98808 | F13: =IFERROR(E13/D13, "") | G13: =SUM('1st Qtr'!G13, '2nd Qtr'!G13, '3rd Qtr'!G13, '4th Qtr'!G13) -> 98895.64 | H13: =SUM('1st Qtr'!H13, '2nd Qtr'!H13, '3rd Qtr'!H13, '4th Qtr'!H13) -> -87.64 | I13: =IFERROR(H13/G13, "") -> -0.00088618669
A14: Kohls - Greece | B14: NY | C14: =SUM('1st Qtr'!C14, '2nd Qtr'!C14, '3rd Qtr'!C14, '4th Qtr'!C14) -> 63819 | D14: =SUM('1st Qtr'!D14, '2nd Qtr'!D14, '3rd Qtr'!D14, '4th Qtr'!D14) -> 0 | E14: =IF(AND(ISNUMBER(C14),ISNUMBER(D14)), C14-D14, "") -> 63819 | F14: =IFERROR(E14/D14, "") | G14: =SUM('1st Qtr'!G14, '2nd Qtr'!G14, '3rd Qtr'!G14, '4th Qtr'!G14) -> 92989.72 | H14: =SUM('1st Qtr'!H14, '2nd Qtr'!H14, '3rd Qtr'!H14, '4th Qtr'!H14) -> -29170.72 | I14: =IFERROR(H14/G14, "") -> -0.31369833
A15: Kohls - Hanover | B15: PA | C15: =SUM('1st Qtr'!C15, '2nd Qtr'!C15, '3rd Qtr'!C15, '4th Qtr'!C15) -> 113224 | D15: =SUM('1st Qtr'!D15, '2nd Qtr'!D15, '3rd Qtr'!D15, '4th Qtr'!D15) -> 0 | E15: =IF(AND(ISNUMBER(C15),ISNUMBER(D15)), C15-D15, "") -> 113224 | F15: =IFERROR(E15/D15, "") | G15: =SUM('1st Qtr'!G15, '2nd Qtr'!G15, '3rd Qtr'!G15, '4th Qtr'!G15) -> 112330.91 | H15: =SUM('1st Qtr'!H15, '2nd Qtr'!H15, '3rd Qtr'!H15, '4th Qtr'!H15) -> 893.09 | I15: =IFERROR(H15/G15, "") -> 0.0079505276
A16: Kohls - Horsehead | B16: NY | C16: =SUM('1st Qtr'!C16, '2nd Qtr'!C16, '3rd Qtr'!C16, '4th Qtr'!C16) -> 73342 | D16: =SUM('1st Qtr'!D16, '2nd Qtr'!D16, '3rd Qtr'!D16, '4th Qtr'!D16) -> 0 | E16: =IF(AND(ISNUMBER(C16),ISNUMBER(D16)), C16-D16, "") -> 73342 | F16: =IFERROR(E16/D16, "") | G16: =SUM('1st Qtr'!G16, '2nd Qtr'!G16, '3rd Qtr'!G16, '4th Qtr'!G16) -> 81919.08 | H16: =SUM('1st Qtr'!H16, '2nd Qtr'!H16, '3rd Qtr'!H16, '4th Qtr'!H16) -> -8577.08 | I16: =IFERROR(H16/G16, "") -> -0.10470186
... A68: Snowline SD - Vista Verde ES | B68: CA | C68: =SUM('1st Qtr'!C68, '2nd Qtr'!C68, '3rd Qtr'!C68, '4th Qtr'!C68) -> 58466 | D68: =SUM('1st Qtr'!D68, '2nd Qtr'!D68, '3rd Qtr'!D68, '4th Qtr'!D68) -> 0 | E68: =IF(AND(ISNUMBER(C68),ISNUMBER(D68)), C68-D68, "") -> 58466 | F68: =IFERROR(E68/D68, "") | G68: =SUM('1st Qtr'!G68, '2nd Qtr'!G68, '3rd Qtr'!G68, '4th Qtr'!G68) -> 66854.41 | H68: =SUM('1st Qtr'!H68, '2nd Qtr'!H68, '3rd Qtr'!H68, '4th Qtr'!H68) -> -36490.32 | I68: =IFERROR(H68/G68, "") -> -0.5458177
A69: North Stonington | B69: CT | C69: =SUM('1st Qtr'!C69, '2nd Qtr'!C69, '3rd Qtr'!C69, '4th Qtr'!C69) -> 4344040 | D69: =SUM('1st Qtr'!D69, '2nd Qtr'!D69, '3rd Qtr'!D69, '4th Qtr'!D69) -> 0 | E69: =IF(AND(ISNUMBER(C69),ISNUMBER(D69)), C69-D69, "") -> 4344040 | G69: =SUM('1st Qtr'!G69, '2nd Qtr'!G69, '3rd Qtr'!G69, '4th Qtr'!G69) -> 0 | H69: =SUM('1st Qtr'!H69, '2nd Qtr'!H69, '3rd Qtr'!H69, '4th Qtr'!H69) -> 2918160 | I69: =IFERROR(H69/G69, "")

Sheet 1st Qtr
A1: {=portfolio} -> Silicon Ranch | D1: 1st Quarter Actual v. Expected | G1: 1st Quarter Actual v. Forecasted
A2: Total | C2: =SUM(C4:C100) -> 8815983 | D2: =SUM(D4:D100) -> 0 | E2: =C2-D2 -> 8815983 | F2: =IFERROR(E2/D2, 0) -> 0 | G2: =SUM(G4:G100) -> 8396081.7 | H2: =C2-G2 -> 419901.31 | I2: =IFERROR(H2/G2, 0) -> 0.05001158
A3: Site | B3: State | C3: Actual | D3: Expected | E3: Delta | F3: % | G3: Forecasted | H3: Delta | I3: %
A4: {=Sites[Site]} -> Iron Mountain - Windsor | B4: {=Sites[State]} -> CT | C4: =SUM(Jan!C4, Feb!C4, Mar!C4) -> 49256 | D4: =SUM(Jan!D4, Feb!D4, Mar!D4) -> 0 | E4: =IF(AND(ISNUMBER(C4),ISNUMBER(D4)), C4-D4, "") -> 49256 | F4: =IFERROR(E4/D4, "") | G4: =SUM(Jan!G4, Feb!G4, Mar!G4) -> 54649.74 | H4: =SUM(Jan!H4, Feb!H4, Mar!H4) -> -5393.74 | I4: =IFERROR(H4/G4, "") -> -0.098696535
A5: Kohls - Auburn | B5: NY | C5: =SUM(Jan!C5, Feb!C5, Mar!C5) -> 38514 | D5: =SUM(Jan!D5, Feb!D5, Mar!D5) -> 0 | E5: =IF(AND(ISNUMBER(C5),ISNUMBER(D5)), C5-D5, "") -> 38514 | F5: =IFERROR(E5/D5, "") | G5: =SUM(Jan!G5, Feb!G5, Mar!G5) -> 39136.03 | H5: =SUM(Jan!H5, Feb!H5, Mar!H5) -> -622.03 | I5: =IFERROR(H5/G5, "") -> -0.01589405
A6: Kohls - Bensalem | B6: PA | C6: =SUM(Jan!C6, Feb!C6, Mar!C6) -> 72426 | D6: =SUM(Jan!D6, Feb!D6, Mar!D6) -> 0 | E6: =IF(AND(ISNUMBER(C6),ISNUMBER(D6)), C6-D6, "") -> 72426 | F6: =IFERROR(E6/D6, "") | G6: =SUM(Jan!G6, Feb!G6, Mar!G6) -> 65202.38 | H6: =SUM(Jan!H6, Feb!H6, Mar!H6) -> 7223.62 | I6: =IFERROR(H6/G6, "") -> 0.11078767
A7: Kohls - Brick | B7: NJ | C7: =SUM(Jan!C7, Feb!C7, Mar!C7) -> 91939 | D7: =SUM(Jan!D7, Feb!D7, Mar!D7) -> 0 | E7: =IF(AND(ISNUMBER(C7),ISNUMBER(D7)), C7-D7, "") -> 91939 | F7: =IFERROR(E7/D7, "") | G7: =SUM(Jan!G7, Feb!G7, Mar!G7) -> 74753.88 | H7: =SUM(Jan!H7, Feb!H7, Mar!H7) -> 17185.12 | I7: =IFERROR(H7/G7, "") -> 0.22988934
A8: Kohls - Buffalo | B8: NY | C8: =SUM(Jan!C8, Feb!C8, Mar!C8) -> 29451 | D8: =SUM(Jan!D8, Feb!D8, Mar!D8) -> 0 | E8: =IF(AND(ISNUMBER(C8),ISNUMBER(D8)), C8-D8, "") -> 29451 | F8: =IFERROR(E8/D8, "") | G8: =SUM(Jan!G8, Feb!G8, Mar!G8) -> 54344.28 | H8: =SUM(Jan!H8, Feb!H8, Mar!H8) -> -24893.28 | I8: =IFERROR(H8/G8, "") -> -0.45806624
A9: Kohls - Canton | B9: CT | C9: =SUM(Jan!C9, Feb!C9, Mar!C9) -> 22796 | D9: =SUM(Jan!D9, Feb!D9, Mar!D9) -> 0 | E9: =IF(AND(ISNUMBER(C9),ISNUMBER(D9)), C9-D9, "") -> 22796 | F9: =IFERROR(E9/D9, "") | G9: =SUM(Jan!G9, Feb!G9, Mar!G9) -> 23886.67 | H9: =SUM(Jan!H9, Feb!H9, Mar!H9) -> -1090.67 | I9: =IFERROR(H9/G9, "") -> -0.045660195
A10: Kohls - East Amherst | B10: NY | C10: =SUM(Jan!C10, Feb!C10, Mar!C10) -> 38997 | D10: =SUM(Jan!D10, Feb!D10, Mar!D10) -> 0 | E10: =IF(AND(ISNUMBER(C10),ISNUMBER(D10)), C10-D10, "") -> 38997 | F10: =IFERROR(E10/D10, "") | G10: =SUM(Jan!G10, Feb!G10, Mar!G10) -> 51187.85 | H10: =SUM(Jan!H10, Feb!H10, Mar!H10) -> -12190.85 | I10: =IFERROR(H10/G10, "") -> -0.23815906
A11: Kohls - East Brunswick | B11: NJ | C11: =SUM(Jan!C11, Feb!C11, Mar!C11) -> 101861 | D11: =SUM(Jan!D11, Feb!D11, Mar!D11) -> 0 | E11: =IF(AND(ISNUMBER(C11),ISNUMBER(D11)), C11-D11, "") -> 101861 | F11: =IFERROR(E11/D11, "") | G11: =SUM(Jan!G11, Feb!G11, Mar!G11) -> 99741.6 | H11: =SUM(Jan!H11, Feb!H11, Mar!H11) -> 2119.4 | I11: =IFERROR(H11/G11, "") -> 0.021248907
A12: Kohls - Edgewood | B12: MD | C12: =SUM(Jan!C12, Feb!C12, Mar!C12) -> 500770 | D12: =SUM(Jan!D12, Feb!D12, Mar!D12) -> 0 | E12: =IF(AND(ISNUMBER(C12),ISNUMBER(D12)), C12-D12, "") -> 500770 | F12: =IFERROR(E12/D12, "") | G12: =SUM(Jan!G12, Feb!G12, Mar!G12) -> 540853.2 | H12: =SUM(Jan!H12, Feb!H12, Mar!H12) -> -40083.2 | I12: =IFERROR(H12/G12, "") -> -0.074111053
A13: Kohls - Granite Run | B13: PA | C13: =SUM(Jan!C13, Feb!C13, Mar!C13) -> 65152 | D13: =SUM(Jan!D13, Feb!D13, Mar!D13) -> 0 | E13: =IF(AND(ISNUMBER(C13),ISNUMBER(D13)), C13-D13, "") -> 65152 | F13: =IFERROR(E13/D13, "") | G13: =SUM(Jan!G13, Feb!G13, Mar!G13) -> 65257.14 | H13: =SUM(Jan!H13, Feb!H13, Mar!H13) -> -105.14 | I13: =IFERROR(H13/G13, "") -> -0.0016111647
A14: Kohls - Greece | B14: NY | C14: =SUM(Jan!C14, Feb!C14, Mar!C14) -> 33497 | D14: =SUM(Jan!D14, Feb!D14, Mar!D14) -> 0 | E14: =IF(AND(ISNUMBER(C14),ISNUMBER(D14)), C14-D14, "") -> 33497 | F14: =IFERROR(E14/D14, "") | G14: =SUM(Jan!G14, Feb!G14, Mar!G14) -> 51595.13 | H14: =SUM(Jan!H14, Feb!H14, Mar!H14) -> -18098.13 | I14: =IFERROR(H14/G14, "") -> -0.35077206
A15: Kohls - Hanover | B15: PA | C15: =SUM(Jan!C15, Feb!C15, Mar!C15) -> 74462 | D15: =SUM(Jan!D15, Feb!D15, Mar!D15) -> 0 | E15: =IF(AND(ISNUMBER(C15),ISNUMBER(D15)), C15-D15, "") -> 74462 | F15: =IFERROR(E15/D15, "") | G15: =SUM(Jan!G15, Feb!G15, Mar!G15) -> 73222.49 | H15: =SUM(Jan!H15, Feb!H15, Mar!H15) -> 1239.51 | I15: =IFERROR(H15/G15, "") -> 0.016927996
A16: Kohls - Horsehead | B16: NY | C16: =SUM(Jan!C16, Feb!C16, Mar!C16) -> 44770 | D16: =SUM(Jan!D16, Feb!D16, Mar!D16) -> 0 | E16: =IF(AND(ISNUMBER(C16),ISNUMBER(D16)), C16-D16, "") -> 44770 | F16: =IFERROR(E16/D16, "") | G16: =SUM(Jan!G16, Feb!G16, Mar!G16) -> 53409.39 | H16: =SUM(Jan!H16, Feb!H16, Mar!H16) -> -8639.39 | I16: =IFERROR(H16/G16, "") -> -0.16175789
... A22: Kohls - North Amherst | B22: NY | C22: =SUM(Jan!C22, Feb!C22, Mar!C22) -> 0 | D22: =SUM(Jan!D22, Feb!D22, Mar!D22) -> 0 | E22: =IF(AND(ISNUMBER(C22),ISNUMBER(D22)), C22-D22, "") -> 0 | F22: =IFERROR(E22/D22, "") | G22: =SUM(Jan!G22, Feb!G22, Mar!G22) -> 44245.55 | H22: =SUM(Jan!H22, Feb!H22, Mar!H22) -> -44245.55 | I22: =IFERROR(H22/G22, "") -> -1
A23: Kohls - Staten Island | B23: NY | C23: =SUM(Jan!C23, Feb!C23, Mar!C23) -> 53681 | D23: =SUM(Jan!D23, Feb!D23, Mar!D23) -> 0 | E23: =IF(AND(ISNUMBER(C23),ISNUMBER(D23)), C23-D23, "") -> 53681 | F23: =IFERROR(E23/D23, "") | G23: =SUM(Jan!G23, Feb!G23, Mar!G24) -> 72887.91 | H23: =SUM(Jan!H23, Feb!H23, Mar!H23) -> -14695.29 | I23: =IFERROR(H23/G23, "") -> -0.20161492
A24: Kohls - Warminster | B24: PA | C24: =SUM(Jan!C24, Feb!C24, Mar!C24) -> 86449 | D24: =SUM(Jan!D24, Feb!D24, Mar!D24) -> 0 | E24: =IF(AND(ISNUMBER(C24),ISNUMBER(D24)), C24-D24, "") -> 86449 | F24: =IFERROR(E24/D24, "") | G24: =SUM(Jan!G24, Feb!G24, Mar!G25) -> 72227.48 | H24: =SUM(Jan!H24, Feb!H24, Mar!H24) -> 6261.49 | I24: =IFERROR(H24/G24, "") -> 0.086691243
A25: Kohls - Waterbury | B25: CT | C25: =SUM(Jan!C25, Feb!C25, Mar!C25) -> 52627 | D25: =SUM(Jan!D25, Feb!D25, Mar!D25) -> 0 | E25: =IF(AND(ISNUMBER(C25),ISNUMBER(D25)), C25-D25, "") -> 52627 | F25: =IFERROR(E25/D25, "") | G25: =SUM(Jan!G25, Feb!G25,Mar!G25) -> 63024.39 | H25: =SUM(Jan!H25, Feb!H25, Mar!H25) -> -10397.39 | I25: =IFERROR(H25/G25, "") -> -0.16497407
A26: Mojave Water Agency - Headquarters | B26: CA | C26: =SUM(Jan!C26, Feb!C26, Mar!C26) -> 97224 | D26: =SUM(Jan!D26, Feb!D26, Mar!D26) -> 0 | E26: =IF(AND(ISNUMBER(C26),ISNUMBER(D26)), C26-D26, "") -> 97224 | F26: =IFERROR(E26/D26, "") | G26: =SUM(Jan!G26, Feb!G26, Mar!G27) -> 169730.46 | H26: =SUM(Jan!H26, Feb!H26, Mar!H26) -> 10627.4 | I26: =IFERROR(H26/G26, "") -> 0.062613393
A27: CSU - Bakersfield | B27: CA | C27: =SUM(Jan!C27, Feb!C27, Mar!C27) -> 286399 | D27: =SUM(Jan!D27, Feb!D27, Mar!D27) -> 0 | E27: =IF(AND(ISNUMBER(C27),ISNUMBER(D27)), C27-D27, "") -> 286399 | F27: =IFERROR(E27/D27, "") | G27: =SUM(Jan!G27, Feb!G27,Mar!G27) -> 257127.57 | H27: =SUM(Jan!H27, Feb!H27, Mar!H27) -> 29271.43 | I27: =IFERROR(H27/G27, "") -> 0.11384011
A28: Greenfield USD - Fairfield ES | B28: CA | C28: =SUM(Jan!C28, Feb!C28, Mar!C28) -> 30631 | D28: =SUM(Jan!D28, Feb!D28, Mar!D28) -> 0 | E28: =IF(AND(ISNUMBER(C28),ISNUMBER(D28)), C28-D28, "") -> 30631 | F28: =IFERROR(E28/D28, "") | G28: =SUM(Jan!G28, Feb!G28, Mar!G29) -> 44355.33 | H28: =SUM(Jan!H28, Feb!H28, Mar!H28) -> 4470.44 | I28: =IFERROR(H28/G28, "") -> 0.10078699
A29: Greenfield USD - Granite Point ES | B29: CA | C29: =SUM(Jan!C29, Feb!C29, Mar!C29) -> 84450 | D29: =SUM(Jan!D29, Feb!D29, Mar!D29) -> 0 | E29: =IF(AND(ISNUMBER(C29),ISNUMBER(D29)), C29-D29, "") -> 84450 | F29: =IFERROR(E29/D29, "") | G29: =SUM(Jan!G29, Feb!G29,Mar!G29) -> 68700.23 | H29: =SUM(Jan!H29, Feb!H29, Mar!H29) -> 15749.77 | I29: =IFERROR(H29/G29, "") -> 0.22925353
A30: Greenfield USD - Greenfield MS | B30: CA | C30: =SUM(Jan!C30, Feb!C30, Mar!C30) -> 45940 | D30: =SUM(Jan!D30, Feb!D30, Mar!D30) -> 0 | E30: =IF(AND(ISNUMBER(C30),ISNUMBER(D30)), C30-D30, "") -> 45940 | F30: =IFERROR(E30/D30, "") | G30: =SUM(Jan!G30, Feb!G30, Mar!G31) -> 49111.12 | H30: =SUM(Jan!H30, Feb!H30, Mar!H30) -> 6930.442 | I30: =IFERROR(H30/G30, "") -> 0.14111757
A31: Greenfield USD - Horizon ES | B31: CA | C31: =SUM(Jan!C31, Feb!C31, Mar!C31) -> 76985 | D31: =SUM(Jan!D31, Feb!D31, Mar!D31) -> 0 | E31: =IF(AND(ISNUMBER(C31),ISNUMBER(D31)), C31-D31, "") -> 76985 | F31: =IFERROR(E31/D31, "") | G31: =SUM(Jan!G31, Feb!G31,Mar!G31) -> 70247.88 | H31: =SUM(Jan!H31, Feb!H31, Mar!H31) -> 6737.12 | I31: =IFERROR(H31/G31, "") -> 0.095904958
A32: Greenfield USD - McKee MS | B32: CA | C32: =SUM(Jan!C32, Feb!C32, Mar!C32) -> 37266 | D32: =SUM(Jan!D32, Feb!D32, Mar!D32) -> 0 | E32: =IF(AND(ISNUMBER(C32),ISNUMBER(D32)), C32-D32, "") -> 37266 | F32: =IFERROR(E32/D32, "") | G32: =SUM(Jan!G32, Feb!G32, Mar!G33) -> 37725.43 | H32: =SUM(Jan!H32, Feb!H32, Mar!H32) -> -5707.84 | I32: =IFERROR(H32/G32, "") -> -0.15129953
A33: Greenfield USD - Plantation ES | B33: CA | C33: =SUM(Jan!C33, Feb!C33, Mar!C33) -> 36245 | D33: =SUM(Jan!D33, Feb!D33, Mar!D33) -> 0 | E33: =IF(AND(ISNUMBER(C33),ISNUMBER(D33)), C33-D33, "") -> 36245 | F33: =IFERROR(E33/D33, "") | G33: =SUM(Jan!G33, Feb!G33,Mar!G33) -> 30727.23 | H33: =SUM(Jan!H33, Feb!H33, Mar!H33) -> 5517.77 | I33: =IFERROR(H33/G33, "") -> 0.17957265
A34: Greenfield USD - Planz ES | B34: CA | C34: =SUM(Jan!C34, Feb!C34, Mar!C34) -> 13923 | D34: =SUM(Jan!D34, Feb!D34, Mar!D34) -> 0 | E34: =IF(AND(ISNUMBER(C34),ISNUMBER(D34)), C34-D34, "") -> 13923 | F34: =IFERROR(E34/D34, "") | G34: =SUM(Jan!G34, Feb!G34, Mar!G35) -> 52884.98 | H34: =SUM(Jan!H34, Feb!H34, Mar!H34) -> -20845.34 | I34: =IFERROR(H34/G34, "") -> -0.39416371
A35: Greenfield USD - Raffaello Palla ES | B35: CA | C35: =SUM(Jan!C35, Feb!C35, Mar!C35) -> 78218 | D35: =SUM(Jan!D35, Feb!D35, Mar!D35) -> 0 | E35: =IF(AND(ISNUMBER(C35),ISNUMBER(D35)), C35-D35, "") -> 78218 | F35: =IFERROR(E35/D35, "") | G35: =SUM(Jan!G35, Feb!G35,Mar!G35) -> 77136.54 | H35: =SUM(Jan!H35, Feb!H35, Mar!H35) -> 1081.46 | I35: =IFERROR(H35/G35, "") -> 0.014020074
A36: Greenfield USD - Valle Verde ES | B36: CA | C36: =SUM(Jan!C36, Feb!C36, Mar!C36) -> 93360 | D36: =SUM(Jan!D36, Feb!D36, Mar!D36) -> 0 | E36: =IF(AND(ISNUMBER(C36),ISNUMBER(D36)), C36-D36, "") -> 93360 | F36: =IFERROR(E36/D36, "") | G36: =SUM(Jan!G36, Feb!G36, Mar!G37) -> 53460.28 | H36: =SUM(Jan!H36, Feb!H36, Mar!H36) -> 20983.41 | I36: =IFERROR(H36/G36, "") -> 0.39250468
A37: Greenfield USD - W.A. Kendrick ES | B37: CA | C37: =SUM(Jan!C37, Feb!C37, Mar!C37) -> 15461 | D37: =SUM(Jan!D37, Feb!D37, Mar!D37) -> 0 | E37: =IF(AND(ISNUMBER(C37),ISNUMBER(D37)), C37-D37, "") -> 15461 | F37: =IFERROR(E37/D37, "") | G37: =SUM(Jan!G37, Feb!G37,Mar!G37) -> 27900.95 | H37: =SUM(Jan!H37, Feb!H37, Mar!H37) -> -12439.95 | I37: =IFERROR(H37/G37, "") -> -0.44586116
A38: Muroc Joint USD - Boron HS | B38: CA | C38: =SUM(Jan!C38, Feb!C38, Mar!C38) -> 0 | D38: =SUM(Jan!D38, Feb!D38, Mar!D38) -> 0 | E38: =IF(AND(ISNUMBER(C38),ISNUMBER(D38)), C38-D38, "") -> 0 | F38: =IFERROR(E38/D38, "") | G38: =SUM(Jan!G38, Feb!G38, Mar!G39) -> 61204.34 | H38: =SUM(Jan!H38, Feb!H38, Mar!H38) -> -83442.21 | I38: =IFERROR(H38/G38, "") -> -1.3633381
A39: Muroc Joint USD - W. Boron ES | B39: CA | C39: =SUM(Jan!C39, Feb!C39, Mar!C39) -> 32348 | D39: =SUM(Jan!D39, Feb!D39, Mar!D39) -> 0 | E39: =IF(AND(ISNUMBER(C39),ISNUMBER(D39)), C39-D39, "") -> 32348 | F39: =IFERROR(E39/D39, "") | G39: =SUM(Jan!G39, Feb!G39,Mar!G39) -> 30870.4 | H39: =SUM(Jan!H39, Feb!H39, Mar!H39) -> 1477.6 | I39: =IFERROR(H39/G39, "") -> 0.047864621
A40: Colusa - WTP | B40: CA | C40: =SUM(Jan!C40, Feb!C40, Mar!C40) -> 0 | D40: =SUM(Jan!D40, Feb!D40, Mar!D40) -> 0 | E40: =IF(AND(ISNUMBER(C40),ISNUMBER(D40)), C40-D40, "") -> 0 | F40: =IFERROR(E40/D40, "") | G40: =SUM(Jan!G40, Feb!G40, Mar!G41) -> 121255.59 | H40: =SUM(Jan!H40, Feb!H40, Mar!H40) -> -83651.3 | I40: =IFERROR(H40/G40, "") -> -0.68987582
A41: CDCR-North Kern State Prision | B41: CA | C41: =SUM(Jan!C41, Feb!C41, Mar!C41) -> 213645 | D41: =SUM(Jan!D41, Feb!D41, Mar!D41) -> 0 | E41: =IF(AND(ISNUMBER(C41),ISNUMBER(D41)), C41-D41, "") -> 213645 | F41: =IFERROR(E41/D41, "") | G41: =SUM(Jan!G41, Feb!G41,Mar!G41) -> 266515.87 | H41: =SUM(Jan!H41, Feb!H41, Mar!H41) -> -52870.87 | I41: =IFERROR(H41/G41, "") -> -0.19837794
A42: Muroc Joint USD - District Office | B42: CA | C42: =SUM(Jan!C42, Feb!C42, Mar!C42) -> 16194 | D42: =SUM(Jan!D42, Feb!D42, Mar!D42) -> 0 | E42: =IF(AND(ISNUMBER(C42),ISNUMBER(D42)), C42-D42, "") -> 16194 | F42: =IFERROR(E42/D42, "") | G42: =SUM(Jan!G42, Feb!G42, Mar!G43) -> 31773.82 | H42: =SUM(Jan!H42, Feb!H42, Mar!H42) -> -5546.94 | I42: =IFERROR(H42/G42, "") -> -0.1745758
A43: Whole Foods - Manhattan Beach | B43: CA | C43: =SUM(Jan!C43, Feb!C43, Mar!C43) -> 39241 | D43: =SUM(Jan!D43, Feb!D43, Mar!D43) -> 0 | E43: =IF(AND(ISNUMBER(C43),ISNUMBER(D43)), C43-D43, "") -> 39241 | F43: =IFERROR(E43/D43, "") | G43: =SUM(Jan!G43, Feb!G43,Mar!G43) -> 48623.56 | H43: =SUM(Jan!H43, Feb!H43, Mar!H43) -> -9382.56 | I43: =IFERROR(H43/G43, "") -> -0.19296325
A44: Pioneer USD - Frontier ES | B44: CA | C44: =SUM(Jan!C44, Feb!C44, Mar!C44) -> 68667 | D44: =SUM(Jan!D44, Feb!D44, Mar!D44) -> 0 | E44: =IF(AND(ISNUMBER(C44),ISNUMBER(D44)), C44-D44, "") -> 68667 | F44: =IFERROR(E44/D44, "") | G44: =SUM(Jan!G44, Feb!G44, Mar!G45) -> 61922.17 | H44: =SUM(Jan!H44, Feb!H44, Mar!H44) -> 7535.03 | I44: =IFERROR(H44/G44, "") -> 0.1216855
A45: Pioneer USD - Pioneer ES | B45: CA | C45: =SUM(Jan!C45, Feb!C45, Mar!C45) -> 40957 | D45: =SUM(Jan!D45, Feb!D45, Mar!D45) -> 0 | E45: =IF(AND(ISNUMBER(C45),ISNUMBER(D45)), C45-D45, "") -> 40957 | F45: =IFERROR(E45/D45, "") | G45: =SUM(Jan!G45, Feb!G45,Mar!G45) -> 62281.26 | H45: =SUM(Jan!H45, Feb!H45, Mar!H45) -> -21324.26 | I45: =IFERROR(H45/G45, "") -> -0.34238646
...

Sheet 2nd Qtr
A1: {=portfolio} -> Silicon Ranch | D1: 2nd Quarter Actual v. Expected | G1: 2nd Quarter Actual v. Forecasted
A2: Total | C2: =SUM(C4:C100) -> 4132672 | D2: =SUM(D4:D100) -> 0 | E2: =C2-D2 -> 4132672 | F2: =IFERROR(E2/D2, 0) -> 0 | G2: =SUM(G4:G100) -> 4664869.3 | H2: =C2-G2 -> -532197.3 | I2: =IFERROR(H2/G2, 0) -> -0.11408622
A3: Site | B3: State | C3: Actual | D3: Expected | E3: Delta | F3: % | G3: Forecasted | H3: Delta | I3: %
A4: {=Sites[Site]} -> Iron Mountain - Windsor | B4: {=Sites[State]} -> CT | C4: =SUM(Apr!C4, May!C4, Jun!C4) -> 31293 | D4: =SUM(Apr!D4, May!D4, Jun!D4) -> 0 | E4: =IF(AND(ISNUMBER(C4),ISNUMBER(D4)), C4-D4, "") -> 31293 | F4: =IFERROR(E4/D4, "") | G4: =SUM(Apr!G4, May!G4, Jun!G4) -> 30934.86 | H4: =SUM(Apr!H4, May!H4, Jun!H4) -> 358.14 | I4: =IFERROR(H4/G4, "") -> 0.01157723
A5: Kohls - Auburn | B5: NY | C5: =SUM(Apr!C5, May!C5, Jun!C5) -> 32335 | D5: =SUM(Apr!D5, May!D5, Jun!D5) -> 0 | E5: =IF(AND(ISNUMBER(C5),ISNUMBER(D5)), C5-D5, "") -> 32335 | F5: =IFERROR(E5/D5, "") | G5: =SUM(Apr!G5, May!G5, Jun!G5) -> 33859.88 | H5: =SUM(Apr!H5, May!H5, Jun!H5) -> -1524.88 | I5: =IFERROR(H5/G5, "") -> -0.045035009
A6: Kohls - Bensalem | B6: PA | C6: =SUM(Apr!C6, May!C6, Jun!C6) -> 25179 | D6: =SUM(Apr!D6, May!D6, Jun!D6) -> 0 | E6: =IF(AND(ISNUMBER(C6),ISNUMBER(D6)), C6-D6, "") -> 25179 | F6: =IFERROR(E6/D6, "") | G6: =SUM(Apr!G6, May!G6, Jun!G6) -> 33628.71 | H6: =SUM(Apr!H6, May!H6, Jun!H6) -> -8449.71 | I6: =IFERROR(H6/G6, "") -> -0.25126477
A7: Kohls - Brick | B7: NJ | C7: =SUM(Apr!C7, May!C7, Jun!C7) -> 43757 | D7: =SUM(Apr!D7, May!D7, Jun!D7) -> 0 | E7: =IF(AND(ISNUMBER(C7),ISNUMBER(D7)), C7-D7, "") -> 43757 | F7: =IFERROR(E7/D7, "") | G7: =SUM(Apr!G7, May!G7, Jun!G7) -> 40857.57 | H7: =SUM(Apr!H7, May!H7, Jun!H7) -> 2899.43 | I7: =IFERROR(H7/G7, "") -> 0.070964328
A8: Kohls - Buffalo | B8: NY | C8: =SUM(Apr!C8, May!C8, Jun!C8) -> 35454 | D8: =SUM(Apr!D8, May!D8, Jun!D8) -> 0 | E8: =IF(AND(ISNUMBER(C8),ISNUMBER(D8)), C8-D8, "") -> 35454 | F8: =IFERROR(E8/D8, "") | G8: =SUM(Apr!G8, May!G8, Jun!G8) -> 43977.12 | H8: =SUM(Apr!H8, May!H8, Jun!H8) -> -8523.12 | I8: =IFERROR(H8/G8, "") -> -0.19380805
A9: Kohls - Canton | B9: CT | C9: =SUM(Apr!C9, May!C9, Jun!C9) -> 15599 | D9: =SUM(Apr!D9, May!D9, Jun!D9) -> 0 | E9: =IF(AND(ISNUMBER(C9),ISNUMBER(D9)), C9-D9, "") -> 15599 | F9: =IFERROR(E9/D9, "") | G9: =SUM(Apr!G9, May!G9, Jun!G9) -> 13622.22 | H9: =SUM(Apr!H9, May!H9, Jun!H9) -> 1976.78 | I9: =IFERROR(H9/G9, "") -> 0.14511438
A10: Kohls - East Amherst | B10: NY | C10: =SUM(Apr!C10, May!C10, Jun!C10) -> 33923 | D10: =SUM(Apr!D10, May!D10, Jun!D10) -> 0 | E10: =IF(AND(ISNUMBER(C10),ISNUMBER(D10)), C10-D10, "") -> 33923 | F10: =IFERROR(E10/D10, "") | G10: =SUM(Apr!G10, May!G10, Jun!G10) -> 38691.72 | H10: =SUM(Apr!H10, May!H10, Jun!H10) -> -4768.72 | I10: =IFERROR(H10/G10, "") -> -0.12324911
A11: Kohls - East Brunswick | B11: NJ | C11: =SUM(Apr!C11, May!C11, Jun!C11) -> 51292 | D11: =SUM(Apr!D11, May!D11, Jun!D11) -> 0 | E11: =IF(AND(ISNUMBER(C11),ISNUMBER(D11)), C11-D11, "") -> 51292 | F11: =IFERROR(E11/D11, "") | G11: =SUM(Apr!G11, May!G11, Jun!G11) -> 52486.96 | H11: =SUM(Apr!H11, May!H11, Jun!H11) -> -1194.96 | I11: =IFERROR(H11/G11, "") -> -0.022766798
A12: Kohls - Edgewood | B12: MD | C12: =SUM(Apr!C12, May!C12, Jun!C12) -> 253311 | D12: =SUM(Apr!D12, May!D12, Jun!D12) -> 0 | E12: =IF(AND(ISNUMBER(C12),ISNUMBER(D12)), C12-D12, "") -> 253311 | F12: =IFERROR(E12/D12, "") | G12: =SUM(Apr!G12, May!G12, Jun!G12) -> 281330.29 | H12: =SUM(Apr!H12, May!H12, Jun!H12) -> -28019.29 | I12: =IFERROR(H12/G12, "") -> -0.09959571
A13: Kohls - Granite Run | B13: PA | C13: =SUM(Apr!C13, May!C13, Jun!C13) -> 33656 | D13: =SUM(Apr!D13, May!D13, Jun!D13) -> 0 | E13: =IF(AND(ISNUMBER(C13),ISNUMBER(D13)), C13-D13, "") -> 33656 | F13: =IFERROR(E13/D13, "") | G13: =SUM(Apr!G13, May!G13, Jun!G13) -> 33638.5 | H13: =SUM(Apr!H13, May!H13, Jun!H13) -> 17.5 | I13: =IFERROR(H13/G13, "") -> 0.00052023723
A14: Kohls - Greece | B14: NY | C14: =SUM(Apr!C14, May!C14, Jun!C14) -> 30322 | D14: =SUM(Apr!D14, May!D14, Jun!D14) -> 0 | E14: =IF(AND(ISNUMBER(C14),ISNUMBER(D14)), C14-D14, "") -> 30322 | F14: =IFERROR(E14/D14, "") | G14: =SUM(Apr!G14, May!G14, Jun!G14) -> 41394.59 | H14: =SUM(Apr!H14, May!H14, Jun!H14) -> -11072.59 | I14: =IFERROR(H14/G14, "") -> -0.26748882
A15: Kohls - Hanover | B15: PA | C15: =SUM(Apr!C15, May!C15, Jun!C15) -> 38762 | D15: =SUM(Apr!D15, May!D15, Jun!D15) -> 0 | E15: =IF(AND(ISNUMBER(C15),ISNUMBER(D15)), C15-D15, "") -> 38762 | F15: =IFERROR(E15/D15, "") | G15: =SUM(Apr!G15, May!G15, Jun!G15) -> 39108.42 | H15: =SUM(Apr!H15, May!H15, Jun!H15) -> -346.42 | I15: =IFERROR(H15/G15, "") -> -0.008857939
A16: Kohls - Horsehead | B16: NY | C16: =SUM(Apr!C16, May!C16, Jun!C16) -> 28572 | D16: =SUM(Apr!D16, May!D16, Jun!D16) -> 0 | E16: =IF(AND(ISNUMBER(C16),ISNUMBER(D16)), C16-D16, "") -> 28572 | F16: =IFERROR(E16/D16, "") | G16: =SUM(Apr!G16, May!G16, Jun!G16) -> 28509.69 | H16: =SUM(Apr!H16, May!H16, Jun!H16) -> 62.31 | I16: =IFERROR(H16/G16, "") -> 0.0021855727
... A69: North Stonington | B69: CT | C69: =SUM(Apr!C69, May!C69, Jun!C69) -> 1425880 | D69: =SUM(Apr!D69, May!D69, Jun!D69) -> 0 | E69: =IF(AND(ISNUMBER(C69),ISNUMBER(D69)), C69-D69, "") -> 1425880 | F69: =IFERROR(E69/D69, "") | G69: =SUM(Apr!G69, May!G69, Jun!G69) -> 0 | H69: =SUM(Apr!H69, May!H69, Jun!H69) -> 0 | I69: =IFERROR(H69/G69, "")

Sheet 3rd Qtr
A1: {=portfolio} -> Silicon Ranch | D1: 3rd Quarter Actual v. Expected | G1: 3rd Quarter Actual v. Forecasted
A2: Total | C2: =SUM(C4:C100) -> 0 | D2: =SUM(D4:D100) -> 0 | E2: =C2-D2 -> 0 | F2: =IFERROR(E2/D2, 0) -> 0 | G2: =SUM(G4:G100) -> 0 | H2: =C2-G2 -> 0 | I2: =IFERROR(H2/G2, 0) -> 0
A3: Site | B3: State | C3: Actual | D3: Expected | E3: Delta | F3: % | G3: Forecasted | H3: Delta | I3: %
A4: {=Sites[Site]} -> Iron Mountain - Windsor | B4: {=Sites[State]} -> CT | C4: =SUM(Jul!C4, Aug!C4, Sep!C4) -> 0 | D4: =SUM(Jul!D4, Aug!D4, Sep!D4) -> 0 | E4: =IF(AND(ISNUMBER(C4),ISNUMBER(D4)), C4-D4, "") -> 0 | F4: =IFERROR(E4/D4, "") | G4: =SUM(Jul!G4, Aug!G4, Sep!G4) -> 0 | H4: =SUM(Jul!H4, Aug!H4, Sep!H4) -> 0 | I4: =IFERROR(H4/G4, "")
A5: Kohls - Auburn | B5: NY | C5: =SUM(Jul!C5, Aug!C5, Sep!C5) -> 0 | D5: =SUM(Jul!D5, Aug!D5, Sep!D5) -> 0 | E5: =IF(AND(ISNUMBER(C5),ISNUMBER(D5)), C5-D5, "") -> 0 | F5: =IFERROR(E5/D5, "") | G5: =SUM(Jul!G5, Aug!G5, Sep!G5) -> 0 | H5: =SUM(Jul!H5, Aug!H5, Sep!H5) -> 0 | I5: =IFERROR(H5/G5, "")
A6: Kohls - Bensalem | B6: PA | C6: =SUM(Jul!C6, Aug!C6, Sep!C6) -> 0 | D6: =SUM(Jul!D6, Aug!D6, Sep!D6) -> 0 | E6: =IF(AND(ISNUMBER(C6),ISNUMBER(D6)), C6-D6, "") -> 0 | F6: =IFERROR(E6/D6, "") | G6: =SUM(Jul!G6, Aug!G6, Sep!G6) -> 0 | H6: =SUM(Jul!H6, Aug!H6, Sep!H6) -> 0 | I6: =IFERROR(H6/G6, "")
A7: Kohls - Brick | B7: NJ | C7: =SUM(Jul!C7, Aug!C7, Sep!C7) -> 0 | D7: =SUM(Jul!D7, Aug!D7, Sep!D7) -> 0 | E7: =IF(AND(ISNUMBER(C7),ISNUMBER(D7)), C7-D7, "") -> 0 | F7: =IFERROR(E7/D7, "") | G7: =SUM(Jul!G7, Aug!G7, Sep!G7) -> 0 | H7: =SUM(Jul!H7, Aug!H7, Sep!H7) -> 0 | I7: =IFERROR(H7/G7, "")
A8: Kohls - Buffalo | B8: NY | C8: =SUM(Jul!C8, Aug!C8, Sep!C8) -> 0 | D8: =SUM(Jul!D8, Aug!D8, Sep!D8) -> 0 | E8: =IF(AND(ISNUMBER(C8),ISNUMBER(D8)), C8-D8, "") -> 0 | F8: =IFERROR(E8/D8, "") | G8: =SUM(Jul!G8, Aug!G8, Sep!G8) -> 0 | H8: =SUM(Jul!H8, Aug!H8, Sep!H8) -> 0 | I8: =IFERROR(H8/G8, "")
A9: Kohls - Canton | B9: CT | C9: =SUM(Jul!C9, Aug!C9, Sep!C9) -> 0 | D9: =SUM(Jul!D9, Aug!D9, Sep!D9) -> 0 | E9: =IF(AND(ISNUMBER(C9),ISNUMBER(D9)), C9-D9, "") -> 0 | F9: =IFERROR(E9/D9, "") | G9: =SUM(Jul!G9, Aug!G9, Sep!G9) -> 0 | H9: =SUM(Jul!H9, Aug!H9, Sep!H9) -> 0 | I9: =IFERROR(H9/G9, "")
A10: Kohls - East Amherst | B10: NY | C10: =SUM(Jul!C10, Aug!C10, Sep!C10) -> 0 | D10: =SUM(Jul!D10, Aug!D10, Sep!D10) -> 0 | E10: =IF(AND(ISNUMBER(C10),ISNUMBER(D10)), C10-D10, "") -> 0 | F10: =IFERROR(E10/D10, "") | G10: =SUM(Jul!G10, Aug!G10, Sep!G10) -> 0 | H10: =SUM(Jul!H10, Aug!H10, Sep!H10) -> 0 | I10: =IFERROR(H10/G10, "")
A11: Kohls - East Brunswick | B11: NJ | C11: =SUM(Jul!C11, Aug!C11, Sep!C11) -> 0 | D11: =SUM(Jul!D11, Aug!D11, Sep!D11) -> 0 | E11: =IF(AND(ISNUMBER(C11),ISNUMBER(D11)), C11-D11, "") -> 0 | F11: =IFERROR(E11/D11, "") | G11: =SUM(Jul!G11, Aug!G11, Sep!G11) -> 0 | H11: =SUM(Jul!H11, Aug!H11, Sep!H11) -> 0 | I11: =IFERROR(H11/G11, "")
A12: Kohls - Edgewood | B12: MD | C12: =SUM(Jul!C12, Aug!C12, Sep!C12) -> 0 | D12: =SUM(Jul!D12, Aug!D12, Sep!D12) -> 0 | E12: =IF(AND(ISNUMBER(C12),ISNUMBER(D12)), C12-D12, "") -> 0 | F12: =IFERROR(E12/D12, "") | G12: =SUM(Jul!G12, Aug!G12, Sep!G12) -> 0 | H12: =SUM(Jul!H12, Aug!H12, Sep!H12) -> 0 | I12: =IFERROR(H12/G12, "")
A13: Kohls - Granite Run | B13: PA | C13: =SUM(Jul!C13, Aug!C13, Sep!C13) -> 0 | D13: =SUM(Jul!D13, Aug!D13, Sep!D13) -> 0 | E13: =IF(AND(ISNUMBER(C13),ISNUMBER(D13)), C13-D13, "") -> 0 | F13: =IFERROR(E13/D13, "") | G13: =SUM(Jul!G13, Aug!G13, Sep!G13) -> 0 | H13: =SUM(Jul!H13, Aug!H13, Sep!H13) -> 0 | I13: =IFERROR(H13/G13, "")
A14: Kohls - Greece | B14: NY | C14: =SUM(Jul!C14, Aug!C14, Sep!C14) -> 0 | D14: =SUM(Jul!D14, Aug!D14, Sep!D14) -> 0 | E14: =IF(AND(ISNUMBER(C14),ISNUMBER(D14)), C14-D14, "") -> 0 | F14: =IFERROR(E14/D14, "") | G14: =SUM(Jul!G14, Aug!G14, Sep!G14) -> 0 | H14: =SUM(Jul!H14, Aug!H14, Sep!H14) -> 0 | I14: =IFERROR(H14/G14, "")
A15: Kohls - Hanover | B15: PA | C15: =SUM(Jul!C15, Aug!C15, Sep!C15) -> 0 | D15: =SUM(Jul!D15, Aug!D15, Sep!D15) -> 0 | E15: =IF(AND(ISNUMBER(C15),ISNUMBER(D15)), C15-D15, "") -> 0 | F15: =IFERROR(E15/D15, "") | G15: =SUM(Jul!G15, Aug!G15, Sep!G15) -> 0 | H15: =SUM(Jul!H15, Aug!H15, Sep!H15) -> 0 | I15: =IFERROR(H15/G15, "")
A16: Kohls - Horsehead | B16: NY | C16: =SUM(Jul!C16, Aug!C16, Sep!C16) -> 0 | D16: =SUM(Jul!D16, Aug!D16, Sep!D16) -> 0 | E16: =IF(AND(ISNUMBER(C16),ISNUMBER(D16)), C16-D16, "") -> 0 | F16: =IFERROR(E16/D16, "") | G16: =SUM(Jul!G16, Aug!G16, Sep!G16) -> 0 | H16: =SUM(Jul!H16, Aug!H16, Sep!H16) -> 0 | I16: =IFERROR(H16/G16, "")
... A18: Kohls - Ithaca | B18: NY | C18: =SUM(Jul!C18, Aug!C18, Sep!C18) -> 0 | D18: =SUM(Jul!D18, Aug!D18, Sep!D18) -> 0 | E18: =IF(AND(ISNUMBER(C18),ISNUMBER(D18)), C18-D18, "") -> 0 | F18: =IFERROR(E18/D18, "") | G18: =SUM(Jul!G18, Aug!G18, Sep!G18) -> 0 | H18: =SUM(Jul!H18, Aug!H18, Sep!H18) -> 0 | I18: =IFERROR(H18/G18, "")
A19: Kohls - Kingston | B19: NY | C19: =SUM(Jul!C19, Aug!C19, Sep!C21) -> 0 | D19: =SUM(Jul!D19, Aug!D19, Sep!D21) -> 0 | E19: =IF(AND(ISNUMBER(C19),ISNUMBER(D19)), C19-D19, "") -> 0 | F19: =IFERROR(E19/D19, "") | G19: =SUM(Jul!G19, Aug!G19, Sep!G19) -> 0 | H19: =SUM(Jul!H19, Aug!H19, Sep!H21) -> 0 | I19: =IFERROR(H19/G19, "")
A20: Kohls - Mechanicsburg | B20: PA | C20: =SUM(Jul!C20, Aug!C20, Sep!C22) -> 0 | D20: =SUM(Jul!D20, Aug!D20, Sep!D22) -> 0 | E20: =IF(AND(ISNUMBER(C20),ISNUMBER(D20)), C20-D20, "") -> 0 | F20: =IFERROR(E20/D20, "") | G20: =SUM(Jul!G20, Aug!G20, Sep!G20) -> 0 | H20: =SUM(Jul!H20, Aug!H20, Sep!H22) -> 0 | I20: =IFERROR(H20/G20, "")
A21: Kohls - Middletown | B21: NJ | C21: =SUM(Jul!C21, Aug!C21, Sep!C23) -> 0 | D21: =SUM(Jul!D21, Aug!D21, Sep!D23) -> 0 | E21: =IF(AND(ISNUMBER(C21),ISNUMBER(D21)), C21-D21, "") -> 0 | F21: =IFERROR(E21/D21, "") | G21: =SUM(Jul!G21, Aug!G21, Sep!G21) -> 0 | H21: =SUM(Jul!H21, Aug!H21, Sep!H23) -> 0 | I21: =IFERROR(H21/G21, "")
A22: Kohls - North Amherst | B22: NY | C22: =SUM(Jul!C22, Aug!C22, Sep!C24) -> 0 | D22: =SUM(Jul!D22, Aug!D22, Sep!D24) -> 0 | E22: =IF(AND(ISNUMBER(C22),ISNUMBER(D22)), C22-D22, "") -> 0 | F22: =IFERROR(E22/D22, "") | G22: =SUM(Jul!G22, Aug!G22, Sep!G22) -> 0 | H22: =SUM(Jul!H22, Aug!H22, Sep!H24) -> 0 | I22: =IFERROR(H22/G22, "")
A23: Kohls - Staten Island | B23: NY | C23: =SUM(Jul!C23, Aug!C23, Sep!C25) -> 0 | D23: =SUM(Jul!D23, Aug!D23, Sep!D25) -> 0 | E23: =IF(AND(ISNUMBER(C23),ISNUMBER(D23)), C23-D23, "") -> 0 | F23: =IFERROR(E23/D23, "") | G23: =SUM(Jul!G23, Aug!G23, Sep!G23) -> 0 | H23: =SUM(Jul!H23, Aug!H23, Sep!H25) -> 0 | I23: =IFERROR(H23/G23, "")
A24: Kohls - Warminster | B24: PA | C24: =SUM(Jul!C24, Aug!C24, Sep!C26) -> 0 | D24: =SUM(Jul!D24, Aug!D24, Sep!D26) -> 0 | E24: =IF(AND(ISNUMBER(C24),ISNUMBER(D24)), C24-D24, "") -> 0 | F24: =IFERROR(E24/D24, "") | G24: =SUM(Jul!G24, Aug!G24, Sep!G24) -> 0 | H24: =SUM(Jul!H24, Aug!H24, Sep!H26) -> 0 | I24: =IFERROR(H24/G24, "")
A25: Kohls - Waterbury | B25: CT | C25: =SUM(Jul!C25, Aug!C25, Sep!C27) -> 0 | D25: =SUM(Jul!D25, Aug!D25, Sep!D27) -> 0 | E25: =IF(AND(ISNUMBER(C25),ISNUMBER(D25)), C25-D25, "") -> 0 | F25: =IFERROR(E25/D25, "") | G25: =SUM(Jul!G25, Aug!G25, Sep!G27) -> 0 | H25: =SUM(Jul!H25, Aug!H25, Sep!H27) -> 0 | I25: =IFERROR(H25/G25, "")
A26: Mojave Water Agency - Headquarters | B26: CA | C26: =SUM(Jul!C26, Aug!C26, Sep!C28) -> 0 | D26: =SUM(Jul!D26, Aug!D26, Sep!D28) -> 0 | E26: =IF(AND(ISNUMBER(C26),ISNUMBER(D26)), C26-D26, "") -> 0 | F26: =IFERROR(E26/D26, "") | G26: =SUM(Jul!G26, Aug!G26, Sep!G26) -> 0 | H26: =SUM(Jul!H26, Aug!H26, Sep!H28) -> 0 | I26: =IFERROR(H26/G26, "")
A27: CSU - Bakersfield | B27: CA | C27: =SUM(Jul!C27, Aug!C27, Sep!C29) -> 0 | D27: =SUM(Jul!D27, Aug!D27, Sep!D29) -> 0 | E27: =IF(AND(ISNUMBER(C27),ISNUMBER(D27)), C27-D27, "") -> 0 | F27: =IFERROR(E27/D27, "") | G27: =SUM(Jul!G27, Aug!G27, Sep!G29) -> 0 | H27: =SUM(Jul!H27, Aug!H27, Sep!H29) -> 0 | I27: =IFERROR(H27/G27, "")
A28: Greenfield USD - Fairfield ES | B28: CA | C28: =SUM(Jul!C28, Aug!C28, Sep!C30) -> 0 | D28: =SUM(Jul!D28, Aug!D28, Sep!D30) -> 0 | E28: =IF(AND(ISNUMBER(C28),ISNUMBER(D28)), C28-D28, "") -> 0 | F28: =IFERROR(E28/D28, "") | G28: =SUM(Jul!G28, Aug!G28, Sep!G28) -> 0 | H28: =SUM(Jul!H28, Aug!H28, Sep!H30) -> 0 | I28: =IFERROR(H28/G28, "")
A29: Greenfield USD - Granite Point ES | B29: CA | C29: =SUM(Jul!C29, Aug!C29, Sep!C31) -> 0 | D29: =SUM(Jul!D29, Aug!D29, Sep!D31) -> 0 | E29: =IF(AND(ISNUMBER(C29),ISNUMBER(D29)), C29-D29, "") -> 0 | F29: =IFERROR(E29/D29, "") | G29: =SUM(Jul!G29, Aug!G29, Sep!G29) -> 0 | H29: =SUM(Jul!H29, Aug!H29, Sep!H31) -> 0 | I29: =IFERROR(H29/G29, "")
A30: Greenfield USD - Greenfield MS | B30: CA | C30: =SUM(Jul!C30, Aug!C30, Sep!C32) -> 0 | D30: =SUM(Jul!D30, Aug!D30, Sep!D32) -> 0 | E30: =IF(AND(ISNUMBER(C30),ISNUMBER(D30)), C30-D30, "") -> 0 | F30: =IFERROR(E30/D30, "") | G30: =SUM(Jul!G30, Aug!G30, Sep!G30) -> 0 | H30: =SUM(Jul!H30, Aug!H30, Sep!H32) -> 0 | I30: =IFERROR(H30/G30, "")
A31: Greenfield USD - Horizon ES | B31: CA | C31: =SUM(Jul!C31, Aug!C31, Sep!C33) -> 0 | D31: =SUM(Jul!D31, Aug!D31, Sep!D33) -> 0 | E31: =IF(AND(ISNUMBER(C31),ISNUMBER(D31)), C31-D31, "") -> 0 | F31: =IFERROR(E31/D31, "") | G31: =SUM(Jul!G31, Aug!G31, Sep!G31) -> 0 | H31: =SUM(Jul!H31, Aug!H31, Sep!H33) -> 0 | I31: =IFERROR(H31/G31, "")
A32: Greenfield USD - McKee MS | B32: CA | C32: =SUM(Jul!C32, Aug!C32, Sep!C34) -> 0 | D32: =SUM(Jul!D32, Aug!D32, Sep!D34) -> 0 | E32: =IF(AND(ISNUMBER(C32),ISNUMBER(D32)), C32-D32, "") -> 0 | F32: =IFERROR(E32/D32, "") | G32: =SUM(Jul!G32, Aug!G32, Sep!G32) -> 0 | H32: =SUM(Jul!H32, Aug!H32, Sep!H34) -> 0 | I32: =IFERROR(H32/G32, "")
A33: Greenfield USD - Plantation ES | B33: CA | C33: =SUM(Jul!C33, Aug!C33, Sep!C35) -> 0 | D33: =SUM(Jul!D33, Aug!D33, Sep!D35) -> 0 | E33: =IF(AND(ISNUMBER(C33),ISNUMBER(D33)), C33-D33, "") -> 0 | F33: =IFERROR(E33/D33, "") | G33: =SUM(Jul!G33, Aug!G33, Sep!G33) -> 0 | H33: =SUM(Jul!H33, Aug!H33, Sep!H35) -> 0 | I33: =IFERROR(H33/G33, "")
A34: Greenfield USD - Planz ES | B34: CA | C34: =SUM(Jul!C34, Aug!C34, Sep!C36) -> 0 | D34: =SUM(Jul!D34, Aug!D34, Sep!D36) -> 0 | E34: =IF(AND(ISNUMBER(C34),ISNUMBER(D34)), C34-D34, "") -> 0 | F34: =IFERROR(E34/D34, "") | G34: =SUM(Jul!G34, Aug!G34, Sep!G34) -> 0 | H34: =SUM(Jul!H34, Aug!H34, Sep!H36) -> 0 | I34: =IFERROR(H34/G34, "")
A35: Greenfield USD - Raffaello Palla ES | B35: CA | C35: =SUM(Jul!C35, Aug!C35, Sep!C37) -> 0 | D35: =SUM(Jul!D35, Aug!D35, Sep!D37) -> 0 | E35: =IF(AND(ISNUMBER(C35),ISNUMBER(D35)), C35-D35, "") -> 0 | F35: =IFERROR(E35/D35, "") | G35: =SUM(Jul!G35, Aug!G35, Sep!G35) -> 0 | H35: =SUM(Jul!H35, Aug!H35, Sep!H37) -> 0 | I35: =IFERROR(H35/G35, "")
A36: Greenfield USD - Valle Verde ES | B36: CA | C36: =SUM(Jul!C36, Aug!C36, Sep!C38) -> 0 | D36: =SUM(Jul!D36, Aug!D36, Sep!D38) -> 0 | E36: =IF(AND(ISNUMBER(C36),ISNUMBER(D36)), C36-D36, "") -> 0 | F36: =IFERROR(E36/D36, "") | G36: =SUM(Jul!G36, Aug!G36, Sep!G36) -> 0 | H36: =SUM(Jul!H36, Aug!H36, Sep!H38) -> 0 | I36: =IFERROR(H36/G36, "")
A37: Greenfield USD - W.A. Kendrick ES | B37: CA | C37: =SUM(Jul!C37, Aug!C37, Sep!C39) -> 0 | D37: =SUM(Jul!D37, Aug!D37, Sep!D39) -> 0 | E37: =IF(AND(ISNUMBER(C37),ISNUMBER(D37)), C37-D37, "") -> 0 | F37: =IFERROR(E37/D37, "") | G37: =SUM(Jul!G37, Aug!G37, Sep!G37) -> 0 | H37: =SUM(Jul!H37, Aug!H37, Sep!H39) -> 0 | I37: =IFERROR(H37/G37, "")
A38: Muroc Joint USD - Boron HS | B38: CA | C38: =SUM(Jul!C38, Aug!C38, Sep!C40) -> 0 | D38: =SUM(Jul!D38, Aug!D38, Sep!D40) -> 0 | E38: =IF(AND(ISNUMBER(C38),ISNUMBER(D38)), C38-D38, "") -> 0 | F38: =IFERROR(E38/D38, "") | G38: =SUM(Jul!G38, Aug!G38, Sep!G40) -> 0 | H38: =SUM(Jul!H38, Aug!H38, Sep!H40) -> 0 | I38: =IFERROR(H38/G38, "")
A39: Muroc Joint USD - W. Boron ES | B39: CA | C39: =SUM(Jul!C39, Aug!C39, Sep!C41) -> 0 | D39: =SUM(Jul!D39, Aug!D39, Sep!D41) -> 0 | E39: =IF(AND(ISNUMBER(C39),ISNUMBER(D39)), C39-D39, "") -> 0 | F39: =IFERROR(E39/D39, "") | G39: =SUM(Jul!G39, Aug!G39, Sep!G41) -> 0 | H39: =SUM(Jul!H39, Aug!H39, Sep!H41) -> 0 | I39: =IFERROR(H39/G39, "")
A40: Colusa - WTP | B40: CA | C40: =SUM(Jul!C40, Aug!C40, Sep!C42) -> 0 | D40: =SUM(Jul!D40, Aug!D40, Sep!D42) -> 0 | E40: =IF(AND(ISNUMBER(C40),ISNUMBER(D40)), C40-D40, "") -> 0 | F40: =IFERROR(E40/D40, "") | G40: =SUM(Jul!G40, Aug!G40, Sep!G42) -> 0 | H40: =SUM(Jul!H40, Aug!H40, Sep!H42) -> 0 | I40: =IFERROR(H40/G40, "")
A41: CDCR-North Kern State Prision | B41: CA | C41: =SUM(Jul!C41, Aug!C41, Sep!C43) -> 0 | D41: =SUM(Jul!D41, Aug!D41, Sep!D43) -> 0 | E41: =IF(AND(ISNUMBER(C41),ISNUMBER(D41)), C41-D41, "") -> 0 | F41: =IFERROR(E41/D41, "") | G41: =SUM(Jul!G41, Aug!G41, Sep!G43) -> 0 | H41: =SUM(Jul!H41, Aug!H41, Sep!H43) -> 0 | I41: =IFERROR(H41/G41, "")
...

Sheet 4th Qtr
A1: {=portfolio} -> Silicon Ranch | D1: 4th Quarter Actual v. Expected | G1: 4th Quarter Actual v. Forecasted
A2: Total | C2: =SUM(C4:C100) -> 0 | D2: =SUM(D4:D100) -> 0 | E2: =C2-D2 -> 0 | F2: =IFERROR(E2/D2, 0) -> 0 | G2: =SUM(G4:G100) -> 0 | H2: =C2-G2 -> 0 | I2: =IFERROR(H2/G2, 0) -> 0
A3: Site | B3: State | C3: Actual | D3: Expected | E3: Delta | F3: % | G3: Forecasted | H3: Delta | I3: %
A4: {=Sites[Site]} -> Iron Mountain - Windsor | B4: {=Sites[State]} -> CT | C4: =SUM(Oct!C4, Nov!C4, Dec!C4) -> 0 | D4: =SUM(Oct!D4, Nov!D4, Dec!D4) -> 0 | E4: =IF(AND(ISNUMBER(C4),ISNUMBER(D4)), C4-D4, "") -> 0 | F4: =IFERROR(E4/D4, "") | G4: =SUM(Oct!G4,Nov!G4,Dec!G4) -> 0 | H4: =SUM(Oct!H4, Nov!H4, Dec!H4) -> 0 | I4: =IFERROR(H4/G4, "")
A5: Kohls - Auburn | B5: NY | C5: =SUM(Oct!C5, Nov!C5, Dec!C5) -> 0 | D5: =SUM(Oct!D5, Nov!D5, Dec!D5) -> 0 | E5: =IF(AND(ISNUMBER(C5),ISNUMBER(D5)), C5-D5, "") -> 0 | F5: =IFERROR(E5/D5, "") | G5: =SUM(Oct!G5,Nov!G5,Dec!G5) -> 0 | H5: =SUM(Oct!H5, Nov!H5, Dec!H5) -> 0 | I5: =IFERROR(H5/G5, "")
A6: Kohls - Bensalem | B6: PA | C6: =SUM(Oct!C6, Nov!C6, Dec!C6) -> 0 | D6: =SUM(Oct!D6, Nov!D6, Dec!D6) -> 0 | E6: =IF(AND(ISNUMBER(C6),ISNUMBER(D6)), C6-D6, "") -> 0 | F6: =IFERROR(E6/D6, "") | G6: =SUM(Oct!G6,Nov!G6,Dec!G6) -> 0 | H6: =SUM(Oct!H6, Nov!H6, Dec!H6) -> 0 | I6: =IFERROR(H6/G6, "")
A7: Kohls - Brick | B7: NJ | C7: =SUM(Oct!C7, Nov!C7, Dec!C7) -> 0 | D7: =SUM(Oct!D7, Nov!D7, Dec!D7) -> 0 | E7: =IF(AND(ISNUMBER(C7),ISNUMBER(D7)), C7-D7, "") -> 0 | F7: =IFERROR(E7/D7, "") | G7: =SUM(Oct!G7,Nov!G7,Dec!G7) -> 0 | H7: =SUM(Oct!H7, Nov!H7, Dec!H7) -> 0 | I7: =IFERROR(H7/G7, "")
A8: Kohls - Buffalo | B8: NY | C8: =SUM(Oct!C8, Nov!C8, Dec!C8) -> 0 | D8: =SUM(Oct!D8, Nov!D8, Dec!D8) -> 0 | E8: =IF(AND(ISNUMBER(C8),ISNUMBER(D8)), C8-D8, "") -> 0 | F8: =IFERROR(E8/D8, "") | G8: =SUM(Oct!G8,Nov!G8,Dec!G8) -> 0 | H8: =SUM(Oct!H8, Nov!H8, Dec!H8) -> 0 | I8: =IFERROR(H8/G8, "")
A9: Kohls - Canton | B9: CT | C9: =SUM(Oct!C9, Nov!C9, Dec!C9) -> 0 | D9: =SUM(Oct!D9, Nov!D9, Dec!D9) -> 0 | E9: =IF(AND(ISNUMBER(C9),ISNUMBER(D9)), C9-D9, "") -> 0 | F9: =IFERROR(E9/D9, "") | G9: =SUM(Oct!G9,Nov!G9,Dec!G9) -> 0 | H9: =SUM(Oct!H9, Nov!H9, Dec!H9) -> 0 | I9: =IFERROR(H9/G9, "")
A10: Kohls - East Amherst | B10: NY | C10: =SUM(Oct!C10, Nov!C10, Dec!C10) -> 0 | D10: =SUM(Oct!D10, Nov!D10, Dec!D10) -> 0 | E10: =IF(AND(ISNUMBER(C10),ISNUMBER(D10)), C10-D10, "") -> 0 | F10: =IFERROR(E10/D10, "") | G10: =SUM(Oct!G10,Nov!G10,Dec!G10) -> 0 | H10: =SUM(Oct!H10, Nov!H10, Dec!H10) -> 0 | I10: =IFERROR(H10/G10, "")
A11: Kohls - East Brunswick | B11: NJ | C11: =SUM(Oct!C11, Nov!C11, Dec!C11) -> 0 | D11: =SUM(Oct!D11, Nov!D11, Dec!D11) -> 0 | E11: =IF(AND(ISNUMBER(C11),ISNUMBER(D11)), C11-D11, "") -> 0 | F11: =IFERROR(E11/D11, "") | G11: =SUM(Oct!G11,Nov!G11,Dec!G11) -> 0 | H11: =SUM(Oct!H11, Nov!H11, Dec!H11) -> 0 | I11: =IFERROR(H11/G11, "")
A12: Kohls - Edgewood | B12: MD | C12: =SUM(Oct!C12, Nov!C12, Dec!C12) -> 0 | D12: =SUM(Oct!D12, Nov!D12, Dec!D12) -> 0 | E12: =IF(AND(ISNUMBER(C12),ISNUMBER(D12)), C12-D12, "") -> 0 | F12: =IFERROR(E12/D12, "") | G12: =SUM(Oct!G12,Nov!G12,Dec!G12) -> 0 | H12: =SUM(Oct!H12, Nov!H12, Dec!H12) -> 0 | I12: =IFERROR(H12/G12, "")
A13: Kohls - Granite Run | B13: PA | C13: =SUM(Oct!C13, Nov!C13, Dec!C13) -> 0 | D13: =SUM(Oct!D13, Nov!D13, Dec!D13) -> 0 | E13: =IF(AND(ISNUMBER(C13),ISNUMBER(D13)), C13-D13, "") -> 0 | F13: =IFERROR(E13/D13, "") | G13: =SUM(Oct!G13,Nov!G13,Dec!G13) -> 0 | H13: =SUM(Oct!H13, Nov!H13, Dec!H13) -> 0 | I13: =IFERROR(H13/G13, "")
A14: Kohls - Greece | B14: NY | C14: =SUM(Oct!C14, Nov!C14, Dec!C14) -> 0 | D14: =SUM(Oct!D14, Nov!D14, Dec!D14) -> 0 | E14: =IF(AND(ISNUMBER(C14),ISNUMBER(D14)), C14-D14, "") -> 0 | F14: =IFERROR(E14/D14, "") | G14: =SUM(Oct!G14,Nov!G14,Dec!G14) -> 0 | H14: =SUM(Oct!H14, Nov!H14, Dec!H14) -> 0 | I14: =IFERROR(H14/G14, "")
A15: Kohls - Hanover | B15: PA | C15: =SUM(Oct!C15, Nov!C15, Dec!C15) -> 0 | D15: =SUM(Oct!D15, Nov!D15, Dec!D15) -> 0 | E15: =IF(AND(ISNUMBER(C15),ISNUMBER(D15)), C15-D15, "") -> 0 | F15: =IFERROR(E15/D15, "") | G15: =SUM(Oct!G15,Nov!G15,Dec!G15) -> 0 | H15: =SUM(Oct!H15, Nov!H15, Dec!H15) -> 0 | I15: =IFERROR(H15/G15, "")
A16: Kohls - Horsehead | B16: NY | C16: =SUM(Oct!C16, Nov!C16, Dec!C16) -> 0 | D16: =SUM(Oct!D16, Nov!D16, Dec!D16) -> 0 | E16: =IF(AND(ISNUMBER(C16),ISNUMBER(D16)), C16-D16, "") -> 0 | F16: =IFERROR(E16/D16, "") | G16: =SUM(Oct!G16,Nov!G16,Dec!G16) -> 0 | H16: =SUM(Oct!H16, Nov!H16, Dec!H16) -> 0 | I16: =IFERROR(H16/G16, "")
... A68: Snowline SD - Vista Verde ES | B68: CA | C68: =SUM(Oct!C68, Nov!C68, Dec!C68) -> 0 | D68: =SUM(Oct!D68, Nov!D68, Dec!D68) -> 0 | E68: =IF(AND(ISNUMBER(C68),ISNUMBER(D68)), C68-D68, "") -> 0 | F68: =IFERROR(E68/D68, "") | G68: =SUM(Oct!G68,Nov!G68,Dec!G68) -> 0 | H68: =SUM(Oct!H68, Nov!H68, Dec!H68) -> 0 | I68: =IFERROR(H68/G68, "")
A69: North Stonington | B69: CT

Sheet Jan
A1: {=portfolio} -> Silicon Ranch | D1: January Actual v. Expected | G1: January Actual v. Forecasted
A2: Total | C2: =SUM(C4:C99) -> 2371481 | D2: =SUM(D4:D99) -> 0 | E2: =C2-D2 -> 2371481 | F2: =IFERROR(E2/D2, 0) -> 0 | G2: =SUM(G4:G99) -> 2199066.1 | H2: =C2-G2 -> 172414.94 | I2: =IFERROR(H2/G2, 0) -> 0.078403711 | J2: =IF(AND(TODAY()>DATE(2024, 1, 1), COUNTA(Sites[Site])<>(COUNT(C:C)-1)), "Some sites are missing actual data; if new sites were added, make sure they are aligned correctly (including prior months!)", "")
A3: Site | B3: State | C3: Actual | D3: Expected | E3: Delta | F3: % | G3: Forecasted | H3: Delta | I3: % | J3: Notes | K3: Service Requests
A4: {=Sites[Site]} -> Iron Mountain - Windsor | B4: {=Sites[State]} -> CT | C4: 13219 | D4: N/A | E4: =IF(AND(ISNUMBER(C4),ISNUMBER(D4)), C4-D4, "") | F4: =IFERROR(E4/D4, "") | G4: 12931.18 | H4: =IF(AND(ISNUMBER(C4),ISNUMBER(G4)), C4-G4, "") -> 287.82 | I4: =IFERROR(H4/G4, "") -> 0.02225783
A5: Kohls - Auburn | B5: NY | C5: 5600 | D5: N/A | E5: =IF(AND(ISNUMBER(C5),ISNUMBER(D5)), C5-D5, "") | F5: =IFERROR(E5/D5, "") | G5: 4748.53 | H5: =IF(AND(ISNUMBER(C5),ISNUMBER(G5)), C5-G5, "") -> 851.47 | I5: =IFERROR(H5/G5, "") -> 0.17931233
A6: Kohls - Bensalem | B6: PA | C6: 16129 | D6: N/A | E6: =IF(AND(ISNUMBER(C6),ISNUMBER(D6)), C6-D6, "") | F6: =IFERROR(E6/D6, "") | G6: 15644.12 | H6: =IF(AND(ISNUMBER(C6),ISNUMBER(G6)), C6-G6, "") -> 484.88 | I6: =IFERROR(H6/G6, "") -> 0.030994393
A7: Kohls - Brick | B7: NJ | C7: 22439 | D7: N/A | E7: =IF(AND(ISNUMBER(C7),ISNUMBER(D7)), C7-D7, "") | F7: =IFERROR(E7/D7, "") | G7: 16579.62 | H7: =IF(AND(ISNUMBER(C7),ISNUMBER(G7)), C7-G7, "") -> 5859.38 | I7: =IFERROR(H7/G7, "") -> 0.35340858 | J7: 1.Inverter tripped offline at 12:25PM on 01/20 due to Asymetrical Array fault and back online on 01/21. | K7: 1.SR094211
A8: Kohls - Buffalo | B8: NY | C8: 4465 | D8: N/A | E8: =IF(AND(ISNUMBER(C8),ISNUMBER(D8)), C8-D8, "") | F8: =IFERROR(E8/D8, "") | G8: 7988.27 | H8: =IF(AND(ISNUMBER(C8),ISNUMBER(G8)), C8-G8, "") -> -3523.27 | I8: =IFERROR(H8/G8, "") -> -0.44105545 | J8: 1.Inverters 7 and 8 are offline from 12/03, due to Grid contactor Open fault and after reset done by technician inverter 7 was back online at 14:25 and inverter 8 was back online at 15:40 on 01/31/25. 2.Inverter 4 tripped offline from 13:35 on 12/30, due to Grid contactor Open fault through out the month. | K8: 1.SR093917, SR096145 2.SR095177 | L8: SR096145 | M8: SR095177
A9: Kohls - Canton | B9: CT | C9: 5915 | D9: N/A | E9: =IF(AND(ISNUMBER(C9),ISNUMBER(D9)), C9-D9, "") | F9: =IFERROR(E9/D9, "") | G9: 5796.5 | H9: =IF(AND(ISNUMBER(C9),ISNUMBER(G9)), C9-G9, "") -> 118.5 | I9: =IFERROR(H9/G9, "") -> 0.020443371
A10: Kohls - East Amherst | B10: NY | C10: 5604 | D10: N/A | E10: =IF(AND(ISNUMBER(C10),ISNUMBER(D10)), C10-D10, "") | F10: =IFERROR(E10/D10, "") | G10: 8423.32 | H10: =IF(AND(ISNUMBER(C10),ISNUMBER(G10)), C10-G10, "") -> -2819.32 | I10: =IFERROR(H10/G10, "") -> -0.33470413 | J10: 1.Low generation due to weather/snow.
A11: Kohls - East Brunswick | B11: NJ | C11: 21858 | D11: N/A | E11: =IF(AND(ISNUMBER(C11),ISNUMBER(D11)), C11-D11, "") | F11: =IFERROR(E11/D11, "") | G11: 23131.39 | H11: =IF(AND(ISNUMBER(C11),ISNUMBER(G11)), C11-G11, "") -> -1273.39 | I11: =IFERROR(H11/G11, "") -> -0.055050302
A12: Kohls - Edgewood | B12: MD | C12: 95387 | D12: N/A | E12: =IF(AND(ISNUMBER(C12),ISNUMBER(D12)), C12-D12, "") | F12: =IFERROR(E12/D12, "") | G12: 135284.96 | H12: =IF(AND(ISNUMBER(C12),ISNUMBER(G12)), C12-G12, "") -> -39897.96 | I12: =IFERROR(H12/G12, "") -> -0.29491793 | J12: 1.Low generation due to weather/snow.
A13: Kohls - Granite Run | B13: PA | C13: 12350 | D13: N/A | E13: =IF(AND(ISNUMBER(C13),ISNUMBER(D13)), C13-D13, "") | F13: =IFERROR(E13/D13, "") | G13: 15908.81 | H13: =IF(AND(ISNUMBER(C13),ISNUMBER(G13)), C13-G13, "") -> -3558.81 | I13: =IFERROR(H13/G13, "") -> -0.22370058 | J13: 1.Low generation due to weather/snow.
A14: Kohls - Greece | B14: NY | C14: 5278 | D14: N/A | E14: =IF(AND(ISNUMBER(C14),ISNUMBER(D14)), C14-D14, "") | F14: =IFERROR(E14/D14, "") | G14: 9358.21 | H14: =IF(AND(ISNUMBER(C14),ISNUMBER(G14)), C14-G14, "") -> -4080.21 | I14: =IFERROR(H14/G14, "") -> -0.43600325 | J14: 1.Low generation due to weather/snow.
A15: Kohls - Hanover | B15: PA | C15: 13440 | D15: N/A | E15: =IF(AND(ISNUMBER(C15),ISNUMBER(D15)), C15-D15, "") | F15: =IFERROR(E15/D15, "") | G15: 18746.47 | H15: =IF(AND(ISNUMBER(C15),ISNUMBER(G15)), C15-G15, "") -> -5306.47 | I15: =IFERROR(H15/G15, "") -> -0.28306503 | J15: 1.Inverter was offline on 01/22 and back online on 01/23. | K15: 1.SR095860
A16: Kohls - Horsehead | B16: NY | C16: 10616 | D16: N/A | E16: =IF(AND(ISNUMBER(C16),ISNUMBER(D16)), C16-D16, "") | F16: =IFERROR(E16/D16, "") | G16: 12681.26 | H16: =IF(AND(ISNUMBER(C16),ISNUMBER(G16)), C16-G16, "") -> -2065.26 | I16: =IFERROR(H16/G16, "") -> -0.16285921 | J16: 1.Inverter started late for its production at 12:15PM on 01/17 due to Idle State fault. | K16: 1.SR095654
A17: Kohls - Hudson | B17: NY | C17: 11567 | D17: N/A | E17: =IF(AND(ISNUMBER(C17),ISNUMBER(D17)), C17-D17, "") | F17: =IFERROR(E17/D17, "") | G17: 12764.56 | H17: =IF(AND(ISNUMBER(C17),ISNUMBER(G17)), C17-G17, "") -> -1197.56 | I17: =IFERROR(H17/G17, "") -> -0.093819137
A18: Kohls - Ithaca | B18: NY | C18: 9275 | D18: N/A | E18: =IF(AND(ISNUMBER(C18),ISNUMBER(D18)), C18-D18, "") | F18: =IFERROR(E18/D18, "") | G18: 11829.67 | H18: =IF(AND(ISNUMBER(C18),ISNUMBER(G18)), C18-G18, "") -> -2554.67 | I18: =IFERROR(H18/G18, "") -> -0.21595446 | J18: 1.Low generation due to weather/snow.
A19: Kohls - Kingston | B19: NY | C19: 18271 | D19: N/A | E19: =IF(AND(ISNUMBER(C19),ISNUMBER(D19)), C19-D19, "") | F19: =IFERROR(E19/D19, "") | G19: 22224.6 | H19: =IF(AND(ISNUMBER(C19),ISNUMBER(G19)), C19-G19, "") -> -3953.6 | I19: =IFERROR(H19/G19, "") -> -0.17789297 | J19: 1.Low generation due to weather/snow.
A20: Kohls - Mechanicsburg | B20: PA | C20: 15891 | D20: N/A | E20: =IF(AND(ISNUMBER(C20),ISNUMBER(D20)), C20-D20, "") | F20: =IFERROR(E20/D20, "") | G20: 21467.31 | H20: =IF(AND(ISNUMBER(C20),ISNUMBER(G20)), C20-G20, "") -> -5576.31 | I20: =IFERROR(H20/G20, "") -> -0.25975821 | J20: 1.Low generation due to weather/snow.
A21: Kohls - Middletown | B21: NJ | C21: 26770 | D21: N/A | E21: =IF(AND(ISNUMBER(C21),ISNUMBER(D21)), C21-D21, "") | F21: =IFERROR(E21/D21, "") | G21: 29428.37 | H21: =IF(AND(ISNUMBER(C21),ISNUMBER(G21)), C21-G21, "") -> -2658.37 | I21: =IFERROR(H21/G21, "") -> -0.090333579
A22: Kohls - North Amherst | B22: NY | C22: 0 | D22: N/A | E22: =IF(AND(ISNUMBER(C22),ISNUMBER(D22)), C22-D22, "") | F22: =IFERROR(E22/D22, "") | G22: 6479.47 | H22: =IF(AND(ISNUMBER(C22),ISNUMBER(G22)), C22-G22, "") -> -6479.47 | I22: =IFERROR(H22/G22, "") -> -1 | J22: 1. Site tripped offline at 09:30am from 08/12/24, due to system removal for roof repair and to start rebuilding the roof. | K22: 1.SR093440,SR093861 | L22: SR093861
A23: Kohls - Staten Island | B23: NY | C23: 10433 | D23: N/A | E23: =IF(AND(ISNUMBER(C23),ISNUMBER(D23)), C23-D23, "") | F23: =IFERROR(E23/D23, "") | G23: 15368.35 | H23: =IF(AND(ISNUMBER(C23),ISNUMBER(G23)), C23-G23, "") -> -4935.35 | I23: =IFERROR(H23/G23, "") -> -0.32113727 | J23: 1. Site tripped offline at 09:05Am on 08/17/24 due to roof replacement and back online at 14:25 on 01/09/25 after technician site walkthrough. 2. Inverter 7 tripped offline at 15:20 from 01/10. Inverter 8 was offline due to Internal hardware “Error E018” fault till date. Inverter 20 was offline from 07/22/24 due to Internal Error -E018 fault. Inverter 21 was tripped offline at 09:05Am on 08/17/24 due to Internal Error - E018 fault. | K23: 1.SR089189 2.SR095623,SR078720 &SR087994 | L23: SR095623 | M23: SR078720 | N23: SR087994
A24: Kohls - Warminster | B24: PA | C24: 16958 | D24: N/A | E24: =IF(AND(ISNUMBER(C24),ISNUMBER(D24)), C24-D24, "") | F24: =IFERROR(E24/D24, "") | G24: 19404.55 | H24: =IF(AND(ISNUMBER(C24),ISNUMBER(G24)), C24-G24, "") -> -2446.55 | I24: =IFERROR(H24/G24, "") -> -0.12608125 | J24: 1.Site was offline on 01/30, 01/31 technician checked-in and confirmed that cell modem is offline due to error and need to be replaced. | K24: 1.SR093127
A25: Kohls - Waterbury | B25: CT | C25: 15637 | D25: N/A | E25: =IF(AND(ISNUMBER(C25),ISNUMBER(D25)), C25-D25, "") | F25: =IFERROR(E25/D25, "") | G25: 15296.56 | H25: =IF(AND(ISNUMBER(C25),ISNUMBER(G25)), C25-G25, "") -> 340.44 | I25: =IFERROR(H25/G25, "") -> 0.022255984
A26: Mojave Water Agency - Headquarters | B26: CA | C26: 26762 | D26: N/A | E26: =IF(AND(ISNUMBER(C26),ISNUMBER(D26)), C26-D26, "") | F26: =IFERROR(E26/D26, "") | G26: 25853.48 | H26: =IF(AND(ISNUMBER(C26),ISNUMBER(G26)), C26-G26, "") -> 908.52 | I26: =IFERROR(H26/G26, "") -> 0.035141111
A27: CSU - Bakersfield | B27: CA | C27: 78098 | D27: N/A | E27: =IF(AND(ISNUMBER(C27),ISNUMBER(D27)), C27-D27, "") | F27: =IFERROR(E27/D27, "") | G27: 60631.17 | H27: =IF(AND(ISNUMBER(C27),ISNUMBER(G27)), C27-G27, "") -> 17466.83 | I27: =IFERROR(H27/G27, "") -> 0.28808334
A28: Greenfield USD - Fairfield ES | B28: CA | C28: 9460 | D28: N/A | E28: =IF(AND(ISNUMBER(C28),ISNUMBER(D28)), C28-D28, "") | F28: =IFERROR(E28/D28, "") | G28: 6747.91 | H28: =IF(AND(ISNUMBER(C28),ISNUMBER(G28)), C28-G28, "") -> 2712.09 | I28: =IFERROR(H28/G28, "") -> 0.40191556
A29: Greenfield USD - Granite Point ES | B29: CA | C29: 26793 | D29: N/A | E29: =IF(AND(ISNUMBER(C29),ISNUMBER(D29)), C29-D29, "") | F29: =IFERROR(E29/D29, "") | G29: 17651.94 | H29: =IF(AND(ISNUMBER(C29),ISNUMBER(G29)), C29-G29, "") -> 9141.06 | I29: =IFERROR(H29/G29, "") -> 0.51785016
A30: Greenfield USD - Greenfield MS | B30: CA | C30: 14901 | D30: N/A | E30: =IF(AND(ISNUMBER(C30),ISNUMBER(D30)), C30-D30, "") | F30: =IFERROR(E30/D30, "") | G30: 3998.76 | H30: =IF(AND(ISNUMBER(C30),ISNUMBER(G30)), C30-G30, "") -> 10902.24 | I30: =IFERROR(H30/G30, "") -> 2.7264052 | J30: 1. Inverter 1 is still not communicating, and as of 01/27/25, production is not being recorded at the meter. It may be offline due to the need for a new MOXA device | K30: 1. SR089763
A31: Greenfield USD - Horizon ES | B31: CA | C31: 22359 | D31: N/A | E31: =IF(AND(ISNUMBER(C31),ISNUMBER(D31)), C31-D31, "") | F31: =IFERROR(E31/D31, "") | G31: 17883.35 | H31: =IF(AND(ISNUMBER(C31),ISNUMBER(G31)), C31-G31, "") -> 4475.65 | I31: =IFERROR(H31/G31, "") -> 0.25026911 | J31: 1. Inverter 2 Pad B back online at 12:50 on 01/02/25 after the technician replaced the faulty capacitors. 2. Inverter 1 Pad A started production late at 11:10 AM on 01/30/25 due to an AC overvoltage fault. | K31: 1. SR089669 2. SR096157 | L31: SR096157
A32: Greenfield USD - McKee MS | B32: CA | C32: 10808 | D32: N/A | E32: =IF(AND(ISNUMBER(C32),ISNUMBER(D32)), C32-D32, "") | F32: =IFERROR(E32/D32, "") | G32: 10950.31 | H32: =IF(AND(ISNUMBER(C32),ISNUMBER(G32)), C32-G32, "") -> -142.31 | I32: =IFERROR(H32/G32, "") -> -0.012995979
A33: Greenfield USD - Plantation ES | B33: CA | C33: 10716 | D33: N/A | E33: =IF(AND(ISNUMBER(C33),ISNUMBER(D33)), C33-D33, "") | F33: =IFERROR(E33/D33, "") | G33: 7840.16 | H33: =IF(AND(ISNUMBER(C33),ISNUMBER(G33)), C33-G33, "") -> 2875.84 | I33: =IFERROR(H33/G33, "") -> 0.36680884
A34: Greenfield USD - Planz ES | B34: CA | C34: 3658 | D34: N/A | E34: =IF(AND(ISNUMBER(C34),ISNUMBER(D34)), C34-D34, "") | F34: =IFERROR(E34/D34, "") | G34: 8710.27 | H34: =IF(AND(ISNUMBER(C34),ISNUMBER(G34)), C34-G34, "") -> -5052.27 | I34: =IFERROR(H34/G34, "") -> -0.58003598 | J34: 1.Low generation due to weather/snow.
A35: Greenfield USD - Raffaello Palla ES | B35: CA | C35: 25273 | D35: N/A | E35: =IF(AND(ISNUMBER(C35),ISNUMBER(D35)), C35-D35, "") | F35: =IFERROR(E35/D35, "") | G35: 19790.17 | H35: =IF(AND(ISNUMBER(C35),ISNUMBER(G35)), C35-G35, "") -> 5482.83 | I35: =IFERROR(H35/G35, "") -> 0.27704815
A36: Greenfield USD - Valle Verde ES | B36: CA | C36: 27972 | D36: N/A | E36: =IF(AND(ISNUMBER(C36),ISNUMBER(D36)), C36-D36, "") | F36: =IFERROR(E36/D36, "") | G36: 18660.89 | H36: =IF(AND(ISNUMBER(C36),ISNUMBER(G36)), C36-G36, "") -> 9311.11 | I36: =IFERROR(H36/G36, "") -> 0.49896388
A37: Greenfield USD - W.A. Kendrick ES | B37: CA | C37: 4765 | D37: N/A | E37: =IF(AND(ISNUMBER(C37),ISNUMBER(D37)), C37-D37, "") | F37: =IFERROR(E37/D37, "") | G37: 7201.47 | H37: =IF(AND(ISNUMBER(C37),ISNUMBER(G37)), C37-G37, "") -> -2436.47 | I37: =IFERROR(H37/G37, "") -> -0.33832954 | J37: 1.Meter reporting half of inverter production since 6/11/22 further repairs are requried. | K37: 1. SR094440
A38: Muroc Joint USD - Boron HS | B38: CA | C38: 0 | D38: N/A | E38: =IF(AND(ISNUMBER(C38),ISNUMBER(D38)), C38-D38, "") | F38: =IFERROR(E38/D38, "") | G38: 23613.12 | H38: =IF(AND(ISNUMBER(C38),ISNUMBER(G38)), C38-G38, "") -> -23613.12 | I38: =IFERROR(H38/G38, "") -> -1 | J38: 1. Site back communication at 9:15AM on 12/30/2024 and Inverter remains offline because of Inverter down hard - Power supply critical failure. 2. Weather station began reporting erroneous values on 12/30/2024, and the POA sensor needed to be replaced along with additional repairs. | K38: 1. SR092023, SR089707 2. SR093065 | L38: SR089707 | M38: SR093065
A39: Muroc Joint USD - W. Boron ES | B39: CA | C39: 9827 | D39: N/A | E39: =IF(AND(ISNUMBER(C39),ISNUMBER(D39)), C39-D39, "") | F39: =IFERROR(E39/D39, "") | G39: 8755.78 | H39: =IF(AND(ISNUMBER(C39),ISNUMBER(G39)), C39-G39, "") -> 1071.22 | I39: =IFERROR(H39/G39, "") -> 0.12234433
A40: Colusa - WTP | B40: CA | C40: 0 | D40: N/A | E40: =IF(AND(ISNUMBER(C40),ISNUMBER(D40)), C40-D40, "") | F40: =IFERROR(E40/D40, "") | G40: 17962.44 | H40: =IF(AND(ISNUMBER(C40),ISNUMBER(G40)), C40-G40, "") -> -17962.44 | I40: =IFERROR(H40/G40, "") -> -1 | J40: 1.No communication to DAS, need a replacement for meter and modem. | K40: 1.SR089464, SR093180, SR093174 & SR095356 | L40: SR093180 | M40: SR093174 | N40: SR095356
...

Sheet Feb
A1: {=portfolio} -> Silicon Ranch | D1: February Actual v. Expected | G1: February Actual v. Forecasted
A2: Total | C2: =SUM(C4:C100) -> 2644477 | D2: =SUM(D4:D100) -> 0 | E2: =C2-D2 -> 2644477 | F2: =IFERROR(E2/D2, 0) -> 0 | G2: =SUM(G4:G100) -> 2618498.3 | H2: =C2-G2 -> 25978.74 | I2: =IFERROR(H2/G2, 0) -> 0.0099212363 | J2: =IF(AND(TODAY()>DATE(2024, 2, 1), COUNTA(Sites[Site])<>(COUNT(C:C)-1)), "Some sites are missing actual data; if new sites were added, make sure they are aligned correctly (including prior months!)", "")
A3: Site | B3: State | C3: Actual | D3: Expected | E3: Delta | F3: % | G3: Forecasted | H3: Delta | I3: % | J3: Notes | K3: Service Requests
