Workbook
Name JanActual: #REF!
Name JanActual2: #REF!
Name JanExpected: #REF!
Name JanExpectedDelta: #REF!
Name JanExpectedPercent: #REF!
Name JanExpPercent: #REF!
Name JanForecasted: #REF!
Name JanForecastedDelta: #REF!
Name JanForecastedPercent: #REF!
Name portfolio: Sites!$B$1:$B$1
Name Year: Sites!#REF!

Sheet Year to Date
A1: {=portfolio} -> 38 DN | D1: Year to Date Actual v. Expected | G1: Year to Date Actual v. Forecasted
A2: Total | C2: =SUM(C4:C99) -> 1879993.2 | D2: =SUM(D4:D99) -> 3100330.9 | E2: =C2-D2 -> -1220337.6 | F2: =IFERROR(E2/D2, 0) -> -0.39361528 | G2: =SUM(G4:G99) -> 2316666 | H2: =C2-G2 -> -436672.78 | I2: =IFERROR(H2/G2, 0) -> -0.1884919
A3: Site | B3: State | C3: Actual | D3: Expected | E3: Delta | F3: % | G3: Forecasted | H3: Delta | I3: %
A4: {=Sites[Site]} -> 6th St. | B4: {=Sites[State]} -> CA | C4: =SUM('1st Qtr'!C4, '2nd Qtr'!C4, '3rd Qtr'!C4, '4th Qtr'!C4) -> 129016 | D4: =SUM('1st Qtr'!D4, '2nd Qtr'!D4, '3rd Qtr'!D4, '4th Qtr'!D4) -> 74840.77 | E4: =IF(AND(ISNUMBER(C4),ISNUMBER(D4)), C4-D4, "") -> 54175.23 | F4: =IFERROR(E4/D4, "") -> 0.72387323 | G4: =SUM('1st Qtr'!G4, '2nd Qtr'!G4, '3rd Qtr'!G4, '4th Qtr'!G4) -> 144521 | H4: =SUM('1st Qtr'!H4, '2nd Qtr'!H4, '3rd Qtr'!H4, '4th Qtr'!H4) -> -15505 | I4: =IFERROR(H4/G4, "") -> -0.10728545
A5: Barton Acres | B5: MA | C5: =SUM('1st Qtr'!C5, '2nd Qtr'!C5, '3rd Qtr'!C5, '4th Qtr'!C5) -> 56999 | D5: =SUM('1st Qtr'!D5, '2nd Qtr'!D5, '3rd Qtr'!D5, '4th Qtr'!D5) -> 142857.9 | E5: =IF(AND(ISNUMBER(C5),ISNUMBER(D5)), C5-D5, "") -> -85858.9 | F5: =IFERROR(E5/D5, "") -> -0.60100911 | G5: =SUM('1st Qtr'!G5, '2nd Qtr'!G5, '3rd Qtr'!G5, '4th Qtr'!G5) -> 69105.15 | H5: =SUM('1st Qtr'!H5, '2nd Qtr'!H5, '3rd Qtr'!H5, '4th Qtr'!H5) -> -12106.15 | I5: =IFERROR(H5/G5, "") -> -0.17518448
A6: Bowden | B6: MA | C6: =SUM('1st Qtr'!C6, '2nd Qtr'!C6, '3rd Qtr'!C6, '4th Qtr'!C6) -> 138818 | D6: =SUM('1st Qtr'!D6, '2nd Qtr'!D6, '3rd Qtr'!D6, '4th Qtr'!D6) -> 194548.5 | E6: =IF(AND(ISNUMBER(C6),ISNUMBER(D6)), C6-D6, "") -> -55730.5 | F6: =IFERROR(E6/D6, "") -> -0.2864607 | G6: =SUM('1st Qtr'!G6, '2nd Qtr'!G6, '3rd Qtr'!G6, '4th Qtr'!G6) -> 166837.3 | H6: =SUM('1st Qtr'!H6, '2nd Qtr'!H6, '3rd Qtr'!H6, '4th Qtr'!H6) -> -28019.3 | I6: =IFERROR(H6/G6, "") -> -0.16794386
A7: Blair Wire Village | B7: MA | C7: =SUM('1st Qtr'!C7, '2nd Qtr'!C7, '3rd Qtr'!C7, '4th Qtr'!C7) -> 67575 | D7: =SUM('1st Qtr'!D7, '2nd Qtr'!D7, '3rd Qtr'!D7, '4th Qtr'!D7) -> 148603.1 | E7: =IF(AND(ISNUMBER(C7),ISNUMBER(D7)), C7-D7, "") -> -81028.1 | F7: =IFERROR(E7/D7, "") -> -0.54526521 | G7: =SUM('1st Qtr'!G7, '2nd Qtr'!G7, '3rd Qtr'!G7, '4th Qtr'!G7) -> 82695.73 | H7: =SUM('1st Qtr'!H7, '2nd Qtr'!H7, '3rd Qtr'!H7, '4th Qtr'!H7) -> -15120.73 | I7: =IFERROR(H7/G7, "") -> -0.18284777
A8: Boutilier | B8: MA | C8: =SUM('1st Qtr'!C8, '2nd Qtr'!C8, '3rd Qtr'!C8, '4th Qtr'!C8) -> 197770 | D8: =SUM('1st Qtr'!D8, '2nd Qtr'!D8, '3rd Qtr'!D8, '4th Qtr'!D8) -> 316212.5 | E8: =IF(AND(ISNUMBER(C8),ISNUMBER(D8)), C8-D8, "") -> -118442.5 | F8: =IFERROR(E8/D8, "") -> -0.37456615 | G8: =SUM('1st Qtr'!G8, '2nd Qtr'!G8, '3rd Qtr'!G8, '4th Qtr'!G8) -> 189703.5 | H8: =SUM('1st Qtr'!H8, '2nd Qtr'!H8, '3rd Qtr'!H8, '4th Qtr'!H8) -> 8066.5 | I8: =IFERROR(H8/G8, "") -> 0.042521619
A9: Cherry Valley | B9: MA | C9: =SUM('1st Qtr'!C9, '2nd Qtr'!C9, '3rd Qtr'!C9, '4th Qtr'!C9) -> 62784 | D9: =SUM('1st Qtr'!D9, '2nd Qtr'!D9, '3rd Qtr'!D9, '4th Qtr'!D9) -> 141889.9 | E9: =IF(AND(ISNUMBER(C9),ISNUMBER(D9)), C9-D9, "") -> -79105.9 | F9: =IFERROR(E9/D9, "") -> -0.55751607 | G9: =SUM('1st Qtr'!G9, '2nd Qtr'!G9, '3rd Qtr'!G9, '4th Qtr'!G9) -> 77483 | H9: =SUM('1st Qtr'!H9, '2nd Qtr'!H9, '3rd Qtr'!H9, '4th Qtr'!H9) -> -14699 | I9: =IFERROR(H9/G9, "") -> -0.18970613
A10: Cohasse | B10: MA | C10: =SUM('1st Qtr'!C10, '2nd Qtr'!C10, '3rd Qtr'!C10, '4th Qtr'!C10) -> 68246 | D10: =SUM('1st Qtr'!D10, '2nd Qtr'!D10, '3rd Qtr'!D10, '4th Qtr'!D10) -> 140408.6 | E10: =IF(AND(ISNUMBER(C10),ISNUMBER(D10)), C10-D10, "") -> -72162.6 | F10: =IFERROR(E10/D10, "") -> -0.51394715 | G10: =SUM('1st Qtr'!G10, '2nd Qtr'!G10, '3rd Qtr'!G10, '4th Qtr'!G10) -> 113608.5 | H10: =SUM('1st Qtr'!H10, '2nd Qtr'!H10, '3rd Qtr'!H10, '4th Qtr'!H10) -> -45362.5 | I10: =IFERROR(H10/G10, "") -> -0.39928791
A11: ISM Dighton Solar 2 | B11: MA | C11: =SUM('1st Qtr'!C11, '2nd Qtr'!C11, '3rd Qtr'!C11, '4th Qtr'!C11) -> 216783 | D11: =SUM('1st Qtr'!D11, '2nd Qtr'!D11, '3rd Qtr'!D11, '4th Qtr'!D11) -> 272074.2 | E11: =IF(AND(ISNUMBER(C11),ISNUMBER(D11)), C11-D11, "") -> -55291.2 | F11: =IFERROR(E11/D11, "") -> -0.20322103 | G11: =SUM('1st Qtr'!G11, '2nd Qtr'!G11, '3rd Qtr'!G11, '4th Qtr'!G11) -> 194872.6 | H11: =SUM('1st Qtr'!H11, '2nd Qtr'!H11, '3rd Qtr'!H11, '4th Qtr'!H11) -> 21910.4 | I11: =IFERROR(H11/G11, "") -> 0.11243448
A12: Dudley River 1 | B12: MA | C12: =SUM('1st Qtr'!C12, '2nd Qtr'!C12, '3rd Qtr'!C12, '4th Qtr'!C12) -> 81072 | D12: =SUM('1st Qtr'!D12, '2nd Qtr'!D12, '3rd Qtr'!D12, '4th Qtr'!D12) -> 112668.6 | E12: =IF(AND(ISNUMBER(C12),ISNUMBER(D12)), C12-D12, "") -> -31596.6 | F12: =IFERROR(E12/D12, "") -> -0.28043838 | G12: =SUM('1st Qtr'!G12, '2nd Qtr'!G12, '3rd Qtr'!G12, '4th Qtr'!G12) -> 83342.55 | H12: =SUM('1st Qtr'!H12, '2nd Qtr'!H12, '3rd Qtr'!H12, '4th Qtr'!H12) -> -2270.55 | I12: =IFERROR(H12/G12, "") -> -0.027243587
A13: Dudley River 2 | B13: MA | C13: =SUM('1st Qtr'!C13, '2nd Qtr'!C13, '3rd Qtr'!C13, '4th Qtr'!C13) -> 77646 | D13: =SUM('1st Qtr'!D13, '2nd Qtr'!D13, '3rd Qtr'!D13, '4th Qtr'!D13) -> 116307.2 | E13: =IF(AND(ISNUMBER(C13),ISNUMBER(D13)), C13-D13, "") -> -38661.2 | F13: =IFERROR(E13/D13, "") -> -0.3324059 | G13: =SUM('1st Qtr'!G13, '2nd Qtr'!G13, '3rd Qtr'!G13, '4th Qtr'!G13) -> 81508.99 | H13: =SUM('1st Qtr'!H13, '2nd Qtr'!H13, '3rd Qtr'!H13, '4th Qtr'!H13) -> -3862.99 | I13: =IFERROR(H13/G13, "") -> -0.047393422
A14: Dudley River 3 | B14: MA | C14: =SUM('1st Qtr'!C14, '2nd Qtr'!C14, '3rd Qtr'!C14, '4th Qtr'!C14) -> 94540 | D14: =SUM('1st Qtr'!D14, '2nd Qtr'!D14, '3rd Qtr'!D14, '4th Qtr'!D14) -> 117412.4 | E14: =IF(AND(ISNUMBER(C14),ISNUMBER(D14)), C14-D14, "") -> -22872.4 | F14: =IFERROR(E14/D14, "") -> -0.19480396 | G14: =SUM('1st Qtr'!G14, '2nd Qtr'!G14, '3rd Qtr'!G14, '4th Qtr'!G14) -> 83727.59 | H14: =SUM('1st Qtr'!H14, '2nd Qtr'!H14, '3rd Qtr'!H14, '4th Qtr'!H14) -> 10812.41 | I14: =IFERROR(H14/G14, "") -> 0.12913796
A15: Flint Pond | B15: MA | C15: =SUM('1st Qtr'!C15, '2nd Qtr'!C15, '3rd Qtr'!C15, '4th Qtr'!C15) -> 30334 | D15: =SUM('1st Qtr'!D15, '2nd Qtr'!D15, '3rd Qtr'!D15, '4th Qtr'!D15) -> 62237.73 | E15: =IF(AND(ISNUMBER(C15),ISNUMBER(D15)), C15-D15, "") -> -31903.73 | F15: =IFERROR(E15/D15, "") -> -0.51261076 | G15: =SUM('1st Qtr'!G15, '2nd Qtr'!G15, '3rd Qtr'!G15, '4th Qtr'!G15) -> 33375.62 | H15: =SUM('1st Qtr'!H15, '2nd Qtr'!H15, '3rd Qtr'!H15, '4th Qtr'!H15) -> -3041.62 | I15: =IFERROR(H15/G15, "") -> -0.091132989
A16: Incom | B16: MA | C16: =SUM('1st Qtr'!C16, '2nd Qtr'!C16, '3rd Qtr'!C16, '4th Qtr'!C16) -> 130021 | D16: =SUM('1st Qtr'!D16, '2nd Qtr'!D16, '3rd Qtr'!D16, '4th Qtr'!D16) -> 227416.1 | E16: =IF(AND(ISNUMBER(C16),ISNUMBER(D16)), C16-D16, "") -> -97395.1 | F16: =IFERROR(E16/D16, "") -> -0.42826827 | G16: =SUM('1st Qtr'!G16, '2nd Qtr'!G16, '3rd Qtr'!G16, '4th Qtr'!G16) -> 219053.9 | H16: =SUM('1st Qtr'!H16, '2nd Qtr'!H16, '3rd Qtr'!H16, '4th Qtr'!H16) -> -89032.9 | I16: =IFERROR(H16/G16, "") -> -0.40644289
... A24: Woodchuck | B24: MA | C24: =SUM('1st Qtr'!C24, '2nd Qtr'!C24, '3rd Qtr'!C24, '4th Qtr'!C24) -> 61310 | D24: =SUM('1st Qtr'!D24, '2nd Qtr'!D24, '3rd Qtr'!D24, '4th Qtr'!D24) -> 111494.1 | E24: =IF(AND(ISNUMBER(C24),ISNUMBER(D24)), C24-D24, "") -> -50184.1 | F24: =IFERROR(E24/D24, "") -> -0.45010543 | G24: =SUM('1st Qtr'!G24, '2nd Qtr'!G24, '3rd Qtr'!G24, '4th Qtr'!G24) -> 95616.23 | H24: =SUM('1st Qtr'!H24, '2nd Qtr'!H24, '3rd Qtr'!H24, '4th Qtr'!H24) -> -34306.23 | I24: =IFERROR(H24/G24, "") -> -0.35879087

Sheet 1st Qtr
A1: {=portfolio} -> 38 DN | D1: 1st Quarter Actual v. Expected | G1: 1st Quarter Actual v. Forecasted
A2: Total | C2: =SUM(C4:C99) -> 1879993.2 | D2: =SUM(D4:D99) -> 3100330.9 | E2: =C2-D2 -> -1220337.6 | F2: =IFERROR(E2/D2, 0) -> -0.39361528 | G2: =SUM(G4:G99) -> 2316666 | H2: =C2-G2 -> -436672.78 | I2: =IFERROR(H2/G2, 0) -> -0.1884919
A3: Site | B3: State | C3: Actual | D3: Expected | E3: Delta | F3: % | G3: Forecasted | H3: Delta | I3: %
A4: {=Sites[Site]} -> 6th St. | B4: {=Sites[State]} -> CA | C4: =SUM(Jan!C4, Feb!C4, Mar!C4) -> 129016 | D4: =SUM(Jan!D4, Feb!D4, Mar!D4) -> 74840.77 | E4: =IF(AND(ISNUMBER(C4),ISNUMBER(D4)), C4-D4, "") -> 54175.23 | F4: =IFERROR(E4/D4, "") -> 0.72387323 | G4: =SUM(Jan!G4, Feb!G4, Mar!G4) -> 144521 | H4: =SUM(Jan!H4, Feb!H4, Mar!H4) -> -15505 | I4: =IFERROR(H4/G4, "") -> -0.10728545
A5: Barton Acres | B5: MA | C5: =SUM(Jan!C5, Feb!C5, Mar!C5) -> 56999 | D5: =SUM(Jan!D5, Feb!D5, Mar!D5) -> 142857.9 | E5: =IF(AND(ISNUMBER(C5),ISNUMBER(D5)), C5-D5, "") -> -85858.9 | F5: =IFERROR(E5/D5, "") -> -0.60100911 | G5: =SUM(Jan!G5, Feb!G5, Mar!G5) -> 69105.15 | H5: =SUM(Jan!H5, Feb!H5, Mar!H5) -> -12106.15 | I5: =IFERROR(H5/G5, "") -> -0.17518448
A6: Bowden | B6: MA | C6: =SUM(Jan!C6, Feb!C6, Mar!C6) -> 138818 | D6: =SUM(Jan!D6, Feb!D6, Mar!D6) -> 194548.5 | E6: =IF(AND(ISNUMBER(C6),ISNUMBER(D6)), C6-D6, "") -> -55730.5 | F6: =IFERROR(E6/D6, "") -> -0.2864607 | G6: =SUM(Jan!G6, Feb!G6, Mar!G6) -> 166837.3 | H6: =SUM(Jan!H6, Feb!H6, Mar!H6) -> -28019.3 | I6: =IFERROR(H6/G6, "") -> -0.16794386
A7: Blair Wire Village | B7: MA | C7: =SUM(Jan!C7, Feb!C7, Mar!C7) -> 67575 | D7: =SUM(Jan!D7, Feb!D7, Mar!D7) -> 148603.1 | E7: =IF(AND(ISNUMBER(C7),ISNUMBER(D7)), C7-D7, "") -> -81028.1 | F7: =IFERROR(E7/D7, "") -> -0.54526521 | G7: =SUM(Jan!G7, Feb!G7, Mar!G7) -> 82695.73 | H7: =SUM(Jan!H7, Feb!H7, Mar!H7) -> -15120.73 | I7: =IFERROR(H7/G7, "") -> -0.18284777
A8: Boutilier | B8: MA | C8: =SUM(Jan!C8, Feb!C8, Mar!C8) -> 197770 | D8: =SUM(Jan!D8, Feb!D8, Mar!D8) -> 316212.5 | E8: =IF(AND(ISNUMBER(C8),ISNUMBER(D8)), C8-D8, "") -> -118442.5 | F8: =IFERROR(E8/D8, "") -> -0.37456615 | G8: =SUM(Jan!G8, Feb!G8, Mar!G8) -> 189703.5 | H8: =SUM(Jan!H8, Feb!H8, Mar!H8) -> 8066.5 | I8: =IFERROR(H8/G8, "") -> 0.042521619
A9: Cherry Valley | B9: MA | C9: =SUM(Jan!C9, Feb!C9, Mar!C9) -> 62784 | D9: =SUM(Jan!D9, Feb!D9, Mar!D9) -> 141889.9 | E9: =IF(AND(ISNUMBER(C9),ISNUMBER(D9)), C9-D9, "") -> -79105.9 | F9: =IFERROR(E9/D9, "") -> -0.55751607 | G9: =SUM(Jan!G9, Feb!G9, Mar!G9) -> 77483 | H9: =SUM(Jan!H9, Feb!H9, Mar!H9) -> -14699 | I9: =IFERROR(H9/G9, "") -> -0.18970613
A10: Cohasse | B10: MA | C10: =SUM(Jan!C10, Feb!C10, Mar!C10) -> 68246 | D10: =SUM(Jan!D10, Feb!D10, Mar!D10) -> 140408.6 | E10: =IF(AND(ISNUMBER(C10),ISNUMBER(D10)), C10-D10, "") -> -72162.6 | F10: =IFERROR(E10/D10, "") -> -0.51394715 | G10: =SUM(Jan!G10, Feb!G10, Mar!G10) -> 113608.5 | H10: =SUM(Jan!H10, Feb!H10, Mar!H10) -> -45362.5 | I10: =IFERROR(H10/G10, "") -> -0.39928791
A11: ISM Dighton Solar 2 | B11: MA | C11: =SUM(Jan!C11, Feb!C11, Mar!C11) -> 216783 | D11: =SUM(Jan!D11, Feb!D11, Mar!D11) -> 272074.2 | E11: =IF(AND(ISNUMBER(C11),ISNUMBER(D11)), C11-D11, "") -> -55291.2 | F11: =IFERROR(E11/D11, "") -> -0.20322103 | G11: =SUM(Jan!G11, Feb!G11, Mar!G11) -> 194872.6 | H11: =SUM(Jan!H11, Feb!H11, Mar!H11) -> 21910.4 | I11: =IFERROR(H11/G11, "") -> 0.11243448
A12: Dudley River 1 | B12: MA | C12: =SUM(Jan!C12, Feb!C12, Mar!C12) -> 81072 | D12: =SUM(Jan!D12, Feb!D12, Mar!D12) -> 112668.6 | E12: =IF(AND(ISNUMBER(C12),ISNUMBER(D12)), C12-D12, "") -> -31596.6 | F12: =IFERROR(E12/D12, "") -> -0.28043838 | G12: =SUM(Jan!G12, Feb!G12, Mar!G12) -> 83342.55 | H12: =SUM(Jan!H12, Feb!H12, Mar!H12) -> -2270.55 | I12: =IFERROR(H12/G12, "") -> -0.027243587
A13: Dudley River 2 | B13: MA | C13: =SUM(Jan!C13, Feb!C13, Mar!C13) -> 77646 | D13: =SUM(Jan!D13, Feb!D13, Mar!D13) -> 116307.2 | E13: =IF(AND(ISNUMBER(C13),ISNUMBER(D13)), C13-D13, "") -> -38661.2 | F13: =IFERROR(E13/D13, "") -> -0.3324059 | G13: =SUM(Jan!G13, Feb!G13, Mar!G13) -> 81508.99 | H13: =SUM(Jan!H13, Feb!H13, Mar!H13) -> -3862.99 | I13: =IFERROR(H13/G13, "") -> -0.047393422
A14: Dudley River 3 | B14: MA | C14: =SUM(Jan!C14, Feb!C14, Mar!C14) -> 94540 | D14: =SUM(Jan!D14, Feb!D14, Mar!D14) -> 117412.4 | E14: =IF(AND(ISNUMBER(C14),ISNUMBER(D14)), C14-D14, "") -> -22872.4 | F14: =IFERROR(E14/D14, "") -> -0.19480396 | G14: =SUM(Jan!G14, Feb!G14, Mar!G14) -> 83727.59 | H14: =SUM(Jan!H14, Feb!H14, Mar!H14) -> 10812.41 | I14: =IFERROR(H14/G14, "") -> 0.12913796
A15: Flint Pond | B15: MA | C15: =SUM(Jan!C15, Feb!C15, Mar!C15) -> 30334 | D15: =SUM(Jan!D15, Feb!D15, Mar!D15) -> 62237.73 | E15: =IF(AND(ISNUMBER(C15),ISNUMBER(D15)), C15-D15, "") -> -31903.73 | F15: =IFERROR(E15/D15, "") -> -0.51261076 | G15: =SUM(Jan!G15, Feb!G15, Mar!G15) -> 33375.62 | H15: =SUM(Jan!H15, Feb!H15, Mar!H15) -> -3041.62 | I15: =IFERROR(H15/G15, "") -> -0.091132989
A16: Incom | B16: MA | C16: =SUM(Jan!C16, Feb!C16, Mar!C16) -> 130021 | D16: =SUM(Jan!D16, Feb!D16, Mar!D16) -> 227416.1 | E16: =IF(AND(ISNUMBER(C16),ISNUMBER(D16)), C16-D16, "") -> -97395.1 | F16: =IFERROR(E16/D16, "") -> -0.42826827 | G16: =SUM(Jan!G16, Feb!G16, Mar!G16) -> 219053.9 | H16: =SUM(Jan!H16, Feb!H16, Mar!H16) -> -89032.9 | I16: =IFERROR(H16/G16, "") -> -0.40644289
... A24: Woodchuck | B24: MA | C24: =SUM(Jan!C24, Feb!C24, Mar!C24) -> 61310 | D24: =SUM(Jan!D24, Feb!D24, Mar!D24) -> 111494.1 | E24: =IF(AND(ISNUMBER(C24),ISNUMBER(D24)), C24-D24, "") -> -50184.1 | F24: =IFERROR(E24/D24, "") -> -0.45010543 | G24: =SUM(Jan!G24, Feb!G24, Mar!G24) -> 95616.23 | H24: =SUM(Jan!H24, Feb!H24, Mar!H24) -> -34306.23 | I24: =IFERROR(H24/G24, "") -> -0.35879087

Sheet 2nd Qtr
A1: {=portfolio} -> 38 DN | D1: 2nd Quarter Actual v. Expected | G1: 2nd Quarter Actual v. Forecasted
A2: Total | C2: =SUM(C4:C99) -> 0 | D2: =SUM(D4:D99) -> 0 | E2: =C2-D2 -> 0 | F2: =IFERROR(E2/D2, 0) -> 0 | G2: =SUM(G4:G99) -> 0 | H2: =C2-G2 -> 0 | I2: =IFERROR(H2/G2, 0) -> 0
A3: Site | B3: State | C3: Actual | D3: Expected | E3: Delta | F3: % | G3: Forecasted | H3: Delta | I3: %
A4: {=Sites[Site]} -> 6th St. | B4: {=Sites[State]} -> CA | C4: =SUM(Apr!C4, May!C4, Jun!C4) -> 0 | D4: =SUM(Apr!D4, May!D4, Jun!D4) -> 0 | E4: =IF(AND(ISNUMBER(C4),ISNUMBER(D4)), C4-D4, "") -> 0 | F4: =IFERROR(E4/D4, "") | G4: =SUM(Apr!G4, May!G4, Jun!G4) -> 0 | H4: =SUM(Apr!H4, May!H4, Jun!H4) -> 0 | I4: =IFERROR(H4/G4, "")
A5: Barton Acres | B5: MA | C5: =SUM(Apr!C5, May!C5, Jun!C5) -> 0 | D5: =SUM(Apr!D5, May!D5, Jun!D5) -> 0 | E5: =IF(AND(ISNUMBER(C5),ISNUMBER(D5)), C5-D5, "") -> 0 | F5: =IFERROR(E5/D5, "") | G5: =SUM(Apr!G5, May!G5, Jun!G5) -> 0 | H5: =SUM(Apr!H5, May!H5, Jun!H5) -> 0 | I5: =IFERROR(H5/G5, "")
A6: Bowden | B6: MA | C6: =SUM(Apr!C6, May!C6, Jun!C6) -> 0 | D6: =SUM(Apr!D6, May!D6, Jun!D6) -> 0 | E6: =IF(AND(ISNUMBER(C6),ISNUMBER(D6)), C6-D6, "") -> 0 | F6: =IFERROR(E6/D6, "") | G6: =SUM(Apr!G6, May!G6, Jun!G6) -> 0 | H6: =SUM(Apr!H6, May!H6, Jun!H6) -> 0 | I6: =IFERROR(H6/G6, "")
A7: Blair Wire Village | B7: MA | C7: =SUM(Apr!C7, May!C7, Jun!C7) -> 0 | D7: =SUM(Apr!D7, May!D7, Jun!D7) -> 0 | E7: =IF(AND(ISNUMBER(C7),ISNUMBER(D7)), C7-D7, "") -> 0 | F7: =IFERROR(E7/D7, "") | G7: =SUM(Apr!G7, May!G7, Jun!G7) -> 0 | H7: =SUM(Apr!H7, May!H7, Jun!H7) -> 0 | I7: =IFERROR(H7/G7, "")
A8: Boutilier | B8: MA | C8: =SUM(Apr!C8, May!C8, Jun!C8) -> 0 | D8: =SUM(Apr!D8, May!D8, Jun!D8) -> 0 | E8: =IF(AND(ISNUMBER(C8),ISNUMBER(D8)), C8-D8, "") -> 0 | F8: =IFERROR(E8/D8, "") | G8: =SUM(Apr!G8, May!G8, Jun!G8) -> 0 | H8: =SUM(Apr!H8, May!H8, Jun!H8) -> 0 | I8: =IFERROR(H8/G8, "")
A9: Cherry Valley | B9: MA | C9: =SUM(Apr!C9, May!C9, Jun!C9) -> 0 | D9: =SUM(Apr!D9, May!D9, Jun!D9) -> 0 | E9: =IF(AND(ISNUMBER(C9),ISNUMBER(D9)), C9-D9, "") -> 0 | F9: =IFERROR(E9/D9, "") | G9: =SUM(Apr!G9, May!G9, Jun!G9) -> 0 | H9: =SUM(Apr!H9, May!H9, Jun!H9) -> 0 | I9: =IFERROR(H9/G9, "")
A10: Cohasse | B10: MA | C10: =SUM(Apr!C10, May!C10, Jun!C10) -> 0 | D10: =SUM(Apr!D10, May!D10, Jun!D10) -> 0 | E10: =IF(AND(ISNUMBER(C10),ISNUMBER(D10)), C10-D10, "") -> 0 | F10: =IFERROR(E10/D10, "") | G10: =SUM(Apr!G10, May!G10, Jun!G10) -> 0 | H10: =SUM(Apr!H10, May!H10, Jun!H10) -> 0 | I10: =IFERROR(H10/G10, "")
A11: ISM Dighton Solar 2 | B11: MA | C11: =SUM(Apr!C11, May!C11, Jun!C11) -> 0 | D11: =SUM(Apr!D11, May!D11, Jun!D11) -> 0 | E11: =IF(AND(ISNUMBER(C11),ISNUMBER(D11)), C11-D11, "") -> 0 | F11: =IFERROR(E11/D11, "") | G11: =SUM(Apr!G11, May!G11, Jun!G11) -> 0 | H11: =SUM(Apr!H11, May!H11, Jun!H11) -> 0 | I11: =IFERROR(H11/G11, "")
A12: Dudley River 1 | B12: MA | C12: =SUM(Apr!C12, May!C12, Jun!C12) -> 0 | D12: =SUM(Apr!D12, May!D12, Jun!D12) -> 0 | E12: =IF(AND(ISNUMBER(C12),ISNUMBER(D12)), C12-D12, "") -> 0 | F12: =IFERROR(E12/D12, "") | G12: =SUM(Apr!G12, May!G12, Jun!G12) -> 0 | H12: =SUM(Apr!H12, May!H12, Jun!H12) -> 0 | I12: =IFERROR(H12/G12, "")
A13: Dudley River 2 | B13: MA | C13: =SUM(Apr!C13, May!C13, Jun!C13) -> 0 | D13: =SUM(Apr!D13, May!D13, Jun!D13) -> 0 | E13: =IF(AND(ISNUMBER(C13),ISNUMBER(D13)), C13-D13, "") -> 0 | F13: =IFERROR(E13/D13, "") | G13: =SUM(Apr!G13, May!G13, Jun!G13) -> 0 | H13: =SUM(Apr!H13, May!H13, Jun!H13) -> 0 | I13: =IFERROR(H13/G13, "")
A14: Dudley River 3 | B14: MA | C14: =SUM(Apr!C14, May!C14, Jun!C14) -> 0 | D14: =SUM(Apr!D14, May!D14, Jun!D14) -> 0 | E14: =IF(AND(ISNUMBER(C14),ISNUMBER(D14)), C14-D14, "") -> 0 | F14: =IFERROR(E14/D14, "") | G14: =SUM(Apr!G14, May!G14, Jun!G14) -> 0 | H14: =SUM(Apr!H14, May!H14, Jun!H14) -> 0 | I14: =IFERROR(H14/G14, "")
A15: Flint Pond | B15: MA | C15: =SUM(Apr!C15, May!C15, Jun!C15) -> 0 | D15: =SUM(Apr!D15, May!D15, Jun!D15) -> 0 | E15: =IF(AND(ISNUMBER(C15),ISNUMBER(D15)), C15-D15, "") -> 0 | F15: =IFERROR(E15/D15, "") | G15: =SUM(Apr!G15, May!G15, Jun!G15) -> 0 | H15: =SUM(Apr!H15, May!H15, Jun!H15) -> 0 | I15: =IFERROR(H15/G15, "")
A16: Incom | B16: MA | C16: =SUM(Apr!C16, May!C16, Jun!C16) -> 0 | D16: =SUM(Apr!D16, May!D16, Jun!D16) -> 0 | E16: =IF(AND(ISNUMBER(C16),ISNUMBER(D16)), C16-D16, "") -> 0 | F16: =IFERROR(E16/D16, "") | G16: =SUM(Apr!G16, May!G16, Jun!G16) -> 0 | H16: =SUM(Apr!H16, May!H16, Jun!H16) -> 0 | I16: =IFERROR(H16/G16, "")
... A24: Woodchuck | B24: MA | C24: =SUM(Apr!C24, May!C24, Jun!C24) -> 0 | D24: =SUM(Apr!D24, May!D24, Jun!D24) -> 0 | E24: =IF(AND(ISNUMBER(C24),ISNUMBER(D24)), C24-D24, "") -> 0 | F24: =IFERROR(E24/D24, "") | G24: =SUM(Apr!G24, May!G24, Jun!G24) -> 0 | H24: =SUM(Apr!H24, May!H24, Jun!H24) -> 0 | I24: =IFERROR(H24/G24, "")

Sheet 3rd Qtr
A1: {=portfolio} -> 38 DN | D1: 3rd Quarter Actual v. Expected | G1: 3rd Quarter Actual v. Forecasted
A2: Total | C2: =SUM(C4:C99) -> 0 | D2: =SUM(D4:D99) -> 0 | E2: =C2-D2 -> 0 | F2: =IFERROR(E2/D2, 0) -> 0 | G2: =SUM(G4:G99) -> 0 | H2: =C2-G2 -> 0 | I2: =IFERROR(H2/G2, 0) -> 0
A3: Site | B3: State | C3: Actual | D3: Expected | E3: Delta | F3: % | G3: Forecasted | H3: Delta | I3: %
A4: {=Sites[Site]} -> 6th St. | B4: {=Sites[State]} -> CA | C4: =SUM(Jul!C4, Aug!C4, Sep!C4) -> 0 | D4: =SUM(Jul!D4, Aug!D4, Sep!D4) -> 0 | E4: =IF(AND(ISNUMBER(C4),ISNUMBER(D4)), C4-D4, "") -> 0 | F4: =IFERROR(E4/D4, "") | G4: =SUM(Jul!G4,Aug!G4,Sep!G4) -> 0 | H4: =SUM(Jul!H4, Aug!H4, Sep!H4) -> 0 | I4: =IFERROR(H4/G4, "")
A5: Barton Acres | B5: MA | C5: =SUM(Jul!C5, Aug!C5, Sep!C5) -> 0 | D5: =SUM(Jul!D5, Aug!D5, Sep!D5) -> 0 | E5: =IF(AND(ISNUMBER(C5),ISNUMBER(D5)), C5-D5, "") -> 0 | F5: =IFERROR(E5/D5, "") | G5: =SUM(Jul!G5,Aug!G5,Sep!G5) -> 0 | H5: =SUM(Jul!H5, Aug!H5, Sep!H5) -> 0 | I5: =IFERROR(H5/G5, "")
A6: Bowden | B6: MA | C6: =SUM(Jul!C6, Aug!C6, Sep!C6) -> 0 | D6: =SUM(Jul!D6, Aug!D6, Sep!D6) -> 0 | E6: =IF(AND(ISNUMBER(C6),ISNUMBER(D6)), C6-D6, "") -> 0 | F6: =IFERROR(E6/D6, "") | G6: =SUM(Jul!G6,Aug!G6,Sep!G6) -> 0 | H6: =SUM(Jul!H6, Aug!H6, Sep!H6) -> 0 | I6: =IFERROR(H6/G6, "")
A7: Blair Wire Village | B7: MA | C7: =SUM(Jul!C7, Aug!C7, Sep!C7) -> 0 | D7: =SUM(Jul!D7, Aug!D7, Sep!D7) -> 0 | E7: =IF(AND(ISNUMBER(C7),ISNUMBER(D7)), C7-D7, "") -> 0 | F7: =IFERROR(E7/D7, "") | G7: =SUM(Jul!G7,Aug!G7,Sep!G7) -> 0 | H7: =SUM(Jul!H7, Aug!H7, Sep!H7) -> 0 | I7: =IFERROR(H7/G7, "")
A8: Boutilier | B8: MA | C8: =SUM(Jul!C8, Aug!C8, Sep!C8) -> 0 | D8: =SUM(Jul!D8, Aug!D8, Sep!D8) -> 0 | E8: =IF(AND(ISNUMBER(C8),ISNUMBER(D8)), C8-D8, "") -> 0 | F8: =IFERROR(E8/D8, "") | G8: =SUM(Jul!G8,Aug!G8,Sep!G8) -> 0 | H8: =SUM(Jul!H8, Aug!H8, Sep!H8) -> 0 | I8: =IFERROR(H8/G8, "")
A9: Cherry Valley | B9: MA | C9: =SUM(Jul!C9, Aug!C9, Sep!C9) -> 0 | D9: =SUM(Jul!D9, Aug!D9, Sep!D9) -> 0 | E9: =IF(AND(ISNUMBER(C9),ISNUMBER(D9)), C9-D9, "") -> 0 | F9: =IFERROR(E9/D9, "") | G9: =SUM(Jul!G9,Aug!G9,Sep!G9) -> 0 | H9: =SUM(Jul!H9, Aug!H9, Sep!H9) -> 0 | I9: =IFERROR(H9/G9, "")
A10: Cohasse | B10: MA | C10: =SUM(Jul!C10, Aug!C10, Sep!C10) -> 0 | D10: =SUM(Jul!D10, Aug!D10, Sep!D10) -> 0 | E10: =IF(AND(ISNUMBER(C10),ISNUMBER(D10)), C10-D10, "") -> 0 | F10: =IFERROR(E10/D10, "") | G10: =SUM(Jul!G10,Aug!G10,Sep!G10) -> 0 | H10: =SUM(Jul!H10, Aug!H10, Sep!H10) -> 0 | I10: =IFERROR(H10/G10, "")
A11: ISM Dighton Solar 2 | B11: MA | C11: =SUM(Jul!C11, Aug!C11, Sep!C11) -> 0 | D11: =SUM(Jul!D11, Aug!D11, Sep!D11) -> 0 | E11: =IF(AND(ISNUMBER(C11),ISNUMBER(D11)), C11-D11, "") -> 0 | F11: =IFERROR(E11/D11, "") | G11: =SUM(Jul!G11,Aug!G11,Sep!G11) -> 0 | H11: =SUM(Jul!H11, Aug!H11, Sep!H11) -> 0 | I11: =IFERROR(H11/G11, "")
A12: Dudley River 1 | B12: MA | C12: =SUM(Jul!C12, Aug!C12, Sep!C12) -> 0 | D12: =SUM(Jul!D12, Aug!D12, Sep!D12) -> 0 | E12: =IF(AND(ISNUMBER(C12),ISNUMBER(D12)), C12-D12, "") -> 0 | F12: =IFERROR(E12/D12, "") | G12: =SUM(Jul!G12,Aug!G12,Sep!G12) -> 0 | H12: =SUM(Jul!H12, Aug!H12, Sep!H12) -> 0 | I12: =IFERROR(H12/G12, "")
A13: Dudley River 2 | B13: MA | C13: =SUM(Jul!C13, Aug!C13, Sep!C13) -> 0 | D13: =SUM(Jul!D13, Aug!D13, Sep!D13) -> 0 | E13: =IF(AND(ISNUMBER(C13),ISNUMBER(D13)), C13-D13, "") -> 0 | F13: =IFERROR(E13/D13, "") | G13: =SUM(Jul!G13,Aug!G13,Sep!G13) -> 0 | H13: =SUM(Jul!H13, Aug!H13, Sep!H13) -> 0 | I13: =IFERROR(H13/G13, "")
A14: Dudley River 3 | B14: MA | C14: =SUM(Jul!C14, Aug!C14, Sep!C14) -> 0 | D14: =SUM(Jul!D14, Aug!D14, Sep!D14) -> 0 | E14: =IF(AND(ISNUMBER(C14),ISNUMBER(D14)), C14-D14, "") -> 0 | F14: =IFERROR(E14/D14, "") | G14: =SUM(Jul!G14,Aug!G14,Sep!G14) -> 0 | H14: =SUM(Jul!H14, Aug!H14, Sep!H14) -> 0 | I14: =IFERROR(H14/G14, "")
A15: Flint Pond | B15: MA | C15: =SUM(Jul!C15, Aug!C15, Sep!C15) -> 0 | D15: =SUM(Jul!D15, Aug!D15, Sep!D15) -> 0 | E15: =IF(AND(ISNUMBER(C15),ISNUMBER(D15)), C15-D15, "") -> 0 | F15: =IFERROR(E15/D15, "") | G15: =SUM(Jul!G15,Aug!G15,Sep!G15) -> 0 | H15: =SUM(Jul!H15, Aug!H15, Sep!H15) -> 0 | I15: =IFERROR(H15/G15, "")
A16: Incom | B16: MA | C16: =SUM(Jul!C16, Aug!C16, Sep!C16) -> 0 | D16: =SUM(Jul!D16, Aug!D16, Sep!D16) -> 0 | E16: =IF(AND(ISNUMBER(C16),ISNUMBER(D16)), C16-D16, "") -> 0 | F16: =IFERROR(E16/D16, "") | G16: =SUM(Jul!G16,Aug!G16,Sep!G16) -> 0 | H16: =SUM(Jul!H16, Aug!H16, Sep!H16) -> 0 | I16: =IFERROR(H16/G16, "")
... A24: Woodchuck | B24: MA | C24: =SUM(Jul!C24, Aug!C24, Sep!C24) -> 0 | D24: =SUM(Jul!D24, Aug!D24, Sep!D24) -> 0 | E24: =IF(AND(ISNUMBER(C24),ISNUMBER(D24)), C24-D24, "") -> 0 | F24: =IFERROR(E24/D24, "") | G24: =SUM(Jul!G24,Aug!G24,Sep!G24) -> 0 | H24: =SUM(Jul!H24, Aug!H24, Sep!H24) -> 0 | I24: =IFERROR(H24/G24, "")

Sheet 4th Qtr
A1: {=portfolio} -> 38 DN | D1: 4th Quarter Actual v. Expected | G1: 4th Quarter Actual v. Forecasted
A2: Total | C2: =SUM(C4:C99) -> 0 | D2: =SUM(D4:D99) -> 0 | E2: =C2-D2 -> 0 | F2: =IFERROR(E2/D2, 0) -> 0 | G2: =SUM(G4:G99) -> 0 | H2: =C2-G2 -> 0 | I2: =IFERROR(H2/G2, 0) -> 0
A3: Site | B3: State | C3: Actual | D3: Expected | E3: Delta | F3: % | G3: Forecasted | H3: Delta | I3: %
A4: {=Sites[Site]} -> 6th St. | B4: {=Sites[State]} -> CA | C4: =SUM(Oct!C4, Nov!C4, Dec!C4) -> 0 | D4: =SUM(Oct!D4, Nov!D4, Dec!D4) -> 0 | E4: =IF(AND(ISNUMBER(C4),ISNUMBER(D4)), C4-D4, "") -> 0 | F4: =IFERROR(E4/D4, "") | H4: =SUM(Oct!H4, Nov!H4, Dec!H4) -> 0 | I4: =IFERROR(H4/G4, "")
A5: Barton Acres | B5: MA | C5: =SUM(Oct!C5, Nov!C5, Dec!C5) -> 0 | D5: =SUM(Oct!D5, Nov!D5, Dec!D5) -> 0 | E5: =IF(AND(ISNUMBER(C5),ISNUMBER(D5)), C5-D5, "") -> 0 | F5: =IFERROR(E5/D5, "") | H5: =SUM(Oct!H5, Nov!H5, Dec!H5) -> 0 | I5: =IFERROR(H5/G5, "")
A6: Bowden | B6: MA | C6: =SUM(Oct!C6, Nov!C6, Dec!C6) -> 0 | D6: =SUM(Oct!D6, Nov!D6, Dec!D6) -> 0 | E6: =IF(AND(ISNUMBER(C6),ISNUMBER(D6)), C6-D6, "") -> 0 | F6: =IFERROR(E6/D6, "") | H6: =SUM(Oct!H6, Nov!H6, Dec!H6) -> 0 | I6: =IFERROR(H6/G6, "")
A7: Blair Wire Village | B7: MA | C7: =SUM(Oct!C7, Nov!C7, Dec!C7) -> 0 | D7: =SUM(Oct!D7, Nov!D7, Dec!D7) -> 0 | E7: =IF(AND(ISNUMBER(C7),ISNUMBER(D7)), C7-D7, "") -> 0 | F7: =IFERROR(E7/D7, "") | H7: =SUM(Oct!H7, Nov!H7, Dec!H7) -> 0 | I7: =IFERROR(H7/G7, "")
A8: Boutilier | B8: MA | C8: =SUM(Oct!C8, Nov!C8, Dec!C8) -> 0 | D8: =SUM(Oct!D8, Nov!D8, Dec!D8) -> 0 | E8: =IF(AND(ISNUMBER(C8),ISNUMBER(D8)), C8-D8, "") -> 0 | F8: =IFERROR(E8/D8, "") | H8: =SUM(Oct!H8, Nov!H8, Dec!H8) -> 0 | I8: =IFERROR(H8/G8, "")
A9: Cherry Valley | B9: MA | C9: =SUM(Oct!C9, Nov!C9, Dec!C9) -> 0 | D9: =SUM(Oct!D9, Nov!D9, Dec!D9) -> 0 | E9: =IF(AND(ISNUMBER(C9),ISNUMBER(D9)), C9-D9, "") -> 0 | F9: =IFERROR(E9/D9, "") | H9: =SUM(Oct!H9, Nov!H9, Dec!H9) -> 0 | I9: =IFERROR(H9/G9, "")
A10: Cohasse | B10: MA | C10: =SUM(Oct!C10, Nov!C10, Dec!C10) -> 0 | D10: =SUM(Oct!D10, Nov!D10, Dec!D10) -> 0 | E10: =IF(AND(ISNUMBER(C10),ISNUMBER(D10)), C10-D10, "") -> 0 | F10: =IFERROR(E10/D10, "") | H10: =SUM(Oct!H10, Nov!H10, Dec!H10) -> 0 | I10: =IFERROR(H10/G10, "")
A11: ISM Dighton Solar 2 | B11: MA | C11: =SUM(Oct!C11, Nov!C11, Dec!C11) -> 0 | D11: =SUM(Oct!D11, Nov!D11, Dec!D11) -> 0 | E11: =IF(AND(ISNUMBER(C11),ISNUMBER(D11)), C11-D11, "") -> 0 | F11: =IFERROR(E11/D11, "") | H11: =SUM(Oct!H11, Nov!H11, Dec!H11) -> 0 | I11: =IFERROR(H11/G11, "")
A12: Dudley River 1 | B12: MA | C12: =SUM(Oct!C12, Nov!C12, Dec!C12) -> 0 | D12: =SUM(Oct!D12, Nov!D12, Dec!D12) -> 0 | E12: =IF(AND(ISNUMBER(C12),ISNUMBER(D12)), C12-D12, "") -> 0 | F12: =IFERROR(E12/D12, "") | H12: =SUM(Oct!H12, Nov!H12, Dec!H12) -> 0 | I12: =IFERROR(H12/G12, "")
A13: Dudley River 2 | B13: MA | C13: =SUM(Oct!C13, Nov!C13, Dec!C13) -> 0 | D13: =SUM(Oct!D13, Nov!D13, Dec!D13) -> 0 | E13: =IF(AND(ISNUMBER(C13),ISNUMBER(D13)), C13-D13, "") -> 0 | F13: =IFERROR(E13/D13, "") | H13: =SUM(Oct!H13, Nov!H13, Dec!H13) -> 0 | I13: =IFERROR(H13/G13, "")
A14: Dudley River 3 | B14: MA | C14: =SUM(Oct!C14, Nov!C14, Dec!C14) -> 0 | D14: =SUM(Oct!D14, Nov!D14, Dec!D14) -> 0 | E14: =IF(AND(ISNUMBER(C14),ISNUMBER(D14)), C14-D14, "") -> 0 | F14: =IFERROR(E14/D14, "") | H14: =SUM(Oct!H14, Nov!H14, Dec!H14) -> 0 | I14: =IFERROR(H14/G14, "")
A15: Flint Pond | B15: MA | C15: =SUM(Oct!C15, Nov!C15, Dec!C15) -> 0 | D15: =SUM(Oct!D15, Nov!D15, Dec!D15) -> 0 | E15: =IF(AND(ISNUMBER(C15),ISNUMBER(D15)), C15-D15, "") -> 0 | F15: =IFERROR(E15/D15, "") | H15: =SUM(Oct!H15, Nov!H15, Dec!H15) -> 0 | I15: =IFERROR(H15/G15, "")
A16: Incom | B16: MA | C16: =SUM(Oct!C16, Nov!C16, Dec!C16) -> 0 | D16: =SUM(Oct!D16, Nov!D16, Dec!D16) -> 0 | E16: =IF(AND(ISNUMBER(C16),ISNUMBER(D16)), C16-D16, "") -> 0 | F16: =IFERROR(E16/D16, "") | H16: =SUM(Oct!H16, Nov!H16, Dec!H16) -> 0 | I16: =IFERROR(H16/G16, "")
... A24: Woodchuck | B24: MA | C24: =SUM(Oct!C24, Nov!C24, Dec!C24) -> 0 | D24: =SUM(Oct!D24, Nov!D24, Dec!D24) -> 0 | E24: =IF(AND(ISNUMBER(C24),ISNUMBER(D24)), C24-D24, "") -> 0 | F24: =IFERROR(E24/D24, "") | H24: =SUM(Oct!H24, Nov!H24, Dec!H24) -> 0 | I24: =IFERROR(H24/G24, "")

Sheet Jan
A1: {=portfolio} -> 38 DN | D1: January Actual v. Expected | G1: January Actual v. Forecasted
A2: Total | C2: =SUM(C4:C98) -> 1879993.2 | D2: =SUM(D4:D98) -> 3100330.9 | E2: =C2-D2 -> -1220337.6 | F2: =IFERROR(E2/D2, 0) -> -0.39361528 | G2: =SUM(G4:G98) -> 2316666 | H2: =C2-G2 -> -436672.78 | I2: =IFERROR(H2/G2, 0) -> -0.1884919 | J2: =IF(AND(TODAY()>DATE(2024, 1, 1), COUNTA(Sites[Site])<>(COUNT(C:C)-1)), "Some sites are missing actual data; if new sites were added, make sure they are aligned correctly (including prior months!)", "")
A3: Site | B3: State | C3: Actual | D3: Expected | E3: Delta | F3: % | G3: Forecasted | H3: Delta | I3: % | J3: Notes | K3: Service Requests
A4: {=Sites[Site]} -> 6th St. | B4: {=Sites[State]} -> CA | C4: 129016 | D4: 74840.77 | E4: =IF(AND(ISNUMBER(C4),ISNUMBER(D4)), C4-D4, "") -> 54175.23 | F4: =IFERROR(E4/D4, "") -> 0.72387323 | G4: 144521 | H4: =IF(AND(ISNUMBER(C4),ISNUMBER(G4)), C4-G4, "") -> -15505 | I4: =IFERROR(H4/G4, "") -> -0.10728545 | J4: 1. PAD 2 inverters and Meter 2 tripped offline at 13:10 on 01/07 due to missing Phase A voltage. The technician found the main breaker open and closed it, restoring PAD 2 inverters at 09:00 on 01/08. Additionally, Inverter 19 lost communication at 13:00 on 01/07 due to a thermal event in the power head control board. It was sent for RMA. A spare inverter was installed from storage, bringing the system back online at 13:15 on 01/08. | K4: 1.SR095378
A5: Barton Acres | B5: MA | C5: 56999 | D5: 142857.9 | E5: =IF(AND(ISNUMBER(C5),ISNUMBER(D5)), C5-D5, "") -> -85858.9 | F5: =IFERROR(E5/D5, "") -> -0.60100911 | G5: 69105.15 | H5: =IF(AND(ISNUMBER(C5),ISNUMBER(G5)), C5-G5, "") -> -12106.15 | I5: =IFERROR(H5/G5, "") -> -0.17518448 | J5: 1.Site was taken offline from 9:00AM to 9:45AM on 01/27 as technician was onsite to collect DGA samples. | K5: 1.SR095405
A6: Bowden | B6: MA | C6: 138818 | D6: 194548.5 | E6: =IF(AND(ISNUMBER(C6),ISNUMBER(D6)), C6-D6, "") -> -55730.5 | F6: =IFERROR(E6/D6, "") -> -0.2864607 | G6: 166837.3 | H6: =IF(AND(ISNUMBER(C6),ISNUMBER(G6)), C6-G6, "") -> -28019.3 | I6: =IFERROR(H6/G6, "") -> -0.16794386 | J6: 1. Inverter 4 tripped offline at 07:45 AM on 01/06. The technician power cycled it, restoring operation at 13:00. 2. The site tripped offline at 22:00 on 01/29 and was restored at 07:00 on 01/30 after remotely closing the recloser. | K6: 1.SR095329 2.SR096129 | L6: SR096129
A7: Blair Wire Village | B7: MA | C7: 67575 | D7: 148603.1 | E7: =IF(AND(ISNUMBER(C7),ISNUMBER(D7)), C7-D7, "") -> -81028.1 | F7: =IFERROR(E7/D7, "") -> -0.54526521 | G7: 82695.73 | H7: =IF(AND(ISNUMBER(C7),ISNUMBER(G7)), C7-G7, "") -> -15120.73 | I7: =IFERROR(H7/G7, "") -> -0.18284777
A8: Boutilier | B8: MA | C8: 197770 | D8: 316212.5 | E8: =IF(AND(ISNUMBER(C8),ISNUMBER(D8)), C8-D8, "") -> -118442.5 | F8: =IFERROR(E8/D8, "") -> -0.37456615 | G8: 189703.5 | H8: =IF(AND(ISNUMBER(C8),ISNUMBER(G8)), C8-G8, "") -> 8066.5 | I8: =IFERROR(H8/G8, "") -> 0.042521619
A9: Cherry Valley | B9: MA | C9: 62784 | D9: 141889.9 | E9: =IF(AND(ISNUMBER(C9),ISNUMBER(D9)), C9-D9, "") -> -79105.9 | F9: =IFERROR(E9/D9, "") -> -0.55751607 | G9: 77483 | H9: =IF(AND(ISNUMBER(C9),ISNUMBER(G9)), C9-G9, "") -> -14699 | I9: =IFERROR(H9/G9, "") -> -0.18970613 | J9: 1. The site tripped offline at 14:00 on 01/24 due to a utility outage. After power was restored, the technician re-energized the site, bringing it back online at 08:45 on 01/25. | K9: 1.SR095966
A10: Cohasse | B10: MA | C10: 68246 | D10: 140408.6 | E10: =IF(AND(ISNUMBER(C10),ISNUMBER(D10)), C10-D10, "") -> -72162.6 | F10: =IFERROR(E10/D10, "") -> -0.51394715 | G10: 113608.5 | H10: =IF(AND(ISNUMBER(C10),ISNUMBER(G10)), C10-G10, "") -> -45362.5 | I10: =IFERROR(H10/G10, "") -> -0.39928791
A11: ISM Dighton Solar 2 | B11: MA | C11: 216783 | D11: 272074.2 | E11: =IF(AND(ISNUMBER(C11),ISNUMBER(D11)), C11-D11, "") -> -55291.2 | F11: =IFERROR(E11/D11, "") -> -0.20322103 | G11: 194872.6 | H11: =IF(AND(ISNUMBER(C11),ISNUMBER(G11)), C11-G11, "") -> 21910.4 | I11: =IFERROR(H11/G11, "") -> 0.11243448 | J11: 1. The site tripped offline at 06:45 AM and was restored at 08:30 AM on 01/04 after a remote recloser operation. 2. Inverter 2, Module 4 tripped offline at 10:15 on 01/26. PE replaced the fuse and re-energized the inverter. It was back online at 11:00 on 01/27. | K11: 1.SR095306 2.SR095988 | L11: SR095988
A12: Dudley River 1 | B12: MA | C12: 81072 | D12: 112668.6 | E12: =IF(AND(ISNUMBER(C12),ISNUMBER(D12)), C12-D12, "") -> -31596.6 | F12: =IFERROR(E12/D12, "") -> -0.28043838 | G12: 83342.55 | H12: =IF(AND(ISNUMBER(C12),ISNUMBER(G12)), C12-G12, "") -> -2270.55 | I12: =IFERROR(H12/G12, "") -> -0.027243587 | J12: 1. The site was taken offline from 11:00 AM to 12:00 PM on 01/09 due to technicians was onsite to collect a DGA sample. | K12: 1.SR095426
A13: Dudley River 2 | B13: MA | C13: 77646 | D13: 116307.2 | E13: =IF(AND(ISNUMBER(C13),ISNUMBER(D13)), C13-D13, "") -> -38661.2 | F13: =IFERROR(E13/D13, "") -> -0.3324059 | G13: 81508.99 | H13: =IF(AND(ISNUMBER(C13),ISNUMBER(G13)), C13-G13, "") -> -3862.99 | I13: =IFERROR(H13/G13, "") -> -0.047393422 | J13: 1.Inverters tripped offline at 8:45AM on 01/08 due to Y3 bushing on the transformer has a leak and B phase BON fuse was blown and back online at 10:30AM on 01/09 after INCOM has been replaced the Bayonet Fuse and re-energized. 2. Inverter 2 did not start production on 01/26 due to a soft shutdown fault. The technician found the keypad bulging due to water and ice intrusion. It was replaced, and the inverter was re-energized and back online at 12:15 PM on the same day. | K13: 1.SR095387 2.SR095983 | L13: SR095983
A14: Dudley River 3 | B14: MA | C14: 94540 | D14: 117412.4 | E14: =IF(AND(ISNUMBER(C14),ISNUMBER(D14)), C14-D14, "") -> -22872.4 | F14: =IFERROR(E14/D14, "") -> -0.19480396 | G14: 83727.59 | H14: =IF(AND(ISNUMBER(C14),ISNUMBER(G14)), C14-G14, "") -> 10812.41 | I14: =IFERROR(H14/G14, "") -> 0.12913796 | J14: 1. The site was taken offline from 10:45 AM to 12:00 PM on 01/09 as a technician was onsite to collect DGA samples | K14: 1. SR095427
A15: Flint Pond | B15: MA | C15: 30334 | D15: 62237.73 | E15: =IF(AND(ISNUMBER(C15),ISNUMBER(D15)), C15-D15, "") -> -31903.73 | F15: =IFERROR(E15/D15, "") -> -0.51261076 | G15: 33375.62 | H15: =IF(AND(ISNUMBER(C15),ISNUMBER(G15)), C15-G15, "") -> -3041.62 | I15: =IFERROR(H15/G15, "") -> -0.091132989 | J15: 1.Site was taken offline from 8:10 AM to 9:10 AM on 01/15 due to a technician checking in to replace the capacitors and SRV board in Inverter A. | K15: 1.SR092409
A16: Incom | B16: MA | C16: 130021 | D16: 227416.1 | E16: =IF(AND(ISNUMBER(C16),ISNUMBER(D16)), C16-D16, "") -> -97395.1 | F16: =IFERROR(E16/D16, "") -> -0.42826827 | G16: 219053.9 | H16: =IF(AND(ISNUMBER(C16),ISNUMBER(G16)), C16-G16, "") -> -89032.9 | I16: =IFERROR(H16/G16, "") -> -0.40644289 | J16: 1.Site was tripped offline due to SEL relay open at 02:45 AM on 01/02. The technician stated that a utility pole was leaning on a tree. After being re-energized, the site was back online at 10:15 AM on 01/08. | K16: 1.SR095216
A17: JH | B17: MA | C17: 61371 | D17: 130704.5 | E17: =IF(AND(ISNUMBER(C17),ISNUMBER(D17)), C17-D17, "") -> -69333.5 | F17: =IFERROR(E17/D17, "") -> -0.53045993 | G17: 105686.5 | H17: =IF(AND(ISNUMBER(C17),ISNUMBER(G17)), C17-G17, "") -> -44315.5 | I17: =IFERROR(H17/G17, "") -> -0.41931089
A18: Ledeaux | B18: MA | C18: 55084 | D18: 97988.62 | E18: =IF(AND(ISNUMBER(C18),ISNUMBER(D18)), C18-D18, "") -> -42904.62 | F18: =IFERROR(E18/D18, "") -> -0.43785309 | G18: 98275.13 | H18: =IF(AND(ISNUMBER(C18),ISNUMBER(G18)), C18-G18, "") -> -43191.13 | I18: =IFERROR(H18/G18, "") -> -0.43949197
A19: Palombo A | B19: MA | C19: 160891 | D19: 285170.7 | E19: =IF(AND(ISNUMBER(C19),ISNUMBER(D19)), C19-D19, "") -> -124279.7 | F19: =IFERROR(E19/D19, "") -> -0.43580811 | G19: 250093 | H19: =IF(AND(ISNUMBER(C19),ISNUMBER(G19)), C19-G19, "") -> -89202.003 | I19: =IFERROR(H19/G19, "") -> -0.35667533
A20: Palombo B | B20: MA | C20: 65753 | D20: 144714.1 | E20: =IF(AND(ISNUMBER(C20),ISNUMBER(D20)), C20-D20, "") -> -78961.1 | F20: =IFERROR(E20/D20, "") -> -0.54563515 | G20: 71408.82 | H20: =IF(AND(ISNUMBER(C20),ISNUMBER(G20)), C20-G20, "") -> -5655.82 | I20: =IFERROR(H20/G20, "") -> -0.079203381
A21: St Josephs Church | B21: MA | C21: 69927 | D21: 146021.7 | E21: =IF(AND(ISNUMBER(C21),ISNUMBER(D21)), C21-D21, "") -> -76094.7 | F21: =IFERROR(E21/D21, "") -> -0.52111912 | G21: 91072.42 | H21: =IF(AND(ISNUMBER(C21),ISNUMBER(G21)), C21-G21, "") -> -21145.42 | I21: =IFERROR(H21/G21, "") -> -0.23218248
A22: Sunset A | B22: MA | C22: 27107 | D22: 67386.6 | E22: =IF(AND(ISNUMBER(C22),ISNUMBER(D22)), C22-D22, "") -> -40279.6 | F22: =IFERROR(E22/D22, "") -> -0.59773902 | G22: 32533.05 | H22: =IF(AND(ISNUMBER(C22),ISNUMBER(G22)), C22-G22, "") -> -5426.05 | I22: =IFERROR(H22/G22, "") -> -0.16678578
A23: Sunset B | B23: MA | C23: 26946.25 | D23: 49373.03 | E23: =IF(AND(ISNUMBER(C23),ISNUMBER(D23)), C23-D23, "") -> -22426.78 | F23: =IFERROR(E23/D23, "") -> -0.45423139 | G23: 32145.45 | H23: =IF(AND(ISNUMBER(C23),ISNUMBER(G23)), C23-G23, "") -> -5199.2 | I23: =IFERROR(H23/G23, "") -> -0.16173984
A24: Woodchuck | B24: MA | C24: 61310 | D24: 111494.1 | E24: =IF(AND(ISNUMBER(C24),ISNUMBER(D24)), C24-D24, "") -> -50184.1 | F24: =IFERROR(E24/D24, "") -> -0.45010543 | G24: 95616.23 | H24: =IF(AND(ISNUMBER(C24),ISNUMBER(G24)), C24-G24, "") -> -34306.23 | I24: =IFERROR(H24/G24, "") -> -0.35879087

Sheet Feb
A1: {=portfolio} -> 38 DN | D1: February Actual v. Expected | G1: February Actual v. Forecasted
A2: Total | C2: =SUM(C4:C99) -> 0 | D2: =SUM(D4:D99) -> 0 | E2: =C2-D2 -> 0 | F2: =IFERROR(E2/D2, 0) -> 0 | G2: =SUM(G4:G99) -> 0 | H2: =C2-G2 -> 0 | I2: =IFERROR(H2/G2, 0) -> 0 | J2: =IF(AND(TODAY()>DATE(2024, 2, 1), COUNTA(Sites[Site])<>(COUNT(C:C)-1)), "Some sites are missing actual data; if new sites were added, make sure they are aligned correctly (including prior months!)", "") -> Some sites are missing actual data; if new sites were added, make sure they are aligned correctly (including prior months!)
A3: Site | B3: State | C3: Actual | D3: Expected | E3: Delta | F3: % | G3: Forecasted | H3: Delta | I3: % | J3: Notes | K3: Service Requests
A4: {=Sites[Site]} -> 6th St. | B4: {=Sites[State]} -> CA | E4: =IF(AND(ISNUMBER(C4),ISNUMBER(D4)), C4-D4, "") | F4: =IFERROR(E4/D4, "") | H4: =IF(AND(ISNUMBER(C4),ISNUMBER(G4)), C4-G4, "") | I4: =IFERROR(H4/G4, "")
A5: Barton Acres | B5: MA | E5: =IF(AND(ISNUMBER(C5),ISNUMBER(D5)), C5-D5, "") | F5: =IFERROR(E5/D5, "") | H5: =IF(AND(ISNUMBER(C5),ISNUMBER(G5)), C5-G5, "") | I5: =IFERROR(H5/G5, "")
A6: Bowden | B6: MA | E6: =IF(AND(ISNUMBER(C6),ISNUMBER(D6)), C6-D6, "") | F6: =IFERROR(E6/D6, "") | H6: =IF(AND(ISNUMBER(C6),ISNUMBER(G6)), C6-G6, "") | I6: =IFERROR(H6/G6, "")
A7: Blair Wire Village | B7: MA | E7: =IF(AND(ISNUMBER(C7),ISNUMBER(D7)), C7-D7, "") | F7: =IFERROR(E7/D7, "") | H7: =IF(AND(ISNUMBER(C7),ISNUMBER(G7)), C7-G7, "") | I7: =IFERROR(H7/G7, "")
A8: Boutilier | B8: MA | E8: =IF(AND(ISNUMBER(C8),ISNUMBER(D8)), C8-D8, "") | F8: =IFERROR(E8/D8, "") | H8: =IF(AND(ISNUMBER(C8),ISNUMBER(G8)), C8-G8, "") | I8: =IFERROR(H8/G8, "")
A9: Cherry Valley | B9: MA | E9: =IF(AND(ISNUMBER(C9),ISNUMBER(D9)), C9-D9, "") | F9: =IFERROR(E9/D9, "") | H9: =IF(AND(ISNUMBER(C9),ISNUMBER(G9)), C9-G9, "") | I9: =IFERROR(H9/G9, "")
A10: Cohasse | B10: MA | E10: =IF(AND(ISNUMBER(C10),ISNUMBER(D10)), C10-D10, "") | F10: =IFERROR(E10/D10, "") | H10: =IF(AND(ISNUMBER(C10),ISNUMBER(G10)), C10-G10, "") | I10: =IFERROR(H10/G10, "")
A11: ISM Dighton Solar 2 | B11: MA | E11: =IF(AND(ISNUMBER(C11),ISNUMBER(D11)), C11-D11, "") | F11: =IFERROR(E11/D11, "") | H11: =IF(AND(ISNUMBER(C11),ISNUMBER(G11)), C11-G11, "") | I11: =IFERROR(H11/G11, "")
A12: Dudley River 1 | B12: MA | E12: =IF(AND(ISNUMBER(C12),ISNUMBER(D12)), C12-D12, "") | F12: =IFERROR(E12/D12, "") | H12: =IF(AND(ISNUMBER(C12),ISNUMBER(G12)), C12-G12, "") | I12: =IFERROR(H12/G12, "")
A13: Dudley River 2 | B13: MA | E13: =IF(AND(ISNUMBER(C13),ISNUMBER(D13)), C13-D13, "") | F13: =IFERROR(E13/D13, "") | H13: =IF(AND(ISNUMBER(C13),ISNUMBER(G13)), C13-G13, "") | I13: =IFERROR(H13/G13, "")
A14: Dudley River 3 | B14: MA | E14: =IF(AND(ISNUMBER(C14),ISNUMBER(D14)), C14-D14, "") | F14: =IFERROR(E14/D14, "") | H14: =IF(AND(ISNUMBER(C14),ISNUMBER(G14)), C14-G14, "") | I14: =IFERROR(H14/G14, "")
A15: Flint Pond | B15: MA | E15: =IF(AND(ISNUMBER(C15),ISNUMBER(D15)), C15-D15, "") | F15: =IFERROR(E15/D15, "") | H15: =IF(AND(ISNUMBER(C15),ISNUMBER(G15)), C15-G15, "") | I15: =IFERROR(H15/G15, "")
A16: Incom | B16: MA | E16: =IF(AND(ISNUMBER(C16),ISNUMBER(D16)), C16-D16, "") | F16: =IFERROR(E16/D16, "") | H16: =IF(AND(ISNUMBER(C16),ISNUMBER(G16)), C16-G16, "") | I16: =IFERROR(H16/G16, "")
A17: JH | B17: MA | F17: =IFERROR(E17/D17, "") | H17: =IF(AND(ISNUMBER(C17),ISNUMBER(G17)), C17-G17, "") | I17: =IFERROR(H17/G17, "")
A18: Ledeaux | B18: MA | E18: =IF(AND(ISNUMBER(C18),ISNUMBER(D18)), C18-D18, "") | F18: =IFERROR(E18/D18, "") | H18: =IF(AND(ISNUMBER(C18),ISNUMBER(G18)), C18-G18, "") | I18: =IFERROR(H18/G18, "")
A19: Palombo A | B19: MA | E19: =IF(AND(ISNUMBER(C19),ISNUMBER(D19)), C19-D19, "") | F19: =IFERROR(E19/D19, "") | H19: =IF(AND(ISNUMBER(C19),ISNUMBER(G19)), C19-G19, "") | I19: =IFERROR(H19/G19, "")
A20: Palombo B | B20: MA | E20: =IF(AND(ISNUMBER(C20),ISNUMBER(D20)), C20-D20, "") | F20: =IFERROR(E20/D20, "") | H20: =IF(AND(ISNUMBER(C20),ISNUMBER(G20)), C20-G20, "") | I20: =IFERROR(H20/G20, "")
A21: St Josephs Church | B21: MA | E21: =IF(AND(ISNUMBER(C21),ISNUMBER(D21)), C21-D21, "") | F21: =IFERROR(E21/D21, "") | H21: =IF(AND(ISNUMBER(C21),ISNUMBER(G21)), C21-G21, "") | I21: =IFERROR(H21/G21, "")
A22: Sunset A | B22: MA | E22: =IF(AND(ISNUMBER(C22),ISNUMBER(D22)), C22-D22, "") | F22: =IFERROR(E22/D22, "") | H22: =IF(AND(ISNUMBER(C22),ISNUMBER(G22)), C22-G22, "") | I22: =IFERROR(H22/G22, "")
A23: Sunset B | B23: MA | E23: =IF(AND(ISNUMBER(C23),ISNUMBER(D23)), C23-D23, "") | F23: =IFERROR(E23/D23, "") | H23: =IF(AND(ISNUMBER(C23),ISNUMBER(G23)), C23-G23, "") | I23: =IFERROR(H23/G23, "")
A24: Woodchuck | B24: MA | E24: =IF(AND(ISNUMBER(C24),ISNUMBER(D24)), C24-D24, "") | F24: =IFERROR(E24/D24, "") | H24: =IF(AND(ISNUMBER(C24),ISNUMBER(G24)), C24-G24, "") | I24: =IFERROR(H24/G24, "")

Sheet Mar
A1: {=portfolio} -> 38 DN | D1: March Actual v. Expected | G1: March Actual v. Forecasted
A2: Total | C2: =SUM(C4:C99) -> 0 | D2: =SUM(D4:D99) -> 0 | E2: =C2-D2 -> 0 | F2: =IFERROR(E2/D2, 0) -> 0 | G2: =SUM(G4:G99) -> 0 | H2: =C2-G2 -> 0 | I2: =IFERROR(H2/G2, 0) -> 0 | J2: =IF(AND(TODAY()>DATE(2024, 3, 1), COUNTA(Sites[Site])<>(COUNT(C:C)-1)), "Some sites are missing actual data; if new sites were added, make sure they are aligned correctly (including prior months!)", "") -> Some sites are missing actual data; if new sites were added, make sure they are aligned correctly (including prior months!)
A3: Site | B3: State | C3: Actual | D3: Expected | E3: Delta | F3: % | G3: Forecasted | H3: Delta | I3: % | J3: Notes | K3: Service Requests
A4: {=Sites[Site]} -> 6th St. | B4: {=Sites[State]} -> CA | E4: =IF(AND(ISNUMBER(C4),ISNUMBER(D4)), C4-D4, "") | F4: =IFERROR(E4/D4, "") | H4: =IF(AND(ISNUMBER(C4),ISNUMBER(G4)), C4-G4, "") | I4: =IFERROR(H4/G4, "")
A5: Barton Acres | B5: MA | E5: =IF(AND(ISNUMBER(C5),ISNUMBER(D5)), C5-D5, "") | F5: =IFERROR(E5/D5, "") | H5: =IF(AND(ISNUMBER(C5),ISNUMBER(G5)), C5-G5, "") | I5: =IFERROR(H5/G5, "")
A6: Bowden | B6: MA | E6: =IF(AND(ISNUMBER(C6),ISNUMBER(D6)), C6-D6, "") | F6: =IFERROR(E6/D6, "") | H6: =IF(AND(ISNUMBER(C6),ISNUMBER(G6)), C6-G6, "") | I6: =IFERROR(H6/G6, "")
A7: Blair Wire Village | B7: MA | E7: =IF(AND(ISNUMBER(C7),ISNUMBER(D7)), C7-D7, "") | F7: =IFERROR(E7/D7, "") | H7: =IF(AND(ISNUMBER(C7),ISNUMBER(G7)), C7-G7, "") | I7: =IFERROR(H7/G7, "")
A8: Boutilier | B8: MA | E8: =IF(AND(ISNUMBER(C8),ISNUMBER(D8)), C8-D8, "") | F8: =IFERROR(E8/D8, "") | H8: =IF(AND(ISNUMBER(C8),ISNUMBER(G8)), C8-G8, "") | I8: =IFERROR(H8/G8, "")
A9: Cherry Valley | B9: MA | E9: =IF(AND(ISNUMBER(C9),ISNUMBER(D9)), C9-D9, "") | F9: =IFERROR(E9/D9, "") | H9: =IF(AND(ISNUMBER(C9),ISNUMBER(G9)), C9-G9, "") | I9: =IFERROR(H9/G9, "")
A10: Cohasse | B10: MA | E10: =IF(AND(ISNUMBER(C10),ISNUMBER(D10)), C10-D10, "") | F10: =IFERROR(E10/D10, "") | H10: =IF(AND(ISNUMBER(C10),ISNUMBER(G10)), C10-G10, "") | I10: =IFERROR(H10/G10, "")
A11: ISM Dighton Solar 2 | B11: MA | E11: =IF(AND(ISNUMBER(C11),ISNUMBER(D11)), C11-D11, "") | F11: =IFERROR(E11/D11, "") | H11: =IF(AND(ISNUMBER(C11),ISNUMBER(G11)), C11-G11, "") | I11: =IFERROR(H11/G11, "")
A12: Dudley River 1 | B12: MA | E12: =IF(AND(ISNUMBER(C12),ISNUMBER(D12)), C12-D12, "") | F12: =IFERROR(E12/D12, "") | H12: =IF(AND(ISNUMBER(C12),ISNUMBER(G12)), C12-G12, "") | I12: =IFERROR(H12/G12, "")
A13: Dudley River 2 | B13: MA | E13: =IF(AND(ISNUMBER(C13),ISNUMBER(D13)), C13-D13, "") | F13: =IFERROR(E13/D13, "") | H13: =IF(AND(ISNUMBER(C13),ISNUMBER(G13)), C13-G13, "") | I13: =IFERROR(H13/G13, "")
A14: Dudley River 3 | B14: MA | E14: =IF(AND(ISNUMBER(C14),ISNUMBER(D14)), C14-D14, "") | F14: =IFERROR(E14/D14, "") | H14: =IF(AND(ISNUMBER(C14),ISNUMBER(G14)), C14-G14, "") | I14: =IFERROR(H14/G14, "")
A15: Flint Pond | B15: MA | E15: =IF(AND(ISNUMBER(C15),ISNUMBER(D15)), C15-D15, "") | F15: =IFERROR(E15/D15, "") | H15: =IF(AND(ISNUMBER(C15),ISNUMBER(G15)), C15-G15, "") | I15: =IFERROR(H15/G15, "")
A16: Incom | B16: MA | E16: =IF(AND(ISNUMBER(C16),ISNUMBER(D16)), C16-D16, "") | F16: =IFERROR(E16/D16, "") | H16: =IF(AND(ISNUMBER(C16),ISNUMBER(G16)), C16-G16, "") | I16: =IFERROR(H16/G16, "")
A17: JH | B17: MA | F17: =IFERROR(E17/D17, "") | H17: =IF(AND(ISNUMBER(C17),ISNUMBER(G17)), C17-G17, "") | I17: =IFERROR(H17/G17, "")
A18: Ledeaux | B18: MA | E18: =IF(AND(ISNUMBER(C18),ISNUMBER(D18)), C18-D18, "") | F18: =IFERROR(E18/D18, "") | H18: =IF(AND(ISNUMBER(C18),ISNUMBER(G18)), C18-G18, "") | I18: =IFERROR(H18/G18, "")
A19: Palombo A | B19: MA | E19: =IF(AND(ISNUMBER(C19),ISNUMBER(D19)), C19-D19, "") | F19: =IFERROR(E19/D19, "") | H19: =IF(AND(ISNUMBER(C19),ISNUMBER(G19)), C19-G19, "") | I19: =IFERROR(H19/G19, "")
A20: Palombo B | B20: MA | E20: =IF(AND(ISNUMBER(C20),ISNUMBER(D20)), C20-D20, "") | F20: =IFERROR(E20/D20, "") | H20: =IF(AND(ISNUMBER(C20),ISNUMBER(G20)), C20-G20, "") | I20: =IFERROR(H20/G20, "")
A21: St Josephs Church | B21: MA | E21: =IF(AND(ISNUMBER(C21),ISNUMBER(D21)), C21-D21, "") | F21: =IFERROR(E21/D21, "") | H21: =IF(AND(ISNUMBER(C21),ISNUMBER(G21)), C21-G21, "") | I21: =IFERROR(H21/G21, "")
A22: Sunset A | B22: MA | E22: =IF(AND(ISNUMBER(C22),ISNUMBER(D22)), C22-D22, "") | F22: =IFERROR(E22/D22, "") | H22: =IF(AND(ISNUMBER(C22),ISNUMBER(G22)), C22-G22, "") | I22: =IFERROR(H22/G22, "")
A23: Sunset B | B23: MA | E23: =IF(AND(ISNUMBER(C23),ISNUMBER(D23)), C23-D23, "") | F23: =IFERROR(E23/D23, "") | H23: =IF(AND(ISNUMBER(C23),ISNUMBER(G23)), C23-G23, "") | I23: =IFERROR(H23/G23, "")
A24: Woodchuck | B24: MA | E24: =IF(AND(ISNUMBER(C24),ISNUMBER(D24)), C24-D24, "") | F24: =IFERROR(E24/D24, "") | H24: =IF(AND(ISNUMBER(C24),ISNUMBER(G24)), C24-G24, "") | I24: =IFERROR(H24/G24, "")

Sheet Apr
A1: {=portfolio} -> 38 DN | D1: April Actual v. Expected | G1: April Actual v. Forecasted
A2: Total | C2: =SUM(C4:C99) -> 0 | D2: =SUM(D4:D99) -> 0 | E2: =C2-D2 -> 0 | F2: =IFERROR(E2/D2, 0) -> 0 | G2: =SUM(G4:G99) -> 0 | H2: =C2-G2 -> 0 | I2: =IFERROR(H2/G2, 0) -> 0 | J2: =IF(AND(TODAY()>DATE(2024, 4, 1), COUNTA(Sites[Site])<>(COUNT(C:C)-1)), "Some sites are missing actual data; if new sites were added, make sure they are aligned correctly (including prior months!)", "") -> Some sites are missing actual data; if new sites were added, make sure they are aligned correctly (including prior months!)
A3: Site | B3: State | C3: Actual | D3: Expected | E3: Delta | F3: % | G3: Forecasted | H3: Delta | I3: % | J3: Notes | K3: Service Requests
A4: {=Sites[Site]} -> 6th St. | B4: {=Sites[State]} -> CA | E4: =IF(AND(ISNUMBER(C4),ISNUMBER(D4)), C4-D4, "") | F4: =IFERROR(E4/D4, "") | H4: =IF(AND(ISNUMBER(C4),ISNUMBER(G4)), C4-G4, "") | I4: =IFERROR(H4/G4, "")
A5: Barton Acres | B5: MA | E5: =IF(AND(ISNUMBER(C5),ISNUMBER(D5)), C5-D5, "") | F5: =IFERROR(E5/D5, "") | H5: =IF(AND(ISNUMBER(C5),ISNUMBER(G5)), C5-G5, "") | I5: =IFERROR(H5/G5, "")
A6: Bowden | B6: MA | E6: =IF(AND(ISNUMBER(C6),ISNUMBER(D6)), C6-D6, "") | F6: =IFERROR(E6/D6, "") | H6: =IF(AND(ISNUMBER(C6),ISNUMBER(G6)), C6-G6, "") | I6: =IFERROR(H6/G6, "")
A7: Blair Wire Village | B7: MA | E7: =IF(AND(ISNUMBER(C7),ISNUMBER(D7)), C7-D7, "") | F7: =IFERROR(E7/D7, "") | H7: =IF(AND(ISNUMBER(C7),ISNUMBER(G7)), C7-G7, "") | I7: =IFERROR(H7/G7, "")
A8: Boutilier | B8: MA | E8: =IF(AND(ISNUMBER(C8),ISNUMBER(D8)), C8-D8, "") | F8: =IFERROR(E8/D8, "") | H8: =IF(AND(ISNUMBER(C8),ISNUMBER(G8)), C8-G8, "") | I8: =IFERROR(H8/G8, "")
A9: Cherry Valley | B9: MA | E9: =IF(AND(ISNUMBER(C9),ISNUMBER(D9)), C9-D9, "") | F9: =IFERROR(E9/D9, "") | H9: =IF(AND(ISNUMBER(C9),ISNUMBER(G9)), C9-G9, "") | I9: =IFERROR(H9/G9, "")
A10: Cohasse | B10: MA | E10: =IF(AND(ISNUMBER(C10),ISNUMBER(D10)), C10-D10, "") | F10: =IFERROR(E10/D10, "") | H10: =IF(AND(ISNUMBER(C10),ISNUMBER(G10)), C10-G10, "") | I10: =IFERROR(H10/G10, "")
A11: ISM Dighton Solar 2 | B11: MA | E11: =IF(AND(ISNUMBER(C11),ISNUMBER(D11)), C11-D11, "") | F11: =IFERROR(E11/D11, "") | H11: =IF(AND(ISNUMBER(C11),ISNUMBER(G11)), C11-G11, "") | I11: =IFERROR(H11/G11, "")
A12: Dudley River 1 | B12: MA | E12: =IF(AND(ISNUMBER(C12),ISNUMBER(D12)), C12-D12, "") | F12: =IFERROR(E12/D12, "") | H12: =IF(AND(ISNUMBER(C12),ISNUMBER(G12)), C12-G12, "") | I12: =IFERROR(H12/G12, "")
A13: Dudley River 2 | B13: MA | E13: =IF(AND(ISNUMBER(C13),ISNUMBER(D13)), C13-D13, "") | F13: =IFERROR(E13/D13, "") | H13: =IF(AND(ISNUMBER(C13),ISNUMBER(G13)), C13-G13, "") | I13: =IFERROR(H13/G13, "")
A14: Dudley River 3 | B14: MA | E14: =IF(AND(ISNUMBER(C14),ISNUMBER(D14)), C14-D14, "") | F14: =IFERROR(E14/D14, "") | H14: =IF(AND(ISNUMBER(C14),ISNUMBER(G14)), C14-G14, "") | I14: =IFERROR(H14/G14, "")
A15: Flint Pond | B15: MA | E15: =IF(AND(ISNUMBER(C15),ISNUMBER(D15)), C15-D15, "") | F15: =IFERROR(E15/D15, "") | H15: =IF(AND(ISNUMBER(C15),ISNUMBER(G15)), C15-G15, "") | I15: =IFERROR(H15/G15, "")
A16: Incom | B16: MA | E16: =IF(AND(ISNUMBER(C16),ISNUMBER(D16)), C16-D16, "") | F16: =IFERROR(E16/D16, "") | H16: =IF(AND(ISNUMBER(C16),ISNUMBER(G16)), C16-G16, "") | I16: =IFERROR(H16/G16, "")
A17: JH | B17: MA | F17: =IFERROR(E17/D17, "") | H17: =IF(AND(ISNUMBER(C17),ISNUMBER(G17)), C17-G17, "") | I17: =IFERROR(H17/G17, "")
A18: Ledeaux | B18: MA | E18: =IF(AND(ISNUMBER(C18),ISNUMBER(D18)), C18-D18, "") | F18: =IFERROR(E18/D18, "") | H18: =IF(AND(ISNUMBER(C18),ISNUMBER(G18)), C18-G18, "") | I18: =IFERROR(H18/G18, "")
A19: Palombo A | B19: MA | E19: =IF(AND(ISNUMBER(C19),ISNUMBER(D19)), C19-D19, "") | F19: =IFERROR(E19/D19, "") | H19: =IF(AND(ISNUMBER(C19),ISNUMBER(G19)), C19-G19, "") | I19: =IFERROR(H19/G19, "")
A20: Palombo B | B20: MA | E20: =IF(AND(ISNUMBER(C20),ISNUMBER(D20)), C20-D20, "") | F20: =IFERROR(E20/D20, "") | H20: =IF(AND(ISNUMBER(C20),ISNUMBER(G20)), C20-G20, "") | I20: =IFERROR(H20/G20, "")
A21: St Josephs Church | B21: MA | E21: =IF(AND(ISNUMBER(C21),ISNUMBER(D21)), C21-D21, "") | F21: =IFERROR(E21/D21, "") | H21: =IF(AND(ISNUMBER(C21),ISNUMBER(G21)), C21-G21, "") | I21: =IFERROR(H21/G21, "")
A22: Sunset A | B22: MA | E22: =IF(AND(ISNUMBER(C22),ISNUMBER(D22)), C22-D22, "") | F22: =IFERROR(E22/D22, "") | H22: =IF(AND(ISNUMBER(C22),ISNUMBER(G22)), C22-G22, "") | I22: =IFERROR(H22/G22, "")
A23: Sunset B | B23: MA | E23: =IF(AND(ISNUMBER(C23),ISNUMBER(D23)), C23-D23, "") | F23: =IFERROR(E23/D23, "") | H23: =IF(AND(ISNUMBER(C23),ISNUMBER(G23)), C23-G23, "") | I23: =IFERROR(H23/G23, "")
A24: Woodchuck | B24: MA | E24: =IF(AND(ISNUMBER(C24),ISNUMBER(D24)), C24-D24, "") | F24: =IFERROR(E24/D24, "") | H24: =IF(AND(ISNUMBER(C24),ISNUMBER(G24)), C24-G24, "") | I24: =IFERROR(H24/G24, "")

Sheet May
A1: {=portfolio} -> 38 DN | D1: May Actual v. Expected | G1: May Actual v. Forecasted
A2: Total | C2: =SUM(C4:C99) -> 0 | D2: =SUM(D4:D99) -> 0 | E2: =C2-D2 -> 0 | F2: =IFERROR(E2/D2, 0) -> 0 | G2: =SUM(G4:G99) -> 0 | H2: =C2-G2 -> 0 | I2: =IFERROR(H2/G2, 0) -> 0 | J2: =IF(AND(TODAY()>DATE(2024, 5, 1), COUNTA(Sites[Site])<>(COUNT(C:C)-1)), "Some sites are missing actual data; if new sites were added, make sure they are aligned correctly (including prior months!)", "") -> Some sites are missing actual data; if new sites were added, make sure they are aligned correctly (including prior months!)
A3: Site | B3: State | C3: Actual | D3: Expected | E3: Delta | F3: % | G3: Forecasted | H3: Delta | I3: % | J3: Notes | K3: Service Requests
A4: {=Sites[Site]} -> 6th St. | B4: {=Sites[State]} -> CA | E4: =IF(AND(ISNUMBER(C4),ISNUMBER(D4)), C4-D4, "") | F4: =IFERROR(E4/D4, "") | H4: =IF(AND(ISNUMBER(C4),ISNUMBER(G4)), C4-G4, "") | I4: =IFERROR(H4/G4, "")
A5: Barton Acres | B5: MA | E5: =IF(AND(ISNUMBER(C5),ISNUMBER(D5)), C5-D5, "") | F5: =IFERROR(E5/D5, "") | H5: =IF(AND(ISNUMBER(C5),ISNUMBER(G5)), C5-G5, "") | I5: =IFERROR(H5/G5, "")
A6: Bowden | B6: MA | E6: =IF(AND(ISNUMBER(C6),ISNUMBER(D6)), C6-D6, "") | F6: =IFERROR(E6/D6, "") | H6: =IF(AND(ISNUMBER(C6),ISNUMBER(G6)), C6-G6, "") | I6: =IFERROR(H6/G6, "")
A7: Blair Wire Village | B7: MA | E7: =IF(AND(ISNUMBER(C7),ISNUMBER(D7)), C7-D7, "") | F7: =IFERROR(E7/D7, "") | H7: =IF(AND(ISNUMBER(C7),ISNUMBER(G7)), C7-G7, "") | I7: =IFERROR(H7/G7, "")
A8: Boutilier | B8: MA | E8: =IF(AND(ISNUMBER(C8),ISNUMBER(D8)), C8-D8, "") | F8: =IFERROR(E8/D8, "") | H8: =IF(AND(ISNUMBER(C8),ISNUMBER(G8)), C8-G8, "") | I8: =IFERROR(H8/G8, "")
A9: Cherry Valley | B9: MA | E9: =IF(AND(ISNUMBER(C9),ISNUMBER(D9)), C9-D9, "") | F9: =IFERROR(E9/D9, "") | H9: =IF(AND(ISNUMBER(C9),ISNUMBER(G9)), C9-G9, "") | I9: =IFERROR(H9/G9, "")
A10: Cohasse | B10: MA | E10: =IF(AND(ISNUMBER(C10),ISNUMBER(D10)), C10-D10, "") | F10: =IFERROR(E10/D10, "") | H10: =IF(AND(ISNUMBER(C10),ISNUMBER(G10)), C10-G10, "") | I10: =IFERROR(H10/G10, "")
A11: ISM Dighton Solar 2 | B11: MA | E11: =IF(AND(ISNUMBER(C11),ISNUMBER(D11)), C11-D11, "") | F11: =IFERROR(E11/D11, "") | H11: =IF(AND(ISNUMBER(C11),ISNUMBER(G11)), C11-G11, "") | I11: =IFERROR(H11/G11, "")
A12: Dudley River 1 | B12: MA | E12: =IF(AND(ISNUMBER(C12),ISNUMBER(D12)), C12-D12, "") | F12: =IFERROR(E12/D12, "") | H12: =IF(AND(ISNUMBER(C12),ISNUMBER(G12)), C12-G12, "") | I12: =IFERROR(H12/G12, "")
A13: Dudley River 2 | B13: MA | E13: =IF(AND(ISNUMBER(C13),ISNUMBER(D13)), C13-D13, "") | F13: =IFERROR(E13/D13, "") | H13: =IF(AND(ISNUMBER(C13),ISNUMBER(G13)), C13-G13, "") | I13: =IFERROR(H13/G13, "")
A14: Dudley River 3 | B14: MA | E14: =IF(AND(ISNUMBER(C14),ISNUMBER(D14)), C14-D14, "") | F14: =IFERROR(E14/D14, "") | H14: =IF(AND(ISNUMBER(C14),ISNUMBER(G14)), C14-G14, "") | I14: =IFERROR(H14/G14, "")
A15: Flint Pond | B15: MA | E15: =IF(AND(ISNUMBER(C15),ISNUMBER(D15)), C15-D15, "") | F15: =IFERROR(E15/D15, "") | H15: =IF(AND(ISNUMBER(C15),ISNUMBER(G15)), C15-G15, "") | I15: =IFERROR(H15/G15, "")
A16: Incom | B16: MA | E16: =IF(AND(ISNUMBER(C16),ISNUMBER(D16)), C16-D16, "") | F16: =IFERROR(E16/D16, "") | H16: =IF(AND(ISNUMBER(C16),ISNUMBER(G16)), C16-G16, "") | I16: =IFERROR(H16/G16, "")
A17: JH | B17: MA | F17: =IFERROR(E17/D17, "") | H17: =IF(AND(ISNUMBER(C17),ISNUMBER(G17)), C17-G17, "") | I17: =IFERROR(H17/G17, "")
A18: Ledeaux | B18: MA | E18: =IF(AND(ISNUMBER(C18),ISNUMBER(D18)), C18-D18, "") | F18: =IFERROR(E18/D18, "") | H18: =IF(AND(ISNUMBER(C18),ISNUMBER(G18)), C18-G18, "") | I18: =IFERROR(H18/G18, "")
A19: Palombo A | B19: MA | E19: =IF(AND(ISNUMBER(C19),ISNUMBER(D19)), C19-D19, "") | F19: =IFERROR(E19/D19, "") | H19: =IF(AND(ISNUMBER(C19),ISNUMBER(G19)), C19-G19, "") | I19: =IFERROR(H19/G19, "")
A20: Palombo B | B20: MA | E20: =IF(AND(ISNUMBER(C20),ISNUMBER(D20)), C20-D20, "") | F20: =IFERROR(E20/D20, "") | H20: =IF(AND(ISNUMBER(C20),ISNUMBER(G20)), C20-G20, "") | I20: =IFERROR(H20/G20, "")
A21: St Josephs Church | B21: MA | E21: =IF(AND(ISNUMBER(C21),ISNUMBER(D21)), C21-D21, "") | F21: =IFERROR(E21/D21, "") | H21: =IF(AND(ISNUMBER(C21),ISNUMBER(G21)), C21-G21, "") | I21: =IFERROR(H21/G21, "")
A22: Sunset A | B22: MA | E22: =IF(AND(ISNUMBER(C22),ISNUMBER(D22)), C22-D22, "") | F22: =IFERROR(E22/D22, "") | H22: =IF(AND(ISNUMBER(C22),ISNUMBER(G22)), C22-G22, "") | I22: =IFERROR(H22/G22, "")
A23: Sunset B | B23: MA | E23: =IF(AND(ISNUMBER(C23),ISNUMBER(D23)), C23-D23, "") | F23: =IFERROR(E23/D23, "") | H23: =IF(AND(ISNUMBER(C23),ISNUMBER(G23)), C23-G23, "") | I23: =IFERROR(H23/G23, "")
A24: Woodchuck | B24: MA | E24: =IF(AND(ISNUMBER(C24),ISNUMBER(D24)), C24-D24, "") | F24: =IFERROR(E24/D24, "") | H24: =IF(AND(ISNUMBER(C24),ISNUMBER(G24)), C24-G24, "") | I24: =IFERROR(H24/G24, "")

Sheet Jun
A1: {=portfolio} -> 38 DN | D1: June Actual v. Expected | G1: June Actual v. Forecasted
A2: Total | C2: =SUM(C4:C99) -> 0 | D2: =SUM(D4:D99) -> 0 | E2: =C2-D2 -> 0 | F2: =IFERROR(E2/D2, 0) -> 0 | G2: =SUM(G4:G99) -> 0 | H2: =C2-G2 -> 0 | I2: =IFERROR(H2/G2, 0) -> 0 | J2: =IF(AND(TODAY()>DATE(2024, 6, 1), COUNTA(Sites[Site])<>(COUNT(C:C)-1)), "Some sites are missing actual data; if new sites were added, make sure they are aligned correctly (including prior months!)", "") -> Some sites are missing actual data; if new sites were added, make sure they are aligned correctly (including prior months!)
A3: Site | B3: State | C3: Actual | D3: Expected | E3: Delta | F3: % | G3: Forecasted | H3: Delta | I3: % | J3: Notes | K3: Service Requests
A4: {=Sites[Site]} -> 6th St. | B4: {=Sites[State]} -> CA | E4: =IF(AND(ISNUMBER(C4),ISNUMBER(D4)), C4-D4, "") | F4: =IFERROR(E4/D4, "") | H4: =IF(AND(ISNUMBER(C4),ISNUMBER(G4)), C4-G4, "") | I4: =IFERROR(H4/G4, "")
A5: Barton Acres | B5: MA | E5: =IF(AND(ISNUMBER(C5),ISNUMBER(D5)), C5-D5, "") | F5: =IFERROR(E5/D5, "") | H5: =IF(AND(ISNUMBER(C5),ISNUMBER(G5)), C5-G5, "") | I5: =IFERROR(H5/G5, "")
A6: Bowden | B6: MA | E6: =IF(AND(ISNUMBER(C6),ISNUMBER(D6)), C6-D6, "") | F6: =IFERROR(E6/D6, "") | H6: =IF(AND(ISNUMBER(C6),ISNUMBER(G6)), C6-G6, "") | I6: =IFERROR(H6/G6, "")
A7: Blair Wire Village | B7: MA | E7: =IF(AND(ISNUMBER(C7),ISNUMBER(D7)), C7-D7, "") | F7: =IFERROR(E7/D7, "") | H7: =IF(AND(ISNUMBER(C7),ISNUMBER(G7)), C7-G7, "") | I7: =IFERROR(H7/G7, "")
A8: Boutilier | B8: MA | E8: =IF(AND(ISNUMBER(C8),ISNUMBER(D8)), C8-D8, "") | F8: =IFERROR(E8/D8, "") | H8: =IF(AND(ISNUMBER(C8),ISNUMBER(G8)), C8-G8, "") | I8: =IFERROR(H8/G8, "")
A9: Cherry Valley | B9: MA | E9: =IF(AND(ISNUMBER(C9),ISNUMBER(D9)), C9-D9, "") | F9: =IFERROR(E9/D9, "") | H9: =IF(AND(ISNUMBER(C9),ISNUMBER(G9)), C9-G9, "") | I9: =IFERROR(H9/G9, "")
A10: Cohasse | B10: MA | E10: =IF(AND(ISNUMBER(C10),ISNUMBER(D10)), C10-D10, "") | F10: =IFERROR(E10/D10, "") | H10: =IF(AND(ISNUMBER(C10),ISNUMBER(G10)), C10-G10, "") | I10: =IFERROR(H10/G10, "")
A11: ISM Dighton Solar 2 | B11: MA | E11: =IF(AND(ISNUMBER(C11),ISNUMBER(D11)), C11-D11, "") | F11: =IFERROR(E11/D11, "") | H11: =IF(AND(ISNUMBER(C11),ISNUMBER(G11)), C11-G11, "") | I11: =IFERROR(H11/G11, "")
A12: Dudley River 1 | B12: MA | E12: =IF(AND(ISNUMBER(C12),ISNUMBER(D12)), C12-D12, "") | F12: =IFERROR(E12/D12, "") | H12: =IF(AND(ISNUMBER(C12),ISNUMBER(G12)), C12-G12, "") | I12: =IFERROR(H12/G12, "")
A13: Dudley River 2 | B13: MA | E13: =IF(AND(ISNUMBER(C13),ISNUMBER(D13)), C13-D13, "") | F13: =IFERROR(E13/D13, "") | H13: =IF(AND(ISNUMBER(C13),ISNUMBER(G13)), C13-G13, "") | I13: =IFERROR(H13/G13, "")
A14: Dudley River 3 | B14: MA | E14: =IF(AND(ISNUMBER(C14),ISNUMBER(D14)), C14-D14, "") | F14: =IFERROR(E14/D14, "") | H14: =IF(AND(ISNUMBER(C14),ISNUMBER(G14)), C14-G14, "") | I14: =IFERROR(H14/G14, "")
A15: Flint Pond | B15: MA | E15: =IF(AND(ISNUMBER(C15),ISNUMBER(D15)), C15-D15, "") | F15: =IFERROR(E15/D15, "") | H15: =IF(AND(ISNUMBER(C15),ISNUMBER(G15)), C15-G15, "") | I15: =IFERROR(H15/G15, "")
A16: Incom | B16: MA | E16: =IF(AND(ISNUMBER(C16),ISNUMBER(D16)), C16-D16, "") | F16: =IFERROR(E16/D16, "") | H16: =IF(AND(ISNUMBER(C16),ISNUMBER(G16)), C16-G16, "") | I16: =IFERROR(H16/G16, "")
A17: JH | B17: MA | F17: =IFERROR(E17/D17, "") | H17: =IF(AND(ISNUMBER(C17),ISNUMBER(G17)), C17-G17, "") | I17: =IFERROR(H17/G17, "")
A18: Ledeaux | B18: MA | E18: =IF(AND(ISNUMBER(C18),ISNUMBER(D18)), C18-D18, "") | F18: =IFERROR(E18/D18, "") | H18: =IF(AND(ISNUMBER(C18),ISNUMBER(G18)), C18-G18, "") | I18: =IFERROR(H18/G18, "")
