Workbook
Name JanActual: #REF!
Name JanActual2: #REF!
Name JanExpected: #REF!
Name JanExpectedDelta: #REF!
Name JanExpectedPercent: #REF!
Name JanExpPercent: #REF!
Name JanForecasted: #REF!
Name JanForecastedDelta: #REF!
Name JanForecastedPercent: #REF!
Name portfolio: Sites!$B$1:$B$1
Name Year: Sites!#REF!

Sheet Year to Date
A1: {=portfolio} -> MN8 KEF | D1: Year to Date Actual v. Expected | G1: Year to Date Actual v. Forecasted
A2: Total | C2: =SUM(C4:C95) -> 1276010.8 | D2: =SUM(D4:D95) -> 1821502.6 | E2: =C2-D2 -> -545491.74 | F2: =IFERROR(E2/D2, 0) -> -0.29947349 | G2: =SUM(G4:G95) -> 1592252.1 | H2: =C2-G2 -> -316241.25 | I2: =IFERROR(H2/G2, 0) -> -0.19861255
A3: Site | B3: State | C3: Actual | D3: Expected | E3: Delta | F3: % | G3: Forecasted | H3: Delta | I3: %
A4: {=Sites[Site]} -> Williamsburg A | B4: {=Sites[State]} -> MA | C4: =SUM('1st Qtr'!C4, '2nd Qtr'!C4, '3rd Qtr'!C4, '4th Qtr'!C4) -> 60069.554 | D4: =SUM('1st Qtr'!D4, '2nd Qtr'!D4, '3rd Qtr'!D4, '4th Qtr'!D4) -> 103795.4 | E4: =IF(AND(ISNUMBER(C4),ISNUMBER(D4)), C4-D4, "") -> -43725.846 | F4: =IFERROR(E4/D4, "") -> -0.42126959 | G4: =SUM('1st Qtr'!G4, '2nd Qtr'!G4, '3rd Qtr'!G4, '4th Qtr'!G4) -> 95772.53 | H4: =SUM('1st Qtr'!H4, '2nd Qtr'!H4, '3rd Qtr'!H4, '4th Qtr'!H4) -> -35702.976 | I4: =IFERROR(H4/G4, "") -> -0.37278931
A5: Orange A KB | B5: MA | C5: =SUM('1st Qtr'!C5, '2nd Qtr'!C5, '3rd Qtr'!C5, '4th Qtr'!C5) -> 64320.283 | D5: =SUM('1st Qtr'!D5, '2nd Qtr'!D5, '3rd Qtr'!D5, '4th Qtr'!D5) -> 86329.8 | E5: =IF(AND(ISNUMBER(C5),ISNUMBER(D5)), C5-D5, "") -> -22009.517 | F5: =IFERROR(E5/D5, "") -> -0.25494692 | G5: =SUM('1st Qtr'!G5, '2nd Qtr'!G5, '3rd Qtr'!G5, '4th Qtr'!G5) -> 78506.72 | H5: =SUM('1st Qtr'!H5, '2nd Qtr'!H5, '3rd Qtr'!H5, '4th Qtr'!H5) -> -14186.437 | I5: =IFERROR(H5/G5, "") -> -0.18070347
A6: Goshen A | B6: MA | C6: =SUM('1st Qtr'!C6, '2nd Qtr'!C6, '3rd Qtr'!C6, '4th Qtr'!C6) -> 49163 | D6: =SUM('1st Qtr'!D6, '2nd Qtr'!D6, '3rd Qtr'!D6, '4th Qtr'!D6) -> 93145.65 | E6: =IF(AND(ISNUMBER(C6),ISNUMBER(D6)), C6-D6, "") -> -43982.65 | F6: =IFERROR(E6/D6, "") -> -0.47219221 | G6: =SUM('1st Qtr'!G6, '2nd Qtr'!G6, '3rd Qtr'!G6, '4th Qtr'!G6) -> 45346.04 | H6: =SUM('1st Qtr'!H6, '2nd Qtr'!H6, '3rd Qtr'!H6, '4th Qtr'!H6) -> 3816.96 | I6: =IFERROR(H6/G6, "") -> 0.084174054
A7: Phillipston A KB | B7: MA | C7: =SUM('1st Qtr'!C7, '2nd Qtr'!C7, '3rd Qtr'!C7, '4th Qtr'!C7) -> 52361 | D7: =SUM('1st Qtr'!D7, '2nd Qtr'!D7, '3rd Qtr'!D7, '4th Qtr'!D7) -> 133149.1 | E7: =IF(AND(ISNUMBER(C7),ISNUMBER(D7)), C7-D7, "") -> -80788.1 | F7: =IFERROR(E7/D7, "") -> -0.60674913 | G7: =SUM('1st Qtr'!G7, '2nd Qtr'!G7, '3rd Qtr'!G7, '4th Qtr'!G7) -> 48584.34 | H7: =SUM('1st Qtr'!H7, '2nd Qtr'!H7, '3rd Qtr'!H7, '4th Qtr'!H7) -> 3776.66 | I7: =IFERROR(H7/G7, "") -> 0.077734101
A8: Uxbridge D | B8: MA | C8: =SUM('1st Qtr'!C8, '2nd Qtr'!C8, '3rd Qtr'!C8, '4th Qtr'!C8) -> 79311 | D8: =SUM('1st Qtr'!D8, '2nd Qtr'!D8, '3rd Qtr'!D8, '4th Qtr'!D8) -> 118820.9 | E8: =IF(AND(ISNUMBER(C8),ISNUMBER(D8)), C8-D8, "") -> -39509.9 | F8: =IFERROR(E8/D8, "") -> -0.33251642 | G8: =SUM('1st Qtr'!G8, '2nd Qtr'!G8, '3rd Qtr'!G8, '4th Qtr'!G8) -> 102742.7 | H8: =SUM('1st Qtr'!H8, '2nd Qtr'!H8, '3rd Qtr'!H8, '4th Qtr'!H8) -> -23431.7 | I8: =IFERROR(H8/G8, "") -> -0.22806195
A9: West Bridgewater A&B | B9: MA | C9: =SUM('1st Qtr'!C9, '2nd Qtr'!C9, '3rd Qtr'!C9, '4th Qtr'!C9) -> 140442 | D9: =SUM('1st Qtr'!D9, '2nd Qtr'!D9, '3rd Qtr'!D9, '4th Qtr'!D9) -> 203218.3 | E9: =IF(AND(ISNUMBER(C9),ISNUMBER(D9)), C9-D9, "") -> -62776.3 | F9: =IFERROR(E9/D9, "") -> -0.30891066 | G9: =SUM('1st Qtr'!G9, '2nd Qtr'!G9, '3rd Qtr'!G9, '4th Qtr'!G9) -> 168220.8 | H9: =SUM('1st Qtr'!H9, '2nd Qtr'!H9, '3rd Qtr'!H9, '4th Qtr'!H9) -> -27778.8 | I9: =IFERROR(H9/G9, "") -> -0.16513297
A10: Sutton A | B10: MA | C10: =SUM('1st Qtr'!C10, '2nd Qtr'!C10, '3rd Qtr'!C10, '4th Qtr'!C10) -> 54236 | D10: =SUM('1st Qtr'!D10, '2nd Qtr'!D10, '3rd Qtr'!D10, '4th Qtr'!D10) -> 92857.71 | E10: =IF(AND(ISNUMBER(C10),ISNUMBER(D10)), C10-D10, "") -> -38621.71 | F10: =IFERROR(E10/D10, "") -> -0.41592357 | G10: =SUM('1st Qtr'!G10, '2nd Qtr'!G10, '3rd Qtr'!G10, '4th Qtr'!G10) -> 92964.7 | H10: =SUM('1st Qtr'!H10, '2nd Qtr'!H10, '3rd Qtr'!H10, '4th Qtr'!H10) -> -38728.7 | I10: =IFERROR(H10/G10, "") -> -0.41659576
A11: North Adams A | B11: MA | C11: =SUM('1st Qtr'!C11, '2nd Qtr'!C11, '3rd Qtr'!C11, '4th Qtr'!C11) -> 61430 | D11: =SUM('1st Qtr'!D11, '2nd Qtr'!D11, '3rd Qtr'!D11, '4th Qtr'!D11) -> 85432.94 | E11: =IF(AND(ISNUMBER(C11),ISNUMBER(D11)), C11-D11, "") -> -24002.94 | F11: =IFERROR(E11/D11, "") -> -0.2809565 | G11: =SUM('1st Qtr'!G11, '2nd Qtr'!G11, '3rd Qtr'!G11, '4th Qtr'!G11) -> 97969.54 | H11: =SUM('1st Qtr'!H11, '2nd Qtr'!H11, '3rd Qtr'!H11, '4th Qtr'!H11) -> -36539.54 | I11: =IFERROR(H11/G11, "") -> -0.37296837
A12: North Adams B | B12: MA | C12: =SUM('1st Qtr'!C12, '2nd Qtr'!C12, '3rd Qtr'!C12, '4th Qtr'!C12) -> 45389 | D12: =SUM('1st Qtr'!D12, '2nd Qtr'!D12, '3rd Qtr'!D12, '4th Qtr'!D12) -> 3439.174 | E12: =IF(AND(ISNUMBER(C12),ISNUMBER(D12)), C12-D12, "") -> 41949.826 | F12: =IFERROR(E12/D12, "") -> 12.197646 | G12: =SUM('1st Qtr'!G12, '2nd Qtr'!G12, '3rd Qtr'!G12, '4th Qtr'!G12) -> 97969.54 | H12: =SUM('1st Qtr'!H12, '2nd Qtr'!H12, '3rd Qtr'!H12, '4th Qtr'!H12) -> -52580.54 | I12: =IFERROR(H12/G12, "") -> -0.53670294
A13: Clarksburg A | B13: MA | C13: =SUM('1st Qtr'!C13, '2nd Qtr'!C13, '3rd Qtr'!C13, '4th Qtr'!C13) -> 33591 | D13: =SUM('1st Qtr'!D13, '2nd Qtr'!D13, '3rd Qtr'!D13, '4th Qtr'!D13) -> 74718.88 | E13: =IF(AND(ISNUMBER(C13),ISNUMBER(D13)), C13-D13, "") -> -41127.88 | F13: =IFERROR(E13/D13, "") -> -0.55043491 | G13: =SUM('1st Qtr'!G13, '2nd Qtr'!G13, '3rd Qtr'!G13, '4th Qtr'!G13) -> 97524.52 | H13: =SUM('1st Qtr'!H13, '2nd Qtr'!H13, '3rd Qtr'!H13, '4th Qtr'!H13) -> -63933.52 | I13: =IFERROR(H13/G13, "") -> -0.65556354
A14: Swansea B | B14: MA | C14: =SUM('1st Qtr'!C14, '2nd Qtr'!C14, '3rd Qtr'!C14, '4th Qtr'!C14) -> 94569 | D14: =SUM('1st Qtr'!D14, '2nd Qtr'!D14, '3rd Qtr'!D14, '4th Qtr'!D14) -> 125325.5 | E14: =IF(AND(ISNUMBER(C14),ISNUMBER(D14)), C14-D14, "") -> -30756.5 | F14: =IFERROR(E14/D14, "") -> -0.24541294 | G14: =SUM('1st Qtr'!G14, '2nd Qtr'!G14, '3rd Qtr'!G14, '4th Qtr'!G14) -> 51394 | H14: =SUM('1st Qtr'!H14, '2nd Qtr'!H14, '3rd Qtr'!H14, '4th Qtr'!H14) -> 43175 | I14: =IFERROR(H14/G14, "") -> 0.84007861
A15: Wareham 2 | B15: MA | C15: =SUM('1st Qtr'!C15, '2nd Qtr'!C15, '3rd Qtr'!C15, '4th Qtr'!C15) -> 87644 | D15: =SUM('1st Qtr'!D15, '2nd Qtr'!D15, '3rd Qtr'!D15, '4th Qtr'!D15) -> 97399.22 | E15: =IF(AND(ISNUMBER(C15),ISNUMBER(D15)), C15-D15, "") -> -9755.22 | F15: =IFERROR(E15/D15, "") -> -0.10015706 | G15: =SUM('1st Qtr'!G15, '2nd Qtr'!G15, '3rd Qtr'!G15, '4th Qtr'!G15) -> 102713.9 | H15: =SUM('1st Qtr'!H15, '2nd Qtr'!H15, '3rd Qtr'!H15, '4th Qtr'!H15) -> -15069.9 | I15: =IFERROR(H15/G15, "") -> -0.14671724
A16: Kingston 1 KB | B16: MA | C16: =SUM('1st Qtr'!C16, '2nd Qtr'!C16, '3rd Qtr'!C16, '4th Qtr'!C16) -> 71770 | D16: =SUM('1st Qtr'!D16, '2nd Qtr'!D16, '3rd Qtr'!D16, '4th Qtr'!D16) -> 101770 | E16: =IF(AND(ISNUMBER(C16),ISNUMBER(D16)), C16-D16, "") -> -30000 | F16: =IFERROR(E16/D16, "") -> -0.29478235 | G16: =SUM('1st Qtr'!G16, '2nd Qtr'!G16, '3rd Qtr'!G16, '4th Qtr'!G16) -> 78160.59 | H16: =SUM('1st Qtr'!H16, '2nd Qtr'!H16, '3rd Qtr'!H16, '4th Qtr'!H16) -> -6390.59 | I16: =IFERROR(H16/G16, "") -> -0.081762305
... A20: Plympton A-2 | B20: MA | C20: =SUM('1st Qtr'!C20, '2nd Qtr'!C20, '3rd Qtr'!C20, '4th Qtr'!C20) -> 86762 | D20: =SUM('1st Qtr'!D20, '2nd Qtr'!D20, '3rd Qtr'!D20, '4th Qtr'!D20) -> 112140.9 | E20: =IF(AND(ISNUMBER(C20),ISNUMBER(D20)), C20-D20, "") -> -25378.9 | F20: =IFERROR(E20/D20, "") -> -0.22631261 | G20: =SUM('1st Qtr'!G20, '2nd Qtr'!G20, '3rd Qtr'!G20, '4th Qtr'!G20) -> 98150.02 | H20: =SUM('1st Qtr'!H20, '2nd Qtr'!H20, '3rd Qtr'!H20, '4th Qtr'!H20) -> -11388.02 | I20: =IFERROR(H20/G20, "") -> -0.11602667

Sheet 1st Qtr
A1: {=portfolio} -> MN8 KEF | D1: 1st Quarter Actual v. Expected | G1: 1st Quarter Actual v. Forecasted
A2: Total | C2: =SUM(C4:C95) -> 1276010.8 | D2: =SUM(D4:D95) -> 1821502.6 | E2: =C2-D2 -> -545491.74 | F2: =IFERROR(E2/D2, 0) -> -0.29947349 | G2: =SUM(G4:G95) -> 1592252.1 | H2: =C2-G2 -> -316241.25 | I2: =IFERROR(H2/G2, 0) -> -0.19861255
A3: Site | B3: State | C3: Actual | D3: Expected | E3: Delta | F3: % | G3: Forecasted | H3: Delta | I3: %
A4: {=Sites[Site]} -> Williamsburg A | B4: {=Sites[State]} -> MA | C4: =SUM(Jan!C4, Feb!C4, Mar!C4) -> 60069.554 | D4: =SUM(Jan!D4, Feb!D4, Mar!D4) -> 103795.4 | E4: =IF(AND(ISNUMBER(C4),ISNUMBER(D4)), C4-D4, "") -> -43725.846 | F4: =IFERROR(E4/D4, "") -> -0.42126959 | G4: =SUM(Jan!G4, Feb!G4, Mar!G4) -> 95772.53 | H4: =SUM(Jan!H4, Feb!H4, Mar!H4) -> -35702.976 | I4: =IFERROR(H4/G4, "") -> -0.37278931
A5: Orange A KB | B5: MA | C5: =SUM(Jan!C5, Feb!C5, Mar!C5) -> 64320.283 | D5: =SUM(Jan!D5, Feb!D5, Mar!D5) -> 86329.8 | E5: =IF(AND(ISNUMBER(C5),ISNUMBER(D5)), C5-D5, "") -> -22009.517 | F5: =IFERROR(E5/D5, "") -> -0.25494692 | G5: =SUM(Jan!G5, Feb!G5, Mar!G5) -> 78506.72 | H5: =SUM(Jan!H5, Feb!H5, Mar!H5) -> -14186.437 | I5: =IFERROR(H5/G5, "") -> -0.18070347
A6: Goshen A | B6: MA | C6: =SUM(Jan!C6, Feb!C6, Mar!C6) -> 49163 | D6: =SUM(Jan!D6, Feb!D6, Mar!D6) -> 93145.65 | E6: =IF(AND(ISNUMBER(C6),ISNUMBER(D6)), C6-D6, "") -> -43982.65 | F6: =IFERROR(E6/D6, "") -> -0.47219221 | G6: =SUM(Jan!G6, Feb!G6, Mar!G6) -> 45346.04 | H6: =SUM(Jan!H6, Feb!H6, Mar!H6) -> 3816.96 | I6: =IFERROR(H6/G6, "") -> 0.084174054
A7: Phillipston A KB | B7: MA | C7: =SUM(Jan!C7, Feb!C7, Mar!C7) -> 52361 | D7: =SUM(Jan!D7, Feb!D7, Mar!D7) -> 133149.1 | E7: =IF(AND(ISNUMBER(C7),ISNUMBER(D7)), C7-D7, "") -> -80788.1 | F7: =IFERROR(E7/D7, "") -> -0.60674913 | G7: =SUM(Jan!G7, Feb!G7, Mar!G7) -> 48584.34 | H7: =SUM(Jan!H7, Feb!H7, Mar!H7) -> 3776.66 | I7: =IFERROR(H7/G7, "") -> 0.077734101
A8: Uxbridge D | B8: MA | C8: =SUM(Jan!C8, Feb!C8, Mar!C8) -> 79311 | D8: =SUM(Jan!D8, Feb!D8, Mar!D8) -> 118820.9 | E8: =IF(AND(ISNUMBER(C8),ISNUMBER(D8)), C8-D8, "") -> -39509.9 | F8: =IFERROR(E8/D8, "") -> -0.33251642 | G8: =SUM(Jan!G8, Feb!G8, Mar!G8) -> 102742.7 | H8: =SUM(Jan!H8, Feb!H8, Mar!H8) -> -23431.7 | I8: =IFERROR(H8/G8, "") -> -0.22806195
A9: West Bridgewater A&B | B9: MA | C9: =SUM(Jan!C9, Feb!C9, Mar!C9) -> 140442 | D9: =SUM(Jan!D9, Feb!D9, Mar!D9) -> 203218.3 | E9: =IF(AND(ISNUMBER(C9),ISNUMBER(D9)), C9-D9, "") -> -62776.3 | F9: =IFERROR(E9/D9, "") -> -0.30891066 | G9: =SUM(Jan!G9, Feb!G9, Mar!G9) -> 168220.8 | H9: =SUM(Jan!H9, Feb!H9, Mar!H9) -> -27778.8 | I9: =IFERROR(H9/G9, "") -> -0.16513297
A10: Sutton A | B10: MA | C10: =SUM(Jan!C10, Feb!C10, Mar!C10) -> 54236 | D10: =SUM(Jan!D10, Feb!D10, Mar!D10) -> 92857.71 | E10: =IF(AND(ISNUMBER(C10),ISNUMBER(D10)), C10-D10, "") -> -38621.71 | F10: =IFERROR(E10/D10, "") -> -0.41592357 | G10: =SUM(Jan!G10, Feb!G10, Mar!G10) -> 92964.7 | H10: =SUM(Jan!H10, Feb!H10, Mar!H10) -> -38728.7 | I10: =IFERROR(H10/G10, "") -> -0.41659576
A11: North Adams A | B11: MA | C11: =SUM(Jan!C11, Feb!C11, Mar!C11) -> 61430 | D11: =SUM(Jan!D11, Feb!D11, Mar!D11) -> 85432.94 | E11: =IF(AND(ISNUMBER(C11),ISNUMBER(D11)), C11-D11, "") -> -24002.94 | F11: =IFERROR(E11/D11, "") -> -0.2809565 | G11: =SUM(Jan!G11, Feb!G11, Mar!G11) -> 97969.54 | H11: =SUM(Jan!H11, Feb!H11, Mar!H11) -> -36539.54 | I11: =IFERROR(H11/G11, "") -> -0.37296837
A12: North Adams B | B12: MA | C12: =SUM(Jan!C12, Feb!C12, Mar!C12) -> 45389 | D12: =SUM(Jan!D12, Feb!D12, Mar!D12) -> 3439.174 | E12: =IF(AND(ISNUMBER(C12),ISNUMBER(D12)), C12-D12, "") -> 41949.826 | F12: =IFERROR(E12/D12, "") -> 12.197646 | G12: =SUM(Jan!G12, Feb!G12, Mar!G12) -> 97969.54 | H12: =SUM(Jan!H12, Feb!H12, Mar!H12) -> -52580.54 | I12: =IFERROR(H12/G12, "") -> -0.53670294
A13: Clarksburg A | B13: MA | C13: =SUM(Jan!C13, Feb!C13, Mar!C13) -> 33591 | D13: =SUM(Jan!D13, Feb!D13, Mar!D13) -> 74718.88 | E13: =IF(AND(ISNUMBER(C13),ISNUMBER(D13)), C13-D13, "") -> -41127.88 | F13: =IFERROR(E13/D13, "") -> -0.55043491 | G13: =SUM(Jan!G13, Feb!G13, Mar!G13) -> 97524.52 | H13: =SUM(Jan!H13, Feb!H13, Mar!H13) -> -63933.52 | I13: =IFERROR(H13/G13, "") -> -0.65556354
A14: Swansea B | B14: MA | C14: =SUM(Jan!C14, Feb!C14, Mar!C14) -> 94569 | D14: =SUM(Jan!D14, Feb!D14, Mar!D14) -> 125325.5 | E14: =IF(AND(ISNUMBER(C14),ISNUMBER(D14)), C14-D14, "") -> -30756.5 | F14: =IFERROR(E14/D14, "") -> -0.24541294 | G14: =SUM(Jan!G14, Feb!G14, Mar!G14) -> 51394 | H14: =SUM(Jan!H14, Feb!H14, Mar!H14) -> 43175 | I14: =IFERROR(H14/G14, "") -> 0.84007861
A15: Wareham 2 | B15: MA | C15: =SUM(Jan!C15, Feb!C15, Mar!C15) -> 87644 | D15: =SUM(Jan!D15, Feb!D15, Mar!D15) -> 97399.22 | E15: =IF(AND(ISNUMBER(C15),ISNUMBER(D15)), C15-D15, "") -> -9755.22 | F15: =IFERROR(E15/D15, "") -> -0.10015706 | G15: =SUM(Jan!G15, Feb!G15, Mar!G15) -> 102713.9 | H15: =SUM(Jan!H15, Feb!H15, Mar!H15) -> -15069.9 | I15: =IFERROR(H15/G15, "") -> -0.14671724
A16: Kingston 1 KB | B16: MA | C16: =SUM(Jan!C16, Feb!C16, Mar!C16) -> 71770 | D16: =SUM(Jan!D16, Feb!D16, Mar!D16) -> 101770 | E16: =IF(AND(ISNUMBER(C16),ISNUMBER(D16)), C16-D16, "") -> -30000 | F16: =IFERROR(E16/D16, "") -> -0.29478235 | G16: =SUM(Jan!G16, Feb!G16, Mar!G16) -> 78160.59 | H16: =SUM(Jan!H16, Feb!H16, Mar!H16) -> -6390.59 | I16: =IFERROR(H16/G16, "") -> -0.081762305
... A20: Plympton A-2 | B20: MA | C20: =SUM(Jan!C20, Feb!C20, Mar!C20) -> 86762 | D20: =SUM(Jan!D20, Feb!D20, Mar!D20) -> 112140.9 | E20: =IF(AND(ISNUMBER(C20),ISNUMBER(D20)), C20-D20, "") -> -25378.9 | F20: =IFERROR(E20/D20, "") -> -0.22631261 | G20: =SUM(Jan!G20, Feb!G20, Mar!G20) -> 98150.02 | H20: =SUM(Jan!H20, Feb!H20, Mar!H20) -> -11388.02 | I20: =IFERROR(H20/G20, "") -> -0.11602667

Sheet 2nd Qtr
A1: {=portfolio} -> MN8 KEF | D1: 2nd Quarter Actual v. Expected | G1: 2nd Quarter Actual v. Forecasted
A2: Total | C2: =SUM(C4:C95) -> 0 | D2: =SUM(D4:D95) -> 0 | E2: =C2-D2 -> 0 | F2: =IFERROR(E2/D2, 0) -> 0 | G2: =SUM(G4:G95) -> 0 | H2: =C2-G2 -> 0 | I2: =IFERROR(H2/G2, 0) -> 0
A3: Site | B3: State | C3: Actual | D3: Expected | E3: Delta | F3: % | G3: Forecasted | H3: Delta | I3: %
A4: {=Sites[Site]} -> Williamsburg A | B4: {=Sites[State]} -> MA | C4: =SUM(Apr!C4, May!C4, Jun!C4) -> 0 | D4: =SUM(Apr!D4, May!D4, Jun!D4) -> 0 | E4: =IF(AND(ISNUMBER(C4),ISNUMBER(D4)), C4-D4, "") -> 0 | F4: =IFERROR(E4/D4, "") | G4: =SUM(Apr!G4+May!G4+Jun!G4) -> 0 | H4: =SUM(Apr!H4, May!H4, Jun!H4) -> 0 | I4: =IFERROR(H4/G4, "")
A5: Orange A KB | B5: MA | C5: =SUM(Apr!C5, May!C5, Jun!C5) -> 0 | D5: =SUM(Apr!D5, May!D5, Jun!D5) -> 0 | E5: =IF(AND(ISNUMBER(C5),ISNUMBER(D5)), C5-D5, "") -> 0 | F5: =IFERROR(E5/D5, "") | G5: =SUM(Apr!G5+May!G5+Jun!G5) -> 0 | H5: =SUM(Apr!H5, May!H5, Jun!H5) -> 0 | I5: =IFERROR(H5/G5, "")
A6: Goshen A | B6: MA | C6: =SUM(Apr!C6, May!C6, Jun!C6) -> 0 | D6: =SUM(Apr!D6, May!D6, Jun!D6) -> 0 | E6: =IF(AND(ISNUMBER(C6),ISNUMBER(D6)), C6-D6, "") -> 0 | F6: =IFERROR(E6/D6, "") | G6: =SUM(Apr!G6+May!G6+Jun!G6) -> 0 | H6: =SUM(Apr!H6, May!H6, Jun!H6) -> 0 | I6: =IFERROR(H6/G6, "")
A7: Phillipston A KB | B7: MA | C7: =SUM(Apr!C7, May!C7, Jun!C7) -> 0 | D7: =SUM(Apr!D7, May!D7, Jun!D7) -> 0 | E7: =IF(AND(ISNUMBER(C7),ISNUMBER(D7)), C7-D7, "") -> 0 | F7: =IFERROR(E7/D7, "") | G7: =SUM(Apr!G7+May!G7+Jun!G7) -> 0 | H7: =SUM(Apr!H7, May!H7, Jun!H7) -> 0 | I7: =IFERROR(H7/G7, "")
A8: Uxbridge D | B8: MA | C8: =SUM(Apr!C8, May!C8, Jun!C8) -> 0 | D8: =SUM(Apr!D8, May!D8, Jun!D8) -> 0 | E8: =IF(AND(ISNUMBER(C8),ISNUMBER(D8)), C8-D8, "") -> 0 | F8: =IFERROR(E8/D8, "") | G8: =SUM(Apr!G8+May!G8+Jun!G8) -> 0 | H8: =SUM(Apr!H8, May!H8, Jun!H8) -> 0 | I8: =IFERROR(H8/G8, "")
A9: West Bridgewater A&B | B9: MA | C9: =SUM(Apr!C9, May!C9, Jun!C9) -> 0 | D9: =SUM(Apr!D9, May!D9, Jun!D9) -> 0 | E9: =IF(AND(ISNUMBER(C9),ISNUMBER(D9)), C9-D9, "") -> 0 | F9: =IFERROR(E9/D9, "") | G9: =SUM(Apr!G9+May!G9+Jun!G9) -> 0 | H9: =SUM(Apr!H9, May!H9, Jun!H9) -> 0 | I9: =IFERROR(H9/G9, "")
A10: Sutton A | B10: MA | C10: =SUM(Apr!C10, May!C10, Jun!C10) -> 0 | D10: =SUM(Apr!D10, May!D10, Jun!D10) -> 0 | E10: =IF(AND(ISNUMBER(C10),ISNUMBER(D10)), C10-D10, "") -> 0 | F10: =IFERROR(E10/D10, "") | G10: =SUM(Apr!G10+May!G10+Jun!G10) -> 0 | H10: =SUM(Apr!H10, May!H10, Jun!H10) -> 0 | I10: =IFERROR(H10/G10, "")
A11: North Adams A | B11: MA | C11: =SUM(Apr!C11, May!C11, Jun!C11) -> 0 | D11: =SUM(Apr!D11, May!D11, Jun!D11) -> 0 | E11: =IF(AND(ISNUMBER(C11),ISNUMBER(D11)), C11-D11, "") -> 0 | F11: =IFERROR(E11/D11, "") | G11: =SUM(Apr!G11+May!G11+Jun!G11) -> 0 | H11: =SUM(Apr!H11, May!H11, Jun!H11) -> 0 | I11: =IFERROR(H11/G11, "")
A12: North Adams B | B12: MA | C12: =SUM(Apr!C12, May!C12, Jun!C12) -> 0 | D12: =SUM(Apr!D12, May!D12, Jun!D12) -> 0 | E12: =IF(AND(ISNUMBER(C12),ISNUMBER(D12)), C12-D12, "") -> 0 | F12: =IFERROR(E12/D12, "") | G12: =SUM(Apr!G12+May!G12+Jun!G12) -> 0 | H12: =SUM(Apr!H12, May!H12, Jun!H12) -> 0 | I12: =IFERROR(H12/G12, "")
A13: Clarksburg A | B13: MA | C13: =SUM(Apr!C13, May!C13, Jun!C13) -> 0 | D13: =SUM(Apr!D13, May!D13, Jun!D13) -> 0 | E13: =IF(AND(ISNUMBER(C13),ISNUMBER(D13)), C13-D13, "") -> 0 | F13: =IFERROR(E13/D13, "") | G13: =SUM(Apr!G13+May!G13+Jun!G13) -> 0 | H13: =SUM(Apr!H13, May!H13, Jun!H13) -> 0 | I13: =IFERROR(H13/G13, "")
A14: Swansea B | B14: MA | C14: =SUM(Apr!C14, May!C14, Jun!C14) -> 0 | D14: =SUM(Apr!D14, May!D14, Jun!D14) -> 0 | E14: =IF(AND(ISNUMBER(C14),ISNUMBER(D14)), C14-D14, "") -> 0 | F14: =IFERROR(E14/D14, "") | G14: =SUM(Apr!G14+May!G14+Jun!G14) -> 0 | H14: =SUM(Apr!H14, May!H14, Jun!H14) -> 0 | I14: =IFERROR(H14/G14, "")
A15: Wareham 2 | B15: MA | C15: =SUM(Apr!C15, May!C15, Jun!C15) -> 0 | D15: =SUM(Apr!D15, May!D15, Jun!D15) -> 0 | E15: =IF(AND(ISNUMBER(C15),ISNUMBER(D15)), C15-D15, "") -> 0 | F15: =IFERROR(E15/D15, "") | G15: =SUM(Apr!G15+May!G15+Jun!G15) -> 0 | H15: =SUM(Apr!H15, May!H15, Jun!H15) -> 0 | I15: =IFERROR(H15/G15, "")
A16: Kingston 1 KB | B16: MA | C16: =SUM(Apr!C16, May!C16, Jun!C16) -> 0 | D16: =SUM(Apr!D16, May!D16, Jun!D16) -> 0 | E16: =IF(AND(ISNUMBER(C16),ISNUMBER(D16)), C16-D16, "") -> 0 | F16: =IFERROR(E16/D16, "") | G16: =SUM(Apr!G16+May!G16+Jun!G16) -> 0 | H16: =SUM(Apr!H16, May!H16, Jun!H16) -> 0 | I16: =IFERROR(H16/G16, "")
... A20: Plympton A-2 | B20: MA | C20: =SUM(Apr!C20, May!C20, Jun!C20) -> 0 | D20: =SUM(Apr!D20, May!D20, Jun!D20) -> 0 | E20: =IF(AND(ISNUMBER(C20),ISNUMBER(D20)), C20-D20, "") -> 0 | F20: =IFERROR(E20/D20, "") | G20: =SUM(Apr!G20+May!G20+Jun!G20) -> 0 | H20: =SUM(Apr!H20, May!H20, Jun!H20) -> 0 | I20: =IFERROR(H20/G20, "")

Sheet 3rd Qtr
A1: {=portfolio} -> MN8 KEF | D1: 3rd Quarter Actual v. Expected | G1: 3rd Quarter Actual v. Forecasted
A2: Total | C2: =SUM(C4:C95) -> 0 | D2: =SUM(D4:D95) -> 0 | E2: =C2-D2 -> 0 | F2: =IFERROR(E2/D2, 0) -> 0 | G2: =SUM(G4:G95) -> 0 | H2: =C2-G2 -> 0 | I2: =IFERROR(H2/G2, 0) -> 0
A3: Site | B3: State | C3: Actual | D3: Expected | E3: Delta | F3: % | G3: Forecasted | H3: Delta | I3: %
A4: {=Sites[Site]} -> Williamsburg A | B4: {=Sites[State]} -> MA | C4: =SUM(Jul!C4, Aug!C4, Sep!C4) -> 0 | D4: =SUM(Jul!D4, Aug!D4, Sep!D4) -> 0 | E4: =IF(AND(ISNUMBER(C4),ISNUMBER(D4)), C4-D4, "") -> 0 | F4: =IFERROR(E4/D4, "") | G4: =SUM(Jul!G4,Aug!G4,Sep!G4) -> 0 | H4: =SUM(Jul!H4, Aug!H4, Sep!H4) -> 0 | I4: =IFERROR(H4/G4, "")
A5: Orange A KB | B5: MA | C5: =SUM(Jul!C5, Aug!C5, Sep!C5) -> 0 | D5: =SUM(Jul!D5, Aug!D5, Sep!D5) -> 0 | E5: =IF(AND(ISNUMBER(C5),ISNUMBER(D5)), C5-D5, "") -> 0 | F5: =IFERROR(E5/D5, "") | G5: =SUM(Jul!G5,Aug!G5,Sep!G5) -> 0 | H5: =SUM(Jul!H5, Aug!H5, Sep!H5) -> 0 | I5: =IFERROR(H5/G5, "")
A6: Goshen A | B6: MA | C6: =SUM(Jul!C6, Aug!C6, Sep!C6) -> 0 | D6: =SUM(Jul!D6, Aug!D6, Sep!D6) -> 0 | E6: =IF(AND(ISNUMBER(C6),ISNUMBER(D6)), C6-D6, "") -> 0 | F6: =IFERROR(E6/D6, "") | G6: =SUM(Jul!G6,Aug!G6,Sep!G6) -> 0 | H6: =SUM(Jul!H6, Aug!H6, Sep!H6) -> 0 | I6: =IFERROR(H6/G6, "")
A7: Phillipston A KB | B7: MA | C7: =SUM(Jul!C7, Aug!C7, Sep!C7) -> 0 | D7: =SUM(Jul!D7, Aug!D7, Sep!D7) -> 0 | E7: =IF(AND(ISNUMBER(C7),ISNUMBER(D7)), C7-D7, "") -> 0 | F7: =IFERROR(E7/D7, "") | G7: =SUM(Jul!G7,Aug!G7,Sep!G7) -> 0 | H7: =SUM(Jul!H7, Aug!H7, Sep!H7) -> 0 | I7: =IFERROR(H7/G7, "")
A8: Uxbridge D | B8: MA | C8: =SUM(Jul!C8, Aug!C8, Sep!C8) -> 0 | D8: =SUM(Jul!D8, Aug!D8, Sep!D8) -> 0 | E8: =IF(AND(ISNUMBER(C8),ISNUMBER(D8)), C8-D8, "") -> 0 | F8: =IFERROR(E8/D8, "") | G8: =SUM(Jul!G8,Aug!G8,Sep!G8) -> 0 | H8: =SUM(Jul!H8, Aug!H8, Sep!H8) -> 0 | I8: =IFERROR(H8/G8, "")
A9: West Bridgewater A&B | B9: MA | C9: =SUM(Jul!C9, Aug!C9, Sep!C9) -> 0 | D9: =SUM(Jul!D9, Aug!D9, Sep!D9) -> 0 | E9: =IF(AND(ISNUMBER(C9),ISNUMBER(D9)), C9-D9, "") -> 0 | F9: =IFERROR(E9/D9, "") | G9: =SUM(Jul!G9,Aug!G9,Sep!G9) -> 0 | H9: =SUM(Jul!H9, Aug!H9, Sep!H9) -> 0 | I9: =IFERROR(H9/G9, "")
A10: Sutton A | B10: MA | C10: =SUM(Jul!C10, Aug!C10, Sep!C10) -> 0 | D10: =SUM(Jul!D10, Aug!D10, Sep!D10) -> 0 | E10: =IF(AND(ISNUMBER(C10),ISNUMBER(D10)), C10-D10, "") -> 0 | F10: =IFERROR(E10/D10, "") | G10: =SUM(Jul!G10,Aug!G10,Sep!G10) -> 0 | H10: =SUM(Jul!H10, Aug!H10, Sep!H10) -> 0 | I10: =IFERROR(H10/G10, "")
A11: North Adams A | B11: MA | C11: =SUM(Jul!C11, Aug!C11, Sep!C11) -> 0 | D11: =SUM(Jul!D11, Aug!D11, Sep!D11) -> 0 | E11: =IF(AND(ISNUMBER(C11),ISNUMBER(D11)), C11-D11, "") -> 0 | F11: =IFERROR(E11/D11, "") | G11: =SUM(Jul!G11,Aug!G11,Sep!G11) -> 0 | H11: =SUM(Jul!H11, Aug!H11, Sep!H11) -> 0 | I11: =IFERROR(H11/G11, "")
A12: North Adams B | B12: MA | C12: =SUM(Jul!C12, Aug!C12, Sep!C12) -> 0 | D12: =SUM(Jul!D12, Aug!D12, Sep!D12) -> 0 | E12: =IF(AND(ISNUMBER(C12),ISNUMBER(D12)), C12-D12, "") -> 0 | F12: =IFERROR(E12/D12, "") | G12: =SUM(Jul!G12,Aug!G12,Sep!G12) -> 0 | H12: =SUM(Jul!H12, Aug!H12, Sep!H12) -> 0 | I12: =IFERROR(H12/G12, "")
A13: Clarksburg A | B13: MA | C13: =SUM(Jul!C13, Aug!C13, Sep!C13) -> 0 | D13: =SUM(Jul!D13, Aug!D13, Sep!D13) -> 0 | E13: =IF(AND(ISNUMBER(C13),ISNUMBER(D13)), C13-D13, "") -> 0 | F13: =IFERROR(E13/D13, "") | G13: =SUM(Jul!G13,Aug!G13,Sep!G13) -> 0 | H13: =SUM(Jul!H13, Aug!H13, Sep!H13) -> 0 | I13: =IFERROR(H13/G13, "")
A14: Swansea B | B14: MA | C14: =SUM(Jul!C14, Aug!C14, Sep!C14) -> 0 | D14: =SUM(Jul!D14, Aug!D14, Sep!D14) -> 0 | E14: =IF(AND(ISNUMBER(C14),ISNUMBER(D14)), C14-D14, "") -> 0 | F14: =IFERROR(E14/D14, "") | G14: =SUM(Jul!G14,Aug!G14,Sep!G14) -> 0 | H14: =SUM(Jul!H14, Aug!H14, Sep!H14) -> 0 | I14: =IFERROR(H14/G14, "")
A15: Wareham 2 | B15: MA | C15: =SUM(Jul!C15, Aug!C15, Sep!C15) -> 0 | D15: =SUM(Jul!D15, Aug!D15, Sep!D15) -> 0 | E15: =IF(AND(ISNUMBER(C15),ISNUMBER(D15)), C15-D15, "") -> 0 | F15: =IFERROR(E15/D15, "") | G15: =SUM(Jul!G15,Aug!G15,Sep!G15) -> 0 | H15: =SUM(Jul!H15, Aug!H15, Sep!H15) -> 0 | I15: =IFERROR(H15/G15, "")
A16: Kingston 1 KB | B16: MA | C16: =SUM(Jul!C16, Aug!C16, Sep!C16) -> 0 | D16: =SUM(Jul!D16, Aug!D16, Sep!D16) -> 0 | E16: =IF(AND(ISNUMBER(C16),ISNUMBER(D16)), C16-D16, "") -> 0 | F16: =IFERROR(E16/D16, "") | G16: =SUM(Jul!G16,Aug!G16,Sep!G16) -> 0 | H16: =SUM(Jul!H16, Aug!H16, Sep!H16) -> 0 | I16: =IFERROR(H16/G16, "")
... A20: Plympton A-2 | B20: MA | C20: =SUM(Jul!C20, Aug!C20, Sep!C20) -> 0 | D20: =SUM(Jul!D20, Aug!D20, Sep!D20) -> 0 | E20: =IF(AND(ISNUMBER(C20),ISNUMBER(D20)), C20-D20, "") -> 0 | F20: =IFERROR(E20/D20, "") | G20: =SUM(Jul!G20,Aug!G20,Sep!G20) -> 0 | H20: =SUM(Jul!H20, Aug!H20, Sep!H20) -> 0 | I20: =IFERROR(H20/G20, "")

Sheet 4th Qtr
A1: {=portfolio} -> MN8 KEF | D1: 4th Quarter Actual v. Expected | G1: 4th Quarter Actual v. Forecasted
A2: Total | C2: =SUM(C4:C95) -> 0 | D2: =SUM(D4:D95) -> 0 | E2: =C2-D2 -> 0 | F2: =IFERROR(E2/D2, 0) -> 0 | G2: =SUM(G4:G95) -> 0 | H2: =C2-G2 -> 0 | I2: =IFERROR(H2/G2, 0) -> 0
A3: Site | B3: State | C3: Actual | D3: Expected | E3: Delta | F3: % | G3: Forecasted | H3: Delta | I3: %
A4: {=Sites[Site]} -> Williamsburg A | B4: {=Sites[State]} -> MA | C4: =SUM(Oct!C4, Nov!C4, Dec!C4) -> 0 | D4: =SUM(Oct!D4, Nov!D4, Dec!D4) -> 0 | E4: =IF(AND(ISNUMBER(C4),ISNUMBER(D4)), C4-D4, "") -> 0 | F4: =IFERROR(E4/D4, "") | G4: =SUM(Oct!G4,Nov!G4,Dec!G4) -> 0 | H4: =SUM(Oct!H4, Nov!H4, Dec!H4) -> 0 | I4: =IFERROR(H4/G4, "")
A5: Orange A KB | B5: MA | C5: =SUM(Oct!C5, Nov!C5, Dec!C5) -> 0 | D5: =SUM(Oct!D5, Nov!D5, Dec!D5) -> 0 | E5: =IF(AND(ISNUMBER(C5),ISNUMBER(D5)), C5-D5, "") -> 0 | F5: =IFERROR(E5/D5, "") | G5: =SUM(Oct!G5,Nov!G5,Dec!G5) -> 0 | H5: =SUM(Oct!H5, Nov!H5, Dec!H5) -> 0 | I5: =IFERROR(H5/G5, "")
A6: Goshen A | B6: MA | C6: =SUM(Oct!C6, Nov!C6, Dec!C6) -> 0 | D6: =SUM(Oct!D6, Nov!D6, Dec!D6) -> 0 | E6: =IF(AND(ISNUMBER(C6),ISNUMBER(D6)), C6-D6, "") -> 0 | F6: =IFERROR(E6/D6, "") | G6: =SUM(Oct!G6,Nov!G6,Dec!G6) -> 0 | H6: =SUM(Oct!H6, Nov!H6, Dec!H6) -> 0 | I6: =IFERROR(H6/G6, "")
A7: Phillipston A KB | B7: MA | C7: =SUM(Oct!C7, Nov!C7, Dec!C7) -> 0 | D7: =SUM(Oct!D7, Nov!D7, Dec!D7) -> 0 | E7: =IF(AND(ISNUMBER(C7),ISNUMBER(D7)), C7-D7, "") -> 0 | F7: =IFERROR(E7/D7, "") | G7: =SUM(Oct!G7,Nov!G7,Dec!G7) -> 0 | H7: =SUM(Oct!H7, Nov!H7, Dec!H7) -> 0 | I7: =IFERROR(H7/G7, "")
A8: Uxbridge D | B8: MA | C8: =SUM(Oct!C8, Nov!C8, Dec!C8) -> 0 | D8: =SUM(Oct!D8, Nov!D8, Dec!D8) -> 0 | E8: =IF(AND(ISNUMBER(C8),ISNUMBER(D8)), C8-D8, "") -> 0 | F8: =IFERROR(E8/D8, "") | G8: =SUM(Oct!G8,Nov!G8,Dec!G8) -> 0 | H8: =SUM(Oct!H8, Nov!H8, Dec!H8) -> 0 | I8: =IFERROR(H8/G8, "")
A9: West Bridgewater A&B | B9: MA | C9: =SUM(Oct!C9, Nov!C9, Dec!C9) -> 0 | D9: =SUM(Oct!D9, Nov!D9, Dec!D9) -> 0 | E9: =IF(AND(ISNUMBER(C9),ISNUMBER(D9)), C9-D9, "") -> 0 | F9: =IFERROR(E9/D9, "") | G9: =SUM(Oct!G9,Nov!G9,Dec!G9) -> 0 | H9: =SUM(Oct!H9, Nov!H9, Dec!H9) -> 0 | I9: =IFERROR(H9/G9, "")
A10: Sutton A | B10: MA | C10: =SUM(Oct!C10, Nov!C10, Dec!C10) -> 0 | D10: =SUM(Oct!D10, Nov!D10, Dec!D10) -> 0 | E10: =IF(AND(ISNUMBER(C10),ISNUMBER(D10)), C10-D10, "") -> 0 | F10: =IFERROR(E10/D10, "") | G10: =SUM(Oct!G10,Nov!G10,Dec!G10) -> 0 | H10: =SUM(Oct!H10, Nov!H10, Dec!H10) -> 0 | I10: =IFERROR(H10/G10, "")
A11: North Adams A | B11: MA | C11: =SUM(Oct!C11, Nov!C11, Dec!C11) -> 0 | D11: =SUM(Oct!D11, Nov!D11, Dec!D11) -> 0 | E11: =IF(AND(ISNUMBER(C11),ISNUMBER(D11)), C11-D11, "") -> 0 | F11: =IFERROR(E11/D11, "") | G11: =SUM(Oct!G11,Nov!G11,Dec!G11) -> 0 | H11: =SUM(Oct!H11, Nov!H11, Dec!H11) -> 0 | I11: =IFERROR(H11/G11, "")
A12: North Adams B | B12: MA | C12: =SUM(Oct!C12, Nov!C12, Dec!C12) -> 0 | D12: =SUM(Oct!D12, Nov!D12, Dec!D12) -> 0 | E12: =IF(AND(ISNUMBER(C12),ISNUMBER(D12)), C12-D12, "") -> 0 | F12: =IFERROR(E12/D12, "") | G12: =SUM(Oct!G12,Nov!G12,Dec!G12) -> 0 | H12: =SUM(Oct!H12, Nov!H12, Dec!H12) -> 0 | I12: =IFERROR(H12/G12, "")
A13: Clarksburg A | B13: MA | C13: =SUM(Oct!C13, Nov!C13, Dec!C13) -> 0 | D13: =SUM(Oct!D13, Nov!D13, Dec!D13) -> 0 | E13: =IF(AND(ISNUMBER(C13),ISNUMBER(D13)), C13-D13, "") -> 0 | F13: =IFERROR(E13/D13, "") | G13: =SUM(Oct!G13,Nov!G13,Dec!G13) -> 0 | H13: =SUM(Oct!H13, Nov!H13, Dec!H13) -> 0 | I13: =IFERROR(H13/G13, "")
A14: Swansea B | B14: MA | C14: =SUM(Oct!C14, Nov!C14, Dec!C14) -> 0 | D14: =SUM(Oct!D14, Nov!D14, Dec!D14) -> 0 | E14: =IF(AND(ISNUMBER(C14),ISNUMBER(D14)), C14-D14, "") -> 0 | F14: =IFERROR(E14/D14, "") | G14: =SUM(Oct!G14,Nov!G14,Dec!G14) -> 0 | H14: =SUM(Oct!H14, Nov!H14, Dec!H14) -> 0 | I14: =IFERROR(H14/G14, "")
A15: Wareham 2 | B15: MA | C15: =SUM(Oct!C15, Nov!C15, Dec!C15) -> 0 | D15: =SUM(Oct!D15, Nov!D15, Dec!D15) -> 0 | E15: =IF(AND(ISNUMBER(C15),ISNUMBER(D15)), C15-D15, "") -> 0 | F15: =IFERROR(E15/D15, "") | G15: =SUM(Oct!G15,Nov!G15,Dec!G15) -> 0 | H15: =SUM(Oct!H15, Nov!H15, Dec!H15) -> 0 | I15: =IFERROR(H15/G15, "")
A16: Kingston 1 KB | B16: MA | C16: =SUM(Oct!C16, Nov!C16, Dec!C16) -> 0 | D16: =SUM(Oct!D16, Nov!D16, Dec!D16) -> 0 | E16: =IF(AND(ISNUMBER(C16),ISNUMBER(D16)), C16-D16, "") -> 0 | F16: =IFERROR(E16/D16, "") | G16: =SUM(Oct!G16,Nov!G16,Dec!G16) -> 0 | H16: =SUM(Oct!H16, Nov!H16, Dec!H16) -> 0 | I16: =IFERROR(H16/G16, "")
... A20: Plympton A-2 | B20: MA | C20: =SUM(Oct!C20, Nov!C20, Dec!C20) -> 0 | D20: =SUM(Oct!D20, Nov!D20, Dec!D20) -> 0 | E20: =IF(AND(ISNUMBER(C20),ISNUMBER(D20)), C20-D20, "") -> 0 | F20: =IFERROR(E20/D20, "") | G20: =SUM(Oct!G20,Nov!G20,Dec!G20) -> 0 | H20: =SUM(Oct!H20, Nov!H20, Dec!H20) -> 0 | I20: =IFERROR(H20/G20, "")

Sheet Jan
A1: {=portfolio} -> MN8 KEF | D1: January Actual v. Expected | G1: January Actual v. Forecasted
A2: Total | C2: =SUM(C4:C94) -> 1276010.8 | D2: =SUM(D4:D94) -> 1821502.6 | E2: =C2-D2 -> -545491.74 | F2: =IFERROR(E2/D2, 0) -> -0.29947349 | G2: =SUM(G4:G94) -> 1592252.1 | H2: =C2-G2 -> -316241.25 | I2: =IFERROR(H2/G2, 0) -> -0.19861255 | J2: =IF(AND(TODAY()>DATE(2024, 1, 1), COUNTA(Sites[Site])<>(COUNT(C:C)-1)), "Some sites are missing actual data; if new sites were added, make sure they are aligned correctly (including prior months!)", "")
A3: Site | B3: State | C3: Actual | D3: Expected | E3: Delta | F3: % | G3: Forecasted | H3: Delta | I3: % | J3: Notes | K3: Service Requests
A4: {=Sites[Site]} -> Williamsburg A | B4: {=Sites[State]} -> MA | C4: 60069.554 | D4: 103795.4 | E4: =IF(AND(ISNUMBER(C4),ISNUMBER(D4)), C4-D4, "") -> -43725.846 | F4: =IFERROR(E4/D4, "") -> -0.42126959 | G4: 95772.53 | H4: =IF(AND(ISNUMBER(C4),ISNUMBER(G4)), C4-G4, "") -> -35702.976 | I4: =IFERROR(H4/G4, "") -> -0.37278931
A5: Orange A KB | B5: MA | C5: 64320.283 | D5: 86329.8 | E5: =IF(AND(ISNUMBER(C5),ISNUMBER(D5)), C5-D5, "") -> -22009.517 | F5: =IFERROR(E5/D5, "") -> -0.25494692 | G5: 78506.72 | H5: =IF(AND(ISNUMBER(C5),ISNUMBER(G5)), C5-G5, "") -> -14186.437 | I5: =IFERROR(H5/G5, "") -> -0.18070347
A6: Goshen A | B6: MA | C6: 49163 | D6: 93145.65 | E6: =IF(AND(ISNUMBER(C6),ISNUMBER(D6)), C6-D6, "") -> -43982.65 | F6: =IFERROR(E6/D6, "") -> -0.47219221 | G6: 45346.04 | H6: =IF(AND(ISNUMBER(C6),ISNUMBER(G6)), C6-G6, "") -> 3816.96 | I6: =IFERROR(H6/G6, "") -> 0.084174054 | J6: 1.Inverter 3.15 tripped offline at 02:00PM on 01/30 due to Arc warning key stop later self resolved at 07:00AM on 01/31. | K6: 1.SR096163
A7: Phillipston A KB | B7: MA | C7: 52361 | D7: 133149.1 | E7: =IF(AND(ISNUMBER(C7),ISNUMBER(D7)), C7-D7, "") -> -80788.1 | F7: =IFERROR(E7/D7, "") -> -0.60674913 | G7: 48584.34 | H7: =IF(AND(ISNUMBER(C7),ISNUMBER(G7)), C7-G7, "") -> 3776.66 | I7: =IFERROR(H7/G7, "") -> 0.077734101
A8: Uxbridge D | B8: MA | C8: 79311 | D8: 118820.9 | E8: =IF(AND(ISNUMBER(C8),ISNUMBER(D8)), C8-D8, "") -> -39509.9 | F8: =IFERROR(E8/D8, "") -> -0.33251642 | G8: 102742.7 | H8: =IF(AND(ISNUMBER(C8),ISNUMBER(G8)), C8-G8, "") -> -23431.7 | I8: =IFERROR(H8/G8, "") -> -0.22806195
A9: West Bridgewater A&B | B9: MA | C9: 140442 | D9: 203218.3 | E9: =IF(AND(ISNUMBER(C9),ISNUMBER(D9)), C9-D9, "") -> -62776.3 | F9: =IFERROR(E9/D9, "") -> -0.30891066 | G9: 168220.8 | H9: =IF(AND(ISNUMBER(C9),ISNUMBER(G9)), C9-G9, "") -> -27778.8 | I9: =IFERROR(H9/G9, "") -> -0.16513297 | J9: 1.Inverter 1.03 has been RMA'd and offline since 12/18, and was brought back online at 2:45 PM on 01/27 by a technician after replacing the RMA'd inverter with a new inverter. 2.Inverter 5.04 has been RMA'd, and the inverter is currently operating with a string down. | K9: 1.SR094920 2.SR094966 | L9: SR094966
A10: Sutton A | B10: MA | C10: 54236 | D10: 92857.71 | E10: =IF(AND(ISNUMBER(C10),ISNUMBER(D10)), C10-D10, "") -> -38621.71 | F10: =IFERROR(E10/D10, "") -> -0.41592357 | G10: 92964.7 | H10: =IF(AND(ISNUMBER(C10),ISNUMBER(G10)), C10-G10, "") -> -38728.7 | I10: =IFERROR(H10/G10, "") -> -0.41659576
A11: North Adams A | B11: MA | C11: 61430 | D11: 85432.94 | E11: =IF(AND(ISNUMBER(C11),ISNUMBER(D11)), C11-D11, "") -> -24002.94 | F11: =IFERROR(E11/D11, "") -> -0.2809565 | G11: 97969.54 | H11: =IF(AND(ISNUMBER(C11),ISNUMBER(G11)), C11-G11, "") -> -36539.54 | I11: =IFERROR(H11/G11, "") -> -0.37296837
A12: North Adams B | B12: MA | C12: 45389 | D12: 3439.174 | E12: =IF(AND(ISNUMBER(C12),ISNUMBER(D12)), C12-D12, "") -> 41949.826 | F12: =IFERROR(E12/D12, "") -> 12.197646 | G12: 97969.54 | H12: =IF(AND(ISNUMBER(C12),ISNUMBER(G12)), C12-G12, "") -> -52580.54 | I12: =IFERROR(H12/G12, "") -> -0.53670294 | J12: 1.Weather station stopped communicating since 07/16/24, and the technician brought it back online at 12:45 PM on 01/30 by replacing the integrated weather station with an ambient temperature sensor by connecting to power logger port 1 and power logger port 2 is being RMA'd. | K12: 1.SR087828
A13: Clarksburg A | B13: MA | C13: 33591 | D13: 74718.88 | E13: =IF(AND(ISNUMBER(C13),ISNUMBER(D13)), C13-D13, "") -> -41127.88 | F13: =IFERROR(E13/D13, "") -> -0.55043491 | G13: 97524.52 | H13: =IF(AND(ISNUMBER(C13),ISNUMBER(G13)), C13-G13, "") -> -63933.52 | I13: =IFERROR(H13/G13, "") -> -0.65556354
A14: Swansea B | B14: MA | C14: 94569 | D14: 125325.5 | E14: =IF(AND(ISNUMBER(C14),ISNUMBER(D14)), C14-D14, "") -> -30756.5 | F14: =IFERROR(E14/D14, "") -> -0.24541294 | G14: 51394 | H14: =IF(AND(ISNUMBER(C14),ISNUMBER(G14)), C14-G14, "") -> 43175 | I14: =IFERROR(H14/G14, "") -> 0.84007861 | J14: 1.Inverter 1.5 was offline and being RMA'd since 11/05/2024, and was brought back online at 02:00PM on 01/09/2025 by a technician after being replaced with a new inverter. | K14: 1.SR092911
A15: Wareham 2 | B15: MA | C15: 87644 | D15: 97399.22 | E15: =IF(AND(ISNUMBER(C15),ISNUMBER(D15)), C15-D15, "") -> -9755.22 | F15: =IFERROR(E15/D15, "") -> -0.10015706 | G15: 102713.9 | H15: =IF(AND(ISNUMBER(C15),ISNUMBER(G15)), C15-G15, "") -> -15069.9 | I15: =IFERROR(H15/G15, "") -> -0.14671724 | J15: 1.Inverter 2.11 tripped offline at 09:45 AM on 01/08 due to an ARC Protection fault. A technician later cleared the fault and brought it back online at 09:15 AM on 01/09. 2.Site tripped offline at 06:00AM on 01/18 due to utility outage and back online at 12:15PM on 01/18. | K15: 1.SR095394 2.SR095692 | L15: SR095692
A16: Kingston 1 KB | B16: MA | C16: 71770 | D16: 101770 | E16: =IF(AND(ISNUMBER(C16),ISNUMBER(D16)), C16-D16, "") -> -30000 | F16: =IFERROR(E16/D16, "") -> -0.29478235 | G16: 78160.59 | H16: =IF(AND(ISNUMBER(C16),ISNUMBER(G16)), C16-G16, "") -> -6390.59 | I16: =IFERROR(H16/G16, "") -> -0.081762305 | J16: 1.Inverter 2.5 tripped offline on 01/01 due to 'Insulation Resistance Low - Isolation Error' and later back online at 10:28 AM on 01/02. | K16: 1. SR095225
A17: Kingston 2 KB | B17: MA | C17: 57696 | D17: 63140.3 | E17: =IF(AND(ISNUMBER(C17),ISNUMBER(D17)), C17-D17, "") -> -5444.3 | F17: =IFERROR(E17/D17, "") -> -0.086225438 | G17: 62736.91 | H17: =IF(AND(ISNUMBER(C17),ISNUMBER(G17)), C17-G17, "") -> -5040.91 | I17: =IFERROR(H17/G17, "") -> -0.080349989
A18: Holliston B | B18: MA | C18: 61173 | D18: 103746 | E18: =IF(AND(ISNUMBER(C18),ISNUMBER(D18)), C18-D18, "") -> -42573 | F18: =IFERROR(E18/D18, "") -> -0.41035799 | G18: 97654.44 | H18: =IF(AND(ISNUMBER(C18),ISNUMBER(G18)), C18-G18, "") -> -36481.44 | I18: =IFERROR(H18/G18, "") -> -0.37357687 | J18: 1.Inverters 17, 19, 14, 27, 11, 15, 25, 26, 9, 20, 24 & 18 are underperforming approximately 44KW down due to shading. | K18: 1.SR094409
A19: Fairhaven C | B19: MA | C19: 176084 | D19: 223072.8 | E19: =IF(AND(ISNUMBER(C19),ISNUMBER(D19)), C19-D19, "") -> -46988.8 | F19: =IFERROR(E19/D19, "") -> -0.21064334 | G19: 175840.8 | H19: =IF(AND(ISNUMBER(C19),ISNUMBER(G19)), C19-G19, "") -> 243.2 | I19: =IFERROR(H19/G19, "") -> 0.0013830692 | J19: 1.Inverter 8 was offline on 01/03, 01/05, 01/06, 01/08, 01/11 and 01/15 due to Bus sum high fault and technician stated that inverter should be RMA'D from 01/16. 2.Inverter 10 was being RMA'd from 11/04/24 and was offline on 01/03, 01/08, 01/14 due to bus sum high fault and on 01/16 technician checked- in and replaced RMA'd inverter with New stock, voltages tested good and production was restored. 3.Inverter 19 has not communicating since 11/19/24, production cannot be confirmed at meter. On 01/15 technician checked in and stated that inverter was dropped offline due to a thermal event within the powerhead and communication board is being RMA'd and on 01/16, technician replaced faulty communications board and get the inverter to begin communicating again via the DAS platform. | K19: 1.SR088896 2.SR092913 3.SR093031 | L19: SR092913 | M19: SR093031
A20: Plympton A-2 | B20: MA | C20: 86762 | D20: 112140.9 | E20: =IF(AND(ISNUMBER(C20),ISNUMBER(D20)), C20-D20, "") -> -25378.9 | F20: =IFERROR(E20/D20, "") -> -0.22631261 | G20: 98150.02 | H20: =IF(AND(ISNUMBER(C20),ISNUMBER(G20)), C20-G20, "") -> -11388.02 | I20: =IFERROR(H20/G20, "") -> -0.11602667 | J20: 1.Site tripped offline at 10:15AM due to SEL relay open and back online at 10:30AM after remote reset on attempted on 01/02. 2.Inverter 1 was offline due to hardware overcurrent fault following brief site outage from 10:15AM to 10:30AM on 01/02 where the site was closed remotely and on 01/03 inverter has self-resolved. | K20: 1.SR095226 2.SR095230 | L20: SR095230

Sheet Feb
A1: {=portfolio} -> MN8 KEF | D1: February Actual v. Expected | G1: February Actual v. Forecasted
A2: Total | C2: =SUM(C4:C95) -> 0 | D2: =SUM(D4:D95) -> 0 | E2: =C2-D2 -> 0 | F2: =IFERROR(E2/D2, 0) -> 0 | G2: =SUM(G4:G95) -> 0 | H2: =C2-G2 -> 0 | I2: =IFERROR(H2/G2, 0) -> 0 | J2: =IF(AND(TODAY()>DATE(2024, 2, 1), COUNTA(Sites[Site])<>(COUNT(C:C)-1)), "Some sites are missing actual data; if new sites were added, make sure they are aligned correctly (including prior months!)", "") -> Some sites are missing actual data; if new sites were added, make sure they are aligned correctly (including prior months!)
A3: Site | B3: State | C3: Actual | D3: Expected | E3: Delta | F3: % | G3: Forecasted | H3: Delta | I3: % | J3: Notes | K3: Service Requests
A4: {=Sites[Site]} -> Williamsburg A | B4: {=Sites[State]} -> MA | E4: =IF(AND(ISNUMBER(C4),ISNUMBER(D4)), C4-D4, "") | F4: =IFERROR(E4/D4, "") | H4: =IF(AND(ISNUMBER(C4),ISNUMBER(G4)), C4-G4, "") | I4: =IFERROR(H4/G4, "")
A5: Orange A KB | B5: MA | E5: =IF(AND(ISNUMBER(C5),ISNUMBER(D5)), C5-D5, "") | F5: =IFERROR(E5/D5, "") | H5: =IF(AND(ISNUMBER(C5),ISNUMBER(G5)), C5-G5, "") | I5: =IFERROR(H5/G5, "")
A6: Goshen A | B6: MA | E6: =IF(AND(ISNUMBER(C6),ISNUMBER(D6)), C6-D6, "") | F6: =IFERROR(E6/D6, "") | H6: =IF(AND(ISNUMBER(C6),ISNUMBER(G6)), C6-G6, "") | I6: =IFERROR(H6/G6, "")
A7: Phillipston A KB | B7: MA | E7: =IF(AND(ISNUMBER(C7),ISNUMBER(D7)), C7-D7, "") | F7: =IFERROR(E7/D7, "") | H7: =IF(AND(ISNUMBER(C7),ISNUMBER(G7)), C7-G7, "") | I7: =IFERROR(H7/G7, "")
A8: Uxbridge D | B8: MA | E8: =IF(AND(ISNUMBER(C8),ISNUMBER(D8)), C8-D8, "") | F8: =IFERROR(E8/D8, "") | H8: =IF(AND(ISNUMBER(C8),ISNUMBER(G8)), C8-G8, "") | I8: =IFERROR(H8/G8, "")
A9: West Bridgewater A&B | B9: MA | E9: =IF(AND(ISNUMBER(C9),ISNUMBER(D9)), C9-D9, "") | F9: =IFERROR(E9/D9, "") | H9: =IF(AND(ISNUMBER(C9),ISNUMBER(G9)), C9-G9, "") | I9: =IFERROR(H9/G9, "")
A10: Sutton A | B10: MA | E10: =IF(AND(ISNUMBER(C10),ISNUMBER(D10)), C10-D10, "") | F10: =IFERROR(E10/D10, "") | H10: =IF(AND(ISNUMBER(C10),ISNUMBER(G10)), C10-G10, "") | I10: =IFERROR(H10/G10, "")
A11: North Adams A | B11: MA | E11: =IF(AND(ISNUMBER(C11),ISNUMBER(D11)), C11-D11, "") | F11: =IFERROR(E11/D11, "") | H11: =IF(AND(ISNUMBER(C11),ISNUMBER(G11)), C11-G11, "") | I11: =IFERROR(H11/G11, "")
A12: North Adams B | B12: MA | E12: =IF(AND(ISNUMBER(C12),ISNUMBER(D12)), C12-D12, "") | F12: =IFERROR(E12/D12, "") | H12: =IF(AND(ISNUMBER(C12),ISNUMBER(G12)), C12-G12, "") | I12: =IFERROR(H12/G12, "")
A13: Clarksburg A | B13: MA | E13: =IF(AND(ISNUMBER(C13),ISNUMBER(D13)), C13-D13, "") | F13: =IFERROR(E13/D13, "") | H13: =IF(AND(ISNUMBER(C13),ISNUMBER(G13)), C13-G13, "") | I13: =IFERROR(H13/G13, "")
A14: Swansea B | B14: MA | E14: =IF(AND(ISNUMBER(C14),ISNUMBER(D14)), C14-D14, "") | F14: =IFERROR(E14/D14, "") | H14: =IF(AND(ISNUMBER(C14),ISNUMBER(G14)), C14-G14, "") | I14: =IFERROR(H14/G14, "")
A15: Wareham 2 | B15: MA | E15: =IF(AND(ISNUMBER(C15),ISNUMBER(D15)), C15-D15, "") | F15: =IFERROR(E15/D15, "") | H15: =IF(AND(ISNUMBER(C15),ISNUMBER(G15)), C15-G15, "") | I15: =IFERROR(H15/G15, "")
A16: Kingston 1 KB | B16: MA | E16: =IF(AND(ISNUMBER(C16),ISNUMBER(D16)), C16-D16, "") | F16: =IFERROR(E16/D16, "") | H16: =IF(AND(ISNUMBER(C16),ISNUMBER(G16)), C16-G16, "") | I16: =IFERROR(H16/G16, "")
... A20: Plympton A-2 | B20: MA | E20: =IF(AND(ISNUMBER(C20),ISNUMBER(D20)), C20-D20, "") | F20: =IFERROR(E20/D20, "") | H20: =IF(AND(ISNUMBER(C20),ISNUMBER(G20)), C20-G20, "") | I20: =IFERROR(H20/G20, "")

Sheet Mar
A1: {=portfolio} -> MN8 KEF | D1: March Actual v. Expected | G1: March Actual v. Forecasted
A2: Total | C2: =SUM(C4:C95) -> 0 | D2: =SUM(D4:D95) -> 0 | E2: =C2-D2 -> 0 | F2: =IFERROR(E2/D2, 0) -> 0 | G2: =SUM(G4:G95) -> 0 | H2: =C2-G2 -> 0 | I2: =IFERROR(H2/G2, 0) -> 0 | J2: =IF(AND(TODAY()>DATE(2024, 3, 1), COUNTA(Sites[Site])<>(COUNT(C:C)-1)), "Some sites are missing actual data; if new sites were added, make sure they are aligned correctly (including prior months!)", "") -> Some sites are missing actual data; if new sites were added, make sure they are aligned correctly (including prior months!)
A3: Site | B3: State | C3: Actual | D3: Expected | E3: Delta | F3: % | G3: Forecasted | H3: Delta | I3: % | J3: Notes | K3: Service Requests
A4: {=Sites[Site]} -> Williamsburg A | B4: {=Sites[State]} -> MA | E4: =IF(AND(ISNUMBER(C4),ISNUMBER(D4)), C4-D4, "") | F4: =IFERROR(E4/D4, "") | H4: =IF(AND(ISNUMBER(C4),ISNUMBER(G4)), C4-G4, "") | I4: =IFERROR(H4/G4, "")
A5: Orange A KB | B5: MA | E5: =IF(AND(ISNUMBER(C5),ISNUMBER(D5)), C5-D5, "") | F5: =IFERROR(E5/D5, "") | H5: =IF(AND(ISNUMBER(C5),ISNUMBER(G5)), C5-G5, "") | I5: =IFERROR(H5/G5, "")
A6: Goshen A | B6: MA | E6: =IF(AND(ISNUMBER(C6),ISNUMBER(D6)), C6-D6, "") | F6: =IFERROR(E6/D6, "") | H6: =IF(AND(ISNUMBER(C6),ISNUMBER(G6)), C6-G6, "") | I6: =IFERROR(H6/G6, "")
A7: Phillipston A KB | B7: MA | E7: =IF(AND(ISNUMBER(C7),ISNUMBER(D7)), C7-D7, "") | F7: =IFERROR(E7/D7, "") | H7: =IF(AND(ISNUMBER(C7),ISNUMBER(G7)), C7-G7, "") | I7: =IFERROR(H7/G7, "")
A8: Uxbridge D | B8: MA | E8: =IF(AND(ISNUMBER(C8),ISNUMBER(D8)), C8-D8, "") | F8: =IFERROR(E8/D8, "") | H8: =IF(AND(ISNUMBER(C8),ISNUMBER(G8)), C8-G8, "") | I8: =IFERROR(H8/G8, "")
A9: West Bridgewater A&B | B9: MA | E9: =IF(AND(ISNUMBER(C9),ISNUMBER(D9)), C9-D9, "") | F9: =IFERROR(E9/D9, "") | H9: =IF(AND(ISNUMBER(C9),ISNUMBER(G9)), C9-G9, "") | I9: =IFERROR(H9/G9, "")
A10: Sutton A | B10: MA | E10: =IF(AND(ISNUMBER(C10),ISNUMBER(D10)), C10-D10, "") | F10: =IFERROR(E10/D10, "") | H10: =IF(AND(ISNUMBER(C10),ISNUMBER(G10)), C10-G10, "") | I10: =IFERROR(H10/G10, "")
A11: North Adams A | B11: MA | E11: =IF(AND(ISNUMBER(C11),ISNUMBER(D11)), C11-D11, "") | F11: =IFERROR(E11/D11, "") | H11: =IF(AND(ISNUMBER(C11),ISNUMBER(G11)), C11-G11, "") | I11: =IFERROR(H11/G11, "")
A12: North Adams B | B12: MA | E12: =IF(AND(ISNUMBER(C12),ISNUMBER(D12)), C12-D12, "") | F12: =IFERROR(E12/D12, "") | H12: =IF(AND(ISNUMBER(C12),ISNUMBER(G12)), C12-G12, "") | I12: =IFERROR(H12/G12, "")
A13: Clarksburg A | B13: MA | E13: =IF(AND(ISNUMBER(C13),ISNUMBER(D13)), C13-D13, "") | F13: =IFERROR(E13/D13, "") | H13: =IF(AND(ISNUMBER(C13),ISNUMBER(G13)), C13-G13, "") | I13: =IFERROR(H13/G13, "")
A14: Swansea B | B14: MA | E14: =IF(AND(ISNUMBER(C14),ISNUMBER(D14)), C14-D14, "") | F14: =IFERROR(E14/D14, "") | H14: =IF(AND(ISNUMBER(C14),ISNUMBER(G14)), C14-G14, "") | I14: =IFERROR(H14/G14, "")
A15: Wareham 2 | B15: MA | E15: =IF(AND(ISNUMBER(C15),ISNUMBER(D15)), C15-D15, "") | F15: =IFERROR(E15/D15, "") | H15: =IF(AND(ISNUMBER(C15),ISNUMBER(G15)), C15-G15, "") | I15: =IFERROR(H15/G15, "")
A16: Kingston 1 KB | B16: MA | E16: =IF(AND(ISNUMBER(C16),ISNUMBER(D16)), C16-D16, "") | F16: =IFERROR(E16/D16, "") | H16: =IF(AND(ISNUMBER(C16),ISNUMBER(G16)), C16-G16, "") | I16: =IFERROR(H16/G16, "")
... A20: Plympton A-2 | B20: MA | E20: =IF(AND(ISNUMBER(C20),ISNUMBER(D20)), C20-D20, "") | F20: =IFERROR(E20/D20, "") | H20: =IF(AND(ISNUMBER(C20),ISNUMBER(G20)), C20-G20, "") | I20: =IFERROR(H20/G20, "")

Sheet Apr
A1: {=portfolio} -> MN8 KEF | D1: April Actual v. Expected | G1: April Actual v. Forecasted
A2: Total | C2: =SUM(C4:C95) -> 0 | D2: =SUM(D4:D95) -> 0 | E2: =C2-D2 -> 0 | F2: =IFERROR(E2/D2, 0) -> 0 | G2: =SUM(G4:G95) -> 0 | H2: =C2-G2 -> 0 | I2: =IFERROR(H2/G2, 0) -> 0 | J2: =IF(AND(TODAY()>DATE(2024, 4, 1), COUNTA(Sites[Site])<>(COUNT(C:C)-1)), "Some sites are missing actual data; if new sites were added, make sure they are aligned correctly (including prior months!)", "") -> Some sites are missing actual data; if new sites were added, make sure they are aligned correctly (including prior months!)
A3: Site | B3: State | C3: Actual | D3: Expected | E3: Delta | F3: % | G3: Forecasted | H3: Delta | I3: % | J3: Notes | K3: Service Requests
A4: {=Sites[Site]} -> Williamsburg A | B4: {=Sites[State]} -> MA | E4: =IF(AND(ISNUMBER(C4),ISNUMBER(D4)), C4-D4, "") | F4: =IFERROR(E4/D4, "") | H4: =IF(AND(ISNUMBER(C4),ISNUMBER(G4)), C4-G4, "") | I4: =IFERROR(H4/G4, "") | J4: 1. Inverter 1.3 tripped offline on 04/05 at 10:24 and back online at 14:17 | K4: 1. SR083119
A5: Orange A KB | B5: MA | E5: =IF(AND(ISNUMBER(C5),ISNUMBER(D5)), C5-D5, "") | F5: =IFERROR(E5/D5, "") | H5: =IF(AND(ISNUMBER(C5),ISNUMBER(G5)), C5-G5, "") | I5: =IFERROR(H5/G5, "")
A6: Goshen A | B6: MA | E6: =IF(AND(ISNUMBER(C6),ISNUMBER(D6)), C6-D6, "") | F6: =IFERROR(E6/D6, "") | H6: =IF(AND(ISNUMBER(C6),ISNUMBER(G6)), C6-G6, "") | I6: =IFERROR(H6/G6, "")
A7: Phillipston A KB | B7: MA | E7: =IF(AND(ISNUMBER(C7),ISNUMBER(D7)), C7-D7, "") | F7: =IFERROR(E7/D7, "") | H7: =IF(AND(ISNUMBER(C7),ISNUMBER(G7)), C7-G7, "") | I7: =IFERROR(H7/G7, "")
A8: Uxbridge D | B8: MA | E8: =IF(AND(ISNUMBER(C8),ISNUMBER(D8)), C8-D8, "") | F8: =IFERROR(E8/D8, "") | H8: =IF(AND(ISNUMBER(C8),ISNUMBER(G8)), C8-G8, "") | I8: =IFERROR(H8/G8, "")
A9: West Bridgewater A&B | B9: MA | E9: =IF(AND(ISNUMBER(C9),ISNUMBER(D9)), C9-D9, "") | F9: =IFERROR(E9/D9, "") | H9: =IF(AND(ISNUMBER(C9),ISNUMBER(G9)), C9-G9, "") | I9: =IFERROR(H9/G9, "")
A10: Sutton A | B10: MA | E10: =IF(AND(ISNUMBER(C10),ISNUMBER(D10)), C10-D10, "") | F10: =IFERROR(E10/D10, "") | H10: =IF(AND(ISNUMBER(C10),ISNUMBER(G10)), C10-G10, "") | I10: =IFERROR(H10/G10, "")
A11: North Adams A | B11: MA | E11: =IF(AND(ISNUMBER(C11),ISNUMBER(D11)), C11-D11, "") | F11: =IFERROR(E11/D11, "") | H11: =IF(AND(ISNUMBER(C11),ISNUMBER(G11)), C11-G11, "") | I11: =IFERROR(H11/G11, "")
A12: North Adams B | B12: MA | E12: =IF(AND(ISNUMBER(C12),ISNUMBER(D12)), C12-D12, "") | F12: =IFERROR(E12/D12, "") | H12: =IF(AND(ISNUMBER(C12),ISNUMBER(G12)), C12-G12, "") | I12: =IFERROR(H12/G12, "")
A13: Clarksburg A | B13: MA | E13: =IF(AND(ISNUMBER(C13),ISNUMBER(D13)), C13-D13, "") | F13: =IFERROR(E13/D13, "") | H13: =IF(AND(ISNUMBER(C13),ISNUMBER(G13)), C13-G13, "") | I13: =IFERROR(H13/G13, "")
A14: Swansea B | B14: MA | E14: =IF(AND(ISNUMBER(C14),ISNUMBER(D14)), C14-D14, "") | F14: =IFERROR(E14/D14, "") | H14: =IF(AND(ISNUMBER(C14),ISNUMBER(G14)), C14-G14, "") | I14: =IFERROR(H14/G14, "")
A15: Wareham 2 | B15: MA | E15: =IF(AND(ISNUMBER(C15),ISNUMBER(D15)), C15-D15, "") | F15: =IFERROR(E15/D15, "") | H15: =IF(AND(ISNUMBER(C15),ISNUMBER(G15)), C15-G15, "") | I15: =IFERROR(H15/G15, "")
A16: Kingston 1 KB | B16: MA | E16: =IF(AND(ISNUMBER(C16),ISNUMBER(D16)), C16-D16, "") | F16: =IFERROR(E16/D16, "") | H16: =IF(AND(ISNUMBER(C16),ISNUMBER(G16)), C16-G16, "") | I16: =IFERROR(H16/G16, "")
... A20: Plympton A-2 | B20: MA | E20: =IF(AND(ISNUMBER(C20),ISNUMBER(D20)), C20-D20, "") | F20: =IFERROR(E20/D20, "") | H20: =IF(AND(ISNUMBER(C20),ISNUMBER(G20)), C20-G20, "") | I20: =IFERROR(H20/G20, "")

Sheet May
A1: {=portfolio} -> MN8 KEF | D1: May Actual v. Expected | G1: May Actual v. Forecasted
A2: Total | C2: =SUM(C4:C95) -> 0 | D2: =SUM(D4:D95) -> 0 | E2: =C2-D2 -> 0 | F2: =IFERROR(E2/D2, 0) -> 0 | G2: =SUM(G4:G95) -> 0 | H2: =C2-G2 -> 0 | I2: =IFERROR(H2/G2, 0) -> 0 | J2: =IF(AND(TODAY()>DATE(2024, 5, 1), COUNTA(Sites[Site])<>(COUNT(C:C)-1)), "Some sites are missing actual data; if new sites were added, make sure they are aligned correctly (including prior months!)", "") -> Some sites are missing actual data; if new sites were added, make sure they are aligned correctly (including prior months!)
A3: Site | B3: State | C3: Actual | D3: Expected | E3: Delta | F3: % | G3: Forecasted | H3: Delta | I3: % | J3: Notes | K3: Service Requests
A4: {=Sites[Site]} -> Williamsburg A | B4: {=Sites[State]} -> MA | E4: =IF(AND(ISNUMBER(C4),ISNUMBER(D4)), C4-D4, "") | F4: =IFERROR(E4/D4, "") | H4: =IF(AND(ISNUMBER(C4),ISNUMBER(G4)), C4-G4, "") | I4: =IFERROR(H4/G4, "")
A5: Orange A KB | B5: MA | E5: =IF(AND(ISNUMBER(C5),ISNUMBER(D5)), C5-D5, "") | F5: =IFERROR(E5/D5, "") | H5: =IF(AND(ISNUMBER(C5),ISNUMBER(G5)), C5-G5, "") | I5: =IFERROR(H5/G5, "")
A6: Goshen A | B6: MA | E6: =IF(AND(ISNUMBER(C6),ISNUMBER(D6)), C6-D6, "") | F6: =IFERROR(E6/D6, "") | H6: =IF(AND(ISNUMBER(C6),ISNUMBER(G6)), C6-G6, "") | I6: =IFERROR(H6/G6, "")
A7: Phillipston A KB | B7: MA | E7: =IF(AND(ISNUMBER(C7),ISNUMBER(D7)), C7-D7, "") | F7: =IFERROR(E7/D7, "") | H7: =IF(AND(ISNUMBER(C7),ISNUMBER(G7)), C7-G7, "") | I7: =IFERROR(H7/G7, "")
A8: Uxbridge D | B8: MA | E8: =IF(AND(ISNUMBER(C8),ISNUMBER(D8)), C8-D8, "") | F8: =IFERROR(E8/D8, "") | H8: =IF(AND(ISNUMBER(C8),ISNUMBER(G8)), C8-G8, "") | I8: =IFERROR(H8/G8, "")
A9: West Bridgewater A&B | B9: MA | E9: =IF(AND(ISNUMBER(C9),ISNUMBER(D9)), C9-D9, "") | F9: =IFERROR(E9/D9, "") | H9: =IF(AND(ISNUMBER(C9),ISNUMBER(G9)), C9-G9, "") | I9: =IFERROR(H9/G9, "")
A10: Sutton A | B10: MA | E10: =IF(AND(ISNUMBER(C10),ISNUMBER(D10)), C10-D10, "") | F10: =IFERROR(E10/D10, "") | H10: =IF(AND(ISNUMBER(C10),ISNUMBER(G10)), C10-G10, "") | I10: =IFERROR(H10/G10, "")
A11: North Adams A | B11: MA | E11: =IF(AND(ISNUMBER(C11),ISNUMBER(D11)), C11-D11, "") | F11: =IFERROR(E11/D11, "") | H11: =IF(AND(ISNUMBER(C11),ISNUMBER(G11)), C11-G11, "") | I11: =IFERROR(H11/G11, "")
A12: North Adams B | B12: MA | E12: =IF(AND(ISNUMBER(C12),ISNUMBER(D12)), C12-D12, "") | F12: =IFERROR(E12/D12, "") | H12: =IF(AND(ISNUMBER(C12),ISNUMBER(G12)), C12-G12, "") | I12: =IFERROR(H12/G12, "")
A13: Clarksburg A | B13: MA | E13: =IF(AND(ISNUMBER(C13),ISNUMBER(D13)), C13-D13, "") | F13: =IFERROR(E13/D13, "") | H13: =IF(AND(ISNUMBER(C13),ISNUMBER(G13)), C13-G13, "") | I13: =IFERROR(H13/G13, "")
A14: Swansea B | B14: MA | E14: =IF(AND(ISNUMBER(C14),ISNUMBER(D14)), C14-D14, "") | F14: =IFERROR(E14/D14, "") | H14: =IF(AND(ISNUMBER(C14),ISNUMBER(G14)), C14-G14, "") | I14: =IFERROR(H14/G14, "")
A15: Wareham 2 | B15: MA | E15: =IF(AND(ISNUMBER(C15),ISNUMBER(D15)), C15-D15, "") | F15: =IFERROR(E15/D15, "") | H15: =IF(AND(ISNUMBER(C15),ISNUMBER(G15)), C15-G15, "") | I15: =IFERROR(H15/G15, "")
A16: Kingston 1 KB | B16: MA | E16: =IF(AND(ISNUMBER(C16),ISNUMBER(D16)), C16-D16, "") | F16: =IFERROR(E16/D16, "") | H16: =IF(AND(ISNUMBER(C16),ISNUMBER(G16)), C16-G16, "") | I16: =IFERROR(H16/G16, "")
... A20: Plympton A-2 | B20: MA | E20: =IF(AND(ISNUMBER(C20),ISNUMBER(D20)), C20-D20, "") | F20: =IFERROR(E20/D20, "") | H20: =IF(AND(ISNUMBER(C20),ISNUMBER(G20)), C20-G20, "") | I20: =IFERROR(H20/G20, "")

Sheet Jun
A1: {=portfolio} -> MN8 KEF | D1: June Actual v. Expected | G1: June Actual v. Forecasted
A2: Total | C2: =SUM(C4:C95) -> 0 | D2: =SUM(D4:D95) -> 0 | E2: =C2-D2 -> 0 | F2: =IFERROR(E2/D2, 0) -> 0 | G2: =SUM(G4:G95) -> 0 | H2: =C2-G2 -> 0 | I2: =IFERROR(H2/G2, 0) -> 0 | J2: =IF(AND(TODAY()>DATE(2024, 6, 1), COUNTA(Sites[Site])<>(COUNT(C:C)-1)), "Some sites are missing actual data; if new sites were added, make sure they are aligned correctly (including prior months!)", "") -> Some sites are missing actual data; if new sites were added, make sure they are aligned correctly (including prior months!)
A3: Site | B3: State | C3: Actual | D3: Expected | E3: Delta | F3: % | G3: Forecasted | H3: Delta | I3: % | J3: Notes | K3: Service Requests
A4: {=Sites[Site]} -> Williamsburg A | B4: {=Sites[State]} -> MA | E4: =IF(AND(ISNUMBER(C4),ISNUMBER(D4)), C4-D4, "") | F4: =IFERROR(E4/D4, "") | H4: =IF(AND(ISNUMBER(C4),ISNUMBER(G4)), C4-G4, "") | I4: =IFERROR(H4/G4, "") | J4: 1. Site was offline from 18:45 on 06/19 and back online at 22:15 on 06/19 | K4: 1. SR086454
A5: Orange A KB | B5: MA | E5: =IF(AND(ISNUMBER(C5),ISNUMBER(D5)), C5-D5, "") | F5: =IFERROR(E5/D5, "") | H5: =IF(AND(ISNUMBER(C5),ISNUMBER(G5)), C5-G5, "") | I5: =IFERROR(H5/G5, "")
A6: Goshen A | B6: MA | E6: =IF(AND(ISNUMBER(C6),ISNUMBER(D6)), C6-D6, "") | F6: =IFERROR(E6/D6, "") | H6: =IF(AND(ISNUMBER(C6),ISNUMBER(G6)), C6-G6, "") | I6: =IFERROR(H6/G6, "")
A7: Phillipston A KB | B7: MA | E7: =IF(AND(ISNUMBER(C7),ISNUMBER(D7)), C7-D7, "") | F7: =IFERROR(E7/D7, "") | H7: =IF(AND(ISNUMBER(C7),ISNUMBER(G7)), C7-G7, "") | I7: =IFERROR(H7/G7, "")
A8: Uxbridge D | B8: MA | E8: =IF(AND(ISNUMBER(C8),ISNUMBER(D8)), C8-D8, "") | F8: =IFERROR(E8/D8, "") | H8: =IF(AND(ISNUMBER(C8),ISNUMBER(G8)), C8-G8, "") | I8: =IFERROR(H8/G8, "")
A9: West Bridgewater A&B | B9: MA | E9: =IF(AND(ISNUMBER(C9),ISNUMBER(D9)), C9-D9, "") | F9: =IFERROR(E9/D9, "") | H9: =IF(AND(ISNUMBER(C9),ISNUMBER(G9)), C9-G9, "") | I9: =IFERROR(H9/G9, "")
A10: Sutton A | B10: MA | E10: =IF(AND(ISNUMBER(C10),ISNUMBER(D10)), C10-D10, "") | F10: =IFERROR(E10/D10, "") | H10: =IF(AND(ISNUMBER(C10),ISNUMBER(G10)), C10-G10, "") | I10: =IFERROR(H10/G10, "")
A11: North Adams A | B11: MA | E11: =IF(AND(ISNUMBER(C11),ISNUMBER(D11)), C11-D11, "") | F11: =IFERROR(E11/D11, "") | H11: =IF(AND(ISNUMBER(C11),ISNUMBER(G11)), C11-G11, "") | I11: =IFERROR(H11/G11, "")
A12: North Adams B | B12: MA | E12: =IF(AND(ISNUMBER(C12),ISNUMBER(D12)), C12-D12, "") | F12: =IFERROR(E12/D12, "") | H12: =IF(AND(ISNUMBER(C12),ISNUMBER(G12)), C12-G12, "") | I12: =IFERROR(H12/G12, "")
A13: Clarksburg A | B13: MA | E13: =IF(AND(ISNUMBER(C13),ISNUMBER(D13)), C13-D13, "") | F13: =IFERROR(E13/D13, "") | H13: =IF(AND(ISNUMBER(C13),ISNUMBER(G13)), C13-G13, "") | I13: =IFERROR(H13/G13, "")
A14: Swansea B | B14: MA | E14: =IF(AND(ISNUMBER(C14),ISNUMBER(D14)), C14-D14, "") | F14: =IFERROR(E14/D14, "") | H14: =IF(AND(ISNUMBER(C14),ISNUMBER(G14)), C14-G14, "") | I14: =IFERROR(H14/G14, "")
A15: Wareham 2 | B15: MA | E15: =IF(AND(ISNUMBER(C15),ISNUMBER(D15)), C15-D15, "") | F15: =IFERROR(E15/D15, "") | H15: =IF(AND(ISNUMBER(C15),ISNUMBER(G15)), C15-G15, "") | I15: =IFERROR(H15/G15, "")
A16: Kingston 1 KB | B16: MA | E16: =IF(AND(ISNUMBER(C16),ISNUMBER(D16)), C16-D16, "") | F16: =IFERROR(E16/D16, "") | H16: =IF(AND(ISNUMBER(C16),ISNUMBER(G16)), C16-G16, "") | I16: =IFERROR(H16/G16, "")
... A20: Plympton A-2 | B20: MA | E20: =IF(AND(ISNUMBER(C20),ISNUMBER(D20)), C20-D20, "") | F20: =IFERROR(E20/D20, "") | H20: =IF(AND(ISNUMBER(C20),ISNUMBER(G20)), C20-G20, "") | I20: =IFERROR(H20/G20, "")

Sheet Jul
A1: {=portfolio} -> MN8 KEF | D1: July Actual v. Expected | G1: July Actual v. Forecasted
A2: Total | C2: =SUM(C4:C95) -> 0 | D2: =SUM(D4:D95) -> 0 | E2: =C2-D2 -> 0 | F2: =IFERROR(E2/D2, 0) -> 0 | G2: =SUM(G4:G95) -> 0 | H2: =C2-G2 -> 0 | I2: =IFERROR(H2/G2, 0) -> 0 | J2: =IF(AND(TODAY()>DATE(2024, 7, 1), COUNTA(Sites[Site])<>(COUNT(C:C)-1)), "Some sites are missing actual data; if new sites were added, make sure they are aligned correctly (including prior months!)", "") -> Some sites are missing actual data; if new sites were added, make sure they are aligned correctly (including prior months!)
A3: Site | B3: State | C3: Actual | D3: Expected | E3: Delta | F3: % | G3: Forecasted | H3: Delta | I3: % | J3: Notes | K3: Service Requests
A4: {=Sites[Site]} -> Williamsburg A | B4: {=Sites[State]} -> MA | E4: =IF(AND(ISNUMBER(C4),ISNUMBER(D4)), C4-D4, "") | F4: =IFERROR(E4/D4, "") | H4: =IF(AND(ISNUMBER(C4),ISNUMBER(G4)), C4-G4, "") | I4: =IFERROR(H4/G4, "") | J4: 1.Site tripped offline from 7/7 at 07:45 and back online on 7/9 at 13:15. 2.Site tripped offline from 15:30 to 16:00 on 7/24. | K4: 1.SR087437 2.SR088137
A5: Orange A KB | B5: MA | E5: =IF(AND(ISNUMBER(C5),ISNUMBER(D5)), C5-D5, "") | F5: =IFERROR(E5/D5, "") | H5: =IF(AND(ISNUMBER(C5),ISNUMBER(G5)), C5-G5, "") | I5: =IFERROR(H5/G5, "")
A6: Goshen A | B6: MA | E6: =IF(AND(ISNUMBER(C6),ISNUMBER(D6)), C6-D6, "") | F6: =IFERROR(E6/D6, "") | H6: =IF(AND(ISNUMBER(C6),ISNUMBER(G6)), C6-G6, "") | I6: =IFERROR(H6/G6, "")
A7: Phillipston A KB | B7: MA | E7: =IF(AND(ISNUMBER(C7),ISNUMBER(D7)), C7-D7, "") | F7: =IFERROR(E7/D7, "") | H7: =IF(AND(ISNUMBER(C7),ISNUMBER(G7)), C7-G7, "") | I7: =IFERROR(H7/G7, "")
A8: Uxbridge D | B8: MA | E8: =IF(AND(ISNUMBER(C8),ISNUMBER(D8)), C8-D8, "") | F8: =IFERROR(E8/D8, "") | H8: =IF(AND(ISNUMBER(C8),ISNUMBER(G8)), C8-G8, "") | I8: =IFERROR(H8/G8, "")
A9: West Bridgewater A&B | B9: MA | E9: =IF(AND(ISNUMBER(C9),ISNUMBER(D9)), C9-D9, "") | F9: =IFERROR(E9/D9, "") | H9: =IF(AND(ISNUMBER(C9),ISNUMBER(G9)), C9-G9, "") | I9: =IFERROR(H9/G9, "")
A10: Sutton A | B10: MA | E10: =IF(AND(ISNUMBER(C10),ISNUMBER(D10)), C10-D10, "") | F10: =IFERROR(E10/D10, "") | H10: =IF(AND(ISNUMBER(C10),ISNUMBER(G10)), C10-G10, "") | I10: =IFERROR(H10/G10, "")
A11: North Adams A | B11: MA | E11: =IF(AND(ISNUMBER(C11),ISNUMBER(D11)), C11-D11, "") | F11: =IFERROR(E11/D11, "") | H11: =IF(AND(ISNUMBER(C11),ISNUMBER(G11)), C11-G11, "") | I11: =IFERROR(H11/G11, "")
A12: North Adams B | B12: MA | E12: =IF(AND(ISNUMBER(C12),ISNUMBER(D12)), C12-D12, "") | F12: =IFERROR(E12/D12, "") | H12: =IF(AND(ISNUMBER(C12),ISNUMBER(G12)), C12-G12, "") | I12: =IFERROR(H12/G12, "")
A13: Clarksburg A | B13: MA | E13: =IF(AND(ISNUMBER(C13),ISNUMBER(D13)), C13-D13, "") | F13: =IFERROR(E13/D13, "") | H13: =IF(AND(ISNUMBER(C13),ISNUMBER(G13)), C13-G13, "") | I13: =IFERROR(H13/G13, "")
A14: Swansea B | B14: MA | E14: =IF(AND(ISNUMBER(C14),ISNUMBER(D14)), C14-D14, "") | F14: =IFERROR(E14/D14, "") | H14: =IF(AND(ISNUMBER(C14),ISNUMBER(G14)), C14-G14, "") | I14: =IFERROR(H14/G14, "")
A15: Wareham 2 | B15: MA | E15: =IF(AND(ISNUMBER(C15),ISNUMBER(D15)), C15-D15, "") | F15: =IFERROR(E15/D15, "") | H15: =IF(AND(ISNUMBER(C15),ISNUMBER(G15)), C15-G15, "") | I15: =IFERROR(H15/G15, "")
A16: Kingston 1 KB | B16: MA | E16: =IF(AND(ISNUMBER(C16),ISNUMBER(D16)), C16-D16, "") | F16: =IFERROR(E16/D16, "") | H16: =IF(AND(ISNUMBER(C16),ISNUMBER(G16)), C16-G16, "") | I16: =IFERROR(H16/G16, "")
... A20: Plympton A-2 | B20: MA | E20: =IF(AND(ISNUMBER(C20),ISNUMBER(D20)), C20-D20, "") | F20: =IFERROR(E20/D20, "") | H20: =IF(AND(ISNUMBER(C20),ISNUMBER(G20)), C20-G20, "") | I20: =IFERROR(H20/G20, "")

Sheet Aug
A1: {=portfolio} -> MN8 KEF | D1: August Actual v. Expected | G1: August Actual v. Forecasted
A2: Total | C2: =SUM(C4:C95) -> 0 | D2: =SUM(D4:D95) -> 0 | E2: =C2-D2 -> 0 | F2: =IFERROR(E2/D2, 0) -> 0 | G2: =SUM(G4:G95) -> 0 | H2: =C2-G2 -> 0 | I2: =IFERROR(H2/G2, 0) -> 0 | J2: =IF(AND(TODAY()>DATE(2024, 8, 1), COUNTA(Sites[Site])<>(COUNT(C:C)-1)), "Some sites are missing actual data; if new sites were added, make sure they are aligned correctly (including prior months!)", "") -> Some sites are missing actual data; if new sites were added, make sure they are aligned correctly (including prior months!)
A3: Site | B3: State | C3: Actual | D3: Expected | E3: Delta | F3: % | G3: Forecasted | H3: Delta | I3: % | J3: Notes | K3: Service Requests
A4: {=Sites[Site]} -> Williamsburg A | B4: {=Sites[State]} -> MA | E4: =IF(AND(ISNUMBER(C4),ISNUMBER(D4)), C4-D4, "") | F4: =IFERROR(E4/D4, "") | H4: =IF(AND(ISNUMBER(C4),ISNUMBER(G4)), C4-G4, "") | I4: =IFERROR(H4/G4, "") | J4: 1.Site tripped offline on 08/08 at 18:45 and back online on 08/09 at 08:30 | K4: 1.SR088809
A5: Orange A KB | B5: MA | E5: =IF(AND(ISNUMBER(C5),ISNUMBER(D5)), C5-D5, "") | F5: =IFERROR(E5/D5, "") | H5: =IF(AND(ISNUMBER(C5),ISNUMBER(G5)), C5-G5, "") | I5: =IFERROR(H5/G5, "")
A6: Goshen A | B6: MA | E6: =IF(AND(ISNUMBER(C6),ISNUMBER(D6)), C6-D6, "") | F6: =IFERROR(E6/D6, "") | H6: =IF(AND(ISNUMBER(C6),ISNUMBER(G6)), C6-G6, "") | I6: =IFERROR(H6/G6, "")
A7: Phillipston A KB | B7: MA | E7: =IF(AND(ISNUMBER(C7),ISNUMBER(D7)), C7-D7, "") | F7: =IFERROR(E7/D7, "") | H7: =IF(AND(ISNUMBER(C7),ISNUMBER(G7)), C7-G7, "") | I7: =IFERROR(H7/G7, "")
A8: Uxbridge D | B8: MA | E8: =IF(AND(ISNUMBER(C8),ISNUMBER(D8)), C8-D8, "") | F8: =IFERROR(E8/D8, "") | H8: =IF(AND(ISNUMBER(C8),ISNUMBER(G8)), C8-G8, "") | I8: =IFERROR(H8/G8, "")
