Workbook
Name JanActual: #REF!
Name JanActual2: #REF!
Name JanExpected: #REF!
Name JanExpectedDelta: #REF!
Name JanExpectedPercent: #REF!
Name JanExpPercent: #REF!
Name JanForecasted: #REF!
Name JanForecastedDelta: #REF!
Name JanForecastedPercent: #REF!
Name portfolio: Sites!$B$1:$B$1
Name Year: Sites!#REF!

Sheet Year to Date
A1: {=portfolio} -> Cushman & Wakefield | D1: Year to Date Actual v. Expected | G1: Year to Date Actual v. Forecasted
A2: Total | C2: =SUM(C4:C100) -> 0 | D2: =SUM(D4:D100) -> 0 | E2: =C2-D2 -> 0 | F2: =IFERROR(E2/D2, 0) -> 0 | G2: =SUM(G4:G100) -> 0 | H2: =C2-G2 -> 0 | I2: =IFERROR(H2/G2, 0) -> 0
A3: Site | B3: State | C3: Actual | D3: Expected | E3: Delta | F3: % | G3: Forecasted | H3: Delta | I3: %
A4: {=Sites[Site]} -> Adelanto - Bank of America | B4: {=Sites[State]} -> CA | C4: =SUM('1st Qtr'!C4, '2nd Qtr'!C4, '3rd Qtr'!C4, '4th Qtr'!C4) -> 0 | D4: =SUM('1st Qtr'!D4, '2nd Qtr'!D4, '3rd Qtr'!D4, '4th Qtr'!D4) -> 0 | E4: =IF(AND(ISNUMBER(C4),ISNUMBER(D4)), C4-D4, "") -> 0 | F4: =IFERROR(E4/D4, "") | H4: =SUM('1st Qtr'!H4, '2nd Qtr'!H4, '3rd Qtr'!H4, '4th Qtr'!H4) -> 0 | I4: =IFERROR(H4/G4, "")
A5: Apple Valley - Bank of America | B5: CA | C5: =SUM(Jan!C5, Feb!C5, Mar!C5) -> 0 | D5: =SUM(Jan!D5, Feb!D5, Mar!D5) -> 0 | E5: =IF(AND(ISNUMBER(C5),ISNUMBER(D5)), C5-D5, "") -> 0 | F5: =IFERROR(E5/D5, "") | H5: =SUM(Jan!H5, Feb!H5, Mar!H5) -> 0 | I5: =IFERROR(H5/G5, "")
A6: Arvin - Bank of America | B6: CA | C6: =SUM(Jan!C6, Feb!C6, Mar!C6) -> 0 | D6: =SUM(Jan!D6, Feb!D6, Mar!D6) -> 0 | E6: =IF(AND(ISNUMBER(C6),ISNUMBER(D6)), C6-D6, "") -> 0 | F6: =IFERROR(E6/D6, "") | H6: =SUM(Jan!H6, Feb!H6, Mar!H6) -> 0 | I6: =IFERROR(H6/G6, "")
A7: Bell - Bank of America | B7: CA | C7: =SUM(Jan!C7, Feb!C7, Mar!C7) -> 0 | D7: =SUM(Jan!D7, Feb!D7, Mar!D7) -> 0 | E7: =IF(AND(ISNUMBER(C7),ISNUMBER(D7)), C7-D7, "") -> 0 | F7: =IFERROR(E7/D7, "") | H7: =SUM(Jan!H7, Feb!H7, Mar!H7) -> 0 | I7: =IFERROR(H7/G7, "")
A8: Chula Vista - Bank of America | B8: CA | C8: =SUM(Jan!C8, Feb!C8, Mar!C8) -> 0 | D8: =SUM(Jan!D8, Feb!D8, Mar!D8) -> 0 | E8: =IF(AND(ISNUMBER(C8),ISNUMBER(D8)), C8-D8, "") -> 0 | F8: =IFERROR(E8/D8, "") | H8: =SUM(Jan!H8, Feb!H8, Mar!H8) -> 0 | I8: =IFERROR(H8/G8, "")
A9: Cupertino - Bank of America | B9: CA | C9: =SUM(Jan!C9, Feb!C9, Mar!C9) -> 0 | D9: =SUM(Jan!D9, Feb!D9, Mar!D9) -> 0 | E9: =IF(AND(ISNUMBER(C9),ISNUMBER(D9)), C9-D9, "") -> 0 | F9: =IFERROR(E9/D9, "") | H9: =SUM(Jan!H9, Feb!H9, Mar!H9) -> 0 | I9: =IFERROR(H9/G9, "")
A10: Diamond Bar - Bank of America | B10: CA | C10: =SUM(Jan!C10, Feb!C10, Mar!C10) -> 0 | D10: =SUM(Jan!D10, Feb!D10, Mar!D10) -> 0 | E10: =IF(AND(ISNUMBER(C10),ISNUMBER(D10)), C10-D10, "") -> 0 | F10: =IFERROR(E10/D10, "") | H10: =SUM(Jan!H10, Feb!H10, Mar!H10) -> 0 | I10: =IFERROR(H10/G10, "")
A11: El Centro - Bank of America | B11: CA | C11: =SUM(Jan!C11, Feb!C11, Mar!C11) -> 0 | D11: =SUM(Jan!D11, Feb!D11, Mar!D11) -> 0 | E11: =IF(AND(ISNUMBER(C11),ISNUMBER(D11)), C11-D11, "") -> 0 | F11: =IFERROR(E11/D11, "") | H11: =SUM(Jan!H11, Feb!H11, Mar!H11) -> 0 | I11: =IFERROR(H11/G11, "")
A12: Moreno Valley - Bank of America | B12: CA | C12: =SUM(Jan!C12, Feb!C12, Mar!C12) -> 0 | D12: =SUM(Jan!D12, Feb!D12, Mar!D12) -> 0 | E12: =IF(AND(ISNUMBER(C12),ISNUMBER(D12)), C12-D12, "") -> 0 | F12: =IFERROR(E12/D12, "") | H12: =SUM(Jan!H12, Feb!H12, Mar!H12) -> 0 | I12: =IFERROR(H12/G12, "")
A13: Redlands - Bank of America | B13: CA | C13: =SUM(Jan!C13, Feb!C13, Mar!C13) -> 0 | D13: =SUM(Jan!D13, Feb!D13, Mar!D13) -> 0 | E13: =IF(AND(ISNUMBER(C13),ISNUMBER(D13)), C13-D13, "") -> 0 | F13: =IFERROR(E13/D13, "") | H13: =SUM(Jan!H13, Feb!H13, Mar!H13) -> 0 | I13: =IFERROR(H13/G13, "")
A14: Roseville - Bank of America | B14: CA | C14: =SUM(Jan!C14, Feb!C14, Mar!C14) -> 0 | D14: =SUM(Jan!D14, Feb!D14, Mar!D14) -> 0 | E14: =IF(AND(ISNUMBER(C14),ISNUMBER(D14)), C14-D14, "") -> 0 | F14: =IFERROR(E14/D14, "") | H14: =SUM(Jan!H14, Feb!H14, Mar!H14) -> 0 | I14: =IFERROR(H14/G14, "")
A15: San Bernardino - Bank of America | B15: CA | C15: =SUM(Jan!C15, Feb!C15, Mar!C15) -> 0 | D15: =SUM(Jan!D15, Feb!D15, Mar!D15) -> 0 | E15: =IF(AND(ISNUMBER(C15),ISNUMBER(D15)), C15-D15, "") -> 0 | F15: =IFERROR(E15/D15, "") | H15: =SUM(Jan!H15, Feb!H15, Mar!H15) -> 0 | I15: =IFERROR(H15/G15, "")
A16: San Diego - Bank of America | B16: CA | C16: =SUM(Jan!C16, Feb!C16, Mar!C16) -> 0 | D16: =SUM(Jan!D16, Feb!D16, Mar!D16) -> 0 | E16: =IF(AND(ISNUMBER(C16),ISNUMBER(D16)), C16-D16, "") -> 0 | F16: =IFERROR(E16/D16, "") | H16: =SUM(Jan!H16, Feb!H16, Mar!H16) -> 0 | I16: =IFERROR(H16/G16, "")
... A38: Salt Lake City - Bank of America | B38: UT | C38: =SUM(Jan!C38, Feb!C38, Mar!C38) -> 0 | D38: =SUM(Jan!D38, Feb!D38, Mar!D38) -> 0 | E38: =IF(AND(ISNUMBER(C38),ISNUMBER(D38)), C38-D38, "") -> 0 | F38: =IFERROR(E38/D38, "") | H38: =SUM(Jan!H38, Feb!H38, Mar!H38) -> 0 | I38: =IFERROR(H38/G38, "")

Sheet 1st Qtr
A1: {=portfolio} -> Cushman & Wakefield | D1: 1st Quarter Actual v. Expected | G1: 1st Quarter Actual v. Forecasted
A2: Total | C2: =SUM(C4:C100) -> 0 | D2: =SUM(D4:D100) -> 0 | E2: =C2-D2 -> 0 | F2: =IFERROR(E2/D2, 0) -> 0 | G2: =SUM(G4:G100) -> 0 | H2: =C2-G2 -> 0 | I2: =IFERROR(H2/G2, 0) -> 0
A3: Site | B3: State | C3: Actual | D3: Expected | E3: Delta | F3: % | G3: Forecasted | H3: Delta | I3: %
A4: {=Sites[Site]} -> Adelanto - Bank of America | B4: {=Sites[State]} -> CA | C4: =SUM(Jan!C4, Feb!C4, Mar!C4) -> 0 | D4: =SUM(Jan!D4, Feb!D4, Mar!D4) -> 0 | E4: =IF(AND(ISNUMBER(C4),ISNUMBER(D4)), C4-D4, "") -> 0 | F4: =IFERROR(E4/D4, "") | G4: =SUM(Jan!G4, Feb!G4, Mar!G4) -> 0 | H4: =SUM(Jan!H4, Feb!H4, Mar!H4) -> 0 | I4: =IFERROR(H4/G4, "")
A5: Apple Valley - Bank of America | B5: CA | C5: =SUM(Jan!C5, Feb!C5, Mar!C5) -> 0 | D5: =SUM(Jan!D5, Feb!D5, Mar!D5) -> 0 | E5: =IF(AND(ISNUMBER(C5),ISNUMBER(D5)), C5-D5, "") -> 0 | F5: =IFERROR(E5/D5, "") | G5: =SUM(Jan!G5, Feb!G5, Mar!G5) -> 0 | H5: =SUM(Jan!H5, Feb!H5, Mar!H5) -> 0 | I5: =IFERROR(H5/G5, "")
A6: Arvin - Bank of America | B6: CA | C6: =SUM(Jan!C6, Feb!C6, Mar!C6) -> 0 | D6: =SUM(Jan!D6, Feb!D6, Mar!D6) -> 0 | E6: =IF(AND(ISNUMBER(C6),ISNUMBER(D6)), C6-D6, "") -> 0 | F6: =IFERROR(E6/D6, "") | G6: =SUM(Jan!G6, Feb!G6, Mar!G6) -> 0 | H6: =SUM(Jan!H6, Feb!H6, Mar!H6) -> 0 | I6: =IFERROR(H6/G6, "")
A7: Bell - Bank of America | B7: CA | C7: =SUM(Jan!C7, Feb!C7, Mar!C7) -> 0 | D7: =SUM(Jan!D7, Feb!D7, Mar!D7) -> 0 | E7: =IF(AND(ISNUMBER(C7),ISNUMBER(D7)), C7-D7, "") -> 0 | F7: =IFERROR(E7/D7, "") | G7: =SUM(Jan!G7, Feb!G7, Mar!G7) -> 0 | H7: =SUM(Jan!H7, Feb!H7, Mar!H7) -> 0 | I7: =IFERROR(H7/G7, "")
A8: Chula Vista - Bank of America | B8: CA | C8: =SUM(Jan!C8, Feb!C8, Mar!C8) -> 0 | D8: =SUM(Jan!D8, Feb!D8, Mar!D8) -> 0 | E8: =IF(AND(ISNUMBER(C8),ISNUMBER(D8)), C8-D8, "") -> 0 | F8: =IFERROR(E8/D8, "") | G8: =SUM(Jan!G8, Feb!G8, Mar!G8) -> 0 | H8: =SUM(Jan!H8, Feb!H8, Mar!H8) -> 0 | I8: =IFERROR(H8/G8, "")
A9: Cupertino - Bank of America | B9: CA | C9: =SUM(Jan!C9, Feb!C9, Mar!C9) -> 0 | D9: =SUM(Jan!D9, Feb!D9, Mar!D9) -> 0 | E9: =IF(AND(ISNUMBER(C9),ISNUMBER(D9)), C9-D9, "") -> 0 | F9: =IFERROR(E9/D9, "") | G9: =SUM(Jan!G9, Feb!G9, Mar!G9) -> 0 | H9: =SUM(Jan!H9, Feb!H9, Mar!H9) -> 0 | I9: =IFERROR(H9/G9, "")
A10: Diamond Bar - Bank of America | B10: CA | C10: =SUM(Jan!C10, Feb!C10, Mar!C10) -> 0 | D10: =SUM(Jan!D10, Feb!D10, Mar!D10) -> 0 | E10: =IF(AND(ISNUMBER(C10),ISNUMBER(D10)), C10-D10, "") -> 0 | F10: =IFERROR(E10/D10, "") | G10: =SUM(Jan!G10, Feb!G10, Mar!G10) -> 0 | H10: =SUM(Jan!H10, Feb!H10, Mar!H10) -> 0 | I10: =IFERROR(H10/G10, "")
A11: El Centro - Bank of America | B11: CA | C11: =SUM(Jan!C11, Feb!C11, Mar!C11) -> 0 | D11: =SUM(Jan!D11, Feb!D11, Mar!D11) -> 0 | E11: =IF(AND(ISNUMBER(C11),ISNUMBER(D11)), C11-D11, "") -> 0 | F11: =IFERROR(E11/D11, "") | G11: =SUM(Jan!G11, Feb!G11, Mar!G11) -> 0 | H11: =SUM(Jan!H11, Feb!H11, Mar!H11) -> 0 | I11: =IFERROR(H11/G11, "")
A12: Moreno Valley - Bank of America | B12: CA | C12: =SUM(Jan!C12, Feb!C12, Mar!C12) -> 0 | D12: =SUM(Jan!D12, Feb!D12, Mar!D12) -> 0 | E12: =IF(AND(ISNUMBER(C12),ISNUMBER(D12)), C12-D12, "") -> 0 | F12: =IFERROR(E12/D12, "") | G12: =SUM(Jan!G12, Feb!G12, Mar!G12) -> 0 | H12: =SUM(Jan!H12, Feb!H12, Mar!H12) -> 0 | I12: =IFERROR(H12/G12, "")
A13: Redlands - Bank of America | B13: CA | C13: =SUM(Jan!C13, Feb!C13, Mar!C13) -> 0 | D13: =SUM(Jan!D13, Feb!D13, Mar!D13) -> 0 | E13: =IF(AND(ISNUMBER(C13),ISNUMBER(D13)), C13-D13, "") -> 0 | F13: =IFERROR(E13/D13, "") | G13: =SUM(Jan!G13, Feb!G13, Mar!G13) -> 0 | H13: =SUM(Jan!H13, Feb!H13, Mar!H13) -> 0 | I13: =IFERROR(H13/G13, "")
A14: Roseville - Bank of America | B14: CA | C14: =SUM(Jan!C14, Feb!C14, Mar!C14) -> 0 | D14: =SUM(Jan!D14, Feb!D14, Mar!D14) -> 0 | E14: =IF(AND(ISNUMBER(C14),ISNUMBER(D14)), C14-D14, "") -> 0 | F14: =IFERROR(E14/D14, "") | G14: =SUM(Jan!G14, Feb!G14, Mar!G14) -> 0 | H14: =SUM(Jan!H14, Feb!H14, Mar!H14) -> 0 | I14: =IFERROR(H14/G14, "")
A15: San Bernardino - Bank of America | B15: CA | C15: =SUM(Jan!C15, Feb!C15, Mar!C15) -> 0 | D15: =SUM(Jan!D15, Feb!D15, Mar!D15) -> 0 | E15: =IF(AND(ISNUMBER(C15),ISNUMBER(D15)), C15-D15, "") -> 0 | F15: =IFERROR(E15/D15, "") | G15: =SUM(Jan!G15, Feb!G15, Mar!G15) -> 0 | H15: =SUM(Jan!H15, Feb!H15, Mar!H15) -> 0 | I15: =IFERROR(H15/G15, "")
A16: San Diego - Bank of America | B16: CA | C16: =SUM(Jan!C16, Feb!C16, Mar!C16) -> 0 | D16: =SUM(Jan!D16, Feb!D16, Mar!D16) -> 0 | E16: =IF(AND(ISNUMBER(C16),ISNUMBER(D16)), C16-D16, "") -> 0 | F16: =IFERROR(E16/D16, "") | G16: =SUM(Jan!G16, Feb!G16, Mar!G16) -> 0 | H16: =SUM(Jan!H16, Feb!H16, Mar!H16) -> 0 | I16: =IFERROR(H16/G16, "")
... A38: Salt Lake City - Bank of America | B38: UT | C38: =SUM(Jan!C38, Feb!C38, Mar!C38) -> 0 | D38: =SUM(Jan!D38, Feb!D38, Mar!D38) -> 0 | E38: =IF(AND(ISNUMBER(C38),ISNUMBER(D38)), C38-D38, "") -> 0 | F38: =IFERROR(E38/D38, "") | G38: =SUM(Jan!G38, Feb!G38, Mar!G38) -> 0 | H38: =SUM(Jan!H38, Feb!H38, Mar!H38) -> 0 | I38: =IFERROR(H38/G38, "")

Sheet 2nd Qtr
A1: {=portfolio} -> Cushman & Wakefield | D1: 2nd Quarter Actual v. Expected | G1: 2nd Quarter Actual v. Forecasted
A2: Total | C2: =SUM(C4:C100) -> 156152.4 | D2: =SUM(D4:D100) -> 0 | E2: =C2-D2 -> 156152.4 | F2: =IFERROR(E2/D2, 0) -> 0 | G2: =SUM(G4:G100) -> 0 | H2: =C2-G2 -> 156152.4 | I2: =IFERROR(H2/G2, 0) -> 0
A3: Site | B3: State | C3: Actual | D3: Expected | E3: Delta | F3: % | G3: Forecasted | H3: Delta | I3: %
A4: {=Sites[Site]} -> Adelanto - Bank of America | B4: {=Sites[State]} -> CA | C4: =SUM(Apr!C4, May!C4, Jun!C4) -> 0 | D4: =SUM(Apr!D4, May!D4, Jun!D4) -> 0 | E4: =IF(AND(ISNUMBER(C4),ISNUMBER(D4)), C4-D4, "") -> 0 | F4: =IFERROR(E4/D4, "") | H4: =SUM(Apr!H4, May!H4, Jun!H4) -> 0 | I4: =IFERROR(H4/G4, "")
A5: Apple Valley - Bank of America | B5: CA | C5: =SUM(Apr!C5, May!C5, Jun!C5) -> 0 | D5: =SUM(Apr!D5, May!D5, Jun!D5) -> 0 | E5: =IF(AND(ISNUMBER(C5),ISNUMBER(D5)), C5-D5, "") -> 0 | F5: =IFERROR(E5/D5, "") | H5: =SUM(Apr!H5, May!H5, Jun!H5) -> 0 | I5: =IFERROR(H5/G5, "")
A6: Arvin - Bank of America | B6: CA | C6: =SUM(Apr!C6, May!C6, Jun!C6) -> 111.589 | D6: =SUM(Apr!D6, May!D6, Jun!D6) -> 0 | E6: =IF(AND(ISNUMBER(C6),ISNUMBER(D6)), C6-D6, "") -> 111.589 | F6: =IFERROR(E6/D6, "") | H6: =SUM(Apr!H6, May!H6, Jun!H6) -> 111.589 | I6: =IFERROR(H6/G6, "")
A7: Bell - Bank of America | B7: CA | C7: =SUM(Apr!C7, May!C7, Jun!C7) -> 3792.873 | D7: =SUM(Apr!D7, May!D7, Jun!D7) -> 0 | E7: =IF(AND(ISNUMBER(C7),ISNUMBER(D7)), C7-D7, "") -> 3792.873 | F7: =IFERROR(E7/D7, "") | H7: =SUM(Apr!H7, May!H7, Jun!H7) -> 3792.873 | I7: =IFERROR(H7/G7, "")
A8: Chula Vista - Bank of America | B8: CA | C8: =SUM(Apr!C8, May!C8, Jun!C8) -> 4240.63 | D8: =SUM(Apr!D8, May!D8, Jun!D8) -> 0 | E8: =IF(AND(ISNUMBER(C8),ISNUMBER(D8)), C8-D8, "") -> 4240.63 | F8: =IFERROR(E8/D8, "") | H8: =SUM(Apr!H8, May!H8, Jun!H8) -> 4240.63 | I8: =IFERROR(H8/G8, "")
A9: Cupertino - Bank of America | B9: CA | C9: =SUM(Apr!C9, May!C9, Jun!C9) -> 0 | D9: =SUM(Apr!D9, May!D9, Jun!D9) -> 0 | E9: =IF(AND(ISNUMBER(C9),ISNUMBER(D9)), C9-D9, "") -> 0 | F9: =IFERROR(E9/D9, "") | H9: =SUM(Apr!H9, May!H9, Jun!H9) -> 0 | I9: =IFERROR(H9/G9, "")
A10: Diamond Bar - Bank of America | B10: CA | C10: =SUM(Apr!C10, May!C10, Jun!C10) -> 9432.964 | D10: =SUM(Apr!D10, May!D10, Jun!D10) -> 0 | E10: =IF(AND(ISNUMBER(C10),ISNUMBER(D10)), C10-D10, "") -> 9432.964 | F10: =IFERROR(E10/D10, "") | H10: =SUM(Apr!H10, May!H10, Jun!H10) -> 9432.964 | I10: =IFERROR(H10/G10, "")
A11: El Centro - Bank of America | B11: CA | C11: =SUM(Apr!C11, May!C11, Jun!C11) -> 0 | D11: =SUM(Apr!D11, May!D11, Jun!D11) -> 0 | E11: =IF(AND(ISNUMBER(C11),ISNUMBER(D11)), C11-D11, "") -> 0 | F11: =IFERROR(E11/D11, "") | H11: =SUM(Apr!H11, May!H11, Jun!H11) -> 0 | I11: =IFERROR(H11/G11, "")
A12: Moreno Valley - Bank of America | B12: CA | C12: =SUM(Apr!C12, May!C12, Jun!C12) -> 14415.777 | D12: =SUM(Apr!D12, May!D12, Jun!D12) -> 0 | E12: =IF(AND(ISNUMBER(C12),ISNUMBER(D12)), C12-D12, "") -> 14415.777 | F12: =IFERROR(E12/D12, "") | H12: =SUM(Apr!H12, May!H12, Jun!H12) -> 14415.777 | I12: =IFERROR(H12/G12, "")
A13: Redlands - Bank of America | B13: CA | C13: =SUM(Apr!C13, May!C13, Jun!C13) -> 0 | D13: =SUM(Apr!D13, May!D13, Jun!D13) -> 0 | E13: =IF(AND(ISNUMBER(C13),ISNUMBER(D13)), C13-D13, "") -> 0 | F13: =IFERROR(E13/D13, "") | H13: =SUM(Apr!H13, May!H13, Jun!H13) -> 0 | I13: =IFERROR(H13/G13, "")
A14: Roseville - Bank of America | B14: CA | C14: =SUM(Apr!C14, May!C14, Jun!C14) -> 26572.962 | D14: =SUM(Apr!D14, May!D14, Jun!D14) -> 0 | E14: =IF(AND(ISNUMBER(C14),ISNUMBER(D14)), C14-D14, "") -> 26572.962 | F14: =IFERROR(E14/D14, "") | H14: =SUM(Apr!H14, May!H14, Jun!H14) -> 26572.962 | I14: =IFERROR(H14/G14, "")
A15: San Bernardino - Bank of America | B15: CA | C15: =SUM(Apr!C15, May!C15, Jun!C15) -> 345.647 | D15: =SUM(Apr!D15, May!D15, Jun!D15) -> 0 | E15: =IF(AND(ISNUMBER(C15),ISNUMBER(D15)), C15-D15, "") -> 345.647 | F15: =IFERROR(E15/D15, "") | H15: =SUM(Apr!H15, May!H15, Jun!H15) -> 345.647 | I15: =IFERROR(H15/G15, "")
A16: San Diego - Bank of America | B16: CA | C16: =SUM(Apr!C16, May!C16, Jun!C16) -> 387.905 | D16: =SUM(Apr!D16, May!D16, Jun!D16) -> 0 | E16: =IF(AND(ISNUMBER(C16),ISNUMBER(D16)), C16-D16, "") -> 387.905 | F16: =IFERROR(E16/D16, "") | H16: =SUM(Apr!H16, May!H16, Jun!H16) -> 387.905 | I16: =IFERROR(H16/G16, "")
... A38: Salt Lake City - Bank of America | B38: UT | C38: =SUM(Apr!C38, May!C38, Jun!C38) -> 1717.263 | D38: =SUM(Apr!D38, May!D38, Jun!D38) -> 0 | E38: =IF(AND(ISNUMBER(C38),ISNUMBER(D38)), C38-D38, "") -> 1717.263 | F38: =IFERROR(E38/D38, "") | H38: =SUM(Apr!H38, May!H38, Jun!H38) -> 1717.263 | I38: =IFERROR(H38/G38, "")

Sheet 3rd Qtr
A1: {=portfolio} -> Cushman & Wakefield | D1: 3rd Quarter Actual v. Expected | G1: 3rd Quarter Actual v. Forecasted
A2: Total | C2: =SUM(C4:C100) -> 0 | D2: =SUM(D4:D100) -> 0 | E2: =C2-D2 -> 0 | F2: =IFERROR(E2/D2, 0) -> 0 | G2: =SUM(G4:G100) -> 0 | H2: =C2-G2 -> 0 | I2: =IFERROR(H2/G2, 0) -> 0
A3: Site | B3: State | C3: Actual | D3: Expected | E3: Delta | F3: % | G3: Forecasted | H3: Delta | I3: %
A4: {=Sites[Site]} -> Adelanto - Bank of America | B4: {=Sites[State]} -> CA | C4: =SUM(Jul!C4, Aug!C4, Sep!C4) -> 0 | D4: =SUM(Jul!D4, Aug!D4, Sep!D4) -> 0 | E4: =IF(AND(ISNUMBER(C4),ISNUMBER(D4)), C4-D4, "") -> 0 | F4: =IFERROR(E4/D4, "") | H4: =SUM(Jul!H4, Aug!H4, Sep!H4) -> 0 | I4: =IFERROR(H4/G4, "")
A5: Apple Valley - Bank of America | B5: CA | C5: =SUM(Jul!C5, Aug!C5, Sep!C5) -> 0 | D5: =SUM(Jul!D5, Aug!D5, Sep!D5) -> 0 | E5: =IF(AND(ISNUMBER(C5),ISNUMBER(D5)), C5-D5, "") -> 0 | F5: =IFERROR(E5/D5, "") | H5: =SUM(Jul!H5, Aug!H5, Sep!H5) -> 0 | I5: =IFERROR(H5/G5, "")
A6: Arvin - Bank of America | B6: CA | C6: =SUM(Jul!C6, Aug!C6, Sep!C6) -> 0 | D6: =SUM(Jul!D6, Aug!D6, Sep!D6) -> 0 | E6: =IF(AND(ISNUMBER(C6),ISNUMBER(D6)), C6-D6, "") -> 0 | F6: =IFERROR(E6/D6, "") | H6: =SUM(Jul!H6, Aug!H6, Sep!H6) -> 0 | I6: =IFERROR(H6/G6, "")
A7: Bell - Bank of America | B7: CA | C7: =SUM(Jul!C7, Aug!C7, Sep!C7) -> 0 | D7: =SUM(Jul!D7, Aug!D7, Sep!D7) -> 0 | E7: =IF(AND(ISNUMBER(C7),ISNUMBER(D7)), C7-D7, "") -> 0 | F7: =IFERROR(E7/D7, "") | H7: =SUM(Jul!H7, Aug!H7, Sep!H7) -> 0 | I7: =IFERROR(H7/G7, "")
A8: Chula Vista - Bank of America | B8: CA | C8: =SUM(Jul!C8, Aug!C8, Sep!C8) -> 0 | D8: =SUM(Jul!D8, Aug!D8, Sep!D8) -> 0 | E8: =IF(AND(ISNUMBER(C8),ISNUMBER(D8)), C8-D8, "") -> 0 | F8: =IFERROR(E8/D8, "") | H8: =SUM(Jul!H8, Aug!H8, Sep!H8) -> 0 | I8: =IFERROR(H8/G8, "")
A9: Cupertino - Bank of America | B9: CA | C9: =SUM(Jul!C9, Aug!C9, Sep!C9) -> 0 | D9: =SUM(Jul!D9, Aug!D9, Sep!D9) -> 0 | E9: =IF(AND(ISNUMBER(C9),ISNUMBER(D9)), C9-D9, "") -> 0 | F9: =IFERROR(E9/D9, "") | H9: =SUM(Jul!H9, Aug!H9, Sep!H9) -> 0 | I9: =IFERROR(H9/G9, "")
A10: Diamond Bar - Bank of America | B10: CA | C10: =SUM(Jul!C10, Aug!C10, Sep!C10) -> 0 | D10: =SUM(Jul!D10, Aug!D10, Sep!D10) -> 0 | E10: =IF(AND(ISNUMBER(C10),ISNUMBER(D10)), C10-D10, "") -> 0 | F10: =IFERROR(E10/D10, "") | H10: =SUM(Jul!H10, Aug!H10, Sep!H10) -> 0 | I10: =IFERROR(H10/G10, "")
A11: El Centro - Bank of America | B11: CA | C11: =SUM(Jul!C11, Aug!C11, Sep!C11) -> 0 | D11: =SUM(Jul!D11, Aug!D11, Sep!D11) -> 0 | E11: =IF(AND(ISNUMBER(C11),ISNUMBER(D11)), C11-D11, "") -> 0 | F11: =IFERROR(E11/D11, "") | H11: =SUM(Jul!H11, Aug!H11, Sep!H11) -> 0 | I11: =IFERROR(H11/G11, "")
A12: Moreno Valley - Bank of America | B12: CA | C12: =SUM(Jul!C12, Aug!C12, Sep!C12) -> 0 | D12: =SUM(Jul!D12, Aug!D12, Sep!D12) -> 0 | E12: =IF(AND(ISNUMBER(C12),ISNUMBER(D12)), C12-D12, "") -> 0 | F12: =IFERROR(E12/D12, "") | H12: =SUM(Jul!H12, Aug!H12, Sep!H12) -> 0 | I12: =IFERROR(H12/G12, "")
A13: Redlands - Bank of America | B13: CA | C13: =SUM(Jul!C13, Aug!C13, Sep!C13) -> 0 | D13: =SUM(Jul!D13, Aug!D13, Sep!D13) -> 0 | E13: =IF(AND(ISNUMBER(C13),ISNUMBER(D13)), C13-D13, "") -> 0 | F13: =IFERROR(E13/D13, "") | H13: =SUM(Jul!H13, Aug!H13, Sep!H13) -> 0 | I13: =IFERROR(H13/G13, "")
A14: Roseville - Bank of America | B14: CA | C14: =SUM(Jul!C14, Aug!C14, Sep!C14) -> 0 | D14: =SUM(Jul!D14, Aug!D14, Sep!D14) -> 0 | E14: =IF(AND(ISNUMBER(C14),ISNUMBER(D14)), C14-D14, "") -> 0 | F14: =IFERROR(E14/D14, "") | H14: =SUM(Jul!H14, Aug!H14, Sep!H14) -> 0 | I14: =IFERROR(H14/G14, "")
A15: San Bernardino - Bank of America | B15: CA | C15: =SUM(Jul!C15, Aug!C15, Sep!C15) -> 0 | D15: =SUM(Jul!D15, Aug!D15, Sep!D15) -> 0 | E15: =IF(AND(ISNUMBER(C15),ISNUMBER(D15)), C15-D15, "") -> 0 | F15: =IFERROR(E15/D15, "") | H15: =SUM(Jul!H15, Aug!H15, Sep!H15) -> 0 | I15: =IFERROR(H15/G15, "")
A16: San Diego - Bank of America | B16: CA | C16: =SUM(Jul!C16, Aug!C16, Sep!C16) -> 0 | D16: =SUM(Jul!D16, Aug!D16, Sep!D16) -> 0 | E16: =IF(AND(ISNUMBER(C16),ISNUMBER(D16)), C16-D16, "") -> 0 | F16: =IFERROR(E16/D16, "") | H16: =SUM(Jul!H16, Aug!H16, Sep!H16) -> 0 | I16: =IFERROR(H16/G16, "")
... A38: Salt Lake City - Bank of America | B38: UT | C38: =SUM(Jul!C38, Aug!C38, Sep!C38) -> 0 | D38: =SUM(Jul!D38, Aug!D38, Sep!D38) -> 0 | E38: =IF(AND(ISNUMBER(C38),ISNUMBER(D38)), C38-D38, "") -> 0 | F38: =IFERROR(E38/D38, "") | H38: =SUM(Jul!H38, Aug!H38, Sep!H38) -> 0 | I38: =IFERROR(H38/G38, "")

Sheet 4th Qtr
A1: {=portfolio} -> Cushman & Wakefield | D1: 4th Quarter Actual v. Expected | G1: 4th Quarter Actual v. Forecasted
A2: Total | C2: =SUM(C4:C100) -> 0 | D2: =SUM(D4:D100) -> 0 | E2: =C2-D2 -> 0 | F2: =IFERROR(E2/D2, 0) -> 0 | G2: =SUM(G4:G100) -> 0 | H2: =C2-G2 -> 0 | I2: =IFERROR(H2/G2, 0) -> 0
A3: Site | B3: State | C3: Actual | D3: Expected | E3: Delta | F3: % | G3: Forecasted | H3: Delta | I3: %
A4: {=Sites[Site]} -> Adelanto - Bank of America | B4: {=Sites[State]} -> CA | C4: =SUM(Oct!C4, Nov!C4, Dec!C4) -> 0 | D4: =SUM(Oct!D4, Nov!D4, Dec!D4) -> 0 | E4: =IF(AND(ISNUMBER(C4),ISNUMBER(D4)), C4-D4, "") -> 0 | F4: =IFERROR(E4/D4, "") | H4: =SUM(Oct!H4, Nov!H4, Dec!H4) -> 0 | I4: =IFERROR(H4/G4, "")
A5: Apple Valley - Bank of America | B5: CA | C5: =SUM(Oct!C5, Nov!C5, Dec!C5) -> 0 | D5: =SUM(Oct!D5, Nov!D5, Dec!D5) -> 0 | E5: =IF(AND(ISNUMBER(C5),ISNUMBER(D5)), C5-D5, "") -> 0 | F5: =IFERROR(E5/D5, "") | H5: =SUM(Oct!H5, Nov!H5, Dec!H5) -> 0 | I5: =IFERROR(H5/G5, "")
A6: Arvin - Bank of America | B6: CA | C6: =SUM(Oct!C6, Nov!C6, Dec!C6) -> 0 | D6: =SUM(Oct!D6, Nov!D6, Dec!D6) -> 0 | E6: =IF(AND(ISNUMBER(C6),ISNUMBER(D6)), C6-D6, "") -> 0 | F6: =IFERROR(E6/D6, "") | H6: =SUM(Oct!H6, Nov!H6, Dec!H6) -> 0 | I6: =IFERROR(H6/G6, "")
A7: Bell - Bank of America | B7: CA | C7: =SUM(Oct!C7, Nov!C7, Dec!C7) -> 0 | D7: =SUM(Oct!D7, Nov!D7, Dec!D7) -> 0 | E7: =IF(AND(ISNUMBER(C7),ISNUMBER(D7)), C7-D7, "") -> 0 | F7: =IFERROR(E7/D7, "") | H7: =SUM(Oct!H7, Nov!H7, Dec!H7) -> 0 | I7: =IFERROR(H7/G7, "")
A8: Chula Vista - Bank of America | B8: CA | C8: =SUM(Oct!C8, Nov!C8, Dec!C8) -> 0 | D8: =SUM(Oct!D8, Nov!D8, Dec!D8) -> 0 | E8: =IF(AND(ISNUMBER(C8),ISNUMBER(D8)), C8-D8, "") -> 0 | F8: =IFERROR(E8/D8, "") | H8: =SUM(Oct!H8, Nov!H8, Dec!H8) -> 0 | I8: =IFERROR(H8/G8, "")
A9: Cupertino - Bank of America | B9: CA | C9: =SUM(Oct!C9, Nov!C9, Dec!C9) -> 0 | D9: =SUM(Oct!D9, Nov!D9, Dec!D9) -> 0 | E9: =IF(AND(ISNUMBER(C9),ISNUMBER(D9)), C9-D9, "") -> 0 | F9: =IFERROR(E9/D9, "") | H9: =SUM(Oct!H9, Nov!H9, Dec!H9) -> 0 | I9: =IFERROR(H9/G9, "")
A10: Diamond Bar - Bank of America | B10: CA | C10: =SUM(Oct!C10, Nov!C10, Dec!C10) -> 0 | D10: =SUM(Oct!D10, Nov!D10, Dec!D10) -> 0 | E10: =IF(AND(ISNUMBER(C10),ISNUMBER(D10)), C10-D10, "") -> 0 | F10: =IFERROR(E10/D10, "") | H10: =SUM(Oct!H10, Nov!H10, Dec!H10) -> 0 | I10: =IFERROR(H10/G10, "")
A11: El Centro - Bank of America | B11: CA | C11: =SUM(Oct!C11, Nov!C11, Dec!C11) -> 0 | D11: =SUM(Oct!D11, Nov!D11, Dec!D11) -> 0 | E11: =IF(AND(ISNUMBER(C11),ISNUMBER(D11)), C11-D11, "") -> 0 | F11: =IFERROR(E11/D11, "") | H11: =SUM(Oct!H11, Nov!H11, Dec!H11) -> 0 | I11: =IFERROR(H11/G11, "")
A12: Moreno Valley - Bank of America | B12: CA | C12: =SUM(Oct!C12, Nov!C12, Dec!C12) -> 0 | D12: =SUM(Oct!D12, Nov!D12, Dec!D12) -> 0 | E12: =IF(AND(ISNUMBER(C12),ISNUMBER(D12)), C12-D12, "") -> 0 | F12: =IFERROR(E12/D12, "") | H12: =SUM(Oct!H12, Nov!H12, Dec!H12) -> 0 | I12: =IFERROR(H12/G12, "")
A13: Redlands - Bank of America | B13: CA | C13: =SUM(Oct!C13, Nov!C13, Dec!C13) -> 0 | D13: =SUM(Oct!D13, Nov!D13, Dec!D13) -> 0 | E13: =IF(AND(ISNUMBER(C13),ISNUMBER(D13)), C13-D13, "") -> 0 | F13: =IFERROR(E13/D13, "") | H13: =SUM(Oct!H13, Nov!H13, Dec!H13) -> 0 | I13: =IFERROR(H13/G13, "")
A14: Roseville - Bank of America | B14: CA | C14: =SUM(Oct!C14, Nov!C14, Dec!C14) -> 0 | D14: =SUM(Oct!D14, Nov!D14, Dec!D14) -> 0 | E14: =IF(AND(ISNUMBER(C14),ISNUMBER(D14)), C14-D14, "") -> 0 | F14: =IFERROR(E14/D14, "") | H14: =SUM(Oct!H14, Nov!H14, Dec!H14) -> 0 | I14: =IFERROR(H14/G14, "")
A15: San Bernardino - Bank of America | B15: CA | C15: =SUM(Oct!C15, Nov!C15, Dec!C15) -> 0 | D15: =SUM(Oct!D15, Nov!D15, Dec!D15) -> 0 | E15: =IF(AND(ISNUMBER(C15),ISNUMBER(D15)), C15-D15, "") -> 0 | F15: =IFERROR(E15/D15, "") | H15: =SUM(Oct!H15, Nov!H15, Dec!H15) -> 0 | I15: =IFERROR(H15/G15, "")
A16: San Diego - Bank of America | B16: CA | C16: =SUM(Oct!C16, Nov!C16, Dec!C16) -> 0 | D16: =SUM(Oct!D16, Nov!D16, Dec!D16) -> 0 | E16: =IF(AND(ISNUMBER(C16),ISNUMBER(D16)), C16-D16, "") -> 0 | F16: =IFERROR(E16/D16, "") | H16: =SUM(Oct!H16, Nov!H16, Dec!H16) -> 0 | I16: =IFERROR(H16/G16, "")
... A38: Salt Lake City - Bank of America | B38: UT | C38: =SUM(Oct!C38, Nov!C38, Dec!C38) -> 0 | D38: =SUM(Oct!D38, Nov!D38, Dec!D38) -> 0 | E38: =IF(AND(ISNUMBER(C38),ISNUMBER(D38)), C38-D38, "") -> 0 | F38: =IFERROR(E38/D38, "") | H38: =SUM(Oct!H38, Nov!H38, Dec!H38) -> 0 | I38: =IFERROR(H38/G38, "")

Sheet Jan
A1: {=portfolio} -> Cushman & Wakefield | D1: January Actual v. Expected | G1: January Actual v. Forecasted
A2: Total | C2: =SUM(C4:C99) -> 0 | D2: =SUM(D4:D99) -> 0 | E2: =C2-D2 -> 0 | F2: =IFERROR(E2/D2, 0) -> 0 | G2: =SUM(G4:G99) -> 0 | H2: =C2-G2 -> 0 | I2: =IFERROR(H2/G2, 0) -> 0 | J2: =IF(AND(TODAY()>DATE(2024, 1, 1), COUNTA(Sites[Site])<>(COUNT(C:C)-1)), "Some sites are missing actual data; if new sites were added, make sure they are aligned correctly (including prior months!)", "") -> Some sites are missing actual data; if new sites were added, make sure they are aligned correctly (including prior months!)
A3: Site | B3: State | C3: Actual | D3: Expected | E3: Delta | F3: % | G3: Forecasted | H3: Delta | I3: % | J3: Notes | K3: Service Requests
A4: {=Sites[Site]} -> Adelanto - Bank of America | B4: {=Sites[State]} -> CA | E4: =IF(AND(ISNUMBER(C4),ISNUMBER(D4)), C4-D4, "") | F4: =IFERROR(E4/D4, "") | H4: =IF(AND(ISNUMBER(C4),ISNUMBER(G4)), C4-G4, "") | I4: =IFERROR(H4/G4, "")
A5: Apple Valley - Bank of America | B5: CA | E5: =IF(AND(ISNUMBER(C5),ISNUMBER(D5)), C5-D5, "") | F5: =IFERROR(E5/D5, "") | H5: =IF(AND(ISNUMBER(C5),ISNUMBER(G5)), C5-G5, "") | I5: =IFERROR(H5/G5, "")
A6: Arvin - Bank of America | B6: CA | E6: =IF(AND(ISNUMBER(C6),ISNUMBER(D6)), C6-D6, "") | F6: =IFERROR(E6/D6, "") | H6: =IF(AND(ISNUMBER(C6),ISNUMBER(G6)), C6-G6, "") | I6: =IFERROR(H6/G6, "")
A7: Bell - Bank of America | B7: CA | E7: =IF(AND(ISNUMBER(C7),ISNUMBER(D7)), C7-D7, "") | F7: =IFERROR(E7/D7, "") | H7: =IF(AND(ISNUMBER(C7),ISNUMBER(G7)), C7-G7, "") | I7: =IFERROR(H7/G7, "")
A8: Chula Vista - Bank of America | B8: CA | E8: =IF(AND(ISNUMBER(C8),ISNUMBER(D8)), C8-D8, "") | F8: =IFERROR(E8/D8, "") | H8: =IF(AND(ISNUMBER(C8),ISNUMBER(G8)), C8-G8, "") | I8: =IFERROR(H8/G8, "")
A9: Cupertino - Bank of America | B9: CA | E9: =IF(AND(ISNUMBER(C9),ISNUMBER(D9)), C9-D9, "") | F9: =IFERROR(E9/D9, "") | H9: =IF(AND(ISNUMBER(C9),ISNUMBER(G9)), C9-G9, "") | I9: =IFERROR(H9/G9, "")
A10: Diamond Bar - Bank of America | B10: CA | E10: =IF(AND(ISNUMBER(C10),ISNUMBER(D10)), C10-D10, "") | F10: =IFERROR(E10/D10, "") | H10: =IF(AND(ISNUMBER(C10),ISNUMBER(G10)), C10-G10, "") | I10: =IFERROR(H10/G10, "")
A11: El Centro - Bank of America | B11: CA | E11: =IF(AND(ISNUMBER(C11),ISNUMBER(D11)), C11-D11, "") | F11: =IFERROR(E11/D11, "") | H11: =IF(AND(ISNUMBER(C11),ISNUMBER(G11)), C11-G11, "") | I11: =IFERROR(H11/G11, "")
A12: Moreno Valley - Bank of America | B12: CA | E12: =IF(AND(ISNUMBER(C12),ISNUMBER(D12)), C12-D12, "") | F12: =IFERROR(E12/D12, "") | H12: =IF(AND(ISNUMBER(C12),ISNUMBER(G12)), C12-G12, "") | I12: =IFERROR(H12/G12, "")
A13: Redlands - Bank of America | B13: CA | E13: =IF(AND(ISNUMBER(C13),ISNUMBER(D13)), C13-D13, "") | F13: =IFERROR(E13/D13, "") | H13: =IF(AND(ISNUMBER(C13),ISNUMBER(G13)), C13-G13, "") | I13: =IFERROR(H13/G13, "")
A14: Roseville - Bank of America | B14: CA | E14: =IF(AND(ISNUMBER(C14),ISNUMBER(D14)), C14-D14, "") | F14: =IFERROR(E14/D14, "") | H14: =IF(AND(ISNUMBER(C14),ISNUMBER(G14)), C14-G14, "") | I14: =IFERROR(H14/G14, "")
A15: San Bernardino - Bank of America | B15: CA | E15: =IF(AND(ISNUMBER(C15),ISNUMBER(D15)), C15-D15, "") | F15: =IFERROR(E15/D15, "") | H15: =IF(AND(ISNUMBER(C15),ISNUMBER(G15)), C15-G15, "") | I15: =IFERROR(H15/G15, "")
A16: San Diego - Bank of America | B16: CA | E16: =IF(AND(ISNUMBER(C16),ISNUMBER(D16)), C16-D16, "") | F16: =IFERROR(E16/D16, "") | H16: =IF(AND(ISNUMBER(C16),ISNUMBER(G16)), C16-G16, "") | I16: =IFERROR(H16/G16, "")
... A38: Salt Lake City - Bank of America | B38: UT | E38: =IF(AND(ISNUMBER(C38),ISNUMBER(D38)), C38-D38, "") | F38: =IFERROR(E38/D38, "") | H38: =IF(AND(ISNUMBER(C38),ISNUMBER(G38)), C38-G38, "") | I38: =IFERROR(H38/G38, "")

Sheet Feb
A1: {=portfolio} -> Cushman & Wakefield | D1: February Actual v. Expected | G1: February Actual v. Forecasted
A2: Total | C2: =SUM(C4:C100) -> 0 | D2: =SUM(D4:D100) -> 0 | E2: =C2-D2 -> 0 | F2: =IFERROR(E2/D2, 0) -> 0 | G2: =SUM(G4:G100) -> 0 | H2: =C2-G2 -> 0 | I2: =IFERROR(H2/G2, 0) -> 0 | J2: =IF(AND(TODAY()>DATE(2024, 2, 1), COUNTA(Sites[Site])<>(COUNT(C:C)-1)), "Some sites are missing actual data; if new sites were added, make sure they are aligned correctly (including prior months!)", "") -> Some sites are missing actual data; if new sites were added, make sure they are aligned correctly (including prior months!)
A3: Site | B3: State | C3: Actual | D3: Expected | E3: Delta | F3: % | G3: Forecasted | H3: Delta | I3: % | J3: Notes | K3: Service Requests
A4: {=Sites[Site]} -> Adelanto - Bank of America | B4: {=Sites[State]} -> CA | E4: =IF(AND(ISNUMBER(C4),ISNUMBER(D4)), C4-D4, "") | F4: =IFERROR(E4/D4, "") | H4: =IF(AND(ISNUMBER(C4),ISNUMBER(G4)), C4-G4, "") | I4: =IFERROR(H4/G4, "")
A5: Apple Valley - Bank of America | B5: CA | E5: =IF(AND(ISNUMBER(C5),ISNUMBER(D5)), C5-D5, "") | F5: =IFERROR(E5/D5, "") | H5: =IF(AND(ISNUMBER(C5),ISNUMBER(G5)), C5-G5, "") | I5: =IFERROR(H5/G5, "")
A6: Arvin - Bank of America | B6: CA | E6: =IF(AND(ISNUMBER(C6),ISNUMBER(D6)), C6-D6, "") | F6: =IFERROR(E6/D6, "") | H6: =IF(AND(ISNUMBER(C6),ISNUMBER(G6)), C6-G6, "") | I6: =IFERROR(H6/G6, "")
A7: Bell - Bank of America | B7: CA | E7: =IF(AND(ISNUMBER(C7),ISNUMBER(D7)), C7-D7, "") | F7: =IFERROR(E7/D7, "") | H7: =IF(AND(ISNUMBER(C7),ISNUMBER(G7)), C7-G7, "") | I7: =IFERROR(H7/G7, "")
A8: Chula Vista - Bank of America | B8: CA | E8: =IF(AND(ISNUMBER(C8),ISNUMBER(D8)), C8-D8, "") | F8: =IFERROR(E8/D8, "") | H8: =IF(AND(ISNUMBER(C8),ISNUMBER(G8)), C8-G8, "") | I8: =IFERROR(H8/G8, "")
A9: Cupertino - Bank of America | B9: CA | E9: =IF(AND(ISNUMBER(C9),ISNUMBER(D9)), C9-D9, "") | F9: =IFERROR(E9/D9, "") | H9: =IF(AND(ISNUMBER(C9),ISNUMBER(G9)), C9-G9, "") | I9: =IFERROR(H9/G9, "")
A10: Diamond Bar - Bank of America | B10: CA | E10: =IF(AND(ISNUMBER(C10),ISNUMBER(D10)), C10-D10, "") | F10: =IFERROR(E10/D10, "") | H10: =IF(AND(ISNUMBER(C10),ISNUMBER(G10)), C10-G10, "") | I10: =IFERROR(H10/G10, "")
A11: El Centro - Bank of America | B11: CA | E11: =IF(AND(ISNUMBER(C11),ISNUMBER(D11)), C11-D11, "") | F11: =IFERROR(E11/D11, "") | H11: =IF(AND(ISNUMBER(C11),ISNUMBER(G11)), C11-G11, "") | I11: =IFERROR(H11/G11, "")
A12: Moreno Valley - Bank of America | B12: CA | E12: =IF(AND(ISNUMBER(C12),ISNUMBER(D12)), C12-D12, "") | F12: =IFERROR(E12/D12, "") | H12: =IF(AND(ISNUMBER(C12),ISNUMBER(G12)), C12-G12, "") | I12: =IFERROR(H12/G12, "")
A13: Redlands - Bank of America | B13: CA | E13: =IF(AND(ISNUMBER(C13),ISNUMBER(D13)), C13-D13, "") | F13: =IFERROR(E13/D13, "") | H13: =IF(AND(ISNUMBER(C13),ISNUMBER(G13)), C13-G13, "") | I13: =IFERROR(H13/G13, "")
A14: Roseville - Bank of America | B14: CA | E14: =IF(AND(ISNUMBER(C14),ISNUMBER(D14)), C14-D14, "") | F14: =IFERROR(E14/D14, "") | H14: =IF(AND(ISNUMBER(C14),ISNUMBER(G14)), C14-G14, "") | I14: =IFERROR(H14/G14, "")
A15: San Bernardino - Bank of America | B15: CA | E15: =IF(AND(ISNUMBER(C15),ISNUMBER(D15)), C15-D15, "") | F15: =IFERROR(E15/D15, "") | H15: =IF(AND(ISNUMBER(C15),ISNUMBER(G15)), C15-G15, "") | I15: =IFERROR(H15/G15, "")
A16: San Diego - Bank of America | B16: CA | E16: =IF(AND(ISNUMBER(C16),ISNUMBER(D16)), C16-D16, "") | F16: =IFERROR(E16/D16, "") | H16: =IF(AND(ISNUMBER(C16),ISNUMBER(G16)), C16-G16, "") | I16: =IFERROR(H16/G16, "")
... A38: Salt Lake City - Bank of America | B38: UT | E38: =IF(AND(ISNUMBER(C38),ISNUMBER(D38)), C38-D38, "") | F38: =IFERROR(E38/D38, "") | H38: =IF(AND(ISNUMBER(C38),ISNUMBER(G38)), C38-G38, "") | I38: =IFERROR(H38/G38, "")

Sheet Mar
A1: {=portfolio} -> Cushman & Wakefield | D1: March Actual v. Expected | G1: March Actual v. Forecasted
A2: Total | C2: =SUM(C4:C100) -> 0 | D2: =SUM(D4:D100) -> 0 | E2: =C2-D2 -> 0 | F2: =IFERROR(E2/D2, 0) -> 0 | G2: =SUM(G4:G100) -> 0 | H2: =C2-G2 -> 0 | I2: =IFERROR(H2/G2, 0) -> 0 | J2: =IF(AND(TODAY()>DATE(2024, 3, 1), COUNTA(Sites[Site])<>(COUNT(C:C)-1)), "Some sites are missing actual data; if new sites were added, make sure they are aligned correctly (including prior months!)", "") -> Some sites are missing actual data; if new sites were added, make sure they are aligned correctly (including prior months!)
A3: Site | B3: State | C3: Actual | D3: Expected | E3: Delta | F3: % | G3: Forecasted | H3: Delta | I3: % | J3: Notes | K3: Service Requests
A4: {=Sites[Site]} -> Adelanto - Bank of America | B4: {=Sites[State]} -> CA | E4: =IF(AND(ISNUMBER(C4),ISNUMBER(D4)), C4-D4, "") | F4: =IFERROR(E4/D4, "") | H4: =IF(AND(ISNUMBER(C4),ISNUMBER(G4)), C4-G4, "") | I4: =IFERROR(H4/G4, "")
A5: Apple Valley - Bank of America | B5: CA | E5: =IF(AND(ISNUMBER(C5),ISNUMBER(D5)), C5-D5, "") | F5: =IFERROR(E5/D5, "") | H5: =IF(AND(ISNUMBER(C5),ISNUMBER(G5)), C5-G5, "") | I5: =IFERROR(H5/G5, "")
A6: Arvin - Bank of America | B6: CA | E6: =IF(AND(ISNUMBER(C6),ISNUMBER(D6)), C6-D6, "") | F6: =IFERROR(E6/D6, "") | H6: =IF(AND(ISNUMBER(C6),ISNUMBER(G6)), C6-G6, "") | I6: =IFERROR(H6/G6, "")
A7: Bell - Bank of America | B7: CA | E7: =IF(AND(ISNUMBER(C7),ISNUMBER(D7)), C7-D7, "") | F7: =IFERROR(E7/D7, "") | H7: =IF(AND(ISNUMBER(C7),ISNUMBER(G7)), C7-G7, "") | I7: =IFERROR(H7/G7, "")
A8: Chula Vista - Bank of America | B8: CA | E8: =IF(AND(ISNUMBER(C8),ISNUMBER(D8)), C8-D8, "") | F8: =IFERROR(E8/D8, "") | H8: =IF(AND(ISNUMBER(C8),ISNUMBER(G8)), C8-G8, "") | I8: =IFERROR(H8/G8, "")
A9: Cupertino - Bank of America | B9: CA | E9: =IF(AND(ISNUMBER(C9),ISNUMBER(D9)), C9-D9, "") | F9: =IFERROR(E9/D9, "") | H9: =IF(AND(ISNUMBER(C9),ISNUMBER(G9)), C9-G9, "") | I9: =IFERROR(H9/G9, "")
A10: Diamond Bar - Bank of America | B10: CA | E10: =IF(AND(ISNUMBER(C10),ISNUMBER(D10)), C10-D10, "") | F10: =IFERROR(E10/D10, "") | H10: =IF(AND(ISNUMBER(C10),ISNUMBER(G10)), C10-G10, "") | I10: =IFERROR(H10/G10, "")
A11: El Centro - Bank of America | B11: CA | E11: =IF(AND(ISNUMBER(C11),ISNUMBER(D11)), C11-D11, "") | F11: =IFERROR(E11/D11, "") | H11: =IF(AND(ISNUMBER(C11),ISNUMBER(G11)), C11-G11, "") | I11: =IFERROR(H11/G11, "")
A12: Moreno Valley - Bank of America | B12: CA | E12: =IF(AND(ISNUMBER(C12),ISNUMBER(D12)), C12-D12, "") | F12: =IFERROR(E12/D12, "") | H12: =IF(AND(ISNUMBER(C12),ISNUMBER(G12)), C12-G12, "") | I12: =IFERROR(H12/G12, "")
A13: Redlands - Bank of America | B13: CA | E13: =IF(AND(ISNUMBER(C13),ISNUMBER(D13)), C13-D13, "") | F13: =IFERROR(E13/D13, "") | H13: =IF(AND(ISNUMBER(C13),ISNUMBER(G13)), C13-G13, "") | I13: =IFERROR(H13/G13, "")
A14: Roseville - Bank of America | B14: CA | E14: =IF(AND(ISNUMBER(C14),ISNUMBER(D14)), C14-D14, "") | F14: =IFERROR(E14/D14, "") | H14: =IF(AND(ISNUMBER(C14),ISNUMBER(G14)), C14-G14, "") | I14: =IFERROR(H14/G14, "")
A15: San Bernardino - Bank of America | B15: CA | E15: =IF(AND(ISNUMBER(C15),ISNUMBER(D15)), C15-D15, "") | F15: =IFERROR(E15/D15, "") | H15: =IF(AND(ISNUMBER(C15),ISNUMBER(G15)), C15-G15, "") | I15: =IFERROR(H15/G15, "")
A16: San Diego - Bank of America | B16: CA | E16: =IF(AND(ISNUMBER(C16),ISNUMBER(D16)), C16-D16, "") | F16: =IFERROR(E16/D16, "") | H16: =IF(AND(ISNUMBER(C16),ISNUMBER(G16)), C16-G16, "") | I16: =IFERROR(H16/G16, "")
... A38: Salt Lake City - Bank of America | B38: UT | E38: =IF(AND(ISNUMBER(C38),ISNUMBER(D38)), C38-D38, "") | F38: =IFERROR(E38/D38, "") | H38: =IF(AND(ISNUMBER(C38),ISNUMBER(G38)), C38-G38, "") | I38: =IFERROR(H38/G38, "")

Sheet Apr
A1: {=portfolio} -> Cushman & Wakefield | D1: April Actual v. Expected | G1: April Actual v. Forecasted
A2: Total | C2: =SUM(C4:C98) -> 46739.67 | D2: =SUM(D4:D98) -> 0 | E2: =C2-D2 -> 46739.67 | F2: =IFERROR(E2/D2, 0) -> 0 | G2: =SUM(G4:G98) -> 0 | H2: =C2-G2 -> 46739.67 | I2: =IFERROR(H2/G2, 0) -> 0 | J2: =IF(AND(TODAY()>DATE(2024, 4, 1), COUNTA(Sites[Site])<>(COUNT(C:C)-1)), "Some sites are missing actual data; if new sites were added, make sure they are aligned correctly (including prior months!)", "")
A3: Site | B3: State | C3: Actual | D3: Expected | E3: Delta | F3: % | G3: Forecasted | H3: Delta | I3: % | J3: Notes | K3: Service Requests
A4: {=Sites[Site]} -> Adelanto - Bank of America | B4: {=Sites[State]} -> CA | C4: 0 | E4: =IF(AND(ISNUMBER(C4),ISNUMBER(D4)), C4-D4, "") | F4: =IFERROR(E4/D4, "") | H4: =IF(AND(ISNUMBER(C4),ISNUMBER(G4)), C4-G4, "") | I4: =IFERROR(H4/G4, "")
A5: Apple Valley - Bank of America | B5: CA | C5: 0 | E5: =IF(AND(ISNUMBER(C5),ISNUMBER(D5)), C5-D5, "") | F5: =IFERROR(E5/D5, "") | H5: =IF(AND(ISNUMBER(C5),ISNUMBER(G5)), C5-G5, "") | I5: =IFERROR(H5/G5, "")
A6: Arvin - Bank of America | B6: CA | C6: 89.616 | D6: 0 | E6: =IF(AND(ISNUMBER(C6),ISNUMBER(D6)), C6-D6, "") -> 89.616 | F6: =IFERROR(E6/D6, "") | G6: 0 | H6: =IF(AND(ISNUMBER(C6),ISNUMBER(G6)), C6-G6, "") -> 89.616 | I6: =IFERROR(H6/G6, "")
A7: Bell - Bank of America | B7: CA | C7: 1328.91 | D7: 0 | E7: =IF(AND(ISNUMBER(C7),ISNUMBER(D7)), C7-D7, "") -> 1328.91 | F7: =IFERROR(E7/D7, "") | G7: 0 | H7: =IF(AND(ISNUMBER(C7),ISNUMBER(G7)), C7-G7, "") -> 1328.91 | I7: =IFERROR(H7/G7, "") | J7: 1. Site is underperforming. Peak performance is 7kW, but site capacity is 20kW. | K7: 1. SR084100
A8: Chula Vista - Bank of America | B8: CA | C8: 1406.354 | D8: 0 | E8: =IF(AND(ISNUMBER(C8),ISNUMBER(D8)), C8-D8, "") -> 1406.354 | F8: =IFERROR(E8/D8, "") | G8: 0 | H8: =IF(AND(ISNUMBER(C8),ISNUMBER(G8)), C8-G8, "") -> 1406.354 | I8: =IFERROR(H8/G8, "")
A9: Cupertino - Bank of America | B9: CA | C9: 0 | E9: =IF(AND(ISNUMBER(C9),ISNUMBER(D9)), C9-D9, "") | F9: =IFERROR(E9/D9, "") | H9: =IF(AND(ISNUMBER(C9),ISNUMBER(G9)), C9-G9, "") | I9: =IFERROR(H9/G9, "")
A10: Diamond Bar - Bank of America | B10: CA | C10: 3093.107 | D10: 0 | E10: =IF(AND(ISNUMBER(C10),ISNUMBER(D10)), C10-D10, "") -> 3093.107 | F10: =IFERROR(E10/D10, "") | G10: 0 | H10: =IF(AND(ISNUMBER(C10),ISNUMBER(G10)), C10-G10, "") -> 3093.107 | I10: =IFERROR(H10/G10, "")
A11: El Centro - Bank of America | B11: CA | C11: 0 | D11: 0 | E11: =IF(AND(ISNUMBER(C11),ISNUMBER(D11)), C11-D11, "") -> 0 | F11: =IFERROR(E11/D11, "") | G11: 0 | H11: =IF(AND(ISNUMBER(C11),ISNUMBER(G11)), C11-G11, "") -> 0 | I11: =IFERROR(H11/G11, "")
A12: Moreno Valley - Bank of America | B12: CA | C12: 4725.482 | D12: 0 | E12: =IF(AND(ISNUMBER(C12),ISNUMBER(D12)), C12-D12, "") -> 4725.482 | F12: =IFERROR(E12/D12, "") | G12: 0 | H12: =IF(AND(ISNUMBER(C12),ISNUMBER(G12)), C12-G12, "") -> 4725.482 | I12: =IFERROR(H12/G12, "") | J12: 1. microinverters are offline. BA.2, BA.3, BA.7, BA.8, BB.6, BB.7, BB.8, BC.5, BC.6, BC.7. | K12: 1.SR084104
A13: Redlands - Bank of America | B13: CA | C13: 0 | E13: =IF(AND(ISNUMBER(C13),ISNUMBER(D13)), C13-D13, "") | F13: =IFERROR(E13/D13, "") | H13: =IF(AND(ISNUMBER(C13),ISNUMBER(G13)), C13-G13, "") | I13: =IFERROR(H13/G13, "")
A14: Roseville - Bank of America | B14: CA | C14: 7831.804 | D14: 0 | E14: =IF(AND(ISNUMBER(C14),ISNUMBER(D14)), C14-D14, "") -> 7831.804 | F14: =IFERROR(E14/D14, "") | G14: 0 | H14: =IF(AND(ISNUMBER(C14),ISNUMBER(G14)), C14-G14, "") -> 7831.804 | I14: =IFERROR(H14/G14, "")
A15: San Bernardino - Bank of America | B15: CA | C15: 123.486 | D15: 0 | E15: =IF(AND(ISNUMBER(C15),ISNUMBER(D15)), C15-D15, "") -> 123.486 | F15: =IFERROR(E15/D15, "") | G15: 0 | H15: =IF(AND(ISNUMBER(C15),ISNUMBER(G15)), C15-G15, "") -> 123.486 | I15: =IFERROR(H15/G15, "")
A16: San Diego - Bank of America | B16: CA | C16: 120.601 | D16: 0 | E16: =IF(AND(ISNUMBER(C16),ISNUMBER(D16)), C16-D16, "") -> 120.601 | F16: =IFERROR(E16/D16, "") | G16: 0 | H16: =IF(AND(ISNUMBER(C16),ISNUMBER(G16)), C16-G16, "") -> 120.601 | I16: =IFERROR(H16/G16, "")
A17: Stockton - Bank of America | B17: CA | C17: 2434.676 | D17: 0 | E17: =IF(AND(ISNUMBER(C17),ISNUMBER(D17)), C17-D17, "") -> 2434.676 | F17: =IFERROR(E17/D17, "") | G17: 0 | H17: =IF(AND(ISNUMBER(C17),ISNUMBER(G17)), C17-G17, "") -> 2434.676 | I17: =IFERROR(H17/G17, "")
A18: Victorville - Bank of America | B18: CA | C18: 0 | E18: =IF(AND(ISNUMBER(C18),ISNUMBER(D18)), C18-D18, "") | F18: =IFERROR(E18/D18, "") | H18: =IF(AND(ISNUMBER(C18),ISNUMBER(G18)), C18-G18, "") | I18: =IFERROR(H18/G18, "")
A19: Aurora - BA - Colfax Ave | B19: CO | C19: 1180.68 | D19: 0 | E19: =IF(AND(ISNUMBER(C19),ISNUMBER(D19)), C19-D19, "") -> 1180.68 | F19: =IFERROR(E19/D19, "") | G19: 0 | H19: =IF(AND(ISNUMBER(C19),ISNUMBER(G19)), C19-G19, "") -> 1180.68 | I19: =IFERROR(H19/G19, "") | J19: 1.Microinverter 202305090409 (B1.07) offline | K19: 1.SR084072
A20: Aurora - BA - Parker Rd | B20: CO | C20: 3520.819 | D20: 0 | E20: =IF(AND(ISNUMBER(C20),ISNUMBER(D20)), C20-D20, "") -> 3520.819 | F20: =IFERROR(E20/D20, "") | G20: 0 | H20: =IF(AND(ISNUMBER(C20),ISNUMBER(G20)), C20-G20, "") -> 3520.819 | I20: =IFERROR(H20/G20, "") | J20: 1.Microinverters 202305087223 (B1.2) offline from 04/19 and back online on 04/22 and again offline on 04/27 and back on 04/28. Microinverter 202305087452 ( B1.7) offline 04/20 and back onlin on 04/21 and again offline from 04/27 and back online on 04/28 Microinverter 202305092763 (B4.1) offline from 04/19 and back online on 04/22 and again offline on 04/27 and back online on 04/28 Microinverter 202305094910 (B5.1) offline from 04/19 and back online on 04/22 and again offline on 04/27 and back online on 04/28 Micoinverter 202305097717 ( B6.9) offline from 04/19 and back online on 04/22 and again offline on 04/27 and back online on 04/28 | K20: 1. SR085357
A21: Broomfield - Bank of America | B21: CO | C21: 1441.335 | D21: 0 | E21: =IF(AND(ISNUMBER(C21),ISNUMBER(D21)), C21-D21, "") -> 1441.335 | F21: =IFERROR(E21/D21, "") | G21: 0 | H21: =IF(AND(ISNUMBER(C21),ISNUMBER(G21)), C21-G21, "") -> 1441.335 | I21: =IFERROR(H21/G21, "") | J21: 1. 8 Microinverters are offline. | K21: 1.SR084073
A22: Colorado Springs - Bank of America | B22: CO | C22: 2872.694 | D22: 0 | E22: =IF(AND(ISNUMBER(C22),ISNUMBER(D22)), C22-D22, "") -> 2872.694 | F22: =IFERROR(E22/D22, "") | G22: 0 | H22: =IF(AND(ISNUMBER(C22),ISNUMBER(G22)), C22-G22, "") -> 2872.694 | I22: =IFERROR(H22/G22, "")
A23: Denver - BA - 49th Ave | B23: CO | C23: 0 | E23: =IF(AND(ISNUMBER(C23),ISNUMBER(D23)), C23-D23, "") | F23: =IFERROR(E23/D23, "") | H23: =IF(AND(ISNUMBER(C23),ISNUMBER(G23)), C23-G23, "") | I23: =IFERROR(H23/G23, "")
A24: Denver - BA Wadsworth Blvd | B24: CO | C24: 2521.677 | D24: 0 | E24: =IF(AND(ISNUMBER(C24),ISNUMBER(D24)), C24-D24, "") -> 2521.677 | F24: =IFERROR(E24/D24, "") | G24: 0 | H24: =IF(AND(ISNUMBER(C24),ISNUMBER(G24)), C24-G24, "") -> 2521.677 | I24: =IFERROR(H24/G24, "")
A25: Fort Collins - Bank of America | B25: CO | C25: 1441.048 | D25: 0 | E25: =IF(AND(ISNUMBER(C25),ISNUMBER(D25)), C25-D25, "") -> 1441.048 | F25: =IFERROR(E25/D25, "") | G25: 0 | H25: =IF(AND(ISNUMBER(C25),ISNUMBER(G25)), C25-G25, "") -> 1441.048 | I25: =IFERROR(H25/G25, "") | J25: 1. Microinverters B2.21, B3.24, and B3.26 are offline. | K25: 1.SR084089
A26: Lafayette - Bank of America | B26: CO | C26: 1738.681 | D26: 0 | E26: =IF(AND(ISNUMBER(C26),ISNUMBER(D26)), C26-D26, "") -> 1738.681 | F26: =IFERROR(E26/D26, "") | G26: 0 | H26: =IF(AND(ISNUMBER(C26),ISNUMBER(G26)), C26-G26, "") -> 1738.681 | I26: =IFERROR(H26/G26, "")
A27: Lakewood - Bank of America | B27: CO | C27: 1143.274 | D27: 0 | E27: =IF(AND(ISNUMBER(C27),ISNUMBER(D27)), C27-D27, "") -> 1143.274 | F27: =IFERROR(E27/D27, "") | G27: 0 | H27: =IF(AND(ISNUMBER(C27),ISNUMBER(G27)), C27-G27, "") -> 1143.274 | I27: =IFERROR(H27/G27, "") | J27: 1.Microinverters B3.20, B3.21, B3.22, and B3.25 are offline. | K27: 1.SR084091
A28: Longmont - Bank of America | B28: CO | C28: 1206.176 | D28: 0 | E28: =IF(AND(ISNUMBER(C28),ISNUMBER(D28)), C28-D28, "") -> 1206.176 | F28: =IFERROR(E28/D28, "") | G28: 0 | H28: =IF(AND(ISNUMBER(C28),ISNUMBER(G28)), C28-G28, "") -> 1206.176 | I28: =IFERROR(H28/G28, "")
A29: Thornton - Bank of America | B29: CO | C29: 1282.641 | D29: 0 | E29: =IF(AND(ISNUMBER(C29),ISNUMBER(D29)), C29-D29, "") -> 1282.641 | F29: =IFERROR(E29/D29, "") | G29: 0 | H29: =IF(AND(ISNUMBER(C29),ISNUMBER(G29)), C29-G29, "") -> 1282.641 | I29: =IFERROR(H29/G29, "") | J29: 1. Microinverter 202305087320 offline from 04/19 Micro inverter 202305090399 offline Microinverter 202305094444 offline from 04/18 2. Gateway stopped communicating, cannot verify site production. | K29: 1. SR084093 2.SR085585
A30: Calumet City - Bank of America | B30: IL | C30: 839.463 | D30: 0 | E30: =IF(AND(ISNUMBER(C30),ISNUMBER(D30)), C30-D30, "") -> 839.463 | F30: =IFERROR(E30/D30, "") | G30: 0 | H30: =IF(AND(ISNUMBER(C30),ISNUMBER(G30)), C30-G30, "") -> 839.463 | I30: =IFERROR(H30/G30, "")
A31: Downers Grove - Bank of America | B31: IL | C31: 1009.329 | D31: 0 | E31: =IF(AND(ISNUMBER(C31),ISNUMBER(D31)), C31-D31, "") -> 1009.329 | F31: =IFERROR(E31/D31, "") | G31: 0 | H31: =IF(AND(ISNUMBER(C31),ISNUMBER(G31)), C31-G31, "") -> 1009.329 | I31: =IFERROR(H31/G31, "") | J31: 1. Microinverter 202315097491 (B5:37) back online on 04/30. | K31: 1. SR084095
A32: Bloomington - Bank of America | B32: MN | C32: 0 | E32: =IF(AND(ISNUMBER(C32),ISNUMBER(D32)), C32-D32, "") | F32: =IFERROR(E32/D32, "") | H32: =IF(AND(ISNUMBER(C32),ISNUMBER(G32)), C32-G32, "") | I32: =IFERROR(H32/G32, "")
A33: Clayton - Bank of America | B33: MO | C33: 2289.44 | D33: 0 | E33: =IF(AND(ISNUMBER(C33),ISNUMBER(D33)), C33-D33, "") -> 2289.44 | F33: =IFERROR(E33/D33, "") | G33: 0 | H33: =IF(AND(ISNUMBER(C33),ISNUMBER(G33)), C33-G33, "") -> 2289.44 | I33: =IFERROR(H33/G33, "")
A34: Manchester - Bank of America | B34: MO | C34: 0 | D34: 0 | E34: =IF(AND(ISNUMBER(C34),ISNUMBER(D34)), C34-D34, "") -> 0 | F34: =IFERROR(E34/D34, "") | G34: 0 | H34: =IF(AND(ISNUMBER(C34),ISNUMBER(G34)), C34-G34, "") -> 0 | I34: =IFERROR(H34/G34, "") | J34: 1. Site was not communicating since 03/04. | K34: 1. SR084096
A35: Las Vegas - BA - Eastern Ave | B35: NV | C35: 0 | D35: 0 | E35: =IF(AND(ISNUMBER(C35),ISNUMBER(D35)), C35-D35, "") -> 0 | F35: =IFERROR(E35/D35, "") | G35: 0 | H35: =IF(AND(ISNUMBER(C35),ISNUMBER(G35)), C35-G35, "") -> 0 | I35: =IFERROR(H35/G35, "") | J35: 1. Site was not communicated for whole month. | K35: 1. SR087220
A36: Las Vegas - BA - Town Ctr Dr | B36: NV | C36: 0 | E36: =IF(AND(ISNUMBER(C36),ISNUMBER(D36)), C36-D36, "") | F36: =IFERROR(E36/D36, "") | H36: =IF(AND(ISNUMBER(C36),ISNUMBER(G36)), C36-G36, "") | I36: =IFERROR(H36/G36, "")
A37: Riverton - Bank of America | B37: UT | C37: 2585.596 | D37: 0 | E37: =IF(AND(ISNUMBER(C37),ISNUMBER(D37)), C37-D37, "") -> 2585.596 | F37: =IFERROR(E37/D37, "") | G37: 0 | H37: =IF(AND(ISNUMBER(C37),ISNUMBER(G37)), C37-G37, "") -> 2585.596 | I37: =IFERROR(H37/G37, "")
A38: Salt Lake City - Bank of America | B38: UT | C38: 512.781 | D38: 0 | E38: =IF(AND(ISNUMBER(C38),ISNUMBER(D38)), C38-D38, "") -> 512.781 | F38: =IFERROR(E38/D38, "") | G38: 0 | H38: =IF(AND(ISNUMBER(C38),ISNUMBER(G38)), C38-G38, "") -> 512.781 | I38: =IFERROR(H38/G38, "")

Sheet May
A1: {=portfolio} -> Cushman & Wakefield | D1: May Actual v. Expected | G1: May Actual v. Forecasted
A2: Total | C2: =SUM(C4:C98) -> 54097.039 | D2: =SUM(D4:D98) -> 0 | E2: =C2-D2 -> 54097.039 | F2: =IFERROR(E2/D2, 0) -> 0 | G2: =SUM(G4:G98) -> 0 | H2: =C2-G2 -> 54097.039 | I2: =IFERROR(H2/G2, 0) -> 0 | J2: =IF(AND(TODAY()>DATE(2024, 5, 1), COUNTA(Sites[Site])<>(COUNT(C:C)-1)), "Some sites are missing actual data; if new sites were added, make sure they are aligned correctly (including prior months!)", "")
A3: Site | B3: State | C3: Actual | D3: Expected | E3: Delta | F3: % | G3: Forecasted | H3: Delta | I3: % | J3: Notes | K3: Service Requests
A4: {=Sites[Site]} -> Adelanto - Bank of America | B4: {=Sites[State]} -> CA | C4: 0 | E4: =IF(AND(ISNUMBER(C4),ISNUMBER(D4)), C4-D4, "") | F4: =IFERROR(E4/D4, "") | H4: =IF(AND(ISNUMBER(C4),ISNUMBER(G4)), C4-G4, "") | I4: =IFERROR(H4/G4, "")
A5: Apple Valley - Bank of America | B5: CA | C5: 0 | E5: =IF(AND(ISNUMBER(C5),ISNUMBER(D5)), C5-D5, "") | F5: =IFERROR(E5/D5, "") | H5: =IF(AND(ISNUMBER(C5),ISNUMBER(G5)), C5-G5, "") | I5: =IFERROR(H5/G5, "")
A6: Arvin - Bank of America | B6: CA | C6: 21.973 | D6: 0 | E6: =IF(AND(ISNUMBER(C6),ISNUMBER(D6)), C6-D6, "") -> 21.973 | F6: =IFERROR(E6/D6, "") | G6: 0 | H6: =IF(AND(ISNUMBER(C6),ISNUMBER(G6)), C6-G6, "") -> 21.973 | I6: =IFERROR(H6/G6, "") | J6: 1. Site stopped communicating possibly offline from 05/08/2024 | K6: 1. SR084097
A7: Bell - Bank of America | B7: CA | C7: 1198.623 | D7: 0 | E7: =IF(AND(ISNUMBER(C7),ISNUMBER(D7)), C7-D7, "") -> 1198.623 | F7: =IFERROR(E7/D7, "") | G7: 0 | H7: =IF(AND(ISNUMBER(C7),ISNUMBER(G7)), C7-G7, "") -> 1198.623 | I7: =IFERROR(H7/G7, "") | J7: 1. Site is underperforming. Peak performance is 7kW, but site capacity is 20kW. | K7: 1.SR084100
A8: Chula Vista - Bank of America | B8: CA | C8: 1452.321 | D8: 0 | E8: =IF(AND(ISNUMBER(C8),ISNUMBER(D8)), C8-D8, "") -> 1452.321 | F8: =IFERROR(E8/D8, "") | G8: 0 | H8: =IF(AND(ISNUMBER(C8),ISNUMBER(G8)), C8-G8, "") -> 1452.321 | I8: =IFERROR(H8/G8, "")
A9: Cupertino - Bank of America | B9: CA | C9: 0 | E9: =IF(AND(ISNUMBER(C9),ISNUMBER(D9)), C9-D9, "") | F9: =IFERROR(E9/D9, "") | H9: =IF(AND(ISNUMBER(C9),ISNUMBER(G9)), C9-G9, "") | I9: =IFERROR(H9/G9, "")
A10: Diamond Bar - Bank of America | B10: CA | C10: 2941.987 | D10: 0 | E10: =IF(AND(ISNUMBER(C10),ISNUMBER(D10)), C10-D10, "") -> 2941.987 | F10: =IFERROR(E10/D10, "") | G10: 0 | H10: =IF(AND(ISNUMBER(C10),ISNUMBER(G10)), C10-G10, "") -> 2941.987 | I10: =IFERROR(H10/G10, "")
A11: El Centro - Bank of America | B11: CA | C11: 0 | D11: 0 | E11: =IF(AND(ISNUMBER(C11),ISNUMBER(D11)), C11-D11, "") -> 0 | F11: =IFERROR(E11/D11, "") | G11: 0 | H11: =IF(AND(ISNUMBER(C11),ISNUMBER(G11)), C11-G11, "") -> 0 | I11: =IFERROR(H11/G11, "")
A12: Moreno Valley - Bank of America | B12: CA | C12: 4958.294 | D12: 0 | E12: =IF(AND(ISNUMBER(C12),ISNUMBER(D12)), C12-D12, "") -> 4958.294 | F12: =IFERROR(E12/D12, "") | G12: 0 | H12: =IF(AND(ISNUMBER(C12),ISNUMBER(G12)), C12-G12, "") -> 4958.294 | I12: =IFERROR(H12/G12, "") | J12: 1. microinverters are offline. BA.2, BA.3, BA.7, BA.8, BB.6, BB.7, BB.8, BC.5, BC.6, BC.7. | K12: 1.SR084104
A13: Redlands - Bank of America | B13: CA | C13: 0 | E13: =IF(AND(ISNUMBER(C13),ISNUMBER(D13)), C13-D13, "") | F13: =IFERROR(E13/D13, "") | H13: =IF(AND(ISNUMBER(C13),ISNUMBER(G13)), C13-G13, "") | I13: =IFERROR(H13/G13, "")
A14: Roseville - Bank of America | B14: CA | C14: 9427.401 | D14: 0 | E14: =IF(AND(ISNUMBER(C14),ISNUMBER(D14)), C14-D14, "") -> 9427.401 | F14: =IFERROR(E14/D14, "") | G14: 0 | H14: =IF(AND(ISNUMBER(C14),ISNUMBER(G14)), C14-G14, "") -> 9427.401 | I14: =IFERROR(H14/G14, "")
A15: San Bernardino - Bank of America | B15: CA | C15: 133.092 | D15: 0 | E15: =IF(AND(ISNUMBER(C15),ISNUMBER(D15)), C15-D15, "") -> 133.092 | F15: =IFERROR(E15/D15, "") | G15: 0 | H15: =IF(AND(ISNUMBER(C15),ISNUMBER(G15)), C15-G15, "") -> 133.092 | I15: =IFERROR(H15/G15, "")
A16: San Diego - Bank of America | B16: CA | C16: 125.218 | D16: 0 | E16: =IF(AND(ISNUMBER(C16),ISNUMBER(D16)), C16-D16, "") -> 125.218 | F16: =IFERROR(E16/D16, "") | G16: 0 | H16: =IF(AND(ISNUMBER(C16),ISNUMBER(G16)), C16-G16, "") -> 125.218 | I16: =IFERROR(H16/G16, "")
A17: Stockton - Bank of America | B17: CA | C17: 3031.547 | D17: 0 | E17: =IF(AND(ISNUMBER(C17),ISNUMBER(D17)), C17-D17, "") -> 3031.547 | F17: =IFERROR(E17/D17, "") | G17: 0 | H17: =IF(AND(ISNUMBER(C17),ISNUMBER(G17)), C17-G17, "") -> 3031.547 | I17: =IFERROR(H17/G17, "")
A18: Victorville - Bank of America | B18: CA | C18: 0 | E18: =IF(AND(ISNUMBER(C18),ISNUMBER(D18)), C18-D18, "") | F18: =IFERROR(E18/D18, "") | H18: =IF(AND(ISNUMBER(C18),ISNUMBER(G18)), C18-G18, "") | I18: =IFERROR(H18/G18, "")
A19: Aurora - BA - Colfax Ave | B19: CO | C19: 1388.135 | D19: 0 | E19: =IF(AND(ISNUMBER(C19),ISNUMBER(D19)), C19-D19, "") -> 1388.135 | F19: =IFERROR(E19/D19, "") | G19: 0 | H19: =IF(AND(ISNUMBER(C19),ISNUMBER(G19)), C19-G19, "") -> 1388.135 | I19: =IFERROR(H19/G19, "") | J19: 1.Microinverter 202305090409 (B1.07) offline | K19: 1.SR084072
A20: Aurora - BA - Parker Rd | B20: CO | C20: 4257.477 | D20: 0 | E20: =IF(AND(ISNUMBER(C20),ISNUMBER(D20)), C20-D20, "") -> 4257.477 | F20: =IFERROR(E20/D20, "") | G20: 0 | H20: =IF(AND(ISNUMBER(C20),ISNUMBER(G20)), C20-G20, "") -> 4257.477 | I20: =IFERROR(H20/G20, "")
A21: Broomfield - Bank of America | B21: CO | C21: 1731.849 | D21: 0 | E21: =IF(AND(ISNUMBER(C21),ISNUMBER(D21)), C21-D21, "") -> 1731.849 | F21: =IFERROR(E21/D21, "") | G21: 0 | H21: =IF(AND(ISNUMBER(C21),ISNUMBER(G21)), C21-G21, "") -> 1731.849 | I21: =IFERROR(H21/G21, "") | J21: 1. 8 micro inverters are offline. | K21: 1.SR084073
A22: Colorado Springs - Bank of America | B22: CO | C22: 3258.226 | D22: 0 | E22: =IF(AND(ISNUMBER(C22),ISNUMBER(D22)), C22-D22, "") -> 3258.226 | F22: =IFERROR(E22/D22, "") | G22: 0 | H22: =IF(AND(ISNUMBER(C22),ISNUMBER(G22)), C22-G22, "") -> 3258.226 | I22: =IFERROR(H22/G22, "")
A23: Denver - BA - 49th Ave | B23: CO | C23: 0 | E23: =IF(AND(ISNUMBER(C23),ISNUMBER(D23)), C23-D23, "") | F23: =IFERROR(E23/D23, "") | H23: =IF(AND(ISNUMBER(C23),ISNUMBER(G23)), C23-G23, "") | I23: =IFERROR(H23/G23, "")
A24: Denver - BA Wadsworth Blvd | B24: CO | C24: 2897.3 | D24: 0 | E24: =IF(AND(ISNUMBER(C24),ISNUMBER(D24)), C24-D24, "") -> 2897.3 | F24: =IFERROR(E24/D24, "") | G24: 0 | H24: =IF(AND(ISNUMBER(C24),ISNUMBER(G24)), C24-G24, "") -> 2897.3 | I24: =IFERROR(H24/G24, "")
A25: Fort Collins - Bank of America | B25: CO | C25: 1800.01 | D25: 0 | E25: =IF(AND(ISNUMBER(C25),ISNUMBER(D25)), C25-D25, "") -> 1800.01 | F25: =IFERROR(E25/D25, "") | G25: 0 | H25: =IF(AND(ISNUMBER(C25),ISNUMBER(G25)), C25-G25, "") -> 1800.01 | I25: =IFERROR(H25/G25, "") | J25: 1.Microinverters B2.21, B3.24, and B3.26 are offline. | K25: 1.SR084089
A26: Lafayette - Bank of America | B26: CO | C26: 2171.084 | D26: 0 | E26: =IF(AND(ISNUMBER(C26),ISNUMBER(D26)), C26-D26, "") -> 2171.084 | F26: =IFERROR(E26/D26, "") | G26: 0 | H26: =IF(AND(ISNUMBER(C26),ISNUMBER(G26)), C26-G26, "") -> 2171.084 | I26: =IFERROR(H26/G26, "")
A27: Lakewood - Bank of America | B27: CO | C27: 1328.74 | D27: 0 | E27: =IF(AND(ISNUMBER(C27),ISNUMBER(D27)), C27-D27, "") -> 1328.74 | F27: =IFERROR(E27/D27, "") | G27: 0 | H27: =IF(AND(ISNUMBER(C27),ISNUMBER(G27)), C27-G27, "") -> 1328.74 | I27: =IFERROR(H27/G27, "") | J27: 1.Microinverters B3.20, B3.21, B3.22, and B3.25 are offline. | K27: 1.SR084091
A28: Longmont - Bank of America | B28: CO | C28: 1464.895 | D28: 0 | E28: =IF(AND(ISNUMBER(C28),ISNUMBER(D28)), C28-D28, "") -> 1464.895 | F28: =IFERROR(E28/D28, "") | G28: 0 | H28: =IF(AND(ISNUMBER(C28),ISNUMBER(G28)), C28-G28, "") -> 1464.895 | I28: =IFERROR(H28/G28, "")
A29: Thornton - Bank of America | B29: CO | C29: 146.175 | D29: 0 | E29: =IF(AND(ISNUMBER(C29),ISNUMBER(D29)), C29-D29, "") -> 146.175 | F29: =IFERROR(E29/D29, "") | G29: 0 | H29: =IF(AND(ISNUMBER(C29),ISNUMBER(G29)), C29-G29, "") -> 146.175 | I29: =IFERROR(H29/G29, "") | J29: 1. Microinverter 202305087320 offline from 04/19 Micro inverter 202305090399 offline Microinverter 202305094444 offline from 04/18 2. Gateway stopped communicating, cannot verify site production. | K29: 1.SR084093 2.SR085585
A30: Calumet City - Bank of America | B30: IL | C30: 1093.383 | D30: 0 | E30: =IF(AND(ISNUMBER(C30),ISNUMBER(D30)), C30-D30, "") -> 1093.383 | F30: =IFERROR(E30/D30, "") | G30: 0 | H30: =IF(AND(ISNUMBER(C30),ISNUMBER(G30)), C30-G30, "") -> 1093.383 | I30: =IFERROR(H30/G30, "")
A31: Downers Grove - Bank of America | B31: IL | C31: 3287.073 | D31: 0 | E31: =IF(AND(ISNUMBER(C31),ISNUMBER(D31)), C31-D31, "") -> 3287.073 | F31: =IFERROR(E31/D31, "") | G31: 0 | H31: =IF(AND(ISNUMBER(C31),ISNUMBER(G31)), C31-G31, "") -> 3287.073 | I31: =IFERROR(H31/G31, "") | J31: 1.Microinverters 202315097491 (B5:37) and 202315094282(B4.30) were offline since 05/01 and back online on 05/28 | K31: 1.SR084095
A32: Bloomington - Bank of America | B32: MN | C32: 0 | E32: =IF(AND(ISNUMBER(C32),ISNUMBER(D32)), C32-D32, "") | F32: =IFERROR(E32/D32, "") | H32: =IF(AND(ISNUMBER(C32),ISNUMBER(G32)), C32-G32, "") | I32: =IFERROR(H32/G32, "")
A33: Clayton - Bank of America | B33: MO | C33: 2481.118 | D33: 0 | E33: =IF(AND(ISNUMBER(C33),ISNUMBER(D33)), C33-D33, "") -> 2481.118 | F33: =IFERROR(E33/D33, "") | G33: 0 | H33: =IF(AND(ISNUMBER(C33),ISNUMBER(G33)), C33-G33, "") -> 2481.118 | I33: =IFERROR(H33/G33, "")
A34: Manchester - Bank of America | B34: MO | C34: 0 | D34: 0 | E34: =IF(AND(ISNUMBER(C34),ISNUMBER(D34)), C34-D34, "") -> 0 | F34: =IFERROR(E34/D34, "") | G34: 0 | H34: =IF(AND(ISNUMBER(C34),ISNUMBER(G34)), C34-G34, "") -> 0 | I34: =IFERROR(H34/G34, "") | J34: 1. Site was not communicating since 03/04. | K34: 1. SR084096
A35: Las Vegas - BA - Eastern Ave | B35: NV | C35: 21.916 | D35: 0 | E35: =IF(AND(ISNUMBER(C35),ISNUMBER(D35)), C35-D35, "") -> 21.916 | F35: =IFERROR(E35/D35, "") | G35: 0 | H35: =IF(AND(ISNUMBER(C35),ISNUMBER(G35)), C35-G35, "") -> 21.916 | I35: =IFERROR(H35/G35, "") | J35: 1. Site was not communicated since 04/01 and regained comms on 05/29 | K35: 1. SR087220
A36: Las Vegas - BA - Town Ctr Dr | B36: NV | C36: 0 | E36: =IF(AND(ISNUMBER(C36),ISNUMBER(D36)), C36-D36, "") | F36: =IFERROR(E36/D36, "") | H36: =IF(AND(ISNUMBER(C36),ISNUMBER(G36)), C36-G36, "") | I36: =IFERROR(H36/G36, "")
A37: Riverton - Bank of America | B37: UT | C37: 2912.849 | D37: 0 | E37: =IF(AND(ISNUMBER(C37),ISNUMBER(D37)), C37-D37, "") -> 2912.849 | F37: =IFERROR(E37/D37, "") | G37: 0 | H37: =IF(AND(ISNUMBER(C37),ISNUMBER(G37)), C37-G37, "") -> 2912.849 | I37: =IFERROR(H37/G37, "")
A38: Salt Lake City - Bank of America | B38: UT | C38: 566.353 | D38: 0 | E38: =IF(AND(ISNUMBER(C38),ISNUMBER(D38)), C38-D38, "") -> 566.353 | F38: =IFERROR(E38/D38, "") | G38: 0 | H38: =IF(AND(ISNUMBER(C38),ISNUMBER(G38)), C38-G38, "") -> 566.353 | I38: =IFERROR(H38/G38, "")

Sheet Jun
A1: {=portfolio} -> Cushman & Wakefield | D1: June Actual v. Expected | G1: June Actual v. Forecasted
A2: Total | C2: =SUM(C4:C98) -> 55315.69 | D2: =SUM(D4:D98) -> 0 | E2: =C2-D2 -> 55315.69 | F2: =IFERROR(E2/D2, 0) -> 0 | G2: =SUM(G4:G98) -> 0 | H2: =C2-G2 -> 55315.69 | I2: =IFERROR(H2/G2, 0) -> 0 | J2: =IF(AND(TODAY()>DATE(2024, 6, 1), COUNTA(Sites[Site])<>(COUNT(C:C)-1)), "Some sites are missing actual data; if new sites were added, make sure they are aligned correctly (including prior months!)", "")
A3: Site | B3: State | C3: Actual | D3: Expected | E3: Delta | F3: % | G3: Forecasted | H3: Delta | I3: % | J3: Notes | K3: Service Requests
A4: {=Sites[Site]} -> Adelanto - Bank of America | B4: {=Sites[State]} -> CA | C4: 0 | E4: =IF(AND(ISNUMBER(C4),ISNUMBER(D4)), C4-D4, "") | F4: =IFERROR(E4/D4, "") | H4: =IF(AND(ISNUMBER(C4),ISNUMBER(G4)), C4-G4, "") | I4: =IFERROR(H4/G4, "")
A5: Apple Valley - Bank of America | B5: CA | C5: 0 | E5: =IF(AND(ISNUMBER(C5),ISNUMBER(D5)), C5-D5, "") | F5: =IFERROR(E5/D5, "") | H5: =IF(AND(ISNUMBER(C5),ISNUMBER(G5)), C5-G5, "") | I5: =IFERROR(H5/G5, "")
A6: Arvin - Bank of America | B6: CA | C6: 0 | D6: 0 | E6: =IF(AND(ISNUMBER(C6),ISNUMBER(D6)), C6-D6, "") -> 0 | F6: =IFERROR(E6/D6, "") | G6: 0 | H6: =IF(AND(ISNUMBER(C6),ISNUMBER(G6)), C6-G6, "") -> 0 | I6: =IFERROR(H6/G6, "") | J6: 1. Site stopped communicating possibly offline from 05/08/2024 | K6: 1. SR084097
A7: Bell - Bank of America | B7: CA | C7: 1265.34 | D7: 0 | E7: =IF(AND(ISNUMBER(C7),ISNUMBER(D7)), C7-D7, "") -> 1265.34 | F7: =IFERROR(E7/D7, "") | G7: 0 | H7: =IF(AND(ISNUMBER(C7),ISNUMBER(G7)), C7-G7, "") -> 1265.34 | I7: =IFERROR(H7/G7, "") | J7: 1. Site is underperforming. Peak performance is 7kW, but site capacity is 20kW. | K7: 1. SR084100
A8: Chula Vista - Bank of America | B8: CA | C8: 1381.955 | D8: 0 | E8: =IF(AND(ISNUMBER(C8),ISNUMBER(D8)), C8-D8, "") -> 1381.955 | F8: =IFERROR(E8/D8, "") | G8: 0 | H8: =IF(AND(ISNUMBER(C8),ISNUMBER(G8)), C8-G8, "") -> 1381.955 | I8: =IFERROR(H8/G8, "")
A9: Cupertino - Bank of America | B9: CA | C9: 0 | E9: =IF(AND(ISNUMBER(C9),ISNUMBER(D9)), C9-D9, "") | F9: =IFERROR(E9/D9, "") | H9: =IF(AND(ISNUMBER(C9),ISNUMBER(G9)), C9-G9, "") | I9: =IFERROR(H9/G9, "")
A10: Diamond Bar - Bank of America | B10: CA | C10: 3397.87 | D10: 0 | E10: =IF(AND(ISNUMBER(C10),ISNUMBER(D10)), C10-D10, "") -> 3397.87 | F10: =IFERROR(E10/D10, "") | G10: 0 | H10: =IF(AND(ISNUMBER(C10),ISNUMBER(G10)), C10-G10, "") -> 3397.87 | I10: =IFERROR(H10/G10, "")
A11: El Centro - Bank of America | B11: CA | C11: 0 | D11: 0 | E11: =IF(AND(ISNUMBER(C11),ISNUMBER(D11)), C11-D11, "") -> 0 | F11: =IFERROR(E11/D11, "") | G11: 0 | H11: =IF(AND(ISNUMBER(C11),ISNUMBER(G11)), C11-G11, "") -> 0 | I11: =IFERROR(H11/G11, "")
