Workbook
Name JanActual: #REF!
Name JanActual2: #REF!
Name JanExpected: #REF!
Name JanExpectedDelta: #REF!
Name JanExpectedPercent: #REF!
Name JanExpPercent: #REF!
Name JanForecasted: #REF!
Name JanForecastedDelta: #REF!
Name JanForecastedPercent: #REF!
Name portfolio: Sites!$B$1:$B$1
Name Year: Sites!#REF!

Sheet Year to Date
A1: {=portfolio} -> Ecofin | D1: Year to Date Actual v. Expected | G1: Year to Date Actual v. Forecasted
A2: Total | C2: =SUM(C4:C91) -> 8557915.4 | D2: =SUM(D4:D91) -> 10057970 | E2: =C2-D2 -> -1500054.8 | F2: =IFERROR(E2/D2, 0) -> -0.14914091 | G2: =SUM(G4:G91) -> 0 | H2: =C2-G2 -> 8557915.4 | I2: =IFERROR(H2/G2, 0) -> 0
A3: Site | B3: State | C3: Actual | D3: Expected | E3: Delta | F3: % | G3: Forecasted | H3: Delta | I3: %
A4: {=Sites[Site]} -> Alamosa School District | B4: {=Sites[State]} -> CO | C4: =SUM('1st Qtr'!C4, '2nd Qtr'!C4, '3rd Qtr'!C4, '4th Qtr'!C4) -> 460134 | D4: =SUM('1st Qtr'!D4, '2nd Qtr'!D4, '3rd Qtr'!D4, '4th Qtr'!D4) -> 741295.83 | E4: =IF(AND(ISNUMBER(C4),ISNUMBER(D4)), C4-D4, "") -> -281161.83 | F4: =IFERROR(E4/D4, "") -> -0.37928425 | H4: =SUM('1st Qtr'!H4, '2nd Qtr'!H4, '3rd Qtr'!H4, '4th Qtr'!H4) -> -125201.65 | I4: =IFERROR(H4/G4, "")
A5: San Luis Valley | B5: CO | C5: =SUM(Jan!C5, Feb!C5, Mar!C5) -> 0 | D5: =SUM(Jan!D5, Feb!D5, Mar!D5) -> 0 | E5: =IF(AND(ISNUMBER(C5),ISNUMBER(D5)), C5-D5, "") -> 0 | F5: =IFERROR(E5/D5, "") | H5: =SUM(Jan!H5, Feb!H5, Mar!H5) -> 0 | I5: =IFERROR(H5/G5, "")
A6: Golden NREL 2 | B6: CO | C6: =SUM('1st Qtr'!C6, '2nd Qtr'!C6, '3rd Qtr'!C6, '4th Qtr'!C6) -> 63028 | D6: =SUM('1st Qtr'!D6, '2nd Qtr'!D6, '3rd Qtr'!D6, '4th Qtr'!D6) -> 58309.109 | E6: =IF(AND(ISNUMBER(C6),ISNUMBER(D6)), C6-D6, "") -> 4718.8907 | F6: =IFERROR(E6/D6, "") -> 0.080928877 | H6: =SUM('1st Qtr'!H6, '2nd Qtr'!H6, '3rd Qtr'!H6, '4th Qtr'!H6) -> -6219.68 | I6: =IFERROR(H6/G6, "")
A7: Golden NREL Wind 3 | B7: CO | C7: =SUM(Jan!C7, Feb!C7, Mar!C7) -> 0 | D7: =SUM(Jan!D7, Feb!D7, Mar!D7) -> 0 | E7: =IF(AND(ISNUMBER(C7),ISNUMBER(D7)), C7-D7, "") -> 0 | F7: =IFERROR(E7/D7, "") | H7: =SUM(Jan!H7, Feb!H7, Mar!H7) -> 0 | I7: =IFERROR(H7/G7, "")
A8: Pratt Solar Farm | B8: KS | C8: =SUM('1st Qtr'!C8, '2nd Qtr'!C8, '3rd Qtr'!C8, '4th Qtr'!C8) -> 4340000 | D8: =SUM('1st Qtr'!D8, '2nd Qtr'!D8, '3rd Qtr'!D8, '4th Qtr'!D8) -> 5526980.7 | E8: =IF(AND(ISNUMBER(C8),ISNUMBER(D8)), C8-D8, "") -> -1186980.7 | F8: =IFERROR(E8/D8, "") -> -0.21476114 | H8: =SUM('1st Qtr'!H8, '2nd Qtr'!H8, '3rd Qtr'!H8, '4th Qtr'!H8) -> -945286.54 | I8: =IFERROR(H8/G8, "")
A9: Rochester - 5516 Valleyhigh NW | B9: MN | C9: =SUM(Jan!C9, Feb!C9, Mar!C9) -> 0 | D9: =SUM(Jan!D9, Feb!D9, Mar!D9) -> 0 | E9: =IF(AND(ISNUMBER(C9),ISNUMBER(D9)), C9-D9, "") -> 0 | F9: =IFERROR(E9/D9, "") | H9: =SUM(Jan!H9, Feb!H9, Mar!H9) -> 0 | I9: =IFERROR(H9/G9, "")
A10: Warsaw - 2201 Richmond | B10: VA | C10: =SUM('1st Qtr'!C10, '2nd Qtr'!C10, '3rd Qtr'!C10, '4th Qtr'!C10) -> 3142172.4 | D10: =SUM('1st Qtr'!D10, '2nd Qtr'!D10, '3rd Qtr'!D10, '4th Qtr'!D10) -> 3258789.5 | E10: =IF(AND(ISNUMBER(C10),ISNUMBER(D10)), C10-D10, "") -> -116617.05 | F10: =IFERROR(E10/D10, "") -> -0.03578539 | H10: =SUM('1st Qtr'!H10, '2nd Qtr'!H10, '3rd Qtr'!H10, '4th Qtr'!H10) -> -262774.03 | I10: =IFERROR(H10/G10, "")
A11: Mount Jackson - Randolf | B11: VA | C11: =SUM(Jan!C11, Feb!C11, Mar!C11) -> 0 | D11: =SUM(Jan!D11, Feb!D11, Mar!D11) -> 0 | E11: =IF(AND(ISNUMBER(C11),ISNUMBER(D11)), C11-D11, "") -> 0 | F11: =IFERROR(E11/D11, "") | H11: =SUM(Jan!H11, Feb!H11, Mar!H11) -> 0 | I11: =IFERROR(H11/G11, "")
A12: Callands Gretna - Monroe | B12: VA | C12: =SUM('1st Qtr'!C12, '2nd Qtr'!C12, '3rd Qtr'!C12, '4th Qtr'!C12) -> 552581 | D12: =SUM('1st Qtr'!D12, '2nd Qtr'!D12, '3rd Qtr'!D12, '4th Qtr'!D12) -> 472595.2 | E12: =IF(AND(ISNUMBER(C12),ISNUMBER(D12)), C12-D12, "") -> 79985.8 | F12: =IFERROR(E12/D12, "") -> 0.16924802 | H12: =SUM('1st Qtr'!H12, '2nd Qtr'!H12, '3rd Qtr'!H12, '4th Qtr'!H12) -> -29919 | I12: =IFERROR(H12/G12, "")
A13: Rockbridge Baths - Small Mouth Bass | B13: VA | C13: =SUM(Jan!C13, Feb!C13, Mar!C13) -> 0 | D13: =SUM(Jan!D13, Feb!D13, Mar!D13) -> 0 | E13: =IF(AND(ISNUMBER(C13),ISNUMBER(D13)), C13-D13, "") -> 0 | F13: =IFERROR(E13/D13, "") | H13: =SUM(Jan!H13, Feb!H13, Mar!H13) -> 0 | I13: =IFERROR(H13/G13, "")

Sheet 1st Qtr
A1: {=portfolio} -> Ecofin | D1: 1st Quarter Actual v. Expected | G1: 1st Quarter Actual v. Forecasted
A2: Total | C2: =SUM(C4:C91) -> 2107421 | D2: =SUM(D4:D91) -> 2460365.2 | E2: =C2-D2 -> -352944.2 | F2: =IFERROR(E2/D2, 0) -> -0.14345196 | G2: =SUM(G4:G91) -> 2220161.3 | H2: =C2-G2 -> -112740.3 | I2: =IFERROR(H2/G2, 0) -> -0.050780229
A3: Site | B3: State | C3: Actual | D3: Expected | E3: Delta | F3: % | G3: Forecasted | H3: Delta | I3: %
A4: {=Sites[Site]} -> Alamosa School District | B4: {=Sites[State]} -> CO | C4: =SUM(Jan!C4, Feb!C4, Mar!C4) -> 288610 | D4: =SUM(Jan!D4, Feb!D4, Mar!D4) -> 269702.07 | E4: =IF(AND(ISNUMBER(C4),ISNUMBER(D4)), C4-D4, "") -> 18907.93 | F4: =IFERROR(E4/D4, "") -> 0.07010673 | G4: =SUM(Jan!G4, Feb!G4, Mar!G4) -> 311701.3 | H4: =SUM(Jan!H4, Feb!H4, Mar!H4) -> -23091.3 | I4: =IFERROR(H4/G4, "") -> -0.0740815
A5: San Luis Valley | B5: CO | C5: =SUM(Jan!C5, Feb!C5, Mar!C5) -> 0 | D5: =SUM(Jan!D5, Feb!D5, Mar!D5) -> 0 | E5: =IF(AND(ISNUMBER(C5),ISNUMBER(D5)), C5-D5, "") -> 0 | F5: =IFERROR(E5/D5, "") | G5: =SUM(Jan!G5, Feb!G5, Mar!G5) -> 0 | H5: =SUM(Jan!H5, Feb!H5, Mar!H5) -> 0 | I5: =IFERROR(H5/G5, "")
A6: Golden NREL 2 | B6: CO | C6: =SUM(Jan!C6, Feb!C6, Mar!C6) -> 22181 | D6: =SUM(Jan!D6, Feb!D6, Mar!D6) -> 22245.206 | E6: =IF(AND(ISNUMBER(C6),ISNUMBER(D6)), C6-D6, "") -> -64.205776 | F6: =IFERROR(E6/D6, "") -> -0.0028862748 | G6: =SUM(Jan!G6, Feb!G6, Mar!G6) -> 28731.96 | H6: =SUM(Jan!H6, Feb!H6, Mar!H6) -> -6550.96 | I6: =IFERROR(H6/G6, "") -> -0.22800254
A7: Golden NREL Wind 3 | B7: CO | C7: =SUM(Jan!C7, Feb!C7, Mar!C7) -> 0 | D7: =SUM(Jan!D7, Feb!D7, Mar!D7) -> 0 | E7: =IF(AND(ISNUMBER(C7),ISNUMBER(D7)), C7-D7, "") -> 0 | F7: =IFERROR(E7/D7, "") | G7: =SUM(Jan!G7, Feb!G7, Mar!G7) -> 0 | H7: =SUM(Jan!H7, Feb!H7, Mar!H7) -> 0 | I7: =IFERROR(H7/G7, "")
A8: Pratt Solar Farm | B8: KS | C8: =SUM(Jan!C8, Feb!C8, Mar!C8) -> 1796630 | D8: =SUM(Jan!D8, Feb!D8, Mar!D8) -> 2168417.9 | E8: =IF(AND(ISNUMBER(C8),ISNUMBER(D8)), C8-D8, "") -> -371787.93 | F8: =IFERROR(E8/D8, "") -> -0.17145585 | G8: =SUM(Jan!G8, Feb!G8, Mar!G8) -> 1879728 | H8: =SUM(Jan!H8, Feb!H8, Mar!H8) -> -83098.04 | I8: =IFERROR(H8/G8, "") -> -0.04420748
A9: Rochester - 5516 Valleyhigh NW | B9: MN | C9: =SUM(Jan!C9, Feb!C9, Mar!C9) -> 0 | D9: =SUM(Jan!D9, Feb!D9, Mar!D9) -> 0 | E9: =IF(AND(ISNUMBER(C9),ISNUMBER(D9)), C9-D9, "") -> 0 | F9: =IFERROR(E9/D9, "") | G9: =SUM(Jan!G9, Feb!G9, Mar!G9) -> 0 | H9: =SUM(Jan!H9, Feb!H9, Mar!H9) -> 0 | I9: =IFERROR(H9/G9, "")
A10: Warsaw - 2201 Richmond | B10: VA | C10: =SUM(Jan!C10, Feb!C10, Mar!C10) -> 0 | D10: =SUM(Jan!D10, Feb!D10, Mar!D10) -> 0 | E10: =IF(AND(ISNUMBER(C10),ISNUMBER(D10)), C10-D10, "") -> 0 | F10: =IFERROR(E10/D10, "") | G10: =SUM(Jan!G10, Feb!G10, Mar!G10) -> 0 | H10: =SUM(Jan!H10, Feb!H10, Mar!H10) -> 0 | I10: =IFERROR(H10/G10, "")
A11: Mount Jackson - Randolf | B11: VA | C11: =SUM(Jan!C11, Feb!C11, Mar!C11) -> 0 | D11: =SUM(Jan!D11, Feb!D11, Mar!D11) -> 0 | E11: =IF(AND(ISNUMBER(C11),ISNUMBER(D11)), C11-D11, "") -> 0 | F11: =IFERROR(E11/D11, "") | G11: =SUM(Jan!G11, Feb!G11, Mar!G11) -> 0 | H11: =SUM(Jan!H11, Feb!H11, Mar!H11) -> 0 | I11: =IFERROR(H11/G11, "")
A12: Callands Gretna - Monroe | B12: VA | C12: =SUM(Jan!C12, Feb!C12, Mar!C12) -> 0 | D12: =SUM(Jan!D12, Feb!D12, Mar!D12) -> 0 | E12: =IF(AND(ISNUMBER(C12),ISNUMBER(D12)), C12-D12, "") -> 0 | F12: =IFERROR(E12/D12, "") | G12: =SUM(Jan!G12, Feb!G12, Mar!G12) -> 0 | H12: =SUM(Jan!H12, Feb!H12, Mar!H12) -> 0 | I12: =IFERROR(H12/G12, "")
A13: Rockbridge Baths - Small Mouth Bass | B13: VA | C13: =SUM(Jan!C13, Feb!C13, Mar!C13) -> 0 | D13: =SUM(Jan!D13, Feb!D13, Mar!D13) -> 0 | E13: =IF(AND(ISNUMBER(C13),ISNUMBER(D13)), C13-D13, "") -> 0 | F13: =IFERROR(E13/D13, "") | G13: =SUM(Jan!G13, Feb!G13, Mar!G13) -> 0 | H13: =SUM(Jan!H13, Feb!H13, Mar!H13) -> 0 | I13: =IFERROR(H13/G13, "")

Sheet 2nd Qtr
A1: {=portfolio} -> Ecofin | D1: 2nd Quarter Actual v. Expected | G1: 2nd Quarter Actual v. Forecasted
A2: Total | C2: =SUM(C4:C91) -> 12072123 | D2: =SUM(D4:D91) -> 15855427 | E2: =C2-D2 -> -3783303.9 | F2: =IFERROR(E2/D2, 0) -> -0.23861255 | G2: =SUM(G4:G91) -> 16394923 | H2: =C2-G2 -> -4322799.9 | I2: =IFERROR(H2/G2, 0) -> -0.26366698
A3: Site | B3: State | C3: Actual | D3: Expected | E3: Delta | F3: % | G3: Forecasted | H3: Delta | I3: %
A4: {=Sites[Site]} -> Alamosa School District | B4: {=Sites[State]} -> CO | C4: =SUM(Apr!C4, May!C4, Jun!C4) -> 171524 | D4: =SUM(Apr!D4, May!D4, Jun!D4) -> 471593.76 | E4: =IF(AND(ISNUMBER(C4),ISNUMBER(D4)), C4-D4, "") -> -300069.76 | F4: =IFERROR(E4/D4, "") -> -0.63628866 | G4: =SUM(Apr!G4+May!G4+Jun!G4) -> 412241.35 | H4: =SUM(Apr!H4, May!H4, Jun!H4) -> -102110.35 | I4: =IFERROR(H4/G4, "") -> -0.24769556
A5: San Luis Valley | B5: CO | C5: =SUM(Apr!C5, May!C5, Jun!C5) -> 403386.42 | D5: =SUM(Apr!D5, May!D5, Jun!D5) -> 168822.4 | E5: =IF(AND(ISNUMBER(C5),ISNUMBER(D5)), C5-D5, "") -> 234564.02 | F5: =IFERROR(E5/D5, "") -> 1.3894129 | G5: =SUM(Apr!G5+May!G5+Jun!G5) -> 0 | H5: =SUM(Apr!H5, May!H5, Jun!H5) -> 403386.42 | I5: =IFERROR(H5/G5, "")
A6: Golden NREL 2 | B6: CO | C6: =SUM(Apr!C6, May!C6, Jun!C6) -> 40847 | D6: =SUM(Apr!D6, May!D6, Jun!D6) -> 36063.903 | E6: =IF(AND(ISNUMBER(C6),ISNUMBER(D6)), C6-D6, "") -> 4783.0965 | F6: =IFERROR(E6/D6, "") -> 0.13262836 | G6: =SUM(Apr!G6+May!G6+Jun!G6) -> 40515.72 | H6: =SUM(Apr!H6, May!H6, Jun!H6) -> 331.28 | I6: =IFERROR(H6/G6, "") -> 0.0081765794
A7: Golden NREL Wind 3 | B7: CO | C7: =SUM(Apr!C7, May!C7, Jun!C7) -> 28261 | D7: =SUM(Apr!D7, May!D7, Jun!D7) -> 81324 | E7: =IF(AND(ISNUMBER(C7),ISNUMBER(D7)), C7-D7, "") -> -53063 | F7: =IFERROR(E7/D7, "") -> -0.65248881 | G7: =SUM(Apr!G7+May!G7+Jun!G7) -> 0 | H7: =SUM(Apr!H7, May!H7, Jun!H7) -> 28261 | I7: =IFERROR(H7/G7, "")
A8: Pratt Solar Farm | B8: KS | C8: =SUM(Apr!C8, May!C8, Jun!C8) -> 2543370 | D8: =SUM(Apr!D8, May!D8, Jun!D8) -> 3358562.7 | E8: =IF(AND(ISNUMBER(C8),ISNUMBER(D8)), C8-D8, "") -> -815192.73 | F8: =IFERROR(E8/D8, "") -> -0.24272071 | G8: =SUM(Apr!G8+May!G8+Jun!G8) -> 3405558.5 | H8: =SUM(Apr!H8, May!H8, Jun!H8) -> -862188.5 | I8: =IFERROR(H8/G8, "") -> -0.25317096
A9: Rochester - 5516 Valleyhigh NW | B9: MN | C9: =SUM(Apr!C9, May!C9, Jun!C9) -> 3935122 | D9: =SUM(Apr!D9, May!D9, Jun!D9) -> 6649248.5 | E9: =IF(AND(ISNUMBER(C9),ISNUMBER(D9)), C9-D9, "") -> -2714126.5 | F9: =IFERROR(E9/D9, "") -> -0.40818545 | G9: =SUM(Apr!G9+May!G9+Jun!G9) -> 7166100.1 | H9: =SUM(Apr!H9, May!H9, Jun!H9) -> -3230978.1 | I9: =IFERROR(H9/G9, "") -> -0.4508698
A10: Warsaw - 2201 Richmond | B10: VA | C10: =SUM(Apr!C10, May!C10, Jun!C10) -> 3142172.4 | D10: =SUM(Apr!D10, May!D10, Jun!D10) -> 3258789.5 | E10: =IF(AND(ISNUMBER(C10),ISNUMBER(D10)), C10-D10, "") -> -116617.05 | F10: =IFERROR(E10/D10, "") -> -0.03578539 | G10: =SUM(Apr!G10+May!G10+Jun!G10) -> 3404946.4 | H10: =SUM(Apr!H10, May!H10, Jun!H10) -> -262774.03 | I10: =IFERROR(H10/G10, "") -> -0.077174204
A11: Mount Jackson - Randolf | B11: VA | C11: =SUM(Apr!C11, May!C11, Jun!C11) -> 769106.9 | D11: =SUM(Apr!D11, May!D11, Jun!D11) -> 866456.3 | E11: =IF(AND(ISNUMBER(C11),ISNUMBER(D11)), C11-D11, "") -> -97349.4 | F11: =IFERROR(E11/D11, "") -> -0.1123535 | G11: =SUM(Apr!G11+May!G11+Jun!G11) -> 828310.8 | H11: =SUM(Apr!H11, May!H11, Jun!H11) -> -59203.9 | I11: =IFERROR(H11/G11, "") -> -0.071475465
A12: Callands Gretna - Monroe | B12: VA | C12: =SUM(Apr!C12, May!C12, Jun!C12) -> 552581 | D12: =SUM(Apr!D12, May!D12, Jun!D12) -> 472595.2 | E12: =IF(AND(ISNUMBER(C12),ISNUMBER(D12)), C12-D12, "") -> 79985.8 | F12: =IFERROR(E12/D12, "") -> 0.16924802 | G12: =SUM(Apr!G12+May!G12+Jun!G12) -> 582500 | H12: =SUM(Apr!H12, May!H12, Jun!H12) -> -29919 | I12: =IFERROR(H12/G12, "") -> -0.05136309
A13: Rockbridge Baths - Small Mouth Bass | B13: VA | C13: =SUM(Apr!C13, May!C13, Jun!C13) -> 485752.3 | D13: =SUM(Apr!D13, May!D13, Jun!D13) -> 491970.7 | E13: =IF(AND(ISNUMBER(C13),ISNUMBER(D13)), C13-D13, "") -> -6218.4 | F13: =IFERROR(E13/D13, "") -> -0.012639777 | G13: =SUM(Apr!G13+May!G13+Jun!G13) -> 554750 | H13: =SUM(Apr!H13, May!H13, Jun!H13) -> -68997.7 | I13: =IFERROR(H13/G13, "") -> -0.12437621

Sheet 3rd Qtr
A1: {=portfolio} -> Ecofin | D1: 3rd Quarter Actual v. Expected | G1: 3rd Quarter Actual v. Forecasted
A2: Total | C2: =SUM(C4:C91) -> 0 | D2: =SUM(D4:D91) -> 0 | E2: =C2-D2 -> 0 | F2: =IFERROR(E2/D2, 0) -> 0 | G2: =SUM(G4:G91) -> 0 | H2: =C2-G2 -> 0 | I2: =IFERROR(H2/G2, 0) -> 0
A3: Site | B3: State | C3: Actual | D3: Expected | E3: Delta | F3: % | G3: Forecasted | H3: Delta | I3: %
A4: {=Sites[Site]} -> Alamosa School District | B4: {=Sites[State]} -> CO | C4: =SUM(Jul!C4, Aug!C4, Sep!C4) -> 0 | D4: =SUM(Jul!D4, Aug!D4, Sep!D4) -> 0 | E4: =IF(AND(ISNUMBER(C4),ISNUMBER(D4)), C4-D4, "") -> 0 | F4: =IFERROR(E4/D4, "") | H4: =SUM(Jul!H4, Aug!H4, Sep!H4) -> 0 | I4: =IFERROR(H4/G4, "")
A5: San Luis Valley | B5: CO | C5: =SUM(Jul!C5, Aug!C5, Sep!C5) -> 0 | D5: =SUM(Jul!D5, Aug!D5, Sep!D5) -> 0 | E5: =IF(AND(ISNUMBER(C5),ISNUMBER(D5)), C5-D5, "") -> 0 | F5: =IFERROR(E5/D5, "") | H5: =SUM(Jul!H5, Aug!H5, Sep!H5) -> 0 | I5: =IFERROR(H5/G5, "")
A6: Golden NREL 2 | B6: CO | C6: =SUM(Jul!C6, Aug!C6, Sep!C6) -> 0 | D6: =SUM(Jul!D6, Aug!D6, Sep!D6) -> 0 | E6: =IF(AND(ISNUMBER(C6),ISNUMBER(D6)), C6-D6, "") -> 0 | F6: =IFERROR(E6/D6, "") | H6: =SUM(Jul!H6, Aug!H6, Sep!H6) -> 0 | I6: =IFERROR(H6/G6, "")
A7: Golden NREL Wind 3 | B7: CO | C7: =SUM(Jul!C7, Aug!C7, Sep!C7) -> 0 | D7: =SUM(Jul!D7, Aug!D7, Sep!D7) -> 0 | E7: =IF(AND(ISNUMBER(C7),ISNUMBER(D7)), C7-D7, "") -> 0 | F7: =IFERROR(E7/D7, "") | H7: =SUM(Jul!H7, Aug!H7, Sep!H7) -> 0 | I7: =IFERROR(H7/G7, "")
A8: Pratt Solar Farm | B8: KS | C8: =SUM(Jul!C8, Aug!C8, Sep!C8) -> 0 | D8: =SUM(Jul!D8, Aug!D8, Sep!D8) -> 0 | E8: =IF(AND(ISNUMBER(C8),ISNUMBER(D8)), C8-D8, "") -> 0 | F8: =IFERROR(E8/D8, "") | H8: =SUM(Jul!H8, Aug!H8, Sep!H8) -> 0 | I8: =IFERROR(H8/G8, "")
A9: Rochester - 5516 Valleyhigh NW | B9: MN | C9: =SUM(Jul!C9, Aug!C9, Sep!C9) -> 0 | D9: =SUM(Jul!D9, Aug!D9, Sep!D9) -> 0 | E9: =IF(AND(ISNUMBER(C9),ISNUMBER(D9)), C9-D9, "") -> 0 | F9: =IFERROR(E9/D9, "") | H9: =SUM(Jul!H9, Aug!H9, Sep!H9) -> 0 | I9: =IFERROR(H9/G9, "")
A10: Warsaw - 2201 Richmond | B10: VA | C10: =SUM(Jul!C10, Aug!C10, Sep!C10) -> 0 | D10: =SUM(Jul!D10, Aug!D10, Sep!D10) -> 0 | E10: =IF(AND(ISNUMBER(C10),ISNUMBER(D10)), C10-D10, "") -> 0 | F10: =IFERROR(E10/D10, "") | H10: =SUM(Jul!H10, Aug!H10, Sep!H10) -> 0 | I10: =IFERROR(H10/G10, "")
A11: Mount Jackson - Randolf | B11: VA | C11: =SUM(Jul!C11, Aug!C11, Sep!C11) -> 0 | D11: =SUM(Jul!D11, Aug!D11, Sep!D11) -> 0 | E11: =IF(AND(ISNUMBER(C11),ISNUMBER(D11)), C11-D11, "") -> 0 | F11: =IFERROR(E11/D11, "") | H11: =SUM(Jul!H11, Aug!H11, Sep!H11) -> 0 | I11: =IFERROR(H11/G11, "")
A12: Callands Gretna - Monroe | B12: VA | C12: =SUM(Jul!C12, Aug!C12, Sep!C12) -> 0 | D12: =SUM(Jul!D12, Aug!D12, Sep!D12) -> 0 | E12: =IF(AND(ISNUMBER(C12),ISNUMBER(D12)), C12-D12, "") -> 0 | F12: =IFERROR(E12/D12, "") | H12: =SUM(Jul!H12, Aug!H12, Sep!H12) -> 0 | I12: =IFERROR(H12/G12, "")
A13: Rockbridge Baths - Small Mouth Bass | B13: VA | C13: =SUM(Jul!C13, Aug!C13, Sep!C13) -> 0 | D13: =SUM(Jul!D13, Aug!D13, Sep!D13) -> 0 | E13: =IF(AND(ISNUMBER(C13),ISNUMBER(D13)), C13-D13, "") -> 0 | F13: =IFERROR(E13/D13, "") | H13: =SUM(Jul!H13, Aug!H13, Sep!H13) -> 0 | I13: =IFERROR(H13/G13, "")

Sheet 4th Qtr
A1: {=portfolio} -> Ecofin | D1: 4th Quarter Actual v. Expected | G1: 4th Quarter Actual v. Forecasted
A2: Total | C2: =SUM(C4:C91) -> 0 | D2: =SUM(D4:D91) -> 0 | E2: =C2-D2 -> 0 | F2: =IFERROR(E2/D2, 0) -> 0 | G2: =SUM(G4:G91) -> 0 | H2: =C2-G2 -> 0 | I2: =IFERROR(H2/G2, 0) -> 0
A3: Site | B3: State | C3: Actual | D3: Expected | E3: Delta | F3: % | G3: Forecasted | H3: Delta | I3: %
A4: {=Sites[Site]} -> Alamosa School District | B4: {=Sites[State]} -> CO | C4: =SUM(Oct!C4, Nov!C4, Dec!C4) -> 0 | D4: =SUM(Oct!D4, Nov!D4, Dec!D4) -> 0 | E4: =IF(AND(ISNUMBER(C4),ISNUMBER(D4)), C4-D4, "") -> 0 | F4: =IFERROR(E4/D4, "") | H4: =SUM(Oct!H4, Nov!H4, Dec!H4) -> 0 | I4: =IFERROR(H4/G4, "")
A5: San Luis Valley | B5: CO | C5: =SUM(Oct!C5, Nov!C5, Dec!C5) -> 0 | D5: =SUM(Oct!D5, Nov!D5, Dec!D5) -> 0 | E5: =IF(AND(ISNUMBER(C5),ISNUMBER(D5)), C5-D5, "") -> 0 | F5: =IFERROR(E5/D5, "") | H5: =SUM(Oct!H5, Nov!H5, Dec!H5) -> 0 | I5: =IFERROR(H5/G5, "")
A6: Golden NREL 2 | B6: CO | C6: =SUM(Oct!C6, Nov!C6, Dec!C6) -> 0 | D6: =SUM(Oct!D6, Nov!D6, Dec!D6) -> 0 | E6: =IF(AND(ISNUMBER(C6),ISNUMBER(D6)), C6-D6, "") -> 0 | F6: =IFERROR(E6/D6, "") | H6: =SUM(Oct!H6, Nov!H6, Dec!H6) -> 0 | I6: =IFERROR(H6/G6, "")
A7: Golden NREL Wind 3 | B7: CO | C7: =SUM(Oct!C7, Nov!C7, Dec!C7) -> 0 | D7: =SUM(Oct!D7, Nov!D7, Dec!D7) -> 0 | E7: =IF(AND(ISNUMBER(C7),ISNUMBER(D7)), C7-D7, "") -> 0 | F7: =IFERROR(E7/D7, "") | H7: =SUM(Oct!H7, Nov!H7, Dec!H7) -> 0 | I7: =IFERROR(H7/G7, "")
A8: Pratt Solar Farm | B8: KS | C8: =SUM(Oct!C8, Nov!C8, Dec!C8) -> 0 | D8: =SUM(Oct!D8, Nov!D8, Dec!D8) -> 0 | E8: =IF(AND(ISNUMBER(C8),ISNUMBER(D8)), C8-D8, "") -> 0 | F8: =IFERROR(E8/D8, "") | H8: =SUM(Oct!H8, Nov!H8, Dec!H8) -> 0 | I8: =IFERROR(H8/G8, "")
A9: Rochester - 5516 Valleyhigh NW | B9: MN | C9: =SUM(Oct!C9, Nov!C9, Dec!C9) -> 0 | D9: =SUM(Oct!D9, Nov!D9, Dec!D9) -> 0 | E9: =IF(AND(ISNUMBER(C9),ISNUMBER(D9)), C9-D9, "") -> 0 | F9: =IFERROR(E9/D9, "") | H9: =SUM(Oct!H9, Nov!H9, Dec!H9) -> 0 | I9: =IFERROR(H9/G9, "")
A10: Warsaw - 2201 Richmond | B10: VA | C10: =SUM(Oct!C10, Nov!C10, Dec!C10) -> 0 | D10: =SUM(Oct!D10, Nov!D10, Dec!D10) -> 0 | E10: =IF(AND(ISNUMBER(C10),ISNUMBER(D10)), C10-D10, "") -> 0 | F10: =IFERROR(E10/D10, "") | H10: =SUM(Oct!H10, Nov!H10, Dec!H10) -> 0 | I10: =IFERROR(H10/G10, "")
A11: Mount Jackson - Randolf | B11: VA | C11: =SUM(Oct!C11, Nov!C11, Dec!C11) -> 0 | D11: =SUM(Oct!D11, Nov!D11, Dec!D11) -> 0 | E11: =IF(AND(ISNUMBER(C11),ISNUMBER(D11)), C11-D11, "") -> 0 | F11: =IFERROR(E11/D11, "") | H11: =SUM(Oct!H11, Nov!H11, Dec!H11) -> 0 | I11: =IFERROR(H11/G11, "")
A12: Callands Gretna - Monroe | B12: VA | C12: =SUM(Oct!C12, Nov!C12, Dec!C12) -> 0 | D12: =SUM(Oct!D12, Nov!D12, Dec!D12) -> 0 | E12: =IF(AND(ISNUMBER(C12),ISNUMBER(D12)), C12-D12, "") -> 0 | F12: =IFERROR(E12/D12, "") | H12: =SUM(Oct!H12, Nov!H12, Dec!H12) -> 0 | I12: =IFERROR(H12/G12, "")
A13: Rockbridge Baths - Small Mouth Bass | B13: VA | C13: =SUM(Oct!C13, Nov!C13, Dec!C13) -> 0 | D13: =SUM(Oct!D13, Nov!D13, Dec!D13) -> 0 | E13: =IF(AND(ISNUMBER(C13),ISNUMBER(D13)), C13-D13, "") -> 0 | F13: =IFERROR(E13/D13, "") | H13: =SUM(Oct!H13, Nov!H13, Dec!H13) -> 0 | I13: =IFERROR(H13/G13, "")

Sheet Jan
A1: {=portfolio} -> Ecofin | D1: January Actual v. Expected | G1: January Actual v. Forecasted
A2: Total | C2: =SUM(C4:C82) -> 78991 | D2: =SUM(D4:D82) -> 79673 | E2: =C2-D2 -> -682 | F2: =IFERROR(E2/D2, 0) -> -0.008559989 | G2: =SUM(G4:G82) -> 100783 | H2: =C2-G2 -> -21792 | I2: =IFERROR(H2/G2, 0) -> -0.21622694 | J2: =IF(AND(TODAY()>DATE(2024, 1, 1), COUNTA(Sites[Site])<>(COUNT(C:C)-1)), "Some sites are missing actual data; if new sites were added, make sure they are aligned correctly (including prior months!)", "") -> Some sites are missing actual data; if new sites were added, make sure they are aligned correctly (including prior months!)
A3: Site | B3: State | C3: Actual | D3: Expected | E3: Delta | F3: % | G3: Forecasted | H3: Delta | I3: % | J3: Notes | K3: Service Requests
A4: {=Sites[Site]} -> Alamosa School District | B4: {=Sites[State]} -> CO | C4: 72896 | D4: 73786 | E4: =IF(AND(ISNUMBER(C4),ISNUMBER(D4)), C4-D4, "") -> -890 | F4: =IFERROR(E4/D4, "") -> -0.012061909 | G4: 93005 | H4: =IF(AND(ISNUMBER(C4),ISNUMBER(G4)), C4-G4, "") -> -20109 | I4: =IFERROR(H4/G4, "") -> -0.21621418 | J4: 1. Inverter 1 is offline on 01/09, 01/10, 01/12, 01/17. | K4: 1. SR080094
A5: San Luis Valley | B5: CO | C5: 0 | D5: 0 | E5: =IF(AND(ISNUMBER(C5),ISNUMBER(D5)), C5-D5, "") -> 0 | F5: =IFERROR(E5/D5, "") | G5: 0 | H5: =IF(AND(ISNUMBER(C5),ISNUMBER(G5)), C5-G5, "") -> 0 | I5: =IFERROR(H5/G5, "") | J5: 1. Site was not communicating from 04/22 | K5: 1. SR077495
A6: Golden NREL 2 | B6: CO | C6: 6095 | D6: 5887 | E6: =IF(AND(ISNUMBER(C6),ISNUMBER(D6)), C6-D6, "") -> 208 | F6: =IFERROR(E6/D6, "") -> 0.035332088 | G6: 7778 | H6: =IF(AND(ISNUMBER(C6),ISNUMBER(G6)), C6-G6, "") -> -1683 | I6: =IFERROR(H6/G6, "") -> -0.21637953 | J6: 1. Inverter was barely produced on 1/13, 1/14 and 1/15 | K6: 1. SR080235
A7: Golden NREL Wind 3 | B7: CO | C7: 0 | D7: 0 | E7: =IF(AND(ISNUMBER(C7),ISNUMBER(D7)), C7-D7, "") -> 0 | F7: =IFERROR(E7/D7, "") | G7: 0 | H7: =IF(AND(ISNUMBER(C7),ISNUMBER(G7)), C7-G7, "") -> 0 | I7: =IFERROR(H7/G7, "") | J7: 1. Site was not communicating from 05/23/2022 | K7: 1. SR079089
A8: Pratt Solar Farm | B8: KS | E8: =IF(AND(ISNUMBER(C8),ISNUMBER(D8)), C8-D8, "") | F8: =IFERROR(E8/D8, "") | H8: =IF(AND(ISNUMBER(C8),ISNUMBER(G8)), C8-G8, "") | I8: =IFERROR(H8/G8, "")
A9: Rochester - 5516 Valleyhigh NW | B9: MN
A10: Warsaw - 2201 Richmond | B10: VA
A11: Mount Jackson - Randolf | B11: VA
A12: Callands Gretna - Monroe | B12: VA
A13: Rockbridge Baths - Small Mouth Bass | B13: VA

Sheet Feb
A1: {=portfolio} -> Ecofin | D1: February Actual v. Expected | G1: February Actual v. Forecasted
A2: Total | C2: =SUM(C4:C91) -> 911881 | D2: =SUM(D4:D91) -> 1076640.6 | E2: =C2-D2 -> -164759.55 | F2: =IFERROR(E2/D2, 0) -> -0.15303116 | G2: =SUM(G4:G91) -> 944891.36 | H2: =C2-G2 -> -33010.36 | I2: =IFERROR(H2/G2, 0) -> -0.034935614 | J2: =IF(AND(TODAY()>DATE(2024, 2, 1), COUNTA(Sites[Site])<>(COUNT(C:C)-1)), "Some sites are missing actual data; if new sites were added, make sure they are aligned correctly (including prior months!)", "") -> Some sites are missing actual data; if new sites were added, make sure they are aligned correctly (including prior months!)
A3: Site | B3: State | C3: Actual | D3: Expected | E3: Delta | F3: % | G3: Forecasted | H3: Delta | I3: % | J3: Notes | K3: Service Requests
A4: {=Sites[Site]} -> Alamosa School District | B4: {=Sites[State]} -> CO | C4: 100394 | D4: 90505.5 | E4: =IF(AND(ISNUMBER(C4),ISNUMBER(D4)), C4-D4, "") -> 9888.5 | F4: =IFERROR(E4/D4, "") -> 0.10925855 | G4: 97813.3 | H4: =IF(AND(ISNUMBER(C4),ISNUMBER(G4)), C4-G4, "") -> 2580.7 | I4: =IFERROR(H4/G4, "") -> 0.026383938
A5: San Luis Valley | B5: CO | C5: 0 | D5: 0 | E5: 0 | F5: =IFERROR(E5/D5, "") | G5: 0 | H5: =IF(AND(ISNUMBER(C5),ISNUMBER(G5)), C5-G5, "") -> 0 | I5: =IFERROR(H5/G5, "") | J5: 1. Site stopped communicating from 04/22 | K5: 1. SR077494
A6: Golden NREL 2 | B6: CO | C6: 6597 | D6: 7237.8 | E6: =IF(AND(ISNUMBER(C6),ISNUMBER(D6)), C6-D6, "") -> -640.8 | F6: =IFERROR(E6/D6, "") -> -0.08853519 | G6: 8862.2 | H6: =IF(AND(ISNUMBER(C6),ISNUMBER(G6)), C6-G6, "") -> -2265.2 | I6: =IFERROR(H6/G6, "") -> -0.25560245
A7: Golden NREL Wind 3 | B7: CO | C7: 0 | D7: 0 | E7: =IF(AND(ISNUMBER(C7),ISNUMBER(D7)), C7-D7, "") -> 0 | F7: =IFERROR(E7/D7, "") | G7: 0 | H7: =IF(AND(ISNUMBER(C7),ISNUMBER(G7)), C7-G7, "") -> 0 | I7: =IFERROR(H7/G7, "") | J7: 1. Site was not communicating from 05/23/2022 | K7: 1. SR079089
A8: Pratt Solar Farm | B8: KS | C8: 804890 | D8: 978897.25 | E8: =IF(AND(ISNUMBER(C8),ISNUMBER(D8)), C8-D8, "") -> -174007.25 | F8: =IFERROR(E8/D8, "") -> -0.17775844 | G8: 838215.86 | H8: =IF(AND(ISNUMBER(C8),ISNUMBER(G8)), C8-G8, "") -> -33325.86 | I8: =IFERROR(H8/G8, "") -> -0.039758088 | J8: 1.(A) Inverter 2 was taken offline by technician on 02/26/2024 at 13:30 to 15:00 & inverter 1 at 15:00 - 16:15. 1.(B) Inverter 2 tripped offline on 02/27/2024 at 15:48 & back online at 12:00 on 02/28/2024. | K8: 1. SR081345
A9: Rochester - 5516 Valleyhigh NW | B9: MN
A10: Warsaw - 2201 Richmond | B10: VA
A11: Mount Jackson - Randolf | B11: VA
A12: Callands Gretna - Monroe | B12: VA
A13: Rockbridge Baths - Small Mouth Bass | B13: VA

Sheet Mar
A1: {=portfolio} -> Ecofin | D1: March Actual v. Expected | G1: March Actual v. Forecasted
A2: Total | C2: =SUM(C4:C92) -> 1116549 | D2: =SUM(D4:D92) -> 1304051.7 | E2: =C2-D2 -> -187502.65 | F2: =IFERROR(E2/D2, 0) -> -0.14378468 | G2: =SUM(G4:G92) -> 1174486.9 | H2: =C2-G2 -> -57937.94 | I2: =IFERROR(H2/G2, 0) -> -0.049330425 | J2: =IF(AND(TODAY()>DATE(2024, 3, 1), COUNTA(Sites[Site])<>(COUNT(C:C)-1)), "Some sites are missing actual data; if new sites were added, make sure they are aligned correctly (including prior months!)", "") -> Some sites are missing actual data; if new sites were added, make sure they are aligned correctly (including prior months!)
A3: Site | B3: State | C3: Actual | D3: Expected | E3: Delta | F3: % | G3: Forecasted | H3: Delta | I3: % | J3: Notes | K3: Service Requests
A4: {=Sites[Site]} -> Alamosa School District | B4: {=Sites[State]} -> CO | C4: 115320 | D4: 105410.57 | E4: =IF(AND(ISNUMBER(C4),ISNUMBER(D4)), C4-D4, "") -> 9909.4301 | F4: =IFERROR(E4/D4, "") -> 0.094007936 | G4: 120883 | H4: =IF(AND(ISNUMBER(C4),ISNUMBER(G4)), C4-G4, "") -> -5563 | I4: =IFERROR(H4/G4, "") -> -0.046019705
A5: San Luis Valley | B5: CO | C5: 0 | D5: 0 | E5: =IF(AND(ISNUMBER(C5),ISNUMBER(D5)), C5-D5, "") -> 0 | F5: =IFERROR(E5/D5, "") | G5: 0 | H5: =IF(AND(ISNUMBER(C5),ISNUMBER(G5)), C5-G5, "") -> 0 | I5: =IFERROR(H5/G5, "") | J5: 1. Site stopped communicating from 04/22/20223 and communication regained on 04/03 | K5: 1. SR077494
A6: Golden NREL 2 | B6: CO | C6: 9489 | D6: 9120.4058 | E6: =IF(AND(ISNUMBER(C6),ISNUMBER(D6)), C6-D6, "") -> 368.59422 | F6: =IFERROR(E6/D6, "") -> 0.040414235 | G6: 12091.76 | H6: =IF(AND(ISNUMBER(C6),ISNUMBER(G6)), C6-G6, "") -> -2602.76 | I6: =IFERROR(H6/G6, "") -> -0.21525072
A7: Golden NREL Wind 3 | B7: CO | C7: 0 | D7: 0 | E7: =IF(AND(ISNUMBER(C7),ISNUMBER(D7)), C7-D7, "") -> 0 | F7: =IFERROR(E7/D7, "") | G7: 0 | H7: =IF(AND(ISNUMBER(C7),ISNUMBER(G7)), C7-G7, "") -> 0 | I7: =IFERROR(H7/G7, "") | J7: 1. Site was not communicating from 05/23/2022 | K7: 1. SR079089
A8: Pratt Solar Farm | B8: KS | C8: 991740 | D8: 1189520.7 | E8: =IF(AND(ISNUMBER(C8),ISNUMBER(D8)), C8-D8, "") -> -197780.68 | F8: =IFERROR(E8/D8, "") -> -0.16626922 | G8: 1041512.2 | H8: =IF(AND(ISNUMBER(C8),ISNUMBER(G8)), C8-G8, "") -> -49772.18 | I8: =IFERROR(H8/G8, "") -> -0.04778838 | J8: 1. Inverter 2 is derating, due to overheating 2 modules are offline | K8: 1. SR081345
A9: Rochester - 5516 Valleyhigh NW | B9: MN | E9: =IF(AND(ISNUMBER(C9),ISNUMBER(D9)), C9-D9, "") | F9: =IFERROR(E9/D9, "") | H9: =IF(AND(ISNUMBER(C9),ISNUMBER(G9)), C9-G9, "") | I9: =IFERROR(H9/G9, "")
A10: Warsaw - 2201 Richmond | B10: VA
A11: Mount Jackson - Randolf | B11: VA
A12: Callands Gretna - Monroe | B12: VA
A13: Rockbridge Baths - Small Mouth Bass | B13: VA

Sheet Apr
A1: {=portfolio} -> Ecofin | D1: April Actual v. Expected | G1: April Actual v. Forecasted
A2: Total | C2: =SUM(C4:C91) -> 3747463.7 | D2: =SUM(D4:D91) -> 4085138.3 | E2: =C2-D2 -> -337674.55 | F2: =IFERROR(E2/D2, 0) -> -0.082659269 | G2: =SUM(G4:G91) -> 4373274.4 | H2: =C2-G2 -> -625810.65 | I2: =IFERROR(H2/G2, 0) -> -0.14309888 | J2: =IF(AND(TODAY()>DATE(2024, 4, 1), COUNTA(Sites[Site])<>(COUNT(C:C)-1)), "Some sites are missing actual data; if new sites were added, make sure they are aligned correctly (including prior months!)", "") -> Some sites are missing actual data; if new sites were added, make sure they are aligned correctly (including prior months!)
A3: Site | B3: State | C3: Actual | D3: Expected | E3: Delta | F3: % | G3: Forecasted | H3: Delta | I3: % | J3: Notes | K3: Service Requests
A4: {=Sites[Site]} -> Alamosa School District | B4: {=Sites[State]} -> CO | C4: 129640 | D4: 120725.55 | E4: =IF(AND(ISNUMBER(C4),ISNUMBER(D4)), C4-D4, "") -> 8914.4462 | F4: =IFERROR(E4/D4, "") -> 0.073840591 | G4: 129601.73 | H4: =IF(AND(ISNUMBER(C4),ISNUMBER(G4)), C4-G4, "") -> 38.27 | I4: =IFERROR(H4/G4, "") -> 0.00029528927
A5: San Luis Valley | B5: CO | C5: 100708.84 | D5: 0 | E5: =IF(AND(ISNUMBER(C5),ISNUMBER(D5)), C5-D5, "") -> 100708.84 | F5: =IFERROR(E5/D5, "") | G5: 0 | H5: =IF(AND(ISNUMBER(C5),ISNUMBER(G5)), C5-G5, "") -> 100708.84 | I5: =IFERROR(H5/G5, "")
A6: Golden NREL 2 | B6: CO | C6: 12208 | D6: 10993.186 | E6: =IF(AND(ISNUMBER(C6),ISNUMBER(D6)), C6-D6, "") -> 1214.8143 | F6: =IFERROR(E6/D6, "") -> 0.11050612 | G6: 12899.28 | H6: =IF(AND(ISNUMBER(C6),ISNUMBER(G6)), C6-G6, "") -> -691.28 | I6: =IFERROR(H6/G6, "") -> -0.053590588
A7: Golden NREL Wind 3 | B7: CO | C7: 0 | D7: 0 | F7: 0 | G7: 0 | H7: =IF(AND(ISNUMBER(C7),ISNUMBER(G7)), C7-G7, "") -> 0 | I7: =IFERROR(H7/G7, "") | J7: 1. Site was not communicating from 05/23/2022 | K7: 1. SR079089
A8: Pratt Solar Farm | B8: KS | C8: 883580 | D8: 1136253.2 | E8: =IF(AND(ISNUMBER(C8),ISNUMBER(D8)), C8-D8, "") -> -252673.17 | F8: =IFERROR(E8/D8, "") -> -0.22237401 | G8: 1094871.9 | H8: =IF(AND(ISNUMBER(C8),ISNUMBER(G8)), C8-G8, "") -> -211291.95 | I8: =IFERROR(H8/G8, "") -> -0.19298325 | J8: 1. Inverter 2 is derating, due to overheating 2 modules are offline 2. Site is offline from 04/17 to 04/19. | K8: 1. SR081345 2. SR083483
A9: Rochester - 5516 Valleyhigh NW | B9: MN | C9: 1731010 | D9: 1818032.7 | E9: =IF(AND(ISNUMBER(C9),ISNUMBER(D9)), C9-D9, "") -> -87022.74 | F9: =IFERROR(E9/D9, "") -> -0.047866432 | G9: 2098181.4 | H9: =IF(AND(ISNUMBER(C9),ISNUMBER(G9)), C9-G9, "") -> -367171.42 | I9: =IFERROR(H9/G9, "") -> -0.17499508 | J9: 1. Inverter 37 is derating due to fan fault during peak hours 2. Inverter 60 is derating during morning hours due to issue with tracker 3. Inverter 30 tripped offline at 12:45 on 04/19 and was back online at 13:00 on 04/22 4. Inverter 47 was offline from 04/01 and was replaced at 13:00 on 04/23 5. Inverter 53 tripped offline at 14:00 on 04/24 and back online at 07:00 on 05/26 | K9: 1. SR083529 2. SR085269 3. SR083529 4. SR083529 5. SR083529
A10: Warsaw - 2201 Richmond | B10: VA | C10: 890316.9 | D10: 999133.63 | E10: =IF(AND(ISNUMBER(C10),ISNUMBER(D10)), C10-D10, "") -> -108816.73 | F10: =IFERROR(E10/D10, "") -> -0.10891109 | G10: 1037720 | H10: =IF(AND(ISNUMBER(C10),ISNUMBER(G10)), C10-G10, "") -> -147403.11 | I10: =IFERROR(H10/G10, "") -> -0.14204516 | J10: 1. Inverters production not as expected due to issue with trackers throughout the month | K10: 1. SR087216
A11: Mount Jackson - Randolf | B11: VA | E11: =IF(AND(ISNUMBER(C11),ISNUMBER(D11)), C11-D11, "") | F11: =IFERROR(E11/D11, "") | H11: =IF(AND(ISNUMBER(C11),ISNUMBER(G11)), C11-G11, "") | I11: =IFERROR(H11/G11, "")
A12: Callands Gretna - Monroe | B12: VA | E12: =IF(AND(ISNUMBER(C12),ISNUMBER(D12)), C12-D12, "") | F12: =IFERROR(E12/D12, "") | H12: =IF(AND(ISNUMBER(C12),ISNUMBER(G12)), C12-G12, "") | I12: =IFERROR(H12/G12, "")
A13: Rockbridge Baths - Small Mouth Bass | B13: VA

Sheet May
A1: {=portfolio} -> Ecofin | D1: May Actual v. Expected | G1: May Actual v. Forecasted
A2: Total | C2: =SUM(C4:C90) -> 3618468.6 | D2: =SUM(D4:D90) -> 4947868 | E2: =C2-D2 -> -1329399.4 | F2: =IFERROR(E2/D2, 0) -> -0.26868126 | G2: =SUM(G4:G90) -> 4965072.7 | H2: =C2-G2 -> -1346604.1 | I2: =IFERROR(H2/G2, 0) -> -0.27121539 | J2: =IF(AND(TODAY()>DATE(2024, 5, 1), COUNTA(Sites[Site])<>(COUNT(C:C)-1)), "Some sites are missing actual data; if new sites were added, make sure they are aligned correctly (including prior months!)", "") -> Some sites are missing actual data; if new sites were added, make sure they are aligned correctly (including prior months!)
A3: Site | B3: State | C3: Actual | D3: Expected | E3: Delta | F3: % | G3: Forecasted | H3: Delta | I3: % | J3: Notes | K3: Service Requests
A4: {=Sites[Site]} -> Alamosa School District | B4: {=Sites[State]} -> CO | C4: 41884 | D4: 123308.21 | E4: =IF(AND(ISNUMBER(C4),ISNUMBER(D4)), C4-D4, "") -> -81424.207 | F4: =IFERROR(E4/D4, "") -> -0.6603308 | G4: 144032.62 | H4: =IF(AND(ISNUMBER(C4),ISNUMBER(G4)), C4-G4, "") -> -102148.62 | I4: =IFERROR(H4/G4, "") -> -0.70920476 | J4: 1. Inverter 2 is offline since 05/03. 2. Inverter 1 didn't start for producton on 05/21 and back online at 01:15 on 05/21 and again offline since 05/22 | K4: 1. SR084239 2. SR084949
A5: San Luis Valley | B5: CO | C5: 122065.89 | D5: 0 | E5: =IF(AND(ISNUMBER(C5),ISNUMBER(D5)), C5-D5, "") -> 122065.89 | F5: =IFERROR(E5/D5, "") | G5: 0 | H5: =IF(AND(ISNUMBER(C5),ISNUMBER(G5)), C5-G5, "") -> 122065.89 | I5: =IFERROR(H5/G5, "") | J5: 1. Site was offline from 05/10 at 07:00am to 11:00am on 05/10. | K5: 1. SR084536
A6: Golden NREL 2 | B6: CO | C6: 14328 | D6: 12274.718 | E6: =IF(AND(ISNUMBER(C6),ISNUMBER(D6)), C6-D6, "") -> 2053.2822 | F6: =IFERROR(E6/D6, "") -> 0.16727735 | G6: 13666.44 | H6: =IF(AND(ISNUMBER(C6),ISNUMBER(G6)), C6-G6, "") -> 661.56 | I6: =IFERROR(H6/G6, "") -> 0.048407632
A7: Golden NREL Wind 3 | B7: CO | C7: 0 | D7: 0 | E7: =IF(AND(ISNUMBER(C7),ISNUMBER(D7)), C7-D7, "") -> 0 | F7: =IFERROR(E7/D7, "") | G7: 0 | H7: =IF(AND(ISNUMBER(C7),ISNUMBER(G7)), C7-G7, "") -> 0 | I7: =IFERROR(H7/G7, "") | J7: 1. Site was not communicating from 05/23/2022 | K7: 1. SR079089
A8: Pratt Solar Farm | B8: KS | C8: 895550 | D8: 1150841.6 | E8: =IF(AND(ISNUMBER(C8),ISNUMBER(D8)), C8-D8, "") -> -255291.56 | F8: =IFERROR(E8/D8, "") -> -0.22183033 | G8: 1173647.6 | H8: =IF(AND(ISNUMBER(C8),ISNUMBER(G8)), C8-G8, "") -> -278097.55 | I8: =IFERROR(H8/G8, "") -> -0.2369515 | J8: 1. Inverter 2 is derating, due to overheating 2 modules are offline 2. Inverter 1 is derating since 05/28. | K8: 1. SR081345 2. SR085401
A9: Rochester - 5516 Valleyhigh NW | B9: MN | C9: 1472046 | D9: 2533439.7 | E9: =IF(AND(ISNUMBER(C9),ISNUMBER(D9)), C9-D9, "") -> -1061393.7 | F9: =IFERROR(E9/D9, "") -> -0.41895361 | G9: 2459554.7 | H9: =IF(AND(ISNUMBER(C9),ISNUMBER(G9)), C9-G9, "") -> -987508.67 | I9: =IFERROR(H9/G9, "") -> -0.40149897 | J9: 1. Inverter 1 is offline due to a permanent fault of the power module. Fault0010 at 14:00 from 05/21. 2. Inverter 27 tripped offline due to bus imbalance. Protect0070 at 12:30PM on 05/23. 3. Inverter 35 tripped offline due to AC SPD Fault. Warn0070 at 11:30 on 05/18. 4. Inverter 49 tripped offline due to bus imbalance. Protect0070 at 15:45 on 05/25. 5. Inverter 71 tripped offline due to a permanent fault of the power module. Fault0010 at 15:15 on 05/05. 6. Inverter 40 tripped offline and reporting Grid Phase Voltage Out of Range at 18:15 on 05/29. 7. Meter MV 2 is not communicated for whole month. | K9: 1. SR085262 2. SR085263 3. SR085264 4. SR085265 5. SR085266 6. SR085294 7. SR085267
A10: Warsaw - 2201 Richmond | B10: VA | C10: 1072594.7 | D10: 1128003.8 | E10: =IF(AND(ISNUMBER(C10),ISNUMBER(D10)), C10-D10, "") -> -55409.118 | F10: =IFERROR(E10/D10, "") -> -0.049121392 | G10: 1174171.4 | H10: =IF(AND(ISNUMBER(C10),ISNUMBER(G10)), C10-G10, "") -> -101576.72 | I10: =IFERROR(H10/G10, "") -> -0.086509276 | J10: 1. Inverter 27 was derating due to fan fault during peak hours throughout the month till 05/22. Inverter 12 is derating due to external fan fault since 05/28 | K10: 1. SR085335
A11: Mount Jackson - Randolf | B11: VA
A12: Callands Gretna - Monroe | B12: VA
A13: Rockbridge Baths - Small Mouth Bass | B13: VA

Sheet Jun
A1: {=portfolio} -> Ecofin | D1: June Actual v. Expected | G1: June Actual v. Forecasted
A2: Total | C2: =SUM(C4:C100) -> 4706190.7 | D2: =SUM(D4:D100) -> 6822420.6 | E2: =C2-D2 -> -2116229.9 | F2: =IFERROR(E2/D2, 0) -> -0.31018755 | G2: =SUM(G4:G100) -> 7056575.8 | H2: =C2-G2 -> -2350385.1 | I2: =IFERROR(H2/G2, 0) -> -0.33307729 | J2: =IF(AND(TODAY()>DATE(2024, 6, 1), COUNTA(Sites[Site])<>(COUNT(C:C)-1)), "Some sites are missing actual data; if new sites were added, make sure they are aligned correctly (including prior months!)", "")
A3: Site | B3: State | C3: Actual | D3: Expected | E3: Delta | F3: % | G3: Forecasted | H3: Delta | I3: % | J3: Notes | K3: Service Requests
A4: {=Sites[Site]} -> Alamosa School District | B4: {=Sites[State]} -> CO | C4: 0 | D4: 227560 | G4: 138607 | I4: =IFERROR(H4/G4, "") -> 0 | J4: 1. Site is offline from 05/21/2024 | K4: 1. SR084949, SR084239
A5: San Luis Valley | B5: CO | C5: 180611.69 | D5: 168822.4 | E5: =IF(AND(ISNUMBER(C5),ISNUMBER(D5)), C5-D5, "") -> 11789.291 | F5: =IFERROR(E5/D5, "") -> 0.069832503 | H5: 180611.69 | I5: =IFERROR(H5/G5, "")
A6: Golden NREL 2 | B6: CO | C6: 14311 | D6: 12796 | E6: =IF(AND(ISNUMBER(C6),ISNUMBER(D6)), C6-D6, "") -> 1515 | F6: =IFERROR(E6/D6, "") -> 0.11839637 | G6: 13950 | H6: =IF(AND(ISNUMBER(C6),ISNUMBER(G6)), C6-G6, "") -> 361 | I6: =IFERROR(H6/G6, "") -> 0.025878136
A7: Golden NREL Wind 3 | B7: CO | C7: 28261 | D7: 81324 | E7: =IF(AND(ISNUMBER(C7),ISNUMBER(D7)), C7-D7, "") -> -53063 | F7: =IFERROR(E7/D7, "") -> -0.65248881 | G7: 0 | H7: =IF(AND(ISNUMBER(C7),ISNUMBER(G7)), C7-G7, "") -> 28261 | I7: =IFERROR(H7/G7, "") | J7: 1. Site started communicating in Also Energy from 6/11.
A8: Pratt Solar Farm | B8: KS | C8: 764240 | D8: 1071468 | E8: =IF(AND(ISNUMBER(C8),ISNUMBER(D8)), C8-D8, "") -> -307228 | F8: =IFERROR(E8/D8, "") -> -0.28673558 | G8: 1137039 | H8: =IF(AND(ISNUMBER(C8),ISNUMBER(G8)), C8-G8, "") -> -372799 | I8: =IFERROR(H8/G8, "") -> -0.32786826 | J8: 1. Inverter 2 tripped offline at 15:00 on 06/15 and back online 06/24 at 14:45 2. Inverter 1 is derated by 1MW on 06/01 and back to expected production on 06/02 and inverter again derated on 06/02, back to expected production on 06/03 3. Inverter 1 started late on 06/09. 4. Inverter 2 is underperforming 550kW compared to inverter 1 for whole month. | K8: 1. SR086275 2. SR085401 3. SR085772 4. SR085507
A9: Rochester - 5516 Valleyhigh NW | B9: MN | C9: 732066 | D9: 2297776 | E9: =IF(AND(ISNUMBER(C9),ISNUMBER(D9)), C9-D9, "") -> -1565710 | F9: =IFERROR(E9/D9, "") -> -0.68140236 | G9: 2608364 | H9: =IF(AND(ISNUMBER(C9),ISNUMBER(G9)), C9-G9, "") -> -1876298 | I9: =IFERROR(H9/G9, "") -> -0.71933902 | J9: 1. Inverters 29,30, 51,52,60 are perfroming low compared to peers due to issue with trackers 2. Inverter 64 tripped offline at 09:00 on 06/18 and back online at 16:00 on the same day 3. Inverter 80 tripped offline at 07:15 on 06/25 and back online on 06/26 4. Inverter 1 is offline from 05/21 and is still offline 5. Inverter 27 is from 05/23 and is still offline 6. Inverter 35 is offline from 05/18 and is still offline 7. Inverter 49 is offline from 05/25 and is still offline 8. Inverter 71 is offline from 05/05 and is still offline 9. Inverter 40 is offline from 05/29 and is still offline 10. Meter MV 2 is not communicated for whole month. | K9: 1. SR085269 2. SR086382 3. SR086892 4. SR085262 5. SR085263 6. SR085264 7. SR085265 8. SR085266 9. SR085294 10. SR085267
A10: Warsaw - 2201 Richmond | B10: VA | C10: 1179260.8 | D10: 1131652 | E10: =IF(AND(ISNUMBER(C10),ISNUMBER(D10)), C10-D10, "") -> 47608.8 | F10: =IFERROR(E10/D10, "") -> 0.042070177 | G10: 1193055 | H10: =IF(AND(ISNUMBER(C10),ISNUMBER(G10)), C10-G10, "") -> -13794.2 | I10: =IFERROR(H10/G10, "") -> -0.011562082 | J10: 1. Inverter 31 is derating during peak hours due to fan fault from 06/01 and fan replaced on 06/26 2. Site tripped offline at 11:00 on 06/20 and back online at 12:45 on 06/26 | K10: 1. SR085551 2. SR086496
A11: Mount Jackson - Randolf | B11: VA | C11: 769106.9 | D11: 866456.3 | E11: =IF(AND(ISNUMBER(C11),ISNUMBER(D11)), C11-D11, "") -> -97349.4 | F11: =IFERROR(E11/D11, "") -> -0.1123535 | G11: 828310.8 | H11: =IF(AND(ISNUMBER(C11),ISNUMBER(G11)), C11-G11, "") -> -59203.9 | I11: =IFERROR(H11/G11, "") -> -0.071475465 | J11: 1. Inverter 24 tripped offline at 16:30 on 06/06 and back online the next day. Inverter 24 again tripped offline at 17:15 on 06/17 and back online the next day 2. Site offline from 13:15 to 18:45 on 06/09 due to utility outage. Site again offline from 09:15 to 13:00 on 06/11 due to utility outage. 3. Inverters 13 and 20 are undeperforming compared to peers and back to expected production on 06/26 4. Inverter 15 tripped offline at 15:30 on 06/18 and back online on 06/19 5. Inverter 9 tripped offline at 10:15 on 06/23 and back online on next day | K11: 1. SR085722 2. SR085785 3. SR086324 4. SR086416 5. SR086758
A12: Callands Gretna - Monroe | B12: VA | C12: 552581 | D12: 472595.2 | E12: =IF(AND(ISNUMBER(C12),ISNUMBER(D12)), C12-D12, "") -> 79985.8 | F12: =IFERROR(E12/D12, "") -> 0.16924802 | G12: 582500 | H12: =IF(AND(ISNUMBER(C12),ISNUMBER(G12)), C12-G12, "") -> -29919 | I12: =IFERROR(H12/G12, "") -> -0.05136309 | J12: 1. Inverters 6 and 10 tripped offline on 06/07 and back online at 18:30 on 06/11 but were curtailed to 50%. Inverters 6 and 10 started producing at rated capacity since 06/18 2. Site production sligthly dropping due to stuck trackers | K12: 1. SR085882 2. SR087034, SR087035, SR087036
A13: Rockbridge Baths - Small Mouth Bass | B13: VA | C13: 485752.3 | D13: 491970.7 | E13: =IF(AND(ISNUMBER(C13),ISNUMBER(D13)), C13-D13, "") -> -6218.4 | F13: =IFERROR(E13/D13, "") -> -0.012639777 | G13: 554750 | H13: =IF(AND(ISNUMBER(C13),ISNUMBER(G13)), C13-G13, "") -> -68997.7 | I13: =IFERROR(H13/G13, "") -> -0.12437621 | J13: 1. Inverter 17 is underperforming by 28 kW and Inverter 18 is underperforming by 14kW according to site drawing. | K13: 1. SR086325
E14: =IF(AND(ISNUMBER(C14),ISNUMBER(D14)), C14-D14, "") | F14: =IFERROR(E14/D14, "") | H14: =IF(AND(ISNUMBER(C14),ISNUMBER(G14)), C14-G14, "") | I14: =IFERROR(H14/G14, "")
E15: =IF(AND(ISNUMBER(C15),ISNUMBER(D15)), C15-D15, "") | F15: =IFERROR(E15/D15, "") | H15: =IF(AND(ISNUMBER(C15),ISNUMBER(G15)), C15-G15, "") | I15: =IFERROR(H15/G15, "")
E16: =IF(AND(ISNUMBER(C16),ISNUMBER(D16)), C16-D16, "") | F16: =IFERROR(E16/D16, "") | H16: =IF(AND(ISNUMBER(C16),ISNUMBER(G16)), C16-G16, "") | I16: =IFERROR(H16/G16, "")
E17: =IF(AND(ISNUMBER(C17),ISNUMBER(D17)), C17-D17, "") | F17: =IFERROR(E17/D17, "") | H17: =IF(AND(ISNUMBER(C17),ISNUMBER(G17)), C17-G17, "") | I17: =IFERROR(H17/G17, "")

Sheet Jul
A1: {=portfolio} -> Ecofin | D1: July Actual v. Expected | G1: July Actual v. Forecasted
A2: Total | C2: =SUM(C4:C100) -> 0 | D2: =SUM(D4:D100) -> 0 | E2: =C2-D2 -> 0 | F2: =IFERROR(E2/D2, 0) -> 0 | G2: =SUM(G4:G100) -> 0 | H2: =C2-G2 -> 0 | I2: =IFERROR(H2/G2, 0) -> 0 | J2: =IF(AND(TODAY()>DATE(2024, 7, 1), COUNTA(Sites[Site])<>(COUNT(C:C)-1)), "Some sites are missing actual data; if new sites were added, make sure they are aligned correctly (including prior months!)", "") -> Some sites are missing actual data; if new sites were added, make sure they are aligned correctly (including prior months!)
A3: Site | B3: State | C3: Actual | D3: Expected | E3: Delta | F3: % | G3: Forecasted | H3: Delta | I3: % | J3: Notes | K3: Service Requests
A4: {=Sites[Site]} -> Alamosa School District | B4: {=Sites[State]} -> CO | E4: =IF(AND(ISNUMBER(C4),ISNUMBER(D4)), C4-D4, "") | F4: =IFERROR(E4/D4, "") | H4: =IF(AND(ISNUMBER(C4),ISNUMBER(G4)), C4-G4, "") | I4: =IFERROR(H4/G4, "")
A5: San Luis Valley | B5: CO | E5: =IF(AND(ISNUMBER(C5),ISNUMBER(D5)), C5-D5, "") | F5: =IFERROR(E5/D5, "") | H5: =IF(AND(ISNUMBER(C5),ISNUMBER(G5)), C5-G5, "") | I5: =IFERROR(H5/G5, "")
A6: Golden NREL 2 | B6: CO | E6: =IF(AND(ISNUMBER(C6),ISNUMBER(D6)), C6-D6, "") | F6: =IFERROR(E6/D6, "") | H6: =IF(AND(ISNUMBER(C6),ISNUMBER(G6)), C6-G6, "") | I6: =IFERROR(H6/G6, "")
A7: Golden NREL Wind 3 | B7: CO | E7: =IF(AND(ISNUMBER(C7),ISNUMBER(D7)), C7-D7, "") | F7: =IFERROR(E7/D7, "") | H7: =IF(AND(ISNUMBER(C7),ISNUMBER(G7)), C7-G7, "") | I7: =IFERROR(H7/G7, "")
A8: Pratt Solar Farm | B8: KS | E8: =IF(AND(ISNUMBER(C8),ISNUMBER(D8)), C8-D8, "") | F8: =IFERROR(E8/D8, "") | H8: =IF(AND(ISNUMBER(C8),ISNUMBER(G8)), C8-G8, "") | I8: =IFERROR(H8/G8, "")
A9: Rochester - 5516 Valleyhigh NW | B9: MN | E9: =IF(AND(ISNUMBER(C9),ISNUMBER(D9)), C9-D9, "") | F9: =IFERROR(E9/D9, "") | H9: =IF(AND(ISNUMBER(C9),ISNUMBER(G9)), C9-G9, "") | I9: =IFERROR(H9/G9, "")
A10: Warsaw - 2201 Richmond | B10: VA | E10: =IF(AND(ISNUMBER(C10),ISNUMBER(D10)), C10-D10, "") | F10: =IFERROR(E10/D10, "") | H10: =IF(AND(ISNUMBER(C10),ISNUMBER(G10)), C10-G10, "") | I10: =IFERROR(H10/G10, "")
A11: Mount Jackson - Randolf | B11: VA | E11: =IF(AND(ISNUMBER(C11),ISNUMBER(D11)), C11-D11, "") | F11: =IFERROR(E11/D11, "") | H11: =IF(AND(ISNUMBER(C11),ISNUMBER(G11)), C11-G11, "") | I11: =IFERROR(H11/G11, "")
A12: Callands Gretna - Monroe | B12: VA | E12: =IF(AND(ISNUMBER(C12),ISNUMBER(D12)), C12-D12, "") | F12: =IFERROR(E12/D12, "") | H12: =IF(AND(ISNUMBER(C12),ISNUMBER(G12)), C12-G12, "") | I12: =IFERROR(H12/G12, "")
A13: Rockbridge Baths - Small Mouth Bass | B13: VA | E13: =IF(AND(ISNUMBER(C13),ISNUMBER(D13)), C13-D13, "") | F13: =IFERROR(E13/D13, "") | H13: =IF(AND(ISNUMBER(C13),ISNUMBER(G13)), C13-G13, "") | I13: =IFERROR(H13/G13, "")
E14: =IF(AND(ISNUMBER(C14),ISNUMBER(D14)), C14-D14, "") | F14: =IFERROR(E14/D14, "") | H14: =IF(AND(ISNUMBER(C14),ISNUMBER(G14)), C14-G14, "") | I14: =IFERROR(H14/G14, "")
E15: =IF(AND(ISNUMBER(C15),ISNUMBER(D15)), C15-D15, "") | F15: =IFERROR(E15/D15, "") | H15: =IF(AND(ISNUMBER(C15),ISNUMBER(G15)), C15-G15, "") | I15: =IFERROR(H15/G15, "")
E16: =IF(AND(ISNUMBER(C16),ISNUMBER(D16)), C16-D16, "") | F16: =IFERROR(E16/D16, "") | H16: =IF(AND(ISNUMBER(C16),ISNUMBER(G16)), C16-G16, "") | I16: =IFERROR(H16/G16, "")
E17: =IF(AND(ISNUMBER(C17),ISNUMBER(D17)), C17-D17, "") | F17: =IFERROR(E17/D17, "") | H17: =IF(AND(ISNUMBER(C17),ISNUMBER(G17)), C17-G17, "") | I17: =IFERROR(H17/G17, "")

Sheet Aug
A1: {=portfolio} -> Ecofin | D1: August Actual v. Expected | G1: August Actual v. Forecasted
A2: Total | C2: =SUM(C4:C100) -> 0 | D2: =SUM(D4:D100) -> 0 | E2: =C2-D2 -> 0 | F2: =IFERROR(E2/D2, 0) -> 0 | G2: =SUM(G4:G100) -> 0 | H2: =C2-G2 -> 0 | I2: =IFERROR(H2/G2, 0) -> 0 | J2: =IF(AND(TODAY()>DATE(2024, 8, 1), COUNTA(Sites[Site])<>(COUNT(C:C)-1)), "Some sites are missing actual data; if new sites were added, make sure they are aligned correctly (including prior months!)", "") -> Some sites are missing actual data; if new sites were added, make sure they are aligned correctly (including prior months!)
A3: Site | B3: State | C3: Actual | D3: Expected | E3: Delta | F3: % | G3: Forecasted | H3: Delta | I3: % | J3: Notes | K3: Service Requests
A4: {=Sites[Site]} -> Alamosa School District | B4: {=Sites[State]} -> CO | E4: =IF(AND(ISNUMBER(C4),ISNUMBER(D4)), C4-D4, "") | F4: =IFERROR(E4/D4, "") | H4: =IF(AND(ISNUMBER(C4),ISNUMBER(G4)), C4-G4, "") | I4: =IFERROR(H4/G4, "")
A5: San Luis Valley | B5: CO | E5: =IF(AND(ISNUMBER(C5),ISNUMBER(D5)), C5-D5, "") | F5: =IFERROR(E5/D5, "") | H5: =IF(AND(ISNUMBER(C5),ISNUMBER(G5)), C5-G5, "") | I5: =IFERROR(H5/G5, "")
A6: Golden NREL 2 | B6: CO | E6: =IF(AND(ISNUMBER(C6),ISNUMBER(D6)), C6-D6, "") | F6: =IFERROR(E6/D6, "") | H6: =IF(AND(ISNUMBER(C6),ISNUMBER(G6)), C6-G6, "") | I6: =IFERROR(H6/G6, "")
A7: Golden NREL Wind 3 | B7: CO | E7: =IF(AND(ISNUMBER(C7),ISNUMBER(D7)), C7-D7, "") | F7: =IFERROR(E7/D7, "") | H7: =IF(AND(ISNUMBER(C7),ISNUMBER(G7)), C7-G7, "") | I7: =IFERROR(H7/G7, "")
A8: Pratt Solar Farm | B8: KS | E8: =IF(AND(ISNUMBER(C8),ISNUMBER(D8)), C8-D8, "") | F8: =IFERROR(E8/D8, "") | H8: =IF(AND(ISNUMBER(C8),ISNUMBER(G8)), C8-G8, "") | I8: =IFERROR(H8/G8, "")
A9: Rochester - 5516 Valleyhigh NW | B9: MN | E9: =IF(AND(ISNUMBER(C9),ISNUMBER(D9)), C9-D9, "") | F9: =IFERROR(E9/D9, "") | H9: =IF(AND(ISNUMBER(C9),ISNUMBER(G9)), C9-G9, "") | I9: =IFERROR(H9/G9, "")
A10: Warsaw - 2201 Richmond | B10: VA | E10: =IF(AND(ISNUMBER(C10),ISNUMBER(D10)), C10-D10, "") | F10: =IFERROR(E10/D10, "") | H10: =IF(AND(ISNUMBER(C10),ISNUMBER(G10)), C10-G10, "") | I10: =IFERROR(H10/G10, "")
A11: Mount Jackson - Randolf | B11: VA | E11: =IF(AND(ISNUMBER(C11),ISNUMBER(D11)), C11-D11, "") | F11: =IFERROR(E11/D11, "") | H11: =IF(AND(ISNUMBER(C11),ISNUMBER(G11)), C11-G11, "") | I11: =IFERROR(H11/G11, "")
A12: Callands Gretna - Monroe | B12: VA | E12: =IF(AND(ISNUMBER(C12),ISNUMBER(D12)), C12-D12, "") | F12: =IFERROR(E12/D12, "") | H12: =IF(AND(ISNUMBER(C12),ISNUMBER(G12)), C12-G12, "") | I12: =IFERROR(H12/G12, "")
A13: Rockbridge Baths - Small Mouth Bass | B13: VA | E13: =IF(AND(ISNUMBER(C13),ISNUMBER(D13)), C13-D13, "") | F13: =IFERROR(E13/D13, "") | H13: =IF(AND(ISNUMBER(C13),ISNUMBER(G13)), C13-G13, "") | I13: =IFERROR(H13/G13, "")
E14: =IF(AND(ISNUMBER(C14),ISNUMBER(D14)), C14-D14, "") | F14: =IFERROR(E14/D14, "") | H14: =IF(AND(ISNUMBER(C14),ISNUMBER(G14)), C14-G14, "") | I14: =IFERROR(H14/G14, "")
E15: =IF(AND(ISNUMBER(C15),ISNUMBER(D15)), C15-D15, "") | F15: =IFERROR(E15/D15, "") | H15: =IF(AND(ISNUMBER(C15),ISNUMBER(G15)), C15-G15, "") | I15: =IFERROR(H15/G15, "")
E16: =IF(AND(ISNUMBER(C16),ISNUMBER(D16)), C16-D16, "") | F16: =IFERROR(E16/D16, "") | H16: =IF(AND(ISNUMBER(C16),ISNUMBER(G16)), C16-G16, "") | I16: =IFERROR(H16/G16, "")
E17: =IF(AND(ISNUMBER(C17),ISNUMBER(D17)), C17-D17, "") | F17: =IFERROR(E17/D17, "") | H17: =IF(AND(ISNUMBER(C17),ISNUMBER(G17)), C17-G17, "") | I17: =IFERROR(H17/G17, "")

Sheet Sep
A1: {=portfolio} -> Ecofin | D1: September Actual v. Expected | G1: September Actual v. Forecasted
A2: Total | C2: =SUM(C4:C100) -> 0 | D2: =SUM(D4:D100) -> 0 | E2: =C2-D2 -> 0 | F2: =IFERROR(E2/D2, 0) -> 0 | G2: =SUM(G4:G100) -> 0 | H2: =C2-G2 -> 0 | I2: =IFERROR(H2/G2, 0) -> 0 | J2: =IF(AND(TODAY()>DATE(2024, 9, 1), COUNTA(Sites[Site])<>(COUNT(C:C)-1)), "Some sites are missing actual data; if new sites were added, make sure they are aligned correctly (including prior months!)", "")
A3: Site | B3: State | C3: Actual | D3: Expected | E3: Delta | F3: % | G3: Forecasted | H3: Delta | I3: % | J3: Notes | K3: Service Requests
A4: {=Sites[Site]} -> Alamosa School District | B4: {=Sites[State]} -> CO | E4: =IF(AND(ISNUMBER(C4),ISNUMBER(D4)), C4-D4, "") | F4: =IFERROR(E4/D4, "") | H4: =IF(AND(ISNUMBER(C4),ISNUMBER(G4)), C4-G4, "") | I4: =IFERROR(H4/G4, "")
A5: San Luis Valley | B5: CO | E5: =IF(AND(ISNUMBER(C5),ISNUMBER(D5)), C5-D5, "") | F5: =IFERROR(E5/D5, "") | H5: =IF(AND(ISNUMBER(C5),ISNUMBER(G5)), C5-G5, "") | I5: =IFERROR(H5/G5, "")
A6: Golden NREL 2 | B6: CO | E6: =IF(AND(ISNUMBER(C6),ISNUMBER(D6)), C6-D6, "") | F6: =IFERROR(E6/D6, "") | H6: =IF(AND(ISNUMBER(C6),ISNUMBER(G6)), C6-G6, "") | I6: =IFERROR(H6/G6, "")
A7: Golden NREL Wind 3 | B7: CO | E7: =IF(AND(ISNUMBER(C7),ISNUMBER(D7)), C7-D7, "") | F7: =IFERROR(E7/D7, "") | H7: =IF(AND(ISNUMBER(C7),ISNUMBER(G7)), C7-G7, "") | I7: =IFERROR(H7/G7, "")
A8: Pratt Solar Farm | B8: KS | E8: =IF(AND(ISNUMBER(C8),ISNUMBER(D8)), C8-D8, "") | F8: =IFERROR(E8/D8, "") | H8: =IF(AND(ISNUMBER(C8),ISNUMBER(G8)), C8-G8, "") | I8: =IFERROR(H8/G8, "")
A9: Rochester - 5516 Valleyhigh NW | B9: MN | E9: =IF(AND(ISNUMBER(C9),ISNUMBER(D9)), C9-D9, "") | F9: =IFERROR(E9/D9, "") | H9: =IF(AND(ISNUMBER(C9),ISNUMBER(G9)), C9-G9, "") | I9: =IFERROR(H9/G9, "")
A10: Warsaw - 2201 Richmond | B10: VA | E10: =IF(AND(ISNUMBER(C10),ISNUMBER(D10)), C10-D10, "") | F10: =IFERROR(E10/D10, "") | H10: =IF(AND(ISNUMBER(C10),ISNUMBER(G10)), C10-G10, "") | I10: =IFERROR(H10/G10, "")
A11: Mount Jackson - Randolf | B11: VA | E11: =IF(AND(ISNUMBER(C11),ISNUMBER(D11)), C11-D11, "") | F11: =IFERROR(E11/D11, "") | H11: =IF(AND(ISNUMBER(C11),ISNUMBER(G11)), C11-G11, "") | I11: =IFERROR(H11/G11, "")
A12: Callands Gretna - Monroe | B12: VA | E12: =IF(AND(ISNUMBER(C12),ISNUMBER(D12)), C12-D12, "") | F12: =IFERROR(E12/D12, "") | H12: =IF(AND(ISNUMBER(C12),ISNUMBER(G12)), C12-G12, "") | I12: =IFERROR(H12/G12, "")
A13: Rockbridge Baths - Small Mouth Bass | B13: VA | E13: =IF(AND(ISNUMBER(C13),ISNUMBER(D13)), C13-D13, "") | F13: =IFERROR(E13/D13, "") | H13: =IF(AND(ISNUMBER(C13),ISNUMBER(G13)), C13-G13, "") | I13: =IFERROR(H13/G13, "")
E14: =IF(AND(ISNUMBER(C14),ISNUMBER(D14)), C14-D14, "") | F14: =IFERROR(E14/D14, "") | H14: =IF(AND(ISNUMBER(C14),ISNUMBER(G14)), C14-G14, "") | I14: =IFERROR(H14/G14, "")
E15: =IF(AND(ISNUMBER(C15),ISNUMBER(D15)), C15-D15, "") | F15: =IFERROR(E15/D15, "") | H15: =IF(AND(ISNUMBER(C15),ISNUMBER(G15)), C15-G15, "") | I15: =IFERROR(H15/G15, "")
E16: =IF(AND(ISNUMBER(C16),ISNUMBER(D16)), C16-D16, "") | F16: =IFERROR(E16/D16, "") | H16: =IF(AND(ISNUMBER(C16),ISNUMBER(G16)), C16-G16, "") | I16: =IFERROR(H16/G16, "")
E17: =IF(AND(ISNUMBER(C17),ISNUMBER(D17)), C17-D17, "") | F17: =IFERROR(E17/D17, "") | H17: =IF(AND(ISNUMBER(C17),ISNUMBER(G17)), C17-G17, "") | I17: =IFERROR(H17/G17, "")

Sheet Oct
A1: {=portfolio} -> Ecofin | D1: October Actual v. Expected | G1: October Actual v. Forecasted
A2: Total | C2: =SUM(C4:C100) -> 0 | D2: =SUM(D4:D100) -> 0 | E2: =C2-D2 -> 0 | F2: =IFERROR(E2/D2, 0) -> 0 | G2: =SUM(G4:G100) -> 0 | H2: =C2-G2 -> 0 | I2: =IFERROR(H2/G2, 0) -> 0 | J2: =IF(AND(TODAY()>DATE(2024, 10, 1), COUNTA(Sites[Site])<>(COUNT(C:C)-1)), "Some sites are missing actual data; if new sites were added, make sure they are aligned correctly (including prior months!)", "")
A3: Site | B3: State | C3: Actual | D3: Expected | E3: Delta | F3: % | G3: Forecasted | H3: Delta | I3: % | J3: Notes | K3: Service Requests
A4: {=Sites[Site]} -> Alamosa School District | B4: {=Sites[State]} -> CO | E4: =IF(AND(ISNUMBER(C4),ISNUMBER(D4)), C4-D4, "") | F4: =IFERROR(E4/D4, "") | H4: =IF(AND(ISNUMBER(C4),ISNUMBER(G4)), C4-G4, "") | I4: =IFERROR(H4/G4, "")
A5: San Luis Valley | B5: CO | E5: =IF(AND(ISNUMBER(C5),ISNUMBER(D5)), C5-D5, "") | F5: =IFERROR(E5/D5, "") | H5: =IF(AND(ISNUMBER(C5),ISNUMBER(G5)), C5-G5, "") | I5: =IFERROR(H5/G5, "")
A6: Golden NREL 2 | B6: CO | E6: =IF(AND(ISNUMBER(C6),ISNUMBER(D6)), C6-D6, "") | F6: =IFERROR(E6/D6, "") | H6: =IF(AND(ISNUMBER(C6),ISNUMBER(G6)), C6-G6, "") | I6: =IFERROR(H6/G6, "")
A7: Golden NREL Wind 3 | B7: CO | E7: =IF(AND(ISNUMBER(C7),ISNUMBER(D7)), C7-D7, "") | F7: =IFERROR(E7/D7, "") | H7: =IF(AND(ISNUMBER(C7),ISNUMBER(G7)), C7-G7, "") | I7: =IFERROR(H7/G7, "")
A8: Pratt Solar Farm | B8: KS | E8: =IF(AND(ISNUMBER(C8),ISNUMBER(D8)), C8-D8, "") | F8: =IFERROR(E8/D8, "") | H8: =IF(AND(ISNUMBER(C8),ISNUMBER(G8)), C8-G8, "") | I8: =IFERROR(H8/G8, "")
A9: Rochester - 5516 Valleyhigh NW | B9: MN | E9: =IF(AND(ISNUMBER(C9),ISNUMBER(D9)), C9-D9, "") | F9: =IFERROR(E9/D9, "") | H9: =IF(AND(ISNUMBER(C9),ISNUMBER(G9)), C9-G9, "") | I9: =IFERROR(H9/G9, "")
A10: Warsaw - 2201 Richmond | B10: VA | E10: =IF(AND(ISNUMBER(C10),ISNUMBER(D10)), C10-D10, "") | F10: =IFERROR(E10/D10, "") | H10: =IF(AND(ISNUMBER(C10),ISNUMBER(G10)), C10-G10, "") | I10: =IFERROR(H10/G10, "")
A11: Mount Jackson - Randolf | B11: VA | E11: =IF(AND(ISNUMBER(C11),ISNUMBER(D11)), C11-D11, "") | F11: =IFERROR(E11/D11, "") | H11: =IF(AND(ISNUMBER(C11),ISNUMBER(G11)), C11-G11, "") | I11: =IFERROR(H11/G11, "")
A12: Callands Gretna - Monroe | B12: VA | E12: =IF(AND(ISNUMBER(C12),ISNUMBER(D12)), C12-D12, "") | F12: =IFERROR(E12/D12, "") | H12: =IF(AND(ISNUMBER(C12),ISNUMBER(G12)), C12-G12, "") | I12: =IFERROR(H12/G12, "")
A13: Rockbridge Baths - Small Mouth Bass | B13: VA | E13: =IF(AND(ISNUMBER(C13),ISNUMBER(D13)), C13-D13, "") | F13: =IFERROR(E13/D13, "") | H13: =IF(AND(ISNUMBER(C13),ISNUMBER(G13)), C13-G13, "") | I13: =IFERROR(H13/G13, "")
E14: =IF(AND(ISNUMBER(C14),ISNUMBER(D14)), C14-D14, "") | F14: =IFERROR(E14/D14, "") | H14: =IF(AND(ISNUMBER(C14),ISNUMBER(G14)), C14-G14, "") | I14: =IFERROR(H14/G14, "")
E15: =IF(AND(ISNUMBER(C15),ISNUMBER(D15)), C15-D15, "") | F15: =IFERROR(E15/D15, "") | H15: =IF(AND(ISNUMBER(C15),ISNUMBER(G15)), C15-G15, "") | I15: =IFERROR(H15/G15, "")
E16: =IF(AND(ISNUMBER(C16),ISNUMBER(D16)), C16-D16, "") | F16: =IFERROR(E16/D16, "") | H16: =IF(AND(ISNUMBER(C16),ISNUMBER(G16)), C16-G16, "") | I16: =IFERROR(H16/G16, "")
E17: =IF(AND(ISNUMBER(C17),ISNUMBER(D17)), C17-D17, "") | F17: =IFERROR(E17/D17, "") | H17: =IF(AND(ISNUMBER(C17),ISNUMBER(G17)), C17-G17, "") | I17: =IFERROR(H17/G17, "")

Sheet Nov
A1: {=portfolio} -> Ecofin | D1: November Actual v. Expected | G1: November Actual v. Forecasted
A2: Total | C2: =SUM(C4:C100) -> 0 | D2: =SUM(D4:D100) -> 0 | E2: =C2-D2 -> 0 | F2: =IFERROR(E2/D2, 0) -> 0 | G2: =SUM(G4:G100) -> 0 | H2: =C2-G2 -> 0 | I2: =IFERROR(H2/G2, 0) -> 0 | J2: =IF(AND(TODAY()>DATE(2024, 11, 1), COUNTA(Sites[Site])<>(COUNT(C:C)-1)), "Some sites are missing actual data; if new sites were added, make sure they are aligned correctly (including prior months!)", "")
A3: Site | B3: State | C3: Actual | D3: Expected | E3: Delta | F3: % | G3: Forecasted | H3: Delta | I3: % | J3: Notes | K3: Service Requests
A4: {=Sites[Site]} -> Alamosa School District | B4: {=Sites[State]} -> CO | E4: =IF(AND(ISNUMBER(C4),ISNUMBER(D4)), C4-D4, "") | F4: =IFERROR(E4/D4, "") | H4: =IF(AND(ISNUMBER(C4),ISNUMBER(G4)), C4-G4, "") | I4: =IFERROR(H4/G4, "")
A5: San Luis Valley | B5: CO | E5: =IF(AND(ISNUMBER(C5),ISNUMBER(D5)), C5-D5, "") | F5: =IFERROR(E5/D5, "") | H5: =IF(AND(ISNUMBER(C5),ISNUMBER(G5)), C5-G5, "") | I5: =IFERROR(H5/G5, "")
A6: Golden NREL 2 | B6: CO | E6: =IF(AND(ISNUMBER(C6),ISNUMBER(D6)), C6-D6, "") | F6: =IFERROR(E6/D6, "") | H6: =IF(AND(ISNUMBER(C6),ISNUMBER(G6)), C6-G6, "") | I6: =IFERROR(H6/G6, "")
A7: Golden NREL Wind 3 | B7: CO | E7: =IF(AND(ISNUMBER(C7),ISNUMBER(D7)), C7-D7, "") | F7: =IFERROR(E7/D7, "") | H7: =IF(AND(ISNUMBER(C7),ISNUMBER(G7)), C7-G7, "") | I7: =IFERROR(H7/G7, "")
A8: Pratt Solar Farm | B8: KS | E8: =IF(AND(ISNUMBER(C8),ISNUMBER(D8)), C8-D8, "") | F8: =IFERROR(E8/D8, "") | H8: =IF(AND(ISNUMBER(C8),ISNUMBER(G8)), C8-G8, "") | I8: =IFERROR(H8/G8, "")
A9: Rochester - 5516 Valleyhigh NW | B9: MN | E9: =IF(AND(ISNUMBER(C9),ISNUMBER(D9)), C9-D9, "") | F9: =IFERROR(E9/D9, "") | H9: =IF(AND(ISNUMBER(C9),ISNUMBER(G9)), C9-G9, "") | I9: =IFERROR(H9/G9, "")
A10: Warsaw - 2201 Richmond | B10: VA | E10: =IF(AND(ISNUMBER(C10),ISNUMBER(D10)), C10-D10, "") | F10: =IFERROR(E10/D10, "") | H10: =IF(AND(ISNUMBER(C10),ISNUMBER(G10)), C10-G10, "") | I10: =IFERROR(H10/G10, "")
A11: Mount Jackson - Randolf | B11: VA | E11: =IF(AND(ISNUMBER(C11),ISNUMBER(D11)), C11-D11, "") | F11: =IFERROR(E11/D11, "") | H11: =IF(AND(ISNUMBER(C11),ISNUMBER(G11)), C11-G11, "") | I11: =IFERROR(H11/G11, "")
A12: Callands Gretna - Monroe | B12: VA | E12: =IF(AND(ISNUMBER(C12),ISNUMBER(D12)), C12-D12, "") | F12: =IFERROR(E12/D12, "") | H12: =IF(AND(ISNUMBER(C12),ISNUMBER(G12)), C12-G12, "") | I12: =IFERROR(H12/G12, "")
A13: Rockbridge Baths - Small Mouth Bass | B13: VA | E13: =IF(AND(ISNUMBER(C13),ISNUMBER(D13)), C13-D13, "") | F13: =IFERROR(E13/D13, "") | H13: =IF(AND(ISNUMBER(C13),ISNUMBER(G13)), C13-G13, "") | I13: =IFERROR(H13/G13, "")
E14: =IF(AND(ISNUMBER(C14),ISNUMBER(D14)), C14-D14, "") | F14: =IFERROR(E14/D14, "") | H14: =IF(AND(ISNUMBER(C14),ISNUMBER(G14)), C14-G14, "") | I14: =IFERROR(H14/G14, "")
E15: =IF(AND(ISNUMBER(C15),ISNUMBER(D15)), C15-D15, "") | F15: =IFERROR(E15/D15, "") | H15: =IF(AND(ISNUMBER(C15),ISNUMBER(G15)), C15-G15, "") | I15: =IFERROR(H15/G15, "")
E16: =IF(AND(ISNUMBER(C16),ISNUMBER(D16)), C16-D16, "") | F16: =IFERROR(E16/D16, "") | H16: =IF(AND(ISNUMBER(C16),ISNUMBER(G16)), C16-G16, "") | I16: =IFERROR(H16/G16, "")
E17: =IF(AND(ISNUMBER(C17),ISNUMBER(D17)), C17-D17, "") | F17: =IFERROR(E17/D17, "") | H17: =IF(AND(ISNUMBER(C17),ISNUMBER(G17)), C17-G17, "") | I17: =IFERROR(H17/G17, "")

Sheet Dec
A1: {=portfolio} -> Ecofin | D1: December Actual v. Expected | G1: December Actual v. Forecasted
A2: Total | C2: =SUM(C4:C100) -> 0 | D2: =SUM(D4:D100) -> 0 | E2: =C2-D2 -> 0 | F2: =IFERROR(E2/D2, 0) -> 0 | G2: =SUM(G4:G100) -> 0 | H2: =C2-G2 -> 0 | I2: =IFERROR(H2/G2, 0) -> 0 | J2: =IF(AND(TODAY()>DATE(2024, 12, 1), COUNTA(Sites[Site])<>(COUNT(C:C)-1)), "Some sites are missing actual data; if new sites were added, make sure they are aligned correctly (including prior months!)", "")
A3: Site | B3: State | C3: Actual | D3: Expected | E3: Delta | F3: % | G3: Forecasted | H3: Delta | I3: % | J3: Notes | K3: Service Requests
A4: {=Sites[Site]} -> Alamosa School District | B4: {=Sites[State]} -> CO | E4: =IF(AND(ISNUMBER(C4),ISNUMBER(D4)), C4-D4, "") | F4: =IFERROR(E4/D4, "") | H4: =IF(AND(ISNUMBER(C4),ISNUMBER(G4)), C4-G4, "") | I4: =IFERROR(H4/G4, "")
A5: San Luis Valley | B5: CO | E5: =IF(AND(ISNUMBER(C5),ISNUMBER(D5)), C5-D5, "") | F5: =IFERROR(E5/D5, "") | H5: =IF(AND(ISNUMBER(C5),ISNUMBER(G5)), C5-G5, "") | I5: =IFERROR(H5/G5, "")
