Workbook
Name JanActual: #REF!
Name JanActual2: #REF!
Name JanExpected: #REF!
Name JanExpectedDelta: #REF!
Name JanExpectedPercent: #REF!
Name JanExpPercent: #REF!
Name JanForecasted: #REF!
Name JanForecastedDelta: #REF!
Name JanForecastedPercent: #REF!
Name portfolio: Sites!$B$1:$B$1
Name Year: Sites!#REF!

Sheet Year to Date
A1: {=portfolio} -> Generate Capital | E1: Year to Date Actual v. Expected | H1: Year to Date Actual v. Forecasted
A2: Total | D2: =SUM(D4:D200) -> 1.3896069e+08 | E2: =SUM(E4:E138) -> 50703012 | F2: =D2-E2 -> 88257674 | G2: =IFERROR(F2/E2, 0) -> 1.7406791 | H2: =SUM(H4:H138) -> 83227244 | I2: =D2-H2 -> 55733442 | J2: =IFERROR(I2/H2, 0) -> 0.66965383
A3: Site | B3: State | C3: SOL# | D3: Actual | E3: Expected | F3: Delta | G3: % | H3: Forecasted | I3: Delta | J3: %
A4: {=Sites[Site]} -> Farmer | B4: {=Sites[State]} -> AZ | C4: =Sites[[#This Row],[SOL'#]] -> SOL-10748 | D4: =SUM('1st Qtr'!D4, '2nd Qtr'!D4, '3rd Qtr'!D4, '4th Qtr'!D4) -> 75721.915 | E4: =SUM('1st Qtr'!E4, '2nd Qtr'!E4, '3rd Qtr'!E4, '4th Qtr'!E4) -> 50382.136 | F4: =IF(AND(ISNUMBER(D4),ISNUMBER(E4)), D4-E4, "") -> 25339.779 | G4: =IFERROR(F4/E4, "") -> 0.50295166 | H4: =SUM('1st Qtr'!H4+'2nd Qtr'!H4+'3rd Qtr'!H4+'4th Qtr'!H4) -> 76784.887 | I4: =SUM('1st Qtr'!I4, '2nd Qtr'!I4, '3rd Qtr'!I4, '4th Qtr'!I4) -> -1062.9722 | J4: =IFERROR(I4/H4, "") -> -0.013843508
A5: Fulton | B5: AZ | C5: =Sites[[#This Row],[SOL'#]] -> SOL-10749 | D5: =SUM('1st Qtr'!D5, '2nd Qtr'!D5, '3rd Qtr'!D5, '4th Qtr'!D5) -> 303626.25 | E5: =SUM('1st Qtr'!E5, '2nd Qtr'!E5, '3rd Qtr'!E5, '4th Qtr'!E5) -> 260820.58 | F5: =IF(AND(ISNUMBER(D5),ISNUMBER(E5)), D5-E5, "") -> 42805.67 | G5: =IFERROR(F5/E5, "") -> 0.16411922 | H5: =SUM('1st Qtr'!H5+'2nd Qtr'!H5+'3rd Qtr'!H5+'4th Qtr'!H5) -> 375615.97 | I5: =SUM('1st Qtr'!I5, '2nd Qtr'!I5, '3rd Qtr'!I5, '4th Qtr'!I5) -> -71989.72 | J5: =IFERROR(I5/H5, "") -> -0.19165777
A6: JFK Elementary | B6: AZ | C6: =Sites[[#This Row],[SOL'#]] -> SOL-10758 | D6: =SUM('1st Qtr'!D6, '2nd Qtr'!D6, '3rd Qtr'!D6, '4th Qtr'!D6) -> 118765.01 | E6: =SUM('1st Qtr'!E6, '2nd Qtr'!E6, '3rd Qtr'!E6, '4th Qtr'!E6) -> 0 | F6: =IF(AND(ISNUMBER(D6),ISNUMBER(E6)), D6-E6, "") -> 118765.01 | G6: =IFERROR(F6/E6, "") | H6: =SUM('1st Qtr'!H6+'2nd Qtr'!H6+'3rd Qtr'!H6+'4th Qtr'!H6) -> 13376 | I6: =SUM('1st Qtr'!I6, '2nd Qtr'!I6, '3rd Qtr'!I6, '4th Qtr'!I6) -> 105389.01 | J6: =IFERROR(I6/H6, "") -> 7.8789631
A7: Noble | B7: AZ | C7: =Sites[[#This Row],[SOL'#]] -> SOL-10750 | D7: =SUM('1st Qtr'!D7, '2nd Qtr'!D7, '3rd Qtr'!D7, '4th Qtr'!D7) -> 59932.357 | E7: =SUM('1st Qtr'!E7, '2nd Qtr'!E7, '3rd Qtr'!E7, '4th Qtr'!E7) -> 85808.034 | F7: =IF(AND(ISNUMBER(D7),ISNUMBER(E7)), D7-E7, "") -> -25875.677 | G7: =IFERROR(F7/E7, "") -> -0.30155308 | H7: =SUM('1st Qtr'!H7+'2nd Qtr'!H7+'3rd Qtr'!H7+'4th Qtr'!H7) -> 85497.33 | I7: =SUM('1st Qtr'!I7, '2nd Qtr'!I7, '3rd Qtr'!I7, '4th Qtr'!I7) -> -25564.973 | J7: =IFERROR(I7/H7, "") -> -0.29901487
A8: Parking 3 | B8: AZ | C8: =Sites[[#This Row],[SOL'#]] -> SOL-10751 | D8: =SUM('1st Qtr'!D8, '2nd Qtr'!D8, '3rd Qtr'!D8, '4th Qtr'!D8) -> 164140.14 | E8: =SUM('1st Qtr'!E8, '2nd Qtr'!E8, '3rd Qtr'!E8, '4th Qtr'!E8) -> 181257.85 | F8: =IF(AND(ISNUMBER(D8),ISNUMBER(E8)), D8-E8, "") -> -17117.706 | G8: =IFERROR(F8/E8, "") -> -0.094438427 | H8: =SUM('1st Qtr'!H8+'2nd Qtr'!H8+'3rd Qtr'!H8+'4th Qtr'!H8) -> 202759 | I8: =SUM('1st Qtr'!I8, '2nd Qtr'!I8, '3rd Qtr'!I8, '4th Qtr'!I8) -> -38618.856 | J8: =IFERROR(I8/H8, "") -> -0.19046679
A9: PE East | B9: AZ | C9: =Sites[[#This Row],[SOL'#]] -> SOL-10752 | D9: =SUM('1st Qtr'!D9, '2nd Qtr'!D9, '3rd Qtr'!D9, '4th Qtr'!D9) -> 171365.66 | E9: =SUM('1st Qtr'!E9, '2nd Qtr'!E9, '3rd Qtr'!E9, '4th Qtr'!E9) -> 118020.26 | F9: =IF(AND(ISNUMBER(D9),ISNUMBER(E9)), D9-E9, "") -> 53345.396 | G9: =IFERROR(F9/E9, "") -> 0.45200202 | H9: =SUM('1st Qtr'!H9+'2nd Qtr'!H9+'3rd Qtr'!H9+'4th Qtr'!H9) -> 185453.2 | I9: =SUM('1st Qtr'!I9, '2nd Qtr'!I9, '3rd Qtr'!I9, '4th Qtr'!I9) -> -14087.544 | J9: =IFERROR(I9/H9, "") -> -0.075962798
A10: Schwada | B10: AZ | C10: =Sites[[#This Row],[SOL'#]] -> SOL-10753 | D10: =SUM('1st Qtr'!D10, '2nd Qtr'!D10, '3rd Qtr'!D10, '4th Qtr'!D10) -> 75807.22 | E10: =SUM('1st Qtr'!E10, '2nd Qtr'!E10, '3rd Qtr'!E10, '4th Qtr'!E10) -> 48899.349 | F10: =IF(AND(ISNUMBER(D10),ISNUMBER(E10)), D10-E10, "") -> 26907.871 | G10: =IFERROR(F10/E10, "") -> 0.55027053 | H10: =SUM('1st Qtr'!H10+'2nd Qtr'!H10+'3rd Qtr'!H10+'4th Qtr'!H10) -> 79462 | I10: =SUM('1st Qtr'!I10, '2nd Qtr'!I10, '3rd Qtr'!I10, '4th Qtr'!I10) -> -3654.7803 | J10: =IFERROR(I10/H10, "") -> -0.045994064
A11: Starshine | B11: AZ | C11: =Sites[[#This Row],[SOL'#]] -> SOL-10757 | D11: =SUM('1st Qtr'!D11, '2nd Qtr'!D11, '3rd Qtr'!D11, '4th Qtr'!D11) -> 44822.692 | E11: =SUM('1st Qtr'!E11, '2nd Qtr'!E11, '3rd Qtr'!E11, '4th Qtr'!E11) -> 0 | F11: =IF(AND(ISNUMBER(D11),ISNUMBER(E11)), D11-E11, "") -> 44822.692 | G11: =IFERROR(F11/E11, "") | H11: =SUM('1st Qtr'!H11+'2nd Qtr'!H11+'3rd Qtr'!H11+'4th Qtr'!H11) -> 0 | I11: =SUM('1st Qtr'!I11, '2nd Qtr'!I11, '3rd Qtr'!I11, '4th Qtr'!I11) -> 44822.692 | J11: =IFERROR(I11/H11, "")
A12: Yuma Airport | B12: AZ | C12: =Sites[[#This Row],[SOL'#]] -> SOL-10754 | D12: =SUM('1st Qtr'!D12, '2nd Qtr'!D12, '3rd Qtr'!D12, '4th Qtr'!D12) -> 450807 | E12: =SUM('1st Qtr'!E12, '2nd Qtr'!E12, '3rd Qtr'!E12, '4th Qtr'!E12) -> 546992.94 | F12: =IF(AND(ISNUMBER(D12),ISNUMBER(E12)), D12-E12, "") -> -96185.94 | G12: =IFERROR(F12/E12, "") -> -0.17584494 | H12: =SUM('1st Qtr'!H12+'2nd Qtr'!H12+'3rd Qtr'!H12+'4th Qtr'!H12) -> 490359 | I12: =SUM('1st Qtr'!I12, '2nd Qtr'!I12, '3rd Qtr'!I12, '4th Qtr'!I12) -> -39552 | J12: =IFERROR(I12/H12, "") -> -0.080659272
A13: Kinsman | B13: OH | C13: =Sites[[#This Row],[SOL'#]] -> SOL-10762 | D13: =SUM('1st Qtr'!D13, '2nd Qtr'!D13, '3rd Qtr'!D13, '4th Qtr'!D13) -> 502045.08 | E13: =SUM('1st Qtr'!E13, '2nd Qtr'!E13, '3rd Qtr'!E13, '4th Qtr'!E13) -> 658378.15 | F13: =IF(AND(ISNUMBER(D13),ISNUMBER(E13)), D13-E13, "") -> -156333.07 | G13: =IFERROR(F13/E13, "") -> -0.23745179 | H13: =SUM('1st Qtr'!H13+'2nd Qtr'!H13+'3rd Qtr'!H13+'4th Qtr'!H13) -> 611188 | I13: =SUM('1st Qtr'!I13, '2nd Qtr'!I13, '3rd Qtr'!I13, '4th Qtr'!I13) -> -109142.92 | J13: =IFERROR(I13/H13, "") -> -0.17857504
A14: Wooster | B14: OH | C14: =Sites[[#This Row],[SOL'#]] -> SOL-10763 | D14: =SUM('1st Qtr'!D14, '2nd Qtr'!D14, '3rd Qtr'!D14, '4th Qtr'!D14) -> 109692 | E14: =SUM('1st Qtr'!E14, '2nd Qtr'!E14, '3rd Qtr'!E14, '4th Qtr'!E14) -> 0 | F14: =IF(AND(ISNUMBER(D14),ISNUMBER(E14)), D14-E14, "") -> 109692 | G14: =IFERROR(F14/E14, "") | H14: =SUM('1st Qtr'!H14+'2nd Qtr'!H14+'3rd Qtr'!H14+'4th Qtr'!H14) -> 144252 | I14: =SUM('1st Qtr'!I14, '2nd Qtr'!I14, '3rd Qtr'!I14, '4th Qtr'!I14) -> -34560 | J14: =IFERROR(I14/H14, "") -> -0.23958073
A15: Globe Gila CC | B15: AZ | C15: =Sites[[#This Row],[SOL'#]] -> SOL-10755 | D15: =SUM('1st Qtr'!D15, '2nd Qtr'!D15, '3rd Qtr'!D15, '4th Qtr'!D15) -> 93527.907 | E15: =SUM('1st Qtr'!E15, '2nd Qtr'!E15, '3rd Qtr'!E15, '4th Qtr'!E15) -> 24864.852 | F15: =IF(AND(ISNUMBER(D15),ISNUMBER(E15)), D15-E15, "") -> 68663.055 | G15: =IFERROR(F15/E15, "") -> 2.7614504 | H15: =SUM('1st Qtr'!H15+'2nd Qtr'!H15+'3rd Qtr'!H15+'4th Qtr'!H15) -> 98117 | I15: =SUM('1st Qtr'!I15, '2nd Qtr'!I15, '3rd Qtr'!I15, '4th Qtr'!I15) -> -4589.0926 | J15: =IFERROR(I15/H15, "") -> -0.046771636
A16: Payson Gila CC | B16: AZ | C16: =Sites[[#This Row],[SOL'#]] -> SOL-10756 | D16: =SUM('1st Qtr'!D16, '2nd Qtr'!D16, '3rd Qtr'!D16, '4th Qtr'!D16) -> 66907.077 | E16: =SUM('1st Qtr'!E16, '2nd Qtr'!E16, '3rd Qtr'!E16, '4th Qtr'!E16) -> 10404.684 | F16: =IF(AND(ISNUMBER(D16),ISNUMBER(E16)), D16-E16, "") -> 56502.393 | G16: =IFERROR(F16/E16, "") -> 5.4304766 | H16: =SUM('1st Qtr'!H16+'2nd Qtr'!H16+'3rd Qtr'!H16+'4th Qtr'!H16) -> 79173 | I16: =SUM('1st Qtr'!I16, '2nd Qtr'!I16, '3rd Qtr'!I16, '4th Qtr'!I16) -> -12265.923 | J16: =IFERROR(I16/H16, "") -> -0.15492559
... A138: Ridgeway #2 | B138: NY | C138: =Sites[[#This Row],[SOL'#]] -> SOL-11027 | D138: =SUM('1st Qtr'!D138, '2nd Qtr'!D138, '3rd Qtr'!D138, '4th Qtr'!D138) -> 2006867.4 | E138: =SUM('1st Qtr'!E138, '2nd Qtr'!E138, '3rd Qtr'!E138, '4th Qtr'!E138) -> 0 | F138: =IF(AND(ISNUMBER(D138),ISNUMBER(E138)), D138-E138, "") -> 2006867.4 | G138: =IFERROR(F138/E138, "") | H138: =SUM('1st Qtr'!H138+'2nd Qtr'!H138+'3rd Qtr'!H138+'4th Qtr'!H138) -> 0 | I138: =SUM('1st Qtr'!I138, '2nd Qtr'!I138, '3rd Qtr'!I138, '4th Qtr'!I138) -> 2006867.4 | J138: =IFERROR(I138/H138, "")
A139: Spencer | B139: NY | C139: =Sites[[#This Row],[SOL'#]] -> SOL-11017 | D139: =SUM('1st Qtr'!D139, '2nd Qtr'!D139, '3rd Qtr'!D139, '4th Qtr'!D139) -> 3021643.4 | E139: =SUM('1st Qtr'!E139, '2nd Qtr'!E139, '3rd Qtr'!E139, '4th Qtr'!E139) -> 0 | F139: =IF(AND(ISNUMBER(D139),ISNUMBER(E139)), D139-E139, "") -> 3021643.4 | G139: =IFERROR(F139/E139, "") | H139: =SUM('1st Qtr'!H139+'2nd Qtr'!H139+'3rd Qtr'!H139+'4th Qtr'!H139) -> 0 | I139: =SUM('1st Qtr'!I139, '2nd Qtr'!I139, '3rd Qtr'!I139, '4th Qtr'!I139) -> 3021643.4
A140: Reisender | B140: NY | C140: ='1st Qtr'!C140 -> SOL-10886 | D140: =SUM('1st Qtr'!D140, '2nd Qtr'!D140, '3rd Qtr'!D140, '4th Qtr'!D140) -> 391080 | E140: =SUM('1st Qtr'!E140, '2nd Qtr'!E140, '3rd Qtr'!E140, '4th Qtr'!E140) -> 392206 | F140: =IF(AND(ISNUMBER(D140),ISNUMBER(E140)), D140-E140, "") -> -1126 | G140: =IFERROR(F140/E140, "") -> -0.0028709403 | H140: =SUM('1st Qtr'!H140+'2nd Qtr'!H140+'3rd Qtr'!H140+'4th Qtr'!H140) -> 381489 | I140: =SUM('1st Qtr'!I140, '2nd Qtr'!I140, '3rd Qtr'!I140, '4th Qtr'!I140) -> 9591
A141: Finney | B141: NY | C141: =Sites[[#This Row],[SOL'#]] -> SOL-10999 | D141: =SUM('1st Qtr'!D141, '2nd Qtr'!D141, '3rd Qtr'!D141, '4th Qtr'!D141) -> 316580 | E141: =SUM('1st Qtr'!E141, '2nd Qtr'!E141, '3rd Qtr'!E141, '4th Qtr'!E141) -> 0 | F141: =IF(AND(ISNUMBER(D141),ISNUMBER(E141)), D141-E141, "") -> 316580 | G141: =IFERROR(F141/E141, "") | H141: =SUM('1st Qtr'!H141+'2nd Qtr'!H141+'3rd Qtr'!H141+'4th Qtr'!H141) -> 0 | I141: =SUM('1st Qtr'!I141, '2nd Qtr'!I141, '3rd Qtr'!I141, '4th Qtr'!I141) -> 0
A142: Davis Solar | B142: NY | C142: =Sites[[#This Row],[SOL'#]] -> SOL-10958 | D142: =SUM('1st Qtr'!D142, '2nd Qtr'!D142, '3rd Qtr'!D142, '4th Qtr'!D142) -> 379098 | E142: =SUM('1st Qtr'!E142, '2nd Qtr'!E142, '3rd Qtr'!E142, '4th Qtr'!E142) -> 415825.2 | F142: =IF(AND(ISNUMBER(D142),ISNUMBER(E142)), D142-E142, "") -> -36727.2 | G142: =IFERROR(F142/E142, "") -> -0.088323651 | H142: =SUM('1st Qtr'!H142+'2nd Qtr'!H142+'3rd Qtr'!H142+'4th Qtr'!H142) -> 235847 | I142: =SUM('1st Qtr'!I142, '2nd Qtr'!I142, '3rd Qtr'!I142, '4th Qtr'!I142) -> 143251
A143: Genesee | B143: NY | C143: =Sites[[#This Row],[SOL'#]] -> SOL-10951 | D143: =SUM('1st Qtr'!D143, '2nd Qtr'!D143, '3rd Qtr'!D143, '4th Qtr'!D143) -> 881988 | E143: =SUM('1st Qtr'!E143, '2nd Qtr'!E143, '3rd Qtr'!E143, '4th Qtr'!E143) -> 0 | F143: =IF(AND(ISNUMBER(D143),ISNUMBER(E143)), D143-E143, "") -> 881988 | G143: =IFERROR(F143/E143, "") | H143: =SUM('1st Qtr'!H143+'2nd Qtr'!H143+'3rd Qtr'!H143+'4th Qtr'!H143) -> 0 | I143: =SUM('1st Qtr'!I143, '2nd Qtr'!I143, '3rd Qtr'!I143, '4th Qtr'!I143) -> 881988
A144: Landau I | B144: NY | C144: =Sites[[#This Row],[SOL'#]] -> SOL-10891 | D144: =SUM('1st Qtr'!D144, '2nd Qtr'!D144, '3rd Qtr'!D144, '4th Qtr'!D144) -> 404690 | E144: =SUM('1st Qtr'!E144, '2nd Qtr'!E144, '3rd Qtr'!E144, '4th Qtr'!E144) -> 0 | F144: =IF(AND(ISNUMBER(D144),ISNUMBER(E144)), D144-E144, "") -> 404690 | G144: =IFERROR(F144/E144, "") | H144: =SUM('1st Qtr'!H144+'2nd Qtr'!H144+'3rd Qtr'!H144+'4th Qtr'!H144) -> 0 | I144: =SUM('1st Qtr'!I144, '2nd Qtr'!I144, '3rd Qtr'!I144, '4th Qtr'!I144) -> 404690
A145: Landau II | B145: NY | C145: =Sites[[#This Row],[SOL'#]] -> SOL-10895 | D145: =SUM('1st Qtr'!D145, '2nd Qtr'!D145, '3rd Qtr'!D145, '4th Qtr'!D145) -> 334690 | E145: =SUM('1st Qtr'!E145, '2nd Qtr'!E145, '3rd Qtr'!E145, '4th Qtr'!E145) -> 0 | F145: =IF(AND(ISNUMBER(D145),ISNUMBER(E145)), D145-E145, "") -> 334690 | G145: =IFERROR(F145/E145, "") | H145: =SUM('1st Qtr'!H145+'2nd Qtr'!H145+'3rd Qtr'!H145+'4th Qtr'!H145) -> 0 | I145: =SUM('1st Qtr'!I145, '2nd Qtr'!I145, '3rd Qtr'!I145, '4th Qtr'!I145) -> 334690
A146: New Beginnings | B146: NY | C146: =Sites[[#This Row],[SOL'#]] -> SOL-10890 | D146: =SUM('1st Qtr'!D146, '2nd Qtr'!D146, '3rd Qtr'!D146, '4th Qtr'!D146) -> 401940 | E146: =SUM('1st Qtr'!E146, '2nd Qtr'!E146, '3rd Qtr'!E146, '4th Qtr'!E146) -> 401968 | F146: =IF(AND(ISNUMBER(D146),ISNUMBER(E146)), D146-E146, "") -> -28 | G146: =IFERROR(F146/E146, "") -> -6.9657286e-05 | H146: =SUM('1st Qtr'!H146+'2nd Qtr'!H146+'3rd Qtr'!H146+'4th Qtr'!H146) -> 398278 | I146: =SUM('1st Qtr'!I146, '2nd Qtr'!I146, '3rd Qtr'!I146, '4th Qtr'!I146) -> 3662
A147: Guilin Farm Solar | B147: NY | C147: =Sites[[#This Row],[SOL'#]] -> SOL-10998 | D147: =SUM('1st Qtr'!D147, '2nd Qtr'!D147, '3rd Qtr'!D147, '4th Qtr'!D147) -> 673297 | E147: =SUM('1st Qtr'!E147, '2nd Qtr'!E147, '3rd Qtr'!E147, '4th Qtr'!E147) -> 683546 | F147: =IF(AND(ISNUMBER(D147),ISNUMBER(E147)), D147-E147, "") -> -10249 | G147: =IFERROR(F147/E147, "") -> -0.01499387 | H147: =SUM('1st Qtr'!H147+'2nd Qtr'!H147+'3rd Qtr'!H147+'4th Qtr'!H147) -> 1048743 | I147: =SUM('1st Qtr'!I147, '2nd Qtr'!I147, '3rd Qtr'!I147, '4th Qtr'!I147) -> -375446
A148: Brodhead Solar | B148: NY | C148: =Sites[[#This Row],[SOL'#]] -> SOL-10899 | D148: =SUM('1st Qtr'!D148, '2nd Qtr'!D148, '3rd Qtr'!D148, '4th Qtr'!D148) -> 486584 | E148: =SUM('1st Qtr'!E148, '2nd Qtr'!E148, '3rd Qtr'!E148, '4th Qtr'!E148) -> 509888 | F148: =IF(AND(ISNUMBER(D148),ISNUMBER(E148)), D148-E148, "") -> -23304 | G148: =IFERROR(F148/E148, "") -> -0.045704155 | H148: =SUM('1st Qtr'!H148+'2nd Qtr'!H148+'3rd Qtr'!H148+'4th Qtr'!H148) -> 522919 | I148: =SUM('1st Qtr'!I148, '2nd Qtr'!I148, '3rd Qtr'!I148, '4th Qtr'!I148) -> -36335
A149: Svenski | B149: NY | C149: =Sites[[#This Row],[SOL'#]] -> SOL-10894 | D149: =SUM('1st Qtr'!D149, '2nd Qtr'!D149, '3rd Qtr'!D149, '4th Qtr'!D149) -> 304918 | E149: =SUM('1st Qtr'!E149, '2nd Qtr'!E149, '3rd Qtr'!E149, '4th Qtr'!E149) -> 0 | F149: =IF(AND(ISNUMBER(D149),ISNUMBER(E149)), D149-E149, "") -> 304918 | G149: =IFERROR(F149/E149, "") | H149: =SUM('1st Qtr'!H149+'2nd Qtr'!H149+'3rd Qtr'!H149+'4th Qtr'!H149) -> 0 | I149: =SUM('1st Qtr'!I149, '2nd Qtr'!I149, '3rd Qtr'!I149, '4th Qtr'!I149) -> 304918
A150: Bantam | B150: NY | C150: =Sites[[#This Row],[SOL'#]] -> SOL-10986 | D150: =SUM('1st Qtr'!D150, '2nd Qtr'!D150, '3rd Qtr'!D150, '4th Qtr'!D150) -> 30270 | E150: =SUM('1st Qtr'!E150, '2nd Qtr'!E150, '3rd Qtr'!E150, '4th Qtr'!E150) -> 0 | F150: =IF(AND(ISNUMBER(D150),ISNUMBER(E150)), D150-E150, "") -> 30270 | G150: =IFERROR(F150/E150, "") | H150: =SUM('1st Qtr'!H150+'2nd Qtr'!H150+'3rd Qtr'!H150+'4th Qtr'!H150) -> 0 | I150: =SUM('1st Qtr'!I150, '2nd Qtr'!I150, '3rd Qtr'!I150, '4th Qtr'!I150) -> 30270
A151: Bogart | B151: NY | C151: =Sites[[#This Row],[SOL'#]] -> SOL-10887 | D151: =SUM('1st Qtr'!D151, '2nd Qtr'!D151, '3rd Qtr'!D151, '4th Qtr'!D151) -> 358420 | E151: =SUM('1st Qtr'!E151, '2nd Qtr'!E151, '3rd Qtr'!E151, '4th Qtr'!E151) -> 382168 | F151: =IF(AND(ISNUMBER(D151),ISNUMBER(E151)), D151-E151, "") -> -23748 | G151: =IFERROR(F151/E151, "") -> -0.062140211 | H151: =SUM('1st Qtr'!H151+'2nd Qtr'!H151+'3rd Qtr'!H151+'4th Qtr'!H151) -> 391479 | I151: =SUM('1st Qtr'!I151, '2nd Qtr'!I151, '3rd Qtr'!I151, '4th Qtr'!I151) -> -33059
A152: Dubois | B152: NY | C152: =Sites[[#This Row],[SOL'#]] -> SOL-10892 | D152: =SUM('1st Qtr'!D152, '2nd Qtr'!D152, '3rd Qtr'!D152, '4th Qtr'!D152) -> 359955 | E152: =SUM('1st Qtr'!E152, '2nd Qtr'!E152, '3rd Qtr'!E152, '4th Qtr'!E152) -> 0 | F152: =IF(AND(ISNUMBER(D152),ISNUMBER(E152)), D152-E152, "") -> 359955 | G152: =IFERROR(F152/E152, "") | H152: =SUM('1st Qtr'!H152+'2nd Qtr'!H152+'3rd Qtr'!H152+'4th Qtr'!H152) -> 0 | I152: =SUM('1st Qtr'!I152, '2nd Qtr'!I152, '3rd Qtr'!I152, '4th Qtr'!I152) -> 359955
... A160: Drinkwater | B160: NY | C160: =Sites[[#This Row],[SOL'#]] -> SOL-10896 | D160: =SUM('1st Qtr'!D160, '2nd Qtr'!D160, '3rd Qtr'!D160, '4th Qtr'!D160) -> 410647 | E160: =SUM('1st Qtr'!E160, '2nd Qtr'!E160, '3rd Qtr'!E160, '4th Qtr'!E160) -> 0 | F160: =IF(AND(ISNUMBER(D160),ISNUMBER(E160)), D160-E160, "") -> 410647 | G160: =IFERROR(F160/E160, "") | H160: =SUM('1st Qtr'!H160+'2nd Qtr'!H160+'3rd Qtr'!H160+'4th Qtr'!H160) -> 0 | I160: =SUM('1st Qtr'!I160, '2nd Qtr'!I160, '3rd Qtr'!I160, '4th Qtr'!I160) -> 410647

Sheet 1st Qtr
A1: {=portfolio} -> Generate Capital | E1: 1st Quarter Actual v. Expected | H1: 1st Quarter Actual v. Forecasted
A2: Total | D2: =SUM(D4:D138) -> 43587557 | E2: =SUM(E4:E138) -> 18064132 | F2: =D2-E2 -> 25523425 | G2: =IFERROR(F2/E2, 0) -> 1.4129339 | H2: =SUM(H4:H138) -> 34188212 | I2: =D2-H2 -> 9399344.7 | J2: =IFERROR(I2/H2, 0) -> 0.2749294
A3: Site | B3: State | C3: SOL# | D3: Actual | E3: Expected | F3: Delta | G3: % | H3: Forecasted | I3: Delta | J3: %
A4: {=Sites[Site]} -> Farmer | B4: {=Sites[State]} -> AZ | C4: =Sites[[#This Row],[SOL'#]] -> SOL-10748 | D4: =SUM(Jan!D4, Feb!D4, Mar!D4) -> 32706.294 | E4: =SUM(Jan!E4, Feb!E4, Mar!E4) -> 24705.273 | F4: =IF(AND(ISNUMBER(D4),ISNUMBER(E4)), D4-E4, "") -> 8001.0206 | G4: =IFERROR(F4/E4, "") -> 0.32385882 | H4: =SUM(Jan!H4, Feb!H4, Mar!H4) -> 33317.317 | I4: =SUM(Jan!I4, Feb!I4, Mar!I4) -> -611.02342 | J4: =IFERROR(I4/H4, "") -> -0.018339514
A5: Fulton | B5: AZ | C5: =Sites[[#This Row],[SOL'#]] -> SOL-10749 | D5: =SUM(Jan!D5, Feb!D5, Mar!D5) -> 107842 | E5: =SUM(Jan!E5, Feb!E5, Mar!E5) -> 112159.54 | F5: =IF(AND(ISNUMBER(D5),ISNUMBER(E5)), D5-E5, "") -> -4317.54 | G5: =IFERROR(F5/E5, "") -> -0.03849463 | H5: =SUM(Jan!H5, Feb!H5, Mar!H5) -> 138999.08 | I5: =SUM(Jan!I5, Feb!I5, Mar!I5) -> -31157.08 | J5: =IFERROR(I5/H5, "") -> -0.22415314
A6: JFK Elementary | B6: AZ | C6: =Sites[[#This Row],[SOL'#]] -> SOL-10758 | D6: =SUM(Jan!D6, Feb!D6, Mar!D6) -> 52126.87 | E6: =SUM(Jan!E6, Feb!E6, Mar!E6) -> 0 | F6: =IF(AND(ISNUMBER(D6),ISNUMBER(E6)), D6-E6, "") -> 52126.87 | G6: =IFERROR(F6/E6, "") | H6: =SUM(Jan!H6, Feb!H6, Mar!H6) -> 6126 | I6: =SUM(Jan!I6, Feb!I6, Mar!I6) -> 46000.87 | J6: =IFERROR(I6/H6, "") -> 7.5091201
A7: Noble | B7: AZ | C7: =Sites[[#This Row],[SOL'#]] -> SOL-10750 | D7: =SUM(Jan!D7, Feb!D7, Mar!D7) -> 31148.242 | E7: =SUM(Jan!E7, Feb!E7, Mar!E7) -> 41886.08 | F7: =IF(AND(ISNUMBER(D7),ISNUMBER(E7)), D7-E7, "") -> -10737.838 | G7: =IFERROR(F7/E7, "") -> -0.25635815 | H7: =SUM(Jan!H7, Feb!H7, Mar!H7) -> 36692.61 | I7: =SUM(Jan!I7, Feb!I7, Mar!I7) -> -5544.368 | J7: =IFERROR(I7/H7, "") -> -0.15110312
A8: Parking 3 | B8: AZ | C8: =Sites[[#This Row],[SOL'#]] -> SOL-10751 | D8: =SUM(Jan!D8, Feb!D8, Mar!D8) -> 72830.78 | E8: =SUM(Jan!E8, Feb!E8, Mar!E8) -> 84541.3 | F8: =IF(AND(ISNUMBER(D8),ISNUMBER(E8)), D8-E8, "") -> -11710.52 | G8: =IFERROR(F8/E8, "") -> -0.13851833 | H8: =SUM(Jan!H8, Feb!H8, Mar!H8) -> 84122 | I8: =SUM(Jan!I8, Feb!I8, Mar!I8) -> -11291.22 | J8: =IFERROR(I8/H8, "") -> -0.13422434
A9: PE East | B9: AZ | C9: =Sites[[#This Row],[SOL'#]] -> SOL-10752 | D9: =SUM(Jan!D9, Feb!D9, Mar!D9) -> 74341.832 | E9: =SUM(Jan!E9, Feb!E9, Mar!E9) -> 57907.94 | F9: =IF(AND(ISNUMBER(D9),ISNUMBER(E9)), D9-E9, "") -> 16433.892 | G9: =IFERROR(F9/E9, "") -> 0.28379342 | H9: =SUM(Jan!H9, Feb!H9, Mar!H9) -> 80684.31 | I9: =SUM(Jan!I9, Feb!I9, Mar!I9) -> -6342.4778 | J9: =IFERROR(I9/H9, "") -> -0.078608564
A10: Schwada | B10: AZ | C10: =Sites[[#This Row],[SOL'#]] -> SOL-10753 | D10: =SUM(Jan!D10, Feb!D10, Mar!D10) -> 32098.551 | E10: =SUM(Jan!E10, Feb!E10, Mar!E10) -> 24254.971 | F10: =IF(AND(ISNUMBER(D10),ISNUMBER(E10)), D10-E10, "") -> 7843.58 | G10: =IFERROR(F10/E10, "") -> 0.32338031 | H10: =SUM(Jan!H10, Feb!H10, Mar!H10) -> 34500 | I10: =SUM(Jan!I10, Feb!I10, Mar!I10) -> -2401.449 | J10: =IFERROR(I10/H10, "") -> -0.069607218
A11: Starshine | B11: AZ | C11: =Sites[[#This Row],[SOL'#]] -> SOL-10757 | D11: =SUM(Jan!D11, Feb!D11, Mar!D11) -> 14150.597 | E11: =SUM(Jan!E11, Feb!E11, Mar!E11) -> 0 | F11: =IF(AND(ISNUMBER(D11),ISNUMBER(E11)), D11-E11, "") -> 14150.597 | G11: =IFERROR(F11/E11, "") | H11: =SUM(Jan!H11, Feb!H11, Mar!H11) -> 0 | I11: =SUM(Jan!I11, Feb!I11, Mar!I11) -> 14150.597 | J11: =IFERROR(I11/H11, "")
A12: Yuma Airport | B12: AZ | C12: =Sites[[#This Row],[SOL'#]] -> SOL-10754 | D12: =SUM(Jan!D12, Feb!D12, Mar!D12) -> 197992 | E12: =SUM(Jan!E12, Feb!E12, Mar!E12) -> 251330.95 | F12: =IF(AND(ISNUMBER(D12),ISNUMBER(E12)), D12-E12, "") -> -53338.95 | G12: =IFERROR(F12/E12, "") -> -0.21222595 | H12: =SUM(Jan!H12, Feb!H12, Mar!H12) -> 220637 | I12: =SUM(Jan!I12, Feb!I12, Mar!I12) -> -22645 | J12: =IFERROR(I12/H12, "") -> -0.10263464
A13: Kinsman | B13: OH | C13: =Sites[[#This Row],[SOL'#]] -> SOL-10762 | D13: =SUM(Jan!D13, Feb!D13, Mar!D13) -> 192799.11 | E13: =SUM(Jan!E13, Feb!E13, Mar!E13) -> 278939.85 | F13: =IF(AND(ISNUMBER(D13),ISNUMBER(E13)), D13-E13, "") -> -86140.741 | G13: =IFERROR(F13/E13, "") -> -0.30881475 | H13: =SUM(Jan!H13, Feb!H13, Mar!H13) -> 217404 | I13: =SUM(Jan!I13, Feb!I13, Mar!I13) -> -24604.891 | J13: =IFERROR(I13/H13, "") -> -0.11317589
A14: Wooster | B14: OH | C14: =Sites[[#This Row],[SOL'#]] -> SOL-10763 | D14: =SUM(Jan!D14, Feb!D14, Mar!D14) -> 41860.5 | E14: =SUM(Jan!E14, Feb!E14, Mar!E14) -> 0 | F14: =IF(AND(ISNUMBER(D14),ISNUMBER(E14)), D14-E14, "") -> 41860.5 | G14: =IFERROR(F14/E14, "") | H14: =SUM(Jan!H14, Feb!H14, Mar!H14) -> 49246 | I14: =SUM(Jan!I14, Feb!I14, Mar!I14) -> -7385.5 | J14: =IFERROR(I14/H14, "") -> -0.14997157
A15: Globe Gila CC | B15: AZ | C15: =Sites[[#This Row],[SOL'#]] -> SOL-10755 | D15: =SUM(Jan!D15, Feb!D15, Mar!D15) -> 37604.479 | E15: =SUM(Jan!E15, Feb!E15, Mar!E15) -> 0 | F15: =IF(AND(ISNUMBER(D15),ISNUMBER(E15)), D15-E15, "") -> 37604.479 | G15: =IFERROR(F15/E15, "") | H15: =SUM(Jan!H15, Feb!H15, Mar!H15) -> 37905 | I15: =SUM(Jan!I15, Feb!I15, Mar!I15) -> -300.52133 | J15: =IFERROR(I15/H15, "") -> -0.0079282768
A16: Payson Gila CC | B16: AZ | C16: =Sites[[#This Row],[SOL'#]] -> SOL-10756 | D16: =SUM(Jan!D16, Feb!D16, Mar!D16) -> 25234.534 | E16: =SUM(Jan!E16, Feb!E16, Mar!E16) -> 0 | F16: =IF(AND(ISNUMBER(D16),ISNUMBER(E16)), D16-E16, "") -> 25234.534 | G16: =IFERROR(F16/E16, "") | H16: =SUM(Jan!H16, Feb!H16, Mar!H16) -> 30379 | I16: =SUM(Jan!I16, Feb!I16, Mar!I16) -> -5144.4662 | J16: =IFERROR(I16/H16, "") -> -0.16934284
... A160: Drinkwater | B160: NY | C160: =Sites[[#This Row],[SOL'#]] -> SOL-10896 | D160: =SUM(Jan!D160, Feb!D160, Mar!D160) -> 0 | E160: =SUM(Jan!E160, Feb!E160, Mar!E160) -> 0 | F160: =IF(AND(ISNUMBER(D160),ISNUMBER(E160)), D160-E160, "") -> 0 | G160: =IFERROR(F160/E160, "") | H160: =SUM(Jan!H160, Feb!H160, Mar!H160) -> 0 | I160: =SUM(Jan!I160, Feb!I160, Mar!I160) -> 0 | J160: =IFERROR(I160/H160, "")

Sheet 2nd Qtr
A1: {=portfolio} -> Generate Capital | E1: 2nd Quarter Actual v. Expected | H1: 2nd Quarter Actual v. Forecasted
A2: Total | D2: =SUM(D4:D100) -> 53004295 | E2: =SUM(E4:E100) -> 23057193 | F2: =D2-E2 -> 29947103 | G2: =IFERROR(F2/E2, 0) -> 1.2988183 | H2: =SUM(H4:H100) -> 36433863 | I2: =D2-H2 -> 16570433 | J2: =IFERROR(I2/H2, 0) -> 0.45480857
A3: Site | B3: State | C3: SOL# | D3: Actual | E3: Expected | F3: Delta | G3: % | H3: Forecasted | I3: Delta | J3: %
A4: {=Sites[Site]} -> Farmer | B4: {=Sites[State]} -> AZ | C4: =Sites[[#This Row],[SOL'#]] -> SOL-10748 | D4: =SUM(Apr!D4, May!D4, Jun!D4) -> 43015.621 | E4: =SUM(Apr!E4, May!E4, Jun!E4) -> 25676.863 | F4: =IF(AND(ISNUMBER(D4),ISNUMBER(E4)), D4-E4, "") -> 17338.758 | G4: =IFERROR(F4/E4, "") -> 0.67526778 | H4: =SUM(Apr!H4, May!H4, Jun!H4) -> 43467.57 | I4: =SUM(Apr!I4, May!I4, Jun!I4) -> -451.94875 | J4: =IFERROR(I4/H4, "") -> -0.010397378
A5: Fulton | B5: AZ | C5: =Sites[[#This Row],[SOL'#]] -> SOL-10749 | D5: =SUM(Apr!D5, May!D5, Jun!D5) -> 195784.25 | E5: =SUM(Apr!E5, May!E5, Jun!E5) -> 148661.04 | F5: =IF(AND(ISNUMBER(D5),ISNUMBER(E5)), D5-E5, "") -> 47123.21 | G5: =IFERROR(F5/E5, "") -> 0.31698426 | H5: =SUM(Apr!H5, May!H5, Jun!H5) -> 236616.89 | I5: =SUM(Apr!I5, May!I5, Jun!I5) -> -40832.64 | J5: =IFERROR(I5/H5, "") -> -0.17256858
A6: JFK Elementary | B6: AZ | C6: =Sites[[#This Row],[SOL'#]] -> SOL-10758 | D6: =SUM(Apr!D6, May!D6, Jun!D6) -> 66638.14 | E6: =SUM(Apr!E6, May!E6, Jun!E6) -> 0 | F6: =IF(AND(ISNUMBER(D6),ISNUMBER(E6)), D6-E6, "") -> 66638.14 | G6: =IFERROR(F6/E6, "") | H6: =SUM(Apr!H6, May!H6, Jun!H6) -> 7250 | I6: =SUM(Apr!I6, May!I6, Jun!I6) -> 59388.14 | J6: =IFERROR(I6/H6, "") -> 8.1914676
A7: Noble | B7: AZ | C7: =Sites[[#This Row],[SOL'#]] -> SOL-10750 | D7: =SUM(Apr!D7, May!D7, Jun!D7) -> 28784.115 | E7: =SUM(Apr!E7, May!E7, Jun!E7) -> 43921.954 | F7: =IF(AND(ISNUMBER(D7),ISNUMBER(E7)), D7-E7, "") -> -15137.839 | G7: =IFERROR(F7/E7, "") -> -0.34465314 | H7: =SUM(Apr!H7, May!H7, Jun!H7) -> 48804.72 | I7: =SUM(Apr!I7, May!I7, Jun!I7) -> -20020.605 | J7: =IFERROR(I7/H7, "") -> -0.41021863
A8: Parking 3 | B8: AZ | C8: =Sites[[#This Row],[SOL'#]] -> SOL-10751 | D8: =SUM(Apr!D8, May!D8, Jun!D8) -> 91309.364 | E8: =SUM(Apr!E8, May!E8, Jun!E8) -> 96716.55 | F8: =IF(AND(ISNUMBER(D8),ISNUMBER(E8)), D8-E8, "") -> -5407.1862 | G8: =IFERROR(F8/E8, "") -> -0.055907558 | H8: =SUM(Apr!H8, May!H8, Jun!H8) -> 118637 | I8: =SUM(Apr!I8, May!I8, Jun!I8) -> -27327.636 | J8: =IFERROR(I8/H8, "") -> -0.23034666
A9: PE East | B9: AZ | C9: =Sites[[#This Row],[SOL'#]] -> SOL-10752 | D9: =SUM(Apr!D9, May!D9, Jun!D9) -> 97023.824 | E9: =SUM(Apr!E9, May!E9, Jun!E9) -> 60112.32 | F9: =IF(AND(ISNUMBER(D9),ISNUMBER(E9)), D9-E9, "") -> 36911.504 | G9: =IFERROR(F9/E9, "") -> 0.61404224 | H9: =SUM(Apr!H9, May!H9, Jun!H9) -> 104768.89 | I9: =SUM(Apr!I9, May!I9, Jun!I9) -> -7745.0662 | J9: =IFERROR(I9/H9, "") -> -0.073925248
A10: Schwada | B10: AZ | C10: =Sites[[#This Row],[SOL'#]] -> SOL-10753 | D10: =SUM(Apr!D10, May!D10, Jun!D10) -> 43708.669 | E10: =SUM(Apr!E10, May!E10, Jun!E10) -> 24644.378 | F10: =IF(AND(ISNUMBER(D10),ISNUMBER(E10)), D10-E10, "") -> 19064.291 | G10: =IFERROR(F10/E10, "") -> 0.77357565 | H10: =SUM(Apr!H10, May!H10, Jun!H10) -> 44962 | I10: =SUM(Apr!I10, May!I10, Jun!I10) -> -1253.3313 | J10: =IFERROR(I10/H10, "") -> -0.027875345
A11: Starshine | B11: AZ | C11: =Sites[[#This Row],[SOL'#]] -> SOL-10757 | D11: =SUM(Apr!D11, May!D11, Jun!D11) -> 30672.095 | E11: =SUM(Apr!E11, May!E11, Jun!E11) -> 0 | F11: =IF(AND(ISNUMBER(D11),ISNUMBER(E11)), D11-E11, "") -> 30672.095 | G11: =IFERROR(F11/E11, "") | H11: =SUM(Apr!H11, May!H11, Jun!H11) -> 0 | I11: =SUM(Apr!I11, May!I11, Jun!I11) -> 30672.095 | J11: =IFERROR(I11/H11, "")
A12: Yuma Airport | B12: AZ | C12: =Sites[[#This Row],[SOL'#]] -> SOL-10754 | D12: =SUM(Apr!D12, May!D12, Jun!D12) -> 252815 | E12: =SUM(Apr!E12, May!E12, Jun!E12) -> 295661.99 | F12: =IF(AND(ISNUMBER(D12),ISNUMBER(E12)), D12-E12, "") -> -42846.99 | G12: =IFERROR(F12/E12, "") -> -0.14491883 | H12: =SUM(Apr!H12, May!H12, Jun!H12) -> 269722 | I12: =SUM(Apr!I12, May!I12, Jun!I12) -> -16907 | J12: =IFERROR(I12/H12, "") -> -0.062683059
A13: Kinsman | B13: OH | C13: =Sites[[#This Row],[SOL'#]] -> SOL-10762 | D13: =SUM(Apr!D13, May!D13, Jun!D13) -> 309245.97 | E13: =SUM(Apr!E13, May!E13, Jun!E13) -> 379438.3 | F13: =IF(AND(ISNUMBER(D13),ISNUMBER(E13)), D13-E13, "") -> -70192.331 | G13: =IFERROR(F13/E13, "") -> -0.18499011 | H13: =SUM(Apr!H13, May!H13, Jun!H13) -> 393784 | I13: =SUM(Apr!I13, May!I13, Jun!I13) -> -84538.031 | J13: =IFERROR(I13/H13, "") -> -0.21468122
A14: Wooster | B14: OH | C14: =Sites[[#This Row],[SOL'#]] -> SOL-10763 | D14: =SUM(Apr!D14, May!D14, Jun!D14) -> 67831.5 | E14: =SUM(Apr!E14, May!E14, Jun!E14) -> 0 | F14: =IF(AND(ISNUMBER(D14),ISNUMBER(E14)), D14-E14, "") -> 67831.5 | G14: =IFERROR(F14/E14, "") | H14: =SUM(Apr!H14, May!H14, Jun!H14) -> 95006 | I14: =SUM(Apr!I14, May!I14, Jun!I14) -> -27174.5 | J14: =IFERROR(I14/H14, "") -> -0.2860293
A15: Globe Gila CC | B15: AZ | C15: =Sites[[#This Row],[SOL'#]] -> SOL-10755 | D15: =SUM(Apr!D15, May!D15, Jun!D15) -> 55923.429 | E15: =SUM(Apr!E15, May!E15, Jun!E15) -> 24864.852 | F15: =IF(AND(ISNUMBER(D15),ISNUMBER(E15)), D15-E15, "") -> 31058.577 | G15: =IFERROR(F15/E15, "") -> 1.2490956 | H15: =SUM(Apr!H15, May!H15, Jun!H15) -> 60212 | I15: =SUM(Apr!I15, May!I15, Jun!I15) -> -4288.5713 | J15: =IFERROR(I15/H15, "") -> -0.071224528
A16: Payson Gila CC | B16: AZ | C16: =Sites[[#This Row],[SOL'#]] -> SOL-10756 | D16: =SUM(Apr!D16, May!D16, Jun!D16) -> 41672.543 | E16: =SUM(Apr!E16, May!E16, Jun!E16) -> 10404.684 | F16: =IF(AND(ISNUMBER(D16),ISNUMBER(E16)), D16-E16, "") -> 31267.859 | G16: =IFERROR(F16/E16, "") -> 3.0051714 | H16: =SUM(Apr!H16, May!H16, Jun!H16) -> 48794 | I16: =SUM(Apr!I16, May!I16, Jun!I16) -> -7121.4573 | J16: =IFERROR(I16/H16, "") -> -0.14594945
... A139: Spencer | B139: NY | C139: =Sites[[#This Row],[SOL'#]] -> SOL-11017 | D139: =SUM(Apr!D139, May!D139, Jun!D139) -> 3021643.4 | E139: =SUM(Apr!E139, May!E139, Jun!E139) -> 0 | F139: =IF(AND(ISNUMBER(D139),ISNUMBER(E139)), D139-E139, "") -> 3021643.4 | G139: =IFERROR(F139/E139, "") | H139: =SUM(Apr!H139, May!H139, Jun!H139) -> 0 | I139: =SUM(Apr!I139, May!I139, Jun!I139) -> 3021643.4 | J139: =IFERROR(I139/H139, "")
A140: Reisender | B140: NY | D140: =SUM(Apr!D140, May!D140, Jun!D140) -> 391080 | E140: =SUM(Apr!E140, May!E140, Jun!E140) -> 392206 | F140: =IF(AND(ISNUMBER(D140),ISNUMBER(E140)), D140-E140, "") -> -1126 | G140: =IFERROR(F140/E140, "") -> -0.0028709403 | H140: =SUM(Apr!H140, May!H140, Jun!H140) -> 381489 | I140: =SUM(Apr!I140, May!I140, Jun!I140) -> 9591 | J140: =IFERROR(I140/H140, "") -> 0.025140961
A141: Finney | B141: NY | D141: =SUM(Apr!D141, May!D141, Jun!D141) -> 316580 | E141: =SUM(Apr!E141, May!E141, Jun!E141) -> 0 | F141: =IF(AND(ISNUMBER(D141),ISNUMBER(E141)), D141-E141, "") -> 316580 | G141: =IFERROR(F141/E141, "") | H141: =SUM(Apr!H141, May!H141, Jun!H141) -> 0 | I141: =SUM(Apr!I141, May!I141, Jun!I141) -> 0 | J141: =IFERROR(I141/H141, "")
A142: Davis Solar | B142: NY | D142: =SUM(Apr!D142, May!D142, Jun!D142) -> 379098 | E142: =SUM(Apr!E142, May!E142, Jun!E142) -> 415825.2 | F142: =IF(AND(ISNUMBER(D142),ISNUMBER(E142)), D142-E142, "") -> -36727.2 | G142: =IFERROR(F142/E142, "") -> -0.088323651 | H142: =SUM(Apr!H142, May!H142, Jun!H142) -> 235847 | I142: =SUM(Apr!I142, May!I142, Jun!I142) -> 143251 | J142: =IFERROR(I142/H142, "") -> 0.60738954
A143: Genesee | B143: NY | D143: =SUM(Apr!D143, May!D143, Jun!D143) -> 881988 | E143: =SUM(Apr!E143, May!E143, Jun!E143) -> 0 | F143: =IF(AND(ISNUMBER(D143),ISNUMBER(E143)), D143-E143, "") -> 881988 | G143: =IFERROR(F143/E143, "") | H143: =SUM(Apr!H143, May!H143, Jun!H143) -> 0 | I143: =SUM(Apr!I143, May!I143, Jun!I143) -> 881988 | J143: =IFERROR(I143/H143, "")
A144: Landau I | B144: NY | D144: =SUM(Apr!D144, May!D144, Jun!D144) -> 404690 | E144: =SUM(Apr!E144, May!E144, Jun!E144) -> 0 | F144: =IF(AND(ISNUMBER(D144),ISNUMBER(E144)), D144-E144, "") -> 404690 | G144: =IFERROR(F144/E144, "") | H144: =SUM(Apr!H144, May!H144, Jun!H144) -> 0 | I144: =SUM(Apr!I144, May!I144, Jun!I144) -> 404690 | J144: =IFERROR(I144/H144, "")
A145: Landau II | B145: NY | D145: =SUM(Apr!D145, May!D145, Jun!D145) -> 334690 | E145: =SUM(Apr!E145, May!E145, Jun!E145) -> 0 | F145: =IF(AND(ISNUMBER(D145),ISNUMBER(E145)), D145-E145, "") -> 334690 | G145: =IFERROR(F145/E145, "") | H145: =SUM(Apr!H145, May!H145, Jun!H145) -> 0 | I145: =SUM(Apr!I145, May!I145, Jun!I145) -> 334690 | J145: =IFERROR(I145/H145, "")
A146: New Beginnings | B146: NY | D146: =SUM(Apr!D146, May!D146, Jun!D146) -> 401940 | E146: =SUM(Apr!E146, May!E146, Jun!E146) -> 401968 | F146: =IF(AND(ISNUMBER(D146),ISNUMBER(E146)), D146-E146, "") -> -28 | G146: =IFERROR(F146/E146, "") -> -6.9657286e-05 | H146: =SUM(Apr!H146, May!H146, Jun!H146) -> 398278 | I146: =SUM(Apr!I146, May!I146, Jun!I146) -> 3662 | J146: =IFERROR(I146/H146, "") -> 0.0091945827
A147: Guilin Farm Solar | B147: NY | D147: =SUM(Apr!D147, May!D147, Jun!D147) -> 673297 | E147: =SUM(Apr!E147, May!E147, Jun!E147) -> 683546 | F147: =IF(AND(ISNUMBER(D147),ISNUMBER(E147)), D147-E147, "") -> -10249 | G147: =IFERROR(F147/E147, "") -> -0.01499387 | H147: =SUM(Apr!H147, May!H147, Jun!H147) -> 1048743 | I147: =SUM(Apr!I147, May!I147, Jun!I147) -> -375446 | J147: =IFERROR(I147/H147, "") -> -0.35799619
A148: Brodhead Solar | B148: NY | D148: =SUM(Apr!D148, May!D148, Jun!D148) -> 486584 | E148: =SUM(Apr!E148, May!E148, Jun!E148) -> 509888 | F148: =IF(AND(ISNUMBER(D148),ISNUMBER(E148)), D148-E148, "") -> -23304 | G148: =IFERROR(F148/E148, "") -> -0.045704155 | H148: =SUM(Apr!H148, May!H148, Jun!H148) -> 522919 | I148: =SUM(Apr!I148, May!I148, Jun!I148) -> -36335 | J148: =IFERROR(I148/H148, "") -> -0.069484949
A149: Svenski | B149: NY | D149: =SUM(Apr!D149, May!D149, Jun!D149) -> 304918 | E149: =SUM(Apr!E149, May!E149, Jun!E149) -> 0 | F149: =IF(AND(ISNUMBER(D149),ISNUMBER(E149)), D149-E149, "") -> 304918 | G149: =IFERROR(F149/E149, "") | H149: =SUM(Apr!H149, May!H149, Jun!H149) -> 0 | I149: =SUM(Apr!I149, May!I149, Jun!I149) -> 304918 | J149: =IFERROR(I149/H149, "")
A150: Bantam | B150: NY | D150: =SUM(Apr!D150, May!D150, Jun!D150) -> 30270 | E150: =SUM(Apr!E150, May!E150, Jun!E150) -> 0 | F150: =IF(AND(ISNUMBER(D150),ISNUMBER(E150)), D150-E150, "") -> 30270 | G150: =IFERROR(F150/E150, "") | H150: =SUM(Apr!H150, May!H150, Jun!H150) -> 0 | I150: =SUM(Apr!I150, May!I150, Jun!I150) -> 30270 | J150: =IFERROR(I150/H150, "")
A151: Bogart | B151: NY | D151: =SUM(Apr!D151, May!D151, Jun!D151) -> 358420 | E151: =SUM(Apr!E151, May!E151, Jun!E151) -> 382168 | F151: =IF(AND(ISNUMBER(D151),ISNUMBER(E151)), D151-E151, "") -> -23748 | G151: =IFERROR(F151/E151, "") -> -0.062140211 | H151: =SUM(Apr!H151, May!H151, Jun!H151) -> 391479 | I151: =SUM(Apr!I151, May!I151, Jun!I151) -> -33059 | J151: =IFERROR(I151/H151, "") -> -0.08444642
... A160: Drinkwater | B160: NY | D160: =SUM(Apr!D160, May!D160, Jun!D160) -> 410647 | E160: =SUM(Apr!E160, May!E160, Jun!E160) -> 0 | F160: =IF(AND(ISNUMBER(D160),ISNUMBER(E160)), D160-E160, "") -> 410647 | G160: =IFERROR(F160/E160, "") | H160: =SUM(Apr!H160, May!H160, Jun!H160) -> 0 | I160: =SUM(Apr!I160, May!I160, Jun!I160) -> 410647 | J160: =IFERROR(I160/H160, "")

Sheet 3rd Qtr
A1: {=portfolio} -> Generate Capital | E1: 3rd Quarter Actual v. Expected | H1: 3rd Quarter Actual v. Forecasted
A2: Total | D2: =SUM(D4:D100) -> 0 | E2: =SUM(E4:E100) -> 0 | F2: =D2-E2 -> 0 | G2: =IFERROR(F2/E2, 0) -> 0 | H2: =SUM(H4:H100) -> 0 | I2: =D2-H2 -> 0 | J2: =IFERROR(I2/H2, 0) -> 0
A3: Site | B3: State | C3: SOL# | D3: Actual | E3: Expected | F3: Delta | G3: % | H3: Forecasted | I3: Delta | J3: %
A4: {=Sites[Site]} -> Farmer | B4: {=Sites[State]} -> AZ | C4: =Sites[[#This Row],[SOL'#]] -> SOL-10748 | D4: =SUM(Jul!D4, Aug!D4, Sep!D4) -> 0 | E4: =SUM(Jul!E4, Aug!E4, Sep!E4) -> 0 | F4: =IF(AND(ISNUMBER(D4),ISNUMBER(E4)), D4-E4, "") -> 0 | G4: =IFERROR(F4/E4, "") | I4: =SUM(Jul!I4, Aug!I4, Sep!I4) -> 0 | J4: =IFERROR(I4/H4, "")
A5: Fulton | B5: AZ | C5: =Sites[[#This Row],[SOL'#]] -> SOL-10749 | D5: =SUM(Jul!D5, Aug!D5, Sep!D5) -> 0 | E5: =SUM(Jul!E5, Aug!E5, Sep!E5) -> 0 | F5: =IF(AND(ISNUMBER(D5),ISNUMBER(E5)), D5-E5, "") -> 0 | G5: =IFERROR(F5/E5, "") | I5: =SUM(Jul!I5, Aug!I5, Sep!I5) -> 0 | J5: =IFERROR(I5/H5, "")
A6: JFK Elementary | B6: AZ | C6: =Sites[[#This Row],[SOL'#]] -> SOL-10758 | D6: =SUM(Jul!D6, Aug!D6, Sep!D6) -> 0 | E6: =SUM(Jul!E6, Aug!E6, Sep!E6) -> 0 | F6: =IF(AND(ISNUMBER(D6),ISNUMBER(E6)), D6-E6, "") -> 0 | G6: =IFERROR(F6/E6, "") | I6: =SUM(Jul!I6, Aug!I6, Sep!I6) -> 0 | J6: =IFERROR(I6/H6, "")
A7: Noble | B7: AZ | C7: =Sites[[#This Row],[SOL'#]] -> SOL-10750 | D7: =SUM(Jul!D7, Aug!D7, Sep!D7) -> 0 | E7: =SUM(Jul!E7, Aug!E7, Sep!E7) -> 0 | F7: =IF(AND(ISNUMBER(D7),ISNUMBER(E7)), D7-E7, "") -> 0 | G7: =IFERROR(F7/E7, "") | I7: =SUM(Jul!I7, Aug!I7, Sep!I7) -> 0 | J7: =IFERROR(I7/H7, "")
A8: Parking 3 | B8: AZ | C8: =Sites[[#This Row],[SOL'#]] -> SOL-10751 | D8: =SUM(Jul!D8, Aug!D8, Sep!D8) -> 0 | E8: =SUM(Jul!E8, Aug!E8, Sep!E8) -> 0 | F8: =IF(AND(ISNUMBER(D8),ISNUMBER(E8)), D8-E8, "") -> 0 | G8: =IFERROR(F8/E8, "") | I8: =SUM(Jul!I8, Aug!I8, Sep!I8) -> 0 | J8: =IFERROR(I8/H8, "")
A9: PE East | B9: AZ | C9: =Sites[[#This Row],[SOL'#]] -> SOL-10752 | D9: =SUM(Jul!D9, Aug!D9, Sep!D9) -> 0 | E9: =SUM(Jul!E9, Aug!E9, Sep!E9) -> 0 | F9: =IF(AND(ISNUMBER(D9),ISNUMBER(E9)), D9-E9, "") -> 0 | G9: =IFERROR(F9/E9, "") | I9: =SUM(Jul!I9, Aug!I9, Sep!I9) -> 0 | J9: =IFERROR(I9/H9, "")
A10: Schwada | B10: AZ | C10: =Sites[[#This Row],[SOL'#]] -> SOL-10753 | D10: =SUM(Jul!D10, Aug!D10, Sep!D10) -> 0 | E10: =SUM(Jul!E10, Aug!E10, Sep!E10) -> 0 | F10: =IF(AND(ISNUMBER(D10),ISNUMBER(E10)), D10-E10, "") -> 0 | G10: =IFERROR(F10/E10, "") | I10: =SUM(Jul!I10, Aug!I10, Sep!I10) -> 0 | J10: =IFERROR(I10/H10, "")
A11: Starshine | B11: AZ | C11: =Sites[[#This Row],[SOL'#]] -> SOL-10757 | D11: =SUM(Jul!D11, Aug!D11, Sep!D11) -> 0 | E11: =SUM(Jul!E11, Aug!E11, Sep!E11) -> 0 | F11: =IF(AND(ISNUMBER(D11),ISNUMBER(E11)), D11-E11, "") -> 0 | G11: =IFERROR(F11/E11, "") | I11: =SUM(Jul!I11, Aug!I11, Sep!I11) -> 0 | J11: =IFERROR(I11/H11, "")
A12: Yuma Airport | B12: AZ | C12: =Sites[[#This Row],[SOL'#]] -> SOL-10754 | D12: =SUM(Jul!D12, Aug!D12, Sep!D12) -> 0 | E12: =SUM(Jul!E12, Aug!E12, Sep!E12) -> 0 | F12: =IF(AND(ISNUMBER(D12),ISNUMBER(E12)), D12-E12, "") -> 0 | G12: =IFERROR(F12/E12, "") | I12: =SUM(Jul!I12, Aug!I12, Sep!I12) -> 0 | J12: =IFERROR(I12/H12, "")
A13: Kinsman | B13: OH | C13: =Sites[[#This Row],[SOL'#]] -> SOL-10762 | D13: =SUM(Jul!D13, Aug!D13, Sep!D13) -> 0 | E13: =SUM(Jul!E13, Aug!E13, Sep!E13) -> 0 | F13: =IF(AND(ISNUMBER(D13),ISNUMBER(E13)), D13-E13, "") -> 0 | G13: =IFERROR(F13/E13, "") | I13: =SUM(Jul!I13, Aug!I13, Sep!I13) -> 0 | J13: =IFERROR(I13/H13, "")
A14: Wooster | B14: OH | C14: =Sites[[#This Row],[SOL'#]] -> SOL-10763 | D14: =SUM(Jul!D14, Aug!D14, Sep!D14) -> 0 | E14: =SUM(Jul!E14, Aug!E14, Sep!E14) -> 0 | F14: =IF(AND(ISNUMBER(D14),ISNUMBER(E14)), D14-E14, "") -> 0 | G14: =IFERROR(F14/E14, "") | I14: =SUM(Jul!I14, Aug!I14, Sep!I14) -> 0 | J14: =IFERROR(I14/H14, "")
A15: Globe Gila CC | B15: AZ | C15: =Sites[[#This Row],[SOL'#]] -> SOL-10755 | D15: =SUM(Jul!D15, Aug!D15, Sep!D15) -> 0 | E15: =SUM(Jul!E15, Aug!E15, Sep!E15) -> 0 | F15: =IF(AND(ISNUMBER(D15),ISNUMBER(E15)), D15-E15, "") -> 0 | G15: =IFERROR(F15/E15, "") | I15: =SUM(Jul!I15, Aug!I15, Sep!I15) -> 0 | J15: =IFERROR(I15/H15, "")
A16: Payson Gila CC | B16: AZ | C16: =Sites[[#This Row],[SOL'#]] -> SOL-10756 | D16: =SUM(Jul!D16, Aug!D16, Sep!D16) -> 0 | E16: =SUM(Jul!E16, Aug!E16, Sep!E16) -> 0 | F16: =IF(AND(ISNUMBER(D16),ISNUMBER(E16)), D16-E16, "") -> 0 | G16: =IFERROR(F16/E16, "") | I16: =SUM(Jul!I16, Aug!I16, Sep!I16) -> 0 | J16: =IFERROR(I16/H16, "")
A17: SCNM | B17: AZ | C17: =Sites[[#This Row],[SOL'#]] -> SOL-10760 | D17: =SUM(Jul!D17, Aug!D17, Sep!D17) -> 0 | E17: =SUM(Jul!E17, Aug!E17, Sep!E17) -> 0 | F17: =IF(AND(ISNUMBER(D17),ISNUMBER(E17)), D17-E17, "") -> 0 | G17: =IFERROR(F17/E17, "") | I17: =SUM(Jul!I17, Aug!I17, Sep!I17) -> 0 | J17: =IFERROR(I17/H17, "")
A18: Sequoia Charter School | B18: AZ | C18: =Sites[[#This Row],[SOL'#]] -> SOL-10759
A19: RCAB | B19: MA | C19: =Sites[[#This Row],[SOL'#]] -> SOL-10838
A20: Spectro Coatings | B20: MA | C20: =Sites[[#This Row],[SOL'#]] -> SOL-10074
A21: K026 | B21: NY | C21: =Sites[[#This Row],[SOL'#]] -> SOL-10356
A22: K041 | B22: NY | C22: =Sites[[#This Row],[SOL'#]] -> SOL-10357
A23: K043 | B23: NY | C23: =Sites[[#This Row],[SOL'#]] -> SOL-10358
A24: K058 | B24: NY | C24: =Sites[[#This Row],[SOL'#]] -> SOL-10360
A25: K115 | B25: NY | C25: =Sites[[#This Row],[SOL'#]] -> SOL-10361
A26: K152 | B26: NY | C26: =Sites[[#This Row],[SOL'#]] -> SOL-10362
A27: K166 | B27: NY | C27: =Sites[[#This Row],[SOL'#]] -> SOL-10363
A28: K206 | B28: NY | C28: =Sites[[#This Row],[SOL'#]] -> SOL-10927
A29: K251 | B29: NY | C29: =Sites[[#This Row],[SOL'#]] -> SOL-10365
... A160: Drinkwater | B160: NY | C160: =Sites[[#This Row],[SOL'#]] -> SOL-10896

Sheet 4th Qtr
A1: {=portfolio} -> Generate Capital | E1: 4th Quarter Actual v. Expected | H1: 4th Quarter Actual v. Forecasted
A2: Total | D2: =SUM(D4:D100) -> 0 | E2: =SUM(E4:E100) -> 0 | F2: =D2-E2 -> 0 | G2: =IFERROR(F2/E2, 0) -> 0 | H2: =SUM(H4:H100) -> 0 | I2: =D2-H2 -> 0 | J2: =IFERROR(I2/H2, 0) -> 0
A3: Site | B3: State | C3: SOL# | D3: Actual | E3: Expected | F3: Delta | G3: % | H3: Forecasted | I3: Delta | J3: %
A4: {=Sites[Site]} -> Farmer | B4: {=Sites[State]} -> AZ | C4: =Sites[[#This Row],[SOL'#]] -> SOL-10748 | D4: =SUM(Oct!D4, Nov!D4, Dec!D4) -> 0 | E4: =SUM(Oct!E4, Nov!E4, Dec!E4) -> 0 | F4: =IF(AND(ISNUMBER(D4),ISNUMBER(E4)), D4-E4, "") -> 0 | G4: =IFERROR(F4/E4, "") | I4: =SUM(Oct!I4, Nov!I4, Dec!I4) -> 0 | J4: =IFERROR(I4/H4, "")
A5: Fulton | B5: AZ | C5: =Sites[[#This Row],[SOL'#]] -> SOL-10749 | D5: =SUM(Oct!D5, Nov!D5, Dec!D5) -> 0 | E5: =SUM(Oct!E5, Nov!E5, Dec!E5) -> 0 | F5: =IF(AND(ISNUMBER(D5),ISNUMBER(E5)), D5-E5, "") -> 0 | G5: =IFERROR(F5/E5, "") | I5: =SUM(Oct!I5, Nov!I5, Dec!I5) -> 0 | J5: =IFERROR(I5/H5, "")
A6: JFK Elementary | B6: AZ | C6: =Sites[[#This Row],[SOL'#]] -> SOL-10758 | D6: =SUM(Oct!D6, Nov!D6, Dec!D6) -> 0 | E6: =SUM(Oct!E6, Nov!E6, Dec!E6) -> 0 | F6: =IF(AND(ISNUMBER(D6),ISNUMBER(E6)), D6-E6, "") -> 0 | G6: =IFERROR(F6/E6, "") | I6: =SUM(Oct!I6, Nov!I6, Dec!I6) -> 0 | J6: =IFERROR(I6/H6, "")
A7: Noble | B7: AZ | C7: =Sites[[#This Row],[SOL'#]] -> SOL-10750 | D7: =SUM(Oct!D7, Nov!D7, Dec!D7) -> 0 | E7: =SUM(Oct!E7, Nov!E7, Dec!E7) -> 0 | F7: =IF(AND(ISNUMBER(D7),ISNUMBER(E7)), D7-E7, "") -> 0 | G7: =IFERROR(F7/E7, "") | I7: =SUM(Oct!I7, Nov!I7, Dec!I7) -> 0 | J7: =IFERROR(I7/H7, "")
A8: Parking 3 | B8: AZ | C8: =Sites[[#This Row],[SOL'#]] -> SOL-10751 | D8: =SUM(Oct!D8, Nov!D8, Dec!D8) -> 0 | E8: =SUM(Oct!E8, Nov!E8, Dec!E8) -> 0 | F8: =IF(AND(ISNUMBER(D8),ISNUMBER(E8)), D8-E8, "") -> 0 | G8: =IFERROR(F8/E8, "") | I8: =SUM(Oct!I8, Nov!I8, Dec!I8) -> 0 | J8: =IFERROR(I8/H8, "")
A9: PE East | B9: AZ | C9: =Sites[[#This Row],[SOL'#]] -> SOL-10752 | D9: =SUM(Oct!D9, Nov!D9, Dec!D9) -> 0 | E9: =SUM(Oct!E9, Nov!E9, Dec!E9) -> 0 | F9: =IF(AND(ISNUMBER(D9),ISNUMBER(E9)), D9-E9, "") -> 0 | G9: =IFERROR(F9/E9, "") | I9: =SUM(Oct!I9, Nov!I9, Dec!I9) -> 0 | J9: =IFERROR(I9/H9, "")
A10: Schwada | B10: AZ | C10: =Sites[[#This Row],[SOL'#]] -> SOL-10753 | D10: =SUM(Oct!D10, Nov!D10, Dec!D10) -> 0 | E10: =SUM(Oct!E10, Nov!E10, Dec!E10) -> 0 | F10: =IF(AND(ISNUMBER(D10),ISNUMBER(E10)), D10-E10, "") -> 0 | G10: =IFERROR(F10/E10, "") | I10: =SUM(Oct!I10, Nov!I10, Dec!I10) -> 0 | J10: =IFERROR(I10/H10, "")
A11: Starshine | B11: AZ | C11: =Sites[[#This Row],[SOL'#]] -> SOL-10757 | D11: =SUM(Oct!D11, Nov!D11, Dec!D11) -> 0 | E11: =SUM(Oct!E11, Nov!E11, Dec!E11) -> 0 | F11: =IF(AND(ISNUMBER(D11),ISNUMBER(E11)), D11-E11, "") -> 0 | G11: =IFERROR(F11/E11, "") | I11: =SUM(Oct!I11, Nov!I11, Dec!I11) -> 0 | J11: =IFERROR(I11/H11, "")
A12: Yuma Airport | B12: AZ | C12: =Sites[[#This Row],[SOL'#]] -> SOL-10754 | D12: =SUM(Oct!D12, Nov!D12, Dec!D12) -> 0 | E12: =SUM(Oct!E12, Nov!E12, Dec!E12) -> 0 | F12: =IF(AND(ISNUMBER(D12),ISNUMBER(E12)), D12-E12, "") -> 0 | G12: =IFERROR(F12/E12, "") | I12: =SUM(Oct!I12, Nov!I12, Dec!I12) -> 0 | J12: =IFERROR(I12/H12, "")
A13: Kinsman | B13: OH | C13: =Sites[[#This Row],[SOL'#]] -> SOL-10762 | D13: =SUM(Oct!D13, Nov!D13, Dec!D13) -> 0 | E13: =SUM(Oct!E13, Nov!E13, Dec!E13) -> 0 | F13: =IF(AND(ISNUMBER(D13),ISNUMBER(E13)), D13-E13, "") -> 0 | G13: =IFERROR(F13/E13, "") | I13: =SUM(Oct!I13, Nov!I13, Dec!I13) -> 0 | J13: =IFERROR(I13/H13, "")
A14: Wooster | B14: OH | C14: =Sites[[#This Row],[SOL'#]] -> SOL-10763 | D14: =SUM(Oct!D14, Nov!D14, Dec!D14) -> 0 | E14: =SUM(Oct!E14, Nov!E14, Dec!E14) -> 0 | F14: =IF(AND(ISNUMBER(D14),ISNUMBER(E14)), D14-E14, "") -> 0 | G14: =IFERROR(F14/E14, "") | I14: =SUM(Oct!I14, Nov!I14, Dec!I14) -> 0 | J14: =IFERROR(I14/H14, "")
A15: Globe Gila CC | B15: AZ | C15: =Sites[[#This Row],[SOL'#]] -> SOL-10755 | D15: =SUM(Oct!D15, Nov!D15, Dec!D15) -> 0 | E15: =SUM(Oct!E15, Nov!E15, Dec!E15) -> 0 | F15: =IF(AND(ISNUMBER(D15),ISNUMBER(E15)), D15-E15, "") -> 0 | G15: =IFERROR(F15/E15, "") | I15: =SUM(Oct!I15, Nov!I15, Dec!I15) -> 0 | J15: =IFERROR(I15/H15, "")
A16: Payson Gila CC | B16: AZ | C16: =Sites[[#This Row],[SOL'#]] -> SOL-10756 | D16: =SUM(Oct!D16, Nov!D16, Dec!D16) -> 0 | E16: =SUM(Oct!E16, Nov!E16, Dec!E16) -> 0 | F16: =IF(AND(ISNUMBER(D16),ISNUMBER(E16)), D16-E16, "") -> 0 | G16: =IFERROR(F16/E16, "") | I16: =SUM(Oct!I16, Nov!I16, Dec!I16) -> 0 | J16: =IFERROR(I16/H16, "")
A17: SCNM | B17: AZ | C17: =Sites[[#This Row],[SOL'#]] -> SOL-10760 | D17: =SUM(Oct!D17, Nov!D17, Dec!D17) -> 0 | E17: =SUM(Oct!E17, Nov!E17, Dec!E17) -> 0 | F17: =IF(AND(ISNUMBER(D17),ISNUMBER(E17)), D17-E17, "") -> 0 | G17: =IFERROR(F17/E17, "") | I17: =SUM(Oct!I17, Nov!I17, Dec!I17) -> 0 | J17: =IFERROR(I17/H17, "")
A18: Sequoia Charter School | B18: AZ | C18: =Sites[[#This Row],[SOL'#]] -> SOL-10759 | E18: =SUM(Oct!E18, Nov!E18, Dec!E18) -> 0
A19: RCAB | B19: MA | C19: =Sites[[#This Row],[SOL'#]] -> SOL-10838 | E19: =SUM(Oct!E19, Nov!E19, Dec!E19) -> 0
A20: Spectro Coatings | B20: MA | C20: =Sites[[#This Row],[SOL'#]] -> SOL-10074
A21: K026 | B21: NY | C21: =Sites[[#This Row],[SOL'#]] -> SOL-10356
A22: K041 | B22: NY | C22: =Sites[[#This Row],[SOL'#]] -> SOL-10357
A23: K043 | B23: NY | C23: =Sites[[#This Row],[SOL'#]] -> SOL-10358
A24: K058 | B24: NY | C24: =Sites[[#This Row],[SOL'#]] -> SOL-10360
A25: K115 | B25: NY | C25: =Sites[[#This Row],[SOL'#]] -> SOL-10361
A26: K152 | B26: NY | C26: =Sites[[#This Row],[SOL'#]] -> SOL-10362
A27: K166 | B27: NY | C27: =Sites[[#This Row],[SOL'#]] -> SOL-10363
A28: K206 | B28: NY | C28: =Sites[[#This Row],[SOL'#]] -> SOL-10927
A29: K251 | B29: NY | C29: =Sites[[#This Row],[SOL'#]] -> SOL-10365
A30: K269 | B30: NY | C30: =Sites[[#This Row],[SOL'#]] -> SOL-10366
A31: K273 | B31: NY | C31: =Sites[[#This Row],[SOL'#]] -> SOL-10367
... A160: Drinkwater | B160: NY | C160: =Sites[[#This Row],[SOL'#]] -> SOL-10896

Sheet Jan
A1: {=portfolio} -> Generate Capital | E1: January Actual v. Expected | H1: January Actual v. Forecasted
A2: Total | D2: =SUM(D4:D137) -> 5231538.1 | E2: =SUM(E4:E137) -> 2888612.6 | F2: =D2-E2 -> 2342925.6 | G2: =IFERROR(F2/E2, 0) -> 0.81109028 | H2: =SUM(H4:H137) -> 9202509.7 | I2: =D2-H2 -> -3970971.6 | J2: =IFERROR(I2/H2, 0) -> -0.43150964 | K2: =IF(AND(TODAY()>DATE(2024, 1, 1), COUNTA(Sites[Site])<>(COUNT(D:D)-1)), "Some sites are missing actual data; if new sites were added, make sure they are aligned correctly (including prior months!)", "") -> Some sites are missing actual data; if new sites were added, make sure they are aligned correctly (including prior months!)
A3: Site | B3: State | C3: SOL# | D3: Actual | E3: Expected | F3: Delta | G3: % | H3: Forecasted | I3: Delta | J3: % | K3: Notes | L3: Service Requests
A4: {=Sites[Site]} -> Farmer | B4: {=Sites[State]} -> AZ | C4: =Sites[[#This Row],[SOL'#]] -> SOL-10748 | D4: 9019.8056 | E4: 7182.884 | F4: =IF(AND(ISNUMBER(D4),ISNUMBER(E4)), D4-E4, "") -> 1836.9216 | G4: =IFERROR(F4/E4, "") -> 0.25573594 | H4: 9612.777 | I4: =IF(AND(ISNUMBER(D4),ISNUMBER(H4)), D4-H4, "") -> -592.97143 | J4: =IFERROR(I4/H4, "") -> -0.061685758
A5: Fulton | B5: AZ | C5: =Sites[[#This Row],[SOL'#]] -> SOL-10749 | D5: 29434.75 | E5: 28981.22 | F5: =IF(AND(ISNUMBER(D5),ISNUMBER(E5)), D5-E5, "") -> 453.53 | G5: =IFERROR(F5/E5, "") -> 0.0156491 | H5: 39673.79 | I5: =IF(AND(ISNUMBER(D5),ISNUMBER(H5)), D5-H5, "") -> -10239.04 | J5: =IFERROR(I5/H5, "") -> -0.25808071
A6: JFK Elementary | B6: AZ | C6: =Sites[[#This Row],[SOL'#]] -> SOL-10758 | D6: 15656.69 | E6: 0 | F6: =IF(AND(ISNUMBER(D6),ISNUMBER(E6)), D6-E6, "") -> 15656.69 | G6: =IFERROR(F6/E6, "") | H6: 1973 | I6: =IF(AND(ISNUMBER(D6),ISNUMBER(H6)), D6-H6, "") -> 13683.69 | J6: =IFERROR(I6/H6, "") -> 6.9354739
A7: Noble | B7: AZ | C7: =Sites[[#This Row],[SOL'#]] -> SOL-10750 | D7: 8806.2478 | E7: 12098.42 | F7: =IF(AND(ISNUMBER(D7),ISNUMBER(E7)), D7-E7, "") -> -3292.1722 | G7: =IFERROR(F7/E7, "") -> -0.27211588 | H7: 11218.66 | I7: =IF(AND(ISNUMBER(D7),ISNUMBER(H7)), D7-H7, "") -> -2412.4122 | J7: =IFERROR(I7/H7, "") -> -0.21503568
A8: Parking 3 | B8: AZ | C8: =Sites[[#This Row],[SOL'#]] -> SOL-10751 | D8: 16586.8 | E8: 24366.89 | F8: =IF(AND(ISNUMBER(D8),ISNUMBER(E8)), D8-E8, "") -> -7780.09 | G8: =IFERROR(F8/E8, "") -> -0.31928941 | H8: 24201.63 | I8: =IF(AND(ISNUMBER(D8),ISNUMBER(H8)), D8-H8, "") -> -7614.83 | J8: =IFERROR(I8/H8, "") -> -0.3146412 | K8: 1.Inverter 1.1 is offline from 01/05 and back online on 01/17 at 10:45AM 2. Inverter 1.1 is offline from 07:00AM on 01/20 and back online at 11:00 on 01/22 | L8: 1.SR079991 2.SR080358
A9: PE East | B9: AZ | C9: =Sites[[#This Row],[SOL'#]] -> SOL-10752 | D9: 20730.183 | E9: 16836.22 | F9: =IF(AND(ISNUMBER(D9),ISNUMBER(E9)), D9-E9, "") -> 3893.9634 | G9: =IFERROR(F9/E9, "") -> 0.23128489 | H9: 24326.73 | I9: =IF(AND(ISNUMBER(D9),ISNUMBER(H9)), D9-H9, "") -> -3596.5466 | J9: =IFERROR(I9/H9, "") -> -0.14784341
A10: Schwada | B10: AZ | C10: =Sites[[#This Row],[SOL'#]] -> SOL-10753 | D10: 8912.9888 | E10: 7118.619 | F10: =IF(AND(ISNUMBER(D10),ISNUMBER(E10)), D10-E10, "") -> 1794.3698 | G10: =IFERROR(F10/E10, "") -> 0.25206712 | H10: 10705 | I10: =IF(AND(ISNUMBER(D10),ISNUMBER(H10)), D10-H10, "") -> -1792.0112 | J10: =IFERROR(I10/H10, "") -> -0.16739946
A11: Starshine | B11: AZ | C11: =Sites[[#This Row],[SOL'#]] -> SOL-10757 | D11: 3747.203 | E11: 0 | F11: =IF(AND(ISNUMBER(D11),ISNUMBER(E11)), D11-E11, "") -> 3747.203 | G11: =IFERROR(F11/E11, "") | H11: 0 | I11: =IF(AND(ISNUMBER(D11),ISNUMBER(H11)), D11-H11, "") -> 3747.203 | J11: =IFERROR(I11/H11, "") | K11: 1.Site did not started on 01/25 and started late on 01/27. | L11: 1.SR080480
A12: Yuma Airport | B12: AZ | C12: =Sites[[#This Row],[SOL'#]] -> SOL-10754 | D12: 52995 | E12: 74566.16 | F12: =IF(AND(ISNUMBER(D12),ISNUMBER(E12)), D12-E12, "") -> -21571.16 | G12: =IFERROR(F12/E12, "") -> -0.28928887 | H12: 67067 | I12: =IF(AND(ISNUMBER(D12),ISNUMBER(H12)), D12-H12, "") -> -14072 | J12: =IFERROR(I12/H12, "") -> -0.20982003
A13: Kinsman | B13: OH | C13: =Sites[[#This Row],[SOL'#]] -> SOL-10762 | D13: 20047.789 | E13: 40688.25 | F13: =IF(AND(ISNUMBER(D13),ISNUMBER(E13)), D13-E13, "") -> -20640.461 | G13: =IFERROR(F13/E13, "") -> -0.50728308 | H13: 55531 | I13: =IF(AND(ISNUMBER(D13),ISNUMBER(H13)), D13-H13, "") -> -35483.211 | J13: =IFERROR(I13/H13, "") -> -0.63898023 | K13: 1. Inveter B did not started for production 1/15 and 1/24. | L13: 1. SR080237
A14: Wooster | B14: OH | C14: =Sites[[#This Row],[SOL'#]] -> SOL-10763 | D14: 6323.25 | E14: 0 | F14: =IF(AND(ISNUMBER(D14),ISNUMBER(E14)), D14-E14, "") -> 6323.25 | G14: =IFERROR(F14/E14, "") | H14: 12400 | I14: =IF(AND(ISNUMBER(D14),ISNUMBER(H14)), D14-H14, "") -> -6076.75 | J14: =IFERROR(I14/H14, "") -> -0.49006048
A15: Globe Gila CC | B15: AZ | C15: =Sites[[#This Row],[SOL'#]] -> SOL-10755 | D15: 10382.778 | E15: 0 | F15: =IF(AND(ISNUMBER(D15),ISNUMBER(E15)), D15-E15, "") -> 10382.778 | G15: =IFERROR(F15/E15, "") | H15: 11007 | I15: =IF(AND(ISNUMBER(D15),ISNUMBER(H15)), D15-H15, "") -> -624.22218 | J15: =IFERROR(I15/H15, "") -> -0.056711382
A16: Payson Gila CC | B16: AZ | C16: =Sites[[#This Row],[SOL'#]] -> SOL-10756 | D16: 6804.5808 | E16: 0 | F16: =IF(AND(ISNUMBER(D16),ISNUMBER(E16)), D16-E16, "") -> 6804.5808 | G16: =IFERROR(F16/E16, "") | H16: 8517 | I16: =IF(AND(ISNUMBER(D16),ISNUMBER(H16)), D16-H16, "") -> -1712.4192 | J16: =IFERROR(I16/H16, "") -> -0.20105896
A17: SCNM | B17: AZ | C17: =Sites[[#This Row],[SOL'#]] -> SOL-10760 | D17: 51680.32 | E17: 0 | F17: =IF(AND(ISNUMBER(D17),ISNUMBER(E17)), D17-E17, "") -> 51680.32 | G17: =IFERROR(F17/E17, "") | H17: 28849 | I17: =IF(AND(ISNUMBER(D17),ISNUMBER(H17)), D17-H17, "") -> 22831.32 | J17: =IFERROR(I17/H17, "") -> 0.79140767
A18: Sequoia Charter School | B18: AZ | C18: =Sites[[#This Row],[SOL'#]] -> SOL-10759 | D18: 20768 | E18: 0 | F18: =IF(AND(ISNUMBER(D18),ISNUMBER(E18)), D18-E18, "") -> 20768 | G18: =IFERROR(F18/E18, "") | H18: 8180 | I18: =IF(AND(ISNUMBER(D18),ISNUMBER(H18)), D18-H18, "") -> 12588 | J18: =IFERROR(I18/H18, "") -> 1.5388753
A19: RCAB | B19: MA | C19: =Sites[[#This Row],[SOL'#]] -> SOL-10838 | D19: 23135 | E19: 43481.12 | F19: =IF(AND(ISNUMBER(D19),ISNUMBER(E19)), D19-E19, "") -> -20346.12 | G19: =IFERROR(F19/E19, "") -> -0.46792999 | H19: 47410.87 | I19: =IF(AND(ISNUMBER(D19),ISNUMBER(H19)), D19-H19, "") -> -24275.87 | J19: =IFERROR(I19/H19, "") -> -0.51203173
A20: Spectro Coatings | B20: MA | C20: =Sites[[#This Row],[SOL'#]] -> SOL-10074 | D20: 5510.625 | E20: 12146.73 | F20: =IF(AND(ISNUMBER(D20),ISNUMBER(E20)), D20-E20, "") -> -6636.105 | G20: =IFERROR(F20/E20, "") -> -0.54632852 | H20: 11789.76 | I20: =IF(AND(ISNUMBER(D20),ISNUMBER(H20)), D20-H20, "") -> -6279.135 | J20: =IFERROR(I20/H20, "") -> -0.53259227 | K20: 1. Site was offline on 1/22 at 15:30 and back online on 1/23 11:45. | L20: 1. SR080401
A21: K026 | B21: NY | C21: =Sites[[#This Row],[SOL'#]] -> SOL-10356 | D21: 7049.125 | E21: 12398.04 | F21: =IF(AND(ISNUMBER(D21),ISNUMBER(E21)), D21-E21, "") -> -5348.915 | G21: =IFERROR(F21/E21, "") -> -0.43143231 | H21: 18592.65 | I21: =IF(AND(ISNUMBER(D21),ISNUMBER(H21)), D21-H21, "") -> -11543.525 | J21: =IFERROR(I21/H21, "") -> -0.62086497
A22: K041 | B22: NY | C22: =Sites[[#This Row],[SOL'#]] -> SOL-10357 | D22: 2400.5966 | E22: 0 | F22: =IF(AND(ISNUMBER(D22),ISNUMBER(E22)), D22-E22, "") -> 2400.5966 | G22: =IFERROR(F22/E22, "") | H22: 0 | I22: =IF(AND(ISNUMBER(D22),ISNUMBER(H22)), D22-H22, "") -> 2400.5966 | J22: =IFERROR(I22/H22, "") | K22: 1. Site started production from 1/18 | L22: 1. SR079892
A23: K043 | B23: NY | C23: =Sites[[#This Row],[SOL'#]] -> SOL-10358 | D23: 7037.3281 | E23: 10909.38 | F23: =IF(AND(ISNUMBER(D23),ISNUMBER(E23)), D23-E23, "") -> -3872.0519 | G23: =IFERROR(F23/E23, "") -> -0.35492868 | H23: 20258 | I23: =IF(AND(ISNUMBER(D23),ISNUMBER(H23)), D23-H23, "") -> -13220.672 | J23: =IFERROR(I23/H23, "") -> -0.65261486
A24: K058 | B24: NY | C24: =Sites[[#This Row],[SOL'#]] -> SOL-10360 | D24: 5262.6875 | E24: 8705.562 | F24: =IF(AND(ISNUMBER(D24),ISNUMBER(E24)), D24-E24, "") -> -3442.8745 | G24: =IFERROR(F24/E24, "") -> -0.39547987 | H24: 13134.4 | I24: =IF(AND(ISNUMBER(D24),ISNUMBER(H24)), D24-H24, "") -> -7871.7125 | J24: =IFERROR(I24/H24, "") -> -0.5993203
A25: K115 | B25: NY | C25: =Sites[[#This Row],[SOL'#]] -> SOL-10361 | D25: 1496.6526 | E25: 5139.646 | F25: =IF(AND(ISNUMBER(D25),ISNUMBER(E25)), D25-E25, "") -> -3642.9934 | G25: =IFERROR(F25/E25, "") -> -0.7088024 | H25: 4549.33 | I25: =IF(AND(ISNUMBER(D25),ISNUMBER(H25)), D25-H25, "") -> -3052.6774 | J25: =IFERROR(I25/H25, "") -> -0.67101692 | K25: 1. Ongoing construction to the array on the roof. 70 percent of the array is offline for construction | L25: 1. SR077214
A26: K152 | B26: NY | C26: =Sites[[#This Row],[SOL'#]] -> SOL-10362 | D26: 1927.1875 | E26: 3008.157 | F26: =IF(AND(ISNUMBER(D26),ISNUMBER(E26)), D26-E26, "") -> -1080.9695 | G26: =IFERROR(F26/E26, "") -> -0.3593461 | H26: 798 | I26: =IF(AND(ISNUMBER(D26),ISNUMBER(H26)), D26-H26, "") -> 1129.1875 | J26: =IFERROR(I26/H26, "") -> 1.4150219
A27: K166 | B27: NY | C27: =Sites[[#This Row],[SOL'#]] -> SOL-10363 | D27: 7390.625 | E27: 11891.79 | F27: =IF(AND(ISNUMBER(D27),ISNUMBER(E27)), D27-E27, "") -> -4501.165 | G27: =IFERROR(F27/E27, "") -> -0.3785103 | H27: 18302.04 | I27: =IF(AND(ISNUMBER(D27),ISNUMBER(H27)), D27-H27, "") -> -10911.415 | J27: =IFERROR(I27/H27, "") -> -0.59618573
A28: K206 | B28: NY | C28: =Sites[[#This Row],[SOL'#]] -> SOL-10927 | D28: 4600.7732 | E28: 0 | F28: =IF(AND(ISNUMBER(D28),ISNUMBER(E28)), D28-E28, "") -> 4600.7732 | G28: =IFERROR(F28/E28, "") | H28: 0 | I28: =IF(AND(ISNUMBER(D28),ISNUMBER(H28)), D28-H28, "") -> 4600.7732 | J28: =IFERROR(I28/H28, "")
A29: K251 | B29: NY | C29: =Sites[[#This Row],[SOL'#]] -> SOL-10365 | D29: 4966.375 | E29: 7470.177 | F29: =IF(AND(ISNUMBER(D29),ISNUMBER(E29)), D29-E29, "") -> -2503.802 | G29: =IFERROR(F29/E29, "") -> -0.33517305 | H29: 9815.687 | I29: =IF(AND(ISNUMBER(D29),ISNUMBER(H29)), D29-H29, "") -> -4849.312 | J29: =IFERROR(I29/H29, "") -> -0.49403694
A30: K269 | B30: NY | C30: =Sites[[#This Row],[SOL'#]] -> SOL-10366 | D30: 4328.3125 | E30: 0 | F30: =IF(AND(ISNUMBER(D30),ISNUMBER(E30)), D30-E30, "") -> 4328.3125 | G30: =IFERROR(F30/E30, "") | H30: 10978.73 | I30: =IF(AND(ISNUMBER(D30),ISNUMBER(H30)), D30-H30, "") -> -6650.4175 | J30: =IFERROR(I30/H30, "") -> -0.60575472
A31: K273 | B31: NY | C31: =Sites[[#This Row],[SOL'#]] -> SOL-10367 | D31: 5062.0312 | E31: 0 | F31: =IF(AND(ISNUMBER(D31),ISNUMBER(E31)), D31-E31, "") -> 5062.0312 | G31: =IFERROR(F31/E31, "") | H31: 11224 | I31: =IF(AND(ISNUMBER(D31),ISNUMBER(H31)), D31-H31, "") -> -6161.9688 | J31: =IFERROR(I31/H31, "") -> -0.54899935
A32: K287 | B32: NY | C32: =Sites[[#This Row],[SOL'#]] -> SOL-10919 | D32: 3720.0499 | E32: 5487.586 | F32: =IF(AND(ISNUMBER(D32),ISNUMBER(E32)), D32-E32, "") -> -1767.5361 | G32: =IFERROR(F32/E32, "") -> -0.3220972 | H32: 0 | I32: =IF(AND(ISNUMBER(D32),ISNUMBER(H32)), D32-H32, "") -> 3720.0499 | J32: =IFERROR(I32/H32, "")
A33: K298 | B33: NY | C33: =Sites[[#This Row],[SOL'#]] -> SOL-10368 | D33: 3421.0781 | E33: 7008.588 | F33: =IF(AND(ISNUMBER(D33),ISNUMBER(E33)), D33-E33, "") -> -3587.5099 | G33: =IFERROR(F33/E33, "") -> -0.51187342 | H33: 0 | I33: =IF(AND(ISNUMBER(D33),ISNUMBER(H33)), D33-H33, "") -> 3421.0781 | J33: =IFERROR(I33/H33, "") | K33: 1. Inverter 1 primary unit offline on 01/19/2024 & back online 01/25/2024 at 10:00. | L33: 1. SR080472
A34: K335 | B34: NY | C34: =Sites[[#This Row],[SOL'#]] -> SOL-10370 | D34: 4100.5625 | E34: 7358.259 | F34: =IF(AND(ISNUMBER(D34),ISNUMBER(E34)), D34-E34, "") -> -3257.6965 | G34: =IFERROR(F34/E34, "") -> -0.44272653 | H34: 11610 | I34: =IF(AND(ISNUMBER(D34),ISNUMBER(H34)), D34-H34, "") -> -7509.4375 | J34: =IFERROR(I34/H34, "") -> -0.64680771
A35: K345 | B35: NY | C35: =Sites[[#This Row],[SOL'#]] -> SOL-10920 | D35: 4561.2969 | E35: 0 | F35: =IF(AND(ISNUMBER(D35),ISNUMBER(E35)), D35-E35, "") -> 4561.2969 | G35: =IFERROR(F35/E35, "") | H35: 0 | I35: =IF(AND(ISNUMBER(D35),ISNUMBER(H35)), D35-H35, "") -> 4561.2969 | J35: =IFERROR(I35/H35, "") | K35: 1. Site tripped offline on 01/11 at 8:15 and back online at 11:15, but inverter 2 again tripped offline 2. Inverter 2 tripped offline on 01/11 at 11:45 and back online on 01/12 | L35: 1. SR080156 2. SR080165
A36: K445 | B36: NY | C36: =Sites[[#This Row],[SOL'#]] -> SOL-10373 | D36: 4488.8051 | E36: 0 | F36: =IF(AND(ISNUMBER(D36),ISNUMBER(E36)), D36-E36, "") -> 4488.8051 | G36: =IFERROR(F36/E36, "") | H36: 0 | I36: =IF(AND(ISNUMBER(D36),ISNUMBER(H36)), D36-H36, "") -> 4488.8051 | J36: =IFERROR(I36/H36, "")
A37: K495 | B37: NY | C37: =Sites[[#This Row],[SOL'#]] -> SOL-10374 | D37: 20449.188 | E37: 0 | F37: =IF(AND(ISNUMBER(D37),ISNUMBER(E37)), D37-E37, "") -> 20449.188 | G37: =IFERROR(F37/E37, "") | H37: 0 | I37: =IF(AND(ISNUMBER(D37),ISNUMBER(H37)), D37-H37, "") -> 20449.188 | J37: =IFERROR(I37/H37, "") | K37: 1. Inverter 4 tripped offline at 10:50 at 01/17 & back online on 01/20/2024. 2. Inverter 8 left unit offline on 01/07/2024 & back online at 01/08/2024 and also left unit offline from 01/16 to 01/22 | L37: 1.SR080297 2.SR080299
A38: M020 | B38: NY | C38: =Sites[[#This Row],[SOL'#]] -> SOL-10380 | D38: 4382.6562 | E38: 7052.359 | F38: =IF(AND(ISNUMBER(D38),ISNUMBER(E38)), D38-E38, "") -> -2669.7028 | G38: =IFERROR(F38/E38, "") -> -0.37855457 | H38: 0 | I38: =IF(AND(ISNUMBER(D38),ISNUMBER(H38)), D38-H38, "") -> 4382.6562 | J38: =IFERROR(I38/H38, "")
A39: M092 | B39: NY | C39: =Sites[[#This Row],[SOL'#]] -> SOL-10383 | D39: 4470.75 | E39: 7217.819 | F39: =IF(AND(ISNUMBER(D39),ISNUMBER(E39)), D39-E39, "") -> -2747.069 | G39: =IFERROR(F39/E39, "") -> -0.38059544 | H39: 11299.41 | I39: =IF(AND(ISNUMBER(D39),ISNUMBER(H39)), D39-H39, "") -> -6828.66 | J39: =IFERROR(I39/H39, "") -> -0.60433775
