Workbook
Name JanActual: #REF!
Name JanActual2: #REF!
Name JanExpected: #REF!
Name JanExpectedDelta: #REF!
Name JanExpectedPercent: #REF!
Name JanExpPercent: #REF!
Name JanForecasted: #REF!
Name JanForecastedDelta: #REF!
Name JanForecastedPercent: #REF!
Name portfolio: Sites!$B$1:$B$1
Name Year: Sites!#REF!

Sheet Year to Date
A1: {=portfolio} -> CITI | D1: PPA Modeled Output | E1: Production VS Acual | F1: Year to Date Actual v. Expected | I1: Year to Date Actual v. Forecasted
A2: Total | C2: =SUM(C4:C100) -> 8666517.4 | D2: =SUM(D4:D22) -> 9089296.7 | E2: =C2/D2 -> 0.95348603 | F2: =SUM(F4:F100) -> 9048736.4 | G2: =C2-F2 -> -382218.99 | H2: =IFERROR(G2/F2, 0) -> -0.04224004 | I2: =SUM(I4:I100) -> 9166088.8 | J2: =C2-I2 -> -499571.43 | K2: =IFERROR(J2/I2, 0) -> -0.054502137
A3: Site | B3: State | C3: Actual | F3: Expected | G3: Delta | H3: % | I3: Forecasted | J3: Delta | K3: %
A4: {=Sites[Site]} -> CA: Antioch Deer Valley - Citi | B4: {=Sites[State]} -> CA | C4: =SUM('1st Qtr'!C4, '2nd Qtr'!C4, '3rd Qtr'!C4, '4th Qtr'!C4) -> 262772.75 | D4: =SUM('1st Qtr'!D4,'2nd Qtr'!D4,'3rd Qtr'!D4,'4th Qtr'!D4) -> 254868.74 | E4: =C4/D4 -> 1.0310121 | F4: =SUM('1st Qtr'!F4, '2nd Qtr'!F4, '3rd Qtr'!F4, '4th Qtr'!F4) -> 252345 | G4: =IF(AND(ISNUMBER(C4),ISNUMBER(F4)), C4-F4, "") -> 10427.75 | H4: =IFERROR(G4/F4, "") -> 0.041323387 | I4: =SUM('1st Qtr'!I4,'2nd Qtr'!I4,'3rd Qtr'!I4,'4th Qtr'!I4) -> 271155.53 | J4: =SUM('1st Qtr'!J4, '2nd Qtr'!J4, '3rd Qtr'!J4, '4th Qtr'!J4) -> -8382.782 | K4: =IFERROR(J4/I4, "") -> -0.030915032
A5: CA: Antioch MC CUP - Citi | B5: CA | C5: =SUM('1st Qtr'!C5, '2nd Qtr'!C5, '3rd Qtr'!C5, '4th Qtr'!C5) -> 899080 | D5: =SUM('1st Qtr'!D5,'2nd Qtr'!D5,'3rd Qtr'!D5,'4th Qtr'!D5) -> 858006.18 | E5: =C5/D5 -> 1.0478712 | F5: =SUM('1st Qtr'!F5, '2nd Qtr'!F5, '3rd Qtr'!F5, '4th Qtr'!F5) -> 849436 | G5: =IF(AND(ISNUMBER(C5),ISNUMBER(F5)), C5-F5, "") -> 49644 | H5: =IFERROR(G5/F5, "") -> 0.058443485 | I5: =SUM('1st Qtr'!I5,'2nd Qtr'!I5,'3rd Qtr'!I5,'4th Qtr'!I5) -> 938022.99 | J5: =SUM(Jan!J5, Feb!J5, Mar!K5) -> -18801.31 | K5: =IFERROR(J5/I5, "") -> -0.020043549
A6: CA: Clovis - Citi | B6: CA | C6: =SUM('1st Qtr'!C6, '2nd Qtr'!C6, '3rd Qtr'!C6, '4th Qtr'!C6) -> 369447 | D6: =SUM('1st Qtr'!D6,'2nd Qtr'!D6,'3rd Qtr'!D6,'4th Qtr'!D6) -> 357752 | E6: =C6/D6 -> 1.0326902 | F6: =SUM('1st Qtr'!F6, '2nd Qtr'!F6, '3rd Qtr'!F6, '4th Qtr'!F6) -> 345399 | G6: =IF(AND(ISNUMBER(C6),ISNUMBER(F6)), C6-F6, "") -> 24048 | H6: =IFERROR(G6/F6, "") -> 0.069623826 | I6: =SUM('1st Qtr'!I6,'2nd Qtr'!I6,'3rd Qtr'!I6,'4th Qtr'!I6) -> 156099.67 | J6: =SUM(Jan!J6, Feb!J6, Mar!K6) -> 37638.94 | K6: =IFERROR(J6/I6, "") -> 0.2411212
A7: CA: Elk Grove MOB - Citi | B7: CA | C7: =SUM('1st Qtr'!C7, '2nd Qtr'!C7, '3rd Qtr'!C7, '4th Qtr'!C7) -> 570859.5 | D7: =SUM('1st Qtr'!D7,'2nd Qtr'!D7,'3rd Qtr'!D7,'4th Qtr'!D7) -> 572482 | E7: =C7/D7 -> 0.99716585 | F7: =SUM('1st Qtr'!F7, '2nd Qtr'!F7, '3rd Qtr'!F7, '4th Qtr'!F7) -> 566814 | G7: =IF(AND(ISNUMBER(C7),ISNUMBER(F7)), C7-F7, "") -> 4045.5 | H7: =IFERROR(G7/F7, "") -> 0.007137262 | I7: =SUM('1st Qtr'!I7,'2nd Qtr'!I7,'3rd Qtr'!I7,'4th Qtr'!I7) -> 612154 | J7: =SUM(Jan!J7, Feb!J7, Mar!K7) -> -16876.8 | K7: =IFERROR(J7/I7, "") -> -0.027569533
A8: CA: Elk Grove Promenade - Citi | B8: CA | C8: =SUM('1st Qtr'!C8, '2nd Qtr'!C8, '3rd Qtr'!C8, '4th Qtr'!C8) -> 305726.5 | D8: =SUM('1st Qtr'!D8,'2nd Qtr'!D8,'3rd Qtr'!D8,'4th Qtr'!D8) -> 306797.5 | E8: =C8/D8 -> 0.9965091 | F8: =SUM('1st Qtr'!F8, '2nd Qtr'!F8, '3rd Qtr'!F8, '4th Qtr'!F8) -> 303789.99 | G8: =IF(AND(ISNUMBER(C8),ISNUMBER(F8)), C8-F8, "") -> 1936.511 | H8: =IFERROR(G8/F8, "") -> 0.0063745056 | I8: =SUM('1st Qtr'!I8,'2nd Qtr'!I8,'3rd Qtr'!I8,'4th Qtr'!I8) -> 330878.15 | J8: =SUM(Jan!J8, Feb!J8, Mar!K8) -> -13241.198 | K8: =IFERROR(J8/I8, "") -> -0.040018351
A9: CA: Fresno Sequioa - Citi | B9: CA | C9: =SUM('1st Qtr'!C9, '2nd Qtr'!C9, '3rd Qtr'!C9, '4th Qtr'!C9) -> 596072.5 | D9: =SUM('1st Qtr'!D9,'2nd Qtr'!D9,'3rd Qtr'!D9,'4th Qtr'!D9) -> 609190.56 | E9: =C9/D9 -> 0.97846641 | F9: =SUM('1st Qtr'!F9, '2nd Qtr'!F9, '3rd Qtr'!F9, '4th Qtr'!F9) -> 603281 | G9: =IF(AND(ISNUMBER(C9),ISNUMBER(F9)), C9-F9, "") -> -7208.5 | H9: =IFERROR(G9/F9, "") -> -0.011948827 | I9: =SUM('1st Qtr'!I9,'2nd Qtr'!I9,'3rd Qtr'!I9,'4th Qtr'!I9) -> 653449.11 | J9: =SUM(Jan!J9, Feb!J9, Mar!K9) -> -32740.3 | K9: =IFERROR(J9/I9, "") -> -0.050103825
A10: CA: Fresno MOB - Citi | B10: CA | C10: =SUM('1st Qtr'!C10, '2nd Qtr'!C10, '3rd Qtr'!C10, '4th Qtr'!C10) -> 217563.75 | D10: =SUM('1st Qtr'!D10,'2nd Qtr'!D10,'3rd Qtr'!D10,'4th Qtr'!D10) -> 246770.88 | E10: =C10/D10 -> 0.88164272 | F10: =SUM('1st Qtr'!F10, '2nd Qtr'!F10, '3rd Qtr'!F10, '4th Qtr'!F10) -> 245682 | G10: =IF(AND(ISNUMBER(C10),ISNUMBER(F10)), C10-F10, "") -> -28118.25 | H10: =IFERROR(G10/F10, "") -> -0.11444978 | I10: =SUM('1st Qtr'!I10,'2nd Qtr'!I10,'3rd Qtr'!I10,'4th Qtr'!I10) -> 232964.72 | J10: =SUM(Jan!J10, Feb!J10, Mar!K10) -> -6133.546 | K10: =IFERROR(J10/I10, "") -> -0.026328218
A11: CA: Modesto Bangs - Citi | B11: CA | C11: =SUM('1st Qtr'!C11, '2nd Qtr'!C11, '3rd Qtr'!C11, '4th Qtr'!C11) -> 153396.75 | D11: =SUM('1st Qtr'!D11,'2nd Qtr'!D11,'3rd Qtr'!D11,'4th Qtr'!D11) -> 162323.72 | E11: =C11/D11 -> 0.94500514 | F11: =SUM('1st Qtr'!F11, '2nd Qtr'!F11, '3rd Qtr'!F11, '4th Qtr'!F11) -> 161587 | G11: =IF(AND(ISNUMBER(C11),ISNUMBER(F11)), C11-F11, "") -> -8190.25 | H11: =IFERROR(G11/F11, "") -> -0.050686318 | I11: =SUM('1st Qtr'!I11,'2nd Qtr'!I11,'3rd Qtr'!I11,'4th Qtr'!I11) -> 78130.415 | J11: =SUM(Jan!J11, Feb!J11, Mar!K11) -> -1666.312 | K11: =IFERROR(J11/I11, "") -> -0.021327315
A12: CA: Napa Data Center - Citi | B12: CA | C12: =SUM('1st Qtr'!C12, '2nd Qtr'!C12, '3rd Qtr'!C12, '4th Qtr'!C12) -> 156201.13 | D12: =SUM('1st Qtr'!D12,'2nd Qtr'!D12,'3rd Qtr'!D12,'4th Qtr'!D12) -> 177624.29 | E12: =C12/D12 -> 0.87939059 | F12: =SUM('1st Qtr'!F12, '2nd Qtr'!F12, '3rd Qtr'!F12, '4th Qtr'!F12) -> 171156 | G12: =IF(AND(ISNUMBER(C12),ISNUMBER(F12)), C12-F12, "") -> -14954.87 | H12: =IFERROR(G12/F12, "") -> -0.087375669 | I12: =SUM('1st Qtr'!I12,'2nd Qtr'!I12,'3rd Qtr'!I12,'4th Qtr'!I12) -> 184666.18 | J12: =SUM(Jan!J12, Feb!J12, Mar!K12) -> -13452.905 | K12: =IFERROR(J12/I12, "") -> -0.072849858
A13: CA: Petaluma MOB - Citi | B13: CA | C13: =SUM('1st Qtr'!C13, '2nd Qtr'!C13, '3rd Qtr'!C13, '4th Qtr'!C13) -> 269808.5 | D13: =SUM('1st Qtr'!D13,'2nd Qtr'!D13,'3rd Qtr'!D13,'4th Qtr'!D13) -> 359736.5 | E13: =C13/D13 -> 0.75001703 | F13: =SUM('1st Qtr'!F13, '2nd Qtr'!F13, '3rd Qtr'!F13, '4th Qtr'!F13) -> 394293 | G13: =IF(AND(ISNUMBER(C13),ISNUMBER(F13)), C13-F13, "") -> -124484.5 | H13: =IFERROR(G13/F13, "") -> -0.31571572 | I13: =SUM('1st Qtr'!I13,'2nd Qtr'!I13,'3rd Qtr'!I13,'4th Qtr'!I13) -> 229461.42 | J13: =SUM(Jan!J13, Feb!J13, Mar!K13) -> -25903.39 | K13: =IFERROR(J13/I13, "") -> -0.11288778
A14: CA: Pleasanton Tec Ctr - Citi | B14: CA | C14: =SUM('1st Qtr'!C14, '2nd Qtr'!C14, '3rd Qtr'!C14, '4th Qtr'!C14) -> 491256.5 | D14: =SUM('1st Qtr'!D14,'2nd Qtr'!D14,'3rd Qtr'!D14,'4th Qtr'!D14) -> 565350.36 | E14: =C14/D14 -> 0.86894169 | F14: =SUM('1st Qtr'!F14, '2nd Qtr'!F14, '3rd Qtr'!F14, '4th Qtr'!F14) -> 559567 | G14: =IF(AND(ISNUMBER(C14),ISNUMBER(F14)), C14-F14, "") -> -68310.5 | H14: =IFERROR(G14/F14, "") -> -0.12207743 | I14: =SUM('1st Qtr'!I14,'2nd Qtr'!I14,'3rd Qtr'!I14,'4th Qtr'!I14) -> 583727.48 | J14: =SUM(Jan!J14, Feb!J14, Mar!K14) -> -32875.356 | K14: =IFERROR(J14/I14, "") -> -0.056319699
A15: CA: Rancho Cordova - Citi | B15: CA | C15: =SUM('1st Qtr'!C15, '2nd Qtr'!C15, '3rd Qtr'!C15, '4th Qtr'!C15) -> 882780 | D15: =SUM('1st Qtr'!D15,'2nd Qtr'!D15,'3rd Qtr'!D15,'4th Qtr'!D15) -> 819342.78 | E15: =C15/D15 -> 1.0774245 | F15: =SUM('1st Qtr'!F15, '2nd Qtr'!F15, '3rd Qtr'!F15, '4th Qtr'!F15) -> 812545 | G15: =IF(AND(ISNUMBER(C15),ISNUMBER(F15)), C15-F15, "") -> 70235 | H15: =IFERROR(G15/F15, "") -> 0.08643829 | I15: =SUM('1st Qtr'!I15,'2nd Qtr'!I15,'3rd Qtr'!I15,'4th Qtr'!I15) -> 922891.69 | J15: =SUM(Jan!J15, Feb!J15, Mar!K15) -> -17879.21 | K15: =IFERROR(J15/I15, "") -> -0.019373032
A16: CA: S Sacramento Wyndham - Citi | B16: CA | C16: =SUM('1st Qtr'!C16, '2nd Qtr'!C16, '3rd Qtr'!C16, '4th Qtr'!C16) -> 463570.5 | D16: =SUM('1st Qtr'!D16,'2nd Qtr'!D16,'3rd Qtr'!D16,'4th Qtr'!D16) -> 494454.69 | E16: =C16/D16 -> 0.93753889 | F16: =SUM('1st Qtr'!F16, '2nd Qtr'!F16, '3rd Qtr'!F16, '4th Qtr'!F16) -> 487036 | G16: =IF(AND(ISNUMBER(C16),ISNUMBER(F16)), C16-F16, "") -> -23465.5 | H16: =IFERROR(G16/F16, "") -> -0.048180217 | I16: =SUM('1st Qtr'!I16,'2nd Qtr'!I16,'3rd Qtr'!I16,'4th Qtr'!I16) -> 488571.76 | J16: =SUM(Jan!J16, Feb!J16, Mar!K16) -> -1200.123 | K16: =IFERROR(J16/I16, "") -> -0.0024563905
... A22: CA: Manteca - KP Manteca Hospital | B22: CA | C22: =SUM('1st Qtr'!C22, '2nd Qtr'!C22, '3rd Qtr'!C22, '4th Qtr'!C22) -> 360631.13 | D22: =SUM('1st Qtr'!D22,'2nd Qtr'!D22,'3rd Qtr'!D22,'4th Qtr'!D22) -> 400258 | E22: =C22/D22 -> 0.90099668 | F22: =SUM('1st Qtr'!F22, '2nd Qtr'!F22, '3rd Qtr'!F22, '4th Qtr'!F22) -> 401309.38 | G22: =IF(AND(ISNUMBER(C22),ISNUMBER(F22)), C22-F22, "") -> -40678.25 | H22: =IFERROR(G22/F22, "") -> -0.10136382 | I22: =SUM('1st Qtr'!I22,'2nd Qtr'!I22,'3rd Qtr'!I22,'4th Qtr'!I22) -> 370231.52 | J22: =SUM(Jan!J22, Feb!J22, Mar!K22) -> -6367.164 | K22: =IFERROR(J22/I22, "") -> -0.01719779
A23: Sacramento - KP South Sacramento HSP | B23: CA

Sheet 1st Qtr
A1: {=portfolio} -> CITI | D1: PPA Modeled Output | E1: Production VS Acual | F1: 1st Quarter Actual v. Expected | I1: 1st Quarter Actual v. Forecasted
A2: Total | C2: =SUM(C4:C100) -> 3997407.8 | D2: =SUM(D4:D22) -> 3960868.1 | E2: =C2/D2 -> 1.0092252 | F2: =SUM(F4:F100) -> 3987723.8 | G2: =C2-F2 -> 9683.939 | H2: =IFERROR(G2/F2, 0) -> 0.0024284377 | I2: =SUM(I4:I100) -> 4290441.3 | J2: =C2-I2 -> -293033.57 | K2: =IFERROR(J2/I2, 0) -> -0.068299167
A3: Site | B3: State | C3: Actual | F3: Expected | G3: Delta | H3: % | I3: Forecasted | J3: Delta | K3: %
A4: {=Sites[Site]} -> CA: Antioch Deer Valley - Citi | B4: {=Sites[State]} -> CA | C4: =SUM(Jan!C4, Feb!C4, Mar!C4) -> 114367.75 | D4: =SUM(Jan!D4,Feb!D4,Mar!D4) -> 115399.63 | E4: =C4/D4 -> 0.9910582 | F4: =SUM(Jan!F4, Feb!F4, Mar!G4) -> 114257 | G4: =IF(AND(ISNUMBER(C4),ISNUMBER(F4)), C4-F4, "") -> 110.75 | H4: =IFERROR(G4/F4, "") -> 0.00096930604 | I4: =SUM(Jan!I4, Feb!I4, Mar!J4) -> 117533.72 | J4: =SUM(Jan!J4, Feb!J4, Mar!K4) -> -3165.967 | K4: =IFERROR(J4/I4, "") -> -0.02693667
A5: CA: Antioch MC CUP - Citi | B5: CA | C5: =SUM(Jan!C5, Feb!C5, Mar!C5) -> 407599 | D5: =SUM(Jan!D5,Feb!D5,Mar!D5) -> 382684.3 | E5: =C5/D5 -> 1.0651051 | F5: =SUM(Jan!F5, Feb!F5, Mar!G5) -> 378862 | G5: =IF(AND(ISNUMBER(C5),ISNUMBER(F5)), C5-F5, "") -> 28737 | H5: =IFERROR(G5/F5, "") -> 0.075850838 | I5: =SUM(Jan!I5, Feb!I5, Mar!J5) -> 426400.31 | J5: =SUM(Jan!J5, Feb!J5, Mar!K5) -> -18801.31 | K5: =IFERROR(J5/I5, "") -> -0.044093096
A6: CA: Clovis - Citi | B6: CA | C6: =SUM(Jan!C6, Feb!C6, Mar!C6) -> 169263.25 | D6: =SUM(Jan!D6,Feb!D6,Mar!D6) -> 152182.5 | E6: =C6/D6 -> 1.1122386 | F6: =SUM(Jan!F6, Feb!F6, Mar!G6) -> 146927 | G6: =IF(AND(ISNUMBER(C6),ISNUMBER(F6)), C6-F6, "") -> 22336.25 | H6: =IFERROR(G6/F6, "") -> 0.15202277 | I6: =SUM(Jan!I6, Feb!I6, Mar!J6) -> 131624.31 | J6: =SUM(Jan!J6, Feb!J6, Mar!K6) -> 37638.94 | K6: =IFERROR(J6/I6, "") -> 0.28595736
A7: CA: Elk Grove MOB - Citi | B7: CA | C7: =SUM(Jan!C7, Feb!C7, Mar!C7) -> 253724 | D7: =SUM(Jan!D7,Feb!D7,Mar!D7) -> 246151.5 | E7: =C7/D7 -> 1.0307636 | F7: =SUM(Jan!F7, Feb!F7, Mar!G7) -> 243714 | G7: =IF(AND(ISNUMBER(C7),ISNUMBER(F7)), C7-F7, "") -> 10010 | H7: =IFERROR(G7/F7, "") -> 0.041072733 | I7: =SUM(Jan!I7, Feb!I7, Mar!J7) -> 270600.8 | J7: =SUM(Jan!J7, Feb!J7, Mar!K7) -> -16876.8 | K7: =IFERROR(J7/I7, "") -> -0.062367887
A8: CA: Elk Grove Promenade - Citi | B8: CA | C8: =SUM(Jan!C8, Feb!C8, Mar!C8) -> 138337 | D8: =SUM(Jan!D8,Feb!D8,Mar!D8) -> 134028.5 | E8: =C8/D8 -> 1.0321461 | F8: =SUM(Jan!F8, Feb!F8, Mar!G8) -> 132731.36 | G8: =IF(AND(ISNUMBER(C8),ISNUMBER(F8)), C8-F8, "") -> 5605.644 | H8: =IFERROR(G8/F8, "") -> 0.042233005 | I8: =SUM(Jan!I8, Feb!I8, Mar!J8) -> 151578.2 | J8: =SUM(Jan!J8, Feb!J8, Mar!K8) -> -13241.198 | K8: =IFERROR(J8/I8, "") -> -0.087355558
A9: CA: Fresno Sequioa - Citi | B9: CA | C9: =SUM(Jan!C9, Feb!C9, Mar!C9) -> 267893 | D9: =SUM(Jan!D9,Feb!D9,Mar!D9) -> 267133.21 | E9: =C9/D9 -> 1.0028442 | F9: =SUM(Jan!F9, Feb!F9, Mar!G9) -> 264542 | G9: =IF(AND(ISNUMBER(C9),ISNUMBER(F9)), C9-F9, "") -> 3351 | H9: =IFERROR(G9/F9, "") -> 0.012667176 | I9: =SUM(Jan!I9, Feb!I9, Mar!J9) -> 300633.3 | J9: =SUM(Jan!J9, Feb!J9, Mar!K9) -> -32740.3 | K9: =IFERROR(J9/I9, "") -> -0.10890444
A10: CA: Fresno MOB - Citi | B10: CA | C10: =SUM(Jan!C10, Feb!C10, Mar!C10) -> 102206.13 | D10: =SUM(Jan!D10,Feb!D10,Mar!D10) -> 107787.71 | E10: =C10/D10 -> 0.94821692 | F10: =SUM(Jan!F10, Feb!F10, Mar!G10) -> 107041 | G10: =IF(AND(ISNUMBER(C10),ISNUMBER(F10)), C10-F10, "") -> -4834.87 | H10: =IFERROR(G10/F10, "") -> -0.045168393 | I10: =SUM(Jan!I10, Feb!I10, Mar!J10) -> 108339.68 | J10: =SUM(Jan!J10, Feb!J10, Mar!K10) -> -6133.546 | K10: =IFERROR(J10/I10, "") -> -0.056614033
A11: CA: Modesto Bangs - Citi | B11: CA | C11: =SUM(Jan!C11, Feb!C11, Mar!C11) -> 68432.75 | D11: =SUM(Jan!D11,Feb!D11,Mar!D11) -> 63424.51 | E11: =C11/D11 -> 1.0789638 | F11: =SUM(Jan!F11, Feb!F11, Mar!G11) -> 63171 | G11: =IF(AND(ISNUMBER(C11),ISNUMBER(F11)), C11-F11, "") -> 5261.75 | H11: =IFERROR(G11/F11, "") -> 0.083293758 | I11: =SUM(Jan!I11, Feb!I11, Mar!J11) -> 70099.062 | J11: =SUM(Jan!J11, Feb!J11, Mar!K11) -> -1666.312 | K11: =IFERROR(J11/I11, "") -> -0.023770817
A12: CA: Napa Data Center - Citi | B12: CA | C12: =SUM(Jan!C12, Feb!C12, Mar!C12) -> 69031.88 | D12: =SUM(Jan!D12,Feb!D12,Mar!D12) -> 78540.47 | E12: =C12/D12 -> 0.87893388 | F12: =SUM(Jan!F12, Feb!F12, Mar!G12) -> 75905 | G12: =IF(AND(ISNUMBER(C12),ISNUMBER(F12)), C12-F12, "") -> -6873.12 | H12: =IFERROR(G12/F12, "") -> -0.090548976 | I12: =SUM(Jan!I12, Feb!I12, Mar!J12) -> 82484.785 | J12: =SUM(Jan!J12, Feb!J12, Mar!K12) -> -13452.905 | K12: =IFERROR(J12/I12, "") -> -0.16309559
A13: CA: Petaluma MOB - Citi | B13: CA | C13: =SUM(Jan!C13, Feb!C13, Mar!C13) -> 148819.5 | D13: =SUM(Jan!D13,Feb!D13,Mar!D13) -> 130900.23 | E13: =C13/D13 -> 1.1368926 | F13: =SUM(Jan!F13, Feb!F13, Mar!G13) -> 174082 | G13: =IF(AND(ISNUMBER(C13),ISNUMBER(F13)), C13-F13, "") -> -25262.5 | H13: =IFERROR(G13/F13, "") -> -0.14511839 | I13: =SUM(Jan!I13, Feb!I13, Mar!J13) -> 174722.89 | J13: =SUM(Jan!J13, Feb!J13, Mar!K13) -> -25903.39 | K13: =IFERROR(J13/I13, "") -> -0.14825413
A14: CA: Pleasanton Tec Ctr - Citi | B14: CA | C14: =SUM(Jan!C14, Feb!C14, Mar!C14) -> 229990.5 | D14: =SUM(Jan!D14,Feb!D14,Mar!D14) -> 252333.64 | E14: =C14/D14 -> 0.91145398 | F14: =SUM(Jan!F14, Feb!F14, Mar!G14) -> 249546 | G14: =IF(AND(ISNUMBER(C14),ISNUMBER(F14)), C14-F14, "") -> -19555.5 | H14: =IFERROR(G14/F14, "") -> -0.07836431 | I14: =SUM(Jan!I14, Feb!I14, Mar!J14) -> 262865.86 | J14: =SUM(Jan!J14, Feb!J14, Mar!K14) -> -32875.356 | K14: =IFERROR(J14/I14, "") -> -0.12506514
A15: CA: Rancho Cordova - Citi | B15: CA | C15: =SUM(Jan!C15, Feb!C15, Mar!C15) -> 427880 | D15: =SUM(Jan!D15,Feb!D15,Mar!D15) -> 377789.61 | E15: =C15/D15 -> 1.1325881 | F15: =SUM(Jan!F15, Feb!F15, Mar!G15) -> 373634 | G15: =IF(AND(ISNUMBER(C15),ISNUMBER(F15)), C15-F15, "") -> 54246 | H15: =IFERROR(G15/F15, "") -> 0.14518486 | I15: =SUM(Jan!I15, Feb!I15, Mar!J15) -> 445759.21 | J15: =SUM(Jan!J15, Feb!J15, Mar!K15) -> -17879.21 | K15: =IFERROR(J15/I15, "") -> -0.040109569
A16: CA: S Sacramento Wyndham - Citi | B16: CA | C16: =SUM(Jan!C16, Feb!C16, Mar!C16) -> 212055 | D16: =SUM(Jan!D16,Feb!D16,Mar!D16) -> 211985.13 | E16: =C16/D16 -> 1.0003296 | F16: =SUM(Jan!F16, Feb!F16, Mar!G16) -> 209458 | G16: =IF(AND(ISNUMBER(C16),ISNUMBER(F16)), C16-F16, "") -> 2597 | H16: =IFERROR(G16/F16, "") -> 0.012398667 | I16: =SUM(Jan!I16, Feb!I16, Mar!J16) -> 213255.12 | J16: =SUM(Jan!J16, Feb!J16, Mar!K16) -> -1200.123 | K16: =IFERROR(J16/I16, "") -> -0.0056276397
... A21: CA: Vacaville Hospital | B21: CA | C21: =SUM(Jan!C21, Feb!C21, Mar!C21) -> 519252.25 | D21: =SUM(Jan!D21,Feb!D21,Mar!D21) -> 553199.78 | E21: =C21/D21 -> 0.93863423 | F21: =SUM(Jan!F21, Feb!F21, Mar!G21) -> 551443 | G21: =IF(AND(ISNUMBER(C21),ISNUMBER(F21)), C21-F21, "") -> -32190.75 | H21: =IFERROR(G21/F21, "") -> -0.05837548 | I21: =SUM(Jan!I21, Feb!I21, Mar!J21) -> 552775.64 | J21: =SUM(Jan!J21, Feb!J21, Mar!K21) -> -33523.387 | K21: =IFERROR(J21/I21, "") -> -0.060645558
A22: CA: Manteca - KP Manteca Hospital | B22: CA | C22: =SUM(Jan!C22, Feb!C22, Mar!C22) -> 185587.5 | D22: =SUM(Jan!D22,Feb!D22,Mar!D22) -> 168096 | E22: =C22/D22 -> 1.1040566 | F22: =SUM(Jan!F22, Feb!F22, Mar!G22) -> 182590.46 | G22: =IF(AND(ISNUMBER(C22),ISNUMBER(F22)), C22-F22, "") -> 2997.035 | I22: =SUM(Jan!I22, Feb!I22, Mar!J22) -> 191954.66 | J22: =SUM(Jan!J22, Feb!J22, Mar!K22) -> -6367.164 | K22: =IFERROR(J22/I22, "") -> -0.033170145
A23: Sacramento - KP South Sacramento HSP | B23: CA

Sheet 2nd Qtr
A1: {=portfolio} -> CITI | D1: PPA Modeled Output | E1: Production VS Acual | F1: 2nd Quarter Actual v. Expected | I1: 2nd Quarter Actual v. Forecasted
A2: Total | C2: =SUM(C4:C99) -> 5341286.8 | D2: =SUM(D4:D22) -> 5128428.5 | E2: =C2/D2 -> 1.0415055 | F2: =SUM(D4:D99) -> 5128428.5 | G2: =C2-F2 -> 212858.22 | H2: =IFERROR(G2/F2, 0) -> 0.041505545 | I2: =SUM(G4:G99) -> -125585.78 | J2: =C2-I2 -> 5466872.5 | K2: =IFERROR(J2/I2, 0) -> -43.530984
A3: Site | B3: State | C3: Actual | F3: Expected | G3: Delta | H3: % | I3: Forecasted | J3: Delta | K3: %
A4: {=Sites[Site]} -> CA: Antioch Deer Valley - Citi | B4: {=Sites[State]} -> CA | C4: =SUM(Apr!C4, May!C4, Jun!C4) -> 148405 | D4: =SUM(Apr!D4,May!D4,Jun!D4) -> 139469.11 | E4: =C4/D4 -> 1.0640707 | F4: =SUM(Apr!F4, May!F4, Jun!G4) -> 138088 | G4: =IF(AND(ISNUMBER(C4),ISNUMBER(F4)), C4-F4, "") -> 10317 | H4: =IFERROR(G4/F4, "") -> 0.074713226 | I4: =SUM(Apr!I4+May!I4+Jun!J4) -> 153621.82 | J4: =SUM(Apr!J4, May!J4, Jun!K4) -> -5216.815 | K4: =IFERROR(J4/I4, "") -> -0.033958816
A5: CA: Antioch MC CUP - Citi | B5: CA | C5: =SUM(Apr!C5, May!C5, Jun!C5) -> 491481 | D5: =SUM(Apr!D5,May!D5,Jun!D5) -> 475321.88 | E5: =C5/D5 -> 1.0339962 | F5: =SUM(Apr!F5, May!F5, Jun!G5) -> 470574 | G5: =IF(AND(ISNUMBER(C5),ISNUMBER(F5)), C5-F5, "") -> 20907 | H5: =IFERROR(G5/F5, "") -> 0.044428719 | I5: =SUM(Apr!I5+May!I5+Jun!J5) -> 511622.68 | J5: =SUM(Apr!J5, May!J5, Jun!K5) -> -20141.684 | K5: =IFERROR(J5/I5, "") -> -0.039368239
A6: CA: Clovis - Citi | B6: CA | C6: =SUM(Apr!C6, May!C6, Jun!C6) -> 200183.75 | D6: =SUM(Apr!D6,May!D6,Jun!D6) -> 205569.5 | E6: =C6/D6 -> 0.97380083 | F6: =SUM(Apr!F6, May!F6, Jun!G6) -> 198472 | G6: =IF(AND(ISNUMBER(C6),ISNUMBER(F6)), C6-F6, "") -> 1711.75 | H6: =IFERROR(G6/F6, "") -> 0.0086246423 | I6: =SUM(Apr!I6+May!I6+Jun!J6) -> 24475.361 | J6: =SUM(Apr!J6, May!J6, Jun!K6) -> 175708.39 | K6: =IFERROR(J6/I6, "") -> 7.1789907
A7: CA: Elk Grove MOB - Citi | B7: CA | C7: =SUM(Apr!C7, May!C7, Jun!C7) -> 317135.5 | D7: =SUM(Apr!D7,May!D7,Jun!D7) -> 326330.5 | E7: =C7/D7 -> 0.97182304 | F7: =SUM(Apr!F7, May!F7, Jun!G7) -> 323100 | G7: =IF(AND(ISNUMBER(C7),ISNUMBER(F7)), C7-F7, "") -> -5964.5 | H7: =IFERROR(G7/F7, "") -> -0.018460229 | I7: =SUM(Apr!I7+May!I7+Jun!J7) -> 341553.2 | J7: =SUM(Apr!J7, May!J7, Jun!K7) -> -24417.703 | K7: =IFERROR(J7/I7, "") -> -0.071490189
A8: CA: Elk Grove Promenade - Citi | B8: CA | C8: =SUM(Apr!C8, May!C8, Jun!C8) -> 167389.5 | D8: =SUM(Apr!D8,May!D8,Jun!D8) -> 172769 | E8: =C8/D8 -> 0.96886305 | F8: =SUM(Apr!F8, May!F8, Jun!G8) -> 171058.63 | G8: =IF(AND(ISNUMBER(C8),ISNUMBER(F8)), C8-F8, "") -> -3669.133 | H8: =IFERROR(G8/F8, "") -> -0.021449563 | I8: =SUM(Apr!I8+May!I8+Jun!J8) -> 179299.96 | J8: =SUM(Apr!J8, May!J8, Jun!K8) -> -11910.455 | K8: =IFERROR(J8/I8, "") -> -0.06642754
A9: CA: Fresno Sequioa - Citi | B9: CA | C9: =SUM(Apr!C9, May!C9, Jun!C9) -> 328179.5 | D9: =SUM(Apr!D9,May!D9,Jun!D9) -> 342057.35 | E9: =C9/D9 -> 0.95942829 | F9: =SUM(Apr!F9, May!F9, Jun!G9) -> 338739 | G9: =IF(AND(ISNUMBER(C9),ISNUMBER(F9)), C9-F9, "") -> -10559.5 | H9: =IFERROR(G9/F9, "") -> -0.031172968 | I9: =SUM(Apr!I9+May!I9+Jun!J9) -> 352815.81 | J9: =SUM(Apr!J9, May!J9, Jun!K9) -> -24636.309 | K9: =IFERROR(J9/I9, "") -> -0.069827679
A10: CA: Fresno MOB - Citi | B10: CA | C10: =SUM(Apr!C10, May!C10, Jun!C10) -> 115357.62 | D10: =SUM(Apr!D10,May!D10,Jun!D10) -> 138983.17 | E10: =C10/D10 -> 0.83001143 | F10: =SUM(Apr!F10, May!F10, Jun!G10) -> 138641 | G10: =IF(AND(ISNUMBER(C10),ISNUMBER(F10)), C10-F10, "") -> -23283.38 | H10: =IFERROR(G10/F10, "") -> -0.16794008 | I10: =SUM(Apr!I10+May!I10+Jun!J10) -> 124625.05 | J10: =SUM(Apr!J10, May!J10, Jun!K10) -> -9267.428 | K10: =IFERROR(J10/I10, "") -> -0.074362483
A11: CA: Modesto Bangs - Citi | B11: CA | C11: =SUM(Apr!C11, May!C11, Jun!C11) -> 84964 | D11: =SUM(Apr!D11,May!D11,Jun!D11) -> 98899.21 | E11: =C11/D11 -> 0.85909685 | F11: =SUM(Apr!F11, May!F11, Jun!G11) -> 98416 | G11: =IF(AND(ISNUMBER(C11),ISNUMBER(F11)), C11-F11, "") -> -13452 | H11: =IFERROR(G11/F11, "") -> -0.13668509 | I11: =SUM(Apr!I11+May!I11+Jun!J11) -> 8031.353 | J11: =SUM(Apr!J11, May!J11, Jun!K11) -> 76932.647 | K11: =IFERROR(J11/I11, "") -> 9.5790394
A12: CA: Napa Data Center - Citi | B12: CA | C12: =SUM(Apr!C12, May!C12, Jun!C12) -> 87169.25 | D12: =SUM(Apr!D12,May!D12,Jun!D12) -> 99083.82 | E12: =C12/D12 -> 0.87975262 | F12: =SUM(Apr!F12, May!F12, Jun!G12) -> 95251 | G12: =IF(AND(ISNUMBER(C12),ISNUMBER(F12)), C12-F12, "") -> -8081.75 | H12: =IFERROR(G12/F12, "") -> -0.084846878 | I12: =SUM(Apr!I12+May!I12+Jun!J12) -> 102181.4 | J12: =SUM(Apr!J12, May!J12, Jun!K12) -> -15012.146 | K12: =IFERROR(J12/I12, "") -> -0.14691663
A13: CA: Petaluma MOB - Citi | B13: CA | C13: =SUM(Apr!C13, May!C13, Jun!C13) -> 120989 | D13: =SUM(Apr!D13,May!D13,Jun!D13) -> 228836.27 | E13: =C13/D13 -> 0.52871426 | F13: =SUM(Apr!F13, May!F13, Jun!G13) -> 220211 | G13: =IF(AND(ISNUMBER(C13),ISNUMBER(F13)), C13-F13, "") -> -99222 | H13: =IFERROR(G13/F13, "") -> -0.45057695 | I13: =SUM(Apr!I13+May!I13+Jun!J13) -> 54738.526 | J13: =SUM(Apr!J13, May!J13, Jun!K13) -> 66250.474 | K13: =IFERROR(J13/I13, "") -> 1.210308
A14: CA: Pleasanton Tec Ctr - Citi | B14: CA | C14: =SUM(Apr!C14, May!C14, Jun!C14) -> 261266 | D14: =SUM(Apr!D14,May!D14,Jun!D14) -> 313016.72 | E14: =C14/D14 -> 0.83467107 | F14: =SUM(Apr!F14, May!F14, Jun!G14) -> 310021 | G14: =IF(AND(ISNUMBER(C14),ISNUMBER(F14)), C14-F14, "") -> -48755 | H14: =IFERROR(G14/F14, "") -> -0.15726354 | I14: =SUM(Apr!I14+May!I14+Jun!J14) -> 320861.63 | J14: =SUM(Apr!J14, May!J14, Jun!K14) -> -59595.628 | K14: =IFERROR(J14/I14, "") -> -0.18573623
A15: CA: Rancho Cordova - Citi | B15: CA | C15: =SUM(Apr!C15, May!C15, Jun!C15) -> 454900 | D15: =SUM(Apr!D15,May!D15,Jun!D15) -> 441553.17 | E15: =C15/D15 -> 1.030227 | F15: =SUM(Apr!F15, May!F15, Jun!G15) -> 438911 | G15: =IF(AND(ISNUMBER(C15),ISNUMBER(F15)), C15-F15, "") -> 15989 | H15: =IFERROR(G15/F15, "") -> 0.036428798 | I15: =SUM(Apr!I15+May!I15+Jun!J15) -> 477132.48 | J15: =SUM(Apr!J15, May!J15, Jun!K15) -> -22232.477 | K15: =IFERROR(J15/I15, "") -> -0.046596025
A16: CA: S Sacramento Wyndham - Citi | B16: CA | C16: =SUM(Apr!C16, May!C16, Jun!C16) -> 251515.5 | D16: =SUM(Apr!D16,May!D16,Jun!D16) -> 282469.56 | E16: =C16/D16 -> 0.8904163 | F16: =SUM(Apr!F16, May!F16, Jun!G16) -> 277578 | G16: =IF(AND(ISNUMBER(C16),ISNUMBER(F16)), C16-F16, "") -> -26062.5 | H16: =IFERROR(G16/F16, "") -> -0.093892528 | I16: =SUM(Apr!I16+May!I16+Jun!J16) -> 275316.63 | J16: =SUM(Apr!J16, May!J16, Jun!K16) -> -23801.134 | K16: =IFERROR(J16/I16, "") -> -0.08645004
... A22: CA: Manteca - KP Manteca Hospital | B22: CA | C22: =SUM(Apr!C22, May!C22, Jun!C22) -> 175043.63 | D22: =SUM(Apr!D22,May!D22,Jun!D22) -> 232162 | E22: =C22/D22 -> 0.75397192 | F22: =SUM(Apr!F22, May!F22, Jun!G22) -> 218718.91 | G22: =IF(AND(ISNUMBER(C22),ISNUMBER(F22)), C22-F22, "") -> -43675.285 | H22: =IFERROR(G22/F22, "") -> -0.19968682 | I22: =SUM(Apr!I22+May!I22+Jun!J22) -> 178276.85 | J22: =SUM(Apr!J22, May!J22, Jun!K22) -> -3233.223 | K22: =IFERROR(J22/I22, "") -> -0.018135966
A23: Sacramento - KP South Sacramento HSP | B23: CA | C23: =SUM(Apr!C23, May!C23, Jun!C23) -> 672177.15 | D23: =SUM(Apr!D23,May!D23,Jun!D23) -> 0 | E23: 0 | F23: =SUM(Apr!F23, May!F23, Jun!G23) -> 405860 | G23: =IF(AND(ISNUMBER(C23),ISNUMBER(F23)), C23-F23, "") -> 266317.15 | H23: =IFERROR(G23/F23, "") -> 0.65617984 | I23: =SUM(Apr!I23+May!I23+Jun!J23) -> 731642 | J23: =SUM(Apr!J23, May!J23, Jun!K23) -> -59464.85 | K23: =IFERROR(J23/I23, "") -> -0.081275884

Sheet 3rd Qtr
A1: {=portfolio} -> CITI | D1: PPA Modeled Output | E1: Production VS Acual | F1: 3rd Quarter Actual v. Expected | I1: 3rd Quarter Actual v. Forecasted
A2: Total | C2: =SUM(C4:C100) -> 0 | D2: =SUM(D3:D22) -> 0 | E2: =C2/D2 -> #DIV/0! | F2: =SUM(D4:D100) -> 0 | G2: =C2-F2 -> 0 | H2: =IFERROR(G2/F2, 0) -> 0 | I2: =SUM(G4:G100) -> 0 | J2: =C2-I2 -> 0 | K2: =IFERROR(J2/I2, 0) -> 0
A3: Site | B3: State | C3: Actual | F3: Expected | G3: Delta | H3: % | I3: Forecasted | J3: Delta | K3: %
A4: {=Sites[Site]} -> CA: Antioch Deer Valley - Citi | B4: {=Sites[State]} -> CA | C4: =SUM(Jul!C4, Aug!C4, Sep!C4) -> 0 | D4: =SUM(Jul!D4,Aug!D4,Sep!D4) -> 0 | E4: =C4/D4 -> #DIV/0! | F4: =SUM(Jul!F4, Aug!F4, Sep!G4) -> 0 | G4: =IF(AND(ISNUMBER(C4),ISNUMBER(F4)), C4-F4, "") -> 0 | H4: =IFERROR(G4/F4, "") | I4: =SUM(Jul!I4, Aug!K4, Sep!L4) -> 0 | J4: =SUM(Jul!J4, Aug!J4, Sep!K4) -> 0 | K4: =IFERROR(J4/I4, "")
A5: CA: Antioch MC CUP - Citi | B5: CA | C5: =SUM(Jul!C5, Aug!C5, Sep!C5) -> 0 | E5: =C5/D5 -> #DIV/0! | F5: =SUM(Jul!F5, Aug!F5, Sep!G5) -> 0 | G5: =IF(AND(ISNUMBER(C5),ISNUMBER(F5)), C5-F5, "") -> 0 | H5: =IFERROR(G5/F5, "") | I5: =SUM(Jul!I5, Aug!K5, Sep!L5) -> 0 | J5: =SUM(Jul!J5, Aug!J5, Sep!K5) -> 0 | K5: =IFERROR(J5/I5, "")
A6: CA: Clovis - Citi | B6: CA | C6: =SUM(Jul!C6, Aug!C6, Sep!C6) -> 0 | D6: =SUM(Jul!D6,Aug!D6,Sep!D6) -> 0 | E6: =C6/D6 -> #DIV/0! | F6: =SUM(Jul!F6, Aug!F6, Sep!G6) -> 0 | G6: =IF(AND(ISNUMBER(C6),ISNUMBER(F6)), C6-F6, "") -> 0 | H6: =IFERROR(G6/F6, "") | I6: =SUM(Jul!I6, Aug!K6, Sep!L6) -> 0 | J6: =SUM(Jul!J6, Aug!J6, Sep!K6) -> 0 | K6: =IFERROR(J6/I6, "")
A7: CA: Elk Grove MOB - Citi | B7: CA | C7: =SUM(Jul!C7, Aug!C7, Sep!C7) -> 0 | E7: =C7/D7 -> #DIV/0! | F7: =SUM(Jul!F7, Aug!F7, Sep!G7) -> 0 | G7: =IF(AND(ISNUMBER(C7),ISNUMBER(F7)), C7-F7, "") -> 0 | H7: =IFERROR(G7/F7, "") | I7: =SUM(Jul!I7, Aug!K7, Sep!L7) -> 0 | J7: =SUM(Jul!J7, Aug!J7, Sep!K7) -> 0 | K7: =IFERROR(J7/I7, "")
A8: CA: Elk Grove Promenade - Citi | B8: CA | C8: =SUM(Jul!C8, Aug!C8, Sep!C8) -> 0 | D8: =SUM(Jul!D8,Aug!D8,Sep!D8) -> 0 | E8: =C8/D8 -> #DIV/0! | F8: =SUM(Jul!F8, Aug!F8, Sep!G8) -> 0 | G8: =IF(AND(ISNUMBER(C8),ISNUMBER(F8)), C8-F8, "") -> 0 | H8: =IFERROR(G8/F8, "") | I8: =SUM(Jul!I8, Aug!K8, Sep!L8) -> 0 | J8: =SUM(Jul!J8, Aug!J8, Sep!K8) -> 0 | K8: =IFERROR(J8/I8, "")
A9: CA: Fresno Sequioa - Citi | B9: CA | C9: =SUM(Jul!C9, Aug!C9, Sep!C9) -> 0 | E9: =C9/D9 -> #DIV/0! | F9: =SUM(Jul!F9, Aug!F9, Sep!G9) -> 0 | G9: =IF(AND(ISNUMBER(C9),ISNUMBER(F9)), C9-F9, "") -> 0 | H9: =IFERROR(G9/F9, "") | I9: =SUM(Jul!I9, Aug!K9, Sep!L9) -> 0 | J9: =SUM(Jul!J9, Aug!J9, Sep!K9) -> 0 | K9: =IFERROR(J9/I9, "")
A10: CA: Fresno MOB - Citi | B10: CA | C10: =SUM(Jul!C10, Aug!C10, Sep!C10) -> 0 | D10: =SUM(Jul!D10,Aug!D10,Sep!D10) -> 0 | E10: =C10/D10 -> #DIV/0! | F10: =SUM(Jul!F10, Aug!F10, Sep!G10) -> 0 | G10: =IF(AND(ISNUMBER(C10),ISNUMBER(F10)), C10-F10, "") -> 0 | H10: =IFERROR(G10/F10, "") | I10: =SUM(Jul!I10, Aug!K10, Sep!L10) -> 0 | J10: =SUM(Jul!J10, Aug!J10, Sep!K10) -> 0 | K10: =IFERROR(J10/I10, "")
A11: CA: Modesto Bangs - Citi | B11: CA | C11: =SUM(Jul!C11, Aug!C11, Sep!C11) -> 0 | E11: =C11/D11 -> #DIV/0! | F11: =SUM(Jul!F11, Aug!F11, Sep!G11) -> 0 | G11: =IF(AND(ISNUMBER(C11),ISNUMBER(F11)), C11-F11, "") -> 0 | H11: =IFERROR(G11/F11, "") | I11: =SUM(Jul!I11, Aug!K11, Sep!L11) -> 0 | J11: =SUM(Jul!J11, Aug!J11, Sep!K11) -> 0 | K11: =IFERROR(J11/I11, "")
A12: CA: Napa Data Center - Citi | B12: CA | C12: =SUM(Jul!C12, Aug!C12, Sep!C12) -> 0 | D12: =SUM(Jul!D12,Aug!D12,Sep!D12) -> 0 | E12: =C12/D12 -> #DIV/0! | F12: =SUM(Jul!F12, Aug!F12, Sep!G12) -> 0 | G12: =IF(AND(ISNUMBER(C12),ISNUMBER(F12)), C12-F12, "") -> 0 | H12: =IFERROR(G12/F12, "") | I12: =SUM(Jul!I12, Aug!K12, Sep!L12) -> 0 | J12: =SUM(Jul!J12, Aug!J12, Sep!K12) -> 0 | K12: =IFERROR(J12/I12, "")
A13: CA: Petaluma MOB - Citi | B13: CA | C13: =SUM(Jul!C13, Aug!C13, Sep!C13) -> 0 | E13: =C13/D13 -> #DIV/0! | F13: =SUM(Jul!F13, Aug!F13, Sep!G13) -> 0 | G13: =IF(AND(ISNUMBER(C13),ISNUMBER(F13)), C13-F13, "") -> 0 | H13: =IFERROR(G13/F13, "") | I13: =SUM(Jul!I13, Aug!K13, Sep!L13) -> 0 | J13: =SUM(Jul!J13, Aug!J13, Sep!K13) -> 0 | K13: =IFERROR(J13/I13, "")
A14: CA: Pleasanton Tec Ctr - Citi | B14: CA | C14: =SUM(Jul!C14, Aug!C14, Sep!C14) -> 0 | D14: =SUM(Jul!D14,Aug!D14,Sep!D14) -> 0 | E14: =C14/D14 -> #DIV/0! | F14: =SUM(Jul!F14, Aug!F14, Sep!G14) -> 0 | G14: =IF(AND(ISNUMBER(C14),ISNUMBER(F14)), C14-F14, "") -> 0 | H14: =IFERROR(G14/F14, "") | I14: =SUM(Jul!I14, Aug!K14, Sep!L14) -> 0 | J14: =SUM(Jul!J14, Aug!J14, Sep!K14) -> 0 | K14: =IFERROR(J14/I14, "")
A15: CA: Rancho Cordova - Citi | B15: CA | C15: =SUM(Jul!C15, Aug!C15, Sep!C15) -> 0 | E15: =C15/D15 -> #DIV/0! | F15: =SUM(Jul!F15, Aug!F15, Sep!G15) -> 0 | G15: =IF(AND(ISNUMBER(C15),ISNUMBER(F15)), C15-F15, "") -> 0 | H15: =IFERROR(G15/F15, "") | I15: =SUM(Jul!I15, Aug!K15, Sep!L15) -> 0 | J15: =SUM(Jul!J15, Aug!J15, Sep!K15) -> 0 | K15: =IFERROR(J15/I15, "")
A16: CA: S Sacramento Wyndham - Citi | B16: CA | C16: =SUM(Jul!C16, Aug!C16, Sep!C16) -> 0 | D16: =SUM(Jul!D16,Aug!D16,Sep!D16) -> 0 | E16: =C16/D16 -> #DIV/0! | F16: =SUM(Jul!F16, Aug!F16, Sep!G16) -> 0 | G16: =IF(AND(ISNUMBER(C16),ISNUMBER(F16)), C16-F16, "") -> 0 | H16: =IFERROR(G16/F16, "") | I16: =SUM(Jul!I16, Aug!K16, Sep!L16) -> 0 | J16: =SUM(Jul!J16, Aug!J16, Sep!K16) -> 0 | K16: =IFERROR(J16/I16, "")
A17: CA: Sacramento Point West - Citi | B17: CA | C17: =SUM(Jul!C17, Aug!C17, Sep!C17) -> 0 | E17: =C17/D17 -> #DIV/0! | F17: =SUM(Jul!F17, Aug!F17, Sep!G17) -> 0 | G17: =IF(AND(ISNUMBER(C17),ISNUMBER(F17)), C17-F17, "") -> 0 | H17: =IFERROR(G17/F17, "") | I17: =SUM(Jul!I17, Aug!K17, Sep!L17) -> 0 | J17: =SUM(Jul!J17, Aug!J17, Sep!K17) -> 0 | K17: =IFERROR(J17/I17, "")
A18: CA: San Jose FHC - Citi | B18: CA | C18: =SUM(Jul!C18, Aug!C18, Sep!C18) -> 0 | D18: =SUM(Jul!D18,Aug!D18,Sep!D18) -> 0 | E18: =C18/D18 -> #DIV/0! | F18: =SUM(Jul!F18, Aug!F18, Sep!G18) -> 0 | G18: =IF(AND(ISNUMBER(C18),ISNUMBER(F18)), C18-F18, "") -> 0 | H18: =IFERROR(G18/F18, "") | I18: =SUM(Jul!I18, Aug!K18, Sep!L18) -> 0 | J18: =SUM(Jul!J18, Aug!J18, Sep!K18) -> 0 | K18: =IFERROR(J18/I18, "")
A19: CA: San Jose MOB - Citi | B19: CA | C19: =SUM(Jul!C19, Aug!C19, Sep!C19) -> 0 | E19: =C19/D19 -> #DIV/0! | F19: =SUM(Jul!F19, Aug!F19, Sep!G19) -> 0 | G19: =IF(AND(ISNUMBER(C19),ISNUMBER(F19)), C19-F19, "") -> 0 | H19: =IFERROR(G19/F19, "") | I19: =SUM(Jul!I19, Aug!K19, Sep!L19) -> 0 | J19: =SUM(Jul!J19, Aug!J19, Sep!K19) -> 0 | K19: =IFERROR(J19/I19, "")
A20: CA: Selma - Citi | B20: CA | C20: =SUM(Jul!C20, Aug!C20, Sep!C20) -> 0 | D20: =SUM(Jul!D20,Aug!D20,Sep!D20) -> 0 | E20: =C20/D20 -> #DIV/0! | F20: =SUM(Jul!F20, Aug!F20, Sep!G20) -> 0 | G20: =IF(AND(ISNUMBER(C20),ISNUMBER(F20)), C20-F20, "") -> 0 | H20: =IFERROR(G20/F20, "") | I20: =SUM(Jul!I20, Aug!K20, Sep!L20) -> 0 | J20: =SUM(Jul!J20, Aug!J20, Sep!K20) -> 0 | K20: =IFERROR(J20/I20, "")
A21: CA: Vacaville Hospital | B21: CA | C21: =SUM(Jul!C21, Aug!C21, Sep!C21) -> 0 | E21: =C21/D21 -> #DIV/0! | F21: =SUM(Jul!F21, Aug!F21, Sep!G21) -> 0 | G21: =SUM(Jul!G21, Aug!G21, Sep!H21) -> 0 | H21: =IFERROR(G21/F21, "") | I21: =SUM(Jul!I21, Aug!K21, Sep!L21) -> 0 | J21: =SUM(Jul!J21, Aug!J21, Sep!K21) -> 0 | K21: =IFERROR(J21/I21, "")
A22: CA: Manteca - KP Manteca Hospital | B22: CA | C22: =SUM(Jul!C22, Aug!C22, Sep!C22) -> 0 | D22: =SUM(Jul!D22,Aug!D22,Sep!D22) -> 0 | E22: =C22/D22 -> #DIV/0! | F22: =SUM(Jul!F22, Aug!F22, Sep!G22) -> 0 | G22: =SUM(Jul!G22, Aug!G22, Sep!H22) -> 0 | H22: =IFERROR(G22/F22, "") | I22: =SUM(Jul!I22, Aug!K22, Sep!L22) -> 0 | J22: =SUM(Jul!J22, Aug!J22, Sep!K22) -> 0 | K22: =IFERROR(J22/I22, "")
A23: Sacramento - KP South Sacramento HSP | B23: CA

Sheet 4th Qtr
A1: {=portfolio} -> CITI | D1: PPA Modeled Output | E1: Production VS Acual | F1: 4th Quarter Actual v. Expected | I1: 4th Quarter Actual v. Forecasted
A2: Total | C2: =SUM(C4:C100) -> 0 | D2: =SUM(D3:D22) -> 0 | E2: =C2/D2 -> #DIV/0! | F2: =SUM(D4:D100) -> 0 | G2: =C2-F2 -> 0 | H2: =IFERROR(G2/F2, 0) -> 0 | I2: =SUM(G4:G100) -> 0 | J2: =C2-I2 -> 0 | K2: =IFERROR(J2/I2, 0) -> 0
A3: Site | B3: State | C3: Actual | F3: Expected | G3: Delta | H3: % | I3: Forecasted | J3: Delta | K3: %
A4: {=Sites[Site]} -> CA: Antioch Deer Valley - Citi | B4: {=Sites[State]} -> CA | C4: =SUM(Oct!C4, Nov!C4, Dec!C4) -> 0 | D4: =SUM(Oct!D4,Nov!D4,Dec!D4) -> 0 | E4: =C4/D4 -> #DIV/0! | F4: =SUM(Oct!F4, Nov!F4, Dec!F4) -> 0 | G4: =IF(AND(ISNUMBER(C4),ISNUMBER(F4)), C4-F4, "") -> 0 | H4: =IFERROR(G4/F4, "") | I4: =SUM(Oct!I4,Nov!I4,Dec!J4) -> 0 | J4: =SUM(Oct!J4, Nov!J4, Dec!J4) -> 0 | K4: =IFERROR(J4/I4, "")
A5: CA: Antioch MC CUP - Citi | B5: CA | C5: =SUM(Oct!C5, Nov!C5, Dec!C5) -> 0 | E5: =C5/D5 -> #DIV/0! | F5: =SUM(Oct!F5, Nov!F5, Dec!F5) -> 0 | G5: =IF(AND(ISNUMBER(C5),ISNUMBER(F5)), C5-F5, "") -> 0 | H5: =IFERROR(G5/F5, "") | I5: =SUM(Oct!I5,Nov!I5,Dec!J5) -> 0 | J5: =SUM(Oct!J5, Nov!J5, Dec!J5) -> 0 | K5: =IFERROR(J5/I5, "")
A6: CA: Clovis - Citi | B6: CA | C6: =SUM(Oct!C6, Nov!C6, Dec!C6) -> 0 | D6: =SUM(Oct!D6,Nov!D6,Dec!D6) -> 0 | E6: =C6/D6 -> #DIV/0! | F6: =SUM(Oct!F6, Nov!F6, Dec!F6) -> 0 | G6: =IF(AND(ISNUMBER(C6),ISNUMBER(F6)), C6-F6, "") -> 0 | H6: =IFERROR(G6/F6, "") | I6: =SUM(Oct!I6,Nov!I6,Dec!J6) -> 0 | J6: =SUM(Oct!J6, Nov!J6, Dec!J6) -> 0 | K6: =IFERROR(J6/I6, "")
A7: CA: Elk Grove MOB - Citi | B7: CA | C7: =SUM(Oct!C7, Nov!C7, Dec!C7) -> 0 | E7: =C7/D7 -> #DIV/0! | F7: =SUM(Oct!F7, Nov!F7, Dec!F7) -> 0 | G7: =IF(AND(ISNUMBER(C7),ISNUMBER(F7)), C7-F7, "") -> 0 | H7: =IFERROR(G7/F7, "") | I7: =SUM(Oct!I7,Nov!I7,Dec!J7) -> 0 | J7: =SUM(Oct!J7, Nov!J7, Dec!J7) -> 0 | K7: =IFERROR(J7/I7, "")
A8: CA: Elk Grove Promenade - Citi | B8: CA | C8: =SUM(Oct!C8, Nov!C8, Dec!C8) -> 0 | D8: =SUM(Oct!D8,Nov!D8,Dec!D8) -> 0 | E8: =C8/D8 -> #DIV/0! | F8: =SUM(Oct!F8, Nov!F8, Dec!F8) -> 0 | G8: =IF(AND(ISNUMBER(C8),ISNUMBER(F8)), C8-F8, "") -> 0 | H8: =IFERROR(G8/F8, "") | I8: =SUM(Oct!I8,Nov!I8,Dec!J8) -> 0 | J8: =SUM(Oct!J8, Nov!J8, Dec!J8) -> 0 | K8: =IFERROR(J8/I8, "")
A9: CA: Fresno Sequioa - Citi | B9: CA | C9: =SUM(Oct!C9, Nov!C9, Dec!C9) -> 0 | E9: =C9/D9 -> #DIV/0! | F9: =SUM(Oct!F9, Nov!F9, Dec!F9) -> 0 | G9: =IF(AND(ISNUMBER(C9),ISNUMBER(F9)), C9-F9, "") -> 0 | H9: =IFERROR(G9/F9, "") | I9: =SUM(Oct!I9,Nov!I9,Dec!J9) -> 0 | J9: =SUM(Oct!J9, Nov!J9, Dec!J9) -> 0 | K9: =IFERROR(J9/I9, "")
A10: CA: Fresno MOB - Citi | B10: CA | C10: =SUM(Oct!C10, Nov!C10, Dec!C10) -> 0 | D10: =SUM(Oct!D10,Nov!D10,Dec!D10) -> 0 | E10: =C10/D10 -> #DIV/0! | F10: =SUM(Oct!F10, Nov!F10, Dec!F10) -> 0 | G10: =IF(AND(ISNUMBER(C10),ISNUMBER(F10)), C10-F10, "") -> 0 | H10: =IFERROR(G10/F10, "") | I10: =SUM(Oct!I10,Nov!I10,Dec!J10) -> 0 | J10: =SUM(Oct!J10, Nov!J10, Dec!J10) -> 0 | K10: =IFERROR(J10/I10, "")
A11: CA: Modesto Bangs - Citi | B11: CA | C11: =SUM(Oct!C11, Nov!C11, Dec!C11) -> 0 | E11: =C11/D11 -> #DIV/0! | F11: =SUM(Oct!F11, Nov!F11, Dec!F11) -> 0 | G11: =IF(AND(ISNUMBER(C11),ISNUMBER(F11)), C11-F11, "") -> 0 | H11: =IFERROR(G11/F11, "") | I11: =SUM(Oct!I11,Nov!I11,Dec!J11) -> 0 | J11: =SUM(Oct!J11, Nov!J11, Dec!J11) -> 0 | K11: =IFERROR(J11/I11, "")
A12: CA: Napa Data Center - Citi | B12: CA | C12: =SUM(Oct!C12, Nov!C12, Dec!C12) -> 0 | D12: =SUM(Oct!D12,Nov!D12,Dec!D12) -> 0 | E12: =C12/D12 -> #DIV/0! | F12: =SUM(Oct!F12, Nov!F12, Dec!F12) -> 0 | G12: =IF(AND(ISNUMBER(C12),ISNUMBER(F12)), C12-F12, "") -> 0 | H12: =IFERROR(G12/F12, "") | I12: =SUM(Oct!I12,Nov!I12,Dec!J12) -> 0 | J12: =SUM(Oct!J12, Nov!J12, Dec!J12) -> 0 | K12: =IFERROR(J12/I12, "")
A13: CA: Petaluma MOB - Citi | B13: CA | C13: =SUM(Oct!C13, Nov!C13, Dec!C13) -> 0 | E13: =C13/D13 -> #DIV/0! | F13: =SUM(Oct!F13, Nov!F13, Dec!F13) -> 0 | G13: =IF(AND(ISNUMBER(C13),ISNUMBER(F13)), C13-F13, "") -> 0 | H13: =IFERROR(G13/F13, "") | I13: =SUM(Oct!I13,Nov!I13,Dec!J13) -> 0 | J13: =SUM(Oct!J13, Nov!J13, Dec!J13) -> 0 | K13: =IFERROR(J13/I13, "")
A14: CA: Pleasanton Tec Ctr - Citi | B14: CA | C14: =SUM(Oct!C14, Nov!C14, Dec!C14) -> 0 | D14: =SUM(Oct!D14,Nov!D14,Dec!D14) -> 0 | E14: =C14/D14 -> #DIV/0! | F14: =SUM(Oct!F14, Nov!F14, Dec!F14) -> 0 | G14: =IF(AND(ISNUMBER(C14),ISNUMBER(F14)), C14-F14, "") -> 0 | H14: =IFERROR(G14/F14, "") | I14: =SUM(Oct!I14,Nov!I14,Dec!J14) -> 0 | J14: =SUM(Oct!J14, Nov!J14, Dec!J14) -> 0 | K14: =IFERROR(J14/I14, "")
A15: CA: Rancho Cordova - Citi | B15: CA | C15: =SUM(Oct!C15, Nov!C15, Dec!C15) -> 0 | E15: =C15/D15 -> #DIV/0! | F15: =SUM(Oct!F15, Nov!F15, Dec!F15) -> 0 | G15: =IF(AND(ISNUMBER(C15),ISNUMBER(F15)), C15-F15, "") -> 0 | H15: =IFERROR(G15/F15, "") | I15: =SUM(Oct!I15,Nov!I15,Dec!J15) -> 0 | J15: =SUM(Oct!J15, Nov!J15, Dec!J15) -> 0 | K15: =IFERROR(J15/I15, "")
A16: CA: S Sacramento Wyndham - Citi | B16: CA | C16: =SUM(Oct!C16, Nov!C16, Dec!C16) -> 0 | D16: =SUM(Oct!D16,Nov!D16,Dec!D16) -> 0 | E16: =C16/D16 -> #DIV/0! | F16: =SUM(Oct!F16, Nov!F16, Dec!F16) -> 0 | G16: =IF(AND(ISNUMBER(C16),ISNUMBER(F16)), C16-F16, "") -> 0 | H16: =IFERROR(G16/F16, "") | I16: =SUM(Oct!I16,Nov!I16,Dec!J16) -> 0 | J16: =SUM(Oct!J16, Nov!J16, Dec!J16) -> 0 | K16: =IFERROR(J16/I16, "")
A17: CA: Sacramento Point West - Citi | B17: CA | C17: =SUM(Oct!C17, Nov!C17, Dec!C17) -> 0 | E17: =C17/D17 -> #DIV/0! | F17: =SUM(Oct!F17, Nov!F17, Dec!F17) -> 0 | G17: =IF(AND(ISNUMBER(C17),ISNUMBER(F17)), C17-F17, "") -> 0 | H17: =IFERROR(G17/F17, "") | I17: =SUM(Oct!I17,Nov!I17,Dec!J17) -> 0 | J17: =SUM(Oct!J17, Nov!J17, Dec!J17) -> 0 | K17: =IFERROR(J17/I17, "")
A18: CA: San Jose FHC - Citi | B18: CA | C18: =SUM(Oct!C18, Nov!C18, Dec!C18) -> 0 | D18: =SUM(Oct!D18,Nov!D18,Dec!D18) -> 0 | E18: =C18/D18 -> #DIV/0! | F18: =SUM(Oct!F18, Nov!F18, Dec!F18) -> 0 | G18: =IF(AND(ISNUMBER(C18),ISNUMBER(F18)), C18-F18, "") -> 0 | H18: =IFERROR(G18/F18, "") | I18: =SUM(Oct!I18,Nov!I18,Dec!J18) -> 0 | J18: =SUM(Oct!J18, Nov!J18, Dec!J18) -> 0 | K18: =IFERROR(J18/I18, "")
A19: CA: San Jose MOB - Citi | B19: CA | C19: =SUM(Oct!C19, Nov!C19, Dec!C19) -> 0 | E19: =C19/D19 -> #DIV/0! | F19: =SUM(Oct!F19, Nov!F19, Dec!F19) -> 0 | G19: =IF(AND(ISNUMBER(C19),ISNUMBER(F19)), C19-F19, "") -> 0 | H19: =IFERROR(G19/F19, "") | I19: =SUM(Oct!I19,Nov!I19,Dec!J19) -> 0 | J19: =SUM(Oct!J19, Nov!J19, Dec!J19) -> 0 | K19: =IFERROR(J19/I19, "")
A20: CA: Selma - Citi | B20: CA | C20: =SUM(Oct!C20, Nov!C20, Dec!C20) -> 0 | D20: =SUM(Oct!D20,Nov!D20,Dec!D20) -> 0 | E20: =C20/D20 -> #DIV/0! | F20: =SUM(Oct!F20, Nov!F20, Dec!F20) -> 0 | G20: =SUM(Oct!G20, Nov!G20, Dec!G20) -> 0 | H20: =IFERROR(G20/F20, "") | I20: =SUM(Oct!I20,Nov!I20,Dec!J20) -> 0 | J20: =SUM(Oct!J20, Nov!J20, Dec!J20) -> 0 | K20: =IFERROR(J20/I20, "")
A21: CA: Vacaville Hospital | B21: CA | C21: =SUM(Oct!C21, Nov!C21, Dec!C21) -> 0 | E21: =C21/D21 -> #DIV/0! | F21: =SUM(Oct!F21, Nov!F21, Dec!F21) -> 0 | G21: =SUM(Oct!G21, Nov!G21, Dec!G21) -> 0 | H21: =IFERROR(G21/F21, "") | I21: =SUM(Oct!I21,Nov!I21,Dec!J21) -> 0 | J21: =SUM(Oct!J21, Nov!J21, Dec!J21) -> 0 | K21: =IFERROR(J21/I21, "")
A22: CA: Manteca - KP Manteca Hospital | B22: CA | C22: =SUM(Oct!C22, Nov!C22, Dec!C22) -> 0 | D22: =SUM(Oct!D22,Nov!D22,Dec!D22) -> 0 | E22: =C22/D22 -> #DIV/0! | F22: =SUM(Oct!F22, Nov!F22, Dec!F22) -> 0 | G22: =SUM(Oct!G22, Nov!G22, Dec!G22) -> 0 | H22: =IFERROR(G22/F22, "") | I22: =SUM(Oct!I22,Nov!I22,Dec!J22) -> 0 | J22: =SUM(Oct!J22, Nov!J22, Dec!J22) -> 0 | K22: =IFERROR(J22/I22, "")
A23: Sacramento - KP South Sacramento HSP | B23: CA

Sheet Jan
A1: {=portfolio} -> CITI | D1: PPA Modeled Output | E1: Production VS Acual | F1: January Actual v. Expected | I1: January Actual v. Forecasted
A2: Total | C2: =SUM(C4:C99) -> 1141760.9 | D2: =SUM(D4:D22) -> 909254.01 | E2: =C2/D2 -> 1.2557117 | F2: =SUM(F4:F99) -> 911851.35 | G2: =C2-F2 -> 229909.53 | H2: =IFERROR(G2/F2, 0) -> 0.25213488 | I2: =SUM(I4:I99) -> 1228093.9 | J2: =C2-I2 -> -86333.056 | K2: =IFERROR(J2/I2, 0) -> -0.070298414 | L2: =IF(AND(TODAY()>DATE(2024, 1, 1), COUNTA(Sites[Site])<>(COUNT(C:C)-1)), "Some sites are missing actual data; if new sites were added, make sure they are aligned correctly (including prior months!)", "") -> Some sites are missing actual data; if new sites were added, make sure they are aligned correctly (including prior months!)
A3: Site | B3: State | C3: Actual | F3: Expected | G3: Delta | H3: % | I3: Forecasted | J3: Delta | K3: % | L3: Notes | M3: Service Requests
A4: {=Sites[Site]} -> CA: Antioch Deer Valley - Citi | B4: {=Sites[State]} -> CA | C4: 35199.75 | D4: 26934.83 | E4: =C4/D4 -> 1.3068488 | F4: 26668 | G4: =IF(AND(ISNUMBER(C4),ISNUMBER(F4)), C4-F4, "") -> 8531.75 | H4: =IFERROR(G4/F4, "") -> 0.31992463 | I4: 36723.827 | J4: =IF(AND(ISNUMBER(C4),ISNUMBER(I4)), C4-I4, "") -> -1524.077 | K4: =IFERROR(J4/I4, "") -> -0.04150104
A5: CA: Antioch MC CUP - Citi | B5: CA | C5: 107451 | D5: 88103.5 | E5: =C5/D5 -> 1.2195997 | F5: 87223 | G5: =IF(AND(ISNUMBER(C5),ISNUMBER(F5)), C5-F5, "") -> 20228 | H5: =IFERROR(G5/F5, "") -> 0.23191131 | I5: 116935 | J5: =IF(AND(ISNUMBER(C5),ISNUMBER(I5)), C5-I5, "") -> -9483.996 | K5: =IFERROR(J5/I5, "") -> -0.081104856
A6: CA: Clovis - Citi | B6: CA | C6: 47404.25 | D6: 30338 | E6: =C6/D6 -> 1.5625371 | F6: 29290 | G6: =IF(AND(ISNUMBER(C6),ISNUMBER(F6)), C6-F6, "") -> 18114.25 | H6: =IFERROR(G6/F6, "") -> 0.61844486 | I6: 48625.771 | J6: =IF(AND(ISNUMBER(C6),ISNUMBER(I6)), C6-I6, "") -> -1221.521 | K6: =IFERROR(J6/I6, "") -> -0.025120856 | L6: 1.Inverter 1 tripped offline at 19:45 on 01/27 due to an arc protection fault and remained offline for through out the month. | M6: 1.SR096073
A7: CA: Elk Grove MOB - Citi | B7: CA | C7: 70088 | D7: 55258.5 | E7: =C7/D7 -> 1.268366 | F7: 54711 | G7: =IF(AND(ISNUMBER(C7),ISNUMBER(F7)), C7-F7, "") -> 15377 | H7: =IFERROR(G7/F7, "") -> 0.28105865 | I7: 76608 | J7: =IF(AND(ISNUMBER(C7),ISNUMBER(I7)), C7-I7, "") -> -6520 | K7: =IFERROR(J7/I7, "") -> -0.085108605
A8: CA: Elk Grove Promenade - Citi | B8: CA | C8: 39878 | D8: 30505 | E8: =C8/D8 -> 1.3072611 | F8: 30232.711 | G8: =IF(AND(ISNUMBER(C8),ISNUMBER(F8)), C8-F8, "") -> 9645.289 | H8: =IFERROR(G8/F8, "") -> 0.31903487 | I8: 44081.56 | J8: =IF(AND(ISNUMBER(C8),ISNUMBER(I8)), C8-I8, "") -> -4203.56 | K8: =IFERROR(J8/I8, "") -> -0.095358694
A9: CA: Fresno Sequioa - Citi | B9: CA | C9: 72064.5 | D9: 54436.21 | E9: =C9/D9 -> 1.3238339 | F9: 53908 | G9: =IF(AND(ISNUMBER(C9),ISNUMBER(F9)), C9-F9, "") -> 18156.5 | H9: =IFERROR(G9/F9, "") -> 0.3368053 | I9: 83519.138 | J9: =IF(AND(ISNUMBER(C9),ISNUMBER(I9)), C9-I9, "") -> -11454.638 | K9: =IFERROR(J9/I9, "") -> -0.13714986 | L9: 1.Inverter 2 tripped offline at 18:35 on 12/31/24 due to an arc protection fault. The technician cleared the fault and re-energized the inverter, bringing it back online at 12:10 on 01/03/25. Inverter 2 again tripped offline at 18:45 on 01/07/25 and was being RMA'D. | M9: 1.SR095212,SR095408 | N9: SR095408
A10: CA: Fresno MOB - Citi | B10: CA | C10: 30119.5 | D10: 21917.91 | E10: =C10/D10 -> 1.3741958 | F10: 21759 | G10: =IF(AND(ISNUMBER(C10),ISNUMBER(F10)), C10-F10, "") -> 8360.5 | H10: =IFERROR(G10/F10, "") -> 0.38423181 | I10: 33751.72 | J10: =IF(AND(ISNUMBER(C10),ISNUMBER(I10)), C10-I10, "") -> -3632.22 | K10: =IFERROR(J10/I10, "") -> -0.10761585 | L10: 1.Inverter 5's arc board is being RMA'd to prevent recurring trips. On 01/22, the technician installed the arc board, and then Inverter 5 is producing usually. | M10: 1.SR095363
A11: CA: Modesto Bangs - Citi | B11: CA | C11: 18323.25 | D11: 12108.41 | E11: =C11/D11 -> 1.5132664 | F11: 12105 | G11: =IF(AND(ISNUMBER(C11),ISNUMBER(F11)), C11-F11, "") -> 6218.25 | H11: =IFERROR(G11/F11, "") -> 0.51369269 | I11: 18407 | J11: =IF(AND(ISNUMBER(C11),ISNUMBER(I11)), C11-I11, "") -> -83.75 | K11: =IFERROR(J11/I11, "") -> -0.0045498995
A12: CA: Napa Data Center - Citi | B12: CA | C12: 18167.75 | D12: 18607.37 | E12: =C12/D12 -> 0.97637388 | F12: 18005 | G12: =IF(AND(ISNUMBER(C12),ISNUMBER(F12)), C12-F12, "") -> 162.75 | H12: =IFERROR(G12/F12, "") -> 0.0090391558 | I12: 22393.513 | J12: =IF(AND(ISNUMBER(C12),ISNUMBER(I12)), C12-I12, "") -> -4225.763 | K12: =IFERROR(J12/I12, "") -> -0.18870478 | L12: 1.Inverters 1, 2, 3, 5 and 6 experienced multiple tripping events. On 01/29, the technician arrived and found all inverters producing. Six new strings were installed for inverters 2, 3, and 5 to prevent further insulation faults. | M12: 1.SR093544,SR094968 | N12: SR094968
A13: CA: Petaluma MOB - Citi | B13: CA | C13: 42798.5 | D13: 45402.4 | E13: =C13/D13 -> 0.94264841 | F13: 43691 | G13: =IF(AND(ISNUMBER(C13),ISNUMBER(F13)), C13-F13, "") -> -892.5 | H13: =IFERROR(G13/F13, "") -> -0.020427548 | I13: 42214.46 | J13: =IF(AND(ISNUMBER(C13),ISNUMBER(I13)), C13-I13, "") -> 584.04 | K13: =IFERROR(J13/I13, "") -> 0.01383507 | L13: 1.When the technician was on site to troubleshot Inverter 2 for its previous trip event on 12/17/24, he identified that it was underperforming and initiated an RMA. Inverter 2 has been in RMA since 01/03/25. | M13: 1.SR094669,SR095487 | N13: SR095487
A14: CA: Pleasanton Tec Ctr - Citi | B14: CA | C14: 60053.5 | D14: 61177.84 | E14: =C14/D14 -> 0.98162178 | F14: 60279 | G14: =IF(AND(ISNUMBER(C14),ISNUMBER(F14)), C14-F14, "") -> -225.5 | H14: =IFERROR(G14/F14, "") -> -0.003740938 | I14: 72294.92 | J14: =IF(AND(ISNUMBER(C14),ISNUMBER(I14)), C14-I14, "") -> -12241.42 | K14: =IFERROR(J14/I14, "") -> -0.16932614 | L14: 1.Inverter 9 tripped offline at 10:10 AM on 01/16/25 and self-resolved, Invereter 9 was back online at 08:30 PM on the same day. | M14: 1.SR095637
A15: CA: Rancho Cordova - Citi | B15: CA | C15: 138722 | D15: 89789.61 | E15: =C15/D15 -> 1.5449672 | F15: 88802 | G15: =IF(AND(ISNUMBER(C15),ISNUMBER(F15)), C15-F15, "") -> 49920 | H15: =IFERROR(G15/F15, "") -> 0.5621495 | I15: 146135.83 | J15: =IF(AND(ISNUMBER(C15),ISNUMBER(I15)), C15-I15, "") -> -7413.825 | K15: =IFERROR(J15/I15, "") -> -0.050732426
A16: CA: S Sacramento Wyndham - Citi | B16: CA | C16: 61514 | D16: 47416.43 | E16: =C16/D16 -> 1.297314 | F16: 46851 | G16: =IF(AND(ISNUMBER(C16),ISNUMBER(F16)), C16-F16, "") -> 14663 | H16: =IFERROR(G16/F16, "") -> 0.31297091 | I16: 56726.753 | J16: =IF(AND(ISNUMBER(C16),ISNUMBER(I16)), C16-I16, "") -> 4787.247 | K16: =IFERROR(J16/I16, "") -> 0.084391345
A17: CA: Sacramento Point West - Citi | B17: CA | C17: 116857 | D17: 90698.8 | E17: =C17/D17 -> 1.2884073 | F17: 90230 | G17: =IF(AND(ISNUMBER(C17),ISNUMBER(F17)), C17-F17, "") -> 26627 | H17: =IFERROR(G17/F17, "") -> 0.29510141 | I17: 132201.53 | J17: =IF(AND(ISNUMBER(C17),ISNUMBER(I17)), C17-I17, "") -> -15344.526 | K17: =IFERROR(J17/I17, "") -> -0.1160692
A18: CA: San Jose FHC - Citi | B18: CA | C18: 20174.5 | D18: 22811.79 | E18: =C18/D18 -> 0.88438917 | F18: 23381 | G18: =IF(AND(ISNUMBER(C18),ISNUMBER(F18)), C18-F18, "") -> -3206.5 | H18: =IFERROR(G18/F18, "") -> -0.13714127 | I18: 25499.26 | J18: =IF(AND(ISNUMBER(C18),ISNUMBER(I18)), C18-I18, "") -> -5324.76 | K18: =IFERROR(J18/I18, "") -> -0.20882018 | L18: 1.Meter current phase B is 10 amps lower than A and C and further troubleshooting will be needed. | M18: 1.SR092732 , SR094546 | N18: SR094546
A19: CA: San Jose MOB - Citi | B19: CA | C19: 30984.25 | D19: 37719.66 | E19: =C19/D19 -> 0.82143503 | F19: 38042 | G19: =IF(AND(ISNUMBER(C19),ISNUMBER(F19)), C19-F19, "") -> -7057.75 | H19: =IFERROR(G19/F19, "") -> -0.18552521 | I19: 41140.37 | J19: =IF(AND(ISNUMBER(C19),ISNUMBER(I19)), C19-I19, "") -> -10156.12 | K19: =IFERROR(J19/I19, "") -> -0.24686506 | L19: 1.Inverter 1 has a history of multiple tripings and technician set the inverter to isolation mode and reenergized it. Then inverter 1 started producing as expected from 01/02. | M19: 1.SR093725
A20: CA: Selma - Citi | B20: CA | C20: 22758.75 | D20: 15404.17 | E20: =C20/D20 -> 1.4774408 | F20: 15194 | G20: =IF(AND(ISNUMBER(C20),ISNUMBER(F20)), C20-F20, "") -> 7564.75 | H20: =IFERROR(G20/F20, "") -> 0.49787745 | I20: 26945.834 | J20: =IF(AND(ISNUMBER(C20),ISNUMBER(I20)), C20-I20, "") -> -4187.084 | K20: =IFERROR(J20/I20, "") -> -0.15538892
A21: CA: Vacaville Hospital | B21: CA | C21: 158667 | D21: 130650.58 | E21: =C21/D21 -> 1.2144378 | F21: 130413 | G21: =IF(AND(ISNUMBER(C21),ISNUMBER(F21)), C21-F21, "") -> 28254 | H21: =IFERROR(G21/F21, "") -> 0.21665018 | I21: 151623.24 | J21: =IF(AND(ISNUMBER(C21),ISNUMBER(I21)), C21-I21, "") -> 7043.758 | K21: =IFERROR(J21/I21, "") -> 0.046455661
A22: CA: Manteca - KP Manteca Hospital | B22: CA | C22: 50535.38 | D22: 29973 | E22: =C22/D22 -> 1.6860301 | F22: 41066.637 | G22: =IF(AND(ISNUMBER(C22),ISNUMBER(F22)), C22-F22, "") -> 9468.743 | H22: =IFERROR(G22/F22, "") -> 0.23057021 | I22: 52266.221 | J22: =IF(AND(ISNUMBER(C22),ISNUMBER(I22)), C22-I22, "") -> -1730.841 | K22: =IFERROR(J22/I22, "") -> -0.033115863
A23: Sacramento - KP South Sacramento HSP | B23: CA

Sheet Feb
A1: {=portfolio} -> CITI | D1: PPA Modeled Output | E1: Production VS Acual | F1: February Actual v. Expected | I1: February Actual v. Forecasted
A2: Total | C2: =SUM(C4:C100) -> 1161890.9 | D2: =SUM(D4:D22) -> 1192644.3 | E2: =C2/D2 -> 0.97421406 | F2: =SUM(F4:F100) -> 1191822.5 | G2: =C2-F2 -> -29931.62 | H2: =IFERROR(G2/F2, 0) -> -0.025114159 | I2: =SUM(I4:I100) -> 1241928.5 | J2: =C2-I2 -> -80037.649 | K2: =IFERROR(J2/I2, 0) -> -0.06444626 | L2: =IF(AND(TODAY()>DATE(2024, 2, 1), COUNTA(Sites[Site])<>(COUNT(C:C)-1)), "Some sites are missing actual data; if new sites were added, make sure they are aligned correctly (including prior months!)", "") -> Some sites are missing actual data; if new sites were added, make sure they are aligned correctly (including prior months!)
A3: Site | B3: State | C3: Actual | F3: Expected | G3: Delta | H3: % | I3: Forecasted | J3: Delta | K3: % | L3: Notes | M3: Service Requests
A4: {=Sites[Site]} -> CA: Antioch Deer Valley - Citi | B4: {=Sites[State]} -> CA | C4: 32720 | D4: 33837.7 | E4: =C4/D4 -> 0.9669688 | F4: 33503 | G4: =IF(AND(ISNUMBER(C4),ISNUMBER(F4)), C4-F4, "") -> -783 | H4: =IFERROR(G4/F4, "") -> -0.023371041 | I4: 33108.406 | J4: =IF(AND(ISNUMBER(C4),ISNUMBER(I4)), C4-I4, "") -> -388.406 | K4: =IFERROR(J4/I4, "") -> -0.011731341 | L4: 1.The site offline on 02/26 at 12:45. On 02/28, a technician checked in and reported a blown fuse and reenergized the site. | M4: 1.SR097891
A5: CA: Antioch MC CUP - Citi | B5: CA | C5: 117003 | D5: 111655.8 | E5: =C5/D5 -> 1.04789 | F5: 110541 | G5: =IF(AND(ISNUMBER(C5),ISNUMBER(F5)), C5-F5, "") -> 6462 | H5: =IFERROR(G5/F5, "") -> 0.058457948 | I5: 121440.24 | J5: =IF(AND(ISNUMBER(C5),ISNUMBER(I5)), C5-I5, "") -> -4437.242 | K5: =IFERROR(J5/I5, "") -> -0.036538481
A6: CA: Clovis - Citi | B6: CA | C6: 49039.75 | D6: 46787.5 | E6: =C6/D6 -> 1.0481379 | F6: 45172 | G6: =IF(AND(ISNUMBER(C6),ISNUMBER(F6)), C6-F6, "") -> 3867.75 | H6: =IFERROR(G6/F6, "") -> 0.085622731 | I6: 45847.381 | J6: =IF(AND(ISNUMBER(C6),ISNUMBER(I6)), C6-I6, "") -> 3192.369 | K6: =IFERROR(J6/I6, "") -> 0.069630346 | L6: 1. Inverter 1 tripped offline at 16:45 from 01/27 due to arc protection fault and back online at 09:30 on 02/05. | M6: 1.SR096073
A7: CA: Elk Grove MOB - Citi | B7: CA | C7: 73432 | D7: 74269 | E7: =C7/D7 -> 0.98873016 | F7: 73534 | G7: =IF(AND(ISNUMBER(C7),ISNUMBER(F7)), C7-F7, "") -> -102 | H7: =IFERROR(G7/F7, "") -> -0.0013871134 | I7: 77096.73 | J7: =IF(AND(ISNUMBER(C7),ISNUMBER(I7)), C7-I7, "") -> -3664.73 | K7: =IFERROR(J7/I7, "") -> -0.047534182
A8: CA: Elk Grove Promenade - Citi | B8: CA | C8: 39950 | D8: 40582 | E8: =C8/D8 -> 0.98442659 | F8: 40180.25 | G8: =IF(AND(ISNUMBER(C8),ISNUMBER(F8)), C8-F8, "") -> -230.25 | H8: =IFERROR(G8/F8, "") -> -0.0057304273 | I8: 43579.704 | J8: =IF(AND(ISNUMBER(C8),ISNUMBER(I8)), C8-I8, "") -> -3629.704 | K8: =IFERROR(J8/I8, "") -> -0.083288863
A9: CA: Fresno Sequioa - Citi | B9: CA | C9: 78020.5 | D9: 83831.7 | E9: =C9/D9 -> 0.93068016 | F9: 83019 | G9: =IF(AND(ISNUMBER(C9),ISNUMBER(F9)), C9-F9, "") -> -4998.5 | H9: =IFERROR(G9/F9, "") -> -0.060209109 | I9: 87819.042 | J9: =IF(AND(ISNUMBER(C9),ISNUMBER(I9)), C9-I9, "") -> -9798.542 | K9: =IFERROR(J9/I9, "") -> -0.11157651 | L9: 1. Inverter 2 tripped offline at 18:45 on 01/07 due to an arc protection fault and was RMA'd on 02/17. | M9: 1.SR095408
A10: CA: Fresno MOB - Citi | B10: CA | C10: 29859.88 | D10: 33738.1 | E10: =C10/D10 -> 0.88504925 | F10: 33456 | G10: =IF(AND(ISNUMBER(C10),ISNUMBER(F10)), C10-F10, "") -> -3596.12 | H10: =IFERROR(G10/F10, "") -> -0.10748804 | I10: 29656.131 | J10: =IF(AND(ISNUMBER(C10),ISNUMBER(I10)), C10-I10, "") -> 203.749 | K10: =IFERROR(J10/I10, "") -> 0.0068703837 | L10: 1. Inverter 7 tripped offline at 19:35 on 02/14 due to an isolation fault and is now under RMA'd. | M10: 1. SR097152
A11: CA: Modesto Bangs - Citi | B11: CA | C11: 19801.5 | D11: 20447.6 | E11: =C11/D11 -> 0.96840216 | F11: 20348 | G11: =IF(AND(ISNUMBER(C11),ISNUMBER(F11)), C11-F11, "") -> -546.5 | H11: =IFERROR(G11/F11, "") -> -0.026857676 | I11: 20554.278 | J11: =IF(AND(ISNUMBER(C11),ISNUMBER(I11)), C11-I11, "") -> -752.778 | K11: =IFERROR(J11/I11, "") -> -0.036623909
A12: CA: Napa Data Center - Citi | B12: CA | C12: 20347.88 | D12: 22694.3 | E12: =C12/D12 -> 0.89660752 | F12: 21965 | G12: =IF(AND(ISNUMBER(C12),ISNUMBER(F12)), C12-F12, "") -> -1617.12 | H12: =IFERROR(G12/F12, "") -> -0.073622581 | I12: 23987.7 | J12: =IF(AND(ISNUMBER(C12),ISNUMBER(I12)), C12-I12, "") -> -3639.82 | K12: =IFERROR(J12/I12, "") -> -0.15173693 | L12: 1. Inverter 1 tripped offline at 07:00 AM on 02/01 and back online at 16:55 on 02/02. It tripped offline again at 07:00 AM on 02/13 and back online at 12:40 on 02/14 due to an isolation fault. 2. Inverter 5 tripped offline at 07:00AM on 02/25 and back online at 16:55 on 02/25. | M12: 1. SR096910 2. SR097715 | N12: SR097715
A13: CA: Petaluma MOB - Citi | B13: CA | C13: 45669.5 | D13: 52699.23 | E13: =C13/D13 -> 0.86660659 | F13: 50713 | G13: =IF(AND(ISNUMBER(C13),ISNUMBER(F13)), C13-F13, "") -> -5043.5 | H13: =IFERROR(G13/F13, "") -> -0.099451817 | I13: 52104.259 | J13: =IF(AND(ISNUMBER(C13),ISNUMBER(I13)), C13-I13, "") -> -6434.759 | K13: =IFERROR(J13/I13, "") -> -0.12349775 | L13: 1. When the technician was on site to troubleshot Inverter 2 for its previous trip event on 12/17/24, he identified that it was underperforming and initiated an RMA. Inverter 2 has been in RMA since 01/03/25. Inverter produced normally on 2/26 technician swapped with new inverter. 2.Inverter 14 has experienced multiple tripping events since 02/09 and is reporting 'PV abnormal input.' On 02/19, the technician removed the jumper bus bar and switched the input mode to 'independent' as per Chint's request, and it resumed normal operation. 3.Inverter 13 has reoccurring late starts, reporting insulation resistance low. This inverter has a history. On 02/26 technician swapped with new inverter and produced normallly. | M13: 1. SR094669,SR095487 2. SR096553 3. SR92736 , SR095488 | N13: SR095487 | O13: SR096553 | P13: SR92736 | Q13: SR095488
A14: CA: Pleasanton Tec Ctr - Citi | B14: CA | C14: 64678 | D14: 71770 | E14: =C14/D14 -> 0.90118434 | F14: 70963 | G14: =IF(AND(ISNUMBER(C14),ISNUMBER(F14)), C14-F14, "") -> -6285 | H14: =IFERROR(G14/F14, "") -> -0.088567282 | I14: 73511.443 | J14: =IF(AND(ISNUMBER(C14),ISNUMBER(I14)), C14-I14, "") -> -8833.443 | K14: =IFERROR(J14/I14, "") -> -0.12016419
A15: CA: Rancho Cordova - Citi | B15: CA | C15: 123056 | D15: 116944 | E15: =C15/D15 -> 1.0522643 | F15: 115658 | G15: =IF(AND(ISNUMBER(C15),ISNUMBER(F15)), C15-F15, "") -> 7398 | H15: =IFERROR(G15/F15, "") -> 0.063964447 | I15: 126414.86 | J15: =IF(AND(ISNUMBER(C15),ISNUMBER(I15)), C15-I15, "") -> -3358.863 | K15: =IFERROR(J15/I15, "") -> -0.026570159
A16: CA: S Sacramento Wyndham - Citi | B16: CA | C16: 62431 | D16: 63883.2 | E16: =C16/D16 -> 0.97726789 | F16: 63122 | G16: =IF(AND(ISNUMBER(C16),ISNUMBER(F16)), C16-F16, "") -> -691 | H16: =IFERROR(G16/F16, "") -> -0.010947055 | I16: 61291.02 | J16: =IF(AND(ISNUMBER(C16),ISNUMBER(I16)), C16-I16, "") -> 1139.98 | K16: =IFERROR(J16/I16, "") -> 0.018599462
A17: CA: Sacramento Point West - Citi | B17: CA | C17: 117073 | D17: 122199 | E17: =C17/D17 -> 0.95805203 | F17: 121584 | G17: =IF(AND(ISNUMBER(C17),ISNUMBER(F17)), C17-F17, "") -> -4511 | H17: =IFERROR(G17/F17, "") -> -0.037101921 | I17: 131537.93 | J17: =IF(AND(ISNUMBER(C17),ISNUMBER(I17)), C17-I17, "") -> -14464.929 | K17: =IFERROR(J17/I17, "") -> -0.10996774 | L17: 1. Inverter 5.4 tripped offline at 10:30 AM on 02/22 due to ARC protection and water in the wire box, so a new wire box is needed for replacement to get back the inverter. | M17: 1. SR097653
A18: CA: San Jose FHC - Citi | B18: CA | C18: 21935.75 | D18: 25812.8 | E18: =C18/D18 -> 0.84980126 | F18: 26457 | G18: =IF(AND(ISNUMBER(C18),ISNUMBER(F18)), C18-F18, "") -> -4521.25 | H18: =IFERROR(G18/F18, "") -> -0.1708905 | I18: 26911.372 | J18: =IF(AND(ISNUMBER(C18),ISNUMBER(I18)), C18-I18, "") -> -4975.622 | K18: =IFERROR(J18/I18, "") -> -0.1848892 | L18: 1.Meter current phase B is 10 amps lower than A and C and further troubleshooting will be needed. 2. The site was offline from 12:05 to 13:35 on 02/28 due to the technician being on site to work on the solar system. | M18: 1. SR092732 , SR094546 2. SR094546 | N18: SR094546 | O18: SR094546
A19: CA: San Jose MOB - Citi | B19: CA | C19: 34046.5 | D19: 41783.9 | E19: =C19/D19 -> 0.81482341 | F19: 42140 | G19: =IF(AND(ISNUMBER(C19),ISNUMBER(F19)), C19-F19, "") -> -8093.5 | H19: =IFERROR(G19/F19, "") -> -0.19206217 | I19: 43555.535 | J19: =IF(AND(ISNUMBER(C19),ISNUMBER(I19)), C19-I19, "") -> -9509.035 | K19: =IFERROR(J19/I19, "") -> -0.21831978 | L19: 1. Inverter 10 has a multiple tripings from 02/27 and technician set the inverter to isolation mode and reenergized it. 2. Inverter 2 is derating by 6 kW, likely due to overheating, and is now under RMA'd. 3. Inverter 12 may have a string down (~3 kW), and inverter 8 may have several strings down (~13 kW). | M19: 1. SR097893 2. SR097777 3. SR097778 | N19: SR097777 | O19: SR097778
A20: CA: Selma - Citi | B20: CA | C20: 23596.12 | D20: 23766.7 | E20: =C20/D20 -> 0.99282273 | F20: 23523 | G20: =IF(AND(ISNUMBER(C20),ISNUMBER(F20)), C20-F20, "") -> 73.12 | H20: =IFERROR(G20/F20, "") -> 0.0031084471 | I20: 27065.457 | J20: =IF(AND(ISNUMBER(C20),ISNUMBER(I20)), C20-I20, "") -> -3469.337 | K20: =IFERROR(J20/I20, "") -> -0.1281832
A21: CA: Vacaville Hospital | B21: CA | C21: 157387 | D21: 157634.8 | E21: =C21/D21 -> 0.99842801 | F21: 157886 | G21: =IF(AND(ISNUMBER(C21),ISNUMBER(F21)), C21-F21, "") -> -499 | H21: =IFERROR(G21/F21, "") -> -0.0031605082 | I21: 160526.9 | J21: =IF(AND(ISNUMBER(C21),ISNUMBER(I21)), C21-I21, "") -> -3139.898 | K21: =IFERROR(J21/I21, "") -> -0.019559949
A22: CA: Manteca - KP Manteca Hospital | B22: CA | C22: 51843.5 | D22: 48307 | E22: =C22/D22 -> 1.0732089 | F22: 58058.25 | G22: =IF(AND(ISNUMBER(C22),ISNUMBER(F22)), C22-F22, "") -> -6214.75 | H22: =IFERROR(G22/F22, "") -> -0.10704336 | I22: 55920.139 | J22: =IF(AND(ISNUMBER(C22),ISNUMBER(I22)), C22-I22, "") -> -4076.639 | K22: =IFERROR(J22/I22, "") -> -0.072901088
A23: Sacramento - KP South Sacramento HSP | B23: CA | J23: =IF(AND(ISNUMBER(C23),ISNUMBER(I23)), C23-I23, "")

Sheet Mar
A1: {=portfolio} -> CITI | D1: PPA Modeled Output | E1: Production VS Acual | F1: Q1 Production Vs PPA | G1: March Actual v. Expected | J1: March Actual v. Forecasted
