Workbook
Name JanActual: #REF!
Name JanActual2: #REF!
Name JanExpected: #REF!
Name JanExpectedDelta: #REF!
Name JanExpectedPercent: #REF!
Name JanExpPercent: #REF!
Name JanForecasted: #REF!
Name JanForecastedDelta: #REF!
Name JanForecastedPercent: #REF!
Name portfolio: Sites!$B$1:$B$1
Name Year: Sites!#REF!

Sheet Year to Date
A1: {=portfolio} -> CBRE | D1: Year to Date Actual v. Expected | G1: Year to Date Actual v. Forecasted
A2: Total | C2: =SUM(C4:C87) -> #REF! | D2: =SUM(D4:D87) -> 0 | E2: =C2-D2 -> #REF! | F2: =IFERROR(E2/D2, 0) -> 0 | G2: =SUM(G4:G87) -> 0 | H2: =C2-G2 -> #REF! | I2: =IFERROR(H2/G2, 0) -> 0
A3: Site | B3: State | C3: Actual | D3: Expected | E3: Delta | F3: % | G3: Forecasted | H3: Delta | I3: %
A4: {=Sites[Site]} -> East Hartford - BA | B4: {=Sites[State]} -> CT | C4: =SUM('1st Qtr'!C4, '2nd Qtr'!C4, '3rd Qtr'!C4, '4th Qtr'!C4) -> 17660.699 | D4: =SUM('1st Qtr'!D4, '2nd Qtr'!D4, '3rd Qtr'!D4, '4th Qtr'!D4) -> 0 | E4: =IF(AND(ISNUMBER(C4),ISNUMBER(D4)), C4-D4, "") -> 17660.699 | F4: =IFERROR(E4/D4, "") | G4: =SUM('1st Qtr'!G4, '2nd Qtr'!G4, '3rd Qtr'!G4, '4th Qtr'!G4) -> 0 | H4: =SUM('1st Qtr'!H4, '2nd Qtr'!H4, '3rd Qtr'!H4, '4th Qtr'!H4) -> 17660.699 | I4: =IFERROR(H4/G4, "")
A5: Indianapolis - BA Speedway | B5: IN | C5: =SUM('1st Qtr'!C5, '2nd Qtr'!C5, '3rd Qtr'!C5, '4th Qtr'!C5) -> 8348.944 | D5: =SUM('1st Qtr'!D5, '2nd Qtr'!D5, '3rd Qtr'!D5, '4th Qtr'!D5) -> 0 | E5: =IF(AND(ISNUMBER(C5),ISNUMBER(D5)), C5-D5, "") -> 8348.944 | F5: =IFERROR(E5/D5, "") | G5: =SUM('1st Qtr'!G5, '2nd Qtr'!G5, '3rd Qtr'!G5, '4th Qtr'!G5) -> 0 | H5: =SUM(Jan!H5, Feb!H5, Mar!H5) -> 0 | I5: =IFERROR(H5/G5, "")
A6: Greenwood - BA | B6: IN | C6: =SUM('1st Qtr'!C6, '2nd Qtr'!C6, '3rd Qtr'!C6, '4th Qtr'!C6) -> 4510.673 | D6: =SUM('1st Qtr'!D6, '2nd Qtr'!D6, '3rd Qtr'!D6, '4th Qtr'!D6) -> 0 | E6: =IF(AND(ISNUMBER(C6),ISNUMBER(D6)), C6-D6, "") -> 4510.673 | F6: =IFERROR(E6/D6, "") | G6: =SUM('1st Qtr'!G6, '2nd Qtr'!G6, '3rd Qtr'!G6, '4th Qtr'!G6) -> 0 | H6: =SUM(Jan!H6, Feb!H6, Mar!H6) -> 0 | I6: =IFERROR(H6/G6, "")
A7: West Chester - BA | B7: OH | C7: =SUM('1st Qtr'!C7, '2nd Qtr'!C7, '3rd Qtr'!C7, '4th Qtr'!C7) -> 9756.511 | D7: =SUM('1st Qtr'!D7, '2nd Qtr'!D7, '3rd Qtr'!D7, '4th Qtr'!D7) -> 0 | E7: =IF(AND(ISNUMBER(C7),ISNUMBER(D7)), C7-D7, "") -> 9756.511 | F7: =IFERROR(E7/D7, "") | G7: =SUM('1st Qtr'!G7, '2nd Qtr'!G7, '3rd Qtr'!G7, '4th Qtr'!G7) -> 0 | H7: =SUM(Jan!H7, Feb!H7, Mar!H7) -> 0 | I7: =IFERROR(H7/G7, "")
A8: Cincinnati - BA MLK and Burnet | B8: OH | C8: =SUM('1st Qtr'!C8, '2nd Qtr'!C8, '3rd Qtr'!C8, '4th Qtr'!C8) -> 14208.01 | D8: =SUM('1st Qtr'!D8, '2nd Qtr'!D8, '3rd Qtr'!D8, '4th Qtr'!D8) -> 0 | E8: =IF(AND(ISNUMBER(C8),ISNUMBER(D8)), C8-D8, "") -> 14208.01 | F8: =IFERROR(E8/D8, "") | G8: =SUM('1st Qtr'!G8, '2nd Qtr'!G8, '3rd Qtr'!G8, '4th Qtr'!G8) -> 0 | H8: =SUM(Jan!H8, Feb!H8, Mar!H8) -> 0 | I8: =IFERROR(H8/G8, "")
A9: Columbus - BA Harrisburg Pike | B9: OH | C9: =SUM('1st Qtr'!C9, '2nd Qtr'!C9, '3rd Qtr'!C9, '4th Qtr'!C9) -> 11795.749 | D9: =SUM('1st Qtr'!D9, '2nd Qtr'!D9, '3rd Qtr'!D9, '4th Qtr'!D9) -> 0 | E9: =IF(AND(ISNUMBER(C9),ISNUMBER(D9)), C9-D9, "") -> 11795.749 | F9: =IFERROR(E9/D9, "") | G9: =SUM('1st Qtr'!G9, '2nd Qtr'!G9, '3rd Qtr'!G9, '4th Qtr'!G9) -> 0 | H9: =SUM(Jan!H9, Feb!H9, Mar!H9) -> 0 | I9: =IFERROR(H9/G9, "")
A10: Cincinnati - BA Hyde Pk Plaza | B10: OH | C10: =SUM('1st Qtr'!C10, '2nd Qtr'!C10, '3rd Qtr'!C10, '4th Qtr'!C10) -> 13796.76 | D10: =SUM('1st Qtr'!D10, '2nd Qtr'!D10, '3rd Qtr'!D10, '4th Qtr'!D10) -> 0 | E10: =IF(AND(ISNUMBER(C10),ISNUMBER(D10)), C10-D10, "") -> 13796.76 | F10: =IFERROR(E10/D10, "") | G10: =SUM('1st Qtr'!G10, '2nd Qtr'!G10, '3rd Qtr'!G10, '4th Qtr'!G10) -> 0 | H10: =SUM(Jan!H10, Feb!H10, Mar!H10) -> 0 | I10: =IFERROR(H10/G10, "")
A11: Cleveland - BA Carnegie & 79th | B11: OH | C11: =SUM('1st Qtr'!C11, '2nd Qtr'!C11, '3rd Qtr'!C11, '4th Qtr'!C11) -> 26897.893 | D11: =SUM('1st Qtr'!D11, '2nd Qtr'!D11, '3rd Qtr'!D11, '4th Qtr'!D11) -> 0 | E11: =IF(AND(ISNUMBER(C11),ISNUMBER(D11)), C11-D11, "") -> 26897.893 | F11: =IFERROR(E11/D11, "") | G11: =SUM('1st Qtr'!G11, '2nd Qtr'!G11, '3rd Qtr'!G11, '4th Qtr'!G11) -> 0 | H11: =SUM(Jan!H11, Feb!H11, Mar!H11) -> 0 | I11: =IFERROR(H11/G11, "")
A12: Cincinnati - BA Sharonville | B12: OH | C12: =SUM('1st Qtr'!C12, '2nd Qtr'!C12, '3rd Qtr'!C12, '4th Qtr'!C12) -> 1192.77 | D12: =SUM('1st Qtr'!D12, '2nd Qtr'!D12, '3rd Qtr'!D12, '4th Qtr'!D12) -> 0 | E12: =IF(AND(ISNUMBER(C12),ISNUMBER(D12)), C12-D12, "") -> 1192.77 | F12: =IFERROR(E12/D12, "") | G12: =SUM('1st Qtr'!G12, '2nd Qtr'!G12, '3rd Qtr'!G12, '4th Qtr'!G12) -> 0 | H12: =SUM(Jan!H12, Feb!H12, Mar!H12) -> 0 | I12: =IFERROR(H12/G12, "")
A13: Zionsville - BA | B13: IN | C13: =SUM('1st Qtr'!C13, '2nd Qtr'!C13, '3rd Qtr'!C13, '4th Qtr'!C13) -> 18256.161 | D13: =SUM('1st Qtr'!D13, '2nd Qtr'!D13, '3rd Qtr'!D13, '4th Qtr'!D13) -> 0 | E13: =IF(AND(ISNUMBER(C13),ISNUMBER(D13)), C13-D13, "") -> 18256.161 | F13: =IFERROR(E13/D13, "") | G13: =SUM('1st Qtr'!G13, '2nd Qtr'!G13, '3rd Qtr'!G13, '4th Qtr'!G13) -> 0 | H13: =SUM(Jan!H13, Feb!H13, Mar!H13) -> 0 | I13: =IFERROR(H13/G13, "")
A14: Columbus - BA Eastgate | B14: OH | C14: =SUM('1st Qtr'!C14, '2nd Qtr'!C14, '3rd Qtr'!C14, '4th Qtr'!C14) -> 9897.4 | D14: =SUM('1st Qtr'!D14, '2nd Qtr'!D14, '3rd Qtr'!D14, '4th Qtr'!D14) -> 0 | E14: =IF(AND(ISNUMBER(C14),ISNUMBER(D14)), C14-D14, "") -> 9897.4 | F14: =IFERROR(E14/D14, "") | G14: =SUM('1st Qtr'!G14, '2nd Qtr'!G14, '3rd Qtr'!G14, '4th Qtr'!G14) -> 0 | H14: =SUM(Jan!H14, Feb!H14, Mar!H14) -> 0 | I14: =IFERROR(H14/G14, "")
A15: Columbus - BA Eastmoor | B15: OH | C15: =SUM('1st Qtr'!C15, '2nd Qtr'!C15, '3rd Qtr'!C15, '4th Qtr'!C15) -> 16495.14 | D15: =SUM('1st Qtr'!D15, '2nd Qtr'!D15, '3rd Qtr'!D15, '4th Qtr'!D15) -> 0 | E15: =IF(AND(ISNUMBER(C15),ISNUMBER(D15)), C15-D15, "") -> 16495.14 | F15: =IFERROR(E15/D15, "") | G15: =SUM('1st Qtr'!G15, '2nd Qtr'!G15, '3rd Qtr'!G15, '4th Qtr'!G15) -> 0 | H15: =SUM(Jan!H15, Feb!H15, Mar!H15) -> 0 | I15: =IFERROR(H15/G15, "")
A16: Brooklyn - BA Canarsie | B16: NY | C16: =SUM('1st Qtr'!C16, '2nd Qtr'!C16, '3rd Qtr'!C16, '4th Qtr'!C16) -> 0 | D16: =SUM('1st Qtr'!D16, '2nd Qtr'!D16, '3rd Qtr'!D16, '4th Qtr'!D16) -> 0 | E16: =IF(AND(ISNUMBER(C16),ISNUMBER(D16)), C16-D16, "") -> 0 | F16: =IFERROR(E16/D16, "") | G16: =SUM('1st Qtr'!G16, '2nd Qtr'!G16, '3rd Qtr'!G16, '4th Qtr'!G16) -> 0 | H16: =SUM(Jan!H16, Feb!H16, Mar!H16) -> 0 | I16: =IFERROR(H16/G16, "")
... A24: Midlothian - BA Brandermill | B24: VA | C24: =SUM('1st Qtr'!C24, '2nd Qtr'!C24, '3rd Qtr'!C24, '4th Qtr'!C24) -> #REF! | D24: =SUM('1st Qtr'!D24, '2nd Qtr'!D24, '3rd Qtr'!D24, '4th Qtr'!D24) -> 0 | E24: =IF(AND(ISNUMBER(C24),ISNUMBER(D24)), C24-D24, "") | F24: =IFERROR(E24/D24, "") | G24: =SUM('1st Qtr'!G24, '2nd Qtr'!G24, '3rd Qtr'!G24, '4th Qtr'!G24) -> 0 | H24: =SUM(Jan!H24, Feb!H24, Mar!H24) -> 0 | I24: =IFERROR(H24/G24, "")
A25: Lexington - BA North Park | B25: KY | C25: =SUM('1st Qtr'!C25, '2nd Qtr'!C25, '3rd Qtr'!C25, '4th Qtr'!C25) -> 7412.4 | D25: =SUM('1st Qtr'!D25, '2nd Qtr'!D25, '3rd Qtr'!D25, '4th Qtr'!D26) -> 0 | E25: =IF(AND(ISNUMBER(C25),ISNUMBER(D25)), C25-D25, "") -> 7412.4 | F25: =IFERROR(E25/D25, "") | G25: =SUM('1st Qtr'!G25, '2nd Qtr'!G25, '3rd Qtr'!G25, '4th Qtr'!G25) -> 0 | H25: =SUM(Jan!H25, Feb!H25, Mar!H25) -> 0 | I25: =IFERROR(H25/G25, "")
A26: Coventry - BA ATM | B26: RI
A27: Woodbridge - BA ATM | B27: VA

Sheet 1st Qtr
A1: {=portfolio} -> CBRE | D1: 1st Quarter Actual v. Expected | G1: 1st Quarter Actual v. Forecasted
A2: Total | C2: =SUM(C4:C87) -> 0 | D2: =SUM(D4:D87) -> 0 | E2: =C2-D2 -> 0 | F2: =IFERROR(E2/D2, 0) -> 0 | G2: =SUM(G4:G87) -> 0 | H2: =C2-G2 -> 0 | I2: =IFERROR(H2/G2, 0) -> 0
A3: Site | B3: State | C3: Actual | D3: Expected | E3: Delta | F3: % | G3: Forecasted | H3: Delta | I3: %
A4: {=Sites[Site]} -> East Hartford - BA | B4: {=Sites[State]} -> CT | C4: =SUM(Jan!C4, Feb!C4, Mar!C4) -> 0 | D4: =SUM(Jan!D4, Feb!D4, Mar!D4) -> 0 | E4: =IF(AND(ISNUMBER(C4),ISNUMBER(D4)), C4-D4, "") -> 0 | F4: =IFERROR(E4/D4, "") | G4: =SUM(Jan!G4, Feb!G4, Mar!G4) -> 0 | H4: =SUM(Jan!H4, Feb!H4, Mar!H4) -> 0 | I4: =IFERROR(H4/G4, "")
A5: Indianapolis - BA Speedway | B5: IN | C5: =SUM(Jan!C5, Feb!C5, Mar!C5) -> 0 | D5: =SUM(Jan!D5, Feb!D5, Mar!D5) -> 0 | E5: =IF(AND(ISNUMBER(C5),ISNUMBER(D5)), C5-D5, "") -> 0 | F5: =IFERROR(E5/D5, "") | G5: =SUM(Jan!G5, Feb!G5, Mar!G5) -> 0 | H5: =SUM(Jan!H5, Feb!H5, Mar!H5) -> 0 | I5: =IFERROR(H5/G5, "")
A6: Greenwood - BA | B6: IN | C6: =SUM(Jan!C6, Feb!C6, Mar!C6) -> 0 | D6: =SUM(Jan!D6, Feb!D6, Mar!D6) -> 0 | E6: =IF(AND(ISNUMBER(C6),ISNUMBER(D6)), C6-D6, "") -> 0 | F6: =IFERROR(E6/D6, "") | G6: =SUM(Jan!G6, Feb!G6, Mar!G6) -> 0 | H6: =SUM(Jan!H6, Feb!H6, Mar!H6) -> 0 | I6: =IFERROR(H6/G6, "")
A7: West Chester - BA | B7: OH | C7: =SUM(Jan!C7, Feb!C7, Mar!C7) -> 0 | D7: =SUM(Jan!D7, Feb!D7, Mar!D7) -> 0 | E7: =IF(AND(ISNUMBER(C7),ISNUMBER(D7)), C7-D7, "") -> 0 | F7: =IFERROR(E7/D7, "") | G7: =SUM(Jan!G7, Feb!G7, Mar!G7) -> 0 | H7: =SUM(Jan!H7, Feb!H7, Mar!H7) -> 0 | I7: =IFERROR(H7/G7, "")
A8: Cincinnati - BA MLK and Burnet | B8: OH | C8: =SUM(Jan!C8, Feb!C8, Mar!C8) -> 0 | D8: =SUM(Jan!D8, Feb!D8, Mar!D8) -> 0 | E8: =IF(AND(ISNUMBER(C8),ISNUMBER(D8)), C8-D8, "") -> 0 | F8: =IFERROR(E8/D8, "") | G8: =SUM(Jan!G8, Feb!G8, Mar!G8) -> 0 | H8: =SUM(Jan!H8, Feb!H8, Mar!H8) -> 0 | I8: =IFERROR(H8/G8, "")
A9: Columbus - BA Harrisburg Pike | B9: OH | C9: =SUM(Jan!C9, Feb!C9, Mar!C9) -> 0 | D9: =SUM(Jan!D9, Feb!D9, Mar!D9) -> 0 | E9: =IF(AND(ISNUMBER(C9),ISNUMBER(D9)), C9-D9, "") -> 0 | F9: =IFERROR(E9/D9, "") | G9: =SUM(Jan!G9, Feb!G9, Mar!G9) -> 0 | H9: =SUM(Jan!H9, Feb!H9, Mar!H9) -> 0 | I9: =IFERROR(H9/G9, "")
A10: Cincinnati - BA Hyde Pk Plaza | B10: OH | C10: =SUM(Jan!C10, Feb!C10, Mar!C10) -> 0 | D10: =SUM(Jan!D10, Feb!D10, Mar!D10) -> 0 | E10: =IF(AND(ISNUMBER(C10),ISNUMBER(D10)), C10-D10, "") -> 0 | F10: =IFERROR(E10/D10, "") | G10: =SUM(Jan!G10, Feb!G10, Mar!G10) -> 0 | H10: =SUM(Jan!H10, Feb!H10, Mar!H10) -> 0 | I10: =IFERROR(H10/G10, "")
A11: Cleveland - BA Carnegie & 79th | B11: OH | C11: =SUM(Jan!C11, Feb!C11, Mar!C11) -> 0 | D11: =SUM(Jan!D11, Feb!D11, Mar!D11) -> 0 | E11: =IF(AND(ISNUMBER(C11),ISNUMBER(D11)), C11-D11, "") -> 0 | F11: =IFERROR(E11/D11, "") | G11: =SUM(Jan!G11, Feb!G11, Mar!G11) -> 0 | H11: =SUM(Jan!H11, Feb!H11, Mar!H11) -> 0 | I11: =IFERROR(H11/G11, "")
A12: Cincinnati - BA Sharonville | B12: OH | C12: =SUM(Jan!C12, Feb!C12, Mar!C12) -> 0 | D12: =SUM(Jan!D12, Feb!D12, Mar!D12) -> 0 | E12: =IF(AND(ISNUMBER(C12),ISNUMBER(D12)), C12-D12, "") -> 0 | F12: =IFERROR(E12/D12, "") | G12: =SUM(Jan!G12, Feb!G12, Mar!G12) -> 0 | H12: =SUM(Jan!H12, Feb!H12, Mar!H12) -> 0 | I12: =IFERROR(H12/G12, "")
A13: Zionsville - BA | B13: IN | C13: =SUM(Jan!C13, Feb!C13, Mar!C13) -> 0 | D13: =SUM(Jan!D13, Feb!D13, Mar!D13) -> 0 | E13: =IF(AND(ISNUMBER(C13),ISNUMBER(D13)), C13-D13, "") -> 0 | F13: =IFERROR(E13/D13, "") | G13: =SUM(Jan!G13, Feb!G13, Mar!G13) -> 0 | H13: =SUM(Jan!H13, Feb!H13, Mar!H13) -> 0 | I13: =IFERROR(H13/G13, "")
A14: Columbus - BA Eastgate | B14: OH | C14: =SUM(Jan!C14, Feb!C14, Mar!C14) -> 0 | D14: =SUM(Jan!D14, Feb!D14, Mar!D14) -> 0 | E14: =IF(AND(ISNUMBER(C14),ISNUMBER(D14)), C14-D14, "") -> 0 | F14: =IFERROR(E14/D14, "") | G14: =SUM(Jan!G14, Feb!G14, Mar!G14) -> 0 | H14: =SUM(Jan!H14, Feb!H14, Mar!H14) -> 0 | I14: =IFERROR(H14/G14, "")
A15: Columbus - BA Eastmoor | B15: OH | C15: =SUM(Jan!C15, Feb!C15, Mar!C15) -> 0 | D15: =SUM(Jan!D15, Feb!D15, Mar!D15) -> 0 | E15: =IF(AND(ISNUMBER(C15),ISNUMBER(D15)), C15-D15, "") -> 0 | F15: =IFERROR(E15/D15, "") | G15: =SUM(Jan!G15, Feb!G15, Mar!G15) -> 0 | H15: =SUM(Jan!H15, Feb!H15, Mar!H15) -> 0 | I15: =IFERROR(H15/G15, "")
A16: Brooklyn - BA Canarsie | B16: NY | C16: =SUM(Jan!C16, Feb!C16, Mar!C16) -> 0 | D16: =SUM(Jan!D16, Feb!D16, Mar!D16) -> 0 | E16: =IF(AND(ISNUMBER(C16),ISNUMBER(D16)), C16-D16, "") -> 0 | F16: =IFERROR(E16/D16, "") | G16: =SUM(Jan!G16, Feb!G16, Mar!G16) -> 0 | H16: =SUM(Jan!H16, Feb!H16, Mar!H16) -> 0 | I16: =IFERROR(H16/G16, "")
... A25: Lexington - BA North Park | B25: KY | C25: =SUM(Jan!C25, Feb!C25, Mar!C25) -> 0 | D25: =SUM(Jan!D25, Feb!D25, Mar!D25) -> 0 | E25: =IF(AND(ISNUMBER(C25),ISNUMBER(D25)), C25-D25, "") -> 0 | F25: =IFERROR(E25/D25, "") | G25: =SUM(Jan!G25, Feb!G25, Mar!G25) -> 0 | H25: =SUM(Jan!H25, Feb!H25, Mar!H25) -> 0 | I25: =IFERROR(H25/G25, "")
A26: Coventry - BA ATM | B26: RI
A27: Woodbridge - BA ATM | B27: VA

Sheet 2nd Qtr
A1: {=portfolio} -> CBRE | D1: 2nd Quarter Actual v. Expected | G1: 2nd Quarter Actual v. Forecasted
A2: Total | C2: =SUM(C4:C86) -> 100099.47 | D2: =SUM(D4:D86) -> 0 | E2: =C2-D2 -> 100099.47 | F2: =IFERROR(E2/D2, 0) -> 0 | G2: =SUM(G4:G86) -> 0 | H2: =C2-G2 -> 100099.47 | I2: =IFERROR(H2/G2, 0) -> 0
A3: Site | B3: State | C3: Actual | D3: Expected | E3: Delta | F3: % | G3: Forecasted | H3: Delta | I3: %
A4: {=Sites[Site]} -> East Hartford - BA | B4: {=Sites[State]} -> CT | C4: =SUM(Apr!C4, May!C4, Jun!C4) -> 9160.799 | D4: =SUM(Apr!D4, May!D4, Jun!D4) -> 0 | E4: =IF(AND(ISNUMBER(C4),ISNUMBER(D4)), C4-D4, "") -> 9160.799 | F4: =IFERROR(E4/D4, "") | G4: =SUM(Apr!G4, May!G4, Jun!G4) -> 0 | H4: =SUM(Apr!H4, May!H4, Jun!H4) -> 9160.799 | I4: =IFERROR(H4/G4, "")
A5: Indianapolis - BA Speedway | B5: IN | C5: =SUM(Apr!C5, May!C5, Jun!C5) -> 4212.07 | D5: =SUM(Apr!D5, May!D5, Jun!D5) -> 0 | E5: =IF(AND(ISNUMBER(C5),ISNUMBER(D5)), C5-D5, "") -> 4212.07 | F5: =IFERROR(E5/D5, "") | G5: =SUM(Apr!G5, May!G5, Jun!G5) -> 0 | H5: =SUM(Apr!H5, May!H5, Jun!H5) -> 4212.07 | I5: =IFERROR(H5/G5, "")
A6: Greenwood - BA | B6: IN | C6: =SUM(Apr!C6, May!C6, Jun!C6) -> 2257 | D6: =SUM(Apr!D6, May!D6, Jun!D6) -> 0 | E6: =IF(AND(ISNUMBER(C6),ISNUMBER(D6)), C6-D6, "") -> 2257 | F6: =IFERROR(E6/D6, "") | G6: =SUM(Apr!G6, May!G6, Jun!G6) -> 0 | H6: =SUM(Apr!H6, May!H6, Jun!H6) -> 2257 | I6: =IFERROR(H6/G6, "")
A7: West Chester - BA | B7: OH | C7: =SUM(Apr!C7, May!C7, Jun!C7) -> 4847 | D7: =SUM(Apr!D7, May!D7, Jun!D7) -> 0 | E7: =IF(AND(ISNUMBER(C7),ISNUMBER(D7)), C7-D7, "") -> 4847 | F7: =IFERROR(E7/D7, "") | G7: =SUM(Apr!G7, May!G7, Jun!G7) -> 0 | H7: =SUM(Apr!H7, May!H7, Jun!H7) -> 4847 | I7: =IFERROR(H7/G7, "")
A8: Cincinnati - BA MLK and Burnet | B8: OH | C8: =SUM(Apr!C8, May!C8, Jun!C8) -> 7155 | D8: =SUM(Apr!D8, May!D8, Jun!D8) -> 0 | E8: =IF(AND(ISNUMBER(C8),ISNUMBER(D8)), C8-D8, "") -> 7155 | F8: =IFERROR(E8/D8, "") | G8: =SUM(Apr!G8, May!G8, Jun!G8) -> 0 | H8: =SUM(Apr!H8, May!H8, Jun!H8) -> 7155 | I8: =IFERROR(H8/G8, "")
A9: Columbus - BA Harrisburg Pike | B9: OH | C9: =SUM(Apr!C9, May!C9, Jun!C9) -> 5955 | D9: =SUM(Apr!D9, May!D9, Jun!D9) -> 0 | E9: =IF(AND(ISNUMBER(C9),ISNUMBER(D9)), C9-D9, "") -> 5955 | F9: =IFERROR(E9/D9, "") | G9: =SUM(Apr!G9, May!G9, Jun!G9) -> 0 | H9: =SUM(Apr!H9, May!H9, Jun!H9) -> 5955 | I9: =IFERROR(H9/G9, "")
A10: Cincinnati - BA Hyde Pk Plaza | B10: OH | C10: =SUM(Apr!C10, May!C10, Jun!C10) -> 6955 | D10: =SUM(Apr!D10, May!D10, Jun!D10) -> 0 | E10: =IF(AND(ISNUMBER(C10),ISNUMBER(D10)), C10-D10, "") -> 6955 | F10: =IFERROR(E10/D10, "") | G10: =SUM(Apr!G10, May!G10, Jun!G10) -> 0 | H10: =SUM(Apr!H10, May!H10, Jun!H10) -> 6955 | I10: =IFERROR(H10/G10, "")
A11: Cleveland - BA Carnegie & 79th | B11: OH | C11: =SUM(Apr!C11, May!C11, Jun!C11) -> 5070.207 | D11: =SUM(Apr!D11, May!D11, Jun!D11) -> 0 | E11: =IF(AND(ISNUMBER(C11),ISNUMBER(D11)), C11-D11, "") -> 5070.207 | F11: =IFERROR(E11/D11, "") | G11: =SUM(Apr!G11, May!G11, Jun!G11) -> 0 | H11: =SUM(Apr!H11, May!H11, Jun!H11) -> 5070.207 | I11: =IFERROR(H11/G11, "")
A12: Cincinnati - BA Sharonville | B12: OH | C12: =SUM(Apr!C12, May!C12, Jun!C12) -> 0 | D12: =SUM(Apr!D12, May!D12, Jun!D12) -> 0 | E12: =IF(AND(ISNUMBER(C12),ISNUMBER(D12)), C12-D12, "") -> 0 | F12: =IFERROR(E12/D12, "") | G12: =SUM(Apr!G12, May!G12, Jun!G12) -> 0 | H12: =SUM(Apr!H12, May!H12, Jun!H12) -> 0 | I12: =IFERROR(H12/G12, "")
A13: Zionsville - BA | B13: IN | C13: =SUM(Apr!C13, May!C13, Jun!C13) -> 9116.761 | D13: =SUM(Apr!D13, May!D13, Jun!D13) -> 0 | E13: =IF(AND(ISNUMBER(C13),ISNUMBER(D13)), C13-D13, "") -> 9116.761 | F13: =IFERROR(E13/D13, "") | G13: =SUM(Apr!G13, May!G13, Jun!G13) -> 0 | H13: =SUM(Apr!H13, May!H13, Jun!H13) -> 9116.761 | I13: =IFERROR(H13/G13, "")
A14: Columbus - BA Eastgate | B14: OH | C14: =SUM(Apr!C14, May!C14, Jun!C14) -> 5070 | D14: =SUM(Apr!D14, May!D14, Jun!D14) -> 0 | E14: =IF(AND(ISNUMBER(C14),ISNUMBER(D14)), C14-D14, "") -> 5070 | F14: =IFERROR(E14/D14, "") | G14: =SUM(Apr!G14, May!G14, Jun!G14) -> 0 | H14: =SUM(Apr!H14, May!H14, Jun!H14) -> 5070 | I14: =IFERROR(H14/G14, "")
A15: Columbus - BA Eastmoor | B15: OH | C15: =SUM(Apr!C15, May!C15, Jun!C15) -> 8285.56 | D15: =SUM(Apr!D15, May!D15, Jun!D15) -> 0 | E15: =IF(AND(ISNUMBER(C15),ISNUMBER(D15)), C15-D15, "") -> 8285.56 | F15: =IFERROR(E15/D15, "") | G15: =SUM(Apr!G15, May!G15, Jun!G15) -> 0 | H15: =SUM(Apr!H15, May!H15, Jun!H15) -> 8285.56 | I15: =IFERROR(H15/G15, "")
A16: Brooklyn - BA Canarsie | B16: NY | C16: =SUM(Apr!C16, May!C16, Jun!C16) -> 0 | D16: =SUM(Apr!D16, May!D16, Jun!D16) -> 0 | E16: =IF(AND(ISNUMBER(C16),ISNUMBER(D16)), C16-D16, "") -> 0 | F16: =IFERROR(E16/D16, "") | G16: =SUM(Apr!G16, May!G16, Jun!G16) -> 0 | H16: =SUM(Apr!H16, May!H16, Jun!H16) -> 0 | I16: =IFERROR(H16/G16, "")
... A25: Lexington - BA North Park | B25: KY | C25: =SUM(Apr!C25, May!C25, Jun!C25) -> 4241 | D25: =SUM(Apr!D25, May!D25, Jun!D25) -> 0 | E25: =IF(AND(ISNUMBER(C25),ISNUMBER(D25)), C25-D25, "") -> 4241 | F25: =IFERROR(E25/D25, "") | G25: =SUM(Apr!G25, May!G25, Jun!G25) -> 0 | H25: =SUM(Apr!H25, May!H25, Jun!H25) -> 4241 | I25: =IFERROR(H25/G25, "")
A26: Coventry - BA ATM | B26: RI
A27: Woodbridge - BA ATM | B27: VA

Sheet 3rd Qtr
A1: {=portfolio} -> CBRE | D1: 3rd Quarter Actual v. Expected | G1: 3rd Quarter Actual v. Forecasted
A2: Total | C2: =SUM(C4:C85) -> #REF! | D2: =SUM(D4:D85) -> 0 | E2: =C2-D2 -> #REF! | F2: =IFERROR(E2/D2, 0) -> 0 | G2: =SUM(G4:G85) -> 0 | H2: =C2-G2 -> #REF! | I2: =IFERROR(H2/G2, 0) -> 0
A3: Site | B3: State | C3: Actual | D3: Expected | E3: Delta | F3: % | G3: Forecasted | H3: Delta | I3: %
A4: {=Sites[Site]} -> East Hartford - BA | B4: {=Sites[State]} -> CT | C4: =SUM(Jul!C4, Aug!C4, Sep!C4) -> 8499.9 | D4: =SUM(Jul!D4, Aug!D4, Sep!D4) -> 0 | E4: =IF(AND(ISNUMBER(C4),ISNUMBER(D4)), C4-D4, "") -> 8499.9 | F4: =IFERROR(E4/D4, "") | G4: =SUM(Jul!G4, Aug!G4, Sep!G4) -> 0 | H4: =SUM(Jul!H4, Aug!H4, Sep!H4) -> 8499.9 | I4: =IFERROR(H4/G4, "")
A5: Indianapolis - BA Speedway | B5: IN | C5: =SUM(Jul!C5, Aug!C5, Sep!C5) -> 4136.874 | D5: =SUM(Jul!D5, Aug!D5, Sep!D5) -> 0 | E5: =IF(AND(ISNUMBER(C5),ISNUMBER(D5)), C5-D5, "") -> 4136.874 | F5: =IFERROR(E5/D5, "") | G5: =SUM(Jul!G5, Aug!G5, Sep!G5) -> 0 | H5: =SUM(Jul!H5, Aug!H5, Sep!H5) -> 4136.874 | I5: =IFERROR(H5/G5, "")
A6: Greenwood - BA | B6: IN | C6: =SUM(Jul!C6, Aug!C6, Sep!C6) -> 2253.673 | D6: =SUM(Jul!D6, Aug!D6, Sep!D6) -> 0 | E6: =IF(AND(ISNUMBER(C6),ISNUMBER(D6)), C6-D6, "") -> 2253.673 | F6: =IFERROR(E6/D6, "") | G6: =SUM(Jul!G6, Aug!G6, Sep!G6) -> 0 | H6: =SUM(Jul!H6, Aug!H6, Sep!H6) -> 2253.673 | I6: =IFERROR(H6/G6, "")
A7: West Chester - BA | B7: OH | C7: =SUM(Jul!C7, Aug!C7, Sep!C7) -> 4909.511 | D7: =SUM(Jul!D7, Aug!D7, Sep!D7) -> 0 | E7: =IF(AND(ISNUMBER(C7),ISNUMBER(D7)), C7-D7, "") -> 4909.511 | F7: =IFERROR(E7/D7, "") | G7: =SUM(Jul!G7, Aug!G7, Sep!G7) -> 0 | H7: =SUM(Jul!H7, Aug!H7, Sep!H7) -> 4909.511 | I7: =IFERROR(H7/G7, "")
A8: Cincinnati - BA MLK and Burnet | B8: OH | C8: =SUM(Jul!C8, Aug!C8, Sep!C8) -> 7053.01 | D8: =SUM(Jul!D8, Aug!D8, Sep!D8) -> 0 | E8: =IF(AND(ISNUMBER(C8),ISNUMBER(D8)), C8-D8, "") -> 7053.01 | F8: =IFERROR(E8/D8, "") | G8: =SUM(Jul!G8, Aug!G8, Sep!G8) -> 0 | H8: =SUM(Jul!H8, Aug!H8, Sep!H8) -> 7053.01 | I8: =IFERROR(H8/G8, "")
A9: Columbus - BA Harrisburg Pike | B9: OH | C9: =SUM(Jul!C9, Aug!C9, Sep!C9) -> 5840.749 | D9: =SUM(Jul!D9, Aug!D9, Sep!D9) -> 0 | E9: =IF(AND(ISNUMBER(C9),ISNUMBER(D9)), C9-D9, "") -> 5840.749 | F9: =IFERROR(E9/D9, "") | G9: =SUM(Jul!G9, Aug!G9, Sep!G9) -> 0 | H9: =SUM(Jul!H9, Aug!H9, Sep!H9) -> 5840.749 | I9: =IFERROR(H9/G9, "")
A10: Cincinnati - BA Hyde Pk Plaza | B10: OH | C10: =SUM(Jul!C10, Aug!C10, Sep!C10) -> 6841.76 | D10: =SUM(Jul!D10, Aug!D10, Sep!D10) -> 0 | E10: =IF(AND(ISNUMBER(C10),ISNUMBER(D10)), C10-D10, "") -> 6841.76 | F10: =IFERROR(E10/D10, "") | G10: =SUM(Jul!G10, Aug!G10, Sep!G10) -> 0 | H10: =SUM(Jul!H10, Aug!H10, Sep!H10) -> 6841.76 | I10: =IFERROR(H10/G10, "")
A11: Cleveland - BA Carnegie & 79th | B11: OH | C11: =SUM(Jul!C11, Aug!C11, Sep!C11) -> 21827.686 | D11: =SUM(Jul!D11, Aug!D11, Sep!D11) -> 0 | E11: =IF(AND(ISNUMBER(C11),ISNUMBER(D11)), C11-D11, "") -> 21827.686 | F11: =IFERROR(E11/D11, "") | G11: =SUM(Jul!G11, Aug!G11, Sep!G11) -> 0 | H11: =SUM(Jul!H11, Aug!H11, Sep!H11) -> 21827.686 | I11: =IFERROR(H11/G11, "")
A12: Cincinnati - BA Sharonville | B12: OH | C12: =SUM(Jul!C12, Aug!C12, Sep!C12) -> 1192.77 | D12: =SUM(Jul!D12, Aug!D12, Sep!D12) -> 0 | E12: =IF(AND(ISNUMBER(C12),ISNUMBER(D12)), C12-D12, "") -> 1192.77 | F12: =IFERROR(E12/D12, "") | G12: =SUM(Jul!G12, Aug!G12, Sep!G12) -> 0 | H12: =SUM(Jul!H12, Aug!H12, Sep!H12) -> 1192.77 | I12: =IFERROR(H12/G12, "")
A13: Zionsville - BA | B13: IN | C13: =SUM(Jul!C13, Aug!C13, Sep!C13) -> 9139.4 | D13: =SUM(Jul!D13, Aug!D13, Sep!D13) -> 0 | E13: =IF(AND(ISNUMBER(C13),ISNUMBER(D13)), C13-D13, "") -> 9139.4 | F13: =IFERROR(E13/D13, "") | G13: =SUM(Jul!G13, Aug!G13, Sep!G13) -> 0 | H13: =SUM(Jul!H13, Aug!H13, Sep!H13) -> 9139.4 | I13: =IFERROR(H13/G13, "")
A14: Columbus - BA Eastgate | B14: OH | C14: =SUM(Jul!C14, Aug!C14, Sep!C14) -> 4827.4 | D14: =SUM(Jul!D14, Aug!D14, Sep!D14) -> 0 | E14: =IF(AND(ISNUMBER(C14),ISNUMBER(D14)), C14-D14, "") -> 4827.4 | F14: =IFERROR(E14/D14, "") | G14: =SUM(Jul!G14, Aug!G14, Sep!G14) -> 0 | H14: =SUM(Jul!H14, Aug!H14, Sep!H14) -> 4827.4 | I14: =IFERROR(H14/G14, "")
A15: Columbus - BA Eastmoor | B15: OH | C15: =SUM(Jul!C15, Aug!C15, Sep!C15) -> 8209.58 | D15: =SUM(Jul!D15, Aug!D15, Sep!D15) -> 0 | E15: =IF(AND(ISNUMBER(C15),ISNUMBER(D15)), C15-D15, "") -> 8209.58 | F15: =IFERROR(E15/D15, "") | G15: =SUM(Jul!G15, Aug!G15, Sep!G15) -> 0 | H15: =SUM(Jul!H15, Aug!H15, Sep!H15) -> 8209.58 | I15: =IFERROR(H15/G15, "")
A16: Brooklyn - BA Canarsie | B16: NY | C16: =SUM(Jul!C16, Aug!C16, Sep!C16) -> 0 | D16: =SUM(Jul!D16, Aug!D16, Sep!D16) -> 0 | E16: =IF(AND(ISNUMBER(C16),ISNUMBER(D16)), C16-D16, "") -> 0 | F16: =IFERROR(E16/D16, "") | G16: =SUM(Jul!G16, Aug!G16, Sep!G16) -> 0 | H16: =SUM(Jul!H16, Aug!H16, Sep!H16) -> 0 | I16: =IFERROR(H16/G16, "")
... A23: Brooklyn - BA North 4th & Berry | B23: NY | C23: =SUM(Jul!C23, Aug!C23, Sep!C23) -> 7754.1 | D23: =SUM(Jul!D23, Aug!D23, Sep!D23) -> 0 | E23: =IF(AND(ISNUMBER(C23),ISNUMBER(D23)), C23-D23, "") -> 7754.1 | F23: =IFERROR(E23/D23, "") | G23: =SUM(Jul!G23, Aug!G23, Sep!G23) -> 0 | H23: =SUM(Jul!H23, Aug!H23, Sep!H23) -> 7754.1 | I23: =IFERROR(H23/G23, "")
A24: Midlothian - BA Brandermill | B24: VA | C24: =SUM(Jul!#REF!, Jul!C24, Sep!C24) -> #REF! | D24: =SUM(Jul!D24, Aug!D24, Sep!D24) -> 0 | E24: =IF(AND(ISNUMBER(C24),ISNUMBER(D24)), C24-D24, "") | F24: =IFERROR(E24/D24, "") | G24: =SUM(Jul!G24, Aug!G24, Sep!G24) -> 0 | H24: =SUM(Jul!H24, Aug!H24, Sep!H24) -> 4097.6 | I24: =IFERROR(H24/G24, "")
A25: Lexington - BA North Park | B25: KY | C25: =SUM(Jul!C25, Aug!C25, Sep!C25) -> 3171.4 | D25: =SUM(Jul!D25, Aug!D25, Sep!D25) -> 0 | E25: =IF(AND(ISNUMBER(C25),ISNUMBER(D25)), C25-D25, "") -> 3171.4 | F25: =IFERROR(E25/D25, "") | G25: =SUM(Jul!G25, Aug!G25, Sep!G25) -> 0 | H25: =SUM(Jul!H25, Aug!H25, Sep!H25) -> 3171.4 | I25: =IFERROR(H25/G25, "")
A26: Coventry - BA ATM | B26: RI
A27: Woodbridge - BA ATM | B27: VA

Sheet 4th Qtr
A1: {=portfolio} -> CBRE | D1: 4th Quarter Actual v. Expected | G1: 4th Quarter Actual v. Forecasted
A2: Total | C2: =SUM(C4:C86) -> 0 | D2: =SUM(D4:D86) -> 0 | E2: =C2-D2 -> 0 | F2: =IFERROR(E2/D2, 0) -> 0 | G2: =SUM(G4:G86) -> 0 | H2: =C2-G2 -> 0 | I2: =IFERROR(H2/G2, 0) -> 0
A3: Site | B3: State | C3: Actual | D3: Expected | E3: Delta | F3: % | G3: Forecasted | H3: Delta | I3: %
A4: {=Sites[Site]} -> #VALUE! | B4: {=Sites[State]} -> CT | C4: =SUM(Oct!C4, Nov!C4, Dec!C4) -> 0 | D4: =SUM(Oct!D4, Nov!D4, Dec!D4) -> 0 | E4: =IF(AND(ISNUMBER(C4),ISNUMBER(D4)), C4-D4, "") -> 0 | F4: =IFERROR(E4/D4, "") | G4: =SUM(Oct!G4, Nov!G4, Dec!G4) -> 0 | H4: =SUM(Oct!H4, Nov!H4, Dec!H4) -> 0 | I4: =IFERROR(H4/G4, "")
B5: IN | C5: =SUM(Oct!C5, Nov!C5, Dec!C5) -> 0 | D5: =SUM(Oct!D5, Nov!D5, Dec!D5) -> 0 | E5: =IF(AND(ISNUMBER(C5),ISNUMBER(D5)), C5-D5, "") -> 0 | F5: =IFERROR(E5/D5, "") | G5: =SUM(Oct!G5, Nov!G5, Dec!G5) -> 0 | H5: =SUM(Oct!H5, Nov!H5, Dec!H5) -> 0 | I5: =IFERROR(H5/G5, "")
B6: IN | C6: =SUM(Oct!C6, Nov!C6, Dec!C6) -> 0 | D6: =SUM(Oct!D6, Nov!D6, Dec!D6) -> 0 | E6: =IF(AND(ISNUMBER(C6),ISNUMBER(D6)), C6-D6, "") -> 0 | F6: =IFERROR(E6/D6, "") | G6: =SUM(Oct!G6, Nov!G6, Dec!G6) -> 0 | H6: =SUM(Oct!H6, Nov!H6, Dec!H6) -> 0 | I6: =IFERROR(H6/G6, "")
B7: OH | C7: =SUM(Oct!C7, Nov!C7, Dec!C7) -> 0 | D7: =SUM(Oct!D7, Nov!D7, Dec!D7) -> 0 | E7: =IF(AND(ISNUMBER(C7),ISNUMBER(D7)), C7-D7, "") -> 0 | F7: =IFERROR(E7/D7, "") | G7: =SUM(Oct!G7, Nov!G7, Dec!G7) -> 0 | H7: =SUM(Oct!H7, Nov!H7, Dec!H7) -> 0 | I7: =IFERROR(H7/G7, "")
B8: OH | C8: =SUM(Oct!C8, Nov!C8, Dec!C8) -> 0 | D8: =SUM(Oct!D8, Nov!D8, Dec!D8) -> 0 | E8: =IF(AND(ISNUMBER(C8),ISNUMBER(D8)), C8-D8, "") -> 0 | F8: =IFERROR(E8/D8, "") | G8: =SUM(Oct!G8, Nov!G8, Dec!G8) -> 0 | H8: =SUM(Oct!H8, Nov!H8, Dec!H8) -> 0 | I8: =IFERROR(H8/G8, "")
B9: OH | C9: =SUM(Oct!C9, Nov!C9, Dec!C9) -> 0 | D9: =SUM(Oct!D9, Nov!D9, Dec!D9) -> 0 | E9: =IF(AND(ISNUMBER(C9),ISNUMBER(D9)), C9-D9, "") -> 0 | F9: =IFERROR(E9/D9, "") | G9: =SUM(Oct!G9, Nov!G9, Dec!G9) -> 0 | H9: =SUM(Oct!H9, Nov!H9, Dec!H9) -> 0 | I9: =IFERROR(H9/G9, "")
B10: OH | C10: =SUM(Oct!C10, Nov!C10, Dec!C10) -> 0 | D10: =SUM(Oct!D10, Nov!D10, Dec!D10) -> 0 | E10: =IF(AND(ISNUMBER(C10),ISNUMBER(D10)), C10-D10, "") -> 0 | F10: =IFERROR(E10/D10, "") | G10: =SUM(Oct!G10, Nov!G10, Dec!G10) -> 0 | H10: =SUM(Oct!H10, Nov!H10, Dec!H10) -> 0 | I10: =IFERROR(H10/G10, "")
B11: OH | C11: =SUM(Oct!C11, Nov!C11, Dec!C11) -> 0 | D11: =SUM(Oct!D11, Nov!D11, Dec!D11) -> 0 | E11: =IF(AND(ISNUMBER(C11),ISNUMBER(D11)), C11-D11, "") -> 0 | F11: =IFERROR(E11/D11, "") | G11: =SUM(Oct!G11, Nov!G11, Dec!G11) -> 0 | H11: =SUM(Oct!H11, Nov!H11, Dec!H11) -> 0 | I11: =IFERROR(H11/G11, "")
B12: OH | C12: =SUM(Oct!C12, Nov!C12, Dec!C12) -> 0 | D12: =SUM(Oct!D12, Nov!D12, Dec!D12) -> 0 | E12: =IF(AND(ISNUMBER(C12),ISNUMBER(D12)), C12-D12, "") -> 0 | F12: =IFERROR(E12/D12, "") | G12: =SUM(Oct!G12, Nov!G12, Dec!G12) -> 0 | H12: =SUM(Oct!H12, Nov!H12, Dec!H12) -> 0 | I12: =IFERROR(H12/G12, "")
B13: IN | C13: =SUM(Oct!C13, Nov!C13, Dec!C13) -> 0 | D13: =SUM(Oct!D13, Nov!D13, Dec!D13) -> 0 | E13: =IF(AND(ISNUMBER(C13),ISNUMBER(D13)), C13-D13, "") -> 0 | F13: =IFERROR(E13/D13, "") | G13: =SUM(Oct!G13, Nov!G13, Dec!G13) -> 0 | H13: =SUM(Oct!H13, Nov!H13, Dec!H13) -> 0 | I13: =IFERROR(H13/G13, "")
B14: OH | C14: =SUM(Oct!C14, Nov!C14, Dec!C14) -> 0 | D14: =SUM(Oct!D14, Nov!D14, Dec!D14) -> 0 | E14: =IF(AND(ISNUMBER(C14),ISNUMBER(D14)), C14-D14, "") -> 0 | F14: =IFERROR(E14/D14, "") | G14: =SUM(Oct!G14, Nov!G14, Dec!G14) -> 0 | H14: =SUM(Oct!H14, Nov!H14, Dec!H14) -> 0 | I14: =IFERROR(H14/G14, "")
B15: OH | C15: =SUM(Oct!C15, Nov!C15, Dec!C15) -> 0 | D15: =SUM(Oct!D15, Nov!D15, Dec!D15) -> 0 | E15: =IF(AND(ISNUMBER(C15),ISNUMBER(D15)), C15-D15, "") -> 0 | F15: =IFERROR(E15/D15, "") | G15: =SUM(Oct!G15, Nov!G15, Dec!G15) -> 0 | H15: =SUM(Oct!H15, Nov!H15, Dec!H15) -> 0 | I15: =IFERROR(H15/G15, "")
B16: NY | C16: =SUM(Oct!C16, Nov!C16, Dec!C16) -> 0 | D16: =SUM(Oct!D16, Nov!D16, Dec!D16) -> 0 | E16: =IF(AND(ISNUMBER(C16),ISNUMBER(D16)), C16-D16, "") -> 0 | F16: =IFERROR(E16/D16, "") | G16: =SUM(Oct!G16, Nov!G16, Dec!G16) -> 0 | H16: =SUM(Oct!H16, Nov!H16, Dec!H16) -> 0 | I16: =IFERROR(H16/G16, "")
... B24: VA | C24: =SUM(Oct!C24, Nov!C24, Dec!C24) -> 0 | D24: =SUM(Oct!D24, Nov!D24, Dec!D24) -> 0 | E24: =IF(AND(ISNUMBER(C24),ISNUMBER(D24)), C24-D24, "") -> 0 | F24: =IFERROR(E24/D24, "") | G24: =SUM(Oct!G24, Nov!G24, Dec!G24) -> 0 | H24: =SUM(Oct!H24, Nov!H24, Dec!H24) -> 0 | I24: =IFERROR(H24/G24, "")
B25: KY | C25: =SUM(Oct!C25, Nov!C25, Dec!C25) -> 0 | E25: =IF(AND(ISNUMBER(C25),ISNUMBER(D26)), C25-D26, "") -> 0 | F25: =IFERROR(E25/D26, "") | G25: =SUM(Oct!G25, Nov!G25, Dec!G25) -> 0 | H25: =SUM(Oct!H25, Nov!H25, Dec!H25) -> 0 | I25: =IFERROR(H25/G25, "")
A26: RI:Coventry | B26: RI | D26: =SUM(Oct!D25, Nov!D25, Dec!D25) -> 0 | E26: =IF(AND(ISNUMBER(C26),ISNUMBER(D27)), C26-D27, "") | F26: =IFERROR(E26/D27, "") | G26: =SUM(Oct!G26, Nov!G26, Dec!G26) -> 0 | H26: =SUM(Oct!H26, Nov!H26, Dec!H26) -> 0 | I26: =IFERROR(H26/G26, "")
A27: VA:Woodbridge | B27: VA | D27: =SUM(Oct!D26, Nov!D26, Dec!D26) -> 0 | E27: =IF(AND(ISNUMBER(C27),ISNUMBER(D28)), C27-D28, "") | F27: =IFERROR(E27/D28, "") | G27: =SUM(Oct!G27, Nov!G27, Dec!G27) -> 0 | H27: =SUM(Oct!H27, Nov!H27, Dec!H27) -> 0 | I27: =IFERROR(H27/G27, "")

Sheet Jan
A1: {=portfolio} -> CBRE | D1: January Actual v. Expected | G1: January Actual v. Forecasted
A2: Total | C2: =SUM(C4:C85) -> 0 | D2: =SUM(D4:D85) -> 0 | E2: =C2-D2 -> 0 | F2: =IFERROR(E2/D2, 0) -> 0 | G2: =SUM(G4:G85) -> 0 | H2: =C2-G2 -> 0 | I2: =IFERROR(H2/G2, 0) -> 0 | J2: =IF(AND(TODAY()>DATE(2024, 1, 1), COUNTA(Sites[Site])<>(COUNT(C:C)-1)), "Some sites are missing actual data; if new sites were added, make sure they are aligned correctly (including prior months!)", "") -> Some sites are missing actual data; if new sites were added, make sure they are aligned correctly (including prior months!)
A3: Site | B3: State | C3: Actual | D3: Expected | E3: Delta | F3: % | G3: Forecasted | H3: Delta | I3: % | J3: Notes | K3: Service Requests
A4: {=Sites[Site]} -> East Hartford - BA | B4: {=Sites[State]} -> CT | E4: =IF(AND(ISNUMBER(C4),ISNUMBER(D4)), C4-D4, "") | F4: =IFERROR(E4/D4, "") | H4: =IF(AND(ISNUMBER(C4),ISNUMBER(G4)), C4-G4, "") | I4: =IFERROR(H4/G4, "")
A5: Indianapolis - BA Speedway | B5: IN | E5: =IF(AND(ISNUMBER(C5),ISNUMBER(D5)), C5-D5, "") | F5: =IFERROR(E5/D5, "") | H5: =IF(AND(ISNUMBER(C5),ISNUMBER(G5)), C5-G5, "") | I5: =IFERROR(H5/G5, "")
A6: Greenwood - BA | B6: IN | E6: =IF(AND(ISNUMBER(C6),ISNUMBER(D6)), C6-D6, "") | F6: =IFERROR(E6/D6, "") | H6: =IF(AND(ISNUMBER(C6),ISNUMBER(G6)), C6-G6, "") | I6: =IFERROR(H6/G6, "")
A7: West Chester - BA | B7: OH | E7: =IF(AND(ISNUMBER(C7),ISNUMBER(D7)), C7-D7, "") | F7: =IFERROR(E7/D7, "") | H7: =IF(AND(ISNUMBER(C7),ISNUMBER(G7)), C7-G7, "") | I7: =IFERROR(H7/G7, "")
A8: Cincinnati - BA MLK and Burnet | B8: OH | E8: =IF(AND(ISNUMBER(C8),ISNUMBER(D8)), C8-D8, "") | F8: =IFERROR(E8/D8, "") | H8: =IF(AND(ISNUMBER(C8),ISNUMBER(G8)), C8-G8, "") | I8: =IFERROR(H8/G8, "")
A9: Columbus - BA Harrisburg Pike | B9: OH | E9: =IF(AND(ISNUMBER(C9),ISNUMBER(D9)), C9-D9, "") | F9: =IFERROR(E9/D9, "") | H9: =IF(AND(ISNUMBER(C9),ISNUMBER(G9)), C9-G9, "") | I9: =IFERROR(H9/G9, "")
A10: Cincinnati - BA Hyde Pk Plaza | B10: OH | E10: =IF(AND(ISNUMBER(C10),ISNUMBER(D10)), C10-D10, "") | F10: =IFERROR(E10/D10, "") | H10: =IF(AND(ISNUMBER(C10),ISNUMBER(G10)), C10-G10, "") | I10: =IFERROR(H10/G10, "")
A11: Cleveland - BA Carnegie & 79th | B11: OH | E11: =IF(AND(ISNUMBER(C11),ISNUMBER(D11)), C11-D11, "") | F11: =IFERROR(E11/D11, "") | H11: =IF(AND(ISNUMBER(C11),ISNUMBER(G11)), C11-G11, "") | I11: =IFERROR(H11/G11, "")
A12: Cincinnati - BA Sharonville | B12: OH | E12: =IF(AND(ISNUMBER(C12),ISNUMBER(D12)), C12-D12, "") | F12: =IFERROR(E12/D12, "") | H12: =IF(AND(ISNUMBER(C12),ISNUMBER(G12)), C12-G12, "") | I12: =IFERROR(H12/G12, "")
A13: Zionsville - BA | B13: IN | E13: =IF(AND(ISNUMBER(C13),ISNUMBER(D13)), C13-D13, "") | F13: =IFERROR(E13/D13, "") | H13: =IF(AND(ISNUMBER(C13),ISNUMBER(G13)), C13-G13, "") | I13: =IFERROR(H13/G13, "")
A14: Columbus - BA Eastgate | B14: OH | E14: =IF(AND(ISNUMBER(C14),ISNUMBER(D14)), C14-D14, "") | F14: =IFERROR(E14/D14, "") | H14: =IF(AND(ISNUMBER(C14),ISNUMBER(G14)), C14-G14, "") | I14: =IFERROR(H14/G14, "")
A15: Columbus - BA Eastmoor | B15: OH | E15: =IF(AND(ISNUMBER(C15),ISNUMBER(D15)), C15-D15, "") | F15: =IFERROR(E15/D15, "") | H15: =IF(AND(ISNUMBER(C15),ISNUMBER(G15)), C15-G15, "") | I15: =IFERROR(H15/G15, "")
A16: Brooklyn - BA Canarsie | B16: NY | E16: =IF(AND(ISNUMBER(C16),ISNUMBER(D16)), C16-D16, "") | F16: =IFERROR(E16/D16, "") | H16: =IF(AND(ISNUMBER(C16),ISNUMBER(G16)), C16-G16, "") | I16: =IFERROR(H16/G16, "")
... A25: Lexington - BA North Park | B25: KY | E25: =IF(AND(ISNUMBER(C25),ISNUMBER(D25)), C25-D25, "") | F25: =IFERROR(E25/D25, "") | H25: =IF(AND(ISNUMBER(C25),ISNUMBER(G25)), C25-G25, "") | I25: =IFERROR(H25/G25, "")
A26: Coventry - BA ATM | B26: RI
A27: Woodbridge - BA ATM | B27: VA

Sheet Feb
A1: {=portfolio} -> CBRE | D1: February Actual v. Expected | G1: February Actual v. Forecasted
A2: Total | C2: =SUM(C4:C86) -> 0 | D2: =SUM(D4:D86) -> 0 | E2: =C2-D2 -> 0 | F2: =IFERROR(E2/D2, 0) -> 0 | G2: =SUM(G4:G86) -> 0 | H2: =C2-G2 -> 0 | I2: =IFERROR(H2/G2, 0) -> 0 | J2: =IF(AND(TODAY()>DATE(2024, 2, 1), COUNTA(Sites[Site])<>(COUNT(C:C)-1)), "Some sites are missing actual data; if new sites were added, make sure they are aligned correctly (including prior months!)", "") -> Some sites are missing actual data; if new sites were added, make sure they are aligned correctly (including prior months!)
A3: Site | B3: State | C3: Actual | D3: Expected | E3: Delta | F3: % | G3: Forecasted | H3: Delta | I3: % | J3: Notes | K3: Service Requests
A4: {=Sites[Site]} -> East Hartford - BA | B4: {=Sites[State]} -> CT | E4: =IF(AND(ISNUMBER(C4),ISNUMBER(D4)), C4-D4, "") | F4: =IFERROR(E4/D4, "") | H4: =IF(AND(ISNUMBER(C4),ISNUMBER(G4)), C4-G4, "") | I4: =IFERROR(H4/G4, "")
A5: Indianapolis - BA Speedway | B5: IN | E5: =IF(AND(ISNUMBER(C5),ISNUMBER(D5)), C5-D5, "") | F5: =IFERROR(E5/D5, "") | H5: =IF(AND(ISNUMBER(C5),ISNUMBER(G5)), C5-G5, "") | I5: =IFERROR(H5/G5, "")
A6: Greenwood - BA | B6: IN | E6: =IF(AND(ISNUMBER(C6),ISNUMBER(D6)), C6-D6, "") | F6: =IFERROR(E6/D6, "") | H6: =IF(AND(ISNUMBER(C6),ISNUMBER(G6)), C6-G6, "") | I6: =IFERROR(H6/G6, "")
A7: West Chester - BA | B7: OH | E7: =IF(AND(ISNUMBER(C7),ISNUMBER(D7)), C7-D7, "") | F7: =IFERROR(E7/D7, "") | H7: =IF(AND(ISNUMBER(C7),ISNUMBER(G7)), C7-G7, "") | I7: =IFERROR(H7/G7, "")
A8: Cincinnati - BA MLK and Burnet | B8: OH | E8: =IF(AND(ISNUMBER(C8),ISNUMBER(D8)), C8-D8, "") | F8: =IFERROR(E8/D8, "") | H8: =IF(AND(ISNUMBER(C8),ISNUMBER(G8)), C8-G8, "") | I8: =IFERROR(H8/G8, "")
A9: Columbus - BA Harrisburg Pike | B9: OH | E9: =IF(AND(ISNUMBER(C9),ISNUMBER(D9)), C9-D9, "") | F9: =IFERROR(E9/D9, "") | H9: =IF(AND(ISNUMBER(C9),ISNUMBER(G9)), C9-G9, "") | I9: =IFERROR(H9/G9, "")
A10: Cincinnati - BA Hyde Pk Plaza | B10: OH | E10: =IF(AND(ISNUMBER(C10),ISNUMBER(D10)), C10-D10, "") | F10: =IFERROR(E10/D10, "") | H10: =IF(AND(ISNUMBER(C10),ISNUMBER(G10)), C10-G10, "") | I10: =IFERROR(H10/G10, "")
A11: Cleveland - BA Carnegie & 79th | B11: OH | E11: =IF(AND(ISNUMBER(C11),ISNUMBER(D11)), C11-D11, "") | F11: =IFERROR(E11/D11, "") | H11: =IF(AND(ISNUMBER(C11),ISNUMBER(G11)), C11-G11, "") | I11: =IFERROR(H11/G11, "")
A12: Cincinnati - BA Sharonville | B12: OH | E12: =IF(AND(ISNUMBER(C12),ISNUMBER(D12)), C12-D12, "") | F12: =IFERROR(E12/D12, "") | H12: =IF(AND(ISNUMBER(C12),ISNUMBER(G12)), C12-G12, "") | I12: =IFERROR(H12/G12, "")
A13: Zionsville - BA | B13: IN | E13: =IF(AND(ISNUMBER(C13),ISNUMBER(D13)), C13-D13, "") | F13: =IFERROR(E13/D13, "") | H13: =IF(AND(ISNUMBER(C13),ISNUMBER(G13)), C13-G13, "") | I13: =IFERROR(H13/G13, "")
A14: Columbus - BA Eastgate | B14: OH | E14: =IF(AND(ISNUMBER(C14),ISNUMBER(D14)), C14-D14, "") | F14: =IFERROR(E14/D14, "") | H14: =IF(AND(ISNUMBER(C14),ISNUMBER(G14)), C14-G14, "") | I14: =IFERROR(H14/G14, "")
A15: Columbus - BA Eastmoor | B15: OH | E15: =IF(AND(ISNUMBER(C15),ISNUMBER(D15)), C15-D15, "") | F15: =IFERROR(E15/D15, "") | H15: =IF(AND(ISNUMBER(C15),ISNUMBER(G15)), C15-G15, "") | I15: =IFERROR(H15/G15, "")
A16: Brooklyn - BA Canarsie | B16: NY | E16: =IF(AND(ISNUMBER(C16),ISNUMBER(D16)), C16-D16, "") | F16: =IFERROR(E16/D16, "") | H16: =IF(AND(ISNUMBER(C16),ISNUMBER(G16)), C16-G16, "") | I16: =IFERROR(H16/G16, "")
... A25: Lexington - BA North Park | B25: KY | E25: =IF(AND(ISNUMBER(C25),ISNUMBER(D25)), C25-D25, "") | F25: =IFERROR(E25/D25, "") | H25: =IF(AND(ISNUMBER(C25),ISNUMBER(G25)), C25-G25, "") | I25: =IFERROR(H25/G25, "")
A26: Coventry - BA ATM | B26: RI
A27: Woodbridge - BA ATM | B27: VA

Sheet Mar
A1: {=portfolio} -> CBRE | D1: March Actual v. Expected | G1: March Actual v. Forecasted
A2: Total | C2: =SUM(C4:C85) -> 0 | D2: =SUM(D4:D85) -> 0 | E2: =C2-D2 -> 0 | F2: =IFERROR(E2/D2, 0) -> 0 | G2: =SUM(G4:G85) -> 0 | H2: =C2-G2 -> 0 | I2: =IFERROR(H2/G2, 0) -> 0 | J2: =IF(AND(TODAY()>DATE(2024, 3, 1), COUNTA(Sites[Site])<>(COUNT(C:C)-1)), "Some sites are missing actual data; if new sites were added, make sure they are aligned correctly (including prior months!)", "") -> Some sites are missing actual data; if new sites were added, make sure they are aligned correctly (including prior months!)
A3: Site | B3: State | C3: Actual | D3: Expected | E3: Delta | F3: % | G3: Forecasted | H3: Delta | I3: % | J3: Notes | K3: Service Requests
A4: {=Sites[Site]} -> East Hartford - BA | B4: {=Sites[State]} -> CT | E4: =IF(AND(ISNUMBER(C4),ISNUMBER(D4)), C4-D4, "") | F4: =IFERROR(E4/D4, "") | H4: =IF(AND(ISNUMBER(C4),ISNUMBER(G4)), C4-G4, "") | I4: =IFERROR(H4/G4, "")
A5: Indianapolis - BA Speedway | B5: IN | E5: =IF(AND(ISNUMBER(C5),ISNUMBER(D5)), C5-D5, "") | F5: =IFERROR(E5/D5, "") | H5: =IF(AND(ISNUMBER(C5),ISNUMBER(G5)), C5-G5, "") | I5: =IFERROR(H5/G5, "")
A6: Greenwood - BA | B6: IN | E6: =IF(AND(ISNUMBER(C6),ISNUMBER(D6)), C6-D6, "") | F6: =IFERROR(E6/D6, "") | H6: =IF(AND(ISNUMBER(C6),ISNUMBER(G6)), C6-G6, "") | I6: =IFERROR(H6/G6, "")
A7: West Chester - BA | B7: OH | E7: =IF(AND(ISNUMBER(C7),ISNUMBER(D7)), C7-D7, "") | F7: =IFERROR(E7/D7, "") | H7: =IF(AND(ISNUMBER(C7),ISNUMBER(G7)), C7-G7, "") | I7: =IFERROR(H7/G7, "")
A8: Cincinnati - BA MLK and Burnet | B8: OH | E8: =IF(AND(ISNUMBER(C8),ISNUMBER(D8)), C8-D8, "") | F8: =IFERROR(E8/D8, "") | H8: =IF(AND(ISNUMBER(C8),ISNUMBER(G8)), C8-G8, "") | I8: =IFERROR(H8/G8, "")
A9: Columbus - BA Harrisburg Pike | B9: OH | E9: =IF(AND(ISNUMBER(C9),ISNUMBER(D9)), C9-D9, "") | F9: =IFERROR(E9/D9, "") | H9: =IF(AND(ISNUMBER(C9),ISNUMBER(G9)), C9-G9, "") | I9: =IFERROR(H9/G9, "")
A10: Cincinnati - BA Hyde Pk Plaza | B10: OH | E10: =IF(AND(ISNUMBER(C10),ISNUMBER(D10)), C10-D10, "") | F10: =IFERROR(E10/D10, "") | H10: =IF(AND(ISNUMBER(C10),ISNUMBER(G10)), C10-G10, "") | I10: =IFERROR(H10/G10, "")
A11: Cleveland - BA Carnegie & 79th | B11: OH | E11: =IF(AND(ISNUMBER(C11),ISNUMBER(D11)), C11-D11, "") | F11: =IFERROR(E11/D11, "") | H11: =IF(AND(ISNUMBER(C11),ISNUMBER(G11)), C11-G11, "") | I11: =IFERROR(H11/G11, "")
A12: Cincinnati - BA Sharonville | B12: OH | E12: =IF(AND(ISNUMBER(C12),ISNUMBER(D12)), C12-D12, "") | F12: =IFERROR(E12/D12, "") | H12: =IF(AND(ISNUMBER(C12),ISNUMBER(G12)), C12-G12, "") | I12: =IFERROR(H12/G12, "")
A13: Zionsville - BA | B13: IN | E13: =IF(AND(ISNUMBER(C13),ISNUMBER(D13)), C13-D13, "") | F13: =IFERROR(E13/D13, "") | H13: =IF(AND(ISNUMBER(C13),ISNUMBER(G13)), C13-G13, "") | I13: =IFERROR(H13/G13, "")
A14: Columbus - BA Eastgate | B14: OH | E14: =IF(AND(ISNUMBER(C14),ISNUMBER(D14)), C14-D14, "") | F14: =IFERROR(E14/D14, "") | H14: =IF(AND(ISNUMBER(C14),ISNUMBER(G14)), C14-G14, "") | I14: =IFERROR(H14/G14, "")
A15: Columbus - BA Eastmoor | B15: OH | E15: =IF(AND(ISNUMBER(C15),ISNUMBER(D15)), C15-D15, "") | F15: =IFERROR(E15/D15, "") | H15: =IF(AND(ISNUMBER(C15),ISNUMBER(G15)), C15-G15, "") | I15: =IFERROR(H15/G15, "")
A16: Brooklyn - BA Canarsie | B16: NY | E16: =IF(AND(ISNUMBER(C16),ISNUMBER(D16)), C16-D16, "") | F16: =IFERROR(E16/D16, "") | H16: =IF(AND(ISNUMBER(C16),ISNUMBER(G16)), C16-G16, "") | I16: =IFERROR(H16/G16, "")
... A25: Lexington - BA North Park | B25: KY | E25: =IF(AND(ISNUMBER(C25),ISNUMBER(D25)), C25-D25, "") | F25: =IFERROR(E25/D25, "") | H25: =IF(AND(ISNUMBER(C25),ISNUMBER(G25)), C25-G25, "") | I25: =IFERROR(H25/G25, "")
A26: Coventry - BA ATM | B26: RI
A27: Woodbridge - BA ATM | B27: VA

Sheet Apr
A1: {=portfolio} -> CBRE | D1: April Actual v. Expected | G1: April Actual v. Forecasted
A2: Total | C2: =SUM(C4:C85) -> 29085.181 | D2: =SUM(D4:D85) -> 0 | E2: =C2-D2 -> 29085.181 | F2: =IFERROR(E2/D2, 0) -> 0 | G2: =SUM(G4:G85) -> 0 | H2: =C2-G2 -> 29085.181 | I2: =IFERROR(H2/G2, 0) -> 0 | J2: =IF(AND(TODAY()>DATE(2024, 4, 1), COUNTA(Sites[Site])<>(COUNT(C:C)-1)), "Some sites are missing actual data; if new sites were added, make sure they are aligned correctly (including prior months!)", "") -> Some sites are missing actual data; if new sites were added, make sure they are aligned correctly (including prior months!)
A3: Site | B3: State | C3: Actual | D3: Expected | E3: Delta | F3: % | G3: Forecasted | H3: Delta | I3: % | J3: Notes | K3: Service Requests
A4: {=Sites[Site]} -> East Hartford - BA | B4: {=Sites[State]} -> CT | C4: 2586.065 | D4: 0 | E4: =IF(AND(ISNUMBER(C4),ISNUMBER(D4)), C4-D4, "") -> 2586.065 | F4: =IFERROR(E4/D4, "") | G4: 0 | H4: =IF(AND(ISNUMBER(C4),ISNUMBER(G4)), C4-G4, "") -> 2586.065 | I4: =IFERROR(H4/G4, "")
A5: Indianapolis - BA Speedway | B5: IN | C5: 1249.07 | D5: 0 | E5: =IF(AND(ISNUMBER(C5),ISNUMBER(D5)), C5-D5, "") -> 1249.07 | F5: =IFERROR(E5/D5, "") | G5: 0 | H5: =IF(AND(ISNUMBER(C5),ISNUMBER(G5)), C5-G5, "") -> 1249.07 | I5: =IFERROR(H5/G5, "")
A6: Greenwood - BA | B6: IN | C6: 661 | D6: 0 | E6: =IF(AND(ISNUMBER(C6),ISNUMBER(D6)), C6-D6, "") -> 661 | F6: =IFERROR(E6/D6, "") | G6: 0 | H6: =IF(AND(ISNUMBER(C6),ISNUMBER(G6)), C6-G6, "") -> 661 | I6: =IFERROR(H6/G6, "")
A7: West Chester - BA | B7: OH | C7: 1473 | D7: 0 | E7: =IF(AND(ISNUMBER(C7),ISNUMBER(D7)), C7-D7, "") -> 1473 | F7: =IFERROR(E7/D7, "") | G7: 0 | H7: =IF(AND(ISNUMBER(C7),ISNUMBER(G7)), C7-G7, "") -> 1473 | I7: =IFERROR(H7/G7, "")
A8: Cincinnati - BA MLK and Burnet | B8: OH | C8: 2200 | D8: 0 | E8: =IF(AND(ISNUMBER(C8),ISNUMBER(D8)), C8-D8, "") -> 2200 | F8: =IFERROR(E8/D8, "") | G8: 0 | H8: =IF(AND(ISNUMBER(C8),ISNUMBER(G8)), C8-G8, "") -> 2200 | I8: =IFERROR(H8/G8, "")
A9: Columbus - BA Harrisburg Pike | B9: OH | C9: 1805 | D9: 0 | E9: =IF(AND(ISNUMBER(C9),ISNUMBER(D9)), C9-D9, "") -> 1805 | F9: =IFERROR(E9/D9, "") | G9: 0 | H9: =IF(AND(ISNUMBER(C9),ISNUMBER(G9)), C9-G9, "") -> 1805 | I9: =IFERROR(H9/G9, "") | J9: 1. Microinverter 202305091322 has never produced from the day site has started | K9: 1. SR088272
A10: Cincinnati - BA Hyde Pk Plaza | B10: OH | C10: 2125 | D10: 0 | E10: =IF(AND(ISNUMBER(C10),ISNUMBER(D10)), C10-D10, "") -> 2125 | F10: =IFERROR(E10/D10, "") | G10: 0 | H10: =IF(AND(ISNUMBER(C10),ISNUMBER(G10)), C10-G10, "") -> 2125 | I10: =IFERROR(H10/G10, "")
A11: Cleveland - BA Carnegie & 79th | B11: OH | C11: 1460.706 | D11: 0 | E11: =IF(AND(ISNUMBER(C11),ISNUMBER(D11)), C11-D11, "") -> 1460.706 | F11: =IFERROR(E11/D11, "") | G11: 0 | H11: =IF(AND(ISNUMBER(C11),ISNUMBER(G11)), C11-G11, "") -> 1460.706 | I11: =IFERROR(H11/G11, "")
A12: Cincinnati - BA Sharonville | B12: OH | C12: 0 | E12: =IF(AND(ISNUMBER(C12),ISNUMBER(D12)), C12-D12, "") | F12: =IFERROR(E12/D12, "") | H12: =IF(AND(ISNUMBER(C12),ISNUMBER(G12)), C12-G12, "") | I12: =IFERROR(H12/G12, "") | J12: 1. Site is offline from 04/01/2024 to 06/27/2024 and again offline from 07/19/2024 (site started communicatimg from April 2024) | K12: 1.SR088245
A13: Zionsville - BA | B13: IN | C13: 2625.993 | D13: 0 | E13: =IF(AND(ISNUMBER(C13),ISNUMBER(D13)), C13-D13, "") -> 2625.993 | F13: =IFERROR(E13/D13, "") | G13: 0 | H13: =IF(AND(ISNUMBER(C13),ISNUMBER(G13)), C13-G13, "") -> 2625.993 | I13: =IFERROR(H13/G13, "")
A14: Columbus - BA Eastgate | B14: OH | C14: 1460 | D14: 0 | E14: =IF(AND(ISNUMBER(C14),ISNUMBER(D14)), C14-D14, "") -> 1460 | F14: =IFERROR(E14/D14, "") | G14: 0 | H14: =IF(AND(ISNUMBER(C14),ISNUMBER(G14)), C14-G14, "") -> 1460 | I14: =IFERROR(H14/G14, "")
A15: Columbus - BA Eastmoor | B15: OH | C15: 2539.623 | D15: 0 | E15: =IF(AND(ISNUMBER(C15),ISNUMBER(D15)), C15-D15, "") -> 2539.623 | F15: =IFERROR(E15/D15, "") | G15: 0 | H15: =IF(AND(ISNUMBER(C15),ISNUMBER(G15)), C15-G15, "") -> 2539.623 | I15: =IFERROR(H15/G15, "") | J15: 1. Microinverter 202305093144 is offline Microinverter 202305091209 has no communication Microinverter 202305089706 has no communication these issues been present since site started communicating | K15: 1. SR086320
A16: Brooklyn - BA Canarsie | B16: NY | C16: 0 | I16: =IFERROR(H16/G16, "")
A17: Pittsburg - BA Fox Chapel | B17: PA | C17: 0 | D17: 0 | E17: =IF(AND(ISNUMBER(C17),ISNUMBER(D17)), C17-D17, "") -> 0 | F17: =IFERROR(E17/D17, "") | G17: 0 | H17: =IF(AND(ISNUMBER(C17),ISNUMBER(G17)), C17-G17, "") -> 0 | I17: =IFERROR(H17/G17, "")
A18: New York - BA Two Bryant Pk | B18: NY | C18: 0 | E18: =IF(AND(ISNUMBER(C18),ISNUMBER(D18)), C18-D18, "") | F18: =IFERROR(E18/D18, "") | H18: =IF(AND(ISNUMBER(C18),ISNUMBER(G18)), C18-G18, "") | I18: =IFERROR(H18/G18, "")
A19: Baltimore - BA Sudbrook Lane | B19: MD | C19: 0 | D19: 0 | E19: =IF(AND(ISNUMBER(C19),ISNUMBER(D19)), C19-D19, "") -> 0 | F19: =IFERROR(E19/D19, "") | G19: 0 | H19: =IF(AND(ISNUMBER(C19),ISNUMBER(G19)), C19-G19, "") -> 0 | I19: =IFERROR(H19/G19, "") | J19: 1. Site gateway not reporting since 08/01/2023 | K19: 1. SR086405
A20: Stamford - BA West Stamford | B20: CT | C20: 1673.382 | D20: 0 | E20: =IF(AND(ISNUMBER(C20),ISNUMBER(D20)), C20-D20, "") -> 1673.382 | F20: =IFERROR(E20/D20, "") | G20: 0 | H20: =IF(AND(ISNUMBER(C20),ISNUMBER(G20)), C20-G20, "") -> 1673.382 | I20: =IFERROR(H20/G20, "")
A21: Hanover - BA Arundel Mills | B21: MD | C21: 2159.108 | D21: 0 | E21: =IF(AND(ISNUMBER(C21),ISNUMBER(D21)), C21-D21, "") -> 2159.108 | F21: =IFERROR(E21/D21, "") | G21: 0 | H21: =IF(AND(ISNUMBER(C21),ISNUMBER(G21)), C21-G21, "") -> 2159.108 | I21: =IFERROR(H21/G21, "")
A22: Glen Cove - BA Forest Ave | B22: NY | C22: 0 | E22: =IF(AND(ISNUMBER(C22),ISNUMBER(D22)), C22-D22, "") | F22: =IFERROR(E22/D22, "") | H22: =IF(AND(ISNUMBER(C22),ISNUMBER(G22)), C22-G22, "") | I22: =IFERROR(H22/G22, "")
A23: Brooklyn - BA North 4th & Berry | B23: NY | C23: 2439.887 | D23: 0 | E23: 2439887 | G23: 0 | H23: 2439887 | I23: =IFERROR(H23/G23, "")
A24: Midlothian - BA Brandermill | B24: VA | C24: 1345.347 | D24: 0 | E24: =IF(AND(ISNUMBER(C24),ISNUMBER(D24)), C24-D24, "") -> 1345.347 | F24: =IFERROR(E24/D24, "") | G24: 0 | H24: =IF(AND(ISNUMBER(C24),ISNUMBER(G24)), C24-G24, "") -> 1345.347 | I24: =IFERROR(H24/G24, "")
A25: Lexington - BA North Park | B25: KY | C25: 1282 | D25: 0 | E25: =IF(AND(ISNUMBER(C25),ISNUMBER(D25)), C25-D25, "") -> 1282 | F25: =IFERROR(E25/D25, "") | G25: 0 | H25: =IF(AND(ISNUMBER(C25),ISNUMBER(G25)), C25-G25, "") -> 1282 | I25: =IFERROR(H25/G25, "") | J25: 1. Microinverter 202305092066 is starting late (between 9:30am to 12pm) for production on multiple days | K25: 1. SR088271
A26: Coventry - BA ATM | B26: RI
A27: Woodbridge - BA ATM | B27: VA

Sheet May
A1: {=portfolio} -> CBRE | D1: May Actual v. Expected | G1: May Actual v. Forecasted
A2: Total | C2: =SUM(C4:C86) -> 33269.074 | D2: =SUM(D4:D86) -> 0 | E2: =C2-D2 -> 33269.074 | F2: =IFERROR(E2/D2, 0) -> 0 | G2: =SUM(G4:G86) -> 0 | H2: =C2-G2 -> 33269.074 | I2: =IFERROR(H2/G2, 0) -> 0 | J2: =IF(AND(TODAY()>DATE(2024, 5, 1), COUNTA(Sites[Site])<>(COUNT(C:C)-1)), "Some sites are missing actual data; if new sites were added, make sure they are aligned correctly (including prior months!)", "") -> Some sites are missing actual data; if new sites were added, make sure they are aligned correctly (including prior months!)
A3: Site | B3: State | C3: Actual | D3: Expected | E3: Delta | F3: % | G3: Forecasted | H3: Delta | I3: % | J3: Notes | K3: Service Requests
A4: {=Sites[Site]} -> East Hartford - BA | B4: {=Sites[State]} -> CT | C4: 3115.716 | D4: 0 | E4: =IF(AND(ISNUMBER(C4),ISNUMBER(D4)), C4-D4, "") -> 3115.716 | F4: =IFERROR(E4/D4, "") | G4: 0 | H4: =IF(AND(ISNUMBER(C4),ISNUMBER(G4)), C4-G4, "") -> 3115.716 | I4: =IFERROR(H4/G4, "")
A5: Indianapolis - BA Speedway | B5: IN | C5: 1447 | D5: 0 | E5: =IF(AND(ISNUMBER(C5),ISNUMBER(D5)), C5-D5, "") -> 1447 | F5: =IFERROR(E5/D5, "") | G5: 0 | H5: =IF(AND(ISNUMBER(C5),ISNUMBER(G5)), C5-G5, "") -> 1447 | I5: =IFERROR(H5/G5, "")
A6: Greenwood - BA | B6: IN | C6: 777 | D6: 0 | E6: =IF(AND(ISNUMBER(C6),ISNUMBER(D6)), C6-D6, "") -> 777 | F6: =IFERROR(E6/D6, "") | G6: 0 | H6: =IF(AND(ISNUMBER(C6),ISNUMBER(G6)), C6-G6, "") -> 777 | I6: =IFERROR(H6/G6, "")
A7: West Chester - BA | B7: OH | C7: 1641 | D7: 0 | E7: =IF(AND(ISNUMBER(C7),ISNUMBER(D7)), C7-D7, "") -> 1641 | F7: =IFERROR(E7/D7, "") | G7: 0 | H7: =IF(AND(ISNUMBER(C7),ISNUMBER(G7)), C7-G7, "") -> 1641 | I7: =IFERROR(H7/G7, "")
A8: Cincinnati - BA MLK and Burnet | B8: OH | C8: 2385 | D8: 0 | E8: =IF(AND(ISNUMBER(C8),ISNUMBER(D8)), C8-D8, "") -> 2385 | F8: =IFERROR(E8/D8, "") | G8: 0 | H8: =IF(AND(ISNUMBER(C8),ISNUMBER(G8)), C8-G8, "") -> 2385 | I8: =IFERROR(H8/G8, "")
A9: Columbus - BA Harrisburg Pike | B9: OH | C9: 1997 | D9: 0 | E9: =IF(AND(ISNUMBER(C9),ISNUMBER(D9)), C9-D9, "") -> 1997 | F9: =IFERROR(E9/D9, "") | G9: 0 | H9: =IF(AND(ISNUMBER(C9),ISNUMBER(G9)), C9-G9, "") -> 1997 | I9: =IFERROR(H9/G9, "") | J9: 1. Microinverter 202305091322 has never produced from the day site has started | K9: 1. SR088272
A10: Cincinnati - BA Hyde Pk Plaza | B10: OH | C10: 2324 | D10: 0 | E10: =IF(AND(ISNUMBER(C10),ISNUMBER(D10)), C10-D10, "") -> 2324 | F10: =IFERROR(E10/D10, "") | G10: 0 | H10: =IF(AND(ISNUMBER(C10),ISNUMBER(G10)), C10-G10, "") -> 2324 | I10: =IFERROR(H10/G10, "")
A11: Cleveland - BA Carnegie & 79th | B11: OH | C11: 1858.76 | D11: 0 | E11: =IF(AND(ISNUMBER(C11),ISNUMBER(D11)), C11-D11, "") -> 1858.76 | F11: =IFERROR(E11/D11, "") | G11: 0 | H11: =IF(AND(ISNUMBER(C11),ISNUMBER(G11)), C11-G11, "") -> 1858.76 | I11: =IFERROR(H11/G11, "")
A12: Cincinnati - BA Sharonville | B12: OH | C12: 0 | E12: =IF(AND(ISNUMBER(C12),ISNUMBER(D12)), C12-D12, "") | F12: =IFERROR(E12/D12, "") | H12: =IF(AND(ISNUMBER(C12),ISNUMBER(G12)), C12-G12, "") | I12: =IFERROR(H12/G12, "") | J12: 1. Site is offline from 04/01/2024 to 06/27/2024 and again offline from 07/19/2024 (site started communicatimg from April 2024) | K12: 1.SR088245
A13: Zionsville - BA | B13: IN | C13: 3194.907 | D13: 0 | E13: =IF(AND(ISNUMBER(C13),ISNUMBER(D13)), C13-D13, "") -> 3194.907 | F13: =IFERROR(E13/D13, "") | G13: 0 | H13: =IF(AND(ISNUMBER(C13),ISNUMBER(G13)), C13-G13, "") -> 3194.907 | I13: =IFERROR(H13/G13, "")
A14: Columbus - BA Eastgate | B14: OH | C14: 1859 | D14: 0 | E14: =IF(AND(ISNUMBER(C14),ISNUMBER(D14)), C14-D14, "") -> 1859 | F14: =IFERROR(E14/D14, "") | G14: 0 | H14: =IF(AND(ISNUMBER(C14),ISNUMBER(G14)), C14-G14, "") -> 1859 | I14: =IFERROR(H14/G14, "")
A15: Columbus - BA Eastmoor | B15: OH | C15: 2798.695 | D15: 0 | E15: =IF(AND(ISNUMBER(C15),ISNUMBER(D15)), C15-D15, "") -> 2798.695 | F15: =IFERROR(E15/D15, "") | G15: 0 | H15: =IF(AND(ISNUMBER(C15),ISNUMBER(G15)), C15-G15, "") -> 2798.695 | I15: =IFERROR(H15/G15, "") | J15: 1. Microinverter 202305093144 is offline Microinverter 202305091209 has no communication Microinverter 202305089706 has no communication these issues been present since site started communicating | K15: 1. SR086320
A16: Brooklyn - BA Canarsie | B16: NY | C16: 0 | I16: =IFERROR(H16/G16, "")
A17: Pittsburg - BA Fox Chapel | B17: PA | C17: 0 | D17: 0 | E17: =IF(AND(ISNUMBER(C17),ISNUMBER(D17)), C17-D17, "") -> 0 | F17: =IFERROR(E17/D17, "") | G17: 0 | H17: =IF(AND(ISNUMBER(C17),ISNUMBER(G17)), C17-G17, "") -> 0 | I17: =IFERROR(H17/G17, "")
A18: New York - BA Two Bryant Pk | B18: NY | C18: 0 | E18: =IF(AND(ISNUMBER(C18),ISNUMBER(D18)), C18-D18, "") | F18: =IFERROR(E18/D18, "") | H18: =IF(AND(ISNUMBER(C18),ISNUMBER(G18)), C18-G18, "") | I18: =IFERROR(H18/G18, "")
A19: Baltimore - BA Sudbrook Lane | B19: MD | C19: 0 | D19: 0 | E19: =IF(AND(ISNUMBER(C19),ISNUMBER(D19)), C19-D19, "") -> 0 | F19: =IFERROR(E19/D19, "") | G19: 0 | H19: =IF(AND(ISNUMBER(C19),ISNUMBER(G19)), C19-G19, "") -> 0 | I19: =IFERROR(H19/G19, "") | J19: 1. Site gateway not reporting since 08/01/2023 | K19: 1. SR086405
A20: Stamford - BA West Stamford | B20: CT | C20: 1975.958 | D20: 0 | E20: =IF(AND(ISNUMBER(C20),ISNUMBER(D20)), C20-D20, "") -> 1975.958 | F20: =IFERROR(E20/D20, "") | G20: 0 | H20: =IF(AND(ISNUMBER(C20),ISNUMBER(G20)), C20-G20, "") -> 1975.958 | I20: =IFERROR(H20/G20, "")
A21: Hanover - BA Arundel Mills | B21: MD | C21: 2269.547 | D21: 0 | E21: =IF(AND(ISNUMBER(C21),ISNUMBER(D21)), C21-D21, "") -> 2269.547 | F21: =IFERROR(E21/D21, "") | G21: 0 | H21: =IF(AND(ISNUMBER(C21),ISNUMBER(G21)), C21-G21, "") -> 2269.547 | I21: =IFERROR(H21/G21, "")
A22: Glen Cove - BA Forest Ave | B22: NY | C22: 0 | E22: =IF(AND(ISNUMBER(C22),ISNUMBER(D22)), C22-D22, "") | F22: =IFERROR(E22/D22, "") | H22: =IF(AND(ISNUMBER(C22),ISNUMBER(G22)), C22-G22, "") | I22: =IFERROR(H22/G22, "")
A23: Brooklyn - BA North 4th & Berry | B23: NY | C23: 2727.1 | D23: 0 | E23: 2727100 | G23: 0 | H23: 2727100 | I23: =IFERROR(H23/G23, "")
A24: Midlothian - BA Brandermill | B24: VA | C24: 1486.391 | D24: 0 | E24: =IF(AND(ISNUMBER(C24),ISNUMBER(D24)), C24-D24, "") -> 1486.391 | F24: =IFERROR(E24/D24, "") | G24: 0 | H24: =IF(AND(ISNUMBER(C24),ISNUMBER(G24)), C24-G24, "") -> 1486.391 | I24: =IFERROR(H24/G24, "")
A25: Lexington - BA North Park | B25: KY | C25: 1412 | D25: 0 | E25: =IF(AND(ISNUMBER(C25),ISNUMBER(D25)), C25-D25, "") -> 1412 | F25: =IFERROR(E25/D25, "") | G25: 0 | H25: =IF(AND(ISNUMBER(C25),ISNUMBER(G25)), C25-G25, "") -> 1412 | I25: =IFERROR(H25/G25, "") | J25: 1. Microinverter 202305092066 is starting late (between 9:30am to 12pm) for production on multiple days | K25: 1. SR088271
A26: Coventry - BA ATM | B26: RI
A27: Woodbridge - BA ATM | B27: VA

Sheet Jun
A1: {=portfolio} -> CBRE | D1: June Actual v. Expected | G1: June Actual v. Forecasted
A2: Total | C2: =SUM(C4:C86) -> 37745.218 | D2: =SUM(D4:D86) -> 0 | E2: =C2-D2 -> 37745.218 | F2: =IFERROR(E2/D2, 0) -> 0 | G2: =SUM(G4:G86) -> 0 | H2: =C2-G2 -> 37745.218 | I2: =IFERROR(H2/G2, 0) -> 0 | J2: =IF(AND(TODAY()>DATE(2024, 6, 1), COUNTA(Sites[Site])<>(COUNT(C:C)-1)), "Some sites are missing actual data; if new sites were added, make sure they are aligned correctly (including prior months!)", "") -> Some sites are missing actual data; if new sites were added, make sure they are aligned correctly (including prior months!)
A3: Site | B3: State | C3: Actual | D3: Expected | E3: Delta | F3: % | G3: Forecasted | H3: Delta | I3: % | J3: Notes | K3: Service Requests
A4: {=Sites[Site]} -> East Hartford - BA | B4: {=Sites[State]} -> CT | C4: 3459.018 | D4: 0 | E4: =IF(AND(ISNUMBER(C4),ISNUMBER(D4)), C4-D4, "") -> 3459.018 | F4: =IFERROR(E4/D4, "") | G4: 0 | H4: =IF(AND(ISNUMBER(C4),ISNUMBER(G4)), C4-G4, "") -> 3459.018 | I4: =IFERROR(H4/G4, "")
A5: Indianapolis - BA Speedway | B5: IN | C5: 1516 | D5: 0 | E5: =IF(AND(ISNUMBER(C5),ISNUMBER(D5)), C5-D5, "") -> 1516 | F5: =IFERROR(E5/D5, "") | G5: 0 | H5: =IF(AND(ISNUMBER(C5),ISNUMBER(G5)), C5-G5, "") -> 1516 | I5: =IFERROR(H5/G5, "")
A6: Greenwood - BA | B6: IN | C6: 819 | D6: 0 | E6: =IF(AND(ISNUMBER(C6),ISNUMBER(D6)), C6-D6, "") -> 819 | F6: =IFERROR(E6/D6, "") | G6: 0 | H6: =IF(AND(ISNUMBER(C6),ISNUMBER(G6)), C6-G6, "") -> 819 | I6: =IFERROR(H6/G6, "")
A7: West Chester - BA | B7: OH | C7: 1733 | D7: 0 | E7: =IF(AND(ISNUMBER(C7),ISNUMBER(D7)), C7-D7, "") -> 1733 | F7: =IFERROR(E7/D7, "") | G7: 0 | H7: =IF(AND(ISNUMBER(C7),ISNUMBER(G7)), C7-G7, "") -> 1733 | I7: =IFERROR(H7/G7, "")
A8: Cincinnati - BA MLK and Burnet | B8: OH | C8: 2570 | D8: 0 | E8: =IF(AND(ISNUMBER(C8),ISNUMBER(D8)), C8-D8, "") -> 2570 | F8: =IFERROR(E8/D8, "") | G8: 0 | H8: =IF(AND(ISNUMBER(C8),ISNUMBER(G8)), C8-G8, "") -> 2570 | I8: =IFERROR(H8/G8, "")
A9: Columbus - BA Harrisburg Pike | B9: OH | C9: 2153 | D9: 0 | E9: =IF(AND(ISNUMBER(C9),ISNUMBER(D9)), C9-D9, "") -> 2153 | F9: =IFERROR(E9/D9, "") | G9: 0 | H9: =IF(AND(ISNUMBER(C9),ISNUMBER(G9)), C9-G9, "") -> 2153 | I9: =IFERROR(H9/G9, "") | J9: 1. Microinverter 202305091322 has never produced from the day site has started | K9: 1. SR088272
A10: Cincinnati - BA Hyde Pk Plaza | B10: OH | C10: 2506 | D10: 0 | E10: =IF(AND(ISNUMBER(C10),ISNUMBER(D10)), C10-D10, "") -> 2506 | F10: =IFERROR(E10/D10, "") | G10: 0 | H10: =IF(AND(ISNUMBER(C10),ISNUMBER(G10)), C10-G10, "") -> 2506 | I10: =IFERROR(H10/G10, "")
A11: Cleveland - BA Carnegie & 79th | B11: OH | C11: 1750.741 | D11: 0 | E11: =IF(AND(ISNUMBER(C11),ISNUMBER(D11)), C11-D11, "") -> 1750.741 | F11: =IFERROR(E11/D11, "") | G11: 0 | H11: =IF(AND(ISNUMBER(C11),ISNUMBER(G11)), C11-G11, "") -> 1750.741 | I11: =IFERROR(H11/G11, "")
A12: Cincinnati - BA Sharonville | B12: OH | C12: 0 | E12: =IF(AND(ISNUMBER(C12),ISNUMBER(D12)), C12-D12, "") | F12: =IFERROR(E12/D12, "") | H12: =IF(AND(ISNUMBER(C12),ISNUMBER(G12)), C12-G12, "") | I12: =IFERROR(H12/G12, "") | J12: 1. Site is offline from 04/01/2024 to 06/27/2024 and again offline from 07/19/2024 (site started communicatimg from April 2024) | K12: 1.SR088245
A13: Zionsville - BA | B13: IN | C13: 3295.861 | D13: 0 | E13: =IF(AND(ISNUMBER(C13),ISNUMBER(D13)), C13-D13, "") -> 3295.861 | F13: =IFERROR(E13/D13, "") | G13: 0 | H13: =IF(AND(ISNUMBER(C13),ISNUMBER(G13)), C13-G13, "") -> 3295.861 | I13: =IFERROR(H13/G13, "")
A14: Columbus - BA Eastgate | B14: OH | C14: 1751 | D14: 0 | E14: =IF(AND(ISNUMBER(C14),ISNUMBER(D14)), C14-D14, "") -> 1751 | F14: =IFERROR(E14/D14, "") | G14: 0 | H14: =IF(AND(ISNUMBER(C14),ISNUMBER(G14)), C14-G14, "") -> 1751 | I14: =IFERROR(H14/G14, "")
A15: Columbus - BA Eastmoor | B15: OH | C15: 2947.242 | D15: 0 | E15: =IF(AND(ISNUMBER(C15),ISNUMBER(D15)), C15-D15, "") -> 2947.242 | F15: =IFERROR(E15/D15, "") | G15: 0 | H15: =IF(AND(ISNUMBER(C15),ISNUMBER(G15)), C15-G15, "") -> 2947.242 | I15: =IFERROR(H15/G15, "") | J15: 1. Microinverter 202305093144 is offline Microinverter 202305091209 has no communication Microinverter 202305089706 has no communication these issues been present since site started communicating | K15: 1. SR086320
A16: Brooklyn - BA Canarsie | B16: NY | C16: 0 | I16: =IFERROR(H16/G16, "")
A17: Pittsburg - BA Fox Chapel | B17: PA | C17: 1570.891 | D17: 0 | E17: =IF(AND(ISNUMBER(C17),ISNUMBER(D17)), C17-D17, "") -> 1570.891 | F17: =IFERROR(E17/D17, "") | G17: 0 | H17: =IF(AND(ISNUMBER(C17),ISNUMBER(G17)), C17-G17, "") -> 1570.891 | I17: =IFERROR(H17/G17, "")
A18: New York - BA Two Bryant Pk | B18: NY | C18: 0 | E18: =IF(AND(ISNUMBER(C18),ISNUMBER(D18)), C18-D18, "") | F18: =IFERROR(E18/D18, "") | H18: =IF(AND(ISNUMBER(C18),ISNUMBER(G18)), C18-G18, "") | I18: =IFERROR(H18/G18, "")
A19: Baltimore - BA Sudbrook Lane | B19: MD | C19: 0 | D19: 0 | E19: =IF(AND(ISNUMBER(C19),ISNUMBER(D19)), C19-D19, "") -> 0 | F19: =IFERROR(E19/D19, "") | G19: 0 | H19: =IF(AND(ISNUMBER(C19),ISNUMBER(G19)), C19-G19, "") -> 0 | I19: =IFERROR(H19/G19, "") | J19: 1. Site gateway not reporting since 08/01/2023 | K19: 1. SR086405
A20: Stamford - BA West Stamford | B20: CT | C20: 2252.659 | D20: 0 | E20: =IF(AND(ISNUMBER(C20),ISNUMBER(D20)), C20-D20, "") -> 2252.659 | F20: =IFERROR(E20/D20, "") | G20: 0 | H20: =IF(AND(ISNUMBER(C20),ISNUMBER(G20)), C20-G20, "") -> 2252.659 | I20: =IFERROR(H20/G20, "")
A21: Hanover - BA Arundel Mills | B21: MD | C21: 2978.542 | D21: 0 | E21: =IF(AND(ISNUMBER(C21),ISNUMBER(D21)), C21-D21, "") -> 2978.542 | F21: =IFERROR(E21/D21, "") | G21: 0 | H21: =IF(AND(ISNUMBER(C21),ISNUMBER(G21)), C21-G21, "") -> 2978.542 | I21: =IFERROR(H21/G21, "")
A22: Glen Cove - BA Forest Ave | B22: NY | C22: 0 | E22: =IF(AND(ISNUMBER(C22),ISNUMBER(D22)), C22-D22, "") | F22: =IFERROR(E22/D22, "") | H22: =IF(AND(ISNUMBER(C22),ISNUMBER(G22)), C22-G22, "") | I22: =IFERROR(H22/G22, "")
