Workbook
Name JanActual: #REF!
Name JanActual2: #REF!
Name JanExpected: #REF!
Name JanExpectedDelta: #REF!
Name JanExpectedPercent: #REF!
Name JanExpPercent: #REF!
Name JanForecasted: #REF!
Name JanForecastedDelta: #REF!
Name JanForecastedPercent: #REF!
Name portfolio: Sites!$B$1:$B$1
Name Year: Sites!#REF!

Sheet Year to Date
A1: {=portfolio} -> MN8 Bond | D1: Year to Date Actual v. Expected | G1: Year to Date Actual v. Forecasted
A2: Total | C2: =SUM(C4:C91) -> 22669434 | D2: =SUM(D4:D91) -> 23974893 | E2: =C2-D2 -> -1305459 | F2: =IFERROR(E2/D2, 0) -> -0.054451088 | G2: =SUM(G4:G91) -> 23315213 | H2: =C2-G2 -> -645779.06 | I2: =IFERROR(H2/G2, 0) -> -0.027697755
A3: Site | B3: State | C3: Actual | D3: Expected | E3: Delta | F3: % | G3: Forecasted | H3: Delta | I3: %
A4: {=Sites[Site]} -> Grafton II | B4: {=Sites[State]} -> MA | C4: =SUM('1st Qtr'!C4, '2nd Qtr'!C4, '3rd Qtr'!C4, '4th Qtr'!C4) -> 3574552.8 | D4: =SUM('1st Qtr'!D4, '2nd Qtr'!D4, '3rd Qtr'!D4, '4th Qtr'!D4) -> 3388155.4 | E4: =IF(AND(ISNUMBER(C4),ISNUMBER(D4)), C4-D4, "") -> 186397.44 | F4: =IFERROR(E4/D4, "") -> 0.055014431 | G4: =SUM('1st Qtr'!G4, '2nd Qtr'!G4, '3rd Qtr'!G4, '4th Qtr'!G4) -> 3736663 | H4: =SUM('1st Qtr'!H4, '2nd Qtr'!H4, '3rd Qtr'!H4, '4th Qtr'!H4) -> -162110.16 | I4: =IFERROR(H4/G4, "") -> -0.043383671
A5: Clara Barton | B5: MA | C5: =SUM('1st Qtr'!C5, '2nd Qtr'!C5, '3rd Qtr'!C5, '4th Qtr'!C5) -> 1312619 | D5: =SUM('1st Qtr'!D5, '2nd Qtr'!D5, '3rd Qtr'!D5, '4th Qtr'!D5) -> 1351311.7 | E5: =IF(AND(ISNUMBER(C5),ISNUMBER(D5)), C5-D5, "") -> -38692.72 | F5: =IFERROR(E5/D5, "") -> -0.028633453 | G5: =SUM('1st Qtr'!G5, '2nd Qtr'!G5, '3rd Qtr'!G5, '4th Qtr'!G5) -> 1369271.3 | H5: =SUM(Jan!H5, Feb!H5, Mar!H5) -> -59831.78 | I5: =IFERROR(H5/G5, "") -> -0.043696075
A6: Fairhaven Solar | B6: MA | C6: =SUM('1st Qtr'!C6, '2nd Qtr'!C6, '3rd Qtr'!C6, '4th Qtr'!C6) -> 1011621 | D6: =SUM('1st Qtr'!D6, '2nd Qtr'!D6, '3rd Qtr'!D6, '4th Qtr'!D6) -> 1067544.6 | E6: =IF(AND(ISNUMBER(C6),ISNUMBER(D6)), C6-D6, "") -> -55923.64 | F6: =IFERROR(E6/D6, "") -> -0.052385294 | G6: =SUM('1st Qtr'!G6, '2nd Qtr'!G6, '3rd Qtr'!G6, '4th Qtr'!G6) -> 1037086.9 | H6: =SUM(Jan!H6, Feb!H6, Mar!H6) -> 1599.61 | I6: =IFERROR(H6/G6, "") -> 0.0015424069
A7: Plympton-1 | B7: MA | C7: =SUM('1st Qtr'!C7, '2nd Qtr'!C7, '3rd Qtr'!C7, '4th Qtr'!C7) -> 1356312 | D7: =SUM('1st Qtr'!D7, '2nd Qtr'!D7, '3rd Qtr'!D7, '4th Qtr'!D7) -> 1400489.3 | E7: =IF(AND(ISNUMBER(C7),ISNUMBER(D7)), C7-D7, "") -> -44177.335 | F7: =IFERROR(E7/D7, "") -> -0.031544214 | G7: =SUM('1st Qtr'!G7, '2nd Qtr'!G7, '3rd Qtr'!G7, '4th Qtr'!G7) -> 1352277.5 | H7: =SUM(Jan!H7, Feb!H7, Mar!H7) -> -21065.93 | I7: =IFERROR(H7/G7, "") -> -0.015578111
A8: French River 2 | B8: MA | C8: =SUM('1st Qtr'!C8, '2nd Qtr'!C8, '3rd Qtr'!C8, '4th Qtr'!C8) -> 1349964.1 | D8: =SUM('1st Qtr'!D8, '2nd Qtr'!D8, '3rd Qtr'!D8, '4th Qtr'!D8) -> 1500426.4 | E8: =IF(AND(ISNUMBER(C8),ISNUMBER(D8)), C8-D8, "") -> -150462.26 | F8: =IFERROR(E8/D8, "") -> -0.10027967 | G8: =SUM('1st Qtr'!G8, '2nd Qtr'!G8, '3rd Qtr'!G8, '4th Qtr'!G8) -> 1356796 | H8: =SUM(Jan!H8, Feb!H8, Mar!H8) -> -12609.89 | I8: =IFERROR(H8/G8, "") -> -0.0092938732
A9: French River 3 | B9: MA | C9: =SUM('1st Qtr'!C9, '2nd Qtr'!C9, '3rd Qtr'!C9, '4th Qtr'!C9) -> 2638740.1 | D9: =SUM('1st Qtr'!D9, '2nd Qtr'!D9, '3rd Qtr'!D9, '4th Qtr'!D9) -> 2702154.4 | E9: =IF(AND(ISNUMBER(C9),ISNUMBER(D9)), C9-D9, "") -> -63414.28 | F9: =IFERROR(E9/D9, "") -> -0.023468045 | G9: =SUM('1st Qtr'!G9, '2nd Qtr'!G9, '3rd Qtr'!G9, '4th Qtr'!G9) -> 2596697.6 | H9: =SUM(Jan!H9, Feb!H9, Mar!H9) -> -5460.98 | I9: =IFERROR(H9/G9, "") -> -0.0021030481
A10: French River 4 | B10: MA | C10: =SUM('1st Qtr'!C10, '2nd Qtr'!C10, '3rd Qtr'!C10, '4th Qtr'!C10) -> 2675501.6 | D10: =SUM('1st Qtr'!D10, '2nd Qtr'!D10, '3rd Qtr'!D10, '4th Qtr'!D10) -> 2907051.5 | E10: =IF(AND(ISNUMBER(C10),ISNUMBER(D10)), C10-D10, "") -> -231549.86 | F10: =IFERROR(E10/D10, "") -> -0.079651105 | G10: =SUM('1st Qtr'!G10, '2nd Qtr'!G10, '3rd Qtr'!G10, '4th Qtr'!G10) -> 2706848.2 | H10: =SUM(Jan!H10, Feb!H10, Mar!H10) -> -37845.964 | I10: =IFERROR(H10/G10, "") -> -0.013981561
A11: French River 5 | B11: MA | C11: =SUM('1st Qtr'!C11, '2nd Qtr'!C11, '3rd Qtr'!C11, '4th Qtr'!C11) -> 2468115.4 | D11: =SUM('1st Qtr'!D11, '2nd Qtr'!D11, '3rd Qtr'!D11, '4th Qtr'!D11) -> 2810949.5 | E11: =IF(AND(ISNUMBER(C11),ISNUMBER(D11)), C11-D11, "") -> -342834.11 | F11: =IFERROR(E11/D11, "") -> -0.12196381 | G11: =SUM('1st Qtr'!G11, '2nd Qtr'!G11, '3rd Qtr'!G11, '4th Qtr'!G11) -> 2657812.2 | H11: =SUM(Jan!H11, Feb!H11, Mar!H11) -> -90612.41 | I11: =IFERROR(H11/G11, "") -> -0.034092857
A12: French River 6 | B12: MA | C12: =SUM('1st Qtr'!C12, '2nd Qtr'!C12, '3rd Qtr'!C12, '4th Qtr'!C12) -> 2401200.4 | D12: =SUM('1st Qtr'!D12, '2nd Qtr'!D12, '3rd Qtr'!D12, '4th Qtr'!D12) -> 2395863.9 | E12: =IF(AND(ISNUMBER(C12),ISNUMBER(D12)), C12-D12, "") -> 5336.53 | F12: =IFERROR(E12/D12, "") -> 0.0022273928 | G12: =SUM('1st Qtr'!G12, '2nd Qtr'!G12, '3rd Qtr'!G12, '4th Qtr'!G12) -> 2549940.3 | H12: =SUM(Jan!H12, Feb!H12, Mar!H12) -> -80776.57 | I12: =IFERROR(H12/G12, "") -> -0.031677828
A13: Stillwater River 1A | B13: MA | C13: =SUM('1st Qtr'!C13, '2nd Qtr'!C13, '3rd Qtr'!C13, '4th Qtr'!C13) -> 673868.03 | D13: =SUM('1st Qtr'!D13, '2nd Qtr'!D13, '3rd Qtr'!D13, '4th Qtr'!D13) -> 679092.8 | E13: =IF(AND(ISNUMBER(C13),ISNUMBER(D13)), C13-D13, "") -> -5224.7725 | F13: =IFERROR(E13/D13, "") -> -0.0076937533 | G13: =SUM('1st Qtr'!G13, '2nd Qtr'!G13, '3rd Qtr'!G13, '4th Qtr'!G13) -> 654316.5 | H13: =SUM(Jan!H13, Feb!H13, Mar!H13) -> 3513.78 | I13: =IFERROR(H13/G13, "") -> 0.0053701534
A14: Stillwater River 2 | B14: MA | C14: =SUM('1st Qtr'!C14, '2nd Qtr'!C14, '3rd Qtr'!C14, '4th Qtr'!C14) -> 1329452.1 | D14: =SUM('1st Qtr'!D14, '2nd Qtr'!D14, '3rd Qtr'!D14, '4th Qtr'!D14) -> 1545079 | E14: =IF(AND(ISNUMBER(C14),ISNUMBER(D14)), C14-D14, "") -> -215626.86 | F14: =IFERROR(E14/D14, "") -> -0.13955718 | G14: =SUM('1st Qtr'!G14, '2nd Qtr'!G14, '3rd Qtr'!G14, '4th Qtr'!G14) -> 1370189.5 | H14: =SUM(Jan!H14, Feb!H14, Mar!H14) -> -38015.67 | I14: =IFERROR(H14/G14, "") -> -0.027744827
A15: Stillwater River 3 | B15: MA | C15: =SUM('1st Qtr'!C15, '2nd Qtr'!C15, '3rd Qtr'!C15, '4th Qtr'!C15) -> 1331818.4 | D15: =SUM('1st Qtr'!D15, '2nd Qtr'!D15, '3rd Qtr'!D15, '4th Qtr'!D15) -> 1493545.2 | E15: =IF(AND(ISNUMBER(C15),ISNUMBER(D15)), C15-D15, "") -> -161726.76 | F15: =IFERROR(E15/D15, "") -> -0.10828381 | G15: =SUM('1st Qtr'!G15, '2nd Qtr'!G15, '3rd Qtr'!G15, '4th Qtr'!G15) -> 1348929.3 | H15: =SUM(Jan!H15, Feb!H15, Mar!H15) -> -30572.69 | I15: =IFERROR(H15/G15, "") -> -0.022664413
A16: Stillwater River 4 | B16: MA | C16: =SUM('1st Qtr'!C16, '2nd Qtr'!C16, '3rd Qtr'!C16, '4th Qtr'!C16) -> 545668.71 | D16: =SUM('1st Qtr'!D16, '2nd Qtr'!D16, '3rd Qtr'!D16, '4th Qtr'!D16) -> 733229.08 | E16: =IF(AND(ISNUMBER(C16),ISNUMBER(D16)), C16-D16, "") -> -187560.37 | F16: =IFERROR(E16/D16, "") -> -0.2558005 | G16: =SUM('1st Qtr'!G16, '2nd Qtr'!G16, '3rd Qtr'!G16, '4th Qtr'!G16) -> 578384.56 | H16: =SUM(Jan!H16, Feb!H16, Mar!H16) -> -28589.282 | I16: =IFERROR(H16/G16, "") -> -0.049429538

Sheet 1st Qtr
A1: {=portfolio} -> MN8 Bond | D1: 1st Quarter Actual v. Expected | G1: 1st Quarter Actual v. Forecasted
A2: Total | C2: =SUM(C4:C91) -> 5209766.2 | D2: =SUM(D4:D91) -> 5804753.6 | E2: =C2-D2 -> -594987.44 | F2: =IFERROR(E2/D2, 0) -> -0.10250003 | G2: =SUM(G4:G91) -> 5740352.1 | H2: =C2-G2 -> -530585.93 | I2: =IFERROR(H2/G2, 0) -> -0.092430904
A3: Site | B3: State | C3: Actual | D3: Expected | E3: Delta | F3: % | G3: Forecasted | H3: Delta | I3: %
A4: {=Sites[Site]} -> Grafton II | B4: {=Sites[State]} -> MA | C4: =SUM(Jan!C4, Feb!C4, Mar!C4) -> 816220.84 | D4: =SUM(Jan!D4, Feb!D4, Mar!D4) -> 874147.8 | E4: =IF(AND(ISNUMBER(C4),ISNUMBER(D4)), C4-D4, "") -> -57926.959 | F4: =IFERROR(E4/D4, "") -> -0.066266779 | G4: =SUM(Jan!G4, Feb!G4, Mar!G4) -> 946539 | H4: =SUM(Jan!H4, Feb!H4, Mar!H4) -> -130318.16 | I4: =IFERROR(H4/G4, "") -> -0.13767859
A5: Clara Barton | B5: MA | C5: =SUM(Jan!C5, Feb!C5, Mar!C5) -> 271482 | D5: =SUM(Jan!D5, Feb!D5, Mar!D5) -> 311908.02 | E5: =IF(AND(ISNUMBER(C5),ISNUMBER(D5)), C5-D5, "") -> -40426.02 | F5: =IFERROR(E5/D5, "") -> -0.12960879 | G5: =SUM(Jan!G5, Feb!G5, Mar!G5) -> 331313.78 | H5: =SUM(Jan!H5, Feb!H5, Mar!H5) -> -59831.78 | I5: =IFERROR(H5/G5, "") -> -0.18058947
A6: Fairhaven Solar | B6: MA | C6: =SUM(Jan!C6, Feb!C6, Mar!C6) -> 250961 | D6: =SUM(Jan!D6, Feb!D6, Mar!D6) -> 274575.84 | E6: =IF(AND(ISNUMBER(C6),ISNUMBER(D6)), C6-D6, "") -> -23614.84 | F6: =IFERROR(E6/D6, "") -> -0.086004799 | G6: =SUM(Jan!G6, Feb!G6, Mar!G6) -> 249361.39 | H6: =SUM(Jan!H6, Feb!H6, Mar!H6) -> 1599.61 | I6: =IFERROR(H6/G6, "") -> 0.0064148263
A7: Plympton-1 | B7: MA | C7: =SUM(Jan!C7, Feb!C7, Mar!C7) -> 297435 | D7: =SUM(Jan!D7, Feb!D7, Mar!D7) -> 317931.23 | E7: =IF(AND(ISNUMBER(C7),ISNUMBER(D7)), C7-D7, "") -> -20496.23 | F7: =IFERROR(E7/D7, "") -> -0.064467495 | G7: =SUM(Jan!G7, Feb!G7, Mar!G7) -> 318500.93 | H7: =SUM(Jan!H7, Feb!H7, Mar!H7) -> -21065.93 | I7: =IFERROR(H7/G7, "") -> -0.066140874
A8: French River 2 | B8: MA | C8: =SUM(Jan!C8, Feb!C8, Mar!C8) -> 320252.11 | D8: =SUM(Jan!D8, Feb!D8, Mar!D8) -> 372903.77 | E8: =IF(AND(ISNUMBER(C8),ISNUMBER(D8)), C8-D8, "") -> -52651.66 | F8: =IFERROR(E8/D8, "") -> -0.14119369 | G8: =SUM(Jan!G8, Feb!G8, Mar!G8) -> 332862 | H8: =SUM(Jan!H8, Feb!H8, Mar!H8) -> -12609.89 | I8: =IFERROR(H8/G8, "") -> -0.037883237
A9: French River 3 | B9: MA | C9: =SUM(Jan!C9, Feb!C9, Mar!C9) -> 632578.12 | D9: =SUM(Jan!D9, Feb!D9, Mar!D9) -> 566613.7 | E9: =IF(AND(ISNUMBER(C9),ISNUMBER(D9)), C9-D9, "") -> 65964.42 | F9: =IFERROR(E9/D9, "") -> 0.11641868 | G9: =SUM(Jan!G9, Feb!G9, Mar!G9) -> 638039.1 | H9: =SUM(Jan!H9, Feb!H9, Mar!H9) -> -5460.98 | I9: =IFERROR(H9/G9, "") -> -0.0085590052
A10: French River 4 | B10: MA | C10: =SUM(Jan!C10, Feb!C10, Mar!C10) -> 627309.64 | D10: =SUM(Jan!D10, Feb!D10, Mar!D10) -> 724748.1 | E10: =IF(AND(ISNUMBER(C10),ISNUMBER(D10)), C10-D10, "") -> -97438.464 | F10: =IFERROR(E10/D10, "") -> -0.13444459 | G10: =SUM(Jan!G10, Feb!G10, Mar!G10) -> 665155.6 | H10: =SUM(Jan!H10, Feb!H10, Mar!H10) -> -37845.964 | I10: =IFERROR(H10/G10, "") -> -0.05689791
A11: French River 5 | B11: MA | C11: =SUM(Jan!C11, Feb!C11, Mar!C11) -> 562261.39 | D11: =SUM(Jan!D11, Feb!D11, Mar!D11) -> 701281.3 | E11: =IF(AND(ISNUMBER(C11),ISNUMBER(D11)), C11-D11, "") -> -139019.91 | F11: =IFERROR(E11/D11, "") -> -0.19823701 | G11: =SUM(Jan!G11, Feb!G11, Mar!G11) -> 652873.8 | H11: =SUM(Jan!H11, Feb!H11, Mar!H11) -> -90612.41 | I11: =IFERROR(H11/G11, "") -> -0.13879008
A12: French River 6 | B12: MA | C12: =SUM(Jan!C12, Feb!C12, Mar!C12) -> 545632.43 | D12: =SUM(Jan!D12, Feb!D12, Mar!D12) -> 605090.4 | E12: =IF(AND(ISNUMBER(C12),ISNUMBER(D12)), C12-D12, "") -> -59457.97 | F12: =IFERROR(E12/D12, "") -> -0.098262954 | G12: =SUM(Jan!G12, Feb!G12, Mar!G12) -> 626409 | H12: =SUM(Jan!H12, Feb!H12, Mar!H12) -> -80776.57 | I12: =IFERROR(H12/G12, "") -> -0.1289518
A13: Stillwater River 1A | B13: MA | C13: =SUM(Jan!C13, Feb!C13, Mar!C13) -> 164251.25 | D13: =SUM(Jan!D13, Feb!D13, Mar!D13) -> 145917.63 | E13: =IF(AND(ISNUMBER(C13),ISNUMBER(D13)), C13-D13, "") -> 18333.62 | F13: =IFERROR(E13/D13, "") -> 0.12564363 | G13: =SUM(Jan!G13, Feb!G13, Mar!G13) -> 160737.47 | H13: =SUM(Jan!H13, Feb!H13, Mar!H13) -> 3513.78 | I13: =IFERROR(H13/G13, "") -> 0.021860366
A14: Stillwater River 2 | B14: MA | C14: =SUM(Jan!C14, Feb!C14, Mar!C14) -> 298612.12 | D14: =SUM(Jan!D14, Feb!D14, Mar!D14) -> 373006.08 | E14: =IF(AND(ISNUMBER(C14),ISNUMBER(D14)), C14-D14, "") -> -74393.96 | F14: =IFERROR(E14/D14, "") -> -0.19944436 | G14: =SUM(Jan!G14, Feb!G14, Mar!G14) -> 336627.79 | H14: =SUM(Jan!H14, Feb!H14, Mar!H14) -> -38015.67 | I14: =IFERROR(H14/G14, "") -> -0.11293087
A15: Stillwater River 3 | B15: MA | C15: =SUM(Jan!C15, Feb!C15, Mar!C15) -> 300820.4 | D15: =SUM(Jan!D15, Feb!D15, Mar!D15) -> 371261.36 | E15: =IF(AND(ISNUMBER(C15),ISNUMBER(D15)), C15-D15, "") -> -70440.96 | F15: =IFERROR(E15/D15, "") -> -0.18973415 | G15: =SUM(Jan!G15, Feb!G15, Mar!G15) -> 331393.09 | H15: =SUM(Jan!H15, Feb!H15, Mar!H15) -> -30572.69 | I15: =IFERROR(H15/G15, "") -> -0.092255062
A16: Stillwater River 4 | B16: MA | C16: =SUM(Jan!C16, Feb!C16, Mar!C16) -> 121949.9 | D16: =SUM(Jan!D16, Feb!D16, Mar!D16) -> 165368.41 | E16: =IF(AND(ISNUMBER(C16),ISNUMBER(D16)), C16-D16, "") -> -43418.511 | F16: =IFERROR(E16/D16, "") -> -0.26255626 | G16: =SUM(Jan!G16, Feb!G16, Mar!G16) -> 150539.18 | H16: =SUM(Jan!H16, Feb!H16, Mar!H16) -> -28589.282 | I16: =IFERROR(H16/G16, "") -> -0.18991256

Sheet 2nd Qtr
A1: {=portfolio} -> MN8 Bond | D1: 2nd Quarter Actual v. Expected | G1: 2nd Quarter Actual v. Forecasted
A2: Total | C2: =SUM(C4:C91) -> 8871453.4 | D2: =SUM(D4:D91) -> 9219914.9 | E2: =C2-D2 -> -348461.43 | F2: =IFERROR(E2/D2, 0) -> -0.03779443 | G2: =SUM(G4:G91) -> 8773584 | H2: =C2-G2 -> 97869.399 | I2: =IFERROR(H2/G2, 0) -> 0.011155008
A3: Site | B3: State | C3: Actual | D3: Expected | E3: Delta | F3: % | G3: Forecasted | H3: Delta | I3: %
A4: {=Sites[Site]} -> Grafton II | B4: {=Sites[State]} -> MA | C4: =SUM(Apr!C4, May!C4, Jun!C4) -> 1401773.8 | D4: =SUM(Apr!D4, May!D4, Jun!D4) -> 1290931.7 | E4: =IF(AND(ISNUMBER(C4),ISNUMBER(D4)), C4-D4, "") -> 110842.11 | F4: =IFERROR(E4/D4, "") -> 0.085862103 | G4: =SUM(Apr!G4+May!G4+Jun!G4) -> 1379105 | H4: =SUM(Apr!H4, May!H4, Jun!H4) -> 22668.81 | I4: =IFERROR(H4/G4, "") -> 0.016437334
A5: Clara Barton | B5: MA | C5: =SUM(Apr!C5, May!C5, Jun!C5) -> 526097 | D5: =SUM(Apr!D5, May!D5, Jun!D5) -> 525286.3 | E5: =IF(AND(ISNUMBER(C5),ISNUMBER(D5)), C5-D5, "") -> 810.7 | F5: =IFERROR(E5/D5, "") -> 0.0015433488 | G5: =SUM(Apr!G5+May!G5+Jun!G5) -> 515243.2 | H5: =SUM(Apr!H5, May!H5, Jun!H5) -> 10853.8 | I5: =IFERROR(H5/G5, "") -> 0.021065392
A6: Fairhaven Solar | B6: MA | C6: =SUM(Apr!C6, May!C6, Jun!C6) -> 384318 | D6: =SUM(Apr!D6, May!D6, Jun!D6) -> 393613.2 | E6: =IF(AND(ISNUMBER(C6),ISNUMBER(D6)), C6-D6, "") -> -9295.2 | F6: =IFERROR(E6/D6, "") -> -0.023615062 | G6: =SUM(Apr!G6+May!G6+Jun!G6) -> 397372.6 | H6: =SUM(Apr!H6, May!H6, Jun!H6) -> -13054.6 | I6: =IFERROR(H6/G6, "") -> -0.03285229
A7: Plympton-1 | B7: MA | C7: =SUM(Apr!C7, May!C7, Jun!C7) -> 543587 | D7: =SUM(Apr!D7, May!D7, Jun!D7) -> 551321.5 | E7: =IF(AND(ISNUMBER(C7),ISNUMBER(D7)), C7-D7, "") -> -7734.5049 | F7: =IFERROR(E7/D7, "") -> -0.014029028 | G7: =SUM(Apr!G7+May!G7+Jun!G7) -> 515104 | H7: =SUM(Apr!H7, May!H7, Jun!H7) -> 28482.995 | I7: =IFERROR(H7/G7, "") -> 0.05529562
A8: French River 2 | B8: MA | C8: =SUM(Apr!C8, May!C8, Jun!C8) -> 521028 | D8: =SUM(Apr!D8, May!D8, Jun!D8) -> 570681.4 | E8: =IF(AND(ISNUMBER(C8),ISNUMBER(D8)), C8-D8, "") -> -49653.4 | F8: =IFERROR(E8/D8, "") -> -0.087007216 | G8: =SUM(Apr!G8+May!G8+Jun!G8) -> 510569 | H8: =SUM(Apr!H8, May!H8, Jun!H8) -> 10459 | I8: =IFERROR(H8/G8, "") -> 0.020484988
A9: French River 3 | B9: MA | C9: =SUM(Apr!C9, May!C9, Jun!C9) -> 1022134 | D9: =SUM(Apr!D9, May!D9, Jun!D9) -> 1083611.1 | E9: =IF(AND(ISNUMBER(C9),ISNUMBER(D9)), C9-D9, "") -> -61477.1 | F9: =IFERROR(E9/D9, "") -> -0.056733546 | G9: =SUM(Apr!G9+May!G9+Jun!G9) -> 977193.1 | H9: =SUM(Apr!H9, May!H9, Jun!H9) -> 44940.9 | I9: =IFERROR(H9/G9, "") -> 0.045989784
A10: French River 4 | B10: MA | C10: =SUM(Apr!C10, May!C10, Jun!C10) -> 1038020 | D10: =SUM(Apr!D10, May!D10, Jun!D10) -> 1106160.3 | E10: =IF(AND(ISNUMBER(C10),ISNUMBER(D10)), C10-D10, "") -> -68140.3 | F10: =IFERROR(E10/D10, "") -> -0.061600746 | G10: =SUM(Apr!G10+May!G10+Jun!G10) -> 1018616.5 | H10: =SUM(Apr!H10, May!H10, Jun!H10) -> 19403.5 | I10: =IFERROR(H10/G10, "") -> 0.019048877
A11: French River 5 | B11: MA | C11: =SUM(Apr!C11, May!C11, Jun!C11) -> 966230 | D11: =SUM(Apr!D11, May!D11, Jun!D11) -> 1071581.8 | E11: =IF(AND(ISNUMBER(C11),ISNUMBER(D11)), C11-D11, "") -> -105351.8 | F11: =IFERROR(E11/D11, "") -> -0.098314286 | G11: =SUM(Apr!G11+May!G11+Jun!G11) -> 1000309.1 | H11: =SUM(Apr!H11, May!H11, Jun!H11) -> -34079.1 | I11: =IFERROR(H11/G11, "") -> -0.034068569
A12: French River 6 | B12: MA | C12: =SUM(Apr!C12, May!C12, Jun!C12) -> 946130 | D12: =SUM(Apr!D12, May!D12, Jun!D12) -> 915179.1 | E12: =IF(AND(ISNUMBER(C12),ISNUMBER(D12)), C12-D12, "") -> 30950.9 | F12: =IFERROR(E12/D12, "") -> 0.0338195 | G12: =SUM(Apr!G12+May!G12+Jun!G12) -> 959687.1 | H12: =SUM(Apr!H12, May!H12, Jun!H12) -> -13557.1 | I12: =IFERROR(H12/G12, "") -> -0.014126584
A13: Stillwater River 1A | B13: MA | C13: =SUM(Apr!C13, May!C13, Jun!C13) -> 257903.53 | D13: =SUM(Apr!D13, May!D13, Jun!D13) -> 269560.55 | E13: =IF(AND(ISNUMBER(C13),ISNUMBER(D13)), C13-D13, "") -> -11657.022 | F13: =IFERROR(E13/D13, "") -> -0.043244542 | G13: =SUM(Apr!G13+May!G13+Jun!G13) -> 246265.04 | H13: =SUM(Apr!H13, May!H13, Jun!H13) -> 11638.488 | I13: =IFERROR(H13/G13, "") -> 0.047260007
A14: Stillwater River 2 | B14: MA | C14: =SUM(Apr!C14, May!C14, Jun!C14) -> 524893 | D14: =SUM(Apr!D14, May!D14, Jun!D14) -> 588997.6 | E14: =IF(AND(ISNUMBER(C14),ISNUMBER(D14)), C14-D14, "") -> -64104.6 | F14: =IFERROR(E14/D14, "") -> -0.10883678 | G14: =SUM(Apr!G14+May!G14+Jun!G14) -> 515679.2 | H14: =SUM(Apr!H14, May!H14, Jun!H14) -> 9213.8 | I14: =IFERROR(H14/G14, "") -> 0.01786731
A15: Stillwater River 3 | B15: MA | C15: =SUM(Apr!C15, May!C15, Jun!C15) -> 522670 | D15: =SUM(Apr!D15, May!D15, Jun!D15) -> 566398.9 | E15: =IF(AND(ISNUMBER(C15),ISNUMBER(D15)), C15-D15, "") -> -43728.9 | F15: =IFERROR(E15/D15, "") -> -0.077205129 | G15: =SUM(Apr!G15+May!G15+Jun!G15) -> 507684.5 | H15: =SUM(Apr!H15, May!H15, Jun!H15) -> 14985.5 | I15: =IFERROR(H15/G15, "") -> 0.029517348
A16: Stillwater River 4 | B16: MA | C16: =SUM(Apr!C16, May!C16, Jun!C16) -> 216669.1 | D16: =SUM(Apr!D16, May!D16, Jun!D16) -> 286591.41 | E16: =IF(AND(ISNUMBER(C16),ISNUMBER(D16)), C16-D16, "") -> -69922.314 | F16: =IFERROR(E16/D16, "") -> -0.2439791 | G16: =SUM(Apr!G16+May!G16+Jun!G16) -> 230755.69 | H16: =SUM(Apr!H16, May!H16, Jun!H16) -> -14086.594 | I16: =IFERROR(H16/G16, "") -> -0.061045488

Sheet 3rd Qtr
A1: {=portfolio} -> MN8 Bond | D1: 3rd Quarter Actual v. Expected | G1: 3rd Quarter Actual v. Forecasted
A2: Total | C2: =SUM(C4:C91) -> 8588214.2 | D2: =SUM(D4:D91) -> 8950224.3 | E2: =C2-D2 -> -362010.12 | F2: =IFERROR(E2/D2, 0) -> -0.040447045 | G2: =SUM(G4:G91) -> 8801276.7 | H2: =C2-G2 -> -213062.52 | I2: =IFERROR(H2/G2, 0) -> -0.024208138
A3: Site | B3: State | C3: Actual | D3: Expected | E3: Delta | F3: % | G3: Forecasted | H3: Delta | I3: %
A4: {=Sites[Site]} -> Grafton II | B4: {=Sites[State]} -> MA | C4: =SUM(Jul!C4, Aug!C4, Sep!C4) -> 1356558.2 | D4: =SUM(Jul!D4, Aug!D4, Sep!D4) -> 1223075.9 | E4: =IF(AND(ISNUMBER(C4),ISNUMBER(D4)), C4-D4, "") -> 133482.29 | F4: =IFERROR(E4/D4, "") -> 0.10913655 | G4: =SUM(Jul!G4,Aug!G4,Sep!G4) -> 1411019 | H4: =SUM(Jul!H4, Aug!H4, Sep!H4) -> -54460.81 | I4: =IFERROR(H4/G4, "") -> -0.038596794
A5: Clara Barton | B5: MA | C5: =SUM(Jul!C5, Aug!C5, Sep!C5) -> 515040 | D5: =SUM(Jul!D5, Aug!D5, Sep!D5) -> 514117.4 | E5: =IF(AND(ISNUMBER(C5),ISNUMBER(D5)), C5-D5, "") -> 922.6 | F5: =IFERROR(E5/D5, "") -> 0.0017945318 | G5: =SUM(Jul!G5,Aug!G5,Sep!G5) -> 522714.3 | H5: =SUM(Jul!H5, Aug!H5, Sep!H5) -> -7674.3 | I5: =IFERROR(H5/G5, "") -> -0.014681634
A6: Fairhaven Solar | B6: MA | C6: =SUM(Jul!C6, Aug!C6, Sep!C6) -> 376342 | D6: =SUM(Jul!D6, Aug!D6, Sep!D6) -> 399355.6 | E6: =IF(AND(ISNUMBER(C6),ISNUMBER(D6)), C6-D6, "") -> -23013.6 | F6: =IFERROR(E6/D6, "") -> -0.057626837 | G6: =SUM(Jul!G6,Aug!G6,Sep!G6) -> 390352.9 | H6: =SUM(Jul!H6, Aug!H6, Sep!H6) -> -14010.9 | I6: =IFERROR(H6/G6, "") -> -0.035892906
A7: Plympton-1 | B7: MA | C7: =SUM(Jul!C7, Aug!C7, Sep!C7) -> 515290 | D7: =SUM(Jul!D7, Aug!D7, Sep!D7) -> 531236.6 | E7: =IF(AND(ISNUMBER(C7),ISNUMBER(D7)), C7-D7, "") -> -15946.6 | F7: =IFERROR(E7/D7, "") -> -0.030017887 | G7: =SUM(Jul!G7,Aug!G7,Sep!G7) -> 518672.6 | H7: =SUM(Jul!H7, Aug!H7, Sep!H7) -> -3382.6 | I7: =IFERROR(H7/G7, "") -> -0.0065216478
A8: French River 2 | B8: MA | C8: =SUM(Jul!C8, Aug!C8, Sep!C8) -> 508684 | D8: =SUM(Jul!D8, Aug!D8, Sep!D8) -> 556841.2 | E8: =IF(AND(ISNUMBER(C8),ISNUMBER(D8)), C8-D8, "") -> -48157.2 | F8: =IFERROR(E8/D8, "") -> -0.086482825 | G8: =SUM(Jul!G8,Aug!G8,Sep!G8) -> 513365 | H8: =SUM(Jul!H8, Aug!H8, Sep!H8) -> -4681 | I8: =IFERROR(H8/G8, "") -> -0.0091182687
A9: French River 3 | B9: MA | C9: =SUM(Jul!C9, Aug!C9, Sep!C9) -> 984028 | D9: =SUM(Jul!D9, Aug!D9, Sep!D9) -> 1051929.6 | E9: =IF(AND(ISNUMBER(C9),ISNUMBER(D9)), C9-D9, "") -> -67901.6 | F9: =IFERROR(E9/D9, "") -> -0.064549567 | G9: =SUM(Jul!G9,Aug!G9,Sep!G9) -> 981465.4 | H9: =SUM(Jul!H9, Aug!H9, Sep!H9) -> 2562.6 | I9: =IFERROR(H9/G9, "") -> 0.0026109937
A10: French River 4 | B10: MA | C10: =SUM(Jul!C10, Aug!C10, Sep!C10) -> 1010172 | D10: =SUM(Jul!D10, Aug!D10, Sep!D10) -> 1076143.1 | E10: =IF(AND(ISNUMBER(C10),ISNUMBER(D10)), C10-D10, "") -> -65971.1 | F10: =IFERROR(E10/D10, "") -> -0.061303278 | G10: =SUM(Jul!G10,Aug!G10,Sep!G10) -> 1023076.1 | H10: =SUM(Jul!H10, Aug!H10, Sep!H10) -> -12904.1 | I10: =IFERROR(H10/G10, "") -> -0.01261304
A11: French River 5 | B11: MA | C11: =SUM(Jul!C11, Aug!C11, Sep!C11) -> 939624 | D11: =SUM(Jul!D11, Aug!D11, Sep!D11) -> 1038086.4 | E11: =IF(AND(ISNUMBER(C11),ISNUMBER(D11)), C11-D11, "") -> -98462.4 | F11: =IFERROR(E11/D11, "") -> -0.094849908 | G11: =SUM(Jul!G11,Aug!G11,Sep!G11) -> 1004629.3 | H11: =SUM(Jul!H11, Aug!H11, Sep!H11) -> -65005.3 | I11: =IFERROR(H11/G11, "") -> -0.064705758
A12: French River 6 | B12: MA | C12: =SUM(Jul!C12, Aug!C12, Sep!C12) -> 909438 | D12: =SUM(Jul!D12, Aug!D12, Sep!D12) -> 875594.4 | E12: =IF(AND(ISNUMBER(C12),ISNUMBER(D12)), C12-D12, "") -> 33843.6 | F12: =IFERROR(E12/D12, "") -> 0.038652143 | G12: =SUM(Jul!G12,Aug!G12,Sep!G12) -> 963844.2 | H12: =SUM(Jul!H12, Aug!H12, Sep!H12) -> -54406.2 | I12: =IFERROR(H12/G12, "") -> -0.05644709
A13: Stillwater River 1A | B13: MA | C13: =SUM(Jul!C13, Aug!C13, Sep!C13) -> 251713.25 | D13: =SUM(Jul!D13, Aug!D13, Sep!D13) -> 263614.62 | E13: =IF(AND(ISNUMBER(C13),ISNUMBER(D13)), C13-D13, "") -> -11901.37 | F13: =IFERROR(E13/D13, "") -> -0.045146851 | G13: =SUM(Jul!G13,Aug!G13,Sep!G13) -> 247313.99 | H13: =SUM(Jul!H13, Aug!H13, Sep!H13) -> 4399.26 | I13: =IFERROR(H13/G13, "") -> 0.017788157
A14: Stillwater River 2 | B14: MA | C14: =SUM(Jul!C14, Aug!C14, Sep!C14) -> 505947 | D14: =SUM(Jul!D14, Aug!D14, Sep!D14) -> 583075.3 | E14: =IF(AND(ISNUMBER(C14),ISNUMBER(D14)), C14-D14, "") -> -77128.3 | F14: =IFERROR(E14/D14, "") -> -0.13227846 | G14: =SUM(Jul!G14,Aug!G14,Sep!G14) -> 517882.5 | H14: =SUM(Jul!H14, Aug!H14, Sep!H14) -> -11935.5 | I14: =IFERROR(H14/G14, "") -> -0.023046734
A15: Stillwater River 3 | B15: MA | C15: =SUM(Jul!C15, Aug!C15, Sep!C15) -> 508328 | D15: =SUM(Jul!D15, Aug!D15, Sep!D15) -> 555884.9 | E15: =IF(AND(ISNUMBER(C15),ISNUMBER(D15)), C15-D15, "") -> -47556.9 | F15: =IFERROR(E15/D15, "") -> -0.085551703 | G15: =SUM(Jul!G15,Aug!G15,Sep!G15) -> 509851.7 | H15: =SUM(Jul!H15, Aug!H15, Sep!H15) -> -1523.7 | I15: =IFERROR(H15/G15, "") -> -0.0029885161
A16: Stillwater River 4 | B16: MA | C16: =SUM(Jul!C16, Aug!C16, Sep!C16) -> 207049.72 | D16: =SUM(Jul!D16, Aug!D16, Sep!D16) -> 281269.26 | E16: =IF(AND(ISNUMBER(C16),ISNUMBER(D16)), C16-D16, "") -> -74219.541 | F16: =IFERROR(E16/D16, "") -> -0.26387363 | G16: =SUM(Jul!G16,Aug!G16,Sep!G16) -> 197089.69 | H16: =SUM(Jul!H16, Aug!H16, Sep!H16) -> 9960.0287 | I16: =IFERROR(H16/G16, "") -> 0.050535514

Sheet 4th Qtr
A1: {=portfolio} -> MN8 Bond | D1: 4th Quarter Actual v. Expected | G1: 4th Quarter Actual v. Forecasted
A2: Total | C2: =SUM(C4:C91) -> 0 | D2: =SUM(D4:D91) -> 0 | E2: =C2-D2 -> 0 | F2: =IFERROR(E2/D2, 0) -> 0 | G2: =SUM(G4:G91) -> 0 | H2: =C2-G2 -> 0 | I2: =IFERROR(H2/G2, 0) -> 0
A3: Site | B3: State | C3: Actual | D3: Expected | E3: Delta | F3: % | G3: Forecasted | H3: Delta | I3: %
A4: {=Sites[Site]} -> Grafton II | B4: {=Sites[State]} -> MA | C4: =SUM(Oct!C4, Nov!C4, Dec!C4) -> 0 | D4: =SUM(Oct!D4, Nov!D4, Dec!D4) -> 0 | E4: =IF(AND(ISNUMBER(C4),ISNUMBER(D4)), C4-D4, "") -> 0 | F4: =IFERROR(E4/D4, "") | H4: =SUM(Oct!H4, Nov!H4, Dec!H4) -> 0 | I4: =IFERROR(H4/G4, "")
A5: Clara Barton | B5: MA | C5: =SUM(Oct!C5, Nov!C5, Dec!C5) -> 0 | D5: =SUM(Oct!D5, Nov!D5, Dec!D5) -> 0 | E5: =IF(AND(ISNUMBER(C5),ISNUMBER(D5)), C5-D5, "") -> 0 | F5: =IFERROR(E5/D5, "") | H5: =SUM(Oct!H5, Nov!H5, Dec!H5) -> 0 | I5: =IFERROR(H5/G5, "")
A6: Fairhaven Solar | B6: MA | C6: =SUM(Oct!C6, Nov!C6, Dec!C6) -> 0 | D6: =SUM(Oct!D6, Nov!D6, Dec!D6) -> 0 | E6: =IF(AND(ISNUMBER(C6),ISNUMBER(D6)), C6-D6, "") -> 0 | F6: =IFERROR(E6/D6, "") | H6: =SUM(Oct!H6, Nov!H6, Dec!H6) -> 0 | I6: =IFERROR(H6/G6, "")
A7: Plympton-1 | B7: MA | C7: =SUM(Oct!C7, Nov!C7, Dec!C7) -> 0 | D7: =SUM(Oct!D7, Nov!D7, Dec!D7) -> 0 | E7: =IF(AND(ISNUMBER(C7),ISNUMBER(D7)), C7-D7, "") -> 0 | F7: =IFERROR(E7/D7, "") | H7: =SUM(Oct!H7, Nov!H7, Dec!H7) -> 0 | I7: =IFERROR(H7/G7, "")
A8: French River 2 | B8: MA | C8: =SUM(Oct!C8, Nov!C8, Dec!C8) -> 0 | D8: =SUM(Oct!D8, Nov!D8, Dec!D8) -> 0 | E8: =IF(AND(ISNUMBER(C8),ISNUMBER(D8)), C8-D8, "") -> 0 | F8: =IFERROR(E8/D8, "") | H8: =SUM(Oct!H8, Nov!H8, Dec!H8) -> 0 | I8: =IFERROR(H8/G8, "")
A9: French River 3 | B9: MA | C9: =SUM(Oct!C9, Nov!C9, Dec!C9) -> 0 | D9: =SUM(Oct!D9, Nov!D9, Dec!D9) -> 0 | E9: =IF(AND(ISNUMBER(C9),ISNUMBER(D9)), C9-D9, "") -> 0 | F9: =IFERROR(E9/D9, "") | H9: =SUM(Oct!H9, Nov!H9, Dec!H9) -> 0 | I9: =IFERROR(H9/G9, "")
A10: French River 4 | B10: MA | C10: =SUM(Oct!C10, Nov!C10, Dec!C10) -> 0 | D10: =SUM(Oct!D10, Nov!D10, Dec!D10) -> 0 | E10: =IF(AND(ISNUMBER(C10),ISNUMBER(D10)), C10-D10, "") -> 0 | F10: =IFERROR(E10/D10, "") | H10: =SUM(Oct!H10, Nov!H10, Dec!H10) -> 0 | I10: =IFERROR(H10/G10, "")
A11: French River 5 | B11: MA | C11: =SUM(Oct!C11, Nov!C11, Dec!C11) -> 0 | D11: =SUM(Oct!D11, Nov!D11, Dec!D11) -> 0 | E11: =IF(AND(ISNUMBER(C11),ISNUMBER(D11)), C11-D11, "") -> 0 | F11: =IFERROR(E11/D11, "") | H11: =SUM(Oct!H11, Nov!H11, Dec!H11) -> 0 | I11: =IFERROR(H11/G11, "")
A12: French River 6 | B12: MA | C12: =SUM(Oct!C12, Nov!C12, Dec!C12) -> 0 | D12: =SUM(Oct!D12, Nov!D12, Dec!D12) -> 0 | E12: =IF(AND(ISNUMBER(C12),ISNUMBER(D12)), C12-D12, "") -> 0 | F12: =IFERROR(E12/D12, "") | H12: =SUM(Oct!H12, Nov!H12, Dec!H12) -> 0 | I12: =IFERROR(H12/G12, "")
A13: Stillwater River 1A | B13: MA | C13: =SUM(Oct!C13, Nov!C13, Dec!C13) -> 0 | D13: =SUM(Oct!D13, Nov!D13, Dec!D13) -> 0 | E13: =IF(AND(ISNUMBER(C13),ISNUMBER(D13)), C13-D13, "") -> 0 | F13: =IFERROR(E13/D13, "") | H13: =SUM(Oct!H13, Nov!H13, Dec!H13) -> 0 | I13: =IFERROR(H13/G13, "")
A14: Stillwater River 2 | B14: MA | C14: =SUM(Oct!C14, Nov!C14, Dec!C14) -> 0 | D14: =SUM(Oct!D14, Nov!D14, Dec!D14) -> 0 | E14: =IF(AND(ISNUMBER(C14),ISNUMBER(D14)), C14-D14, "") -> 0 | F14: =IFERROR(E14/D14, "") | H14: =SUM(Oct!H14, Nov!H14, Dec!H14) -> 0 | I14: =IFERROR(H14/G14, "")
A15: Stillwater River 3 | B15: MA | C15: =SUM(Oct!C15, Nov!C15, Dec!C15) -> 0 | D15: =SUM(Oct!D15, Nov!D15, Dec!D15) -> 0 | E15: =IF(AND(ISNUMBER(C15),ISNUMBER(D15)), C15-D15, "") -> 0 | F15: =IFERROR(E15/D15, "") | H15: =SUM(Oct!H15, Nov!H15, Dec!H15) -> 0 | I15: =IFERROR(H15/G15, "")
A16: Stillwater River 4 | B16: MA | C16: =SUM(Oct!C16, Nov!C16, Dec!C16) -> 0 | D16: =SUM(Oct!D16, Nov!D16, Dec!D16) -> 0 | E16: =IF(AND(ISNUMBER(C16),ISNUMBER(D16)), C16-D16, "") -> 0 | F16: =IFERROR(E16/D16, "") | H16: =SUM(Oct!H16, Nov!H16, Dec!H16) -> 0 | I16: =IFERROR(H16/G16, "")

Sheet Jan
A1: {=portfolio} -> MN8 Bond | D1: January Actual v. Expected | G1: January Actual v. Forecasted
A2: Total | C2: =SUM(C4:C90) -> 777232.61 | D2: =SUM(D4:D90) -> 1271145.1 | E2: =C2-D2 -> -493912.52 | F2: =IFERROR(E2/D2, 0) -> -0.38855714 | G2: =SUM(G4:G90) -> 1396020.5 | H2: =C2-G2 -> -618787.85 | I2: =IFERROR(H2/G2, 0) -> -0.44325127 | J2: =IF(AND(TODAY()>DATE(2024, 1, 1), COUNTA(Sites[Site])<>(COUNT(C:C)-1)), "Some sites are missing actual data; if new sites were added, make sure they are aligned correctly (including prior months!)", "")
A3: Site | B3: State | C3: Actual | D3: Expected | E3: Delta | F3: % | G3: Forecasted | H3: Delta | I3: % | J3: Notes | K3: Service Requests
A4: {=Sites[Site]} -> Grafton II | B4: {=Sites[State]} -> MA | C4: 108788.84 | D4: 176557 | E4: =IF(AND(ISNUMBER(C4),ISNUMBER(D4)), C4-D4, "") -> -67768.159 | F4: =IFERROR(E4/D4, "") -> -0.38383162 | G4: 245116 | H4: =IF(AND(ISNUMBER(C4),ISNUMBER(G4)), C4-G4, "") -> -136327.16 | I4: =IFERROR(H4/G4, "") -> -0.55617405 | J4: 1. Site tripped offline on 01/10 at 13:15 and later back online on 01/11 at 11:45AM. 2. Inverter 5.6B was did not came back online after site re-enerziation 01/11 at and later back online on 01/12 at 09:15AM. 3. Inverters 5.7B, 6.2B, and 6.5B are offline from 01/25 and later 5.7B is back online on 01/30 at 09:00AM | K4: 1. SR080136 2. SR080158 3. SR080474
A5: Clara Barton | B5: MA | C5: 41686.145 | D5: 61398.72 | E5: =IF(AND(ISNUMBER(C5),ISNUMBER(D5)), C5-D5, "") -> -19712.575 | F5: =IFERROR(E5/D5, "") -> -0.32105841 | G5: 84576.48 | H5: =IF(AND(ISNUMBER(C5),ISNUMBER(G5)), C5-G5, "") -> -42890.335 | I5: =IFERROR(H5/G5, "") -> -0.50711895 | J5: 1. Inverter 5.8 has tripped offline on 01/17 at 12:00 and back oline on 01/17 at 15:00. 2. Site tripped offline on 01/26 at 18:45 and back online on 01/27 at 10:45AM | K5: 1. SR080289 2. SR080520
A6: Fairhaven Solar | B6: MA | C6: 55436 | D6: 67352.87 | E6: =IF(AND(ISNUMBER(C6),ISNUMBER(D6)), C6-D6, "") -> -11916.87 | F6: =IFERROR(E6/D6, "") -> -0.17693188 | G6: 63727.01 | H6: =IF(AND(ISNUMBER(C6),ISNUMBER(G6)), C6-G6, "") -> -8291.01 | I6: =IFERROR(H6/G6, "") -> -0.13010198 | J6: 1. Inverter 3 is offline on 01/11 after site is re-energized later back online on 01/11 at 13:30. 2. Inverters 1,4 12, 25, 28, 29 & 49 offline on 01/15 from 07:00AM and later back online on 01/17 at 11:15AM. 3. Site was tripped offline on 01/11 at 07:00 and back online 11:45 | K6: 1. SR080159 2. SR080243 1. SR080152
A7: Plympton-1 | B7: MA | C7: 67619 | D7: 73871.03 | E7: =IF(AND(ISNUMBER(C7),ISNUMBER(D7)), C7-D7, "") -> -6252.03 | F7: =IFERROR(E7/D7, "") -> -0.084634396 | G7: 79420.95 | H7: =IF(AND(ISNUMBER(C7),ISNUMBER(G7)), C7-G7, "") -> -11801.95 | I7: =IFERROR(H7/G7, "") -> -0.14859996
A8: French River 2 | B8: MA | C8: 41541.11 | D8: 80016.27 | E8: =IF(AND(ISNUMBER(C8),ISNUMBER(D8)), C8-D8, "") -> -38475.16 | F8: =IFERROR(E8/D8, "") -> -0.48084171 | G8: 78833 | H8: =IF(AND(ISNUMBER(C8),ISNUMBER(G8)), C8-G8, "") -> -37291.89 | I8: =IFERROR(H8/G8, "") -> -0.47304923 | J8: 01. Site was tripped offline on 01/26 at 18:00 and back online at 01/27 at 8:00 AM. | K8: 1. SR080519
A9: French River 3 | B9: MA | C9: 86149.12 | D9: 150506.8 | E9: =IF(AND(ISNUMBER(C9),ISNUMBER(D9)), C9-D9, "") -> -64357.68 | F9: =IFERROR(E9/D9, "") -> -0.42760646 | G9: 151308.7 | H9: =IF(AND(ISNUMBER(C9),ISNUMBER(G9)), C9-G9, "") -> -65159.58 | I9: =IFERROR(H9/G9, "") -> -0.43064001 | J9: 01. Site was tripped offline on 01/26 at 18:00 and back online at 01/27 at 8:00 AM. | K9: 1. SR080519
A10: French River 4 | B10: MA | C10: 85549.466 | D10: 154184.8 | E10: =IF(AND(ISNUMBER(C10),ISNUMBER(D10)), C10-D10, "") -> -68635.334 | F10: =IFERROR(E10/D10, "") -> -0.4451498 | G10: 157760 | H10: =IF(AND(ISNUMBER(C10),ISNUMBER(G10)), C10-G10, "") -> -72210.534 | I10: =IFERROR(H10/G10, "") -> -0.45772397 | J10: 01. Site was tripped offline on 01/26 at 18:00 and back online at 01/27 at 8:00 AM. | K10: 1. SR080519
A11: French River 5 | B11: MA | C11: 83292.5 | D11: 147678.6 | E11: =IF(AND(ISNUMBER(C11),ISNUMBER(D11)), C11-D11, "") -> -64386.1 | F11: =IFERROR(E11/D11, "") -> -0.43598802 | G11: 154754.9 | H11: =IF(AND(ISNUMBER(C11),ISNUMBER(G11)), C11-G11, "") -> -71462.4 | I11: =IFERROR(H11/G11, "") -> -0.46177795 | J11: 1. Inverter 62 is offline on 01/14 and later back online on 01/15 2. Site was tripped offline on 01/26 at 18:00 and back online at 01/27 at 8:00 AM. | K11: 1. SR080199 2. SR080519
A12: French River 6 | B12: MA | C12: 78703 | D12: 125159 | E12: =IF(AND(ISNUMBER(C12),ISNUMBER(D12)), C12-D12, "") -> -46456 | F12: =IFERROR(E12/D12, "") -> -0.37117586 | G12: 148483.1 | H12: =IF(AND(ISNUMBER(C12),ISNUMBER(G12)), C12-G12, "") -> -69780.1 | I12: =IFERROR(H12/G12, "") -> -0.46995315 | J12: 1. Inverter 41B is offline on 01/13 and later back online 01/14. 2. Inverter 62B is offline on 01/14 and later back online on 01/15. 3. Inverters 60 and 62 are tripped offline on 01/22 at 14:00, later 62B is back online on 01/23 at 07:00AM and 60B have multiple tripping events. 4. Site was tripped offline on 01/26 at 18:00 and back online at 01/27 at 8:00 AM. | K12: 1. SR080195 2. SR080198 3. SR080402 4. SR080519
A13: Stillwater River 1A | B13: MA | C13: 21302 | D13: 36938.76 | E13: =IF(AND(ISNUMBER(C13),ISNUMBER(D13)), C13-D13, "") -> -15636.76 | F13: =IFERROR(E13/D13, "") -> -0.42331578 | G13: 38086.07 | H13: =IF(AND(ISNUMBER(C13),ISNUMBER(G13)), C13-G13, "") -> -16784.07 | I13: =IFERROR(H13/G13, "") -> -0.44068789 | J13: 01. Site was tripped offline on 01/26 at 18:00 and back online at 01/27 at 8:00 AM. | K13: 1. SR080519
A14: Stillwater River 2 | B14: MA | C14: 44604.12 | D14: 82849.68 | E14: =IF(AND(ISNUMBER(C14),ISNUMBER(D14)), C14-D14, "") -> -38245.56 | F14: =IFERROR(E14/D14, "") -> -0.46162592 | G14: 79775.59 | H14: =IF(AND(ISNUMBER(C14),ISNUMBER(G14)), C14-G14, "") -> -35171.47 | I14: =IFERROR(H14/G14, "") -> -0.4408801 | J14: 01. Site was tripped offline on 01/26 at 18:00 and back online at 01/27 at 8:00 AM. | K14: 1. SR080519
A15: Stillwater River 3 | B15: MA | C15: 44552 | D15: 81817.76 | E15: =IF(AND(ISNUMBER(C15),ISNUMBER(D15)), C15-D15, "") -> -37265.76 | F15: =IFERROR(E15/D15, "") -> -0.45547275 | G15: 78530.19 | H15: =IF(AND(ISNUMBER(C15),ISNUMBER(G15)), C15-G15, "") -> -33978.19 | I15: =IFERROR(H15/G15, "") -> -0.43267678 | J15: 01. Site was tripped offline on 01/26 at 18:00 and back online at 01/27 at 8:00 AM. | K15: 1. SR080519
A16: Stillwater River 4 | B16: MA | C16: 18009.312 | D16: 32813.84 | E16: =IF(AND(ISNUMBER(C16),ISNUMBER(D16)), C16-D16, "") -> -14804.527 | F16: =IFERROR(E16/D16, "") -> -0.45116718 | G16: 35648.47 | H16: =IF(AND(ISNUMBER(C16),ISNUMBER(G16)), C16-G16, "") -> -17639.158 | I16: =IFERROR(H16/G16, "") -> -0.49480826 | J16: 01. Site was tripped offline on 01/26 at 18:00 and back online at 01/27 at 8:00 AM. | K16: 1. SR080519

Sheet Feb
A1: {=portfolio} -> MN8 Bond | D1: February Actual v. Expected | G1: February Actual v. Forecasted
A2: Total | C2: =SUM(C4:C91) -> 2159606.9 | D2: =SUM(D4:D91) -> 2449165.7 | E2: =C2-D2 -> -289558.85 | F2: =IFERROR(E2/D2, 0) -> -0.11822755 | G2: =SUM(G4:G91) -> 1818738.4 | H2: =C2-G2 -> 340868.47 | I2: =IFERROR(H2/G2, 0) -> 0.18742028 | J2: =IF(AND(TODAY()>DATE(2024, 2, 1), COUNTA(Sites[Site])<>(COUNT(C:C)-1)), "Some sites are missing actual data; if new sites were added, make sure they are aligned correctly (including prior months!)", "")
A3: Site | B3: State | C3: Actual | D3: Expected | E3: Delta | F3: % | G3: Forecasted | H3: Delta | I3: % | J3: Notes | K3: Service Requests
A4: {=Sites[Site]} -> Grafton II | B4: {=Sites[State]} -> MA | C4: 323940 | D4: 341873.5 | E4: =IF(AND(ISNUMBER(C4),ISNUMBER(D4)), C4-D4, "") -> -17933.5 | F4: =IFERROR(E4/D4, "") -> -0.052456537 | G4: 295886 | H4: =IF(AND(ISNUMBER(C4),ISNUMBER(G4)), C4-G4, "") -> 28054 | I4: =IFERROR(H4/G4, "") -> 0.094813543 | J4: 1. Inverters 5.7B & 6.5B tripped offline due to isolation failures and are detecting ground faults. 2. Inverter 3.2C tripped offline and is reporting a generic "Error" code and back online on 02/20 3. Inverter 9.7B is offline on 02/21 and back online on same day. 4. Inverter 6.4b tripped offline on 02/22 and is reporting a generic inverter Error and back online on same day. | K4: 1. SR081002 2. SR081064 3. SR081151 4. SR081183
A5: Clara Barton | B5: MA | C5: 116495.31 | D5: 126875.4 | E5: =IF(AND(ISNUMBER(C5),ISNUMBER(D5)), C5-D5, "") -> -10380.086 | F5: =IFERROR(E5/D5, "") -> -0.081813229 | G5: 101882.3 | H5: =IF(AND(ISNUMBER(C5),ISNUMBER(G5)), C5-G5, "") -> 14613.014 | I5: =IFERROR(H5/G5, "") -> 0.14343035 | J5: 1. Inverter 2.1 tripped offline at 08:00 on 02/20 and back online at 14:22 on 02/22. Inverter again tripped offline at 08:00 on 02/25, Inverter being RMA'd 2. Site tripped offline at 08:30 on 02/28 and back online at 08:00 on 02/29 | K5: 1. SR081306,SR081139 2. SR081400
A6: Fairhaven Solar | B6: MA | C6: 89525 | D6: 98220.97 | E6: =IF(AND(ISNUMBER(C6),ISNUMBER(D6)), C6-D6, "") -> -8695.97 | F6: =IFERROR(E6/D6, "") -> -0.08853476 | G6: 78120.28 | H6: =IF(AND(ISNUMBER(C6),ISNUMBER(G6)), C6-G6, "") -> 11404.72 | I6: =IFERROR(H6/G6, "") -> 0.14598924 | J6: 1. Inverter 2 tripped offline at 11:30 and back online at 15:45 by remote reset on 02/04 2. Inverter 41 is offline on 02/29 and back online at 08:15 on 03/01 by remote reset | K6: 1. SR080714 2. SR081449
A7: Plympton-1 | B7: MA | C7: 114034 | D7: 124223.6 | E7: =IF(AND(ISNUMBER(C7),ISNUMBER(D7)), C7-D7, "") -> -10189.6 | F7: =IFERROR(E7/D7, "") -> -0.082026282 | G7: 98091.58 | H7: =IF(AND(ISNUMBER(C7),ISNUMBER(G7)), C7-G7, "") -> 15942.42 | I7: =IFERROR(H7/G7, "") -> 0.16252588 | J7: 1. Inverter SA-4 3-D was underperforming 4kW cpmpared to peers and was troubleshooted on 02/21 | K7: 1. SR081140
A8: French River 2 | B8: MA | C8: 132153 | D8: 156172.9 | E8: =IF(AND(ISNUMBER(C8),ISNUMBER(D8)), C8-D8, "") -> -24019.9 | F8: =IFERROR(E8/D8, "") -> -0.15380325 | G8: 106405 | H8: =IF(AND(ISNUMBER(C8),ISNUMBER(G8)), C8-G8, "") -> 25748 | I8: =IFERROR(H8/G8, "") -> 0.24198111
A9: French River 3 | B9: MA | C9: 257405 | D9: 299390.1 | E9: =IF(AND(ISNUMBER(C9),ISNUMBER(D9)), C9-D9, "") -> -41985.1 | F9: =IFERROR(E9/D9, "") -> -0.14023543 | G9: 203894.6 | H9: =IF(AND(ISNUMBER(C9),ISNUMBER(G9)), C9-G9, "") -> 53510.4 | I9: =IFERROR(H9/G9, "") -> 0.26244148 | J9: 1. Inverter 40 is underperforming 3kW compared to peers from 02/20/24 | K9: 1. SR081195
A10: French River 4 | B10: MA | C10: 265549.75 | D10: 304548.2 | E10: =IF(AND(ISNUMBER(C10),ISNUMBER(D10)), C10-D10, "") -> -38998.45 | F10: =IFERROR(E10/D10, "") -> -0.12805346 | G10: 212563.8 | H10: =IF(AND(ISNUMBER(C10),ISNUMBER(G10)), C10-G10, "") -> 52985.95 | I10: =IFERROR(H10/G10, "") -> 0.24927081
A11: French River 5 | B11: MA | C11: 243741 | D11: 295557.5 | E11: =IF(AND(ISNUMBER(C11),ISNUMBER(D11)), C11-D11, "") -> -51816.5 | F11: =IFERROR(E11/D11, "") -> -0.17531783 | G11: 208635.1 | H11: =IF(AND(ISNUMBER(C11),ISNUMBER(G11)), C11-G11, "") -> 35105.9 | I11: =IFERROR(H11/G11, "") -> 0.16826459 | J11: 1. Inverter 39 is offline several times in the month 2. Inverter 158 is offline from 01/28 and relay board was replaced on 02/07 at 15:00 3. Inverter 129 tripped offline at 10:00 on 02/12 and back online at 7:00 on 02/16 4. Inverters 106 and 141 are underperforming 4kW each compared to its peers 5. Inverter 76 was offline on 02/20,02/28 and back online by next day | K11: 1. SR080867,SR080705 2. SR080754 3. SR080950 4. SR081033 5. SR081147
A12: French River 6 | B12: MA | C12: 230604 | D12: 254770 | E12: =IF(AND(ISNUMBER(C12),ISNUMBER(D12)), C12-D12, "") -> -24166 | F12: =IFERROR(E12/D12, "") -> -0.094854182 | G12: 200185.5 | H12: =IF(AND(ISNUMBER(C12),ISNUMBER(G12)), C12-G12, "") -> 30418.5 | I12: =IFERROR(H12/G12, "") -> 0.15195156 | J12: 1. Inverter 62-6B was offline on 02/12 and back online on 02/14 2. Inverter 97-6A was offline from 02/19 and back online on 02/21. Inverter 97 again offline from 02/24 and back online on 02/27 3. Inverter 68-6A is offline the entire month. Inverter being RMA'd 4. Inverter 60-6B is offline the entire month. Inverter being RMA'd | K12: 1. SR080951 2. SR081119 3. SR081135 4. SR078134
A13: Stillwater River 1A | B13: MA | C13: 65138.813 | D13: 63898.28 | E13: =IF(AND(ISNUMBER(C13),ISNUMBER(D13)), C13-D13, "") -> 1240.533 | F13: =IFERROR(E13/D13, "") -> 0.019414185 | G13: 51386.81 | H13: =IF(AND(ISNUMBER(C13),ISNUMBER(G13)), C13-G13, "") -> 13752.003 | I13: =IFERROR(H13/G13, "") -> 0.26761737
A14: Stillwater River 2 | B14: MA | C14: 134132 | D14: 158022.2 | E14: =IF(AND(ISNUMBER(C14),ISNUMBER(D14)), C14-D14, "") -> -23890.2 | F14: =IFERROR(E14/D14, "") -> -0.15118256 | G14: 107616.5 | H14: =IF(AND(ISNUMBER(C14),ISNUMBER(G14)), C14-G14, "") -> 26515.5 | I14: =IFERROR(H14/G14, "") -> 0.2463888
A15: Stillwater River 3 | B15: MA | C15: 134092 | D15: 158570.9 | E15: =IF(AND(ISNUMBER(C15),ISNUMBER(D15)), C15-D15, "") -> -24478.9 | F15: =IFERROR(E15/D15, "") -> -0.15437196 | G15: 105943.3 | H15: =IF(AND(ISNUMBER(C15),ISNUMBER(G15)), C15-G15, "") -> 28148.7 | I15: =IFERROR(H15/G15, "") -> 0.2656959
A16: Stillwater River 4 | B16: MA | C16: 52797 | D16: 67042.18 | E16: =IF(AND(ISNUMBER(C16),ISNUMBER(D16)), C16-D16, "") -> -14245.18 | F16: =IFERROR(E16/D16, "") -> -0.21248086 | G16: 48127.64 | H16: =IF(AND(ISNUMBER(C16),ISNUMBER(G16)), C16-G16, "") -> 4669.36 | I16: =IFERROR(H16/G16, "") -> 0.09702034 | J16: 1. Inverter 20-4A was offline from 01/26 and back online on 02/05. Inverter 20 again 02/28 and back online on 03/01 | K16: 1.SR080709, SR081456

Sheet Mar
A1: {=portfolio} -> MN8 Bond | D1: March Actual v. Expected | G1: March Actual v. Forecasted
A2: Total | C2: =SUM(C4:C91) -> 2272926.7 | D2: =SUM(D4:D91) -> 2084442.8 | E2: =C2-D2 -> 188483.92 | F2: =IFERROR(E2/D2, 0) -> 0.09042413 | G2: =SUM(G4:G91) -> 2525593.3 | H2: =C2-G2 -> -252666.56 | I2: =IFERROR(H2/G2, 0) -> -0.10004246 | J2: =IF(AND(TODAY()>DATE(2024, 3, 1), COUNTA(Sites[Site])<>(COUNT(C:C)-1)), "Some sites are missing actual data; if new sites were added, make sure they are aligned correctly (including prior months!)", "")
A3: Site | B3: State | C3: Actual | D3: Expected | E3: Delta | F3: % | G3: Forecasted | H3: Delta | I3: % | J3: Notes | K3: Service Requests
A4: {=Sites[Site]} -> Grafton II | B4: {=Sites[State]} -> MA | C4: 383492 | D4: 355717.3 | E4: =IF(AND(ISNUMBER(C4),ISNUMBER(D4)), C4-D4, "") -> 27774.7 | F4: =IFERROR(E4/D4, "") -> 0.078080824 | G4: 405537 | H4: =IF(AND(ISNUMBER(C4),ISNUMBER(G4)), C4-G4, "") -> -22045 | I4: =IFERROR(H4/G4, "") -> -0.054360021 | J4: 1. Inverters 5.7B, 6.4B & 6.5B are offline due to Insulation failure on 03/05 and back online on 03/06 and 6.5B again offline on 03/23 and back online at 14:45 on 03/23. 2. Inverters 5.7B, 9.3B are offline today due to insulation failure on 03/23 and inverter 9.3B back online at 16:15 on 03/23 and inverter 5.7B is back online on 03/24. 3. Inverter 5.3B tripped offline on an arc fault at 14:30 on 03/17 and back online at 15:15 and again tripped offline at 15:15 on 03/19 and back online at 16:30 and again tripped offline again at 13:42 on 03/27 and back online at 17:00 on 03/27 and again tripped offline at 14:45 on 03/30 4. Inverters 5.7b 6.4b 6.5b 7.7b 9.3b didn't start for production and reporting "Insulation failure" on 03/28 and back online on 03/29. 5. Inverter 9.7b is offline on 03/01, 03/2, 03/15 & 03/23. Inverter being RMA'd | K4: 1. SR081590 2. SR081590 3. SR081974 4. SR082875 5. SR081151
A5: Clara Barton | B5: MA | C5: 113300.54 | D5: 123633.9 | E5: =IF(AND(ISNUMBER(C5),ISNUMBER(D5)), C5-D5, "") -> -10333.359 | F5: =IFERROR(E5/D5, "") -> -0.083580304 | G5: 144855 | H5: =IF(AND(ISNUMBER(C5),ISNUMBER(G5)), C5-G5, "") -> -31554.459 | I5: =IFERROR(H5/G5, "") -> -0.21783479 | J5: 1. Inverter 2.5 is offline due to 6411 interference device fault from 03/13 2. Inverter 4.6 tripping offline due to DC fault at 10:30 on 03/18 and back online at 15:15 on 03/18 and having several tripping events on multiple days. 3. Inverter 5.7 is offline on an arc fault at 12:00pm from 03/06 4. Inverter 21 is being RMA'd 5. Site tripped offline on 03/02 at 18:30 and back online on 03/03 at 08:00am | K5: 1. SR081993 2. SR081994 3. SR082311 4. SR081306 5. SR081400
A6: Fairhaven Solar | B6: MA | C6: 106000 | D6: 109002 | E6: =IF(AND(ISNUMBER(C6),ISNUMBER(D6)), C6-D6, "") -> -3002 | F6: =IFERROR(E6/D6, "") -> -0.027540779 | G6: 107514.1 | H6: =IF(AND(ISNUMBER(C6),ISNUMBER(G6)), C6-G6, "") -> -1514.1 | I6: =IFERROR(H6/G6, "") -> -0.014082804 | J6: 1. Inverter 2 tripped offline at 10:15 on 03/08 and back online at 11:15 by remote reset on 03/08. | K6: 1. SR081698
A7: Plympton-1 | B7: MA | C7: 115782 | D7: 119836.6 | E7: =IF(AND(ISNUMBER(C7),ISNUMBER(D7)), C7-D7, "") -> -4054.6 | F7: =IFERROR(E7/D7, "") -> -0.033834405 | G7: 140988.4 | H7: =IF(AND(ISNUMBER(C7),ISNUMBER(G7)), C7-G7, "") -> -25206.4 | I7: =IFERROR(H7/G7, "") -> -0.1787835 | J7: 1. Site offline due to utility planned outage from 03/28 at 13:15. 2. Inverter 1-8A was offline from 03/15 t and back online on 03/22 after replacing | K7: 1. SR081605 2. SR081943
A8: French River 2 | B8: MA | C8: 146558 | D8: 136714.6 | E8: =IF(AND(ISNUMBER(C8),ISNUMBER(D8)), C8-D8, "") -> 9843.4 | F8: =IFERROR(E8/D8, "") -> 0.071999625 | G8: 147624 | H8: =IF(AND(ISNUMBER(C8),ISNUMBER(G8)), C8-G8, "") -> -1066 | I8: =IFERROR(H8/G8, "") -> -0.0072210481
A9: French River 3 | B9: MA | C9: 289024 | D9: 116716.8 | E9: =IF(AND(ISNUMBER(C9),ISNUMBER(D9)), C9-D9, "") -> 172307.2 | F9: =IFERROR(E9/D9, "") -> 1.4762845 | G9: 282835.8 | H9: =IF(AND(ISNUMBER(C9),ISNUMBER(G9)), C9-G9, "") -> 6188.2 | I9: =IFERROR(H9/G9, "") -> 0.021879126 | J9: 1. Inverter 115 is offline on 03/17 and back online at 10:00am on 03/17 | K9: 1. SR081964
A10: French River 4 | B10: MA | C10: 276210.42 | D10: 266015.1 | E10: =IF(AND(ISNUMBER(C10),ISNUMBER(D10)), C10-D10, "") -> 10195.32 | F10: =IFERROR(E10/D10, "") -> 0.038326095 | G10: 294831.8 | H10: =IF(AND(ISNUMBER(C10),ISNUMBER(G10)), C10-G10, "") -> -18621.38 | I10: =IFERROR(H10/G10, "") -> -0.063159334 | J10: 1. Site was taken offline by USNE to install new transformer on 03/25between 07:30am to 16:00 | K10: 1. SR081807
A11: French River 5 | B11: MA | C11: 235227.89 | D11: 258045.2 | E11: =IF(AND(ISNUMBER(C11),ISNUMBER(D11)), C11-D11, "") -> -22817.31 | F11: =IFERROR(E11/D11, "") -> -0.088423695 | G11: 289483.8 | H11: =IF(AND(ISNUMBER(C11),ISNUMBER(G11)), C11-G11, "") -> -54255.91 | I11: =IFERROR(H11/G11, "") -> -0.18742296 | J11: 1. Inverter 54 is being RMA'd 2. Inverter 17 tripped offline on 03/22 at 11:45 and back online on 03/23 3. Inverter 76 was offline on 03/03 & 03/18 4. Inverter 39 is offline from 03/01 to 03/06 5. Inverters 106 and 141 are underperforming 4kW each compared to its peers 6. Site is offline at 11:15 on 03/24 and back online at 10:45 on 03/30 a due to utility Planned outage. | K11: 1. SR082907 2. SR082496 3. SR081147 4. SR080867 5. SR081033 6. SR082320
A12: French River 6 | B12: MA | C12: 236325.43 | D12: 225161.4 | E12: =IF(AND(ISNUMBER(C12),ISNUMBER(D12)), C12-D12, "") -> 11164.03 | F12: =IFERROR(E12/D12, "") -> 0.049582344 | G12: 277740.4 | H12: =IF(AND(ISNUMBER(C12),ISNUMBER(G12)), C12-G12, "") -> -41414.97 | I12: =IFERROR(H12/G12, "") -> -0.14911396 | J12: 1. Site is offline at 11:30 on 03/24 and back online at 12:15 on 03/29 a due to utility Planned outage. 2. Inverter 68-6A is offline the entire month. Inverter being RMA'd 3. Inverter 72 & 84 are offline from 03/29 and back online on 04/01 | K12: 1. SR082321 2. SR081135 3. SR082909
A13: Stillwater River 1A | B13: MA | C13: 77810.437 | D13: 45080.59 | E13: =IF(AND(ISNUMBER(C13),ISNUMBER(D13)), C13-D13, "") -> 32729.847 | F13: =IFERROR(E13/D13, "") -> 0.72602969 | G13: 71264.59 | H13: =IF(AND(ISNUMBER(C13),ISNUMBER(G13)), C13-G13, "") -> 6545.847 | I13: =IFERROR(H13/G13, "") -> 0.091852728
A14: Stillwater River 2 | B14: MA | C14: 119876 | D14: 132134.2 | E14: =IF(AND(ISNUMBER(C14),ISNUMBER(D14)), C14-D14, "") -> -12258.2 | F14: =IFERROR(E14/D14, "") -> -0.092770835 | G14: 149235.7 | H14: =IF(AND(ISNUMBER(C14),ISNUMBER(G14)), C14-G14, "") -> -29359.7 | I14: =IFERROR(H14/G14, "") -> -0.19673376 | J14: 1. Site is offline at 11:15 on 03/24 and back online at 11:00 on 03/30 a due to utility Planned outage. | K14: 1. SR082325, SR082326
A15: Stillwater River 3 | B15: MA | C15: 122176.4 | D15: 130872.7 | E15: =IF(AND(ISNUMBER(C15),ISNUMBER(D15)), C15-D15, "") -> -8696.3 | F15: =IFERROR(E15/D15, "") -> -0.066448541 | G15: 146919.6 | H15: =IF(AND(ISNUMBER(C15),ISNUMBER(G15)), C15-G15, "") -> -24743.2 | I15: =IFERROR(H15/G15, "") -> -0.1684132 | J15: 1. Site is offline at 11:15 on 03/24 and back online at 11:00 on 03/30 a due to utility Planned outage. | K15: 1. SR082327
A16: Stillwater River 4 | B16: MA | C16: 51143.586 | D16: 65512.39 | E16: =IF(AND(ISNUMBER(C16),ISNUMBER(D16)), C16-D16, "") -> -14368.804 | F16: =IFERROR(E16/D16, "") -> -0.21932956 | G16: 66763.07 | H16: =IF(AND(ISNUMBER(C16),ISNUMBER(G16)), C16-G16, "") -> -15619.484 | I16: =IFERROR(H16/G16, "") -> -0.23395395 | J16: 1. Site is offline at 11:15 on 03/24 and back online at 10:45 on 03/30 a due to utility Planned outage. | K16: 1. SR082328

Sheet Apr
A1: {=portfolio} -> MN8 Bond | D1: April Actual v. Expected | G1: April Actual v. Forecasted
A2: Total | C2: =SUM(C4:C91) -> 2585724.1 | D2: =SUM(D4:D91) -> 2705253.3 | E2: =C2-D2 -> -119529.2 | F2: =IFERROR(E2/D2, 0) -> -0.044184108 | G2: =SUM(G4:G91) -> 2704748.7 | H2: =C2-G2 -> -119024.64 | I2: =IFERROR(H2/G2, 0) -> -0.044005805 | J2: =IF(AND(TODAY()>DATE(2024, 4, 1), COUNTA(Sites[Site])<>(COUNT(C:C)-1)), "Some sites are missing actual data; if new sites were added, make sure they are aligned correctly (including prior months!)", "")
A3: Site | B3: State | C3: Actual | D3: Expected | E3: Delta | F3: % | G3: Forecasted | H3: Delta | I3: % | J3: Notes | K3: Service Requests
A4: {=Sites[Site]} -> Grafton II | B4: {=Sites[State]} -> MA | C4: 406325.32 | D4: 383163.7 | E4: =IF(AND(ISNUMBER(C4),ISNUMBER(D4)), C4-D4, "") -> 23161.62 | F4: =IFERROR(E4/D4, "") -> 0.060448367 | G4: 444997 | H4: =IF(AND(ISNUMBER(C4),ISNUMBER(G4)), C4-G4, "") -> -38671.68 | I4: =IFERROR(H4/G4, "") -> -0.086903238 | J4: 1. Inverter 5.3B is tripped offline on 03/30 at 14:45 and back online on 04/01 with remote reset at 13:30 and again tripped offline on 14:45 on same day and back online on 9:00am on 04/05 2. Inverters 2.2B, 5.4B, 5.7B and 6.5B are offline and reporting insulation failure on 04/04 and later self resolved on afternoon. 3. Inverter 4.1B is underproducing 9kW compared to its peers from 04/17 to 04/24 | K4: 1. SR081974 2. SR083073 3. SR083728
A5: Clara Barton | B5: MA | C5: 151790 | D5: 150612.3 | E5: =IF(AND(ISNUMBER(C5),ISNUMBER(D5)), C5-D5, "") -> 1177.7 | F5: =IFERROR(E5/D5, "") -> 0.0078194145 | G5: 163762 | H5: =IF(AND(ISNUMBER(C5),ISNUMBER(G5)), C5-G5, "") -> -11972 | I5: =IFERROR(H5/G5, "") -> -0.073106093 | J5: 1. Inverter 8.7 tripped offline on 04/9 at 1:45pm and back online on 04/11 and again offline on 04/12 to 04/17 and again offline on 04/21 and is being RMA'd 2. Inverter 6.7 is offline on 04/04, 04/12, 04/15, 04/17,04/18 and technician has replaced inverter and it is back online on 04/19. 3. Inverter 1.3 is offline on 04/01 and technician powercycled the inverter it is back online on 04/08 at 8:15am. 4. Site tripped offline and reporting A phase Voltages on 04/18 at 16:45 and is back online at 19:00 on same day and again offline with same fault on 04/30 at 5:30am and back online on same day at 8:15am. | K5: 1. SR083611 2. SR083420 3. SR083156 4. SR083608, SR083988
A6: Fairhaven Solar | B6: MA | C6: 104937 | D6: 105598 | E6: =IF(AND(ISNUMBER(C6),ISNUMBER(D6)), C6-D6, "") -> -661 | F6: =IFERROR(E6/D6, "") -> -0.0062595882 | G6: 123663.1 | H6: =IF(AND(ISNUMBER(C6),ISNUMBER(G6)), C6-G6, "") -> -18726.1 | I6: =IFERROR(H6/G6, "") -> -0.15142836 | J6: 1.Site was offline due to utility outage on 04/07 from 12:00 to 15:00. 2. Site was offline due to utility outage from 04/08 at 09:00am to 14:45. 3. Inverter 5 tripped ofline on 04/13 from 11:45 to 15:00. 4. Site tripped offline on 04/16 at 11:45 and back online on 04/19 at 07:00 and again tripped offline on 04/20 from 10:15 to 16:00. 5.Inverter 30 tripped offline on 04/20 at 16:00 and back online on 04/21 at 07:00. | K6: 1.SR083159 2.SR083168 3.SR083385 4.SR083490 5. SR083652
A7: Plympton-1 | B7: MA | C7: 161074 | D7: 160586.2 | E7: =IF(AND(ISNUMBER(C7),ISNUMBER(D7)), C7-D7, "") -> 487.79509 | F7: =IFERROR(E7/D7, "") -> 0.0030375903 | G7: 162902.4 | H7: =IF(AND(ISNUMBER(C7),ISNUMBER(G7)), C7-G7, "") -> -1828.4049 | I7: =IFERROR(H7/G7, "") -> -0.011223929
A8: French River 2 | B8: MA | C8: 152350 | D8: 168447.2 | E8: =IF(AND(ISNUMBER(C8),ISNUMBER(D8)), C8-D8, "") -> -16097.2 | F8: =IFERROR(E8/D8, "") -> -0.095562289 | G8: 154735 | H8: =IF(AND(ISNUMBER(C8),ISNUMBER(G8)), C8-G8, "") -> -2385 | I8: =IFERROR(H8/G8, "") -> -0.015413449 | J8: 1. Site was taken offline on 04/26 at 11:30am and reenergised at 12:30pm | K8: 1. PM2819
A9: French River 3 | B9: MA | C9: 301481 | D9: 320682.3 | E9: =IF(AND(ISNUMBER(C9),ISNUMBER(D9)), C9-D9, "") -> -19201.3 | F9: =IFERROR(E9/D9, "") -> -0.059876395 | G9: 296383.2 | H9: =IF(AND(ISNUMBER(C9),ISNUMBER(G9)), C9-G9, "") -> 5097.8 | I9: =IFERROR(H9/G9, "") -> 0.01720003 | J9: 1. Site was taken offline on 04/26 at 07:00am and reenergised at 08:00am | K9: 1. PM2819
A10: French River 4 | B10: MA | C10: 302821 | D10: 326893.3 | E10: =IF(AND(ISNUMBER(C10),ISNUMBER(D10)), C10-D10, "") -> -24072.3 | F10: =IFERROR(E10/D10, "") -> -0.073639625 | G10: 308948 | H10: =IF(AND(ISNUMBER(C10),ISNUMBER(G10)), C10-G10, "") -> -6127 | I10: =IFERROR(H10/G10, "") -> -0.019831816 | J10: 1. Site was taken offline on 04/26 at 08:30am and reenergised at 10:00am | K10: 1. PM2820
A11: French River 5 | B11: MA | C11: 280833 | D11: 316928.7 | E11: =IF(AND(ISNUMBER(C11),ISNUMBER(D11)), C11-D11, "") -> -36095.7 | F11: =IFERROR(E11/D11, "") -> -0.11389218 | G11: 303377.1 | H11: =IF(AND(ISNUMBER(C11),ISNUMBER(G11)), C11-G11, "") -> -22544.1 | I11: =IFERROR(H11/G11, "") -> -0.074310487 | J11: 1. Inverter 54 is offline from 04/01 to 04/18 2. Inverter 123 is offline from 04/01 to 04/30 3. Inverter 165 is offline from 04/25 | K11: 1. SR082907 2. SR082908 3. SR083837
A12: French River 6 | B12: MA | C12: 276927 | D12: 274522.2 | E12: =IF(AND(ISNUMBER(C12),ISNUMBER(D12)), C12-D12, "") -> 2404.8 | F12: =IFERROR(E12/D12, "") -> 0.0087599473 | G12: 291071.4 | H12: =IF(AND(ISNUMBER(C12),ISNUMBER(G12)), C12-G12, "") -> -14144.4 | I12: =IFERROR(H12/G12, "") -> -0.048594262 | J12: 1. Inverter 10 6A tripped offline on 04/12 at 15:45 and back online on 04/15 at 08:45am 2. Inverter 98 6B was tripped offline on 04/08 at 13:30 and back online on 04/11 at 10:15am 3. Inverter 73 was offline on 04/07, 04/25 and self resolved on next day 4. Inverter 56 was offline on 04/02, 04/16, 04/18, 04/26 and self resolved on next day 5. Inverter 60 is offline for most of the days in month and being RMA'd | K12: 1. SR083386 2. SR083203 3. SR083142 4. SR083028 5. SR078134
A13: Stillwater River 1A | B13: MA | C13: 75569.09 | D13: 79753.7 | E13: =IF(AND(ISNUMBER(C13),ISNUMBER(D13)), C13-D13, "") -> -4184.61 | F13: =IFERROR(E13/D13, "") -> -0.052469164 | G13: 74666.54 | H13: =IF(AND(ISNUMBER(C13),ISNUMBER(G13)), C13-G13, "") -> 902.55 | I13: =IFERROR(H13/G13, "") -> 0.012087744
A14: Stillwater River 2 | B14: MA | C14: 154773 | D14: 170679 | E14: =IF(AND(ISNUMBER(C14),ISNUMBER(D14)), C14-D14, "") -> -15906 | F14: =IFERROR(E14/D14, "") -> -0.093192484 | G14: 156355.5 | H14: =IF(AND(ISNUMBER(C14),ISNUMBER(G14)), C14-G14, "") -> -1582.5 | I14: =IFERROR(H14/G14, "") -> -0.010121166
A15: Stillwater River 3 | B15: MA | C15: 153420 | D15: 166403.6 | E15: =IF(AND(ISNUMBER(C15),ISNUMBER(D15)), C15-D15, "") -> -12983.6 | F15: =IFERROR(E15/D15, "") -> -0.078024754 | G15: 153930.2 | H15: =IF(AND(ISNUMBER(C15),ISNUMBER(G15)), C15-G15, "") -> -510.2 | I15: =IFERROR(H15/G15, "") -> -0.0033144893
A16: Stillwater River 4 | B16: MA | C16: 63423.69 | D16: 80983.1 | E16: =IF(AND(ISNUMBER(C16),ISNUMBER(D16)), C16-D16, "") -> -17559.41 | F16: =IFERROR(E16/D16, "") -> -0.21682808 | G16: 69957.3 | H16: =IF(AND(ISNUMBER(C16),ISNUMBER(G16)), C16-G16, "") -> -6533.61 | I16: =IFERROR(H16/G16, "") -> -0.093394256 | J16: 1. Inverter 20 4A is offline from 04/11 to 04/14 and was offline on 04/05 and back online on 04/06 2. Inverter 14 4A tripped offline on 04/15 at 14:15 | K16: 1. SR083128 2. SR083462

Sheet May
A1: {=portfolio} -> MN8 Bond | D1: May Actual v. Expected | G1: May Actual v. Forecasted
A2: Total | C2: =SUM(C4:C91) -> 2997080.8 | D2: =SUM(D4:D91) -> 3076133.9 | E2: =C2-D2 -> -79053.055 | F2: =IFERROR(E2/D2, 0) -> -0.025698835 | G2: =SUM(G4:G91) -> 3037038.1 | H2: =C2-G2 -> -39957.295 | I2: =IFERROR(H2/G2, 0) -> -0.013156666 | J2: =IF(AND(TODAY()>DATE(2024, 5, 1), COUNTA(Sites[Site])<>(COUNT(C:C)-1)), "Some sites are missing actual data; if new sites were added, make sure they are aligned correctly (including prior months!)", "")
A3: Site | B3: State | C3: Actual | D3: Expected | E3: Delta | F3: % | G3: Forecasted | H3: Delta | I3: % | J3: Notes | K3: Service Requests
A4: {=Sites[Site]} -> Grafton II | B4: {=Sites[State]} -> MA | C4: 482443.68 | D4: 433338.9 | E4: =IF(AND(ISNUMBER(C4),ISNUMBER(D4)), C4-D4, "") -> 49104.78 | F4: =IFERROR(E4/D4, "") -> 0.11331727 | G4: 468050 | H4: =IF(AND(ISNUMBER(C4),ISNUMBER(G4)), C4-G4, "") -> 14393.68 | I4: =IFERROR(H4/G4, "") -> 0.030752441 | J4: 1. Inverters 5.7B & 6.2B are offline between 07:00 to 16:30 on 05/16 2. Inverter 10.2A was offline from 05/24 to 06/02 | K4: 1. SR084771 2. SR085153
A5: Clara Barton | B5: MA | C5: 178515 | D5: 175637.8 | E5: =IF(AND(ISNUMBER(C5),ISNUMBER(D5)), C5-D5, "") -> 2877.2 | F5: =IFERROR(E5/D5, "") -> 0.01638144 | G5: 174462 | H5: =IF(AND(ISNUMBER(C5),ISNUMBER(G5)), C5-G5, "") -> 4053 | I5: =IFERROR(H5/G5, "") -> 0.02323142 | J5: 1. Site was offline on 05/08 between 09:15am to 12:45pm 2. Site tripped offline on 05/27 and back online on 05/28 at 07:00am 3. Inverter 8.7 is offline and being RMA'd 4. Inverter 5.10 offline on from 05/26 and being RMA'd 5. Inverter 5.8 offline from 05/26 and back online on 05/28 6. Inverter 4.1 offline from 05/26 and being RMA'd | K5: 1. SR084424 2. SR085200 3. SR083611 4. SR085080 5. SR084869 6. SR085165
A6: Fairhaven Solar | B6: MA | C6: 135590 | D6: 135996.6 | E6: =IF(AND(ISNUMBER(C6),ISNUMBER(D6)), C6-D6, "") -> -406.6 | F6: =IFERROR(E6/D6, "") -> -0.0029897806 | G6: 136467.3 | H6: =IF(AND(ISNUMBER(C6),ISNUMBER(G6)), C6-G6, "") -> -877.3 | I6: =IFERROR(H6/G6, "") -> -0.0064286463 | J6: 1. Inverter 13 is offline from 05/25 and being RMA'd 2. Inverter 37 is offline on 05/26 & 05/27 3. Inverter 26 is offline from 05/29 4. Inverter 14 was offline from 05/31 | K6: 1. SR085068 2. SR085166 3. SR085290 4. SR085365
A7: Plympton-1 | B7: MA | C7: 180284 | D7: 182321.4 | E7: =IF(AND(ISNUMBER(C7),ISNUMBER(D7)), C7-D7, "") -> -2037.4 | F7: =IFERROR(E7/D7, "") -> -0.011174772 | G7: 176437.3 | H7: =IF(AND(ISNUMBER(C7),ISNUMBER(G7)), C7-G7, "") -> 3846.7 | I7: =IFERROR(H7/G7, "") -> 0.021802079 | J7: 1. Inverter 31C tripped offline at 10:30 on 05/16 and back online at 10:30 on 05/20 | K7: 1. SR084772
A8: French River 2 | B8: MA | C8: 173798 | D8: 189859.6 | E8: =IF(AND(ISNUMBER(C8),ISNUMBER(D8)), C8-D8, "") -> -16061.6 | F8: =IFERROR(E8/D8, "") -> -0.08459725 | G8: 178136 | H8: =IF(AND(ISNUMBER(C8),ISNUMBER(G8)), C8-G8, "") -> -4338 | I8: =IFERROR(H8/G8, "") -> -0.02435218 | J8: 1. Inverters 43,44,45 are underperforming 7 kW each on 05/21 and fuses were closed on 05/22 | K8: 1. SR084968
A9: French River 3 | B9: MA | C9: 342706 | D9: 360003.1 | E9: =IF(AND(ISNUMBER(C9),ISNUMBER(D9)), C9-D9, "") -> -17297.1 | F9: =IFERROR(E9/D9, "") -> -0.048047086 | G9: 340894.3 | H9: =IF(AND(ISNUMBER(C9),ISNUMBER(G9)), C9-G9, "") -> 1811.7 | I9: =IFERROR(H9/G9, "") -> 0.0053145506 | J9: 1. Inverter 40 was underperforming offline from 05/31 2. Inverter 115 was offline throughout the month | K9: 1. SR085387 2. SR083436
A10: French River 4 | B10: MA | C10: 348062 | D10: 367665.5 | E10: =IF(AND(ISNUMBER(C10),ISNUMBER(D10)), C10-D10, "") -> -19603.5 | F10: =IFERROR(E10/D10, "") -> -0.053318846 | G10: 355344.7 | H10: =IF(AND(ISNUMBER(C10),ISNUMBER(G10)), C10-G10, "") -> -7282.7 | I10: =IFERROR(H10/G10, "") -> -0.020494748
