Workbook
Name JanActual: #REF!
Name JanActual2: #REF!
Name JanExpected: #REF!
Name JanExpectedDelta: #REF!
Name JanExpectedPercent: #REF!
Name JanExpPercent: #REF!
Name JanForecasted: #REF!
Name JanForecastedDelta: #REF!
Name JanForecastedPercent: #REF!
Name portfolio: Sites!$B$1:$B$1
Name Year: Sites!#REF!

Sheet Year to Date
A1: {=portfolio} -> Wells Fargo | C1: Year to Date Actual v. Expected | F1: Year to Date Actual v. Forecasted
A2: Total | B2: =SUM(B4:B95) -> 17321723 | C2: =SUM(C4:C94) -> 16765648 | D2: =B2-C2 -> 556075.08 | E2: =IFERROR(D2/C2, 0) -> 0.033167527 | F2: =SUM(F4:F94) -> 18327822 | G2: =B2-F2 -> -1006098.9 | H2: =IFERROR(G2/F2, 0) -> -0.054894623
A3: Site | B3: Actual | C3: Expected | D3: Delta | E3: % | F3: Forecasted | G3: Delta | H3: %
A4: {=_xlfn.UNIQUE(Sites[State])} -> CA | B4: =SUM('1st Qtr'!B4, '2nd Qtr'!B4, '3rd Qtr'!B4, '4th Qtr'!B4) -> 1155268.8 | C4: =SUM('1st Qtr'!C4, '2nd Qtr'!C4, '3rd Qtr'!C4, '4th Qtr'!C4) -> 1038132.4 | D4: =IF(AND(ISNUMBER($B4),ISNUMBER(C4)), $B4-C4, "") -> 117136.38 | E4: =IFERROR(D4/C4, "") -> 0.11283376 | F4: =SUM('1st Qtr'!F4, '2nd Qtr'!F4, '3rd Qtr'!F4, '4th Qtr'!F4) -> 1234377.8 | G4: =IF(AND(ISNUMBER($B4),ISNUMBER(F4)), $B4-F4, "") -> -79108.987 | H4: =IFERROR(G4/F4, "") -> -0.064088149
A5: CO | B5: =SUM('1st Qtr'!B5, '2nd Qtr'!B5, '3rd Qtr'!B5, '4th Qtr'!B5) -> 226625.61 | C5: =SUM('1st Qtr'!C5, '2nd Qtr'!C5, '3rd Qtr'!C5, '4th Qtr'!C5) -> 0 | D5: =IF(AND(ISNUMBER($B5),ISNUMBER(C5)), $B5-C5, "") -> 226625.61 | E5: =IFERROR(D5/C5, "") | F5: =SUM('1st Qtr'!F5, '2nd Qtr'!F5, '3rd Qtr'!F5, '4th Qtr'!F5) -> 233013.47 | G5: =IF(AND(ISNUMBER($B5),ISNUMBER(F5)), $B5-F5, "") -> -6387.8529 | H5: =IFERROR(G5/F5, "") -> -0.027414093
A6: CT | B6: =SUM('1st Qtr'!B6, '2nd Qtr'!B6, '3rd Qtr'!B6, '4th Qtr'!B6) -> 11886.723 | C6: =SUM('1st Qtr'!C6, '2nd Qtr'!C6, '3rd Qtr'!C6, '4th Qtr'!C6) -> 14097.136 | D6: =IF(AND(ISNUMBER($B6),ISNUMBER(C6)), $B6-C6, "") -> -2210.4131 | E6: =IFERROR(D6/C6, "") -> -0.15679874 | F6: =SUM('1st Qtr'!F6, '2nd Qtr'!F6, '3rd Qtr'!F6, '4th Qtr'!F6) -> 14860.036 | G6: =IF(AND(ISNUMBER($B6),ISNUMBER(F6)), $B6-F6, "") -> -2973.3136 | H6: =IFERROR(G6/F6, "") -> -0.20008791
A7: FL | B7: =SUM('1st Qtr'!B7, '2nd Qtr'!B7, '3rd Qtr'!B7, '4th Qtr'!B7) -> 11628.316 | C7: =SUM('1st Qtr'!C7, '2nd Qtr'!C7, '3rd Qtr'!C7, '4th Qtr'!C7) -> 36841.061 | D7: =IF(AND(ISNUMBER($B7),ISNUMBER(C7)), $B7-C7, "") -> -25212.745 | E7: =IFERROR(D7/C7, "") -> -0.68436533 | F7: =SUM('1st Qtr'!F7, '2nd Qtr'!F7, '3rd Qtr'!F7, '4th Qtr'!F7) -> 43768 | G7: =IF(AND(ISNUMBER($B7),ISNUMBER(F7)), $B7-F7, "") -> -32139.684 | H7: =IFERROR(G7/F7, "") -> -0.73431922
A8: IA | B8: =SUM('1st Qtr'!B8, '2nd Qtr'!B8, '3rd Qtr'!B8, '4th Qtr'!B8) -> 2240940.5 | C8: =SUM('1st Qtr'!C8, '2nd Qtr'!C8, '3rd Qtr'!C8, '4th Qtr'!C8) -> 2310057.3 | D8: =IF(AND(ISNUMBER($B8),ISNUMBER(C8)), $B8-C8, "") -> -69116.76 | E8: =IFERROR(D8/C8, "") -> -0.029919934 | F8: =SUM('1st Qtr'!F8, '2nd Qtr'!F8, '3rd Qtr'!F8, '4th Qtr'!F8) -> 2312856.2 | G8: =IF(AND(ISNUMBER($B8),ISNUMBER(F8)), $B8-F8, "") -> -71915.73 | H8: =IFERROR(G8/F8, "") -> -0.031093904
A9: NC | B9: =SUM('1st Qtr'!B9, '2nd Qtr'!B9, '3rd Qtr'!B9, '4th Qtr'!B9) -> 2804781.2 | C9: =SUM('1st Qtr'!C9, '2nd Qtr'!C9, '3rd Qtr'!C9, '4th Qtr'!C9) -> 2948151 | D9: =IF(AND(ISNUMBER($B9),ISNUMBER(C9)), $B9-C9, "") -> -143369.81 | E9: =IFERROR(D9/C9, "") -> -0.048630415 | F9: =SUM('1st Qtr'!F9, '2nd Qtr'!F9, '3rd Qtr'!F9, '4th Qtr'!F9) -> 2880008.7 | G9: =IF(AND(ISNUMBER($B9),ISNUMBER(F9)), $B9-F9, "") -> -75227.541 | H9: =IFERROR(G9/F9, "") -> -0.026120595
A10: NJ | B10: =SUM('1st Qtr'!B10, '2nd Qtr'!B10, '3rd Qtr'!B10, '4th Qtr'!B10) -> 694136.11 | C10: =SUM('1st Qtr'!C10, '2nd Qtr'!C10, '3rd Qtr'!C10, '4th Qtr'!C10) -> 687632.49 | D10: =IF(AND(ISNUMBER($B10),ISNUMBER(C10)), $B10-C10, "") -> 6503.6182 | E10: =IFERROR(D10/C10, "") -> 0.0094579857 | F10: =SUM('1st Qtr'!F10, '2nd Qtr'!F10, '3rd Qtr'!F10, '4th Qtr'!F10) -> 756542.08 | G10: =IF(AND(ISNUMBER($B10),ISNUMBER(F10)), $B10-F10, "") -> -62405.97 | H10: =IFERROR(G10/F10, "") -> -0.082488432
A11: TX | B11: =SUM('1st Qtr'!B11, '2nd Qtr'!B11, '3rd Qtr'!B11, '4th Qtr'!B11) -> 6236150.9 | C11: =SUM('1st Qtr'!C11, '2nd Qtr'!C11, '3rd Qtr'!C11, '4th Qtr'!C11) -> 6146609.4 | D11: =IF(AND(ISNUMBER($B11),ISNUMBER(C11)), $B11-C11, "") -> 89541.461 | E11: =IFERROR(D11/C11, "") -> 0.014567618 | F11: =SUM('1st Qtr'!F11, '2nd Qtr'!F11, '3rd Qtr'!F11, '4th Qtr'!F11) -> 6934260.3 | G11: =IF(AND(ISNUMBER($B11),ISNUMBER(F11)), $B11-F11, "") -> -698109.4 | H11: =IFERROR(G11/F11, "") -> -0.1006754
A12: AZ | B12: =SUM('1st Qtr'!B12, '2nd Qtr'!B12, '3rd Qtr'!B12, '4th Qtr'!B12) -> 3940304.9 | C12: =SUM('1st Qtr'!C12, '2nd Qtr'!C12, '3rd Qtr'!C12, '4th Qtr'!C12) -> 3584127.2 | D12: =IF(AND(ISNUMBER($B12),ISNUMBER(C12)), $B12-C12, "") -> 356177.73 | E12: =IFERROR(D12/C12, "") -> 0.09937642 | F12: =SUM('1st Qtr'!F12, '2nd Qtr'!F12, '3rd Qtr'!F12, '4th Qtr'!F12) -> 3855804.3 | G12: =IF(AND(ISNUMBER($B12),ISNUMBER(F12)), $B12-F12, "") -> 84500.594 | H12: =IFERROR(G12/F12, "") -> 0.021915166
C16: 62% of the sites (41 of the 66 sites from 2024; 81 sites as of September) outperformed vs September 2024 information.
C18: 17% of the sites (14 of the 81 sites) appear to have inaccurate modeling information. I will be reviewing the PVsyst information, assuming it was made available to O&M.
C20: Sites with positive performance (actual vs expected):
C21: N Black Canyon Hwy, Phoenix - North
C22: AZ: Tucson - RINCON
C23: CA: Ventura - BUENAVENTURA
C24: NJ: Barnegat - WF
C26: Sites with under-performance issues (actual vs. expected):
C27: FL:Hialeah Gardens | F27: SR098791 - re-power
C28: TX: San Antonio - Ops Ctr GM | F28: SR108958 - pending return visit
C29: NJ: Holmdel - WF | F29: SR100979 - pending return visit
C30: NJ: Mahwah | F30: SR100593 -pending return visit
C31: NJ: Middletown | F31: SR100592 -pending return visit
C32: CA: Sacramento - Arden Fair Mall | F32: Nothing mechanical
C34: Most common issues seen:
C35: Communication issues on equipment (meters, weather stations, etc). - Followed up with AE Support. Will address next time onsite.
C36: String issues on several inverters of various capacities.
C38: Plan to remediate:
C39: Operations is reviewing all open SRs and prioritizing accordingly.
C53: 81 sites | D53: 2025
D54: Actual | E54: Expected | F54: Delta | G54: % | H54: Forecasted | I54: Delta | J54: %
D55: 2009886 | E55: 1966799 | F55: 43087 | G55: 0.02 | H55: 2174763 | I55: -164877 | J55: -0.08
C57: 66 Sites | D57: 2024
D58: Actual | E58: Expected | F58: Delta | G58: % | H58: Forecasted | I58: Delta | J58: %
D59: 1566588 | E59: 1547344 | F59: 19244 | G59: 0.01 | H59: 1863295 | I59: -296707 | J59: -0.16

Sheet 1st Qtr
A1: {=portfolio} -> Wells Fargo | C1: 1st Quarter Actual v. Expected | F1: 1st Quarter Actual v. Forecasted
A2: Total | B2: =SUM(B4:B90) -> 4616998.7 | C2: =SUM(C4:C90) -> 4690989.6 | D2: =B2-C2 -> -73990.915 | E2: =IFERROR(D2/C2, 0) -> -0.015772986 | F2: =SUM(F4:F90) -> 4770063.2 | G2: =B2-F2 -> -153064.55 | H2: =IFERROR(G2/F2, 0) -> -0.032088578
A3: State | B3: Actual | C3: Expected | D3: Delta | E3: % | F3: Forecasted | G3: Delta | H3: %
A4: {=_xlfn.UNIQUE(Sites[State])} -> CA | B4: =SUM(SUMIF(_xlfn.ANCHORARRAY(Jan!$B$4), $A4, Jan!C$4:C$65), SUMIF(_xlfn.ANCHORARRAY(Feb!$B$4), $A4, Feb!C$4:C$76), SUMIF(_xlfn.ANCHORARRAY(Mar!$B$4), $A4, Mar!C$4:C$65)) -> 323914.59 | C4: =SUM(SUMIF(_xlfn.ANCHORARRAY(Jan!$B$4), $A4, Jan!D$4:D$65), SUMIF(_xlfn.ANCHORARRAY(Feb!$B$4), $A4, Feb!D$4:D$76), SUMIF(_xlfn.ANCHORARRAY(Mar!$B$4), $A4, Mar!D$4:D$65)) -> 315455.56 | D4: =IF(AND(ISNUMBER(B4),ISNUMBER(C4)), B4-C4, "") -> 8459.0248 | E4: =IFERROR(D4/C4, "") -> 0.026815266 | F4: =SUM(SUMIF(_xlfn.ANCHORARRAY(Jan!$B$4), $A4, Jan!G$4:G$65), SUMIF(_xlfn.ANCHORARRAY(Feb!$B$4), $A4, Feb!G$4:G$76), SUMIF(_xlfn.ANCHORARRAY(Mar!$B$4), $A4, Mar!G$4:G$65)) -> 335472.12 | G4: =IF(AND(ISNUMBER(B4),ISNUMBER(F4)), B4-F4, "") -> -11557.537 | H4: =IFERROR(G4/F4, "") -> -0.034451557
A5: CO | B5: =SUM(SUMIF(_xlfn.ANCHORARRAY(Jan!$B$4), $A5, Jan!C$4:C$65), SUMIF(_xlfn.ANCHORARRAY(Feb!$B$4), $A5, Feb!C$4:C$76), SUMIF(_xlfn.ANCHORARRAY(Mar!$B$4), $A5, Mar!C$4:C$65)) -> 54979.615 | C5: =SUM(SUMIF(_xlfn.ANCHORARRAY(Jan!$B$4), $A5, Jan!D$4:D$65), SUMIF(_xlfn.ANCHORARRAY(Feb!$B$4), $A5, Feb!D$4:D$76), SUMIF(_xlfn.ANCHORARRAY(Mar!$B$4), $A5, Mar!D$4:D$65)) -> 0 | D5: =IF(AND(ISNUMBER(B5),ISNUMBER(C5)), B5-C5, "") -> 54979.615 | E5: =IFERROR(D5/C5, "") | F5: =SUM(SUMIF(_xlfn.ANCHORARRAY(Jan!$B$4), $A5, Jan!G$4:G$65), SUMIF(_xlfn.ANCHORARRAY(Feb!$B$4), $A5, Feb!G$4:G$76), SUMIF(_xlfn.ANCHORARRAY(Mar!$B$4), $A5, Mar!G$4:G$65)) -> 55712.069 | G5: =IF(AND(ISNUMBER(B5),ISNUMBER(F5)), B5-F5, "") -> -732.45357 | H5: =IFERROR(G5/F5, "") -> -0.013147126
A6: CT | B6: =SUM(SUMIF(_xlfn.ANCHORARRAY(Jan!$B$4), $A6, Jan!C$4:C$65), SUMIF(_xlfn.ANCHORARRAY(Feb!$B$4), $A6, Feb!C$4:C$76), SUMIF(_xlfn.ANCHORARRAY(Mar!$B$4), $A6, Mar!C$4:C$65)) -> 1851.4829 | C6: =SUM(SUMIF(_xlfn.ANCHORARRAY(Jan!$B$4), $A6, Jan!D$4:D$65), SUMIF(_xlfn.ANCHORARRAY(Feb!$B$4), $A6, Feb!D$4:D$76), SUMIF(_xlfn.ANCHORARRAY(Mar!$B$4), $A6, Mar!D$4:D$65)) -> 5169.1618 | D6: =IF(AND(ISNUMBER(B6),ISNUMBER(C6)), B6-C6, "") -> -3317.6789 | E6: =IFERROR(D6/C6, "") -> -0.64182145 | F6: =SUM(SUMIF(_xlfn.ANCHORARRAY(Jan!$B$4), $A6, Jan!G$4:G$65), SUMIF(_xlfn.ANCHORARRAY(Feb!$B$4), $A6, Feb!G$4:G$76), SUMIF(_xlfn.ANCHORARRAY(Mar!$B$4), $A6, Mar!G$4:G$65)) -> 2893.9708 | G6: =IF(AND(ISNUMBER(B6),ISNUMBER(F6)), B6-F6, "") -> -1042.4879 | H6: =IFERROR(G6/F6, "") -> -0.36022752
A7: FL | B7: =SUM(SUMIF(_xlfn.ANCHORARRAY(Jan!$B$4), $A7, Jan!C$4:C$65), SUMIF(_xlfn.ANCHORARRAY(Feb!$B$4), $A7, Feb!C$4:C$76), SUMIF(_xlfn.ANCHORARRAY(Mar!$B$4), $A7, Mar!C$4:C$65)) -> 6794.6116 | C7: =SUM(SUMIF(_xlfn.ANCHORARRAY(Jan!$B$4), $A7, Jan!D$4:D$65), SUMIF(_xlfn.ANCHORARRAY(Feb!$B$4), $A7, Feb!D$4:D$76), SUMIF(_xlfn.ANCHORARRAY(Mar!$B$4), $A7, Mar!D$4:D$65)) -> 10102.5 | D7: =IF(AND(ISNUMBER(B7),ISNUMBER(C7)), B7-C7, "") -> -3307.8884 | E7: =IFERROR(D7/C7, "") -> -0.32743266 | F7: =SUM(SUMIF(_xlfn.ANCHORARRAY(Jan!$B$4), $A7, Jan!G$4:G$65), SUMIF(_xlfn.ANCHORARRAY(Feb!$B$4), $A7, Feb!G$4:G$76), SUMIF(_xlfn.ANCHORARRAY(Mar!$B$4), $A7, Mar!G$4:G$65)) -> 12194 | G7: =IF(AND(ISNUMBER(B7),ISNUMBER(F7)), B7-F7, "") -> -5399.3884 | H7: =IFERROR(G7/F7, "") -> -0.44279059
A8: IA | B8: =SUM(SUMIF(_xlfn.ANCHORARRAY(Jan!$B$4), $A8, Jan!C$4:C$65), SUMIF(_xlfn.ANCHORARRAY(Feb!$B$4), $A8, Feb!C$4:C$76), SUMIF(_xlfn.ANCHORARRAY(Mar!$B$4), $A8, Mar!C$4:C$65)) -> 613482 | C8: =SUM(SUMIF(_xlfn.ANCHORARRAY(Jan!$B$4), $A8, Jan!D$4:D$65), SUMIF(_xlfn.ANCHORARRAY(Feb!$B$4), $A8, Feb!D$4:D$76), SUMIF(_xlfn.ANCHORARRAY(Mar!$B$4), $A8, Mar!D$4:D$65)) -> 684039.11 | D8: =IF(AND(ISNUMBER(B8),ISNUMBER(C8)), B8-C8, "") -> -70557.11 | E8: =IFERROR(D8/C8, "") -> -0.10314777 | F8: =SUM(SUMIF(_xlfn.ANCHORARRAY(Jan!$B$4), $A8, Jan!G$4:G$65), SUMIF(_xlfn.ANCHORARRAY(Feb!$B$4), $A8, Feb!G$4:G$76), SUMIF(_xlfn.ANCHORARRAY(Mar!$B$4), $A8, Mar!G$4:G$65)) -> 584111.82 | G8: =IF(AND(ISNUMBER(B8),ISNUMBER(F8)), B8-F8, "") -> 29370.18 | H8: =IFERROR(G8/F8, "") -> 0.050281777
A9: NC | B9: =SUM(SUMIF(_xlfn.ANCHORARRAY(Jan!$B$4), $A9, Jan!C$4:C$65), SUMIF(_xlfn.ANCHORARRAY(Feb!$B$4), $A9, Feb!C$4:C$76), SUMIF(_xlfn.ANCHORARRAY(Mar!$B$4), $A9, Mar!C$4:C$65)) -> 815835 | C9: =SUM(SUMIF(_xlfn.ANCHORARRAY(Jan!$B$4), $A9, Jan!D$4:D$65), SUMIF(_xlfn.ANCHORARRAY(Feb!$B$4), $A9, Feb!D$4:D$76), SUMIF(_xlfn.ANCHORARRAY(Mar!$B$4), $A9, Mar!D$4:D$65)) -> 857584.95 | D9: =IF(AND(ISNUMBER(B9),ISNUMBER(C9)), B9-C9, "") -> -41749.95 | E9: =IFERROR(D9/C9, "") -> -0.048683165 | F9: =SUM(SUMIF(_xlfn.ANCHORARRAY(Jan!$B$4), $A9, Jan!G$4:G$65), SUMIF(_xlfn.ANCHORARRAY(Feb!$B$4), $A9, Feb!G$4:G$76), SUMIF(_xlfn.ANCHORARRAY(Mar!$B$4), $A9, Mar!G$4:G$65)) -> 817328.02 | G9: =IF(AND(ISNUMBER(B9),ISNUMBER(F9)), B9-F9, "") -> -1493.016 | H9: =IFERROR(G9/F9, "") -> -0.0018267036
A10: NJ | B10: =SUM(SUMIF(_xlfn.ANCHORARRAY(Jan!$B$4), $A10, Jan!C$4:C$65), SUMIF(_xlfn.ANCHORARRAY(Feb!$B$4), $A10, Feb!C$4:C$76), SUMIF(_xlfn.ANCHORARRAY(Mar!$B$4), $A10, Mar!C$4:C$65)) -> 170714.78 | C10: =SUM(SUMIF(_xlfn.ANCHORARRAY(Jan!$B$4), $A10, Jan!D$4:D$65), SUMIF(_xlfn.ANCHORARRAY(Feb!$B$4), $A10, Feb!D$4:D$76), SUMIF(_xlfn.ANCHORARRAY(Mar!$B$4), $A10, Mar!D$4:D$65)) -> 178700.01 | D10: =IF(AND(ISNUMBER(B10),ISNUMBER(C10)), B10-C10, "") -> -7985.2383 | E10: =IFERROR(D10/C10, "") -> -0.044685157 | F10: =SUM(SUMIF(_xlfn.ANCHORARRAY(Jan!$B$4), $A10, Jan!G$4:G$65), SUMIF(_xlfn.ANCHORARRAY(Feb!$B$4), $A10, Feb!G$4:G$76), SUMIF(_xlfn.ANCHORARRAY(Mar!$B$4), $A10, Mar!G$4:G$65)) -> 163692.16 | G10: =IF(AND(ISNUMBER(B10),ISNUMBER(F10)), B10-F10, "") -> 7022.6171 | H10: =IFERROR(G10/F10, "") -> 0.042901365
A11: TX | B11: =SUM(SUMIF(_xlfn.ANCHORARRAY(Jan!$B$4), $A11, Jan!C$4:C$65), SUMIF(_xlfn.ANCHORARRAY(Feb!$B$4), $A11, Feb!C$4:C$76), SUMIF(_xlfn.ANCHORARRAY(Mar!$B$4), $A11, Mar!C$4:C$65)) -> 1715281.4 | C11: =SUM(SUMIF(_xlfn.ANCHORARRAY(Jan!$B$4), $A11, Jan!D$4:D$65), SUMIF(_xlfn.ANCHORARRAY(Feb!$B$4), $A11, Feb!D$4:D$76), SUMIF(_xlfn.ANCHORARRAY(Mar!$B$4), $A11, Mar!D$4:D$65)) -> 1848663.6 | D11: =IF(AND(ISNUMBER(B11),ISNUMBER(C11)), B11-C11, "") -> -133382.27 | E11: =IFERROR(D11/C11, "") -> -0.072150642 | F11: =SUM(SUMIF(_xlfn.ANCHORARRAY(Jan!$B$4), $A11, Jan!G$4:G$65), SUMIF(_xlfn.ANCHORARRAY(Feb!$B$4), $A11, Feb!G$4:G$76), SUMIF(_xlfn.ANCHORARRAY(Mar!$B$4), $A11, Mar!G$4:G$65)) -> 1849858.5 | G11: =IF(AND(ISNUMBER(B11),ISNUMBER(F11)), B11-F11, "") -> -134577.11 | H11: =IFERROR(G11/F11, "") -> -0.072749949
A12: AZ | B12: =SUM(SUMIF(_xlfn.ANCHORARRAY(Jan!$B$4), $A12, Jan!C$4:C$65), SUMIF(_xlfn.ANCHORARRAY(Feb!$B$4), $A12, Feb!C$4:C$76), SUMIF(_xlfn.ANCHORARRAY(Mar!$B$4), $A12, Mar!C$4:C$65)) -> 914145.21 | C12: =SUM(SUMIF(_xlfn.ANCHORARRAY(Jan!$B$4), $A12, Jan!D$4:D$65), SUMIF(_xlfn.ANCHORARRAY(Feb!$B$4), $A12, Feb!D$4:D$76), SUMIF(_xlfn.ANCHORARRAY(Mar!$B$4), $A12, Mar!D$4:D$65)) -> 791274.63 | D12: =IF(AND(ISNUMBER(B12),ISNUMBER(C12)), B12-C12, "") -> 122870.58 | E12: =IFERROR(D12/C12, "") -> 0.15528184 | F12: =SUM(SUMIF(_xlfn.ANCHORARRAY(Jan!$B$4), $A12, Jan!G$4:G$65), SUMIF(_xlfn.ANCHORARRAY(Feb!$B$4), $A12, Feb!G$4:G$76), SUMIF(_xlfn.ANCHORARRAY(Mar!$B$4), $A12, Mar!G$4:G$65)) -> 948800.56 | G12: =IF(AND(ISNUMBER(B12),ISNUMBER(F12)), B12-F12, "") -> -34655.349 | H12: =IFERROR(G12/F12, "") -> -0.036525431

Sheet 2nd Qtr
A1: {=portfolio} -> Wells Fargo | C1: 2nd Quarter Actual v. Expected | F1: 2nd Quarter Actual v. Forecasted
A2: Total | B2: =SUM(B4:B85) -> 6574334.1 | C2: =SUM(C4:C85) -> 6120289.5 | D2: =B2-C2 -> 454044.6 | E2: =IFERROR(D2/C2, 0) -> 0.074186785 | F2: =SUM(F4:F85) -> 6888363.2 | G2: =B2-F2 -> -314029.09 | H2: =IFERROR(G2/F2, 0) -> -0.045588347
A3: State | B3: Actual | C3: Expected | D3: Delta | E3: % | F3: Forecasted | G3: Delta | H3: %
A4: {=_xlfn.UNIQUE(Sites[State])} -> CA | B4: =SUM(SUMIF(_xlfn.ANCHORARRAY(Apr!$B$4), $A4, Apr!C$4:C$78), SUMIF(_xlfn.ANCHORARRAY(May!$B$4), $A4, May!C$4:C$65), SUMIF(_xlfn.ANCHORARRAY(Jun!$B$4), $A4, Jun!C$4:C$65)) -> 454466.31 | C4: =SUM(SUMIF(_xlfn.ANCHORARRAY(Apr!$B$4), $A4, Apr!D$4:D$78), SUMIF(_xlfn.ANCHORARRAY(May!$B$4), $A4, May!D$4:D$65), SUMIF(_xlfn.ANCHORARRAY(Jun!$B$4), $A4, Jun!D$4:D$65)) -> 384952.97 | D4: =IF(AND(ISNUMBER(B4),ISNUMBER(C4)), B4-C4, "") -> 69513.337 | E4: =IFERROR(D4/C4, "") -> 0.18057618 | F4: =SUM(SUMIF(_xlfn.ANCHORARRAY(Apr!$B$4), $A4, Apr!G$4:G$78), SUMIF(_xlfn.ANCHORARRAY(May!$B$4), $A4, May!G$4:G$65), SUMIF(_xlfn.ANCHORARRAY(Jun!$B$4), $A4, Jun!G$4:G$65)) -> 468977.56 | G4: =IF(AND(ISNUMBER(B4),ISNUMBER(F4)), B4-F4, "") -> -14511.249 | H4: =IFERROR(G4/F4, "") -> -0.03094231
A5: CO | B5: =SUM(SUMIF(_xlfn.ANCHORARRAY(Apr!$B$4), $A5, Apr!C$4:C$78), SUMIF(_xlfn.ANCHORARRAY(May!$B$4), $A5, May!C$4:C$65), SUMIF(_xlfn.ANCHORARRAY(Jun!$B$4), $A5, Jun!C$4:C$65)) -> 86879.912 | C5: =SUM(SUMIF(_xlfn.ANCHORARRAY(Apr!$B$4), $A5, Apr!D$4:D$78), SUMIF(_xlfn.ANCHORARRAY(May!$B$4), $A5, May!D$4:D$65), SUMIF(_xlfn.ANCHORARRAY(Jun!$B$4), $A5, Jun!D$4:D$65)) -> 0 | D5: =IF(AND(ISNUMBER(B5),ISNUMBER(C5)), B5-C5, "") -> 86879.912 | E5: =IFERROR(D5/C5, "") | F5: =SUM(SUMIF(_xlfn.ANCHORARRAY(Apr!$B$4), $A5, Apr!G$4:G$78), SUMIF(_xlfn.ANCHORARRAY(May!$B$4), $A5, May!G$4:G$65), SUMIF(_xlfn.ANCHORARRAY(Jun!$B$4), $A5, Jun!G$4:G$65)) -> 91826.591 | G5: =IF(AND(ISNUMBER(B5),ISNUMBER(F5)), B5-F5, "") -> -4946.6787 | H5: =IFERROR(G5/F5, "") -> -0.053869785
A6: CT | B6: =SUM(SUMIF(_xlfn.ANCHORARRAY(Apr!$B$4), $A6, Apr!C$4:C$78), SUMIF(_xlfn.ANCHORARRAY(May!$B$4), $A6, May!C$4:C$65), SUMIF(_xlfn.ANCHORARRAY(Jun!$B$4), $A6, Jun!C$4:C$65)) -> 4925.5769 | C6: =SUM(SUMIF(_xlfn.ANCHORARRAY(Apr!$B$4), $A6, Apr!D$4:D$78), SUMIF(_xlfn.ANCHORARRAY(May!$B$4), $A6, May!D$4:D$65), SUMIF(_xlfn.ANCHORARRAY(Jun!$B$4), $A6, Jun!D$4:D$65)) -> 5258.8701 | D6: =IF(AND(ISNUMBER(B6),ISNUMBER(C6)), B6-C6, "") -> -333.29323 | E6: =IFERROR(D6/C6, "") -> -0.063377346 | F6: =SUM(SUMIF(_xlfn.ANCHORARRAY(Apr!$B$4), $A6, Apr!G$4:G$78), SUMIF(_xlfn.ANCHORARRAY(May!$B$4), $A6, May!G$4:G$65), SUMIF(_xlfn.ANCHORARRAY(Jun!$B$4), $A6, Jun!G$4:G$65)) -> 6002.8584 | G6: =IF(AND(ISNUMBER(B6),ISNUMBER(F6)), B6-F6, "") -> -1077.2815 | H6: =IFERROR(G6/F6, "") -> -0.17946142
A7: FL | B7: =SUM(SUMIF(_xlfn.ANCHORARRAY(Apr!$B$4), $A7, Apr!C$4:C$78), SUMIF(_xlfn.ANCHORARRAY(May!$B$4), $A7, May!C$4:C$65), SUMIF(_xlfn.ANCHORARRAY(Jun!$B$4), $A7, Jun!C$4:C$65)) -> 2624.6016 | C7: =SUM(SUMIF(_xlfn.ANCHORARRAY(Apr!$B$4), $A7, Apr!D$4:D$78), SUMIF(_xlfn.ANCHORARRAY(May!$B$4), $A7, May!D$4:D$65), SUMIF(_xlfn.ANCHORARRAY(Jun!$B$4), $A7, Jun!D$4:D$65)) -> 13156.327 | D7: =IF(AND(ISNUMBER(B7),ISNUMBER(C7)), B7-C7, "") -> -10531.725 | E7: =IFERROR(D7/C7, "") -> -0.80050651 | F7: =SUM(SUMIF(_xlfn.ANCHORARRAY(Apr!$B$4), $A7, Apr!G$4:G$78), SUMIF(_xlfn.ANCHORARRAY(May!$B$4), $A7, May!G$4:G$65), SUMIF(_xlfn.ANCHORARRAY(Jun!$B$4), $A7, Jun!G$4:G$65)) -> 16185 | G7: =IF(AND(ISNUMBER(B7),ISNUMBER(F7)), B7-F7, "") -> -13560.398 | H7: =IFERROR(G7/F7, "") -> -0.83783741
A8: IA | B8: =SUM(SUMIF(_xlfn.ANCHORARRAY(Apr!$B$4), $A8, Apr!C$4:C$78), SUMIF(_xlfn.ANCHORARRAY(May!$B$4), $A8, May!C$4:C$65), SUMIF(_xlfn.ANCHORARRAY(Jun!$B$4), $A8, Jun!C$4:C$65)) -> 832180 | C8: =SUM(SUMIF(_xlfn.ANCHORARRAY(Apr!$B$4), $A8, Apr!D$4:D$78), SUMIF(_xlfn.ANCHORARRAY(May!$B$4), $A8, May!D$4:D$65), SUMIF(_xlfn.ANCHORARRAY(Jun!$B$4), $A8, Jun!D$4:D$65)) -> 787358.67 | D8: =IF(AND(ISNUMBER(B8),ISNUMBER(C8)), B8-C8, "") -> 44821.33 | E8: =IFERROR(D8/C8, "") -> 0.056926191 | F8: =SUM(SUMIF(_xlfn.ANCHORARRAY(Apr!$B$4), $A8, Apr!G$4:G$78), SUMIF(_xlfn.ANCHORARRAY(May!$B$4), $A8, May!G$4:G$65), SUMIF(_xlfn.ANCHORARRAY(Jun!$B$4), $A8, Jun!G$4:G$65)) -> 856428.44 | G8: =IF(AND(ISNUMBER(B8),ISNUMBER(F8)), B8-F8, "") -> -24248.44 | H8: =IFERROR(G8/F8, "") -> -0.028313446
A9: NC | B9: =SUM(SUMIF(_xlfn.ANCHORARRAY(Apr!$B$4), $A9, Apr!C$4:C$78), SUMIF(_xlfn.ANCHORARRAY(May!$B$4), $A9, May!C$4:C$65), SUMIF(_xlfn.ANCHORARRAY(Jun!$B$4), $A9, Jun!C$4:C$65)) -> 1111185.5 | C9: =SUM(SUMIF(_xlfn.ANCHORARRAY(Apr!$B$4), $A9, Apr!D$4:D$78), SUMIF(_xlfn.ANCHORARRAY(May!$B$4), $A9, May!D$4:D$65), SUMIF(_xlfn.ANCHORARRAY(Jun!$B$4), $A9, Jun!D$4:D$65)) -> 1158864.9 | D9: =IF(AND(ISNUMBER(B9),ISNUMBER(C9)), B9-C9, "") -> -47679.437 | E9: =IFERROR(D9/C9, "") -> -0.041143222 | F9: =SUM(SUMIF(_xlfn.ANCHORARRAY(Apr!$B$4), $A9, Apr!G$4:G$78), SUMIF(_xlfn.ANCHORARRAY(May!$B$4), $A9, May!G$4:G$65), SUMIF(_xlfn.ANCHORARRAY(Jun!$B$4), $A9, Jun!G$4:G$65)) -> 1153402 | G9: =IF(AND(ISNUMBER(B9),ISNUMBER(F9)), B9-F9, "") -> -42216.525 | H9: =IFERROR(G9/F9, "") -> -0.036601743
A10: NJ | B10: =SUM(SUMIF(_xlfn.ANCHORARRAY(Apr!$B$4), $A10, Apr!C$4:C$78), SUMIF(_xlfn.ANCHORARRAY(May!$B$4), $A10, May!C$4:C$65), SUMIF(_xlfn.ANCHORARRAY(Jun!$B$4), $A10, Jun!C$4:C$65)) -> 247241.29 | C10: =SUM(SUMIF(_xlfn.ANCHORARRAY(Apr!$B$4), $A10, Apr!D$4:D$78), SUMIF(_xlfn.ANCHORARRAY(May!$B$4), $A10, May!D$4:D$65), SUMIF(_xlfn.ANCHORARRAY(Jun!$B$4), $A10, Jun!D$4:D$65)) -> 248115.66 | D10: =IF(AND(ISNUMBER(B10),ISNUMBER(C10)), B10-C10, "") -> -874.37344 | E10: =IFERROR(D10/C10, "") -> -0.0035240558 | F10: =SUM(SUMIF(_xlfn.ANCHORARRAY(Apr!$B$4), $A10, Apr!G$4:G$78), SUMIF(_xlfn.ANCHORARRAY(May!$B$4), $A10, May!G$4:G$65), SUMIF(_xlfn.ANCHORARRAY(Jun!$B$4), $A10, Jun!G$4:G$65)) -> 297563.63 | G10: =IF(AND(ISNUMBER(B10),ISNUMBER(F10)), B10-F10, "") -> -50322.342 | H10: =IFERROR(G10/F10, "") -> -0.16911456
A11: TX | B11: =SUM(SUMIF(_xlfn.ANCHORARRAY(Apr!$B$4), $A11, Apr!C$4:C$78), SUMIF(_xlfn.ANCHORARRAY(May!$B$4), $A11, May!C$4:C$65), SUMIF(_xlfn.ANCHORARRAY(Jun!$B$4), $A11, Jun!C$4:C$65)) -> 2239247 | C11: =SUM(SUMIF(_xlfn.ANCHORARRAY(Apr!$B$4), $A11, Apr!D$4:D$78), SUMIF(_xlfn.ANCHORARRAY(May!$B$4), $A11, May!D$4:D$65), SUMIF(_xlfn.ANCHORARRAY(Jun!$B$4), $A11, Jun!D$4:D$65)) -> 2042211.1 | D11: =IF(AND(ISNUMBER(B11),ISNUMBER(C11)), B11-C11, "") -> 197035.84 | E11: =IFERROR(D11/C11, "") -> 0.096481621 | F11: =SUM(SUMIF(_xlfn.ANCHORARRAY(Apr!$B$4), $A11, Apr!G$4:G$78), SUMIF(_xlfn.ANCHORARRAY(May!$B$4), $A11, May!G$4:G$65), SUMIF(_xlfn.ANCHORARRAY(Jun!$B$4), $A11, Jun!G$4:G$65)) -> 2473075.6 | G11: =IF(AND(ISNUMBER(B11),ISNUMBER(F11)), B11-F11, "") -> -233828.6 | H11: =IFERROR(G11/F11, "") -> -0.094549717
A12: AZ | B12: =SUM(SUMIF(_xlfn.ANCHORARRAY(Apr!$B$4), $A12, Apr!C$4:C$78), SUMIF(_xlfn.ANCHORARRAY(May!$B$4), $A12, May!C$4:C$65), SUMIF(_xlfn.ANCHORARRAY(Jun!$B$4), $A12, Jun!C$4:C$65)) -> 1595583.9 | C12: =SUM(SUMIF(_xlfn.ANCHORARRAY(Apr!$B$4), $A12, Apr!D$4:D$78), SUMIF(_xlfn.ANCHORARRAY(May!$B$4), $A12, May!D$4:D$65), SUMIF(_xlfn.ANCHORARRAY(Jun!$B$4), $A12, Jun!D$4:D$65)) -> 1480370.9 | D12: =IF(AND(ISNUMBER(B12),ISNUMBER(C12)), B12-C12, "") -> 115213.01 | E12: =IFERROR(D12/C12, "") -> 0.077827124 | F12: =SUM(SUMIF(_xlfn.ANCHORARRAY(Apr!$B$4), $A12, Apr!G$4:G$78), SUMIF(_xlfn.ANCHORARRAY(May!$B$4), $A12, May!G$4:G$65), SUMIF(_xlfn.ANCHORARRAY(Jun!$B$4), $A12, Jun!G$4:G$65)) -> 1524901.5 | G12: =IF(AND(ISNUMBER(B12),ISNUMBER(F12)), B12-F12, "") -> 70682.422 | H12: =IFERROR(G12/F12, "") -> 0.046352123

Sheet 3rd Qtr
A1: {=portfolio} -> Wells Fargo | C1: 3rd Quarter Actual v. Expected | F1: 3rd Quarter Actual v. Forecasted
A2: Total | B2: =SUM(B4:B90) -> 6130390.4 | C2: =SUM(C4:C90) -> 5954369 | D2: =B2-C2 -> 176021.39 | E2: =IFERROR(D2/C2, 0) -> 0.029561721 | F2: =SUM(F4:F90) -> 6607064.6 | G2: =B2-F2 -> -476674.25 | H2: =IFERROR(G2/F2, 0) -> -0.072146146
A3: State | B3: Actual | C3: Expected | D3: Delta | E3: % | F3: Forecasted | G3: Delta | H3: %
A4: {=_xlfn.UNIQUE(Sites[State])} -> CA | B4: =SUM(SUMIF(_xlfn.ANCHORARRAY(Jul!$B$4), $A4, Jul!C$4:C$65), SUMIF(_xlfn.ANCHORARRAY(Aug!$C$4), $A4, Aug!D$4:D$69), SUMIF(_xlfn.ANCHORARRAY(Sep!$B$4), $A4, Sep!C$4:C$69)) -> 376887.9 | C4: =SUM(SUMIF(_xlfn.ANCHORARRAY(Jul!$B$4), $A4, Jul!D$4:D$65), SUMIF(_xlfn.ANCHORARRAY(Aug!$C$4), $A4, Aug!E$4:E$69), SUMIF(_xlfn.ANCHORARRAY(Sep!$B$4), $A4, Sep!D$4:D$69)) -> 337723.88 | D4: =IF(AND(ISNUMBER(B4),ISNUMBER(C4)), B4-C4, "") -> 39164.023 | E4: =IFERROR(D4/C4, "") -> 0.11596463 | F4: =SUM(SUMIF(_xlfn.ANCHORARRAY(Jul!$B$4), $A4, Jul!G$4:G$65), SUMIF(_xlfn.ANCHORARRAY(Aug!$C$4), $A4, Aug!H$4:H$69), SUMIF(_xlfn.ANCHORARRAY(Sep!$B$4), $A4, Sep!G$4:G$69)) -> 429928.1 | G4: =IF(AND(ISNUMBER(B4),ISNUMBER(F4)), B4-F4, "") -> -53040.201 | H4: =IFERROR(G4/F4, "") -> -0.12336993
A5: CO | B5: =SUM(SUMIF(_xlfn.ANCHORARRAY(Jul!$B$4), $A5, Jul!C$4:C$65), SUMIF(_xlfn.ANCHORARRAY(Aug!$C$4), $A5, Aug!D$4:D$69), SUMIF(_xlfn.ANCHORARRAY(Sep!$B$4), $A5, Sep!C$4:C$69)) -> 84766.084 | C5: =SUM(SUMIF(_xlfn.ANCHORARRAY(Jul!$B$4), $A5, Jul!D$4:D$65), SUMIF(_xlfn.ANCHORARRAY(Aug!$C$4), $A5, Aug!E$4:E$69), SUMIF(_xlfn.ANCHORARRAY(Sep!$B$4), $A5, Sep!D$4:D$69)) -> 0 | D5: =IF(AND(ISNUMBER(B5),ISNUMBER(C5)), B5-C5, "") -> 84766.084 | E5: =IFERROR(D5/C5, "") | F5: =SUM(SUMIF(_xlfn.ANCHORARRAY(Jul!$B$4), $A5, Jul!G$4:G$65), SUMIF(_xlfn.ANCHORARRAY(Aug!$C$4), $A5, Aug!H$4:H$69), SUMIF(_xlfn.ANCHORARRAY(Sep!$B$4), $A5, Sep!G$4:G$69)) -> 85474.805 | G5: =IF(AND(ISNUMBER(B5),ISNUMBER(F5)), B5-F5, "") -> -708.72064 | H5: =IFERROR(G5/F5, "") -> -0.0082915737
A6: CT | B6: =SUM(SUMIF(_xlfn.ANCHORARRAY(Jul!$B$4), $A6, Jul!C$4:C$65), SUMIF(_xlfn.ANCHORARRAY(Aug!$C$4), $A6, Aug!D$4:D$69), SUMIF(_xlfn.ANCHORARRAY(Sep!$B$4), $A6, Sep!C$4:C$69)) -> 5109.663 | C6: =SUM(SUMIF(_xlfn.ANCHORARRAY(Jul!$B$4), $A6, Jul!D$4:D$65), SUMIF(_xlfn.ANCHORARRAY(Aug!$C$4), $A6, Aug!E$4:E$69), SUMIF(_xlfn.ANCHORARRAY(Sep!$B$4), $A6, Sep!D$4:D$69)) -> 3669.104 | D6: =IF(AND(ISNUMBER(B6),ISNUMBER(C6)), B6-C6, "") -> 1440.559 | E6: =IFERROR(D6/C6, "") -> 0.39261875 | F6: =SUM(SUMIF(_xlfn.ANCHORARRAY(Jul!$B$4), $A6, Jul!G$4:G$65), SUMIF(_xlfn.ANCHORARRAY(Aug!$C$4), $A6, Aug!H$4:H$69), SUMIF(_xlfn.ANCHORARRAY(Sep!$B$4), $A6, Sep!G$4:G$69)) -> 5963.2072 | G6: =IF(AND(ISNUMBER(B6),ISNUMBER(F6)), B6-F6, "") -> -853.54419 | H6: =IFERROR(G6/F6, "") -> -0.14313509
A7: FL | B7: =SUM(SUMIF(_xlfn.ANCHORARRAY(Jul!$B$4), $A7, Jul!C$4:C$65), SUMIF(_xlfn.ANCHORARRAY(Aug!$C$4), $A7, Aug!D$4:D$69), SUMIF(_xlfn.ANCHORARRAY(Sep!$B$4), $A7, Sep!C$4:C$69)) -> 2209.103 | C7: =SUM(SUMIF(_xlfn.ANCHORARRAY(Jul!$B$4), $A7, Jul!D$4:D$65), SUMIF(_xlfn.ANCHORARRAY(Aug!$C$4), $A7, Aug!E$4:E$69), SUMIF(_xlfn.ANCHORARRAY(Sep!$B$4), $A7, Sep!D$4:D$69)) -> 13582.234 | D7: =IF(AND(ISNUMBER(B7),ISNUMBER(C7)), B7-C7, "") -> -11373.131 | E7: =IFERROR(D7/C7, "") -> -0.83735348 | F7: =SUM(SUMIF(_xlfn.ANCHORARRAY(Jul!$B$4), $A7, Jul!G$4:G$65), SUMIF(_xlfn.ANCHORARRAY(Aug!$C$4), $A7, Aug!H$4:H$69), SUMIF(_xlfn.ANCHORARRAY(Sep!$B$4), $A7, Sep!G$4:G$69)) -> 15389 | G7: =IF(AND(ISNUMBER(B7),ISNUMBER(F7)), B7-F7, "") -> -13179.897 | H7: =IFERROR(G7/F7, "") -> -0.85644921
A8: IA | B8: =SUM(SUMIF(_xlfn.ANCHORARRAY(Jul!$B$4), $A8, Jul!C$4:C$65), SUMIF(_xlfn.ANCHORARRAY(Aug!$C$4), $A8, Aug!D$4:D$69), SUMIF(_xlfn.ANCHORARRAY(Sep!$B$4), $A8, Sep!C$4:C$69)) -> 795278.5 | C8: =SUM(SUMIF(_xlfn.ANCHORARRAY(Jul!$B$4), $A8, Jul!D$4:D$65), SUMIF(_xlfn.ANCHORARRAY(Aug!$C$4), $A8, Aug!E$4:E$69), SUMIF(_xlfn.ANCHORARRAY(Sep!$B$4), $A8, Sep!D$4:D$69)) -> 838659.48 | D8: =IF(AND(ISNUMBER(B8),ISNUMBER(C8)), B8-C8, "") -> -43380.98 | E8: =IFERROR(D8/C8, "") -> -0.051726572 | F8: =SUM(SUMIF(_xlfn.ANCHORARRAY(Jul!$B$4), $A8, Jul!G$4:G$65), SUMIF(_xlfn.ANCHORARRAY(Aug!$C$4), $A8, Aug!H$4:H$69), SUMIF(_xlfn.ANCHORARRAY(Sep!$B$4), $A8, Sep!G$4:G$69)) -> 872315.97 | G8: =IF(AND(ISNUMBER(B8),ISNUMBER(F8)), B8-F8, "") -> -77037.47 | H8: =IFERROR(G8/F8, "") -> -0.088313722
A9: NC | B9: =SUM(SUMIF(_xlfn.ANCHORARRAY(Jul!$B$4), $A9, Jul!C$4:C$65), SUMIF(_xlfn.ANCHORARRAY(Aug!$C$4), $A9, Aug!D$4:D$69), SUMIF(_xlfn.ANCHORARRAY(Sep!$B$4), $A9, Sep!C$4:C$69)) -> 877760.7 | C9: =SUM(SUMIF(_xlfn.ANCHORARRAY(Jul!$B$4), $A9, Jul!D$4:D$65), SUMIF(_xlfn.ANCHORARRAY(Aug!$C$4), $A9, Aug!E$4:E$69), SUMIF(_xlfn.ANCHORARRAY(Sep!$B$4), $A9, Sep!D$4:D$69)) -> 931701.12 | D9: =IF(AND(ISNUMBER(B9),ISNUMBER(C9)), B9-C9, "") -> -53940.421 | E9: =IFERROR(D9/C9, "") -> -0.057894554 | F9: =SUM(SUMIF(_xlfn.ANCHORARRAY(Jul!$B$4), $A9, Jul!G$4:G$65), SUMIF(_xlfn.ANCHORARRAY(Aug!$C$4), $A9, Aug!H$4:H$69), SUMIF(_xlfn.ANCHORARRAY(Sep!$B$4), $A9, Sep!G$4:G$69)) -> 909278.7 | G9: =IF(AND(ISNUMBER(B9),ISNUMBER(F9)), B9-F9, "") -> -31518 | H9: =IFERROR(G9/F9, "") -> -0.03466264
A10: NJ | B10: =SUM(SUMIF(_xlfn.ANCHORARRAY(Jul!$B$4), $A10, Jul!C$4:C$65), SUMIF(_xlfn.ANCHORARRAY(Aug!$C$4), $A10, Aug!D$4:D$69), SUMIF(_xlfn.ANCHORARRAY(Sep!$B$4), $A10, Sep!C$4:C$69)) -> 276180.04 | C10: =SUM(SUMIF(_xlfn.ANCHORARRAY(Jul!$B$4), $A10, Jul!D$4:D$65), SUMIF(_xlfn.ANCHORARRAY(Aug!$C$4), $A10, Aug!E$4:E$69), SUMIF(_xlfn.ANCHORARRAY(Sep!$B$4), $A10, Sep!D$4:D$69)) -> 260816.81 | D10: =IF(AND(ISNUMBER(B10),ISNUMBER(C10)), B10-C10, "") -> 15363.23 | E10: =IFERROR(D10/C10, "") -> 0.058904293 | F10: =SUM(SUMIF(_xlfn.ANCHORARRAY(Jul!$B$4), $A10, Jul!G$4:G$65), SUMIF(_xlfn.ANCHORARRAY(Aug!$C$4), $A10, Aug!H$4:H$69), SUMIF(_xlfn.ANCHORARRAY(Sep!$B$4), $A10, Sep!G$4:G$69)) -> 295286.29 | G10: =IF(AND(ISNUMBER(B10),ISNUMBER(F10)), B10-F10, "") -> -19106.244 | H10: =IFERROR(G10/F10, "") -> -0.064704137
A11: TX | B11: =SUM(SUMIF(_xlfn.ANCHORARRAY(Jul!$B$4), $A11, Jul!C$4:C$65), SUMIF(_xlfn.ANCHORARRAY(Aug!$C$4), $A11, Aug!D$4:D$69), SUMIF(_xlfn.ANCHORARRAY(Sep!$B$4), $A11, Sep!C$4:C$69)) -> 2281622.6 | C11: =SUM(SUMIF(_xlfn.ANCHORARRAY(Jul!$B$4), $A11, Jul!D$4:D$65), SUMIF(_xlfn.ANCHORARRAY(Aug!$C$4), $A11, Aug!E$4:E$69), SUMIF(_xlfn.ANCHORARRAY(Sep!$B$4), $A11, Sep!D$4:D$69)) -> 2255734.7 | D11: =IF(AND(ISNUMBER(B11),ISNUMBER(C11)), B11-C11, "") -> 25887.889 | E11: =IFERROR(D11/C11, "") -> 0.011476478 | F11: =SUM(SUMIF(_xlfn.ANCHORARRAY(Jul!$B$4), $A11, Jul!G$4:G$65), SUMIF(_xlfn.ANCHORARRAY(Aug!$C$4), $A11, Aug!H$4:H$69), SUMIF(_xlfn.ANCHORARRAY(Sep!$B$4), $A11, Sep!G$4:G$69)) -> 2611326.2 | G11: =IF(AND(ISNUMBER(B11),ISNUMBER(F11)), B11-F11, "") -> -329703.69 | H11: =IFERROR(G11/F11, "") -> -0.1262591
A12: AZ | B12: =SUM(SUMIF(_xlfn.ANCHORARRAY(Jul!$B$4), $A12, Jul!C$4:C$65), SUMIF(_xlfn.ANCHORARRAY(Aug!$C$4), $A12, Aug!D$4:D$69), SUMIF(_xlfn.ANCHORARRAY(Sep!$B$4), $A12, Sep!C$4:C$69)) -> 1430575.8 | C12: =SUM(SUMIF(_xlfn.ANCHORARRAY(Jul!$B$4), $A12, Jul!D$4:D$65), SUMIF(_xlfn.ANCHORARRAY(Aug!$C$4), $A12, Aug!E$4:E$69), SUMIF(_xlfn.ANCHORARRAY(Sep!$B$4), $A12, Sep!D$4:D$69)) -> 1312481.7 | D12: =IF(AND(ISNUMBER(B12),ISNUMBER(C12)), B12-C12, "") -> 118094.14 | E12: =IFERROR(D12/C12, "") -> 0.089977744 | F12: =SUM(SUMIF(_xlfn.ANCHORARRAY(Jul!$B$4), $A12, Jul!G$4:G$65), SUMIF(_xlfn.ANCHORARRAY(Aug!$C$4), $A12, Aug!H$4:H$69), SUMIF(_xlfn.ANCHORARRAY(Sep!$B$4), $A12, Sep!G$4:G$69)) -> 1382102.3 | G12: =IF(AND(ISNUMBER(B12),ISNUMBER(F12)), B12-F12, "") -> 48473.522 | H12: =IFERROR(G12/F12, "") -> 0.035072311

Sheet 4th Qtr
A1: {=portfolio} -> Wells Fargo | C1: 4th Quarter Actual v. Expected | F1: 4th Quarter Actual v. Forecasted
A2: Total | B2: =SUM(B4:B90) -> 0 | C2: =SUM(C4:C90) -> 0 | D2: =B2-C2 -> 0 | E2: =IFERROR(D2/C2, 0) -> 0 | F2: =SUM(F4:F90) -> 0 | G2: =B2-F2 -> 0 | H2: =IFERROR(G2/F2, 0) -> 0
A3: State | B3: Actual | C3: Expected | D3: Delta | E3: % | F3: Forecasted | G3: Delta | H3: %
A4: {=_xlfn.UNIQUE(Sites[State])} -> CA | B4: =SUM(SUMIF(_xlfn.ANCHORARRAY(Oct!$B$4), $A4, Oct!C$4:C$69), SUMIF(_xlfn.ANCHORARRAY(Nov!$B$4), $A4, Nov!C$4:C$69), SUMIF(_xlfn.ANCHORARRAY(Dec!$B$4), $A4, Dec!C$4:C$69)) -> 0 | C4: =SUM(SUMIF(_xlfn.ANCHORARRAY(Oct!$B$4), $A4, Oct!D$4:D$69), SUMIF(_xlfn.ANCHORARRAY(Nov!$B$4), $A4, Nov!D$4:D$69), SUMIF(_xlfn.ANCHORARRAY(Dec!$B$4), $A4, Dec!D$4:D$69)) -> 0 | D4: =IF(AND(ISNUMBER(B4),ISNUMBER(C4)), B4-C4, "") -> 0 | E4: =IFERROR(D4/C4, "") | F4: =SUM(SUMIF(_xlfn.ANCHORARRAY(Oct!$B$4), $A4, Oct!G$4:G$69), SUMIF(_xlfn.ANCHORARRAY(Nov!$B$4), $A4, Nov!G$4:G$69), SUMIF(_xlfn.ANCHORARRAY(Dec!$B$4), $A4, Dec!G$4:G$69)) -> 0 | G4: =IF(AND(ISNUMBER(B4),ISNUMBER(F4)), B4-F4, "") -> 0 | H4: =IFERROR(G4/F4, "")
A5: CO | B5: =SUM(SUMIF(_xlfn.ANCHORARRAY(Oct!$B$4), $A5, Oct!C$4:C$69), SUMIF(_xlfn.ANCHORARRAY(Nov!$B$4), $A5, Nov!C$4:C$69), SUMIF(_xlfn.ANCHORARRAY(Dec!$B$4), $A5, Dec!C$4:C$69)) -> 0 | C5: =SUM(SUMIF(_xlfn.ANCHORARRAY(Oct!$B$4), $A5, Oct!D$4:D$69), SUMIF(_xlfn.ANCHORARRAY(Nov!$B$4), $A5, Nov!D$4:D$69), SUMIF(_xlfn.ANCHORARRAY(Dec!$B$4), $A5, Dec!D$4:D$69)) -> 0 | D5: =IF(AND(ISNUMBER(B5),ISNUMBER(C5)), B5-C5, "") -> 0 | E5: =IFERROR(D5/C5, "") | F5: =SUM(SUMIF(_xlfn.ANCHORARRAY(Oct!$B$4), $A5, Oct!G$4:G$69), SUMIF(_xlfn.ANCHORARRAY(Nov!$B$4), $A5, Nov!G$4:G$69), SUMIF(_xlfn.ANCHORARRAY(Dec!$B$4), $A5, Dec!G$4:G$69)) -> 0 | G5: =IF(AND(ISNUMBER(B5),ISNUMBER(F5)), B5-F5, "") -> 0 | H5: =IFERROR(G5/F5, "")
A6: CT | B6: =SUM(SUMIF(_xlfn.ANCHORARRAY(Oct!$B$4), $A6, Oct!C$4:C$69), SUMIF(_xlfn.ANCHORARRAY(Nov!$B$4), $A6, Nov!C$4:C$69), SUMIF(_xlfn.ANCHORARRAY(Dec!$B$4), $A6, Dec!C$4:C$69)) -> 0 | C6: =SUM(SUMIF(_xlfn.ANCHORARRAY(Oct!$B$4), $A6, Oct!D$4:D$69), SUMIF(_xlfn.ANCHORARRAY(Nov!$B$4), $A6, Nov!D$4:D$69), SUMIF(_xlfn.ANCHORARRAY(Dec!$B$4), $A6, Dec!D$4:D$69)) -> 0 | D6: =IF(AND(ISNUMBER(B6),ISNUMBER(C6)), B6-C6, "") -> 0 | E6: =IFERROR(D6/C6, "") | F6: =SUM(SUMIF(_xlfn.ANCHORARRAY(Oct!$B$4), $A6, Oct!G$4:G$69), SUMIF(_xlfn.ANCHORARRAY(Nov!$B$4), $A6, Nov!G$4:G$69), SUMIF(_xlfn.ANCHORARRAY(Dec!$B$4), $A6, Dec!G$4:G$69)) -> 0 | G6: =IF(AND(ISNUMBER(B6),ISNUMBER(F6)), B6-F6, "") -> 0 | H6: =IFERROR(G6/F6, "")
A7: FL | B7: =SUM(SUMIF(_xlfn.ANCHORARRAY(Oct!$B$4), $A7, Oct!C$4:C$69), SUMIF(_xlfn.ANCHORARRAY(Nov!$B$4), $A7, Nov!C$4:C$69), SUMIF(_xlfn.ANCHORARRAY(Dec!$B$4), $A7, Dec!C$4:C$69)) -> 0 | C7: =SUM(SUMIF(_xlfn.ANCHORARRAY(Oct!$B$4), $A7, Oct!D$4:D$69), SUMIF(_xlfn.ANCHORARRAY(Nov!$B$4), $A7, Nov!D$4:D$69), SUMIF(_xlfn.ANCHORARRAY(Dec!$B$4), $A7, Dec!D$4:D$69)) -> 0 | D7: =IF(AND(ISNUMBER(B7),ISNUMBER(C7)), B7-C7, "") -> 0 | E7: =IFERROR(D7/C7, "") | F7: =SUM(SUMIF(_xlfn.ANCHORARRAY(Oct!$B$4), $A7, Oct!G$4:G$69), SUMIF(_xlfn.ANCHORARRAY(Nov!$B$4), $A7, Nov!G$4:G$69), SUMIF(_xlfn.ANCHORARRAY(Dec!$B$4), $A7, Dec!G$4:G$69)) -> 0 | G7: =IF(AND(ISNUMBER(B7),ISNUMBER(F7)), B7-F7, "") -> 0 | H7: =IFERROR(G7/F7, "")
A8: IA | B8: =SUM(SUMIF(_xlfn.ANCHORARRAY(Oct!$B$4), $A8, Oct!C$4:C$69), SUMIF(_xlfn.ANCHORARRAY(Nov!$B$4), $A8, Nov!C$4:C$69), SUMIF(_xlfn.ANCHORARRAY(Dec!$B$4), $A8, Dec!C$4:C$69)) -> 0 | C8: =SUM(SUMIF(_xlfn.ANCHORARRAY(Oct!$B$4), $A8, Oct!D$4:D$69), SUMIF(_xlfn.ANCHORARRAY(Nov!$B$4), $A8, Nov!D$4:D$69), SUMIF(_xlfn.ANCHORARRAY(Dec!$B$4), $A8, Dec!D$4:D$69)) -> 0 | D8: =IF(AND(ISNUMBER(B8),ISNUMBER(C8)), B8-C8, "") -> 0 | E8: =IFERROR(D8/C8, "") | F8: =SUM(SUMIF(_xlfn.ANCHORARRAY(Oct!$B$4), $A8, Oct!G$4:G$69), SUMIF(_xlfn.ANCHORARRAY(Nov!$B$4), $A8, Nov!G$4:G$69), SUMIF(_xlfn.ANCHORARRAY(Dec!$B$4), $A8, Dec!G$4:G$69)) -> 0 | G8: =IF(AND(ISNUMBER(B8),ISNUMBER(F8)), B8-F8, "") -> 0 | H8: =IFERROR(G8/F8, "")
A9: NC | B9: =SUM(SUMIF(_xlfn.ANCHORARRAY(Oct!$B$4), $A9, Oct!C$4:C$69), SUMIF(_xlfn.ANCHORARRAY(Nov!$B$4), $A9, Nov!C$4:C$69), SUMIF(_xlfn.ANCHORARRAY(Dec!$B$4), $A9, Dec!C$4:C$69)) -> 0 | C9: =SUM(SUMIF(_xlfn.ANCHORARRAY(Oct!$B$4), $A9, Oct!D$4:D$69), SUMIF(_xlfn.ANCHORARRAY(Nov!$B$4), $A9, Nov!D$4:D$69), SUMIF(_xlfn.ANCHORARRAY(Dec!$B$4), $A9, Dec!D$4:D$69)) -> 0 | D9: =IF(AND(ISNUMBER(B9),ISNUMBER(C9)), B9-C9, "") -> 0 | E9: =IFERROR(D9/C9, "") | F9: =SUM(SUMIF(_xlfn.ANCHORARRAY(Oct!$B$4), $A9, Oct!G$4:G$69), SUMIF(_xlfn.ANCHORARRAY(Nov!$B$4), $A9, Nov!G$4:G$69), SUMIF(_xlfn.ANCHORARRAY(Dec!$B$4), $A9, Dec!G$4:G$69)) -> 0 | G9: =IF(AND(ISNUMBER(B9),ISNUMBER(F9)), B9-F9, "") -> 0 | H9: =IFERROR(G9/F9, "")
A10: NJ | B10: =SUM(SUMIF(_xlfn.ANCHORARRAY(Oct!$B$4), $A10, Oct!C$4:C$69), SUMIF(_xlfn.ANCHORARRAY(Nov!$B$4), $A10, Nov!C$4:C$69), SUMIF(_xlfn.ANCHORARRAY(Dec!$B$4), $A10, Dec!C$4:C$69)) -> 0 | C10: =SUM(SUMIF(_xlfn.ANCHORARRAY(Oct!$B$4), $A10, Oct!D$4:D$69), SUMIF(_xlfn.ANCHORARRAY(Nov!$B$4), $A10, Nov!D$4:D$69), SUMIF(_xlfn.ANCHORARRAY(Dec!$B$4), $A10, Dec!D$4:D$69)) -> 0 | D10: =IF(AND(ISNUMBER(B10),ISNUMBER(C10)), B10-C10, "") -> 0 | E10: =IFERROR(D10/C10, "") | F10: =SUM(SUMIF(_xlfn.ANCHORARRAY(Oct!$B$4), $A10, Oct!G$4:G$69), SUMIF(_xlfn.ANCHORARRAY(Nov!$B$4), $A10, Nov!G$4:G$69), SUMIF(_xlfn.ANCHORARRAY(Dec!$B$4), $A10, Dec!G$4:G$69)) -> 0 | G10: =IF(AND(ISNUMBER(B10),ISNUMBER(F10)), B10-F10, "") -> 0 | H10: =IFERROR(G10/F10, "")
A11: TX | B11: =SUM(SUMIF(_xlfn.ANCHORARRAY(Oct!$B$4), $A11, Oct!C$4:C$69), SUMIF(_xlfn.ANCHORARRAY(Nov!$B$4), $A11, Nov!C$4:C$69), SUMIF(_xlfn.ANCHORARRAY(Dec!$B$4), $A11, Dec!C$4:C$69)) -> 0 | C11: =SUM(SUMIF(_xlfn.ANCHORARRAY(Oct!$B$4), $A11, Oct!D$4:D$69), SUMIF(_xlfn.ANCHORARRAY(Nov!$B$4), $A11, Nov!D$4:D$69), SUMIF(_xlfn.ANCHORARRAY(Dec!$B$4), $A11, Dec!D$4:D$69)) -> 0 | D11: =IF(AND(ISNUMBER(B11),ISNUMBER(C11)), B11-C11, "") -> 0 | E11: =IFERROR(D11/C11, "") | F11: =SUM(SUMIF(_xlfn.ANCHORARRAY(Oct!$B$4), $A11, Oct!G$4:G$69), SUMIF(_xlfn.ANCHORARRAY(Nov!$B$4), $A11, Nov!G$4:G$69), SUMIF(_xlfn.ANCHORARRAY(Dec!$B$4), $A11, Dec!G$4:G$69)) -> 0 | G11: =IF(AND(ISNUMBER(B11),ISNUMBER(F11)), B11-F11, "") -> 0 | H11: =IFERROR(G11/F11, "")
A12: AZ | B12: =SUM(SUMIF(_xlfn.ANCHORARRAY(Oct!$B$4), $A12, Oct!C$4:C$69), SUMIF(_xlfn.ANCHORARRAY(Nov!$B$4), $A12, Nov!C$4:C$69), SUMIF(_xlfn.ANCHORARRAY(Dec!$B$4), $A12, Dec!C$4:C$69)) -> 0 | C12: =SUM(SUMIF(_xlfn.ANCHORARRAY(Oct!$B$4), $A12, Oct!D$4:D$69), SUMIF(_xlfn.ANCHORARRAY(Nov!$B$4), $A12, Nov!D$4:D$69), SUMIF(_xlfn.ANCHORARRAY(Dec!$B$4), $A12, Dec!D$4:D$69)) -> 0 | D12: =IF(AND(ISNUMBER(B12),ISNUMBER(C12)), B12-C12, "") -> 0 | E12: =IFERROR(D12/C12, "") | F12: =SUM(SUMIF(_xlfn.ANCHORARRAY(Oct!$B$4), $A12, Oct!G$4:G$69), SUMIF(_xlfn.ANCHORARRAY(Nov!$B$4), $A12, Nov!G$4:G$69), SUMIF(_xlfn.ANCHORARRAY(Dec!$B$4), $A12, Dec!G$4:G$69)) -> 0 | G12: =IF(AND(ISNUMBER(B12),ISNUMBER(F12)), B12-F12, "") -> 0 | H12: =IFERROR(G12/F12, "")

Sheet Jan
A1: {=portfolio} -> Wells Fargo | D1: January Actual v. Expected | G1: January Actual v. Forecasted
A2: Total | C2: =SUM(C4:C65) -> 972233.77 | D2: =SUM(D4:D65) -> 1090495.1 | E2: =C2-D2 -> -118261.3 | F2: =IFERROR(E2/D2, 0) -> -0.10844735 | G2: =SUM(G4:G65) -> 1037915.7 | H2: =C2-G2 -> -65681.9 | I2: =IFERROR(H2/G2, 0) -> -0.063282502 | J2: =IF(AND(TODAY()>DATE(2024, 1, 1), COUNTA(Sites[Site])<>(COUNT(C:C)-1)), "Some sites are missing actual data; if new sites were added, make sure they are aligned correctly (including prior months!)", "") -> Some sites are missing actual data; if new sites were added, make sure they are aligned correctly (including prior months!)
A3: Site | B3: State | C3: Actual | D3: Expected | E3: Delta | F3: % | G3: Forecasted | H3: Delta | I3: % | J3: Notes | K3: Service Requests
A4: {=Sites[Site]} -> Adams & Broadway | B4: {=Sites[State]} -> CA | C4: 501.8 | D4: 0 | E4: =IF(AND(ISNUMBER(C4),ISNUMBER(D4)), C4-D4, "") -> 501.8 | F4: =IFERROR(E4/D4, "") | G4: 661 | H4: =IF(AND(ISNUMBER(C4),ISNUMBER(G4)), C4-G4, "") -> -159.2 | I4: =IFERROR(H4/G4, "") -> -0.2408472 | J4: 1.Low generation due to weather/snow.
A5: Otay Mesa | B5: CA | C5: 39.49 | D5: 0 | E5: =IF(AND(ISNUMBER(C5),ISNUMBER(D5)), C5-D5, "") -> 39.49 | F5: =IFERROR(E5/D5, "") | G5: 0 | H5: =IF(AND(ISNUMBER(C5),ISNUMBER(G5)), C5-G5, "") -> 39.49 | I5: =IFERROR(H5/G5, "") | J5: 1. Production data taken from consumption meter.
A6: San Leandro | B6: CA | C6: 25601 | D6: 35709.12 | E6: =IF(AND(ISNUMBER(C6),ISNUMBER(D6)), C6-D6, "") -> -10108.12 | F6: =IFERROR(E6/D6, "") -> -0.2830683 | G6: 22352.73 | H6: =IF(AND(ISNUMBER(C6),ISNUMBER(G6)), C6-G6, "") -> 3248.27 | I6: =IFERROR(H6/G6, "") -> 0.14531871 | J6: 1.Inverter 4 underperforming by 7kW since 06/11, down 2 strings. Dispatch has been scheduled. Inverter 2 underperforming by 3kW since 05/10, down 1 string. Dispatch has been scheduled. Inverter 7 underperforming by 3kW since 09/09, down 1 string. Dispatch has been scheduled. 2.The inverter 3 has a history of wire box damage, so a complete inverter and wire box upgrade was required. The current wire box string fuse configuration was not acceptable. So, Inverter 3 has been undergoing an RMA process since 07/26/24. | K6: 1.SR091496 2.SR088261 | L6: SR088261
A7: Van Nuys | B7: CA | C7: 914 | D7: 0 | E7: =IF(AND(ISNUMBER(C7),ISNUMBER(D7)), C7-D7, "") -> 914 | F7: =IFERROR(E7/D7, "") | G7: 1320.568 | H7: =IF(AND(ISNUMBER(C7),ISNUMBER(G7)), C7-G7, "") -> -406.568 | I7: =IFERROR(H7/G7, "") -> -0.30787358
A8: 98th & Grant | B8: CO | C8: 468.1 | D8: 0 | E8: =IF(AND(ISNUMBER(C8),ISNUMBER(D8)), C8-D8, "") -> 468.1 | F8: =IFERROR(E8/D8, "") | G8: 1170 | H8: =IF(AND(ISNUMBER(C8),ISNUMBER(G8)), C8-G8, "") -> -701.9 | I8: =IFERROR(H8/G8, "") -> -0.59991453
A9: Arapahoe Crossings | B9: CO | C9: 1869.1064 | D9: 0 | E9: =IF(AND(ISNUMBER(C9),ISNUMBER(D9)), C9-D9, "") -> 1869.1064 | F9: =IFERROR(E9/D9, "") | G9: 2127.951 | H9: =IF(AND(ISNUMBER(C9),ISNUMBER(G9)), C9-G9, "") -> -258.84462 | I9: =IFERROR(H9/G9, "") -> -0.12164031
A10: Aurora City Center | B10: CO | C10: 976.1 | D10: 0 | E10: =IF(AND(ISNUMBER(C10),ISNUMBER(D10)), C10-D10, "") -> 976.1 | F10: =IFERROR(E10/D10, "") | G10: 1050 | H10: =IF(AND(ISNUMBER(C10),ISNUMBER(G10)), C10-G10, "") -> -73.9 | I10: =IFERROR(H10/G10, "") -> -0.070380952
A11: Dry Creek | B11: CO | C11: 1116.8 | D11: 0 | E11: =IF(AND(ISNUMBER(C11),ISNUMBER(D11)), C11-D11, "") -> 1116.8 | F11: =IFERROR(E11/D11, "") | G11: 1261 | H11: =IF(AND(ISNUMBER(C11),ISNUMBER(G11)), C11-G11, "") -> -144.2 | I11: =IFERROR(H11/G11, "") -> -0.11435369
A12: Highlands Ranch S. | B12: CO | C12: 875.3 | D12: 0 | E12: =IF(AND(ISNUMBER(C12),ISNUMBER(D12)), C12-D12, "") -> 875.3 | F12: =IFERROR(E12/D12, "") | G12: 1109 | H12: =IF(AND(ISNUMBER(C12),ISNUMBER(G12)), C12-G12, "") -> -233.7 | I12: =IFERROR(H12/G12, "") -> -0.21073039 | J12: 1.Low generation due to weather/snow.
A13: Lone Tree | B13: CO | C13: 1474.8 | D13: 0 | E13: =IF(AND(ISNUMBER(C13),ISNUMBER(D13)), C13-D13, "") -> 1474.8 | F13: =IFERROR(E13/D13, "") | G13: 2554 | H13: =IF(AND(ISNUMBER(C13),ISNUMBER(G13)), C13-G13, "") -> -1079.2 | I13: =IFERROR(H13/G13, "") -> -0.42255286 | J13: 1.Low generation due to weather/snow.
A14: Meridian | B14: CO | C14: 1503.6 | D14: 0 | E14: =IF(AND(ISNUMBER(C14),ISNUMBER(D14)), C14-D14, "") -> 1503.6 | F14: =IFERROR(E14/D14, "") | G14: 1505 | H14: =IF(AND(ISNUMBER(C14),ISNUMBER(G14)), C14-G14, "") -> -1.4 | I14: =IFERROR(H14/G14, "") -> -0.00093023256
A15: Southglenn | B15: CO | C15: 1413.4 | D15: 0 | E15: =IF(AND(ISNUMBER(C15),ISNUMBER(D15)), C15-D15, "") -> 1413.4 | F15: =IFERROR(E15/D15, "") | H15: =IF(AND(ISNUMBER(C15),ISNUMBER(G15)), C15-G15, "") | I15: =IFERROR(H15/G15, "")
A16: Standley Lake | B16: CO | C16: 1429.4 | D16: 0 | E16: =IF(AND(ISNUMBER(C16),ISNUMBER(D16)), C16-D16, "") -> 1429.4 | F16: =IFERROR(E16/D16, "") | G16: 2142 | H16: =IF(AND(ISNUMBER(C16),ISNUMBER(G16)), C16-G16, "") -> -712.6 | I16: =IFERROR(H16/G16, "") -> -0.33267974 | J16: 1.Low generation due to weather/snow.
A17: Havana Gardens | B17: CO | C17: 1605.7 | D17: 0 | E17: =IF(AND(ISNUMBER(C17),ISNUMBER(D17)), C17-D17, "") -> 1605.7 | F17: =IFERROR(E17/D17, "") | G17: 839 | H17: =IF(AND(ISNUMBER(C17),ISNUMBER(G17)), C17-G17, "") -> 766.7 | I17: =IFERROR(H17/G17, "") -> 0.91382598
A18: East Hartford | B18: CT | C18: 207.4 | D18: 701.6656 | E18: =IF(AND(ISNUMBER(C18),ISNUMBER(D18)), C18-D18, "") -> -494.2656 | F18: =IFERROR(E18/D18, "") -> -0.7044176 | G18: 271.0787 | H18: =IF(AND(ISNUMBER(C18),ISNUMBER(G18)), C18-G18, "") -> -63.6787 | I18: =IFERROR(H18/G18, "") -> -0.23490853 | J18: 1.Low generation due to weather/snow.
A19: Norwalk | B19: CT | C19: -47.866832 | D19: 1301.297 | E19: =IF(AND(ISNUMBER(C19),ISNUMBER(D19)), C19-D19, "") -> -1349.1638 | F19: =IFERROR(E19/D19, "") -> -1.0367839 | G19: 380.0995 | H19: =IF(AND(ISNUMBER(C19),ISNUMBER(G19)), C19-G19, "") -> -427.96633 | I19: =IFERROR(H19/G19, "") -> -1.1259324 | J19: 1.Weather station reporting erroneous values from 07/04/2024. Will investigate next time onsite. 2.The meter's Phase C current/power factor was experiencing intermittent glitches, which are affecting the reported energy production, but there was no impact on actual production. Will investigate next time onsite. | K19: 1.SR088667 2.SR077700 | L19: SR077700
A20: Hialeah Gardens | B20: FL | C20: 2375.3065 | D20: 2836.864 | E20: =IF(AND(ISNUMBER(C20),ISNUMBER(D20)), C20-D20, "") -> -461.55753 | F20: =IFERROR(E20/D20, "") -> -0.16269991 | G20: 3416 | H20: =IF(AND(ISNUMBER(C20),ISNUMBER(G20)), C20-G20, "") -> -1040.6935 | I20: =IFERROR(H20/G20, "") -> -0.30465267 | J20: 1.Low generation due to weather/snow.
A21: W. Des Moines Campus EAST | B21: IA | C21: 118781 | D21: 137811.7 | E21: =IF(AND(ISNUMBER(C21),ISNUMBER(D21)), C21-D21, "") -> -19030.7 | F21: =IFERROR(E21/D21, "") -> -0.13809205 | G21: 103900 | H21: =IF(AND(ISNUMBER(C21),ISNUMBER(G21)), C21-G21, "") -> 14881 | I21: =IFERROR(H21/G21, "") -> 0.14322425
A22: W. Des Moines Campus SW | B22: IA | C22: 62762.75 | D22: 76926.26 | E22: =IF(AND(ISNUMBER(C22),ISNUMBER(D22)), C22-D22, "") -> -14163.51 | F22: =IFERROR(E22/D22, "") -> -0.18411801 | G22: 54917.89 | H22: =IF(AND(ISNUMBER(C22),ISNUMBER(G22)), C22-G22, "") -> 7844.86 | I22: =IFERROR(H22/G22, "") -> 0.14284708 | J22: 1.Low generation due to weather/snow.
A23: WF - CIC | B23: NC | C23: 116508 | D23: 113752.8 | E23: =IF(AND(ISNUMBER(C23),ISNUMBER(D23)), C23-D23, "") -> 2755.2 | F23: =IFERROR(E23/D23, "") -> 0.024220942 | G23: 106712 | H23: =IF(AND(ISNUMBER(C23),ISNUMBER(G23)), C23-G23, "") -> 9796 | I23: =IFERROR(H23/G23, "") -> 0.091798486
A24: Charlotte - Wells Fargo - DUC | B24: NC | C24: 110087 | D24: 128961.2 | E24: =IF(AND(ISNUMBER(C24),ISNUMBER(D24)), C24-D24, "") -> -18874.2 | F24: =IFERROR(E24/D24, "") -> -0.14635565 | G24: 129978 | H24: =IF(AND(ISNUMBER(C24),ISNUMBER(G24)), C24-G24, "") -> -19891 | I24: =IFERROR(H24/G24, "") -> -0.15303359 | J24: 1.Low generation due to weather/snow.
A25: East Windsor | B25: NJ | C25: 394.6 | D25: 635.3872 | E25: =IF(AND(ISNUMBER(C25),ISNUMBER(D25)), C25-D25, "") -> -240.7872 | F25: =IFERROR(E25/D25, "") -> -0.37896136 | G25: 406.457 | H25: =IF(AND(ISNUMBER(C25),ISNUMBER(G25)), C25-G25, "") -> -11.857 | I25: =IFERROR(H25/G25, "") -> -0.029171597 | J25: 1.Low generation due to weather/snow.
A26: Burlington | B26: NJ | C26: 1271.3 | D26: 1261 | E26: =IF(AND(ISNUMBER(C26),ISNUMBER(D26)), C26-D26, "") -> 10.3 | F26: =IFERROR(E26/D26, "") -> 0.0081681205 | G26: 1086.787 | H26: =IF(AND(ISNUMBER(C26),ISNUMBER(G26)), C26-G26, "") -> 184.513 | I26: =IFERROR(H26/G26, "") -> 0.16977844
A27: Bayonne | B27: NJ | C27: 1508.7 | D27: 1667.269 | E27: =IF(AND(ISNUMBER(C27),ISNUMBER(D27)), C27-D27, "") -> -158.569 | F27: =IFERROR(E27/D27, "") -> -0.095107028 | G27: 2001.37 | H27: =IF(AND(ISNUMBER(C27),ISNUMBER(G27)), C27-G27, "") -> -492.67 | I27: =IFERROR(H27/G27, "") -> -0.24616638 | J27: 1.Low generation due to weather/snow.
A28: Clifton | B28: NJ | C28: 1389.4922 | D28: 2166.088 | E28: =IF(AND(ISNUMBER(C28),ISNUMBER(D28)), C28-D28, "") -> -776.59581 | F28: =IFERROR(E28/D28, "") -> -0.35852459 | G28: 2509.623 | H28: =IF(AND(ISNUMBER(C28),ISNUMBER(G28)), C28-G28, "") -> -1120.1308 | I28: =IFERROR(H28/G28, "") -> -0.4463343 | J28: 1.Low generation due to weather/snow.
A29: North Elizabeth | B29: NJ | C29: 1257.8 | D29: 1301.25 | E29: =IF(AND(ISNUMBER(C29),ISNUMBER(D29)), C29-D29, "") -> -43.45 | F29: =IFERROR(E29/D29, "") -> -0.03339097 | G29: 1349.336 | H29: =IF(AND(ISNUMBER(C29),ISNUMBER(G29)), C29-G29, "") -> -91.536 | I29: =IFERROR(H29/G29, "") -> -0.067837811 | J29: 1. Low generation due to weather/snow.
A30: Haddon Westmont Plaza | B30: NJ | C30: 744.8 | D30: 1160.956 | E30: =IF(AND(ISNUMBER(C30),ISNUMBER(D30)), C30-D30, "") -> -416.156 | F30: =IFERROR(E30/D30, "") -> -0.35845975 | G30: 961.447 | H30: =IF(AND(ISNUMBER(C30),ISNUMBER(G30)), C30-G30, "") -> -216.647 | I30: =IFERROR(H30/G30, "") -> -0.22533431 | J30: 1.Low generation due to weather/snow.
A31: Parsippany | B31: NJ | C31: 1080 | D31: 2126.363 | E31: =IF(AND(ISNUMBER(C31),ISNUMBER(D31)), C31-D31, "") -> -1046.363 | F31: =IFERROR(E31/D31, "") -> -0.49209049 | G31: 1075.335 | H31: =IF(AND(ISNUMBER(C31),ISNUMBER(G31)), C31-G31, "") -> 4.665 | I31: =IFERROR(H31/G31, "") -> 0.004338183 | J31: 1.Low generation due to weather/snow.
A32: Clark | B32: NJ | C32: 904.5 | D32: 1197.726 | E32: =IF(AND(ISNUMBER(C32),ISNUMBER(D32)), C32-D32, "") -> -293.226 | F32: =IFERROR(E32/D32, "") -> -0.24481893 | G32: 915.5334 | H32: =IF(AND(ISNUMBER(C32),ISNUMBER(G32)), C32-G32, "") -> -11.0334 | I32: =IFERROR(H32/G32, "") -> -0.012051335 | J32: 1.Low generation due to weather/snow.
A33: Closter | B33: NJ | C33: 183.5 | D33: 273.6331 | E33: =IF(AND(ISNUMBER(C33),ISNUMBER(D33)), C33-D33, "") -> -90.1331 | F33: =IFERROR(E33/D33, "") -> -0.329394 | G33: 462.303 | H33: =IF(AND(ISNUMBER(C33),ISNUMBER(G33)), C33-G33, "") -> -278.803 | I33: =IFERROR(H33/G33, "") -> -0.60307417 | J33: 1.Low generation due to weather/snow.
A34: Holmdel | B34: NJ | C34: 761.3 | D34: 3879.251 | E34: =IF(AND(ISNUMBER(C34),ISNUMBER(D34)), C34-D34, "") -> -3117.951 | F34: =IFERROR(E34/D34, "") -> -0.80375078 | G34: 803.5939 | H34: =IF(AND(ISNUMBER(C34),ISNUMBER(G34)), C34-G34, "") -> -42.2939 | I34: =IFERROR(H34/G34, "") -> -0.052630937 | J34: 1.Low generation due to weather/snow.
A35: Ellisburg Circle Center | B35: NJ | C35: 357.1 | D35: 561.869 | E35: =IF(AND(ISNUMBER(C35),ISNUMBER(D35)), C35-D35, "") -> -204.769 | F35: =IFERROR(E35/D35, "") -> -0.3644426 | G35: 450.7773 | H35: =IF(AND(ISNUMBER(C35),ISNUMBER(G35)), C35-G35, "") -> -93.6773 | I35: =IFERROR(H35/G35, "") -> -0.20781282 | J35: 1.Low generation due to weather/snow.
A36: Nutley | B36: NJ | C36: 1173.7 | D36: 1685.373 | E36: =IF(AND(ISNUMBER(C36),ISNUMBER(D36)), C36-D36, "") -> -511.673 | F36: =IFERROR(E36/D36, "") -> -0.3035963 | G36: 1646.605 | H36: =IF(AND(ISNUMBER(C36),ISNUMBER(G36)), C36-G36, "") -> -472.905 | I36: =IFERROR(H36/G36, "") -> -0.28720003 | J36: 1.Low generation due to weather/snow.
A37: Marlton | B37: NJ | C37: 1398.6 | D37: 1470.661 | E37: =IF(AND(ISNUMBER(C37),ISNUMBER(D37)), C37-D37, "") -> -72.061 | F37: =IFERROR(E37/D37, "") -> -0.048999056 | G37: 1600.195 | H37: =IF(AND(ISNUMBER(C37),ISNUMBER(G37)), C37-G37, "") -> -201.595 | I37: =IFERROR(H37/G37, "") -> -0.12598152
A38: Middletown | B38: NJ | C38: 1802.6 | D38: 1488.243 | E38: =IF(AND(ISNUMBER(C38),ISNUMBER(D38)), C38-D38, "") -> 314.357 | F38: =IFERROR(E38/D38, "") -> 0.21122693 | G38: 1620.887 | H38: =IF(AND(ISNUMBER(C38),ISNUMBER(G38)), C38-G38, "") -> 181.713 | I38: =IFERROR(H38/G38, "") -> 0.11210714
A39: Whiting Crestwood | B39: NJ | C39: 2646.9 | D39: 2942.696 | E39: =IF(AND(ISNUMBER(C39),ISNUMBER(D39)), C39-D39, "") -> -295.796 | F39: =IFERROR(E39/D39, "") -> -0.10051871 | G39: 2442.152 | H39: =IF(AND(ISNUMBER(C39),ISNUMBER(G39)), C39-G39, "") -> 204.748 | I39: =IFERROR(H39/G39, "") -> 0.083839171
A40: Barnegat | B40: NJ | C40: 2473.5 | D40: 2067.944 | E40: =IF(AND(ISNUMBER(C40),ISNUMBER(D40)), C40-D40, "") -> 405.556 | F40: =IFERROR(E40/D40, "") -> 0.19611556 | G40: 2007.527 | H40: =IF(AND(ISNUMBER(C40),ISNUMBER(G40)), C40-G40, "") -> 465.973 | I40: =IFERROR(H40/G40, "") -> 0.23211294
...

Sheet Feb
A1: {=portfolio} -> Wells Fargo | D1: February Actual v. Expected | G1: February Actual v. Forecasted
A2: Total | C2: =SUM(C4:C97) -> 1283462.5 | D2: =SUM(D4:D97) -> 1301887.9 | E2: =C2-D2 -> -18425.44 | F2: =IFERROR(E2/D2, 0) -> -0.014152862 | G2: =SUM(G4:G97) -> 1468472.4 | H2: =C2-G2 -> -185009.98 | I2: =IFERROR(H2/G2, 0) -> -0.12598805 | J2: Some sites are missing actual data; if new sites were added, make sure they are aligned correctly (including prior months!)
A3: Site | B3: State | C3: Actual | D3: Expected | E3: Delta | F3: % | G3: Forecasted | H3: Delta | I3: % | J3: Notes | K3: Service Requests
A4: {=Sites[Site]} -> Adams & Broadway | B4: {=Sites[State]} -> CA | C4: 715.3 | D4: 0 | E4: =IF(AND(ISNUMBER(C4),ISNUMBER(D4)), C4-D4, "") -> 715.3 | F4: =IFERROR(E4/D4, "") | G4: 734 | H4: =IF(AND(ISNUMBER(C4),ISNUMBER(G4)), C4-G4, "") -> -18.7 | I4: =IFERROR(H4/G4, "") -> -0.025476839
A5: Otay Mesa | B5: CA | C5: 35.7 | D5: 0 | E5: =IF(AND(ISNUMBER(C5),ISNUMBER(D5)), C5-D5, "") -> 35.7 | F5: =IFERROR(E5/D5, "") | G5: 0 | H5: =IF(AND(ISNUMBER(C5),ISNUMBER(G5)), C5-G5, "") -> 35.7 | I5: =IFERROR(H5/G5, "") | J5: 1. Production data taken from consumption meter.
A6: San Leandro | B6: CA | C6: 23817.5 | D6: 28486.74 | E6: =IF(AND(ISNUMBER(C6),ISNUMBER(D6)), C6-D6, "") -> -4669.24 | F6: =IFERROR(E6/D6, "") -> -0.16390924 | G6: 25171.85 | H6: =IF(AND(ISNUMBER(C6),ISNUMBER(G6)), C6-G6, "") -> -1354.35 | I6: =IFERROR(H6/G6, "") -> -0.05380415 | J6: 1.Inverter 4 is underperforming by 7KW from 06/13/24 due to 2 non-operational strings. Inverter 2 underperforming by 3kW since 05/10/24 due to a string down and after technician replaced blown fuse on 02/20/25 inverter is producing in line with peers. Inverter 7 underperforming by 3kW since 09/09/24 due to a string down and after technician replaced blown fuse on 02/20/25 inverter is producing in line with peers. Inverter 5 underperforming by 4kW since 02/08/2 due to a string down. 2. Inverter 3 has a history of wire box damage, necessitating a complete inverter and wire box upgrade. The current wire box string fuse configuration was not acceptable. As a result, Inverter 3 has been undergoing the RMA process since 07/26/24. After the technician installed a new wire box, an arc fault was detected due to a damaged negative home run, which needs to be replaced. 3. SIte stopped communicating at 17:00 on 02/14 and regained communication at 8AM on 02/16 energy was not backfilled. | K6: 1.SR091496 2.SR088261, SR097801 3.SR097144 | L6: SR088261 | M6: SR097801 | N6: SR097144
A7: Van Nuys | B7: CA | C7: 1286.2 | D7: 0 | E7: =IF(AND(ISNUMBER(C7),ISNUMBER(D7)), C7-D7, "") -> 1286.2 | F7: =IFERROR(E7/D7, "") | G7: 1479.198 | H7: =IF(AND(ISNUMBER(C7),ISNUMBER(G7)), C7-G7, "") -> -192.998 | I7: =IFERROR(H7/G7, "") -> -0.13047476 | J7: 1. Low generation due to weather/snow.
A8: 98th & Grant | B8: CO | C8: 685.8 | D8: 0 | E8: =IF(AND(ISNUMBER(C8),ISNUMBER(D8)), C8-D8, "") -> 685.8 | F8: =IFERROR(E8/D8, "") | G8: 1280 | H8: =IF(AND(ISNUMBER(C8),ISNUMBER(G8)), C8-G8, "") -> -594.2 | I8: =IFERROR(H8/G8, "") -> -0.46421875 | J8: 1. Low generation due to weather/snow.
A9: Arapahoe Crossings | B9: CO | C9: 2273.604 | D9: 0 | E9: =IF(AND(ISNUMBER(C9),ISNUMBER(D9)), C9-D9, "") -> 2273.604 | F9: =IFERROR(E9/D9, "") | G9: 2351.179 | H9: =IF(AND(ISNUMBER(C9),ISNUMBER(G9)), C9-G9, "") -> -77.574992 | I9: =IFERROR(H9/G9, "") -> -0.032994082
A10: Aurora City Center | B10: CO | C10: 1251.8 | D10: 0 | E10: =IF(AND(ISNUMBER(C10),ISNUMBER(D10)), C10-D10, "") -> 1251.8 | F10: =IFERROR(E10/D10, "") | G10: 1140 | H10: =IF(AND(ISNUMBER(C10),ISNUMBER(G10)), C10-G10, "") -> 111.8 | I10: =IFERROR(H10/G10, "") -> 0.098070175
A11: Dry Creek | B11: CO | C11: 1268.3 | D11: 0 | E11: =IF(AND(ISNUMBER(C11),ISNUMBER(D11)), C11-D11, "") -> 1268.3 | F11: =IFERROR(E11/D11, "") | G11: 1386 | H11: =IF(AND(ISNUMBER(C11),ISNUMBER(G11)), C11-G11, "") -> -117.7 | I11: =IFERROR(H11/G11, "") -> -0.084920635
A12: Highlands Ranch S. | B12: CO | C12: 1187.6 | D12: 0 | E12: =IF(AND(ISNUMBER(C12),ISNUMBER(D12)), C12-D12, "") -> 1187.6 | F12: =IFERROR(E12/D12, "") | G12: 1265 | H12: =IF(AND(ISNUMBER(C12),ISNUMBER(G12)), C12-G12, "") -> -77.4 | I12: =IFERROR(H12/G12, "") -> -0.061185771
A13: Lone Tree | B13: CO | C13: 1907.1 | D13: 0 | E13: =IF(AND(ISNUMBER(C13),ISNUMBER(D13)), C13-D13, "") -> 1907.1 | F13: =IFERROR(E13/D13, "") | G13: 2891 | H13: =IF(AND(ISNUMBER(C13),ISNUMBER(G13)), C13-G13, "") -> -983.9 | I13: =IFERROR(H13/G13, "") -> -0.34033207 | J13: 1. Low generation due to weather/snow.
A14: Meridian | B14: CO | C14: 2004.1 | D14: 0 | E14: =IF(AND(ISNUMBER(C14),ISNUMBER(D14)), C14-D14, "") -> 2004.1 | F14: =IFERROR(E14/D14, "") | G14: 1699 | H14: =IF(AND(ISNUMBER(C14),ISNUMBER(G14)), C14-G14, "") -> 305.1 | I14: =IFERROR(H14/G14, "") -> 0.17957622
A15: Southglenn | B15: CO | C15: 1877.4 | D15: 0 | E15: =IF(AND(ISNUMBER(C15),ISNUMBER(D15)), C15-D15, "") -> 1877.4 | F15: =IFERROR(E15/D15, "") | H15: =IF(AND(ISNUMBER(C15),ISNUMBER(G15)), C15-G15, "") | I15: =IFERROR(H15/G15, "")
A16: Standley Lake | B16: CO | C16: 1987 | D16: 0 | E16: =IF(AND(ISNUMBER(C16),ISNUMBER(D16)), C16-D16, "") -> 1987 | F16: =IFERROR(E16/D16, "") | G16: 2371 | H16: =IF(AND(ISNUMBER(C16),ISNUMBER(G16)), C16-G16, "") -> -384 | I16: =IFERROR(H16/G16, "") -> -0.16195698 | J16: 1. Low generation due to weather/snow.
A17: Havana Gardens | B17: CO | C17: 2177 | D17: 0 | E17: =IF(AND(ISNUMBER(C17),ISNUMBER(D17)), C17-D17, "") -> 2177 | F17: =IFERROR(E17/D17, "") | G17: 926 | H17: =IF(AND(ISNUMBER(C17),ISNUMBER(G17)), C17-G17, "") -> 1251 | I17: =IFERROR(H17/G17, "") -> 1.3509719 | J17: 1. Low generation due to weather/snow.
A18: East Hartford | B18: CT | C18: 203.1 | D18: 980.1935 | E18: =IF(AND(ISNUMBER(C18),ISNUMBER(D18)), C18-D18, "") -> -777.0935 | F18: =IFERROR(E18/D18, "") -> -0.79279601 | G18: 429.0254 | H18: =IF(AND(ISNUMBER(C18),ISNUMBER(G18)), C18-G18, "") -> -225.9254 | I18: =IFERROR(H18/G18, "") -> -0.52660146 | J18: 1. Low generation due to weather/snow.
A19: Norwalk | B19: CT | C19: 219.84971 | D19: 426.5024 | E19: =IF(AND(ISNUMBER(C19),ISNUMBER(D19)), C19-D19, "") -> -206.65269 | F19: =IFERROR(E19/D19, "") -> -0.48452879 | G19: 487.9305 | H19: =IF(AND(ISNUMBER(C19),ISNUMBER(G19)), C19-G19, "") -> -268.08079 | I19: =IFERROR(H19/G19, "") -> -0.54942414 | J19: 1.Weather station reporting erroneous values from 07/04/2024. Will investigate next time onsite. 2.The meter's Phase C current/power factor was experiencing intermittent glitches, which are affecting the reported energy production, but there was no impact on actual production. Will investigate next time onsite. | K19: 1.SR088667 2.SR077700 | L19: SR077700
A20: Hialeah Gardens | B20: FL | C20: 2564.7028 | D20: 3093.609 | E20: =IF(AND(ISNUMBER(C20),ISNUMBER(D20)), C20-D20, "") -> -528.90617 | F20: =IFERROR(E20/D20, "") -> -0.17096736 | G20: 3739 | H20: =IF(AND(ISNUMBER(C20),ISNUMBER(G20)), C20-G20, "") -> -1174.2972 | I20: =IFERROR(H20/G20, "") -> -0.31406718 | J20: 1. Low generation due to weather/snow.
A21: W. Des Moines Campus EAST | B21: IA | C21: 116148 | D21: 129057.3 | E21: =IF(AND(ISNUMBER(C21),ISNUMBER(D21)), C21-D21, "") -> -12909.3 | F21: =IFERROR(E21/D21, "") -> -0.10002766 | G21: 124800 | H21: =IF(AND(ISNUMBER(C21),ISNUMBER(G21)), C21-G21, "") -> -8652 | I21: =IFERROR(H21/G21, "") -> -0.069326923
A22: W. Des Moines Campus SW | B22: IA | C22: 49019.25 | D22: 70697.89 | E22: =IF(AND(ISNUMBER(C22),ISNUMBER(D22)), C22-D22, "") -> -21678.64 | F22: =IFERROR(E22/D22, "") -> -0.30663772 | G22: 62858.07 | H22: =IF(AND(ISNUMBER(C22),ISNUMBER(G22)), C22-G22, "") -> -13838.82 | I22: =IFERROR(H22/G22, "") -> -0.2201598 | J22: 1. Low generation due to weather/snow.
A23: WF - CIC | B23: NC | C23: 121252 | D23: 120285.93 | E23: =IF(AND(ISNUMBER(C23),ISNUMBER(D23)), C23-D23, "") -> 966.073 | F23: =IFERROR(E23/D23, "") -> 0.0080314715 | G23: 116371 | H23: =IF(AND(ISNUMBER(C23),ISNUMBER(G23)), C23-G23, "") -> 4881 | I23: =IFERROR(H23/G23, "") -> 0.04194344
A24: Charlotte - Wells Fargo - DUC | B24: NC | C24: 115950 | D24: 130575.52 | E24: =IF(AND(ISNUMBER(C24),ISNUMBER(D24)), C24-D24, "") -> -14625.523 | F24: =IFERROR(E24/D24, "") -> -0.11200815 | G24: 128348.52 | H24: =IF(AND(ISNUMBER(C24),ISNUMBER(G24)), C24-G24, "") -> -12398.516 | I24: =IFERROR(H24/G24, "") -> -0.096600385
A25: East Windsor | B25: NJ | C25: 572.2 | D25: 628.52 | E25: =IF(AND(ISNUMBER(C25),ISNUMBER(D25)), C25-D25, "") -> -56.32 | F25: =IFERROR(E25/D25, "") -> -0.089607332 | G25: 479.2575 | H25: =IF(AND(ISNUMBER(C25),ISNUMBER(G25)), C25-G25, "") -> 92.9425 | I25: =IFERROR(H25/G25, "") -> 0.19393019
A26: Burlington | B26: NJ | C26: 1564 | D26: 1361.461 | E26: =IF(AND(ISNUMBER(C26),ISNUMBER(D26)), C26-D26, "") -> 202.539 | F26: =IFERROR(E26/D26, "") -> 0.14876592 | G26: 1358.153 | H26: =IF(AND(ISNUMBER(C26),ISNUMBER(G26)), C26-G26, "") -> 205.847 | I26: =IFERROR(H26/G26, "") -> 0.15156393
A27: Bayonne | B27: NJ | C27: 1883.8 | D27: 1981.854 | E27: =IF(AND(ISNUMBER(C27),ISNUMBER(D27)), C27-D27, "") -> -98.054 | F27: =IFERROR(E27/D27, "") -> -0.049475895 | G27: 2310.944 | H27: =IF(AND(ISNUMBER(C27),ISNUMBER(G27)), C27-G27, "") -> -427.144 | I27: =IFERROR(H27/G27, "") -> -0.18483529 | J27: 1. Low generation due to weather/snow.
A28: Clifton | B28: NJ | C28: 2260.6562 | D28: 2567.895 | E28: =IF(AND(ISNUMBER(C28),ISNUMBER(D28)), C28-D28, "") -> -307.23875 | F28: =IFERROR(E28/D28, "") -> -0.11964615 | G28: 3023.081 | H28: =IF(AND(ISNUMBER(C28),ISNUMBER(G28)), C28-G28, "") -> -762.42475 | I28: =IFERROR(H28/G28, "") -> -0.25220123 | J28: 1. Low generation due to weather/snow.
A29: North Elizabeth | B29: NJ | C29: 1699.2 | D29: 1480.147 | E29: =IF(AND(ISNUMBER(C29),ISNUMBER(D29)), C29-D29, "") -> 219.053 | F29: =IFERROR(E29/D29, "") -> 0.14799408 | G29: 1907.788 | H29: =IF(AND(ISNUMBER(C29),ISNUMBER(G29)), C29-G29, "") -> -208.588 | I29: =IFERROR(H29/G29, "") -> -0.109335 | J29: 1. Low generation due to weather/snow.
